{"op":"mcm","id":2,"clk":"AMIwALJBALlH","pt":1710508008987,"mc":[{"id":"1.226122413","rc":[{"batl":[[2,260,2.65],[1,250,1.98],[0,240,1.49]],"id":41200638}]}],"ArrivalTime":1710508008994}
{"op":"mcm","id":2,"clk":"AMgwALxBAMBH","pt":1710508009098,"mc":[{"id":"1.226122413","rc":[{"batb":[[0,8.2,52.55]],"id":41122648},{"batb":[[2,190,1.11],[1,200,3.59],[0,210,1.43]],"id":41200638}]}],"ArrivalTime":1710508009105}
{"op":"mcm","id":2,"clk":"AM0wAMtBAMpH","pt":1710508009202,"mc":[{"id":"1.226122413","rc":[{"batl":[[0,8.4,14.69]],"id":41122648}]}],"ArrivalTime":1710508009209}
{"op":"mcm","id":2,"clk":"ANUwANFBANNH","pt":1710508009309,"mc":[{"id":"1.226122413","rc":[{"batl":[[2,270,1.19],[1,260,2.65],[0,250,2.22]],"id":41200638}]}],"ArrivalTime":1710508009317}
{"op":"mcm","id":2,"clk":"AN0wANpBANxH","pt":1710508009404,"mc":[{"id":"1.226122413","rc":[{"batl":[[2,280,1.33],[1,270,1.19],[0,260,3.61]],"id":41200638}]}],"ArrivalTime":1710508009412}
{"op":"mcm","id":2,"clk":"AOYwAOVBAOlH","pt":1710508009512,"mc":[{"id":"1.226122413","rc":[{"tv":13832.35,"batb":[[0,4.4,72.73]],"trd":[[4.4,3308.05]],"id":50466254}],"tv":101022.6}],"ArrivalTime":1710508009519}
{"op":"mcm","id":2,"clk":"AO4wAOhBAPNH","pt":1710508009614,"mc":[{"id":"1.226122413","rc":[{"batl":[[0,4.5,99.55]],"id":50466254}]}],"ArrivalTime":1710508009622}
{"op":"mcm","id":2,"clk":"AIoxAI1CAKdI","pt":1710508010028,"mc":[{"id":"1.226122413","rc":[{"tv":72642.73,"batb":[[0,1.87,76.78]],"trd":[[1.87,7083.73]],"id":51922},{"tv":13892.51,"batb":[[0,4.4,42.64]],"trd":[[4.4,3368.21]],"id":50466254}],"tv":101122.4}],"ArrivalTime":1710508010036}
{"op":"mcm","id":2,"clk":"AJAxAJRCALFI","pt":1710508010131,"mc":[{"id":"1.226122413","rc":[{"batb":[[0,8.2,62.55]],"id":41122648},{"batb":[[0,1.87,78.78]],"id":51922}]}],"ArrivalTime":1710508010138}
{"op":"mcm","id":2,"clk":"AJkxAKFCAL1I","pt":1710508010231,"mc":[{"id":"1.226122413","rc":[{"batb":[[0,1.87,120.57]],"id":51922}]}],"ArrivalTime":1710508010239}
{"op":"mcm","id":2,"clk":"AJ0xAKlCAMVI","pt":1710508010339,"mc":[{"id":"1.226122413","rc":[{"batb":[[2,280,1.17]],"id":54370634},{"batb":[[0,4.4,101.76]],"id":50466254}]}],"ArrivalTime":1710508010347}
{"op":"mcm","id":2,"clk":"AKIxAK5CANBI","pt":1710508010438,"mc":[{"id":"1.226122413","rc":[{"batl":[[0,26,6.63]],"id":55632148},{"batb":[[0,1.87,207]],"id":51922}]}],"ArrivalTime":1710508010445}
{"op":"mcm","id":2,"clk":"AKsxAMJCAONI","pt":1710508010599,"mc":[{"id":"1.226122413","rc":[{"batl":[[2,1.9,257.28]],"id":51922}]}],"ArrivalTime":1710508010607}
{"op":"mcm","id":2,"clk":"ALIxAMdCAPBI","pt":1710508010706,"mc":[{"id":"1.226122413","rc":[{"tv":72662.09,"trd":[[1.88,6902.34]],"ltp":1.88,"batl":[[0,1.88,248.62]],"id":51922},{"batl":[[0,4.5,199.55]],"id":50466254}],"tv":101141.76}],"ArrivalTime":1710508010713}
{"op":"mcm","id":2,"clk":"ANIxAO5CAJxJ","pt":1710508011223,"mc":[{"id":"1.226122413","rc":[{"batb":[[0,1.87,1060.98]],"id":51922}]}],"ArrivalTime":1710508011230}
{"op":"mcm","id":2,"clk":"ANgxAPdCAKxJ","pt":1710508011361,"mc":[{"id":"1.226122413","rc":[{"tv":72666.97,"batb":[[2,1.85,510.22]],"trd":[[1.88,6907.22]],"batl":[[0,1.88,206.96]],"id":51922},{"tv":14096.03,"batb":[[2,4.1,115.65],[1,4.2,177.91],[0,4.3,249.02]],"trd":[[4.4,3571.73]],"id":50466254}],"tv":101350.16}],"ArrivalTime":1710508011368}
{"op":"mcm","id":2,"clk":"AOAxAP5CALFJ","pt":1710508011426,"mc":[{"id":"1.226122413","rc":[{"tv":72787.01,"trd":[[1.88,7027.26]],"batl":[[0,1.88,146.94]],"id":51922}],"tv":101470.2}],"ArrivalTime":1710508011434}
{"op":"mcm","id":2,"clk":"AOYxAIpDAL9J","pt":1710508011528,"mc":[{"id":"1.226122413","rc":[{"tv":7401.59,"trd":[[8.4,858.92]],"batl":[[0,8.4,8.08]],"id":41122648},{"tv":433.79,"batb":[[2,180,1.42],[1,190,1.11],[0,200,1.02]],"trd":[[210,22.74],[200,75.3]],"ltp":200,"id":41200638},{"tv":73080.87,"batb":[[0,1.87,1062.98]],"trd":[[1.88,7321.12]],"batl":[[2,1.91,231.16],[1,1.9,257.28],[0,1.89,225.95]],"id":51922},{"tv":2318.18,"trd":[[38,29.78]],"batl":[[0,38,11.1]],"id":49744721},{"tv":14114.03,"batb":[[2,4.1,83.39],[0,4.3,263.18]],"trd":[[4.5,2893.24]],"ltp":4.5,"batl":[[0,4.5,190.55]],"id":50466254},{"tv":1844.18,"trd":[[25,188.33]],"ltp":25,"batl":[[0,25,27.39]],"id":106596}],"tv":101817.56}],"ArrivalTime":1710508011536}
{"op":"mcm","id":2,"clk":"AO0xAJRDAM5J","pt":1710508011634,"mc":[{"id":"1.226122413","rc":[{"batb":[[2,1.86,377.66],[1,1.87,1062.98],[0,1.88,253.58]],"id":51922}]}],"ArrivalTime":1710508011642}
{"op":"mcm","id":2,"clk":"APUxAJ5DANtJ","pt":1710508011741,"mc":[{"id":"1.226122413","rc":[{"batb":[[2,170,19.37],[0,200,1.16]],"batl":[[2,270,1.19],[1,260,2.65],[0,250,2.07]],"id":41200638},{"batb":[[2,1.86,283.66]],"id":51922},{"batl":[[0,38,8.73]],"id":49744721},{"batb":[],"batl":[[0,4.5,211.31]],"id":50466254},{"batb":[[0,23,23.92]],"id":106596}]}],"ArrivalTime":1710508011749}
{"op":"mcm","id":2,"clk":"APsxAKZDAOhJ","pt":1710508011843,"mc":[{"id":"1.226122413","rc":[{"batb":[[1,8,111.35]],"id":41122648},{"batb":[[0,200,2.54]],"id":41200638},{"batl":[[1,27,13.8]],"id":55632148},{"tv":73081.02,"batb":[[0,1.88,374.35]],"trd":[[1.89,2886.41]],"ltp":1.89,"batl":[[0,1.89,199.2]],"id":51922},{"batb":[[2,4.1,100.48]],"batl":[],"id":50466254}],"tv":101817.71}],"ArrivalTime":1710508011850}
{"op":"mcm","id":2,"clk":"AIYyAK9DAPJJ","pt":1710508011947,"mc":[{"id":"1.226122413","rc":[{"batb":[[2,190,1.11],[1,200,2.54],[0,210,9]],"batl":[[2,260,2.65],[1,250,1.83],[0,240,1.39]],"id":41200638},{"tv":73091.02,"batb":[[1,1.87,1065.98],[0,1.88,369.35]],"trd":[[1.88,7331.12]],"ltp":1.88,"id":51922},{"batl":[[1,40,12.68],[0,38,10.73]],"id":49744721},{"batl":[[0,4.5,212.31]],"id":50466254}],"tv":101827.71}],"ArrivalTime":1710508011954}
{"op":"mcm","id":2,"clk":"AIwyALpDAIBK","pt":1710508012000,"mc":[{"id":"1.226122413","rc":[{"batb":[[1,8,127.3]],"id":41122648},{"tv":73130.26,"trd":[[1.89,2925.65]],"ltp":1.89,"batl":[[0,1.89,179.58]],"id":51922},{"batl":[[2,4.6,172.94],[1,4.5,212.31],[0,4.4,49.77]],"id":50466254},{"batb":[[1,22,22.64]],"id":106596}],"tv":101866.95}],"ArrivalTime":1710508012008}
{"op":"mcm","id":2,"clk":"AJUyAM1DAI1K","pt":1710508012113,"mc":[{"id":"1.226122413","rc":[{"batb":[[0,210,10.31]],"batl":[[2,250,1.83],[1,240,1.15],[0,230,1.43]],"id":41200638},{"batb":[[0,4.3,258.95]],"batl":[[2,4.6,176.95]],"id":50466254}]}],"ArrivalTime":1710508012122}
{"op":"mcm","id":2,"clk":"AJkyANpDAJlK","pt":1710508012214,"mc":[{"id":"1.226122413","rc":[{"batl":[[2,250,2.83]],"id":41200638},{"tv":73172.19,"batb":[[0,1.88,368.01]],"trd":[[1.88,7333.81],[1.89,2964.89]],"batl":[[0,1.89,159.96]],"id":51922}],"tv":101908.88}],"ArrivalTime":1710508012222}
{"op":"mcm","id":2,"clk":"AJ8yAOFDAKZK","pt":1710508012313,"mc":[{"id":"1.226122413","rc":[{"tv":433.93,"trd":[[220,45.44]],"ltp":220,"batl":[[0,230,1.36]],"id":41200638},{"tv":73222.19,"trd":[[1.89,3014.89]],"batl":[[0,1.89,134.96]],"id":51922},{"batl":[[0,4.4,130.77]],"id":50466254}],"tv":101959.02}],"ArrivalTime":1710508012321}
{"op":"mcm","id":2,"clk":"AKEyAO5DALBK","pt":1710508012414,"mc":[{"id":"1.226122413","rc":[{"tv":73294.03,"trd":[[1.89,3086.73]],"batl":[[0,1.89,99.04]],"id":51922}],"tv":102030.86}],"ArrivalTime":1710508012422}
{"op":"mcm","id":2,"clk":"AKcyAPZDALtK","pt":1710508012543,"mc":[{"id":"1.226122413","rc":[{"batb":[[1,1.87,1134.98]],"id":51922},{"batb":[[0,4.3,244.79]],"id":50466254}]}],"ArrivalTime":1710508012553}
{"op":"mcm","id":2,"clk":"AK4yAPpDAMtK","pt":1710508012621,"mc":[{"id":"1.226122413","rc":[{"tv":7405.01,"batb":[[0,8.2,60.84]],"trd":[[8.2,487.26]],"ltp":8.2,"id":41122648},{"tv":2324.18,"batb":[[0,34,27.09]],"trd":[[34,137.03]],"ltp":34,"id":49744721}],"tv":102040.28}],"ArrivalTime":1710508012628}
{"op":"mcm","id":2,"clk":"ALYyAIZEANZK","pt":1710508012727,"mc":[{"id":"1.226122413","rc":[{"tv":73341.4,"batb":[[1,1.87,1136.98]],"trd":[[1.89,3134.1]],"batl":[[0,1.89,75.35]],"id":51922},{"batl":[[0,4.4,136.77]],"id":50466254}],"tv":102087.65}],"ArrivalTime":1710508012735}
{"op":"mcm","id":2,"clk":"ALwyAJJEAN9K","pt":1710508012831,"mc":[{"id":"1.226122413","rc":[{"batl":[[0,8.4,20.68]],"id":41122648},{"batb":[[1,1.87,1139.28]],"id":51922},{"batl":[[0,38,11.17]],"id":49744721}]}],"ArrivalTime":1710508012839}
{"op":"mcm","id":2,"clk":"AL4yAKFEAO1K","pt":1710508012932,"mc":[{"id":"1.226122413","rc":[{"batl":[[2,250,1.83]],"id":41200638},{"tv":1783.01,"batb":[[0,25,5.28]],"trd":[[25,339.36]],"ltp":25,"id":55632148},{"batb":[[0,34,30.09]],"id":49744721},{"tv":14133.53,"batb":[[0,4.3,235.04]],"trd":[[4.3,3852.29]],"ltp":4.3,"id":50466254}],"tv":102117.15}],"ArrivalTime":1710508012939}
{"op":"mcm","id":2,"clk":"AMIyAKxEAPtK","pt":1710508013039,"mc":[{"id":"1.226122413","rc":[{"tv":7446.37,"trd":[[8.4,900.28]],"ltp":8.4,"batl":[[2,9,36.42],[1,8.8,26.49],[0,8.6,25.41]],"id":41122648},{"tv":73400.08,"batb":[[2,1.86,285.99]],"trd":[[1.89,3192.78]],"batl":[[0,1.89,46.01]],"id":51922},{"batb":[[2,21,53.27]],"id":106596}],"tv":102217.19}],"ArrivalTime":1710508013046}
{"op":"mcm","id":2,"clk":"AMkyALVEAIZL","pt":1710508013141,"mc":[{"id":"1.226122413","rc":[{"batb":[[0,25,8.28]],"id":55632148},{"tv":73492.1,"batb":[[2,1.87,1139.28],[1,1.88,368.01],[0,1.89,94.52]],"trd":[[1.89,3284.8]],"batl":[[2,1.92,344.95],[1,1.91,231.16],[0,1.9,257.28]],"id":51922},{"batl":[[1,40,15.92]],"id":49744721},{"batb":[[0,4.3,243.79]],"id":50466254}],"tv":102309.21}],"ArrivalTime":1710508013149}
{"op":"mcm","id":2,"clk":"ANAyAMREAJRL","pt":1710508013251,"mc":[{"id":"1.226122413","rc":[{"batb":[[2,8,127.3],[1,8.2,75.23],[0,8.4,21.1]],"id":41122648},{"batl":[[0,4.4,163.33]],"id":50466254}]}],"ArrivalTime":1710508013259}
{"op":"mcm","id":2,"clk":"ANUyAM9EAJxL","pt":1710508013354,"mc":[{"id":"1.226122413","rc":[{"batb":[[1,24,14.53]],"id":55632148},{"batl":[[0,38,14.01]],"id":49744721},{"batb":[],"batl":[[2,4.6,180.04]],"id":50466254}]}],"ArrivalTime":1710508013362}
{"op":"mcm","id":2,"clk":"ANwyANdEAKVL","pt":1710508013406,"mc":[{"id":"1.226122413","rc":[{"batb":[[2,8,95.41]],"batl":[],"id":41122648},{"batb":[[2,1.86,285.99],[1,1.87,1139.28],[0,1.88,368.01]],"batl":[],"id":51922}]}],"ArrivalTime":1710508013413}
{"op":"mcm","id":2,"clk":"AIIzAJ9FAPBL","pt":1710508014044,"mc":[{"id":"1.226122413","rc":[{"tv":357.68,"trd":[[400,26.12]],"batl":[[0,410,3.14]],"id":54370634},{"tv":7470.47,"batb":[[0,8.4,9.05],[2,8,110.98]],"trd":[[8.4,924.38]],"batl":[[0,8.6,24.24]],"id":41122648},{"tv":434.27,"batb":[[0,210,12.31]],"trd":[[220,45.78]],"batl":[[0,230,1.19]],"id":41200638},{"batl":[[1,27,13.06]],"id":55632148},{"tv":73492.2,"batb":[[0,1.88,370.23],[1,1.87,292.5]],"trd":[[1.88,7333.91]],"ltp":1.88,"batl":[[1,1.91,188.46],[0,1.9,214.58]],"id":51922},{"tv":14133.63,"batb":[[0,4.3,245.74]],"trd":[[4.3,3852.39]],"batl":[[2,4.6,176.95]],"id":50466254}],"tv":102334.37,"con":true}],"ArrivalTime":1710508014052}
{"op":"mcm","id":2,"clk":"AIszAKlFAPZL","pt":1710508014134,"mc":[{"id":"1.226122413","rc":[{"batl":[[0,8.6,26.24]],"id":41122648}]}],"ArrivalTime":1710508014142}
{"op":"mcm","id":2,"clk":"AJEzAK9FAIBM","pt":1710508014238,"mc":[{"id":"1.226122413","rc":[{"batb":[[2,200,2.54],[1,210,12.31],[0,220,2]],"batl":[[2,260,2.65],[1,250,1.83],[0,240,1.15]],"id":41200638},{"tv":1884.18,"trd":[[25,228.33]],"batl":[[0,25,7.39]],"id":106596}],"tv":102374.37}],"ArrivalTime":1710508014246}
{"op":"mcm","id":2,"clk":"AJkzALxFAIhM","pt":1710508014343,"mc":[{"id":"1.226122413","rc":[{"batb":[[0,34,26.38]],"id":49744721},{"batb":[],"batl":[[0,25,5.73]],"id":106596}]}],"ArrivalTime":1710508014351}
{"op":"mcm","id":2,"clk":"AJ4zAMBFAJRM","pt":1710508014442,"mc":[{"id":"1.226122413","rc":[{"tv":14147.63,"trd":[[4.4,3585.73]],"ltp":4.4,"batl":[[0,4.4,156.33]],"id":50466254},{"tv":1895.63,"batb":[[2,23,23.48],[1,24,8.22],[0,25,14.27]],"trd":[[25,239.78]],"batl":[[2,28,8.7],[1,27,6.4],[0,26,30.1]],"id":106596}],"tv":102399.82}],"ArrivalTime":1710508014450}
{"op":"mcm","id":2,"clk":"AK8zANJFALBM","pt":1710508014644,"mc":[{"id":"1.226122413","rc":[{"batb":[[2,7.8,68.7],[1,8,110.98],[0,8.2,75.23]],"id":41122648},{"batl":[[2,28,27.86]],"id":55632148},{"batb":[[0,1.88,343.46]],"batl":[[2,1.91,188.46],[1,1.9,291.38],[0,1.89,27.59]],"id":51922},{"tv":14149.81,"trd":[[4.4,3587.91]],"batl":[[0,4.4,155.24]],"id":50466254},{"tv":1924.17,"batb":[[2,22,22.64],[1,23,23.48],[0,24,12.32]],"trd":[[25,268.32]],"id":106596}],"tv":102430.54}],"ArrivalTime":1710508014653}
{"op":"mcm","id":2,"clk":"AL4zAN5FAMBM","pt":1710508014854,"mc":[{"id":"1.226122413","rc":[{"batb":[[0,330,4.4]],"id":54370634},{"batb":[[1,210,13.31]],"id":41200638},{"batl":[[2,28,28.55]],"id":55632148},{"batl":[[0,1.89,94.58]],"id":51922},{"batl":[[2,42,7.94],[1,40,18.48]],"id":49744721},{"batb":[[0,24,22.82]],"batl":[[1,27,7.43],[0,26,24.8]],"id":106596}]}],"ArrivalTime":1710508014862}
{"op":"mcm","id":2,"clk":"AMMzAOFFAMtM","pt":1710508014912,"mc":[{"id":"1.226122413","rc":[{"batb":[[1,1.87,294.5]],"id":51922}]}],"ArrivalTime":1710508014920}
{"op":"mcm","id":2,"clk":"AMszAOtFANZM","pt":1710508015015,"mc":[{"id":"1.226122413","rc":[{"batb":[[0,220,3.21]],"id":41200638},{"batb":[[0,1.88,307.52]],"batl":[[1,1.9,289.38]],"id":51922}]}],"ArrivalTime":1710508015023}
{"op":"mcm","id":2,"clk":"ANUzAPJFAOJM","pt":1710508015116,"mc":[{"id":"1.226122413","rc":[{"tv":73492.54,"batb":[[0,1.88,312.52]],"trd":[[1.89,3285.14]],"ltp":1.89,"batl":[[0,1.89,94.41]],"id":51922},{"batb":[],"batl":[[1,27,6.4]],"id":106596}],"tv":102430.88}],"ArrivalTime":1710508015124}
{"op":"mcm","id":2,"clk":"ANozAPlFAO1M","pt":1710508015221,"mc":[{"id":"1.226122413","rc":[{"batb":[[1,210,11.31]],"id":41200638},{"tv":73501.42,"trd":[[1.89,3294.02]],"batl":[[0,1.89,89.97]],"id":51922}],"tv":102439.76}],"ArrivalTime":1710508015231}
{"op":"mcm","id":2,"clk":"AOMzAIJGAPtM","pt":1710508015318,"mc":[{"id":"1.226122413","rc":[{"batb":[[2,200,3.58]],"id":41200638},{"batb":[[0,4.3,247.74]],"id":50466254}]}],"ArrivalTime":1710508015326}
{"op":"mcm","id":2,"clk":"AOozAItGAIRN","pt":1710508015421,"mc":[{"id":"1.226122413","rc":[{"tv":1805.59,"batb":[[2,22,26.29],[1,23,13.81],[0,24,11.52]],"trd":[[25,355.92],[24,219.81]],"ltp":24,"id":55632148},{"batb":[[1,1.87,251.81]],"id":51922}],"tv":102462.34}],"ArrivalTime":1710508015428}
{"op":"mcm","id":2,"clk":"APEzAJVGAJBN","pt":1710508015525,"mc":[{"id":"1.226122413","rc":[{"batl":[[0,8.6,27.41]],"id":41122648},{"batl":[[2,27,13.06],[1,26,6.63],[0,25,3.38]],"id":55632148}]}],"ArrivalTime":1710508015533}
{"op":"mcm","id":2,"clk":"APozAJtGAJhN","pt":1710508015631,"mc":[{"id":"1.226122413","rc":[{"batb":[[2,22,21.48],[0,24,12.03]],"batl":[[1,26,9.27]],"id":55632148}]}],"ArrivalTime":1710508015639}
{"op":"mcm","id":2,"clk":"AIE0AKRGAKRN","pt":1710508015738,"mc":[{"id":"1.226122413","rc":[{"batb":[[2,22,20.97]],"id":55632148}]}],"ArrivalTime":1710508015745}
{"op":"mcm","id":2,"clk":"AIQ0AKtGAKtN","pt":1710508015840,"mc":[{"id":"1.226122413","rc":[{"tv":73505.42,"batb":[[0,1.88,310.52]],"trd":[[1.88,7337.91]],"ltp":1.88,"id":51922}],"tv":102466.34}],"ArrivalTime":1710508015848}
{"op":"mcm","id":2,"clk":"AIw0ALFGALNN","pt":1710508015939,"mc":[{"id":"1.226122413","rc":[{"batl":[[1,4.5,214.31]],"id":50466254}]}],"ArrivalTime":1710508015947}
{"op":"mcm","id":2,"clk":"AJE0ALtGALxN","pt":1710508016050,"mc":[{"id":"1.226122413","rc":[{"batb":[[1,1.87,253.81]],"id":51922},{"tv":14203.81,"batb":[[0,4.3,220.74]],"trd":[[4.3,3906.39]],"ltp":4.3,"id":50466254}],"tv":102520.34}],"ArrivalTime":1710508016058}
{"op":"mcm","id":2,"clk":"AJ80ANRGAOBN","pt":1710508016355,"mc":[{"id":"1.226122413","rc":[{"batl":[[2,1.91,190.46]],"id":51922}]}],"ArrivalTime":1710508016362}
{"op":"mcm","id":2,"clk":"AKc0ANxGAOhN","pt":1710508016407,"mc":[{"id":"1.226122413","rc":[{"batb":[[2,200,4.62]],"id":41200638},{"batb":[[0,1.88,312.09]],"id":51922},{"batl":[[1,4.5,216.31]],"id":50466254}]}],"ArrivalTime":1710508016414}
{"op":"mcm","id":2,"clk":"AK00AOdGAPZN","pt":1710508016529,"mc":[{"id":"1.226122413","rc":[{"tv":73545.42,"batb":[[0,1.88,321.9]],"trd":[[1.88,7377.91]],"id":51922}],"tv":102560.34}],"ArrivalTime":1710508016537}
{"op":"mcm","id":2,"clk":"ALY0APVGAIRO","pt":1710508016678,"mc":[{"id":"1.226122413","rc":[{"batb":[[1,23,19.87]],"id":55632148},{"batl":[[0,1.89,66.99]],"id":51922}]}],"ArrivalTime":1710508016686}
{"op":"mcm","id":2,"clk":"AL80APpGAI9O","pt":1710508016734,"mc":[{"id":"1.226122413","rc":[{"batb":[[2,7.8,65.02]],"batl":[[2,9,32.58]],"id":41122648},{"tv":73585.42,"batb":[[0,1.88,301.9]],"trd":[[1.88,7417.91]],"batl":[],"id":51922},{"batb":[[2,4.1,94.34]],"batl":[[2,4.6,172.94]],"id":50466254}],"tv":102600.34}],"ArrivalTime":1710508016742}
{"op":"mcm","id":2,"clk":"AMY0AIFHAJxO","pt":1710508016833,"mc":[{"id":"1.226122413","rc":[{"batb":[[2,22,23.97],[1,23,13.81]],"batl":[],"id":55632148}]}],"ArrivalTime":1710508016841}
{"op":"mcm","id":2,"clk":"AMw0AIhHAKNO","pt":1710508016934,"mc":[{"id":"1.226122413","rc":[{"tv":73661.26,"batb":[[0,1.88,281.06]],"trd":[[1.88,7459.59],[1.89,3328.18]],"ltp":1.89,"batl":[[0,1.89,49.91]],"id":51922},{"tv":14208.87,"batb":[[0,4.3,220.62]],"trd":[[4.4,3592.73],[4.3,3906.63]],"batl":[[0,4.4,147.83]],"id":50466254}],"tv":102681.24}],"ArrivalTime":1710508016942}
{"op":"mcm","id":2,"clk":"ANQ0AJVHAK5O","pt":1710508017036,"mc":[{"id":"1.226122413","rc":[{"tv":14218.87,"batb":[[0,4.3,215.62]],"trd":[[4.3,3916.63]],"id":50466254}],"tv":102691.24}],"ArrivalTime":1710508017044}
{"op":"mcm","id":2,"clk":"AOI0AJxHALlO","pt":1710508017140,"mc":[{"id":"1.226122413","rc":[{"tv":7480.47,"batb":[[0,8.2,70.23]],"trd":[[8.2,497.26]],"ltp":8.2,"id":41122648},{"batb":[[0,24,14.03]],"batl":[[0,25,6.38]],"id":55632148},{"batb":[[1,1.87,255.81]],"id":51922},{"tv":1928.17,"batb":[[0,24,20.82]],"trd":[[24,192.65]],"ltp":24,"id":106596}],"tv":102705.24}],"ArrivalTime":1710508017148}
{"op":"mcm","id":2,"clk":"AO40ALRHAM9O","pt":1710508017342,"mc":[{"id":"1.226122413","rc":[{"batb":[[1,1.87,257.81]],"id":51922},{"batb":[[0,24,21.82]],"id":106596}]}],"ArrivalTime":1710508017349}
{"op":"mcm","id":2,"clk":"APk0AMhHAONO","pt":1710508017507,"mc":[{"id":"1.226122413","rc":[{"tv":14288.87,"trd":[[4.4,3662.73]],"ltp":4.4,"batl":[[0,4.4,112.95]],"id":50466254}],"tv":102775.24}],"ArrivalTime":1710508017515}
{"op":"mcm","id":2,"clk":"AIY1ANlHAPZO","pt":1710508017715,"mc":[{"id":"1.226122413","rc":[{"batl":[[0,1.89,74.91]],"id":51922},{"tv":14335.33,"trd":[[4.4,3709.19]],"batl":[[0,4.4,89.72]],"id":50466254}],"tv":102821.7}],"ArrivalTime":1710508017722}
{"op":"mcm","id":2,"clk":"AI41AOFHAIJP","pt":1710508017819,"mc":[{"id":"1.226122413","rc":[{"batb":[[1,4.2,131.03]],"id":50466254}]}],"ArrivalTime":1710508017829}
{"op":"mcm","id":2,"clk":"AJY1AO1HAIxP","pt":1710508017920,"mc":[{"id":"1.226122413","rc":[{"tv":73795.42,"trd":[[1.89,3462.34]],"batl":[[0,1.89,107.83]],"id":51922},{"batb":[[2,4.1,101.5]],"batl":[[0,4.4,63.16]],"id":50466254}],"tv":102955.86}],"ArrivalTime":1710508017928}
{"op":"mcm","id":2,"clk":"AJ41APJHAJlP","pt":1710508018017,"mc":[{"id":"1.226122413","rc":[{"batl":[[0,1.89,175.15]],"id":51922},{"batl":[[0,4.4,76.96]],"id":50466254},{"tv":495.33,"batb":[[2,120,5.31],[1,130,1],[0,140,5.8]],"trd":[[150,41.64]],"id":66251581}],"tv":102956.44}],"ArrivalTime":1710508018025}
{"op":"mcm","id":2,"clk":"AKY1APtHAKFP","pt":1710508018126,"mc":[{"id":"1.226122413","rc":[{"batb":[[0,8.2,79.8]],"id":41122648},{"batb":[[0,1.88,251.25]],"batl":[[0,1.89,205]],"id":51922},{"batl":[[0,4.4,19.92]],"id":50466254}]}],"ArrivalTime":1710508018134}
{"op":"mcm","id":2,"clk":"AK01AIhIAKtP","pt":1710508018231,"mc":[{"id":"1.226122413","rc":[{"tv":14449.41,"batb":[[0,4.3,158.58]],"trd":[[4.3,4030.71]],"ltp":4.3,"batl":[[1,4.5,216.43]],"id":50466254},{"batb":[[0,140,8.17]],"id":66251581}],"tv":103070.52}],"ArrivalTime":1710508018239}
{"op":"mcm","id":2,"clk":"ALI1AI5IALVP","pt":1710508018331,"mc":[{"id":"1.226122413","rc":[{"batb":[[2,1.86,243.29]],"id":51922}]}],"ArrivalTime":1710508018339}
{"op":"mcm","id":2,"clk":"ALU1AJVIAL5P","pt":1710508018433,"mc":[{"id":"1.226122413","rc":[{"batb":[[2,300,1.23]],"id":54370634},{"tv":73898.4,"batb":[[0,1.88,199.76]],"trd":[[1.88,7562.57]],"ltp":1.88,"batl":[[0,1.89,215]],"id":51922},{"batb":[[0,4.3,187]],"id":50466254},{"batl":[[0,170,4.27]],"id":66251581}],"tv":103173.5}],"ArrivalTime":1710508018440}
{"op":"mcm","id":2,"clk":"ALs1AKNIAMxP","pt":1710508018554,"mc":[{"id":"1.226122413","rc":[{"batl":[[1,1.9,314.38]],"id":51922}]}],"ArrivalTime":1710508018561}
{"op":"mcm","id":2,"clk":"AL81AKtIANNP","pt":1710508018642,"mc":[{"id":"1.226122413","rc":[{"batb":[],"batl":[[2,210,1],[1,200,2.56],[0,180,2.54]],"id":66251581}]}],"ArrivalTime":1710508018650}
{"op":"mcm","id":2,"clk":"AMU1ALNIANtP","pt":1710508018745,"mc":[{"id":"1.226122413","rc":[{"batl":[[0,25,3]],"id":55632148},{"batb":[[2,1.86,244.29]],"id":51922}]}],"ArrivalTime":1710508018753}
{"op":"mcm","id":2,"clk":"AM81AMNIAPNP","pt":1710508018956,"mc":[{"id":"1.226122413","rc":[{"batb":[[1,1.87,259.81]],"id":51922}]}],"ArrivalTime":1710508018964}
{"op":"mcm","id":2,"clk":"ANY1AMxIAP5P","pt":1710508019004,"mc":[{"id":"1.226122413","rc":[{"batl":[[0,8.6,20.2]],"id":41122648}]}],"ArrivalTime":1710508019012}
{"op":"mcm","id":2,"clk":"AN41ANNIAItQ","pt":1710508019107,"mc":[{"id":"1.226122413","rc":[{"batl":[[2,8.8,26.49],[1,8.6,20.2],[0,8.4,22.14]],"id":41122648},{"batb":[[1,1.87,261.81]],"id":51922}]}],"ArrivalTime":1710508019115}
{"op":"mcm","id":2,"clk":"AOQ1AN9IAJNQ","pt":1710508019218,"mc":[{"id":"1.226122413","rc":[{"batb":[[2,7.8,66.96]],"batl":[[1,8.6,28.61]],"id":41122648},{"tv":74198.4,"trd":[[1.89,3762.34]],"ltp":1.89,"batl":[[0,1.89,65]],"id":51922}],"tv":103473.5}],"ArrivalTime":1710508019225}
{"op":"mcm","id":2,"clk":"AO81AOhIAJ9Q","pt":1710508019317,"mc":[{"id":"1.226122413","rc":[{"tv":7492.19,"trd":[[8.4,936.1]],"ltp":8.4,"batl":[[0,8.4,29.51]],"id":41122648},{"tv":74232.56,"batb":[[2,1.86,249.29],[0,1.88,242.46]],"trd":[[1.89,3796.5]],"batl":[[2,1.91,215.46],[0,1.89,39.85]],"id":51922},{"batl":[[2,4.6,173.06],[0,4.4,67.8]],"id":50466254}],"tv":103519.38}],"ArrivalTime":1710508019325}
{"op":"mcm","id":2,"clk":"APc1AOxIAKxQ","pt":1710508019423,"mc":[{"id":"1.226122413","rc":[{"batb":[[0,8.2,81.8]],"batl":[[1,8.6,26.61]],"id":41122648},{"batb":[[0,1.88,272.45]],"batl":[[0,1.89,10]],"id":51922},{"batl":[[0,4.4,96.94]],"id":50466254}]}],"ArrivalTime":1710508019431}
{"op":"mcm","id":2,"clk":"AP01APBIALdQ","pt":1710508019525,"mc":[{"id":"1.226122413","rc":[{"batl":[[0,8.4,31.51]],"id":41122648},{"batb":[[0,4.3,188]],"id":50466254}]}],"ArrivalTime":1710508019532}
{"op":"mcm","id":2,"clk":"AIg2APZIAMRQ","pt":1710508019625,"mc":[{"id":"1.226122413","rc":[{"tv":74302.56,"batb":[[0,1.88,237.45]],"trd":[[1.88,7632.57]],"ltp":1.88,"id":51922}],"tv":103589.38}],"ArrivalTime":1710508019633}
{"op":"mcm","id":2,"clk":"AJw2AI1JAONQ","pt":1710508019941,"mc":[{"id":"1.226122413","rc":[{"batb":[[0,1.88,247.45]],"id":51922},{"batl":[[0,4.4,98.94]],"id":50466254}]}],"ArrivalTime":1710508019948}
{"op":"mcm","id":2,"clk":"AKE2AJNJAPBQ","pt":1710508020043,"mc":[{"id":"1.226122413","rc":[{"batb":[[0,140,5.01]],"batl":[],"id":66251581}]}],"ArrivalTime":1710508020050}
{"op":"mcm","id":2,"clk":"AKc2AJ1JAP9Q","pt":1710508020150,"mc":[{"id":"1.226122413","rc":[{"tv":7510.98,"trd":[[8.4,954.89]],"batl":[[0,8.4,20.12]],"id":41122648}],"tv":103608.17}],"ArrivalTime":1710508020158}
{"op":"mcm","id":2,"clk":"ALQ2AK5JAJVR","pt":1710508020310,"mc":[{"id":"1.226122413","rc":[{"tv":7524.75,"batb":[[2,7.8,65.02],[0,8.2,81.81]],"trd":[[8.4,968.66]],"batl":[[2,9,32.58],[1,8.8,26.49],[0,8.6,26.61]],"id":41122648},{"batb":[[1,1.87,262.81],[0,1.88,153.45]],"id":51922}],"tv":103621.94}],"ArrivalTime":1710508020318}
{"op":"mcm","id":2,"clk":"ALs2ALZJAJ9R","pt":1710508020407,"mc":[{"id":"1.226122413","rc":[{"batb":[],"batl":[[0,8.6,25.44]],"id":41122648},{"batl":[[0,1.89,76.6]],"id":51922}]}],"ArrivalTime":1710508020415}
{"op":"mcm","id":2,"clk":"AME2AL5JAKpR","pt":1710508020513,"mc":[{"id":"1.226122413","rc":[{"tv":7540.12,"batb":[[2,8,110.98],[1,8.2,74.12],[0,8.4,13.31]],"trd":[[8.4,968.68],[8.2,512.61]],"ltp":8.2,"id":41122648}],"tv":103637.31}],"ArrivalTime":1710508020521}
{"op":"mcm","id":2,"clk":"AMY2AM1JALdR","pt":1710508020623,"mc":[{"id":"1.226122413","rc":[{"batl":[[2,27,13.8],[1,26,10.07]],"id":55632148},{"tv":74302.76,"batb":[[0,1.88,153.35]],"trd":[[1.88,7632.77]],"id":51922}],"tv":103637.51}],"ArrivalTime":1710508020630}
{"op":"mcm","id":2,"clk":"AM42ANRJAMJR","pt":1710508020727,"mc":[{"id":"1.226122413","rc":[{"batl":[[0,8.6,27.44]],"id":41122648},{"tv":74492.15,"batb":[[0,1.88,103.35]],"trd":[[1.88,7732.77],[1.89,3885.89]],"ltp":1.89,"batl":[[0,1.89,61.71]],"id":51922}],"tv":103826.9}],"ArrivalTime":1710508020735}
{"op":"mcm","id":2,"clk":"ANA2AN5JANBR","pt":1710508020830,"mc":[{"id":"1.226122413","rc":[{"batb":[[2,7.8,67.59],[1,8,110.98],[0,8.2,74.12]],"batl":[[0,8.6,19.03]],"id":41122648},{"batb":[[0,1.88,73.36]],"batl":[],"id":51922}]}],"ArrivalTime":1710508020838}
{"op":"mcm","id":2,"clk":"ANw2APpJAPRR","pt":1710508021078,"mc":[{"id":"1.226122413","rc":[{"tv":74502.15,"batb":[[0,1.88,68.36]],"trd":[[1.88,7742.77]],"ltp":1.88,"id":51922}],"tv":103836.9,"con":true}],"ArrivalTime":1710508021086}
{"op":"mcm","id":2,"clk":"APA2AI5KAIRS","pt":1710508021256,"mc":[{"id":"1.226122413","rc":[{"tv":7545.12,"trd":[[8.6,497.84]],"ltp":8.6,"batl":[[0,8.6,16.53]],"id":41122648},{"tv":74690.55,"batb":[[2,1.85,510.22],[1,1.86,251.29],[0,1.87,236.97]],"trd":[[1.87,7135.41],[1.88,7879.49]],"ltp":1.87,"id":51922}],"tv":104030.3}],"ArrivalTime":1710508021263}
{"op":"mcm","id":2,"clk":"APc2AJlKAIpS","pt":1710508021371,"mc":[{"id":"1.226122413","rc":[{"batb":[[1,1.86,253.29]],"id":51922}]}],"ArrivalTime":1710508021379}
{"op":"mcm","id":2,"clk":"APk2AKdKAJVS","pt":1710508021460,"mc":[{"id":"1.226122413","rc":[{"tv":7604.9,"batb":[[0,8.2,44.23]],"trd":[[8.2,572.39]],"ltp":8.2,"id":41122648},{"batl":[[1,26,9.27]],"id":55632148},{"batl":[[0,1.89,99.35]],"id":51922},{"batl":[[0,26,20.85]],"id":106596}],"tv":104090.08}],"ArrivalTime":1710508021467}
{"op":"mcm","id":2,"clk":"AP42ALNKAJ5S","pt":1710508021523,"mc":[{"id":"1.226122413","rc":[{"batb":[[0,4.3,88]],"id":50466254}]}],"ArrivalTime":1710508021530}
{"op":"mcm","id":2,"clk":"AIU3AL9KAKZS","pt":1710508021631,"mc":[{"id":"1.226122413","rc":[{"batb":[[0,8.2,58.47]],"batl":[[0,8.6,25.18]],"id":41122648},{"batb":[[1,4.2,231.03]],"batl":[[0,4.4,85.14]],"id":50466254}]}],"ArrivalTime":1710508021639}
{"op":"mcm","id":2,"clk":"AIc3AMxKAK9S","pt":1710508021734,"mc":[{"id":"1.226122413","rc":[{"batl":[[2,8.8,26.49],[1,8.6,25.18],[0,8.4,6]],"id":41122648},{"tv":434.57,"trd":[[240,5.3]],"ltp":240,"batl":[[0,240,1]],"id":41200638},{"tv":14453.59,"batb":[[0,4.3,57.49]],"trd":[[4.3,4034.89]],"id":50466254}],"tv":104094.56}],"ArrivalTime":1710508021743}
{"op":"mcm","id":2,"clk":"AI03ANlKALxS","pt":1710508021828,"mc":[{"id":"1.226122413","rc":[{"batb":[[0,330,4.5]],"id":54370634},{"tv":7616.9,"batb":[[2,8,110.98],[1,8.2,58.47],[0,8.4,4]],"trd":[[8.4,980.68]],"ltp":8.4,"batl":[[2,9,32.58],[1,8.8,26.49],[0,8.6,25.18]],"id":41122648},{"tv":74699.57,"trd":[[1.89,3894.91]],"ltp":1.89,"batl":[[0,1.89,94.84]],"id":51922},{"batl":[[0,38,14.13]],"id":49744721},{"tv":14477.87,"batb":[[0,4.3,55.35]],"trd":[[4.4,3729.19],[4.3,4039.17]],"ltp":4.4,"batl":[[0,4.4,75.14]],"id":50466254},{"tv":1936.03,"trd":[[26,261.86]],"ltp":26,"batl":[[0,26,16.92]],"id":106596}],"tv":104147.72}],"ArrivalTime":1710508021836}
{"op":"mcm","id":2,"clk":"AI83AN9KAMlS","pt":1710508021931,"mc":[{"id":"1.226122413","rc":[{"tv":7624.9,"batb":[[2,7.8,69.53],[1,8,110.98],[0,8.2,58.47]],"trd":[[8.4,988.68]],"batl":[[2,8.8,26.49],[1,8.6,25.18],[0,8.4,9.01]],"id":41122648},{"batb":[[2,210,11.31],[1,220,3.21],[0,230,1.15]],"id":41200638},{"tv":1808.29,"trd":[[25,358.62]],"ltp":25,"batl":[[0,25,1.65]],"id":55632148},{"tv":74718.57,"trd":[[1.89,3913.91]],"batl":[[0,1.89,85.34]],"id":51922},{"batb":[[0,24,25.67]],"id":106596}],"tv":104177.42}],"ArrivalTime":1710508021939}
{"op":"mcm","id":2,"clk":"AJQ3AOpKANRS","pt":1710508022031,"mc":[{"id":"1.226122413","rc":[{"batl":[[2,270,1.19],[1,260,2.65],[0,250,1.83]],"id":41200638},{"batb":[[0,34,29.46]],"id":49744721},{"batb":[[0,4.3,104.22]],"id":50466254},{"tv":1941.18,"batb":[[2,23,23.48],[1,24,25.67],[0,25,6.24]],"trd":[[26,267.01]],"batl":[[0,26,14.35]],"id":106596}],"tv":104182.57}],"ArrivalTime":1710508022039}
{"op":"mcm","id":2,"clk":"AJ43APNKAOFS","pt":1710508022136,"mc":[{"id":"1.226122413","rc":[{"batb":[[0,1.87,237.59]],"id":51922},{"tv":14519.87,"trd":[[4.4,3771.19]],"batl":[[0,4.4,54.14]],"id":50466254}],"tv":104224.57}],"ArrivalTime":1710508022143}
{"op":"mcm","id":2,"clk":"AKY3AIdLAPhS","pt":1710508022242,"mc":[{"id":"1.226122413","rc":[{"batl":[[2,9,32.58],[1,8.8,26.49],[0,8.6,25.18]],"id":41122648},{"batb":[[1,220,4.21]],"id":41200638},{"batb":[[0,4.3,141.84]],"batl":[],"id":50466254},{"batb":[[1,24,25.12],[0,25,12.99]],"batl":[[0,26,6.51]],"id":106596}]}],"ArrivalTime":1710508022250}
{"op":"mcm","id":2,"clk":"ALM3AJRLAP5S","pt":1710508022351,"mc":[{"id":"1.226122413","rc":[{"tv":74719.81,"batb":[[0,1.87,236.97]],"trd":[[1.88,7880.73]],"ltp":1.88,"batl":[[2,1.9,314.38],[1,1.89,98.82],[0,1.88,65.68]],"id":51922},{"tv":14523.51,"batb":[[0,4.3,140.02]],"trd":[[4.3,4042.81]],"ltp":4.3,"id":50466254},{"batb":[[0,140,5.64]],"batl":[[2,200,2.56],[1,180,2.54],[0,150,1]],"id":66251581},{"tv":1950.4,"trd":[[26,276.23]],"batl":[[0,26,1.9]],"id":106596}],"tv":104238.67}],"ArrivalTime":1710508022358}
{"op":"mcm","id":2,"clk":"ALg3AJ1LAIVT","pt":1710508022454,"mc":[{"id":"1.226122413","rc":[{"batb":[[2,7.8,67.59]],"id":41122648},{"batb":[[2,200,4.72],[1,210,11.31],[0,220,4.21]],"id":41200638},{"batl":[[1,1.89,101.07]],"id":51922},{"tv":497.33,"batb":[[0,140,4.64]],"trd":[[140,62.2]],"ltp":140,"id":66251581}],"tv":104240.67}],"ArrivalTime":1710508022461}
{"op":"mcm","id":2,"clk":"AL43AKBLAJNT","pt":1710508022550,"mc":[{"id":"1.226122413","rc":[{"batl":[[0,38,14.25]],"id":49744721},{"tv":499.35,"batb":[[1,130,1.33],[0,140,4.92]],"trd":[[150,43.66]],"ltp":150,"batl":[],"id":66251581},{"tv":1954.19,"batb":[[2,24,25.12],[1,25,15.99],[0,26,9.06]],"trd":[[26,280.02]],"batl":[[2,29,12.04],[1,28,8.7],[0,27,6.4]],"id":106596}],"tv":104246.48}],"ArrivalTime":1710508022557}
{"op":"mcm","id":2,"clk":"AMg3AK9LAJtT","pt":1710508022659,"mc":[{"id":"1.226122413","rc":[{"batl":[[0,4.4,26.23]],"id":50466254},{"batb":[[1,130,2.5]],"id":66251581},{"batb":[[1,25,20.22]],"id":106596}]}],"ArrivalTime":1710508022667}
{"op":"mcm","id":2,"clk":"AM43ALpLAKdT","pt":1710508022766,"mc":[{"id":"1.226122413","rc":[{"tv":499.95,"batb":[[2,120,5.7]],"trd":[[150,44.26]],"batl":[[2,210,1],[1,200,2.56],[0,180,3.24]],"id":66251581},{"tv":1960.37,"batb":[],"trd":[[27,195.11]],"ltp":27,"batl":[[0,27,3.31]],"id":106596}],"tv":104253.26}],"ArrivalTime":1710508022774}
{"op":"mcm","id":2,"clk":"AOE3AMdLAL5T","pt":1710508022968,"mc":[{"id":"1.226122413","rc":[{"tv":7668.96,"batb":[[0,8.2,36.44]],"trd":[[8.2,616.45]],"ltp":8.2,"id":41122648},{"batl":[[1,260,1.23]],"id":41200638},{"tv":1819.85,"batb":[[0,24,8.25]],"trd":[[24,231.37]],"ltp":24,"id":55632148},{"batb":[[0,1.87,169.97]],"id":51922},{"tv":2354.64,"batb":[[0,34,14.23]],"trd":[[34,167.49]],"id":49744721},{"batb":[[2,120,5.31],[1,130,2.17],[0,140,3.54]],"batl":[[0,180,2.54]],"id":66251581},{"tv":1965.53,"batb":[[0,26,9.58]],"trd":[[27,200.27]],"batl":[[2,30,8.75],[1,29,12.04],[0,28,9.43]],"id":106596}],"tv":104344.5}],"ArrivalTime":1710508022977}
{"op":"mcm","id":2,"clk":"AOg3ANRLAMhT","pt":1710508023027,"mc":[{"id":"1.226122413","rc":[{"batl":[[0,1.88,65.78]],"id":51922},{"tv":1980.91,"batb":[[0,26,1.88]],"trd":[[26,295.4]],"ltp":26,"id":106596}],"tv":104359.88}],"ArrivalTime":1710508023035}
{"op":"mcm","id":2,"clk":"AO83ANxLANRT","pt":1710508023123,"mc":[{"id":"1.226122413","rc":[{"tv":7715.22,"batb":[[0,8.2,13.31]],"trd":[[8.2,662.71]],"id":41122648},{"batb":[[0,24,11.68]],"batl":[[0,25,4.94]],"id":55632148},{"batb":[[0,34,11.16]],"batl":[[2,40,18.48],[1,38,13.69],[0,36,4.89]],"id":49744721},{"tv":1986.05,"batb":[[2,24,34.03]],"trd":[[27,205.41]],"ltp":27,"batl":[[2,29,12.04],[1,28,13.63],[0,27,3.26]],"id":106596}],"tv":104411.28}],"ArrivalTime":1710508023131}
{"op":"mcm","id":2,"clk":"APY3AORLAOFT","pt":1710508023225,"mc":[{"id":"1.226122413","rc":[{"batl":[[2,8.8,26.49],[1,8.6,25.18],[0,8.4,20.65]],"id":41122648},{"batl":[[2,1.91,215.46],[1,1.9,314.38],[0,1.89,101.17]],"id":51922},{"batb":[[2,23,23.52],[1,24,34.03],[0,25,20.74]],"id":106596}]}],"ArrivalTime":1710508023233}
{"op":"mcm","id":2,"clk":"APo3AOxLAPFT","pt":1710508023343,"mc":[{"id":"1.226122413","rc":[{"batb":[[0,24,14.39]],"id":55632148},{"tv":74720.01,"batb":[[2,1.86,253.29],[1,1.87,249.97],[0,1.88,67.06]],"trd":[[1.88,7880.93]],"batl":[[0,1.89,101.07]],"id":51922},{"batb":[[0,34,8.08]],"id":49744721},{"batl":[[0,4.4,36.23]],"id":50466254},{"batb":[[2,24,34.03],[1,25,20.22],[0,26,5.8]],"batl":[[0,27,7.07]],"id":106596}],"tv":104411.48}],"ArrivalTime":1710508023351}
{"op":"mcm","id":2,"clk":"AIA4APpLAPpT","pt":1710508023443,"mc":[{"id":"1.226122413","rc":[{"batb":[[1,8,95.41]],"id":41122648},{"tv":74763.94,"batb":[[0,1.88,65.69]],"trd":[[1.88,7884.68],[1.89,3954.09]],"ltp":1.89,"batl":[[0,1.89,80.98]],"id":51922},{"batl":[[0,36,8.66]],"id":49744721},{"batb":[[0,4.3,163.05]],"id":50466254}],"tv":104455.41}],"ArrivalTime":1710508023451}
{"op":"mcm","id":2,"clk":"AIQ4AP5LAIxU","pt":1710508023550,"mc":[{"id":"1.226122413","rc":[{"tv":7723.48,"batb":[[2,7.6,84.3],[1,7.8,67.59],[0,8,95.41]],"trd":[[8.2,670.97]],"batl":[[1,8.6,23.18],[0,8.4,22.6]],"id":41122648},{"batb":[[0,1.88,80.69]],"id":51922},{"tv":2360.32,"batb":[[0,34,4.82]],"trd":[[34,173.17]],"batl":[[1,38,11.69]],"id":49744721},{"batb":[],"batl":[[1,28,7.22]],"id":106596}],"tv":104469.35}],"ArrivalTime":1710508023559}
{"op":"mcm","id":2,"clk":"AIg4AIlMAJVU","pt":1710508023670,"mc":[{"id":"1.226122413","rc":[{"batl":[[0,1.89,147.06]],"id":51922}]}],"ArrivalTime":1710508023678}
{"op":"mcm","id":2,"clk":"AJA4AJxMAKRU","pt":1710508023757,"mc":[{"id":"1.226122413","rc":[{"batl":[[0,8.4,31.49]],"id":41122648},{"batb":[[0,1.88,110.18]],"id":51922},{"batl":[[0,36,11.09]],"id":49744721},{"batl":[[0,27,3.26]],"id":106596}]}],"ArrivalTime":1710508023765}
{"op":"mcm","id":2,"clk":"AJc4AKZMAKlU","pt":1710508023851,"mc":[{"id":"1.226122413","rc":[{"tv":74773.94,"batb":[[0,1.88,105.18]],"trd":[[1.88,7894.68]],"ltp":1.88,"id":51922}],"tv":104479.35}],"ArrivalTime":1710508023858}
{"op":"mcm","id":2,"clk":"AKE4ALdMALtU","pt":1710508024006,"mc":[{"id":"1.226122413","rc":[{"tv":74777.94,"batb":[[1,1.87,254.99],[0,1.88,73.69]],"trd":[[1.88,7898.68]],"id":51922},{"batl":[[0,36,13.09]],"id":49744721}],"tv":104483.35}],"ArrivalTime":1710508024013}
{"op":"mcm","id":2,"clk":"ALk4ANNMANxU","pt":1710508024319,"mc":[{"id":"1.226122413","rc":[{"batb":[[0,140,4.97]],"id":66251581}]}],"ArrivalTime":1710508024327}
{"op":"mcm","id":2,"clk":"ALw4AOVMAOlU","pt":1710508024426,"mc":[{"id":"1.226122413","rc":[{"batl":[[2,40,18.6]],"id":49744721}]}],"ArrivalTime":1710508024433}
{"op":"mcm","id":2,"clk":"AME4AO1MAPlU","pt":1710508024531,"mc":[{"id":"1.226122413","rc":[{"batl":[[2,1.91,225.46]],"id":51922},{"tv":2365.44,"batb":[[0,34,2.26]],"trd":[[34,178.29]],"id":49744721}],"tv":104488.47}],"ArrivalTime":1710508024538}
{"op":"mcm","id":2,"clk":"AMU4APhMAINV","pt":1710508024631,"mc":[{"id":"1.226122413","rc":[{"batl":[[2,8.6,23.18],[1,8.4,33.49],[0,8.2,1.31]],"id":41122648}]}],"ArrivalTime":1710508024638}
{"op":"mcm","id":2,"clk":"AMw4AIpNAJFV","pt":1710508024736,"mc":[{"id":"1.226122413","rc":[{"batb":[[1,7.8,69.53],[0,8,97.25]],"batl":[[1,8.4,34.69]],"id":41122648},{"tv":2369.96,"batb":[[2,29,12.4],[1,30,17.71],[0,32,21.8]],"trd":[[34,182.81]],"batl":[[0,36,13.39]],"id":49744721},{"batl":[[0,4.4,39.64]],"id":50466254}],"tv":104492.99}],"ArrivalTime":1710508024744}
{"op":"mcm","id":2,"clk":"ANM4AI9NAJpV","pt":1710508024834,"mc":[{"id":"1.226122413","rc":[{"tv":7726.1,"trd":[[8.2,673.59]],"batl":[[2,8.8,26.49],[1,8.6,23.18],[0,8.4,44.69]],"id":41122648},{"batb":[[2,1.86,264.31]],"id":51922}],"tv":104495.61}],"ArrivalTime":1710508024842}
{"op":"mcm","id":2,"clk":"ANk4AJlNAKRV","pt":1710508024941,"mc":[{"id":"1.226122413","rc":[{"batb":[[2,7.6,82.26],[1,7.8,67.59],[0,8,95.41]],"id":41122648},{"batl":[[1,26,10.07]],"id":55632148},{"batb":[[0,32,16.18]],"batl":[[2,38,11.69],[1,36,12.65],[0,34,3.3]],"id":49744721}]}],"ArrivalTime":1710508024949}
{"op":"mcm","id":2,"clk":"AN84AK1NAKpV","pt":1710508025048,"mc":[{"id":"1.226122413","rc":[{"batl":[[0,8.4,43.49]],"id":41122648},{"batb":[[0,220,7.23]],"id":41200638},{"batl":[[0,25,1.65]],"id":55632148},{"batb":[[2,130,2.17],[1,140,4.97],[0,150,1.01]],"id":66251581},{"tv":1989.45,"trd":[[27,208.81]],"batl":[[0,27,1.56]],"id":106596}],"tv":104499.01}],"ArrivalTime":1710508025056}
{"op":"mcm","id":2,"clk":"AOc4ALdNALNV","pt":1710508025150,"mc":[{"id":"1.226122413","rc":[{"batl":[[1,36,10.65]],"id":49744721},{"batb":[[0,4.3,191.09]],"id":50466254}]}],"ArrivalTime":1710508025158}
{"op":"mcm","id":2,"clk":"AO04AMRNALhV","pt":1710508025254,"mc":[{"id":"1.226122413","rc":[{"batb":[[0,220,7.56]],"id":41200638},{"batb":[[0,150,2.57]],"id":66251581},{"batl":[[2,30,8.75],[1,29,12.04],[0,28,7.22]],"id":106596}]}],"ArrivalTime":1710508025261}
{"op":"mcm","id":2,"clk":"API4AM5NAMBV","pt":1710508025355,"mc":[{"id":"1.226122413","rc":[{"tv":74782.06,"batb":[[0,1.88,71.63]],"trd":[[1.88,7902.8]],"id":51922},{"batb":[[2,24,34.98]],"id":106596}],"tv":104503.13}],"ArrivalTime":1710508025363}
{"op":"mcm","id":2,"clk":"APc4AONNAMZV","pt":1710508025461,"mc":[{"id":"1.226122413","rc":[{"batl":[[1,1.9,316.38]],"id":51922},{"batl":[[1,4.5,213.1]],"id":50466254},{"batb":[[0,26,8.8]],"id":106596}]}],"ArrivalTime":1710508025468}
{"op":"mcm","id":2,"clk":"AP04APJNANFV","pt":1710508025573,"mc":[{"id":"1.226122413","rc":[{"batl":[[0,34,7.58]],"id":49744721},{"batb":[[2,24,34.03]],"id":106596}]}],"ArrivalTime":1710508025581}
{"op":"mcm","id":2,"clk":"AJI5AJtOAPtV","pt":1710508025931,"mc":[{"id":"1.226122413","rc":[{"batl":[[1,1.9,331.38]],"id":51922}]}],"ArrivalTime":1710508025938}
{"op":"mcm","id":2,"clk":"AJ05AKxOAJBW","pt":1710508026150,"mc":[{"id":"1.226122413","rc":[{"batl":[[0,8.4,41.54]],"id":41122648},{"batl":[[1,29,6.02]],"id":106596}]}],"ArrivalTime":1710508026157}
{"op":"mcm","id":2,"clk":"AKk5ALdOAJtW","pt":1710508026250,"mc":[{"id":"1.226122413","rc":[{"batb":[[0,1.88,100.89]],"batl":[[0,1.89,119.45]],"id":51922}]}],"ArrivalTime":1710508026258}
{"op":"mcm","id":2,"clk":"AMQ5ANxOAL9W","pt":1710508026563,"mc":[{"id":"1.226122413","rc":[{"batl":[[2,28,28.55],[1,27,13.8],[0,26,10.07]],"id":55632148},{"tv":74807.67,"batb":[[0,1.88,88.08]],"trd":[[1.88,7928.41]],"id":51922}],"tv":104528.74}],"ArrivalTime":1710508026570}
{"op":"mcm","id":2,"clk":"AMo5ANxOAMlW","pt":1710508026615,"mc":[{"id":"1.226122413","rc":[{"tv":1823.14,"batb":[[0,24,12.74]],"trd":[[24,234.66]],"id":55632148},{"tv":14602.79,"batb":[[2,4.2,231.03],[1,4.3,191.09],[0,4.4,6.02]],"trd":[[4.4,3850.47]],"ltp":4.4,"batl":[[2,4.7,77.01],[1,4.6,173.06],[0,4.5,213.1]],"id":50466254}],"tv":104611.31}],"ArrivalTime":1710508026623}
{"op":"mcm","id":2,"clk":"AM45AOxOANNW","pt":1710508026720,"mc":[{"id":"1.226122413","rc":[{"batb":[[2,23,13.81],[1,24,12.74],[0,25,2]],"batl":[[1,27,13.06],[0,26,9.27]],"id":55632148},{"batb":[[1,1.87,279.99]],"id":51922},{"batb":[[0,4.4,8.63]],"batl":[[2,4.7,79.95]],"id":50466254}]}],"ArrivalTime":1710508026727}
{"op":"mcm","id":2,"clk":"ANg5APxOAORW","pt":1710508026923,"mc":[{"id":"1.226122413","rc":[{"tv":1824.88,"batb":[[0,25,1.13]],"trd":[[25,360.36]],"ltp":25,"batl":[[1,27,13.8],[0,26,10.07]],"id":55632148}],"tv":104613.05}],"ArrivalTime":1710508026930}
{"op":"mcm","id":2,"clk":"AOI5AIlPAOlW","pt":1710508027031,"mc":[{"id":"1.226122413","rc":[{"tv":74841.83,"batb":[[0,1.88,71]],"trd":[[1.88,7962.57]],"id":51922}],"tv":104647.21}],"ArrivalTime":1710508027040}
{"op":"mcm","id":2,"clk":"AOY5AJFPAPBW","pt":1710508027154,"mc":[{"id":"1.226122413","rc":[{"tv":74891.84,"batb":[[0,1.88,96]],"trd":[[1.89,4004.1]],"ltp":1.89,"batl":[[1,1.9,333.38],[0,1.89,94.45]],"id":51922}],"tv":104697.22}],"ArrivalTime":1710508027162}
{"op":"mcm","id":2,"clk":"AOk5AJlPAPpW","pt":1710508027234,"mc":[{"id":"1.226122413","rc":[{"tv":74936.9,"batb":[[0,1.88,73.47]],"trd":[[1.88,8007.63]],"ltp":1.88,"id":51922}],"tv":104742.28}],"ArrivalTime":1710508027242}
{"op":"mcm","id":2,"clk":"AO45AKZPAIFX","pt":1710508027333,"mc":[{"id":"1.226122413","rc":[{"tv":75016.9,"trd":[[1.89,4084.1]],"ltp":1.89,"batl":[[0,1.89,41.81]],"id":51922},{"tv":14620.05,"batb":[[2,4.1,101.5],[1,4.2,231.03],[0,4.3,191.09]],"trd":[[4.4,3867.73]],"batl":[[2,4.6,173.06],[1,4.5,213.1],[0,4.4,47.03]],"id":50466254}],"tv":104839.54}],"ArrivalTime":1710508027341}
{"op":"mcm","id":2,"clk":"APE5ALBPAIpX","pt":1710508027440,"mc":[{"id":"1.226122413","rc":[{"batb":[[1,24,13.74]],"id":55632148},{"tv":75040.34,"batb":[[0,1.88,61.75]],"trd":[[1.88,8031.07]],"ltp":1.88,"batl":[],"id":51922},{"tv":14625.39,"batb":[[2,4.1,105.54]],"trd":[[4.4,3873.07]],"batl":[[0,4.4,44.36]],"id":50466254}],"tv":104868.32}],"ArrivalTime":1710508027448}
{"op":"mcm","id":2,"clk":"APM5AMJPAJNX","pt":1710508027541,"mc":[{"id":"1.226122413","rc":[{"batb":[[0,1.88,137.45]],"id":51922}]}],"ArrivalTime":1710508027549}
{"op":"mcm","id":2,"clk":"AP05AMRPAKNX","pt":1710508027647,"mc":[{"id":"1.226122413","rc":[{"tv":75100.34,"batb":[[0,1.88,107.45]],"trd":[[1.88,8091.07]],"id":51922},{"batb":[[2,4.1,101.5]],"id":50466254}],"tv":104928.32}],"ArrivalTime":1710508027655}
{"op":"mcm","id":2,"clk":"AIA6AM9PAK5X","pt":1710508027749,"mc":[{"id":"1.226122413","rc":[{"tv":14627.39,"batb":[[0,4.3,190.09]],"trd":[[4.3,4044.81]],"ltp":4.3,"id":50466254},{"tv":2002.91,"batb":[[0,26,2.07]],"trd":[[26,308.86]],"ltp":26,"batl":[[0,28,11.59]],"id":106596}],"tv":104943.78}],"ArrivalTime":1710508027756}
{"op":"mcm","id":2,"clk":"AI06ANtPALVX","pt":1710508027809,"mc":[{"id":"1.226122413","rc":[{"batb":[[0,1.88,129.92]],"id":51922},{"batl":[[0,28,7.22]],"id":106596}]}],"ArrivalTime":1710508027817}
{"op":"mcm","id":2,"clk":"AJI6AONPALtX","pt":1710508027916,"mc":[{"id":"1.226122413","rc":[{"tv":14633.39,"batb":[[0,4.3,187.09]],"trd":[[4.3,4050.81]],"id":50466254},{"batb":[[0,26,7.34]],"id":106596}],"tv":104949.78}],"ArrivalTime":1710508027924}
{"op":"mcm","id":2,"clk":"AJk6AO5PAMVX","pt":1710508028015,"mc":[{"id":"1.226122413","rc":[{"tv":75110.34,"batb":[[0,1.88,124.92]],"trd":[[1.88,8101.07]],"batl":[[0,1.89,46.81]],"id":51922},{"batb":[[1,25,19.67]],"id":106596}],"tv":104959.78}],"ArrivalTime":1710508028023}
{"op":"mcm","id":2,"clk":"AK06AIhQAOhX","pt":1710508028331,"mc":[{"id":"1.226122413","rc":[{"tv":1834.07,"batb":[[2,22,23.97],[1,23,13.81],[0,24,10.28]],"trd":[[25,362.62],[24,241.59]],"ltp":24,"id":55632148},{"batb":[[1,1.87,285.01]],"id":51922}],"tv":104968.97}],"ArrivalTime":1710508028339}
{"op":"mcm","id":2,"clk":"ALE6AJFQAPFX","pt":1710508028429,"mc":[{"id":"1.226122413","rc":[{"batl":[[2,28,27.86],[1,27,13.06],[0,26,13.15]],"id":55632148},{"batb":[[0,1.88,129.92]],"id":51922}]}],"ArrivalTime":1710508028436}
{"op":"mcm","id":2,"clk":"ALY6AJtQAPxX","pt":1710508028529,"mc":[{"id":"1.226122413","rc":[{"batb":[[0,24,7.28]],"batl":[[2,27,13.06],[1,26,13.15],[0,25,3.25]],"id":55632148},{"batb":[[0,26,11.15]],"id":106596}]}],"ArrivalTime":1710508028537}
{"op":"mcm","id":2,"clk":"AMk6AKpQAJJY","pt":1710508028737,"mc":[{"id":"1.226122413","rc":[{"batl":[[1,1.9,335.38]],"id":51922}]}],"ArrivalTime":1710508028744}
{"op":"mcm","id":2,"clk":"ANc6AL9QAKhY","pt":1710508028940,"mc":[{"id":"1.226122413","rc":[{"batb":[[1,7.8,67.85]],"id":41122648}]}],"ArrivalTime":1710508028948}
{"op":"mcm","id":2,"clk":"ANw6AMpQALJY","pt":1710508029048,"mc":[{"id":"1.226122413","rc":[{"batl":[[1,1.9,336.38]],"id":51922}]}],"ArrivalTime":1710508029056}
{"op":"mcm","id":2,"clk":"AOM6ANRQAL1Y","pt":1710508029145,"mc":[{"id":"1.226122413","rc":[{"batb":[[0,4.3,167.78]],"id":50466254},{"batl":[[2,210,6]],"id":66251581}]}],"ArrivalTime":1710508029153}
{"op":"mcm","id":2,"clk":"AOk6ANtQAMhY","pt":1710508029256,"mc":[{"id":"1.226122413","rc":[{"tv":14672.01,"trd":[[4.4,3911.69]],"ltp":4.4,"batl":[[0,4.4,25.05]],"id":50466254}],"tv":105007.59}],"ArrivalTime":1710508029264}
{"op":"mcm","id":2,"clk":"AO86AONQANFY","pt":1710508029308,"mc":[{"id":"1.226122413","rc":[{"tv":75116.34,"trd":[[1.89,4090.1]],"ltp":1.89,"batl":[[0,1.89,72.77]],"id":51922}],"tv":105013.59}],"ArrivalTime":1710508029315}
{"op":"mcm","id":2,"clk":"APQ6AO1QAN1Y","pt":1710508029416,"mc":[{"id":"1.226122413","rc":[{"batb":[[0,1.88,105.7]],"id":51922},{"batb":[[0,4.3,172.78]],"batl":[[2,4.7,77.01],[1,4.6,173.06],[0,4.5,213.1]],"id":50466254}]}],"ArrivalTime":1710508029424}
{"op":"mcm","id":2,"clk":"APc6APtQAOVY","pt":1710508029514,"mc":[{"id":"1.226122413","rc":[{"tv":2371.96,"batb":[[0,32,15.18]],"trd":[[32,108.16]],"ltp":32,"id":49744721}],"tv":105015.59}],"ArrivalTime":1710508029522}
{"op":"mcm","id":2,"clk":"AP86AIVRAO1Y","pt":1710508029619,"mc":[{"id":"1.226122413","rc":[{"batb":[[1,320,1.94]],"id":54370634}]}],"ArrivalTime":1710508029627}
{"op":"mcm","id":2,"clk":"AIc7AJFRAPZY","pt":1710508029726,"mc":[{"id":"1.226122413","rc":[{"batl":[[0,34,9.58]],"id":49744721},{"batl":[[2,210,5]],"id":66251581}]}],"ArrivalTime":1710508029734}
{"op":"mcm","id":2,"clk":"AI07AJpRAIJZ","pt":1710508029827,"mc":[{"id":"1.226122413","rc":[{"batl":[[0,1.89,82.77]],"id":51922},{"tv":501.95,"batb":[[0,150,1.57]],"trd":[[150,46.26]],"id":66251581}],"tv":105017.59}],"ArrivalTime":1710508029835}
{"op":"mcm","id":2,"clk":"AJQ7AKRRAI5Z","pt":1710508029928,"mc":[{"id":"1.226122413","rc":[{"batl":[[2,4.6,173.06],[1,4.5,213.1],[0,4.4,1.5]],"id":50466254},{"tv":2022.91,"batb":[[0,26,1.15]],"trd":[[26,328.86]],"id":106596}],"tv":105037.59}],"ArrivalTime":1710508029936}
{"op":"mcm","id":2,"clk":"AKQ7ALZRAKJZ","pt":1710508030141,"mc":[{"id":"1.226122413","rc":[{"tv":1840.57,"batb":[[2,23,13.81],[1,24,9.65],[0,25,1.75]],"trd":[[25,369.12]],"ltp":25,"batl":[[2,28,28.55],[1,27,13.06],[0,26,13.15]],"id":55632148},{"batb":[[1,1.87,260.01]],"batl":[[2,1.91,226.46]],"id":51922},{"batl":[[2,38,14.39]],"id":49744721},{"batb":[[0,26,3.56]],"id":106596}],"tv":105044.09}],"ArrivalTime":1710508030149}
{"op":"mcm","id":2,"clk":"AKw7AL5RAKdZ","pt":1710508030236,"mc":[{"id":"1.226122413","rc":[{"batb":[[0,1.88,130.7]],"id":51922},{"batl":[[1,4.5,214.1]],"id":50466254}]}],"ArrivalTime":1710508030243}
{"op":"mcm","id":2,"clk":"ALM7AMhRALRZ","pt":1710508030344,"mc":[{"id":"1.226122413","rc":[{"batl":[[0,8.4,43.49]],"id":41122648},{"tv":1842.31,"batb":[[2,22,23.97],[1,23,13.81],[0,24,10.53]],"trd":[[25,370.86]],"batl":[[1,27,13.8],[0,26,13.95]],"id":55632148}],"tv":105045.83}],"ArrivalTime":1710508030355}
{"op":"mcm","id":2,"clk":"ALw7ANNRAMJZ","pt":1710508030452,"mc":[{"id":"1.226122413","rc":[{"batl":[[1,1.9,338.38]],"id":51922},{"batb":[[0,26,7.99]],"id":106596}]}],"ArrivalTime":1710508030459}
{"op":"mcm","id":2,"clk":"AMA7AOFRAM5Z","pt":1710508030555,"mc":[{"id":"1.226122413","rc":[{"batl":[[2,28,27.86],[1,27,13.06],[0,26,13.15]],"id":55632148},{"batb":[[2,1.86,253.29]],"id":51922},{"tv":2377.96,"trd":[[34,188.81]],"ltp":34,"batl":[[0,34,6.58]],"id":49744721}],"tv":105051.83}],"ArrivalTime":1710508030563}
{"op":"mcm","id":2,"clk":"AMc7AOdRANRZ","pt":1710508030662,"mc":[{"id":"1.226122413","rc":[{"tv":75136.74,"trd":[[1.89,4110.5]],"batl":[[0,1.89,72.57]],"id":51922},{"batb":[[0,26,11.74]],"id":106596}],"tv":105072.23}],"ArrivalTime":1710508030670}
{"op":"mcm","id":2,"clk":"AM07APBRAN1Z","pt":1710508030763,"mc":[{"id":"1.226122413","rc":[{"batl":[[0,34,2.3]],"id":49744721}]}],"ArrivalTime":1710508030771}
{"op":"mcm","id":2,"clk":"AOA7AJBSAPxZ","pt":1710508031022,"mc":[{"id":"1.226122413","rc":[{"tv":7746.11,"trd":[[8.4,1008.69]],"ltp":8.4,"batl":[[0,8.4,33.49]],"id":41122648},{"tv":75139.62,"trd":[[1.89,4113.38]],"batl":[[0,1.89,71.13]],"id":51922},{"tv":2382.56,"batb":[[2,30,17.71],[1,32,15.18],[0,34,1.03]],"trd":[[34,193.41]],"batl":[[2,40,16.53],[1,38,14.39],[0,36,10.65]],"id":49744721},{"tv":2029.41,"trd":[[28,232.27]],"ltp":28,"batl":[[0,28,3.97]],"id":106596}],"tv":105106.22}],"ArrivalTime":1710508031030}
{"op":"mcm","id":2,"clk":"AOg7AJxSAIRa","pt":1710508031124,"mc":[{"id":"1.226122413","rc":[{"batb":[[2,7.8,67.85],[1,8,95.41],[0,8.2,12.24]],"batl":[[0,8.4,34.69]],"id":41122648},{"tv":14672.21,"batb":[[0,4.3,172.88]],"trd":[[4.4,3911.89]],"batl":[[0,4.4,1.4]],"id":50466254}],"tv":105106.42}],"ArrivalTime":1710508031131}
{"op":"mcm","id":2,"clk":"AO47AJ9SAI1a","pt":1710508031228,"mc":[{"id":"1.226122413","rc":[{"batl":[[0,26,19.68]],"id":55632148},{"tv":75401.02,"batb":[[2,1.85,485.22],[1,1.86,253.29],[0,1.87,260.01]],"trd":[[1.88,8362.47]],"ltp":1.88,"batl":[[2,1.9,338.38],[1,1.89,71.13],[0,1.88,183.13]],"id":51922}],"tv":105367.82}],"ArrivalTime":1710508031236}
{"op":"mcm","id":2,"clk":"APU7AKtSAJVa","pt":1710508031337,"mc":[{"id":"1.226122413","rc":[{"tv":7750.83,"batb":[[0,8.2,10.12]],"trd":[[8.2,678.31]],"ltp":8.2,"batl":[[0,8.4,33.49]],"id":41122648},{"tv":75481.6,"trd":[[1.88,8443.05]],"batl":[[0,1.88,202.55]],"id":51922},{"batl":[[0,36,12.65]],"id":49744721}],"tv":105453.12}],"ArrivalTime":1710508031344}
{"op":"mcm","id":2,"clk":"APg7ALJSAJ9a","pt":1710508031437,"mc":[{"id":"1.226122413","rc":[{"batl":[[0,8.4,24.6]],"id":41122648}]}],"ArrivalTime":1710508031444}
{"op":"mcm","id":2,"clk":"AP07ALtSAKda","pt":1710508031541,"mc":[{"id":"1.226122413","rc":[{"tv":7755.21,"batb":[[0,8.2,14.24]],"trd":[[8.2,682.69]],"id":41122648}],"tv":105457.5}],"ArrivalTime":1710508031549}
{"op":"mcm","id":2,"clk":"AIU8AMRSALBa","pt":1710508031642,"mc":[{"id":"1.226122413","rc":[{"batl":[[1,1.89,86.13]],"id":51922}]}],"ArrivalTime":1710508031650}
{"op":"mcm","id":2,"clk":"AJw8AOFSANVa","pt":1710508031955,"mc":[{"id":"1.226122413","rc":[{"batb":[[2,23,13.81],[1,24,9.65],[0,25,5.15]],"id":55632148}]}],"ArrivalTime":1710508031963}
{"op":"mcm","id":2,"clk":"AKo8APRSAOZa","pt":1710508032162,"mc":[{"id":"1.226122413","rc":[{"batl":[[2,28,28.55],[1,27,13.8],[0,26,15.8]],"id":55632148},{"batl":[[1,4.5,212.1]],"id":50466254}]}],"ArrivalTime":1710508032170}
{"op":"mcm","id":2,"clk":"ALE8AINTAPJa","pt":1710508032264,"mc":[{"id":"1.226122413","rc":[{"batl":[[0,4.4,4.4]],"id":50466254}]}],"ArrivalTime":1710508032271}
{"op":"mcm","id":2,"clk":"AL48AJBTAIdb","pt":1710508032422,"mc":[{"id":"1.226122413","rc":[{"batl":[[0,8.4,22.65]],"id":41122648},{"batl":[[2,1.9,340.38]],"id":51922}]}],"ArrivalTime":1710508032430}
{"op":"mcm","id":2,"clk":"AMM8AKFTAJBb","pt":1710508032525,"mc":[{"id":"1.226122413","rc":[{"batl":[[0,26,16.6]],"id":55632148}]}],"ArrivalTime":1710508032532}
{"op":"mcm","id":2,"clk":"AM48ALNTAKhb","pt":1710508032730,"mc":[{"id":"1.226122413","rc":[{"tv":75500.6,"trd":[[1.88,8462.05]],"batl":[[0,1.88,193.05]],"id":51922}],"tv":105476.5}],"ArrivalTime":1710508032738}
{"op":"mcm","id":2,"clk":"ANU8ALlTALFb","pt":1710508032834,"mc":[{"id":"1.226122413","rc":[{"batl":[[0,1.88,208.05]],"id":51922}]}],"ArrivalTime":1710508032842}
{"op":"mcm","id":2,"clk":"AN48AMpTAMZb","pt":1710508033035,"mc":[{"id":"1.226122413","rc":[{"tv":14681.01,"batb":[[2,4.2,231.03],[1,4.3,172.88],[0,4.4,34.57]],"trd":[[4.4,3920.69]],"batl":[[2,4.7,77.01],[1,4.6,173.06],[0,4.5,212.1]],"id":50466254}],"tv":105485.3}],"ArrivalTime":1710508033043}
{"op":"mcm","id":2,"clk":"AOw8AN1TANlb","pt":1710508033240,"mc":[{"id":"1.226122413","rc":[{"tv":7772.93,"batb":[[0,8.2,5.38]],"trd":[[8.2,700.41]],"id":41122648},{"batb":[[0,1.87,180.01]],"batl":[[0,1.88,236.9]],"id":51922}],"tv":105503.02}],"ArrivalTime":1710508033247}
{"op":"mcm","id":2,"clk":"APM8AOlTAONb","pt":1710508033346,"mc":[{"id":"1.226122413","rc":[{"batl":[[0,8.4,20.87]],"id":41122648}]}],"ArrivalTime":1710508033354}
{"op":"mcm","id":2,"clk":"APo8APlTAO9b","pt":1710508033447,"mc":[{"id":"1.226122413","rc":[{"tv":75551.14,"batb":[[0,1.87,128.2]],"trd":[[1.87,7185.95]],"ltp":1.87,"id":51922}],"tv":105553.56}],"ArrivalTime":1710508033455}
{"op":"mcm","id":2,"clk":"AIA9AP1TAPxb","pt":1710508033551,"mc":[{"id":"1.226122413","rc":[{"batb":[[0,8.2,17.26]],"id":41122648},{"tv":75561.14,"batb":[[0,1.87,63.31]],"trd":[[1.87,7195.95]],"id":51922}],"tv":105563.56}],"ArrivalTime":1710508033559}
{"op":"mcm","id":2,"clk":"AIY9AIdUAIVc","pt":1710508033661,"mc":[{"id":"1.226122413","rc":[{"tv":75604.2,"batb":[[0,1.87,41.78]],"trd":[[1.87,7239.01]],"id":51922}],"tv":105606.62}],"ArrivalTime":1710508033668}
{"op":"mcm","id":2,"clk":"AJk9AJlUAJxc","pt":1710508033766,"mc":[{"id":"1.226122413","rc":[{"tv":75687.76,"batb":[[2,1.84,135.43],[1,1.85,485.22],[0,1.86,253.29]],"trd":[[1.87,7322.57]],"batl":[[2,1.89,86.13],[1,1.88,236.9],[0,1.87,123.29]],"id":51922}],"tv":105690.18}],"ArrivalTime":1710508033774}
{"op":"mcm","id":2,"clk":"AJ09AKFUAKNc","pt":1710508033870,"mc":[{"id":"1.226122413","rc":[{"batl":[[0,1.87,193.59]],"id":51922}]}],"ArrivalTime":1710508033878}
{"op":"mcm","id":2,"clk":"AKY9AKdUAK1c","pt":1710508033923,"mc":[{"id":"1.226122413","rc":[{"batb":[[0,8.2,25.47]],"batl":[[0,8.4,12.65]],"id":41122648},{"batb":[[1,24,10.65]],"id":55632148},{"batb":[[0,4.4,82.11]],"id":50466254}]}],"ArrivalTime":1710508033931}
{"op":"mcm","id":2,"clk":"AKo9ALFUALdc","pt":1710508034022,"mc":[{"id":"1.226122413","rc":[{"batb":[[0,8.2,44.5]],"id":41122648},{"batb":[[1,1.85,516.22],[0,1.86,191.29]],"id":51922},{"batl":[[0,4.5,191.34]],"id":50466254},{"batl":[[1,200,3.56]],"id":66251581}]}],"ArrivalTime":1710508034030}
{"op":"mcm","id":2,"clk":"ALI9ALtUAMFc","pt":1710508034125,"mc":[{"id":"1.226122413","rc":[{"batl":[[1,1.88,238.41]],"id":51922}]}],"ArrivalTime":1710508034133}
{"op":"mcm","id":2,"clk":"ALg9AMJUAM5c","pt":1710508034233,"mc":[{"id":"1.226122413","rc":[{"tv":76245.76,"trd":[[1.87,7709.75],[1.88,8632.87]],"ltp":1.88,"batl":[[2,1.9,342.38],[1,1.89,86.13],[0,1.88,153]],"id":51922},{"batl":[[2,40,16.17]],"id":49744721}],"tv":106248.18}],"ArrivalTime":1710508034240}
{"op":"mcm","id":2,"clk":"AMI9ANVUAO1c","pt":1710508034427,"mc":[{"id":"1.226122413","rc":[{"batl":[[2,1.89,86.13],[1,1.88,153],[0,1.87,5]],"id":51922}]}],"ArrivalTime":1710508034435}
{"op":"mcm","id":2,"clk":"AMg9AOZUAP9c","pt":1710508034535,"mc":[{"id":"1.226122413","rc":[{"tv":76255.76,"trd":[[1.87,7719.75]],"ltp":1.87,"batl":[[2,1.9,342.38],[1,1.89,86.13],[0,1.88,153]],"id":51922}],"tv":106258.18}],"ArrivalTime":1710508034542}
{"op":"mcm","id":2,"clk":"AM09AOxUAI9d","pt":1710508034637,"mc":[{"id":"1.226122413","rc":[{"batb":[[2,210,11.31],[1,220,7.23],[0,230,1.57]],"id":41200638},{"tv":2384.62,"batb":[[2,29,12.4],[1,30,17.71],[0,32,15.18]],"trd":[[34,195.47]],"batl":[[2,40,16.04],[0,36,13.62]],"id":49744721}],"tv":106260.24}],"ArrivalTime":1710508034644}
{"op":"mcm","id":2,"clk":"ANY9APlUAJxd","pt":1710508034741,"mc":[{"id":"1.226122413","rc":[{"batl":[[1,200,4.56]],"id":66251581}]}],"ArrivalTime":1710508034749}
{"op":"mcm","id":2,"clk":"AOM9AIxVAL1d","pt":1710508034955,"mc":[{"id":"1.226122413","rc":[{"batl":[[2,1.89,86.13],[1,1.88,153],[0,1.87,15]],"id":51922}]}],"ArrivalTime":1710508034963}
{"op":"mcm","id":2,"clk":"AOo9AJJVAMpd","pt":1710508035054,"mc":[{"id":"1.226122413","rc":[{"tv":76671.75,"batb":[[2,1.85,516.22],[1,1.86,191.29],[0,1.88,645.97]],"trd":[[1.87,7829.75],[1.88,8938.86]],"ltp":1.88,"batl":[[2,1.91,220.28],[1,1.9,344.38],[0,1.89,86.13]],"id":51922}],"tv":106676.23}],"ArrivalTime":1710508035062}
{"op":"mcm","id":2,"clk":"APA9AJ9VANVd","pt":1710508035159,"mc":[{"id":"1.226122413","rc":[{"batb":[[0,8.2,36.29]],"batl":[[0,8.4,20.88]],"id":41122648},{"batb":[[2,1.86,191.29],[1,1.87,59.91]],"id":51922},{"batl":[[0,36,12.65]],"id":49744721},{"batl":[[0,4.5,91.34]],"id":50466254}]}],"ArrivalTime":1710508035167}
{"op":"mcm","id":2,"clk":"APU9AKxVAN1d","pt":1710508035266,"mc":[{"id":"1.226122413","rc":[{"batb":[[0,8.2,17.26]],"id":41122648},{"tv":76754.43,"batb":[[1,1.87,141.47],[0,1.88,734.36]],"trd":[[1.89,4196.06]],"ltp":1.89,"batl":[[0,1.89,75.1]],"id":51922},{"batb":[[0,4.4,34.57]],"batl":[[2,4.7,79.95],[0,4.5,112.04]],"id":50466254}],"tv":106758.91}],"ArrivalTime":1710508035274}
{"op":"mcm","id":2,"clk":"AKY+AO5VAKVe","pt":1710508035935,"mc":[{"id":"1.226122413","rc":[{"batb":[[0,8.2,5.38]],"batl":[[0,8.4,30.23]],"id":41122648},{"tv":438.23,"batb":[[0,250,10.28],[2,220,4.21],[1,230,1.57]],"trd":[[250,20.35]],"ltp":250,"batl":[[2,650,1.71],[1,380,3.5],[0,280,1.33]],"id":41200638},{"tv":1852.61,"batb":[[0,24,9.65],[2,22,23.97],[1,23,13.81]],"trd":[[25,381.16]],"batl":[[2,27,13.06],[1,26,15.8],[0,25,3.01]],"id":55632148},{"tv":76813.41,"batb":[[2,1.86,196.29],[1,1.87,170.05],[0,1.88,729.87]],"trd":[[1.89,4246.06],[1.88,8947.84]],"ltp":1.89,"batl":[[1,1.9,341.38],[0,1.89,109.76]],"id":51922},{"tv":14681.45,"trd":[[4.5,2893.68]],"ltp":4.5,"batl":[[0,4.5,111.82]],"id":50466254}],"tv":106832.29,"con":true}],"ArrivalTime":1710508035943}
{"op":"mcm","id":2,"clk":"AK4+AP1VAK5e","pt":1710508036048,"mc":[{"id":"1.226122413","rc":[{"tv":77013.41,"batb":[[0,1.88,629.87]],"trd":[[1.88,9147.84]],"ltp":1.88,"id":51922},{"batl":[[2,38,14.39],[1,36,12.65],[0,34,8.54]],"id":49744721}],"tv":107032.29}],"ArrivalTime":1710508036056}
{"op":"mcm","id":2,"clk":"ALI+AIBWALle","pt":1710508036147,"mc":[{"id":"1.226122413","rc":[{"batb":[[0,8.2,5.62]],"id":41122648},{"tv":77045.27,"batb":[[0,1.88,613.94]],"trd":[[1.88,9179.7]],"id":51922},{"tv":14685.87,"trd":[[4.5,2898.1]],"batl":[[0,4.5,109.61]],"id":50466254},{"batb":[[1,140,4.34]],"id":66251581}],"tv":107068.57}],"ArrivalTime":1710508036157}
{"op":"mcm","id":2,"clk":"ALc+AIxWAL9e","pt":1710508036254,"mc":[{"id":"1.226122413","rc":[{"batl":[[1,36,10.65],[0,34,11.8]],"id":49744721},{"batb":[[0,4.4,82.13]],"id":50466254}]}],"ArrivalTime":1710508036262}
{"op":"mcm","id":2,"clk":"AL0+AJRWAMle","pt":1710508036364,"mc":[{"id":"1.226122413","rc":[{"tv":7784.17,"batb":[[2,7.6,82.26],[1,7.8,67.85],[0,8,95.41]],"trd":[[8.2,711.65]],"batl":[[2,8.6,23.18],[1,8.4,30.23],[0,8.2,1.15]],"id":41122648},{"batb":[[0,250,10.4]],"id":41200638},{"batl":[[1,1.9,343.38]],"id":51922}],"tv":107079.81}],"ArrivalTime":1710508036372}
{"op":"mcm","id":2,"clk":"AMQ+AKZWANhe","pt":1710508036467,"mc":[{"id":"1.226122413","rc":[{"batb":[],"batl":[[2,1000,5.28],[1,650,1.71],[0,380,3.79]],"id":41200638}]}],"ArrivalTime":1710508036475}
{"op":"mcm","id":2,"clk":"AM0+ALVWAN9e","pt":1710508036572,"mc":[{"id":"1.226122413","rc":[{"batb":[[2,7.6,84.3]],"batl":[[1,8.4,31.43],[0,8.2,12.43]],"id":41122648},{"batb":[[2,1.86,236.51]],"batl":[],"id":51922},{"batl":[[2,4.7,77.01],[0,4.5,88.91]],"id":50466254}]}],"ArrivalTime":1710508036580}
{"op":"mcm","id":2,"clk":"ANU+AMNWAOte","pt":1710508036673,"mc":[{"id":"1.226122413","rc":[{"batb":[[2,230,1.57],[1,250,10.4],[0,260,1.07]],"batl":[[2,1000,4.28]],"id":41200638},{"tv":77064.25,"batb":[[0,1.88,585.22]],"trd":[[1.89,4265.04]],"ltp":1.89,"batl":[[0,1.89,128.37]],"id":51922},{"tv":504.23,"batb":[[2,120,5.31],[1,130,2.17],[0,140,4.77]],"trd":[[150,48.54]],"id":66251581},{"tv":2033.99,"batb":[[0,26,9.45]],"trd":[[26,333.44]],"ltp":26,"batl":[[0,28,7.74]],"id":106596}],"tv":107105.65}],"ArrivalTime":1710508036681}
{"op":"mcm","id":2,"clk":"ANs+AMxWAPVe","pt":1710508036736,"mc":[{"id":"1.226122413","rc":[{"batb":[[0,8,78.06]],"id":41122648},{"batl":[[2,650,1.71],[1,380,3.06],[0,370,1.97]],"id":41200638},{"tv":77085.08,"batb":[[0,1.88,583.34]],"trd":[[1.88,9183.45],[1.89,4282.12]],"ltp":1.88,"batl":[[0,1.89,119.83]],"id":51922}],"tv":107126.48}],"ArrivalTime":1710508036744}
{"op":"mcm","id":2,"clk":"AOM+ANVWAP9e","pt":1710508036841,"mc":[{"id":"1.226122413","rc":[{"batl":[[1,8.4,29.43]],"id":41122648},{"batl":[[2,4.7,79.95]],"id":50466254},{"batb":[],"batl":[[0,28,7.36]],"id":106596}]}],"ArrivalTime":1710508036849}
{"op":"mcm","id":2,"clk":"AOo+AN1WAIVf","pt":1710508036934,"mc":[{"id":"1.226122413","rc":[{"batb":[[0,1.88,59.67]],"id":51922},{"tv":2035.99,"batb":[[0,26,8.45]],"trd":[[26,335.44]],"id":106596}],"tv":107128.48}],"ArrivalTime":1710508036942}
{"op":"mcm","id":2,"clk":"APE+AOpWAI9f","pt":1710508037039,"mc":[{"id":"1.226122413","rc":[{"batb":[[1,7.8,67.59]],"id":41122648},{"batl":[[2,380,2.82],[1,370,1.38],[0,350,3.39]],"id":41200638},{"batb":[[2,1.85,474.22],[1,1.86,236.51],[0,1.87,170.05]],"id":51922},{"batb":[[0,140,6.14]],"id":66251581}]}],"ArrivalTime":1710508037047}
{"op":"mcm","id":2,"clk":"APY+APRWAJVf","pt":1710508037142,"mc":[{"id":"1.226122413","rc":[{"batb":[[2,1.85,514.22]],"id":51922},{"batl":[[2,4.7,77.01],[0,4.5,98.91]],"id":50466254}]}],"ArrivalTime":1710508037149}
{"op":"mcm","id":2,"clk":"APs+APpWAJ9f","pt":1710508037240,"mc":[{"id":"1.226122413","rc":[{"batl":[[0,4.5,124.65]],"id":50466254}]}],"ArrivalTime":1710508037248}
{"op":"mcm","id":2,"clk":"AP4+AIhXAKtf","pt":1710508037353,"mc":[{"id":"1.226122413","rc":[{"batl":[[1,370,1.14],[0,350,3.63]],"id":41200638},{"batb":[[0,140,10.79]],"id":66251581}]}],"ArrivalTime":1710508037361}
{"op":"mcm","id":2,"clk":"AIY/AJBXALhf","pt":1710508037451,"mc":[{"id":"1.226122413","rc":[{"batl":[[0,8.2,11.28]],"id":41122648},{"batb":[[2,230,2.34],[1,250,11.4]],"batl":[[2,380,2.95],[0,350,3.44]],"id":41200638},{"batb":[[1,1.86,297.51]],"batl":[[1,1.9,345.38]],"id":51922},{"batb":[[0,26,11.18]],"id":106596}]}],"ArrivalTime":1710508037459}
{"op":"mcm","id":2,"clk":"AI0/AJpXAMFf","pt":1710508037558,"mc":[{"id":"1.226122413","rc":[{"batl":[[2,8.8,26.49],[1,8.6,23.18],[0,8.4,29.43]],"id":41122648}]}],"ArrivalTime":1710508037566}
{"op":"mcm","id":2,"clk":"AJI/AJ5XAMtf","pt":1710508037658,"mc":[{"id":"1.226122413","rc":[{"batb":[[0,1.87,181.5]],"id":51922},{"batb":[[0,140,9.42]],"id":66251581}]}],"ArrivalTime":1710508037666}
{"op":"mcm","id":2,"clk":"AJ0/AKRXANZf","pt":1710508037759,"mc":[{"id":"1.226122413","rc":[{"batb":[[2,7.6,82.26]],"id":41122648},{"batl":[[2,200,4.56],[1,180,2.28],[0,170,1.44]],"id":66251581}]}],"ArrivalTime":1710508037767}
{"op":"mcm","id":2,"clk":"AKQ/AKtXAOBf","pt":1710508037879,"mc":[{"id":"1.226122413","rc":[{"batb":[[2,1.85,551.13]],"id":51922}]}],"ArrivalTime":1710508037887}
{"op":"mcm","id":2,"clk":"AK0/ALFXAO5f","pt":1710508037975,"mc":[{"id":"1.226122413","rc":[{"batl":[[0,8.4,31.43]],"id":41122648},{"batl":[[2,650,1.71],[1,380,3.09]],"id":41200638}]}],"ArrivalTime":1710508037982}
{"op":"mcm","id":2,"clk":"ALE/ALZXAPlf","pt":1710508038031,"mc":[{"id":"1.226122413","rc":[{"batl":[[2,380,3.09],[1,350,2.8],[0,340,1.64]],"id":41200638}]}],"ArrivalTime":1710508038039}
{"op":"mcm","id":2,"clk":"ALk/AMVXAIlg","pt":1710508038181,"mc":[{"id":"1.226122413","rc":[{"batl":[[2,1.9,345.38],[1,1.89,119.83],[0,1.88,100]],"id":51922}]}],"ArrivalTime":1710508038189}
{"op":"mcm","id":2,"clk":"AMA/AMlXAJJg","pt":1710508038228,"mc":[{"id":"1.226122413","rc":[{"batl":[[1,350,2.56],[0,340,1.87]],"id":41200638}]}],"ArrivalTime":1710508038236}
{"op":"mcm","id":2,"clk":"AMY/ANZXAJ1g","pt":1710508038337,"mc":[{"id":"1.226122413","rc":[{"tv":77123.58,"batb":[[2,1.85,536.22],[0,1.87,99.94]],"trd":[[1.88,9221.95]],"batl":[[2,1.9,347.38],[0,1.88,142.29]],"id":51922}],"tv":107166.98}],"ArrivalTime":1710508038344}
{"op":"mcm","id":2,"clk":"AM4/AOFXAKlg","pt":1710508038443,"mc":[{"id":"1.226122413","rc":[{"batl":[[2,650,1.94],[1,380,3.09]],"id":41200638},{"tv":77473.22,"trd":[[1.88,9506.53],[1.89,4347.18]],"ltp":1.89,"batl":[[2,1.91,220.28],[1,1.9,347.38],[0,1.89,87.3]],"id":51922},{"batl":[[0,170,2.62]],"id":66251581}],"tv":107516.62}],"ArrivalTime":1710508038451}
{"op":"mcm","id":2,"clk":"AOU/AIZYAN5g","pt":1710508038853,"mc":[{"id":"1.226122413","rc":[{"batl":[[1,380,2.95],[0,360,1.01]],"id":41200638},{"batb":[[1,1.86,289.51]],"id":51922},{"tv":14686.47,"trd":[[4.5,2898.7]],"batl":[[0,4.5,124.35]],"id":50466254}],"tv":107517.22}],"ArrivalTime":1710508038861}
{"op":"mcm","id":2,"clk":"AOs/AI1YAOhg","pt":1710508038957,"mc":[{"id":"1.226122413","rc":[{"batl":[[2,380,2.95],[1,370,1]],"id":41200638}]}],"ArrivalTime":1710508038965}
{"op":"mcm","id":2,"clk":"APA/AJlYAPZg","pt":1710508039059,"mc":[{"id":"1.226122413","rc":[{"tv":14846.47,"batb":[[0,4.4,2.13]],"trd":[[4.4,4080.69]],"ltp":4.4,"id":50466254}],"tv":107677.22}],"ArrivalTime":1710508039067}
{"op":"mcm","id":2,"clk":"AP4/ALBYAIth","pt":1710508039263,"mc":[{"id":"1.226122413","rc":[{"batb":[[2,1.86,289.51],[1,1.87,145.18],[0,1.88,61.23]],"batl":[[1,1.9,349.38]],"id":51922},{"batb":[[2,4.1,133.76],[1,4.2,231.03],[0,4.3,172.88]],"batl":[[0,4.5,143.74]],"id":50466254},{"batl":[[0,170,3.8]],"id":66251581}]}],"ArrivalTime":1710508039271}
{"op":"mcm","id":2,"clk":"AI1AAMVYAJ5h","pt":1710508039471,"mc":[{"id":"1.226122413","rc":[{"batb":[[2,4.1,101.5]],"batl":[],"id":50466254}]}],"ArrivalTime":1710508039479}
{"op":"mcm","id":2,"clk":"AJRAAMpYAKlh","pt":1710508039577,"mc":[{"id":"1.226122413","rc":[{"batb":[[0,140,10.14]],"id":66251581}]}],"ArrivalTime":1710508039585}
{"op":"mcm","id":2,"clk":"AJlAANZYALZh","pt":1710508039629,"mc":[{"id":"1.226122413","rc":[{"tv":77477.76,"batb":[[0,1.88,58.96]],"trd":[[1.88,9511.07]],"ltp":1.88,"id":51922}],"tv":107681.76}],"ArrivalTime":1710508039637}
{"op":"mcm","id":2,"clk":"AKBAAONYAMBh","pt":1710508039734,"mc":[{"id":"1.226122413","rc":[{"batl":[[2,180,2.28],[1,170,3.54],[0,160,1.26]],"id":66251581}]}],"ArrivalTime":1710508039741}
{"op":"mcm","id":2,"clk":"AKdAAOxYAMth","pt":1710508039833,"mc":[{"id":"1.226122413","rc":[{"batb":[[1,1.87,227.18]],"id":51922},{"batb":[[2,120,5.7],[1,130,2.5]],"id":66251581}]}],"ArrivalTime":1710508039843}
{"op":"mcm","id":2,"clk":"AK1AAPZYANZh","pt":1710508039937,"mc":[{"id":"1.226122413","rc":[{"batb":[],"batl":[[2,1.91,228.82]],"id":51922},{"batb":[[0,140,9.71]],"id":66251581}]}],"ArrivalTime":1710508039944}
{"op":"mcm","id":2,"clk":"ALpAAIZZAPVh","pt":1710508040248,"mc":[{"id":"1.226122413","rc":[{"batl":[[2,38,11.69]],"id":49744721},{"batb":[[0,140,5.06]],"id":66251581}]}],"ArrivalTime":1710508040256}
{"op":"mcm","id":2,"clk":"AMBAAI1ZAIFi","pt":1710508040349,"mc":[{"id":"1.226122413","rc":[{"batb":[[0,1.88,152.96]],"id":51922}]}],"ArrivalTime":1710508040357}
{"op":"mcm","id":2,"clk":"AMxAAJlZAJVi","pt":1710508040552,"mc":[{"id":"1.226122413","rc":[{"batl":[[2,650,1.94],[1,380,2.95],[0,370,1.78]],"id":41200638},{"batb":[[0,1.88,183.78]],"batl":[[1,1.9,351.38]],"id":51922},{"tv":2404.62,"trd":[[34,215.47]],"batl":[[0,34,1.8]],"id":49744721},{"batl":[[2,180,2.98]],"id":66251581}],"tv":107701.76}],"ArrivalTime":1710508040560}
{"op":"mcm","id":2,"clk":"ANFAAJ9ZAKJi","pt":1710508040656,"mc":[{"id":"1.226122413","rc":[{"batl":[[0,1.89,92.45]],"id":51922}]}],"ArrivalTime":1710508040664}
{"op":"mcm","id":2,"clk":"ANhAAKlZAKpi","pt":1710508040760,"mc":[{"id":"1.226122413","rc":[{"batb":[[1,1.87,229.48]],"batl":[[0,1.89,64.35]],"id":51922},{"batl":[[2,40,19.09],[1,38,11.69],[0,36,10.65]],"id":49744721}]}],"ArrivalTime":1710508040768}
{"op":"mcm","id":2,"clk":"ANxAALFZALZi","pt":1710508040867,"mc":[{"id":"1.226122413","rc":[{"batl":[[2,1.91,226.82]],"id":51922}]}],"ArrivalTime":1710508040874}
{"op":"mcm","id":2,"clk":"AONAALpZAL5i","pt":1710508040969,"mc":[{"id":"1.226122413","rc":[{"batb":[[0,32,19.04]],"id":49744721},{"batl":[[2,4.6,173.06],[1,4.5,143.74],[0,4.4,47.07]],"id":50466254}]}],"ArrivalTime":1710508040977}
{"op":"mcm","id":2,"clk":"AOdAAMNZAMti","pt":1710508041078,"mc":[{"id":"1.226122413","rc":[{"batl":[[2,380,2.95],[1,370,1],[0,360,3.35]],"id":41200638},{"tv":77689.4,"trd":[[1.9,3983.57],[1.89,4475.88]],"ltp":1.9,"batl":[[2,1.92,288.73],[1,1.91,226.82],[0,1.9,309.91]],"id":51922},{"tv":2408.62,"batb":[[0,32,17.04]],"trd":[[32,112.16]],"ltp":32,"id":49744721}],"tv":107917.4}],"ArrivalTime":1710508041086}
{"op":"mcm","id":2,"clk":"AOxAAMxZANhi","pt":1710508041179,"mc":[{"id":"1.226122413","rc":[{"batl":[[0,36,12.65]],"id":49744721}]}],"ArrivalTime":1710508041187}
{"op":"mcm","id":2,"clk":"APFAANZZAOVi","pt":1710508041230,"mc":[{"id":"1.226122413","rc":[{"batl":[[0,1.9,339.99]],"id":51922},{"batb":[[0,32,20.04]],"id":49744721},{"batb":[[0,4.3,149.85]],"id":50466254}]}],"ArrivalTime":1710508041237}
{"op":"mcm","id":2,"clk":"APlAAONZAOti","pt":1710508041337,"mc":[{"id":"1.226122413","rc":[{"batl":[[2,1.91,226.82],[1,1.9,339.99],[0,1.89,61.98]],"id":51922},{"batb":[[0,4.3,161.3]],"batl":[[2,4.7,79.95],[1,4.6,173.06],[0,4.5,143.74]],"id":50466254}]}],"ArrivalTime":1710508041345}
{"op":"mcm","id":2,"clk":"AP1AAO1ZAPpi","pt":1710508041438,"mc":[{"id":"1.226122413","rc":[{"batb":[[0,4.3,184.93]],"batl":[[2,4.6,173.06],[1,4.5,143.74],[0,4.4,48.91]],"id":50466254}]}],"ArrivalTime":1710508041446}
{"op":"mcm","id":2,"clk":"AINBAPdZAIVj","pt":1710508041546,"mc":[{"id":"1.226122413","rc":[{"tv":7804.17,"batb":[],"trd":[[8.4,1028.69]],"ltp":8.4,"batl":[[0,8.4,21.43]],"id":41122648},{"tv":1855.31,"trd":[[25,383.86]],"batl":[[0,25,1.66]],"id":55632148},{"tv":77709.4,"trd":[[1.89,4495.88]],"ltp":1.89,"batl":[[1,1.9,341.99],[0,1.89,51.98]],"id":51922},{"batb":[[2,30,17.71],[1,32,20.04],[0,34,3.33]],"id":49744721},{"tv":14866.47,"batb":[],"trd":[[4.4,4100.69]],"batl":[[0,4.4,38.91]],"id":50466254}],"tv":107980.1}],"ArrivalTime":1710508041554}
{"op":"mcm","id":2,"clk":"AIlBAIJaAJVj","pt":1710508041653,"mc":[{"id":"1.226122413","rc":[{"tv":2410.62,"batb":[[0,34,2.33]],"trd":[[34,217.47]],"ltp":34,"batl":[],"id":49744721},{"batb":[[0,4.3,161.3]],"id":50466254},{"batb":[[0,26,17.78]],"id":106596}],"tv":107982.1}],"ArrivalTime":1710508041662}
{"op":"mcm","id":2,"clk":"AJFBAItaAKBj","pt":1710508041746,"mc":[{"id":"1.226122413","rc":[{"tv":2414.62,"batb":[[2,29,12.4],[1,30,17.71],[0,32,20.37]],"trd":[[34,221.47]],"id":49744721}],"tv":107986.1}],"ArrivalTime":1710508041754}
{"op":"mcm","id":2,"clk":"AJdBAJVaAKhj","pt":1710508041854,"mc":[{"id":"1.226122413","rc":[{"tv":2415.28,"batb":[[0,32,20.04]],"trd":[[34,222.13]],"batl":[[0,36,13.61]],"id":49744721}],"tv":107986.76}],"ArrivalTime":1710508041862}
{"op":"mcm","id":2,"clk":"AJ1BAJtaALtj","pt":1710508041957,"mc":[{"id":"1.226122413","rc":[{"batb":[[2,250,11.4],[1,260,1.07],[0,270,2]],"id":41200638},{"batl":[[0,1.89,2]],"id":51922},{"batb":[[0,32,16.18]],"batl":[[2,38,11.69],[1,36,12.65],[0,34,1.61]],"id":49744721},{"batb":[[0,26,18.78]],"id":106596}]}],"ArrivalTime":1710508041965}
{"op":"mcm","id":2,"clk":"AKJBAKlaAMpj","pt":1710508042061,"mc":[{"id":"1.226122413","rc":[{"batb":[[0,270,3.16]],"id":41200638},{"tv":77713.39,"batb":[[2,1.87,229.48],[1,1.88,183.78],[0,1.89,36.88]],"trd":[[1.89,4499.87]],"batl":[[2,1.92,288.73],[1,1.91,226.82],[0,1.9,341.99]],"id":51922},{"tv":2455.28,"batb":[[2,28,16.25],[1,29,12.4],[0,30,13.89]],"trd":[[30,106.56],[32,144.52]],"ltp":30,"id":49744721}],"tv":108030.75}],"ArrivalTime":1710508042070}
{"op":"mcm","id":2,"clk":"AKxBAK5aANtj","pt":1710508042169,"mc":[{"id":"1.226122413","rc":[{"batl":[[0,28,3.97]],"id":106596}]}],"ArrivalTime":1710508042176}
{"op":"mcm","id":2,"clk":"ALBBAL5aAOdj","pt":1710508042268,"mc":[{"id":"1.226122413","rc":[{"batb":[[2,260,1.07],[1,270,3.16],[0,280,2]],"id":41200638},{"batb":[[2,1.86,289.51],[1,1.87,229.48],[0,1.88,183.78]],"id":51922},{"batb":[[0,30,20.32]],"batl":[[2,36,10.65],[1,34,12.2],[0,32,12.28]],"id":49744721}]}],"ArrivalTime":1710508042276}
{"op":"mcm","id":2,"clk":"ALNBAMpaAPBj","pt":1710508042379,"mc":[{"id":"1.226122413","rc":[{"tv":7804.37,"batb":[[0,8,77.96]],"trd":[[8,27.5]],"ltp":8,"id":41122648},{"batl":[[0,32,15.44]],"id":49744721}],"tv":108030.95}],"ArrivalTime":1710508042386}
{"op":"mcm","id":2,"clk":"ALZBANVaAPVj","pt":1710508042475,"mc":[{"id":"1.226122413","rc":[{"batb":[[0,8,89.67]],"id":41122648},{"batb":[[0,280,3.12]],"id":41200638},{"batl":[[2,28,27.86],[1,27,13.06],[0,26,15.8]],"id":55632148},{"batb":[[0,30,17.69]],"batl":[],"id":49744721},{"batb":[[1,130,2.17]],"id":66251581}]}],"ArrivalTime":1710508042482}
{"op":"mcm","id":2,"clk":"ALtBAN5aAP1j","pt":1710508042579,"mc":[{"id":"1.226122413","rc":[{"batl":[[2,650,1.94],[1,380,2.95]],"id":41200638},{"batb":[[2,1.87,229.48],[1,1.88,183.78],[0,1.89,59.47]],"id":51922},{"batl":[[1,34,10.59]],"id":49744721}]}],"ArrivalTime":1710508042587}
{"op":"mcm","id":2,"clk":"AMNBAO1aAIpk","pt":1710508042647,"mc":[{"id":"1.226122413","rc":[{"batb":[[1,270,1.16]],"batl":[[2,380,2.95],[1,360,2.71],[0,350,1.64]],"id":41200638},{"batl":[[0,1.9,343.99]],"id":51922},{"batl":[[0,32,21.58]],"id":49744721},{"batl":[[0,4.4,41.26]],"id":50466254},{"batb":[[1,130,2.5]],"id":66251581}]}],"ArrivalTime":1710508042655}
{"op":"mcm","id":2,"clk":"AMRBAPhaAJBk","pt":1710508042738,"mc":[{"id":"1.226122413","rc":[{"tv":361.68,"batb":[[0,330,2.5]],"trd":[[350,14.64],[340,21.76],[330,41.12]],"ltp":330,"id":54370634},{"tv":7824.37,"trd":[[8.4,1048.69]],"ltp":8.4,"batl":[[0,8.4,11.43]],"id":41122648},{"tv":442.23,"batb":[[2,260,1.78],[0,280,1.12]],"trd":[[280,15.93]],"ltp":280,"batl":[[0,350,1.15]],"id":41200638},{"batl":[[2,27,13.06],[1,26,15.8],[0,25,2]],"id":55632148},{"batb":[],"batl":[[0,1.9,267.19]],"id":51922},{"tv":2459.28,"batb":[[0,30,15.69]],"trd":[[30,110.56]],"id":49744721},{"tv":508.23,"batb":[[0,140,3.06]],"trd":[[140,66.2]],"ltp":140,"id":66251581},{"tv":2039.99,"batb":[[0,26,16.78]],"trd":[[26,339.44]],"id":106596}],"tv":108070.95}],"ArrivalTime":1710508042746}
{"op":"mcm","id":2,"clk":"ANRBAJJbALVk","pt":1710508043058,"mc":[{"id":"1.226122413","rc":[{"batb":[[2,7.8,67.59],[1,8,89.67],[0,8.2,21.26]],"batl":[[0,8.4,13.39],[1,8.6,32.95]],"id":41122648},{"batb":[[1,270,2.73]],"batl":[[2,650,1.94],[1,380,3.09]],"id":41200638},{"tv":77717.89,"batb":[[2,1.87,234.68],[1,1.88,266.78],[0,1.89,57.22]],"trd":[[1.89,4504.37]],"batl":[[1,1.91,235.82]],"id":51922},{"batb":[[1,29,12.4],[0,30,18.69]],"id":49744721},{"batl":[[2,4.6,176.15]],"id":50466254},{"tv":508.71,"batb":[[2,120,5.31],[1,130,2.5],[0,140,4.16]],"trd":[[150,49.02]],"ltp":150,"batl":[[2,180,2.98],[1,170,3.54],[0,160,2.05]],"id":66251581}],"tv":108075.93,"con":true}],"ArrivalTime":1710508043065}
{"op":"mcm","id":2,"clk":"AN5BAJxbAMJk","pt":1710508043157,"mc":[{"id":"1.226122413","rc":[{"batl":[[0,32,22.94]],"id":49744721},{"batb":[[1,130,2.17]],"id":66251581}]}],"ArrivalTime":1710508043165}
{"op":"mcm","id":2,"clk":"AOlBAK5bANFk","pt":1710508043358,"mc":[{"id":"1.226122413","rc":[{"batb":[[0,30,14.57]],"id":49744721},{"tv":14886.47,"batb":[[0,4.3,151.3]],"trd":[[4.3,4070.81]],"ltp":4.3,"batl":[[2,4.6,173.06]],"id":50466254}],"tv":108095.93}],"ArrivalTime":1710508043366}
{"op":"mcm","id":2,"clk":"APBBALpbAN1k","pt":1710508043466,"mc":[{"id":"1.226122413","rc":[{"batb":[[0,1.89,74.3]],"id":51922},{"batl":[[0,4.4,55.04]],"id":50466254}]}],"ArrivalTime":1710508043474}
{"op":"mcm","id":2,"clk":"APhBAMNbAORk","pt":1710508043565,"mc":[{"id":"1.226122413","rc":[{"batl":[[0,32,25.27]],"id":49744721},{"tv":2043.99,"batb":[[0,26,14.78]],"trd":[[26,343.44]],"id":106596}],"tv":108099.93}],"ArrivalTime":1710508043572}
{"op":"mcm","id":2,"clk":"AIFCAMhbAOlk","pt":1710508043672,"mc":[{"id":"1.226122413","rc":[{"batb":[[0,330,2.8]],"id":54370634},{"batl":[[2,650,1.37],[1,450,1.06],[0,350,1]],"id":41200638},{"tv":77725.89,"batb":[[0,1.89,100.06]],"trd":[[1.89,4512.37]],"batl":[],"id":51922}],"tv":108107.93}],"ArrivalTime":1710508043680}
{"op":"mcm","id":2,"clk":"AIlCANFbAPVk","pt":1710508043773,"mc":[{"id":"1.226122413","rc":[{"batl":[[2,650,1.71],[1,420,3.54]],"id":41200638},{"batl":[[1,1.91,288.1]],"id":51922}]}],"ArrivalTime":1710508043781}
{"op":"mcm","id":2,"clk":"AJBCANlbAPtk","pt":1710508043880,"mc":[{"id":"1.226122413","rc":[{"batb":[[1,1.88,269.05]],"batl":[[0,1.9,247.11]],"id":51922}]}],"ArrivalTime":1710508043888}
{"op":"mcm","id":2,"clk":"AJVCAONbAIFl","pt":1710508043936,"mc":[{"id":"1.226122413","rc":[{"batl":[[1,1.91,235.82]],"id":51922}]}],"ArrivalTime":1710508043944}
{"op":"mcm","id":2,"clk":"AJpCAOpbAIpl","pt":1710508044036,"mc":[{"id":"1.226122413","rc":[{"tv":7848.37,"batb":[[0,8.2,9.26]],"trd":[[8.2,735.65]],"ltp":8.2,"id":41122648},{"batb":[[2,1.87,236.68]],"id":51922}],"tv":108131.93}],"ArrivalTime":1710508044044}
{"op":"mcm","id":2,"clk":"AKlCAP9bAKNl","pt":1710508044245,"mc":[{"id":"1.226122413","rc":[{"batl":[[0,8.4,21.63]],"id":41122648},{"batl":[[2,1000,4.28],[1,650,1.71],[0,420,3.54]],"id":41200638},{"tv":77785.89,"batb":[[0,1.89,70.06]],"trd":[[1.89,4572.37]],"id":51922}],"tv":108191.93}],"ArrivalTime":1710508044252}
{"op":"mcm","id":2,"clk":"ALBCAIRcAKtl","pt":1710508044354,"mc":[{"id":"1.226122413","rc":[{"batb":[[0,8.2,21.07]],"id":41122648}]}],"ArrivalTime":1710508044361}
{"op":"mcm","id":2,"clk":"ALZCAIlcALRl","pt":1710508044452,"mc":[{"id":"1.226122413","rc":[{"batb":[[0,8.2,31.07]],"id":41122648}]}],"ArrivalTime":1710508044460}
{"op":"mcm","id":2,"clk":"ALpCAJJcALxl","pt":1710508044547,"mc":[{"id":"1.226122413","rc":[{"tv":7850.37,"batb":[[0,8.2,30.07]],"trd":[[8.2,737.65]],"id":41122648},{"tv":77805.89,"batb":[[0,1.89,60.06]],"trd":[[1.89,4592.37]],"batl":[[1,1.91,237.28]],"id":51922}],"tv":108213.93}],"ArrivalTime":1710508044555}
{"op":"mcm","id":2,"clk":"AMJCAJhcAMZl","pt":1710508044650,"mc":[{"id":"1.226122413","rc":[{"tv":77806.19,"trd":[[1.9,3983.87]],"ltp":1.9,"batl":[[0,1.9,276.31]],"id":51922}],"tv":108214.23}],"ArrivalTime":1710508044658}
{"op":"mcm","id":2,"clk":"AMlCAJ9cANBl","pt":1710508044755,"mc":[{"id":"1.226122413","rc":[{"batb":[[1,1.88,524.05],[0,1.89,39.8]],"id":51922}]}],"ArrivalTime":1710508044762}
{"op":"mcm","id":2,"clk":"ANFCAKRcANll","pt":1710508044862,"mc":[{"id":"1.226122413","rc":[{"batl":[[2,1.92,298.73]],"id":51922}]}],"ArrivalTime":1710508044869}
{"op":"mcm","id":2,"clk":"ANtCAK5cAOVl","pt":1710508044968,"mc":[{"id":"1.226122413","rc":[{"tv":77885.79,"batb":[[2,1.86,289.51],[1,1.87,236.68],[0,1.88,535.05]],"trd":[[1.89,4671.97]],"ltp":1.89,"batl":[[2,1.91,237.28],[1,1.9,276.31],[0,1.89,60.2]],"id":51922}],"tv":108293.83}],"ArrivalTime":1710508044976}
{"op":"mcm","id":2,"clk":"AONCALVcAO1l","pt":1710508045072,"mc":[{"id":"1.226122413","rc":[{"batl":[[2,650,1.71],[1,420,3.04],[0,410,3.06]],"id":41200638},{"tv":77899.31,"trd":[[1.89,4685.49]],"batl":[[0,1.89,53.94]],"id":51922},{"batb":[[2,120,5.7]],"id":66251581}],"tv":108307.35}],"ArrivalTime":1710508045080}
{"op":"mcm","id":2,"clk":"AOxCAMNcAPll","pt":1710508045174,"mc":[{"id":"1.226122413","rc":[{"tv":7854.37,"trd":[[8.4,1052.69]],"ltp":8.4,"batl":[[0,8.4,19.63]],"id":41122648},{"batb":[],"batl":[[1,4.5,163.74],[0,4.4,38.91]],"id":50466254},{"batb":[[0,140,3.44]],"id":66251581}],"tv":108311.35}],"ArrivalTime":1710508045182}
{"op":"mcm","id":2,"clk":"AO9CAMpcAIVm","pt":1710508045279,"mc":[{"id":"1.226122413","rc":[{"batb":[[1,1.87,241.88],[0,1.88,537.05]],"batl":[[1,1.9,278.31]],"id":51922}]}],"ArrivalTime":1710508045286}
{"op":"mcm","id":2,"clk":"APVCANdcAJNm","pt":1710508045383,"mc":[{"id":"1.226122413","rc":[{"batb":[[2,270,2.12],[1,300,1.23],[0,320,2.74]],"id":54370634},{"batb":[[0,24,10.51]],"id":55632148},{"batl":[[2,36,13.51]],"id":49744721}]}],"ArrivalTime":1710508045391}
{"op":"mcm","id":2,"clk":"APxCAN1cAJxm","pt":1710508045487,"mc":[{"id":"1.226122413","rc":[{"batb":[[2,1.86,287.51]],"id":51922}]}],"ArrivalTime":1710508045495}
{"op":"mcm","id":2,"clk":"AItDAPRcALNm","pt":1710508045649,"mc":[{"id":"1.226122413","rc":[{"batl":[[0,8.4,21.63]],"id":41122648}]}],"ArrivalTime":1710508045657}
{"op":"mcm","id":2,"clk":"AJBDAPhcAL1m","pt":1710508045739,"mc":[{"id":"1.226122413","rc":[{"batl":[[0,410,4.06]],"id":41200638},{"batl":[[2,1.91,237.78]],"id":51922}]}],"ArrivalTime":1710508045747}
{"op":"mcm","id":2,"clk":"AJRDAIRdAMpm","pt":1710508045844,"mc":[{"id":"1.226122413","rc":[{"batl":[[2,890,1.63],[1,430,2.24],[0,420,1.47]],"id":54370634},{"batl":[[0,410,3.92]],"id":41200638},{"tv":14894.47,"batb":[[0,4.3,147.3]],"trd":[[4.3,4078.81]],"id":50466254}],"tv":108319.35}],"ArrivalTime":1710508045852}
{"op":"mcm","id":2,"clk":"AJhDAItdANNm","pt":1710508045947,"mc":[{"id":"1.226122413","rc":[{"batl":[[2,480,3.24]],"id":54370634},{"tv":1859.31,"batb":[[0,24,8.51]],"trd":[[24,245.59]],"ltp":24,"id":55632148}],"tv":108323.35}],"ArrivalTime":1710508045954}
{"op":"mcm","id":2,"clk":"AKBDAJRdANxm","pt":1710508046051,"mc":[{"id":"1.226122413","rc":[{"batl":[[1,1.9,280.31]],"id":51922}]}],"ArrivalTime":1710508046062}
{"op":"mcm","id":2,"clk":"AKZDAKRdAPpm","pt":1710508046267,"mc":[{"id":"1.226122413","rc":[{"tv":7874.37,"batb":[[0,8.2,20.07]],"trd":[[8.2,757.65]],"ltp":8.2,"id":41122648},{"tv":77901.31,"batb":[[0,1.88,539.05]],"trd":[[1.89,4687.49]],"batl":[[0,1.89,52.94]],"id":51922}],"tv":108345.35}],"ArrivalTime":1710508046275}
{"op":"mcm","id":2,"clk":"AK1DAK5dAIFn","pt":1710508046364,"mc":[{"id":"1.226122413","rc":[{"batb":[[0,320,2.44]],"id":54370634},{"tv":14894.84,"batb":[[0,4.3,147.12]],"trd":[[4.3,4079.18]],"id":50466254}],"tv":108345.72}],"ArrivalTime":1710508046372}
{"op":"mcm","id":2,"clk":"ALZDAL1dAJFn","pt":1710508046575,"mc":[{"id":"1.226122413","rc":[{"batb":[[0,320,2.84]],"id":54370634},{"tv":14899.84,"trd":[[4.4,4105.69]],"ltp":4.4,"batl":[[0,4.4,36.41]],"id":50466254}],"tv":108350.72}],"ArrivalTime":1710508046583}
{"op":"mcm","id":2,"clk":"AMJDAM5dAKln","pt":1710508046785,"mc":[{"id":"1.226122413","rc":[{"batl":[[0,1.89,54.94]],"id":51922},{"tv":14901.84,"batb":[[0,4.3,146.12]],"trd":[[4.3,4081.18]],"ltp":4.3,"id":50466254}],"tv":108352.72}],"ArrivalTime":1710508046793}
{"op":"mcm","id":2,"clk":"AMZDANZdALRn","pt":1710508046885,"mc":[{"id":"1.226122413","rc":[{"batl":[[0,1.89,62.94]],"id":51922}]}],"ArrivalTime":1710508046893}
{"op":"mcm","id":2,"clk":"AM1DAORdAL5n","pt":1710508046991,"mc":[{"id":"1.226122413","rc":[{"tv":7876.37,"batb":[[0,8.2,19.07]],"trd":[[8.2,759.65]],"id":41122648}],"tv":108354.72}],"ArrivalTime":1710508046999}
{"op":"mcm","id":2,"clk":"ANJDAOldAMZn","pt":1710508047037,"mc":[{"id":"1.226122413","rc":[{"batb":[[0,320,3.15]],"id":54370634},{"tv":7886.37,"batb":[[0,8.2,14.07]],"trd":[[8.2,769.65]],"id":41122648},{"batl":[[0,1.89,70.94]],"id":51922}],"tv":108364.72}],"ArrivalTime":1710508047045}
{"op":"mcm","id":2,"clk":"ANpDAPBdANVn","pt":1710508047146,"mc":[{"id":"1.226122413","rc":[{"tv":77901.81,"batb":[[0,1.88,538.8]],"trd":[[1.88,9511.57]],"ltp":1.88,"id":51922}],"tv":108365.22}],"ArrivalTime":1710508047154}
{"op":"mcm","id":2,"clk":"AN5DAPhdAN5n","pt":1710508047248,"mc":[{"id":"1.226122413","rc":[{"batl":[[2,1000,4.28],[1,650,1.93]],"id":41200638},{"tv":77919.81,"batb":[[0,1.88,540.8]],"trd":[[1.89,4705.49]],"ltp":1.89,"batl":[[0,1.89,69.94]],"id":51922},{"tv":2053.99,"batb":[[0,26,9.78]],"trd":[[26,353.44]],"id":106596}],"tv":108393.22}],"ArrivalTime":1710508047256}
{"op":"mcm","id":2,"clk":"AONDAIJeAOZn","pt":1710508047347,"mc":[{"id":"1.226122413","rc":[{"batl":[[2,650,1.93],[1,410,3.56],[0,400,3.18]],"id":41200638}]}],"ArrivalTime":1710508047355}
{"op":"mcm","id":2,"clk":"AOpDAI9eAO5n","pt":1710508047454,"mc":[{"id":"1.226122413","rc":[{"batl":[[0,1.89,77.94]],"id":51922},{"batb":[[0,26,13.14]],"id":106596}]}],"ArrivalTime":1710508047462}
{"op":"mcm","id":2,"clk":"AO1DAJVeAPln","pt":1710508047550,"mc":[{"id":"1.226122413","rc":[{"batl":[[0,8.4,23.58]],"id":41122648},{"batl":[[0,1.89,93.94]],"id":51922},{"tv":14903.84,"batb":[[0,4.3,163.45]],"trd":[[4.3,4083.18]],"batl":[[2,4.6,176.15]],"id":50466254},{"batb":[[0,26,16.68]],"id":106596}],"tv":108395.22}],"ArrivalTime":1710508047558}
{"op":"mcm","id":2,"clk":"APNDAKBeAINo","pt":1710508047657,"mc":[{"id":"1.226122413","rc":[{"batb":[[2,270,2.73],[1,280,1.12],[0,300,4]],"id":41200638},{"batl":[[2,4.7,79.95],[1,4.6,176.15],[0,4.5,163.74]],"id":50466254}]}],"ArrivalTime":1710508047664}
{"op":"mcm","id":2,"clk":"APlDAKdeAIlo","pt":1710508047755,"mc":[{"id":"1.226122413","rc":[{"batl":[[0,1.89,101.94]],"id":51922},{"batb":[],"batl":[[1,4.6,173.06]],"id":50466254}]}],"ArrivalTime":1710508047763}
{"op":"mcm","id":2,"clk":"AP9DAKxeAJVo","pt":1710508047865,"mc":[{"id":"1.226122413","rc":[{"batl":[[2,8.8,29.49],[0,8.4,32.56]],"id":41122648},{"batb":[[2,280,1.12],[1,290,1.57]],"batl":[[1,410,2.56]],"id":41200638},{"batl":[[2,27,15.59],[1,26,19.48]],"id":55632148},{"tv":77942.17,"batb":[[0,1.88,447.8]],"trd":[[1.88,9531.57],[1.89,4707.85]],"ltp":1.88,"batl":[[0,1.89,100.76]],"id":51922},{"batb":[[2,28,22.02],[1,29,20.78],[0,30,23]],"id":49744721},{"batb":[[2,4.1,144.23]],"id":50466254},{"batb":[[2,24,37.12],[1,25,24.17],[0,26,21.2]],"id":106596}],"tv":108417.58}],"ArrivalTime":1710508047873}
{"op":"mcm","id":2,"clk":"AIdEALpeAKJo","pt":1710508047977,"mc":[{"id":"1.226122413","rc":[{"batl":[[2,410,2.56],[1,400,3.05],[0,390,1.13]],"id":41200638},{"batb":[[0,1.88,449.8]],"batl":[[0,1.89,110.76]],"id":51922}]}],"ArrivalTime":1710508047985}
{"op":"mcm","id":2,"clk":"AI5EAMNeAKto","pt":1710508048079,"mc":[{"id":"1.226122413","rc":[{"batl":[[2,650,1.93]],"id":41200638},{"batl":[[0,32,22.94]],"id":49744721},{"tv":14904.28,"batb":[[0,4.3,163.23]],"trd":[[4.3,4083.62]],"id":50466254},{"batb":[[2,120,5.31]],"id":66251581}],"tv":108418.02}],"ArrivalTime":1710508048087}
{"op":"mcm","id":2,"clk":"AJdEAMxeALBo","pt":1710508048169,"mc":[{"id":"1.226122413","rc":[{"batl":[[2,1.91,245.78],[1,1.9,282.31]],"id":51922}]}],"ArrivalTime":1710508048177}
{"op":"mcm","id":2,"clk":"AJ5EANleALho","pt":1710508048271,"mc":[{"id":"1.226122413","rc":[{"tv":7886.81,"batb":[[0,8.2,13.85]],"trd":[[8.2,770.09]],"id":41122648},{"batl":[[1,4.6,173.35]],"id":50466254}],"tv":108418.46}],"ArrivalTime":1710508048279}
{"op":"mcm","id":2,"clk":"AKREAOReAMJo","pt":1710508048384,"mc":[{"id":"1.226122413","rc":[{"batl":[[2,1.91,261.78]],"id":51922}]}],"ArrivalTime":1710508048392}
{"op":"mcm","id":2,"clk":"ALFEAPBeANho","pt":1710508048601,"mc":[{"id":"1.226122413","rc":[{"tv":78073.01,"batb":[[0,1.88,399.38]],"trd":[[1.88,9632.41],[1.89,4737.85]],"batl":[[2,1.91,277.78],[0,1.89,95.76]],"id":51922},{"batl":[[2,180,3.65]],"id":66251581}],"tv":108549.3}],"ArrivalTime":1710508048609}
{"op":"mcm","id":2,"clk":"ALlEAPdeAOBo","pt":1710508048640,"mc":[{"id":"1.226122413","rc":[{"tv":14906.28,"batb":[[0,4.3,162.23]],"trd":[[4.3,4085.62]],"id":50466254}],"tv":108551.3}],"ArrivalTime":1710508048647}
{"op":"mcm","id":2,"clk":"AMNEAP5eAOxo","pt":1710508048748,"mc":[{"id":"1.226122413","rc":[{"batl":[[0,25,5.3]],"id":55632148},{"batb":[[0,1.88,468.17]],"batl":[[2,1.91,285.78],[0,1.89,163.4]],"id":51922}]}],"ArrivalTime":1710508048756}
{"op":"mcm","id":2,"clk":"AMxEAIxfAPlo","pt":1710508048854,"mc":[{"id":"1.226122413","rc":[{"batl":[[2,1.91,301.78]],"id":51922}]}],"ArrivalTime":1710508048862}
{"op":"mcm","id":2,"clk":"ANREAJdfAP9o","pt":1710508048958,"mc":[{"id":"1.226122413","rc":[{"batb":[[0,1.88,470.17]],"batl":[[2,1.91,305.78]],"id":51922}]}],"ArrivalTime":1710508048966}
{"op":"mcm","id":2,"clk":"AOlEAKdfAJNp","pt":1710508049159,"mc":[{"id":"1.226122413","rc":[{"batl":[[2,1.91,348.48]],"id":51922}]}],"ArrivalTime":1710508049167}
{"op":"mcm","id":2,"clk":"APJEALNfAJ5p","pt":1710508049267,"mc":[{"id":"1.226122413","rc":[{"batb":[],"batl":[[0,8.4,33.7]],"id":41122648}]}],"ArrivalTime":1710508049274}
{"op":"mcm","id":2,"clk":"APlEALdfAKNp","pt":1710508049364,"mc":[{"id":"1.226122413","rc":[{"tv":14908.28,"batb":[[0,4.3,161.23]],"trd":[[4.3,4087.62]],"id":50466254}],"tv":108553.3}],"ArrivalTime":1710508049372}
{"op":"mcm","id":2,"clk":"AP9EAMRfAKpp","pt":1710508049470,"mc":[{"id":"1.226122413","rc":[{"batb":[[0,8.2,15.01]],"id":41122648},{"tv":78075.07,"trd":[[1.89,4739.91]],"ltp":1.89,"batl":[[0,1.89,162.37]],"id":51922}],"tv":108555.36}],"ArrivalTime":1710508049477}
{"op":"mcm","id":2,"clk":"AIVFAMdfALFp","pt":1710508049569,"mc":[{"id":"1.226122413","rc":[{"batb":[],"batl":[[0,8.4,25.46]],"id":41122648},{"tv":78175.07,"batb":[[0,1.88,420.17]],"trd":[[1.88,9732.41]],"ltp":1.88,"id":51922}],"tv":108655.36}],"ArrivalTime":1710508049576}
{"op":"mcm","id":2,"clk":"AJFFANxfALxp","pt":1710508049686,"mc":[{"id":"1.226122413","rc":[{"batl":[[0,1.89,94.73]],"id":51922},{"batb":[[2,120,6.41]],"id":66251581}]}],"ArrivalTime":1710508049694}
{"op":"mcm","id":2,"clk":"AJlFAORfAMdp","pt":1710508049783,"mc":[{"id":"1.226122413","rc":[{"tv":78178.07,"batb":[[0,1.88,418.67]],"trd":[[1.88,9735.41]],"batl":[[1,1.9,287.31]],"id":51922},{"tv":14919.14,"batb":[[0,4.3,155.8]],"trd":[[4.3,4098.48]],"id":50466254}],"tv":108669.22}],"ArrivalTime":1710508049791}
{"op":"mcm","id":2,"clk":"AJ9FAO9fAM9p","pt":1710508049889,"mc":[{"id":"1.226122413","rc":[{"tv":7892.77,"batb":[[0,8.2,12.03]],"trd":[[8.2,776.05]],"id":41122648},{"batb":[[1,1.87,299.84]],"batl":[[0,1.89,164.84]],"id":51922},{"batl":[[0,32,23.94]],"id":49744721},{"tv":2055.99,"batb":[[0,26,20.2]],"trd":[[26,355.44]],"id":106596}],"tv":108677.18}],"ArrivalTime":1710508049896}
{"op":"mcm","id":2,"clk":"AKVFAPhfANdp","pt":1710508049993,"mc":[{"id":"1.226122413","rc":[{"tv":78198.13,"batb":[[1,1.87,241.88],[0,1.88,409.67]],"trd":[[1.88,9753.41],[1.89,4741.97]],"ltp":1.89,"batl":[[0,1.89,163.81]],"id":51922},{"batl":[[2,4.6,173.35],[1,4.5,163.74],[0,4.4,5]],"id":50466254}],"tv":108697.24}],"ArrivalTime":1710508050001}
{"op":"mcm","id":2,"clk":"AKxFAP5fAN9p","pt":1710508050046,"mc":[{"id":"1.226122413","rc":[{"batl":[[0,4.4,7.1]],"id":50466254}]}],"ArrivalTime":1710508050054}
{"op":"mcm","id":2,"clk":"ALRFAI5gAOxp","pt":1710508050157,"mc":[{"id":"1.226122413","rc":[{"batb":[[1,8,77.96]],"id":41122648},{"batl":[[2,27,10.82],[1,26,12.95]],"id":55632148},{"batb":[[2,1.86,243.81],[0,1.88,411.67]],"id":51922},{"batl":[[2,36,9.74],[1,34,5.3]],"id":49744721},{"tv":14921.14,"batb":[[0,4.3,136.47]],"trd":[[4.3,4100.48]],"batl":[[2,4.6,176.44],[1,4.5,144.35]],"id":50466254},{"batb":[[2,24,29.62],[1,25,17.42],[0,26,13.6]],"id":106596}],"tv":108699.24}],"ArrivalTime":1710508050165}
{"op":"mcm","id":2,"clk":"ALtFAJtgAPVp","pt":1710508050252,"mc":[{"id":"1.226122413","rc":[{"tv":7897.77,"trd":[[8.4,1057.69]],"ltp":8.4,"batl":[[0,8.4,22.96]],"id":41122648},{"tv":79052.07,"trd":[[1.9,4510.17],[1.89,5069.61]],"ltp":1.9,"batl":[[2,1.92,298.73],[1,1.91,348.48],[0,1.9,24.17]],"id":51922}],"tv":109558.18}],"ArrivalTime":1710508050260}
{"op":"mcm","id":2,"clk":"AMFFAKZgAIBq","pt":1710508050377,"mc":[{"id":"1.226122413","rc":[{"batb":[[2,1.87,241.88],[1,1.88,411.67],[0,1.89,18.21]],"id":51922},{"batl":[[0,4.4,68.29]],"id":50466254}]}],"ArrivalTime":1710508050385}
{"op":"mcm","id":2,"clk":"AMpFAKxgAIhq","pt":1710508050478,"mc":[{"id":"1.226122413","rc":[{"batb":[[0,1.89,89.55]],"id":51922},{"batb":[[2,120,5.31]],"id":66251581}]}],"ArrivalTime":1710508050487}
{"op":"mcm","id":2,"clk":"ANBFALpgAJVq","pt":1710508050588,"mc":[{"id":"1.226122413","rc":[{"batb":[[1,1.88,498.67],[0,1.89,122.78]],"batl":[[1,1.91,419.08],[0,1.9,11]],"id":51922},{"batb":[[0,4.3,144.83]],"batl":[[1,4.5,147.6]],"id":50466254}]}],"ArrivalTime":1710508050597}
{"op":"mcm","id":2,"clk":"ANdFAL5gAJlq","pt":1710508050696,"mc":[{"id":"1.226122413","rc":[{"tv":79056.07,"trd":[[1.9,4514.17]],"batl":[[0,1.9,9]],"id":51922},{"batb":[[2,28,28.02]],"id":49744721}],"tv":109562.18}],"ArrivalTime":1710508050703}
{"op":"mcm","id":2,"clk":"ANtFAMZgAKRq","pt":1710508050741,"mc":[{"id":"1.226122413","rc":[{"batl":[[0,390,1]],"id":41200638},{"batl":[[0,1.9,79.81]],"id":51922}]}],"ArrivalTime":1710508050748}
{"op":"mcm","id":2,"clk":"AOJFANNgAK1q","pt":1710508050848,"mc":[{"id":"1.226122413","rc":[{"batb":[[1,1.88,499.7]],"batl":[[1,1.91,434.08]],"id":51922}]}],"ArrivalTime":1710508050856}
{"op":"mcm","id":2,"clk":"AO1FANpgALZq","pt":1710508050958,"mc":[{"id":"1.226122413","rc":[{"batl":[[2,430,2.24],[1,420,1.15],[0,410,3.14]],"id":54370634},{"tv":14923.14,"batb":[[0,4.3,143.83]],"trd":[[4.3,4102.48]],"id":50466254}],"tv":109564.18}],"ArrivalTime":1710508050966}
{"op":"mcm","id":2,"clk":"APNFAOJgALpq","pt":1710508051056,"mc":[{"id":"1.226122413","rc":[{"batb":[[2,1.87,196.64]],"id":51922},{"batb":[[0,4.3,153.23]],"id":50466254}]}],"ArrivalTime":1710508051063}
{"op":"mcm","id":2,"clk":"AIdGAPtgANRq","pt":1710508051263,"mc":[{"id":"1.226122413","rc":[{"batl":[[2,400,3.05],[1,390,1],[0,380,1.71]],"id":41200638},{"batb":[[0,1.89,167.54]],"id":51922},{"tv":15011.25,"batb":[[0,4.3,109.17]],"trd":[[4.3,4190.59]],"id":50466254}],"tv":109652.29}],"ArrivalTime":1710508051271}
{"op":"mcm","id":2,"clk":"AJJGAIRhAN1q","pt":1710508051365,"mc":[{"id":"1.226122413","rc":[{"tv":7919.77,"trd":[[8.4,1079.69]],"batl":[[0,8.4,11.96]],"id":41122648},{"tv":79056.57,"batb":[[1,1.88,500.73],[0,1.89,167.29]],"trd":[[1.89,5070.11]],"ltp":1.89,"batl":[[0,1.9,9]],"id":51922},{"tv":2061.15,"batb":[[0,26,11.02]],"trd":[[26,360.6]],"id":106596}],"tv":109679.95}],"ArrivalTime":1710508051373}
{"op":"mcm","id":2,"clk":"AJ1GAIlhAOdq","pt":1710508051482,"mc":[{"id":"1.226122413","rc":[{"batb":[[0,8.2,20.25]],"batl":[[0,8.4,21.99]],"id":41122648},{"batb":[[1,1.88,501.76]],"batl":[[0,1.9,79.42]],"id":51922},{"tv":15011.47,"batb":[[0,4.3,109.06]],"trd":[[4.3,4190.81]],"id":50466254},{"batb":[[2,120,6.41]],"id":66251581}],"tv":109680.17}],"ArrivalTime":1710508051490}
{"op":"mcm","id":2,"clk":"AKVGAJRhAPBq","pt":1710508051581,"mc":[{"id":"1.226122413","rc":[{"batb":[[0,26,14.02]],"id":106596}]}],"ArrivalTime":1710508051589}
{"op":"mcm","id":2,"clk":"ALRGAKlhAIZr","pt":1710508051783,"mc":[{"id":"1.226122413","rc":[{"batb":[[0,8.2,34.13]],"id":41122648},{"tv":79176.57,"batb":[[1,1.88,503.76]],"trd":[[1.9,4634.17]],"ltp":1.9,"batl":[[0,1.9,19.42]],"id":51922},{"tv":15013.47,"batb":[[0,4.3,108.06]],"trd":[[4.3,4192.81]],"id":50466254}],"tv":109802.17}],"ArrivalTime":1710508051791}
{"op":"mcm","id":2,"clk":"AL1GALRhAI9r","pt":1710508051890,"mc":[{"id":"1.226122413","rc":[{"batl":[[2,650,1.93],[1,400,3.05]],"id":41200638},{"batb":[[1,1.88,505.76],[0,1.89,192.74]],"id":51922}]}],"ArrivalTime":1710508051898}
{"op":"mcm","id":2,"clk":"AMRGALxhAJtr","pt":1710508052001,"mc":[{"id":"1.226122413","rc":[{"batl":[[0,8.4,23.99]],"id":41122648},{"batl":[[2,400,3.05],[1,380,1.71],[0,370,1]],"id":41200638},{"tv":79213.39,"batb":[[2,1.87,199.22],[0,1.89,175.36]],"trd":[[1.9,4636.23],[1.89,5104.87]],"ltp":1.89,"batl":[[0,1.9,18.39]],"id":51922}],"tv":109838.99}],"ArrivalTime":1710508052008}
{"op":"mcm","id":2,"clk":"AM1GAMRhAKVr","pt":1710508052052,"mc":[{"id":"1.226122413","rc":[{"tv":79215.45,"trd":[[1.9,4638.29]],"ltp":1.9,"batl":[[0,1.9,17.36]],"id":51922}],"tv":109841.05}],"ArrivalTime":1710508052060}
{"op":"mcm","id":2,"clk":"ANNGAM1hAK9r","pt":1710508052151,"mc":[{"id":"1.226122413","rc":[{"tv":364.84,"batb":[[0,320,1.57]],"trd":[[330,42.74],[320,29.36]],"ltp":320,"id":54370634}],"tv":109844.21}],"ArrivalTime":1710508052159}
{"op":"mcm","id":2,"clk":"AORGAN1hAL5r","pt":1710508052357,"mc":[{"id":"1.226122413","rc":[{"tv":79237.51,"batb":[[0,1.89,164.78]],"trd":[[1.9,4640.35],[1.89,5124.87]],"ltp":1.89,"batl":[[0,1.9,16.33]],"id":51922}],"tv":109866.27}],"ArrivalTime":1710508052365}
{"op":"mcm","id":2,"clk":"AOtGAOlhAMhr","pt":1710508052475,"mc":[{"id":"1.226122413","rc":[{"tv":79239.57,"trd":[[1.9,4642.41]],"ltp":1.9,"batl":[[0,1.9,15.3]],"id":51922}],"tv":109868.33}],"ArrivalTime":1710508052483}
{"op":"mcm","id":2,"clk":"APJGAPNhANJr","pt":1710508052563,"mc":[{"id":"1.226122413","rc":[{"tv":15115.47,"batb":[[0,4.3,107.06]],"trd":[[4.4,4205.69],[4.3,4194.81]],"ltp":4.4,"batl":[[0,4.4,18.29]],"id":50466254}],"tv":109970.33}],"ArrivalTime":1710508052571}
{"op":"mcm","id":2,"clk":"APtGAPlhANpr","pt":1710508052668,"mc":[{"id":"1.226122413","rc":[{"tv":445.65,"batb":[[0,300,2.29]],"trd":[[300,35.24]],"ltp":300,"id":41200638},{"tv":79241.63,"trd":[[1.9,4644.47]],"batl":[[0,1.9,14.27]],"id":51922},{"batl":[[0,4.4,20.64]],"id":50466254}],"tv":109975.81}],"ArrivalTime":1710508052676}
{"op":"mcm","id":2,"clk":"AIFHAP9hAN5r","pt":1710508052770,"mc":[{"id":"1.226122413","rc":[{"tv":79243.69,"trd":[[1.9,4646.53]],"batl":[[0,1.9,13.24]],"id":51922}],"tv":109977.87}],"ArrivalTime":1710508052778}
{"op":"mcm","id":2,"clk":"AIlHAIRiAOdr","pt":1710508052871,"mc":[{"id":"1.226122413","rc":[{"tv":449.07,"batb":[[2,270,2.73],[1,280,1.12],[0,290,2.15]],"trd":[[300,38.66]],"id":41200638},{"tv":79244.83,"trd":[[1.9,4647.67]],"batl":[[0,1.9,12.67]],"id":51922},{"batl":[[0,160,2.53]],"id":66251581}],"tv":109982.43}],"ArrivalTime":1710508052879}
{"op":"mcm","id":2,"clk":"AJFHAJFiAPJr","pt":1710508052981,"mc":[{"id":"1.226122413","rc":[{"tv":79246.89,"trd":[[1.9,4649.73]],"batl":[[0,1.9,11.64]],"id":51922}],"tv":109984.49}],"ArrivalTime":1710508052989}
{"op":"mcm","id":2,"clk":"AJpHAJpiAIBs","pt":1710508053077,"mc":[{"id":"1.226122413","rc":[{"batl":[[0,4.4,30.64]],"id":50466254}]}],"ArrivalTime":1710508053085}
{"op":"mcm","id":2,"clk":"AKVHAKViAIxs","pt":1710508053192,"mc":[{"id":"1.226122413","rc":[{"tv":7940.57,"batb":[[0,8.2,23.73]],"trd":[[8.2,796.85]],"ltp":8.2,"id":41122648},{"batb":[[0,1.89,204.78]],"id":51922}],"tv":110005.29}],"ArrivalTime":1710508053200}
{"op":"mcm","id":2,"clk":"AK5HALBiAJZs","pt":1710508053296,"mc":[{"id":"1.226122413","rc":[{"tv":79250.95,"batb":[[0,1.89,203.78]],"trd":[[1.9,4651.79],[1.89,5126.87]],"batl":[[0,1.9,10.61]],"id":51922},{"tv":2461.78,"batb":[[0,30,21.75]],"trd":[[30,113.06]],"id":49744721}],"tv":110011.85}],"ArrivalTime":1710508053304}
{"op":"mcm","id":2,"clk":"ALhHALpiAKBs","pt":1710508053402,"mc":[{"id":"1.226122413","rc":[{"batb":[[0,8.2,15.51]],"batl":[[0,8.4,32.22]],"id":41122648}]}],"ArrivalTime":1710508053410}
{"op":"mcm","id":2,"clk":"AL9HAMBiAKVs","pt":1710508053500,"mc":[{"id":"1.226122413","rc":[{"batl":[[2,420,1.15],[1,410,3.14],[0,400,1]],"id":54370634},{"batb":[[0,30,24.01]],"id":49744721}]}],"ArrivalTime":1710508053508}
{"op":"mcm","id":2,"clk":"AMZHAMpiALBs","pt":1710508053587,"mc":[{"id":"1.226122413","rc":[{"tv":15117.47,"batb":[[0,4.3,106.06]],"trd":[[4.3,4196.81]],"ltp":4.3,"id":50466254}],"tv":110013.85}],"ArrivalTime":1710508053595}
{"op":"mcm","id":2,"clk":"AMtHANJiALVs","pt":1710508053655,"mc":[{"id":"1.226122413","rc":[{"batl":[[2,380,1.71],[1,370,1],[0,360,1.71]],"id":41200638},{"tv":79253.01,"trd":[[1.9,4653.85]],"batl":[[0,1.9,9.58]],"id":51922}],"tv":110015.91}],"ArrivalTime":1710508053663}
{"op":"mcm","id":2,"clk":"ANJHAN1iAMJs","pt":1710508053768,"mc":[{"id":"1.226122413","rc":[{"tv":79255.07,"trd":[[1.9,4655.91]],"batl":[[0,1.9,8.55]],"id":51922}],"tv":110017.97}],"ArrivalTime":1710508053776}
{"op":"mcm","id":2,"clk":"ANxHAORiAM1s","pt":1710508053863,"mc":[{"id":"1.226122413","rc":[{"batb":[[1,280,1.78]],"batl":[],"id":41200638}]}],"ArrivalTime":1710508053870}
{"op":"mcm","id":2,"clk":"AOZHAOxiANds","pt":1710508053972,"mc":[{"id":"1.226122413","rc":[{"batl":[[2,400,3.05],[1,380,1.71]],"id":41200638}]}],"ArrivalTime":1710508053980}
{"op":"mcm","id":2,"clk":"AO5HAP1iAORs","pt":1710508054070,"mc":[{"id":"1.226122413","rc":[{"batl":[[2,380,1.71],[1,360,1.71],[0,350,2.71]],"id":41200638},{"tv":79274.45,"batb":[[2,1.88,505.76],[1,1.89,203.78],[0,1.9,10.31]],"trd":[[1.9,4675.29]],"batl":[[2,1.93,278.27],[1,1.92,298.73],[0,1.91,434.08]],"id":51922}],"tv":110037.35}],"ArrivalTime":1710508054078}
{"op":"mcm","id":2,"clk":"APpHAINjAO5s","pt":1710508054171,"mc":[{"id":"1.226122413","rc":[{"tv":79295.07,"batb":[[2,1.87,199.22],[1,1.88,505.76],[0,1.89,203.78]],"trd":[[1.9,4695.91]],"batl":[[2,1.92,298.73],[1,1.91,434.08],[0,1.9,70.31]],"id":51922}],"tv":110057.97}],"ArrivalTime":1710508054179}
{"op":"mcm","id":2,"clk":"AP9HAI9jAPVs","pt":1710508054283,"mc":[{"id":"1.226122413","rc":[{"batb":[[2,1.87,157.22],[0,1.89,291.81]],"batl":[],"id":51922}]}],"ArrivalTime":1710508054291}
{"op":"mcm","id":2,"clk":"AIJIAJRjAP9s","pt":1710508054383,"mc":[{"id":"1.226122413","rc":[{"batb":[[1,1.88,507.76]],"id":51922},{"batb":[[2,120,5.31]],"id":66251581}]}],"ArrivalTime":1710508054391}
{"op":"mcm","id":2,"clk":"AIpIAJtjAIdt","pt":1710508054482,"mc":[{"id":"1.226122413","rc":[{"batl":[[0,350,1.71]],"id":41200638}]}],"ArrivalTime":1710508054490}
{"op":"mcm","id":2,"clk":"AJJIAKZjAI9t","pt":1710508054592,"mc":[{"id":"1.226122413","rc":[{"batb":[[1,1.88,475.97],[0,1.89,292.84]],"id":51922}]}],"ArrivalTime":1710508054600}
{"op":"mcm","id":2,"clk":"AJtIAK5jAJlt","pt":1710508054700,"mc":[{"id":"1.226122413","rc":[{"batl":[[2,360,1.71],[1,350,1.71],[0,340,1.71]],"id":41200638},{"batb":[[2,1.87,181.22],[0,1.89,206.87]],"id":51922}]}],"ArrivalTime":1710508054708}
{"op":"mcm","id":2,"clk":"AKVIALdjAKZt","pt":1710508054805,"mc":[{"id":"1.226122413","rc":[{"batb":[[2,260,3.94],[1,270,2.12],[0,300,2]],"batl":[[2,420,1.49]],"id":54370634},{"tv":15117.51,"trd":[[4.4,4205.73]],"ltp":4.4,"batl":[[0,4.4,30.62]],"id":50466254}],"tv":110058.01}],"ArrivalTime":1710508054813}
{"op":"mcm","id":2,"clk":"AKtIAL1jALFt","pt":1710508054851,"mc":[{"id":"1.226122413","rc":[{"tv":449.11,"batb":[[0,290,2.13]],"trd":[[300,38.7]],"id":41200638}],"tv":110058.05}],"ArrivalTime":1710508054859}
{"op":"mcm","id":2,"clk":"ALJIAMdjALtt","pt":1710508054952,"mc":[{"id":"1.226122413","rc":[{"batl":[[0,1.9,75.31]],"id":51922}]}],"ArrivalTime":1710508054960}
{"op":"mcm","id":2,"clk":"ALdIANJjAMlt","pt":1710508055111,"mc":[{"id":"1.226122413","rc":[{"tv":449.21,"batb":[[0,290,2.08]],"trd":[[300,38.8]],"id":41200638},{"batl":[[1,4.5,137.6]],"id":50466254}],"tv":110058.15}],"ArrivalTime":1710508055119}
{"op":"mcm","id":2,"clk":"AMFIANZjANZt","pt":1710508055157,"mc":[{"id":"1.226122413","rc":[{"batl":[[0,4.4,40.62]],"id":50466254}]}],"ArrivalTime":1710508055165}
{"op":"mcm","id":2,"clk":"AOFIAPxjAIRu","pt":1710508055575,"mc":[{"id":"1.226122413","rc":[{"tv":79427.87,"batb":[[0,1.89,140.47]],"trd":[[1.89,5259.67]],"ltp":1.89,"id":51922}],"tv":110190.95}],"ArrivalTime":1710508055583}
{"op":"mcm","id":2,"clk":"AO5IAI1kAJtu","pt":1710508055749,"mc":[{"id":"1.226122413","rc":[{"tv":374.56,"trd":[[420,1.44],[410,9.06],[400,28.12]],"ltp":420,"batl":[[2,890,1.2],[1,580,3.55],[0,430,3.01]],"id":54370634},{"tv":1938.69,"trd":[[28,289.03],[27,240.31],[26,336.26],[25,394.46]],"ltp":28,"batl":[[2,30,13.83],[1,29,13.83],[0,28,7.39]],"id":55632148},{"tv":81029.41,"batb":[[2,1.85,516.22],[1,1.86,240.69],[0,1.88,28]],"trd":[[1.87,8192.18],[1.86,8134.48],[1.88,10705.35],[1.89,5540.6]],"ltp":1.86,"id":51922},{"tv":2576.74,"trd":[[40,12.2],[38,54.58],[36,125.37],[34,232.73],[32,192.4]],"ltp":40,"batl":[[2,44,8.41],[1,42,8.06],[0,40,6.09]],"id":49744721},{"tv":15662.01,"trd":[[4.4,4286.97],[4.6,1326.27],[4.5,3173.9]],"ltp":4.6,"batl":[[2,4.8,166.59],[1,4.7,79.95],[0,4.6,82.41]],"id":50466254},{"tv":536.84,"batb":[[2,120,6.41]],"trd":[[200,8.14],[190,0.56],[180,7.33],[170,31.95],[160,22.16],[150,50.6]],"ltp":200,"batl":[[2,250,2.25],[1,240,3.71],[0,210,5.23]],"id":66251581},{"tv":2104.03,"batb":[[2,23,18.47],[1,24,29.62],[0,25,10]],"trd":[[26,388.64],[25,283.16]],"ltp":25,"id":106596}],"tv":112612.06}],"ArrivalTime":1710508055756}
{"op":"mcm","id":2,"clk":"APFIAJBkAJ9u","pt":1710508055791,"mc":[{"id":"1.226122413","rc":[{"batb":[[0,8.2,25.56]],"id":41122648},{"tv":81031.47,"trd":[[1.9,4697.97]],"ltp":1.9,"batl":[[0,1.9,74.28]],"id":51922}],"tv":112614.12}],"ArrivalTime":1710508055799}
{"op":"mcm","id":2,"clk":"APpIAKBkAKlu","pt":1710508055904,"mc":[{"id":"1.226122413","rc":[{"tv":7971.59,"batb":[[2,7.6,86.33],[1,7.8,67.59],[0,8,77.96]],"trd":[[8.2,827.87]],"id":41122648},{"batb":[[2,260,2.78],[1,270,1.16],[0,280,2.29]],"id":41200638},{"batb":[[0,24,9.21]],"batl":[],"id":55632148},{"tv":81091.47,"batb":[[2,1.84,89.43],[1,1.85,565.22],[0,1.86,179.69]],"trd":[[1.88,10765.35]],"ltp":1.88,"batl":[[2,1.91,434.08],[1,1.9,113.93],[0,1.89,71.32]],"id":51922},{"batb":[[2,29,20.78],[1,30,24.01],[0,32,3.71]],"batl":[[2,42,8.06],[1,40,6.09],[0,38,2.7]],"id":49744721},{"batb":[],"batl":[[2,4.8,163.79],[1,4.7,77.01],[0,4.6,79.32]],"id":50466254},{"batb":[[0,25,8.73]],"batl":[[0,28,7.21]],"id":106596}],"tv":112705.14}],"ArrivalTime":1710508055912}
{"op":"mcm","id":2,"clk":"AIFJAKVkALJu","pt":1710508056006,"mc":[{"id":"1.226122413","rc":[{"batb":[[2,270,2.12],[1,300,1.52],[0,310,1.58]],"id":54370634},{"batl":[[2,8.6,32.95],[1,8.4,32.22],[0,8.2,2]],"id":41122648},{"batb":[[2,23,13.81],[1,24,8.51],[0,25,6.29]],"batl":[[2,29,13.83],[1,28,7.39],[0,27,2.32]],"id":55632148},{"batl":[[2,1.9,113.93],[1,1.89,103.41],[0,1.87,100.27]],"id":51922},{"batb":[[1,30,32.01],[0,32,7.58]],"batl":[[1,40,10.31],[0,38,8.3]],"id":49744721},{"batb":[[2,4.2,231.03],[1,4.3,106.06],[0,4.4,45.07]],"batl":[[2,4.7,77.01],[1,4.6,151.72],[0,4.5,29.94]],"id":50466254}]}],"ArrivalTime":1710508056014}
{"op":"mcm","id":2,"clk":"AIVJALdkAL9u","pt":1710508056114,"mc":[{"id":"1.226122413","rc":[{"batb":[[2,270,1.85]],"id":54370634},{"batb":[],"batl":[[1,8.4,23.99],[0,8.2,12.92]],"id":41122648},{"batb":[[1,270,2.74]],"id":41200638},{"tv":81113.47,"trd":[[1.87,8214.18]],"ltp":1.87,"batl":[[2,1.89,141.04],[1,1.88,32.26],[0,1.87,89.27]],"id":51922},{"batb":[[0,32,11.16]],"batl":[[2,40,10.31],[1,38,8.3],[0,36,5.9]],"id":49744721},{"batb":[[0,25,15.48]],"batl":[[2,29,6.02],[1,28,7.21],[0,27,6.13]],"id":106596}],"tv":112727.14}],"ArrivalTime":1710508056122}
{"op":"mcm","id":2,"clk":"AI5JAMNkAMlu","pt":1710508056168,"mc":[{"id":"1.226122413","rc":[{"tv":7993.16,"batb":[[2,7.6,88.37],[1,7.8,69.53]],"trd":[[8.2,849.44]],"batl":[[0,8.2,2.13]],"id":41122648},{"batb":[[2,24,8.51],[1,25,9.29],[0,26,2.96]],"id":55632148},{"tv":81139.67,"batb":[[0,1.86,120.19]],"trd":[[1.87,8240.38]],"batl":[[1,1.88,103.77],[0,1.87,76.17]],"id":51922},{"tv":15721.89,"batb":[[2,4.3,106.06],[1,4.4,75.75],[0,4.5,44.04]],"trd":[[4.5,3233.78]],"ltp":4.5,"batl":[[2,4.8,163.79],[1,4.7,77.01],[0,4.6,151.72]],"id":50466254}],"tv":112834.79}],"ArrivalTime":1710508056176}
{"op":"mcm","id":2,"clk":"AJRJAMdkANJu","pt":1710508056267,"mc":[{"id":"1.226122413","rc":[{"tv":1943.23,"batb":[[2,23,13.81],[1,24,13.59],[0,25,9.98]],"trd":[[26,340.8]],"ltp":26,"batl":[],"id":55632148},{"tv":81179.77,"batb":[[0,1.86,85.51]],"trd":[[1.87,8280.48]],"batl":[[0,1.87,56.12]],"id":51922},{"batl":[[0,36,9.22]],"id":49744721},{"tv":15731.89,"batb":[[2,4.3,108.64],[1,4.4,92.75],[0,4.5,39.04]],"trd":[[4.5,3243.78]],"batl":[],"id":50466254},{"batl":[[2,28,7.21],[1,27,6.13],[0,26,2.9]],"id":106596}],"tv":112889.43}],"ArrivalTime":1710508056275}
{"op":"mcm","id":2,"clk":"AJpJANJkAN5u","pt":1710508056380,"mc":[{"id":"1.226122413","rc":[{"batb":[[1,7.8,67.59]],"batl":[[1,8.4,21.99]],"id":41122648},{"tv":1947.87,"batb":[[2,24,13.59],[1,25,9.98],[0,27,2.84]],"trd":[[27,244.95]],"ltp":27,"batl":[[2,30,13.83],[1,29,13.83],[0,28,7.39]],"id":55632148},{"tv":81350.79,"batb":[[2,1.83,154.15],[1,1.84,89.43],[0,1.85,565.22]],"trd":[[1.86,8305.5]],"ltp":1.86,"batl":[[2,1.88,103.77],[1,1.87,56.12],[0,1.86,111.99]],"id":51922},{"batl":[[2,40,8.31]],"id":49744721},{"tv":15763.77,"batb":[[0,4.5,23.1]],"trd":[[4.5,3275.66]],"batl":[[0,4.6,108.61]],"id":50466254},{"tv":2113.94,"batb":[[0,25,10.53]],"trd":[[25,293.07]],"id":106596}],"tv":113106.88}],"ArrivalTime":1710508056388}
{"op":"mcm","id":2,"clk":"AKBJANtkAOZu","pt":1710508056481,"mc":[{"id":"1.226122413","rc":[{"tv":7997.43,"batb":[[2,7.6,74.3]],"trd":[[8.2,853.71]],"batl":[[2,8.8,29.49],[1,8.6,42.95],[0,8.4,21.99]],"id":41122648},{"batl":[[2,350,1.71],[1,340,1.71],[0,330,1.71]],"id":41200638},{"tv":1953.55,"batb":[[2,23,13.81],[1,24,13.59],[0,25,9.98]],"trd":[[27,250.63]],"id":55632148},{"batl":[[0,36,11.22]],"id":49744721},{"batl":[[2,240,3.71],[1,210,5.39],[0,200,2.79]],"id":66251581},{"batb":[[2,23,13.47]],"id":106596}],"tv":113116.83}],"ArrivalTime":1710508056489}
{"op":"mcm","id":2,"clk":"AKZJAOFkAO9u","pt":1710508056580,"mc":[{"id":"1.226122413","rc":[{"batb":[[2,270,3.34]],"batl":[[2,580,3.55],[1,430,2.24],[0,420,3.33]],"id":54370634},{"batl":[[2,30,14.43],[1,29,14.47]],"id":55632148},{"tv":81390.89,"trd":[[1.86,8345.6]],"batl":[[0,1.86,91.94]],"id":51922},{"tv":15767.39,"batb":[[0,4.5,21.29]],"trd":[[4.5,3279.28]],"batl":[[0,4.6,151.54]],"id":50466254},{"batl":[[0,200,3.79]],"id":66251581},{"batb":[[1,24,25.17]],"id":106596}],"tv":113160.55}],"ArrivalTime":1710508056588}
{"op":"mcm","id":2,"clk":"AKlJAO5kAPhu","pt":1710508056683,"mc":[{"id":"1.226122413","rc":[{"batb":[[2,7.6,72.26]],"id":41122648},{"batl":[[0,28,5.95]],"id":55632148},{"tv":81425.75,"batb":[[1,1.84,153.43],[0,1.85,476.22]],"trd":[[1.86,8380.46]],"batl":[[1,1.87,88.54],[0,1.86,74.51]],"id":51922},{"tv":15777.39,"batb":[[0,4.5,16.29]],"trd":[[4.5,3289.28]],"id":50466254},{"tv":2125.97,"batb":[[0,25,4.51]],"trd":[[25,305.1]],"id":106596}],"tv":113217.44}],"ArrivalTime":1710508056691}
{"op":"mcm","id":2,"clk":"ALRJAPVkAIRv","pt":1710508056794,"mc":[{"id":"1.226122413","rc":[{"batb":[[0,310,2.01]],"id":54370634},{"batl":[[2,30,13.83],[1,29,13.83]],"id":55632148},{"tv":81441.39,"trd":[[1.86,8396.1]],"batl":[[0,1.86,66.69]],"id":51922},{"tv":2578.64,"trd":[[36,127.27]],"ltp":36,"batl":[[0,36,10.27]],"id":49744721},{"tv":15784.09,"batb":[[0,4.5,12.94]],"trd":[[4.5,3295.98]],"id":50466254},{"batb":[[0,140,4.76]],"id":66251581}],"tv":113241.68}],"ArrivalTime":1710508056801}
{"op":"mcm","id":2,"clk":"ALhJAPhkAJJv","pt":1710508056893,"mc":[{"id":"1.226122413","rc":[{"tv":2134.99,"batb":[[2,22,22.64],[1,23,13.47],[0,24,25.17]],"trd":[[25,314.12]],"batl":[[2,27,6.13],[1,26,2.9],[0,25,5.96]],"id":106596}],"tv":113250.7}],"ArrivalTime":1710508056901}
{"op":"mcm","id":2,"clk":"ALtJAIJlAJ9v","pt":1710508056996,"mc":[{"id":"1.226122413","rc":[{"batl":[[0,8.4,23.99]],"id":41122648},{"tv":1956.55,"batb":[[0,25,8.48]],"trd":[[26,342.18],[25,396.08]],"ltp":25,"id":55632148},{"batl":[[2,1.89,141.04],[1,1.88,103.77],[0,1.87,88.54]],"id":51922},{"batl":[[0,36,11.04]],"id":49744721},{"batl":[[0,200,4.21]],"id":66251581},{"batb":[[0,24,20.71]],"id":106596}],"tv":113253.7}],"ArrivalTime":1710508057004}
{"op":"mcm","id":2,"clk":"AMhJAI5lAKlv","pt":1710508057101,"mc":[{"id":"1.226122413","rc":[{"batb":[[1,7.8,45.53]],"id":41122648},{"batb":[[1,24,16.98]],"id":55632148},{"batb":[[2,4.2,234.85],[1,4.3,108.64],[0,4.4,92.75]],"batl":[],"id":50466254},{"batl":[[1,210,5]],"id":66251581},{"batb":[[2,22,23.77],[0,24,19.71]],"batl":[[0,25,3.04]],"id":106596}]}],"ArrivalTime":1710508057109}
{"op":"mcm","id":2,"clk":"AMxJAJllALJv","pt":1710508057156,"mc":[{"id":"1.226122413","rc":[{"batb":[[2,270,1.85]],"id":54370634},{"batb":[],"batl":[[0,8.4,26.99]],"id":41122648},{"batl":[[2,340,1.71],[1,330,1.71],[0,320,1.71]],"id":41200638},{"batb":[[2,24,16.98],[1,25,8.48],[0,26,5.45]],"id":55632148},{"batb":[[2,1.84,153.43],[1,1.85,476.22],[0,1.86,71.62]],"id":51922},{"batb":[[2,4.2,231.03]],"id":50466254},{"batl":[[0,200,2.79]],"id":66251581}]}],"ArrivalTime":1710508057163}
{"op":"mcm","id":2,"clk":"ANBJAJ9lALpv","pt":1710508057255,"mc":[{"id":"1.226122413","rc":[{"batb":[[2,300,1.52],[1,310,1.58],[0,320,4.04]],"id":54370634},{"batb":[[0,280,1.17]],"id":41200638},{"batb":[[1,1.85,539.22],[0,1.86,104.09]],"batl":[[0,1.87,56.12]],"id":51922},{"batl":[[2,28,7.21],[1,27,6.13],[0,26,2.9]],"id":106596}]}],"ArrivalTime":1710508057263}
{"op":"mcm","id":2,"clk":"AOlJALVlAN1v","pt":1710508057583,"mc":[{"id":"1.226122413","rc":[{"batl":[[2,890,1.2],[1,580,3.55],[0,430,3.01]],"id":54370634},{"tv":8007.43,"trd":[[8.4,1089.69]],"ltp":8.4,"batl":[[0,8.4,23.19]],"id":41122648},{"tv":449.57,"batb":[[2,250,11.4],[1,260,2.78],[0,270,3.73]],"trd":[[300,39.16]],"batl":[[2,330,1.71],[1,320,1.71],[0,310,1.71]],"id":41200638},{"batl":[[1,29,8.87]],"id":55632148},{"tv":81487.29,"batb":[[0,1.86,81.14]],"trd":[[1.86,8442]],"batl":[[2,1.9,145.84],[1,1.89,141.04],[0,1.88,103.77]],"id":51922},{"batl":[[0,4.6,82.63]],"id":50466254},{"batb":[[2,22,22.64]],"batl":[[2,28,9.75]],"id":106596}],"tv":113309.96,"con":true}],"ArrivalTime":1710508057591}
{"op":"mcm","id":2,"clk":"AIdKAOBlAN5v","pt":1710508058172,"mc":[{"id":"1.226122413","rc":[{"batb":[[0,320,5.29]],"batl":[[2,580,3.55],[1,430,2.24],[0,420,3.33]],"id":54370634},{"tv":450.23,"batb":[[0,270,2.74]],"trd":[[300,39.82]],"batl":[],"id":41200638},{"batb":[[0,26,2.95]],"batl":[[2,30,14.43]],"id":55632148},{"tv":82644.33,"batb":[[2,1.83,194.15],[1,1.84,153.43],[0,1.85,539.22]],"trd":[[1.87,8697.14],[1.86,8762.58],[1.88,10976.89],[1.89,5748.86]],"ltp":1.89,"batl":[[2,1.9,145.84],[1,1.89,36.92],[0,1.88,2.27]],"id":51922},{"batb":[[0,4.4,102.75]],"batl":[],"id":50466254},{"tv":2143.29,"batb":[[0,24,15.56]],"trd":[[24,200.95]],"ltp":24,"id":106596}],"tv":114475.96,"con":true}],"ArrivalTime":1710508058180}
{"op":"mcm","id":2,"clk":"AIxKAO1lAJtw","pt":1710508058298,"mc":[{"id":"1.226122413","rc":[{"batl":[[2,30,13.83]],"id":55632148},{"tv":82850.28,"batb":[[2,1.84,153.43],[1,1.85,506.05],[0,1.86,34.9]],"trd":[[1.86,8902.18],[1.85,12779.45]],"ltp":1.85,"batl":[[1,1.89,136.73],[0,1.88,68.19]],"id":51922}],"tv":114681.91}],"ArrivalTime":1710508058306}
{"op":"mcm","id":2,"clk":"AJVKAPVlAKBw","pt":1710508058411,"mc":[{"id":"1.226122413","rc":[{"batl":[[2,320,1.71],[1,310,1.71],[0,300,1.71]],"id":41200638},{"batb":[[0,1.86,59.9]],"id":51922},{"batb":[[2,4.3,112.83],[1,4.4,102.75],[0,4.5,21.56]],"id":50466254},{"batb":[[0,24,16.59]],"id":106596}]}],"ArrivalTime":1710508058418}
{"op":"mcm","id":2,"clk":"AJtKAPxlAKdw","pt":1710508058460,"mc":[{"id":"1.226122413","rc":[{"batb":[[2,7.8,45.53],[1,8,77.96],[0,8.2,8.22]],"id":41122648},{"batl":[[2,30,14.43]],"id":55632148},{"tv":82926.94,"batb":[[2,1.85,506.05],[1,1.86,59.9],[0,1.87,30.83]],"trd":[[1.87,8773.8]],"ltp":1.87,"id":51922}],"tv":114758.57}],"ArrivalTime":1710508058467}
{"op":"mcm","id":2,"clk":"AKJKAIVmALFw","pt":1710508058557,"mc":[{"id":"1.226122413","rc":[{"batb":[[0,8.2,19.16]],"id":41122648},{"batb":[[2,240,1.54],[1,250,11.4],[0,260,2.78]],"id":41200638},{"tv":82977.48,"batb":[[1,1.86,129.23],[0,1.87,5.56]],"trd":[[1.87,8824.34]],"batl":[[1,1.89,138.98]],"id":51922},{"batl":[[2,40,7.95]],"id":49744721},{"tv":2151.64,"batb":[[0,24,12.41]],"trd":[[24,209.3]],"id":106596}],"tv":114817.46}],"ArrivalTime":1710508058565}
{"op":"mcm","id":2,"clk":"AKlKAIxmALpw","pt":1710508058665,"mc":[{"id":"1.226122413","rc":[{"batl":[[2,30,13.83]],"id":55632148},{"tv":82997.48,"batb":[[2,1.84,153.43],[1,1.85,506.05],[0,1.86,185.79]],"trd":[[1.87,8835.46],[1.86,8911.06]],"ltp":1.86,"id":51922},{"batb":[[0,24,8.56]],"batl":[[0,26,6.79]],"id":106596}],"tv":114837.46}],"ArrivalTime":1710508058673}
{"op":"mcm","id":2,"clk":"AKxKAJNmAMBw","pt":1710508058763,"mc":[{"id":"1.226122413","rc":[{"batb":[[2,1.84,127.43]],"batl":[[0,1.88,70.19]],"id":51922},{"tv":2160.46,"batb":[[0,24,9.22]],"trd":[[24,218.12]],"batl":[[2,27,6.13],[1,26,6.79],[0,25,2.91]],"id":106596}],"tv":114846.28}],"ArrivalTime":1710508058771}
{"op":"mcm","id":2,"clk":"ALFKAJlmAMtw","pt":1710508058862,"mc":[{"id":"1.226122413","rc":[{"batl":[[2,1.89,141.23],[1,1.88,70.19],[0,1.87,15]],"id":51922},{"batb":[],"batl":[[1,26,10]],"id":106596}]}],"ArrivalTime":1710508058870}
{"op":"mcm","id":2,"clk":"ALZKAKlmANZw","pt":1710508058970,"mc":[{"id":"1.226122413","rc":[{"batl":[[1,1.88,104.71]],"id":51922},{"batl":[[2,40,7.82]],"id":49744721},{"tv":2171.15,"batb":[[0,24,1.84]],"trd":[[24,228.81]],"id":106596}],"tv":114856.97}],"ArrivalTime":1710508058977}
{"op":"mcm","id":2,"clk":"AL1KALFmAN1w","pt":1710508059076,"mc":[{"id":"1.226122413","rc":[{"batl":[[2,890,1.2],[1,580,3.55],[0,430,3.01]],"id":54370634},{"tv":83022.94,"trd":[[1.87,8860.92]],"ltp":1.87,"batl":[[0,1.87,2.27]],"id":51922},{"tv":2174.83,"batb":[[2,21,43.3],[1,22,22.64],[0,23,13.47]],"trd":[[24,232.49]],"batl":[[2,26,10],[1,25,2.91],[0,24,6.49]],"id":106596}],"tv":114886.11}],"ArrivalTime":1710508059083}
{"op":"mcm","id":2,"clk":"AMZKALVmAOdw","pt":1710508059184,"mc":[{"id":"1.226122413","rc":[{"batl":[[0,1.87,2.31]],"id":51922},{"tv":2177.99,"trd":[[24,235.65]],"batl":[[0,24,4.91]],"id":106596}],"tv":114889.27}],"ArrivalTime":1710508059192}
{"op":"mcm","id":2,"clk":"AM9KAL9mAO1w","pt":1710508059286,"mc":[{"id":"1.226122413","rc":[{"tv":83027.56,"trd":[[1.87,8865.54]],"batl":[[0,1.87,1.48]],"id":51922},{"batb":[[2,21,44.56],[1,22,23.77]],"batl":[[1,25,4.15],[0,24,7.92]],"id":106596}],"tv":114893.89}],"ArrivalTime":1710508059294}
{"op":"mcm","id":2,"clk":"ANNKAMxmAPpw","pt":1710508059385,"mc":[{"id":"1.226122413","rc":[{"batb":[[0,260,2.07]],"id":41200638},{"tv":1960.55,"batb":[[2,23,13.81],[1,24,16.98],[0,25,9.43]],"trd":[[26,346.18]],"ltp":26,"id":55632148},{"tv":83111.56,"batb":[[0,1.86,149.79]],"trd":[[1.87,8868.5],[1.86,8983.06],[1.88,10985.93]],"ltp":1.88,"batl":[[2,1.9,145.84],[1,1.89,141.23],[0,1.88,100.19]],"id":51922},{"tv":2582.64,"batb":[[0,32,9.16]],"trd":[[32,196.4]],"ltp":32,"id":49744721},{"tv":15788.09,"batb":[[0,4.5,19.56]],"trd":[[4.5,3299.98]],"id":50466254},{"tv":2179.53,"batb":[],"trd":[[24,237.19]],"batl":[[2,26,12],[0,24,7.15]],"id":106596}],"tv":114991.43}],"ArrivalTime":1710508059393}
{"op":"mcm","id":2,"clk":"AN5KANpmAIBx","pt":1710508059497,"mc":[{"id":"1.226122413","rc":[{"batb":[[0,4.5,32.89]],"id":50466254},{"batb":[[2,21,43.3],[1,22,16.41]],"id":106596}]}],"ArrivalTime":1710508059505}
{"op":"mcm","id":2,"clk":"AOFKAONmAIxx","pt":1710508059597,"mc":[{"id":"1.226122413","rc":[{"batb":[],"batl":[[0,8.4,25.19]],"id":41122648},{"batb":[[0,1.86,185.07]],"id":51922},{"batb":[[0,32,19.41]],"id":49744721},{"batl":[[1,25,7.24]],"id":106596}]}],"ArrivalTime":1710508059605}
{"op":"mcm","id":2,"clk":"AOxKAPFmAJhx","pt":1710508059703,"mc":[{"id":"1.226122413","rc":[{"batl":[[2,580,3.55],[1,430,2.24],[0,420,3.33]],"id":54370634},{"tv":8010.53,"trd":[[8.4,1092.79]],"batl":[[0,8.4,23.64]],"id":41122648},{"tv":2583.92,"trd":[[36,128.55]],"ltp":36,"batl":[[0,36,10.4]],"id":49744721}],"tv":114995.81}],"ArrivalTime":1710508059711}
{"op":"mcm","id":2,"clk":"AO9KAP1mAKFx","pt":1710508059799,"mc":[{"id":"1.226122413","rc":[{"tv":8030.52,"batb":[[0,8.2,9.16]],"trd":[[8.2,873.7]],"ltp":8.2,"id":41122648},{"batb":[[2,1.85,506.05],[1,1.86,185.07],[0,1.87,1.03]],"id":51922}],"tv":115015.8}],"ArrivalTime":1710508059807}
{"op":"mcm","id":2,"clk":"APdKAIJnAKVx","pt":1710508059866,"mc":[{"id":"1.226122413","rc":[{"batl":[[0,8.4,25.17]],"id":41122648},{"batl":[[0,1.88,162.4]],"id":51922},{"batb":[[2,30,32.01],[1,32,19.41],[0,34,5.74]],"id":49744721}]}],"ArrivalTime":1710508059874}
{"op":"mcm","id":2,"clk":"APxKAI9nAK9x","pt":1710508060012,"mc":[{"id":"1.226122413","rc":[{"batb":[[2,7.6,72.26],[1,7.8,45.53],[0,8,77.96]],"batl":[[0,8.4,33.39]],"id":41122648},{"batb":[[0,34,9.12]],"id":49744721},{"batb":[[1,4.4,105.32]],"batl":[[2,4.8,166.59]],"id":50466254}]}],"ArrivalTime":1710508060019}
{"op":"mcm","id":2,"clk":"AINLAJdnALdx","pt":1710508060066,"mc":[{"id":"1.226122413","rc":[{"batl":[[2,8.6,42.95],[1,8.4,33.39],[0,8.2,13]],"id":41122648},{"batb":[[0,34,12.12]],"batl":[[0,36,7.93]],"id":49744721}]}],"ArrivalTime":1710508060074}
{"op":"mcm","id":2,"clk":"AItLAJ9nAMJx","pt":1710508060243,"mc":[{"id":"1.226122413","rc":[{"batl":[[0,36,5.93]],"id":49744721},{"batl":[[2,4.8,163.79]],"id":50466254}]}],"ArrivalTime":1710508060251}
{"op":"mcm","id":2,"clk":"AJBLAKdnAMtx","pt":1710508060268,"mc":[{"id":"1.226122413","rc":[{"batl":[[0,8.2,23.71]],"id":41122648},{"tv":83113.62,"batb":[[2,1.84,127.43],[1,1.85,506.05],[0,1.86,185.07]],"trd":[[1.87,8870.56]],"ltp":1.87,"batl":[[2,1.89,141.23],[1,1.88,251.76],[0,1.87,8.97]],"id":51922},{"batb":[[0,34,15.24]],"id":49744721},{"batb":[[2,4.3,112.73]],"id":50466254}],"tv":115017.86}],"ArrivalTime":1710508060276}
{"op":"mcm","id":2,"clk":"AJpLAK9nANRx","pt":1710508060381,"mc":[{"id":"1.226122413","rc":[{"batb":[[2,7.6,74.3]],"id":41122648},{"tv":454.37,"batb":[[2,230,1.57],[1,240,1.54],[0,250,11.4]],"trd":[[260,10.16]],"ltp":260,"batl":[[2,310,1.71],[1,300,1.71],[0,260,1.35]],"id":41200638},{"batb":[[2,24,16.98],[1,25,8.48],[0,26,4.53]],"id":55632148},{"batb":[[0,1.86,124.07]],"id":51922},{"batb":[[0,4.5,74.43]],"id":50466254}],"tv":115022}],"ArrivalTime":1710508060389}
{"op":"mcm","id":2,"clk":"AKBLALdnAN5x","pt":1710508060485,"mc":[{"id":"1.226122413","rc":[{"batb":[[0,320,4.86]],"batl":[[2,890,1.2],[1,580,3.55],[0,430,3.01]],"id":54370634},{"batb":[[0,140,3.44]],"id":66251581}]}],"ArrivalTime":1710508060493}
{"op":"mcm","id":2,"clk":"AKVLAL1nAO1x","pt":1710508060596,"mc":[{"id":"1.226122413","rc":[{"batb":[[0,320,7.39]],"id":54370634},{"batb":[[1,240,3.6],[0,250,9.29]],"id":41200638},{"batb":[[0,26,6.97]],"batl":[[1,29,5.3]],"id":55632148},{"batl":[[1,38,5.6]],"id":49744721},{"batb":[[2,130,2.17],[1,140,3.44],[0,150,4]],"batl":[],"id":66251581},{"batb":[],"batl":[[1,25,10.67]],"id":106596}]}],"ArrivalTime":1710508060603}
{"op":"mcm","id":2,"clk":"AKhLAMxnAPdx","pt":1710508060688,"mc":[{"id":"1.226122413","rc":[{"batl":[[0,8.2,33.71]],"id":41122648},{"batb":[[0,1.86,88.79]],"batl":[[2,1.89,146.23],[1,1.88,255.76]],"id":51922}]}],"ArrivalTime":1710508060696}
{"op":"mcm","id":2,"clk":"AK9LANVnAP5x","pt":1710508060796,"mc":[{"id":"1.226122413","rc":[{"batl":[[1,8.4,31.39],[0,8.2,38.54]],"id":41122648},{"tv":83115.75,"trd":[[1.87,8872.69]],"batl":[[0,1.87,74.3]],"id":51922},{"batb":[[0,150,5]],"id":66251581}],"tv":115024.13}],"ArrivalTime":1710508060804}
{"op":"mcm","id":2,"clk":"ALJLAN1nAIdy","pt":1710508060895,"mc":[{"id":"1.226122413","rc":[{"tv":8032.52,"trd":[[8.2,875.7]],"batl":[[0,8.2,37.54]],"id":41122648},{"tv":83117.81,"trd":[[1.87,8874.75]],"batl":[[0,1.87,73.27]],"id":51922}],"tv":115028.19}],"ArrivalTime":1710508060902}
{"op":"mcm","id":2,"clk":"ALlLAOZnAJRy","pt":1710508061009,"mc":[{"id":"1.226122413","rc":[{"batb":[],"batl":[[0,1.87,107.18]],"id":51922},{"tv":15790.09,"batb":[[0,4.5,73.43]],"trd":[[4.5,3301.98]],"id":50466254}],"tv":115030.19}],"ArrivalTime":1710508061017}
{"op":"mcm","id":2,"clk":"AL1LAOxnAJ5y","pt":1710508061110,"mc":[{"id":"1.226122413","rc":[{"batb":[[1,240,2.06]],"batl":[[1,300,2.07]],"id":41200638},{"tv":83119.87,"trd":[[1.87,8876.81]],"batl":[[0,1.87,106.15]],"id":51922}],"tv":115032.25}],"ArrivalTime":1710508061118}
{"op":"mcm","id":2,"clk":"AMNLAPlnAKly","pt":1710508061217,"mc":[{"id":"1.226122413","rc":[{"batl":[[2,580,3.55],[1,430,2.24],[0,420,3.33]],"id":54370634},{"tv":83297.45,"batb":[[2,1.83,194.15],[1,1.84,127.43],[0,1.85,506.05]],"trd":[[1.86,9160.64]],"ltp":1.86,"batl":[[2,1.88,255.76],[1,1.87,106.15],[0,1.86,11.21]],"id":51922}],"tv":115209.83}],"ArrivalTime":1710508061225}
{"op":"mcm","id":2,"clk":"AMdLAINoALJy","pt":1710508061262,"mc":[{"id":"1.226122413","rc":[{"batl":[[0,8.2,46.08]],"id":41122648},{"tv":83299.51,"trd":[[1.86,9162.7]],"batl":[[0,1.86,10.18]],"id":51922},{"batl":[[2,210,5],[1,200,2.79],[0,190,2.82]],"id":66251581}],"tv":115211.89}],"ArrivalTime":1710508061269}
{"op":"mcm","id":2,"clk":"AMpLAIhoALty","pt":1710508061370,"mc":[{"id":"1.226122413","rc":[{"batb":[[0,320,8.11]],"id":54370634},{"batl":[[0,28,4.14]],"id":55632148},{"tv":83319.87,"batb":[[2,1.84,127.43],[1,1.85,506.05],[0,1.86,68.42]],"trd":[[1.86,9183.06]],"batl":[[2,1.89,146.23],[1,1.88,255.76],[0,1.87,106.15]],"id":51922},{"batb":[[0,4.5,88.43]],"batl":[],"id":50466254}],"tv":115232.25}],"ArrivalTime":1710508061378}
{"op":"mcm","id":2,"clk":"ANBLAJJoAMRy","pt":1710508061467,"mc":[{"id":"1.226122413","rc":[{"batb":[[2,7.6,72.26]],"id":41122648},{"tv":83321.93,"trd":[[1.87,8878.87]],"ltp":1.87,"batl":[[1,1.88,260.76],[0,1.87,105.12]],"id":51922},{"batb":[[0,23,12.86]],"id":106596}],"tv":115234.31}],"ArrivalTime":1710508061475}
{"op":"mcm","id":2,"clk":"ANVLAKBoANFy","pt":1710508061587,"mc":[{"id":"1.226122413","rc":[{"batl":[[2,1.89,147.23]],"id":51922}]}],"ArrivalTime":1710508061595}
{"op":"mcm","id":2,"clk":"ANpLAKloANZy","pt":1710508061683,"mc":[{"id":"1.226122413","rc":[{"batl":[[2,30,11.31],[0,28,4.02]],"id":55632148},{"tv":83343.99,"trd":[[1.87,8900.93]],"batl":[[1,1.88,264.76],[0,1.87,96.09]],"id":51922},{"batl":[[0,24,8.4]],"id":106596}],"tv":115256.37}],"ArrivalTime":1710508061691}
{"op":"mcm","id":2,"clk":"AOJLALRoAOJy","pt":1710508061785,"mc":[{"id":"1.226122413","rc":[{"tv":8052.52,"trd":[[8.2,895.7]],"batl":[[0,8.2,38.08]],"id":41122648},{"batb":[[2,4.3,103.33]],"id":50466254}],"tv":115276.37}],"ArrivalTime":1710508061793}
{"op":"mcm","id":2,"clk":"AOhLAMBoAOxy","pt":1710508061894,"mc":[{"id":"1.226122413","rc":[{"tv":83386.79,"batb":[[0,1.86,73.05]],"trd":[[1.87,8902.99],[1.86,9223.8]],"ltp":1.86,"batl":[[0,1.87,95.06]],"id":51922}],"tv":115319.17}],"ArrivalTime":1710508061903}
{"op":"mcm","id":2,"clk":"APFLAMtoAPdy","pt":1710508061998,"mc":[{"id":"1.226122413","rc":[{"batl":[[0,8.2,27.37]],"id":41122648},{"batl":[[0,1.87,95.43]],"id":51922}]}],"ArrivalTime":1710508062006}
{"op":"mcm","id":2,"clk":"APRLANJoAPxy","pt":1710508062094,"mc":[{"id":"1.226122413","rc":[{"tv":457.78,"batb":[[0,250,7.58]],"trd":[[250,23.76]],"ltp":250,"id":41200638},{"batl":[[2,240,3.71],[1,210,5.23]],"id":66251581}],"tv":115322.58}],"ArrivalTime":1710508062101}
{"op":"mcm","id":2,"clk":"APxLANpoAIdz","pt":1710508062194,"mc":[{"id":"1.226122413","rc":[{"batl":[[2,890,1.2],[1,580,3.55],[0,430,3.01]],"id":54370634},{"tv":83388.85,"trd":[[1.87,8905.05]],"ltp":1.87,"batl":[[0,1.87,94.4]],"id":51922}],"tv":115324.64}],"ArrivalTime":1710508062202}
{"op":"mcm","id":2,"clk":"AIZMAOFoAJNz","pt":1710508062301,"mc":[{"id":"1.226122413","rc":[{"tv":461.2,"batb":[[0,250,5.87]],"trd":[[250,27.18]],"id":41200638},{"tv":83390.91,"trd":[[1.87,8907.11]],"batl":[[0,1.87,98.37]],"id":51922}],"tv":115330.12}],"ArrivalTime":1710508062308}
{"op":"mcm","id":2,"clk":"AI5MAOZoAJhz","pt":1710508062404,"mc":[{"id":"1.226122413","rc":[{"batb":[[2,7.6,74.3]],"id":41122648},{"tv":464.62,"batb":[[0,250,4.16]],"trd":[[250,30.6]],"id":41200638},{"batb":[[0,1.86,75.38]],"id":51922}],"tv":115333.54}],"ArrivalTime":1710508062411}
{"op":"mcm","id":2,"clk":"AJNMAO5oAKFz","pt":1710508062507,"mc":[{"id":"1.226122413","rc":[{"batb":[[0,8,77.71]],"batl":[[0,8.2,25.37]],"id":41122648},{"tv":83392.97,"trd":[[1.87,8909.17]],"batl":[[0,1.87,97.34]],"id":51922}],"tv":115335.6}],"ArrivalTime":1710508062515}
{"op":"mcm","id":2,"clk":"AJdMAPloAK9z","pt":1710508062619,"mc":[{"id":"1.226122413","rc":[{"batb":[[0,8,79.71]],"id":41122648},{"tv":468.04,"batb":[[0,250,2.45]],"trd":[[250,34.02]],"id":41200638},{"tv":83395.03,"trd":[[1.87,8911.23]],"batl":[[0,1.87,116.31]],"id":51922}],"tv":115341.08}],"ArrivalTime":1710508062627}
{"op":"mcm","id":2,"clk":"AJxMAIFpALdz","pt":1710508062669,"mc":[{"id":"1.226122413","rc":[{"batl":[[2,580,3.55],[1,430,2.24],[0,420,3.33]],"id":54370634},{"tv":83399.03,"batb":[[0,1.86,73.38]],"trd":[[1.86,9227.8]],"ltp":1.86,"batl":[],"id":51922},{"tv":2584.76,"trd":[[36,129.39]],"batl":[[0,36,5.51]],"id":49744721},{"batb":[[2,4.3,104.33]],"id":50466254}],"tv":115345.92}],"ArrivalTime":1710508062677}
{"op":"mcm","id":2,"clk":"AKRMAIxpAL5z","pt":1710508062772,"mc":[{"id":"1.226122413","rc":[{"tv":468.36,"batb":[[0,250,2.29]],"trd":[[250,34.34]],"id":41200638},{"tv":83401.09,"trd":[[1.87,8913.29]],"ltp":1.87,"batl":[[1,1.88,266.76],[0,1.87,115.28]],"id":51922}],"tv":115348.3}],"ArrivalTime":1710508062780}
{"op":"mcm","id":2,"clk":"AK1MAJdpAMdz","pt":1710508062876,"mc":[{"id":"1.226122413","rc":[{"batb":[[2,7.6,72.26]],"id":41122648},{"tv":471.78,"batb":[[2,220,1.63],[1,230,1.57],[0,240,2.64]],"trd":[[250,37.76]],"id":41200638}],"tv":115351.72}],"ArrivalTime":1710508062884}
{"op":"mcm","id":2,"clk":"ALFMAJ9pAM9z","pt":1710508062978,"mc":[{"id":"1.226122413","rc":[{"batl":[[0,8.2,36.39]],"id":41122648},{"batb":[[2,220,2.78],[0,240,1.58]],"id":41200638},{"tv":15830.09,"batb":[[0,4.5,68.43]],"trd":[[4.5,3341.98]],"id":50466254}],"tv":115391.72}],"ArrivalTime":1710508062986}
{"op":"mcm","id":2,"clk":"ALZMAKxpANhz","pt":1710508063083,"mc":[{"id":"1.226122413","rc":[{"tv":472.94,"batb":[[2,200,2.34],[1,220,3.11],[0,240,1]],"trd":[[250,38.92]],"batl":[[2,300,2.07],[1,260,1.35],[0,250,1.13]],"id":41200638}],"tv":115392.88}],"ArrivalTime":1710508063090}
{"op":"mcm","id":2,"clk":"AL5MALJpAOFz","pt":1710508063180,"mc":[{"id":"1.226122413","rc":[{"tv":83405.21,"trd":[[1.87,8917.41]],"batl":[[0,1.87,113.22]],"id":51922}],"tv":115397}],"ArrivalTime":1710508063188}
{"op":"mcm","id":2,"clk":"AMRMALtpAOVz","pt":1710508063291,"mc":[{"id":"1.226122413","rc":[{"batl":[[0,250,2.84]],"id":41200638},{"batb":[[0,4.5,70.43]],"id":50466254}]}],"ArrivalTime":1710508063299}
{"op":"mcm","id":2,"clk":"AMxMAMhpAPBz","pt":1710508063402,"mc":[{"id":"1.226122413","rc":[{"tv":474.94,"batb":[[2,190,1.11],[1,200,2.34],[0,220,3.11]],"trd":[[240,7.3]],"ltp":240,"batl":[[0,250,4.54]],"id":41200638},{"tv":83469.21,"batb":[[0,1.86,41.38]],"trd":[[1.86,9291.8]],"ltp":1.86,"id":51922},{"tv":2588.76,"batb":[[0,34,13.24]],"trd":[[34,236.73]],"ltp":34,"id":49744721},{"batb":[[0,4.5,28.89]],"id":50466254},{"batl":[[1,210,5]],"id":66251581}],"tv":115467}],"ArrivalTime":1710508063410}
{"op":"mcm","id":2,"clk":"ANFMAM5pAPVz","pt":1710508063488,"mc":[{"id":"1.226122413","rc":[{"tv":83471.27,"trd":[[1.87,8919.47]],"ltp":1.87,"batl":[[1,1.88,268.76],[0,1.87,112.19]],"id":51922}],"tv":115469.06}],"ArrivalTime":1710508063496}
{"op":"mcm","id":2,"clk":"ANZMANhpAIF0","pt":1710508063602,"mc":[{"id":"1.226122413","rc":[{"batl":[[2,890,1.2],[1,580,3.55],[0,430,3.01]],"id":54370634},{"batb":[[2,200,2.34],[1,210,2.77]],"id":41200638},{"tv":83473.33,"trd":[[1.87,8921.53]],"batl":[[0,1.87,111.16]],"id":51922},{"batl":[[2,280,1.51],[1,240,3.71],[0,210,5]],"id":66251581}],"tv":115471.12}],"ArrivalTime":1710508063609}
{"op":"mcm","id":2,"clk":"ANxMAN9pAI50","pt":1710508063694,"mc":[{"id":"1.226122413","rc":[{"batl":[[2,290,1]],"id":41200638},{"batb":[[0,1.86,51.6]],"batl":[],"id":51922},{"batl":[[2,240,3.71],[1,210,5],[0,200,2.82]],"id":66251581}]}],"ArrivalTime":1710508063702}
{"op":"mcm","id":2,"clk":"AOZMAOppAJx0","pt":1710508063807,"mc":[{"id":"1.226122413","rc":[{"batb":[[2,7.6,74.3]],"id":41122648},{"tv":83475.39,"batb":[[1,1.85,491.05]],"trd":[[1.87,8923.59]],"batl":[[0,1.87,110.13]],"id":51922},{"batb":[[0,4.5,68.55]],"id":50466254}],"tv":115473.18}],"ArrivalTime":1710508063815}
{"op":"mcm","id":2,"clk":"APRMAPppAKt0","pt":1710508063905,"mc":[{"id":"1.226122413","rc":[{"batb":[[2,200,1.3],[0,220,1.96]],"id":41200638},{"tv":83589.47,"batb":[[1,1.85,485.61],[0,1.86,15]],"trd":[[1.86,9395],[1.85,12790.33]],"ltp":1.85,"id":51922}],"tv":115587.26}],"ArrivalTime":1710508063912}
{"op":"mcm","id":2,"clk":"APlMAI9qALx0","pt":1710508064022,"mc":[{"id":"1.226122413","rc":[{"tv":8052.62,"batb":[[0,8,79.66]],"trd":[[8,27.6]],"ltp":8,"id":41122648},{"tv":83631.53,"batb":[[2,1.83,194.15],[1,1.84,127.43],[0,1.85,480.61]],"trd":[[1.87,8925.65],[1.86,9425],[1.85,12800.33]],"batl":[[2,1.88,268.76],[1,1.87,109.1],[0,1.86,111.05]],"id":51922},{"tv":15830.19,"batb":[[0,4.5,68.5]],"trd":[[4.5,3342.08]],"id":50466254}],"tv":115629.52}],"ArrivalTime":1710508064030}
{"op":"mcm","id":2,"clk":"AIBNAJNqAMF0","pt":1710508064070,"mc":[{"id":"1.226122413","rc":[{"tv":376,"batb":[[0,320,7.39]],"trd":[[330,44.18]],"ltp":330,"id":54370634},{"batb":[[0,150,3.55]],"id":66251581}],"tv":115630.96}],"ArrivalTime":1710508064078}
{"op":"mcm","id":2,"clk":"AIdNAKFqAM90","pt":1710508064217,"mc":[{"id":"1.226122413","rc":[{"batl":[[2,580,3.55],[1,430,2.24],[0,420,3.33]],"id":54370634},{"tv":8120.74,"batb":[[1,7.8,57.3],[0,8,33.75]],"trd":[[8,95.72]],"batl":[],"id":41122648},{"batb":[[1,25,9.48]],"id":55632148},{"tv":83643.59,"batb":[[0,1.85,453.66]],"trd":[[1.86,9437.06]],"ltp":1.86,"batl":[[0,1.86,105.02]],"id":51922},{"tv":2590.34,"batb":[[0,34,12.45]],"trd":[[34,238.31]],"batl":[[0,36,2.19]],"id":49744721},{"tv":2194.55,"batb":[[2,20,19.88],[1,21,43.3],[0,22,13.31]],"trd":[[23,77.6]],"ltp":23,"batl":[[2,25,10.67],[1,24,8.4],[0,23,10.57]],"id":106596}],"tv":115727.74}],"ArrivalTime":1710508064225}
{"op":"mcm","id":2,"clk":"AIxNAKxqANl0","pt":1710508064271,"mc":[{"id":"1.226122413","rc":[{"batb":[[2,310,1.58],[1,320,7.39],[0,330,1]],"id":54370634},{"batl":[[1,8.4,44.03]],"id":41122648},{"tv":83975.58,"batb":[[0,1.85,387.66]],"trd":[[1.86,9637.06],[1.85,12932.32]],"ltp":1.85,"batl":[[0,1.86,5.17]],"id":51922},{"batl":[[2,42,10.5],[1,40,7.82],[0,38,6.37]],"id":49744721},{"tv":15840.19,"trd":[[4.6,1336.27]],"ltp":4.6,"batl":[[0,4.6,77.63]],"id":50466254}],"tv":116069.73}],"ArrivalTime":1710508064279}
{"op":"mcm","id":2,"clk":"AJBNALpqAO10","pt":1710508064384,"mc":[{"id":"1.226122413","rc":[{"tv":8184.15,"batb":[[2,7.6,57.68],[0,8,2.05]],"trd":[[8,159.13]],"id":41122648},{"batl":[[2,300,2.07]],"id":41200638},{"tv":83991.98,"batb":[[2,1.84,127.43],[1,1.85,488.39],[0,1.86,230.38]],"trd":[[1.87,8927.71],[1.86,9651.4]],"ltp":1.87,"batl":[[2,1.89,147.23],[1,1.88,268.76],[0,1.87,108.07]],"id":51922},{"batb":[[2,30,35.05]],"id":49744721},{"batl":[[0,4.6,52.93]],"id":50466254},{"batl":[[1,24,11.16]],"id":106596}],"tv":116149.54}],"ArrivalTime":1710508064391}
{"op":"mcm","id":2,"clk":"AJdNAMRqAPF0","pt":1710508064489,"mc":[{"id":"1.226122413","rc":[{"tv":8186.78,"batb":[[2,7.4,45.01],[1,7.6,57.68],[0,7.8,58.03]],"trd":[[8,161.76]],"id":41122648},{"tv":84452.75,"batb":[[2,1.83,194.15],[1,1.84,127.43],[0,1.85,488.39]],"trd":[[1.86,10112.17]],"ltp":1.86,"batl":[[1,1.88,270.76]],"id":51922},{"batb":[[2,30,32.01]],"id":49744721},{"batb":[[0,4.5,94.31]],"batl":[[0,4.6,54.93]],"id":50466254},{"batl":[[2,250,1.14]],"id":66251581}],"tv":116612.94}],"ArrivalTime":1710508064497}
{"op":"mcm","id":2,"clk":"AKFNANBqAIF1","pt":1710508064597,"mc":[{"id":"1.226122413","rc":[{"tv":8205,"batb":[[1,7.6,55.64],[0,7.8,57.3]],"trd":[[8,179.98]],"batl":[[2,8.4,44.03],[1,8.2,44.41],[0,8,1.33]],"id":41122648},{"batb":[[2,190,1.11],[1,200,1.3],[0,210,3.1]],"id":41200638},{"tv":84454.91,"trd":[[1.87,8929.87]],"ltp":1.87,"batl":[[2,1.88,270.76],[1,1.87,73.08],[0,1.86,65.4]],"id":51922},{"batl":[[0,38,8.37]],"id":49744721},{"batb":[[1,21,46.71],[0,22,7.62]],"id":106596}],"tv":116633.32}],"ArrivalTime":1710508064605}
{"op":"mcm","id":2,"clk":"AKpNANlqAIx1","pt":1710508064695,"mc":[{"id":"1.226122413","rc":[{"batl":[[1,1.87,115.78]],"id":51922},{"tv":15840.59,"trd":[[4.6,1336.67]],"batl":[[0,4.6,54.73]],"id":50466254}],"tv":116633.72}],"ArrivalTime":1710508064703}
{"op":"mcm","id":2,"clk":"AK9NAOdqAJZ1","pt":1710508064793,"mc":[{"id":"1.226122413","rc":[{"tv":8207.56,"batb":[[1,7.6,57.68],[0,7.8,59.24]],"trd":[[8,182.54]],"batl":[[2,8.4,31.39],[0,8,8.26]],"id":41122648},{"batb":[[1,200,2.53]],"id":41200638},{"tv":84467.11,"trd":[[1.86,10124.37]],"ltp":1.86,"batl":[[1,1.87,145.71],[0,1.86,59.3]],"id":51922},{"tv":15935.99,"trd":[[4.6,1432.07]],"batl":[[0,4.6,7.03]],"id":50466254}],"tv":116743.88}],"ArrivalTime":1710508064801}
{"op":"mcm","id":2,"clk":"ALdNAO1qAKF1","pt":1710508064898,"mc":[{"id":"1.226122413","rc":[{"tv":376.07,"trd":[[420,1.51]],"ltp":420,"batl":[[0,420,3.26]],"id":54370634},{"tv":8211.03,"trd":[[8,186.01]],"batl":[[0,8,16.69]],"id":41122648},{"tv":475.05,"trd":[[250,39.03]],"ltp":250,"batl":[[0,250,4.43]],"id":41200638},{"tv":1961.54,"trd":[[28,290.02]],"ltp":28,"batl":[[0,28,3.03]],"id":55632148},{"tv":84484.07,"batb":[[0,1.85,493.39]],"trd":[[1.86,10141.33]],"batl":[[0,1.86,43.37]],"id":51922},{"tv":2591.11,"trd":[[36,130.16]],"ltp":36,"batl":[[0,38,7.6]],"id":49744721},{"tv":15944.02,"batb":[[2,4.4,105.32],[1,4.5,94.31],[0,4.6,38.1]],"trd":[[4.6,1440.1]],"batl":[[2,4.9,142.24],[1,4.8,163.79],[0,4.7,77.01]],"id":50466254},{"tv":536.98,"trd":[[200,8.28]],"batl":[[0,200,2.68]],"id":66251581},{"tv":2211.05,"batb":[[2,19.5,26.31],[1,20,19.88],[0,21,46.71]],"trd":[[22,61.12]],"ltp":22,"batl":[[2,24,11.16],[1,23,10.57],[0,22,2]],"id":106596}],"tv":116790.92}],"ArrivalTime":1710508064905}
{"op":"mcm","id":2,"clk":"AMpNAIFrAMN1","pt":1710508065202,"mc":[{"id":"1.226122413","rc":[{"batl":[[2,890,1.2],[1,580,3.55],[0,430,2.94]],"id":54370634},{"batb":[[2,25,9.48],[1,26,6.97],[0,27,3.02]],"batl":[],"id":55632148},{"tv":84488.07,"batb":[[0,1.85,468.12]],"trd":[[1.86,10145.33]],"batl":[[2,1.88,272.76],[1,1.87,148.01],[0,1.86,41.37]],"id":51922},{"tv":15959.26,"batb":[[0,4.6,57.47],[2,4.4,107.32]],"trd":[[4.6,1455.34]],"batl":[],"id":50466254},{"batb":[[0,150,4.13]],"id":66251581},{"tv":2215.05,"batb":[[2,19.5,23.06],[1,20,30.72]],"trd":[[22,65.12]],"batl":[[2,25,7.33],[1,24,14.74],[0,23,10.57]],"id":106596}],"tv":116814.16,"con":true}],"ArrivalTime":1710508065210}
{"op":"mcm","id":2,"clk":"AMxNAIVrAMR1","pt":1710508065217,"mc":[{"id":"1.226122413","rc":[{"batl":[[0,430,2.6]],"id":54370634},{"batl":[[1,8.2,39.58]],"id":41122648},{"tv":84490.13,"batb":[[1,1.84,194.3]],"trd":[[1.86,10147.39]],"batl":[[0,1.86,60.34]],"id":51922},{"tv":15963.26,"batb":[[2,4.4,123.97],[0,4.6,55.47]],"trd":[[4.6,1459.34]],"id":50466254},{"batb":[[1,20,22.72],[0,21,42.7]],"id":106596}],"tv":116820.22}],"ArrivalTime":1710508065225}
{"op":"mcm","id":2,"clk":"AN1NAI9rAM91","pt":1710508065324,"mc":[{"id":"1.226122413","rc":[{"batb":[[2,7.4,61.88]],"id":41122648},{"tv":1963.02,"batb":[[0,27,4.95]],"trd":[[27,252.11]],"ltp":27,"batl":[[1,29,5.94],[0,28,3.72]],"id":55632148},{"tv":84587.96,"batb":[[0,1.85,354.8]],"trd":[[1.86,10149.45],[1.85,13028.09]],"batl":[[0,1.86,59.31]],"id":51922},{"tv":16006.68,"batb":[],"trd":[[4.7,141.46]],"ltp":4.7,"batl":[[1,4.8,119.98],[0,4.7,47.76]],"id":50466254}],"tv":116962.95}],"ArrivalTime":1710508065332}
{"op":"mcm","id":2,"clk":"AOJNAJZrANZ1","pt":1710508065423,"mc":[{"id":"1.226122413","rc":[{"tv":1967.02,"batb":[[1,26,8],[0,27,2.95]],"trd":[[27,256.11]],"id":55632148},{"batb":[[2,4.4,127.39]],"batl":[],"id":50466254},{"batb":[[1,140,4.47]],"id":66251581},{"batb":[[2,19.5,28.74]],"batl":[],"id":106596}],"tv":116966.95}],"ArrivalTime":1710508065430}
{"op":"mcm","id":2,"clk":"AOpNAJxrAN51","pt":1710508065531,"mc":[{"id":"1.226122413","rc":[{"batb":[[1,320,8.39]],"id":54370634},{"batb":[[2,7.4,70.88]],"id":41122648},{"tv":1972.92,"batb":[[2,24,16.98],[1,25,9.48],[0,26,8]],"trd":[[27,262.01]],"batl":[[2,29,5.94],[1,28,3.72],[0,27,2.78]],"id":55632148},{"batl":[[1,1.87,159.5],[0,1.86,88.46]],"id":51922},{"batb":[[0,4.6,82.54]],"id":50466254},{"tv":2219.05,"batb":[[2,19.5,32.74],[0,21,40.7]],"trd":[[22,66.9],[21,2.22]],"ltp":21,"id":106596}],"tv":116976.85}],"ArrivalTime":1710508065539}
{"op":"mcm","id":2,"clk":"AO5NAKlrAOx1","pt":1710508065625,"mc":[{"id":"1.226122413","rc":[{"batb":[[0,7.8,55.24]],"batl":[[1,8.2,81.3]],"id":41122648},{"batb":[[0,210,5.4]],"id":41200638},{"batb":[[0,26,9.04]],"id":55632148},{"tv":84590.02,"trd":[[1.86,10151.51]],"batl":[[0,1.86,107.43]],"id":51922},{"batb":[[1,4.5,92.31]],"batl":[],"id":50466254},{"batb":[[1,140,5.51]],"id":66251581},{"batb":[[1,20,11.88]],"id":106596}],"tv":116978.91}],"ArrivalTime":1710508065633}
{"op":"mcm","id":2,"clk":"APNNALVrAPR1","pt":1710508065685,"mc":[{"id":"1.226122413","rc":[{"batb":[],"batl":[[2,29,5.3],[1,28,3.03]],"id":55632148},{"batl":[[1,1.87,174.5],[0,1.86,150.13]],"id":51922},{"batl":[[0,4.7,26.41]],"id":50466254},{"batl":[[2,25,7.34],[0,23,10.58]],"id":106596}]}],"ArrivalTime":1710508065692}
{"op":"mcm","id":2,"clk":"APtNALlrAIB2","pt":1710508065786,"mc":[{"id":"1.226122413","rc":[{"batl":[[2,1.88,275.8],[0,1.86,160.13]],"id":51922},{"batl":[[2,24,14.74],[1,23,10.58],[0,22,3.37]],"id":106596}]}],"ArrivalTime":1710508065794}
{"op":"mcm","id":2,"clk":"AIJOAMFrAI52","pt":1710508065896,"mc":[{"id":"1.226122413","rc":[{"batb":[[0,7.8,53.3]],"id":41122648},{"batl":[[2,1.88,272.76]],"id":51922},{"batb":[[0,4.6,102.97]],"id":50466254},{"tv":2225.45,"batb":[],"trd":[[22,73.3]],"ltp":22,"batl":[[2,25,7.34],[1,24,14.74],[0,23,10.75]],"id":106596}],"tv":116985.31}],"ArrivalTime":1710508065903}
{"op":"mcm","id":2,"clk":"AIhOAMtrAJh2","pt":1710508065997,"mc":[{"id":"1.226122413","rc":[{"batb":[[0,26,8]],"id":55632148},{"tv":85127.37,"batb":[[0,1.85,98.18]],"trd":[[1.86,10155.62],[1.85,13561.33]],"ltp":1.85,"batl":[[0,1.86,158.07]],"id":51922},{"batb":[[0,4.6,186.3]],"id":50466254},{"tv":2225.79,"batb":[[1,20,15.62]],"trd":[[22,73.64]],"batl":[[0,23,10.58]],"id":106596}],"tv":117523}],"ArrivalTime":1710508066005}
{"op":"mcm","id":2,"clk":"AI5OANJrAKR2","pt":1710508066104,"mc":[{"id":"1.226122413","rc":[{"tv":8228.76,"batb":[[0,7.8,55.24]],"trd":[[8,203.74]],"batl":[[0,8,7.82]],"id":41122648},{"tv":85147.77,"trd":[[1.86,10176.02]],"ltp":1.86,"batl":[[0,1.86,147.87]],"id":51922},{"batb":[[2,20,15.62],[1,21,40.7],[0,22,5.1]],"id":106596}],"tv":117561.13}],"ArrivalTime":1710508066111}
{"op":"mcm","id":2,"clk":"AJNOAN9rAKx2","pt":1710508066206,"mc":[{"id":"1.226122413","rc":[{"tv":8244.4,"batb":[[0,7.8,55.79]],"trd":[[8,219.38]],"batl":[[2,8.6,33.18],[1,8.4,31.39],[0,8.2,81.3]],"id":41122648},{"batb":[[0,26,6.97]],"id":55632148},{"tv":85220.18,"batb":[[2,1.82,158.13],[1,1.83,194.15],[0,1.84,192.82]],"trd":[[1.86,10178.08],[1.85,13631.68]],"ltp":1.85,"batl":[[2,1.88,275.33],[0,1.86,146.84]],"id":51922},{"batb":[[0,4.6,211.15]],"batl":[[0,4.7,15]],"id":50466254},{"batb":[[0,22,9.19]],"batl":[[1,24,22.37],[0,23,12.58]],"id":106596}],"tv":117649.18}],"ArrivalTime":1710508066214}
{"op":"mcm","id":2,"clk":"AJpOAOhrALZ2","pt":1710508066314,"mc":[{"id":"1.226122413","rc":[{"batl":[[2,1.87,174.5],[1,1.86,146.84],[0,1.85,164.62]],"id":51922},{"tv":2235.99,"batb":[[2,20,19.62],[0,22,4.09]],"trd":[[22,83.84]],"id":106596}],"tv":117659.38}],"ArrivalTime":1710508066322}
{"op":"mcm","id":2,"clk":"AKFOAPNrAMp2","pt":1710508066420,"mc":[{"id":"1.226122413","rc":[{"batb":[[2,7.4,68.69],[1,7.6,55.64],[0,7.8,53.85]],"batl":[[0,8.2,72.76]],"id":41122648},{"tv":85222.24,"batb":[[1,1.83,261.2]],"trd":[[1.85,13633.74]],"batl":[[0,1.85,163.59]],"id":51922},{"tv":16036.68,"batb":[[1,4.5,95.56],[0,4.6,213.11]],"trd":[[4.7,171.46]],"batl":[[2,5,65.88],[1,4.9,142.24],[0,4.8,119.98]],"id":50466254}],"tv":117691.44}],"ArrivalTime":1710508066428}
{"op":"mcm","id":2,"clk":"AKdOAPRrAM52","pt":1710508066513,"mc":[{"id":"1.226122413","rc":[{"tv":8245.5,"batb":[[0,7.8,53.3]],"trd":[[8,220.48]],"batl":[[2,8.4,31.39],[1,8.2,72.76],[0,8,7.99]],"id":41122648},{"tv":85229.22,"batb":[[1,1.83,143.87],[0,1.84,125.95]],"trd":[[1.85,13640.72]],"batl":[[0,1.85,160.1]],"id":51922},{"batb":[[2,4.5,97.56],[1,4.6,213.11],[0,4.7,7.89]],"id":50466254},{"batb":[[1,140,4.47]],"id":66251581}],"tv":117699.52}],"ArrivalTime":1710508066521}
{"op":"mcm","id":2,"clk":"ALJOAPprANZ2","pt":1710508066624,"mc":[{"id":"1.226122413","rc":[{"batb":[[2,7.4,70.88]],"batl":[[2,8.4,44.5]],"id":41122648},{"tv":85483.19,"batb":[[2,1.81,83.87],[1,1.82,259.96],[0,1.83,143.87]],"trd":[[1.85,13642.78],[1.84,12240.08]],"ltp":1.84,"batl":[[2,1.86,146.84],[1,1.85,159.07],[0,1.84,57.5]],"id":51922},{"batb":[[2,4.5,94.31],[0,4.7,44.55]],"id":50466254}],"tv":117953.49}],"ArrivalTime":1710508066633}
{"op":"mcm","id":2,"clk":"ALpOAIBsAOR2","pt":1710508066686,"mc":[{"id":"1.226122413","rc":[{"batb":[[1,7.6,57.68],[0,7.8,55.24]],"id":41122648},{"batl":[[2,1.86,161.84],[1,1.85,189.15],[0,1.84,77.65]],"id":51922},{"batb":[],"batl":[[1,4.9,177.35]],"id":50466254}]}],"ArrivalTime":1710508066693}
{"op":"mcm","id":2,"clk":"AMBOAI1sAO52","pt":1710508066786,"mc":[{"id":"1.226122413","rc":[{"tv":85598.19,"batb":[[2,1.81,118.87],[0,1.83,167.87]],"trd":[[1.84,12355.08]],"batl":[[0,1.84,20.15]],"id":51922},{"batb":[[2,4.5,97.56],[0,4.7,58.55]],"batl":[[0,4.8,100.81]],"id":50466254},{"batb":[[0,150,4.29]],"id":66251581}],"tv":118068.49}],"ArrivalTime":1710508066795}
{"op":"mcm","id":2,"clk":"AMdOAJlsAPp2","pt":1710508066899,"mc":[{"id":"1.226122413","rc":[{"batb":[[1,1.82,158.13]],"id":51922},{"batb":[[1,21,43.7],[0,22,7.09]],"id":106596}]}],"ArrivalTime":1710508066907}
{"op":"mcm","id":2,"clk":"AM5OAKdsAIF3","pt":1710508066995,"mc":[{"id":"1.226122413","rc":[{"tv":85602.19,"trd":[[1.84,12359.08]],"batl":[[0,1.84,64.23]],"id":51922},{"batl":[[0,4.8,71.18]],"id":50466254}],"tv":118072.49}],"ArrivalTime":1710508067003}
{"op":"mcm","id":2,"clk":"ANNOAK1sAIh3","pt":1710508067098,"mc":[{"id":"1.226122413","rc":[{"batb":[[2,1.81,209.54]],"batl":[],"id":51922},{"batb":[[0,4.7,63.55]],"batl":[[1,4.9,77.35]],"id":50466254},{"tv":543.16,"batb":[[0,150,1.21]],"trd":[[170,32.28],[160,23.32],[150,55.29]],"ltp":150,"id":66251581}],"tv":118078.67}],"ArrivalTime":1710508067105}
{"op":"mcm","id":2,"clk":"AN1OALlsAJF3","pt":1710508067191,"mc":[{"id":"1.226122413","rc":[{"batl":[[2,8.4,31.39]],"id":41122648},{"batl":[[1,1.85,214.15],[0,1.84,129.23]],"id":51922},{"tv":16056.68,"batb":[[0,4.7,53.55]],"trd":[[4.7,191.46]],"id":50466254}],"tv":118098.67}],"ArrivalTime":1710508067199}
{"op":"mcm","id":2,"clk":"AOJOALxsAJt3","pt":1710508067298,"mc":[{"id":"1.226122413","rc":[{"tv":8265.5,"batb":[[0,7.8,45.24]],"trd":[[7.8,26.69]],"ltp":7.8,"id":41122648},{"tv":85612.19,"trd":[[1.84,12369.08]],"batl":[[0,1.84,139.23]],"id":51922},{"batb":[[1,140,3.44],[0,150,4.22]],"batl":[[2,210,5],[1,200,2.68],[0,190,2.64]],"id":66251581}],"tv":118128.67}],"ArrivalTime":1710508067306}
{"op":"mcm","id":2,"clk":"AO1OAMNsAKh3","pt":1710508067399,"mc":[{"id":"1.226122413","rc":[{"tv":85614.25,"trd":[[1.84,12371.14]],"batl":[[0,1.84,138.2]],"id":51922}],"tv":118130.73}],"ArrivalTime":1710508067406}
{"op":"mcm","id":2,"clk":"APJOAMtsALB3","pt":1710508067502,"mc":[{"id":"1.226122413","rc":[{"batl":[[0,8,21.74]],"id":41122648},{"batl":[[2,1.86,164.17]],"id":51922},{"batb":[[1,21,43.73]],"id":106596}]}],"ArrivalTime":1710508067510}
{"op":"mcm","id":2,"clk":"APpOANRsALh3","pt":1710508067607,"mc":[{"id":"1.226122413","rc":[{"tv":1975.92,"batb":[[0,26,5.47]],"trd":[[26,349.18]],"ltp":26,"id":55632148},{"batl":[[0,1.84,163.2]],"id":51922},{"batb":[[0,4.7,66.36]],"batl":[[1,4.9,65.44]],"id":50466254},{"batl":[[2,250,1.14],[1,210,5],[0,190,3.64]],"id":66251581}],"tv":118133.73}],"ArrivalTime":1710508067615}
{"op":"mcm","id":2,"clk":"AIRPAN5sAMd3","pt":1710508067719,"mc":[{"id":"1.226122413","rc":[{"batl":[[2,1.86,121.58]],"id":51922},{"tv":2238,"batb":[[1,21,43.79],[0,22,6.08]],"trd":[[22,85.85]],"batl":[],"id":106596}],"tv":118135.74}],"ArrivalTime":1710508067727}
{"op":"mcm","id":2,"clk":"AIpPAOhsAM93","pt":1710508067821,"mc":[{"id":"1.226122413","rc":[{"batb":[[0,7.8,43.3]],"id":41122648},{"batl":[[2,30,11.31],[1,29,5.3],[0,28,3.03]],"id":55632148},{"tv":85616.31,"trd":[[1.84,12373.2]],"batl":[[0,1.84,177.17]],"id":51922},{"tv":551.59,"batb":[[2,120,6.41],[1,130,2.17],[0,140,3.44]],"trd":[[150,63.72]],"batl":[[2,210,5],[1,190,3.64],[0,150,1.51]],"id":66251581}],"tv":118146.23}],"ArrivalTime":1710508067829}
{"op":"mcm","id":2,"clk":"AJFPAPFsANx3","pt":1710508067878,"mc":[{"id":"1.226122413","rc":[{"batb":[[1,25,8.48],[0,26,8.13]],"batl":[],"id":55632148},{"tv":85628.07,"trd":[[1.84,12384.96]],"batl":[[0,1.84,171.29]],"id":51922}],"tv":118157.99}],"ArrivalTime":1710508067886}
{"op":"mcm","id":2,"clk":"AJ1PAIJtAOd3","pt":1710508068035,"mc":[{"id":"1.226122413","rc":[{"batl":[[1,8.2,62.76]],"id":41122648},{"tv":85648.07,"batb":[[0,1.83,157.87]],"trd":[[1.83,7914.69]],"ltp":1.83,"id":51922},{"tv":554.61,"batb":[[1,130,2.5],[0,140,4.69]],"trd":[[150,66.74]],"batl":[[2,250,1.14],[1,210,5],[0,190,1.11]],"id":66251581}],"tv":118181.01}],"ArrivalTime":1710508068043}
{"op":"mcm","id":2,"clk":"AKRPAIhtAPJ3","pt":1710508068086,"mc":[{"id":"1.226122413","rc":[{"batl":[[0,8,31.74]],"id":41122648},{"batb":[[2,25,8.48],[1,26,8.13],[0,27,2.31]],"id":55632148},{"tv":85688.43,"batb":[[0,1.83,142.87]],"trd":[[1.84,12395.32],[1.83,7944.69]],"batl":[[0,1.84,166.11]],"id":51922}],"tv":118221.37}],"ArrivalTime":1710508068094}
{"op":"mcm","id":2,"clk":"AK1PAJFtAPx3","pt":1710508068186,"mc":[{"id":"1.226122413","rc":[{"batb":[[1,7.6,55.64]],"batl":[[0,8,33.74]],"id":41122648},{"batl":[[2,30,11.91],[1,29,5.94]],"id":55632148},{"tv":85690.49,"trd":[[1.84,12397.38]],"ltp":1.84,"batl":[[2,1.86,124.73],[1,1.85,189.15],[0,1.84,165.08]],"id":51922},{"batb":[[1,130,2.17],[0,140,4.17]],"batl":[[0,190,1.66]],"id":66251581}],"tv":118223.43}],"ArrivalTime":1710508068194}
{"op":"mcm","id":2,"clk":"ALJPAKNtAIt4","pt":1710508068295,"mc":[{"id":"1.226122413","rc":[{"tv":85699.23,"batb":[[2,1.81,211.54],[1,1.82,224.48]],"trd":[[1.84,12406.12]],"batl":[[0,1.84,160.71]],"id":51922}],"tv":118232.17}],"ArrivalTime":1710508068303}
{"op":"mcm","id":2,"clk":"ALlPAKxtAJh4","pt":1710508068399,"mc":[{"id":"1.226122413","rc":[{"batb":[[1,7.6,57.68]],"id":41122648},{"tv":1977.4,"batb":[[0,27,1.57]],"trd":[[27,263.49]],"ltp":27,"batl":[[0,28,3.72]],"id":55632148},{"tv":85701.29,"batb":[[0,1.83,170.2]],"trd":[[1.84,12408.18]],"batl":[[0,1.84,159.68]],"id":51922},{"tv":16076.68,"trd":[[4.8,27.84]],"ltp":4.8,"batl":[[0,4.8,61.18]],"id":50466254}],"tv":118255.71}],"ArrivalTime":1710508068407}
{"op":"mcm","id":2,"clk":"AMFPALRtAKN4","pt":1710508068508,"mc":[{"id":"1.226122413","rc":[{"tv":86555.26,"trd":[[1.86,10334.37],[1.85,14021.08],[1.84,12727.56]],"ltp":1.86,"batl":[[2,1.88,282.37],[1,1.87,130.6],[0,1.86,46.58]],"id":51922},{"batl":[[2,210,5],[1,190,1],[0,180,1]],"id":66251581}],"tv":119109.68}],"ArrivalTime":1710508068515}
{"op":"mcm","id":2,"clk":"AMlPAMFtALB4","pt":1710508068614,"mc":[{"id":"1.226122413","rc":[{"tv":1977.88,"batb":[[0,27,1.33]],"trd":[[27,263.97]],"id":55632148},{"tv":86575.27,"batb":[[0,1.83,160.2]],"trd":[[1.83,7964.7]],"ltp":1.83,"batl":[[1,1.87,132.6]],"id":51922},{"batl":[[2,200,2.82]],"id":66251581}],"tv":119130.17}],"ArrivalTime":1710508068622}
{"op":"mcm","id":2,"clk":"AM5PAM5tALp4","pt":1710508068726,"mc":[{"id":"1.226122413","rc":[{"batb":[[1,7.6,55.64],[0,7.8,33.34]],"batl":[[0,8,41.51]],"id":41122648},{"batl":[[2,30,11.31],[1,29,5.3],[0,28,3.03]],"id":55632148},{"batb":[[2,1.82,225.48],[1,1.83,160.2],[0,1.84,103.96]],"batl":[[2,1.88,279.33],[1,1.87,129.51],[0,1.86,43.43]],"id":51922},{"batl":[[0,38,10.72]],"id":49744721},{"batb":[[2,4.5,94.31],[1,4.6,223.33],[0,4.7,53.55]],"batl":[[0,4.8,86.8]],"id":50466254},{"tv":2250.16,"batb":[[2,19.5,37],[1,20,19.62],[0,21,43.79]],"trd":[[22,98.01]],"id":106596}],"tv":119142.33}],"ArrivalTime":1710508068733}
{"op":"mcm","id":2,"clk":"ANZPAN1tAMR4","pt":1710508068769,"mc":[{"id":"1.226122413","rc":[{"tv":1980.54,"batb":[[2,24,16.98],[1,25,8.48],[0,26,8.13]],"trd":[[27,266.63]],"id":55632148},{"tv":86618.63,"batb":[[0,1.84,66.35]],"trd":[[1.84,12770.92]],"ltp":1.84,"batl":[[2,1.87,129.51],[1,1.86,82.3],[0,1.85,25]],"id":51922},{"batb":[[0,4.7,66.36]],"id":50466254}],"tv":119188.35}],"ArrivalTime":1710508068777}
{"op":"mcm","id":2,"clk":"AN1PAORtAM94","pt":1710508068877,"mc":[{"id":"1.226122413","rc":[{"batb":[[1,7.6,57.68],[0,7.8,25.34]],"id":41122648},{"batb":[[1,25,9.48]],"batl":[[2,30,11.91]],"id":55632148},{"tv":86668.63,"batb":[[2,1.83,160.2],[1,1.84,66.35],[0,1.85,68.22]],"trd":[[1.85,14071.08]],"ltp":1.85,"batl":[[2,1.88,282.37],[1,1.87,117.6],[0,1.86,82.3]],"id":51922},{"batb":[[2,4.5,97.56]],"batl":[[0,4.8,121.5]],"id":50466254},{"batb":[[1,20,15.62],[0,21,40.79]],"batl":[[2,24,22.37],[1,23,15.33],[0,22,3.79]],"id":106596}],"tv":119238.35}],"ArrivalTime":1710508068885}
{"op":"mcm","id":2,"clk":"AORPAPNtAOJ4","pt":1710508069034,"mc":[{"id":"1.226122413","rc":[{"tv":8279.46,"batb":[[0,7.8,18.36]],"trd":[[7.8,40.65]],"id":41122648},{"batl":[[2,30,11.31]],"id":55632148},{"tv":86678.63,"batb":[[0,1.85,63.22]],"trd":[[1.85,14081.08]],"batl":[[2,1.88,297.37],[0,1.86,92.59]],"id":51922},{"batb":[[2,4.5,94.31]],"id":50466254}],"tv":119262.31}],"ArrivalTime":1710508069042}
{"op":"mcm","id":2,"clk":"AOxPAP1tAOZ4","pt":1710508069093,"mc":[{"id":"1.226122413","rc":[{"batb":[[1,7.6,71.14]],"id":41122648},{"batb":[[1,1.84,120.96],[0,1.85,177.48]],"batl":[[2,1.88,398.98],[1,1.87,115.6]],"id":51922}]}],"ArrivalTime":1710508069101}
{"op":"mcm","id":2,"clk":"APNPAIZuAPJ4","pt":1710508069190,"mc":[{"id":"1.226122413","rc":[{"batb":[[0,7.8,6.59]],"batl":[[2,8.4,29.39],[0,8,50.06]],"id":41122648},{"batb":[[2,1.83,162.77],[1,1.84,150.79]],"id":51922}]}],"ArrivalTime":1710508069198}
{"op":"mcm","id":2,"clk":"APtPAI5uAP14","pt":1710508069298,"mc":[{"id":"1.226122413","rc":[{"batb":[[1,7.6,52.15]],"id":41122648},{"batb":[[2,1.83,167.8]],"id":51922},{"batb":[[0,21,37.38]],"id":106596}]}],"ArrivalTime":1710508069306}
{"op":"mcm","id":2,"clk":"AIBQAJZuAIp5","pt":1710508069394,"mc":[{"id":"1.226122413","rc":[{"tv":8288.97,"batb":[[2,7.4,54.01],[0,7.8,1.84]],"trd":[[7.8,50.16]],"id":41122648},{"tv":86722.63,"batb":[[0,1.85,155.48]],"trd":[[1.85,14125.08]],"id":51922},{"batl":[[2,200,3.82]],"id":66251581}],"tv":119315.82}],"ArrivalTime":1710508069402}
{"op":"mcm","id":2,"clk":"AIlQAKBuAJR5","pt":1710508069504,"mc":[{"id":"1.226122413","rc":[{"tv":8292.65,"batb":[[2,7.2,40.92],[1,7.4,54.01],[0,7.6,52.15]],"trd":[[7.8,53.84]],"batl":[[0,8,50.22]],"id":41122648},{"tv":87012.97,"batb":[[1,1.84,151.82],[0,1.85,10.31]],"trd":[[1.85,14415.42]],"id":51922}],"tv":119609.84}],"ArrivalTime":1710508069511}
{"op":"mcm","id":2,"clk":"AI9QAKtuAKF5","pt":1710508069606,"mc":[{"id":"1.226122413","rc":[{"batl":[[2,8.2,62.87],[1,8,52.06],[0,7.8,11.42]],"id":41122648},{"batl":[[2,310,1.71],[1,300,2.07]],"id":41200638}]}],"ArrivalTime":1710508069613}
{"op":"mcm","id":2,"clk":"AJlQALluAKl5","pt":1710508069710,"mc":[{"id":"1.226122413","rc":[{"tv":8303.11,"batb":[[1,7.4,51.82]],"trd":[[7.8,64.3]],"batl":[[2,8.2,55.6],[0,7.8,6.18]],"id":41122648},{"tv":87017.67,"batb":[[0,1.85,7.96]],"trd":[[1.85,14420.12]],"batl":[[1,1.87,112.51],[0,1.86,121.08]],"id":51922},{"batl":[[0,4.8,86.8]],"id":50466254},{"batb":[[0,21,41.49]],"batl":[[2,24,21.12]],"id":106596}],"tv":119625}],"ArrivalTime":1710508069718}
{"op":"mcm","id":2,"clk":"AKNQAL5uALZ5","pt":1710508069812,"mc":[{"id":"1.226122413","rc":[{"batb":[[0,330,1.07]],"id":54370634},{"batb":[[2,7.2,58.07],[1,7.4,54.01],[0,7.6,54.19]],"id":41122648},{"batl":[[2,5,84.28]],"id":50466254}]}],"ArrivalTime":1710508069819}
{"op":"mcm","id":2,"clk":"AK1QAMhuAMJ5","pt":1710508069920,"mc":[{"id":"1.226122413","rc":[{"batl":[[2,8.4,29.39],[1,8.2,55.6],[0,8,52.06]],"id":41122648},{"batb":[[2,1.82,225.48],[1,1.83,167.8],[0,1.84,151.82]],"batl":[[2,1.87,112.51],[1,1.86,121.08],[0,1.85,37.97]],"id":51922},{"batl":[[2,40,7.82],[1,38,10.72],[0,36,15.45]],"id":49744721},{"batl":[[2,200,2.82]],"id":66251581}]}],"ArrivalTime":1710508069928}
{"op":"mcm","id":2,"clk":"ALRQANJuAMx5","pt":1710508070002,"mc":[{"id":"1.226122413","rc":[{"batb":[[2,320,8.39],[1,330,1],[0,340,1.07]],"id":54370634}]}],"ArrivalTime":1710508070009}
{"op":"mcm","id":2,"clk":"ALhQAN5uANd5","pt":1710508070077,"mc":[{"id":"1.226122413","rc":[{"batb":[[1,7.4,51.82],[0,7.6,52.15]],"id":41122648},{"batb":[[2,200,2.53],[1,210,5.07],[0,220,1.48]],"batl":[[2,320,1.71],[1,310,1.71],[0,300,2.07]],"id":41200638},{"tv":87019.73,"trd":[[1.85,14422.18]],"batl":[[2,1.87,114.51],[0,1.85,36.94]],"id":51922},{"tv":2601.67,"batb":[[0,34,7.17]],"trd":[[34,248.87]],"ltp":34,"batl":[[1,38,8.72],[0,36,18.44]],"id":49744721},{"tv":16079.32,"batb":[],"trd":[[4.8,30.48]],"batl":[[0,4.8,85.48]],"id":50466254}],"tv":119640.26}],"ArrivalTime":1710508070085}
{"op":"mcm","id":2,"clk":"AL5QAOhuAON5","pt":1710508070180,"mc":[{"id":"1.226122413","rc":[{"batb":[[2,210,5.07],[1,220,1.15],[0,230,1.42]],"id":41200638},{"tv":87029.73,"batb":[[0,1.84,146.82]],"trd":[[1.84,12780.92]],"ltp":1.84,"id":51922}],"tv":119650.26}],"ArrivalTime":1710508070187}
{"op":"mcm","id":2,"clk":"AMFQAPFuAOx5","pt":1710508070283,"mc":[{"id":"1.226122413","rc":[{"batb":[[0,34,4.05]],"id":49744721},{"batl":[[2,210,5],[1,200,2.82],[0,190,1.66]],"id":66251581},{"batb":[[1,20,10.47]],"id":106596}]}],"ArrivalTime":1710508070291}
{"op":"mcm","id":2,"clk":"AMhQAP1uAPR5","pt":1710508070386,"mc":[{"id":"1.226122413","rc":[{"batb":[[1,7.4,54.01]],"id":41122648}]}],"ArrivalTime":1710508070394}
{"op":"mcm","id":2,"clk":"AMxQAIVvAP95","pt":1710508070489,"mc":[{"id":"1.226122413","rc":[{"tv":87195.79,"batb":[[2,1.82,230.51],[0,1.84,64.82]],"trd":[[1.85,14424.24],[1.84,12944.92]],"ltp":1.85,"batl":[[0,1.85,35.91]],"id":51922},{"batb":[[2,19.5,40.25]],"id":106596}],"tv":119816.32}],"ArrivalTime":1710508070497}
{"op":"mcm","id":2,"clk":"ANBQAI9vAI16","pt":1710508070605,"mc":[{"id":"1.226122413","rc":[{"batb":[[2,320,5.86]],"id":54370634},{"batb":[[1,1.83,168.8]],"batl":[[0,1.85,74.86]],"id":51922},{"tv":2257.74,"batb":[[0,21,41.78]],"trd":[[22,105.59]],"batl":[[2,25,7.34],[1,24,21.12],[0,23,15.33]],"id":106596}],"tv":119823.9}],"ArrivalTime":1710508070613}
{"op":"mcm","id":2,"clk":"ANdQAJBvAJZ6","pt":1710508070700,"mc":[{"id":"1.226122413","rc":[{"batb":[[0,340,3.07]],"batl":[[1,580,3.65]],"id":54370634},{"batb":[[2,7.4,54.01],[1,7.6,61.15],[0,7.8,7.84]],"batl":[[2,8.4,26.39],[0,8,44.29]],"id":41122648},{"batb":[[2,210,2.77],[1,220,1.99],[0,230,4.19]],"batl":[[0,300,1.71]],"id":41200638},{"batl":[[2,40,10.38],[0,36,20.44]],"id":49744721},{"tv":16095.32,"trd":[[4.8,46.48]],"batl":[[0,4.8,77.48]],"id":50466254}],"tv":119839.9}],"ArrivalTime":1710508070708}
{"op":"mcm","id":2,"clk":"AN1QAJlvAKV6","pt":1710508070814,"mc":[{"id":"1.226122413","rc":[{"batb":[[1,7.6,52.15]],"id":41122648},{"batb":[[1,1.83,171.21]],"batl":[[1,1.86,143.64]],"id":51922},{"tv":16099.32,"batb":[[2,4.5,97.56],[0,4.7,64.36]],"trd":[[4.7,195.46]],"ltp":4.7,"id":50466254},{"tv":2258.33,"batb":[[2,19.5,37],[0,21,41.49]],"trd":[[22,106.18]],"batl":[[0,23,12.58]],"id":106596}],"tv":119844.49}],"ArrivalTime":1710508070822}
{"op":"mcm","id":2,"clk":"AOJQAKNvAK56","pt":1710508070912,"mc":[{"id":"1.226122413","rc":[{"batb":[[1,7.6,54.19]],"batl":[[0,8,34.29]],"id":41122648},{"tv":87202.31,"batb":[[0,1.84,61.56]],"trd":[[1.84,12951.44]],"ltp":1.84,"batl":[[1,1.86,146.79],[0,1.85,123.29]],"id":51922},{"batl":[[2,250,3.14],[1,210,5],[0,200,3.48]],"id":66251581}],"tv":119851.01}],"ArrivalTime":1710508070920}
{"op":"mcm","id":2,"clk":"AOxQAK9vALx6","pt":1710508071027,"mc":[{"id":"1.226122413","rc":[{"batb":[[0,1.84,32.76]],"batl":[[2,1.87,117.6]],"id":51922},{"batl":[[2,210,5],[1,200,2.82],[0,180,1.66]],"id":66251581}]}],"ArrivalTime":1710508071035}
{"op":"mcm","id":2,"clk":"APBQALZvAMt6","pt":1710508071126,"mc":[{"id":"1.226122413","rc":[{"batb":[[1,330,2.58]],"id":54370634},{"tv":8323.11,"batb":[[0,7.8,14.07]],"trd":[[7.8,84.3]],"batl":[[0,8,36.29]],"id":41122648},{"batb":[[2,220,2.99],[1,230,3.42],[0,240,1.8]],"batl":[],"id":41200638},{"tv":87222.31,"batb":[[1,1.83,148.21],[0,1.84,51.09]],"trd":[[1.85,14444.24]],"ltp":1.85,"batl":[[1,1.86,143.64],[0,1.85,64.86]],"id":51922},{"tv":554.63,"batb":[[0,140,4.16]],"trd":[[150,66.76]],"id":66251581}],"tv":119891.03}],"ArrivalTime":1710508071133}
{"op":"mcm","id":2,"clk":"APlQALxvANR6","pt":1710508071178,"mc":[{"id":"1.226122413","rc":[{"batl":[[2,1.87,116.51]],"id":51922},{"batb":[[2,4.5,94.31]],"id":50466254}]}],"ArrivalTime":1710508071186}
{"op":"mcm","id":2,"clk":"AINRAMNvAN16","pt":1710508071277,"mc":[{"id":"1.226122413","rc":[{"batb":[[1,7.6,52.15],[0,7.8,22.24]],"id":41122648},{"batl":[[2,1.87,191.51],[0,1.85,89.86]],"id":51922},{"batl":[[0,23,15.26]],"id":106596}]}],"ArrivalTime":1710508071285}
{"op":"mcm","id":2,"clk":"AIlRAMlvAOd6","pt":1710508071383,"mc":[{"id":"1.226122413","rc":[{"batb":[[0,140,2.73]],"id":66251581}]}],"ArrivalTime":1710508071391}
{"op":"mcm","id":2,"clk":"AI1RAM1vAPF6","pt":1710508071489,"mc":[{"id":"1.226122413","rc":[{"batb":[[1,330,1.58],[0,340,2.07]],"id":54370634},{"batb":[[2,7.4,71.4],[1,7.6,36.65],[0,7.8,8.17]],"batl":[[0,8,22.54]],"id":41122648},{"batb":[[2,210,2.77],[1,220,1.84],[0,230,3.1]],"id":41200638},{"batb":[[0,26,5.47]],"id":55632148},{"tv":87324.49,"batb":[[2,1.81,211.54],[1,1.82,230.51],[0,1.83,81.16]],"trd":[[1.84,13053.62]],"ltp":1.84,"batl":[[2,1.86,143.64],[1,1.85,117.01],[0,1.84,300.31]],"id":51922},{"batb":[[2,30,35.57],[1,32,15.54],[0,34,3]],"batl":[[2,40,13.05],[0,36,17.45]],"id":49744721},{"batb":[[0,4.7,31.81]],"batl":[[2,5,116.66],[1,4.9,30.33]],"id":50466254},{"batb":[[1,130,1],[0,140,1.63]],"id":66251581},{"batb":[[0,21,37.38]],"batl":[[0,23,4.69]],"id":106596}],"tv":119993.21}],"ArrivalTime":1710508071497}
{"op":"mcm","id":2,"clk":"AJNRANJvAPx6","pt":1710508071594,"mc":[{"id":"1.226122413","rc":[{"batb":[[1,7.6,38.69]],"id":41122648},{"tv":87675.27,"trd":[[1.84,13404.4]],"batl":[[2,1.86,168.64],[0,1.84,124.92]],"id":51922},{"batb":[[2,4.5,97.56]],"id":50466254},{"tv":555.95,"batb":[[2,130,1],[1,140,1.63],[0,160,5.31]],"trd":[[160,24.64]],"ltp":160,"batl":[[0,180,1]],"id":66251581}],"tv":120345.31}],"ArrivalTime":1710508071602}
{"op":"mcm","id":2,"clk":"AJtRAOBvAIt7","pt":1710508071702,"mc":[{"id":"1.226122413","rc":[{"batb":[[0,7.8,16.75]],"id":41122648},{"batb":[[1,220,7.84]],"batl":[[2,310,1.71],[1,300,1.71],[0,290,1]],"id":41200638},{"batb":[[2,1.81,274.61],[1,1.82,164.16],[0,1.83,40.16]],"id":51922},{"batl":[[0,23,2.01]],"id":106596}]}],"ArrivalTime":1710508071710}
{"op":"mcm","id":2,"clk":"AKBRAOlvAJN7","pt":1710508071803,"mc":[{"id":"1.226122413","rc":[{"batb":[[1,25,8.48]],"id":55632148},{"tv":87689.8,"batb":[[0,1.83,38.28]],"trd":[[1.84,13415.18],[1.83,7968.45]],"ltp":1.83,"batl":[[2,1.86,161.96],[0,1.84,119.53]],"id":51922},{"batb":[[2,130,2.13],[0,160,6.31]],"batl":[[0,180,1.56]],"id":66251581},{"batb":[[2,20,10.47],[1,21,40.38],[0,22,3.58]],"id":106596}],"tv":120359.84}],"ArrivalTime":1710508071811}
{"op":"mcm","id":2,"clk":"AKZRAPJvAKJ7","pt":1710508071905,"mc":[{"id":"1.226122413","rc":[{"batb":[[1,7.6,36.65]],"id":41122648},{"batb":[[1,1.82,226.89]],"batl":[[2,1.86,165.11],[1,1.85,142.01],[0,1.84,161.77]],"id":51922},{"batb":[[0,4.7,33.97]],"id":50466254}]}],"ArrivalTime":1710508071913}
{"op":"mcm","id":2,"clk":"AKxRAPtvALN7","pt":1710508072014,"mc":[{"id":"1.226122413","rc":[{"batl":[[1,1.85,145.21]],"id":51922},{"batb":[[0,22,6.51]],"id":106596}]}],"ArrivalTime":1710508072022}
{"op":"mcm","id":2,"clk":"ALlRAI9wAMd7","pt":1710508072221,"mc":[{"id":"1.226122413","rc":[{"tv":8356.61,"batb":[[2,7.2,58.07],[1,7.4,71.4],[0,7.6,36.65]],"trd":[[7.8,117.8]],"batl":[[2,8.2,55.6],[1,8,22.54],[0,7.8,42.25]],"id":41122648},{"tv":87692.44,"trd":[[1.84,13417.82]],"ltp":1.84,"batl":[[0,1.84,168.14]],"id":51922},{"tv":16103.32,"batb":[[0,4.7,31.97]],"trd":[[4.7,199.46]],"id":50466254}],"tv":120399.98}],"ArrivalTime":1710508072228}
{"op":"mcm","id":2,"clk":"AL5RAJhwANV7","pt":1710508072325,"mc":[{"id":"1.226122413","rc":[{"batl":[[2,8.2,62.59]],"id":41122648},{"batl":[[2,1.86,161.96],[1,1.85,142.01],[0,1.84,125.9]],"id":51922}]}],"ArrivalTime":1710508072332}
{"op":"mcm","id":2,"clk":"AMJRAKNwAOV7","pt":1710508072428,"mc":[{"id":"1.226122413","rc":[{"batb":[[2,320,4.61]],"id":54370634},{"tv":8360.49,"batb":[[2,7.2,66.07],[0,7.6,38.69]],"trd":[[7.8,121.68]],"batl":[[2,8.2,65.16],[1,8,30.42],[0,7.8,40.31]],"id":41122648},{"batl":[[2,32,15.49],[1,30,11.31],[0,29,5.6]],"id":55632148},{"batb":[[0,1.83,79.86]],"batl":[],"id":51922},{"batb":[[0,34,5.86]],"id":49744721},{"tv":16144.88,"trd":[[4.8,88.04]],"ltp":4.8,"batl":[[0,4.8,41.08]],"id":50466254},{"batb":[[1,21,45.02],[0,22,10.58]],"batl":[[1,24,18.11]],"id":106596}],"tv":120445.42}],"ArrivalTime":1710508072436}
{"op":"mcm","id":2,"clk":"AMZRAKxwAPB7","pt":1710508072532,"mc":[{"id":"1.226122413","rc":[{"batb":[[0,7.6,36.65]],"batl":[[2,8.2,61.78]],"id":41122648}]}],"ArrivalTime":1710508072540}
{"op":"mcm","id":2,"clk":"ANBRALpwAP57","pt":1710508072601,"mc":[{"id":"1.226122413","rc":[{"batl":[[1,8,46.79]],"id":41122648},{"batb":[[2,25,8.48],[1,26,5.47],[0,27,2.21]],"id":55632148},{"batl":[[2,1.86,145.97],[0,1.84,130.9]],"id":51922},{"tv":16227.04,"batb":[[2,4.6,223.33],[1,4.7,52.67],[0,4.8,61.04]],"trd":[[4.8,170.2]],"batl":[[2,5.1,35.69],[1,5,116.66],[0,4.9,30.33]],"id":50466254},{"tv":2262.35,"batb":[[2,21,45.02],[1,22,10.58],[0,23,1.2]],"trd":[[23,81.62]],"ltp":23,"batl":[[2,26,10],[1,25,7.34],[0,24,18.11]],"id":106596}],"tv":120531.6}],"ArrivalTime":1710508072609}
{"op":"mcm","id":2,"clk":"ANZRAMZwAIx8","pt":1710508072698,"mc":[{"id":"1.226122413","rc":[{"tv":481.24,"batb":[[2,200,2.53],[1,210,2.77],[0,220,7.85]],"trd":[[240,8.85],[230,5.22]],"ltp":230,"id":41200638},{"batl":[[0,29,2.68]],"id":55632148},{"tv":87733.52,"batb":[[0,1.83,72.17]],"trd":[[1.84,13443.52],[1.83,7983.83]],"ltp":1.83,"batl":[[0,1.84,318.05]],"id":51922},{"batb":[[0,160,8.56]],"id":66251581}],"tv":120578.87}],"ArrivalTime":1710508072706}
{"op":"mcm","id":2,"clk":"ANxRAM9wAJZ8","pt":1710508072801,"mc":[{"id":"1.226122413","rc":[{"batb":[[2,7.2,84.23],[0,7.6,35.33]],"batl":[[1,8,49.79]],"id":41122648},{"batb":[[2,210,2.77],[1,220,7.84],[0,230,2.03]],"id":41200638},{"tv":1984.58,"batb":[[2,24,16.98],[1,25,8.48],[0,26,5.66]],"trd":[[27,270.67]],"batl":[[2,32,16.57]],"id":55632148},{"batb":[[1,1.82,164.16]],"batl":[[2,1.86,149.12],[1,1.85,145.21],[0,1.84,375.61]],"id":51922},{"batb":[[0,4.8,46.06]],"batl":[[2,5.1,66.96],[1,5,84.28],[0,4.9,28.49]],"id":50466254},{"tv":2264.75,"batb":[[2,20,10.47],[1,21,45.02],[0,22,10.58]],"trd":[[23,84.02]],"batl":[[2,25,7.34],[1,24,18.11],[0,23,4.25]],"id":106596}],"tv":120585.31}],"ArrivalTime":1710508072810}
{"op":"mcm","id":2,"clk":"AONRANpwAKB8","pt":1710508072906,"mc":[{"id":"1.226122413","rc":[{"batl":[[1,580,3.44]],"id":54370634},{"batl":[[1,8,47.79]],"id":41122648},{"batb":[[2,200,2.53],[1,210,1.58],[0,220,9.96]],"id":41200638},{"tv":87748.9,"batb":[[0,1.83,44.9]],"trd":[[1.83,7999.21]],"batl":[[2,1.86,133.24],[1,1.85,147.21]],"id":51922},{"batb":[[0,4.8,18.32]],"id":50466254},{"batb":[[1,21,51.09]],"batl":[[1,24,10.48]],"id":106596}],"tv":120600.69}],"ArrivalTime":1710508072914}
{"op":"mcm","id":2,"clk":"AOtRAOpwAKl8","pt":1710508073033,"mc":[{"id":"1.226122413","rc":[{"batb":[[2,320,1]],"id":54370634},{"batb":[[1,25,14.4]],"batl":[[2,32,15.49]],"id":55632148},{"tv":87795.4,"batb":[[0,1.83,3.32]],"trd":[[1.84,13490.02]],"ltp":1.84,"batl":[[0,1.84,349.1]],"id":51922}],"tv":120647.19}],"ArrivalTime":1710508073041}
{"op":"mcm","id":2,"clk":"APJRAO9wALZ8","pt":1710508073140,"mc":[{"id":"1.226122413","rc":[{"batb":[[2,330,1.58],[1,340,2.07],[0,350,1.15]],"id":54370634},{"tv":87802.04,"batb":[[2,1.8,473.63],[1,1.81,274.61],[0,1.82,164.16]],"trd":[[1.83,8005.85]],"ltp":1.83,"batl":[[2,1.85,149.21],[1,1.84,349.1],[0,1.83,4.36]],"id":51922},{"batb":[[1,4.7,62.88]],"id":50466254},{"batb":[[1,21,45.02]],"id":106596}],"tv":120653.83}],"ArrivalTime":1710508073148}
{"op":"mcm","id":2,"clk":"APZRAPRwALx8","pt":1710508073183,"mc":[{"id":"1.226122413","rc":[{"batb":[[2,25,14.4],[1,26,5.47],[0,27,2.15]],"id":55632148},{"tv":87880.55,"trd":[[1.83,8084.36]],"batl":[[1,1.84,352.36],[0,1.83,15.11]],"id":51922},{"batl":[[2,26,10],[1,25,7.34],[0,24,10.48]],"id":106596}],"tv":120732.34}],"ArrivalTime":1710508073191}
{"op":"mcm","id":2,"clk":"APpRAP1wAMN8","pt":1710508073294,"mc":[{"id":"1.226122413","rc":[{"batb":[[1,340,3.07]],"id":54370634},{"batb":[[0,27,5.74]],"id":55632148},{"tv":87955.41,"batb":[[1,1.81,183.94]],"trd":[[1.83,8159.22]],"batl":[[1,1.84,298.06],[0,1.83,29.01]],"id":51922},{"tv":16263.92,"batb":[[0,4.8,23.45]],"trd":[[4.9,37.3]],"ltp":4.9,"batl":[[0,4.9,10.05]],"id":50466254}],"tv":120844.08}],"ArrivalTime":1710508073301}
{"op":"mcm","id":2,"clk":"AP9RAIZxAM98","pt":1710508073400,"mc":[{"id":"1.226122413","rc":[{"batb":[[0,350,4.45]],"id":54370634},{"tv":87966.69,"trd":[[1.83,8170.5]],"batl":[[1,1.84,324.1],[0,1.83,28.37]],"id":51922}],"tv":120855.36}],"ArrivalTime":1710508073408}
{"op":"mcm","id":2,"clk":"AIVSAI5xANt8","pt":1710508073500,"mc":[{"id":"1.226122413","rc":[{"batb":[[2,1.8,537.15],[1,1.81,120.87]],"id":51922},{"tv":16284.01,"batb":[[2,4.7,62.88],[1,4.8,35.97],[0,4.9,41.95]],"trd":[[4.9,57.39]],"batl":[[2,5.2,66.77],[1,5.1,66.96],[0,5,80.5]],"id":50466254}],"tv":120875.45}],"ArrivalTime":1710508073509}
{"op":"mcm","id":2,"clk":"AJBSAJZxAOV8","pt":1710508073598,"mc":[{"id":"1.226122413","rc":[{"tv":87970.69,"batb":[],"trd":[[1.83,8174.5]],"batl":[[0,1.83,26.37]],"id":51922},{"tv":16322.95,"batb":[[2,4.6,223.33],[1,4.7,62.88],[0,4.8,35.97]],"trd":[[4.9,96.33]],"batl":[[1,5.1,35.69]],"id":50466254}],"tv":120918.39}],"ArrivalTime":1710508073606}
{"op":"mcm","id":2,"clk":"AJxSAKRxAPB8","pt":1710508073715,"mc":[{"id":"1.226122413","rc":[{"tv":88170.7,"batb":[[0,1.82,24.15]],"trd":[[1.82,3955.46]],"ltp":1.82,"batl":[[0,1.83,29.68]],"id":51922},{"tv":16368.23,"batb":[[0,4.8,15.97]],"trd":[[4.9,101.61],[4.8,210.2]],"ltp":4.8,"batl":[],"id":50466254}],"tv":121163.68}],"ArrivalTime":1710508073723}
{"op":"mcm","id":2,"clk":"AKBSAKhxAPZ8","pt":1710508073810,"mc":[{"id":"1.226122413","rc":[{"tv":8380.49,"trd":[[7.8,141.68]],"batl":[[0,7.8,30.31]],"id":41122648},{"tv":88230.06,"batb":[[2,1.81,120.87],[1,1.82,24.15],[0,1.83,30.57]],"trd":[[1.83,8233.86]],"ltp":1.83,"batl":[[2,1.86,118.24],[1,1.85,174.21],[0,1.84,324.1]],"id":51922},{"batb":[[2,4.7,62.88],[1,4.8,15.97],[0,4.9,1.26]],"batl":[[1,5.1,66.25]],"id":50466254}],"tv":121243.04}],"ArrivalTime":1710508073817}
{"op":"mcm","id":2,"clk":"AKRSALZxAId9","pt":1710508073913,"mc":[{"id":"1.226122413","rc":[{"tv":88391.2,"batb":[[2,1.79,134.53],[1,1.8,537.15],[0,1.81,95.02]],"trd":[[1.81,1352.85],[1.83,8295],[1.82,4003.76]],"ltp":1.81,"batl":[[2,1.85,171.01],[1,1.84,313.15],[0,1.83,9.23]],"id":51922}],"tv":121404.18}],"ArrivalTime":1710508073921}
{"op":"mcm","id":2,"clk":"AKpSAMBxAJJ9","pt":1710508074022,"mc":[{"id":"1.226122413","rc":[{"batl":[[0,7.8,33.6]],"id":41122648},{"batb":[[0,27,2.15]],"id":55632148},{"tv":88545.08,"batb":[[0,1.81,157.77]],"trd":[[1.82,4157.64]],"ltp":1.82,"batl":[[2,1.84,315.15],[1,1.83,214.95],[0,1.82,23.06]],"id":51922},{"tv":16370.75,"batb":[[2,4.6,223.33],[1,4.7,62.88],[0,4.8,30.56]],"trd":[[4.9,104.13]],"ltp":4.9,"batl":[[2,5.1,66.25],[1,5,80.5],[0,4.9,31.65]],"id":50466254}],"tv":121560.58}],"ArrivalTime":1710508074030}
{"op":"mcm","id":2,"clk":"AK1SANNxAJx9","pt":1710508074128,"mc":[{"id":"1.226122413","rc":[{"batl":[[1,8,31.42]],"id":41122648},{"tv":88575.08,"batb":[[2,1.79,262.2]],"trd":[[1.82,4187.64]],"batl":[[1,1.83,122.32],[0,1.82,8.06]],"id":51922},{"tv":16405.8,"trd":[[4.9,139.18]],"batl":[[0,4.9,14.13]],"id":50466254}],"tv":121625.63}],"ArrivalTime":1710508074135}
{"op":"mcm","id":2,"clk":"ALFSANlxAKZ9","pt":1710508074238,"mc":[{"id":"1.226122413","rc":[{"tv":8383.53,"batb":[[0,7.6,37.37]],"trd":[[7.8,144.72]],"batl":[[0,7.8,30.79]],"id":41122648},{"batb":[[0,27,6.74]],"id":55632148},{"tv":88576.62,"batb":[[0,1.81,183.84]],"trd":[[1.82,4189.18]],"batl":[[1,1.83,122.36],[0,1.82,7.29]],"id":51922},{"batb":[[2,4.7,62.88],[1,4.8,30.56],[0,4.9,18.58]],"batl":[[2,5.2,66.77],[1,5.1,66.25],[0,5,80.5]],"id":50466254},{"batb":[[1,21,48.79]],"batl":[[1,25,15.8]],"id":106596}],"tv":121630.21}],"ArrivalTime":1710508074246}
{"op":"mcm","id":2,"clk":"ALZSAORxALV9","pt":1710508074284,"mc":[{"id":"1.226122413","rc":[{"batb":[[1,340,1.07]],"id":54370634},{"tv":8385.59,"batb":[[1,7.4,61.11]],"trd":[[7.8,146.78]],"batl":[[1,8,47.42],[0,7.8,29.76]],"id":41122648},{"batb":[[0,220,9.12]],"id":41200638},{"tv":88591.2,"batb":[[2,1.8,537.15],[1,1.81,183.84],[0,1.82,29.35]],"trd":[[1.82,4203.76]],"batl":[[2,1.85,171.01],[1,1.84,315.15],[0,1.83,122.36]],"id":51922},{"tv":16417.58,"batb":[[0,4.9,12.69]],"trd":[[4.9,150.96]],"batl":[[1,5.1,35.69]],"id":50466254}],"tv":121658.63}],"ArrivalTime":1710508074291}
{"op":"mcm","id":2,"clk":"ALxSAO1xAMJ9","pt":1710508074396,"mc":[{"id":"1.226122413","rc":[{"batb":[[0,7.6,35.33]],"id":41122648},{"tv":88649.9,"batb":[[2,1.79,262.2],[1,1.8,537.15],[0,1.81,121.09]],"trd":[[1.82,4262.46]],"batl":[[2,1.84,315.15],[1,1.83,148.14],[0,1.82,61.89]],"id":51922},{"batb":[[2,4.6,223.33],[1,4.7,62.88],[0,4.8,30.56]],"batl":[],"id":50466254}],"tv":121717.33}],"ArrivalTime":1710508074404}
{"op":"mcm","id":2,"clk":"AMJSAPNxAM59","pt":1710508074499,"mc":[{"id":"1.226122413","rc":[{"batl":[[2,8.2,59.78]],"id":41122648},{"tv":88805.44,"batb":[[2,1.8,537.15],[1,1.81,121.09],[0,1.82,26.7]],"trd":[[1.82,4386.24],[1.83,8326.76]],"ltp":1.83,"batl":[[2,1.85,148.36],[1,1.84,315.15],[0,1.83,132.26]],"id":51922},{"batl":[[1,5.1,65.78]],"id":50466254}],"tv":121872.87}],"ArrivalTime":1710508074506}
{"op":"mcm","id":2,"clk":"AMhSAINyAN19","pt":1710508074610,"mc":[{"id":"1.226122413","rc":[{"tv":8393.37,"batb":[[0,7.6,37.37]],"trd":[[7.8,154.56]],"batl":[[0,7.8,25.87]],"id":41122648},{"batl":[[2,34,27.07],[1,32,15.49],[0,30,11.64]],"id":55632148},{"batb":[[0,1.82,34.39]],"batl":[],"id":51922},{"tv":2605.67,"batb":[[0,34,3.86]],"trd":[[34,252.87]],"id":49744721},{"batb":[[0,4.8,49.96]],"batl":[],"id":50466254}],"tv":121884.65}],"ArrivalTime":1710508074618}
{"op":"mcm","id":2,"clk":"AM1SAItyAOV9","pt":1710508074702,"mc":[{"id":"1.226122413","rc":[{"batb":[[0,7.6,35.33]],"batl":[[1,8,31.42]],"id":41122648}]}],"ArrivalTime":1710508074710}
{"op":"mcm","id":2,"clk":"ANdSAJtyAPV9","pt":1710508074837,"mc":[{"id":"1.226122413","rc":[{"batb":[[1,7.4,58.92]],"id":41122648},{"tv":88971.88,"trd":[[1.83,8493.2]],"batl":[[0,1.83,49.04]],"id":51922}],"tv":122051.09}],"ArrivalTime":1710508074844}
{"op":"mcm","id":2,"clk":"AN9SAKByAPp9","pt":1710508074923,"mc":[{"id":"1.226122413","rc":[{"batl":[[0,1.83,23.26]],"id":51922}]}],"ArrivalTime":1710508074931}
{"op":"mcm","id":2,"clk":"AONSAKhyAIJ+","pt":1710508075015,"mc":[{"id":"1.226122413","rc":[{"batl":[[1,32,22.4]],"id":55632148},{"tv":89061.88,"batb":[[0,1.82,54.9]],"trd":[[1.82,4476.24]],"ltp":1.82,"batl":[[0,1.83,84.64]],"id":51922},{"batb":[[0,34,1]],"id":49744721},{"batb":[[0,4.8,30.56]],"id":50466254}],"tv":122141.09}],"ArrivalTime":1710508075023}
{"op":"mcm","id":2,"clk":"AOpSAK9yAJJ+","pt":1710508075133,"mc":[{"id":"1.226122413","rc":[{"tv":89202.18,"batb":[[2,1.79,262.2],[1,1.8,537.15],[0,1.81,121.09]],"trd":[[1.83,8508.32],[1.82,4601.42]],"batl":[[2,1.84,315.15],[1,1.83,77.08],[0,1.82,137.41]],"id":51922}],"tv":122281.39}],"ArrivalTime":1710508075141}
{"op":"mcm","id":2,"clk":"APNSALlyAJ5+","pt":1710508075191,"mc":[{"id":"1.226122413","rc":[{"tv":89376.32,"trd":[[1.82,4775.56]],"batl":[[2,1.84,340.15],[0,1.82,60.34]],"id":51922}],"tv":122455.53}],"ArrivalTime":1710508075199}
{"op":"mcm","id":2,"clk":"APpSAMJyAKl+","pt":1710508075291,"mc":[{"id":"1.226122413","rc":[{"batb":[[1,7.4,61.11]],"id":41122648},{"tv":89497,"batb":[[2,1.8,537.15],[1,1.81,121.09],[0,1.82,13.55]],"trd":[[1.82,4896.24]],"batl":[[2,1.85,148.36],[1,1.84,340.15],[0,1.83,77.08]],"id":51922}],"tv":122576.21}],"ArrivalTime":1710508075299}
{"op":"mcm","id":2,"clk":"AP5SAMhyALR+","pt":1710508075384,"mc":[{"id":"1.226122413","rc":[{"batl":[[2,300,1.71],[1,290,1],[0,280,2]],"id":41200638},{"tv":89524.1,"batb":[[2,1.79,262.2],[1,1.8,537.15],[0,1.81,121.09]],"trd":[[1.82,4923.34]],"batl":[[2,1.84,340.15],[1,1.83,77.08],[0,1.82,61]],"id":51922},{"batb":[[2,4.6,140]],"id":50466254}],"tv":122603.31}],"ArrivalTime":1710508075391}
{"op":"mcm","id":2,"clk":"AIVTANFyAMJ+","pt":1710508075495,"mc":[{"id":"1.226122413","rc":[{"batb":[[1,7.4,58.92]],"id":41122648},{"tv":89598.84,"batb":[[0,1.81,83.72]],"trd":[[1.81,1427.59]],"ltp":1.81,"batl":[[2,1.85,149.52],[1,1.84,340.15],[0,1.83,77.08]],"id":51922},{"tv":16421.86,"trd":[[5,4.28]],"ltp":5,"batl":[[1,5.1,55.17],[0,5,78.36]],"id":50466254}],"tv":122682.33}],"ArrivalTime":1710508075503}
{"op":"mcm","id":2,"clk":"AJFTANVyAMh+","pt":1710508075607,"mc":[{"id":"1.226122413","rc":[{"batb":[[1,7.4,61.11]],"id":41122648},{"batl":[[2,310,1.71],[1,300,1.71]],"id":41200638},{"batl":[[1,1.84,342.72],[0,1.83,102.33]],"id":51922}]}],"ArrivalTime":1710508075615}
{"op":"mcm","id":2,"clk":"AJdTAONyANJ+","pt":1710508075707,"mc":[{"id":"1.226122413","rc":[{"tv":89599.34,"batb":[[2,1.8,537.15],[1,1.81,83.72],[0,1.82,25.03]],"trd":[[1.82,4923.84]],"ltp":1.82,"batl":[[0,1.83,142.03]],"id":51922},{"batb":[[1,4.7,74.38]],"batl":[],"id":50466254}],"tv":122682.83}],"ArrivalTime":1710508075715}
{"op":"mcm","id":2,"clk":"AJ1TAOpyANp+","pt":1710508075808,"mc":[{"id":"1.226122413","rc":[{"batb":[[1,7.4,58.92]],"id":41122648},{"tv":89664.78,"batb":[[2,1.79,262.2],[1,1.8,537.15],[0,1.81,83.72]],"trd":[[1.83,8523.7],[1.82,4973.9]],"batl":[[2,1.84,342.82],[1,1.83,134.34],[0,1.82,49.08]],"id":51922}],"tv":122748.27}],"ArrivalTime":1710508075815}
{"op":"mcm","id":2,"clk":"AKFTAPZyAOp+","pt":1710508075926,"mc":[{"id":"1.226122413","rc":[{"batb":[[1,7.4,48.92]],"id":41122648},{"batl":[[2,1.85,149.52],[1,1.84,342.82],[0,1.83,134.34]],"id":51922},{"tv":2609.07,"batb":[[2,29,20.78],[1,30,35.57],[0,32,14.84]],"trd":[[34,254.87],[32,197.8]],"ltp":32,"id":49744721}],"tv":122751.67}],"ArrivalTime":1710508075934}
{"op":"mcm","id":2,"clk":"AKhTAPdyAPR+","pt":1710508076030,"mc":[{"id":"1.226122413","rc":[{"batb":[[1,7.4,51.11]],"batl":[[1,8,28.42]],"id":41122648}]}],"ArrivalTime":1710508076037}
{"op":"mcm","id":2,"clk":"AK9TAP9yAIR/","pt":1710508076122,"mc":[{"id":"1.226122413","rc":[{"tv":8399.37,"batb":[[0,7.6,32.33]],"trd":[[7.6,96.13]],"ltp":7.6,"id":41122648},{"tv":2611.41,"batb":[[0,32,17.22]],"trd":[[36,132.5]],"ltp":36,"batl":[[0,36,16.28]],"id":49744721}],"tv":122760.01}],"ArrivalTime":1710508076129}
{"op":"mcm","id":2,"clk":"ALZTAI1zAIl/","pt":1710508076224,"mc":[{"id":"1.226122413","rc":[{"batb":[[1,7.4,48.92]],"batl":[[0,7.8,28.22]],"id":41122648},{"tv":89684.78,"batb":[[2,1.8,537.15],[1,1.81,83.72],[0,1.82,16.29]],"trd":[[1.82,4993.9]],"id":51922},{"tv":16425.86,"trd":[[5,8.28]],"batl":[[0,5,76.36]],"id":50466254}],"tv":122784.01}],"ArrivalTime":1710508076232}
{"op":"mcm","id":2,"clk":"ALtTAJdzAJl/","pt":1710508076324,"mc":[{"id":"1.226122413","rc":[{"batb":[[0,32,20.46]],"batl":[[1,38,5.46]],"id":49744721}]}],"ArrivalTime":1710508076331}
{"op":"mcm","id":2,"clk":"AMFTAJ1zAKd/","pt":1710508076433,"mc":[{"id":"1.226122413","rc":[{"batl":[[1,8,43.81]],"id":41122648},{"tv":89717.36,"batb":[[2,1.79,262.2],[1,1.8,537.15],[0,1.81,83.72]],"trd":[[1.82,5026.48]],"batl":[[2,1.84,345.2],[1,1.83,134.34],[0,1.82,27.51]],"id":51922}],"tv":122816.59}],"ArrivalTime":1710508076442}
{"op":"mcm","id":2,"clk":"AMhTAKVzAKx/","pt":1710508076536,"mc":[{"id":"1.226122413","rc":[{"batb":[[2,30,35.57],[1,32,20.46],[0,34,2.79]],"id":49744721},{"batb":[[0,4.8,32.56]],"id":50466254}]}],"ArrivalTime":1710508076544}
{"op":"mcm","id":2,"clk":"AM9TALBzALZ/","pt":1710508076590,"mc":[{"id":"1.226122413","rc":[{"batb":[[1,7.4,51.11]],"id":41122648},{"tv":1994.88,"batb":[[0,27,1.59]],"trd":[[27,280.97]],"id":55632148},{"batl":[[2,1.85,149.52],[1,1.84,345.2],[0,1.83,134.34]],"id":51922},{"tv":558.07,"batb":[[0,160,5.25]],"trd":[[160,26.76]],"id":66251581}],"tv":122829.01}],"ArrivalTime":1710508076597}
{"op":"mcm","id":2,"clk":"ANNTALtzAL9/","pt":1710508076743,"mc":[{"id":"1.226122413","rc":[{"batb":[[0,7.6,34.37]],"id":41122648},{"tv":1998.06,"batb":[[2,24,16.98],[1,25,15.4],[0,26,5.47]],"trd":[[27,284.15]],"id":55632148},{"batb":[[2,1.79,323.53]],"batl":[[2,1.84,360.2],[1,1.83,134.34],[0,1.82,100]],"id":51922},{"batb":[[0,34,6.38]],"id":49744721},{"tv":558.39,"batb":[[0,160,5.09]],"trd":[[160,27.08]],"id":66251581}],"tv":122832.51}],"ArrivalTime":1710508076751}
{"op":"mcm","id":2,"clk":"AN1TAMNzAMZ/","pt":1710508076788,"mc":[{"id":"1.226122413","rc":[{"batl":[[1,1.83,135.34]],"id":51922},{"tv":2614.83,"batb":[[0,34,4.67]],"trd":[[34,258.29]],"ltp":34,"id":49744721},{"batb":[[0,4.8,57.3]],"id":50466254},{"tv":559.51,"batb":[[2,140,1.63],[1,160,5.09],[0,170,1.56]],"trd":[[170,33.4]],"ltp":170,"batl":[[0,180,1]],"id":66251581}],"tv":122837.05}],"ArrivalTime":1710508076796}
{"op":"mcm","id":2,"clk":"AOdTAMtzAM5/","pt":1710508076900,"mc":[{"id":"1.226122413","rc":[{"batb":[[2,25,15.4],[1,26,5.47],[0,27,6.06]],"batl":[[2,32,22.4],[1,30,11.31],[0,29,2.25]],"id":55632148},{"batb":[[0,1.81,293.48]],"batl":[[1,1.83,134.4]],"id":51922},{"batb":[[0,4.8,77.34]],"batl":[[1,5.1,25.08]],"id":50466254},{"batb":[[2,140,2.7]],"id":66251581}]}],"ArrivalTime":1710508076908}
{"op":"mcm","id":2,"clk":"AO9TANtzANl/","pt":1710508077011,"mc":[{"id":"1.226122413","rc":[{"tv":8403.37,"batb":[[0,7.6,30.33]],"trd":[[7.6,100.13]],"batl":[[1,8,28.42]],"id":41122648},{"batb":[[0,27,9.06]],"id":55632148},{"tv":89725.8,"batb":[[1,1.8,473.63],[0,1.81,294.48]],"trd":[[1.82,5034.92]],"batl":[[1,1.83,160.54],[0,1.82,95.78]],"id":51922},{"batb":[[2,4.7,85.07],[1,4.8,77.34],[0,4.9,2]],"batl":[[0,5,77.36]],"id":50466254},{"tv":560.69,"batb":[[2,130,2.13],[1,140,2.7],[0,160,6.06]],"trd":[[170,34.58]],"id":66251581}],"tv":122850.67}],"ArrivalTime":1710508077019}
{"op":"mcm","id":2,"clk":"APZTAOFzAOV/","pt":1710508077112,"mc":[{"id":"1.226122413","rc":[{"tv":376.5,"trd":[[420,1.87],[430,0.07]],"ltp":430,"batl":[[0,430,2.17]],"id":54370634},{"tv":8426.56,"trd":[[7.8,177.75]],"ltp":7.8,"batl":[[0,7.8,5.03]],"id":41122648},{"tv":481.88,"trd":[[280,16.57]],"ltp":280,"batl":[[0,280,1.36]],"id":41200638},{"tv":2004.18,"trd":[[30,37.73],[29,66.99],[28,290.32]],"ltp":30,"batl":[[2,34,27.07],[1,32,22.4],[0,30,7.44]],"id":55632148},{"tv":89825.22,"trd":[[1.82,5134.34]],"batl":[[0,1.82,6.36]],"id":51922},{"tv":2619.85,"batb":[[0,34,6.39]],"trd":[[36,137.52]],"ltp":36,"batl":[[0,36,11.26]],"id":49744721},{"tv":16622.23,"batb":[[2,4.5,94.31],[1,4.6,140],[0,4.7,85.07]],"trd":[[4.9,154.96],[4.8,402.57]],"ltp":4.8,"batl":[[2,5.1,25.08],[1,5,76.38],[0,4.8,314.95]],"id":50466254},{"tv":562.97,"batb":[[0,160,5.42]],"trd":[[180,8.33],[170,35.86]],"ltp":180,"batl":[[2,250,3.14],[1,210,5],[0,200,2.82]],"id":66251581},{"tv":2272.29,"trd":[[24,244.73]],"ltp":24,"batl":[[0,24,2.94]],"id":106596}],"tv":123191.68}],"ArrivalTime":1710508077120}
{"op":"mcm","id":2,"clk":"AIBUAPFzAO9/","pt":1710508077222,"mc":[{"id":"1.226122413","rc":[{"batl":[[1,8,43.59],[0,7.8,6.03]],"id":41122648},{"tv":89837.94,"trd":[[1.82,5147.06]],"batl":[[2,1.85,149.52],[1,1.84,360.2],[0,1.83,120.59]],"id":51922},{"tv":16655.41,"batb":[[2,4.5,97.56]],"trd":[[4.8,435.75]],"batl":[[0,4.8,298.36]],"id":50466254},{"batl":[[1,25,4.43]],"id":106596}],"tv":123237.58}],"ArrivalTime":1710508077230}
{"op":"mcm","id":2,"clk":"AIVUAPVzAPp/","pt":1710508077315,"mc":[{"id":"1.226122413","rc":[{"tv":8438.62,"batb":[[2,7.4,51.11],[1,7.6,32.37],[0,7.8,4.75]],"trd":[[7.8,189.81]],"batl":[[2,8.4,26.39],[1,8.2,59.78],[0,8,43.59]],"id":41122648},{"batb":[[2,26,7.89],[1,27,9.06],[0,28,4.38]],"id":55632148},{"batb":[[2,1.8,534.82],[1,1.81,294.48],[0,1.82,176.18]],"batl":[[0,1.83,94.45]],"id":51922},{"tv":16786.27,"batb":[[1,4.6,143.09],[0,4.7,64.37]],"trd":[[4.8,566.61]],"batl":[[2,5,105.7],[1,4.9,18.96],[0,4.8,232.93]],"id":50466254},{"batb":[[0,160,5.87]],"batl":[[2,250,1.14]],"id":66251581},{"tv":2277.43,"batb":[[0,22,15.06]],"trd":[[24,249.87]],"batl":[[2,27,9.26],[1,26,10],[0,25,5.17]],"id":106596}],"tv":123385.64}],"ArrivalTime":1710508077323}
{"op":"mcm","id":2,"clk":"AIlUAIh0AISAAQ==","pt":1710508077434,"mc":[{"id":"1.226122413","rc":[{"batb":[[1,7.6,33.69]],"batl":[[2,8.4,28.3]],"id":41122648},{"batb":[[0,28,4.75]],"id":55632148},{"batb":[[1,1.81,304.48]],"batl":[[1,1.84,160.2]],"id":51922},{"tv":16788.27,"batb":[[0,4.7,63.37]],"trd":[[4.7,201.46]],"ltp":4.7,"id":50466254},{"batb":[[2,21,48.79],[1,22,15.06],[0,23,3.64]],"batl":[[2,26,10],[1,25,4.43],[0,24,1.17]],"id":106596}],"tv":123387.64}],"ArrivalTime":1710508077442}
{"op":"mcm","id":2,"clk":"AJFUAI90AIuAAQ==","pt":1710508077525,"mc":[{"id":"1.226122413","rc":[{"batb":[[2,7.2,84.23],[1,7.4,51.11],[0,7.6,33.69]],"id":41122648},{"batb":[[0,28,7.75]],"batl":[],"id":55632148},{"tv":89865.28,"batb":[[1,1.81,365.4],[0,1.82,216.18]],"trd":[[1.83,8551.04]],"ltp":1.83,"batl":[[0,1.83,80.78]],"id":51922},{"tv":2279.78,"batb":[[2,22,15.06],[1,23,8.69],[0,24,1.4]],"trd":[[24,252.22]],"batl":[[2,27,12.91],[1,26,7.1],[0,25,4.43]],"id":106596}],"tv":123417.33}],"ArrivalTime":1710508077533}
{"op":"mcm","id":2,"clk":"AJVUAJR0AJmAAQ==","pt":1710508077631,"mc":[{"id":"1.226122413","rc":[{"batb":[[2,7.4,48.92],[1,7.6,31.65],[0,7.8,8.59]],"batl":[[1,8.2,21.72],[0,8,28.42]],"id":41122648},{"batl":[[1,32,15.49]],"id":55632148},{"batb":[[0,1.82,286.89]],"id":51922},{"tv":16972.72,"batb":[[1,4.6,140],[0,4.7,39.02]],"trd":[[4.8,751.06]],"ltp":4.8,"batl":[[0,4.8,140.71]],"id":50466254},{"batb":[[1,23,12.28]],"id":106596}],"tv":123601.78}],"ArrivalTime":1710508077639}
{"op":"mcm","id":2,"clk":"AJxUAKR0AKOAAQ==","pt":1710508077734,"mc":[{"id":"1.226122413","rc":[{"tv":89888.18,"batb":[[1,1.81,415.4],[0,1.82,220.01]],"trd":[[1.83,8573.94]],"batl":[[1,1.84,134.16],[0,1.83,69.33]],"id":51922},{"batb":[[0,160,6.06]],"id":66251581},{"batb":[[2,21,48.79],[1,22,15.06],[0,23,12.28]],"batl":[[2,27,13.65],[1,26,11.69]],"id":106596}],"tv":123624.68}],"ArrivalTime":1710508077742}
{"op":"mcm","id":2,"clk":"AKFUAK50AK6AAQ==","pt":1710508077845,"mc":[{"id":"1.226122413","rc":[{"batb":[],"batl":[[0,8,30.42]],"id":41122648},{"batl":[[2,300,1.71],[1,290,1]],"id":41200638},{"tv":89979.18,"trd":[[1.83,8664.94]],"batl":[[0,1.83,23.83]],"id":51922},{"tv":17012.72,"trd":[[4.8,791.06]],"batl":[[0,4.8,120.71]],"id":50466254},{"tv":563.36,"batb":[[0,160,5.87]],"trd":[[190,0.95]],"ltp":190,"batl":[[2,210,5],[1,200,2.82],[0,190,1.81]],"id":66251581},{"batl":[[2,26,11.69],[1,25,4.43],[0,24,1.4]],"id":106596}],"tv":123756.07}],"ArrivalTime":1710508077852}
{"op":"mcm","id":2,"clk":"AKhUALh0ALSAAQ==","pt":1710508077890,"mc":[{"id":"1.226122413","rc":[{"batl":[[1,1.84,159.61]],"id":51922},{"batl":[[0,190,3.81]],"id":66251581},{"batl":[[2,26,10.89]],"id":106596}]}],"ArrivalTime":1710508077898}
{"op":"mcm","id":2,"clk":"AK5UALx0ALyAAQ==","pt":1710508078049,"mc":[{"id":"1.226122413","rc":[{"batb":[[2,26,13.82]],"id":55632148},{"tv":90026.84,"batb":[[2,1.81,415.4],[1,1.82,220.01],[0,1.83,32.01]],"trd":[[1.83,8712.6]],"batl":[[2,1.86,228.09],[1,1.85,149.52],[0,1.84,159.61]],"id":51922},{"batb":[[0,160,7.16]],"batl":[],"id":66251581},{"tv":2282.58,"batb":[[2,22,15.06],[1,23,12.28],[0,24,7.33]],"trd":[[24,255.02]],"batl":[[2,27,12.91],[1,26,10.89],[0,25,4.43]],"id":106596}],"tv":123806.53}],"ArrivalTime":1710508078057}
{"op":"mcm","id":2,"clk":"ALNUAMh0AMWAAQ==","pt":1710508078093,"mc":[{"id":"1.226122413","rc":[{"batb":[[2,26,18.35]],"id":55632148}]}],"ArrivalTime":1710508078101}
{"op":"mcm","id":2,"clk":"ALpUANF0ANCAAQ==","pt":1710508078205,"mc":[{"id":"1.226122413","rc":[{"batb":[[2,7.2,81.92],[1,7.4,48.92],[0,7.6,31.65]],"id":41122648},{"batb":[[0,28,4.75]],"id":55632148},{"tv":90031.66,"batb":[[2,1.8,534.82],[1,1.81,415.4],[0,1.82,220.01]],"trd":[[1.83,8717.42]],"batl":[[2,1.85,149.52],[1,1.84,159.61],[0,1.83,34.29]],"id":51922},{"batb":[[2,4.5,94.31]],"id":50466254},{"tv":2284.94,"batb":[[0,24,4.3]],"trd":[[24,257.38]],"batl":[[2,27,13.65],[1,26,7.9]],"id":106596}],"tv":123813.71}],"ArrivalTime":1710508078212}
{"op":"mcm","id":2,"clk":"AMFUANp0AN6AAQ==","pt":1710508078318,"mc":[{"id":"1.226122413","rc":[{"batb":[[2,21,48.79],[1,22,15.06],[0,23,12.28]],"id":106596}]}],"ArrivalTime":1710508078325}
{"op":"mcm","id":2,"clk":"AMdUAOF0AOOAAQ==","pt":1710508078411,"mc":[{"id":"1.226122413","rc":[{"batl":[[2,1.86,228.09],[1,1.85,149.52],[0,1.84,77.5]],"id":51922},{"batb":[[2,4.5,97.56]],"batl":[],"id":50466254},{"batl":[[2,27,12.91],[1,26,7.1],[0,25,1.34]],"id":106596}]}],"ArrivalTime":1710508078420}
{"op":"mcm","id":2,"clk":"ANBUAON0AO2AAQ==","pt":1710508078513,"mc":[{"id":"1.226122413","rc":[{"batb":[[2,200,1.49]],"id":41200638}]}],"ArrivalTime":1710508078520}
{"op":"mcm","id":2,"clk":"ANVUAOt0APeAAQ==","pt":1710508078619,"mc":[{"id":"1.226122413","rc":[{"tv":2012.92,"batb":[[2,25,15.4],[1,26,18.35],[0,27,9.44]],"trd":[[28,299.06]],"ltp":28,"id":55632148},{"batb":[[2,4.5,94.31]],"id":50466254}],"tv":123822.45}],"ArrivalTime":1710508078626}
{"op":"mcm","id":2,"clk":"AN1UAPN0AIeBAQ==","pt":1710508078722,"mc":[{"id":"1.226122413","rc":[{"batl":[[0,1.84,52.05]],"id":51922},{"batb":[[2,22,15.06],[1,23,12.28],[0,24,1.92]],"id":106596}]}],"ArrivalTime":1710508078730}
{"op":"mcm","id":2,"clk":"APBUAI11AK2BAQ==","pt":1710508079027,"mc":[{"id":"1.226122413","rc":[{"tv":2013.66,"batb":[[1,26,15.93],[0,27,9.06]],"trd":[[28,299.8]],"batl":[],"id":55632148},{"tv":90131.66,"batb":[[0,1.82,170.01]],"trd":[[1.82,5247.06]],"ltp":1.82,"batl":[[1,1.84,51.95],[0,1.83,4],[2,1.85,149.52]],"id":51922},{"batl":[[2,27,13.65],[1,26,7.9]],"id":106596}],"tv":123923.19,"con":true}],"ArrivalTime":1710508079035}
{"op":"mcm","id":2,"clk":"APJUAI51AK+BAQ==","pt":1710508079041,"mc":[{"id":"1.226122413","rc":[{"tv":90147.65,"batb":[[2,1.81,417.4],[1,1.82,130.38],[0,1.83,12.26]],"trd":[[1.83,8733.41]],"ltp":1.83,"batl":[[2,1.86,228.09],[1,1.85,149.52],[0,1.84,77.24]],"id":51922},{"batb":[[0,4.7,57.96]],"id":50466254},{"batb":[[0,24,5.51]],"id":106596}],"tv":123939.18}],"ArrivalTime":1710508079048}
{"op":"mcm","id":2,"clk":"AKpVALx1APGBAQ==","pt":1710508079607,"mc":[{"id":"1.226122413","rc":[{"batb":[],"batl":[[0,8,47.61]],"id":41122648},{"batb":[[1,26,11.4]],"id":55632148},{"tv":90157.77,"batb":[[0,1.83,6.02],[1,1.82,104.67]],"trd":[[1.83,8743.53]],"id":51922},{"tv":2623.85,"batb":[[1,32,17.22],[0,34,4.39]],"trd":[[34,262.29]],"ltp":34,"id":49744721},{"batb":[[0,4.7,58]],"batl":[[2,5.1,53.65],[1,5,76.38],[0,4.9,14.7]],"id":50466254},{"tv":565.36,"batb":[[0,160,6.16]],"trd":[[180,9.23],[170,36.84],[160,27.2]],"ltp":160,"batl":[[0,190,4.16]],"id":66251581},{"batb":[[0,24,1.92]],"batl":[[0,25,4.98]],"id":106596}],"tv":123955.3,"con":true}],"ArrivalTime":1710508079615}
{"op":"mcm","id":2,"clk":"AKtVAMB1APaBAQ==","pt":1710508079614,"mc":[{"id":"1.226122413","rc":[{"tv":378.5,"batb":[[0,350,3.45]],"trd":[[350,16.64]],"ltp":350,"id":54370634},{"batb":[[1,1.82,130.32]],"id":51922},{"batl":[[0,36,11.65]],"id":49744721},{"batl":[[2,27,12.91],[1,26,7.1],[0,25,4.11]],"id":106596}],"tv":123957.3}],"ArrivalTime":1710508079622}
{"op":"mcm","id":2,"clk":"ALZVAM11AI6CAQ==","pt":1710508079821,"mc":[{"id":"1.226122413","rc":[{"batb":[[1,1.82,136.42]],"id":51922}]}],"ArrivalTime":1710508079829}
{"op":"mcm","id":2,"clk":"AMFVANd1AJyCAQ==","pt":1710508080030,"mc":[{"id":"1.226122413","rc":[{"tv":8501.92,"batb":[[2,7,36.34],[1,7.2,81.92],[0,7.4,48.92]],"trd":[[7.6,163.43]],"ltp":7.6,"batl":[[1,8.2,63.16]],"id":41122648},{"tv":90163.77,"trd":[[1.84,13496.02]],"ltp":1.84,"batl":[[0,1.84,74.24]],"id":51922},{"tv":17014.42,"batb":[[0,4.7,57.15]],"trd":[[4.7,203.08],[4.8,791.14]],"ltp":4.7,"id":50466254}],"tv":124028.3}],"ArrivalTime":1710508080038}
{"op":"mcm","id":2,"clk":"AM9VAO91ALaCAQ==","pt":1710508080245,"mc":[{"id":"1.226122413","rc":[{"batb":[[2,7,53.36],[0,7.4,31.53]],"batl":[[2,8.2,63.16],[1,8,47.61],[0,7.8,8.72]],"id":41122648},{"batb":[[0,1.83,45.32]],"id":51922}]}],"ArrivalTime":1710508080253}
{"op":"mcm","id":2,"clk":"ANdVAPt1AMSCAQ==","pt":1710508080353,"mc":[{"id":"1.226122413","rc":[{"batb":[[1,7.2,64.77]],"batl":[[0,7.8,16.58]],"id":41122648},{"tv":90247.69,"trd":[[1.84,13579.94]],"batl":[[2,1.86,231.24],[0,1.84,32.28]],"id":51922},{"tv":17016.42,"batb":[[2,4.6,140],[1,4.7,57.15],[0,4.8,17.46]],"trd":[[4.8,793.14]],"ltp":4.8,"id":50466254},{"batl":[[0,25,1.34]],"id":106596}],"tv":124114.22}],"ArrivalTime":1710508080361}
{"op":"mcm","id":2,"clk":"AN1VAIh2AMiCAQ==","pt":1710508080395,"mc":[{"id":"1.226122413","rc":[{"batb":[[2,7,55.82],[0,7.4,71.1]],"batl":[[2,8.2,21.72]],"id":41122648},{"batb":[[1,1.82,195.26],[0,1.83,48.34]],"batl":[[0,1.84,6.99]],"id":51922}]}],"ArrivalTime":1710508080403}
{"op":"mcm","id":2,"clk":"AOJVAJR2ANiCAQ==","pt":1710508080508,"mc":[{"id":"1.226122413","rc":[{"batb":[[2,7,64.82],[0,7.4,60.9]],"batl":[[2,8,45.61],[1,7.8,18.58],[0,7.6,8.84]],"id":41122648},{"tv":90257.69,"batb":[[2,1.81,419.87],[0,1.83,68.61]],"trd":[[1.83,8753.53]],"ltp":1.83,"batl":[[1,1.85,152.72],[0,1.84,10.25]],"id":51922},{"batb":[[0,34,2.67]],"id":49744721},{"batb":[[2,22,16.06],[0,24,5.51]],"id":106596}],"tv":124124.22}],"ArrivalTime":1710508080515}
{"op":"mcm","id":2,"clk":"AOZVAJx2AOWCAQ==","pt":1710508080610,"mc":[{"id":"1.226122413","rc":[{"tv":8506,"batb":[[1,7.2,67.08],[0,7.4,23.52]],"trd":[[7.6,167.51]],"batl":[[0,7.6,6.8]],"id":41122648},{"batl":[[2,34,30.1],[1,32,12.26]],"id":55632148},{"tv":17051.33,"batb":[[2,4.5,94.31],[1,4.6,140],[0,4.7,57.15]],"trd":[[4.8,828.05]],"batl":[[2,5,76.38],[1,4.9,14.7],[0,4.8,34.03]],"id":50466254}],"tv":124163.21}],"ArrivalTime":1710508080617}
{"op":"mcm","id":2,"clk":"AO5VAKZ2APCCAQ==","pt":1710508080727,"mc":[{"id":"1.226122413","rc":[{"tv":2031.78,"batb":[[2,24,16.98],[1,25,15.4],[0,26,11.4]],"trd":[[27,302.27]],"ltp":27,"id":55632148},{"batl":[[0,36,14.15]],"id":49744721},{"batl":[[2,5,104.86]],"id":50466254},{"batb":[[0,24,8.21]],"id":106596}],"tv":124181.33}],"ArrivalTime":1710508080735}
{"op":"mcm","id":2,"clk":"APFVAK52APeCAQ==","pt":1710508080824,"mc":[{"id":"1.226122413","rc":[{"batb":[[1,7.2,104.26]],"batl":[[0,7.6,11.88]],"id":41122648},{"tv":90278.19,"batb":[[2,1.82,200.29],[1,1.83,70.62],[0,1.84,67.81]],"trd":[[1.84,13600.44]],"ltp":1.84,"batl":[[2,1.87,196.6],[1,1.86,238.74],[0,1.85,125.57]],"id":51922},{"batl":[[1,4.9,33.43]],"id":50466254},{"batl":[[2,260,3.09],[1,210,5]],"id":66251581}],"tv":124201.83}],"ArrivalTime":1710508080832}
{"op":"mcm","id":2,"clk":"APZVALV2AIGDAQ==","pt":1710508080921,"mc":[{"id":"1.226122413","rc":[{"batb":[[0,7.4,21.33]],"batl":[],"id":41122648},{"tv":484.6,"trd":[[280,19.29]],"batl":[[2,310,1.71],[1,300,1.71],[0,290,1]],"id":41200638},{"batb":[[1,25,12.42]],"batl":[[2,32,12.26],[1,30,7.44],[0,29,2.08]],"id":55632148},{"batb":[[2,1.82,197.12],[0,1.84,68.07]],"batl":[[1,1.86,238.85],[0,1.85,122.37]],"id":51922},{"tv":17051.53,"batb":[[0,4.7,57.05]],"trd":[[4.7,203.28]],"ltp":4.7,"batl":[],"id":50466254},{"batb":[[1,23,16.27]],"batl":[[2,27,13.65]],"id":106596}],"tv":124204.75}],"ArrivalTime":1710508080929}
{"op":"mcm","id":2,"clk":"AIFWAL92AI2DAQ==","pt":1710508081025,"mc":[{"id":"1.226122413","rc":[{"tv":8595.86,"batb":[[2,7.2,101.95],[1,7.4,21.33],[0,7.8,55.07]],"trd":[[7.8,255.91],[7.6,191.27]],"ltp":7.8,"batl":[[2,8.4,28.3],[1,8.2,21.72],[0,8,45.61]],"id":41122648},{"tv":486.6,"trd":[[290,30.53]],"ltp":290,"batl":[[2,320,1.71],[1,310,1.71],[0,300,1.71]],"id":41200638},{"batb":[[1,1.83,128.03],[0,1.84,125.35]],"batl":[[2,1.87,193.51],[1,1.86,235.7],[0,1.85,161.61]],"id":51922},{"batb":[[0,4.7,38.11]],"id":50466254},{"batb":[[0,160,5.03]],"batl":[[2,250,1.18]],"id":66251581}],"tv":124296.61}],"ArrivalTime":1710508081033}
{"op":"mcm","id":2,"clk":"AIZWAMx2AJSDAQ==","pt":1710508081137,"mc":[{"id":"1.226122413","rc":[{"tv":378.7,"batb":[[0,350,3.35]],"trd":[[350,16.84]],"id":54370634},{"batb":[[2,7.2,104.26]],"id":41122648},{"tv":486.8,"batb":[[0,220,9.02]],"trd":[[220,45.98]],"ltp":220,"id":41200638},{"batb":[[2,25,12.42],[1,26,11.4],[0,27,2.23]],"batl":[],"id":55632148},{"tv":90358.2,"batb":[[0,1.84,150.48]],"trd":[[1.85,14524.25]],"ltp":1.85,"batl":[[0,1.85,121.6]],"id":51922},{"tv":2652.15,"trd":[[36,165.82]],"ltp":36,"batl":[[2,42,8.06],[1,40,13.05],[0,38,5.46]],"id":49744721},{"tv":17051.73,"trd":[[4.8,828.25]],"ltp":4.8,"batl":[[0,4.8,33.93]],"id":50466254},{"tv":565.56,"batb":[[0,160,4.93]],"trd":[[160,27.4]],"id":66251581}],"tv":124405.72}],"ArrivalTime":1710508081145}
{"op":"mcm","id":2,"clk":"AJBWANJ2AKaDAQ==","pt":1710508081303,"mc":[{"id":"1.226122413","rc":[{"tv":8723.05,"batb":[[2,7.2,101.95],[1,7.4,38.8],[0,7.6,14.6]],"trd":[[7.8,383.1]],"batl":[[2,8.2,23.46],[1,8,21.79],[0,7.8,57.75]],"id":41122648},{"batb":[[1,210,1.61]],"batl":[],"id":41200638},{"batl":[[2,32,12.29]],"id":55632148},{"batb":[[1,1.83,175.03],[0,1.84,92.67]],"batl":[[2,1.87,196.6],[1,1.86,238.85],[0,1.85,149.79]],"id":51922},{"batb":[[1,32,20.42],[0,36,3.33]],"batl":[[2,42,10.5],[1,40,10.38],[0,38,8.15]],"id":49744721},{"tv":17153.11,"batb":[[2,4.5,97.56]],"trd":[[4.8,929.63]],"batl":[[0,4.8,2.26]],"id":50466254},{"tv":2290.08,"batb":[[0,24,5.64]],"trd":[[24,262.52]],"batl":[[2,27,12.91]],"id":106596}],"tv":124639.43}],"ArrivalTime":1710508081311}
{"op":"mcm","id":2,"clk":"AJZWAN12AKyDAQ==","pt":1710508081339,"mc":[{"id":"1.226122413","rc":[{"batb":[[0,7.6,23.38]],"id":41122648},{"batb":[[2,24,16.98],[1,25,12.42],[0,26,11.4]],"id":55632148},{"batb":[[1,1.83,117.62],[0,1.84,67.54]],"id":51922},{"batb":[[2,32,20.42],[1,34,5.63],[0,36,5.81]],"batl":[[1,40,7.15],[0,38,5.81]],"id":49744721},{"batb":[[1,23,12.28]],"id":106596}]}],"ArrivalTime":1710508081347}
{"op":"mcm","id":2,"clk":"AJlWAOJ2ALaDAQ==","pt":1710508081449,"mc":[{"id":"1.226122413","rc":[{"tv":383.04,"trd":[[430,4.41]],"ltp":430,"batl":[[2,1000,3.31],[1,890,1.2],[0,580,3.44]],"id":54370634},{"tv":8736.29,"batb":[[2,7.2,104.26],[0,7.6,8.17]],"trd":[[7.6,204.51]],"ltp":7.6,"batl":[[2,8.2,21.72],[1,8,38.04]],"id":41122648},{"tv":90481.82,"batb":[[0,1.84,5.73]],"trd":[[1.84,13724.06]],"ltp":1.84,"batl":[[0,1.85,121.6]],"id":51922},{"batb":[[1,34,9.22],[0,36,9.4]],"batl":[[0,38,2.69]],"id":49744721},{"batb":[[2,4.5,94.31],[0,4.7,57.49]],"batl":[],"id":50466254}],"tv":124780.63}],"ArrivalTime":1710508081456}
{"op":"mcm","id":2,"clk":"AKNWAOh2AL6DAQ==","pt":1710508081554,"mc":[{"id":"1.226122413","rc":[{"batb":[[1,7.4,47.84]],"batl":[[0,7.8,66.33]],"id":41122648},{"batl":[[1,40,4.93]],"id":49744721},{"tv":17273.11,"trd":[[4.9,221.82],[5,61.42]],"ltp":5,"batl":[[2,5.2,69.11],[1,5.1,53.65],[0,5,78.29]],"id":50466254},{"batb":[[0,24,2.94]],"id":106596}],"tv":124900.63}],"ArrivalTime":1710508081561}
{"op":"mcm","id":2,"clk":"AKlWAPR2AM2DAQ==","pt":1710508081658,"mc":[{"id":"1.226122413","rc":[{"tv":8752.63,"batb":[[2,7,64.82],[1,7.2,104.26],[0,7.4,31.37]],"trd":[[7.6,220.85]],"batl":[[2,8,38.04],[1,7.8,8.58],[0,7.6,7.93]],"id":41122648},{"tv":90492.11,"trd":[[1.85,14534.54]],"ltp":1.85,"batl":[[0,1.85,116.45]],"id":51922},{"tv":2658.27,"trd":[[38,60.7]],"ltp":38,"batl":[[2,42,8.06],[0,38,1.63]],"id":49744721},{"batb":[[2,4.6,140],[1,4.7,57.49],[0,4.8,13.01]],"batl":[[2,5.2,66.77]],"id":50466254}],"tv":124933.38}],"ArrivalTime":1710508081667}
{"op":"mcm","id":2,"clk":"ALJWAIF3ANqDAQ==","pt":1710508081764,"mc":[{"id":"1.226122413","rc":[{"batl":[[0,580,3.6]],"id":54370634},{"batb":[[1,7.2,117.68]],"batl":[[1,7.8,17.32],[0,7.6,33.13]],"id":41122648},{"batb":[[2,210,1.61],[1,220,9.02],[0,230,1.26]],"id":41200638},{"tv":90712.03,"batb":[[2,1.8,539.82],[1,1.81,419.87],[0,1.82,185.24]],"trd":[[1.84,13735.52],[1.83,8938.23],[1.82,5270.82]],"ltp":1.82,"batl":[[2,1.86,238.85],[1,1.85,141.24],[0,1.84,44.57]],"id":51922},{"batb":[[0,4.8,25.51]],"batl":[[0,5,49.81]],"id":50466254},{"batb":[[2,21,48.79],[1,22,16.06],[0,23,12.28]],"batl":[[1,26,10.56],[0,25,3.87]],"id":106596}],"tv":125153.3}],"ArrivalTime":1710508081772}
{"op":"mcm","id":2,"clk":"ALZWAI93AOKDAQ==","pt":1710508081869,"mc":[{"id":"1.226122413","rc":[{"batl":[[2,890,1],[1,750,1.91]],"id":54370634},{"batb":[[2,7,83.24],[1,7.2,86.1]],"batl":[[2,8,46.25],[1,7.8,33.85],[0,7.6,27.94]],"id":41122648},{"batl":[[2,310,1.71],[1,300,1.71],[0,290,2.56]],"id":41200638},{"batl":[[1,1.85,140.08]],"id":51922},{"tv":2663.01,"batb":[[2,34,9.22],[1,36,9.4],[0,38,3.82]],"trd":[[40,13.68],[38,63.96]],"ltp":40,"batl":[[2,44,10.73],[1,42,8.06],[0,40,4.18]],"id":49744721},{"batb":[[0,4.8,44.05]],"batl":[[1,5.1,25.08],[0,5,39.14]],"id":50466254},{"batl":[[2,250,4]],"id":66251581},{"batl":[[2,27,13.65]],"id":106596}],"tv":125158.04}],"ArrivalTime":1710508081877}
{"op":"mcm","id":2,"clk":"ALpWAJh3AOWDAQ==","pt":1710508081961,"mc":[{"id":"1.226122413","rc":[{"tv":8771.14,"batb":[[0,7.4,13.08]],"trd":[[7.4,24.23]],"ltp":7.4,"batl":[[0,7.6,38.69]],"id":41122648},{"batb":[[2,210,2.8]],"id":41200638},{"batb":[[0,1.82,100.75]],"batl":[[2,1.85,140.08],[1,1.84,44.57],[0,1.83,25.58]],"id":51922},{"batb":[[0,4.8,58.05]],"batl":[[1,5.1,84.32]],"id":50466254},{"tv":566.26,"trd":[[180,9.93]],"ltp":180,"batl":[[0,190,3.81]],"id":66251581}],"tv":125177.25}],"ArrivalTime":1710508081969}
{"op":"mcm","id":2,"clk":"AMFWAKV3APaDAQ==","pt":1710508082079,"mc":[{"id":"1.226122413","rc":[{"tv":8797.3,"batb":[[2,6.8,28.76],[1,7,83.24],[0,7.2,103.93]],"trd":[[7.4,50.39]],"id":41122648},{"tv":2049.5,"batb":[[0,26,2.54]],"trd":[[26,366.9]],"ltp":26,"id":55632148},{"tv":90716.03,"batb":[[1,1.81,332.88]],"trd":[[1.83,8942.23]],"ltp":1.83,"batl":[[0,1.83,23.58]],"id":51922},{"tv":2671.21,"batb":[[0,38,2.39]],"trd":[[40,14.24],[38,71.6]],"batl":[[1,42,4.18],[0,40,2.4]],"id":49744721},{"tv":17277.11,"batb":[[2,4.7,57.49],[1,4.8,58.05],[0,4.9,16.21]],"trd":[[4.9,225.82]],"ltp":4.9,"batl":[],"id":50466254},{"batl":[[2,27,12.91]],"id":106596}],"tv":125237.33}],"ArrivalTime":1710508082086}
{"op":"mcm","id":2,"clk":"AMhWAK53APqDAQ==","pt":1710508082174,"mc":[{"id":"1.226122413","rc":[{"batb":[[0,7.2,93.65]],"batl":[[0,7.6,22.36]],"id":41122648},{"batb":[[2,23,10.81],[1,24,16.98],[0,25,12.42]],"id":55632148},{"tv":90763.18,"batb":[[2,1.81,424.58],[1,1.82,100.75],[0,1.83,2]],"trd":[[1.83,8989.38]],"batl":[[2,1.86,238.85],[1,1.85,140.08],[0,1.84,5.19]],"id":51922},{"batb":[[0,38,5.98]],"batl":[[0,40,4.4]],"id":49744721},{"tv":17365.21,"batb":[[2,4.6,140],[1,4.7,57.49],[0,4.8,30.21]],"trd":[[4.9,258.24],[4.8,985.31]],"ltp":4.8,"id":50466254},{"tv":2297.82,"trd":[[25,321.86]],"ltp":25,"batl":[[2,28,8.8],[1,27,12.91],[0,26,10.56]],"id":106596}],"tv":125380.32}],"ArrivalTime":1710508082183}
