{"op":"mcm","id":2,"clk":"AM9WALZ3AImEAQ==","pt":1710508082236,"mc":[{"id":"1.226122413","rc":[{"batb":[[2,6.8,37.76],[0,7.2,91.34]],"id":41122648},{"batb":[[2,24,16.98],[1,25,12.42],[0,26,3.59]],"batl":[[2,30,7.44],[1,29,2.08],[0,28,2.88]],"id":55632148},{"batb":[[2,1.81,481.66],[1,1.82,55.75]],"id":51922},{"batl":[[2,44,8.41],[0,40,4.68]],"id":49744721},{"tv":17371.21,"batb":[[2,4.7,57.49],[1,4.8,27.21],[0,4.9,1.98]],"trd":[[4.8,991.31]],"batl":[[1,5.1,25.08]],"id":50466254},{"batl":[[0,26,7.1]],"id":106596}],"tv":125386.32}],"ArrivalTime":1710508082244}
{"op":"mcm","id":2,"clk":"ANZWAL53AJKEAQ==","pt":1710508082337,"mc":[{"id":"1.226122413","rc":[{"batl":[[2,750,1.91],[1,580,2.98],[0,570,3.18]],"id":54370634},{"batb":[[2,7,63.76],[1,7.2,91.34],[0,7.4,8.88]],"id":41122648},{"tv":2061.36,"batb":[[2,23,10.81],[1,24,14.41],[0,25,11.42]],"trd":[[26,378.76]],"batl":[[0,28,3.17]],"id":55632148},{"tv":90923.26,"batb":[[2,1.81,415.29],[0,1.83,17.91]],"trd":[[1.84,13745.9],[1.83,9139.08]],"ltp":1.84,"batl":[[2,1.86,235.7],[0,1.84,24.91]],"id":51922},{"batb":[[1,36,12.19]],"id":49744721},{"batl":[[1,5.1,52.21]],"id":50466254},{"batb":[[0,23,20.16]],"batl":[[2,28,12.01],[1,27,9.26]],"id":106596}],"tv":125558.26}],"ArrivalTime":1710508082345}
{"op":"mcm","id":2,"clk":"ANxWAMd3AJqEAQ==","pt":1710508082438,"mc":[{"id":"1.226122413","rc":[{"tv":8815.05,"batb":[[2,6.8,40.33],[1,7,63.76],[0,7.2,73.51]],"trd":[[7.4,68.14]],"batl":[[0,7.6,22.66]],"id":41122648},{"tv":2061.94,"batb":[[2,24,14.41],[1,25,11.42],[0,26,14.35]],"trd":[[26,379.34]],"batl":[[0,28,2.88]],"id":55632148},{"batl":[[1,1.85,143.28]],"id":51922},{"tv":2671.73,"trd":[[40,14.76]],"batl":[[0,40,4.42]],"id":49744721},{"batb":[[2,22,16.06],[1,23,20.16],[0,24,2.62]],"id":106596}],"tv":125577.11}],"ArrivalTime":1710508082446}
{"op":"mcm","id":2,"clk":"AORWANB3AKOEAQ==","pt":1710508082544,"mc":[{"id":"1.226122413","rc":[{"batb":[[0,350,3.38]],"batl":[[1,580,2.82],[0,570,3.34]],"id":54370634},{"tv":2066.48,"batb":[[0,26,12.46]],"trd":[[27,303.03],[26,383.12]],"ltp":27,"batl":[[2,29,2.08],[1,28,2.88],[0,27,1.86]],"id":55632148},{"tv":90957.02,"batb":[[1,1.82,83.38],[0,1.83,7.91]],"trd":[[1.84,13759.66],[1.83,9159.08]],"ltp":1.83,"batl":[[2,1.86,238.85],[0,1.84,20.03]],"id":51922},{"tv":2673.45,"trd":[[40,16.48]],"batl":[[0,40,3.56]],"id":49744721},{"batb":[[0,160,4.99]],"id":66251581},{"batb":[[0,24,3.05]],"batl":[[1,27,12.59]],"id":106596}],"tv":125617.13}],"ArrivalTime":1710508082552}
{"op":"mcm","id":2,"clk":"AOxWANt3AK6EAQ==","pt":1710508082649,"mc":[{"id":"1.226122413","rc":[{"batl":[[0,290,4.56]],"id":41200638},{"batb":[[0,26,17.71]],"id":55632148},{"tv":90972.84,"batb":[[2,1.8,539.82],[1,1.81,415.29],[0,1.82,125.97]],"trd":[[1.83,9174.9]],"id":51922},{"tv":2673.85,"batb":[[2,34,14.67]],"trd":[[40,16.88]],"batl":[[0,40,3.36]],"id":49744721},{"batb":[[0,4.9,24.29]],"id":50466254},{"batb":[[0,24,6.64]],"id":106596}],"tv":125633.35}],"ArrivalTime":1710508082657}
{"op":"mcm","id":2,"clk":"APNWAOF3ALSEAQ==","pt":1710508082752,"mc":[{"id":"1.226122413","rc":[{"batb":[[0,7.2,72.22]],"batl":[[0,7.6,23.98]],"id":41122648},{"batl":[[0,290,2]],"id":41200638},{"tv":2074.2,"batb":[[0,26,13.85]],"trd":[[26,390.84]],"ltp":26,"id":55632148},{"batl":[[2,46,12.44],[1,44,8.87]],"id":49744721},{"tv":17431.21,"trd":[[5,121.42]],"ltp":5,"batl":[[0,5,9.14]],"id":50466254}],"tv":125701.07}],"ArrivalTime":1710508082760}
{"op":"mcm","id":2,"clk":"AP5WAO13AL6EAQ==","pt":1710508082851,"mc":[{"id":"1.226122413","rc":[{"tv":2079.96,"batb":[[2,25,11.42],[1,26,11.6],[0,28,9.12]],"trd":[[28,305.56]],"ltp":28,"batl":[[2,32,12.29],[1,30,7.44],[0,29,2.08]],"id":55632148},{"batb":[[0,1.82,105.81]],"batl":[[2,1.86,185.7],[1,1.85,140.08],[0,1.84,144.98]],"id":51922},{"tv":17471.21,"batb":[[1,4.8,29.78],[0,4.9,22.24]],"trd":[[4.9,298.24]],"ltp":4.9,"batl":[],"id":50466254}],"tv":125746.83}],"ArrivalTime":1710508082859}
{"op":"mcm","id":2,"clk":"AIRXAPR3AMmEAQ==","pt":1710508082958,"mc":[{"id":"1.226122413","rc":[{"batb":[[1,7,66.22]],"id":41122648},{"tv":2098.2,"batb":[[2,24,14.41],[1,25,14.15],[0,26,11.6]],"trd":[[28,323.8]],"batl":[[2,30,7.44],[1,29,2.08],[0,28,3.59]],"id":55632148},{"tv":90973.14,"batb":[[2,1.81,413.29],[1,1.82,105.81],[0,1.83,2.26]],"trd":[[1.83,9175.2]],"batl":[[0,1.84,144.83]],"id":51922},{"tv":17489.49,"batb":[[2,4.8,29.78],[1,4.9,34.57],[0,5,90.86]],"trd":[[5,139.7]],"ltp":5,"batl":[[2,5.3,38.04],[1,5.2,66.77],[0,5.1,25.08]],"id":50466254}],"tv":125783.65}],"ArrivalTime":1710508082966}
{"op":"mcm","id":2,"clk":"AIlXAIB4ANiEAQ==","pt":1710508083061,"mc":[{"id":"1.226122413","rc":[{"batl":[[2,7.8,33.85],[1,7.6,25.68],[0,7.4,10.3]],"id":41122648},{"batb":[[0,230,1.3]],"batl":[[2,300,1.71],[1,290,2],[0,280,2]],"id":41200638},{"batb":[[2,25,14.15],[1,26,11.6],[0,27,3.59]],"batl":[[2,32,12.29],[1,30,7.44],[0,29,2.08]],"id":55632148},{"tv":90977.66,"batb":[[2,1.8,539.82],[1,1.81,356.21],[0,1.82,63.22]],"trd":[[1.83,9179.72]],"batl":[[2,1.85,143.28],[1,1.84,144.83],[0,1.83,92.5]],"id":51922}],"tv":125788.17}],"ArrivalTime":1710508083069}
{"op":"mcm","id":2,"clk":"AJVXAIZ4AN6EAQ==","pt":1710508083163,"mc":[{"id":"1.226122413","rc":[{"batb":[[1,7,63.76]],"batl":[[1,7.6,42.4]],"id":41122648},{"batb":[[2,210,1.61]],"id":41200638},{"batl":[[2,30,7.44],[1,29,2.08],[0,28,2.08]],"id":55632148},{"tv":91146.1,"batb":[[2,1.79,267.2],[1,1.8,539.82],[0,1.81,336.2]],"trd":[[1.81,1467.6],[1.83,9181.72],[1.82,5397.25]],"ltp":1.81,"batl":[[1,1.84,148.09],[0,1.83,125.8]],"id":51922},{"batb":[[0,38,2.39]],"id":49744721},{"batb":[[2,4.8,55.28],[1,4.9,48.57],[0,5,108.52]],"batl":[[2,5.3,65.84],[1,5.2,36.68],[0,5.1,46.3]],"id":50466254},{"batb":[[0,24,3.05]],"batl":[],"id":106596}],"tv":125956.61}],"ArrivalTime":1710508083171}
{"op":"mcm","id":2,"clk":"AJdXAI94AO6EAQ==","pt":1710508083268,"mc":[{"id":"1.226122413","rc":[{"batl":[[2,890,1],[1,750,1.91],[0,580,3.59]],"id":54370634},{"tv":8823.55,"batb":[[2,6.8,58.99],[1,7,66.22],[0,7.2,74.53]],"trd":[[7.4,76.64]],"batl":[[0,7.4,32.55]],"id":41122648},{"tv":2105.5,"batb":[[2,25,11.42],[0,27,2.08]],"trd":[[27,310.33]],"ltp":27,"batl":[],"id":55632148},{"batb":[],"batl":[[2,5.3,63.59],[0,5.1,65.12]],"id":50466254},{"tv":566.32,"batb":[[0,160,4.96]],"trd":[[170,36.9]],"ltp":170,"id":66251581}],"tv":125972.47}],"ArrivalTime":1710508083276}
{"op":"mcm","id":2,"clk":"AJ9XAJd4APqEAQ==","pt":1710508083375,"mc":[{"id":"1.226122413","rc":[{"tv":2125.28,"batb":[[2,26,11.6],[1,27,2.08],[0,29,40.11]],"trd":[[29,82.61],[28,327.96]],"ltp":29,"batl":[[2,34,30.34],[1,32,12.29],[0,30,7.44]],"id":55632148},{"batb":[[2,1.8,478.63],[1,1.81,310.87],[0,1.82,1]],"batl":[[0,1.83,122.49]],"id":51922},{"batb":[[0,38,5.98]],"id":49744721},{"batb":[[0,24,6.64]],"batl":[],"id":106596}],"tv":125992.25}],"ArrivalTime":1710508083383}
{"op":"mcm","id":2,"clk":"AKdXAKJ4AIWFAQ==","pt":1710508083480,"mc":[{"id":"1.226122413","rc":[{"batb":[[0,7.2,72.22]],"id":41122648},{"batb":[[2,25,11.42],[1,26,11.6]],"id":55632148},{"batl":[[1,1.84,150.09]],"id":51922},{"tv":17489.81,"batb":[[0,5,108.36]],"trd":[[5,140.02]],"id":50466254}],"tv":125992.57}],"ArrivalTime":1710508083488}
{"op":"mcm","id":2,"clk":"AK9XAKZ4AJKFAQ==","pt":1710508083583,"mc":[{"id":"1.226122413","rc":[{"tv":8826.53,"batb":[[0,7.2,62.73]],"trd":[[7.2,86.77]],"ltp":7.2,"batl":[[1,7.6,40.4]],"id":41122648},{"batl":[[2,300,2.32]],"id":41200638},{"tv":2199.06,"batb":[[2,26,11.6],[1,28,12.09],[0,29,3.22]],"trd":[[29,156.39]],"batl":[[2,34,31.29],[1,32,13.37],[0,30,5.7]],"id":55632148},{"tv":91168.1,"batb":[[2,1.79,323.74],[1,1.8,478.63],[0,1.81,310.87]],"trd":[[1.82,5419.25]],"ltp":1.82,"batl":[[2,1.84,150.09],[1,1.83,212.39],[0,1.82,10.37]],"id":51922},{"tv":2680.57,"batb":[[2,36,12.19],[1,38,5.98],[0,40,2.45]],"trd":[[40,23.6]],"batl":[[2,48,9.54],[1,46,12.44],[0,44,8.87]],"id":49744721},{"tv":17491.81,"batb":[],"trd":[[5.1,2]],"ltp":5.1,"batl":[[0,5.1,64.12]],"id":50466254},{"tv":566.38,"batb":[[0,160,4.93]],"trd":[[170,36.96]],"id":66251581}],"tv":126100.11}],"ArrivalTime":1710508083590}
{"op":"mcm","id":2,"clk":"ALNXAK14AJmFAQ==","pt":1710508083638,"mc":[{"id":"1.226122413","rc":[{"tv":8846.82,"batb":[[0,7.2,42.17]],"trd":[[7.2,107.06]],"batl":[[2,7.8,35.85],[0,7.4,42.55]],"id":41122648},{"batl":[[2,1.84,160.09],[1,1.83,217.39]],"id":51922},{"batb":[[1,38,8.37]],"id":49744721},{"tv":17496.01,"batb":[[0,5,106.26]],"trd":[[5,144.22]],"ltp":5,"id":50466254}],"tv":126124.6}],"ArrivalTime":1710508083647}
{"op":"mcm","id":2,"clk":"ALtXALh4AKGFAQ==","pt":1710508083745,"mc":[{"id":"1.226122413","rc":[{"tv":8948.12,"batb":[[2,6.6,38.33],[1,6.8,58.99],[0,7,66.22]],"trd":[[7.4,88.98],[7.2,196.02]],"batl":[[2,7.6,40.4],[1,7.4,36.38],[0,7.2,10.12]],"id":41122648},{"tv":2199.8,"batb":[[1,28,6.26],[0,29,2.85]],"trd":[[29,157.13]],"batl":[[0,30,5.1]],"id":55632148},{"batb":[[1,1.8,458.58],[0,1.81,275.87]],"batl":[[0,1.82,13.74]],"id":51922},{"batb":[[1,38,16.06],[0,40,1.73]],"batl":[[2,48,11.57],[1,46,10.24]],"id":49744721}],"tv":126226.64}],"ArrivalTime":1710508083753}
{"op":"mcm","id":2,"clk":"AMFXAMJ4ALKFAQ==","pt":1710508083852,"mc":[{"id":"1.226122413","rc":[{"batl":[[2,750,1.91],[1,580,2.82],[0,570,3.34]],"id":54370634},{"batl":[[0,1.82,3.37]],"id":51922}]}],"ArrivalTime":1710508083859}
{"op":"mcm","id":2,"clk":"AMdXAMZ4ALqFAQ==","pt":1710508083956,"mc":[{"id":"1.226122413","rc":[{"tv":8962.28,"batb":[[0,7,84.7]],"trd":[[7.2,210.18]],"batl":[[1,7.4,53.43],[0,7.2,3.04]],"id":41122648},{"tv":2216.8,"batb":[[2,25,14.15],[1,26,3],[0,27,3.78]],"trd":[[29,162.83],[28,339.26]],"ltp":28,"id":55632148},{"batl":[[1,1.83,214.08],[0,1.82,26.01]],"id":51922},{"batb":[[0,40,5.32]],"batl":[[0,44,6.71]],"id":49744721},{"tv":17500.01,"batb":[[0,5,104.26]],"trd":[[5,148.22]],"batl":[],"id":50466254}],"tv":126261.8}],"ArrivalTime":1710508083964}
{"op":"mcm","id":2,"clk":"AMxXANV4AMSFAQ==","pt":1710508084057,"mc":[{"id":"1.226122413","rc":[{"tv":8968.36,"batb":[[2,6.8,56.37],[1,7,45.34],[0,7.2,1.96]],"trd":[[7.2,216.26]],"batl":[[2,7.8,35.85],[1,7.6,40.4],[0,7.4,53.43]],"id":41122648},{"batb":[[0,27,5.92]],"id":55632148},{"batb":[[1,1.8,484.88]],"id":51922}],"tv":126267.88}],"ArrivalTime":1710508084065}
{"op":"mcm","id":2,"clk":"ANBXAN54ANKFAQ==","pt":1710508084163,"mc":[{"id":"1.226122413","rc":[{"batb":[[1,7,63.15]],"id":41122648},{"tv":2218.02,"batb":[[0,27,5.73]],"trd":[[28,340.48]],"batl":[[2,34,30.34],[1,32,12.29],[0,30,7.29]],"id":55632148},{"tv":2691.21,"batb":[[2,34,14.67],[1,36,12.19],[0,38,16.06]],"trd":[[40,34.24]],"batl":[[2,48,9.54],[0,44,8.71]],"id":49744721}],"tv":126279.74}],"ArrivalTime":1710508084171}
{"op":"mcm","id":2,"clk":"ANhXAOZ4ANuFAQ==","pt":1710508084266,"mc":[{"id":"1.226122413","rc":[{"tv":8975.38,"batb":[[2,6.6,35.53],[1,6.8,56.37],[0,7,57.39]],"trd":[[7,22.19]],"ltp":7,"batl":[[2,7.6,40.4],[1,7.4,53.43],[0,7.2,19.43]],"id":41122648},{"batl":[[1,1.83,302.79]],"id":51922}],"tv":126286.76}],"ArrivalTime":1710508084274}
{"op":"mcm","id":2,"clk":"AOVXAO54AOyFAQ==","pt":1710508084377,"mc":[{"id":"1.226122413","rc":[{"batb":[[0,7,41.83]],"batl":[[1,7.4,36.38]],"id":41122648},{"batb":[[0,38,13.67]],"batl":[[2,48,11.59],[0,44,10.85]],"id":49744721}]}],"ArrivalTime":1710508084385}
{"op":"mcm","id":2,"clk":"AO1XAPV4APKFAQ==","pt":1710508084476,"mc":[{"id":"1.226122413","rc":[{"batb":[[1,1.8,541.52]],"batl":[[1,1.83,309.48]],"id":51922},{"batb":[[0,24,7.64]],"batl":[],"id":106596}]}],"ArrivalTime":1710508084484}
{"op":"mcm","id":2,"clk":"APFXAP94AP2FAQ==","pt":1710508084581,"mc":[{"id":"1.226122413","rc":[{"batb":[[0,7,57.39]],"batl":[[1,7.4,53.33]],"id":41122648},{"batl":[[2,310,1.71],[1,300,2.32],[0,290,2]],"id":41200638},{"batb":[[1,26,5.21]],"id":55632148},{"batl":[[0,44,5.6]],"id":49744721}]}],"ArrivalTime":1710508084588}
{"op":"mcm","id":2,"clk":"APpXAIV5AImGAQ==","pt":1710508084634,"mc":[{"id":"1.226122413","rc":[{"batb":[[1,340,1.46]],"id":54370634},{"batl":[[2,7.8,35.85],[1,7.6,40.4],[0,7.4,53.33]],"id":41122648},{"batb":[[0,27,11.18]],"id":55632148},{"batl":[[0,1.82,111.41]],"id":51922},{"tv":2300.32,"batb":[[0,24,6.39]],"trd":[[24,265.02]],"ltp":24,"id":106596}],"tv":126289.26}],"ArrivalTime":1710508084641}
{"op":"mcm","id":2,"clk":"AIJYAJN5AJOGAQ==","pt":1710508084750,"mc":[{"id":"1.226122413","rc":[{"batl":[[2,890,1],[1,750,1.91],[0,580,3.59]],"id":54370634},{"batb":[[2,6.6,38.33]],"batl":[],"id":41122648},{"batb":[[2,210,2.79]],"id":41200638},{"batb":[[0,27,7.59]],"batl":[[0,30,7.03]],"id":55632148},{"tv":91338.89,"batb":[[0,1.81,190.47]],"trd":[[1.81,1638.39]],"ltp":1.81,"id":51922},{"batb":[[0,5,104.3]],"id":50466254}],"tv":126460.05}],"ArrivalTime":1710508084758}
{"op":"mcm","id":2,"clk":"AIhYAJ15AJ+GAQ==","pt":1710508084848,"mc":[{"id":"1.226122413","rc":[{"batl":[[0,580,3.44]],"id":54370634},{"tv":8995.4,"batb":[[0,7,47.38]],"trd":[[7,42.21]],"batl":[],"id":41122648},{"batb":[[1,1.8,458.58]],"id":51922},{"batb":[[0,24,7.86]],"id":106596}],"tv":126480.07}],"ArrivalTime":1710508084856}
{"op":"mcm","id":2,"clk":"AIxYAKN5AKyGAQ==","pt":1710508084955,"mc":[{"id":"1.226122413","rc":[{"batb":[[2,6.6,35.53]],"id":41122648},{"tv":91406.93,"batb":[[0,1.81,161.45]],"trd":[[1.81,1706.43]],"id":51922},{"tv":2692.13,"batb":[[2,36,12.19],[1,38,13.67],[0,40,2.4]],"trd":[[42,0.92]],"ltp":42,"batl":[[0,44,5.14]],"id":49744721}],"tv":126549.03}],"ArrivalTime":1710508084963}
{"op":"mcm","id":2,"clk":"AJJYAK55ALmGAQ==","pt":1710508085058,"mc":[{"id":"1.226122413","rc":[{"tv":8999.44,"batb":[[0,7,45.36]],"trd":[[7,46.25]],"batl":[[2,7.6,40.4],[1,7.4,62.5],[0,7.2,7.84]],"id":41122648},{"tv":91464.85,"batb":[[0,1.81,132.49]],"trd":[[1.81,1764.35]],"batl":[[0,1.82,121.41]],"id":51922},{"batl":[[1,5.2,37.67]],"id":50466254}],"tv":126610.99}],"ArrivalTime":1710508085066}
{"op":"mcm","id":2,"clk":"AJtYALd5AMOGAQ==","pt":1710508085171,"mc":[{"id":"1.226122413","rc":[{"tv":9090.16,"batb":[[2,6.4,48.48],[1,6.6,35.53],[0,6.8,56.37]],"trd":[[7,136.97]],"batl":[[2,7.4,62.5],[1,7.2,7.84],[0,7,10]],"id":41122648},{"tv":91677,"batb":[[0,1.81,26.42]],"trd":[[1.81,1976.5]],"batl":[[2,1.84,199.09]],"id":51922},{"tv":2706.55,"batb":[[0,40,6.19]],"trd":[[44,14.42]],"ltp":44,"batl":[[2,50,7.32],[1,48,9.54],[0,46,10.24]],"id":49744721},{"batl":[[1,5.2,22.07]],"id":50466254},{"batb":[[1,23,21.16]],"batl":[],"id":106596}],"tv":126928.28}],"ArrivalTime":1710508085179}
{"op":"mcm","id":2,"clk":"AJ5YAMd5AMyGAQ==","pt":1710508085267,"mc":[{"id":"1.226122413","rc":[{"tv":9101.14,"batb":[[2,6.4,51.47],[1,6.6,38.33]],"trd":[[7,147.95]],"batl":[[0,7,4.51]],"id":41122648},{"batb":[[0,27,10.59]],"id":55632148},{"tv":91729.84,"batb":[[2,1.78,184.93],[1,1.79,323.74],[0,1.8,458.58]],"trd":[[1.81,2029.34]],"batl":[[2,1.84,203.09]],"id":51922},{"batb":[[2,36,19.57],[0,40,5.99]],"id":49744721}],"tv":126992.1}],"ArrivalTime":1710508085275}
{"op":"mcm","id":2,"clk":"AKJYAM95ANKGAQ==","pt":1710508085372,"mc":[{"id":"1.226122413","rc":[{"tv":9117.7,"batb":[[1,6.6,57.07],[0,6.8,40.33]],"trd":[[7,164.51]],"batl":[[1,7.2,42.75],[0,7,6.23]],"id":41122648},{"batb":[[2,26,5.21],[1,27,14.13],[0,28,2.18]],"id":55632148},{"tv":92029.86,"batb":[[2,1.79,323.74],[1,1.8,458.58],[0,1.81,1.47]],"trd":[[1.81,2106.55],[1.82,5642.06]],"ltp":1.82,"batl":[[2,1.84,199.83],[0,1.82,10]],"id":51922},{"tv":2707.07,"batb":[[2,38,13.67],[1,40,5.73],[0,42,3.38]],"trd":[[40,34.76]],"ltp":40,"batl":[[2,50,6.89]],"id":49744721},{"batb":[[0,5,118.3]],"batl":[[1,5.2,7.14]],"id":50466254},{"batl":[[1,27,9.26],[0,26,3.89]],"id":106596}],"tv":127309.2}],"ArrivalTime":1710508085379}
{"op":"mcm","id":2,"clk":"AKpYANl5AN2GAQ==","pt":1710508085474,"mc":[{"id":"1.226122413","rc":[{"batl":[[2,750,1.91],[1,580,2.82],[0,570,3.18]],"id":54370634},{"tv":9123.06,"trd":[[7,169.87]],"batl":[[0,7,3.55]],"id":41122648},{"tv":92032.79,"batb":[[2,1.78,243.26],[1,1.79,323.74],[0,1.8,458.58]],"trd":[[1.81,2109.48]],"ltp":1.81,"batl":[[2,1.83,309.48],[1,1.82,10],[0,1.81,87.55]],"id":51922},{"tv":2710.27,"batb":[],"trd":[[46,3.2]],"ltp":46,"batl":[[1,48,10.01],[0,46,9.15]],"id":49744721}],"tv":127320.69}],"ArrivalTime":1710508085482}
{"op":"mcm","id":2,"clk":"ALNYAOd5APKGAQ==","pt":1710508085599,"mc":[{"id":"1.226122413","rc":[{"batb":[[2,6.4,48.48],[1,6.6,54.27],[0,6.8,37.71]],"id":41122648},{"tv":2233.2,"batb":[[2,25,14.15],[1,26,8.71],[0,27,8.72]],"trd":[[28,344.84],[27,321.15]],"ltp":27,"id":55632148},{"tv":2717.03,"batb":[[0,42,3.59]],"trd":[[42,7.68]],"ltp":42,"batl":[[2,50,7.32],[0,46,8.01]],"id":49744721},{"tv":17509.43,"trd":[[5.1,11.42]],"ltp":5.1,"batl":[[0,5.1,59.41]],"id":50466254}],"tv":127352.05}],"ArrivalTime":1710508085607}
{"op":"mcm","id":2,"clk":"ALRYAOx5APyGAQ==","pt":1710508085683,"mc":[{"id":"1.226122413","rc":[{"tv":9134.52,"batb":[[0,6.8,31.98]],"trd":[[6.8,25.39]],"ltp":6.8,"batl":[[2,7.4,74.44]],"id":41122648},{"batb":[[2,26,8.71],[1,27,8.72],[0,28,2.59]],"id":55632148},{"batl":[[2,1.83,312.06],[1,1.82,35.65],[0,1.81,61.76]],"id":51922},{"batl":[[1,48,9.54],[0,46,7.5]],"id":49744721},{"tv":17583.35,"batb":[[0,5,93.3]],"trd":[[5,198.22],[5.1,35.34]],"ltp":5,"batl":[[0,5.1,18.82]],"id":50466254}],"tv":127437.43}],"ArrivalTime":1710508085691}
{"op":"mcm","id":2,"clk":"ALxYAPp5AISHAQ==","pt":1710508085792,"mc":[{"id":"1.226122413","rc":[{"tv":383.64,"batb":[[0,350,5.51]],"trd":[[460,0.6]],"ltp":460,"batl":[[0,570,2.88]],"id":54370634},{"batb":[[1,220,6.9]],"id":41200638},{"batb":[[1,27,10.98]],"id":55632148},{"tv":92040.99,"batb":[[0,1.8,460.06]],"trd":[[1.81,2117.68]],"batl":[[0,1.81,57.66]],"id":51922},{"batb":[[0,42,5.93]],"batl":[[2,50,6.89],[0,46,9.5]],"id":49744721},{"batb":[[2,22,17.06]],"id":106596}],"tv":127446.23}],"ArrivalTime":1710508085799}
{"op":"mcm","id":2,"clk":"AL5YAIR6AI6HAQ==","pt":1710508085844,"mc":[{"id":"1.226122413","rc":[{"tv":9141.62,"batb":[[2,6.6,54.27],[1,6.8,31.98],[0,7,9.25]],"trd":[[7,176.97]],"ltp":7,"batl":[[2,7.6,40.4],[1,7.4,74.44],[0,7.2,42.75]],"id":41122648},{"tv":2234.24,"batb":[[0,28,2.07]],"trd":[[28,345.88]],"ltp":28,"id":55632148},{"batl":[[0,1.81,143.06]],"id":51922},{"tv":2728.89,"batb":[[2,36,12.19],[1,38,13.67],[0,40,5.73]],"trd":[[42,19.54]],"batl":[[2,48,9.54],[1,46,9.5],[0,42,4.07]],"id":49744721},{"tv":17603.65,"trd":[[5.1,55.64]],"ltp":5.1,"batl":[[0,5.1,8.67]],"id":50466254}],"tv":127486.53}],"ArrivalTime":1710508085852}
{"op":"mcm","id":2,"clk":"AMFYAIl6AJWHAQ==","pt":1710508085949,"mc":[{"id":"1.226122413","rc":[{"tv":490.8,"trd":[[290,34.53]],"ltp":290,"batl":[[2,320,1.71],[1,310,1.71],[0,300,2.32]],"id":41200638},{"tv":92149.23,"batb":[],"trd":[[1.81,2225.92]],"batl":[[0,1.81,98.94]],"id":51922},{"tv":2737.03,"trd":[[42,27.68]],"batl":[[2,50,8.88],[1,48,9.54],[0,46,9.5]],"id":49744721},{"tv":17605.33,"trd":[[5.1,57.32]],"batl":[[0,5.1,7.83]],"id":50466254}],"tv":127608.59}],"ArrivalTime":1710508085956}
{"op":"mcm","id":2,"clk":"AMpYAJR6AKCHAQ==","pt":1710508086067,"mc":[{"id":"1.226122413","rc":[{"tv":9146.02,"batb":[[0,7,7.05]],"trd":[[7,181.37]],"batl":[[0,7.2,25.57]],"id":41122648},{"batb":[[2,25,14.15],[1,26,8.71],[0,27,10.98]],"id":55632148},{"batl":[[2,48,9.54],[1,46,9.5],[0,44,2.24]],"id":49744721},{"tv":17619.87,"batb":[],"trd":[[5.1,71.86]],"batl":[[2,5.4,114.05],[1,5.3,63.59],[0,5.2,7.7]],"id":50466254}],"tv":127627.53}],"ArrivalTime":1710508086074}
{"op":"mcm","id":2,"clk":"ANFYAKF6AKuHAQ==","pt":1710508086157,"mc":[{"id":"1.226122413","rc":[{"batb":[[0,1.8,463.61]],"batl":[[0,1.81,104.85]],"id":51922},{"tv":2738.41,"batb":[[0,40,5.04]],"trd":[[40,36.14]],"ltp":40,"batl":[],"id":49744721},{"tv":17620.99,"batb":[],"trd":[[5.1,72.98]],"batl":[[0,5.2,7.14]],"id":50466254}],"tv":127630.03}],"ArrivalTime":1710508086165}
{"op":"mcm","id":2,"clk":"ANdYAK56ALWHAQ==","pt":1710508086263,"mc":[{"id":"1.226122413","rc":[{"batl":[[2,890,1],[1,750,1.91],[0,580,3.14]],"id":54370634},{"tv":9160.12,"batb":[[2,6.4,51.47],[1,6.6,54.27],[0,6.8,31.98]],"trd":[[7,195.47]],"batl":[[2,7.4,66.59],[1,7.2,25.57],[0,7,17.25]],"id":41122648},{"tv":92320.02,"trd":[[1.81,2396.71]],"batl":[[0,1.81,54.9]],"id":51922},{"batl":[[2,50,6.89],[1,48,9.54],[0,46,9.5]],"id":49744721},{"batb":[],"batl":[[1,5.3,38.04],[0,5.2,7.47]],"id":50466254}],"tv":127814.92}],"ArrivalTime":1710508086270}
{"op":"mcm","id":2,"clk":"AN1YALd6ALmHAQ==","pt":1710508086359,"mc":[{"id":"1.226122413","rc":[{"batl":[[1,7.2,27.57]],"id":41122648},{"tv":92367.63,"trd":[[1.81,2444.32]],"batl":[[0,1.81,31.09]],"id":51922},{"tv":2739.67,"batb":[[0,40,4.41]],"trd":[[40,37.4]],"batl":[[0,46,9.64]],"id":49744721},{"batb":[],"batl":[[0,5.2,7.35]],"id":50466254}],"tv":127863.79}],"ArrivalTime":1710508086367}
{"op":"mcm","id":2,"clk":"AOVYAMF6AMeHAQ==","pt":1710508086475,"mc":[{"id":"1.226122413","rc":[{"tv":385.65,"batb":[[0,350,4.51]],"trd":[[360,21.63],[350,18.79]],"ltp":350,"id":54370634},{"batb":[[1,6.6,57.07]],"batl":[[1,7.2,37.06]],"id":41122648},{"batl":[[2,310,1.71],[1,300,2.32],[0,280,1]],"id":41200638},{"tv":2236.64,"batb":[[0,27,9.78]],"trd":[[27,323.55]],"ltp":27,"id":55632148},{"tv":92600.61,"batb":[[2,1.79,323.74],[1,1.8,463.61],[0,1.81,120.05]],"trd":[[1.81,2677.3]],"batl":[[2,1.84,189.83],[1,1.83,312.06],[0,1.82,35.65]],"id":51922},{"tv":2742.05,"batb":[[0,40,3.22]],"trd":[[40,39.78]],"id":49744721},{"batb":[[2,4.9,48.57],[1,5,93.3],[0,5.1,28.28]],"id":50466254},{"tv":568.38,"batb":[[0,160,3.93]],"trd":[[160,29.4]],"ltp":160,"id":66251581},{"batb":[[0,24,11.75]],"batl":[[0,26,1]],"id":106596}],"tv":128105.56}],"ArrivalTime":1710508086483}
{"op":"mcm","id":2,"clk":"APlYAMd6AMuHAQ==","pt":1710508086706,"mc":[{"id":"1.226122413","rc":[{"batl":[[0,7,8.74]],"id":41122648},{"batb":[[1,26,14.33]],"id":55632148},{"tv":92759.13,"batb":[[1,1.8,489.19],[0,1.81,90.8]],"trd":[[1.81,2835.82]],"batl":[[2,1.84,193.09],[1,1.83,225.46]],"id":51922},{"batl":[[0,46,10.26]],"id":49744721},{"tv":17635.69,"batb":[[0,5.1,29.2]],"trd":[[5.2,14.7]],"ltp":5.2,"batl":[[2,5.5,33.63],[1,5.4,114.05],[0,5.3,38.04]],"id":50466254}],"tv":128278.78,"con":true}],"ArrivalTime":1710508086714}
{"op":"mcm","id":2,"clk":"APxYAOB6AOOHAQ==","pt":1710508086780,"mc":[{"id":"1.226122413","rc":[{"tv":9175.8,"batb":[[1,6.6,54.27],[0,6.8,21.57]],"trd":[[6.8,41.07]],"ltp":6.8,"id":41122648},{"tv":92761.47,"batb":[[0,1.81,89.63]],"trd":[[1.81,2838.16]],"batl":[[0,1.82,125.87]],"id":51922},{"batb":[[0,40,5.66]],"batl":[[2,50,8.87]],"id":49744721},{"tv":17637.53,"batb":[[2,5,95.87],[1,5.1,42.28],[0,5.2,2.71]],"trd":[[5.2,16.54]],"batl":[[0,5.3,81.34]],"id":50466254}],"tv":128298.64}],"ArrivalTime":1710508086787}
{"op":"mcm","id":2,"clk":"AIFZAO56AOmHAQ==","pt":1710508086886,"mc":[{"id":"1.226122413","rc":[{"batl":[[2,750,1.91],[1,580,2.82],[0,570,2.88]],"id":54370634},{"tv":92940.73,"batb":[[2,1.78,243.26],[1,1.79,323.74],[0,1.8,489.19]],"trd":[[1.81,3017.42]],"batl":[[2,1.83,284.16],[1,1.82,125.87],[0,1.81,30.5]],"id":51922},{"batb":[[2,36,45.19]],"id":49744721}],"tv":128477.9}],"ArrivalTime":1710508086893}
{"op":"mcm","id":2,"clk":"AIhZAPl6AO+HAQ==","pt":1710508086950,"mc":[{"id":"1.226122413","rc":[{"batl":[[1,7.2,35.06]],"id":41122648},{"batb":[[0,1.8,463.61]],"batl":[[2,1.84,193.09],[1,1.83,287.47],[0,1.82,125.87]],"id":51922},{"tv":17642.95,"batb":[[2,4.9,48.57],[1,5,95.87],[0,5.1,42.28]],"trd":[[5.2,21.96]],"batl":[],"id":50466254},{"tv":576,"trd":[[190,8.57]],"ltp":190,"batl":[[2,260,2.37],[1,250,4],[0,210,5]],"id":66251581}],"tv":128490.94}],"ArrivalTime":1710508086958}
{"op":"mcm","id":2,"clk":"AIxZAIJ7APeHAQ==","pt":1710508087053,"mc":[{"id":"1.226122413","rc":[{"batb":[[1,6.6,57.07],[0,6.8,31.06]],"batl":[[2,7.6,40.4],[1,7.4,66.59],[0,7.2,35.06]],"id":41122648},{"tv":93052.25,"batb":[[1,1.79,303.58],[0,1.8,455.43]],"trd":[[1.81,3078.42],[1.82,5676.22],[1.8,148.34]],"ltp":1.8,"batl":[[2,1.83,287.47],[1,1.82,108.79],[0,1.81,37.99]],"id":51922},{"batl":[[2,50,6.89]],"id":49744721}],"tv":128602.46}],"ArrivalTime":1710508087060}
{"op":"mcm","id":2,"clk":"AJJZAI57AICIAQ==","pt":1710508087153,"mc":[{"id":"1.226122413","rc":[{"batl":[[0,570,3.88]],"id":54370634},{"batl":[[2,7.6,67.06]],"id":41122648},{"batl":[[2,5.5,57.22]],"id":50466254},{"batb":[[0,160,4.22]],"batl":[[2,250,4],[1,210,5],[0,200,2.19]],"id":66251581}]}],"ArrivalTime":1710508087161}
{"op":"mcm","id":2,"clk":"AJpZAJR7AIyIAQ==","pt":1710508087255,"mc":[{"id":"1.226122413","rc":[{"batl":[[0,570,3.97]],"id":54370634},{"batb":[[2,6.4,48.48],[1,6.6,54.27]],"batl":[[2,7.4,66.59],[1,7.2,35.06],[0,7,1]],"id":41122648},{"batb":[[0,27,8.8]],"id":55632148},{"batl":[[2,1.83,284.16],[0,1.81,63.18]],"id":51922},{"batl":[[0,46,6.09]],"id":49744721},{"tv":17662.95,"batb":[[0,5.1,32.28]],"trd":[[5.1,92.98]],"ltp":5.1,"batl":[[0,5.3,60.77]],"id":50466254},{"batb":[[2,23,21.16],[1,24,11.75],[0,25,1]],"batl":[],"id":106596}],"tv":128622.46}],"ArrivalTime":1710508087263}
{"op":"mcm","id":2,"clk":"AKFZAJ17AJSIAQ==","pt":1710508087354,"mc":[{"id":"1.226122413","rc":[{"batl":[[1,7.2,60.06]],"id":41122648},{"batb":[[0,230,3.3]],"id":41200638},{"batl":[[0,30,7.37]],"id":55632148},{"batb":[[1,1.79,329.05]],"id":51922},{"batb":[[2,38,13.67],[1,40,5.66],[0,42,2.34]],"id":49744721}]}],"ArrivalTime":1710508087361}
{"op":"mcm","id":2,"clk":"AKhZAKZ7AKGIAQ==","pt":1710508087462,"mc":[{"id":"1.226122413","rc":[{"batb":[[2,6.4,51.47],[1,6.6,57.07]],"id":41122648},{"batl":[[2,28,12.7],[1,27,10],[0,26,1.8]],"id":106596}]}],"ArrivalTime":1710508087470}
{"op":"mcm","id":2,"clk":"ALlZALN7ALGIAQ==","pt":1710508087579,"mc":[{"id":"1.226122413","rc":[{"tv":492.8,"batb":[[2,220,6.9],[1,230,3.3],[0,280,4.73]],"trd":[[280,21.29]],"ltp":280,"batl":[[2,320,1.71],[1,310,1.71],[0,300,2.32]],"id":41200638},{"batl":[[0,30,7.04]],"id":55632148},{"batb":[[0,42,4.93]],"id":49744721},{"batb":[[0,25,4.59]],"id":106596}],"tv":128624.46}],"ArrivalTime":1710508087587}
{"op":"mcm","id":2,"clk":"AL5ZALp7ALiIAQ==","pt":1710508087668,"mc":[{"id":"1.226122413","rc":[{"batb":[[2,26,14.33],[1,27,8.8],[0,28,8]],"id":55632148},{"tv":93052.29,"trd":[[1.81,3078.46]],"ltp":1.81,"batl":[[0,1.81,148.56]],"id":51922},{"batb":[[0,5.1,32.36]],"id":50466254}],"tv":128624.5}],"ArrivalTime":1710508087676}
{"op":"mcm","id":2,"clk":"AMRZAMF7AL6IAQ==","pt":1710508087763,"mc":[{"id":"1.226122413","rc":[{"batl":[[0,7,6.73]],"id":41122648},{"tv":497.61,"batb":[[1,230,4.35],[0,280,2.32]],"trd":[[280,26.1]],"id":41200638},{"batb":[[0,28,8.07]],"id":55632148},{"batb":[[1,1.79,272.51]],"batl":[[2,1.83,289.88]],"id":51922},{"tv":17727.5,"batb":[[2,4.8,55.28],[1,4.9,48.57],[0,5,95.95]],"trd":[[5.1,157.53]],"id":50466254},{"tv":2303.92,"batb":[],"trd":[[26,392.24]],"ltp":26,"batl":[[2,29,9.03],[1,28,12.7],[0,27,10]],"id":106596}],"tv":128697.46}],"ArrivalTime":1710508087770}
{"op":"mcm","id":2,"clk":"AMxZAM97AMWIAQ==","pt":1710508087873,"mc":[{"id":"1.226122413","rc":[{"batl":[[0,570,1.41]],"id":54370634},{"batb":[[1,230,3.09]],"id":41200638},{"batb":[[0,28,10.45]],"batl":[[0,30,5.11]],"id":55632148},{"tv":93075.27,"batb":[[0,1.8,443.94]],"trd":[[1.8,171.32]],"ltp":1.8,"id":51922},{"tv":2751.91,"batb":[[2,36,45.19],[1,38,13.67],[0,40,5.66]],"trd":[[42,37.54]],"ltp":42,"id":49744721},{"batl":[[2,29,9.67]],"id":106596}],"tv":128730.3}],"ArrivalTime":1710508087881}
{"op":"mcm","id":2,"clk":"ANNZANh7ANGIAQ==","pt":1710508087980,"mc":[{"id":"1.226122413","rc":[{"batl":[[1,7.2,52.22]],"id":41122648},{"tv":498.07,"batb":[[2,220,8],[0,280,2.09]],"trd":[[280,26.56]],"id":41200638},{"tv":93081.29,"batb":[[0,1.8,445.94]],"trd":[[1.81,3084.48]],"ltp":1.81,"batl":[[2,1.83,201.17],[0,1.81,145.55]],"id":51922},{"batb":[[0,40,9.93]],"batl":[[0,46,3.95]],"id":49744721},{"tv":17734.36,"batb":[[2,4.9,48.57],[1,5,92.52],[0,5.1,9.55]],"trd":[[5,204.92],[5.1,157.69]],"ltp":5,"id":50466254},{"batb":[[1,24,15.25],[0,25,7.86]],"batl":[[2,29,12.57],[1,28,8.8],[0,27,9.26]],"id":106596}],"tv":128743.64}],"ArrivalTime":1710508087987}
{"op":"mcm","id":2,"clk":"ANdZAN97ANiIAQ==","pt":1710508088108,"mc":[{"id":"1.226122413","rc":[{"batb":[[2,26,18.95],[1,27,20.8]],"id":55632148},{"batl":[[0,1.81,155.55]],"id":51922},{"batb":[[2,38,13.67],[1,40,9.93],[0,42,3.85]],"batl":[],"id":49744721},{"batl":[[2,29,11.93],[0,27,12.48]],"id":106596}]}],"ArrivalTime":1710508088115}
{"op":"mcm","id":2,"clk":"ANtZAOd7AOSIAQ==","pt":1710508088137,"mc":[{"id":"1.226122413","rc":[{"batl":[[0,7,15.85]],"id":41122648},{"tv":498.69,"batb":[[0,280,1.78]],"trd":[[280,27.18]],"id":41200638},{"batb":[],"batl":[[2,1.83,204.48]],"id":51922},{"tv":2752.51,"batb":[[0,42,4.38]],"trd":[[44,15.02]],"ltp":44,"batl":[[2,50,8.87],[0,46,5.71]],"id":49744721},{"batl":[[0,27,3.23]],"id":106596}],"tv":128744.86}],"ArrivalTime":1710508088145}
{"op":"mcm","id":2,"clk":"AONZAPR7APKIAQ==","pt":1710508088250,"mc":[{"id":"1.226122413","rc":[{"batb":[[0,6.8,21.57]],"batl":[],"id":41122648},{"batb":[[2,230,3.09],[1,270,1.59]],"id":41200638},{"batb":[[2,27,20.8],[1,28,12.52],[0,29,2.32]],"id":55632148},{"tv":93237.29,"batb":[[0,1.8,367.94]],"trd":[[1.8,327.32]],"ltp":1.8,"batl":[[2,1.83,219.48]],"id":51922},{"tv":2753.15,"batb":[[0,42,6.38]],"trd":[[44,15.66]],"batl":[[0,46,5.39]],"id":49744721}],"tv":128901.5}],"ArrivalTime":1710508088257}
{"op":"mcm","id":2,"clk":"AOtZAP97AP2IAQ==","pt":1710508088354,"mc":[{"id":"1.226122413","rc":[{"batl":[[2,580,2.82],[1,570,1],[0,560,2.97]],"id":54370634},{"tv":93408.09,"batb":[[0,1.8,282.53]],"trd":[[1.8,498.12]],"id":51922},{"batb":[[0,5.1,27.21]],"id":50466254},{"batl":[[2,30,11.58],[1,29,9.03],[0,28,8.8]],"id":106596}],"tv":129072.3}],"ArrivalTime":1710508088362}
{"op":"mcm","id":2,"clk":"APNZAIh8AIaJAQ==","pt":1710508088458,"mc":[{"id":"1.226122413","rc":[{"tv":9185.54,"batb":[[0,6.8,17.55]],"trd":[[7,197.17],[6.8,49.11]],"ltp":7,"batl":[[0,7,15]],"id":41122648},{"tv":93790.67,"batb":[[0,1.8,91.24]],"trd":[[1.8,880.7]],"id":51922},{"batl":[[0,46,3.33]],"id":49744721}],"tv":129464.62}],"ArrivalTime":1710508088466}
{"op":"mcm","id":2,"clk":"APlZAI18AJCJAQ==","pt":1710508088547,"mc":[{"id":"1.226122413","rc":[{"tv":9225.89,"batb":[[2,6.2,38.67],[1,6.4,51.47],[0,6.6,57.07]],"trd":[[6.8,89.46]],"ltp":6.8,"batl":[[2,7.2,52.22],[1,7,15],[0,6.8,4.83]],"id":41122648},{"batb":[[2,270,1.59],[1,280,1.78],[0,290,1]],"id":41200638},{"tv":2237.42,"trd":[[30,38.51]],"ltp":30,"batl":[[0,30,4.72]],"id":55632148},{"tv":93823.63,"batb":[[1,1.79,247.04],[0,1.8,74.76]],"trd":[[1.8,913.66]],"batl":[[0,1.81,255.55]],"id":51922},{"batl":[[2,50,6.89]],"id":49744721},{"batb":[[0,5.1,43.25]],"id":50466254},{"batb":[[2,24,15.25],[1,25,11.2],[0,26,2.62]],"batl":[[0,28,5.56]],"id":106596}],"tv":129538.71}],"ArrivalTime":1710508088555}
{"op":"mcm","id":2,"clk":"AP5ZAJh8AJyJAQ==","pt":1710508088666,"mc":[{"id":"1.226122413","rc":[{"batl":[[1,7,17]],"id":41122648},{"batl":[[0,300,1.71]],"id":41200638},{"tv":2240.1,"batb":[[0,29,5.2]],"trd":[[30,41.19]],"batl":[[0,30,3.38]],"id":55632148},{"tv":94867.49,"batb":[[2,1.77,138.85],[1,1.78,184.93],[0,1.79,67.46]],"trd":[[1.81,3811.46],[1.79,103.84],[1.8,1126.7]],"batl":[[2,1.83,218.17],[0,1.8,21.54]],"id":51922},{"batb":[[0,26,3.62]],"batl":[[2,30,12.18],[0,28,8.46]],"id":106596}],"tv":130585.25}],"ArrivalTime":1710508088674}
{"op":"mcm","id":2,"clk":"AIVaAKp8AKSJAQ==","pt":1710508088765,"mc":[{"id":"1.226122413","rc":[{"tv":9235.55,"batb":[[1,6.4,69.36],[0,6.6,47.33]],"trd":[[6.8,99.12]],"batl":[[2,7.4,66.59],[1,7.2,52.22],[0,7,32.06]],"id":41122648},{"tv":498.96,"batb":[[1,280,2.78]],"trd":[[300,40.09]],"ltp":300,"batl":[[0,300,1.57]],"id":41200638},{"batb":[[1,28,12.59],[0,29,5.69]],"id":55632148},{"tv":94910.56,"trd":[[1.8,1169.77]],"batl":[[2,1.84,108.43],[1,1.83,230.67],[0,1.82,108.79]],"id":51922},{"batb":[[0,5.1,55.25]],"batl":[[0,5.3,45.87]],"id":50466254},{"batb":[[0,26,7.21]],"batl":[[2,30,9.38]],"id":106596}],"tv":130638.25}],"ArrivalTime":1710508088772}
{"op":"mcm","id":2,"clk":"AIxaALB8AKyJAQ==","pt":1710508088861,"mc":[{"id":"1.226122413","rc":[{"batb":[[2,27,23.4]],"id":55632148},{"batb":[[2,1.78,246.02],[1,1.79,92.52],[0,1.8,40.33]],"batl":[[0,1.82,133.79]],"id":51922},{"tv":17749.56,"batb":[[0,5.1,47.65]],"trd":[[5.1,172.89]],"ltp":5.1,"batl":[[2,5.4,114.05],[1,5.3,45.87],[0,5.2,11.93]],"id":50466254},{"batl":[[0,28,12.27]],"id":106596}],"tv":130653.45}],"ArrivalTime":1710508088869}
{"op":"mcm","id":2,"clk":"AJdaALx8ALiJAQ==","pt":1710508088962,"mc":[{"id":"1.226122413","rc":[{"batb":[[1,6.4,66.37],[0,6.6,34.89]],"batl":[[2,7.2,54.79],[1,7,32.06],[0,6.8,12.09]],"id":41122648},{"tv":499.18,"trd":[[300,40.31]],"batl":[[0,300,1.46]],"id":41200638},{"tv":94944.06,"trd":[[1.82,5709.72]],"ltp":1.82,"batl":[[2,1.84,105.17],[0,1.82,117.04]],"id":51922},{"tv":2754.17,"trd":[[46,4.22]],"ltp":46,"batl":[[0,46,2.82]],"id":49744721},{"batl":[[1,5.3,61.35]],"id":50466254},{"tv":2305.72,"trd":[[28,234.07]],"ltp":28,"batl":[[0,28,11.37]],"id":106596}],"tv":130689.99}],"ArrivalTime":1710508088970}
{"op":"mcm","id":2,"clk":"AJ5aAM58AMCJAQ==","pt":1710508089066,"mc":[{"id":"1.226122413","rc":[{"batb":[[1,28,12.66]],"id":55632148},{"batb":[[0,1.8,68.03]],"batl":[[0,1.82,129.7]],"id":51922},{"tv":2759.81,"trd":[[46,9.86]],"batl":[[2,55,5.76],[1,50,6.89],[0,48,9.54]],"id":49744721}],"tv":130695.63}],"ArrivalTime":1710508089074}
{"op":"mcm","id":2,"clk":"AKNaANl8AMyJAQ==","pt":1710508089174,"mc":[{"id":"1.226122413","rc":[{"batb":[[1,6.4,69.36],[0,6.6,37.69]],"batl":[],"id":41122648},{"tv":94944.12,"batb":[[2,1.79,92.52],[1,1.8,68.03],[0,1.81,94.91]],"trd":[[1.81,3811.52]],"ltp":1.81,"batl":[[0,1.82,155.27]],"id":51922},{"batb":[[0,42,10.65]],"id":49744721},{"batl":[[2,5.5,57.22],[1,5.4,114.05],[0,5.3,61.35]],"id":50466254}],"tv":130695.69}],"ArrivalTime":1710508089182}
{"op":"mcm","id":2,"clk":"AKZaAOB8ANWJAQ==","pt":1710508089280,"mc":[{"id":"1.226122413","rc":[{"tv":386.09,"trd":[[480,0.44]],"ltp":480,"batl":[[0,560,2.75]],"id":54370634},{"batl":[[1,7,30.06],[0,6.8,22.09]],"id":41122648},{"tv":499.54,"trd":[[300,40.67]],"batl":[[0,300,1.28]],"id":41200638},{"tv":2763.85,"trd":[[48,4.04]],"ltp":48,"batl":[[0,48,9.52]],"id":49744721},{"tv":17795.86,"batb":[[0,5.1,24.5]],"trd":[[5.1,219.19]],"batl":[[0,5.3,85.38]],"id":50466254},{"tv":578,"batb":[[0,160,3.22]],"trd":[[170,37.54],[160,30.82]],"ltp":160,"id":66251581}],"tv":130748.83}],"ArrivalTime":1710508089288}
{"op":"mcm","id":2,"clk":"AKtaAOd8AN+JAQ==","pt":1710508089380,"mc":[{"id":"1.226122413","rc":[{"batl":[[2,890,1],[1,750,1.91],[0,580,3.01]],"id":54370634},{"batb":[[0,6.6,27.41]],"batl":[[2,7.2,54.84]],"id":41122648},{"tv":94994.12,"batb":[[2,1.79,152.45],[0,1.81,69.91]],"trd":[[1.81,3861.52]],"batl":[[2,1.84,108.43]],"id":51922},{"batb":[[2,40,9.93],[1,42,10.65],[0,44,2.14]],"id":49744721},{"batb":[],"batl":[[1,29,9.67],[0,28,9.18]],"id":106596}],"tv":130798.83}],"ArrivalTime":1710508089388}
{"op":"mcm","id":2,"clk":"ALFaAO58AOeJAQ==","pt":1710508089488,"mc":[{"id":"1.226122413","rc":[{"batb":[[0,350,4.73]],"batl":[[2,750,1.91],[1,580,2.91],[0,550,1.1]],"id":54370634},{"tv":499.88,"trd":[[300,41.01]],"batl":[[0,300,1.11]],"id":41200638},{"tv":95164.92,"batb":[[2,1.78,246.02],[1,1.79,152.45],[0,1.8,52.9]],"trd":[[1.81,4001.33],[1.8,1200.76]],"ltp":1.8,"id":51922},{"tv":2767.65,"trd":[[48,7.84]],"batl":[[0,48,6.55]],"id":49744721},{"tv":17844.86,"batb":[[0,5.1,3.13]],"trd":[[5.1,268.19]],"batl":[[2,5.4,114.05],[1,5.3,85.38],[0,5.2,11.98]],"id":50466254},{"tv":2317.18,"batb":[[0,26,4.59]],"trd":[[28,245.53]],"batl":[[0,28,3.45]],"id":106596}],"tv":131034.23}],"ArrivalTime":1710508089496}
{"op":"mcm","id":2,"clk":"ALhaAPh8AO6JAQ==","pt":1710508089538,"mc":[{"id":"1.226122413","rc":[{"tv":95168.91,"batb":[[0,1.8,104.49]],"trd":[[1.8,1204.75]],"batl":[],"id":51922},{"batb":[[0,44,4.73]],"batl":[],"id":49744721}],"tv":131038.22}],"ArrivalTime":1710508089546}
{"op":"mcm","id":2,"clk":"AL9aAIN9APeJAQ==","pt":1710508089639,"mc":[{"id":"1.226122413","rc":[{"tv":2241.72,"trd":[[30,42.81]],"batl":[[0,30,2.57]],"id":55632148},{"tv":95360.04,"batb":[[2,1.79,152.45],[1,1.8,19.1],[0,1.81,15.45]],"trd":[[1.8,1375.54],[1.82,5730.06]],"ltp":1.82,"batl":[[2,1.84,105.17],[0,1.82,145.1]],"id":51922},{"batl":[[2,55,3.95]],"id":49744721},{"tv":17851.12,"batb":[[2,4.8,55.28],[1,4.9,48.57],[0,5,92.52]],"trd":[[5.1,274.45]],"batl":[[2,5.3,85.38],[1,5.2,27.97],[0,5.1,32.02]],"id":50466254},{"batb":[[2,140,2.7],[1,160,3.22],[0,180,2.11]],"id":66251581},{"tv":2324.08,"batb":[[2,26,10.44],[1,27,1],[0,28,2.95]],"trd":[[28,252.43]],"batl":[[2,32,17.32],[1,30,9.38],[0,29,9.03]],"id":106596}],"tv":131244.13}],"ArrivalTime":1710508089647}
{"op":"mcm","id":2,"clk":"AMdaAIh9AP2JAQ==","pt":1710508089751,"mc":[{"id":"1.226122413","rc":[{"tv":502.1,"trd":[[300,43.23]],"batl":[[2,330,1.71],[1,320,1.71],[0,310,1.71]],"id":41200638},{"tv":95390.94,"batb":[[2,1.78,246.02],[1,1.79,92.52],[0,1.8,19.1]],"trd":[[1.81,4032.23]],"ltp":1.81,"batl":[[2,1.83,230.67],[1,1.82,145.1],[0,1.81,2.52]],"id":51922},{"batb":[[2,150,1.34]],"id":66251581},{"tv":2329.98,"batb":[[2,25,11.2],[1,26,10.44],[0,27,1]],"trd":[[28,258.33]],"batl":[[0,29,9.78]],"id":106596}],"tv":131283.15}],"ArrivalTime":1710508089759}
{"op":"mcm","id":2,"clk":"AMtaAJN9AIeKAQ==","pt":1710508089862,"mc":[{"id":"1.226122413","rc":[{"batl":[[2,580,2.91],[1,550,1],[0,540,2.66]],"id":54370634},{"tv":9242.23,"trd":[[6.8,105.8]],"batl":[[2,7.2,29.84],[0,6.8,18.75]],"id":41122648},{"tv":95391.64,"batb":[[1,1.79,94.52]],"trd":[[1.81,4032.93]],"batl":[[1,1.82,198.5],[0,1.81,40.01]],"id":51922},{"batb":[[2,4.8,58.08]],"id":50466254},{"tv":2331.98,"trd":[[28,260.33]],"batl":[[0,29,10.11]],"id":106596}],"tv":131292.53}],"ArrivalTime":1710508089870}
{"op":"mcm","id":2,"clk":"AM1aAJl9AI6KAQ==","pt":1710508089956,"mc":[{"id":"1.226122413","rc":[{"tv":9246.23,"batb":[[0,6.6,25.41]],"trd":[[6.6,49.28]],"ltp":6.6,"id":41122648},{"tv":502.17,"trd":[[310,0.86]],"ltp":310,"batl":[[0,310,1.67]],"id":41200638},{"tv":2243.44,"trd":[[30,44.53]],"batl":[[0,30,1.71]],"id":55632148},{"tv":95509.86,"batb":[[2,1.79,94.52],[1,1.8,68.01],[0,1.81,59.99]],"trd":[[1.81,4112.95],[1.8,1413.74]],"batl":[[2,1.84,108.43],[1,1.83,230.67],[0,1.82,198.5]],"id":51922},{"batb":[[2,160,3.22],[1,170,1.59]],"id":66251581},{"tv":2332.86,"batb":[[2,26,10.44],[1,27,4.59],[0,28,2.14]],"trd":[[28,261.21]],"batl":[[0,29,9.67]],"id":106596}],"tv":131417.42}],"ArrivalTime":1710508089964}
{"op":"mcm","id":2,"clk":"ANNaAKN9AJ6KAQ==","pt":1710508090067,"mc":[{"id":"1.226122413","rc":[{"batl":[[2,750,1.91],[1,580,2.91]],"id":54370634},{"batb":[[0,6.6,42.25]],"batl":[[0,6.8,10]],"id":41122648},{"tv":95564.94,"batb":[[2,1.79,194.52],[0,1.81,32.45]],"trd":[[1.81,4168.03]],"batl":[[2,1.84,105.17]],"id":51922},{"tv":17878.2,"batb":[[0,5,78.98]],"trd":[[5,232]],"ltp":5,"batl":[[0,5.1,7.27]],"id":50466254},{"tv":2333.66,"batb":[[0,28,1.74]],"trd":[[28,262.01]],"batl":[[2,32,16.24],[1,30,8.78],[0,29,9.03]],"id":106596}],"tv":131500.38}],"ArrivalTime":1710508090075}
{"op":"mcm","id":2,"clk":"ANZaAK19AKaKAQ==","pt":1710508090157,"mc":[{"id":"1.226122413","rc":[{"batl":[[2,580,2.82],[1,570,1.09]],"id":54370634},{"tv":9297.05,"batb":[[0,6.6,16.84]],"trd":[[6.6,100.1]],"batl":[[0,6.8,11.38]],"id":41122648},{"tv":2244.16,"trd":[[30,45.25]],"batl":[[0,30,1.35]],"id":55632148},{"batb":[[1,1.8,68.03]],"batl":[[1,1.83,232.67]],"id":51922},{"batb":[[2,40,14.56]],"id":49744721},{"tv":17917.36,"batb":[[2,4.8,55.28],[0,5,59.4]],"trd":[[5,271.16]],"id":50466254},{"batb":[[2,25,12.2],[1,26,10.44],[0,27,7.14]],"batl":[],"id":106596}],"tv":131591.08}],"ArrivalTime":1710508090164}
{"op":"mcm","id":2,"clk":"ANxaALt9ALGKAQ==","pt":1710508090272,"mc":[{"id":"1.226122413","rc":[{"batb":[[0,6.6,18.98]],"batl":[[1,7,32.63],[0,6.8,21.02]],"id":41122648},{"tv":95735.74,"batb":[[2,1.78,246.02],[1,1.79,194.52],[0,1.8,15.08]],"trd":[[1.81,4232.93],[1.8,1519.64]],"ltp":1.8,"batl":[[2,1.83,232.67],[1,1.82,173.5],[0,1.81,92.82]],"id":51922},{"batl":[[0,48,3.6]],"id":49744721},{"batb":[[1,4.9,63.24]],"id":50466254}],"tv":131761.88}],"ArrivalTime":1710508090280}
{"op":"mcm","id":2,"clk":"AOdaAMR9AMCKAQ==","pt":1710508090374,"mc":[{"id":"1.226122413","rc":[{"batb":[[0,6.6,17.87]],"batl":[[0,6.8,32.66]],"id":41122648},{"batb":[[0,1.8,35.68]],"batl":[[0,1.81,94.82]],"id":51922},{"batb":[[2,26,10.44],[1,27,7.14],[0,28,1]],"batl":[[0,29,6.69]],"id":106596}]}],"ArrivalTime":1710508090382}
{"op":"mcm","id":2,"clk":"APNaAMx9AMeKAQ==","pt":1710508090475,"mc":[{"id":"1.226122413","rc":[{"batl":[[0,6.8,23.02]],"id":41122648},{"tv":2246.24,"trd":[[30,47.33]],"batl":[[2,36,27.38],[1,34,30.34],[0,32,12.6]],"id":55632148},{"tv":95854.03,"batb":[[2,1.77,203.68],[1,1.78,246.02],[0,1.79,253.29]],"trd":[[1.8,1637.93]],"batl":[[2,1.82,173.5],[1,1.81,94.82],[0,1.8,41.34]],"id":51922},{"tv":17931.9,"batb":[[2,4.9,63.24],[1,5,59.4],[0,5.1,11.93]],"trd":[[5.1,288.99]],"ltp":5.1,"batl":[[2,5.4,114.05],[1,5.3,85.38],[0,5.2,15.99]],"id":50466254}],"tv":131896.79}],"ArrivalTime":1710508090482}
{"op":"mcm","id":2,"clk":"APhaANN9AM+KAQ==","pt":1710508090573,"mc":[{"id":"1.226122413","rc":[{"tv":2246.86,"trd":[[30,47.95]],"batl":[[0,32,12.29]],"id":55632148},{"tv":2768.33,"trd":[[48,8.52]],"batl":[[0,48,3.26]],"id":49744721}],"tv":131898.09}],"ArrivalTime":1710508090581}
{"op":"mcm","id":2,"clk":"APxaAN99ANiKAQ==","pt":1710508090679,"mc":[{"id":"1.226122413","rc":[{"batl":[[2,750,1.91],[1,580,2.91]],"id":54370634},{"tv":9304.48,"batb":[[2,6.2,57.4],[0,6.6,16.96]],"trd":[[6.6,107.53]],"id":41122648},{"batb":[[0,29,7.69]],"batl":[],"id":55632148},{"tv":95936.71,"batb":[[1,1.78,184.93]],"trd":[[1.8,1720.61]],"batl":[[2,1.83,235.98],[1,1.82,176.87],[0,1.81,126.21]],"id":51922},{"tv":17946.45,"batb":[[0,5.1,7.01]],"trd":[[5.1,303.54]],"id":50466254}],"tv":132002.75}],"ArrivalTime":1710508090687}
{"op":"mcm","id":2,"clk":"AIdbAPF9AOiKAQ==","pt":1710508090788,"mc":[{"id":"1.226122413","rc":[{"batl":[[2,580,2.91],[1,540,2.56],[0,530,1.1]],"id":54370634},{"batb":[[2,28,13.66],[1,29,7.69],[0,30,4.87]],"batl":[[2,36,30.24],[1,34,27.07],[0,32,18.44]],"id":55632148},{"batl":[[2,1.82,176.87],[1,1.81,126.21],[0,1.8,2]],"id":51922},{"batl":[[1,50,2.09]],"id":49744721},{"batb":[[2,4.9,48.57]],"batl":[[1,5.3,42.08]],"id":50466254},{"batl":[[2,250,3.54]],"id":66251581},{"batl":[[2,32,14.09],[1,30,9.38],[0,29,4.32]],"id":106596}]}],"ArrivalTime":1710508090796}
{"op":"mcm","id":2,"clk":"AIlbAP19AO2KAQ==","pt":1710508090847,"mc":[{"id":"1.226122413","rc":[{"batl":[[2,750,1.91],[1,580,2.91]],"id":54370634},{"tv":9319.19,"batb":[[2,6.2,75.23],[0,6.6,40.46]],"trd":[[6.6,122.24]],"id":41122648},{"tv":2262.24,"batb":[[2,27,23.4],[1,28,13.66],[0,29,4.87]],"trd":[[30,57.69],[29,168.47]],"ltp":29,"id":55632148},{"batb":[[0,1.79,194.52]],"batl":[[2,1.82,173.5],[1,1.81,122.78],[0,1.8,12.42]],"id":51922},{"tv":17960.47,"batb":[[2,4.8,55.28],[1,4.9,48.57],[0,5,69.4]],"trd":[[5.1,317.56]],"batl":[[0,5.2,16.25]],"id":50466254}],"tv":132046.86}],"ArrivalTime":1710508090855}
{"op":"mcm","id":2,"clk":"AJJbAIZ+APeKAQ==","pt":1710508090950,"mc":[{"id":"1.226122413","rc":[{"batb":[[1,340,1.4]],"batl":[[2,580,2.91],[1,530,1],[0,520,1.1]],"id":54370634},{"batl":[[2,36,31.09]],"id":55632148},{"tv":95974.71,"trd":[[1.81,4246.03],[1.8,1745.51]],"ltp":1.81,"batl":[[2,1.83,235.98],[1,1.82,173.5],[0,1.81,116.23]],"id":51922},{"batb":[[2,4.8,58.08]],"batl":[],"id":50466254},{"batb":[[2,160,3.41]],"id":66251581},{"tv":2340.81,"trd":[[29,210.17]],"ltp":29,"batl":[[2,34,15.74],[1,32,14.09],[0,30,10.12]],"id":106596}],"tv":132092.01}],"ArrivalTime":1710508090958}
{"op":"mcm","id":2,"clk":"AJZbAI1+AP6KAQ==","pt":1710508091058,"mc":[{"id":"1.226122413","rc":[{"batl":[[0,6.8,25.1]],"id":41122648},{"batl":[[2,36,30.24]],"id":55632148},{"batb":[[0,1.79,197.05]],"batl":[[2,1.83,232.67],[0,1.81,201.63]],"id":51922},{"batb":[[2,4.8,55.28]],"id":50466254},{"batb":[[1,27,10.11]],"batl":[[1,32,13.01],[0,30,8.78]],"id":106596}]}],"ArrivalTime":1710508091066}
{"op":"mcm","id":2,"clk":"AJ9bAJZ+AImLAQ==","pt":1710508091160,"mc":[{"id":"1.226122413","rc":[{"batl":[[2,750,1.91],[1,580,2.91]],"id":54370634},{"batb":[[0,29,16.87]],"id":55632148},{"batl":[[0,5.2,15.99]],"id":50466254},{"batl":[[1,32,10.4]],"id":106596}]}],"ArrivalTime":1710508091168}
{"op":"mcm","id":2,"clk":"AKNbAJp+AIuLAQ==","pt":1710508091285,"mc":[{"id":"1.226122413","rc":[{"batl":[[2,580,2.82],[1,570,1.09]],"id":54370634},{"batb":[[0,29,19.25]],"id":55632148},{"batl":[[2,1.82,173.5],[1,1.81,201.63],[0,1.8,5]],"id":51922}]}],"ArrivalTime":1710508091292}
{"op":"mcm","id":2,"clk":"AKVbAKN+AJOLAQ==","pt":1710508091357,"mc":[{"id":"1.226122413","rc":[{"tv":95975.43,"batb":[[0,1.79,196.69]],"trd":[[1.79,104.56]],"ltp":1.79,"id":51922}],"tv":132092.73}],"ArrivalTime":1710508091365}
{"op":"mcm","id":2,"clk":"AKlbAKl+AJqLAQ==","pt":1710508091458,"mc":[{"id":"1.226122413","rc":[{"batl":[[2,570,1.09],[1,520,1],[0,510,2.66]],"id":54370634},{"tv":96004.83,"trd":[[1.8,1774.91]],"ltp":1.8,"batl":[[1,1.81,287.02],[0,1.8,74.24]],"id":51922},{"batb":[[2,4.9,48.57],[1,5,69.4],[0,5.1,3.27]],"batl":[[2,5.5,57.22],[1,5.4,114.05],[0,5.3,42.08]],"id":50466254},{"batb":[[2,27,10.11],[1,28,1],[0,29,3.33]],"id":106596}],"tv":132122.13}],"ArrivalTime":1710508091466}
{"op":"mcm","id":2,"clk":"AKxbALB+AKOLAQ==","pt":1710508091568,"mc":[{"id":"1.226122413","rc":[{"tv":9400.11,"batb":[[2,6,33.4],[1,6.2,75.23],[0,6.4,69.36]],"trd":[[6.6,203.16]],"batl":[[2,7,32.63],[1,6.8,25.1],[0,6.6,16.59]],"id":41122648},{"batb":[[1,1.78,243.15]],"id":51922},{"tv":2342.81,"trd":[[30,141.92]],"ltp":30,"batl":[[0,30,7.78]],"id":106596}],"tv":132205.05}],"ArrivalTime":1710508091575}
{"op":"mcm","id":2,"clk":"ALFbALx+AKuLAQ==","pt":1710508091664,"mc":[{"id":"1.226122413","rc":[{"batb":[[0,6.4,51.47]],"batl":[],"id":41122648},{"batb":[[1,1.78,282.15],[0,1.79,137.63]],"batl":[[0,1.8,105.01]],"id":51922},{"batb":[[1,5,75.13],[0,5.1,15.22]],"id":50466254},{"batb":[[1,28,6.03]],"batl":[[2,34,16.69],[1,32,11.48]],"id":106596}]}],"ArrivalTime":1710508091672}
{"op":"mcm","id":2,"clk":"ALhbAMV+ALiLAQ==","pt":1710508091777,"mc":[{"id":"1.226122413","rc":[{"batl":[[2,580,2.91]],"id":54370634},{"batb":[[2,6.2,75.23],[1,6.4,60.47],[0,6.6,3.73]],"batl":[[2,7.2,29.84],[1,7,32.63],[0,6.8,25.1]],"id":41122648},{"batb":[[1,280,1]],"id":41200638},{"batb":[[2,28,13.66],[1,29,19.25],[0,30,4.31]],"id":55632148},{"tv":96009.83,"trd":[[1.8,1779.91]],"batl":[[0,1.8,102.5]],"id":51922},{"batb":[[0,5.1,45.17]],"batl":[[0,5.3,18.05]],"id":50466254},{"tv":2352.19,"trd":[[30,151.3]],"batl":[[0,30,3.09]],"id":106596}],"tv":132219.43}],"ArrivalTime":1710508091785}
{"op":"mcm","id":2,"clk":"AL9bAMx+AMGLAQ==","pt":1710508091879,"mc":[{"id":"1.226122413","rc":[{"batl":[[2,520,1],[1,510,2.56],[0,500,1.1]],"id":54370634},{"batl":[[1,7,42.63]],"id":41122648},{"tv":96013.83,"batb":[[0,1.79,140.66]],"trd":[[1.79,108.56]],"ltp":1.79,"batl":[[1,1.81,289.02]],"id":51922},{"tv":2769.59,"trd":[[48,9.78]],"batl":[[0,48,2.63]],"id":49744721}],"tv":132224.69}],"ArrivalTime":1710508091887}
{"op":"mcm","id":2,"clk":"AMRbAM9+AMmLAQ==","pt":1710508091972,"mc":[{"id":"1.226122413","rc":[{"tv":9407.57,"batb":[[2,6,62.9],[1,6.2,75.23],[0,6.4,57.48]],"trd":[[6.6,210.62]],"batl":[[2,7,42.63],[1,6.8,25.1],[0,6.6,23.53]],"id":41122648},{"tv":2266.96,"batb":[[0,30,1.95]],"trd":[[30,62.41]],"ltp":30,"batl":[[2,36,31.09]],"id":55632148},{"batb":[[1,1.78,223.93]],"id":51922},{"batl":[[2,50,2.09],[1,48,2.63],[0,46,1]],"id":49744721},{"batb":[[2,4.9,63.13]],"batl":[[0,5.3,2.57]],"id":50466254},{"tv":2360.36,"batb":[[2,28,6.03],[1,29,2.33],[0,30,5.23]],"trd":[[30,157.47],[29,212.17]],"batl":[[2,36,5.53],[1,34,16.69],[0,32,11.48]],"id":106596}],"tv":132245.04}],"ArrivalTime":1710508091980}
{"op":"mcm","id":2,"clk":"AMpbANV+ANGLAQ==","pt":1710508092078,"mc":[{"id":"1.226122413","rc":[{"batb":[[0,350,5.24]],"id":54370634},{"batb":[],"batl":[[0,6.6,3.36]],"id":41122648},{"batl":[[0,32,13.38]],"id":55632148},{"batl":[[1,1.81,291.02]],"id":51922},{"tv":582.38,"trd":[[200,12.66]],"ltp":200,"batl":[[2,260,2.83],[1,250,3.54],[0,210,5]],"id":66251581}],"tv":132249.42}],"ArrivalTime":1710508092086}
{"op":"mcm","id":2,"clk":"ANNbAOV+ANuLAQ==","pt":1710508092186,"mc":[{"id":"1.226122413","rc":[{"batb":[[0,6.4,60.47]],"batl":[[2,7,42.48]],"id":41122648},{"batb":[[0,30,2.37]],"id":55632148},{"tv":96043.84,"trd":[[1.8,1809.92]],"ltp":1.8,"batl":[[0,1.8,87.5]],"id":51922},{"batb":[[2,28,11.03],[1,29,5.06]],"batl":[[2,36,7.73],[1,34,14.27]],"id":106596}],"tv":132279.43}],"ArrivalTime":1710508092194}
{"op":"mcm","id":2,"clk":"ANtbAOx+AOiLAQ==","pt":1710508092293,"mc":[{"id":"1.226122413","rc":[{"batb":[[0,1.79,243.19]],"batl":[],"id":51922},{"tv":2771.59,"batb":[[2,40,10.29],[1,42,6.38]],"trd":[[46,11.86]],"ltp":46,"batl":[[2,55,7.07],[1,50,2.09],[0,48,2.63]],"id":49744721},{"batb":[[2,5,75.13],[1,5.1,45.17],[0,5.2,15.29]],"id":50466254},{"batb":[[2,160,4.52],[0,180,3.82]],"id":66251581},{"batb":[[2,27,10.11],[1,28,11.03],[0,29,5.06]],"id":106596}],"tv":132281.43}],"ArrivalTime":1710508092301}
{"op":"mcm","id":2,"clk":"AOJbAPd+APCLAQ==","pt":1710508092344,"mc":[{"id":"1.226122413","rc":[{"batl":[[2,580,2.91],[1,520,1]],"id":54370634},{"batb":[[2,6,82],[1,6.2,56.5]],"id":41122648},{"batb":[[2,240,2.04],[1,270,1.59],[0,280,1]],"id":41200638},{"tv":96053.83,"batb":[[0,1.79,238.19]],"trd":[[1.79,118.55]],"ltp":1.79,"id":51922},{"tv":18050.81,"batb":[[2,4.9,63.13],[1,5,75.13],[0,5.1,15.29]],"trd":[[5.2,52.54],[5.1,377.32]],"id":50466254},{"tv":2364.76,"batb":[[0,29,3.86]],"trd":[[29,214.57],[32,142.42]],"ltp":29,"batl":[[0,32,13.43]],"id":106596}],"tv":132386.16}],"ArrivalTime":1710508092352}
{"op":"mcm","id":2,"clk":"AOlbAP9+APmLAQ==","pt":1710508092448,"mc":[{"id":"1.226122413","rc":[{"batb":[[0,6.4,57.48]],"id":41122648},{"batb":[[2,230,3.05],[1,240,2.04],[0,260,1.6]],"id":41200638},{"batl":[[1,1.81,316.02],[0,1.8,89.5]],"id":51922},{"batb":[],"batl":[[2,5.4,114.05],[1,5.3,2.57],[0,5.2,6.83]],"id":50466254},{"batb":[[0,29,8.24]],"batl":[[0,32,12.35]],"id":106596}]}],"ArrivalTime":1710508092455}
{"op":"mcm","id":2,"clk":"AO5bAIV/AISMAQ==","pt":1710508092550,"mc":[{"id":"1.226122413","rc":[{"batl":[[2,7.2,29.84],[1,7,42.48],[0,6.8,23.1]],"id":41122648},{"tv":96190.47,"batb":[[1,1.78,203.37],[0,1.79,169.87]],"trd":[[1.79,255.19]],"batl":[],"id":51922},{"tv":18052.81,"batb":[[0,5.1,14.29]],"trd":[[5.1,379.32]],"batl":[[1,5.3,17.66]],"id":50466254},{"batl":[[0,32,9.93]],"id":106596}],"tv":132524.8}],"ArrivalTime":1710508092560}
{"op":"mcm","id":2,"clk":"APFbAIp/AJCMAQ==","pt":1710508092656,"mc":[{"id":"1.226122413","rc":[{"tv":9407.83,"batb":[[2,6.2,56.5],[1,6.4,57.48],[0,6.6,1.55]],"trd":[[6.6,210.88]],"id":41122648},{"tv":96240.47,"batb":[[1,1.78,208.4],[0,1.79,144.87]],"trd":[[1.79,305.19]],"batl":[[1,1.81,327.87],[0,1.8,60.73]],"id":51922},{"batl":[[0,48,3.43]],"id":49744721},{"batb":[[0,5.1,26.22]],"batl":[[1,5.3,40.09]],"id":50466254},{"tv":2368.76,"batb":[[0,29,6.24]],"trd":[[29,218.57]],"id":106596}],"tv":132579.06}],"ArrivalTime":1710508092664}
{"op":"mcm","id":2,"clk":"APdbAJV/AJaMAQ==","pt":1710508092754,"mc":[{"id":"1.226122413","rc":[{"tv":9410.93,"batb":[[2,6,90.88],[1,6.2,56.5],[0,6.4,59.16]],"trd":[[6.6,213.98]],"batl":[[2,7,42.48],[1,6.8,23.1],[0,6.6,16.18]],"id":41122648},{"batb":[[0,5.1,11.93]],"id":50466254},{"batb":[[0,29,4.38]],"id":106596}],"tv":132582.16}],"ArrivalTime":1710508092761}
{"op":"mcm","id":2,"clk":"AP1bAKF/AKOMAQ==","pt":1710508092868,"mc":[{"id":"1.226122413","rc":[{"batb":[[1,6.2,53.29]],"batl":[[0,6.6,21.8]],"id":41122648},{"batb":[[2,230,3.44],[0,260,3.6]],"id":41200638},{"batb":[[2,28,16.39]],"id":55632148},{"batb":[[0,1.79,154.87]],"batl":[[2,1.82,176.87],[0,1.8,85.73]],"id":51922},{"tv":2773.19,"batb":[[0,44,3.93]],"trd":[[44,17.26]],"ltp":44,"id":49744721},{"batb":[],"batl":[[1,34,13.32]],"id":106596}],"tv":132583.76}],"ArrivalTime":1710508092876}
{"op":"mcm","id":2,"clk":"AIFcAKZ/AKeMAQ==","pt":1710508092959,"mc":[{"id":"1.226122413","rc":[{"tv":391.7,"batb":[[0,350,2.44]],"trd":[[360,22.66],[350,23.37]],"ltp":350,"batl":[[2,520,1],[1,500,1.1],[0,490,2.56]],"id":54370634},{"batl":[[0,6.6,5.62]],"id":41122648},{"batb":[[0,30,4.97]],"id":55632148},{"tv":96240.93,"batb":[[0,1.79,155.09]],"trd":[[1.8,1810.38]],"ltp":1.8,"batl":[[0,1.8,85.5]],"id":51922}],"tv":132589.83}],"ArrivalTime":1710508092967}
{"op":"mcm","id":2,"clk":"AIlcAK5/AK6MAQ==","pt":1710508093072,"mc":[{"id":"1.226122413","rc":[{"tv":9420.91,"batb":[[1,6.2,56.5],[0,6.4,62.15]],"trd":[[6.6,223.96]],"batl":[[2,7.2,29.84],[1,7,42.48],[0,6.8,23.73]],"id":41122648},{"batb":[[2,240,2.04],[1,260,3.6],[0,280,1.04]],"id":41200638},{"batb":[[2,28,20.64]],"id":55632148},{"batl":[[0,1.8,113.48]],"id":51922},{"batb":[[0,5.1,40.18]],"batl":[[1,5.3,17.66]],"id":50466254},{"batl":[[2,250,3.54],[1,210,5],[0,200,1]],"id":66251581},{"tv":2370.76,"batb":[[2,27,16.67],[0,29,7.09]],"trd":[[32,144.42]],"ltp":32,"batl":[[1,34,14.27],[0,32,8.93]],"id":106596}],"tv":132601.81}],"ArrivalTime":1710508093080}
{"op":"mcm","id":2,"clk":"AI5cALZ/ALaMAQ==","pt":1710508093175,"mc":[{"id":"1.226122413","rc":[{"batl":[[0,6.8,23.1]],"id":41122648},{"batb":[[0,30,7.35]],"batl":[],"id":55632148},{"tv":96250.93,"trd":[[1.8,1820.38]],"batl":[[1,1.81,242.47],[0,1.8,108.47]],"id":51922},{"tv":2780.05,"batb":[[1,42,10.65]],"trd":[[48,16.64]],"ltp":48,"batl":[[2,60,21.3],[1,55,7.07],[0,50,2.09]],"id":49744721}],"tv":132618.67}],"ArrivalTime":1710508093183}
{"op":"mcm","id":2,"clk":"AJdcALx/AL6MAQ==","pt":1710508093281,"mc":[{"id":"1.226122413","rc":[{"batb":[[1,260,1.6]],"id":41200638},{"batl":[[0,1.8,118.47]],"id":51922},{"tv":18116.47,"batb":[[2,5,75.13],[1,5.1,15.18],[0,5.2,6.64]],"trd":[[5.2,66.2],[5.1,429.32]],"ltp":5.2,"batl":[[2,5.5,57.22],[1,5.4,114.05],[0,5.3,17.66]],"id":50466254},{"tv":2372.76,"batb":[[2,28,11.03],[1,29,7.09],[0,30,2.87]],"trd":[[32,146.42]],"batl":[[0,32,7.93]],"id":106596}],"tv":132684.33}],"ArrivalTime":1710508093289}
{"op":"mcm","id":2,"clk":"AKBcAMN/AMeMAQ==","pt":1710508093378,"mc":[{"id":"1.226122413","rc":[{"batb":[[2,6,89.18],[1,6.2,53.29],[0,6.4,59.16]],"batl":[[0,6.8,32.89]],"id":41122648},{"tv":96421.73,"batb":[[0,1.79,69.69]],"trd":[[1.79,475.99]],"ltp":1.79,"batl":[[2,1.82,173.5]],"id":51922},{"batb":[[0,44,7]],"batl":[[1,55,5.34]],"id":49744721},{"batl":[[2,36,6.88],[1,34,13.32]],"id":106596}],"tv":132855.13}],"ArrivalTime":1710508093385}
{"op":"mcm","id":2,"clk":"AKlcAM9/ANGMAQ==","pt":1710508093492,"mc":[{"id":"1.226122413","rc":[{"batb":[[2,240,2.42]],"id":41200638},{"tv":96561.11,"batb":[[2,1.76,283.31],[1,1.77,203.68],[0,1.78,208.4]],"trd":[[1.79,615.37]],"batl":[],"id":51922},{"tv":18129.75,"batb":[[2,4.9,84.48],[1,5,75.13],[0,5.1,15.18]],"trd":[[5.2,79.48]],"batl":[[2,5.4,114.05],[1,5.3,17.66],[0,5.2,48.18]],"id":50466254},{"batb":[],"batl":[[2,36,7.73],[1,34,14.27],[0,32,9.01]],"id":106596}],"tv":133007.79}],"ArrivalTime":1710508093499}
{"op":"mcm","id":2,"clk":"AKtcANR/ANaMAQ==","pt":1710508093584,"mc":[{"id":"1.226122413","rc":[{"batb":[[2,1.76,341.92],[1,1.77,142.12]],"batl":[[2,1.81,245.04],[1,1.8,118.47],[0,1.79,60.28]],"id":51922}]}],"ArrivalTime":1710508093592}
{"op":"mcm","id":2,"clk":"ALJcANx/AN6MAQ==","pt":1710508093638,"mc":[{"id":"1.226122413","rc":[{"batl":[[2,36,30.24],[0,32,11.18]],"id":55632148},{"batl":[[0,50,4.09]],"id":49744721},{"tv":18159.53,"batb":[[2,4.8,76.63],[1,4.9,84.48],[0,5,75.42]],"trd":[[5.1,459.1]],"ltp":5.1,"batl":[[1,5.3,39.57]],"id":50466254},{"tv":2388.62,"batb":[[2,29,7.09],[1,30,2.87],[0,32,1.74]],"trd":[[32,162.28]],"batl":[[2,38,4.87],[1,36,7.73],[0,34,14.27]],"id":106596}],"tv":133053.43}],"ArrivalTime":1710508093645}
{"op":"mcm","id":2,"clk":"AL9cAO5/AOaMAQ==","pt":1710508093796,"mc":[{"id":"1.226122413","rc":[{"batl":[[2,580,2.91],[1,520,1],[0,500,1.1]],"id":54370634},{"batb":[[2,6,90.88],[1,6.2,56.5]],"id":41122648},{"batb":[[2,260,1.6],[1,270,1.6]],"id":41200638},{"batb":[[2,1.77,124.29],[1,1.78,169.4],[0,1.79,58.81]],"batl":[[2,1.82,176.87],[1,1.81,248.47],[0,1.8,120.18]],"id":51922},{"batb":[[2,4.9,84.48],[1,5,75.13],[0,5.1,13.29]],"batl":[[0,5.2,7.13]],"id":50466254},{"batl":[[2,260,3.55]],"id":66251581},{"tv":2390,"batb":[[1,30,11.33],[0,32,1.05]],"trd":[[32,163.66]],"batl":[[2,38,6.9],[1,36,5.53]],"id":106596}],"tv":133054.81}],"ArrivalTime":1710508093804}
{"op":"mcm","id":2,"clk":"AMJcAPd/APCMAQ==","pt":1710508093842,"mc":[{"id":"1.226122413","rc":[{"batb":[[2,240,2.42],[1,260,1.6],[0,270,1.6]],"batl":[[2,320,1.71],[1,310,1.67],[0,300,1]],"id":41200638},{"tv":96566.11,"trd":[[1.8,1825.38]],"ltp":1.8,"batl":[[0,1.8,117.68]],"id":51922}],"tv":133059.81}],"ArrivalTime":1710508093850}
{"op":"mcm","id":2,"clk":"AMZcAIaAAQD5jAE=","pt":1710508093952,"mc":[{"id":"1.226122413","rc":[{"batb":[[1,6.2,53.29]],"id":41122648},{"batb":[[2,230,3.44],[1,240,2.42],[0,250,1.6]],"id":41200638},{"tv":96693.73,"batb":[[2,1.76,341.92],[1,1.77,182.79],[0,1.78,210.4]],"trd":[[1.78,10],[1.79,732.99]],"ltp":1.78,"batl":[[2,1.82,173.5],[1,1.81,245.04]],"id":51922},{"batb":[],"batl":[[0,5.2,19.07]],"id":50466254},{"tv":2392.1,"batb":[[2,28,11.03],[1,29,7.09],[0,30,11.33]],"trd":[[32,165.76]],"batl":[[2,36,7.67],[1,34,14.27],[0,32,10]],"id":106596}],"tv":133189.53}],"ArrivalTime":1710508093960}
{"op":"mcm","id":2,"clk":"AMpcAJaAAQCBjQE=","pt":1710508094060,"mc":[{"id":"1.226122413","rc":[{"tv":391.9,"trd":[[500,0.2]],"ltp":500,"batl":[[2,750,1.91],[1,580,2.91],[0,520,1.23]],"id":54370634},{"batb":[[2,28,14.35]],"id":106596}],"tv":133189.73}],"ArrivalTime":1710508094068}
{"op":"mcm","id":2,"clk":"AM1cAKKAAQCIjQE=","pt":1710508094160,"mc":[{"id":"1.226122413","rc":[{"batl":[[2,580,2.91],[1,520,1],[0,480,1.23]],"id":54370634},{"batb":[[2,28,24.9]],"id":55632148},{"batl":[[1,1.81,257.04]],"id":51922},{"batb":[[0,30,8.76]],"id":106596}]}],"ArrivalTime":1710508094169}
{"op":"mcm","id":2,"clk":"ANFcAK2AAQCRjQE=","pt":1710508094262,"mc":[{"id":"1.226122413","rc":[{"tv":96698.79,"batb":[[1,1.77,187.82]],"trd":[[1.79,738.05]],"ltp":1.79,"batl":[[2,1.81,257.04],[1,1.8,117.68],[0,1.79,7.47]],"id":51922},{"batb":[[0,5.1,28.17]],"id":50466254},{"tv":2394.1,"trd":[[32,167.76]],"batl":[[0,32,7.95]],"id":106596}],"tv":133196.79}],"ArrivalTime":1710508094271}
{"op":"mcm","id":2,"clk":"ANVcALWAAQCYjQE=","pt":1710508094364,"mc":[{"id":"1.226122413","rc":[{"batl":[[2,520,1],[1,490,2.56]],"id":54370634},{"batb":[[1,1.77,287.82]],"batl":[[2,1.81,290.22]],"id":51922},{"tv":2394.12,"batb":[[0,30,13.89]],"trd":[[32,167.78]],"batl":[[0,32,10.63]],"id":106596}],"tv":133196.81}],"ArrivalTime":1710508094372}
{"op":"mcm","id":2,"clk":"ANtcAMOAAQCijQE=","pt":1710508094472,"mc":[{"id":"1.226122413","rc":[{"tv":96724.3,"batb":[[1,1.77,229.32]],"trd":[[1.79,763.56]],"batl":[[0,1.79,10.16]],"id":51922},{"tv":18164.17,"batb":[[0,5.1,25.86]],"trd":[[5.1,463.74]],"id":50466254},{"batb":[[0,30,19.44]],"id":106596}],"tv":133226.96}],"ArrivalTime":1710508094479}
{"op":"mcm","id":2,"clk":"AN1cAMuAAQCwjQE=","pt":1710508094577,"mc":[{"id":"1.226122413","rc":[{"tv":2268.96,"batb":[[0,30,6.35]],"trd":[[30,64.41]],"id":55632148},{"batl":[[1,1.8,125.9],[0,1.79,18.43]],"id":51922},{"batb":[[1,42,6.38]],"id":49744721}],"tv":133228.96}],"ArrivalTime":1710508094584}
{"op":"mcm","id":2,"clk":"AORcANaAAQC7jQE=","pt":1710508094672,"mc":[{"id":"1.226122413","rc":[{"batb":[[0,5.1,29.81]],"id":50466254}]}],"ArrivalTime":1710508094679}
{"op":"mcm","id":2,"clk":"AOVcAOaAAQDEjQE=","pt":1710508094779,"mc":[{"id":"1.226122413","rc":[{"batl":[[1,490,5.38]],"id":54370634},{"batb":[[2,240,2.42],[1,250,1.6],[0,270,1.08]],"id":41200638},{"batb":[[1,29,16.87],[0,30,5.4]],"batl":[],"id":55632148}]}],"ArrivalTime":1710508094788}
{"op":"mcm","id":2,"clk":"AOtcAPOAAQDMjQE=","pt":1710508094906,"mc":[{"id":"1.226122413","rc":[{"batb":[[0,350,2.75]],"id":54370634},{"tv":2279.76,"batb":[[2,27,26.85],[1,28,24.9],[0,29,16.87]],"trd":[[30,75.21]],"id":55632148},{"batl":[[2,1.81,292.22],[1,1.8,150.9]],"id":51922},{"tv":18182.03,"trd":[[5.2,97.34]],"ltp":5.2,"batl":[[0,5.2,10.13]],"id":50466254},{"batl":[[2,36,6.82],[1,34,13.32]],"id":106596}],"tv":133257.62}],"ArrivalTime":1710508094914}
{"op":"mcm","id":2,"clk":"APJcAP6AAQDWjQE=","pt":1710508094961,"mc":[{"id":"1.226122413","rc":[{"batb":[[2,250,1.6],[1,260,1.6]],"id":41200638},{"batb":[[0,1.78,164.4]],"id":51922}]}],"ArrivalTime":1710508094969}
{"op":"mcm","id":2,"clk":"APRcAIqBAQDhjQE=","pt":1710508095064,"mc":[{"id":"1.226122413","rc":[{"tv":9539.24,"batb":[[2,5.9,43.03],[1,6,90.88],[0,6.2,53.29]],"trd":[[6.4,148]],"ltp":6.4,"batl":[[1,7,67.48]],"id":41122648},{"batb":[[2,28,24.9],[1,29,16.87],[0,30,12.54]],"batl":[[0,32,13.59]],"id":55632148},{"tv":96763.71,"batb":[[2,1.77,229.32],[1,1.78,164.4],[0,1.79,2.53]],"trd":[[1.79,800.42],[1.8,1827.93]],"ltp":1.8,"batl":[[2,1.82,175.5],[1,1.81,292.22],[0,1.8,149.63]],"id":51922},{"tv":18184.19,"batb":[[0,5.1,28.73]],"trd":[[5.1,465.9]],"ltp":5.1,"id":50466254}],"tv":133417.52}],"ArrivalTime":1710508095072}
{"op":"mcm","id":2,"clk":"APpcAJKBAQDrjQE=","pt":1710508095166,"mc":[{"id":"1.226122413","rc":[{"batb":[[1,6,89.18]],"batl":[[2,7,67.48],[1,6.8,32.89],[0,6.6,9.89]],"id":41122648},{"batl":[[2,36,31.09]],"id":55632148},{"batb":[[1,1.78,146.12]],"batl":[],"id":51922},{"batb":[[0,44,11.27]],"id":49744721},{"batb":[],"batl":[[2,5.5,57.22],[1,5.4,114.05],[0,5.3,39.57]],"id":50466254},{"batb":[[0,30,22.78]],"id":106596}]}],"ArrivalTime":1710508095174}
{"op":"mcm","id":2,"clk":"AIBdAJiBAQD0jQE=","pt":1710508095276,"mc":[{"id":"1.226122413","rc":[{"batb":[[1,6,106.49],[0,6.2,38.67]],"batl":[[2,7,70.48],[0,6.6,58.19]],"id":41122648},{"tv":504.17,"trd":[[300,45.23]],"ltp":300,"batl":[[2,330,1.71],[1,320,1.71],[0,310,1.67]],"id":41200638},{"batb":[[0,30,17.12]],"batl":[],"id":55632148},{"batb":[[2,1.77,286.74],[1,1.78,193.12]],"batl":[[0,1.8,147.92]],"id":51922},{"batl":[[0,5.3,17.66]],"id":50466254},{"tv":2413.32,"trd":[[32,186.98]],"batl":[[0,32,1.03]],"id":106596}],"tv":133438.72}],"ArrivalTime":1710508095284}
{"op":"mcm","id":2,"clk":"AItdAKKBAQCDjgE=","pt":1710508095381,"mc":[{"id":"1.226122413","rc":[{"batl":[[1,490,2.82]],"id":54370634},{"batb":[[1,6,108.19],[0,6.2,47.67]],"batl":[[0,6.6,60.19]],"id":41122648},{"batl":[[0,32,11.18]],"id":55632148},{"tv":96768.77,"batb":[[2,1.76,341.92],[1,1.77,286.74],[0,1.78,223.9]],"trd":[[1.79,805.48]],"ltp":1.79,"batl":[[2,1.81,292.22],[1,1.8,147.92],[0,1.79,7.47]],"id":51922},{"tv":18185.29,"batb":[[0,5.1,39.17]],"trd":[[5.1,467]],"batl":[[0,5.3,2.57]],"id":50466254}],"tv":133444.88}],"ArrivalTime":1710508095389}
{"op":"mcm","id":2,"clk":"AI5dAKuBAQCJjgE=","pt":1710508095482,"mc":[{"id":"1.226122413","rc":[{"tv":97642.77,"trd":[[1.81,4809.05],[1.79,820.42],[1.8,2123.97]],"ltp":1.81,"batl":[[2,1.83,235.67],[1,1.82,175.5],[0,1.81,10.71]],"id":51922},{"tv":18189.29,"batb":[[2,5,75.13],[1,5.1,39.17],[0,5.2,12.78]],"trd":[[5.2,101.34]],"ltp":5.2,"id":50466254},{"tv":2415.38,"batb":[[2,29,7.09],[1,30,22.78],[0,32,7.44]],"trd":[[32,189.04]],"batl":[[2,38,6.14],[1,36,6.82],[0,34,13.32]],"id":106596}],"tv":134324.94}],"ArrivalTime":1710508095490}
{"op":"mcm","id":2,"clk":"AJVdALmBAQCUjgE=","pt":1710508095583,"mc":[{"id":"1.226122413","rc":[{"batb":[[2,240,2.42],[1,250,1.6],[0,260,1.6]],"id":41200638},{"tv":2282.48,"batb":[[0,30,15.76]],"trd":[[30,77.93]],"batl":[[2,36,30.24]],"id":55632148},{"tv":97652.77,"batb":[[0,1.78,221.46]],"trd":[[1.78,20]],"ltp":1.78,"id":51922},{"tv":18194.43,"batb":[[1,5.1,59.14]],"trd":[[5.3,5.14]],"ltp":5.3,"batl":[[2,5.6,32.11],[1,5.5,57.22],[0,5.4,114.05]],"id":50466254},{"batb":[[1,30,24.55]],"id":106596}],"tv":134342.8}],"ArrivalTime":1710508095591}
{"op":"mcm","id":2,"clk":"AJxdAMCBAQCojgE=","pt":1710508095692,"mc":[{"id":"1.226122413","rc":[{"batl":[[2,490,2.82],[1,480,1.23],[0,470,2]],"id":54370634},{"tv":9567.16,"batb":[[0,6.2,19.98]],"trd":[[6.2,41.36]],"ltp":6.2,"batl":[[2,6.8,32.89],[1,6.6,60.19],[0,6.4,11.67]],"id":41122648},{"tv":2285.58,"batb":[[0,30,14.21]],"trd":[[30,81.03]],"batl":[[0,32,13.68]],"id":55632148},{"batb":[[2,1.78,278.33],[1,1.79,40.43],[0,1.8,27.71]],"batl":[],"id":51922},{"tv":18219.99,"batb":[[2,4.9,84.48],[1,5,75.13],[0,5.1,50.87]],"trd":[[5.2,126.9]],"ltp":5.2,"id":50466254},{"batb":[[2,160,3.41]],"id":66251581},{"batb":[[0,32,3.98]],"batl":[[2,38,6.9],[1,36,5.53],[0,34,14.27]],"id":106596}],"tv":134399.38}],"ArrivalTime":1710508095699}
{"op":"mcm","id":2,"clk":"AKBdAMiBAQC5jgE=","pt":1710508095798,"mc":[{"id":"1.226122413","rc":[{"batl":[[2,520,1]],"id":54370634},{"batb":[[0,6.2,16.77]],"id":41122648},{"batb":[[2,230,3.44],[1,240,2.42],[0,250,1.6]],"id":41200638},{"batb":[],"batl":[[0,1.81,18.71]],"id":51922},{"tv":18471.98,"batb":[[2,4.7,88.29],[1,4.8,84.48],[0,4.9,84.48]],"trd":[[5,421.42],[5.1,568.73]],"ltp":5,"batl":[[2,5.5,57.22],[1,5.4,114.05],[0,5,300.99]],"id":50466254}],"tv":134651.37}],"ArrivalTime":1710508095806}
{"op":"mcm","id":2,"clk":"AKtdAM+BAQDOjgE=","pt":1710508095916,"mc":[{"id":"1.226122413","rc":[{"batl":[[0,470,4.56]],"id":54370634},{"tv":9573.14,"batb":[[0,6.2,19.98]],"trd":[[6.4,153.98]],"ltp":6.4,"batl":[[1,6.6,58.19],[0,6.4,10.68]],"id":41122648},{"batb":[[2,240,2.42],[1,250,1.6],[0,260,2]],"id":41200638},{"batl":[[2,36,31.09]],"id":55632148},{"tv":97710.19,"batb":[[1,1.79,90.03],[0,1.8,17.71]],"trd":[[1.81,4846.47],[1.8,2143.97]],"ltp":1.81,"batl":[[2,1.84,95.17],[1,1.83,235.67],[0,1.82,149.93]],"id":51922},{"batl":[[2,5.4,114.05],[1,5.3,14.55]],"id":50466254},{"batl":[[2,260,1.55]],"id":66251581},{"batb":[[1,30,27.21],[0,32,5.98]],"batl":[[2,38,4.2]],"id":106596}],"tv":134714.77}],"ArrivalTime":1710508095924}
{"op":"mcm","id":2,"clk":"AK5dANeBAQDVjgE=","pt":1710508095999,"mc":[{"id":"1.226122413","rc":[{"tv":9578.43,"trd":[[6.4,159.27]],"batl":[[0,6.4,8.03]],"id":41122648},{"batl":[[0,32,11.18]],"id":55632148},{"tv":97920.18,"batb":[[1,1.79,131.79],[0,1.81,97.51]],"trd":[[1.81,4936.4],[1.79,905.04],[1.8,2179.41]],"batl":[[0,1.82,109.71]],"id":51922},{"tv":19102.73,"batb":[[2,4.7,91.23],[1,4.8,61.78],[0,4.9,72.77]],"trd":[[4.9,327.02],[5,1023.39]],"ltp":4.9,"batl":[[1,5.3,17.12],[0,5.2,38.19]],"id":50466254},{"batb":[[1,170,2.59]],"id":66251581},{"tv":2422.88,"trd":[[34,69.64]],"ltp":34,"batl":[[0,34,10.52]],"id":106596}],"tv":135568.3}],"ArrivalTime":1710508096007}
{"op":"mcm","id":2,"clk":"ALVdAN2BAQDejgE=","pt":1710508096051,"mc":[{"id":"1.226122413","rc":[{"batb":[[2,230,3.44],[1,240,2.42],[0,250,3.6]],"id":41200638},{"batb":[[2,1.79,131.79],[1,1.8,54.6],[0,1.81,124.73]],"batl":[[1,1.83,209.38]],"id":51922},{"batb":[[0,4.9,58.21]],"batl":[[2,5.3,17.12],[1,5.2,38.19],[0,5.1,15.02]],"id":50466254},{"batl":[[0,34,7.47]],"id":106596}]}],"ArrivalTime":1710508096058}
{"op":"mcm","id":2,"clk":"AL5dAOSBAQDpjgE=","pt":1710508096156,"mc":[{"id":"1.226122413","rc":[{"batb":[[2,240,2.42],[1,250,3.6],[0,260,1.12]],"id":41200638},{"tv":98165.2,"batb":[[0,1.81,29.76]],"trd":[[1.81,5181.42]],"batl":[],"id":51922},{"batb":[[2,4.8,37.63],[1,4.9,34.18],[0,5,26.85]],"id":50466254},{"tv":2424.14,"trd":[[34,70.9]],"batl":[[0,34,6.84]],"id":106596}],"tv":135814.58}],"ArrivalTime":1710508096164}
{"op":"mcm","id":2,"clk":"AMJdAOuBAQD0jgE=","pt":1710508096261,"mc":[{"id":"1.226122413","rc":[{"tv":2297.04,"batb":[[2,28,32.9],[0,30,8.48]],"trd":[[30,92.49]],"id":55632148},{"batb":[[2,1.79,208.29]],"batl":[[1,1.83,236.62]],"id":51922},{"batl":[[2,55,5.34],[1,50,4.09],[0,48,1]],"id":49744721},{"tv":19132.77,"trd":[[5.1,598.77]],"ltp":5.1,"batl":[[2,5.4,114.05],[1,5.3,17.12],[0,5.2,38.19]],"id":50466254},{"tv":584.38,"trd":[[200,14.66]],"batl":[[2,280,1.38],[1,260,1.55],[0,210,5]],"id":66251581}],"tv":135858.08}],"ArrivalTime":1710508096268}
{"op":"mcm","id":2,"clk":"AMhdAO+BAQD9jgE=","pt":1710508096368,"mc":[{"id":"1.226122413","rc":[{"batb":[[2,1.79,152.07]],"id":51922},{"tv":2781.01,"batb":[[0,44,10.79]],"trd":[[46,12.82]],"ltp":46,"id":49744721},{"batb":[],"batl":[[0,5.2,16.82]],"id":50466254}],"tv":135859.04}],"ArrivalTime":1710508096376}
{"op":"mcm","id":2,"clk":"AMtdAPmBAQCFjwE=","pt":1710508096473,"mc":[{"id":"1.226122413","rc":[{"tv":2311.02,"batb":[[2,28,24.9],[0,30,1.49]],"trd":[[30,106.47]],"batl":[[0,32,13.69]],"id":55632148},{"tv":98801.64,"batb":[[2,1.78,291],[1,1.79,152.07],[0,1.8,54.6]],"trd":[[1.81,5185.86],[1.82,5949.48],[1.83,9594.3]],"ltp":1.83,"batl":[[2,1.85,108.84],[1,1.84,95.17],[0,1.83,30.33]],"id":51922},{"batl":[[2,55,7.03],[1,50,2.09],[0,48,3]],"id":49744721},{"batb":[[2,4.9,34.18],[1,5,26.85],[0,5.1,3.09]],"id":50466254},{"batb":[[2,160,4.49]],"id":66251581}],"tv":136509.46}],"ArrivalTime":1710508096481}
{"op":"mcm","id":2,"clk":"ANFdAP+BAQCPjwE=","pt":1710508096573,"mc":[{"id":"1.226122413","rc":[{"tv":9582.63,"batb":[[0,6.2,17.88]],"trd":[[6.2,45.56]],"ltp":6.2,"id":41122648},{"batb":[[2,27,26.85],[1,28,24.9],[0,29,16.87]],"id":55632148},{"batb":[[0,1.8,79.6]],"id":51922},{"tv":19149.55,"batb":[[2,4.8,45.95],[1,4.9,42.15],[0,5,26.85]],"trd":[[5.2,137.5],[5.1,604.95]],"batl":[[0,5.2,11.52]],"id":50466254}],"tv":136530.44}],"ArrivalTime":1710508096581}
{"op":"mcm","id":2,"clk":"ANRdAIOCAQCYjwE=","pt":1710508096676,"mc":[{"id":"1.226122413","rc":[{"tv":9611.97,"batb":[[2,5.8,60.73],[1,5.9,43.03],[0,6,108.19]],"trd":[[6.2,74.9]],"batl":[[1,6.6,83.19]],"id":41122648},{"batb":[[1,28,22.17]],"batl":[[2,34,27.07],[1,32,13.69],[0,30,3.59]],"id":55632148},{"batb":[[2,1.8,134.64],[1,1.81,39.75],[0,1.82,26.71]],"batl":[[0,1.83,3.09]],"id":51922},{"batb":[],"batl":[[2,5.3,17.12],[1,5.2,11.52],[0,5.1,12.24]],"id":50466254},{"batb":[[1,30,28.31]],"batl":[[0,34,8.96]],"id":106596}],"tv":136559.78}],"ArrivalTime":1710508096684}
{"op":"mcm","id":2,"clk":"ANldAJWCAQCljwE=","pt":1710508096785,"mc":[{"id":"1.226122413","rc":[{"batl":[[2,580,2.91],[1,520,4.05]],"id":54370634},{"batb":[[1,5.9,60.04]],"batl":[[0,6.4,9.51]],"id":41122648},{"tv":98816.64,"batb":[[0,1.82,19.21]],"trd":[[1.82,5964.48]],"ltp":1.82,"batl":[],"id":51922},{"tv":2426.14,"trd":[[34,72.9]],"batl":[[0,34,7.96]],"id":106596}],"tv":136576.78}],"ArrivalTime":1710508096793}
{"op":"mcm","id":2,"clk":"AOFdAJ6CAQCzjwE=","pt":1710508096888,"mc":[{"id":"1.226122413","rc":[{"batl":[[2,520,4.05],[1,470,2],[0,460,1]],"id":54370634},{"batb":[[0,6,50.59]],"id":41122648},{"batb":[[0,29,14.49]],"batl":[[2,36,30.24],[1,34,27.07],[0,32,13.69]],"id":55632148},{"tv":98878.23,"batb":[[1,1.81,95.35],[0,1.82,8.67]],"trd":[[1.83,9634.81],[1.82,5985.56]],"batl":[[2,1.86,108.2],[1,1.85,108.84],[0,1.84,77.14]],"id":51922},{"batb":[[2,29,15.16]],"id":106596}],"tv":136638.37}],"ArrivalTime":1710508096896}
{"op":"mcm","id":2,"clk":"AOhdAKiCAQC9jwE=","pt":1710508096995,"mc":[{"id":"1.226122413","rc":[{"batb":[[1,28,14.17]],"id":55632148},{"batb":[[1,1.81,145.35]],"id":51922},{"batl":[[0,34,5.84]],"id":106596}]}],"ArrivalTime":1710508097003}
{"op":"mcm","id":2,"clk":"AO1dALGCAQC/jwE=","pt":1710508097040,"mc":[{"id":"1.226122413","rc":[{"batb":[[2,5.8,77.93],[1,5.9,43.03]],"batl":[],"id":41122648},{"batb":[[0,29,17.29]],"batl":[],"id":55632148},{"tv":98895.57,"batb":[[2,1.79,152.07],[1,1.8,134.64],[0,1.81,172.2]],"trd":[[1.82,6002.9]],"batl":[[2,1.85,108.84],[1,1.84,103.55],[0,1.83,50.79]],"id":51922},{"tv":19203.25,"batb":[[0,5,2]],"trd":[[5,1077.09]],"ltp":5,"id":50466254},{"batb":[[0,32,8.24]],"id":106596}],"tv":136709.41}],"ArrivalTime":1710508097048}
{"op":"mcm","id":2,"clk":"APBdALuCAQDLjwE=","pt":1710508097148,"mc":[{"id":"1.226122413","rc":[{"tv":9659.97,"batb":[[0,6,52.29]],"trd":[[6.6,252.94],[6.4,178.29]],"ltp":6.6,"batl":[[2,7,58.11],[1,6.8,32.89],[0,6.6,68.7]],"id":41122648},{"batb":[[2,1.8,134.64],[1,1.81,172.2],[0,1.82,18.03]],"id":51922},{"batl":[[2,5.3,37.7]],"id":50466254}],"tv":136757.41}],"ArrivalTime":1710508097156}
{"op":"mcm","id":2,"clk":"APNdAMKCAQDWjwE=","pt":1710508097253,"mc":[{"id":"1.226122413","rc":[{"batb":[[2,5.9,41.27],[1,6,52.29],[0,6.2,9.97]],"id":41122648},{"batl":[[0,32,15.69]],"id":55632148},{"batl":[[0,1.83,90.52]],"id":51922},{"batl":[[1,5.2,14.09]],"id":50466254}]}],"ArrivalTime":1710508097261}
{"op":"mcm","id":2,"clk":"APldAMyCAQDhjwE=","pt":1710508097364,"mc":[{"id":"1.226122413","rc":[{"batb":[[2,5.9,22.97],[1,6,53.16],[0,6.2,19.57]],"batl":[[1,6.8,45.01]],"id":41122648},{"tv":99125.19,"batb":[[2,1.79,152.07],[1,1.8,134.64],[0,1.81,141.44]],"trd":[[1.81,5247.38],[1.82,6038.96],[1.83,9766.85]],"ltp":1.83,"batl":[[0,1.83,24.5]],"id":51922}],"tv":136987.03}],"ArrivalTime":1710508097371}
{"op":"mcm","id":2,"clk":"AP9dANKCAQDnjwE=","pt":1710508097459,"mc":[{"id":"1.226122413","rc":[{"batb":[[1,6,69.71]],"id":41122648},{"tv":99173.19,"batb":[[2,1.8,134.64],[1,1.81,141.44],[0,1.82,39.69]],"trd":[[1.83,9814.85]],"batl":[[2,1.86,111.35],[1,1.85,108.84],[0,1.84,103.55]],"id":51922},{"tv":2428.14,"trd":[[34,74.9]],"batl":[[0,34,4.84]],"id":106596}],"tv":137037.03}],"ArrivalTime":1710508097466}
{"op":"mcm","id":2,"clk":"AINeANiCAQDujwE=","pt":1710508097563,"mc":[{"id":"1.226122413","rc":[{"batb":[[2,5.9,38.64]],"batl":[[2,6.8,45.01],[1,6.6,78.64],[0,6.4,11.21]],"id":41122648},{"batl":[[1,34,27.31]],"id":55632148},{"batb":[],"batl":[[2,1.86,108.2],[0,1.84,77.14]],"id":51922},{"tv":2802.59,"batb":[[2,38,16.1],[1,40,10.29],[0,42,6.38]],"trd":[[44,38.84]],"ltp":44,"batl":[[2,50,2.09],[1,48,3],[0,44,1.74]],"id":49744721},{"batb":[[0,5,17.4]],"id":50466254}],"tv":137058.61}],"ArrivalTime":1710508097570}
{"op":"mcm","id":2,"clk":"AIVeAN6CAQD2jwE=","pt":1710508097669,"mc":[{"id":"1.226122413","rc":[{"tv":9661.97,"batb":[[2,5.9,40.4],[1,6,71.41],[0,6.2,18.57]],"trd":[[6.2,76.9]],"ltp":6.2,"id":41122648},{"batb":[[0,1.82,66.71]],"batl":[],"id":51922},{"tv":2806.07,"trd":[[44,42.32]],"batl":[[2,55,7.03],[1,50,2.09],[0,48,3]],"id":49744721}],"tv":137064.09}],"ArrivalTime":1710508097677}
{"op":"mcm","id":2,"clk":"AI9eAOWCAQCEkAE=","pt":1710508097774,"mc":[{"id":"1.226122413","rc":[{"tv":9664.99,"batb":[[2,5.9,59.7]],"trd":[[6.4,181.31]],"ltp":6.4,"batl":[[0,6.4,9.7]],"id":41122648},{"tv":2311.64,"trd":[[32,67.7]],"ltp":32,"batl":[[1,34,27.07],[0,32,15.38]],"id":55632148},{"tv":99252.57,"batb":[[0,1.82,27.02]],"trd":[[1.82,6118.34]],"ltp":1.82,"batl":[[1,1.85,58.84]],"id":51922},{"batl":[[1,50,3.9],[0,48,4.65]],"id":49744721},{"tv":19205.63,"batb":[],"trd":[[5.1,607.33]],"ltp":5.1,"batl":[[0,5.1,11.05]],"id":50466254},{"tv":584.56,"trd":[[210,0.18]],"ltp":210,"batl":[[0,210,4.91]],"id":66251581},{"tv":2428.72,"trd":[[34,75.48]],"batl":[[0,34,4.55]],"id":106596}],"tv":137150.25}],"ArrivalTime":1710508097782}
{"op":"mcm","id":2,"clk":"AJFeAO2CAQCLkAE=","pt":1710508097886,"mc":[{"id":"1.226122413","rc":[{"batl":[[2,470,2],[1,460,1],[0,450,2]],"id":54370634},{"batb":[[1,1.81,194.47]],"id":51922},{"tv":2812.07,"trd":[[48,20.1],[46,15.36]],"ltp":48,"batl":[[0,48,2.92]],"id":49744721},{"tv":2430.71,"batb":[[0,32,7.24]],"trd":[[32,191.03]],"ltp":32,"id":106596}],"tv":137158.24}],"ArrivalTime":1710508097893}
{"op":"mcm","id":2,"clk":"AJReAPKCAQCSkAE=","pt":1710508097977,"mc":[{"id":"1.226122413","rc":[{"batl":[[2,460,1],[1,450,2],[0,440,1]],"id":54370634},{"batl":[[0,6.4,18.17]],"id":41122648},{"tv":99270.17,"batb":[[0,1.82,18.22]],"trd":[[1.82,6135.94]],"batl":[[0,1.84,103.87]],"id":51922}],"tv":137175.84}],"ArrivalTime":1710508097985}
{"op":"mcm","id":2,"clk":"AJdeAP2CAQCakAE=","pt":1710508098081,"mc":[{"id":"1.226122413","rc":[{"batl":[[2,470,2]],"id":54370634},{"tv":99618.17,"batb":[[2,1.79,134.35],[1,1.8,134.64],[0,1.81,48.69]],"trd":[[1.81,5558.94],[1.82,6172.38]],"ltp":1.81,"id":51922},{"batl":[[1,50,5.33]],"id":49744721},{"tv":19209.07,"trd":[[5.1,610.77]],"batl":[[0,5.1,9.33]],"id":50466254},{"batb":[[0,32,8.4]],"batl":[[2,38,5.94]],"id":106596}],"tv":137527.28}],"ArrivalTime":1710508098089}
{"op":"mcm","id":2,"clk":"AJ1eAIeDAQCjkAE=","pt":1710508098180,"mc":[{"id":"1.226122413","rc":[{"batl":[[0,440,2]],"id":54370634},{"tv":9688.47,"batb":[[0,6.2,21.78]],"trd":[[6.4,204.79]],"batl":[[0,6.4,6.53]],"id":41122648},{"batl":[[2,340,2.14]],"id":41200638},{"batb":[[1,1.8,161.96]],"id":51922},{"batl":[[1,50,3.52]],"id":49744721},{"batb":[[0,5,19.4]],"id":50466254},{"tv":2432.71,"trd":[[34,77.48]],"ltp":34,"batl":[[0,34,3.55]],"id":106596}],"tv":137552.76}],"ArrivalTime":1710508098188}
{"op":"mcm","id":2,"clk":"AKVeAJGDAQCukAE=","pt":1710508098310,"mc":[{"id":"1.226122413","rc":[{"batb":[],"batl":[[1,6.6,68.7]],"id":41122648},{"batb":[[2,1.79,187.55],[1,1.8,106.92],[0,1.81,84.77]],"batl":[[2,1.85,58.84],[1,1.84,103.87],[0,1.83,75.2]],"id":51922},{"batb":[[0,5,31.56]],"id":50466254}]}],"ArrivalTime":1710508098318}
{"op":"mcm","id":2,"clk":"AKheAJaDAQC7kAE=","pt":1710508098389,"mc":[{"id":"1.226122413","rc":[{"batb":[[1,6,62.53],[0,6.2,33.73]],"batl":[[0,6.4,6.64]],"id":41122648},{"batb":[[2,1.79,190.55]],"id":51922},{"batl":[[0,34,3.07]],"id":106596}]}],"ArrivalTime":1710508098397}
{"op":"mcm","id":2,"clk":"AKleAJ2DAQDHkAE=","pt":1710508098493,"mc":[{"id":"1.226122413","rc":[{"tv":2346.22,"batb":[[2,26,30.72],[1,27,26.85],[0,28,14.17]],"trd":[[29,203.05]],"ltp":29,"id":55632148},{"tv":99622.17,"batb":[[0,1.81,82.77]],"trd":[[1.81,5562.94]],"batl":[[0,1.83,83.2]],"id":51922}],"tv":137591.34}],"ArrivalTime":1710508098501}
{"op":"mcm","id":2,"clk":"AKxeAKWDAQDNkAE=","pt":1710508098549,"mc":[{"id":"1.226122413","rc":[{"batb":[[0,1.81,168.17]],"batl":[[1,1.84,141.35]],"id":51922}]}],"ArrivalTime":1710508098557}
{"op":"mcm","id":2,"clk":"AK9eALCDAQDckAE=","pt":1710508098648,"mc":[{"id":"1.226122413","rc":[{"batb":[[1,6,64.53]],"batl":[[2,6.8,32.89]],"id":41122648},{"batb":[[1,27,24.25],[0,28,14.72]],"batl":[],"id":55632148},{"batb":[[2,1.79,191.8]],"batl":[[2,1.85,124.84],[1,1.84,148.19],[0,1.83,99.2]],"id":51922},{"batb":[[0,5,42.56]],"batl":[[2,5.4,114.05],[1,5.3,37.7],[0,5.2,14.09]],"id":50466254}]}],"ArrivalTime":1710508098655}
{"op":"mcm","id":2,"clk":"ALVeALaDAQDjkAE=","pt":1710508098749,"mc":[{"id":"1.226122413","rc":[{"batb":[[0,6.2,42.33]],"batl":[[0,6.4,8.12]],"id":41122648},{"tv":2347.32,"batb":[[0,28,14.17]],"trd":[[29,204.15]],"batl":[[2,32,15.38],[1,30,2.98],[0,29,2.02]],"id":55632148},{"tv":99632.17,"batb":[[0,1.81,163.17]],"trd":[[1.81,5572.94]],"id":51922},{"tv":19209.09,"batb":[[0,5,42.55]],"trd":[[5,1077.11]],"ltp":5,"batl":[[1,5.3,17.12]],"id":50466254}],"tv":137602.46}],"ArrivalTime":1710508098757}
{"op":"mcm","id":2,"clk":"ALxeALmDAQDrkAE=","pt":1710508098852,"mc":[{"id":"1.226122413","rc":[{"batl":[[2,6.8,34.89]],"id":41122648},{"tv":507.51,"trd":[[310,4.2]],"ltp":310,"batl":[[2,350,1.71],[1,340,2.14],[0,320,1.71]],"id":41200638},{"batb":[[0,28,13.17]],"id":55632148},{"batb":[[2,1.8,116.92],[1,1.81,163.17],[0,1.82,4.44]],"batl":[[1,1.84,110.71],[0,1.83,115.2]],"id":51922},{"batb":[],"batl":[[0,5.2,15.09]],"id":50466254},{"batb":[[2,160,5.65],[0,180,4.82]],"id":66251581}],"tv":137605.8}],"ArrivalTime":1710508098860}
{"op":"mcm","id":2,"clk":"AL9eAMKDAQDzkAE=","pt":1710508098958,"mc":[{"id":"1.226122413","rc":[{"tv":9708.47,"batb":[[0,6.2,32.34]],"trd":[[6.2,96.9]],"ltp":6.2,"id":41122648},{"batb":[[1,250,1.6],[0,260,3.12]],"id":41200638},{"tv":2351.36,"batb":[[2,27,24.25],[1,28,10.79],[0,29,5.69]],"trd":[[29,208.19]],"batl":[[2,34,27.07],[1,32,15.38],[0,30,2.98]],"id":55632148}],"tv":137629.84}],"ArrivalTime":1710508098966}
{"op":"mcm","id":2,"clk":"AMReAMeDAQD2kAE=","pt":1710508099054,"mc":[{"id":"1.226122413","rc":[{"tv":395.9,"trd":[[440,4]],"ltp":440,"batl":[[2,520,4.36],[1,470,2],[0,450,2]],"id":54370634},{"batb":[[0,6.2,33.34]],"id":41122648},{"tv":99641.05,"batb":[[2,1.79,191.8],[1,1.8,169.15],[0,1.81,163.17]],"trd":[[1.82,6181.26]],"ltp":1.82,"batl":[[2,1.84,110.71],[1,1.83,131.2],[0,1.82,24.51]],"id":51922}],"tv":137642.72}],"ArrivalTime":1710508099062}
{"op":"mcm","id":2,"clk":"AMpeANGDAQD/kAE=","pt":1710508099161,"mc":[{"id":"1.226122413","rc":[{"tv":397.04,"batb":[],"trd":[[450,1.14]],"ltp":450,"batl":[[0,450,1.43]],"id":54370634},{"batb":[[1,28,13.92]],"id":55632148}],"tv":137643.86}],"ArrivalTime":1710508099168}
{"op":"mcm","id":2,"clk":"ANBeAN2DAQCMkQE=","pt":1710508099269,"mc":[{"id":"1.226122413","rc":[{"batl":[[2,6.8,40.81]],"id":41122648},{"batl":[[2,34,33.72]],"id":55632148},{"tv":99911.44,"batb":[[0,1.81,161.17]],"trd":[[1.81,5576.94],[1.83,10081.24]],"ltp":1.83,"batl":[[2,1.86,111.35],[1,1.85,124.84],[0,1.84,110.71]],"id":51922},{"batl":[[2,50,3.52],[1,48,2.92],[0,46,4.27]],"id":49744721},{"tv":19239.27,"batb":[[2,4.9,42.15],[1,5,42.55],[0,5.1,53.75]],"trd":[[5.2,167.68]],"ltp":5.2,"batl":[[2,5.5,62.43],[1,5.4,114.05],[0,5.3,17.12]],"id":50466254}],"tv":137944.43}],"ArrivalTime":1710508099276}
{"op":"mcm","id":2,"clk":"ANZeAOaDAQCVkQE=","pt":1710508099379,"mc":[{"id":"1.226122413","rc":[{"tv":2362.74,"batb":[[2,26,30.72],[1,27,24.25],[0,28,13.92]],"trd":[[29,219.57]],"batl":[[2,32,15.38],[1,30,2.98],[0,29,1.71]],"id":55632148},{"batb":[[0,1.81,163.64]],"batl":[[2,1.86,108.2]],"id":51922}],"tv":137955.81}],"ArrivalTime":1710508099387}
{"op":"mcm","id":2,"clk":"ANteAPiDAQChkQE=","pt":1710508099473,"mc":[{"id":"1.226122413","rc":[{"tv":9754.23,"batb":[[1,6,47.98],[0,6.2,7.24]],"trd":[[6.2,142.66]],"batl":[[0,6.4,19.54]],"id":41122648},{"batl":[[2,34,33.72],[1,32,15.62],[0,30,2.98]],"id":55632148},{"batb":[[2,1.8,169.15],[1,1.81,163.64],[0,1.82,27.27]],"batl":[],"id":51922},{"batl":[[2,50,5.27],[0,46,5.92]],"id":49744721},{"tv":19254.27,"batb":[[0,5.1,67.75]],"trd":[[5.3,20.14]],"ltp":5.3,"batl":[[0,5.3,9.62]],"id":50466254},{"batb":[[0,32,8.46]],"id":106596}],"tv":138016.57}],"ArrivalTime":1710508099481}
{"op":"mcm","id":2,"clk":"AIVfALWEAQDekQE=","pt":1710508100144,"mc":[{"id":"1.226122413","rc":[{"batb":[[1,350,2.53],[0,360,1.5],[2,340,1.4]],"id":54370634},{"tv":9783.33,"batb":[[2,5.8,78.68],[1,5.9,41.22],[0,6,33.06]],"trd":[[6.2,165.76],[6,6]],"ltp":6.2,"batl":[[2,6.6,51.27],[1,6.4,29.79],[0,6.2,10.5]],"id":41122648},{"batb":[[0,28,10.79]],"batl":[],"id":55632148},{"tv":99915,"batb":[[0,1.82,36.49],[2,1.8,174.22],[1,1.81,240.08]],"trd":[[1.82,6182.82],[1.83,10083.24]],"ltp":1.82,"batl":[[0,1.84,103.87],[2,1.86,113.2],[1,1.85,124.84]],"id":51922},{"tv":2812.33,"batb":[[0,42,4]],"trd":[[42,37.8]],"ltp":42,"batl":[[2,48,1.65],[1,46,7.92],[0,44,1]],"id":49744721},{"batb":[[1,5,52.55],[0,5.1,89.68]],"batl":[[0,5.3,2.57],[1,5.4,89.64]],"id":50466254},{"tv":2434.71,"batb":[],"trd":[[34,79.48]],"batl":[[0,34,2.07]],"id":106596}],"tv":138051.49,"con":true}],"ArrivalTime":1710508100152}
{"op":"mcm","id":2,"clk":"AIZfALeEAQDfkQE=","pt":1710508100155,"mc":[{"id":"1.226122413","rc":[{"tv":9796.79,"batb":[[2,5.8,80.51],[1,5.9,27.31]],"trd":[[6.2,179.22]],"batl":[[0,6.2,23.77]],"id":41122648},{"batb":[[2,1.81,240.08],[1,1.82,61.49],[0,1.83,24.1]],"batl":[[0,1.84,103.13]],"id":51922},{"batl":[[1,46,5.92]],"id":49744721},{"batl":[[2,5.4,89.64],[1,5.3,2.57],[0,5.2,10.71]],"id":50466254}],"tv":138064.95}],"ArrivalTime":1710508100163}
{"op":"mcm","id":2,"clk":"AIhfAMGEAQDqkQE=","pt":1710508100255,"mc":[{"id":"1.226122413","rc":[{"tv":99929,"batb":[[0,1.83,17.1]],"trd":[[1.83,10097.24]],"ltp":1.83,"batl":[],"id":51922},{"tv":19275.69,"batb":[[2,5,52.55],[1,5.1,89.68],[0,5.2,13.28]],"trd":[[5.2,189.1]],"ltp":5.2,"batl":[[2,5.5,62.43],[1,5.4,89.64],[0,5.3,2.57]],"id":50466254}],"tv":138100.37}],"ArrivalTime":1710508100262}
{"op":"mcm","id":2,"clk":"AI9fAMqEAQDykQE=","pt":1710508100363,"mc":[{"id":"1.226122413","rc":[{"batb":[[1,5.9,25.55]],"batl":[[1,6.4,49.79],[0,6.2,34.12]],"id":41122648},{"tv":2366.06,"batb":[[0,28,9.13]],"trd":[[28,349.2]],"ltp":28,"id":55632148},{"tv":99951.1,"batb":[[0,1.83,34.48]],"trd":[[1.83,10119.34]],"batl":[[2,1.86,116.35],[0,1.84,76.4]],"id":51922},{"batb":[[0,5.2,40.28]],"batl":[],"id":50466254}],"tv":138125.79}],"ArrivalTime":1710508100371}
{"op":"mcm","id":2,"clk":"AJZfANCEAQD3kQE=","pt":1710508100458,"mc":[{"id":"1.226122413","rc":[{"tv":9862.92,"batb":[[1,5.9,25.54],[0,6,2]],"trd":[[5.9,0.02],[6,72.11]],"ltp":5.9,"batl":[[0,6.2,41.85]],"id":41122648},{"batb":[[0,5.2,54.79]],"id":50466254}],"tv":138191.92}],"ArrivalTime":1710508100465}
{"op":"mcm","id":2,"clk":"AJtfANWEAQD8kQE=","pt":1710508100567,"mc":[{"id":"1.226122413","rc":[{"batb":[[1,350,3.53]],"id":54370634},{"batb":[[2,5.8,63.31],[1,5.9,34.54]],"batl":[],"id":41122648},{"batl":[[2,34,40.37]],"id":55632148},{"tv":99995.4,"batb":[[2,1.81,242.65],[1,1.82,110.09],[0,1.83,12.33]],"trd":[[1.83,10163.64]],"id":51922},{"batb":[[0,5.2,81.79]],"id":50466254}],"tv":138236.22}],"ArrivalTime":1710508100575}
{"op":"mcm","id":2,"clk":"AKBfANuEAQD+kQE=","pt":1710508100666,"mc":[{"id":"1.226122413","rc":[{"tv":9866.92,"batb":[[2,5.7,42.02],[1,5.8,63.31],[0,5.9,23.48]],"trd":[[6,76.11]],"ltp":6,"id":41122648},{"batl":[[2,650,1.71],[1,400,2.82],[0,380,1.29]],"id":41200638},{"batb":[[1,1.82,159.82]],"id":51922},{"tv":19285.69,"batb":[[0,5.2,76.79]],"trd":[[5.2,199.1]],"id":50466254}],"tv":138250.22}],"ArrivalTime":1710508100674}
{"op":"mcm","id":2,"clk":"AKhfAOOEAQCFkgE=","pt":1710508100776,"mc":[{"id":"1.226122413","rc":[{"batb":[[0,5.9,21.86]],"batl":[[0,6.2,66.85]],"id":41122648},{"tv":2818.23,"batb":[[0,42,1.05]],"trd":[[42,43.7]],"id":49744721}],"tv":138256.12}],"ArrivalTime":1710508100784}
{"op":"mcm","id":2,"clk":"ALNfAO2EAQCQkgE=","pt":1710508100880,"mc":[{"id":"1.226122413","rc":[{"batb":[[1,350,1.4],[0,360,3.22]],"id":54370634},{"batl":[[2,34,43.4]],"id":55632148},{"batb":[[0,1.83,27.43]],"batl":[[1,1.85,58.84],[0,1.84,142.4]],"id":51922},{"batb":[[0,180,7.41]],"id":66251581},{"tv":2436.71,"batb":[[2,29,23.23]],"trd":[[34,81.48]],"batl":[[0,34,1.07]],"id":106596}],"tv":138258.12}],"ArrivalTime":1710508100888}
{"op":"mcm","id":2,"clk":"ALhfAPWEAQCYkgE=","pt":1710508100990,"mc":[{"id":"1.226122413","rc":[{"batl":[[2,520,1.54]],"id":54370634},{"batb":[],"batl":[[0,6.2,67.05]],"id":41122648},{"tv":2368.26,"batb":[[0,28,8.03]],"trd":[[28,351.4]],"id":55632148},{"batl":[[0,44,5.79]],"id":49744721}],"tv":138260.32}],"ArrivalTime":1710508100998}
{"op":"mcm","id":2,"clk":"AMNfAICFAQCkkgE=","pt":1710508101099,"mc":[{"id":"1.226122413","rc":[{"batb":[[2,5.7,40.12],[1,5.8,61.48]],"id":41122648},{"tv":2377.09,"batb":[[0,28,3.61]],"trd":[[28,360.23]],"id":55632148},{"tv":100046.88,"batb":[[0,1.83,1.69]],"trd":[[1.83,10215.12]],"batl":[[2,1.86,113.2]],"id":51922},{"batb":[[2,5,60.39]],"id":50466254}],"tv":138320.63}],"ArrivalTime":1710508101106}
{"op":"mcm","id":2,"clk":"AMdfAIuFAQCqkgE=","pt":1710508101189,"mc":[{"id":"1.226122413","rc":[{"batb":[[0,28,5.61]],"id":55632148},{"batb":[[2,1.81,252.65]],"id":51922},{"tv":2820.33,"batb":[[2,36,48.42],[1,38,16.1],[0,40,10.29]],"trd":[[42,45.8]],"batl":[[2,48,3.42]],"id":49744721},{"tv":19287.69,"batb":[[0,5.2,75.79]],"trd":[[5.2,201.1]],"id":50466254}],"tv":138324.73}],"ArrivalTime":1710508101197}
{"op":"mcm","id":2,"clk":"ANBfAJWFAQC5kgE=","pt":1710508101290,"mc":[{"id":"1.226122413","rc":[{"batb":[[1,5.8,42.79]],"id":41122648},{"batb":[[0,1.83,27.43]],"id":51922},{"batl":[[2,46,5.92],[1,44,5.79],[0,42,2]],"id":49744721}]}],"ArrivalTime":1710508101297}
{"op":"mcm","id":2,"clk":"ANhfAJqFAQDIkgE=","pt":1710508101398,"mc":[{"id":"1.226122413","rc":[{"batl":[[2,34,45.4]],"id":55632148},{"tv":100050.26,"batb":[[2,1.81,254.65],[0,1.83,25.74]],"trd":[[1.83,10218.5]],"id":51922},{"batl":[[1,44,7.38]],"id":49744721}],"tv":138328.11}],"ArrivalTime":1710508101405}
{"op":"mcm","id":2,"clk":"AORfAKSFAQDQkgE=","pt":1710508101505,"mc":[{"id":"1.226122413","rc":[{"batl":[[1,400,3.68],[0,350,2.99]],"id":41200638},{"tv":2822.89,"trd":[[42,48.36]],"batl":[[2,48,3.42],[1,46,5.92],[0,44,6.13]],"id":49744721},{"tv":19291.68,"batb":[[0,5.2,73.79]],"trd":[[5.2,205.09]],"id":50466254},{"batl":[[2,40,4.53],[1,38,5.18],[0,36,4.8]],"id":106596}],"tv":138334.66}],"ArrivalTime":1710508101512}
{"op":"mcm","id":2,"clk":"AOlfAKmFAQDUkgE=","pt":1710508101556,"mc":[{"id":"1.226122413","rc":[{"batl":[[2,430,1.15]],"id":41200638},{"tv":100051.02,"batb":[[0,1.83,125.41]],"trd":[[1.83,10219.26]],"id":51922},{"batl":[[0,44,3.31]],"id":49744721},{"tv":2438.71,"trd":[[36,14.19],[34,81.72]],"ltp":36,"batl":[[0,36,3.8]],"id":106596}],"tv":138337.42}],"ArrivalTime":1710508101563}
{"op":"mcm","id":2,"clk":"APBfALOFAQDckgE=","pt":1710508101656,"mc":[{"id":"1.226122413","rc":[{"tv":9892.8,"batb":[[2,5.7,42.02],[1,5.8,67.79],[0,5.9,12.86]],"trd":[[6,76.51],[6.2,204.7]],"ltp":6.2,"batl":[[0,6.2,54.11]],"id":41122648},{"batb":[[2,26,28.01]],"id":55632148},{"tv":100061.02,"batb":[[0,1.83,120.41]],"trd":[[1.83,10229.26]],"id":51922},{"tv":2824.33,"trd":[[42,49.8]],"batl":[[0,44,2.59]],"id":49744721},{"batb":[[2,30,28.31],[1,32,8.46],[0,34,2.6]],"batl":[[2,40,6.43]],"id":106596}],"tv":138374.74}],"ArrivalTime":1710508101664}
{"op":"mcm","id":2,"clk":"APRfAL+FAQDkkgE=","pt":1710508101761,"mc":[{"id":"1.226122413","rc":[{"batb":[[2,5.7,40.12]],"id":41122648},{"tv":100081.02,"trd":[[1.84,13779.66]],"ltp":1.84,"batl":[[0,1.84,132.4]],"id":51922},{"tv":19294,"trd":[[5.3,22.46]],"ltp":5.3,"batl":[[0,5.3,1.42]],"id":50466254},{"tv":2442.75,"batb":[[0,34,1.64]],"trd":[[34,85.76]],"ltp":34,"batl":[[1,38,5.94],[0,36,4.65]],"id":106596}],"tv":138401.1}],"ArrivalTime":1710508101769}
{"op":"mcm","id":2,"clk":"APhfAMWFAQDskgE=","pt":1710508101873,"mc":[{"id":"1.226122413","rc":[{"batb":[[2,5.8,67.79],[1,5.9,12.86],[0,6,15.52]],"id":41122648},{"tv":2379.22,"batb":[[2,26,31.62],[1,27,27.72],[0,28,4.54]],"trd":[[28,362.36]],"batl":[],"id":55632148},{"tv":100087.02,"batb":[[2,1.81,256.65],[1,1.82,209.02],[0,1.83,229.24]],"trd":[[1.84,13785.66]],"batl":[[0,1.84,129.4]],"id":51922},{"batl":[[0,44,4.82]],"id":49744721},{"batl":[[1,5.4,108.55]],"id":50466254},{"batb":[[0,180,8.43]],"id":66251581},{"tv":2446.03,"batb":[[2,29,26.43],[1,30,25.15],[0,32,8.46]],"trd":[[34,89.04]],"batl":[[2,40,7.11],[0,36,5.91]],"id":106596}],"tv":138412.51}],"ArrivalTime":1710508101881}
{"op":"mcm","id":2,"clk":"AIBgAMmFAQDzkgE=","pt":1710508101971,"mc":[{"id":"1.226122413","rc":[{"tv":9902.5,"batb":[[2,5.8,69.62],[1,5.9,2.57]],"trd":[[6.2,214.4]],"batl":[[0,6.2,49.26]],"id":41122648},{"batl":[[2,1.86,116.35],[0,1.84,131.4]],"id":51922},{"batl":[[0,36,6.76]],"id":106596}],"tv":138422.21}],"ArrivalTime":1710508101979}
{"op":"mcm","id":2,"clk":"AIZgANaFAQD4kgE=","pt":1710508102097,"mc":[{"id":"1.226122413","rc":[{"batl":[[2,510,3.05]],"id":54370634},{"tv":9907.94,"batb":[[1,5.9,14.56],[0,6,12.8]],"trd":[[6,81.95]],"ltp":6,"id":41122648},{"tv":19441.59,"batb":[[2,4.9,63.5],[1,5,60.39],[0,5.1,89.68]],"trd":[[5.2,352.68]],"ltp":5.2,"id":50466254},{"batb":[[2,160,6.68],[0,180,8.74]],"id":66251581},{"batb":[[2,29,34.5]],"batl":[[2,40,6.43],[1,38,5.18]],"id":106596}],"tv":138575.24}],"ArrivalTime":1710508102105}
{"op":"mcm","id":2,"clk":"AJBgAN+FAQD/kgE=","pt":1710508102175,"mc":[{"id":"1.226122413","rc":[{"batb":[[0,6,32.8]],"id":41122648},{"batl":[[0,36,5.91]],"id":106596}]}],"ArrivalTime":1710508102184}
{"op":"mcm","id":2,"clk":"AJhgAOuFAQCJkwE=","pt":1710508102278,"mc":[{"id":"1.226122413","rc":[{"batl":[[2,400,3.68],[1,350,2.56],[0,340,2.43]],"id":41200638},{"tv":2381.36,"batb":[[0,28,3.48]],"trd":[[28,364.5]],"id":55632148},{"tv":100129.08,"batb":[[1,1.82,211.59],[0,1.83,278.09]],"trd":[[1.84,13827.72]],"batl":[[2,1.86,113.2],[1,1.85,34.05],[0,1.84,81.97]],"id":51922},{"batb":[],"batl":[[2,5.4,108.55],[1,5.3,14.72],[0,5.2,19.72]],"id":50466254}],"tv":138619.44}],"ArrivalTime":1710508102285}
{"op":"mcm","id":2,"clk":"AJ9gAPSFAQCOkwE=","pt":1710508102392,"mc":[{"id":"1.226122413","rc":[{"tv":100129.28,"batb":[[1,1.82,214.03],[0,1.83,277.99]],"trd":[[1.83,10229.46]],"ltp":1.83,"batl":[[1,1.85,36.05]],"id":51922},{"batb":[[0,40,5.66]],"batl":[[0,44,6.82]],"id":49744721},{"tv":19444.09,"batb":[[0,5.1,88.43]],"trd":[[5.1,613.27]],"ltp":5.1,"batl":[[2,5.4,98.27]],"id":50466254},{"tv":2448.03,"trd":[[36,16.19]],"ltp":36,"batl":[[0,36,4.91]],"id":106596}],"tv":138624.14}],"ArrivalTime":1710508102399}
{"op":"mcm","id":2,"clk":"AKpgAP6FAQCYkwE=","pt":1710508102493,"mc":[{"id":"1.226122413","rc":[{"batb":[[1,5.9,25.32]],"id":41122648},{"tv":100299.22,"batb":[[0,1.83,274.99]],"trd":[[1.84,13991.66],[1.83,10235.46]],"ltp":1.84,"batl":[[2,1.87,137.6],[1,1.86,113.2],[0,1.85,36.05]],"id":51922},{"batb":[[2,30,25.15],[1,32,8.46],[0,34,2.6]],"id":106596}],"tv":138794.08}],"ArrivalTime":1710508102501}
{"op":"mcm","id":2,"clk":"AK5gAIqGAQClkwE=","pt":1710508102550,"mc":[{"id":"1.226122413","rc":[{"batb":[[0,1.83,284.99]],"id":51922},{"tv":2837.97,"batb":[],"trd":[[44,55.96]],"ltp":44,"batl":[[2,50,3.84],[1,48,3.42],[0,46,5.92]],"id":49744721}],"tv":138807.72}],"ArrivalTime":1710508102557}
{"op":"mcm","id":2,"clk":"ALVgAI+GAQCwkwE=","pt":1710508102711,"mc":[{"id":"1.226122413","rc":[{"batb":[[1,5.9,23.56]],"batl":[],"id":41122648},{"tv":2383.8,"batb":[[0,28,2.26]],"trd":[[28,366.94]],"batl":[[2,34,52.06]],"id":55632148},{"tv":100327.88,"batb":[[2,1.81,237.05],[0,1.83,321.66]],"trd":[[1.83,10264.12]],"ltp":1.83,"batl":[[2,1.87,134.51]],"id":51922},{"batb":[[2,38,16.1],[1,40,10.36],[0,42,1.57]],"batl":[[0,46,7.75]],"id":49744721},{"tv":2453.23,"batb":[[2,29,34.5],[1,30,25.15],[0,32,8.46]],"trd":[[34,94.24]],"ltp":34,"batl":[[2,42,9.56],[1,40,7.11],[0,38,6.79]],"id":106596}],"tv":138844.02}],"ArrivalTime":1710508102719}
{"op":"mcm","id":2,"clk":"AMJgAJiGAQC1kwE=","pt":1710508102757,"mc":[{"id":"1.226122413","rc":[{"tv":9958.08,"trd":[[6.2,264.54]],"ltp":6.2,"batl":[[0,6.2,24.19]],"id":41122648},{"tv":19483.53,"batb":[[2,5,60.39],[1,5.1,88.43],[0,5.2,4.6]],"trd":[[5.2,392.12]],"ltp":5.2,"batl":[[2,5.5,62.43],[1,5.4,98.27],[0,5.3,14.72]],"id":50466254}],"tv":138933.6}],"ArrivalTime":1710508102764}
{"op":"mcm","id":2,"clk":"AMlgAJ+GAQC6kwE=","pt":1710508102852,"mc":[{"id":"1.226122413","rc":[{"tv":399.9,"trd":[[450,4]],"batl":[[2,520,1.31],[1,510,3.05],[0,470,2]],"id":54370634},{"batb":[[1,5.9,25.32]],"id":41122648},{"batl":[[2,430,1.15],[1,400,3.68]],"id":41200638},{"tv":2384.32,"batb":[[2,25,11.15],[1,26,31.62],[0,27,27.72]],"trd":[[28,367.46]],"batl":[[2,32,15.62],[1,30,2.98],[0,28,2.32]],"id":55632148},{"batb":[[2,1.81,151.65]],"batl":[[2,1.87,137.6],[1,1.86,115.2]],"id":51922},{"batb":[[1,40,8.37],[0,42,6.07]],"id":49744721},{"tv":2454.93,"batb":[[2,30,25.15],[1,32,8.46],[0,34,2.6]],"trd":[[36,17.89]],"ltp":36,"batl":[[1,40,6.43],[0,38,5.18]],"id":106596}],"tv":138938.68}],"ArrivalTime":1710508102859}
{"op":"mcm","id":2,"clk":"AM9gAKWGAQDFkwE=","pt":1710508102959,"mc":[{"id":"1.226122413","rc":[{"batl":[[0,1.85,62.67]],"id":51922},{"batb":[[1,170,4.27]],"id":66251581},{"tv":2456.93,"batb":[],"trd":[[38,3.13]],"ltp":38,"batl":[[2,42,10.17],[1,40,7.11],[0,38,4.94]],"id":106596}],"tv":138940.68}],"ArrivalTime":1710508102967}
{"op":"mcm","id":2,"clk":"ANlgAKyGAQDPkwE=","pt":1710508103063,"mc":[{"id":"1.226122413","rc":[{"batb":[[1,5.9,23.56],[0,6,44.56]],"id":41122648},{"batb":[[1,26,17.76],[0,27,25.46]],"batl":[[2,30,2.98],[1,29,3.49]],"id":55632148},{"batb":[[2,1.82,214.03],[1,1.83,321.66],[0,1.84,49.18]],"id":51922},{"batb":[[0,42,7.68]],"id":49744721},{"batb":[[0,34,4.74]],"batl":[[0,38,4.18]],"id":106596}]}],"ArrivalTime":1710508103071}
{"op":"mcm","id":2,"clk":"AOZgALiGAQDXkwE=","pt":1710508103168,"mc":[{"id":"1.226122413","rc":[{"batb":[[0,6,64.56]],"batl":[[0,6.2,34.62]],"id":41122648},{"tv":2435.25,"batb":[[2,24,14.9],[1,25,11.15],[0,26,17.76]],"trd":[[27,374.48]],"ltp":27,"batl":[[2,32,15.62],[1,30,2.98],[0,29,3.49]],"id":55632148},{"tv":100342.96,"batb":[[0,1.84,41.64]],"trd":[[1.84,14006.74]],"ltp":1.84,"batl":[[1,1.86,118.35]],"id":51922},{"tv":19492.72,"batb":[[2,4.9,63.5],[1,5,60.39],[0,5.1,88.43]],"trd":[[5.2,401.31]],"id":50466254},{"batl":[[0,38,4.94]],"id":106596}],"tv":139015.88}],"ArrivalTime":1710508103175}
{"op":"mcm","id":2,"clk":"AO5gAL6GAQDhkwE=","pt":1710508103274,"mc":[{"id":"1.226122413","rc":[{"batl":[[1,510,3.29]],"id":54370634},{"batb":[[0,6,75.01]],"batl":[[0,6.2,35.26]],"id":41122648},{"batb":[[0,26,14.15]],"id":55632148},{"tv":100347.3,"batb":[[1,1.83,345.64],[0,1.84,39.47]],"trd":[[1.84,14011.08]],"batl":[[1,1.86,117.2]],"id":51922},{"batb":[],"batl":[[2,5.4,98.27],[1,5.3,34.92],[0,5.2,24.41]],"id":50466254},{"batl":[[0,38,6.45]],"id":106596}],"tv":139020.22}],"ArrivalTime":1710508103281}
{"op":"mcm","id":2,"clk":"APdgAMWGAQDskwE=","pt":1710508103388,"mc":[{"id":"1.226122413","rc":[{"batb":[[0,26,4.85]],"batl":[[2,30,2.98],[1,29,3.49],[0,28,4.37]],"id":55632148},{"tv":2841.07,"batb":[[0,42,6.13]],"trd":[[42,52.9]],"ltp":42,"id":49744721},{"tv":19504.18,"trd":[[5.2,412.77]],"batl":[[0,5.2,18.68]],"id":50466254}],"tv":139034.78}],"ArrivalTime":1710508103396}
{"op":"mcm","id":2,"clk":"AIBhAM2GAQD2kwE=","pt":1710508103481,"mc":[{"id":"1.226122413","rc":[{"batb":[[1,5.9,25.32]],"id":41122648},{"batb":[[0,1.84,49.47]],"id":51922},{"batb":[[0,5.1,78.43]],"batl":[],"id":50466254}]}],"ArrivalTime":1710508103489}
{"op":"mcm","id":2,"clk":"AIlhANuGAQD+kwE=","pt":1710508103581,"mc":[{"id":"1.226122413","rc":[{"batb":[[0,6,95.01]],"id":41122648},{"tv":2440.39,"batb":[[0,26,1.28]],"trd":[[26,395.98]],"ltp":26,"id":55632148},{"batb":[],"batl":[[1,1.86,107.2],[0,1.85,36.05]],"id":51922},{"batb":[[2,4.9,85.12]],"batl":[[1,5.3,42.77]],"id":50466254},{"batb":[[1,32,14.96]],"id":106596}],"tv":139039.92}],"ArrivalTime":1710508103589}
{"op":"mcm","id":2,"clk":"AIxhAN2GAQCNlAE=","pt":1710508103682,"mc":[{"id":"1.226122413","rc":[{"tv":401.9,"batb":[[0,360,2.22]],"trd":[[360,24.66]],"ltp":360,"batl":[],"id":54370634},{"batb":[[1,5.9,23.56]],"batl":[],"id":41122648},{"tv":509.51,"batb":[[0,260,2.12]],"trd":[[260,12.16]],"ltp":260,"batl":[],"id":41200638},{"tv":2441.41,"batb":[[2,23,11.91],[1,24,14.9],[0,25,11.93]],"trd":[[26,397]],"batl":[[2,29,3.49],[1,28,4.37],[0,27,1]],"id":55632148},{"tv":100440.24,"batb":[[0,1.84,3]],"trd":[[1.84,14104.02]],"id":51922},{"tv":2843.07,"batb":[[0,42,5.13]],"trd":[[42,54.9]],"id":49744721},{"tv":19508.18,"batb":[[0,5.1,76.43]],"trd":[[5.1,617.27]],"ltp":5.1,"batl":[],"id":50466254},{"tv":586.56,"batb":[[0,180,7.74]],"trd":[[190,9.19],[180,11.31]],"ltp":180,"id":66251581},{"tv":2458.93,"batb":[[0,34,3.74]],"trd":[[34,96.24]],"ltp":34,"id":106596}],"tv":139147.88}],"ArrivalTime":1710508103690}
{"op":"mcm","id":2,"clk":"AJNhAOaGAQCYlAE=","pt":1710508103788,"mc":[{"id":"1.226122413","rc":[{"batb":[[2,5.8,75.57],[0,6,104.01]],"id":41122648},{"batb":[[0,25,13.93]],"batl":[[0,27,4.64]],"id":55632148},{"batb":[[0,1.84,50.71]],"batl":[[0,1.85,44.05]],"id":51922},{"tv":19578.18,"batb":[[0,5.1,41.43]],"trd":[[5.1,687.27]],"id":50466254}],"tv":139217.88}],"ArrivalTime":1710508103795}
{"op":"mcm","id":2,"clk":"AJVhAO6GAQCclAE=","pt":1710508103892,"mc":[{"id":"1.226122413","rc":[{"tv":2442.96,"batb":[[0,25,13.15]],"trd":[[26,398.55]],"batl":[[2,28,4.37],[1,27,4.64],[0,26,1.8]],"id":55632148},{"batb":[],"batl":[[0,1.85,70.67]],"id":51922},{"batb":[[0,42,4.21]],"id":49744721},{"batb":[[0,34,4.39]],"id":106596}],"tv":139219.43}],"ArrivalTime":1710508103900}
{"op":"mcm","id":2,"clk":"AJphAPiGAQCplAE=","pt":1710508103996,"mc":[{"id":"1.226122413","rc":[{"batb":[],"batl":[[0,1.85,58.97]],"id":51922},{"batb":[[0,5.1,29.5]],"batl":[[0,5.2,30.64]],"id":50466254}]}],"ArrivalTime":1710508104004}
{"op":"mcm","id":2,"clk":"AKJhAIGHAQCxlAE=","pt":1710508104044,"mc":[{"id":"1.226122413","rc":[{"batb":[[0,6,124.01]],"id":41122648},{"batl":[[2,29,3.49],[1,28,4.37],[0,27,4.64]],"id":55632148},{"batl":[[0,1.85,32.35]],"id":51922},{"batb":[[0,42,2.6]],"id":49744721}]}],"ArrivalTime":1710508104052}
{"op":"mcm","id":2,"clk":"AKxhAIqHAQC3lAE=","pt":1710508104154,"mc":[{"id":"1.226122413","rc":[{"batb":[[0,360,2]],"batl":[[0,470,2.01]],"id":54370634},{"batl":[[1,400,3.69]],"id":41200638},{"batb":[[1,24,11.51]],"batl":[],"id":55632148},{"batb":[[0,1.84,3]],"id":51922},{"batl":[[0,46,7.84]],"id":49744721},{"batl":[[0,210,4.93]],"id":66251581},{"batb":[],"batl":[[0,38,6.56]],"id":106596}]}],"ArrivalTime":1710508104162}
{"op":"mcm","id":2,"clk":"ALJhAJKHAQDBlAE=","pt":1710508104260,"mc":[{"id":"1.226122413","rc":[{"batb":[[1,1.83,347.64]],"batl":[[0,1.85,48.35]],"id":51922},{"tv":2843.26,"trd":[[44,56.15]],"ltp":44,"batl":[[0,46,7.75]],"id":49744721}],"tv":139219.62}],"ArrivalTime":1710508104268}
{"op":"mcm","id":2,"clk":"ALlhAJ2HAQDKlAE=","pt":1710508104364,"mc":[{"id":"1.226122413","rc":[{"tv":10206.1,"batb":[[2,5.7,61.09],[1,5.8,75.57],[0,5.9,23.56]],"trd":[[6,329.97]],"ltp":6,"id":41122648},{"batb":[[0,25,7.23]],"batl":[[2,29,7.69]],"id":55632148},{"tv":100503.36,"batb":[[2,1.81,177],[1,1.82,164.3],[0,1.83,328.78]],"trd":[[1.84,14129.42],[1.83,10301.84]],"ltp":1.83,"batl":[[2,1.87,147.6]],"id":51922},{"batl":[[1,5.3,62.77]],"id":50466254},{"batb":[[2,160,7.72]],"batl":[[2,280,1.62]],"id":66251581},{"tv":2459.41,"batb":[[1,32,16.56],[0,34,4.15]],"trd":[[34,96.72]],"batl":[[1,40,8.32],[0,38,4.82]],"id":106596}],"tv":139531.24}],"ArrivalTime":1710508104372}
{"op":"mcm","id":2,"clk":"ALthAKSHAQDXlAE=","pt":1710508104466,"mc":[{"id":"1.226122413","rc":[{"tv":10211.62,"batb":[[1,5.8,73.74],[0,5.9,36.45]],"trd":[[5.9,5.54]],"ltp":5.9,"id":41122648},{"batb":[[2,1.82,164.3],[1,1.83,328.78],[0,1.84,85.86]],"batl":[[2,1.87,144.51],[1,1.86,76.34],[0,1.85,64.35]],"id":51922},{"tv":19588.24,"batb":[[0,5.1,24.47]],"trd":[[5.1,697.33]],"batl":[[0,5.2,18.68]],"id":50466254},{"batb":[[2,30,27.76]],"id":106596}],"tv":139546.82}],"ArrivalTime":1710508104474}
{"op":"mcm","id":2,"clk":"AMhhAK+HAQDmlAE=","pt":1710508104576,"mc":[{"id":"1.226122413","rc":[{"tv":10216.64,"batb":[[0,5.9,33.94]],"trd":[[5.9,10.56]],"batl":[[0,6.2,46.84]],"id":41122648},{"tv":100556.76,"batb":[[1,1.83,331.36]],"trd":[[1.85,14587.94]],"ltp":1.85,"batl":[[2,1.87,154.51],[0,1.85,37.65]],"id":51922},{"batl":[[0,46,9.75]],"id":49744721},{"batb":[[0,5.1,36.41]],"id":50466254},{"tv":2462.35,"batb":[[0,34,4.94]],"trd":[[34,99.66]],"batl":[[0,38,2.9]],"id":106596}],"tv":139608.18}],"ArrivalTime":1710508104584}
{"op":"mcm","id":2,"clk":"ANBhALaHAQDxlAE=","pt":1710508104687,"mc":[{"id":"1.226122413","rc":[{"tv":10232.63,"batb":[[2,5.8,73.74],[1,5.9,25.95],[0,6,20]],"trd":[[5.9,26.55]],"id":41122648},{"tv":514.38,"trd":[[340,7.25]],"ltp":340,"batl":[[2,650,1.59],[1,430,1.15],[0,400,3.69]],"id":41200638},{"batb":[[0,1.84,112.1]],"batl":[[1,1.86,92.34],[0,1.85,45.65]],"id":51922},{"tv":2844.16,"trd":[[46,16.26]],"ltp":46,"batl":[[0,46,9.3]],"id":49744721}],"tv":139629.94}],"ArrivalTime":1710508104695}
{"op":"mcm","id":2,"clk":"ANFhAL+HAQD7lAE=","pt":1710508104776,"mc":[{"id":"1.226122413","rc":[{"tv":10275.31,"trd":[[6.2,307.22]],"ltp":6.2,"batl":[[0,6.2,25.5]],"id":41122648},{"tv":100656.56,"batb":[[2,1.83,331.36],[1,1.84,112.1],[0,1.85,34.56]],"trd":[[1.85,14687.74]],"batl":[[2,1.88,308.41],[1,1.87,154.51],[0,1.86,92.34]],"id":51922},{"tv":2462.57,"trd":[[36,18.11]],"ltp":36,"batl":[[0,38,2.79]],"id":106596}],"tv":139772.64}],"ArrivalTime":1710508104784}
{"op":"mcm","id":2,"clk":"AN1hAMeHAQCAlQE=","pt":1710508104880,"mc":[{"id":"1.226122413","rc":[{"tv":10301.13,"batb":[[2,5.8,75.57],[0,6,7.09]],"trd":[[6,355.79]],"ltp":6,"id":41122648},{"batl":[[0,400,3.94]],"id":41200638},{"batb":[[0,25,4.5]],"id":55632148},{"tv":100676.56,"batb":[[0,1.85,24.56]],"trd":[[1.85,14707.74]],"batl":[[1,1.87,157.6],[0,1.86,100.34]],"id":51922},{"batb":[[0,34,6.94]],"id":106596}],"tv":139818.46}],"ArrivalTime":1710508104888}
{"op":"mcm","id":2,"clk":"AORhANKHAQCQlQE=","pt":1710508104987,"mc":[{"id":"1.226122413","rc":[{"batb":[[1,5.9,36.76],[0,6,42.42]],"id":41122648},{"tv":2450.41,"batb":[[2,22,16.44],[1,23,11.91],[0,24,12.29]],"trd":[[25,403.53]],"ltp":25,"id":55632148},{"tv":100692.8,"batb":[[1,1.84,167.1],[0,1.85,16.44]],"trd":[[1.85,14723.98]],"id":51922}],"tv":139842.15}],"ArrivalTime":1710508104994}
{"op":"mcm","id":2,"clk":"AO1hANuHAQCflQE=","pt":1710508105098,"mc":[{"id":"1.226122413","rc":[{"batb":[[2,350,1.4],[1,360,2],[0,370,2]],"id":54370634},{"batb":[[2,5.8,93.05]],"id":41122648},{"tv":514.4,"trd":[[350,3.08]],"ltp":350,"batl":[[0,400,3.93]],"id":41200638},{"batb":[[2,1.83,416.75]],"batl":[[0,1.86,116.34]],"id":51922},{"batl":[[0,5.2,43.68]],"id":50466254},{"tv":587.36,"batb":[[0,180,4.75]],"trd":[[180,12.11]],"id":66251581},{"batb":[[2,30,26.9]],"id":106596}],"tv":139842.97}],"ArrivalTime":1710508105105}
{"op":"mcm","id":2,"clk":"APJhAOCHAQCllQE=","pt":1710508105191,"mc":[{"id":"1.226122413","rc":[{"tv":2451.96,"batb":[[0,24,11.51]],"trd":[[25,405.08]],"batl":[[2,28,4.37],[1,27,4.64],[0,25,1.8]],"id":55632148},{"tv":100767.12,"batb":[[2,1.82,142.7],[1,1.83,416.75],[0,1.84,129.94]],"trd":[[1.84,14203.74]],"ltp":1.84,"batl":[[1,1.87,154.51]],"id":51922},{"tv":19594.84,"trd":[[5.2,419.37]],"ltp":5.2,"batl":[[0,5.2,40.38]],"id":50466254},{"batb":[[0,180,7.34]],"id":66251581}],"tv":139925.44}],"ArrivalTime":1710508105199}
{"op":"mcm","id":2,"clk":"APdhAO6HAQCulQE=","pt":1710508105294,"mc":[{"id":"1.226122413","rc":[{"batb":[[2,5.8,91.42]],"id":41122648},{"batb":[[0,1.84,139.94]],"batl":[[0,1.86,132.34]],"id":51922},{"tv":19650.33,"batb":[[0,5.1,8.67]],"trd":[[5.1,752.82]],"ltp":5.1,"id":50466254}],"tv":139980.93}],"ArrivalTime":1710508105301}
{"op":"mcm","id":2,"clk":"APphAPaHAQC4lQE=","pt":1710508105407,"mc":[{"id":"1.226122413","rc":[{"batb":[[1,360,3]],"id":54370634},{"batb":[[2,5.8,89.59]],"id":41122648},{"batb":[[0,24,13.51]],"batl":[[0,26,3.35]],"id":55632148},{"batb":[[2,1.83,416.75],[1,1.84,139.94],[0,1.85,11.45]],"batl":[[2,1.88,305.37]],"id":51922},{"tv":19667.66,"batb":[[2,4.8,75.66],[1,4.9,85.12],[0,5,52.55]],"trd":[[5.1,770.15]],"batl":[[1,5.3,67.77]],"id":50466254}],"tv":139998.26}],"ArrivalTime":1710508105415}
{"op":"mcm","id":2,"clk":"AP9hAIOIAQDClQE=","pt":1710508105451,"mc":[{"id":"1.226122413","rc":[{"batb":[[0,6,74.42]],"batl":[[1,6.4,51.79]],"id":41122648},{"batl":[[2,430,1.15],[1,400,3.5],[0,370,2.99]],"id":41200638},{"batl":[[0,1.86,134.34]],"id":51922},{"tv":2844.84,"trd":[[46,16.94]],"batl":[[0,46,8.96]],"id":49744721},{"batl":[[2,5.3,67.77],[1,5.2,52.36],[0,5.1,12.78]],"id":50466254}],"tv":139998.94}],"ArrivalTime":1710508105459}
{"op":"mcm","id":2,"clk":"AIRiAI2IAQDLlQE=","pt":1710508105560,"mc":[{"id":"1.226122413","rc":[{"batb":[[2,5.8,91.42],[0,6,83.42]],"batl":[[0,6.2,13.92]],"id":41122648},{"batb":[[2,23,11.91],[1,24,13.51],[0,25,2.6]],"batl":[[2,29,7.69],[1,28,4.37],[0,27,4.64]],"id":55632148},{"tv":100790.03,"batb":[[2,1.82,142.7],[1,1.83,416.75],[0,1.84,139.94]],"trd":[[1.85,14746.89]],"ltp":1.85,"id":51922},{"batb":[],"batl":[[1,5.2,64.99]],"id":50466254}],"tv":140021.85}],"ArrivalTime":1710508105567}
{"op":"mcm","id":2,"clk":"AJFiAJqIAQDSlQE=","pt":1710508105665,"mc":[{"id":"1.226122413","rc":[{"batb":[[1,360,3.38]],"id":54370634},{"batb":[[2,5.8,75.57]],"id":41122648},{"batb":[[2,240,4.12]],"id":41200638},{"tv":100950.03,"batb":[[0,1.84,59.94]],"trd":[[1.84,14363.74]],"ltp":1.84,"batl":[],"id":51922}],"tv":140181.85}],"ArrivalTime":1710508105673}
{"op":"mcm","id":2,"clk":"AJJiAKWIAQDglQE=","pt":1710508105764,"mc":[{"id":"1.226122413","rc":[{"batb":[[0,25,6.05]],"id":55632148},{"batb":[[2,1.83,416.75],[1,1.84,59.94],[0,1.85,85.4]],"batl":[[1,1.87,171.47]],"id":51922},{"tv":19692.92,"batb":[],"trd":[[5.1,795.41]],"batl":[[2,5.4,98.27],[1,5.3,67.77],[0,5.2,65.14]],"id":50466254}],"tv":140207.11}],"ArrivalTime":1710508105771}
{"op":"mcm","id":2,"clk":"AJxiALKIAQDrlQE=","pt":1710508105897,"mc":[{"id":"1.226122413","rc":[{"batb":[[0,260,2.83]],"batl":[],"id":41200638},{"batb":[[0,25,9.76]],"batl":[[1,28,8.3],[0,27,8.57]],"id":55632148},{"tv":101061.56,"batb":[[2,1.83,409.92],[0,1.85,29.63]],"trd":[[1.85,14858.42]],"ltp":1.85,"batl":[],"id":51922},{"tv":19693.22,"batb":[[2,4.9,85.12],[1,5,52.55],[0,5.1,11.82]],"trd":[[5.1,795.71]],"batl":[[0,5.2,64.99]],"id":50466254}],"tv":140318.94}],"ArrivalTime":1710508105905}
{"op":"mcm","id":2,"clk":"AKRiALeIAQD1lQE=","pt":1710508105976,"mc":[{"id":"1.226122413","rc":[{"batl":[[0,27,4.93]],"id":55632148},{"tv":101120.82,"batb":[[2,1.82,142.7],[1,1.83,409.92],[0,1.84,106.5]],"trd":[[1.85,14917.68]],"batl":[[1,1.87,172.47]],"id":51922}],"tv":140378.2}],"ArrivalTime":1710508105984}
{"op":"mcm","id":2,"clk":"ALJiAMKIAQCGlgE=","pt":1710508106099,"mc":[{"id":"1.226122413","rc":[{"batb":[[1,360,1.38]],"id":54370634},{"tv":2462.02,"batb":[[0,25,4.73]],"trd":[[25,415.14]],"batl":[],"id":55632148},{"batb":[[2,1.82,164.05]],"batl":[[2,1.87,158.6],[1,1.86,134.34],[0,1.85,42.93]],"id":51922},{"batb":[[2,4.8,75.66],[1,4.9,92.96],[0,5,52.55]],"batl":[[2,5.3,67.77],[1,5.2,64.99],[0,5.1,19.47]],"id":50466254},{"batb":[[0,180,5.4]],"batl":[],"id":66251581}],"tv":140388.26}],"ArrivalTime":1710508106107}
{"op":"mcm","id":2,"clk":"ALZiAM2IAQCNlgE=","pt":1710508106183,"mc":[{"id":"1.226122413","rc":[{"batb":[[0,1.84,56.56]],"id":51922},{"batl":[[1,5.2,74.99]],"id":50466254}]}],"ArrivalTime":1710508106191}
{"op":"mcm","id":2,"clk":"ALliANmIAQCalgE=","pt":1710508106286,"mc":[{"id":"1.226122413","rc":[{"batb":[[1,5.9,38.52]],"id":41122648},{"batb":[[1,1.83,419.92]],"batl":[[2,1.88,305.37],[1,1.87,155.51],[0,1.86,134.34]],"id":51922},{"tv":19717.66,"batb":[[2,4.8,78.46]],"trd":[[5.1,820.15]],"batl":[[1,5.2,75.99],[0,5.1,7.25]],"id":50466254},{"batb":[[0,180,4.75]],"id":66251581}],"tv":140412.7}],"ArrivalTime":1710508106293}
{"op":"mcm","id":2,"clk":"AMFiAOCIAQCelgE=","pt":1710508106391,"mc":[{"id":"1.226122413","rc":[{"batb":[[2,250,1.6],[1,260,2.83],[0,270,2]],"id":41200638},{"batb":[[0,25,9.07]],"id":55632148},{"batl":[[2,1.87,155.51],[1,1.86,134.34],[0,1.85,24.66]],"id":51922}]}],"ArrivalTime":1710508106398}
{"op":"mcm","id":2,"clk":"AMZiAOuIAQColgE=","pt":1710508106490,"mc":[{"id":"1.226122413","rc":[{"batb":[[1,5.9,36.76]],"id":41122648},{"batb":[[1,24,14.51]],"id":55632148},{"batb":[[1,1.83,422.33]],"batl":[],"id":51922},{"batb":[[2,4.8,75.66]],"batl":[[2,5.4,128.27],[1,5.3,67.77],[0,5.2,75.99]],"id":50466254},{"batl":[[2,260,1.55],[1,210,4.93],[0,200,1.01]],"id":66251581}]}],"ArrivalTime":1710508106498}
{"op":"mcm","id":2,"clk":"AM5iAPeIAQCwlgE=","pt":1710508106594,"mc":[{"id":"1.226122413","rc":[{"batb":[[1,5.9,38.52]],"id":41122648},{"batb":[[2,250,2.43],[1,270,2],[0,280,1.88]],"id":41200638},{"batl":[[0,27,8.05]],"id":55632148},{"batb":[[2,4.8,78.46]],"id":50466254}]}],"ArrivalTime":1710508106602}
{"op":"mcm","id":2,"clk":"ANRiAP6IAQC7lgE=","pt":1710508106646,"mc":[{"id":"1.226122413","rc":[{"batb":[[0,370,2.21]],"id":54370634},{"tv":589.38,"trd":[[200,16.68]],"ltp":200,"batl":[[2,280,1.62],[1,260,1.55],[0,210,4.93]],"id":66251581}],"tv":140414.72}],"ArrivalTime":1710508106654}
{"op":"mcm","id":2,"clk":"ANtiAIuJAQDHlgE=","pt":1710508106755,"mc":[{"id":"1.226122413","rc":[{"batb":[[2,350,1.31]],"id":54370634},{"batb":[[1,5.9,36.76]],"id":41122648},{"batb":[[2,4.8,75.66]],"id":50466254},{"batb":[[0,180,4.85]],"id":66251581}]}],"ArrivalTime":1710508106762}
{"op":"mcm","id":2,"clk":"AONiAJiJAQDRlgE=","pt":1710508106864,"mc":[{"id":"1.226122413","rc":[{"batb":[[0,6,56.33]],"id":41122648},{"tv":19736.46,"trd":[[5.2,438.17]],"ltp":5.2,"batl":[[0,5.2,66.59]],"id":50466254}],"tv":140433.52}],"ArrivalTime":1710508106872}
{"op":"mcm","id":2,"clk":"AOxiAJ6JAQDblgE=","pt":1710508106960,"mc":[{"id":"1.226122413","rc":[{"batb":[[1,360,1.74]],"id":54370634},{"batb":[[0,280,2.54]],"id":41200638},{"batb":[[0,1.84,63.39]],"batl":[[2,1.87,115.51]],"id":51922},{"batb":[[2,4.9,92.96],[1,5,52.55],[0,5.1,11.96]],"id":50466254},{"batb":[[2,160,8.87]],"id":66251581}]}],"ArrivalTime":1710508106967}
{"op":"mcm","id":2,"clk":"APViAKmJAQDmlgE=","pt":1710508107065,"mc":[{"id":"1.226122413","rc":[{"batb":[[0,1.84,75.27]],"batl":[[2,1.87,118.6]],"id":51922},{"batb":[],"batl":[[0,5.2,53.96]],"id":50466254}]}],"ArrivalTime":1710508107072}
{"op":"mcm","id":2,"clk":"AJBjAMGJAQD3lgE=","pt":1710508107324,"mc":[{"id":"1.226122413","rc":[{"batb":[[0,370,2.3]],"id":54370634},{"batl":[[0,6.2,22.46]],"id":41122648},{"batb":[[2,250,2.79]],"id":41200638},{"tv":101170.14,"batb":[[2,1.83,422.33],[1,1.84,75.27],[0,1.85,75.34]],"trd":[[1.85,14967]],"batl":[[2,1.88,309.66],[1,1.87,118.6],[0,1.86,134.34]],"id":51922},{"tv":19776.06,"batb":[[2,4.9,92.96],[1,5,52.55],[0,5.1,4.61]],"trd":[[5.1,859.75]],"ltp":5.1,"id":50466254}],"tv":140522.44,"con":true}],"ArrivalTime":1710508107331}
{"op":"mcm","id":2,"clk":"AJJjAMWJAQD8lgE=","pt":1710508107381,"mc":[{"id":"1.226122413","rc":[{"tv":402.98,"batb":[[0,370,1.76]],"trd":[[390,11.71],[370,9.82]],"ltp":370,"id":54370634},{"batb":[[0,6,47.33]],"id":41122648},{"batb":[[1,270,3]],"id":41200638},{"tv":2467.17,"batb":[[0,25,6.5]],"trd":[[25,420.29]],"id":55632148},{"batb":[[1,1.84,169.15]],"batl":[[2,1.88,306.62],[1,1.87,115.51]],"id":51922},{"tv":19785.28,"batb":[[2,4.8,75.66],[1,4.9,92.96],[0,5,52.55]],"trd":[[5.1,868.97]],"batl":[[2,5.3,67.77],[1,5.2,53.96],[0,5.1,15.15]],"id":50466254}],"tv":140537.89}],"ArrivalTime":1710508107389}
{"op":"mcm","id":2,"clk":"AJ1jANKJAQCFlwE=","pt":1710508107478,"mc":[{"id":"1.226122413","rc":[{"batl":[[1,400,3.25],[0,370,3.21]],"id":41200638},{"tv":101273.52,"batb":[[0,1.85,69.2]],"trd":[[1.85,15070.38]],"id":51922},{"batb":[],"batl":[[0,5.1,39.53]],"id":50466254}],"tv":140641.27}],"ArrivalTime":1710508107486}
{"op":"mcm","id":2,"clk":"AKJjANmJAQCLlwE=","pt":1710508107578,"mc":[{"id":"1.226122413","rc":[{"tv":10306.27,"batb":[[0,6,44.76]],"trd":[[6,360.93]],"id":41122648},{"batb":[[0,25,4.16]],"id":55632148},{"batb":[[1,1.84,193.3]],"id":51922},{"batl":[[1,5.2,66.18]],"id":50466254}],"tv":140646.41}],"ArrivalTime":1710508107585}
{"op":"mcm","id":2,"clk":"AKVjAOWJAQCTlwE=","pt":1710508107685,"mc":[{"id":"1.226122413","rc":[{"batb":[[0,280,8.27]],"id":41200638}]}],"ArrivalTime":1710508107692}
{"op":"mcm","id":2,"clk":"AKxjAPCJAQCelwE=","pt":1710508107783,"mc":[{"id":"1.226122413","rc":[{"tv":10325.23,"batb":[[0,6,35.28]],"trd":[[6,379.89]],"id":41122648},{"batb":[[2,270,3],[1,280,8.27],[0,290,2]],"id":41200638},{"tv":2475.49,"batb":[[2,22,16.44],[1,23,11.91],[0,24,14.51]],"trd":[[25,428.61]],"id":55632148}],"tv":140673.69}],"ArrivalTime":1710508107790}
{"op":"mcm","id":2,"clk":"ALBjAPqJAQCrlwE=","pt":1710508107895,"mc":[{"id":"1.226122413","rc":[{"batb":[[0,6,15.28]],"id":41122648},{"tv":101373.52,"batb":[[0,1.85,19.2]],"trd":[[1.85,15170.38]],"id":51922}],"tv":140773.69}],"ArrivalTime":1710508107902}
{"op":"mcm","id":2,"clk":"ALhjAISKAQCzlwE=","pt":1710508107990,"mc":[{"id":"1.226122413","rc":[{"tv":10342.23,"batb":[[0,6,6.78]],"trd":[[6,396.89]],"id":41122648},{"batb":[[1,280,9.27]],"id":41200638},{"batb":[[2,23,11.91],[1,24,14.51],[0,25,2.6]],"batl":[[2,28,8.3],[1,27,8.05],[0,26,5.67]],"id":55632148},{"batl":[[1,40,9.35]],"id":106596}],"tv":140790.69}],"ArrivalTime":1710508107998}
{"op":"mcm","id":2,"clk":"AL5jAJWKAQDAlwE=","pt":1710508108104,"mc":[{"id":"1.226122413","rc":[{"tv":19832.32,"trd":[[5.1,916.01]],"batl":[[2,5.4,128.27],[1,5.3,67.77],[0,5.2,66.18]],"id":50466254}],"tv":140837.73}],"ArrivalTime":1710508108112}
{"op":"mcm","id":2,"clk":"AMpjAJ+KAQDJlwE=","pt":1710508108207,"mc":[{"id":"1.226122413","rc":[{"tv":10409.55,"batb":[[0,6,19.34]],"trd":[[6,401.31],[6.2,370.12]],"ltp":6.2,"batl":[[0,6.2,2.74]],"id":41122648},{"tv":2480.63,"batb":[[2,22,16.44],[1,23,11.91],[0,24,17.15]],"trd":[[25,433.75]],"batl":[[0,26,8.15]],"id":55632148},{"batl":[[0,1.86,105.85]],"id":51922},{"tv":2862.76,"trd":[[46,34.86]],"batl":[[2,55,7.03],[1,50,3.84],[0,48,3.42]],"id":49744721}],"tv":140928.11}],"ArrivalTime":1710508108215}
{"op":"mcm","id":2,"clk":"AM9jAKaKAQDXlwE=","pt":1710508108310,"mc":[{"id":"1.226122413","rc":[{"batb":[[2,5.8,73.74]],"id":41122648},{"tv":2480.69,"batb":[[0,24,17.12]],"trd":[[25,433.81]],"batl":[[1,27,4.12]],"id":55632148},{"tv":101411.92,"batb":[[2,1.82,164.05],[1,1.83,422.33],[0,1.84,193.3]],"trd":[[1.85,15208.78]],"id":51922},{"batl":[[2,55,8.78]],"id":49744721},{"batb":[[2,4.9,92.96],[1,5,52.55],[0,5.1,12.3]],"batl":[[0,5.2,53.96]],"id":50466254}],"tv":140966.57}],"ArrivalTime":1710508108318}
{"op":"mcm","id":2,"clk":"ANRjALCKAQDilwE=","pt":1710508108367,"mc":[{"id":"1.226122413","rc":[{"tv":10419.85,"batb":[[0,6,17.55]],"trd":[[6,411.61]],"ltp":6,"batl":[[2,6.8,71.37],[1,6.6,51.27],[0,6.4,51.79]],"id":41122648},{"tv":518.88,"batb":[[0,290,4.8]],"trd":[[370,11.54],[360,8.22]],"ltp":370,"batl":[[1,400,2.82],[0,380,1.39]],"id":41200638},{"batb":[[2,22,19.44],[1,23,15.61],[0,24,15.12]],"batl":[[0,26,8.58]],"id":55632148},{"batl":[[0,1.86,129.04]],"id":51922},{"batb":[[0,42,6.81]],"id":49744721}],"tv":140981.35}],"ArrivalTime":1710508108374}
{"op":"mcm","id":2,"clk":"ANxjALiKAQDslwE=","pt":1710508108470,"mc":[{"id":"1.226122413","rc":[{"tv":403,"trd":[[450,4.02]],"ltp":450,"batl":[[0,470,2]],"id":54370634},{"batb":[[1,280,7.39]],"batl":[[2,650,1.75],[1,430,1.15],[0,400,3.46]],"id":41200638},{"batb":[[0,24,12.29]],"id":55632148},{"batb":[[0,1.84,169.15]],"batl":[[1,1.87,125.51]],"id":51922},{"tv":19856.92,"batb":[[2,4.8,75.66],[1,4.9,92.96],[0,5,52.55]],"trd":[[5.1,940.61]],"batl":[],"id":50466254}],"tv":141005.97}],"ArrivalTime":1710508108478}
{"op":"mcm","id":2,"clk":"AOFjAL6KAQDylwE=","pt":1710508108574,"mc":[{"id":"1.226122413","rc":[{"batl":[[2,1000,4.41],[1,650,1.75],[0,430,1.79]],"id":41200638},{"tv":101670,"trd":[[1.86,10592.45]],"ltp":1.86,"batl":[[2,1.89,91.14],[1,1.88,306.62],[0,1.87,125.51]],"id":51922},{"batb":[],"batl":[[1,5.3,59.92]],"id":50466254}],"tv":141264.05}],"ArrivalTime":1710508108581}
{"op":"mcm","id":2,"clk":"AOljAMiKAQD7lwE=","pt":1710508108681,"mc":[{"id":"1.226122413","rc":[{"batl":[[2,6.6,51.27],[1,6.4,51.79],[0,6.2,10.47]],"id":41122648},{"batl":[[0,430,4.4]],"id":41200638},{"batb":[[0,24,11.29]],"id":55632148},{"batb":[[2,1.83,422.33],[1,1.84,169.15],[0,1.85,169.91]],"batl":[],"id":51922}]}],"ArrivalTime":1710508108689}
{"op":"mcm","id":2,"clk":"AO9jANGKAQCGmAE=","pt":1710508108783,"mc":[{"id":"1.226122413","rc":[{"batb":[[1,1.84,192.6]],"batl":[[0,1.87,89.8]],"id":51922},{"batl":[[0,5.2,66.04]],"id":50466254}]}],"ArrivalTime":1710508108790}
{"op":"mcm","id":2,"clk":"APRjANuKAQCOmAE=","pt":1710508108885,"mc":[{"id":"1.226122413","rc":[{"batb":[[0,6,43.38]],"id":41122648},{"batb":[[2,30,25.15]],"id":106596}]}],"ArrivalTime":1710508108893}
{"op":"mcm","id":2,"clk":"APxjAOOKAQCamAE=","pt":1710508108988,"mc":[{"id":"1.226122413","rc":[{"batl":[[0,6.2,22.55]],"id":41122648},{"batb":[[2,280,7.39],[1,290,4.8],[0,300,2.23]],"id":41200638}]}],"ArrivalTime":1710508108996}
{"op":"mcm","id":2,"clk":"AINkAO+KAQCjmAE=","pt":1710508109094,"mc":[{"id":"1.226122413","rc":[{"batb":[[0,300,2.35]],"id":41200638},{"batl":[[2,5.3,59.92],[1,5.2,66.04],[0,5.1,19.51]],"id":50466254}]}],"ArrivalTime":1710508109101}
{"op":"mcm","id":2,"clk":"AItkAPqKAQCtmAE=","pt":1710508109196,"mc":[{"id":"1.226122413","rc":[{"batb":[[1,290,2]],"id":41200638},{"batb":[[0,1.85,203.23]],"id":51922}]}],"ArrivalTime":1710508109203}
{"op":"mcm","id":2,"clk":"AJFkAICLAQCzmAE=","pt":1710508109291,"mc":[{"id":"1.226122413","rc":[{"batb":[[2,5.8,75.57]],"id":41122648},{"batb":[[1,290,3]],"id":41200638},{"batb":[[0,5,41.55]],"id":50466254}]}],"ArrivalTime":1710508109299}
{"op":"mcm","id":2,"clk":"AKZkAJmLAQDVmAE=","pt":1710508109601,"mc":[{"id":"1.226122413","rc":[{"tv":10506.61,"batb":[[2,5.7,61.09],[1,5.8,75.57],[0,5.9,36.76]],"trd":[[6,498.37]],"batl":[[0,6.2,10.47]],"id":41122648},{"tv":101676,"batb":[[0,1.85,200.24]],"trd":[[1.85,15214.78]],"ltp":1.85,"id":51922},{"tv":19876.92,"batb":[[0,5,31.55]],"trd":[[5,1097.11]],"ltp":5,"id":50466254}],"tv":141376.81}],"ArrivalTime":1710508109609}
{"op":"mcm","id":2,"clk":"AK1kAKOLAQDfmAE=","pt":1710508109653,"mc":[{"id":"1.226122413","rc":[{"tv":10516.61,"batb":[[0,5.9,31.76]],"trd":[[5.9,36.55]],"ltp":5.9,"batl":[],"id":41122648},{"batb":[[0,300,3.07]],"batl":[[0,430,3.97]],"id":41200638},{"batb":[[1,40,13.01]],"id":49744721},{"tv":19880.92,"batb":[[0,5,29.55]],"trd":[[5,1101.11]],"batl":[],"id":50466254},{"batb":[[2,30,32.84]],"id":106596}],"tv":141390.81}],"ArrivalTime":1710508109661}
{"op":"mcm","id":2,"clk":"ALJkAK6LAQDnmAE=","pt":1710508109758,"mc":[{"id":"1.226122413","rc":[{"batb":[[1,5.8,73.74]],"batl":[[0,6.2,22.5]],"id":41122648},{"batl":[[0,430,4.27]],"id":41200638},{"batb":[[1,23,16.61],[0,24,13.29]],"id":55632148},{"batb":[[2,1.84,192.6],[1,1.85,200.24],[0,1.86,45.67]],"batl":[],"id":51922}]}],"ArrivalTime":1710508109765}
{"op":"mcm","id":2,"clk":"AL5kALSLAQDymAE=","pt":1710508109866,"mc":[{"id":"1.226122413","rc":[{"batb":[[1,1.85,257.24]],"id":51922},{"batb":[[0,5,37.31]],"batl":[],"id":50466254}]}],"ArrivalTime":1710508109874}
{"op":"mcm","id":2,"clk":"AMZkALqLAQD2mAE=","pt":1710508109962,"mc":[{"id":"1.226122413","rc":[{"batb":[[2,290,3],[1,300,2.69],[0,310,2.38]],"id":41200638},{"batb":[[1,4.9,71.61]],"id":50466254}]}],"ArrivalTime":1710508109970}
{"op":"mcm","id":2,"clk":"ANBkAMaLAQCFmQE=","pt":1710508110071,"mc":[{"id":"1.226122413","rc":[{"tv":101680,"batb":[[0,1.86,43.67]],"trd":[[1.86,10596.45]],"ltp":1.86,"id":51922}],"tv":141394.81}],"ArrivalTime":1710508110079}
{"op":"mcm","id":2,"clk":"ANpkAMqLAQCJmQE=","pt":1710508110173,"mc":[{"id":"1.226122413","rc":[{"tv":2482.69,"batb":[[0,24,12.29]],"trd":[[24,247.59]],"ltp":24,"id":55632148}],"tv":141396.81}],"ArrivalTime":1710508110181}
{"op":"mcm","id":2,"clk":"AN9kANmLAQCXmQE=","pt":1710508110283,"mc":[{"id":"1.226122413","rc":[{"batb":[[1,300,2.59]],"id":41200638},{"batb":[[1,4.9,63.77]],"id":50466254}]}],"ArrivalTime":1710508110290}
{"op":"mcm","id":2,"clk":"AOhkAOeLAQCjmQE=","pt":1710508110388,"mc":[{"id":"1.226122413","rc":[{"tv":10518.61,"batb":[[0,5.9,30.76]],"trd":[[5.9,38.55]],"id":41122648},{"tv":101690,"batb":[[0,1.86,38.67]],"trd":[[1.86,10606.45]],"id":51922}],"tv":141408.81}],"ArrivalTime":1710508110395}
{"op":"mcm","id":2,"clk":"AO1kAPCLAQCwmQE=","pt":1710508110489,"mc":[{"id":"1.226122413","rc":[{"batb":[[1,360,1.36]],"id":54370634},{"batb":[[2,280,7.71],[1,290,3.36],[0,310,2.8]],"batl":[[2,650,1],[1,550,1.05]],"id":41200638}]}],"ArrivalTime":1710508110496}
{"op":"mcm","id":2,"clk":"APZkAPqLAQC8mQE=","pt":1710508110592,"mc":[{"id":"1.226122413","rc":[{"batb":[[0,370,2.14]],"id":54370634},{"tv":10532.67,"batb":[[0,5.9,63.33]],"trd":[[6.2,384.18]],"ltp":6.2,"batl":[[0,6.2,15.47]],"id":41122648},{"tv":2487.69,"batb":[[0,24,9.78]],"trd":[[24,252.59]],"id":55632148},{"tv":101691.4,"batb":[[2,1.84,191.6]],"trd":[[1.87,8931.27]],"ltp":1.87,"batl":[[0,1.87,89.1]],"id":51922}],"tv":141429.27}],"ArrivalTime":1710508110600}
{"op":"mcm","id":2,"clk":"APxkAIWMAQDKmQE=","pt":1710508110697,"mc":[{"id":"1.226122413","rc":[{"batb":[[0,5.9,73.85]],"id":41122648},{"tv":2502.69,"trd":[[26,413.55]],"ltp":26,"batl":[[2,28,9.5],[0,26,1.08]],"id":55632148},{"batl":[[0,1.87,59.17]],"id":51922}],"tv":141444.27}],"ArrivalTime":1710508110705}
{"op":"mcm","id":2,"clk":"AIBlAI+MAQDSmQE=","pt":1710508110799,"mc":[{"id":"1.226122413","rc":[{"batl":[[2,27,4.12],[1,26,1.08],[0,25,2.04]],"id":55632148},{"tv":101699.4,"batb":[[2,1.84,184.77],[1,1.85,262.26],[0,1.86,34.67]],"trd":[[1.86,10614.45]],"ltp":1.86,"id":51922}],"tv":141452.27}],"ArrivalTime":1710508110806}
{"op":"mcm","id":2,"clk":"AIdlAJeMAQDgmQE=","pt":1710508110902,"mc":[{"id":"1.226122413","rc":[{"batl":[[2,6.6,61.27]],"id":41122648},{"batb":[[0,24,20.23]],"id":55632148},{"batb":[[0,1.86,122.07]],"batl":[[0,1.87,82.57]],"id":51922},{"batb":[[2,30,37.26]],"id":106596}]}],"ArrivalTime":1710508110909}
{"op":"mcm","id":2,"clk":"AI5lAKSMAQDsmQE=","pt":1710508111005,"mc":[{"id":"1.226122413","rc":[{"batb":[[2,5.7,59.19]],"id":41122648},{"batb":[[2,290,3.36],[1,310,2],[0,320,2.99]],"id":41200638},{"tv":2506.77,"batb":[[2,23,16.61],[1,24,20.23],[0,25,1.02]],"trd":[[25,437.89]],"ltp":25,"batl":[[2,28,9.5],[1,27,4.12],[0,26,2.9]],"id":55632148},{"batl":[[0,1.87,103.77]],"id":51922},{"batb":[[0,42,11.08]],"id":49744721},{"batb":[[0,180,7.44]],"id":66251581}],"tv":141456.35}],"ArrivalTime":1710508111012}
{"op":"mcm","id":2,"clk":"AJBlAKyMAQD3mQE=","pt":1710508111059,"mc":[{"id":"1.226122413","rc":[{"tv":2511.77,"batb":[[2,22,19.44],[1,23,16.61],[0,24,18.75]],"trd":[[25,439.93],[24,255.55]],"ltp":24,"id":55632148},{"tv":19900.92,"trd":[[5.1,960.61]],"ltp":5.1,"batl":[[0,5.1,9.51]],"id":50466254}],"tv":141481.35}],"ArrivalTime":1710508111066}
{"op":"mcm","id":2,"clk":"AJhlALeMAQCDmgE=","pt":1710508111168,"mc":[{"id":"1.226122413","rc":[{"batb":[[2,5.7,61.09]],"id":41122648},{"batl":[[2,1.89,94.13]],"id":51922},{"batl":[[0,210,5.96]],"id":66251581}]}],"ArrivalTime":1710508111175}
{"op":"mcm","id":2,"clk":"AJ9lAL+MAQCImgE=","pt":1710508111268,"mc":[{"id":"1.226122413","rc":[{"batb":[[0,1.86,128.9]],"batl":[[2,1.89,91.14]],"id":51922}]}],"ArrivalTime":1710508111275}
{"op":"mcm","id":2,"clk":"AKdlAMqMAQCRmgE=","pt":1710508111382,"mc":[{"id":"1.226122413","rc":[{"batb":[[1,5.8,81.3]],"batl":[[2,6.4,51.79],[1,6.2,15.47],[0,6,2]],"id":41122648},{"batl":[[0,430,1.45]],"id":41200638},{"batb":[[1,40,16.01]],"id":49744721}]}],"ArrivalTime":1710508111391}
{"op":"mcm","id":2,"clk":"AKtlANCMAQCbmgE=","pt":1710508111483,"mc":[{"id":"1.226122413","rc":[{"tv":10536.07,"batb":[[1,5.8,90.68],[0,5.9,75.61]],"trd":[[6,501.77]],"ltp":6,"batl":[[2,6.6,61.27],[1,6.4,51.79],[0,6.2,15.77]],"id":41122648},{"batb":[[2,290,3.67],[0,320,5.77]],"batl":[[2,650,1.52],[1,490,3.35]],"id":41200638},{"tv":101851.41,"batb":[[0,1.86,62.89]],"trd":[[1.87,8951.27],[1.86,10746.46]],"batl":[[0,1.87,93.77]],"id":51922},{"tv":2865.84,"trd":[[48,23.18]],"ltp":48,"batl":[[0,48,1.88]],"id":49744721},{"tv":19919.94,"trd":[[5.1,979.63]],"batl":[[2,5.4,128.27],[1,5.3,59.92],[0,5.2,66.04]],"id":50466254}],"tv":141658.86}],"ArrivalTime":1710508111491}
{"op":"mcm","id":2,"clk":"ALVlANmMAQCkmgE=","pt":1710508111582,"mc":[{"id":"1.226122413","rc":[{"tv":10580.07,"batb":[[2,5.8,88.85],[1,5.9,73.85],[0,6,16.24]],"trd":[[6,502.37],[6.2,415.12],[6.4,217.25]],"ltp":6.4,"batl":[[2,6.8,71.37],[1,6.6,61.27],[0,6.4,45.56]],"id":41122648},{"batl":[[0,1.87,70.37]],"id":51922},{"batb":[[2,40,16.01],[1,42,11.08],[0,44,1.66]],"batl":[[0,48,1.77]],"id":49744721}],"tv":141702.86}],"ArrivalTime":1710508111589}
{"op":"mcm","id":2,"clk":"AMFlAOCMAQCumgE=","pt":1710508111709,"mc":[{"id":"1.226122413","rc":[{"tv":404.71,"batb":[[0,370,1.28]],"trd":[[380,5.81],[370,10.78]],"ltp":370,"id":54370634},{"tv":10592.61,"batb":[[1,5.9,71.9],[0,6,9.97]],"trd":[[6,514.91]],"ltp":6,"id":41122648},{"tv":520.58,"batb":[[0,320,4.91]],"trd":[[370,11.58],[340,8.08],[320,14.83]],"ltp":320,"id":41200638},{"batl":[[1,27,4.97]],"id":55632148},{"batb":[[2,1.84,175.27],[0,1.86,117.97]],"batl":[[2,1.89,94.13],[1,1.88,309.66]],"id":51922},{"batl":[[2,5.3,101.12],[1,5.2,66.04],[0,5.1,12.17]],"id":50466254},{"tv":591.09,"batb":[[0,180,6.59]],"trd":[[190,9.39],[180,13.62]],"ltp":180,"id":66251581},{"tv":2464.27,"batb":[[0,34,6.09]],"trd":[[34,101.36]],"ltp":34,"batl":[[0,38,2.03]],"id":106596}],"tv":141722.22}],"ArrivalTime":1710508111716}
{"op":"mcm","id":2,"clk":"AMZlAOiMAQC3mgE=","pt":1710508111796,"mc":[{"id":"1.226122413","rc":[{"batb":[[1,5.9,45.98],[0,6,47.79]],"id":41122648},{"batb":[[2,280,7.38],[1,310,1]],"id":41200638},{"batb":[[0,1.86,132.49]],"batl":[[0,1.87,131.91]],"id":51922},{"batb":[[0,44,4.27]],"batl":[[2,60,21.3],[1,55,8.78],[0,50,3.84]],"id":49744721},{"batb":[[0,5,25.15]],"id":50466254},{"batl":[[2,40,9.35],[1,38,2.03],[0,36,2.01]],"id":106596}]}],"ArrivalTime":1710508111803}
{"op":"mcm","id":2,"clk":"AMllAPCMAQDAmgE=","pt":1710508111899,"mc":[{"id":"1.226122413","rc":[{"tv":10616.21,"batb":[[2,5.9,45.98],[1,6,37.82],[0,6.2,62.22]],"trd":[[6,534.85],[6.2,418.78]],"ltp":6.2,"id":41122648},{"batb":[[2,1.84,184.66]],"batl":[[1,1.88,306.62],[0,1.87,177.12]],"id":51922},{"tv":19921.16,"batb":[[0,5,24.54]],"trd":[[5,1102.33]],"ltp":5,"batl":[[0,5.1,30.94]],"id":50466254},{"batl":[[2,260,1.55],[1,210,5.96],[0,200,1.09]],"id":66251581},{"batb":[[0,34,7.51]],"id":106596}],"tv":141747.04}],"ArrivalTime":1710508111906}
{"op":"mcm","id":2,"clk":"ANBlAP2MAQDKmgE=","pt":1710508111995,"mc":[{"id":"1.226122413","rc":[{"tv":408.71,"trd":[[470,4]],"ltp":470,"batl":[[2,750,2.21],[1,520,1.31],[0,510,3.29]],"id":54370634},{"tv":10625.03,"batb":[[1,6,46.82],[0,6.2,57.81]],"trd":[[6.2,427.6]],"batl":[[0,6.4,46.86]],"id":41122648},{"batb":[[1,42,15.35]],"batl":[[0,50,1.75]],"id":49744721},{"tv":19970.24,"batb":[[2,4.7,112.58],[1,4.8,75.66],[0,4.9,63.77]],"trd":[[5,1151.41]],"id":50466254},{"tv":2478.35,"batb":[[2,29,42.57],[1,30,37.26],[0,32,17.03]],"trd":[[34,115.44]],"batl":[[1,38,5.11],[0,36,2.86]],"id":106596}],"tv":141823.02}],"ArrivalTime":1710508112002}
{"op":"mcm","id":2,"clk":"ANdlAIaNAQDTmgE=","pt":1710508112105,"mc":[{"id":"1.226122413","rc":[{"tv":409.65,"trd":[[500,0.68],[480,0.9]],"ltp":500,"batl":[[0,510,2.82]],"id":54370634},{"tv":101904.39,"batb":[[0,1.86,70.92]],"trd":[[1.86,10799.44]],"batl":[[1,1.88,309.66],[0,1.87,180.21]],"id":51922},{"batb":[[2,4.7,109.64]],"batl":[[0,5.1,43.72]],"id":50466254}],"tv":141876.94}],"ArrivalTime":1710508112113}
{"op":"mcm","id":2,"clk":"AOFlAI6NAQDdmgE=","pt":1710508112208,"mc":[{"id":"1.226122413","rc":[{"batb":[[0,370,1.07]],"id":54370634},{"batb":[],"batl":[[2,6.8,77.28]],"id":41122648},{"tv":101926.19,"batb":[[0,1.86,62.92]],"trd":[[1.87,8957.07],[1.86,10815.44]],"batl":[[0,1.87,177.31]],"id":51922},{"batl":[[2,65,5.65],[1,60,21.3],[0,55,8.78]],"id":49744721},{"tv":592.81,"trd":[[200,18.4]],"ltp":200,"batl":[[2,280,1.62],[1,260,1.55],[0,210,6.19]],"id":66251581},{"tv":2479.29,"batb":[[0,32,16.56]],"trd":[[34,116.38]],"batl":[[2,40,8.67],[1,38,4.35],[0,36,2.01]],"id":106596}],"tv":141901.4}],"ArrivalTime":1710508112216}
{"op":"mcm","id":2,"clk":"AOJlAJSNAQDmmgE=","pt":1710508112308,"mc":[{"id":"1.226122413","rc":[{"tv":10633.99,"batb":[[0,6.2,55.82]],"trd":[[6.2,431.6],[6.4,222.21]],"batl":[[0,6.4,44.38]],"id":41122648},{"batb":[[0,320,2.13]],"id":41200638},{"tv":101932.49,"batb":[[0,1.86,104.9]],"trd":[[1.86,10821.74]],"batl":[[1,1.88,306.62],[0,1.87,174.22]],"id":51922},{"batl":[[2,5.3,121.71]],"id":50466254}],"tv":141916.66}],"ArrivalTime":1710508112315}
{"op":"mcm","id":2,"clk":"AOplAJmNAQDwmgE=","pt":1710508112417,"mc":[{"id":"1.226122413","rc":[{"tv":10649.46,"batb":[[0,6.2,48.08]],"trd":[[6.2,447.07]],"id":41122648},{"tv":101953.05,"batb":[[0,1.86,94.62]],"trd":[[1.86,10842.3]],"id":51922},{"batb":[[2,42,15.35],[1,44,4.27],[0,46,1.6]],"batl":[[0,55,13.15]],"id":49744721},{"batb":[[0,180,7.02]],"id":66251581},{"batb":[[1,30,32.84],[0,32,17.17]],"id":106596}],"tv":141952.69}],"ArrivalTime":1710508112425}
{"op":"mcm","id":2,"clk":"AO1lAKGNAQD7mgE=","pt":1710508112469,"mc":[{"id":"1.226122413","rc":[{"batb":[[0,320,4.13]],"id":41200638},{"batl":[[1,1.88,309.66]],"id":51922},{"batb":[[1,4.8,67.82],[0,4.9,69.49]],"id":50466254}]}],"ArrivalTime":1710508112477}
{"op":"mcm","id":2,"clk":"APdlAKiNAQCEmwE=","pt":1710508112580,"mc":[{"id":"1.226122413","rc":[{"batl":[[2,520,1.31],[1,510,2.82],[0,500,2.56]],"id":54370634},{"tv":10686.46,"batb":[[0,6.2,29.58]],"trd":[[6.2,484.07]],"id":41122648},{"tv":2534.25,"batb":[[0,24,7.5]],"trd":[[24,278.03]],"batl":[[2,29,7.69],[1,28,9.5],[0,27,4.97]],"id":55632148},{"tv":101972.27,"batb":[[0,1.86,85.01]],"trd":[[1.86,10861.52]],"id":51922},{"batb":[[0,46,4.21]],"batl":[[0,55,15.15]],"id":49744721},{"batb":[[2,160,6.81]],"id":66251581},{"batb":[[0,32,12.59]],"id":106596}],"tv":142031.39}],"ArrivalTime":1710508112588}
{"op":"mcm","id":2,"clk":"APllALWNAQCPmwE=","pt":1710508112673,"mc":[{"id":"1.226122413","rc":[{"tv":10698.36,"batb":[[0,6.2,23.63]],"trd":[[6.2,495.97]],"id":41122648},{"batb":[[0,4.9,47.87]],"id":50466254}],"tv":142043.29}],"ArrivalTime":1710508112681}
{"op":"mcm","id":2,"clk":"AIVmAL2NAQCdmwE=","pt":1710508112831,"mc":[{"id":"1.226122413","rc":[{"batb":[[0,24,3.98]],"batl":[[2,28,9.5],[1,27,4.97],[0,26,10.28]],"id":55632148},{"tv":102004.27,"batb":[[0,1.86,169.01]],"trd":[[1.86,10893.52]],"id":51922}],"tv":142075.29}],"ArrivalTime":1710508112839}
{"op":"mcm","id":2,"clk":"AIlmAMGNAQCnmwE=","pt":1710508112881,"mc":[{"id":"1.226122413","rc":[{"batb":[[2,44,4.27],[1,46,4.21],[0,48,1.66]],"id":49744721},{"batl":[[2,5.3,150.34]],"id":50466254},{"tv":2480.51,"batb":[[0,32,11.98]],"trd":[[34,117.6]],"id":106596}],"tv":142076.51}],"ArrivalTime":1710508112888}
{"op":"mcm","id":2,"clk":"AI5mAMuNAQC0mwE=","pt":1710508113023,"mc":[{"id":"1.226122413","rc":[{"batb":[[2,21,86.06],[1,22,19.44],[0,23,13.39]],"id":55632148},{"tv":102020.27,"batb":[[0,1.86,161.01]],"trd":[[1.86,10909.52]],"id":51922},{"batb":[[1,4.8,46.47]],"batl":[[2,5.3,119.45]],"id":50466254},{"batb":[[2,29,50.64]],"id":106596}],"tv":142092.51}],"ArrivalTime":1710508113031}
{"op":"mcm","id":2,"clk":"AJVmAM6NAQDCmwE=","pt":1710508113102,"mc":[{"id":"1.226122413","rc":[{"batb":[],"batl":[[2,65,6.31],[1,60,22.08],[0,55,16.64]],"id":49744721},{"batl":[[2,5.3,90.82]],"id":50466254},{"batb":[[2,160,7.84]],"id":66251581}]}],"ArrivalTime":1710508113110}
{"op":"mcm","id":2,"clk":"AJpmANiNAQDSmwE=","pt":1710508113193,"mc":[{"id":"1.226122413","rc":[{"batl":[[0,6.4,44.9]],"id":41122648},{"batb":[[1,22,23.16]],"batl":[[2,27,4.97],[1,26,10.28],[0,25,3.05]],"id":55632148},{"tv":102036.27,"batb":[[0,1.86,153.01]],"trd":[[1.86,10925.52]],"batl":[[1,1.88,306.62],[0,1.87,153.02]],"id":51922}],"tv":142108.51}],"ArrivalTime":1710508113201}
{"op":"mcm","id":2,"clk":"AJ1mAOCNAQDbmwE=","pt":1710508113303,"mc":[{"id":"1.226122413","rc":[{"tv":521.18,"trd":[[420,0.6]],"ltp":420,"batl":[[0,430,1.15]],"id":41200638},{"batb":[[0,23,9.69]],"id":55632148},{"tv":102078.67,"batb":[[0,1.86,131.81]],"trd":[[1.86,10967.92]],"id":51922},{"batb":[[2,42,8.99],[1,44,4.27],[0,46,4.21]],"id":49744721},{"batl":[[2,5.3,59.92]],"id":50466254}],"tv":142151.51}],"ArrivalTime":1710508113311}
{"op":"mcm","id":2,"clk":"AKhmAOuNAQDgmwE=","pt":1710508113402,"mc":[{"id":"1.226122413","rc":[{"tv":2538.25,"batb":[],"trd":[[25,443.93]],"ltp":25,"batl":[[1,26,5.22],[0,25,1.05]],"id":55632148},{"tv":102090.67,"batb":[[2,1.84,175.66],[0,1.86,125.81]],"trd":[[1.86,10979.92]],"id":51922},{"batb":[[1,30,25.15]],"batl":[[2,40,10.49]],"id":106596}],"tv":142167.51}],"ArrivalTime":1710508113409}
{"op":"mcm","id":2,"clk":"ALRmAPONAQDqmwE=","pt":1710508113520,"mc":[{"id":"1.226122413","rc":[{"tv":102108.67,"batb":[[2,1.84,177.66]],"trd":[[1.87,8975.07]],"ltp":1.87,"batl":[[0,1.87,144.02]],"id":51922},{"tv":2866.96,"trd":[[50,1.12]],"ltp":50,"batl":[[2,65,5.65],[1,60,21.3],[0,55,15.15]],"id":49744721}],"tv":142186.63}],"ArrivalTime":1710508113527}
{"op":"mcm","id":2,"clk":"ALhmAP2NAQDwmwE=","pt":1710508113609,"mc":[{"id":"1.226122413","rc":[{"batl":[[2,750,2.43],[1,520,1.31],[0,510,2.82]],"id":54370634},{"batl":[[2,6.8,83.2]],"id":41122648},{"batb":[[0,23,12.25]],"batl":[[1,26,2.95],[0,25,2.9]],"id":55632148},{"batb":[],"batl":[[0,1.87,152.02]],"id":51922},{"batb":[[1,44,8.54]],"id":49744721},{"batl":[[2,40,11.53]],"id":106596}]}],"ArrivalTime":1710508113616}
{"op":"mcm","id":2,"clk":"AL1mAIyOAQD7mwE=","pt":1710508113718,"mc":[{"id":"1.226122413","rc":[{"tv":10711,"batb":[[0,6.2,17.31]],"trd":[[6.2,508.61]],"id":41122648},{"batb":[[0,1.86,129.81]],"batl":[[0,1.87,168.02]],"id":51922},{"batb":[[2,30,25.15],[1,32,11.98],[0,34,1]],"id":106596}],"tv":142199.27}],"ArrivalTime":1710508113725}
{"op":"mcm","id":2,"clk":"AMlmAJeOAQCEnAE=","pt":1710508113764,"mc":[{"id":"1.226122413","rc":[{"batb":[],"batl":[[0,1.87,176.02]],"id":51922},{"batb":[[2,44,8.54],[1,46,4.21],[0,48,1.68]],"id":49744721}]}],"ArrivalTime":1710508113772}
{"op":"mcm","id":2,"clk":"ANNmAKWOAQCSnAE=","pt":1710508113926,"mc":[{"id":"1.226122413","rc":[{"tv":10716.42,"batb":[[0,6.2,14.6]],"trd":[[6.2,514.03]],"batl":[[2,6.8,46.73]],"id":41122648},{"batb":[[1,1.85,264.61]],"batl":[[1,1.88,309.66]],"id":51922},{"batl":[[1,5.2,107.73]],"id":50466254},{"tv":2482.41,"batb":[[2,29,58.71],[1,30,25.15],[0,32,12.03]],"trd":[[34,119.5]],"batl":[[2,40,13.24],[1,38,5.11],[0,36,2.86]],"id":106596}],"tv":142206.59}],"ArrivalTime":1710508113933}
{"op":"mcm","id":2,"clk":"ANZmALCOAQCYnAE=","pt":1710508113975,"mc":[{"id":"1.226122413","rc":[{"batb":[[2,310,1],[1,320,4.13],[0,340,1]],"id":41200638},{"batl":[[0,1.87,184.02]],"id":51922},{"batb":[[2,160,8.87]],"id":66251581}]}],"ArrivalTime":1710508113982}
{"op":"mcm","id":2,"clk":"ANxmALuOAQChnAE=","pt":1710508114083,"mc":[{"id":"1.226122413","rc":[{"batl":[[2,520,1.31],[1,510,2.82],[0,500,2.56]],"id":54370634},{"tv":102465.07,"trd":[[1.87,9331.47]],"batl":[[1,1.88,306.62],[0,1.87,5.82]],"id":51922},{"batl":[[2,65,6.31]],"id":49744721},{"tv":2482.51,"batb":[[0,32,11.98]],"trd":[[34,119.6]],"batl":[[2,38,4.35],[1,36,2.01],[0,34,2.52]],"id":106596}],"tv":142563.09}],"ArrivalTime":1710508114091}
{"op":"mcm","id":2,"clk":"AONmAMOOAQCqnAE=","pt":1710508114183,"mc":[{"id":"1.226122413","rc":[{"batl":[[2,28,9.5],[1,27,4.97],[0,26,2.95]],"id":55632148},{"batl":[[0,1.87,13.82]],"id":51922},{"batl":[[2,65,5.65]],"id":49744721},{"batl":[[2,270,2.82]],"id":66251581},{"batl":[[2,40,12.56],[1,38,4.35],[0,36,2.01]],"id":106596}]}],"ArrivalTime":1710508114191}
{"op":"mcm","id":2,"clk":"AO5mAM+OAQC2nAE=","pt":1710508114288,"mc":[{"id":"1.226122413","rc":[{"tv":10753.46,"batb":[],"trd":[[6.4,259.25]],"ltp":6.4,"batl":[[0,6.4,26.37]],"id":41122648},{"batb":[[1,22,24.16]],"id":55632148},{"tv":102492.71,"batb":[[2,1.85,264.61],[1,1.86,152.86],[0,1.87,113.82]],"trd":[[1.87,9359.11]],"batl":[[2,1.9,106.23],[1,1.89,94.13],[0,1.88,306.62]],"id":51922}],"tv":142627.77}],"ArrivalTime":1710508114295}
{"op":"mcm","id":2,"clk":"APNmAN6OAQDEnAE=","pt":1710508114397,"mc":[{"id":"1.226122413","rc":[{"tv":10782.66,"batb":[[2,5.8,115.11],[1,5.9,45.98],[0,6,46.82]],"trd":[[6.2,543.23]],"ltp":6.2,"batl":[[2,6.6,61.27],[1,6.4,26.37],[0,6.2,6.61]],"id":41122648},{"batb":[[0,340,2]],"id":41200638},{"tv":102524.71,"batb":[[0,1.87,97.82]],"trd":[[1.87,9391.11]],"batl":[[0,1.88,261.99]],"id":51922},{"batl":[[2,65,6.31],[1,60,26.84]],"id":49744721},{"batb":[],"batl":[[2,5.2,107.73],[1,5.1,43.72],[0,5,18.78]],"id":50466254}],"tv":142688.97}],"ArrivalTime":1710508114404}
{"op":"mcm","id":2,"clk":"APpmAOSOAQDOnAE=","pt":1710508114498,"mc":[{"id":"1.226122413","rc":[{"tv":414.51,"batb":[[2,310,1.27],[1,320,1.61],[0,350,1.31]],"trd":[[370,12.92],[360,27.38]],"ltp":360,"batl":[[2,510,2.82],[1,500,2.56],[0,360,7.57]],"id":54370634},{"tv":10785.98,"batb":[[0,6,45.16]],"trd":[[6,538.17]],"ltp":6,"batl":[[1,6.4,27.85]],"id":41122648},{"batb":[[2,320,4.13],[1,330,1.61]],"id":41200638},{"batb":[[2,21,89.06],[1,22,21.16],[0,23,11.4]],"id":55632148},{"batb":[[0,4.9,33.87]],"id":50466254}],"tv":142697.15}],"ArrivalTime":1710508114507}
{"op":"mcm","id":2,"clk":"AP1mAPKOAQDUnAE=","pt":1710508114599,"mc":[{"id":"1.226122413","rc":[{"tv":416.51,"trd":[[360,29.38]],"batl":[[0,360,6.57]],"id":54370634},{"batb":[[2,5.8,116.94]],"batl":[[1,6.4,40.5],[0,6.2,33.96]],"id":41122648},{"batb":[[2,320,2.1]],"id":41200638},{"tv":102528.71,"batb":[[0,1.87,95.82]],"trd":[[1.87,9395.11]],"batl":[[1,1.89,91.14],[0,1.88,240.43]],"id":51922},{"batl":[[1,60,21.3]],"id":49744721},{"batb":[[1,4.8,30.3]],"batl":[],"id":50466254}],"tv":142703.15}],"ArrivalTime":1710508114607}
{"op":"mcm","id":2,"clk":"AIdnAP2OAQDfnAE=","pt":1710508114698,"mc":[{"id":"1.226122413","rc":[{"batb":[[2,310,1.2],[1,340,2.27],[0,350,3.02]],"id":54370634},{"tv":10797.18,"batb":[],"trd":[[6.2,554.43]],"ltp":6.2,"batl":[[0,6.2,21.75]],"id":41122648},{"batb":[[2,320,2]],"id":41200638},{"batb":[],"batl":[[0,1.88,248.43]],"id":51922},{"batl":[[0,55,12.01]],"id":49744721}],"tv":142714.35}],"ArrivalTime":1710508114706}
{"op":"mcm","id":2,"clk":"AJBnAISPAQDvnAE=","pt":1710508114805,"mc":[{"id":"1.226122413","rc":[{"batl":[[2,28,8.3]],"id":55632148},{"batb":[[1,1.86,211.86],[0,1.87,118.57]],"id":51922},{"tv":2868.38,"batb":[[2,42,8.99],[1,44,8.54],[0,46,5.18]],"trd":[[48,24.6]],"ltp":48,"id":49744721},{"batb":[[2,30,25.15],[1,32,11.98],[0,34,2.61]],"id":106596}],"tv":142715.77}],"ArrivalTime":1710508114813}
{"op":"mcm","id":2,"clk":"AJNnAI2PAQD5nAE=","pt":1710508114908,"mc":[{"id":"1.226122413","rc":[{"tv":423.01,"trd":[[360,35.88]],"batl":[[0,360,3.32]],"id":54370634},{"tv":2554.25,"trd":[[28,367.62],[27,384.42],[26,419.45]],"ltp":28,"batl":[[2,30,11.47],[1,29,12.76],[0,28,8.22]],"id":55632148},{"batl":[[0,1.88,256.43]],"id":51922},{"tv":19986.92,"batb":[[0,4.9,25.53]],"trd":[[4.9,343.7]],"ltp":4.9,"id":50466254}],"tv":142754.95}],"ArrivalTime":1710508114915}
{"op":"mcm","id":2,"clk":"AJdnAJaPAQCDnQE=","pt":1710508115010,"mc":[{"id":"1.226122413","rc":[{"batb":[[2,280,7.67],[0,340,3.83]],"id":41200638},{"tv":2870.32,"batb":[[0,46,4.21]],"trd":[[48,26.54]],"batl":[[2,65,5.65]],"id":49744721},{"batb":[],"batl":[[2,40,13.24],[1,38,5.11]],"id":106596}],"tv":142756.89}],"ArrivalTime":1710508115017}
{"op":"mcm","id":2,"clk":"AKFnAKGPAQCTnQE=","pt":1710508115122,"mc":[{"id":"1.226122413","rc":[{"tv":429.51,"trd":[[360,42.38]],"batl":[[2,750,2.43],[1,520,1.31],[0,510,2.89]],"id":54370634},{"batb":[[1,5.9,47.74]],"id":41122648},{"batb":[[2,330,1.61],[1,340,3.83],[0,350,1.86]],"id":41200638},{"batb":[[2,22,21.16],[1,23,11.4],[0,24,7.5]],"batl":[[2,29,12.76],[1,28,8.22],[0,27,2.73]],"id":55632148},{"batb":[[0,1.87,128.77]],"batl":[[0,1.88,357.82]],"id":51922},{"batb":[[0,4.9,28.69]],"id":50466254}],"tv":142763.39}],"ArrivalTime":1710508115129}
{"op":"mcm","id":2,"clk":"AKNnAK2PAQCZnQE=","pt":1710508115165,"mc":[{"id":"1.226122413","rc":[{"tv":10832.9,"trd":[[6.2,590.15]],"batl":[[0,6.2,3.89]],"id":41122648},{"batb":[[2,1.85,274]],"id":51922}],"tv":142799.11}],"ArrivalTime":1710508115172}
{"op":"mcm","id":2,"clk":"AKtnALqPAQCjnQE=","pt":1710508115329,"mc":[{"id":"1.226122413","rc":[{"tv":429.65,"trd":[[360,42.52]],"batl":[[0,510,2.82]],"id":54370634},{"batb":[[2,23,11.4],[1,24,7.5],[0,25,3.27]],"id":55632148},{"batl":[[0,1.88,359.82]],"id":51922},{"tv":20040.91,"batb":[[2,4.7,112.58],[0,4.9,1.7]],"trd":[[4.9,397.69]],"batl":[[0,5,31.11]],"id":50466254}],"tv":142853.24}],"ArrivalTime":1710508115337}
{"op":"mcm","id":2,"clk":"AK5nAMOPAQCrnQE=","pt":1710508115428,"mc":[{"id":"1.226122413","rc":[{"batb":[[1,340,1.87]],"batl":[[2,750,1.91],[1,520,1],[0,510,3.02]],"id":54370634},{"batb":[[0,350,1.95]],"id":41200638},{"batb":[[0,46,8.24]],"id":49744721},{"tv":20044.31,"batb":[[2,4.6,150.47],[1,4.7,112.58],[0,4.8,30.3]],"trd":[[4.9,401.09]],"batl":[[2,5.2,97.31],[0,5,32.11]],"id":50466254}],"tv":142856.64}],"ArrivalTime":1710508115435}
{"op":"mcm","id":2,"clk":"ALNnAM+PAQC3nQE=","pt":1710508115483,"mc":[{"id":"1.226122413","rc":[{"tv":10840.68,"batb":[[2,5.9,47.74],[1,6,45.16],[0,6.2,5.61]],"trd":[[6.2,597.93]],"batl":[[2,6.8,43.77],[1,6.6,61.27],[0,6.4,40.5]],"id":41122648},{"batl":[[1,1.89,94.13]],"id":51922},{"batb":[[2,4.6,147.38],[1,4.7,109.64]],"batl":[[2,5.1,44.26],[1,5,32.11],[0,4.9,27.77]],"id":50466254}],"tv":142864.42}],"ArrivalTime":1710508115490}
{"op":"mcm","id":2,"clk":"ALRnANaPAQDCnQE=","pt":1710508115579,"mc":[{"id":"1.226122413","rc":[{"batb":[[2,5.9,45.98]],"batl":[[0,6.4,20.5]],"id":41122648},{"batl":[[2,1.9,103.29]],"id":51922},{"batb":[],"batl":[[1,5,34.11]],"id":50466254},{"tv":2484.85,"batb":[[0,34,1.44]],"trd":[[34,121.94]],"batl":[[1,38,4.35]],"id":106596}],"tv":142866.76}],"ArrivalTime":1710508115586}
{"op":"mcm","id":2,"clk":"AMFnAOCPAQDMnQE=","pt":1710508115702,"mc":[{"id":"1.226122413","rc":[{"batl":[[2,510,2.82],[1,500,2.56],[0,490,3.02]],"id":54370634},{"tv":10880.68,"batb":[[2,5.8,116.94],[1,5.9,45.98],[0,6,31.96]],"trd":[[6,566.95],[6.2,609.15]],"ltp":6,"id":41122648},{"batb":[[1,340,4.83]],"id":41200638},{"batb":[[2,23,14.4]],"id":55632148},{"batb":[[1,1.86,286.86]],"id":51922},{"batb":[[2,44,8.54],[1,46,8.24],[0,48,1.7]],"id":49744721},{"batb":[[2,4.6,150.47]],"batl":[[1,5,48.22]],"id":50466254},{"batb":[[2,29,42.57],[1,30,25.15],[0,32,11.98]],"batl":[[2,38,4.35],[1,36,2.01],[0,34,2.57]],"id":106596}],"tv":142906.76}],"ArrivalTime":1710508115709}
{"op":"mcm","id":2,"clk":"AMNnAOyPAQDXnQE=","pt":1710508115797,"mc":[{"id":"1.226122413","rc":[{"batb":[[0,25,6.22]],"id":55632148},{"tv":102537.81,"batb":[[0,1.87,124.22]],"trd":[[1.87,9404.21]],"batl":[[2,1.9,106.23]],"id":51922}],"tv":142915.86}],"ArrivalTime":1710508115805}
{"op":"mcm","id":2,"clk":"AMpnAPSPAQDinQE=","pt":1710508115911,"mc":[{"id":"1.226122413","rc":[{"tv":10944.6,"batb":[[2,5.7,74.34],[1,5.8,115.11],[0,5.9,45.98]],"trd":[[6,630.87]],"batl":[[2,6.6,61.27],[1,6.4,20.5],[0,6,118.04]],"id":41122648},{"batl":[[1,1.89,91.14]],"id":51922},{"tv":20086.07,"batb":[[2,4.6,147.38]],"trd":[[4.9,442.85]],"batl":[[2,5.1,54.26],[0,4.9,6.89]],"id":50466254}],"tv":143021.54}],"ArrivalTime":1710508115918}
{"op":"mcm","id":2,"clk":"ANJnAP2PAQDsnQE=","pt":1710508116011,"mc":[{"id":"1.226122413","rc":[{"batb":[[2,300,2.31],[1,310,1.2],[0,340,2.45]],"id":54370634},{"tv":10971.68,"trd":[[6,657.95]],"batl":[[0,6,104.5]],"id":41122648},{"batb":[[1,340,3],[0,350,3.73]],"id":41200638},{"batb":[[0,1.87,134.22]],"batl":[[2,1.9,103.29],[0,1.88,367.82]],"id":51922},{"tv":2874.32,"batb":[[2,42,8.99],[1,44,8.54],[0,46,7.94]],"trd":[[48,29.94],[46,35.46]],"ltp":46,"id":49744721},{"tv":20099.63,"batb":[[1,4.7,63.62]],"trd":[[4.9,456.41]],"batl":[[2,5.2,87.31],[1,5.1,54.26],[0,5,48.33]],"id":50466254},{"batl":[[2,40,12.56],[1,38,4.35],[0,36,2.01]],"id":106596}],"tv":143066.18}],"ArrivalTime":1710508116018}
{"op":"mcm","id":2,"clk":"ANVnAIeQAQDxnQE=","pt":1710508116111,"mc":[{"id":"1.226122413","rc":[{"tv":11180.68,"batb":[[2,5.8,116.94],[1,5.9,79.46],[0,6,2.61]],"trd":[[6,866.95]],"batl":[[0,6.2,12.95]],"id":41122648},{"batl":[[2,30,8.02],[1,29,12.76],[0,28,8.22]],"id":55632148},{"tv":102906.96,"batb":[[1,1.86,189.43]],"trd":[[1.88,11355.08]],"ltp":1.88,"batl":[[0,1.88,183.25]],"id":51922},{"batb":[[2,44,8.54],[1,46,7.94],[0,48,2.61]],"batl":[[0,55,10.01]],"id":49744721},{"batb":[[2,4.6,150.47]],"batl":[[0,5,48.22]],"id":50466254},{"batb":[[2,29,34.5],[0,32,15.14]],"id":106596}],"tv":143644.33}],"ArrivalTime":1710508116119}
{"op":"mcm","id":2,"clk":"ANxnAJCQAQD/nQE=","pt":1710508116241,"mc":[{"id":"1.226122413","rc":[{"batb":[[2,290,1.17],[1,300,3.26]],"batl":[[0,490,3.26]],"id":54370634},{"batb":[[0,25,9.22]],"id":55632148},{"tv":103328.24,"batb":[[0,1.87,108.48]],"trd":[[1.87,9455.69],[1.88,11724.88]],"batl":[[1,1.89,137.12],[0,1.88,6.35]],"id":51922},{"tv":2876.32,"batb":[[1,46,17.94],[0,48,1.61]],"trd":[[48,31.94]],"ltp":48,"batl":[],"id":49744721},{"batb":[[2,4.6,147.38]],"batl":[[2,5.2,62.31],[0,5,34.11]],"id":50466254},{"batb":[[2,30,25.15],[1,32,15.14],[0,34,2.61]],"id":106596}],"tv":144067.61}],"ArrivalTime":1710508116249}
{"op":"mcm","id":2,"clk":"AOFnAJiQAQCHngE=","pt":1710508116328,"mc":[{"id":"1.226122413","rc":[{"tv":430.05,"trd":[[440,4.4]],"ltp":440,"batl":[[0,490,3.06]],"id":54370634},{"tv":11195.09,"batb":[[2,5.8,115.11],[1,5.9,87.7],[0,6,29.5]],"trd":[[6.2,623.56]],"ltp":6.2,"batl":[[2,6.8,43.77],[1,6.6,61.27],[0,6.4,20.5]],"id":41122648},{"batl":[[1,29,14.76]],"id":55632148},{"tv":103340.94,"batb":[[2,1.86,189.43],[1,1.87,108.48],[0,1.88,32.46]],"trd":[[1.88,11737.58]],"batl":[[2,1.91,238.57],[1,1.9,103.29],[0,1.89,137.12]],"id":51922},{"batb":[[0,48,1.76]],"id":49744721},{"batb":[[1,4.7,42.28]],"id":50466254}],"tv":144095.12}],"ArrivalTime":1710508116336}
{"op":"mcm","id":2,"clk":"AOhnAKKQAQCRngE=","pt":1710508116424,"mc":[{"id":"1.226122413","rc":[{"tv":433.05,"trd":[[480,1.14],[490,2.51],[460,0.85]],"ltp":490,"batl":[[0,490,1.56]],"id":54370634},{"batb":[],"batl":[[2,6.6,61.27],[1,6.4,20.5],[0,6.2,10.51]],"id":41122648},{"tv":103449.38,"batb":[[2,1.85,274],[1,1.86,189.43],[0,1.87,159.9]],"trd":[[1.88,11846.02]],"batl":[[1,1.9,106.23],[0,1.89,102.77]],"id":51922},{"batl":[[0,5,48.13]],"id":50466254},{"tv":2486.75,"batb":[[0,34,1.66]],"trd":[[34,123.84]],"batl":[[1,38,5.11],[0,36,2.86]],"id":106596}],"tv":144208.46}],"ArrivalTime":1710508116431}
{"op":"mcm","id":2,"clk":"AO1nAK2QAQCcngE=","pt":1710508116539,"mc":[{"id":"1.226122413","rc":[{"batl":[[2,520,1]],"id":54370634},{"batb":[[0,6,48.95]],"id":41122648},{"batl":[[2,29,14.76],[1,28,8.22],[0,27,2.79]],"id":55632148},{"tv":103479.98,"batb":[[0,1.87,144.6]],"trd":[[1.87,9486.29]],"ltp":1.87,"id":51922},{"batb":[[0,48,4.37]],"id":49744721},{"batb":[],"batl":[[2,5.1,54.26],[1,5,48.13],[0,4.9,18.33]],"id":50466254},{"batb":[[2,29,34.5],[1,30,25.15],[0,32,15.14]],"id":106596}],"tv":144239.06}],"ArrivalTime":1710508116547}
{"op":"mcm","id":2,"clk":"AO5nALSQAQCjngE=","pt":1710508116580,"mc":[{"id":"1.226122413","rc":[{"batl":[[2,750,1.91],[1,520,1]],"id":54370634},{"tv":11216.11,"batb":[[0,6,49.92]],"trd":[[6.2,644.58]],"batl":[[2,6.8,43.77],[1,6.6,61.27],[0,6.4,20.5]],"id":41122648},{"tv":103483.74,"batb":[[0,1.87,142.72]],"trd":[[1.87,9490.05]],"batl":[[2,1.9,103.29],[1,1.89,125.26],[0,1.88,86.56]],"id":51922},{"batl":[[0,4.9,19.33]],"id":50466254},{"batl":[[2,40,13.24],[0,36,2.01]],"id":106596}],"tv":144263.84}],"ArrivalTime":1710508116588}
{"op":"mcm","id":2,"clk":"APdnAL6QAQCzngE=","pt":1710508116696,"mc":[{"id":"1.226122413","rc":[{"tv":20123.63,"batb":[[2,4.6,150.47],[0,4.8,18.3]],"trd":[[4.8,1015.31]],"ltp":4.8,"id":50466254},{"batl":[[1,38,4.35],[0,36,4.47]],"id":106596}],"tv":144287.84}],"ArrivalTime":1710508116704}
{"op":"mcm","id":2,"clk":"APlnAMaQAQC/ngE=","pt":1710508116794,"mc":[{"id":"1.226122413","rc":[{"batl":[[1,1.89,141.26],[0,1.88,102.56]],"id":51922},{"tv":20160.22,"batb":[[2,4.5,103.91],[1,4.6,150.47],[0,4.7,42.28]],"trd":[[4.8,1051.9]],"batl":[[2,5,48.13],[1,4.9,19.33],[0,4.8,36.12]],"id":50466254},{"batl":[[2,40,12.56]],"id":106596}],"tv":144324.43}],"ArrivalTime":1710508116802}
{"op":"mcm","id":2,"clk":"AINoANCQAQDNngE=","pt":1710508116901,"mc":[{"id":"1.226122413","rc":[{"batb":[[0,340,2.67]],"id":54370634},{"batl":[[1,1.89,149.26],[0,1.88,118.56]],"id":51922},{"batl":[[1,4.9,21.9]],"id":50466254}]}],"ArrivalTime":1710508116909}
{"op":"mcm","id":2,"clk":"AItoANyQAQDWngE=","pt":1710508117003,"mc":[{"id":"1.226122413","rc":[{"batb":[[2,320,1.34],[1,340,2.27],[0,350,1.19]],"batl":[[2,750,2.07]],"id":54370634},{"batb":[[2,5.8,137.47]],"id":41122648},{"tv":103567.74,"batb":[[2,1.86,189.43],[1,1.87,142.72],[0,1.88,27.9]],"trd":[[1.88,11930.02]],"ltp":1.88,"batl":[[2,1.91,235.67],[1,1.9,103.29],[0,1.89,157.26]],"id":51922},{"tv":20232.46,"batb":[[1,4.6,147.38]],"trd":[[4.8,1124.14]],"batl":[[1,4.9,36.13],[0,4.8,18.6]],"id":50466254}],"tv":144480.67}],"ArrivalTime":1710508117010}
{"op":"mcm","id":2,"clk":"AI5oAOOQAQDjngE=","pt":1710508117100,"mc":[{"id":"1.226122413","rc":[{"batb":[[2,340,2.27],[1,350,1.19],[0,370,2]],"id":54370634},{"tv":2878.32,"trd":[[55,2]],"ltp":55,"batl":[[0,55,9.01]],"id":49744721},{"tv":20236.28,"trd":[[4.8,1127.96]],"batl":[[2,5,48.29],[0,4.8,16.69]],"id":50466254},{"batb":[[2,30,25.15],[1,32,15.14],[0,34,2.61]],"id":106596}],"tv":144486.49}],"ArrivalTime":1710508117107}
{"op":"mcm","id":2,"clk":"AJVoAO+QAQDwngE=","pt":1710508117210,"mc":[{"id":"1.226122413","rc":[{"batl":[[2,520,1],[1,490,1.56],[0,480,2.56]],"id":54370634},{"batb":[[2,5.8,85.73]],"id":41122648},{"batb":[[2,1.86,249.1]],"batl":[[0,1.89,165.26]],"id":51922},{"batl":[[0,55,11.01]],"id":49744721}]}],"ArrivalTime":1710508117218}
{"op":"mcm","id":2,"clk":"AJxoAPqQAQD5ngE=","pt":1710508117311,"mc":[{"id":"1.226122413","rc":[{"batb":[[2,340,1.24],[1,360,2.22]],"id":54370634},{"batl":[[0,6.4,45.5]],"id":41122648},{"tv":2572.69,"batb":[[2,22,21.16],[1,23,14.4],[0,24,7.5]],"trd":[[25,462.37]],"ltp":25,"id":55632148},{"tv":103600.96,"batb":[[0,1.88,11.29]],"trd":[[1.88,11963.24]],"id":51922},{"batb":[[2,46,17.94],[1,48,4.37],[0,50,2.88]],"batl":[[2,65,6.31]],"id":49744721},{"tv":20261.88,"trd":[[4.8,1153.56]],"batl":[[0,4.8,3.89]],"id":50466254},{"tv":2491.9,"batb":[[2,29,34.5],[1,30,25.15],[0,32,15.14]],"trd":[[34,128.99]],"batl":[[2,40,13.24],[1,38,5.11]],"id":106596}],"tv":144568.9}],"ArrivalTime":1710508117319}
{"op":"mcm","id":2,"clk":"AJ5oAIGRAQCGnwE=","pt":1710508117421,"mc":[{"id":"1.226122413","rc":[{"batb":[[1,5.9,46.98],[0,6,47.31]],"id":41122648},{"batb":[[2,340,3],[1,350,3.73],[0,360,2]],"id":41200638},{"batb":[[2,1.85,274],[1,1.86,249.1],[0,1.87,142.72]],"batl":[[0,1.89,181.26]],"id":51922},{"batl":[[2,5.1,54.26],[1,5,48.29],[0,4.9,36.13]],"id":50466254}]}],"ArrivalTime":1710508117428}
{"op":"mcm","id":2,"clk":"AKloAIyRAQCVnwE=","pt":1710508117538,"mc":[{"id":"1.226122413","rc":[{"batl":[[2,28,8.22],[1,27,2.79],[0,26,1.46]],"id":55632148},{"tv":103647.06,"batb":[[2,1.85,295.35],[0,1.87,119.67]],"trd":[[1.87,9536.15]],"ltp":1.87,"batl":[[2,1.9,103.29],[1,1.89,181.26],[0,1.88,88.1]],"id":51922},{"tv":2884.08,"batb":[[2,44,10.62],[1,46,17.94],[0,48,4.37]],"trd":[[50,6.88]],"ltp":50,"batl":[[2,60,21.3],[1,55,11.01],[0,50,2.39]],"id":49744721},{"tv":20271.54,"batb":[],"trd":[[4.9,466.07]],"ltp":4.9,"batl":[[0,4.9,31.3]],"id":50466254},{"batl":[[2,40,12.56],[1,38,4.35]],"id":106596}],"tv":144630.42}],"ArrivalTime":1710508117546}
{"op":"mcm","id":2,"clk":"ALBoAJaRAQCbnwE=","pt":1710508117571,"mc":[{"id":"1.226122413","rc":[{"batb":[[1,360,2]],"id":54370634},{"batl":[[0,26,4.4]],"id":55632148},{"batl":[[1,1.89,191.26]],"id":51922},{"batb":[[2,4.5,100.66]],"id":50466254},{"tv":593.27,"trd":[[200,18.86]],"batl":[[0,210,5.96]],"id":66251581}],"tv":144630.88}],"ArrivalTime":1710508117579}
{"op":"mcm","id":2,"clk":"ALhoAKCRAQCnnwE=","pt":1710508117676,"mc":[{"id":"1.226122413","rc":[{"batb":[[0,370,3.66]],"id":54370634},{"batl":[[0,6.4,47.5]],"id":41122648},{"batb":[[1,1.86,189.43]],"id":51922},{"tv":2888.86,"trd":[[50,11.66]],"batl":[[2,65,5.65],[1,60,21.3],[0,55,11.01]],"id":49744721},{"batb":[[2,4.6,147.38],[1,4.7,42.28],[0,4.8,14.39]],"batl":[[0,4.9,17.07]],"id":50466254}],"tv":144635.66}],"ArrivalTime":1710508117683}
{"op":"mcm","id":2,"clk":"ALloAK2RAQCwnwE=","pt":1710508117782,"mc":[{"id":"1.226122413","rc":[{"batb":[],"batl":[[0,4.9,3.57]],"id":50466254}]}],"ArrivalTime":1710508117790}
{"op":"mcm","id":2,"clk":"AMFoALWRAQC+nwE=","pt":1710508117884,"mc":[{"id":"1.226122413","rc":[{"tv":11218.06,"batb":[[0,6,46.34]],"trd":[[6.2,646.53]],"id":41122648},{"batb":[[0,1.87,96.92]],"batl":[[0,1.88,111.61]],"id":51922}],"tv":144637.61}],"ArrivalTime":1710508117891}
{"op":"mcm","id":2,"clk":"AMxoALyRAQDMnwE=","pt":1710508117990,"mc":[{"id":"1.226122413","rc":[{"tv":523.48,"trd":[[430,2.3]],"ltp":430,"batl":[[2,1000,4.41],[1,650,1.52],[0,490,3.35]],"id":41200638},{"tv":104247.05,"batb":[[1,1.86,239.32]],"trd":[[1.88,12186.46],[1.89,6125.63]],"ltp":1.89,"batl":[[2,1.91,238.57],[1,1.9,103.29],[0,1.89,2.87]],"id":51922}],"tv":145239.9}],"ArrivalTime":1710508117997}
{"op":"mcm","id":2,"clk":"AM5oAMGRAQDTnwE=","pt":1710508118090,"mc":[{"id":"1.226122413","rc":[{"batl":[[2,750,2.07],[1,520,1],[0,490,1.56]],"id":54370634},{"batb":[[1,350,1.87]],"id":41200638},{"tv":104267.05,"batb":[[0,1.87,86.92]],"trd":[[1.87,9556.15]],"ltp":1.87,"batl":[[0,1.89,10.87]],"id":51922}],"tv":145259.9}],"ArrivalTime":1710508118097}
{"op":"mcm","id":2,"clk":"AN1oAM6RAQDfnwE=","pt":1710508118201,"mc":[{"id":"1.226122413","rc":[{"tv":11224.06,"batb":[[0,6,43.34]],"trd":[[6,872.95]],"ltp":6,"batl":[[2,6.6,36.27],[1,6.4,47.5],[0,6.2,12.94]],"id":41122648},{"batb":[[0,24,4.08]],"id":55632148},{"batb":[[2,1.86,239.32],[1,1.87,86.92],[0,1.88,106.37]],"batl":[[2,1.91,235.67]],"id":51922}],"tv":145265.9}],"ArrivalTime":1710508118208}
{"op":"mcm","id":2,"clk":"AOBoANmRAQDnnwE=","pt":1710508118295,"mc":[{"id":"1.226122413","rc":[{"tv":104395.13,"batb":[[2,1.87,86.92],[1,1.88,111.39],[0,1.89,35.96]],"trd":[[1.89,6253.71]],"ltp":1.89,"batl":[[2,1.92,369.23],[1,1.91,235.67],[0,1.9,103.29]],"id":51922},{"tv":20273.54,"batb":[[0,4.8,13.39]],"trd":[[4.8,1155.56]],"ltp":4.8,"id":50466254}],"tv":145395.98}],"ArrivalTime":1710508118302}
{"op":"mcm","id":2,"clk":"AOloAN6RAQDznwE=","pt":1710508118405,"mc":[{"id":"1.226122413","rc":[{"batb":[[2,340,1.46]],"id":54370634},{"batb":[],"batl":[[0,6.2,23.29]],"id":41122648},{"batb":[[0,24,1]],"id":55632148},{"tv":104399.97,"batb":[[2,1.87,113.13],[1,1.88,73.96],[0,1.89,33.54]],"trd":[[1.89,6258.55]],"batl":[[2,1.92,263.08],[1,1.91,261.66],[0,1.9,148.1]],"id":51922},{"tv":20300.32,"batb":[[2,4.5,98.66],[1,4.6,147.38],[0,4.7,42.28]],"trd":[[4.8,1182.34]],"batl":[],"id":50466254},{"tv":2502.52,"batb":[[0,32,9.83]],"trd":[[32,201.65]],"ltp":32,"batl":[[2,38,4.35],[1,36,4.47],[0,34,1.32]],"id":106596}],"tv":145438.22}],"ArrivalTime":1710508118412}
{"op":"mcm","id":2,"clk":"APtoAO6RAQCCoAE=","pt":1710508118519,"mc":[{"id":"1.226122413","rc":[{"tv":104467.05,"batb":[[2,1.86,189.43],[1,1.87,151.8],[0,1.88,73.96]],"trd":[[1.89,6325.63]],"batl":[[2,1.91,261.66],[1,1.9,148.1],[0,1.89,63.4]],"id":51922},{"batl":[[0,4.9,21.29]],"id":50466254},{"batl":[[2,40,12.56],[1,38,4.35],[0,36,4.47]],"id":106596}],"tv":145505.3}],"ArrivalTime":1710508118526}
{"op":"mcm","id":2,"clk":"AINpAPmRAQCKoAE=","pt":1710508118611,"mc":[{"id":"1.226122413","rc":[{"batb":[[1,350,2.87]],"id":41200638},{"batb":[[2,22,24.16],[1,23,11.4]],"id":55632148},{"tv":104520.71,"batb":[[1,1.87,217.8],[0,1.88,47.13]],"trd":[[1.88,12240.12]],"ltp":1.88,"batl":[[2,1.91,258.76]],"id":51922},{"batb":[[0,32,17.15]],"batl":[[2,38,4.35],[1,36,4.47],[0,34,2.01]],"id":106596}],"tv":145558.96}],"ArrivalTime":1710508118619}
{"op":"mcm","id":2,"clk":"AIZpAICSAQCUoAE=","pt":1710508118712,"mc":[{"id":"1.226122413","rc":[{"batl":[[0,6.2,10.35]],"id":41122648},{"batb":[[2,350,2.87],[1,360,2],[0,370,1.76]],"id":41200638},{"batb":[[1,1.87,179.13]],"batl":[[0,1.89,79.4]],"id":51922},{"batl":[[0,4.9,36.03]],"id":50466254}]}],"ArrivalTime":1710508118719}
{"op":"mcm","id":2,"clk":"AJNpAImSAQCeoAE=","pt":1710508118817,"mc":[{"id":"1.226122413","rc":[{"batb":[[0,370,2]],"id":54370634},{"tv":11228.06,"batb":[[0,6,41.34]],"trd":[[6,876.95]],"id":41122648},{"tv":104532.17,"batb":[[0,1.88,70.64]],"trd":[[1.89,6337.09]],"ltp":1.89,"batl":[[0,1.89,73.67]],"id":51922},{"batb":[[1,30,22.78]],"batl":[],"id":106596}],"tv":145574.42}],"ArrivalTime":1710508118825}
{"op":"mcm","id":2,"clk":"AJVpAJKSAQCtoAE=","pt":1710508118870,"mc":[{"id":"1.226122413","rc":[{"batb":[[2,360,2],[1,370,2],[0,380,1.66]],"id":54370634},{"batb":[[2,1.86,264.93]],"batl":[[0,1.89,24]],"id":51922},{"batl":[[2,38,5.11],[1,36,5.32]],"id":106596}]}],"ArrivalTime":1710508118878}
{"op":"mcm","id":2,"clk":"AJ5pAJqSAQC3oAE=","pt":1710508118976,"mc":[{"id":"1.226122413","rc":[{"tv":11245.3,"batb":[],"trd":[[6.2,663.77]],"ltp":6.2,"batl":[[0,6.2,1.73]],"id":41122648},{"tv":104580.17,"batb":[[2,1.87,179.13],[1,1.88,70.64],[0,1.89,36.94]],"trd":[[1.89,6385.09]],"batl":[[2,1.92,263.08],[1,1.91,258.76],[0,1.9,148.1]],"id":51922},{"batl":[[2,38,4.35],[1,36,4.47]],"id":106596}],"tv":145639.66}],"ArrivalTime":1710508118984}
{"op":"mcm","id":2,"clk":"AKZpAKWSAQDDoAE=","pt":1710508119082,"mc":[{"id":"1.226122413","rc":[{"batb":[[2,350,2.78]],"id":41200638},{"tv":104620.56,"batb":[[2,1.87,221.83],[0,1.89,57.8]],"trd":[[1.9,4722.36],[1.89,6401.09]],"ltp":1.9,"batl":[[0,1.9,135.9]],"id":51922}],"tv":145680.05}],"ArrivalTime":1710508119089}
{"op":"mcm","id":2,"clk":"AKlpAK6SAQDOoAE=","pt":1710508119194,"mc":[{"id":"1.226122413","rc":[{"tv":104681.76,"batb":[[1,1.88,76.37],[0,1.89,27.2]],"trd":[[1.89,6462.29]],"ltp":1.89,"batl":[],"id":51922}],"tv":145741.25}],"ArrivalTime":1710508119202}
{"op":"mcm","id":2,"clk":"AK1pALuSAQDdoAE=","pt":1710508119301,"mc":[{"id":"1.226122413","rc":[{"tv":104685.76,"batb":[[0,1.89,25.2]],"trd":[[1.89,6466.29]],"id":51922}],"tv":145745.25}],"ArrivalTime":1710508119308}
{"op":"mcm","id":2,"clk":"AK9pAMGSAQDjoAE=","pt":1710508119411,"mc":[{"id":"1.226122413","rc":[{"tv":104722.22,"batb":[[0,1.89,6.97]],"trd":[[1.89,6502.75]],"id":51922}],"tv":145781.71}],"ArrivalTime":1710508119419}
{"op":"mcm","id":2,"clk":"ALtpAMySAQDyoAE=","pt":1710508119495,"mc":[{"id":"1.226122413","rc":[{"tv":11327.98,"batb":[[2,5.7,74.34],[1,5.8,85.73],[0,5.9,46.98]],"trd":[[6,959.63]],"ltp":6,"id":41122648},{"batb":[[0,1.89,11.99]],"id":51922},{"tv":2889.1,"batb":[[0,48,4.25]],"trd":[[48,32.18]],"ltp":48,"id":49744721},{"batb":[[0,4.7,67.28]],"id":50466254}],"tv":145864.63}],"ArrivalTime":1710508119502}
{"op":"mcm","id":2,"clk":"AL9pANiSAQD8oAE=","pt":1710508119598,"mc":[{"id":"1.226122413","rc":[{"batb":[],"batl":[[0,6.2,7.19]],"id":41122648},{"batb":[[0,24,4.88]],"id":55632148},{"tv":104736.16,"batb":[[2,1.87,227.03],[1,1.88,78.94],[0,1.89,5.02]],"trd":[[1.89,6516.69]],"batl":[[2,1.92,260.23],[0,1.9,105.87]],"id":51922},{"tv":2889.3,"batb":[[0,48,4.15]],"trd":[[48,32.38]],"id":49744721},{"tv":597.27,"batb":[[0,180,5.02]],"trd":[[190,10.25],[180,16.76]],"ltp":180,"id":66251581}],"tv":145882.77}],"ArrivalTime":1710508119606}
{"op":"mcm","id":2,"clk":"AMhpAN6SAQCEoQE=","pt":1710508119699,"mc":[{"id":"1.226122413","rc":[{"batl":[[0,6.2,20.04]],"id":41122648},{"batb":[[0,1.89,49.28]],"batl":[[1,1.91,235.67]],"id":51922},{"batl":[[0,4.9,37.03]],"id":50466254},{"batl":[[2,40,12.56],[1,38,4.35],[0,36,4.47]],"id":106596}]}],"ArrivalTime":1710508119706}
{"op":"mcm","id":2,"clk":"AM1pAOmSAQCOoQE=","pt":1710508119799,"mc":[{"id":"1.226122413","rc":[{"batb":[[0,380,1.87]],"id":54370634},{"batb":[[0,370,1.84]],"id":41200638},{"batb":[[0,24,11.18]],"id":55632148},{"tv":104947.9,"batb":[[1,1.88,128.47]],"trd":[[1.9,4934.1]],"ltp":1.9,"batl":[[2,1.93,209.88],[1,1.92,260.23],[0,1.91,235.67]],"id":51922}],"tv":146094.51}],"ArrivalTime":1710508119806}
{"op":"mcm","id":2,"clk":"ANdpAPCSAQCcoQE=","pt":1710508119907,"mc":[{"id":"1.226122413","rc":[{"batl":[[2,890,1],[1,750,2.07],[0,520,1]],"id":54370634},{"batl":[[2,6.4,47.5],[1,6.2,20.04],[0,6,10.86]],"id":41122648},{"tv":104972.9,"batb":[[2,1.88,128.47],[1,1.89,49.28],[0,1.9,93.05]],"trd":[[1.9,4959.1]],"batl":[[0,1.91,279.3]],"id":51922},{"batb":[[1,170,2.59]],"batl":[[2,260,1.55],[1,210,5.96],[0,200,1.24]],"id":66251581},{"batl":[[2,38,4.35],[1,36,4.47],[0,34,2.03]],"id":106596}],"tv":146119.51}],"ArrivalTime":1710508119915}
{"op":"mcm","id":2,"clk":"ANxpAPeSAQCroQE=","pt":1710508120011,"mc":[{"id":"1.226122413","rc":[{"batl":[[2,750,1.91],[1,570,1.72]],"id":54370634},{"tv":104992.9,"batb":[[1,1.89,109.37],[0,1.9,83.05]],"trd":[[1.9,4979.1]],"batl":[[2,1.93,207.07],[0,1.91,345.3]],"id":51922},{"batb":[[0,180,5.08]],"id":66251581}],"tv":146139.51}],"ArrivalTime":1710508120018}
{"op":"mcm","id":2,"clk":"AOJpAP+SAQC2oQE=","pt":1710508120117,"mc":[{"id":"1.226122413","rc":[{"batb":[[1,370,3]],"id":54370634},{"batb":[[2,5.7,76.24],[1,5.8,87.56],[0,5.9,36.98]],"batl":[],"id":41122648},{"batb":[[1,360,3]],"id":41200638},{"batb":[[2,1.88,195.47]],"batl":[[2,1.93,209.88],[0,1.91,326.68]],"id":51922},{"batb":[[1,4.6,149.17]],"id":50466254}]}],"ArrivalTime":1710508120124}
{"op":"mcm","id":2,"clk":"AItqALWTAQD1oQE=","pt":1710508120712,"mc":[{"id":"1.226122413","rc":[{"tv":435.05,"batb":[[0,380,2.51]],"trd":[[520,2]],"ltp":520,"batl":[[2,750,2],[1,570,1.56],[0,560,2.72]],"id":54370634},{"tv":11349.7,"batb":[[1,5.9,48.36],[2,5.8,57.1],[0,6,2.35]],"trd":[[6,981.35]],"batl":[[2,6.6,26.27],[1,6.4,47.5],[0,6.2,20.04]],"id":41122648},{"batl":[[0,490,3.19]],"id":41200638},{"batl":[[0,26,1.46]],"id":55632148},{"tv":105057.58,"batb":[[0,1.9,158.26],[2,1.88,152.77]],"trd":[[1.9,5006.1],[1.91,1965.09]],"ltp":1.91,"batl":[[1,1.92,286.05],[0,1.91,330.7]],"id":51922},{"tv":2899.3,"batb":[[0,50,11],[2,44,10.62],[1,46,18.5]],"trd":[[48,40.68],[46,37.16]],"ltp":46,"batl":[[2,65,6.31]],"id":49744721},{"batb":[[2,4.5,98.66],[1,4.6,174.17]],"batl":[[0,4.8,76.8],[2,5,47.13],[1,4.9,37.03]],"id":50466254}],"tv":146237.91,"con":true}],"ArrivalTime":1710508120720}
{"op":"mcm","id":2,"clk":"AIxqALyTAQD9oQE=","pt":1710508120793,"mc":[{"id":"1.226122413","rc":[{"batb":[[2,5.7,74.34],[1,5.8,38.41],[0,5.9,48.36]],"id":41122648},{"batb":[[0,1.9,301.58]],"id":51922},{"batb":[[2,46,18.5],[1,48,1.79]],"batl":[],"id":49744721},{"tv":20337.62,"trd":[[4.8,1219.64]],"batl":[[0,4.8,58.15]],"id":50466254}],"tv":146275.21}],"ArrivalTime":1710508120800}
{"op":"mcm","id":2,"clk":"AJBqAMKTAQCIogE=","pt":1710508120892,"mc":[{"id":"1.226122413","rc":[{"batb":[[0,4.7,47.9]],"id":50466254}]}],"ArrivalTime":1710508120900}
{"op":"mcm","id":2,"clk":"AJxqAMyTAQCaogE=","pt":1710508121008,"mc":[{"id":"1.226122413","rc":[{"batb":[[0,380,4.64]],"id":54370634},{"batb":[[0,5.9,88.26]],"batl":[],"id":41122648},{"batb":[[2,350,1]],"id":41200638},{"batb":[[0,1.9,317.58]],"batl":[[0,1.91,241.84]],"id":51922},{"batl":[[0,4.8,39.97]],"id":50466254},{"batb":[[0,180,2.81]],"id":66251581}]}],"ArrivalTime":1710508121015}
{"op":"mcm","id":2,"clk":"AJ1qANSTAQCkogE=","pt":1710508121101,"mc":[{"id":"1.226122413","rc":[{"batb":[[0,380,4.87]],"id":54370634},{"batb":[],"batl":[[1,1.92,330.17],[0,1.91,259.37]],"id":51922}]}],"ArrivalTime":1710508121109}
{"op":"mcm","id":2,"clk":"AK1qANiTAQC2ogE=","pt":1710508121219,"mc":[{"id":"1.226122413","rc":[{"batb":[[0,24,10.18]],"batl":[],"id":55632148},{"batl":[[1,1.92,327.32]],"id":51922},{"batb":[[1,48,6.09]],"batl":[[1,60,22.08]],"id":49744721},{"tv":20357.62,"batb":[[0,4.7,49.65]],"trd":[[4.8,1239.64]],"batl":[[0,4.8,29.97]],"id":50466254},{"batb":[[0,180,2.49]],"id":66251581}],"tv":146295.21}],"ArrivalTime":1710508121226}
{"op":"mcm","id":2,"clk":"ALFqAOOTAQC5ogE=","pt":1710508121307,"mc":[{"id":"1.226122413","rc":[{"tv":105077.58,"batb":[],"trd":[[1.91,1985.09]],"batl":[[0,1.91,205.74]],"id":51922},{"batl":[[1,4.9,37.15]],"id":50466254}],"tv":146315.21}],"ArrivalTime":1710508121314}
{"op":"mcm","id":2,"clk":"ALlqAOqTAQDFogE=","pt":1710508121416,"mc":[{"id":"1.226122413","rc":[{"tv":11351.7,"batb":[[0,5.9,87.26]],"trd":[[5.9,40.55]],"ltp":5.9,"id":41122648}],"tv":146317.21}],"ArrivalTime":1710508121424}
{"op":"mcm","id":2,"clk":"AMZqAPOTAQDSogE=","pt":1710508121519,"mc":[{"id":"1.226122413","rc":[{"tv":105172,"batb":[[0,1.9,292.58]],"trd":[[1.9,5056.1],[1.91,2029.51]],"batl":[[0,1.91,183.53]],"id":51922},{"batb":[[2,4.5,111.53]],"batl":[],"id":50466254}],"tv":146411.63}],"ArrivalTime":1710508121527}
{"op":"mcm","id":2,"clk":"AM5qAPeTAQDbogE=","pt":1710508121617,"mc":[{"id":"1.226122413","rc":[{"batl":[[2,810,2.82],[1,750,2],[0,570,1.72]],"id":54370634},{"batb":[[2,5.8,40.24],[1,5.9,89.02],[0,6,1.7]],"id":41122648},{"batb":[[2,1.88,192.77]],"batl":[[0,1.91,226.01]],"id":51922},{"tv":20379.62,"batb":[[0,4.7,38.65]],"trd":[[4.7,225.28]],"ltp":4.7,"batl":[[0,4.8,30.13]],"id":50466254}],"tv":146433.63}],"ArrivalTime":1710508121624}
{"op":"mcm","id":2,"clk":"ANNqAICUAQDmogE=","pt":1710508121724,"mc":[{"id":"1.226122413","rc":[{"batb":[[1,5.9,75.52]],"id":41122648},{"tv":105305.88,"trd":[[1.91,2163.39]],"batl":[[0,1.91,159.07]],"id":51922},{"batl":[[0,4.8,31.13]],"id":50466254}],"tv":146567.51}],"ArrivalTime":1710508121731}
{"op":"mcm","id":2,"clk":"ANhqAIaUAQDsogE=","pt":1710508121831,"mc":[{"id":"1.226122413","rc":[{"batb":[[2,5.7,80.79],[1,5.8,40.24],[0,5.9,73.76]],"id":41122648},{"tv":2575.09,"batb":[[0,24,8.98]],"trd":[[24,280.43]],"ltp":24,"id":55632148},{"batb":[[0,1.9,315.39]],"batl":[[1,1.92,330.17]],"id":51922},{"batl":[[1,60,21.3]],"id":49744721},{"batb":[[1,4.6,222.38]],"batl":[[0,4.8,49.42]],"id":50466254}],"tv":146569.91}],"ArrivalTime":1710508121838}
{"op":"mcm","id":2,"clk":"ANpqAJGUAQD4ogE=","pt":1710508121884,"mc":[{"id":"1.226122413","rc":[{"batb":[[0,5.9,87.23]],"id":41122648},{"tv":105476.86,"batb":[[0,1.9,290.39]],"trd":[[1.9,5106.1],[1.91,2284.37]],"batl":[[0,1.91,100.58]],"id":51922}],"tv":146740.89}],"ArrivalTime":1710508121892}
{"op":"mcm","id":2,"clk":"AOhqAJ6UAQCIowE=","pt":1710508122010,"mc":[{"id":"1.226122413","rc":[{"batb":[[2,5.7,78.89],[1,5.8,38.41]],"id":41122648},{"tv":523.7,"batb":[[2,360,3],[1,370,1.84],[0,400,1]],"trd":[[440,0.76]],"ltp":440,"batl":[[0,490,3.08]],"id":41200638},{"tv":106435.42,"batb":[[1,1.89,104.85],[0,1.91,47.88]],"trd":[[1.91,2653.11],[1.9,5686.88],[1.89,6525.73]],"ltp":1.89,"batl":[[2,1.94,85.38],[1,1.93,209.88],[0,1.92,327.32]],"id":51922},{"batl":[[1,60,22.08]],"id":49744721},{"batl":[[0,200,3.24]],"id":66251581}],"tv":147699.67}],"ArrivalTime":1710508122017}
{"op":"mcm","id":2,"clk":"AOlqAKOUAQCQowE=","pt":1710508122101,"mc":[{"id":"1.226122413","rc":[{"batl":[[2,750,2],[1,570,1.56],[0,560,2.72]],"id":54370634},{"tv":106519.56,"batb":[[0,1.91,5.81]],"trd":[[1.91,2737.25]],"ltp":1.91,"batl":[],"id":51922}],"tv":147783.81}],"ArrivalTime":1710508122108}
{"op":"mcm","id":2,"clk":"APhqAK2UAQCdowE=","pt":1710508122198,"mc":[{"id":"1.226122413","rc":[{"batb":[[2,380,1],[1,400,1],[0,410,1]],"id":41200638},{"tv":106531.18,"batb":[[0,1.9,46.52]],"trd":[[1.91,2748.87]],"batl":[[2,1.93,209.88],[1,1.92,327.32],[0,1.91,144.69]],"id":51922},{"tv":2903.3,"batb":[[0,50,9]],"trd":[[50,15.66]],"ltp":50,"id":49744721}],"tv":147799.43}],"ArrivalTime":1710508122205}
{"op":"mcm","id":2,"clk":"APpqALSUAQCnowE=","pt":1710508122303,"mc":[{"id":"1.226122413","rc":[{"batb":[],"batl":[[0,1.91,189.71]],"id":51922},{"batl":[[1,60,21.3]],"id":49744721}]}],"ArrivalTime":1710508122310}
{"op":"mcm","id":2,"clk":"AIdrAMOUAQCyowE=","pt":1710508122405,"mc":[{"id":"1.226122413","rc":[{"batb":[[2,400,1],[1,410,1],[0,420,1]],"id":41200638},{"tv":106581.18,"batb":[[2,1.88,185.94],[0,1.9,21.52]],"trd":[[1.9,5736.88]],"ltp":1.9,"id":51922},{"batb":[[0,4.7,54.64]],"batl":[],"id":50466254}],"tv":147849.43}],"ArrivalTime":1710508122412}
{"op":"mcm","id":2,"clk":"AI9rAMyUAQC4owE=","pt":1710508122512,"mc":[{"id":"1.226122413","rc":[{"tv":11351.86,"trd":[[6.2,663.93]],"ltp":6.2,"batl":[[0,6.2,19.96]],"id":41122648},{"tv":106592.64,"trd":[[1.91,2760.33]],"ltp":1.91,"batl":[[0,1.91,206.68]],"id":51922}],"tv":147861.05}],"ArrivalTime":1710508122519}
{"op":"mcm","id":2,"clk":"AJRrANeUAQDHowE=","pt":1710508122619,"mc":[{"id":"1.226122413","rc":[{"batl":[[2,6.6,41.51]],"id":41122648},{"tv":106623.22,"batb":[[0,1.9,6.23]],"trd":[[1.9,5767.46]],"ltp":1.9,"id":51922},{"batl":[[0,4.8,31.13]],"id":50466254}],"tv":147891.63}],"ArrivalTime":1710508122626}
{"op":"mcm","id":2,"clk":"AJhrANyUAQDNowE=","pt":1710508122715,"mc":[{"id":"1.226122413","rc":[{"batl":[[1,6.4,62.5]],"id":41122648},{"batb":[[2,1.87,270.88],[1,1.88,185.94],[0,1.89,104.85]],"id":51922},{"batl":[[1,60,22.97]],"id":49744721}]}],"ArrivalTime":1710508122722}
{"op":"mcm","id":2,"clk":"AKNrAOaUAQDaowE=","pt":1710508122826,"mc":[{"id":"1.226122413","rc":[{"batb":[[1,410,2.61]],"id":41200638},{"batb":[[0,1.89,81.75]],"batl":[[2,1.92,327.32],[1,1.91,206.68],[0,1.9,38.01]],"id":51922},{"batb":[[0,4.7,66.64]],"id":50466254},{"tv":603.75,"trd":[[200,25.34]],"ltp":200,"batl":[[2,270,2.82],[1,260,1.55],[0,210,5.96]],"id":66251581}],"tv":147898.11}],"ArrivalTime":1710508122833}
{"op":"mcm","id":2,"clk":"AKdrAPSUAQDrowE=","pt":1710508122922,"mc":[{"id":"1.226122413","rc":[{"tv":106627.22,"trd":[[1.9,5771.46]],"batl":[[0,1.9,36.01]],"id":51922}],"tv":147902.11}],"ArrivalTime":1710508122929}
{"op":"mcm","id":2,"clk":"AKtrAPiUAQD4owE=","pt":1710508123030,"mc":[{"id":"1.226122413","rc":[{"batb":[],"batl":[[2,6.4,62.5],[1,6.2,19.96],[0,6,1]],"id":41122648},{"tv":106699.24,"batb":[[2,1.88,185.94],[1,1.89,81.75],[0,1.9,21.6]],"trd":[[1.9,5843.48]],"batl":[[2,1.93,209.88],[1,1.92,327.32],[0,1.91,206.68]],"id":51922},{"tv":20381.62,"batb":[[2,4.5,114.78],[0,4.7,65.64]],"trd":[[4.7,227.28]],"id":50466254},{"batb":[[0,180,2.56]],"id":66251581}],"tv":147976.13}],"ArrivalTime":1710508123037}
{"op":"mcm","id":2,"clk":"AK1rAIWVAQD+owE=","pt":1710508123107,"mc":[{"id":"1.226122413","rc":[{"batl":[[2,740,3.11]],"id":54370634},{"tv":106709.24,"batb":[[0,1.9,16.6]],"trd":[[1.9,5853.48]],"id":51922}],"tv":147986.13}],"ArrivalTime":1710508123115}
{"op":"mcm","id":2,"clk":"ALRrAImVAQCHpAE=","pt":1710508123186,"mc":[{"id":"1.226122413","rc":[{"tv":11353.86,"batb":[[2,5.8,40.24],[1,5.9,88.99],[0,6,17.48]],"trd":[[6,983.35]],"ltp":6,"batl":[[2,6.6,41.51],[1,6.4,62.5],[0,6.2,19.96]],"id":41122648},{"batb":[[2,410,2.61],[1,420,1],[0,430,1.51]],"id":41200638},{"batb":[[1,1.89,104.69]],"id":51922}],"tv":147988.13}],"ArrivalTime":1710508123193}
{"op":"mcm","id":2,"clk":"ALtrAJGVAQCbpAE=","pt":1710508123299,"mc":[{"id":"1.226122413","rc":[{"batl":[[2,750,1.71],[1,740,3.11],[0,570,1.72]],"id":54370634},{"batb":[[2,5.8,38.41],[1,5.9,87.23]],"id":41122648},{"tv":106726.32,"batb":[[0,1.9,8.06]],"trd":[[1.9,5870.56]],"batl":[[1,1.92,330.17]],"id":51922},{"tv":20391.62,"batb":[[2,4.5,111.53],[1,4.6,220.42],[0,4.7,60.64]],"trd":[[4.7,237.28]],"batl":[[0,4.8,49.64]],"id":50466254}],"tv":148015.21}],"ArrivalTime":1710508123306}
{"op":"mcm","id":2,"clk":"AL1rAJiVAQCgpAE=","pt":1710508123391,"mc":[{"id":"1.226122413","rc":[{"batb":[[2,1.87,270.88],[1,1.88,185.94],[0,1.89,104.69]],"id":51922},{"tv":20395.62,"batb":[[0,4.7,58.64]],"trd":[[4.7,241.28]],"id":50466254}],"tv":148019.21}],"ArrivalTime":1710508123398}
{"op":"mcm","id":2,"clk":"AMRrAKCVAQCrpAE=","pt":1710508123504,"mc":[{"id":"1.226122413","rc":[{"batb":[[2,5.8,62.08]],"id":41122648},{"batl":[[1,1.92,327.32],[0,1.91,169.75]],"id":51922}]}],"ArrivalTime":1710508123511}
{"op":"mcm","id":2,"clk":"AMtrAKqVAQC6pAE=","pt":1710508123600,"mc":[{"id":"1.226122413","rc":[{"batl":[[0,570,1.56]],"id":54370634},{"tv":11359.36,"batb":[[0,6,20.23]],"trd":[[6.2,669.43]],"ltp":6.2,"batl":[[0,6.2,17.21]],"id":41122648},{"tv":2576.07,"batb":[[0,24,9.47]],"trd":[[26,420.43]],"ltp":26,"batl":[[2,29,14.76],[1,28,8.22],[0,27,3.76]],"id":55632148},{"batl":[[2,5,47.15],[0,4.8,62.41]],"id":50466254},{"tv":2503.48,"batb":[[0,32,16.67]],"trd":[[32,202.61]],"batl":[[0,34,2.51]],"id":106596}],"tv":148026.65}],"ArrivalTime":1710508123607}
{"op":"mcm","id":2,"clk":"ANFrALOVAQDEpAE=","pt":1710508123699,"mc":[{"id":"1.226122413","rc":[{"batl":[[2,740,3.11],[1,570,1.56],[0,560,2.56]],"id":54370634},{"batb":[[0,6,33.45]],"batl":[[2,6.6,41.52]],"id":41122648},{"batb":[[1,420,1.07]],"id":41200638}]}],"ArrivalTime":1710508123706}
{"op":"mcm","id":2,"clk":"ANdrAL2VAQDRpAE=","pt":1710508123805,"mc":[{"id":"1.226122413","rc":[{"batl":[[2,650,1],[1,620,1.55]],"id":41200638},{"batl":[[0,1.91,170.61]],"id":51922}]}],"ArrivalTime":1710508123813}
{"op":"mcm","id":2,"clk":"AOJrANGVAQDdpAE=","pt":1710508123909,"mc":[{"id":"1.226122413","rc":[{"tv":11426.26,"batb":[[2,5.7,78.89],[1,5.8,62.08],[0,5.9,87.23]],"trd":[[6,1050.25]],"ltp":6,"batl":[],"id":41122648},{"tv":106806.32,"batb":[[0,1.89,64.69]],"trd":[[1.89,6605.73]],"ltp":1.89,"batl":[[0,1.91,171.47]],"id":51922},{"tv":20397.62,"batb":[[1,4.6,233.29],[0,4.7,57.64]],"trd":[[4.7,243.28]],"id":50466254}],"tv":148175.55}],"ArrivalTime":1710508123916}
{"op":"mcm","id":2,"clk":"AO1rAN6VAQDppAE=","pt":1710508124014,"mc":[{"id":"1.226122413","rc":[{"batl":[[0,6.2,27.75]],"id":41122648}]}],"ArrivalTime":1710508124022}
{"op":"mcm","id":2,"clk":"APNrAOiVAQDzpAE=","pt":1710508124114,"mc":[{"id":"1.226122413","rc":[{"tv":106808.04,"batb":[],"trd":[[1.9,5872.28]],"ltp":1.9,"batl":[[2,1.93,207.07],[0,1.91,173.11]],"id":51922},{"tv":20421.98,"trd":[[4.8,1264]],"ltp":4.8,"batl":[[0,4.8,50.23]],"id":50466254}],"tv":148201.63}],"ArrivalTime":1710508124121}
{"op":"mcm","id":2,"clk":"APhrAPGVAQCCpQE=","pt":1710508124219,"mc":[{"id":"1.226122413","rc":[{"tv":440.17,"trd":[[560,5.12]],"ltp":560,"batl":[[2,750,1.71],[1,740,3.11],[0,570,1.56]],"id":54370634},{"batb":[[1,1.88,191.14]],"batl":[[2,1.92,327.32],[1,1.91,173.11],[0,1.9,75]],"id":51922}],"tv":148206.75}],"ArrivalTime":1710508124226}
{"op":"mcm","id":2,"clk":"AIBsAPmVAQCLpQE=","pt":1710508124326,"mc":[{"id":"1.226122413","rc":[{"tv":106876.62,"trd":[[1.9,5940.86]],"batl":[[0,1.9,40.71]],"id":51922},{"tv":20425.2,"trd":[[4.8,1267.22]],"batl":[[0,4.8,35.85]],"id":50466254}],"tv":148278.55}],"ArrivalTime":1710508124333}
{"op":"mcm","id":2,"clk":"AIRsAIqWAQCWpQE=","pt":1710508124383,"mc":[{"id":"1.226122413","rc":[{"batb":[],"batl":[[0,6.2,27.8]],"id":41122648},{"batb":[[1,420,1]],"id":41200638},{"tv":107352.22,"batb":[[2,1.86,244.8],[1,1.87,270.88],[0,1.88,191.14]],"trd":[[1.9,6022.28],[1.91,2930.53],[1.89,6829.71]],"ltp":1.91,"batl":[[2,1.93,209.88],[1,1.92,312.32],[0,1.91,88.01]],"id":51922},{"batb":[[2,4.5,114.78]],"batl":[[1,4.9,36.15]],"id":50466254}],"tv":148754.15}],"ArrivalTime":1710508124390}
{"op":"mcm","id":2,"clk":"AIlsAJCWAQCjpQE=","pt":1710508124492,"mc":[{"id":"1.226122413","rc":[{"tv":11448.95,"batb":[[2,5.8,62.08],[1,5.9,87.23],[0,6,6.65]],"trd":[[6,1072.94]],"batl":[[0,6.2,27.75]],"id":41122648},{"batl":[[0,490,2.93]],"id":41200638},{"batb":[[2,1.87,270.88],[1,1.88,191.14],[0,1.89,36.83]],"batl":[[2,1.93,207.07],[0,1.91,88.05]],"id":51922},{"tv":2903.54,"batb":[[0,50,8.88]],"trd":[[50,15.9]],"id":49744721},{"tv":20457.26,"batb":[[2,4.5,111.53]],"trd":[[4.8,1299.28]],"batl":[[0,4.8,2.31]],"id":50466254},{"batl":[[1,36,4.53]],"id":106596}],"tv":148809.14}],"ArrivalTime":1710508124500}
{"op":"mcm","id":2,"clk":"AIxsAJOWAQCypQE=","pt":1710508124683,"mc":[{"id":"1.226122413","rc":[{"batb":[[2,5.8,68.03]],"batl":[[0,6.2,34.19]],"id":41122648},{"batb":[[0,1.89,105.45]],"batl":[[0,1.91,133.34]],"id":51922},{"tv":20500.52,"trd":[[4.9,504.7],[4.8,1303.91]],"ltp":4.9,"batl":[[1,4.9,16.84],[0,4.8,12.76]],"id":50466254}],"tv":148852.4}],"ArrivalTime":1710508124691}
{"op":"mcm","id":2,"clk":"AJVsAJqWAQC2pQE=","pt":1710508124707,"mc":[{"id":"1.226122413","rc":[{"tv":107414.07,"batb":[[2,1.87,249.53],[0,1.89,79.52]],"trd":[[1.9,6032.28],[1.89,6881.56]],"ltp":1.89,"batl":[[2,1.93,209.88],[0,1.91,133.3]],"id":51922},{"tv":20526.05,"batb":[[2,4.6,233.29],[1,4.7,57.64],[0,4.8,4.37]],"trd":[[4.8,1329.44]],"ltp":4.8,"batl":[[2,5.1,44.26],[1,5,47.15],[0,4.9,16.84]],"id":50466254},{"batl":[[2,260,1.55],[1,210,5.96],[0,200,1.21]],"id":66251581}],"tv":148939.78}],"ArrivalTime":1710508124714}
{"op":"mcm","id":2,"clk":"AJtsAJ+WAQDEpQE=","pt":1710508124792,"mc":[{"id":"1.226122413","rc":[{"batb":[[2,370,3],[1,380,4.63],[0,390,3.91]],"id":54370634},{"batb":[[1,420,2.61]],"batl":[[2,1000,4.41],[1,650,1],[0,620,1.66]],"id":41200638},{"batb":[[0,4.8,22.81]],"batl":[[2,5.1,44.37]],"id":50466254},{"tv":603.89,"batb":[[0,180,2.49]],"trd":[[190,10.39]],"ltp":190,"id":66251581}],"tv":148939.92}],"ArrivalTime":1710508124800}
{"op":"mcm","id":2,"clk":"AKJsAKOWAQDNpQE=","pt":1710508124896,"mc":[{"id":"1.226122413","rc":[{"batb":[[2,5.7,78.89],[1,5.8,68.03],[0,5.9,87.23]],"id":41122648},{"batb":[[2,420,2.61],[1,430,1.51],[0,440,1]],"id":41200638},{"tv":107416.07,"trd":[[1.91,2932.53]],"ltp":1.91,"batl":[[1,1.92,315.17],[0,1.91,132.3]],"id":51922},{"batb":[[0,4.8,22.51]],"batl":[],"id":50466254}],"tv":148941.92}],"ArrivalTime":1710508124904}
{"op":"mcm","id":2,"clk":"AKpsAKmWAQDYpQE=","pt":1710508125005,"mc":[{"id":"1.226122413","rc":[{"batb":[[2,5.8,68.03],[1,5.9,87.23],[0,6,2]],"id":41122648},{"tv":525.7,"batb":[[2,410,2.61],[1,420,2.61],[0,430,1.51]],"trd":[[440,2.76]],"batl":[[0,620,1.8]],"id":41200638},{"tv":20571.07,"batb":[[2,4.5,114.78],[1,4.6,233.29],[0,4.7,57.64]],"trd":[[4.8,1374.46]],"id":50466254}],"tv":148988.94}],"ArrivalTime":1710508125013}
{"op":"mcm","id":2,"clk":"ALRsALGWAQDipQE=","pt":1710508125108,"mc":[{"id":"1.226122413","rc":[{"batl":[[1,740,3.02]],"id":54370634},{"batb":[[0,1.89,56.67]],"id":51922},{"tv":20591.06,"batb":[[0,4.7,47.64]],"trd":[[4.7,263.27]],"ltp":4.7,"id":50466254}],"tv":149008.93}],"ArrivalTime":1710508125116}
{"op":"mcm","id":2,"clk":"ALlsAL6WAQDupQE=","pt":1710508125214,"mc":[{"id":"1.226122413","rc":[{"batb":[[2,5.8,62.08]],"id":41122648},{"tv":526.16,"batb":[[0,430,2.28]],"trd":[[450,0.22],[430,2.54]],"ltp":450,"batl":[[0,620,1.69]],"id":41200638},{"batl":[[1,1.92,312.32]],"id":51922},{"batb":[[2,4.5,111.53],[0,4.7,49.64]],"batl":[],"id":50466254}],"tv":149009.39}],"ArrivalTime":1710508125221}
{"op":"mcm","id":2,"clk":"AMBsAMCWAQD1pQE=","pt":1710508125318,"mc":[{"id":"1.226122413","rc":[{"batb":[[0,6,4.93]],"id":41122648},{"batb":[[0,430,2.35]],"batl":[[0,620,1.55]],"id":41200638},{"tv":107552.71,"batb":[[1,1.88,179.49],[0,1.89,35.35]],"trd":[[1.88,12263.42],[1.89,6994.9]],"ltp":1.88,"id":51922},{"batl":[[2,5,47.15],[1,4.9,16.84],[0,4.8,12.79]],"id":50466254},{"batb":[[2,170,2.59],[1,180,2.49],[0,190,2.1]],"id":66251581}],"tv":149146.03}],"ArrivalTime":1710508125326}
{"op":"mcm","id":2,"clk":"AMZsAMOWAQD/pQE=","pt":1710508125416,"mc":[{"id":"1.226122413","rc":[{"tv":527.94,"batb":[[2,420,2.61],[1,430,1.46],[0,480,1]],"trd":[[460,1.78]],"ltp":460,"batl":[[2,650,1],[1,620,1.2],[0,540,2.06]],"id":41200638},{"batl":[[2,1.92,312.32],[1,1.91,132.3],[0,1.9,20]],"id":51922},{"batl":[[1,60,23.07]],"id":49744721}],"tv":149147.81}],"ArrivalTime":1710508125424}
{"op":"mcm","id":2,"clk":"AMlsAMiWAQCMpgE=","pt":1710508125521,"mc":[{"id":"1.226122413","rc":[{"batb":[[2,430,1.46],[1,480,1],[0,490,1]],"id":41200638},{"batb":[[0,1.89,52.57]],"id":51922},{"batb":[[0,4.7,76.24]],"id":50466254},{"tv":605.89,"batb":[[0,190,1.1]],"trd":[[190,12.39]],"id":66251581}],"tv":149149.81}],"ArrivalTime":1710508125528}
{"op":"mcm","id":2,"clk":"AM9sANKWAQCSpgE=","pt":1710508125621,"mc":[{"id":"1.226122413","rc":[{"batl":[[2,740,3.02],[1,620,1.03]],"id":54370634},{"batl":[[2,6.6,41.6],[0,6.2,59.19]],"id":41122648},{"batl":[[2,1.92,315.17]],"id":51922},{"batb":[[2,4.5,114.78],[0,4.7,77.24]],"batl":[[0,4.8,31.56]],"id":50466254}]}],"ArrivalTime":1710508125628}
{"op":"mcm","id":2,"clk":"ANRsANmWAQCbpgE=","pt":1710508125720,"mc":[{"id":"1.226122413","rc":[{"batb":[[0,490,2]],"id":41200638},{"tv":107566.71,"batb":[[0,1.89,50.57]],"trd":[[1.9,6042.28],[1.89,6998.9]],"ltp":1.9,"batl":[[0,1.9,25]],"id":51922},{"batb":[[0,50,63.88]],"id":49744721}],"tv":149163.81}],"ArrivalTime":1710508125727}
{"op":"mcm","id":2,"clk":"ANlsAOGWAQCipgE=","pt":1710508125832,"mc":[{"id":"1.226122413","rc":[{"batb":[[2,420,2.68]],"id":41200638},{"tv":107567.03,"trd":[[1.9,6042.6]],"batl":[[0,1.9,24.84]],"id":51922}],"tv":149164.13}],"ArrivalTime":1710508125841}
{"op":"mcm","id":2,"clk":"AN5sAOmWAQCvpgE=","pt":1710508125926,"mc":[{"id":"1.226122413","rc":[{"tv":528.44,"batb":[[2,420,2.88]],"trd":[[500,0.5]],"ltp":500,"batl":[[0,540,1.81]],"id":41200638},{"tv":107582.41,"batb":[[0,1.89,42.88]],"trd":[[1.89,7014.28]],"ltp":1.89,"id":51922},{"batb":[[2,46,19.53],[0,50,65.63]],"batl":[[0,55,9.06]],"id":49744721},{"batl":[[1,4.9,19.41]],"id":50466254}],"tv":149180.01}],"ArrivalTime":1710508125934}
{"op":"mcm","id":2,"clk":"AOVsAO2WAQC6pgE=","pt":1710508125982,"mc":[{"id":"1.226122413","rc":[{"batb":[[1,380,4.19],[0,390,4.13]],"id":54370634},{"batl":[[1,6.4,66.5]],"id":41122648},{"batb":[[2,420,2.81]],"batl":[[1,620,1.38]],"id":41200638},{"batb":[[0,1.89,49.71]],"id":51922},{"batl":[[0,4.8,12.79]],"id":50466254}]}],"ArrivalTime":1710508125989}
{"op":"mcm","id":2,"clk":"AO5sAPOWAQDBpgE=","pt":1710508126085,"mc":[{"id":"1.226122413","rc":[{"tv":11453.17,"batb":[[0,6,2.82]],"trd":[[6,1077.16]],"batl":[[0,6.2,84.19]],"id":41122648},{"batl":[[2,630,2.82]],"id":41200638},{"batl":[[1,28,8.24]],"id":55632148}],"tv":149184.23}],"ArrivalTime":1710508126093}
{"op":"mcm","id":2,"clk":"APVsAPiWAQDIpgE=","pt":1710508126193,"mc":[{"id":"1.226122413","rc":[{"batb":[[2,360,3.02],[1,410,1.61],[0,420,1.81]],"id":41200638},{"tv":107597.79,"batb":[[0,1.89,42.02]],"trd":[[1.89,7029.66]],"id":51922},{"tv":2903.74,"trd":[[55,2.2]],"ltp":55,"batl":[[0,55,8.96]],"id":49744721}],"tv":149199.81}],"ArrivalTime":1710508126201}
{"op":"mcm","id":2,"clk":"AP5sAICXAQDUpgE=","pt":1710508126297,"mc":[{"id":"1.226122413","rc":[{"batb":[[2,380,2.06],[1,390,4.13],[0,400,2.44]],"id":54370634},{"tv":11457.17,"batb":[[1,5.9,47.33]],"trd":[[6.2,673.43]],"ltp":6.2,"batl":[[0,6.2,82.19]],"id":41122648},{"batb":[[2,410,1.61],[1,420,1.81],[0,500,1.2]],"id":41200638}],"tv":149203.81}],"ArrivalTime":1710508126304}
{"op":"mcm","id":2,"clk":"AIFtAIaXAQDapgE=","pt":1710508126392,"mc":[{"id":"1.226122413","rc":[{"tv":530.44,"batb":[[2,360,3.02],[1,410,1.61],[0,420,2.01]],"trd":[[500,2.5]],"id":41200638},{"batl":[[2,5,55.15]],"id":50466254}],"tv":149205.81}],"ArrivalTime":1710508126399}
{"op":"mcm","id":2,"clk":"AIVtAI2XAQDopgE=","pt":1710508126501,"mc":[{"id":"1.226122413","rc":[{"batb":[[1,390,3.91],[0,400,2.64]],"id":54370634},{"tv":11462.81,"batb":[[2,5.7,80.79],[1,5.8,62.08],[0,5.9,47.33]],"trd":[[6,1082.8]],"ltp":6,"batl":[[2,6.4,64.5],[1,6.2,82.19],[0,6,10]],"id":41122648},{"batb":[[2,360,2.78],[0,420,2.2]],"id":41200638},{"batb":[[0,1.89,60.02]],"id":51922},{"batl":[[2,5,47.15]],"id":50466254}],"tv":149211.45}],"ArrivalTime":1710508126508}
{"op":"mcm","id":2,"clk":"AIttAJeXAQDupgE=","pt":1710508126599,"mc":[{"id":"1.226122413","rc":[{"batb":[[0,400,2.84]],"id":54370634},{"tv":11486.8,"batb":[[2,5.8,63.91],[1,5.9,47.09],[0,6,55.75]],"trd":[[5.9,44.54],[6,1102.8]],"batl":[[2,6.6,45.6],[1,6.4,64.5],[0,6.2,82.19]],"id":41122648},{"batb":[[0,420,2.27]],"id":41200638},{"tv":107797.79,"batb":[[2,1.86,244.8],[1,1.87,249.53],[0,1.88,139.51]],"trd":[[1.88,12343.38],[1.89,7149.7]],"ltp":1.88,"batl":[[2,1.92,312.32]],"id":51922},{"batl":[[0,55,6.96]],"id":49744721}],"tv":149435.44}],"ArrivalTime":1710508126607}
{"op":"mcm","id":2,"clk":"AI9tAJyXAQD4pgE=","pt":1710508126731,"mc":[{"id":"1.226122413","rc":[{"batb":[[1,390,4.91]],"id":54370634},{"batb":[[2,5.8,62.08],[1,5.9,20.99],[0,6,54.05]],"id":41122648},{"batl":[[0,1.9,68.55]],"id":51922},{"tv":20616.64,"trd":[[4.8,1400.04]],"ltp":4.8,"batl":[[2,5.1,44.37],[1,5,47.15],[0,4.9,19.41]],"id":50466254}],"tv":149461.02}],"ArrivalTime":1710508126738}
{"op":"mcm","id":2,"clk":"AJJtAKOXAQCApwE=","pt":1710508126809,"mc":[{"id":"1.226122413","rc":[{"batb":[[1,390,1.24]],"id":54370634},{"tv":11489.53,"batb":[[0,6,52.68]],"trd":[[6,1105.53]],"id":41122648},{"batb":[[0,420,1.88]],"id":41200638},{"tv":2590.31,"batb":[[0,24,2.35]],"trd":[[24,294.67]],"ltp":24,"id":55632148},{"batl":[[0,1.9,91.9]],"id":51922}],"tv":149477.99}],"ArrivalTime":1710508126816}
{"op":"mcm","id":2,"clk":"AJhtAK2XAQCKpwE=","pt":1710508126914,"mc":[{"id":"1.226122413","rc":[{"batb":[[1,5.9,45.76]],"id":41122648},{"tv":2595.01,"batb":[[2,21,92.74],[1,22,24.16],[0,23,11.4]],"trd":[[24,299.37]],"id":55632148},{"batb":[[2,1.86,265.8],[0,1.88,72.51]],"batl":[[0,1.9,101.9]],"id":51922},{"tv":20621.64,"batb":[[2,4.6,245.29],[1,4.7,74.74],[0,4.8,2.05]],"trd":[[4.7,268.27]],"ltp":4.7,"id":50466254}],"tv":149487.69}],"ArrivalTime":1710508126921}
{"op":"mcm","id":2,"clk":"AJ1tALiXAQCRpwE=","pt":1710508127009,"mc":[{"id":"1.226122413","rc":[{"tv":11502.27,"batb":[[0,6,46.31]],"trd":[[6,1118.27]],"id":41122648},{"batl":[[2,28,8.24],[1,27,2.79],[0,26,1.95]],"id":55632148},{"tv":107804.07,"trd":[[1.9,6048.88]],"ltp":1.9,"batl":[[0,1.9,98.76]],"id":51922},{"batb":[[2,46,20.57]],"id":49744721}],"tv":149506.71}],"ArrivalTime":1710508127016}
{"op":"mcm","id":2,"clk":"AKJtALuXAQCcpwE=","pt":1710508127112,"mc":[{"id":"1.226122413","rc":[{"batb":[[2,360,3.01]],"id":41200638},{"batb":[[1,22,21.16]],"batl":[[0,26,5.86]],"id":55632148},{"batl":[[2,1.92,315.17]],"id":51922},{"batl":[[0,55,8.96]],"id":49744721}]}],"ArrivalTime":1710508127119}
{"op":"mcm","id":2,"clk":"AKltAMOXAQCopwE=","pt":1710508127217,"mc":[{"id":"1.226122413","rc":[{"batl":[[2,750,1.71],[1,740,3.02],[0,620,1.03]],"id":54370634},{"batl":[[1,6.4,39.5]],"id":41122648},{"batb":[[2,21,89.06]],"id":55632148},{"batl":[[0,1.9,88.76]],"id":51922}]}],"ArrivalTime":1710508127224}
{"op":"mcm","id":2,"clk":"ALJtAMmXAQCzpwE=","pt":1710508127321,"mc":[{"id":"1.226122413","rc":[{"tv":11504.31,"batb":[[0,6,45.29]],"trd":[[6,1120.31]],"batl":[],"id":41122648},{"batl":[[0,26,8.74]],"id":55632148},{"batl":[[0,4.9,18.41]],"id":50466254},{"tv":607.89,"trd":[[200,27.34]],"ltp":200,"batl":[[2,270,2.82],[1,260,1.55],[0,210,6.17]],"id":66251581}],"tv":149510.75}],"ArrivalTime":1710508127328}
{"op":"mcm","id":2,"clk":"ALhtANmXAQC7pwE=","pt":1710508127430,"mc":[{"id":"1.226122413","rc":[{"batb":[[2,390,1.24],[1,400,2.84],[0,410,3.49]],"id":54370634},{"tv":11543.33,"batb":[[0,6,25.78]],"trd":[[6,1159.33]],"id":41122648},{"batb":[[0,23,7.84]],"id":55632148},{"tv":108200.07,"batb":[[2,1.85,202.86],[1,1.86,265.8],[0,1.87,124.04]],"trd":[[1.87,9807.13],[1.88,12488.4]],"ltp":1.87,"id":51922},{"batb":[[0,50,66.81]],"id":49744721},{"batb":[[0,190,2.37]],"id":66251581}],"tv":149945.77}],"ArrivalTime":1710508127437}
{"op":"mcm","id":2,"clk":"AL5tAN2XAQDIpwE=","pt":1710508127476,"mc":[{"id":"1.226122413","rc":[{"tv":11548.99,"batb":[[0,6,22.95]],"trd":[[6,1164.99]],"id":41122648}],"tv":149951.43}],"ArrivalTime":1710508127484}
{"op":"mcm","id":2,"clk":"AMVtAOaXAQDWpwE=","pt":1710508127586,"mc":[{"id":"1.226122413","rc":[{"batb":[[1,400,3.64],[0,410,3.67]],"id":54370634},{"batb":[[0,420,2]],"batl":[[1,620,1.47]],"id":41200638},{"tv":108203.21,"batb":[[0,1.87,147.15]],"trd":[[1.87,9810.27]],"batl":[[2,1.91,132.3],[1,1.9,88.76],[0,1.89,68.11]],"id":51922},{"batb":[[1,48,9.95]],"id":49744721},{"batb":[[0,4.8,14.67]],"batl":[[0,4.9,3.67]],"id":50466254}],"tv":149954.57}],"ArrivalTime":1710508127594}
{"op":"mcm","id":2,"clk":"AMptAPKXAQDdpwE=","pt":1710508127690,"mc":[{"id":"1.226122413","rc":[{"batb":[[1,1.86,244.45]],"batl":[[2,1.91,134.87]],"id":51922},{"batb":[[1,4.7,77.32]],"batl":[[0,4.9,2.69]],"id":50466254}]}],"ArrivalTime":1710508127697}
{"op":"mcm","id":2,"clk":"ANJtAPmXAQDtpwE=","pt":1710508127886,"mc":[{"id":"1.226122413","rc":[{"tv":2612.49,"batb":[[2,22,21.16],[1,23,7.84],[0,26,6.44]],"trd":[[26,437.91]],"ltp":26,"batl":[[2,29,14.76],[1,28,8.24],[0,27,2.79]],"id":55632148},{"batb":[[0,50,68.03]],"id":49744721},{"batb":[[2,4.6,248.38],[0,4.8,30.35]],"id":50466254},{"tv":610.97,"batb":[[0,190,1.83]],"trd":[[190,15.47]],"ltp":190,"batl":[[2,260,1.55],[1,220,2]],"id":66251581}],"tv":149975.13}],"ArrivalTime":1710508127893}
{"op":"mcm","id":2,"clk":"ANNtAPyXAQD0pwE=","pt":1710508127897,"mc":[{"id":"1.226122413","rc":[{"tv":2613.35,"batb":[[2,23,7.84],[1,24,2.86],[0,26,6.01]],"trd":[[26,438.77]],"id":55632148},{"batl":[[1,1.9,91.33]],"id":51922},{"batl":[[2,65,5.65]],"id":49744721}],"tv":149975.99}],"ArrivalTime":1710508127904}
{"op":"mcm","id":2,"clk":"ANltAIOYAQD3pwE=","pt":1710508127999,"mc":[{"id":"1.226122413","rc":[{"batb":[[0,6,24.43]],"id":41122648},{"tv":2615.81,"batb":[[2,24,2.86],[1,25,5.75],[0,26,4.78]],"trd":[[26,441.23]],"batl":[[2,30,12.07],[1,29,15.4],[0,28,9.67]],"id":55632148},{"batb":[[2,1.85,221.86],[0,1.87,95.08]],"batl":[[2,1.9,94.36],[1,1.89,156.54],[0,1.88,6.06]],"id":51922},{"batb":[[0,190,1.89]],"id":66251581}],"tv":149978.45}],"ArrivalTime":1710508128007}
{"op":"mcm","id":2,"clk":"AOJtAIaYAQCEqAE=","pt":1710508128102,"mc":[{"id":"1.226122413","rc":[{"tv":11562.19,"batb":[[0,6,17.83]],"trd":[[6,1178.19]],"id":41122648},{"tv":2625.37,"batb":[[2,23,10.34],[1,24,6],[0,25,5.75]],"trd":[[26,450.79]],"batl":[[2,30,11.47],[1,29,14.76],[0,28,8.24]],"id":55632148},{"tv":108393.47,"batb":[[2,1.85,139.46],[0,1.87,7.63]],"trd":[[1.87,9985.17],[1.88,12500.52],[1.89,7152.94]],"batl":[[2,1.91,134.87],[1,1.9,94.36],[0,1.89,154.92]],"id":51922},{"batb":[[1,180,2.43]],"batl":[],"id":66251581}],"tv":150191.47}],"ArrivalTime":1710508128110}
{"op":"mcm","id":2,"clk":"AOhtAJCYAQCMqAE=","pt":1710508128216,"mc":[{"id":"1.226122413","rc":[{"batb":[[1,400,3.44]],"id":54370634},{"tv":11564.19,"batb":[[0,6,27.29]],"trd":[[6,1180.19]],"id":41122648},{"batb":[[0,25,9.52]],"batl":[],"id":55632148},{"batl":[[2,1.9,97.3],[1,1.89,154.92],[0,1.88,81.61]],"id":51922}],"tv":150193.47}],"ArrivalTime":1710508128223}
{"op":"mcm","id":2,"clk":"AOptAJqYAQCaqAE=","pt":1710508128314,"mc":[{"id":"1.226122413","rc":[{"batb":[[2,23,14.61]],"batl":[[2,29,14.76],[1,28,8.24],[0,27,1.72]],"id":55632148},{"tv":108408.73,"batb":[[2,1.84,129.71],[1,1.85,118.12],[0,1.86,244.45]],"trd":[[1.87,10000.43]],"batl":[[2,1.89,154.92],[1,1.88,106.16],[0,1.87,12.19]],"id":51922},{"batl":[[1,60,31.61]],"id":49744721},{"batb":[[2,4.6,245.29]],"id":50466254},{"tv":611.39,"trd":[[200,27.76]],"ltp":200,"batl":[[0,210,5.96]],"id":66251581}],"tv":150209.15}],"ArrivalTime":1710508128321}
{"op":"mcm","id":2,"clk":"APFtAKCYAQCjqAE=","pt":1710508128416,"mc":[{"id":"1.226122413","rc":[{"batb":[[0,25,6.78]],"batl":[],"id":55632148},{"tv":108419.55,"batb":[[2,1.84,131.71],[0,1.86,168.95]],"trd":[[1.87,10011.25]],"batl":[[0,1.87,6.78]],"id":51922}],"tv":150219.97}],"ArrivalTime":1710508128423}
{"op":"mcm","id":2,"clk":"APhtAKOYAQCwqAE=","pt":1710508128522,"mc":[{"id":"1.226122413","rc":[{"tv":108443.93,"batb":[[2,1.84,213.54]],"trd":[[1.87,10035.63]],"batl":[[0,1.87,79.98]],"id":51922},{"batb":[[0,4.8,32.46]],"batl":[],"id":50466254}],"tv":150244.35}],"ArrivalTime":1710508128529}
{"op":"mcm","id":2,"clk":"AP1tAKyYAQC7qAE=","pt":1710508128620,"mc":[{"id":"1.226122413","rc":[{"tv":11618.78,"batb":[[2,5.7,80.79],[1,5.8,62.08],[0,5.9,45.75]],"trd":[[5.9,44.56],[6,1234.76]],"ltp":5.9,"id":41122648}],"tv":150298.94}],"ArrivalTime":1710508128629}
{"op":"mcm","id":2,"clk":"AIJuALWYAQDEqAE=","pt":1710508128676,"mc":[{"id":"1.226122413","rc":[{"batb":[[2,400,3.44],[1,410,3.67],[0,430,1.43]],"id":54370634},{"batl":[[2,1.89,157.49]],"id":51922}]}],"ArrivalTime":1710508128683}
{"op":"mcm","id":2,"clk":"AIluAL2YAQDSqAE=","pt":1710508128777,"mc":[{"id":"1.226122413","rc":[{"batb":[[2,5.7,78.89]],"batl":[],"id":41122648},{"tv":20686.56,"batb":[[0,4.8,12.57]],"trd":[[4.8,1464.96]],"ltp":4.8,"id":50466254}],"tv":150363.86}],"ArrivalTime":1710508128784}
{"op":"mcm","id":2,"clk":"AI1uAMeYAQDcqAE=","pt":1710508128930,"mc":[{"id":"1.226122413","rc":[{"batb":[[1,410,3.68],[0,430,1.65]],"id":54370634},{"tv":108643.93,"batb":[[2,1.84,215.54],[0,1.86,68.95]],"trd":[[1.86,11179.92]],"ltp":1.86,"batl":[[1,1.88,156.16]],"id":51922},{"batb":[[0,4.8,14.95]],"batl":[[0,4.9,20.5]],"id":50466254},{"tv":620.03,"batb":[[2,150,3.74],[1,160,9.44],[0,170,2.59]],"trd":[[190,19.25],[180,21.62]],"ltp":180,"batl":[[2,220,2],[1,210,5.96],[0,180,1.68]],"id":66251581},{"tv":2507.48,"batb":[[0,32,14.67]],"trd":[[32,206.61]],"batl":[[2,40,12.57],[1,38,4.35],[0,36,5.01]],"id":106596}],"tv":150576.5}],"ArrivalTime":1710508128938}
{"op":"mcm","id":2,"clk":"AJNuANCYAQDjqAE=","pt":1710508128987,"mc":[{"id":"1.226122413","rc":[{"tv":108680.18,"trd":[[1.87,10071.88]],"ltp":1.87,"batl":[[0,1.87,61.86]],"id":51922},{"batb":[[0,4.8,3.52]],"id":50466254}],"tv":150612.75}],"ArrivalTime":1710508128995}
{"op":"mcm","id":2,"clk":"AJduANmYAQDvqAE=","pt":1710508129094,"mc":[{"id":"1.226122413","rc":[{"tv":442.23,"batb":[[2,410,3.49],[1,420,1.81]],"trd":[[620,2.06]],"ltp":620,"batl":[[2,890,1],[1,750,1.71],[0,740,3.02]],"id":54370634},{"batb":[[0,25,12.5]],"id":55632148},{"tv":108805.62,"batb":[[2,1.84,234.54],[0,1.86,52.4]],"trd":[[1.87,10157.46],[1.86,11219.78]],"batl":[[0,1.87,54.61]],"id":51922},{"batb":[[0,4.8,31.69]],"batl":[],"id":50466254},{"tv":620.37,"batb":[[0,170,7.13]],"trd":[[180,21.96]],"batl":[[2,200,1.18],[1,190,1.24],[0,180,1.51]],"id":66251581},{"tv":2508.44,"batb":[[2,30,22.78],[1,32,14.67],[0,34,2.14]],"trd":[[34,129.95]],"ltp":34,"batl":[[0,36,4.53]],"id":106596}],"tv":150741.55}],"ArrivalTime":1710508129101}
{"op":"mcm","id":2,"clk":"AKFuAOGYAQD2qAE=","pt":1710508129195,"mc":[{"id":"1.226122413","rc":[{"batb":[[2,5.8,62.08],[1,5.9,45.75],[0,6,14.61]],"batl":[[0,6.2,69.34]],"id":41122648},{"tv":109227.18,"batb":[[2,1.85,118.12],[1,1.86,52.4],[0,1.88,19.19]],"trd":[[1.87,10266.68],[1.88,12812.86]],"ltp":1.88,"batl":[[2,1.91,136.91],[1,1.9,96.86],[0,1.89,157.49]],"id":51922},{"batb":[[2,4.6,248.38]],"id":50466254},{"batl":[[2,40,13.25],[1,38,5.11]],"id":106596}],"tv":151163.11}],"ArrivalTime":1710508129203}
{"op":"mcm","id":2,"clk":"AKxuAOyYAQCFqQE=","pt":1710508129305,"mc":[{"id":"1.226122413","rc":[{"tv":11647.99,"batb":[[2,5.7,78.89],[1,5.8,62.08],[0,5.9,45.75]],"trd":[[6,1263.97]],"ltp":6,"batl":[[2,6.4,39.5],[1,6.2,69.34],[0,6,8.2]],"id":41122648},{"tv":109265.56,"batb":[[2,1.84,234.54],[1,1.85,118.12],[0,1.86,52.4]],"trd":[[1.88,12851.24]],"batl":[[2,1.9,99.8],[1,1.89,157.49],[0,1.88,5.53]],"id":51922},{"tv":20727.56,"batb":[[2,4.7,77.32],[1,4.8,31.69],[0,4.9,4.92]],"trd":[[4.9,545.7]],"ltp":4.9,"batl":[[2,5.2,61.31],[1,5.1,44.37],[0,5,47.15]],"id":50466254},{"tv":2512.72,"batb":[[2,29,34.5],[1,30,22.78],[0,32,14.67]],"trd":[[34,134.23]],"batl":[[0,36,5.81]],"id":106596}],"tv":151275.98}],"ArrivalTime":1710508129312}
{"op":"mcm","id":2,"clk":"AK5uAPWYAQCLqQE=","pt":1710508129399,"mc":[{"id":"1.226122413","rc":[{"batb":[[2,400,2.44]],"id":54370634},{"batl":[[1,6.2,83.47]],"id":41122648},{"tv":109276.62,"batb":[[2,1.85,118.12],[1,1.86,119.02],[0,1.87,61.83]],"trd":[[1.88,12862.3]],"batl":[[2,1.91,136.91],[1,1.9,99.8],[0,1.89,157.49]],"id":51922},{"batb":[[2,4.7,80.46],[1,4.8,16.14]],"id":50466254}],"tv":151287.04}],"ArrivalTime":1710508129407}
{"op":"mcm","id":2,"clk":"ALNuAP6YAQCbqQE=","pt":1710508129514,"mc":[{"id":"1.226122413","rc":[{"batb":[[2,400,2.66],[0,430,2.07]],"id":54370634},{"batb":[[2,5.7,80.79],[1,5.8,63.91],[0,5.9,24.04]],"id":41122648},{"tv":109502.62,"batb":[[1,1.86,109.02],[0,1.87,41.92]],"trd":[[1.87,10466.68],[1.86,11239.78],[1.89,7158.94]],"ltp":1.89,"batl":[[1,1.9,116.86],[0,1.89,154.49]],"id":51922},{"batb":[[0,4.9,7.67]],"batl":[[2,5.2,63.65],[0,5,45.15]],"id":50466254},{"batb":[[0,32,18.86]],"batl":[[2,40,12.57],[1,38,4.35],[0,36,4.53]],"id":106596}],"tv":151513.04}],"ArrivalTime":1710508129521}
{"op":"mcm","id":2,"clk":"ALxuAIGZAQChqQE=","pt":1710508129611,"mc":[{"id":"1.226122413","rc":[{"batb":[[0,5.9,22.28]],"id":41122648},{"tv":109802.63,"batb":[[2,1.83,135.43],[1,1.84,216.54],[0,1.85,124.08]],"trd":[[1.87,10550.52],[1.86,11455.95]],"ltp":1.86,"id":51922},{"tv":20729.46,"batb":[[1,4.8,31.69],[0,4.9,6.72]],"trd":[[4.9,547.6]],"id":50466254},{"batb":[[1,160,9.25]],"batl":[],"id":66251581},{"batb":[[1,30,20.78],[0,32,16.86]],"id":106596}],"tv":151814.95}],"ArrivalTime":1710508129618}
{"op":"mcm","id":2,"clk":"AMRuAIeZAQCsqQE=","pt":1710508129715,"mc":[{"id":"1.226122413","rc":[{"batb":[[1,420,1.62]],"id":54370634},{"tv":11664.39,"batb":[[1,5.8,40.24]],"trd":[[6,1280.37]],"batl":[[2,6.6,45.6],[1,6.4,39.5],[0,6.2,83.47]],"id":41122648},{"tv":109814.63,"batb":[[0,1.85,118.07]],"trd":[[1.86,11457.83],[1.85,15224.9]],"ltp":1.85,"batl":[[2,1.9,116.86],[1,1.89,154.49],[0,1.88,81.18]],"id":51922},{"batb":[[1,4.8,35.98]],"batl":[[2,5.2,61.31]],"id":50466254}],"tv":151843.35}],"ArrivalTime":1710508129723}
{"op":"mcm","id":2,"clk":"AMVuAJKZAQC2qQE=","pt":1710508129819,"mc":[{"id":"1.226122413","rc":[{"batb":[[2,1.83,114.08]],"batl":[[2,1.89,154.49],[1,1.88,105.74],[0,1.86,85.4]],"id":51922},{"batl":[[2,5.2,30.04]],"id":50466254},{"batb":[[2,30,20.78],[1,32,16.86],[0,34,2.62]],"id":106596}]}],"ArrivalTime":1710508129826}
{"op":"mcm","id":2,"clk":"AM1uAJeZAQDCqQE=","pt":1710508129931,"mc":[{"id":"1.226122413","rc":[{"batb":[[2,420,1.62],[1,430,1.65],[0,440,3.68]],"id":54370634},{"tv":11717.14,"batb":[[2,5.7,78.89],[1,5.8,38.41],[0,5.9,9.77]],"trd":[[5.9,97.31]],"ltp":5.9,"id":41122648},{"batl":[[2,1.88,105.74],[1,1.87,81.55]],"id":51922}],"tv":151896.1}],"ArrivalTime":1710508129938}
{"op":"mcm","id":2,"clk":"ANJuAJ+ZAQDMqQE=","pt":1710508130031,"mc":[{"id":"1.226122413","rc":[{"batb":[[0,5.9,19.77]],"batl":[[2,6.6,30.37]],"id":41122648},{"tv":110017.44,"batb":[[2,1.83,219.85],[1,1.84,134.71]],"trd":[[1.86,11660.64]],"ltp":1.86,"batl":[[1,1.87,98.38],[0,1.86,43.99]],"id":51922},{"batb":[[1,32,12.67]],"batl":[[2,40,13.25],[1,38,5.11],[0,36,2.07]],"id":106596}],"tv":152098.91}],"ArrivalTime":1710508130039}
{"op":"mcm","id":2,"clk":"ANluAKqZAQDVqQE=","pt":1710508130083,"mc":[{"id":"1.226122413","rc":[{"batb":[[1,430,2.65]],"id":54370634},{"batb":[[0,5.9,34.02]],"batl":[[2,6.4,39.5],[1,6.2,83.47],[0,6,14.33]],"id":41122648},{"tv":110105.42,"trd":[[1.86,11748.62]],"batl":[[2,1.89,154.49],[1,1.88,105.74],[0,1.87,98.38]],"id":51922}],"tv":152186.89}],"ArrivalTime":1710508130090}
{"op":"mcm","id":2,"clk":"AOFuALGZAQDfqQE=","pt":1710508130218,"mc":[{"id":"1.226122413","rc":[{"tv":11720.54,"batb":[[1,5.8,40.24],[0,5.9,25.78]],"trd":[[6,1283.77]],"ltp":6,"batl":[[0,6,12.63]],"id":41122648},{"batb":[[1,24,7]],"id":55632148},{"batb":[[2,1.83,281.78]],"batl":[],"id":51922},{"tv":20735.46,"batb":[[2,4.7,78.7],[0,4.9,3.72]],"trd":[[4.9,553.6]],"id":50466254}],"tv":152196.29}],"ArrivalTime":1710508130226}
{"op":"mcm","id":2,"clk":"AONuALiZAQDpqQE=","pt":1710508130291,"mc":[{"id":"1.226122413","rc":[{"tv":110141.42,"trd":[[1.87,10586.52]],"ltp":1.87,"batl":[[0,1.87,80.38]],"id":51922}],"tv":152232.29}],"ArrivalTime":1710508130298}
{"op":"mcm","id":2,"clk":"AOpuAMGZAQDyqQE=","pt":1710508130393,"mc":[{"id":"1.226122413","rc":[{"batb":[[2,5.7,80.79],[0,5.9,24.02]],"id":41122648},{"tv":530.64,"trd":[[510,2.12]],"ltp":510,"batl":[[0,540,1.71]],"id":41200638},{"batb":[[2,1.84,134.71],[1,1.85,118.07],[0,1.86,24.83]],"batl":[[0,1.87,180.38]],"id":51922},{"tv":20745.46,"batb":[[2,4.6,266.64],[1,4.7,78.7],[0,4.8,34.7]],"trd":[[4.9,561.04],[4.8,1467.52]],"ltp":4.8,"id":50466254}],"tv":152242.49}],"ArrivalTime":1710508130400}
{"op":"mcm","id":2,"clk":"APBuAMSZAQCAqgE=","pt":1710508130497,"mc":[{"id":"1.226122413","rc":[{"batb":[[0,440,3.86]],"id":54370634},{"batb":[],"batl":[[0,1.87,160.05]],"id":51922}]}],"ArrivalTime":1710508130504}
{"op":"mcm","id":2,"clk":"APZuAMuZAQCJqgE=","pt":1710508130606,"mc":[{"id":"1.226122413","rc":[{"batb":[[1,48,17.68],[0,50,75.76]],"id":49744721},{"batb":[[2,30,24.7]],"id":106596}]}],"ArrivalTime":1710508130613}
