{"op":"connection","connectionId":"106-150324130517-1736998","ArrivalTime":1710507917311}
{"op":"status","connectionClosed":false,"id":1,"ArrivalTime":1710507917425}
{"op":"status","connectionClosed":false,"id":2,"ArrivalTime":1710507917457}
{"op":"mcm","id":2,"initialClk":"GpSZ6vkEG/Wb6ukEFOHyyPQE","clk":"AAAAAAAA","conflateMs":0,"heartbeatMs":5000,"pt":1710507917481,"ct":"SUB_IMAGE","mc":[{"id":"1.226122413","marketDefinition":{"bspMarket":true,"turnInPlayEnabled":true,"persistenceEnabled":true,"marketBaseRate":5,"bettingType":"ODDS","status":"OPEN","venue":"Fakenham","timezone":"Europe/London","regulators":["MR_INT"],"marketType":"WIN","numberOfWinners":1,"countryCode":"GB","inPlay":false,"betDelay":0,"numberOfActiveRunners":9,"eventId":"33106089","crossMatching":true,"runnersVoidable":false,"suspendTime":"2024-03-15T13:10:00Z","discountAllowed":true,"runners":[{"status":"ACTIVE","sortPriority":1,"id":51922,"adjustmentFactor":52.91},{"status":"ACTIVE","sortPriority":2,"id":50466254,"adjustmentFactor":22.828},{"status":"ACTIVE","sortPriority":3,"id":41122648,"adjustmentFactor":9.588},{"status":"ACTIVE","sortPriority":4,"id":49744721,"adjustmentFactor":4.794},{"status":"ACTIVE","sortPriority":5,"id":55632148,"adjustmentFactor":3.995},{"status":"ACTIVE","sortPriority":6,"id":106596,"adjustmentFactor":3.995},{"status":"ACTIVE","sortPriority":7,"id":66251581,"adjustmentFactor":0.959},{"status":"ACTIVE","sortPriority":8,"id":41200638,"adjustmentFactor":0.533},{"status":"ACTIVE","sortPriority":9,"id":54370634,"adjustmentFactor":0.399},{"status":"REMOVED","sortPriority":10,"removalDate":"2024-03-15T09:18:23Z","id":47855509,"adjustmentFactor":10.417}],"version":5797175553,"eventTypeId":"7","complete":true,"openDate":"2024-03-15T13:10:00Z","marketTime":"2024-03-15T13:10:00Z","bspReconciled":false},"rc":[{"tv":0,"ltp":6.4,"id":47855509},{"tv":306.46,"batb":[[1,300,2.21],[2,290,1.49],[0,320,1.78]],"trd":[[320,20.26],[340,20.02],[330,28.48],[350,14.44],[390,11.53],[380,5.06],[310,12.67],[300,14.08],[290,9.52],[280,6.9],[260,1.4],[370,8.92],[360,21.57],[400,23.6],[410,2.78],[130,9.19],[270,2.72],[190,7.56],[200,2.65],[150,14.28],[160,5.64],[140,6.82],[120,13.07],[110,18.56],[100,2.74],[210,0.16],[170,0.1],[89.58,2.17],[179.17,0.05],[107.5,3.48],[85.1,1.83],[134.37,0.16],[197.08,0.03],[125.42,5.12],[188.12,4.87],[116.46,2.18],[143.33,1.85]],"ltp":320,"batl":[[1,420,2.25],[0,360,3],[2,430,2.24]],"id":54370634},{"tv":6399.64,"batb":[[0,8.2,47.91],[1,8,66.88],[2,7.8,85.87]],"trd":[[8.2,30.9],[8.4,461.25],[8.6,361.5],[8.8,481.21],[9,451.66],[9.2,476.16],[9.4,566.52],[6.6,45.28],[9.8,344.05],[7.52,66.69],[11.5,245.85],[11,78.54],[10.5,426.72],[5.55,57.63],[10,1105.57],[5.2,27.99],[4.75,32.55],[9.6,194.54],[5.29,22.41],[6.4,29.67],[6.09,13.99],[7.8,6.69],[7.2,83.79],[12,62.68],[12.5,11.56],[13,10.74],[4.93,21.99],[7.6,90.13],[6.99,73.05],[7.88,6.97],[5.11,41.67],[7.17,75.02],[6.81,63.1],[8,7.3],[6.8,13.93],[5.37,84.23],[7.4,5.72],[7,15.17],[6.2,13.44],[7.35,0.78],[4.66,5.22],[4.03,13.69],[5.91,4],[6.45,15.24],[6.63,67.52],[3.85,6.08],[4.48,7.54],[5.02,28.78],[6.27,4],[4.84,25.41],[4.12,6.3],[4.57,7.22]],"ltp":8.2,"batl":[[0,8.4,14.05],[1,8.6,44.47],[2,8.8,22.38]],"id":41122648},{"tv":339.25,"batb":[[1,190,1.04],[2,180,2.98],[0,200,8.22]],"trd":[[210,19.4],[240,5],[220,23.81],[250,16.69],[280,11.93],[290,28.53],[300,31.82],[400,12.5],[390,3.2],[360,7.36],[320,14],[410,2.98],[380,1.04],[370,7.92],[340,2.38],[310,0.79],[270,12.12],[200,47.22],[230,0.38],[260,6.02],[350,3.06],[330,3.12],[510,1.92],[520,2.16],[440,0.54],[190,10.92],[180,14.93],[150,2],[160,5.34],[62.71,2.28],[107.5,7.11],[170,10.29],[179.17,0.66],[125.42,0.6],[188.12,0.03],[170.21,1.76],[67.19,1.12],[71.67,0.74],[161.25,2.6],[37.62,1.42],[58.23,0.99],[35.83,1.9],[197.08,0.14],[53.75,1.9],[80.62,2],[116.46,2.16],[143.33,2.47]],"ltp":210,"batl":[[1,240,5.25],[0,230,6.42],[2,250,1.98]],"id":41200638},{"tv":1582.84,"batb":[[2,24,20.13],[0,26,10.82],[1,25,13.66]],"trd":[[26,234],[27,218.67],[25,216.69],[28,267.79],[24,212.65],[30,33.86],[29,65.04],[23,148.32],[58.23,19.66],[32,67.08],[22,16.92],[67.19,2.79],[49.27,4.33],[34,36.94],[36,1.65],[134.37,1.76],[40,4.65],[38,1.15],[98.54,0.7],[62.71,14.31],[85.1,1.74],[71.67,3.04],[89.58,3.86],[107.5,0.9],[44.79,0.96],[53.75,0.7],[76.15,0.04],[80.62,2.64]],"ltp":26,"batl":[[2,29,11.03],[1,28,26.26],[0,27,1.89]],"id":55632148},{"tv":57282,"batb":[[1,1.81,206.15],[2,1.8,488.61],[0,1.82,141.79]],"trd":[[1.83,6236.9],[1.82,3599.03],[1.81,1301.15],[1.8,131.98],[1.84,9280.29],[1.85,10630.55],[2.47,81.01],[2.22,121.39],[1.89,2403.32],[1.88,4319.65],[2.33,372.86],[1.96,163.25],[2.65,37.25],[2.67,92.87],[1.87,3817.24],[1.98,96.38],[2.53,66.88],[2.45,54.33],[1.86,5684.91],[1.9,3900.63],[2.63,48.48],[2,221.67],[1.91,1927.41],[1.92,114.47],[2.1,81.59],[1.93,144.43],[1.97,159.75],[2.62,122.03],[1.94,49.46],[2.18,8.4],[2.02,25.2],[2.49,93.85],[2.24,44.82],[2.08,222.13],[2.14,134.95],[1.95,74.64],[2.6,124.9],[2.17,33.42],[2.56,40.78],[2.51,96.63],[2.26,16.6],[2.04,42.66],[2.29,59.38],[2.54,112.2],[2.38,62.05],[1.99,150.14],[2.12,65.86],[2.06,35.02],[2.2,54.44],[2.96,62.81],[2.69,21.27],[2.35,63.58],[2.19,18.06],[2.44,45.66],[3.31,1.08],[3.36,0.92],[2.31,34.1],[2.42,28.64],[2.15,63.98],[2.11,64.11],[2.4,16.42],[2.36,8.04],[2.73,14.28],[2.78,5.68],[2.91,34.62],[2.28,9.72],[2.13,27.84],[3,1.96]],"ltp":1.83,"batl":[[0,1.83,126.9],[2,1.85,147.81],[1,1.84,123.46]],"id":51922},{"tv":2106.85,"batb":[[0,32,21.4],[2,29,17.28],[1,30,26.78]],"trd":[[32,102.26],[34,59.27],[30,98.92],[29,33.78],[28,13.55],[27,76.14],[24,159.55],[22,369.08],[21,95.09],[20,118.21],[19,83.43],[12.09,32.69],[10.75,9.03],[8.6,24.05],[8.42,7.07],[11.2,51.79],[26,15.3],[25,132.99],[23,193.49],[19.5,60.86],[18.5,37.06],[8.96,14],[15.5,2.4],[11.65,58.87],[18,49.73],[16.57,6.52],[17.5,9.19],[17,3.22],[15,4.56],[14.33,6.54],[16.12,16.6],[17.02,1.06],[6.99,28.31],[8.06,7.06],[19.71,0.02],[15.23,5.04],[10.3,11.33],[13.89,2.3],[12.99,2],[15.68,12],[18.81,1.13],[8.24,6],[9.85,56.42],[14.78,3.9],[8.78,10.16],[9.41,7.88],[12.54,7]],"ltp":32,"batl":[[2,38,20.19],[0,34,6.66],[1,36,13.54]],"id":49744721},{"tv":12520.75,"batb":[[0,4.5,162.98],[2,4.3,231.29],[1,4.4,256.33]],"trd":[[4.5,2118.43],[4.6,734.31],[4.7,63.37],[4.4,3191.83],[4.21,12.99],[4.2,1393.25],[4.1,221.18],[3.94,170.23],[4.12,58.44],[3.85,157.1],[4.3,3832.79],[3.58,47.62],[3.76,226.51],[4,62.58],[4.9,0.42],[4.8,7.84],[3.67,68.45],[3.4,22.58],[4.39,13.74],[3.54,5.14],[4.66,3.36],[4.03,70.61],[3.49,14],[3.45,3.98],[4.48,20]],"ltp":4.5,"batl":[[2,4.8,345.88],[0,4.6,88.25],[1,4.7,89.26]],"id":50466254},{"tv":425.31,"batb":[[0,140,2.74],[2,120,5.45],[1,130,4.57]],"trd":[[140,49.1],[150,24.01],[130,66.58],[170,17.59],[160,6.02],[120,36.67],[110,49],[100,38.99],[90,7.91],[95,8.65],[98.54,3.78],[80,3.9],[22.4,16],[32.25,4.62],[180,0.02],[190,0.04],[85,1.79],[75,2.4],[70,1.6],[26.87,1.22],[85.1,4.14],[41.21,5.47],[28.67,2.38],[49.27,1.7],[39.42,1.84],[71.67,2.74],[37.62,5.9],[23.29,24],[24.19,11.88],[17.47,0.6],[89.58,2],[58.23,2],[30.46,12.14],[44.79,3.75],[34.04,1.92],[53.75,1.7],[76.15,1.26]],"ltp":140,"batl":[[2,190,3.94],[1,170,1.58],[0,160,1.95]],"id":66251581},{"tv":1278.11,"batb":[[0,32,11.66],[1,30,30.6],[2,29,15.26]],"trd":[[32,112.79],[30,77.2],[29,152.54],[28,177.39],[27,164.97],[26,192.94],[25,155.77],[24,36.57],[25.08,40.58],[34,62.14],[40,1.58],[38,1.13],[36,12.43],[14.33,0.72],[16.12,3.79],[17.02,13.99],[21.5,1.7],[20.6,8.68],[28.67,0.85],[23.29,8.44],[24.19,9.7],[17.92,3.74],[17.47,7.42],[16.57,5.76],[30.46,1.14],[35.83,0.26],[18.81,1.22],[22.4,4.79],[34.04,7.24],[14.78,3.82],[15.23,5.46],[32.25,1.36]],"ltp":32,"batl":[[1,36,8.39],[2,38,4.64],[0,34,14.4]],"id":106596}],"img":true,"tv":82241.21}],"ArrivalTime":1710507917484}
{"op":"mcm","id":2,"clk":"AAoADQAL","pt":1710507917588,"mc":[{"id":"1.226122413","rc":[{"batl":[[0,4.6,91.25]],"id":50466254}]}],"ArrivalTime":1710507917591}
{"op":"mcm","id":2,"clk":"ABAAFAAU","pt":1710507917692,"mc":[{"id":"1.226122413","rc":[{"batb":[[1,1.81,208.15]],"id":51922}]}],"ArrivalTime":1710507917695}
{"op":"mcm","id":2,"clk":"ABQAJAAp","pt":1710507917847,"mc":[{"id":"1.226122413","rc":[{"tv":57307.12,"batb":[[0,1.82,136.19]],"trd":[[1.83,6250.82],[1.82,3610.23]],"ltp":1.82,"batl":[[0,1.83,119.94]],"id":51922},{"tv":12524.75,"trd":[[4.6,738.31]],"ltp":4.6,"batl":[[0,4.6,89.25]],"id":50466254}],"tv":82270.33}],"ArrivalTime":1710507917850}
{"op":"mcm","id":2,"clk":"ACgAPABG","pt":1710507918162,"mc":[{"id":"1.226122413","rc":[{"tv":57320.78,"batb":[[2,1.8,478.55],[0,1.82,129.36]],"trd":[[1.82,3623.89]],"id":51922},{"batb":[[2,29,21.92]],"id":106596}],"tv":82283.99}],"ArrivalTime":1710507918165}
{"op":"mcm","id":2,"clk":"ADMARQBN","pt":1710507918264,"mc":[{"id":"1.226122413","rc":[{"tv":6403.64,"batb":[[0,8.2,45.91]],"trd":[[8.2,34.9]],"batl":[[0,8.4,16.05]],"id":41122648},{"batb":[[0,1.82,159.42]],"id":51922}],"tv":82287.99}],"ArrivalTime":1710507918267}
{"op":"mcm","id":2,"clk":"ADkATwBX","pt":1710507918363,"mc":[{"id":"1.226122413","rc":[{"batl":[[1,8.6,47.03]],"id":41122648},{"batl":[[2,38,22.89]],"id":49744721},{"batl":[[2,4.8,44.88]],"id":50466254},{"batb":[[1,30,38.22]],"batl":[],"id":106596}]}],"ArrivalTime":1710507918366}
{"op":"mcm","id":2,"clk":"AD0AUQBd","pt":1710507918472,"mc":[{"id":"1.226122413","rc":[{"batb":[[0,8.2,42.57]],"id":41122648},{"batb":[[0,140,3.74]],"id":66251581}]}],"ArrivalTime":1710507918476}
{"op":"mcm","id":2,"clk":"AEcAXQBq","pt":1710507918578,"mc":[{"id":"1.226122413","rc":[{"tv":6435.74,"batb":[[2,8,66.88],[1,8.2,42.57],[0,8.4,3.95]],"trd":[[8.4,493.35]],"ltp":8.4,"batl":[[2,9,34.25],[1,8.8,22.38],[0,8.6,47.03]],"id":41122648}],"tv":82320.09}],"ArrivalTime":1710507918581}
{"op":"mcm","id":2,"clk":"AE0AYwB2","pt":1710507918681,"mc":[{"id":"1.226122413","rc":[{"batb":[],"batl":[[0,8.6,31.56]],"id":41122648},{"batb":[[0,4.5,191.55]],"id":50466254}]}],"ArrivalTime":1710507918684}
{"op":"mcm","id":2,"clk":"AFIAZwCBAQ==","pt":1710507918786,"mc":[{"id":"1.226122413","rc":[{"tv":6441.42,"batb":[[1,8.2,49.23],[0,8.4,1.11]],"trd":[[8.4,499.03]],"id":41122648},{"tv":339.73,"batb":[[0,200,7.98]],"trd":[[210,19.88]],"batl":[[2,240,5.25],[1,230,6.42],[0,210,5.76]],"id":41200638},{"batb":[[1,1.81,210.15]],"id":51922}],"tv":82326.25}],"ArrivalTime":1710507918789}
{"op":"mcm","id":2,"clk":"AFkAbACJAQ==","pt":1710507918886,"mc":[{"id":"1.226122413","rc":[{"tv":6443.64,"batb":[[2,7.8,85.87],[1,8,66.88],[0,8.2,49.23]],"trd":[[8.4,501.25]],"batl":[[0,8.6,32.45]],"id":41122648}],"tv":82328.47}],"ArrivalTime":1710507918889}
{"op":"mcm","id":2,"clk":"AF4AeACVAQ==","pt":1710507918989,"mc":[{"id":"1.226122413","rc":[{"batl":[[2,8.8,22.38],[1,8.6,31.56],[0,8.4,1.96]],"id":41122648},{"batb":[[1,190,2.54],[0,200,6.63]],"id":41200638}]}],"ArrivalTime":1710507918994}
{"op":"mcm","id":2,"clk":"AHEAiAEApwE=","pt":1710507919152,"mc":[{"id":"1.226122413","rc":[{"tv":310.01,"batb":[[2,270,1.77],[1,290,1.49],[0,300,2.22]],"trd":[[320,23.81]],"id":54370634},{"batl":[[0,8.4,13.21]],"id":41122648},{"batl":[[0,4.6,84.25]],"id":50466254}],"tv":82332.02}],"ArrivalTime":1710507919156}
{"op":"mcm","id":2,"clk":"AHcAlQEAswE=","pt":1710507919317,"mc":[{"id":"1.226122413","rc":[{"tv":57340.78,"trd":[[1.83,6270.82]],"ltp":1.83,"batl":[[0,1.83,109.94]],"id":51922},{"tv":12545.47,"batb":[[0,4.5,186.55]],"trd":[[4.6,749.03],[4.5,2128.43]],"ltp":4.5,"batl":[[0,4.6,78.89]],"id":50466254}],"tv":82372.74}],"ArrivalTime":1710507919321}
{"op":"mcm","id":2,"clk":"AHkAngEAwAE=","pt":1710507919364,"mc":[{"id":"1.226122413","rc":[{"tv":6447.98,"batb":[[0,8.2,47.06]],"trd":[[8.2,39.24]],"ltp":8.2,"id":41122648}],"tv":82377.08}],"ArrivalTime":1710507919367}
{"op":"mcm","id":2,"clk":"AHsAoQEAygE=","pt":1710507919462,"mc":[{"id":"1.226122413","rc":[{"batl":[[0,8.4,12.32]],"id":41122648},{"tv":1282.1,"batb":[[0,32,9.67]],"trd":[[32,116.78]],"id":106596}],"tv":82381.07}],"ArrivalTime":1710507919465}
{"op":"mcm","id":2,"clk":"AIIBAKwBANMB","pt":1710507919567,"mc":[{"id":"1.226122413","rc":[{"batb":[[0,32,10.82]],"id":106596}]}],"ArrivalTime":1710507919570}
{"op":"mcm","id":2,"clk":"AIgBALABANoB","pt":1710507919670,"mc":[{"id":"1.226122413","rc":[{"batb":[[1,1.81,212.15]],"id":51922},{"batl":[[0,160,7.36]],"id":66251581},{"batb":[[1,30,37.07]],"id":106596}]}],"ArrivalTime":1710507919673}
{"op":"mcm","id":2,"clk":"AI8BALsBAOcB","pt":1710507919773,"mc":[{"id":"1.226122413","rc":[{"batl":[[1,8.6,48.99]],"id":41122648}]}],"ArrivalTime":1710507919776}
{"op":"mcm","id":2,"clk":"AJMBAMUBAPEB","pt":1710507919876,"mc":[{"id":"1.226122413","rc":[{"batl":[[0,8.4,18.81]],"id":41122648},{"batb":[[2,180,2.24]],"id":41200638}]}],"ArrivalTime":1710507919879}
{"op":"mcm","id":2,"clk":"AJoBANABAPwB","pt":1710507919978,"mc":[{"id":"1.226122413","rc":[{"tv":57400.78,"batb":[[0,1.82,129.42]],"trd":[[1.82,3683.89]],"ltp":1.82,"id":51922}],"tv":82441.07}],"ArrivalTime":1710507919981}
{"op":"mcm","id":2,"clk":"AK0BAPMBAJsC","pt":1710507920296,"mc":[{"id":"1.226122413","rc":[{"batl":[[2,420,2.25],[1,360,3],[0,350,1]],"id":54370634}]}],"ArrivalTime":1710507920299}
{"op":"mcm","id":2,"clk":"ALoBAIcCALMC","pt":1710507920504,"mc":[{"id":"1.226122413","rc":[{"batb":[[1,1.81,214.15]],"id":51922},{"batb":[],"batl":[[0,4.6,76.11]],"id":50466254}]}],"ArrivalTime":1710507920507}
{"op":"mcm","id":2,"clk":"AL8BAIsCALsC","pt":1710507920559,"mc":[{"id":"1.226122413","rc":[{"batl":[[1,4.7,38.26],[0,4.6,56.11]],"id":50466254}]}],"ArrivalTime":1710507920562}
{"op":"mcm","id":2,"clk":"AMoBAJYCAMcC","pt":1710507920662,"mc":[{"id":"1.226122413","rc":[{"batb":[[2,260,5.39],[1,270,1.77]],"id":54370634},{"batb":[[0,8.2,40.4]],"batl":[[0,8.4,28.81]],"id":41122648},{"batl":[[0,4.6,34.31]],"id":50466254}]}],"ArrivalTime":1710507920665}
{"op":"mcm","id":2,"clk":"AM0BAJ0CANEC","pt":1710507920763,"mc":[{"id":"1.226122413","rc":[{"tv":57440.78,"batb":[[0,1.82,109.42]],"trd":[[1.82,3723.89]],"id":51922}],"tv":82481.07}],"ArrivalTime":1710507920766}
{"op":"mcm","id":2,"clk":"ANoBAKcCANwC","pt":1710507920870,"mc":[{"id":"1.226122413","rc":[{"batl":[[1,8.6,47.34]],"id":41122648}]}],"ArrivalTime":1710507920875}
{"op":"mcm","id":2,"clk":"AOgBALkCAPAC","pt":1710507921070,"mc":[{"id":"1.226122413","rc":[{"batl":[[0,1.83,131.45]],"id":51922}]}],"ArrivalTime":1710507921074}
{"op":"mcm","id":2,"clk":"AOwBAMMCAPsC","pt":1710507921176,"mc":[{"id":"1.226122413","rc":[{"batb":[[1,1.81,216.15]],"id":51922}]}],"ArrivalTime":1710507921179}
{"op":"mcm","id":2,"clk":"APQBAM4CAIYD","pt":1710507921281,"mc":[{"id":"1.226122413","rc":[{"batl":[[2,400,3.32]],"id":54370634},{"tv":57460.78,"trd":[[1.83,6290.82]],"ltp":1.83,"batl":[[0,1.83,121.45]],"id":51922}],"tv":82501.07}],"ArrivalTime":1710507921285}
{"op":"mcm","id":2,"clk":"AP8BANUCAJUD","pt":1710507921386,"mc":[{"id":"1.226122413","rc":[{"batl":[[0,8.4,43.07]],"id":41122648},{"tv":57474.22,"batb":[[0,1.82,102.7]],"trd":[[1.82,3737.33]],"ltp":1.82,"id":51922}],"tv":82514.51}],"ArrivalTime":1710507921389}
{"op":"mcm","id":2,"clk":"AJECAOgCAKwD","pt":1710507921592,"mc":[{"id":"1.226122413","rc":[{"batb":[[0,1.82,302.7]],"id":51922},{"batl":[[0,4.6,36.33]],"id":50466254}]}],"ArrivalTime":1710507921595}
{"op":"mcm","id":2,"clk":"AL4CAKUDAPsD","pt":1710507922329,"mc":[{"id":"1.226122413","rc":[{"batb":[],"batl":[[0,8.4,33.07]],"id":41122648},{"tv":357.01,"batb":[[2,160,2.34],[0,180,2],[1,170,14.59]],"trd":[[200,64.5]],"ltp":200,"batl":[[0,200,2.36],[2,230,6.42],[1,210,5.76]],"id":41200638},{"batb":[[2,24,22.58]],"batl":[],"id":55632148},{"tv":57565.34,"batb":[[0,1.83,49.34],[1,1.82,395.7],[2,1.81,218.15]],"trd":[[1.83,6381.94]],"ltp":1.83,"batl":[[2,1.86,622.85],[1,1.85,147.81],[0,1.84,123.46]],"id":51922},{"tv":12553.19,"batb":[[2,4.3,227.68],[0,4.5,182.69]],"trd":[[4.5,2136.15]],"batl":[[0,4.6,38.55]],"id":50466254},{"batb":[[2,120,6.53]],"id":66251581}],"tv":82630.63,"con":true}],"ArrivalTime":1710507922332}
{"op":"mcm","id":2,"clk":"AMECAKgDAP8D","pt":1710507922375,"mc":[{"id":"1.226122413","rc":[{"batb":[[0,1.83,69.86]],"id":51922}]}],"ArrivalTime":1710507922379}
{"op":"mcm","id":2,"clk":"ANICAMQDAJQE","pt":1710507922575,"mc":[{"id":"1.226122413","rc":[{"batb":[[2,160,4.04]],"id":41200638},{"tv":57568.32,"batb":[[0,1.83,68.37]],"trd":[[1.83,6384.92]],"id":51922}],"tv":82633.61}],"ArrivalTime":1710507922578}
{"op":"mcm","id":2,"clk":"ANgCAMoDAKIE","pt":1710507922683,"mc":[{"id":"1.226122413","rc":[{"tv":6448.58,"trd":[[8.4,501.85]],"ltp":8.4,"batl":[[0,8.4,32.77]],"id":41122648},{"batl":[[2,230,6],[0,200,2.77]],"id":41200638},{"batb":[[0,1.83,20.52]],"id":51922}],"tv":82634.21}],"ArrivalTime":1710507922687}
{"op":"mcm","id":2,"clk":"ANkCANADAKcE","pt":1710507922778,"mc":[{"id":"1.226122413","rc":[{"batl":[[1,170,2.88]],"id":66251581}]}],"ArrivalTime":1710507922781}
{"op":"mcm","id":2,"clk":"AOICANgDALYE","pt":1710507922875,"mc":[{"id":"1.226122413","rc":[{"tv":6450.58,"batb":[[0,8.2,39.4]],"trd":[[8.2,41.24]],"ltp":8.2,"id":41122648},{"tv":57577.8,"batb":[[2,1.81,270.15],[0,1.83,15.78]],"trd":[[1.83,6394.4]],"id":51922}],"tv":82645.69}],"ArrivalTime":1710507922879}
{"op":"mcm","id":2,"clk":"AOgCAN0DAMEE","pt":1710507922983,"mc":[{"id":"1.226122413","rc":[{"batb":[[0,300,1.08]],"id":54370634},{"tv":57595.32,"batb":[[0,1.83,7.02]],"trd":[[1.83,6411.92]],"id":51922},{"tv":2110.75,"batb":[[0,32,19.44]],"trd":[[32,106.16]],"id":49744721}],"tv":82667.11}],"ArrivalTime":1710507922987}
{"op":"mcm","id":2,"clk":"AOoCAOYDAMoE","pt":1710507923082,"mc":[{"id":"1.226122413","rc":[{"batb":[[1,30,25.75],[0,32,21.91]],"id":49744721},{"tv":1302.1,"batb":[[2,28,11.12],[1,29,21.92],[0,30,37.89]],"trd":[[32,136.78]],"id":106596}],"tv":82687.11}],"ArrivalTime":1710507923086}
{"op":"mcm","id":2,"clk":"APMCAO8DANcE","pt":1710507923201,"mc":[{"id":"1.226122413","rc":[{"batb":[[1,1.82,495.7]],"id":51922},{"batb":[[1,30,28.38]],"id":49744721},{"tv":1303.74,"batb":[[0,30,37.07]],"trd":[[32,138.42]],"id":106596}],"tv":82688.75}],"ArrivalTime":1710507923204}
{"op":"mcm","id":2,"clk":"APgCAPEDAN0E","pt":1710507923297,"mc":[{"id":"1.226122413","rc":[{"batl":[[2,29,11.67]],"id":55632148}]}],"ArrivalTime":1710507923301}
{"op":"mcm","id":2,"clk":"AIADAPgDAOgE","pt":1710507923399,"mc":[{"id":"1.226122413","rc":[{"batb":[[1,1.82,545.7]],"id":51922},{"batb":[[2,29,21.92],[1,30,37.07],[0,32,2.61]],"id":106596}]}],"ArrivalTime":1710507923403}
{"op":"mcm","id":2,"clk":"AIUDAP8DAPEE","pt":1710507923508,"mc":[{"id":"1.226122413","rc":[{"tv":1305.74,"batb":[[0,32,1.61]],"trd":[[32,140.42]],"id":106596}],"tv":82690.75}],"ArrivalTime":1710507923512}
{"op":"mcm","id":2,"clk":"AIsDAIkEAPgE","pt":1710507923604,"mc":[{"id":"1.226122413","rc":[{"tv":358.69,"batb":[[0,180,1.16]],"trd":[[190,12.44],[180,15.09]],"ltp":180,"id":41200638},{"batl":[[2,29,11.03]],"id":55632148},{"batb":[[2,29,14.23]],"batl":[],"id":106596}],"tv":82692.43}],"ArrivalTime":1710507923608}
{"op":"mcm","id":2,"clk":"AI8DAI8EAIUF","pt":1710507923665,"mc":[{"id":"1.226122413","rc":[{"batl":[[0,8.4,42.77]],"id":41122648},{"batb":[[2,1.81,272.15]],"id":51922},{"batb":[[2,28,11.12],[1,29,14.23],[0,30,37.07]],"id":106596}]}],"ArrivalTime":1710507923669}
{"op":"mcm","id":2,"clk":"AJgDAJoEAI8F","pt":1710507923766,"mc":[{"id":"1.226122413","rc":[{"batb":[[0,180,2.24]],"batl":[[0,200,3.03]],"id":41200638},{"batl":[[2,29,11.67]],"id":55632148}]}],"ArrivalTime":1710507923770}
{"op":"mcm","id":2,"clk":"AKwDAK8EAKUF","pt":1710507923981,"mc":[{"id":"1.226122413","rc":[{"batl":[[2,230,8.82]],"id":41200638}]}],"ArrivalTime":1710507923985}
{"op":"mcm","id":2,"clk":"ALgDAMYEALkF","pt":1710507924182,"mc":[{"id":"1.226122413","rc":[{"tv":12555.25,"batb":[[0,4.5,181.66]],"trd":[[4.5,2138.21]],"id":50466254}],"tv":82694.49}],"ArrivalTime":1710507924186}
{"op":"mcm","id":2,"clk":"AL0DANEEAMQF","pt":1710507924286,"mc":[{"id":"1.226122413","rc":[{"tv":310.02,"batb":[[0,300,1.07]],"trd":[[320,23.82]],"batl":[[2,360,3],[1,350,1],[0,320,2.99]],"id":54370634}],"tv":82694.5}],"ArrivalTime":1710507924290}
{"op":"mcm","id":2,"clk":"AMMDANgEAMsF","pt":1710507924381,"mc":[{"id":"1.226122413","rc":[{"batl":[[2,230,9.66]],"id":41200638}]}],"ArrivalTime":1710507924384}
{"op":"mcm","id":2,"clk":"AMgDAN8EANYF","pt":1710507924491,"mc":[{"id":"1.226122413","rc":[{"tv":310.22,"batb":[[1,270,1.03],[0,280,1.71]],"trd":[[310,12.87]],"ltp":310,"id":54370634}],"tv":82694.7}],"ArrivalTime":1710507924494}
{"op":"mcm","id":2,"clk":"ANIDAOkEAN0F","pt":1710507924596,"mc":[{"id":"1.226122413","rc":[{"batb":[[2,1.81,276.15],[0,1.83,19.02]],"id":51922}]}],"ArrivalTime":1710507924600}
{"op":"mcm","id":2,"clk":"ANQDAPMEAOcF","pt":1710507924691,"mc":[{"id":"1.226122413","rc":[{"batb":[[1,1.82,551.8]],"id":51922}]}],"ArrivalTime":1710507924695}
{"op":"mcm","id":2,"clk":"ANoDAPsEAO8F","pt":1710507924801,"mc":[{"id":"1.226122413","rc":[{"tv":310.4,"batb":[[0,280,1.62]],"trd":[[310,13.05]],"id":54370634},{"batb":[[0,1.83,76.48]],"id":51922},{"tv":12561.25,"batb":[[0,4.5,178.66]],"trd":[[4.5,2144.21]],"id":50466254}],"tv":82700.88}],"ArrivalTime":1710507924805}
{"op":"mcm","id":2,"clk":"AOADAIgFAPcF","pt":1710507924899,"mc":[{"id":"1.226122413","rc":[{"batb":[[1,1.82,562.63]],"id":51922},{"batb":[[1,29,15.26]],"id":106596}]}],"ArrivalTime":1710507924903}
{"op":"mcm","id":2,"clk":"AOcDAJAFAIAG","pt":1710507925002,"mc":[{"id":"1.226122413","rc":[{"tv":310.5,"batb":[[0,280,1.57]],"trd":[[310,13.15]],"batl":[[2,400,3.32],[1,360,3]],"id":54370634}],"tv":82700.98}],"ArrivalTime":1710507925006}
{"op":"mcm","id":2,"clk":"APADAJkFAI4G","pt":1710507925108,"mc":[{"id":"1.226122413","rc":[{"batb":[[1,1.82,508.75]],"id":51922}]}],"ArrivalTime":1710507925112}
{"op":"mcm","id":2,"clk":"AP4DAKwFAKUG","pt":1710507925272,"mc":[{"id":"1.226122413","rc":[{"batb":[[1,1.82,308.75]],"id":51922}]}],"ArrivalTime":1710507925276}
{"op":"mcm","id":2,"clk":"AIQEALkFAK0G","pt":1710507925374,"mc":[{"id":"1.226122413","rc":[{"batl":[[1,210,5.88],[0,200,3.33]],"id":41200638},{"batb":[[0,1.83,276.48]],"id":51922}]}],"ArrivalTime":1710507925378}
{"op":"mcm","id":2,"clk":"AIwEAL0FALYG","pt":1710507925475,"mc":[{"id":"1.226122413","rc":[{"batb":[[0,1.83,282.5]],"batl":[[2,1.86,616.13]],"id":51922},{"batl":[[2,36,8.39],[1,34,14.4],[0,32,3.73]],"id":106596}]}],"ArrivalTime":1710507925479}
{"op":"mcm","id":2,"clk":"AJIEAMgFAMEG","pt":1710507925574,"mc":[{"id":"1.226122413","rc":[{"tv":6456.58,"batb":[[0,8.2,36.4]],"trd":[[8.2,47.24]],"id":41122648},{"batl":[[1,210,5.76],[0,200,3.03]],"id":41200638},{"batb":[[0,1.83,304.41]],"id":51922}],"tv":82706.98}],"ArrivalTime":1710507925578}
{"op":"mcm","id":2,"clk":"AJsEAMwFAMkG","pt":1710507925679,"mc":[{"id":"1.226122413","rc":[{"batl":[[0,200,9.03]],"id":41200638},{"batb":[[1,1.82,301.8]],"batl":[[0,1.84,96.88]],"id":51922},{"batl":[[0,4.6,36.33]],"id":50466254}]}],"ArrivalTime":1710507925683}
{"op":"mcm","id":2,"clk":"AKYEAN8FAOAG","pt":1710507925881,"mc":[{"id":"1.226122413","rc":[{"batb":[[1,8,78.73]],"id":41122648}]}],"ArrivalTime":1710507925885}
{"op":"mcm","id":2,"clk":"AKsEAOYFAOgG","pt":1710507925985,"mc":[{"id":"1.226122413","rc":[{"tv":57597.03,"batb":[[2,1.81,226.15],[1,1.82,303.8],[0,1.83,403.56]],"trd":[[1.83,6413.63]],"id":51922}],"tv":82708.69}],"ArrivalTime":1710507925990}
{"op":"mcm","id":2,"clk":"ALIEAPMFAPIG","pt":1710507926089,"mc":[{"id":"1.226122413","rc":[{"batl":[[0,8.4,28.51]],"id":41122648}]}],"ArrivalTime":1710507926092}
{"op":"mcm","id":2,"clk":"ALUEAP0FAP4G","pt":1710507926203,"mc":[{"id":"1.226122413","rc":[{"tv":12566.97,"batb":[[0,4.5,175.8]],"trd":[[4.5,2149.93]],"id":50466254}],"tv":82714.41}],"ArrivalTime":1710507926207}
{"op":"mcm","id":2,"clk":"AM8EAKUGAKsH","pt":1710507926704,"mc":[{"id":"1.226122413","rc":[{"batl":[[0,8.4,30.51]],"id":41122648}]}],"ArrivalTime":1710507926708}
{"op":"mcm","id":2,"clk":"ANQEALgGALwH","pt":1710507926860,"mc":[{"id":"1.226122413","rc":[{"batb":[[2,160,4.23]],"id":41200638}]}],"ArrivalTime":1710507926864}
{"op":"mcm","id":2,"clk":"AOUEANAGANUH","pt":1710507927168,"mc":[{"id":"1.226122413","rc":[{"tv":57609.03,"batb":[[0,1.83,405.56]],"trd":[[1.84,9292.29]],"ltp":1.84,"batl":[[0,1.84,90.88]],"id":51922}],"tv":82726.41}],"ArrivalTime":1710507927172}
{"op":"mcm","id":2,"clk":"AOoEANYGANwH","pt":1710507927270,"mc":[{"id":"1.226122413","rc":[{"batl":[[0,4.6,69.32]],"id":50466254}]}],"ArrivalTime":1710507927274}
{"op":"mcm","id":2,"clk":"AIQFAO8GAP0H","pt":1710507927584,"mc":[{"id":"1.226122413","rc":[{"batl":[[0,8.4,20.51]],"id":41122648},{"batb":[[0,1.83,205.56]],"id":51922}]}],"ArrivalTime":1710507927588}
{"op":"mcm","id":2,"clk":"AJEFAP4GAJAI","pt":1710507927786,"mc":[{"id":"1.226122413","rc":[{"batl":[[0,1.84,113.37]],"id":51922}]}],"ArrivalTime":1710507927790}
{"op":"mcm","id":2,"clk":"AJwFAIoHAJYI","pt":1710507927897,"mc":[{"id":"1.226122413","rc":[{"batl":[[2,230,6.84]],"id":41200638},{"tv":12567.17,"batb":[[0,4.5,175.7]],"trd":[[4.5,2150.13]],"id":50466254}],"tv":82726.61}],"ArrivalTime":1710507927901}
{"op":"mcm","id":2,"clk":"AKIFAJMHAKMI","pt":1710507928011,"mc":[{"id":"1.226122413","rc":[{"batb":[[0,1.83,183.65]],"id":51922}]}],"ArrivalTime":1710507928015}
{"op":"mcm","id":2,"clk":"AKQFAJsHAK0I","pt":1710507928105,"mc":[{"id":"1.226122413","rc":[{"tv":57618.71,"batb":[[0,1.83,180.81]],"trd":[[1.83,6423.31]],"ltp":1.83,"id":51922}],"tv":82736.29}],"ArrivalTime":1710507928109}
{"op":"mcm","id":2,"clk":"AKwFAKYHALgI","pt":1710507928231,"mc":[{"id":"1.226122413","rc":[{"tv":12597.05,"trd":[[4.6,778.91]],"ltp":4.6,"batl":[[0,4.6,54.39]],"id":50466254}],"tv":82766.17}],"ArrivalTime":1710507928235}
{"op":"mcm","id":2,"clk":"AMEFALsHAMoI","pt":1710507928410,"mc":[{"id":"1.226122413","rc":[{"batb":[[0,1.83,123.35]],"id":51922},{"tv":12614.32,"trd":[[4.6,796.18]],"batl":[[0,4.6,12.76]],"id":50466254}],"tv":82783.44}],"ArrivalTime":1710507928414}
{"op":"mcm","id":2,"clk":"ANMFAMkHANsI","pt":1710507928625,"mc":[{"id":"1.226122413","rc":[{"tv":57646.79,"batb":[[0,1.83,109.31]],"trd":[[1.83,6451.39]],"id":51922},{"batb":[[0,30,31.36]],"batl":[],"id":106596}],"tv":82811.52}],"ArrivalTime":1710507928633}
{"op":"mcm","id":2,"clk":"ANkFANIHAOMI","pt":1710507928685,"mc":[{"id":"1.226122413","rc":[{"tv":57656.85,"batb":[[0,1.83,104.28]],"trd":[[1.83,6461.45]],"id":51922}],"tv":82821.58}],"ArrivalTime":1710507928689}
{"op":"mcm","id":2,"clk":"AOYFAN8HAOwI","pt":1710507928787,"mc":[{"id":"1.226122413","rc":[{"tv":57865.41,"batb":[[2,1.8,435.02],[1,1.81,226.15],[0,1.82,303.8]],"trd":[[1.83,6670.01]],"batl":[[2,1.85,147.81],[1,1.84,113.37],[0,1.83,62.77]],"id":51922},{"batb":[[0,140,4.79]],"id":66251581}],"tv":83030.14}],"ArrivalTime":1710507928791}
{"op":"mcm","id":2,"clk":"AO0FAOUHAPII","pt":1710507928885,"mc":[{"id":"1.226122413","rc":[{"batl":[[2,420,1.75],[1,400,3.32],[0,360,3]],"id":54370634},{"tv":57883.53,"batb":[[0,1.82,294.74]],"trd":[[1.82,3755.45]],"ltp":1.82,"batl":[],"id":51922},{"batb":[[2,4.3,231.29]],"batl":[[0,4.6,5.02]],"id":50466254}],"tv":83048.26}],"ArrivalTime":1710507928890}
{"op":"mcm","id":2,"clk":"APIFAO8HAPoI","pt":1710507928988,"mc":[{"id":"1.226122413","rc":[{"tv":312.17,"batb":[[2,250,3],[1,260,5.39],[0,270,1.77]],"trd":[[310,14.17],[300,14.73]],"ltp":300,"batl":[[2,400,3.32],[1,360,3],[0,300,2.16]],"id":54370634},{"batb":[[0,8.2,43.32]],"id":41122648},{"batb":[[0,180,3.74]],"batl":[],"id":41200638},{"tv":57914.05,"trd":[[1.83,6700.53]],"ltp":1.83,"batl":[[0,1.83,47.51]],"id":51922},{"batb":[[0,4.5,194.18]],"batl":[],"id":50466254}],"tv":83080.45}],"ArrivalTime":1710507928992}
{"op":"mcm","id":2,"clk":"APsFAPcHAIgJ","pt":1710507929109,"mc":[{"id":"1.226122413","rc":[{"batb":[[2,260,5.39],[1,270,1.03],[0,280,1.12]],"batl":[],"id":54370634},{"batl":[[1,1.84,119.36]],"id":51922},{"batb":[[2,4.3,227.68]],"id":50466254}]}],"ArrivalTime":1710507929113}
{"op":"mcm","id":2,"clk":"AIsGAJEIAJ8J","pt":1710507929356,"mc":[{"id":"1.226122413","rc":[{"batb":[[2,260,4.39]],"batl":[],"id":54370634},{"batb":[[0,8.2,50.49]],"id":41122648},{"tv":358.99,"trd":[[190,12.74]],"ltp":190,"batl":[[0,200,9.18],[1,210,5.88]],"id":41200638},{"tv":58009.07,"batb":[[2,1.81,226.15],[1,1.82,294.74],[0,1.83,152.49]],"trd":[[1.83,6795.55]],"batl":[[2,1.86,626.13],[1,1.85,147.81],[0,1.84,119.36]],"id":51922}],"tv":83175.77,"con":true}],"ArrivalTime":1710507929360}
{"op":"mcm","id":2,"clk":"AJcGAJoIAKgJ","pt":1710507929506,"mc":[{"id":"1.226122413","rc":[{"batl":[[2,360,3],[1,350,1]],"id":54370634},{"batb":[[0,180,2.24]],"batl":[[2,230,6.95]],"id":41200638}]}],"ArrivalTime":1710507929510}
{"op":"mcm","id":2,"clk":"AJ4GAJ0IALQJ","pt":1710507929607,"mc":[{"id":"1.226122413","rc":[{"batl":[[0,34,8.66]],"id":49744721}]}],"ArrivalTime":1710507929611}
{"op":"mcm","id":2,"clk":"AKEGAKoIAMQJ","pt":1710507929714,"mc":[{"id":"1.226122413","rc":[{"tv":58017.31,"trd":[[1.84,9300.53]],"ltp":1.84,"batl":[[0,1.84,115.24]],"id":51922}],"tv":83184.01}],"ArrivalTime":1710507929718}
{"op":"mcm","id":2,"clk":"ALIGALYIANsJ","pt":1710507929932,"mc":[{"id":"1.226122413","rc":[{"batl":[[2,230,6.84],[1,210,5.76],[0,200,9.03]],"id":41200638},{"tv":58026.39,"trd":[[1.84,9309.61]],"batl":[[0,1.84,110.7]],"id":51922}],"tv":83193.09}],"ArrivalTime":1710507929936}
{"op":"mcm","id":2,"clk":"ALcGALwIAOYJ","pt":1710507929973,"mc":[{"id":"1.226122413","rc":[{"batb":[[0,1.83,212.67]],"id":51922}]}],"ArrivalTime":1710507929977}
{"op":"mcm","id":2,"clk":"AL4GAMMIAPUJ","pt":1710507930075,"mc":[{"id":"1.226122413","rc":[{"batb":[[2,250,4],[1,260,4.39],[0,270,1.41]],"batl":[[2,400,3.32],[1,360,3]],"id":54370634},{"batl":[[2,210,5.76],[1,200,9.03],[0,190,1.07]],"id":41200638},{"tv":58036.39,"batb":[[0,1.83,207.67]],"trd":[[1.83,6805.55]],"ltp":1.83,"batl":[[1,1.85,211.73]],"id":51922}],"tv":83203.09}],"ArrivalTime":1710507930079}
{"op":"mcm","id":2,"clk":"AL8GAMsIAPsJ","pt":1710507930175,"mc":[{"id":"1.226122413","rc":[{"tv":360.99,"trd":[[190,14.74]],"batl":[[2,230,6.84],[1,210,5.76],[0,200,8.98]],"id":41200638},{"batb":[[0,1.83,230.82]],"batl":[[1,1.85,147.81]],"id":51922},{"tv":428.53,"batb":[[0,140,3.19]],"trd":[[140,52.32]],"batl":[],"id":66251581}],"tv":83208.31}],"ArrivalTime":1710507930180}
{"op":"mcm","id":2,"clk":"AM0GANIIAIUK","pt":1710507930335,"mc":[{"id":"1.226122413","rc":[{"batb":[[0,270,1.74]],"id":54370634},{"batb":[[0,180,3.84]],"batl":[[0,200,8.84]],"id":41200638},{"batb":[[1,1.82,299.77]],"id":51922},{"batl":[[2,170,2.88],[1,160,6.94],[0,150,1.83]],"id":66251581}]}],"ArrivalTime":1710507930339}
{"op":"mcm","id":2,"clk":"ANUGAOAIAJEK","pt":1710507930385,"mc":[{"id":"1.226122413","rc":[{"tv":58096.39,"batb":[[0,1.83,200.82]],"trd":[[1.83,6865.55]],"id":51922},{"batb":[[2,120,5.45]],"batl":[],"id":66251581}],"tv":83268.31}],"ArrivalTime":1710507930389}
{"op":"mcm","id":2,"clk":"AN0GAOwIAJsK","pt":1710507930490,"mc":[{"id":"1.226122413","rc":[{"batb":[[2,160,3.39]],"id":41200638},{"batb":[[2,120,5.84],[0,140,2.13]],"id":66251581}]}],"ArrivalTime":1710507930494}
{"op":"mcm","id":2,"clk":"AOQGAPcIAKIK","pt":1710507930588,"mc":[{"id":"1.226122413","rc":[{"tv":6551.82,"batb":[[0,8.2,2.87]],"trd":[[8.2,142.48]],"batl":[[0,8.4,34.65]],"id":41122648},{"tv":58166.39,"batb":[[0,1.83,165.82]],"trd":[[1.83,6935.55]],"id":51922},{"tv":432.53,"batb":[[2,110,1.82],[1,120,5.84],[0,130,4.69]],"trd":[[140,56.32]],"id":66251581}],"tv":83437.55}],"ArrivalTime":1710507930592}
{"op":"mcm","id":2,"clk":"APEGAIAJAKgK","pt":1710507930699,"mc":[{"id":"1.226122413","rc":[{"tv":6557.56,"batb":[[2,7.6,47.9],[1,7.8,85.87],[0,8,78.73]],"trd":[[8.2,148.22]],"batl":[[2,8.6,47.34],[1,8.4,28.82],[0,8.2,11.38]],"id":41122648}],"tv":83443.29}],"ArrivalTime":1710507930703}
{"op":"mcm","id":2,"clk":"APoGAIMJALAK","pt":1710507930801,"mc":[{"id":"1.226122413","rc":[{"tv":6567.56,"trd":[[8.2,158.22]],"batl":[[0,8.2,10.3]],"id":41122648},{"batl":[[1,28,26.95]],"id":55632148},{"tv":432.78,"batb":[[1,120,5.45],[0,130,5.27]],"trd":[[140,56.57]],"batl":[[2,160,6.94],[1,150,1.83],[0,140,1.18]],"id":66251581}],"tv":83453.54}],"ArrivalTime":1710507930805}
{"op":"mcm","id":2,"clk":"AIQHAIgJALgK","pt":1710507930902,"mc":[{"id":"1.226122413","rc":[{"tv":6597.08,"batb":[[2,7.8,85.87],[1,8,78.73],[0,8.2,5.43]],"trd":[[8.2,187.74]],"batl":[[2,8.8,22.38],[1,8.6,47.34],[0,8.4,28.82]],"id":41122648},{"batl":[[0,1.84,82.22]],"id":51922},{"batb":[[2,4.3,167.68]],"id":50466254},{"batl":[[0,140,2.67]],"id":66251581}],"tv":83483.06}],"ArrivalTime":1710507930906}
{"op":"mcm","id":2,"clk":"AI8HAJcJAMEK","pt":1710507931016,"mc":[{"id":"1.226122413","rc":[{"batl":[[2,360,3],[1,350,2.82]],"id":54370634},{"batb":[[2,7.8,69.99]],"id":41122648},{"batb":[[0,1.83,167.82]],"id":51922},{"tv":433.34,"batb":[[1,120,5.84],[0,130,5.6]],"trd":[[140,57.13]],"batl":[[1,150,1.41],[0,140,2.39]],"id":66251581}],"tv":83483.62}],"ArrivalTime":1710507931020}
{"op":"mcm","id":2,"clk":"AJ4HAKoJANUK","pt":1710507931220,"mc":[{"id":"1.226122413","rc":[{"tv":6601.08,"batb":[[0,8.2,3.43]],"trd":[[8.2,191.74]],"id":41122648}],"tv":83487.62}],"ArrivalTime":1710507931225}
{"op":"mcm","id":2,"clk":"AK0HAMMJAN0K","pt":1710507931376,"mc":[{"id":"1.226122413","rc":[{"tv":6607.94,"batb":[[2,7.6,59.25],[1,7.8,69.99],[0,8,78.73]],"trd":[[8.2,198.6]],"batl":[[2,8.6,47.34],[1,8.4,28.82],[0,8.2,11.37]],"id":41122648},{"batb":[[0,130,5.27]],"id":66251581}],"tv":83494.48}],"ArrivalTime":1710507931380}
{"op":"mcm","id":2,"clk":"ALAHAMkJAOQK","pt":1710507931477,"mc":[{"id":"1.226122413","rc":[{"batb":[[2,7.6,61.29]],"batl":[[0,8.2,17.1]],"id":41122648}]}],"ArrivalTime":1710507931482}
{"op":"mcm","id":2,"clk":"AMwHAOwJAPcK","pt":1710507931791,"mc":[{"id":"1.226122413","rc":[{"batl":[[2,8.6,31.56]],"id":41122648},{"batb":[[0,1.83,170.23]],"id":51922}]}],"ArrivalTime":1710507931796}
{"op":"mcm","id":2,"clk":"ANcHAPsJAIYL","pt":1710507931991,"mc":[{"id":"1.226122413","rc":[{"tv":6652.67,"trd":[[8.4,512.39],[8.2,232.79]],"ltp":8.4,"batl":[[2,8.8,22.38],[1,8.6,31.56],[0,8.4,21.55]],"id":41122648}],"tv":83539.21}],"ArrivalTime":1710507931997}
{"op":"mcm","id":2,"clk":"ANwHAIEKAI0L","pt":1710507932095,"mc":[{"id":"1.226122413","rc":[{"tv":314.75,"trd":[[300,17.31]],"batl":[[2,400,3.32],[1,360,3],[0,350,3.69]],"id":54370634},{"batb":[[2,7.6,62.6]],"id":41122648},{"tv":1604.49,"batb":[[2,23,13.81],[1,24,22.58],[0,25,13.66]],"trd":[[26,255.65]],"id":55632148},{"batb":[[0,1.83,172.23]],"id":51922},{"tv":2128.07,"batb":[],"trd":[[34,76.59]],"ltp":34,"batl":[[2,40,6.51],[1,38,22.89],[0,36,13.54]],"id":49744721},{"tv":1369.46,"batb":[[2,27,17.94],[1,28,11.12],[0,29,14.76]],"trd":[[30,139.92],[29,153.54]],"ltp":29,"id":106596}],"tv":83644.48}],"ArrivalTime":1710507932100}
{"op":"mcm","id":2,"clk":"AOkHAIUKAJUL","pt":1710507932200,"mc":[{"id":"1.226122413","rc":[{"batb":[[2,7.8,69.99],[1,8,86.58],[0,8.2,24.79]],"batl":[[1,8.6,35.39]],"id":41122648},{"batl":[[2,29,11.03],[1,28,26.26]],"id":55632148},{"batl":[[1,1.85,127.81]],"id":51922},{"batl":[[0,32,7.15]],"id":106596}]}],"ArrivalTime":1710507932204}
{"op":"mcm","id":2,"clk":"APgHAI4KAKEL","pt":1710507932313,"mc":[{"id":"1.226122413","rc":[{"batl":[[2,360,3],[1,350,2.82],[0,330,2.87]],"id":54370634},{"tv":6695.77,"batb":[],"trd":[[8.4,555.49]],"batl":[[2,9,39.25],[1,8.8,22.38],[0,8.6,35.39]],"id":41122648},{"tv":1631.8,"batb":[[0,25,7.2]],"trd":[[25,244]],"ltp":25,"id":55632148},{"batb":[[0,32,27.53]],"id":49744721},{"tv":1398.99,"batb":[[0,29,5.91]],"trd":[[29,183.07]],"batl":[[0,32,11.39]],"id":106596}],"tv":83744.42}],"ArrivalTime":1710507932322}
{"op":"mcm","id":2,"clk":"AP4HAJcKAKkL","pt":1710507932407,"mc":[{"id":"1.226122413","rc":[{"batb":[[2,27,14.82]],"batl":[[2,34,14.4],[1,32,11.39],[0,30,4.19]],"id":106596}]}],"ArrivalTime":1710507932411}
{"op":"mcm","id":2,"clk":"AIUIAJ8KALIL","pt":1710507932522,"mc":[{"id":"1.226122413","rc":[{"batb":[[0,8.2,39.73]],"batl":[[0,8.6,37.39]],"id":41122648},{"batb":[[0,25,16.05]],"batl":[[0,27,2.83]],"id":55632148},{"batl":[[2,40,6.58],[0,36,15.54]],"id":49744721},{"tv":1416.81,"batb":[[2,26,12.19],[1,27,14.82],[0,28,11.12]],"trd":[[29,200.89]],"batl":[[2,32,11.39],[1,30,4.19],[0,29,1.32]],"id":106596}],"tv":83762.24}],"ArrivalTime":1710507932527}
{"op":"mcm","id":2,"clk":"AI0IAKYKAMEL","pt":1710507932623,"mc":[{"id":"1.226122413","rc":[{"tv":6766.55,"trd":[[8.6,432.28]],"ltp":8.6,"batl":[[0,8.6,2]],"id":41122648},{"tv":1639,"batb":[[0,25,12.45]],"trd":[[25,251.2]],"id":55632148},{"batl":[[1,38,17.99]],"id":49744721},{"batb":[[1,4.4,156.33]],"id":50466254},{"tv":1417.69,"batb":[[0,28,10.48]],"trd":[[29,201.77]],"batl":[[2,34,14.4],[1,32,11.39],[0,30,5.07]],"id":106596}],"tv":83841.1}],"ArrivalTime":1710507932627}
{"op":"mcm","id":2,"clk":"AJQIAKgKAMQL","pt":1710507932725,"mc":[{"id":"1.226122413","rc":[{"batb":[[0,8.2,54.58]],"batl":[],"id":41122648},{"tv":1642.38,"batb":[[1,24,20.13]],"trd":[[26,259.03]],"ltp":26,"batl":[[2,28,26.26],[1,27,1.89],[0,26,2.18]],"id":55632148},{"tv":58206.39,"batb":[[0,1.83,152.23]],"trd":[[1.83,6975.55]],"id":51922},{"batb":[[2,4.3,267.68]],"id":50466254},{"tv":1418.93,"trd":[[29,203.01]],"batl":[[0,30,4.45]],"id":106596}],"tv":83885.72}],"ArrivalTime":1710507932729}
{"op":"mcm","id":2,"clk":"AJoIALIKAM0L","pt":1710507932820,"mc":[{"id":"1.226122413","rc":[{"batl":[[2,350,2.82],[1,340,1]],"id":54370634},{"tv":6770.55,"batb":[[2,8,86.58],[1,8.2,62.69],[0,8.4,21.91]],"trd":[[8.6,436.28]],"batl":[[2,9.2,17.87],[1,9,39.25],[0,8.8,22.38]],"id":41122648},{"tv":1643.94,"batb":[],"trd":[[26,260.59]],"batl":[[0,26,1.4]],"id":55632148},{"tv":1439.9,"batb":[[2,25,14.12],[1,26,12.19],[0,27,14.82]],"trd":[[28,198.36]],"ltp":28,"batl":[[2,32,11.39],[1,30,4.45],[0,28,4.46]],"id":106596}],"tv":83912.25}],"ArrivalTime":1710507932824}
{"op":"mcm","id":2,"clk":"AKAIALcKANQL","pt":1710507932879,"mc":[{"id":"1.226122413","rc":[{"batb":[[1,8.2,49.38]],"id":41122648},{"batb":[[0,25,9.39]],"batl":[[1,27,4.45]],"id":55632148},{"batl":[[0,1.84,105.48]],"id":51922}]}],"ArrivalTime":1710507932887}
{"op":"mcm","id":2,"clk":"AKcIAMAKAOAL","pt":1710507933031,"mc":[{"id":"1.226122413","rc":[{"batb":[[0,8.4,29.91]],"batl":[[0,8.8,24.38]],"id":41122648},{"tv":1644.66,"batb":[[0,25,12.42]],"trd":[[26,261.31]],"batl":[[0,26,1.04]],"id":55632148},{"batb":[[0,1.83,157.23]],"batl":[[0,1.84,110.48]],"id":51922},{"tv":12624.32,"batb":[[0,4.5,189.18]],"trd":[[4.5,2160.13]],"ltp":4.5,"id":50466254},{"tv":1448.82,"batb":[[1,26,15.19],[0,27,9.5]],"trd":[[29,203.02],[28,207.27]],"ltp":29,"batl":[[2,34,14.4],[1,32,11.39],[0,30,7.39]],"id":106596}],"tv":83931.89}],"ArrivalTime":1710507933035}
{"op":"mcm","id":2,"clk":"AKsIAMYKAOsL","pt":1710507933079,"mc":[{"id":"1.226122413","rc":[{"batb":[[0,1.83,159.23]],"id":51922},{"batb":[[1,26,19.97],[0,27,6.79]],"id":106596}]}],"ArrivalTime":1710507933083}
{"op":"mcm","id":2,"clk":"ALQIANIKAPcL","pt":1710507933194,"mc":[{"id":"1.226122413","rc":[{"batb":[[2,8,89.94]],"batl":[],"id":41122648},{"batl":[[2,220,1.69]],"id":41200638},{"batb":[[0,1.83,136.08]],"id":51922},{"batb":[[2,26,19.97],[1,27,6.79],[0,28,2.42]],"batl":[[0,30,6.78]],"id":106596}]}],"ArrivalTime":1710507933198}
{"op":"mcm","id":2,"clk":"ALoIANkKAIMM","pt":1710507933288,"mc":[{"id":"1.226122413","rc":[{"batb":[[2,8.2,49.38],[1,8.4,29.91],[0,8.6,10.76]],"id":41122648},{"batl":[[2,38,17.99],[1,36,15.54],[0,34,2.82]],"id":49744721},{"tv":1453.66,"batb":[[2,25,14.12],[1,26,19.97],[0,27,6.79]],"trd":[[28,212.11]],"ltp":28,"id":106596}],"tv":83936.73}],"ArrivalTime":1710507933292}
{"op":"mcm","id":2,"clk":"AMUIAOYKAI8M","pt":1710507933397,"mc":[{"id":"1.226122413","rc":[{"batl":[[2,360,3],[1,350,2.82]],"id":54370634},{"batb":[[0,1.83,146.08]],"id":51922},{"tv":1460.68,"trd":[[28,219.13]],"batl":[[2,32,11.39],[1,30,6.78],[0,28,3.32]],"id":106596}],"tv":83943.75}],"ArrivalTime":1710507933402}
{"op":"mcm","id":2,"clk":"AM4IAO8KAJ4M","pt":1710507933500,"mc":[{"id":"1.226122413","rc":[{"batb":[[2,240,1.04],[1,250,4],[0,260,5.1]],"batl":[[2,350,2.82],[1,330,2],[0,320,1]],"id":54370634},{"tv":6777.31,"batb":[[0,8.6,7.38]],"trd":[[8.6,443.04]],"batl":[],"id":41122648},{"tv":2133.71,"trd":[[34,82.23]],"batl":[[2,40,9.14],[1,38,15.29],[0,36,15.54]],"id":49744721},{"batb":[],"batl":[[2,32,20.92]],"id":106596}],"tv":83956.15}],"ArrivalTime":1710507933505}
{"op":"mcm","id":2,"clk":"ANYIAPUKAKQM","pt":1710507933614,"mc":[{"id":"1.226122413","rc":[{"tv":316.5,"batb":[[2,250,4],[1,260,4.23],[0,300,1.03]],"trd":[[280,7.66],[270,3.39],[260,1.72]],"ltp":260,"id":54370634},{"tv":6790.79,"batb":[[2,8,93.61],[1,8.2,49.38],[0,8.4,30.55]],"trd":[[8.6,456.52]],"id":41122648},{"batl":[[0,36,13.54]],"id":49744721},{"tv":1467.32,"trd":[[28,225.77]],"batl":[[2,34,14.4],[1,32,20.92],[0,30,6.78]],"id":106596}],"tv":83978.02}],"ArrivalTime":1710507933619}
{"op":"mcm","id":2,"clk":"ANgIAIELAK8M","pt":1710507933704,"mc":[{"id":"1.226122413","rc":[{"batb":[[0,8.4,29.91]],"batl":[[2,9.2,19.23],[1,9,40.68],[0,8.8,25.88]],"id":41122648}]}],"ArrivalTime":1710507933709}
{"op":"mcm","id":2,"clk":"AOAIAI8LALYM","pt":1710507933830,"mc":[{"id":"1.226122413","rc":[{"tv":316.64,"batb":[[2,240,1.04],[1,250,4],[0,260,5.19]],"trd":[[300,17.45]],"ltp":300,"id":54370634},{"batl":[[2,38,19.55],[1,36,13.54],[0,34,11.12]],"id":49744721},{"batb":[[0,130,5.6]],"id":66251581},{"batl":[[2,32,20.92],[1,30,6.53],[0,29,3.3]],"id":106596}],"tv":83978.16}],"ArrivalTime":1710507933835}
{"op":"mcm","id":2,"clk":"AOMIAJULAMEM","pt":1710507933912,"mc":[{"id":"1.226122413","rc":[{"batl":[[2,9,39.25],[1,8.8,24.38],[0,8.6,10.57]],"id":41122648},{"batb":[],"batl":[[2,32,13.21]],"id":106596}]}],"ArrivalTime":1710507933916}
{"op":"mcm","id":2,"clk":"AO0IAJ8LAMcM","pt":1710507934015,"mc":[{"id":"1.226122413","rc":[{"batb":[[2,29,17.92],[1,30,28.98]],"batl":[[0,34,14.02]],"id":49744721},{"batb":[[0,130,5.27]],"id":66251581}]}],"ArrivalTime":1710507934020}
{"op":"mcm","id":2,"clk":"APcIAKwLANAM","pt":1710507934114,"mc":[{"id":"1.226122413","rc":[{"batb":[[2,8,101.79],[0,8.4,23.12]],"batl":[[1,8.8,22.38],[0,8.6,18.07]],"id":41122648},{"tv":2155.95,"trd":[[34,104.47]],"batl":[[0,34,2.9]],"id":49744721},{"batb":[[1,26,9.79]],"id":106596}],"tv":84000.4}],"ArrivalTime":1710507934118}
{"op":"mcm","id":2,"clk":"AP0IALQLANkM","pt":1710507934216,"mc":[{"id":"1.226122413","rc":[{"batb":[[0,1.83,171.54]],"id":51922},{"batb":[[2,4.3,271.29]],"id":50466254}]}],"ArrivalTime":1710507934221}
{"op":"mcm","id":2,"clk":"AIUJAL8LAOIM","pt":1710507934329,"mc":[{"id":"1.226122413","rc":[{"tv":6819.11,"batb":[],"trd":[[8.6,484.84]],"batl":[[0,8.6,3.91]],"id":41122648},{"batl":[[2,29,11.67],[1,28,26.26],[0,27,4.45]],"id":55632148},{"tv":2161.75,"batb":[[0,32,30.75]],"trd":[[34,110.27]],"batl":[[2,40,9.14],[1,38,19.55],[0,36,13.54]],"id":49744721},{"tv":1487.32,"batb":[[2,24,19.53],[1,25,14.12],[0,26,7.58]],"trd":[[27,178.55],[26,199.36]],"ltp":26,"id":106596}],"tv":84054.52}],"ArrivalTime":1710507934334}
{"op":"mcm","id":2,"clk":"AIcJAM4LAOgM","pt":1710507934382,"mc":[{"id":"1.226122413","rc":[{"tv":58226.39,"batb":[[0,1.83,173.54]],"trd":[[1.84,9329.61]],"ltp":1.84,"batl":[[0,1.84,77.22]],"id":51922}],"tv":84074.52}],"ArrivalTime":1710507934386}
{"op":"mcm","id":2,"clk":"AI8JANoLAPEM","pt":1710507934497,"mc":[{"id":"1.226122413","rc":[{"batl":[[0,8.6,14.34]],"id":41122648},{"tv":58232.39,"batb":[[0,1.83,170.54]],"trd":[[1.83,6981.55]],"ltp":1.83,"id":51922},{"batb":[[2,30,28.38],[1,32,30.75],[0,34,1.92]],"id":49744721},{"batb":[[0,130,5.6]],"id":66251581},{"batb":[[1,25,18.92],[0,26,10.19]],"batl":[[2,30,6.53],[1,29,9.32],[0,28,5.05]],"id":106596}],"tv":84080.52}],"ArrivalTime":1710507934501}
{"op":"mcm","id":2,"clk":"AJQJAOYLAPcM","pt":1710507934586,"mc":[{"id":"1.226122413","rc":[{"tv":2164.57,"batb":[[2,30,26.46],[0,34,3.45]],"trd":[[34,113.09]],"batl":[[0,36,11.76]],"id":49744721},{"batb":[[0,26,5.41]],"id":106596}],"tv":84083.34}],"ArrivalTime":1710507934591}
{"op":"mcm","id":2,"clk":"AJsJAPMLAIIN","pt":1710507934690,"mc":[{"id":"1.226122413","rc":[{"batb":[[1,250,3]],"id":54370634},{"tv":6823.11,"trd":[[8.6,488.84]],"batl":[[0,8.6,12.34]],"id":41122648},{"batl":[[2,29,11.03]],"id":55632148},{"tv":2168.57,"batb":[[0,34,1.45]],"trd":[[34,117.09]],"id":49744721},{"batb":[[0,130,5.27]],"id":66251581},{"batb":[[0,26,9]],"batl":[[2,29,9.32],[1,28,5.05],[0,27,4.42]],"id":106596}],"tv":84091.34}],"ArrivalTime":1710507934695}
{"op":"mcm","id":2,"clk":"AKAJAPgLAIgN","pt":1710507934799,"mc":[{"id":"1.226122413","rc":[{"batb":[[2,240,2.55]],"id":54370634},{"tv":2172.57,"trd":[[34,121.09]],"id":49744721},{"batb":[[1,25,14.74]],"id":106596}],"tv":84095.34}],"ArrivalTime":1710507934803}
{"op":"mcm","id":2,"clk":"AKUJAIQMAI4N","pt":1710507934900,"mc":[{"id":"1.226122413","rc":[{"batb":[[0,34,4.39]],"batl":[[1,38,15.29]],"id":49744721},{"tv":1491.6,"batb":[[1,25,13.53]],"trd":[[27,182.83]],"ltp":27,"batl":[[1,28,4.29],[0,27,2.28]],"id":106596}],"tv":84099.62}],"ArrivalTime":1710507934905}
{"op":"mcm","id":2,"clk":"AK8JAJMMAKEN","pt":1710507935102,"mc":[{"id":"1.226122413","rc":[{"batl":[[0,8.6,22.34]],"id":41122648},{"tv":1496.16,"trd":[[27,187.39]],"batl":[[2,30,6.53],[1,29,9.32],[0,28,4.29]],"id":106596}],"tv":84104.18}],"ArrivalTime":1710507935107}
{"op":"mcm","id":2,"clk":"ALgJAJ0MAKgN","pt":1710507935215,"mc":[{"id":"1.226122413","rc":[{"batb":[[2,8,106.39],[0,8.4,30.71]],"batl":[[0,8.6,20.43]],"id":41122648},{"tv":58243.19,"batb":[[0,1.83,165.14]],"trd":[[1.83,6992.35]],"id":51922},{"tv":1499.34,"batb":[[0,26,7.41]],"trd":[[26,202.54]],"ltp":26,"id":106596}],"tv":84118.16}],"ArrivalTime":1710507935220}
{"op":"mcm","id":2,"clk":"AL0JAKYMALgN","pt":1710507935319,"mc":[{"id":"1.226122413","rc":[{"batl":[[0,8.6,25.93]],"id":41122648},{"tv":58243.47,"batb":[[0,1.83,165]],"trd":[[1.83,6992.63]],"id":51922}],"tv":84118.44}],"ArrivalTime":1710507935324}
{"op":"mcm","id":2,"clk":"AMMJALQMAMcN","pt":1710507935547,"mc":[{"id":"1.226122413","rc":[{"batl":[[1,38,12.6]],"id":49744721},{"batb":[[2,24,26.39]],"id":106596}]}],"ArrivalTime":1710507935557}
{"op":"mcm","id":2,"clk":"ANAJAMMMANAN","pt":1710507935632,"mc":[{"id":"1.226122413","rc":[{"batb":[[0,4.5,249.18]],"id":50466254}]}],"ArrivalTime":1710507935637}
{"op":"mcm","id":2,"clk":"AOMJAN8MAOMN","pt":1710507935803,"mc":[{"id":"1.226122413","rc":[{"batb":[[0,1.83,167]],"id":51922}]}],"ArrivalTime":1710507935807}
{"op":"mcm","id":2,"clk":"AOgJAOYMAO0N","pt":1710507935910,"mc":[{"id":"1.226122413","rc":[{"tv":12709.72,"batb":[[0,4.5,206.48]],"trd":[[4.5,2245.53]],"id":50466254}],"tv":84203.84}],"ArrivalTime":1710507935915}
{"op":"mcm","id":2,"clk":"AOsJAPEMAPYN","pt":1710507935993,"mc":[{"id":"1.226122413","rc":[{"tv":6840.25,"batb":[[0,8.4,22.14]],"trd":[[8.4,572.63]],"ltp":8.4,"id":41122648},{"tv":1651.66,"batb":[[0,25,8.92]],"trd":[[25,258.2]],"ltp":25,"id":55632148},{"tv":2176.33,"batb":[[0,34,2.51]],"trd":[[34,124.85]],"id":49744721},{"batl":[[0,4.6,18.31]],"id":50466254},{"tv":436.2,"batb":[[0,130,3.84]],"trd":[[130,69.44]],"ltp":130,"batl":[],"id":66251581},{"batl":[[0,28,5.06]],"id":106596}],"tv":84234.6}],"ArrivalTime":1710507935998}
{"op":"mcm","id":2,"clk":"APoJAPkMAIAO","pt":1710507936102,"mc":[{"id":"1.226122413","rc":[{"batl":[[0,200,10.44]],"id":41200638},{"batb":[[0,4.5,258.91]],"id":50466254}]}],"ArrivalTime":1710507936107}
{"op":"mcm","id":2,"clk":"AIQKAIINAIgO","pt":1710507936204,"mc":[{"id":"1.226122413","rc":[{"batl":[[0,27,9.22]],"id":55632148},{"batb":[[1,1.82,278.58]],"id":51922},{"tv":1500.88,"trd":[[27,188.93]],"ltp":27,"batl":[[0,28,4.29]],"id":106596}],"tv":84236.14}],"ArrivalTime":1710507936209}
{"op":"mcm","id":2,"clk":"AIwKAI8NAJEO","pt":1710507936309,"mc":[{"id":"1.226122413","rc":[{"batl":[[2,160,5.94]],"id":66251581},{"tv":1515.7,"batb":[[2,23,11.04],[1,24,26.39],[0,25,13.53]],"trd":[[26,217.36]],"ltp":26,"batl":[[2,29,9.32],[1,28,4.29],[0,27,4.26]],"id":106596}],"tv":84250.96}],"ArrivalTime":1710507936313}
{"op":"mcm","id":2,"clk":"AJMKAJkNAJkO","pt":1710507936415,"mc":[{"id":"1.226122413","rc":[{"batb":[[0,25,8.82]],"id":55632148},{"tv":58306.39,"batb":[[0,1.83,162.54]],"trd":[[1.84,9383.61],[1.83,7001.55]],"ltp":1.84,"batl":[[0,1.84,50.22]],"id":51922},{"batb":[[0,25,14.53]],"id":106596}],"tv":84313.88}],"ArrivalTime":1710507936420}
{"op":"mcm","id":2,"clk":"AJgKAJ8NAKcO","pt":1710507936518,"mc":[{"id":"1.226122413","rc":[{"tv":58308.39,"batb":[[0,1.83,161.54]],"trd":[[1.83,7003.55]],"ltp":1.83,"batl":[[0,1.84,49.75]],"id":51922},{"batb":[[2,24,26.39],[1,25,14.53],[0,26,3.51]],"batl":[[1,28,6.58]],"id":106596}],"tv":84315.88}],"ArrivalTime":1710507936523}
{"op":"mcm","id":2,"clk":"AJsKAKMNAKwO","pt":1710507936616,"mc":[{"id":"1.226122413","rc":[{"batb":[[0,26,5.97]],"id":106596}]}],"ArrivalTime":1710507936620}
{"op":"mcm","id":2,"clk":"AKcKALUNALoO","pt":1710507936821,"mc":[{"id":"1.226122413","rc":[{"batl":[[1,8.8,24.38]],"id":41122648}]}],"ArrivalTime":1710507936825}
{"op":"mcm","id":2,"clk":"ALAKALkNAMMO","pt":1710507936924,"mc":[{"id":"1.226122413","rc":[{"batb":[[2,24,22.96]],"id":106596}]}],"ArrivalTime":1710507936929}
{"op":"mcm","id":2,"clk":"ALUKAMQNAMwO","pt":1710507937026,"mc":[{"id":"1.226122413","rc":[{"batl":[[2,360,3]],"id":54370634},{"batb":[[0,25,9.67]],"id":55632148},{"batl":[[2,160,6.94]],"id":66251581}]}],"ArrivalTime":1710507937030}
{"op":"mcm","id":2,"clk":"AMYKAN0NAOUO","pt":1710507937289,"mc":[{"id":"1.226122413","rc":[{"tv":6842.25,"batb":[[0,8.4,21.14]],"trd":[[8.4,574.63]],"id":41122648}],"tv":84317.88}],"ArrivalTime":1710507937293}
{"op":"mcm","id":2,"clk":"ANAKAOQNAPIO","pt":1710507937395,"mc":[{"id":"1.226122413","rc":[{"batb":[[1,24,22.55]],"batl":[],"id":55632148},{"tv":58456.48,"batb":[[0,1.83,87.49]],"trd":[[1.83,7151.64]],"id":51922}],"tv":84465.97}],"ArrivalTime":1710507937399}
{"op":"mcm","id":2,"clk":"ANgKAPANAPwO","pt":1710507937510,"mc":[{"id":"1.226122413","rc":[{"batb":[[0,8.4,29.18]],"id":41122648},{"batl":[[0,1.84,103.89]],"id":51922}]}],"ArrivalTime":1710507937514}
{"op":"mcm","id":2,"clk":"AOAKAPoNAIoP","pt":1710507937609,"mc":[{"id":"1.226122413","rc":[{"batl":[[0,8.6,27.93]],"id":41122648},{"tv":361.19,"batb":[[0,180,3.74]],"trd":[[180,15.29]],"ltp":180,"id":41200638},{"batb":[[0,25,10.56]],"id":55632148},{"tv":58476.26,"trd":[[1.84,9403.39]],"ltp":1.84,"batl":[[0,1.84,94]],"id":51922},{"batl":[[0,4.6,5.02]],"id":50466254}],"tv":84485.95}],"ArrivalTime":1710507937613}
{"op":"mcm","id":2,"clk":"AOMKAIQOAI8P","pt":1710507937708,"mc":[{"id":"1.226122413","rc":[{"batl":[[0,8.6,22.43]],"id":41122648},{"batl":[[0,200,10.54]],"id":41200638}]}],"ArrivalTime":1710507937713}
{"op":"mcm","id":2,"clk":"AO4KAIYOAJsP","pt":1710507937809,"mc":[{"id":"1.226122413","rc":[{"batb":[[0,180,4.1]],"id":41200638}]}],"ArrivalTime":1710507937815}
{"op":"mcm","id":2,"clk":"APUKAJIOAKEP","pt":1710507937915,"mc":[{"id":"1.226122413","rc":[{"tv":12719.76,"batb":[[2,4.4,156.33],[1,4.5,258.91],[0,4.6,24.98]],"trd":[[4.6,806.22]],"ltp":4.6,"batl":[[2,4.9,143.24],[1,4.8,44.88],[0,4.7,38.26]],"id":50466254},{"tv":1527.64,"batb":[[2,23,18.14],[1,24,22.96],[0,25,14.53]],"trd":[[26,229.3]],"batl":[[2,28,6.58],[1,27,4.26],[0,26,1.72]],"id":106596}],"tv":84507.93}],"ArrivalTime":1710507937919}
{"op":"mcm","id":2,"clk":"APoKAJYOAKkP","pt":1710507938015,"mc":[{"id":"1.226122413","rc":[{"batl":[[0,1.84,117.51]],"id":51922},{"batb":[[1,4.5,259.01],[0,4.6,25.08]],"id":50466254}]}],"ArrivalTime":1710507938020}
{"op":"mcm","id":2,"clk":"AP0KAJ8OALYP","pt":1710507938112,"mc":[{"id":"1.226122413","rc":[{"batl":[[2,29,11.67]],"id":55632148},{"batb":[[0,1.83,64.03]],"id":51922},{"tv":12723.76,"batb":[[0,4.6,70.32]],"trd":[[4.6,810.22]],"batl":[],"id":50466254},{"tv":1531.08,"batb":[[1,24,25.96],[0,25,13.53]],"trd":[[26,232.74]],"batl":[[0,26,4.24]],"id":106596}],"tv":84515.37}],"ArrivalTime":1710507938116}
{"op":"mcm","id":2,"clk":"AIILAKwOAL8P","pt":1710507938223,"mc":[{"id":"1.226122413","rc":[{"batb":[[1,1.82,273.58]],"id":51922},{"batb":[[1,24,30.55]],"batl":[],"id":106596}]}],"ArrivalTime":1710507938228}
{"op":"mcm","id":2,"clk":"AIkLALoOAMcP","pt":1710507938328,"mc":[{"id":"1.226122413","rc":[{"batb":[[0,8.4,54.18]],"id":41122648},{"tv":58486.26,"trd":[[1.84,9413.39]],"batl":[[0,1.84,112.51]],"id":51922}],"tv":84525.37}],"ArrivalTime":1710507938333}
{"op":"mcm","id":2,"clk":"AI8LAMIOAM8P","pt":1710507938381,"mc":[{"id":"1.226122413","rc":[{"batb":[[0,1.83,29.41]],"id":51922},{"tv":1539.56,"batb":[[2,24,30.55],[1,25,13.53],[0,26,1.54]],"trd":[[26,241.22]],"batl":[[2,29,9.32],[1,28,6.58],[0,27,4.26]],"id":106596}],"tv":84533.85}],"ArrivalTime":1710507938386}
{"op":"mcm","id":2,"clk":"AJULAMwOAOAP","pt":1710507938537,"mc":[{"id":"1.226122413","rc":[{"batl":[[0,8.6,23.6]],"id":41122648},{"batl":[[1,28,26.95],[0,27,9.96]],"id":55632148},{"batb":[[0,26,5.05]],"id":106596}]}],"ArrivalTime":1710507938545}
{"op":"mcm","id":2,"clk":"AJkLANQOAOUP","pt":1710507938595,"mc":[{"id":"1.226122413","rc":[{"tv":58496.42,"batb":[[0,1.83,24.33]],"trd":[[1.83,7161.8]],"ltp":1.83,"id":51922}],"tv":84544.01}],"ArrivalTime":1710507938600}
{"op":"mcm","id":2,"clk":"AJ4LANsOAO8P","pt":1710507938696,"mc":[{"id":"1.226122413","rc":[{"batl":[[2,29,11.03],[1,28,26.26],[0,27,9.22]],"id":55632148},{"batb":[[0,34,4.08]],"id":49744721}]}],"ArrivalTime":1710507938701}
{"op":"mcm","id":2,"clk":"AKMLAOgOAPoP","pt":1710507938803,"mc":[{"id":"1.226122413","rc":[{"tv":58503.78,"batb":[[0,1.83,29.65]],"trd":[[1.83,7169.16]],"id":51922}],"tv":84551.37}],"ArrivalTime":1710507938808}
{"op":"mcm","id":2,"clk":"AKoLAPAOAIcQ","pt":1710507938902,"mc":[{"id":"1.226122413","rc":[{"batb":[[0,34,6.08]],"id":49744721},{"tv":1543.56,"batb":[[0,26,3.05]],"trd":[[26,245.22]],"id":106596}],"tv":84555.37}],"ArrivalTime":1710507938908}
{"op":"mcm","id":2,"clk":"ALULAIUPAKAQ","pt":1710507939139,"mc":[{"id":"1.226122413","rc":[{"tv":318.64,"batb":[[2,250,3],[1,260,5.19],[0,320,1]],"trd":[[320,25.82]],"ltp":320,"batl":[[2,400,3.32],[1,360,3],[0,330,2]],"id":54370634}],"tv":84557.37}],"ArrivalTime":1710507939143}
{"op":"mcm","id":2,"clk":"AMMLAJ0PALMQ","pt":1710507939315,"mc":[{"id":"1.226122413","rc":[{"tv":319,"batb":[[1,260,4.23],[0,300,1.78]],"trd":[[320,26.18]],"id":54370634}],"tv":84557.73}],"ArrivalTime":1710507939320}
{"op":"mcm","id":2,"clk":"ANILALMPAMwQ","pt":1710507939533,"mc":[{"id":"1.226122413","rc":[{"tv":58522.78,"trd":[[1.84,9432.39]],"ltp":1.84,"batl":[[0,1.84,103.01]],"id":51922}],"tv":84576.73}],"ArrivalTime":1710507939538}
{"op":"mcm","id":2,"clk":"ANYLALoPANYQ","pt":1710507939623,"mc":[{"id":"1.226122413","rc":[{"tv":319.32,"batb":[[0,300,1.62]],"trd":[[320,26.5]],"id":54370634},{"batl":[[0,1.84,105.39]],"id":51922},{"batl":[[0,4.7,40.26]],"id":50466254}],"tv":84577.05}],"ArrivalTime":1710507939627}
{"op":"mcm","id":2,"clk":"ANwLAMQPAN4Q","pt":1710507939721,"mc":[{"id":"1.226122413","rc":[{"batb":[[0,8.4,66.11]],"id":41122648},{"batb":[[1,1.82,280.53]],"id":51922}]}],"ArrivalTime":1710507939726}
{"op":"mcm","id":2,"clk":"AOILAMoPAOcQ","pt":1710507939830,"mc":[{"id":"1.226122413","rc":[{"batb":[[2,260,4.23],[1,270,1.19]],"id":54370634},{"batl":[[0,27,6.26]],"id":106596}]}],"ArrivalTime":1710507939835}
{"op":"mcm","id":2,"clk":"APILAN8PAPAQ","pt":1710507939986,"mc":[{"id":"1.226122413","rc":[{"tv":1549.66,"batb":[[2,23,18.14],[1,24,30.55],[0,25,13.53]],"trd":[[26,251.32]],"batl":[[2,28,6.58],[1,27,8.4],[0,26,8.62]],"id":106596}],"tv":84583.15}],"ArrivalTime":1710507939991}
{"op":"mcm","id":2,"clk":"APYLAOcPAP4Q","pt":1710507940098,"mc":[{"id":"1.226122413","rc":[{"batb":[[2,260,5.23]],"id":54370634},{"tv":6846.25,"trd":[[8.6,492.84]],"ltp":8.6,"batl":[[0,8.6,21.6]],"id":41122648},{"tv":1552.34,"batb":[],"trd":[[26,254]],"batl":[[0,26,7.28]],"id":106596}],"tv":84589.83}],"ArrivalTime":1710507940103}
{"op":"mcm","id":2,"clk":"AIIMAPcPAI4R","pt":1710507940298,"mc":[{"id":"1.226122413","rc":[{"batb":[[0,1.83,81.26]],"id":51922},{"tv":2199.85,"trd":[[36,23.52]],"ltp":36,"batl":[[2,42,7.94],[1,40,9.14],[0,38,12.6]],"id":49744721},{"batb":[[1,24,27.12]],"id":106596}],"tv":84613.35}],"ArrivalTime":1710507940302}
{"op":"mcm","id":2,"clk":"AIgMAP8PAJcR","pt":1710507940401,"mc":[{"id":"1.226122413","rc":[{"batb":[],"batl":[[0,38,15.28]],"id":49744721},{"batl":[[0,26,11.28]],"id":106596}]}],"ArrivalTime":1710507940406}
{"op":"mcm","id":2,"clk":"AI8MAIMQAJ4R","pt":1710507940509,"mc":[{"id":"1.226122413","rc":[{"tv":6874.77,"batb":[[0,8.4,51.85]],"trd":[[8.4,603.15]],"ltp":8.4,"id":41122648},{"batb":[[0,34,27.02]],"batl":[[0,38,17.28]],"id":49744721}],"tv":84641.87}],"ArrivalTime":1710507940514}
{"op":"mcm","id":2,"clk":"AJQMAIsQAKcR","pt":1710507940602,"mc":[{"id":"1.226122413","rc":[{"batb":[[0,8.4,53.85]],"id":41122648},{"batl":[[2,28,8.58]],"id":106596}]}],"ArrivalTime":1710507940607}
{"op":"mcm","id":2,"clk":"AJ4MAJEQAKsR","pt":1710507940704,"mc":[{"id":"1.226122413","rc":[{"batb":[[0,8.4,64.03]],"id":41122648},{"batb":[[1,1.82,273.58],[0,1.83,29.65]],"id":51922}]}],"ArrivalTime":1710507940709}
{"op":"mcm","id":2,"clk":"AKIMAJkQAK8R","pt":1710507940815,"mc":[{"id":"1.226122413","rc":[{"batb":[[0,25,11.52]],"batl":[],"id":106596}]}],"ArrivalTime":1710507940820}
{"op":"mcm","id":2,"clk":"AKkMAKAQALsR","pt":1710507940913,"mc":[{"id":"1.226122413","rc":[{"tv":1656.22,"batb":[[0,25,8.28]],"trd":[[26,263.01],[25,261.06]],"id":55632148},{"tv":58526.34,"batb":[[0,1.83,27.87]],"trd":[[1.83,7172.72]],"ltp":1.83,"id":51922}],"tv":84649.99}],"ArrivalTime":1710507940918}
{"op":"mcm","id":2,"clk":"AKwMAKsQAMYR","pt":1710507941019,"mc":[{"id":"1.226122413","rc":[{"batl":[[2,28,26.26],[1,27,9.22],[0,26,2.94]],"id":55632148},{"batb":[[2,32,30.75],[1,34,27.02],[0,36,2.84]],"id":49744721}]}],"ArrivalTime":1710507941024}
{"op":"mcm","id":2,"clk":"ALIMALUQAMwR","pt":1710507941130,"mc":[{"id":"1.226122413","rc":[{"tv":58534.92,"batb":[[0,1.83,23.58]],"trd":[[1.83,7181.3]],"id":51922},{"batl":[[1,40,8.78]],"id":49744721}],"tv":84658.57}],"ArrivalTime":1710507941135}
{"op":"mcm","id":2,"clk":"ALoMALoQANQR","pt":1710507941226,"mc":[{"id":"1.226122413","rc":[{"batb":[[1,24,15.1]],"batl":[],"id":55632148}]}],"ArrivalTime":1710507941231}
{"op":"mcm","id":2,"clk":"AMMMAMUQANsR","pt":1710507941330,"mc":[{"id":"1.226122413","rc":[{"batb":[[2,4.4,190.34]],"id":50466254}]}],"ArrivalTime":1710507941335}
{"op":"mcm","id":2,"clk":"AMoMAM0QAOER","pt":1710507941432,"mc":[{"id":"1.226122413","rc":[{"batl":[[0,26,7.89]],"id":55632148},{"batl":[[1,40,8.65]],"id":49744721}]}],"ArrivalTime":1710507941437}
{"op":"mcm","id":2,"clk":"ANgMANgQAOYR","pt":1710507941535,"mc":[{"id":"1.226122413","rc":[{"batl":[[2,1.86,628.13]],"id":51922},{"tv":2203.85,"batb":[[2,30,26.46],[1,32,30.75],[0,34,27.86]],"trd":[[36,27.52]],"batl":[[0,38,15.28]],"id":49744721}],"tv":84662.57}],"ArrivalTime":1710507941540}
{"op":"mcm","id":2,"clk":"AN4MAOAQAO8R","pt":1710507941644,"mc":[{"id":"1.226122413","rc":[{"batb":[[0,34,27.02]],"id":49744721}]}],"ArrivalTime":1710507941649}
{"op":"mcm","id":2,"clk":"AOYMAOsQAPMR","pt":1710507941703,"mc":[{"id":"1.226122413","rc":[{"batl":[[2,400,3.64]],"id":54370634},{"batb":[[0,8.4,72.03]],"id":41122648},{"tv":58540.02,"trd":[[1.84,9437.49]],"ltp":1.84,"batl":[[0,1.84,102.84]],"id":51922},{"batl":[[0,38,15.65]],"id":49744721}],"tv":84667.67}],"ArrivalTime":1710507941708}
{"op":"mcm","id":2,"clk":"AOsMAO0QAPoR","pt":1710507941802,"mc":[{"id":"1.226122413","rc":[{"tv":319.54,"batb":[[0,300,1.51]],"trd":[[320,26.72]],"id":54370634},{"batb":[],"batl":[[0,8.6,20.43]],"id":41122648},{"tv":1668.22,"batb":[[0,25,2.28]],"trd":[[25,273.06]],"id":55632148},{"batb":[[0,1.83,38.58]],"id":51922},{"batl":[[2,160,6.44]],"id":66251581},{"batl":[[0,26,17.28]],"id":106596}],"tv":84679.89}],"ArrivalTime":1710507941807}
{"op":"mcm","id":2,"clk":"APMMAPYQAIYS","pt":1710507941909,"mc":[{"id":"1.226122413","rc":[{"batb":[[2,22,25.47],[1,23,13.81],[0,24,15.99]],"id":55632148},{"batb":[[0,1.83,88.99]],"id":51922},{"batb":[[0,25,3]],"id":106596}]}],"ArrivalTime":1710507941914}
{"op":"mcm","id":2,"clk":"APgMAIARAJAS","pt":1710507942008,"mc":[{"id":"1.226122413","rc":[{"batl":[[1,8.8,26.38]],"id":41122648}]}],"ArrivalTime":1710507942013}
{"op":"mcm","id":2,"clk":"AP0MAIoRAJoS","pt":1710507942108,"mc":[{"id":"1.226122413","rc":[{"batb":[[0,8.4,60.1]],"batl":[],"id":41122648},{"tv":1670,"batb":[[0,24,15.1]],"trd":[[25,274.84]],"batl":[[2,27,9.22],[1,26,7.89],[0,25,7.11]],"id":55632148},{"batb":[[2,22,14.64],[1,23,21.14],[0,24,27.12]],"batl":[],"id":106596}],"tv":84681.67}],"ArrivalTime":1710507942113}
{"op":"mcm","id":2,"clk":"AIkNAJURAKQS","pt":1710507942232,"mc":[{"id":"1.226122413","rc":[{"batl":[[0,25,10.2]],"id":55632148},{"batb":[[1,1.82,279.68]],"batl":[[0,1.84,202.84]],"id":51922},{"batl":[[1,40,13.9]],"id":49744721}]}],"ArrivalTime":1710507942237}
{"op":"mcm","id":2,"clk":"AJANAJ8RAKkS","pt":1710507942324,"mc":[{"id":"1.226122413","rc":[{"tv":1677.5,"trd":[[25,282.34]],"batl":[[1,26,10.5],[0,25,6.45]],"id":55632148},{"tv":58552.02,"batb":[[0,1.83,112.45]],"trd":[[1.84,9449.49]],"batl":[[0,1.84,196.84]],"id":51922},{"batb":[[0,4.6,94.87]],"id":50466254},{"batb":[],"batl":[[0,26,19.41]],"id":106596}],"tv":84701.17}],"ArrivalTime":1710507942329}
{"op":"mcm","id":2,"clk":"AJUNAKYRAK8S","pt":1710507942422,"mc":[{"id":"1.226122413","rc":[{"batb":[[2,22,19.67]],"id":55632148},{"batb":[[2,23,14.04],[1,24,27.12],[0,25,3.51]],"id":106596}]}],"ArrivalTime":1710507942427}
{"op":"mcm","id":2,"clk":"AJkNAK4RALgS","pt":1710507942521,"mc":[{"id":"1.226122413","rc":[{"batl":[[2,220,1.8]],"id":41200638},{"batl":[[2,1.86,618.13]],"id":51922},{"batb":[[0,4.6,113.82]],"batl":[[1,4.8,74.51]],"id":50466254}]}],"ArrivalTime":1710507942526}
{"op":"mcm","id":2,"clk":"AMoNAPYRAIAT","pt":1710507943310,"mc":[{"id":"1.226122413","rc":[{"batb":[[0,8.4,61.29]],"batl":[],"id":41122648},{"batl":[[0,25,3.36]],"id":55632148},{"tv":58602.9,"batb":[[0,1.83,63.55]],"trd":[[1.83,7232.18]],"ltp":1.83,"batl":[[1,1.85,129.81]],"id":51922},{"batl":[[0,38,16.19]],"id":49744721},{"batb":[[1,24,28.12]],"id":106596}],"tv":84752.05,"con":true}],"ArrivalTime":1710507943315}
{"op":"mcm","id":2,"clk":"AM8NAP8RAIUT","pt":1710507943402,"mc":[{"id":"1.226122413","rc":[{"batb":[[0,1.83,13.14]],"id":51922}]}],"ArrivalTime":1710507943407}
{"op":"mcm","id":2,"clk":"AN0NAJ4SAJoT","pt":1710507943615,"mc":[{"id":"1.226122413","rc":[{"tv":1678.3,"trd":[[25,283.14]],"batl":[[0,25,2.96]],"id":55632148},{"tv":58608.72,"batb":[[0,1.83,10.23]],"trd":[[1.83,7238]],"id":51922}],"tv":84758.67}],"ArrivalTime":1710507943620}
{"op":"mcm","id":2,"clk":"AOgNAKkSAKgT","pt":1710507943732,"mc":[{"id":"1.226122413","rc":[{"batl":[[2,42,10.38],[1,40,11.34]],"id":49744721}]}],"ArrivalTime":1710507943737}
{"op":"mcm","id":2,"clk":"AO0NALMSALET","pt":1710507943825,"mc":[{"id":"1.226122413","rc":[{"tv":1679.14,"trd":[[25,283.98]],"batl":[[0,25,2.54]],"id":55632148}],"tv":84759.51}],"ArrivalTime":1710507943830}
{"op":"mcm","id":2,"clk":"APMNAL0SAL0T","pt":1710507943920,"mc":[{"id":"1.226122413","rc":[{"tv":1680.38,"trd":[[25,285.22]],"batl":[[0,25,1.92]],"id":55632148}],"tv":84760.75}],"ArrivalTime":1710507943925}
{"op":"mcm","id":2,"clk":"APYNAM0SAMwT","pt":1710507944025,"mc":[{"id":"1.226122413","rc":[{"tv":58612.36,"batb":[[0,1.83,8.41]],"trd":[[1.83,7241.64]],"id":51922},{"tv":2205.85,"batb":[[0,34,26.02]],"trd":[[34,126.85]],"ltp":34,"id":49744721}],"tv":84766.39}],"ArrivalTime":1710507944030}
{"op":"mcm","id":2,"clk":"AP0NANQSANYT","pt":1710507944127,"mc":[{"id":"1.226122413","rc":[{"tv":1682.6,"trd":[[25,287.44]],"batl":[[2,28,26.26],[1,27,9.22],[0,26,11.31]],"id":55632148},{"tv":58618.78,"batb":[[0,1.83,5.2]],"trd":[[1.83,7248.06]],"id":51922}],"tv":84775.03}],"ArrivalTime":1710507944132}
{"op":"mcm","id":2,"clk":"AIEOANkSAOIT","pt":1710507944242,"mc":[{"id":"1.226122413","rc":[{"batb":[[1,1.82,259.68]],"id":51922}]}],"ArrivalTime":1710507944247}
{"op":"mcm","id":2,"clk":"AIUOAOMSAOwT","pt":1710507944357,"mc":[{"id":"1.226122413","rc":[{"tv":1684.22,"trd":[[25,289.06]],"batl":[[0,26,10.5]],"id":55632148},{"batb":[[0,1.83,25.2]],"id":51922},{"batb":[[0,4.6,118.82]],"id":50466254},{"batb":[[2,23,21.41]],"id":106596}],"tv":84776.65}],"ArrivalTime":1710507944362}
{"op":"mcm","id":2,"clk":"AIkOAPASAPgT","pt":1710507944393,"mc":[{"id":"1.226122413","rc":[{"tv":58628.9,"batb":[[0,1.83,20.14]],"trd":[[1.83,7258.18]],"batl":[[0,1.84,206.84]],"id":51922}],"tv":84786.77}],"ArrivalTime":1710507944399}
{"op":"mcm","id":2,"clk":"AJIOAPgSAIIU","pt":1710507944511,"mc":[{"id":"1.226122413","rc":[{"tv":58630.48,"batb":[[0,1.83,19.35]],"trd":[[1.83,7259.76]],"id":51922}],"tv":84788.35}],"ArrivalTime":1710507944516}
{"op":"mcm","id":2,"clk":"AJYOAIATAI4U","pt":1710507944602,"mc":[{"id":"1.226122413","rc":[{"tv":6899.63,"batb":[[0,8.4,48.86]],"trd":[[8.4,628.01]],"id":41122648},{"tv":1559.36,"batb":[[2,22,14.64],[1,23,21.41],[0,24,28.12]],"trd":[[25,162.79]],"ltp":25,"batl":[[0,26,19.62]],"id":106596}],"tv":84820.23}],"ArrivalTime":1710507944607}
{"op":"mcm","id":2,"clk":"AJwOAIkTAJgU","pt":1710507944709,"mc":[{"id":"1.226122413","rc":[{"batb":[[0,8.4,56.24]],"id":41122648},{"batl":[[0,4.7,24.67]],"id":50466254},{"tv":1559.78,"batb":[[2,22,17.64]],"trd":[[25,163.21]],"batl":[[2,27,8.4],[1,26,19.41],[0,25,4.27]],"id":106596}],"tv":84820.65}],"ArrivalTime":1710507944714}
{"op":"mcm","id":2,"clk":"AKIOAI8TAKAU","pt":1710507944810,"mc":[{"id":"1.226122413","rc":[{"tv":59044.17,"batb":[[2,1.82,259.68],[1,1.83,19.35],[0,1.84,647.12]],"trd":[[1.84,9863.18]],"ltp":1.84,"batl":[[2,1.87,146.95],[1,1.86,618.13],[0,1.85,129.81]],"id":51922},{"batb":[[1,23,11.04],[0,24,25.12]],"batl":[],"id":106596}],"tv":85234.34}],"ArrivalTime":1710507944815}
{"op":"mcm","id":2,"clk":"AKgOAJsTAKkU","pt":1710507944927,"mc":[{"id":"1.226122413","rc":[{"batb":[[0,8.4,53.75]],"batl":[[0,8.6,28.51]],"id":41122648},{"batl":[[1,210,5.88]],"id":41200638},{"tv":59082.68,"batb":[[1,1.83,69.06],[0,1.84,694.66]],"trd":[[1.85,10663.45],[1.84,9868.79]],"ltp":1.85,"batl":[[1,1.86,667.94],[0,1.85,113.36]],"id":51922},{"batl":[[0,4.7,52.11]],"id":50466254},{"batb":[[1,120,5.45]],"id":66251581},{"batb":[[2,22,18.77],[1,23,15.7],[0,24,24.12]],"id":106596}],"tv":85272.85}],"ArrivalTime":1710507944932}
{"op":"mcm","id":2,"clk":"ALAOAKYTALUU","pt":1710507945032,"mc":[{"id":"1.226122413","rc":[{"tv":319.7,"batb":[[0,300,1.43]],"trd":[[320,26.88]],"id":54370634},{"tv":6980.93,"batb":[[0,8.4,2.92]],"trd":[[8.4,709.31]],"batl":[[0,8.6,35.72]],"id":41122648},{"tv":59409.5,"batb":[[1,1.83,92.65],[0,1.84,718.12]],"trd":[[1.85,10990.27]],"batl":[[0,1.85,68.08]],"id":51922},{"batb":[[0,24,19.53]],"id":106596}],"tv":85681.13}],"ArrivalTime":1710507945037}
{"op":"mcm","id":2,"clk":"ALcOALATAL4U","pt":1710507945125,"mc":[{"id":"1.226122413","rc":[{"tv":319.86,"batb":[[0,300,1.35]],"trd":[[320,27.04]],"id":54370634},{"batb":[[2,7.8,69.99],[1,8,106.39],[0,8.2,49.38]],"id":41122648},{"batb":[[0,4.6,77.32]],"batl":[[0,4.7,70.85]],"id":50466254},{"batb":[[0,24,17.39]],"id":106596}],"tv":85681.29}],"ArrivalTime":1710507945131}
{"op":"mcm","id":2,"clk":"ALwOALkTAMcU","pt":1710507945225,"mc":[{"id":"1.226122413","rc":[{"batl":[[2,8.8,26.38],[1,8.6,35.72],[0,8.4,13.06]],"id":41122648},{"tv":59545.66,"batb":[[2,1.83,92.65],[1,1.84,721.12],[0,1.85,50.71]],"trd":[[1.85,11126.43]],"batl":[[2,1.88,273.84],[1,1.87,146.95],[0,1.86,667.94]],"id":51922}],"tv":85817.45}],"ArrivalTime":1710507945231}
{"op":"mcm","id":2,"clk":"AMIOAL4TANAU","pt":1710507945329,"mc":[{"id":"1.226122413","rc":[{"tv":319.9,"batb":[[0,300,1.33]],"trd":[[320,27.08]],"id":54370634},{"batb":[[1,8,99.39],[0,8.2,41.38]],"batl":[],"id":41122648},{"batl":[[2,220,1.69],[1,210,5.76]],"id":41200638},{"batb":[[2,1.83,202.16]],"id":51922},{"batb":[[2,22,26.45]],"id":106596}],"tv":85817.49}],"ArrivalTime":1710507945334}
{"op":"mcm","id":2,"clk":"AMgOAMgTANoU","pt":1710507945433,"mc":[{"id":"1.226122413","rc":[{"batb":[[0,8.2,26.53]],"batl":[[1,8.6,33.72],[0,8.4,15.06]],"id":41122648},{"batb":[[2,1.83,331.4],[1,1.84,735.11]],"id":51922},{"batb":[[1,23,7.51]],"id":106596}]}],"ArrivalTime":1710507945439}
{"op":"mcm","id":2,"clk":"AMsOANATAOUU","pt":1710507945536,"mc":[{"id":"1.226122413","rc":[{"batb":[],"batl":[[2,8.8,26.49]],"id":41122648},{"batb":[[0,24,21.88]],"id":106596}]}],"ArrivalTime":1710507945541}
{"op":"mcm","id":2,"clk":"ANEOANoTAO4U","pt":1710507945608,"mc":[{"id":"1.226122413","rc":[{"batb":[[2,1.82,259.97],[1,1.83,331.4],[0,1.84,735.11]],"id":51922},{"batb":[[0,130,3.93]],"id":66251581},{"batb":[[1,23,6.9]],"id":106596}]}],"ArrivalTime":1710507945614}
{"op":"mcm","id":2,"clk":"ANcOAOkTAPYU","pt":1710507945750,"mc":[{"id":"1.226122413","rc":[{"batb":[[0,130,3.85]],"id":66251581}]}],"ArrivalTime":1710507945755}
{"op":"mcm","id":2,"clk":"AOMOAPoTAIkV","pt":1710507945907,"mc":[{"id":"1.226122413","rc":[{"batb":[[1,8,96.04]],"id":41122648},{"batb":[[0,1.84,743.65]],"id":51922}]}],"ArrivalTime":1710507945913}
{"op":"mcm","id":2,"clk":"AO0OAP4TAJIV","pt":1710507946015,"mc":[{"id":"1.226122413","rc":[{"batb":[[1,8,83.25]],"id":41122648},{"tv":59547.17,"batb":[[0,1.84,742.9]],"trd":[[1.84,9870.3]],"ltp":1.84,"id":51922}],"tv":85819}],"ArrivalTime":1710507946020}
{"op":"mcm","id":2,"clk":"APQOAIUUAJ8V","pt":1710507946108,"mc":[{"id":"1.226122413","rc":[{"batb":[[0,4.6,75.32]],"id":50466254}]}],"ArrivalTime":1710507946113}
{"op":"mcm","id":2,"clk":"APcOAIsUAKsV","pt":1710507946204,"mc":[{"id":"1.226122413","rc":[{"tv":59569.83,"batb":[[0,1.84,731.57]],"trd":[[1.84,9892.96]],"id":51922}],"tv":85841.66}],"ArrivalTime":1710507946209}
{"op":"mcm","id":2,"clk":"AIQPAKAUAL8V","pt":1710507946413,"mc":[{"id":"1.226122413","rc":[{"tv":59613.83,"batb":[[0,1.84,709.57]],"trd":[[1.84,9936.96]],"id":51922}],"tv":85885.66}],"ArrivalTime":1710507946418}
{"op":"mcm","id":2,"clk":"AJQPALIUANMV","pt":1710507946627,"mc":[{"id":"1.226122413","rc":[{"batl":[[2,1.87,146.95],[1,1.86,667.94],[0,1.85,56.29]],"id":51922}]}],"ArrivalTime":1710507946632}
{"op":"mcm","id":2,"clk":"AKQPAMgUAOYV","pt":1710507946838,"mc":[{"id":"1.226122413","rc":[{"batb":[[0,24,16.1]],"id":55632148}]}],"ArrivalTime":1710507946843}
{"op":"mcm","id":2,"clk":"AK0PANMUAPEV","pt":1710507946933,"mc":[{"id":"1.226122413","rc":[{"batb":[[0,1.84,99.34]],"id":51922}]}],"ArrivalTime":1710507946938}
{"op":"mcm","id":2,"clk":"ALsPAOMUAIMW","pt":1710507947102,"mc":[{"id":"1.226122413","rc":[{"batl":[[0,8.4,25.06]],"id":41122648},{"batb":[[2,23,13.81],[1,24,16.1],[0,25,3.52]],"id":55632148},{"batb":[[0,1.84,75.88]],"batl":[[0,1.85,81.05]],"id":51922}]}],"ArrivalTime":1710507947108}
{"op":"mcm","id":2,"clk":"AMYPAOoUAIkW","pt":1710507947220,"mc":[{"id":"1.226122413","rc":[{"batl":[[2,28,26.95],[1,27,9.96]],"id":55632148},{"batb":[[0,1.84,77.88]],"id":51922}]}],"ArrivalTime":1710507947225}
{"op":"mcm","id":2,"clk":"AM0PAPUUAJYW","pt":1710507947300,"mc":[{"id":"1.226122413","rc":[{"batb":[[1,8,91.25],[0,8.2,34.53]],"id":41122648},{"tv":12739.76,"batb":[[0,4.6,67.32]],"trd":[[4.6,826.22]],"id":50466254}],"tv":85901.66}],"ArrivalTime":1710507947306}
{"op":"mcm","id":2,"clk":"ANUPAP4UAJ4W","pt":1710507947400,"mc":[{"id":"1.226122413","rc":[{"batb":[[0,24,24.16]],"id":106596}]}],"ArrivalTime":1710507947405}
{"op":"mcm","id":2,"clk":"APUPAJwVAL4W","pt":1710507947812,"mc":[{"id":"1.226122413","rc":[{"tv":59633.83,"batb":[[0,1.84,67.88]],"trd":[[1.84,9956.96]],"id":51922}],"tv":85921.66}],"ArrivalTime":1710507947817}
{"op":"mcm","id":2,"clk":"AP4PAKcVAMgW","pt":1710507947923,"mc":[{"id":"1.226122413","rc":[{"batb":[[1,270,1.6]],"id":54370634},{"tv":1560.52,"batb":[],"trd":[[25,163.95]],"batl":[[0,25,3.9]],"id":106596}],"tv":85922.4}],"ArrivalTime":1710507947928}
{"op":"mcm","id":2,"clk":"AIUQAKsVANQW","pt":1710507948018,"mc":[{"id":"1.226122413","rc":[{"batl":[[0,25,4.9]],"id":106596}]}],"ArrivalTime":1710507948024}
{"op":"mcm","id":2,"clk":"AJIQAL4VAOQW","pt":1710507948229,"mc":[{"id":"1.226122413","rc":[{"batl":[[1,8.6,23.72]],"id":41122648},{"tv":59653.73,"batb":[[0,1.84,57.93]],"trd":[[1.84,9976.86]],"id":51922}],"tv":85942.3}],"ArrivalTime":1710507948235}
{"op":"mcm","id":2,"clk":"AJsQANAVAPcW","pt":1710507948439,"mc":[{"id":"1.226122413","rc":[{"batb":[[1,1.83,202.16]],"id":51922}]}],"ArrivalTime":1710507948444}
{"op":"mcm","id":2,"clk":"AKAQANgVAIAX","pt":1710507948536,"mc":[{"id":"1.226122413","rc":[{"batb":[[0,1.84,59.93]],"id":51922},{"tv":2216.11,"trd":[[38,8.44],[36,29.34]],"ltp":38,"batl":[[0,38,11.06]],"id":49744721},{"tv":12755.76,"batb":[[0,4.6,59.32]],"trd":[[4.6,842.22]],"id":50466254}],"tv":85968.56}],"ArrivalTime":1710507948542}
{"op":"mcm","id":2,"clk":"AKsQAOcVAJIX","pt":1710507948706,"mc":[{"id":"1.226122413","rc":[{"batb":[[0,34,29.09]],"id":49744721}]}],"ArrivalTime":1710507948711}
{"op":"mcm","id":2,"clk":"ALIQAOwVAJkX","pt":1710507948797,"mc":[{"id":"1.226122413","rc":[{"tv":59735.73,"batb":[[0,1.84,18.93]],"trd":[[1.84,10058.86]],"id":51922},{"batl":[[2,42,7.94],[1,40,8.65]],"id":49744721},{"batb":[[0,4.6,61.32]],"id":50466254}],"tv":86050.56}],"ArrivalTime":1710507948802}
{"op":"mcm","id":2,"clk":"ALkQAPYVAKEX","pt":1710507948906,"mc":[{"id":"1.226122413","rc":[{"tv":59775.73,"batb":[[2,1.81,185.22],[1,1.82,259.97],[0,1.83,201.09]],"trd":[[1.84,10096.72],[1.83,7261.9]],"ltp":1.83,"batl":[[0,1.85,86.05]],"id":51922},{"batb":[[2,32,30.75],[1,34,29.09],[0,36,3.97]],"id":49744721}],"tv":86090.56}],"ArrivalTime":1710507948911}
{"op":"mcm","id":2,"clk":"AL8QAP8VAK4X","pt":1710507949012,"mc":[{"id":"1.226122413","rc":[{"batl":[[1,27,9.22]],"id":55632148},{"batb":[[0,36,5.97]],"batl":[[0,38,6.81]],"id":49744721}]}],"ArrivalTime":1710507949017}
{"op":"mcm","id":2,"clk":"AMcQAIoWALwX","pt":1710507949113,"mc":[{"id":"1.226122413","rc":[{"tv":59785.27,"batb":[[0,1.83,245.37]],"trd":[[1.85,11135.97]],"ltp":1.85,"batl":[[0,1.85,81.28]],"id":51922},{"batb":[],"batl":[[1,40,12.24]],"id":49744721},{"batb":[[0,4.6,63.32]],"id":50466254}],"tv":86100.1}],"ArrivalTime":1710507949119}
{"op":"mcm","id":2,"clk":"AM0QAI8WAMUX","pt":1710507949215,"mc":[{"id":"1.226122413","rc":[{"batl":[[0,1.85,96.28]],"id":51922},{"batb":[[0,36,8.42]],"id":49744721}]}],"ArrivalTime":1710507949221}
{"op":"mcm","id":2,"clk":"ANEQAJsWAM8X","pt":1710507949315,"mc":[{"id":"1.226122413","rc":[{"batl":[[0,8.4,23.06]],"id":41122648}]}],"ArrivalTime":1710507949321}
{"op":"mcm","id":2,"clk":"ANcQAKIWANcX","pt":1710507949419,"mc":[{"id":"1.226122413","rc":[{"tv":2217.19,"batb":[[0,36,7.88]],"trd":[[36,30.42]],"ltp":36,"id":49744721}],"tv":86101.18}],"ArrivalTime":1710507949425}
{"op":"mcm","id":2,"clk":"AOMQALIWAOIX","pt":1710507949536,"mc":[{"id":"1.226122413","rc":[{"tv":2219.63,"batb":[[0,36,6.66]],"trd":[[36,32.86]],"id":49744721},{"batb":[[0,24,25.16]],"id":106596}],"tv":86103.62}],"ArrivalTime":1710507949542}
{"op":"mcm","id":2,"clk":"AOsQALgWAOsX","pt":1710507949629,"mc":[{"id":"1.226122413","rc":[{"batb":[[1,34,27.52]],"id":49744721}]}],"ArrivalTime":1710507949635}
{"op":"mcm","id":2,"clk":"APsQANAWAIEY","pt":1710507949838,"mc":[{"id":"1.226122413","rc":[{"tv":12758.27,"batb":[[0,4.6,62.07]],"trd":[[4.6,844.73]],"id":50466254}],"tv":86106.13}],"ArrivalTime":1710507949843}
{"op":"mcm","id":2,"clk":"AJIRAOoWAKEY","pt":1710507950115,"mc":[{"id":"1.226122413","rc":[{"batl":[[0,200,10.13]],"id":41200638},{"tv":2219.73,"trd":[[38,8.54]],"ltp":38,"batl":[[0,38,6.76]],"id":49744721}],"tv":86106.23}],"ArrivalTime":1710507950121}
{"op":"mcm","id":2,"clk":"AJsRAP8WALoY","pt":1710507950355,"mc":[{"id":"1.226122413","rc":[{"batb":[[2,1.82,259.97],[1,1.83,245.37],[0,1.84,4]],"id":51922},{"batl":[[1,40,8.23]],"id":49744721}],"con":true}],"ArrivalTime":1710507950361}
{"op":"mcm","id":2,"clk":"AKURAIgXAMAY","pt":1710507950420,"mc":[{"id":"1.226122413","rc":[{"batl":[[0,8.4,25.06]],"id":41122648},{"tv":12762.27,"batb":[[0,4.6,60.07]],"trd":[[4.6,848.73]],"id":50466254}],"tv":86110.23}],"ArrivalTime":1710507950426}
{"op":"mcm","id":2,"clk":"ALMRAJQXANEY","pt":1710507950640,"mc":[{"id":"1.226122413","rc":[{"tv":12770.27,"batb":[[0,4.6,56.07]],"trd":[[4.6,856.73]],"id":50466254}],"tv":86118.23}],"ArrivalTime":1710507950646}
{"op":"mcm","id":2,"clk":"AMIRAKwXAPUY","pt":1710507950923,"mc":[{"id":"1.226122413","rc":[{"batb":[[1,1.83,247.78]],"id":51922},{"batb":[],"batl":[[2,4.9,145.92]],"id":50466254}]}],"ArrivalTime":1710507950929}
{"op":"mcm","id":2,"clk":"ANoRAMsXAJAZ","pt":1710507951244,"mc":[{"id":"1.226122413","rc":[{"batb":[[0,1.84,6.38]],"id":51922}]}],"ArrivalTime":1710507951250}
{"op":"mcm","id":2,"clk":"AOIRANAXAJgZ","pt":1710507951349,"mc":[{"id":"1.226122413","rc":[{"tv":6985.63,"trd":[[8.4,714.01]],"batl":[[0,8.4,22.71]],"id":41122648}],"tv":86122.93}],"ArrivalTime":1710507951355}
{"op":"mcm","id":2,"clk":"AIMSAP0XAMsZ","pt":1710507951812,"mc":[{"id":"1.226122413","rc":[{"batb":[[1,1.83,255.8]],"id":51922}]}],"ArrivalTime":1710507951818}
{"op":"mcm","id":2,"clk":"AI4SAIEYANIZ","pt":1710507951932,"mc":[{"id":"1.226122413","rc":[{"tv":59885.27,"trd":[[1.85,11235.97]],"batl":[[0,1.85,46.28]],"id":51922}],"tv":86222.93}],"ArrivalTime":1710507951937}
{"op":"mcm","id":2,"clk":"AJMSAI0YANwZ","pt":1710507952021,"mc":[{"id":"1.226122413","rc":[{"batb":[[0,1.84,68.19]],"id":51922}]}],"ArrivalTime":1710507952027}
{"op":"mcm","id":2,"clk":"AJkSAJQYAOcZ","pt":1710507952126,"mc":[{"id":"1.226122413","rc":[{"batb":[[0,1.84,107.09]],"id":51922}]}],"ArrivalTime":1710507952132}
{"op":"mcm","id":2,"clk":"AJ4SAKEYAOwZ","pt":1710507952238,"mc":[{"id":"1.226122413","rc":[{"batb":[[0,1.84,133.22]],"batl":[[0,1.85,21.52]],"id":51922}]}],"ArrivalTime":1710507952243}
{"op":"mcm","id":2,"clk":"ALwSANQYAJMa","pt":1710507952605,"mc":[{"id":"1.226122413","rc":[{"batl":[[0,1.85,64.22]],"id":51922}]}],"ArrivalTime":1710507952611}
{"op":"mcm","id":2,"clk":"AMMSAN0YAJ4a","pt":1710507952708,"mc":[{"id":"1.226122413","rc":[{"batb":[[1,1.83,257.8]],"id":51922}]}],"ArrivalTime":1710507952715}
{"op":"mcm","id":2,"clk":"ANsSAPkYAL8a","pt":1710507953021,"mc":[{"id":"1.226122413","rc":[{"tv":59895.45,"trd":[[1.85,11246.15]],"batl":[[0,1.85,59.13]],"id":51922}],"tv":86233.11}],"ArrivalTime":1710507953026}
{"op":"mcm","id":2,"clk":"AOUSAIQZAM8a","pt":1710507953133,"mc":[{"id":"1.226122413","rc":[{"tv":59899.45,"batb":[[0,1.84,131.22]],"trd":[[1.84,10100.72]],"ltp":1.84,"id":51922}],"tv":86237.11}],"ArrivalTime":1710507953139}
{"op":"mcm","id":2,"clk":"APgSAJQZAOQa","pt":1710507953333,"mc":[{"id":"1.226122413","rc":[{"batl":[[0,1.85,120.45]],"id":51922},{"batl":[[0,4.7,90.85]],"id":50466254}]}],"ArrivalTime":1710507953339}
{"op":"mcm","id":2,"clk":"AP8SAJsZAPIa","pt":1710507953440,"mc":[{"id":"1.226122413","rc":[{"batb":[[0,1.84,146.22]],"id":51922}]}],"ArrivalTime":1710507953449}
{"op":"mcm","id":2,"clk":"AIkTAKYZAP0a","pt":1710507953535,"mc":[{"id":"1.226122413","rc":[{"batl":[[0,8.4,26.71]],"id":41122648},{"tv":361.21,"batb":[[0,180,4.09]],"trd":[[180,15.31]],"id":41200638},{"tv":12778.27,"batb":[[0,4.6,19.83]],"trd":[[4.6,864.73]],"id":50466254},{"tv":1561.12,"trd":[[25,164.55]],"batl":[[0,25,4.6]],"id":106596}],"tv":86245.73}],"ArrivalTime":1710507953541}
{"op":"mcm","id":2,"clk":"AJMTALMZAIgb","pt":1710507953646,"mc":[{"id":"1.226122413","rc":[{"tv":12780.27,"batb":[[0,4.6,18.83]],"trd":[[4.6,866.73]],"id":50466254}],"tv":86247.73}],"ArrivalTime":1710507953652}
{"op":"mcm","id":2,"clk":"AJcTALsZAI8b","pt":1710507953692,"mc":[{"id":"1.226122413","rc":[{"batb":[[0,4.6,12]],"id":50466254},{"tv":1561.54,"trd":[[25,164.97]],"batl":[[0,25,4.39]],"id":106596}],"tv":86248.15}],"ArrivalTime":1710507953697}
{"op":"mcm","id":2,"clk":"AJ0TAMAZAJYb","pt":1710507953846,"mc":[{"id":"1.226122413","rc":[{"tv":1690.22,"batb":[[2,22,19.67],[1,23,13.81],[0,24,16.62]],"trd":[[25,295.06]],"id":55632148},{"batl":[[1,40,5.67]],"id":49744721},{"batl":[[0,4.7,91.85]],"id":50466254},{"batl":[[0,25,1]],"id":106596}],"tv":86254.15}],"ArrivalTime":1710507953853}
{"op":"mcm","id":2,"clk":"AKUTAMwZAJ4b","pt":1710507953902,"mc":[{"id":"1.226122413","rc":[{"tv":60191.89,"batb":[[2,1.81,178.22],[1,1.82,259.97],[0,1.83,257.8]],"trd":[[1.84,10393.16]],"batl":[[2,1.86,667.94],[1,1.85,120.45],[0,1.84,8.78]],"id":51922}],"tv":86546.59}],"ArrivalTime":1710507953908}
{"op":"mcm","id":2,"clk":"AK0TANYZAKUb","pt":1710507954007,"mc":[{"id":"1.226122413","rc":[{"batl":[[2,28,26.26]],"id":55632148},{"batb":[[0,1.83,259.8]],"batl":[[1,1.85,146.29]],"id":51922},{"batl":[[2,4.9,143.24]],"id":50466254},{"batb":[[1,120,5.84]],"id":66251581},{"tv":1563.36,"trd":[[25,166.79]],"batl":[[2,28,8.58],[1,27,8.4],[0,26,19.5]],"id":106596}],"tv":86548.41}],"ArrivalTime":1710507954013}
{"op":"mcm","id":2,"clk":"ALQTAOEZAK4b","pt":1710507954111,"mc":[{"id":"1.226122413","rc":[{"tv":1563.54,"batb":[[2,22,25.32]],"trd":[[25,166.97]],"batl":[[0,26,19.41]],"id":106596}],"tv":86548.59}],"ArrivalTime":1710507954117}
{"op":"mcm","id":2,"clk":"AMQTAPQZALob","pt":1710507954314,"mc":[{"id":"1.226122413","rc":[{"tv":319.92,"batb":[[0,300,1.32]],"trd":[[320,27.1]],"id":54370634},{"batl":[[0,26,24.71]],"id":106596}],"tv":86548.61}],"ArrivalTime":1710507954320}
{"op":"mcm","id":2,"clk":"ANETAPsZAMUb","pt":1710507954421,"mc":[{"id":"1.226122413","rc":[{"batl":[[2,420,2.09],[1,400,3.64]],"id":54370634}]}],"ArrivalTime":1710507954427}
{"op":"mcm","id":2,"clk":"ANkTAIkaAMwb","pt":1710507954523,"mc":[{"id":"1.226122413","rc":[{"tv":322.56,"batb":[[2,250,3],[1,260,5.23],[0,270,1.6]],"trd":[[320,27.82],[300,19.37]],"ltp":300,"batl":[[2,400,3.64],[1,330,2],[0,300,1.68]],"id":54370634}],"tv":86551.25}],"ArrivalTime":1710507954529}
{"op":"mcm","id":2,"clk":"AOQTAI8aANQb","pt":1710507954628,"mc":[{"id":"1.226122413","rc":[{"tv":60197.01,"trd":[[1.84,10398.28]],"batl":[[0,1.84,6.22]],"id":51922}],"tv":86556.37}],"ArrivalTime":1710507954633}
{"op":"mcm","id":2,"clk":"AOkTAJ4aANwb","pt":1710507954720,"mc":[{"id":"1.226122413","rc":[{"batb":[[0,270,1.92]],"id":54370634},{"tv":60207.01,"batb":[[0,1.83,254.8]],"trd":[[1.83,7271.9]],"ltp":1.83,"id":51922},{"batb":[[0,4.6,13]],"id":50466254}],"tv":86566.37}],"ArrivalTime":1710507954726}
{"op":"mcm","id":2,"clk":"APETAKgaAOob","pt":1710507954835,"mc":[{"id":"1.226122413","rc":[{"batl":[[1,1.85,148.64]],"id":51922}]}],"ArrivalTime":1710507954840}
{"op":"mcm","id":2,"clk":"APkTALAaAPIb","pt":1710507954941,"mc":[{"id":"1.226122413","rc":[{"batl":[[0,1.84,8.22]],"id":51922}]}],"ArrivalTime":1710507954947}
{"op":"mcm","id":2,"clk":"AP4TALYaAPkb","pt":1710507955034,"mc":[{"id":"1.226122413","rc":[{"tv":60221.01,"trd":[[1.84,10412.28]],"ltp":1.84,"batl":[[0,1.84,1.22]],"id":51922},{"batb":[[0,4.6,33]],"batl":[[2,4.9,145.92],[1,4.8,77.31]],"id":50466254}],"tv":86580.37}],"ArrivalTime":1710507955040}
{"op":"mcm","id":2,"clk":"AIoUAMYaAI0c","pt":1710507955240,"mc":[{"id":"1.226122413","rc":[{"batb":[[2,250,4],[1,260,4.23]],"id":54370634},{"batb":[[2,23,13.81],[1,24,16.1],[0,25,3]],"id":55632148},{"batb":[[0,4.6,61.9]],"id":50466254}]}],"ArrivalTime":1710507955246}
{"op":"mcm","id":2,"clk":"AJAUAM0aAJgc","pt":1710507955340,"mc":[{"id":"1.226122413","rc":[{"batb":[[0,270,1.51]],"batl":[[2,400,4.06]],"id":54370634},{"tv":361.61,"trd":[[200,64.56],[190,15.08]],"ltp":200,"batl":[[0,200,9.93]],"id":41200638}],"tv":86580.77}],"ArrivalTime":1710507955346}
{"op":"mcm","id":2,"clk":"AJgUANMaAKEc","pt":1710507955445,"mc":[{"id":"1.226122413","rc":[{"batl":[[2,28,26.95]],"id":55632148},{"batb":[],"batl":[[2,4.9,143.24],[1,4.8,74.51]],"id":50466254}]}],"ArrivalTime":1710507955451}
{"op":"mcm","id":2,"clk":"AKEUAOMaAKwc","pt":1710507955509,"mc":[{"id":"1.226122413","rc":[{"batb":[],"batl":[[2,210,5.76],[1,200,9.93],[0,190,2.01]],"id":41200638}]}],"ArrivalTime":1710507955515}
{"op":"mcm","id":2,"clk":"AKcUAOgaALYc","pt":1710507955606,"mc":[{"id":"1.226122413","rc":[{"tv":363.61,"trd":[[190,17.08]],"ltp":190,"batl":[[0,190,1.01]],"id":41200638},{"batl":[[0,1.84,16.22]],"id":51922}],"tv":86582.77}],"ArrivalTime":1710507955612}
{"op":"mcm","id":2,"clk":"AK4UAPIaAMIc","pt":1710507955710,"mc":[{"id":"1.226122413","rc":[{"tv":60240.05,"batb":[[0,1.83,245.28]],"trd":[[1.83,7290.94]],"ltp":1.83,"id":51922}],"tv":86601.81}],"ArrivalTime":1710507955716}
{"op":"mcm","id":2,"clk":"ALUUAPwaAMoc","pt":1710507955813,"mc":[{"id":"1.226122413","rc":[{"batb":[[0,1.83,247.28]],"id":51922}]}],"ArrivalTime":1710507955819}
{"op":"mcm","id":2,"clk":"ALsUAIIbANQc","pt":1710507955924,"mc":[{"id":"1.226122413","rc":[{"batl":[[2,220,1.69],[1,210,5.76],[0,200,9.93]],"id":41200638}]}],"ArrivalTime":1710507955930}
{"op":"mcm","id":2,"clk":"AMQUAIsbAN0c","pt":1710507956017,"mc":[{"id":"1.226122413","rc":[{"tv":12904.07,"batb":[[2,4.3,249.02],[1,4.4,190.34],[0,4.5,259.01]],"trd":[[4.6,990.53]],"id":50466254}],"tv":86725.61}],"ArrivalTime":1710507956023}
{"op":"mcm","id":2,"clk":"AMoUAJEbAOgc","pt":1710507956117,"mc":[{"id":"1.226122413","rc":[{"tv":60272.49,"batb":[[2,1.82,259.97],[1,1.83,247.28],[0,1.84,61.08]],"trd":[[1.84,10444.72]],"ltp":1.84,"batl":[[2,1.87,146.95],[1,1.86,667.94],[0,1.85,148.64]],"id":51922},{"batb":[[0,24,26.16]],"id":106596}],"tv":86758.05}],"ArrivalTime":1710507956126}
{"op":"mcm","id":2,"clk":"AM4UAJsbAPEc","pt":1710507956224,"mc":[{"id":"1.226122413","rc":[{"batb":[],"batl":[[0,8.4,24.71]],"id":41122648},{"batb":[[0,1.84,66.22]],"id":51922},{"batb":[[1,120,5.45]],"id":66251581}]}],"ArrivalTime":1710507956230}
{"op":"mcm","id":2,"clk":"ANsUALEbAIQd","pt":1710507956449,"mc":[{"id":"1.226122413","rc":[{"batl":[[0,1.85,147.21]],"id":51922}]}],"ArrivalTime":1710507956455}
{"op":"mcm","id":2,"clk":"AOYUALwbAIod","pt":1710507956545,"mc":[{"id":"1.226122413","rc":[{"tv":7005.63,"batb":[[0,8.2,24.53]],"trd":[[8.2,252.79]],"ltp":8.2,"id":41122648}],"tv":86778.05}],"ArrivalTime":1710507956550}
{"op":"mcm","id":2,"clk":"AO4UAMQbAJEd","pt":1710507956643,"mc":[{"id":"1.226122413","rc":[{"batb":[[0,1.84,69.81]],"id":51922}]}],"ArrivalTime":1710507956649}
{"op":"mcm","id":2,"clk":"APYUANEbAJod","pt":1710507956713,"mc":[{"id":"1.226122413","rc":[{"batl":[[0,8.4,26.71]],"id":41122648},{"batl":[[0,38,8.76]],"id":49744721}]}],"ArrivalTime":1710507956719}
{"op":"mcm","id":2,"clk":"AP4UANsbAKQd","pt":1710507956811,"mc":[{"id":"1.226122413","rc":[{"batb":[[1,1.83,249.28]],"id":51922}]}],"ArrivalTime":1710507956817}
{"op":"mcm","id":2,"clk":"AJ8VAIEcANYd","pt":1710507957234,"mc":[{"id":"1.226122413","rc":[{"batl":[[2,4.8,74.51],[1,4.7,91.85],[0,4.6,5]],"id":50466254}]}],"ArrivalTime":1710507957240}
{"op":"mcm","id":2,"clk":"AKwVAJMcAO0d","pt":1710507957452,"mc":[{"id":"1.226122413","rc":[{"batb":[[1,260,5.23]],"id":54370634},{"tv":7007.63,"batb":[[0,8.2,23.53]],"trd":[[8.2,254.79]],"id":41122648},{"tv":1569.54,"batb":[[0,24,23.16]],"trd":[[24,42.57]],"ltp":24,"batl":[],"id":106596}],"tv":86786.05}],"ArrivalTime":1710507957458}
{"op":"mcm","id":2,"clk":"ALYVAJwcAPwd","pt":1710507957551,"mc":[{"id":"1.226122413","rc":[{"batb":[[1,1.83,251.28]],"id":51922}]}],"ArrivalTime":1710507957557}
{"op":"mcm","id":2,"clk":"AM0VALAcAJoe","pt":1710507957813,"mc":[{"id":"1.226122413","rc":[{"tv":60392.49,"batb":[[0,1.84,9.81]],"trd":[[1.84,10564.72]],"id":51922}],"tv":86906.05}],"ArrivalTime":1710507957819}
{"op":"mcm","id":2,"clk":"ANUVALQcAKMe","pt":1710507957911,"mc":[{"id":"1.226122413","rc":[{"tv":60402.91,"trd":[[1.85,11256.57]],"ltp":1.85,"batl":[[0,1.85,142]],"id":51922}],"tv":86916.47}],"ArrivalTime":1710507957917}
{"op":"mcm","id":2,"clk":"AOEVAMgcALwe","pt":1710507958124,"mc":[{"id":"1.226122413","rc":[{"tv":7039.02,"batb":[[0,8.2,15.53]],"trd":[[8.4,729.39],[8.2,270.8]],"ltp":8.4,"batl":[[0,8.4,19.02]],"id":41122648},{"tv":60405.38,"batb":[[0,1.84,8.58]],"trd":[[1.84,10567.19]],"ltp":1.84,"id":51922}],"tv":86950.33}],"ArrivalTime":1710507958130}
{"op":"mcm","id":2,"clk":"AOsVAN8cAM0e","pt":1710507958327,"mc":[{"id":"1.226122413","rc":[{"batb":[[0,8.2,25.22]],"id":41122648},{"tv":60445.38,"batb":[[0,1.84,49.92]],"trd":[[1.84,10607.19]],"id":51922}],"tv":86990.33}],"ArrivalTime":1710507958333}
{"op":"mcm","id":2,"clk":"APgVAPgcAOAe","pt":1710507958530,"mc":[{"id":"1.226122413","rc":[{"tv":7049.02,"batb":[[0,8.2,27.11]],"trd":[[8.2,280.8]],"ltp":8.2,"id":41122648},{"tv":60455.38,"trd":[[1.85,11266.57]],"ltp":1.85,"batl":[[0,1.85,137]],"id":51922},{"tv":2224.85,"batb":[[0,36,4.1]],"trd":[[36,37.98]],"ltp":36,"id":49744721}],"tv":87015.45}],"ArrivalTime":1710507958536}
{"op":"mcm","id":2,"clk":"AP8VAIAdAOke","pt":1710507958641,"mc":[{"id":"1.226122413","rc":[{"batb":[[1,1.83,253.28]],"id":51922}]}],"ArrivalTime":1710507958650}
{"op":"mcm","id":2,"clk":"AIIWAIcdAPIe","pt":1710507958731,"mc":[{"id":"1.226122413","rc":[{"tv":60555.22,"batb":[[2,1.81,178.22],[1,1.82,259.97],[0,1.83,253.28]],"trd":[[1.84,10707.03]],"ltp":1.84,"batl":[[2,1.86,667.94],[1,1.85,137],[0,1.84,4.14]],"id":51922},{"batb":[[0,36,2.45]],"id":49744721}],"tv":87115.29}],"ArrivalTime":1710507958737}
{"op":"mcm","id":2,"clk":"AIsWAI8dAPge","pt":1710507958841,"mc":[{"id":"1.226122413","rc":[{"tv":60563.5,"trd":[[1.84,10715.31]],"batl":[[2,1.87,146.95],[1,1.86,667.94],[0,1.85,137]],"id":51922},{"batb":[[0,36,5.93]],"id":49744721},{"batb":[[1,120,5.84]],"id":66251581}],"tv":87123.57}],"ArrivalTime":1710507958847}
{"op":"mcm","id":2,"clk":"AJEWAJwdAIEf","pt":1710507958947,"mc":[{"id":"1.226122413","rc":[{"batb":[[2,1.82,259.97],[1,1.83,253.28],[0,1.84,66.57]],"id":51922},{"batb":[[0,36,8.45]],"batl":[[2,42,10.38]],"id":49744721},{"batl":[[0,4.6,7]],"id":50466254}]}],"ArrivalTime":1710507958953}
{"op":"mcm","id":2,"clk":"AJsWAKQdAIgf","pt":1710507959052,"mc":[{"id":"1.226122413","rc":[{"tv":2228.85,"batb":[[0,36,6.45]],"trd":[[36,41.98]],"id":49744721},{"batb":[[1,120,5.45]],"id":66251581}],"tv":87127.57}],"ArrivalTime":1710507959057}
{"op":"mcm","id":2,"clk":"AJ4WAK0dAI8f","pt":1710507959107,"mc":[{"id":"1.226122413","rc":[{"batb":[[0,270,1.62]],"id":54370634},{"batb":[[2,170,14.59],[1,180,4.09],[0,190,1.27]],"id":41200638},{"tv":436.73,"trd":[[140,57.66]],"ltp":140,"batl":[[0,140,2.12]],"id":66251581}],"tv":87128.1}],"ArrivalTime":1710507959113}
{"op":"mcm","id":2,"clk":"AKkWALcdAJUf","pt":1710507959209,"mc":[{"id":"1.226122413","rc":[{"batb":[[0,36,8.37]],"id":49744721}]}],"ArrivalTime":1710507959215}
{"op":"mcm","id":2,"clk":"AK8WAMIdAKUf","pt":1710507959319,"mc":[{"id":"1.226122413","rc":[{"batl":[[0,4.6,12]],"id":50466254}]}],"ArrivalTime":1710507959325}
{"op":"mcm","id":2,"clk":"ALUWAMkdAK0f","pt":1710507959416,"mc":[{"id":"1.226122413","rc":[{"tv":366.14,"batb":[[2,160,3.39],[1,170,14.59],[0,180,4.09]],"trd":[[190,19.61]],"batl":[[2,210,5.76],[1,200,9.93],[0,190,4.46]],"id":41200638},{"tv":444.43,"batb":[[2,100,7.07],[1,110,1.82],[0,120,5.45]],"trd":[[130,77.14]],"ltp":130,"batl":[[2,150,1.41],[1,140,2.12],[0,130,1.88]],"id":66251581},{"batl":[[0,26,30.44]],"id":106596}],"tv":87138.33}],"ArrivalTime":1710507959422}
{"op":"mcm","id":2,"clk":"ALwWAM4dALcf","pt":1710507959520,"mc":[{"id":"1.226122413","rc":[{"batl":[[0,300,7.41]],"id":54370634},{"tv":368.76,"batb":[[0,180,2.49]],"trd":[[190,22.23]],"batl":[[0,190,5.05]],"id":41200638},{"batb":[[0,1.84,67.07]],"id":51922},{"tv":447.33,"batb":[[0,120,5.84]],"trd":[[130,80.04]],"batl":[[2,160,6.44],[1,150,1.41],[0,140,2.88]],"id":66251581}],"tv":87143.85}],"ArrivalTime":1710507959527}
{"op":"mcm","id":2,"clk":"AMIWANIdAMQf","pt":1710507959624,"mc":[{"id":"1.226122413","rc":[{"tv":322.79,"batb":[[0,270,1.51]],"trd":[[290,9.75]],"ltp":290,"batl":[[0,300,7.62]],"id":54370634},{"batb":[[0,8.2,27.35]],"id":41122648},{"batl":[[0,38,6.76]],"id":49744721},{"batb":[[1,110,1.36],[0,120,7.45]],"batl":[[2,160,1.97]],"id":66251581}],"tv":87144.08}],"ArrivalTime":1710507959630}
{"op":"mcm","id":2,"clk":"AMkWAN0dAM8f","pt":1710507959733,"mc":[{"id":"1.226122413","rc":[{"batb":[[0,270,1.19]],"id":54370634},{"batb":[[0,180,4.52]],"id":41200638},{"batb":[[0,1.84,67.57]],"id":51922},{"batb":[[2,100,6.8],[0,120,8.17]],"id":66251581}]}],"ArrivalTime":1710507959740}
{"op":"mcm","id":2,"clk":"ANAWAOQdANkf","pt":1710507959832,"mc":[{"id":"1.226122413","rc":[{"batb":[[0,1.84,69.57]],"id":51922},{"batl":[[2,160,1.53],[0,140,1.92]],"id":66251581}]}],"ArrivalTime":1710507959839}
{"op":"mcm","id":2,"clk":"ANcWAO0dAOIf","pt":1710507959942,"mc":[{"id":"1.226122413","rc":[{"tv":60581.5,"batb":[[0,1.84,60.57]],"trd":[[1.84,10733.31]],"id":51922},{"batb":[[0,24,20.88]],"batl":[[0,26,24.44]],"id":106596}],"tv":87162.08}],"ArrivalTime":1710507959948}
{"op":"mcm","id":2,"clk":"ANwWAPYdAO4f","pt":1710507960037,"mc":[{"id":"1.226122413","rc":[{"tv":1581.54,"batb":[[0,24,14.88]],"trd":[[24,54.57]],"id":106596}],"tv":87174.08}],"ArrivalTime":1710507960043}
{"op":"mcm","id":2,"clk":"AOQWAP0dAPgf","pt":1710507960139,"mc":[{"id":"1.226122413","rc":[{"tv":60626.24,"batb":[[0,1.84,38.2]],"trd":[[1.84,10778.05]],"id":51922},{"tv":2230.85,"trd":[[38,10.54]],"ltp":38,"batl":[[0,38,5.76]],"id":49744721},{"tv":447.35,"batb":[[0,120,5.07]],"trd":[[120,36.69]],"ltp":120,"id":66251581}],"tv":87220.84}],"ArrivalTime":1710507960146}
{"op":"mcm","id":2,"clk":"AOkWAIkeAIIg","pt":1710507960246,"mc":[{"id":"1.226122413","rc":[{"tv":60630.24,"batb":[[0,1.84,36.2]],"trd":[[1.84,10782.05]],"id":51922},{"tv":12925.81,"trd":[[4.6,1012.27]],"batl":[[0,4.6,1.13]],"id":50466254}],"tv":87246.58}],"ArrivalTime":1710507960252}
{"op":"mcm","id":2,"clk":"APQWAJQeAJUg","pt":1710507960446,"mc":[{"id":"1.226122413","rc":[{"batl":[[2,27,8.4],[1,26,24.44],[0,25,4.55]],"id":106596}]}],"ArrivalTime":1710507960452}
{"op":"mcm","id":2,"clk":"APsWAJ4eAKAg","pt":1710507960549,"mc":[{"id":"1.226122413","rc":[{"batb":[[0,1.84,51.2]],"id":51922},{"batl":[[2,4.8,118.32]],"id":50466254},{"tv":1585.02,"trd":[[25,170.45]],"ltp":25,"batl":[[0,25,2.81]],"id":106596}],"tv":87250.06}],"ArrivalTime":1710507960555}
{"op":"mcm","id":2,"clk":"AIEXAK4eAKgg","pt":1710507960614,"mc":[{"id":"1.226122413","rc":[{"batb":[[2,22,26.45]],"id":106596}]}],"ArrivalTime":1710507960621}
{"op":"mcm","id":2,"clk":"AIUXALUeALMg","pt":1710507960720,"mc":[{"id":"1.226122413","rc":[{"batl":[[0,1.85,142]],"id":51922}]}],"ArrivalTime":1710507960726}
{"op":"mcm","id":2,"clk":"AJIXAMceAMUg","pt":1710507960925,"mc":[{"id":"1.226122413","rc":[{"tv":2233.67,"trd":[[38,13.36]],"batl":[[0,38,4.35]],"id":49744721}],"tv":87252.88}],"ArrivalTime":1710507960931}
{"op":"mcm","id":2,"clk":"AJcXAMoeAMwg","pt":1710507961019,"mc":[{"id":"1.226122413","rc":[{"batb":[[0,1.84,53.2]],"id":51922}]}],"ArrivalTime":1710507961025}
{"op":"mcm","id":2,"clk":"ALYXAOkeAPEg","pt":1710507961434,"mc":[{"id":"1.226122413","rc":[{"tv":7055.02,"batb":[[0,8.2,24.35]],"trd":[[8.2,286.8]],"id":41122648},{"tv":2243.67,"batb":[[0,36,3.37]],"trd":[[36,51.98]],"ltp":36,"id":49744721}],"tv":87268.88}],"ArrivalTime":1710507961440}
{"op":"mcm","id":2,"clk":"ALsXAPEeAPog","pt":1710507961533,"mc":[{"id":"1.226122413","rc":[{"tv":60634.24,"trd":[[1.85,11270.57]],"ltp":1.85,"batl":[[0,1.85,140]],"id":51922}],"tv":87272.88}],"ArrivalTime":1710507961540}
{"op":"mcm","id":2,"clk":"AMMXAPYeAIIh","pt":1710507961643,"mc":[{"id":"1.226122413","rc":[{"batb":[[0,36,3.98]],"id":49744721},{"batb":[[2,100,7.07]],"id":66251581}]}],"ArrivalTime":1710507961649}
{"op":"mcm","id":2,"clk":"AMoXAP4eAIoh","pt":1710507961743,"mc":[{"id":"1.226122413","rc":[{"batb":[[0,36,7.38]],"id":49744721}]}],"ArrivalTime":1710507961749}
{"op":"mcm","id":2,"clk":"ANIXAIcfAJMh","pt":1710507961843,"mc":[{"id":"1.226122413","rc":[{"batb":[[2,32,30.14]],"id":49744721},{"tv":12926.45,"trd":[[4.6,1012.91]],"batl":[[2,4.9,143.24],[1,4.8,118.32],[0,4.7,92.66]],"id":50466254},{"batb":[[2,22,37.87]],"id":106596}],"tv":87273.52}],"ArrivalTime":1710507961849}
{"op":"mcm","id":2,"clk":"ANgXAJMfAJ8h","pt":1710507961948,"mc":[{"id":"1.226122413","rc":[{"batb":[[1,23,9.9],[0,24,17.88]],"id":106596}]}],"ArrivalTime":1710507961954}
{"op":"mcm","id":2,"clk":"AOAXAKEfAKch","pt":1710507962050,"mc":[{"id":"1.226122413","rc":[{"batb":[[0,8.2,38.35]],"id":41122648}]}],"ArrivalTime":1710507962056}
{"op":"mcm","id":2,"clk":"AOIXAKYfALQh","pt":1710507962105,"mc":[{"id":"1.226122413","rc":[{"batb":[[0,8.2,40.35]],"id":41122648},{"batb":[[0,24,19.88]],"id":106596}]}],"ArrivalTime":1710507962112}
{"op":"mcm","id":2,"clk":"AOwXALQfAL8h","pt":1710507962213,"mc":[{"id":"1.226122413","rc":[{"tv":60637.38,"batb":[[0,1.84,51.63]],"trd":[[1.84,10785.19]],"ltp":1.84,"id":51922},{"batb":[[1,23,6.9],[0,24,16.88]],"id":106596}],"tv":87276.66}],"ArrivalTime":1710507962219}
{"op":"mcm","id":2,"clk":"APYXALwfAMkh","pt":1710507962317,"mc":[{"id":"1.226122413","rc":[{"batb":[[0,4.5,261.05]],"id":50466254}]}],"ArrivalTime":1710507962323}
{"op":"mcm","id":2,"clk":"AIgYANkfAOAh","pt":1710507962529,"mc":[{"id":"1.226122413","rc":[{"batb":[[1,8,95.54]],"id":41122648}]}],"ArrivalTime":1710507962535}
{"op":"mcm","id":2,"clk":"AJIYAOUfAPMh","pt":1710507962735,"mc":[{"id":"1.226122413","rc":[{"tv":60677.38,"batb":[[0,1.84,31.63]],"trd":[[1.84,10825.19]],"id":51922},{"batb":[[1,23,8.9]],"id":106596}],"tv":87316.66}],"ArrivalTime":1710507962741}
{"op":"mcm","id":2,"clk":"ALAYAIcgAJ4i","pt":1710507963149,"mc":[{"id":"1.226122413","rc":[{"tv":60679.38,"batb":[[0,1.84,30.63]],"trd":[[1.84,10827.19]],"id":51922}],"tv":87318.66}],"ArrivalTime":1710507963155}
{"op":"mcm","id":2,"clk":"ALgYAI0gAKki","pt":1710507963259,"mc":[{"id":"1.226122413","rc":[{"batb":[[2,22,39.87]],"id":106596}]}],"ArrivalTime":1710507963265}
{"op":"mcm","id":2,"clk":"AMIYAKAgALsi","pt":1710507963422,"mc":[{"id":"1.226122413","rc":[{"batl":[[0,1.85,150]],"id":51922}]}],"ArrivalTime":1710507963428}
{"op":"mcm","id":2,"clk":"AMgYALAgAMQi","pt":1710507963516,"mc":[{"id":"1.226122413","rc":[{"batl":[[0,190,1.9]],"id":41200638},{"tv":60698.38,"trd":[[1.85,11289.57]],"ltp":1.85,"batl":[[0,1.85,140.5]],"id":51922}],"tv":87337.66}],"ArrivalTime":1710507963522}
{"op":"mcm","id":2,"clk":"AIMZAP4gAJcj","pt":1710507964405,"mc":[{"id":"1.226122413","rc":[{"tv":7117.02,"batb":[[0,8.2,10.35]],"trd":[[8.2,346.8],[8.4,731.39]],"ltp":8.2,"batl":[[0,8.4,18.02]],"id":41122648},{"batb":[[2,22,19.67],[1,23,13.81],[0,24,16.1]],"batl":[[2,28,26.26]],"id":55632148},{"tv":60718.3,"trd":[[1.85,11309.49]],"batl":[[0,1.85,130.54]],"id":51922},{"tv":12930.45,"trd":[[4.7,65.75],[4.6,1014.53]],"ltp":4.7,"batl":[[0,4.7,90.66]],"id":50466254},{"tv":448.2,"batb":[[2,100,6.8],[0,120,3.07]],"trd":[[130,80.89]],"ltp":130,"batl":[[2,170,2.88],[1,160,1.53],[0,150,1.41]],"id":66251581},{"tv":1590.18,"batb":[[0,24,14.3]],"trd":[[25,172.45],[24,57.73]],"ltp":24,"batl":[[0,25,1.81]],"id":106596}],"tv":87429.59,"con":true}],"ArrivalTime":1710507964411}
{"op":"mcm","id":2,"clk":"AIgZAIAhAJcj","pt":1710507964441,"mc":[{"id":"1.226122413","rc":[{"batl":[[0,8.4,26.25]],"id":41122648},{"tv":12934.45,"batb":[[0,4.5,260.29]],"trd":[[4.5,2249.53]],"ltp":4.5,"id":50466254}],"tv":87433.59}],"ArrivalTime":1710507964448}
{"op":"mcm","id":2,"clk":"AJMZAI4hAKEj","pt":1710507964556,"mc":[{"id":"1.226122413","rc":[{"batb":[[1,8,87.54]],"batl":[[0,8.4,32.74]],"id":41122648},{"batb":[[1,23,11.9],[0,24,17.3]],"id":106596}]}],"ArrivalTime":1710507964563}
{"op":"mcm","id":2,"clk":"AJ0ZAJIhAK4j","pt":1710507964658,"mc":[{"id":"1.226122413","rc":[{"tv":60723.66,"trd":[[1.85,11314.85]],"batl":[[0,1.85,127.86]],"id":51922}],"tv":87438.95}],"ArrivalTime":1710507964664}
{"op":"mcm","id":2,"clk":"AKoZAKUhAMMj","pt":1710507964853,"mc":[{"id":"1.226122413","rc":[{"batb":[[1,260,4.1]],"id":54370634},{"tv":1624.78,"batb":[[2,21,44.56],[1,22,39.87],[0,23,11.9]],"trd":[[24,92.33]],"id":106596}],"tv":87473.55}],"ArrivalTime":1710507964860}
{"op":"mcm","id":2,"clk":"ALwZALohANoj","pt":1710507965070,"mc":[{"id":"1.226122413","rc":[{"batb":[[0,8.2,20.31]],"batl":[],"id":41122648},{"batl":[[0,1.85,66.54]],"id":51922},{"tv":12940.17,"batb":[[0,4.5,257.43]],"trd":[[4.5,2255.25]],"id":50466254},{"batb":[[2,21,48.56],[1,22,35.74],[0,23,8.9]],"batl":[[0,25,4.05]],"id":106596}],"tv":87479.27}],"ArrivalTime":1710507965076}
{"op":"mcm","id":2,"clk":"AMUZAMQhAOMj","pt":1710507965120,"mc":[{"id":"1.226122413","rc":[{"tv":1642.58,"batb":[[2,20,17.82],[1,21,48.56],[0,22,24.32]],"trd":[[23,17.8]],"ltp":23,"id":106596}],"tv":87497.07}],"ArrivalTime":1710507965127}
{"op":"mcm","id":2,"clk":"AMkZAMkhAOwj","pt":1710507965218,"mc":[{"id":"1.226122413","rc":[{"tv":60805.06,"batb":[[2,1.83,253.28],[1,1.84,56.08],[0,1.85,87.28]],"trd":[[1.85,11396.25]],"batl":[[2,1.88,273.84],[1,1.87,146.95],[0,1.86,667.94]],"id":51922},{"batb":[[2,4.4,190.34],[1,4.5,257.43],[0,4.6,13.07]],"id":50466254},{"batb":[[2,20,17.14],[1,21,47.3],[0,22,22.31]],"batl":[[2,26,24.44],[1,25,8.03],[0,24,6.35]],"id":106596}],"tv":87578.47}],"ArrivalTime":1710507965224}
{"op":"mcm","id":2,"clk":"ANAZANIhAPUj","pt":1710507965323,"mc":[{"id":"1.226122413","rc":[{"tv":60809.96,"batb":[[0,1.85,84.83]],"trd":[[1.85,11401.15]],"id":51922},{"tv":2255.13,"batb":[[0,36,1.65]],"trd":[[36,63.44]],"id":49744721}],"tv":87594.83}],"ArrivalTime":1710507965329}
{"op":"mcm","id":2,"clk":"ANYZANshAP0j","pt":1710507965429,"mc":[{"id":"1.226122413","rc":[{"tv":60859.67,"batb":[[0,1.85,59.99]],"trd":[[1.86,5684.95],[1.85,11450.82]],"ltp":1.86,"batl":[[0,1.86,667.92]],"id":51922},{"batb":[[2,30,28.05],[1,32,30.14],[0,34,27.52]],"batl":[[2,40,5.67],[1,38,4.35],[0,36,1.65]],"id":49744721},{"batl":[[2,4.9,145.92],[1,4.8,121.12]],"id":50466254},{"tv":1689.36,"batb":[[2,19.5,23.78],[1,20,17.82],[0,21,47.3]],"trd":[[24,94.49],[22,44.62]],"ltp":22,"batl":[[0,24,5.27]],"id":106596}],"tv":87691.32}],"ArrivalTime":1710507965435}
{"op":"mcm","id":2,"clk":"AN0ZAOEhAIUk","pt":1710507965537,"mc":[{"id":"1.226122413","rc":[{"tv":324.79,"trd":[[290,10.17],[300,20.95]],"ltp":300,"batl":[[0,300,6.62]],"id":54370634},{"batl":[[0,8.4,24.51]],"id":41122648},{"batl":[[1,38,6.35],[0,36,3.91]],"id":49744721},{"batb":[[0,4.6,53.4]],"id":50466254},{"batb":[[0,21,53.27]],"batl":[[2,25,8.03],[1,24,11.66],[0,23,5.45]],"id":106596}],"tv":87693.32}],"ArrivalTime":1710507965544}
{"op":"mcm","id":2,"clk":"AOUZAOwhAJEk","pt":1710507965641,"mc":[{"id":"1.226122413","rc":[{"batb":[[1,1.84,179.64]],"id":51922},{"tv":2257.49,"trd":[[36,65.8]],"batl":[[0,36,2.73]],"id":49744721},{"tv":1700.56,"batb":[[2,20,17.82],[1,21,49.27],[0,22,5.12]],"trd":[[24,94.79],[23,28.7]],"ltp":24,"batl":[[2,26,24.44],[1,25,8.03],[0,24,11.51]],"id":106596}],"tv":87706.88}],"ArrivalTime":1710507965648}
{"op":"mcm","id":2,"clk":"AOoZAPQhAJsk","pt":1710507965735,"mc":[{"id":"1.226122413","rc":[{"batb":[[0,8.2,26.92]],"id":41122648},{"batb":[[2,23,13.81],[1,24,16.1],[0,25,3.53]],"id":55632148},{"batb":[[2,1.82,202.97],[1,1.83,253.28],[0,1.84,179.64]],"id":51922},{"batl":[[1,38,8.52],[0,36,6.31]],"id":49744721},{"batb":[[0,4.6,68.4]],"batl":[[1,4.8,74.51]],"id":50466254},{"tv":1704.84,"batb":[[0,22,8.31]],"trd":[[24,99.07]],"batl":[[0,24,8.22]],"id":106596}],"tv":87711.16}],"ArrivalTime":1710507965742}
{"op":"mcm","id":2,"clk":"AO8ZAP8hAKUk","pt":1710507965836,"mc":[{"id":"1.226122413","rc":[{"tv":325.23,"trd":[[300,21.39]],"batl":[[0,300,6.18]],"id":54370634},{"tv":7132.85,"trd":[[8.4,747.22]],"ltp":8.4,"batl":[[0,8.4,8.68]],"id":41122648},{"tv":369.46,"trd":[[190,22.93]],"batl":[[0,190,1.2]],"id":41200638},{"tv":1695.33,"trd":[[26,268.12]],"ltp":26,"batl":[[0,26,5.39]],"id":55632148},{"tv":61798.16,"batb":[[2,1.81,178.22],[1,1.82,202.97],[0,1.85,25.23]],"trd":[[1.84,11186.47],[1.83,7870.15]],"ltp":1.83,"batl":[[0,1.86,641.58]],"id":51922},{"tv":2261.9,"trd":[[36,70.21]],"batl":[[0,36,2.26]],"id":49744721},{"tv":12968.46,"trd":[[4.7,94.04]],"ltp":4.7,"batl":[[2,4.9,143.24],[0,4.7,62.37]],"id":50466254},{"tv":449.09,"trd":[[150,24.9]],"ltp":150,"batl":[[2,190,3.94],[1,170,2.88],[0,160,2.05]],"id":66251581},{"tv":1720.62,"batb":[[2,21,49.27],[1,22,8.31],[0,23,1.32]],"trd":[[24,104.61],[23,38.94]],"ltp":23,"batl":[[0,24,2.68]],"id":106596}],"tv":88721.1}],"ArrivalTime":1710507965842}
{"op":"mcm","id":2,"clk":"APYZAIciALEk","pt":1710507965946,"mc":[{"id":"1.226122413","rc":[{"tv":7132.95,"batb":[[0,8.2,26.87]],"trd":[[8.2,346.9]],"ltp":8.2,"batl":[[0,8.4,11.95]],"id":41122648},{"batb":[[0,25,7.11]],"batl":[[2,28,26.95],[1,27,9.96],[0,26,6.19]],"id":55632148},{"tv":61848.62,"batb":[[0,1.83,61.96]],"trd":[[1.85,11501.28]],"ltp":1.85,"batl":[[2,1.86,641.58],[1,1.85,100.63],[0,1.84,86.99]],"id":51922},{"tv":12968.56,"batb":[[0,4.6,68.35]],"trd":[[4.6,1014.63]],"ltp":4.6,"batl":[[0,4.7,49.28]],"id":50466254},{"batb":[],"batl":[[0,24,5.19]],"id":106596}],"tv":88771.76}],"ArrivalTime":1710507965952}
{"op":"mcm","id":2,"clk":"AIAaAI0iALsk","pt":1710507966054,"mc":[{"id":"1.226122413","rc":[{"batb":[[1,8,95.54],[0,8.2,43.02]],"id":41122648},{"batb":[[1,170,15.59]],"id":41200638},{"batb":[[1,24,17.43],[0,25,13.37]],"batl":[[0,26,3.58]],"id":55632148},{"tv":62022.61,"trd":[[1.84,11360.46]],"ltp":1.84,"batl":[[2,1.87,146.95],[1,1.86,666.67],[0,1.85,100.68]],"id":51922},{"batl":[[2,42,10.38],[1,40,5.67],[0,38,6.52]],"id":49744721},{"batb":[[2,4.4,192.92]],"id":50466254},{"batb":[[2,110,1.36],[1,120,3.07],[0,130,1.51]],"batl":[[0,160,2.38]],"id":66251581},{"batb":[[1,22,11.31],[0,23,5.59]],"batl":[[0,24,7.55]],"id":106596}],"tv":88945.75}],"ArrivalTime":1710507966060}
{"op":"mcm","id":2,"clk":"AIcaAJUiAMck","pt":1710507966150,"mc":[{"id":"1.226122413","rc":[{"tv":7137.79,"batb":[[0,8.2,56.9]],"trd":[[8.4,752.06]],"ltp":8.4,"batl":[[0,8.4,9.53]],"id":41122648},{"batl":[[0,26,3.43]],"id":55632148},{"batb":[[2,1.82,202.97],[1,1.83,61.96],[0,1.84,10]],"id":51922},{"batb":[[0,4.6,108.89]],"batl":[[0,4.7,30.54]],"id":50466254},{"batb":[[2,21,50.53]],"id":106596}],"tv":88950.59}],"ArrivalTime":1710507966157}
{"op":"mcm","id":2,"clk":"AI4aAJ8iAM0k","pt":1710507966251,"mc":[{"id":"1.226122413","rc":[{"tv":62042.61,"batb":[[2,1.81,178.22],[1,1.82,231.97],[0,1.83,61.96]],"trd":[[1.84,11380.46]],"batl":[[2,1.86,666.67],[1,1.85,100.68],[0,1.84,82.77]],"id":51922},{"batl":[[0,38,4.35]],"id":49744721},{"batb":[[0,130,2.51]],"id":66251581},{"tv":1723.26,"batb":[[0,23,4.27]],"trd":[[23,41.58]],"batl":[[2,27,6.4],[1,26,24.44],[0,25,8.03]],"id":106596}],"tv":88973.23}],"ArrivalTime":1710507966257}
{"op":"mcm","id":2,"clk":"AJYaAKoiANkk","pt":1710507966358,"mc":[{"id":"1.226122413","rc":[{"batl":[[2,9,39.25],[1,8.8,26.49],[0,8.6,23.72]],"id":41122648},{"tv":62054.51,"trd":[[1.84,11392.36]],"batl":[[1,1.85,148.45],[0,1.84,76.82]],"id":51922},{"batb":[[2,21,49.27]],"batl":[[2,26,24.44],[1,25,8.03],[0,24,5.12]],"id":106596}],"tv":88985.13}],"ArrivalTime":1710507966364}
{"op":"mcm","id":2,"clk":"AJ8aALEiAOMk","pt":1710507966464,"mc":[{"id":"1.226122413","rc":[{"batb":[[0,23,12.06]],"id":106596}]}],"ArrivalTime":1710507966470}
{"op":"mcm","id":2,"clk":"AKgaALYiAOwk","pt":1710507966572,"mc":[{"id":"1.226122413","rc":[{"batb":[],"batl":[[0,8.6,25.72]],"id":41122648},{"batl":[[2,29,5.94],[1,28,26.95],[0,27,9.96]],"id":55632148},{"batb":[[2,1.81,170.66]],"batl":[[1,1.85,154.37]],"id":51922},{"batb":[[1,4.5,257.83]],"id":50466254},{"tv":1729.72,"batb":[[2,21,50.53],[0,23,8.83]],"trd":[[23,48.04]],"id":106596}],"tv":88991.59}],"ArrivalTime":1710507966579}
{"op":"mcm","id":2,"clk":"ALAaALoiAPck","pt":1710507966635,"mc":[{"id":"1.226122413","rc":[{"batl":[[1,1.85,179.31]],"id":51922},{"batl":[[2,40,5.67],[1,38,4.35],[0,36,1]],"id":49744721},{"tv":12986.56,"batb":[[0,4.6,99.89]],"trd":[[4.6,1032.63]],"id":50466254}],"tv":89009.59}],"ArrivalTime":1710507966641}
{"op":"mcm","id":2,"clk":"ALcaAMUiAIIl","pt":1710507966729,"mc":[{"id":"1.226122413","rc":[{"batl":[[0,27,9.22]],"id":55632148},{"batb":[[2,21,49.27],[1,22,12.44]],"id":106596}]}],"ArrivalTime":1710507966735}
{"op":"mcm","id":2,"clk":"AL4aANEiAIol","pt":1710507966834,"mc":[{"id":"1.226122413","rc":[{"batb":[[2,24,17.43],[1,25,13.37],[0,26,3.44]],"id":55632148},{"tv":62059.27,"trd":[[1.84,11397.12]],"batl":[[0,1.84,75.94]],"id":51922},{"tv":2262.74,"batb":[],"trd":[[36,71.05]],"batl":[[2,42,10.38],[1,40,5.67],[0,38,4.93]],"id":49744721},{"batb":[[1,22,14.21]],"id":106596}],"tv":89015.19}],"ArrivalTime":1710507966840}
{"op":"mcm","id":2,"clk":"AMQaANciAJAl","pt":1710507966938,"mc":[{"id":"1.226122413","rc":[{"tv":1696.93,"batb":[[0,26,2.64]],"trd":[[26,269.72]],"batl":[[0,27,9.96]],"id":55632148}],"tv":89016.79}],"ArrivalTime":1710507966944}
{"op":"mcm","id":2,"clk":"AMoaAOIiAJsl","pt":1710507967036,"mc":[{"id":"1.226122413","rc":[{"batb":[],"batl":[[1,40,8.61]],"id":49744721},{"batb":[[1,22,13.08]],"batl":[],"id":106596}]}],"ArrivalTime":1710507967042}
{"op":"mcm","id":2,"clk":"ANEaAO0iAKkl","pt":1710507967138,"mc":[{"id":"1.226122413","rc":[{"batb":[[2,24,20.1]],"id":55632148},{"batl":[[0,1.84,80.94]],"id":51922},{"tv":2263.46,"trd":[[36,71.77]],"batl":[[0,38,4.57]],"id":49744721}],"tv":89017.51}],"ArrivalTime":1710507967144}
{"op":"mcm","id":2,"clk":"ANYaAPEiALEl","pt":1710507967242,"mc":[{"id":"1.226122413","rc":[{"batb":[[2,23,13.81],[1,24,20.1],[0,25,13.37]],"id":55632148},{"tv":62069.59,"trd":[[1.84,11407.44]],"batl":[[0,1.84,75.78]],"id":51922},{"batb":[[0,23,10.83]],"id":106596}],"tv":89027.83}],"ArrivalTime":1710507967249}
{"op":"mcm","id":2,"clk":"AN8aAIAjAL0l","pt":1710507967357,"mc":[{"id":"1.226122413","rc":[{"tv":2263.9,"trd":[[36,72.21]],"batl":[[0,38,4.35]],"id":49744721}],"tv":89028.27}],"ArrivalTime":1710507967364}
{"op":"mcm","id":2,"clk":"AOYaAIkjAMkl","pt":1710507967449,"mc":[{"id":"1.226122413","rc":[{"batb":[[1,120,2.35],[0,130,3.18]],"id":66251581}]}],"ArrivalTime":1710507967455}
{"op":"mcm","id":2,"clk":"AOwaAJcjANUl","pt":1710507967579,"mc":[{"id":"1.226122413","rc":[{"batl":[[2,29,5.3],[1,28,26.26],[0,27,9.22]],"id":55632148},{"batb":[[0,1.83,64.37]],"id":51922}]}],"ArrivalTime":1710507967585}
{"op":"mcm","id":2,"clk":"APMaAJ8jAOYl","pt":1710507967659,"mc":[{"id":"1.226122413","rc":[{"batb":[[0,8.2,57.14]],"id":41122648}]}],"ArrivalTime":1710507967666}
{"op":"mcm","id":2,"clk":"APkaAKEjAO4l","pt":1710507967716,"mc":[{"id":"1.226122413","rc":[{"batl":[[1,1.85,194.31]],"id":51922}]}],"ArrivalTime":1710507967722}
{"op":"mcm","id":2,"clk":"AP8aAK4jAPol","pt":1710507967872,"mc":[{"id":"1.226122413","rc":[{"batb":[[2,1.81,164.49]],"id":51922}]}],"ArrivalTime":1710507967878}
{"op":"mcm","id":2,"clk":"AIkbALYjAIUm","pt":1710507967921,"mc":[{"id":"1.226122413","rc":[{"batb":[[1,22,15.08]],"id":106596}]}],"ArrivalTime":1710507967927}
{"op":"mcm","id":2,"clk":"AJIbAMAjAJIm","pt":1710507968037,"mc":[{"id":"1.226122413","rc":[{"batb":[[1,4.5,257.73]],"id":50466254}]}],"ArrivalTime":1710507968043}
{"op":"mcm","id":2,"clk":"AJobAMUjAJ8m","pt":1710507968131,"mc":[{"id":"1.226122413","rc":[{"batl":[[1,1.85,196.66]],"id":51922}]}],"ArrivalTime":1710507968137}
{"op":"mcm","id":2,"clk":"AKIbAMwjALIm","pt":1710507968239,"mc":[{"id":"1.226122413","rc":[{"batl":[[1,4.8,93.68]],"id":50466254}]}],"ArrivalTime":1710507968245}
{"op":"mcm","id":2,"clk":"AK0bANcjAMAm","pt":1710507968339,"mc":[{"id":"1.226122413","rc":[{"tv":62135.59,"trd":[[1.84,11473.44]],"batl":[[0,1.84,42.78]],"id":51922},{"tv":1748.22,"trd":[[25,180.71],[24,114.85]],"ltp":25,"batl":[[2,27,6.4],[1,26,24.44],[0,25,3.9]],"id":106596}],"tv":89112.77}],"ArrivalTime":1710507968345}
{"op":"mcm","id":2,"clk":"ALUbAOMjAM4m","pt":1710507968435,"mc":[{"id":"1.226122413","rc":[{"tv":62147.19,"trd":[[1.84,11485.04]],"batl":[[0,1.84,31.98]],"id":51922},{"batb":[[0,23,15.82]],"id":106596}],"tv":89124.37}],"ArrivalTime":1710507968442}
{"op":"mcm","id":2,"clk":"AL8bAOwjAN0m","pt":1710507968546,"mc":[{"id":"1.226122413","rc":[{"batl":[[0,1.84,54.98]],"id":51922},{"batb":[[0,23,16.44]],"batl":[[0,25,9.81]],"id":106596}]}],"ArrivalTime":1710507968552}
{"op":"mcm","id":2,"clk":"AMcbAPwjAOsm","pt":1710507968644,"mc":[{"id":"1.226122413","rc":[{"tv":7147.79,"batb":[[0,8.2,52.14]],"trd":[[8.2,356.9]],"ltp":8.2,"id":41122648},{"tv":1752.22,"batb":[[0,23,14.44]],"trd":[[23,52.04]],"ltp":23,"id":106596}],"tv":89138.37}],"ArrivalTime":1710507968650}
{"op":"mcm","id":2,"clk":"AMwbAIokAPsm","pt":1710507968751,"mc":[{"id":"1.226122413","rc":[{"tv":62171.73,"batb":[[0,1.83,52.1]],"trd":[[1.83,7894.69]],"ltp":1.83,"batl":[[0,1.84,114.03]],"id":51922},{"tv":12990.56,"trd":[[4.7,98.04]],"ltp":4.7,"batl":[[0,4.7,28.54]],"id":50466254}],"tv":89166.91}],"ArrivalTime":1710507968758}
{"op":"mcm","id":2,"clk":"ANQbAJskAIkn","pt":1710507968857,"mc":[{"id":"1.226122413","rc":[{"tv":12992,"batb":[[0,4.6,99.17]],"trd":[[4.6,1034.07]],"ltp":4.6,"id":50466254}],"tv":89168.35}],"ArrivalTime":1710507968863}
{"op":"mcm","id":2,"clk":"ANwbAKgkAJkn","pt":1710507968957,"mc":[{"id":"1.226122413","rc":[{"batl":[[2,1.86,669]],"id":51922},{"batb":[[0,23,17.44]],"id":106596}]}],"ArrivalTime":1710507968964}
{"op":"mcm","id":2,"clk":"AOEbALAkAKYn","pt":1710507969063,"mc":[{"id":"1.226122413","rc":[{"tv":62173.53,"trd":[[1.84,11486.84]],"ltp":1.84,"batl":[[0,1.84,113.13]],"id":51922},{"batb":[[2,30,26.46]],"id":49744721}],"tv":89170.15}],"ArrivalTime":1710507969070}
{"op":"mcm","id":2,"clk":"AOobAMAkALgn","pt":1710507969169,"mc":[{"id":"1.226122413","rc":[{"batl":[[2,29,5.94]],"id":55632148},{"tv":62793.1,"batb":[[2,1.82,231.97],[1,1.83,52.1],[0,1.85,544.18]],"trd":[[1.85,11894.6],[1.84,11713.09]],"ltp":1.85,"batl":[[2,1.88,275.84],[1,1.87,146.95],[0,1.86,669]],"id":51922},{"tv":2265.9,"trd":[[38,15.36]],"ltp":38,"batl":[[0,38,3.35]],"id":49744721},{"batb":[[0,130,5.8]],"id":66251581}],"tv":89791.72}],"ArrivalTime":1710507969176}
{"op":"mcm","id":2,"clk":"APEbAMYkAMMn","pt":1710507969216,"mc":[{"id":"1.226122413","rc":[{"batl":[[2,1.88,277.84]],"id":51922}]}],"ArrivalTime":1710507969222}
{"op":"mcm","id":2,"clk":"APkbANgkANUn","pt":1710507969375,"mc":[{"id":"1.226122413","rc":[{"batb":[],"batl":[[0,8.6,26.89]],"id":41122648},{"batl":[[2,29,5.3]],"id":55632148},{"batb":[[2,1.83,76.94],[1,1.84,24.7]],"batl":[[0,1.86,691.71]],"id":51922},{"batl":[[0,38,5.51]],"id":49744721},{"batb":[[0,4.6,57.33]],"batl":[[0,4.7,65.17]],"id":50466254},{"batb":[[0,23,13.45]],"id":106596}]}],"ArrivalTime":1710507969381}
{"op":"mcm","id":2,"clk":"AIUcAOkkAN8n","pt":1710507969437,"mc":[{"id":"1.226122413","rc":[{"batl":[[2,8.8,26.49],[1,8.6,26.89],[0,8.4,9.9]],"id":41122648},{"batb":[[1,1.84,84.8]],"id":51922},{"tv":13002,"batb":[[0,4.6,17]],"trd":[[4.6,1044.07]],"id":50466254}],"tv":89801.72}],"ArrivalTime":1710507969443}
{"op":"mcm","id":2,"clk":"AIocAPIkAO4n","pt":1710507969542,"mc":[{"id":"1.226122413","rc":[{"tv":63336.82,"batb":[[0,1.85,601.72]],"trd":[[1.86,6222.57],[1.85,11900.7]],"ltp":1.86,"batl":[[0,1.86,422.9]],"id":51922},{"tv":13036,"batb":[[2,4.3,249.02],[1,4.4,192.92],[0,4.5,257.73]],"trd":[[4.6,1078.07]],"batl":[[2,4.8,93.68],[1,4.7,65.17],[0,4.6,44.43]],"id":50466254}],"tv":90379.44}],"ArrivalTime":1710507969549}
{"op":"mcm","id":2,"clk":"AJMcAPskAPgn","pt":1710507969641,"mc":[{"id":"1.226122413","rc":[{"batb":[[0,8.2,43.99]],"batl":[[2,8.8,54.79]],"id":41122648},{"batl":[[2,28,26.26],[1,27,9.22],[0,26,3.47]],"id":55632148},{"tv":63859.64,"batb":[[2,1.83,194.27],[0,1.85,624.89]],"trd":[[1.86,6705.39],[1.85,11940.7]],"batl":[[1,1.87,206.96],[0,1.86,44.89]],"id":51922}],"tv":90902.26}],"ArrivalTime":1710507969648}
{"op":"mcm","id":2,"clk":"AJscAIclAIso","pt":1710507969751,"mc":[{"id":"1.226122413","rc":[{"batb":[[0,8.2,37.38]],"batl":[[0,8.4,17.55]],"id":41122648},{"tv":63949.42,"batb":[[2,1.84,150.33],[1,1.85,624.89],[0,1.86,311.05]],"trd":[[1.86,6795.17]],"batl":[[2,1.89,147.94],[1,1.88,277.84],[0,1.87,206.96]],"id":51922}],"tv":90992.04}],"ArrivalTime":1710507969758}
{"op":"mcm","id":2,"clk":"AKEcAI4lAJko","pt":1710507969843,"mc":[{"id":"1.226122413","rc":[{"batl":[[1,8.6,24.89],[0,8.4,24.8]],"id":41122648},{"tv":63961.34,"batb":[],"trd":[[1.87,3829.16]],"ltp":1.87,"batl":[[0,1.87,173.57]],"id":51922}],"tv":91003.96}],"ArrivalTime":1710507969849}
{"op":"mcm","id":2,"clk":"AKocAJclAKko","pt":1710507969949,"mc":[{"id":"1.226122413","rc":[{"tv":64302.59,"trd":[[1.87,4170.41]],"batl":[[0,1.87,2.94]],"id":51922},{"batb":[[0,23,11]],"id":106596}],"tv":91345.21}],"ArrivalTime":1710507969955}
{"op":"mcm","id":2,"clk":"ALIcAKMlALUo","pt":1710507970060,"mc":[{"id":"1.226122413","rc":[{"batb":[[0,8.2,13.54]],"batl":[[2,8.8,26.49]],"id":41122648},{"batb":[[0,1.86,335.23]],"id":51922}]}],"ArrivalTime":1710507970068}
{"op":"mcm","id":2,"clk":"ALgcAKglAMMo","pt":1710507970158,"mc":[{"id":"1.226122413","rc":[{"batb":[[1,8,91.25]],"batl":[[0,8.4,33.05]],"id":41122648},{"batb":[[0,25,9.6]],"id":55632148},{"tv":64308.47,"batb":[[2,1.85,624.89],[1,1.86,335.23],[0,1.87,34.84]],"trd":[[1.87,4176.29]],"batl":[[2,1.9,55.1],[1,1.89,147.94],[0,1.88,337.83]],"id":51922}],"tv":91351.09}],"ArrivalTime":1710507970164}
{"op":"mcm","id":2,"clk":"AMEcALMlAM8o","pt":1710507970263,"mc":[{"id":"1.226122413","rc":[{"batl":[[0,1.88,319.72]],"id":51922},{"batl":[[0,4.6,57.7]],"id":50466254},{"batb":[[0,23,11.09]],"id":106596}]}],"ArrivalTime":1710507970270}
{"op":"mcm","id":2,"clk":"AMkcAMglAOEo","pt":1710507970365,"mc":[{"id":"1.226122413","rc":[{"tv":7158.87,"batb":[[2,7.6,62.6],[1,7.8,69.99],[0,8,91.25]],"trd":[[8.2,367.98]],"batl":[[2,8.6,24.89],[1,8.4,33.05],[0,8.2,2.41]],"id":41122648},{"tv":64333.69,"batb":[[2,1.84,120.8],[1,1.85,624.89],[0,1.86,403.23]],"trd":[[1.87,4201.51]],"batl":[[2,1.89,147.94],[1,1.88,319.72],[0,1.87,82.56]],"id":51922},{"batl":[[0,38,7.51]],"id":49744721}],"tv":91387.39}],"ArrivalTime":1710507970371}
{"op":"mcm","id":2,"clk":"ANAcAM4lAO4o","pt":1710507970423,"mc":[{"id":"1.226122413","rc":[{"tv":64345.15,"trd":[[1.87,4212.97]],"batl":[[1,1.88,343.64],[0,1.87,76.83]],"id":51922}],"tv":91398.85}],"ArrivalTime":1710507970430}
{"op":"mcm","id":2,"clk":"ANkcAOYlAPso","pt":1710507970543,"mc":[{"id":"1.226122413","rc":[{"batb":[[2,7.6,64.64]],"batl":[[0,8.2,12.65]],"id":41122648},{"tv":64354.64,"trd":[[1.87,4222.46]],"batl":[[0,1.87,72.08]],"id":51922},{"batb":[[2,110,1.82],[1,120,2.74]],"id":66251581}],"tv":91408.34}],"ArrivalTime":1710507970549}
{"op":"mcm","id":2,"clk":"AN8cAPElAIIp","pt":1710507970635,"mc":[{"id":"1.226122413","rc":[{"batb":[[2,7.6,73.35]],"batl":[],"id":41122648},{"tv":64392.64,"trd":[[1.87,4260.46]],"batl":[[0,1.87,53.08]],"id":51922},{"batl":[[1,4.7,67.17]],"id":50466254}],"tv":91446.34}],"ArrivalTime":1710507970641}
{"op":"mcm","id":2,"clk":"AOYcAPolAIop","pt":1710507970734,"mc":[{"id":"1.226122413","rc":[{"batl":[[1,1.88,345.64]],"id":51922}]}],"ArrivalTime":1710507970741}
{"op":"mcm","id":2,"clk":"AOocAIcmAJQp","pt":1710507970869,"mc":[{"id":"1.226122413","rc":[{"tv":64498.8,"trd":[[1.87,4366.62]],"batl":[[2,1.9,55.1],[1,1.89,147.94],[0,1.88,345.64]],"id":51922}],"tv":91552.5}],"ArrivalTime":1710507970876}
{"op":"mcm","id":2,"clk":"AO8cAJAmAJ4p","pt":1710507970937,"mc":[{"id":"1.226122413","rc":[{"batb":[[0,8,87.58]],"batl":[[2,8.6,28.61]],"id":41122648},{"batb":[[1,1.85,103.75]],"batl":[[1,1.89,140.83]],"id":51922}]}],"ArrivalTime":1710507970944}
{"op":"mcm","id":2,"clk":"APgcAJkmAKgp","pt":1710507971051,"mc":[{"id":"1.226122413","rc":[{"batb":[[2,7.6,71.31],[0,8,86.33]],"id":41122648},{"batl":[[2,1.89,140.83],[1,1.88,345.64],[0,1.87,60.77]],"id":51922}]}],"ArrivalTime":1710507971058}
{"op":"mcm","id":2,"clk":"AP8cAKAmALMp","pt":1710507971150,"mc":[{"id":"1.226122413","rc":[{"tv":64528.8,"trd":[[1.87,4396.62]],"batl":[[0,1.87,45.77]],"id":51922}],"tv":91582.5}],"ArrivalTime":1710507971157}
{"op":"mcm","id":2,"clk":"AJQdAMEmANMp","pt":1710507971429,"mc":[{"id":"1.226122413","rc":[{"batb":[[1,7.8,79.99],[2,7.6,73.35]],"id":41122648},{"tv":64611.12,"batb":[[1,1.85,171.75],[0,1.86,294.07]],"trd":[[1.86,6877.49]],"ltp":1.86,"id":51922},{"batl":[[1,170,1.58]],"id":66251581},{"batb":[[2,22,15.08],[1,23,11.09],[0,24,7.95]],"id":106596}],"tv":91664.82,"con":true}],"ArrivalTime":1710507971436}
{"op":"mcm","id":2,"clk":"AJkdAMYmANMp","pt":1710507971458,"mc":[{"id":"1.226122413","rc":[{"tv":64755.76,"batb":[[0,1.86,193.42]],"trd":[[1.86,7022.13]],"id":51922},{"batb":[[0,4.5,267.13]],"id":50466254},{"tv":1753.84,"batb":[[1,23,13.77],[0,24,7.15]],"trd":[[24,116.47]],"ltp":24,"batl":[],"id":106596}],"tv":91811.08}],"ArrivalTime":1710507971465}
{"op":"mcm","id":2,"clk":"AKEdANEmAN4p","pt":1710507971568,"mc":[{"id":"1.226122413","rc":[{"tv":7178.87,"batb":[[0,8,76.33]],"trd":[[8,27.3]],"ltp":8,"batl":[[1,8.4,25.8]],"id":41122648},{"tv":64768.03,"batb":[[0,1.86,187.28]],"trd":[[1.86,7034.4]],"id":51922},{"batl":[[1,4.7,115.73]],"id":50466254}],"tv":91843.35}],"ArrivalTime":1710507971575}
{"op":"mcm","id":2,"clk":"AKgdANsmAOwp","pt":1710507971618,"mc":[{"id":"1.226122413","rc":[{"batb":[],"batl":[[2,380,1.3]],"id":54370634},{"tv":64813.15,"batb":[[0,1.86,164.72]],"trd":[[1.86,7079.52]],"id":51922}],"tv":91888.47}],"ArrivalTime":1710507971625}
{"op":"mcm","id":2,"clk":"AK8dAOcmAPMp","pt":1710507971770,"mc":[{"id":"1.226122413","rc":[{"tv":7190.32,"batb":[[2,7.6,74.56]],"trd":[[8.2,379.43]],"ltp":8.2,"batl":[[0,8.2,6.92]],"id":41122648},{"batb":[],"batl":[[1,1.88,347.64],[0,1.87,69.53]],"id":51922},{"batl":[[0,4.6,44.43]],"id":50466254}],"tv":91899.92}],"ArrivalTime":1710507971776}
{"op":"mcm","id":2,"clk":"ALkdAPImAIMq","pt":1710507971836,"mc":[{"id":"1.226122413","rc":[{"tv":7204.16,"batb":[[2,7.8,79.99],[1,8,76.33],[0,8.2,3.08]],"trd":[[8.2,393.27]],"batl":[[2,8.8,26.49],[1,8.6,28.61],[0,8.4,25.8]],"id":41122648},{"batb":[[0,1.86,140.54]],"id":51922}],"tv":91913.76}],"ArrivalTime":1710507971843}
{"op":"mcm","id":2,"clk":"AMcdAPomAI0q","pt":1710507971934,"mc":[{"id":"1.226122413","rc":[{"batb":[[0,8.2,4.5]],"batl":[],"id":41122648},{"batb":[[2,1.83,196.84],[1,1.84,130.8],[0,1.85,171.75]],"id":51922}]}],"ArrivalTime":1710507971941}
{"op":"mcm","id":2,"clk":"ANAdAIMnAJcq","pt":1710507972038,"mc":[{"id":"1.226122413","rc":[{"batb":[[2,7.8,83.67],[0,8.2,15]],"id":41122648},{"tv":64823.55,"trd":[[1.87,4407.02]],"ltp":1.87,"batl":[[0,1.87,64.33]],"id":51922},{"batl":[[1,170,2.61]],"id":66251581}],"tv":91924.16}],"ArrivalTime":1710507972044}
{"op":"mcm","id":2,"clk":"AOIdAJcnAKcq","pt":1710507972243,"mc":[{"id":"1.226122413","rc":[{"batl":[[0,4.6,45.15]],"id":50466254},{"tv":452.05,"batb":[[0,130,4.32]],"trd":[[130,83.85]],"ltp":130,"batl":[],"id":66251581},{"tv":1768.14,"batb":[[2,21,49.27],[1,22,15.08],[0,23,13.77]],"trd":[[24,130.77]],"id":106596}],"tv":91941.42}],"ArrivalTime":1710507972249}
{"op":"mcm","id":2,"clk":"AO4dALMnALcq","pt":1710507972451,"mc":[{"id":"1.226122413","rc":[{"tv":64832.69,"batb":[[0,1.85,167.18]],"trd":[[1.85,11949.84]],"ltp":1.85,"id":51922},{"batb":[[1,22,27.46]],"batl":[[1,26,26.5]],"id":106596}],"tv":91950.56}],"ArrivalTime":1710507972458}
{"op":"mcm","id":2,"clk":"AP0dAM8nAMsq","pt":1710507972667,"mc":[{"id":"1.226122413","rc":[{"batb":[[0,1.85,200.18]],"id":51922},{"tv":13048,"trd":[[4.6,1090.07]],"batl":[[0,4.6,39.15]],"id":50466254}],"tv":91962.56}],"ArrivalTime":1710507972674}
{"op":"mcm","id":2,"clk":"AJIeAO4nAO0q","pt":1710507972972,"mc":[{"id":"1.226122413","rc":[{"batl":[[1,1.88,349.64]],"id":51922},{"batl":[[0,160,7.56]],"id":66251581}]}],"ArrivalTime":1710507972979}
{"op":"mcm","id":2,"clk":"AJoeAPsnAPcq","pt":1710507973031,"mc":[{"id":"1.226122413","rc":[{"tv":327.23,"trd":[[300,23.39]],"batl":[[0,300,5.18]],"id":54370634}],"tv":91964.56}],"ArrivalTime":1710507973038}
{"op":"mcm","id":2,"clk":"AKgeAI0oAI4r","pt":1710507973251,"mc":[{"id":"1.226122413","rc":[{"batb":[[0,1.85,202.53]],"id":51922},{"batb":[[1,22,19.51]],"batl":[[1,26,25.47]],"id":106596}]}],"ArrivalTime":1710507973258}
{"op":"mcm","id":2,"clk":"ANUeANIoANAr","pt":1710507973761,"mc":[{"id":"1.226122413","rc":[{"batb":[[0,1.85,204.88]],"id":51922}]}],"ArrivalTime":1710507973768}
{"op":"mcm","id":2,"clk":"AOgeAN4oAOgr","pt":1710507973965,"mc":[{"id":"1.226122413","rc":[{"tv":1712.37,"batb":[[0,25,1.88]],"trd":[[25,310.5]],"ltp":25,"id":55632148}],"tv":91980}],"ArrivalTime":1710507973972}
{"op":"mcm","id":2,"clk":"APIeAOcoAPcr","pt":1710507974032,"mc":[{"id":"1.226122413","rc":[{"batl":[[1,1.88,351.64]],"id":51922}]}],"ArrivalTime":1710507974038}
{"op":"mcm","id":2,"clk":"APUeAPYoAIMs","pt":1710507974132,"mc":[{"id":"1.226122413","rc":[{"batb":[[0,25,7.3]],"id":55632148},{"tv":64841.01,"batb":[[2,1.83,232.84],[0,1.85,200.72]],"trd":[[1.85,11958.16]],"batl":[[0,1.87,40.57]],"id":51922}],"tv":91988.32}],"ArrivalTime":1710507974138}
{"op":"mcm","id":2,"clk":"APseAIEpAIos","pt":1710507974288,"mc":[{"id":"1.226122413","rc":[{"tv":64846.43,"trd":[[1.87,4412.44]],"ltp":1.87,"batl":[[0,1.87,37.86]],"id":51922},{"batb":[[0,130,1.7]],"id":66251581}],"tv":91993.74}],"ArrivalTime":1710507974294}
{"op":"mcm","id":2,"clk":"AIQfAJIpAJMs","pt":1710507974333,"mc":[{"id":"1.226122413","rc":[{"batb":[[0,8.2,15.24]],"id":41122648},{"batb":[[2,1.84,130.8],[1,1.85,253.84],[0,1.86,25.5]],"id":51922}]}],"ArrivalTime":1710507974340}
{"op":"mcm","id":2,"clk":"AIofAJopAJ8s","pt":1710507974435,"mc":[{"id":"1.226122413","rc":[{"batl":[[0,8.4,27.8]],"id":41122648},{"batb":[[0,25,9.83]],"batl":[],"id":55632148},{"batb":[[0,1.86,86.49]],"id":51922}]}],"ArrivalTime":1710507974442}
{"op":"mcm","id":2,"clk":"AJIfAKEpAKos","pt":1710507974540,"mc":[{"id":"1.226122413","rc":[{"batb":[[2,110,1.36],[1,120,2.35]],"id":66251581}]}],"ArrivalTime":1710507974546}
{"op":"mcm","id":2,"clk":"AJgfAKspALUs","pt":1710507974647,"mc":[{"id":"1.226122413","rc":[{"tv":64946.43,"batb":[[0,1.86,36.49]],"trd":[[1.86,7179.52]],"ltp":1.86,"batl":[[0,1.87,47.86]],"id":51922},{"tv":13058,"batb":[[0,4.5,262.13]],"trd":[[4.5,2265.25]],"ltp":4.5,"id":50466254},{"batb":[[0,130,2.71]],"id":66251581},{"batb":[[0,23,15.77]],"id":106596}],"tv":92103.74}],"ArrivalTime":1710507974653}
{"op":"mcm","id":2,"clk":"AJ8fAKwpAMAs","pt":1710507974738,"mc":[{"id":"1.226122413","rc":[{"tv":64991.35,"batb":[[2,1.83,232.84],[1,1.84,130.8],[0,1.85,253.84]],"trd":[[1.86,7224.44]],"id":51922}],"tv":92148.66}],"ArrivalTime":1710507974745}
{"op":"mcm","id":2,"clk":"AKgfALcpAMos","pt":1710507974859,"mc":[{"id":"1.226122413","rc":[{"batl":[[2,1.88,351.64],[1,1.87,47.86],[0,1.86,28.64]],"id":51922}]}],"ArrivalTime":1710507974866}
{"op":"mcm","id":2,"clk":"ALAfAMUpANgs","pt":1710507974948,"mc":[{"id":"1.226122413","rc":[{"tv":13059.8,"trd":[[4.6,1091.87]],"ltp":4.6,"batl":[[0,4.6,38.25]],"id":50466254}],"tv":92150.46}],"ArrivalTime":1710507974955}
{"op":"mcm","id":2,"clk":"ALcfANIpAOos","pt":1710507975054,"mc":[{"id":"1.226122413","rc":[{"batl":[[2,1.89,140.83],[1,1.88,353.64],[0,1.87,73.22]],"id":51922}]}],"ArrivalTime":1710507975061}
{"op":"mcm","id":2,"clk":"AL0fANcpAPcs","pt":1710507975152,"mc":[{"id":"1.226122413","rc":[{"batb":[[1,1.84,133.18]],"id":51922}]}],"ArrivalTime":1710507975159}
{"op":"mcm","id":2,"clk":"AMEfAOEpAIQt","pt":1710507975261,"mc":[{"id":"1.226122413","rc":[{"batb":[[2,1.83,247.84]],"id":51922}]}],"ArrivalTime":1710507975268}
{"op":"mcm","id":2,"clk":"AMQfAOspAJAt","pt":1710507975366,"mc":[{"id":"1.226122413","rc":[{"batl":[[0,190,7.2]],"id":41200638}]}],"ArrivalTime":1710507975373}
{"op":"mcm","id":2,"clk":"ANIfAPgpAKQt","pt":1710507975521,"mc":[{"id":"1.226122413","rc":[{"batb":[[1,1.84,266.78]],"id":51922},{"batl":[[1,4.7,67.17]],"id":50466254}]}],"ArrivalTime":1710507975527}
{"op":"mcm","id":2,"clk":"ANYfAIYqAK8t","pt":1710507975625,"mc":[{"id":"1.226122413","rc":[{"batb":[[1,1.84,139.52]],"id":51922}]}],"ArrivalTime":1710507975632}
{"op":"mcm","id":2,"clk":"ANwfAI0qALot","pt":1710507975733,"mc":[{"id":"1.226122413","rc":[{"tv":7208.16,"batb":[[0,8.2,13.24]],"trd":[[8.2,397.27]],"id":41122648},{"batl":[[0,1.87,47.86]],"id":51922},{"batb":[[2,21,57.62]],"id":106596}],"tv":92154.46}],"ArrivalTime":1710507975739}
{"op":"mcm","id":2,"clk":"AOcfAJYqAMQt","pt":1710507975840,"mc":[{"id":"1.226122413","rc":[{"batl":[[1,1.88,355.64]],"id":51922}]}],"ArrivalTime":1710507975847}
{"op":"mcm","id":2,"clk":"AO8fAKAqANAt","pt":1710507975945,"mc":[{"id":"1.226122413","rc":[{"batb":[[2,1.84,139.52],[1,1.85,253.84],[0,1.86,26.21]],"id":51922}]}],"ArrivalTime":1710507975951}
{"op":"mcm","id":2,"clk":"APYfAKYqANUt","pt":1710507976037,"mc":[{"id":"1.226122413","rc":[{"tv":65038.05,"batb":[[0,1.86,2.86]],"trd":[[1.86,7271.14]],"id":51922}],"tv":92201.16}],"ArrivalTime":1710507976044}
{"op":"mcm","id":2,"clk":"AP4fAK8qAOIt","pt":1710507976142,"mc":[{"id":"1.226122413","rc":[{"batb":[[2,1.84,133.18]],"batl":[[0,1.87,73.93]],"id":51922}]}],"ArrivalTime":1710507976149}
{"op":"mcm","id":2,"clk":"AIUgALcqAO0t","pt":1710507976251,"mc":[{"id":"1.226122413","rc":[{"batb":[[2,7.8,83.41]],"id":41122648},{"batb":[[2,1.84,148.18],[0,1.86,4.47]],"batl":[],"id":51922}]}],"ArrivalTime":1710507976258}
{"op":"mcm","id":2,"clk":"AJAgAL4qAPIt","pt":1710507976348,"mc":[{"id":"1.226122413","rc":[{"tv":65046.05,"batb":[[2,1.83,247.84],[1,1.84,148.18],[0,1.85,254.31]],"trd":[[1.86,7279.14]],"id":51922}],"tv":92209.16}],"ArrivalTime":1710507976355}
{"op":"mcm","id":2,"clk":"AJggAMsqAPst","pt":1710507976449,"mc":[{"id":"1.226122413","rc":[{"batl":[[0,38,5.35]],"id":49744721}]}],"ArrivalTime":1710507976456}
{"op":"mcm","id":2,"clk":"AKEgANoqAIcu","pt":1710507976559,"mc":[{"id":"1.226122413","rc":[{"tv":65473.04,"batb":[[0,1.85,40.81]],"trd":[[1.86,7280.08],[1.85,12384.21]],"ltp":1.85,"id":51922}],"tv":92636.15}],"ArrivalTime":1710507976565}
{"op":"mcm","id":2,"clk":"AKggAOcqAJAu","pt":1710507976661,"mc":[{"id":"1.226122413","rc":[{"batl":[[2,1.88,355.64],[1,1.87,73.93],[0,1.86,58.53]],"id":51922},{"batb":[[0,23,20.2]],"id":106596}]}],"ArrivalTime":1710507976668}
{"op":"mcm","id":2,"clk":"AKwgAOkqAJsu","pt":1710507976759,"mc":[{"id":"1.226122413","rc":[{"tv":65515.06,"batb":[[0,1.85,81.09]],"trd":[[1.85,12426.23]],"batl":[[0,1.86,119.49]],"id":51922}],"tv":92678.17}],"ArrivalTime":1710507976766}
{"op":"mcm","id":2,"clk":"ALIgAPUqAKYu","pt":1710507976856,"mc":[{"id":"1.226122413","rc":[{"batb":[[0,8.2,21.24]],"id":41122648},{"batl":[[2,29,5.3],[1,28,26.26],[0,27,9.22]],"id":55632148},{"batb":[[1,1.84,169.18]],"id":51922},{"batb":[[0,23,19.77]],"id":106596}]}],"ArrivalTime":1710507976863}
{"op":"mcm","id":2,"clk":"AL0gAIArALMu","pt":1710507976965,"mc":[{"id":"1.226122413","rc":[{"tv":65631.84,"batb":[[0,1.85,22.7]],"trd":[[1.85,12543.01]],"id":51922}],"tv":92794.95}],"ArrivalTime":1710507976972}
{"op":"mcm","id":2,"clk":"AMogAJIrAMUu","pt":1710507977173,"mc":[{"id":"1.226122413","rc":[{"tv":65661.84,"batb":[[2,1.82,238.92],[1,1.83,247.84],[0,1.84,169.18]],"trd":[[1.85,12573.01]],"batl":[[2,1.87,73.93],[1,1.86,146.37],[0,1.85,18.33]],"id":51922}],"tv":92824.95}],"ArrivalTime":1710507977180}
{"op":"mcm","id":2,"clk":"AM8gAJsrANIu","pt":1710507977223,"mc":[{"id":"1.226122413","rc":[{"batl":[[2,1.87,75.93]],"id":51922}]}],"ArrivalTime":1710507977229}
{"op":"mcm","id":2,"clk":"ANQgAKQrAOAu","pt":1710507977377,"mc":[{"id":"1.226122413","rc":[{"batb":[[0,25,14.19]],"id":55632148},{"tv":65698.49,"batb":[[0,1.84,217.86]],"trd":[[1.85,12609.66]],"batl":[[2,1.88,355.64],[1,1.87,75.93],[0,1.86,146.37]],"id":51922},{"batl":[[2,4.9,143.24],[1,4.8,93.68],[0,4.7,67.89]],"id":50466254},{"batl":[[0,25,5.91]],"id":106596}],"tv":92861.6}],"ArrivalTime":1710507977384}
{"op":"mcm","id":2,"clk":"ANkgAKsrAOwu","pt":1710507977428,"mc":[{"id":"1.226122413","rc":[{"tv":65901.45,"batb":[[0,1.84,116.38]],"trd":[[1.84,11916.05]],"ltp":1.84,"id":51922}],"tv":93064.56}],"ArrivalTime":1710507977436}
{"op":"mcm","id":2,"clk":"AOIgALErAPku","pt":1710507977537,"mc":[{"id":"1.226122413","rc":[{"batb":[],"batl":[[0,8.4,19.55]],"id":41122648},{"batb":[[2,1.83,247.84],[1,1.84,203.41],[0,1.85,1.39]],"batl":[],"id":51922},{"tv":13061.24,"batb":[],"trd":[[4.6,1093.31]],"batl":[[0,4.7,67.17]],"id":50466254}],"tv":93066}],"ArrivalTime":1710507977544}
{"op":"mcm","id":2,"clk":"AOcgALorAIQv","pt":1710507977640,"mc":[{"id":"1.226122413","rc":[{"tv":65904.23,"batb":[[2,1.82,238.92],[1,1.83,247.84],[0,1.84,203.41]],"trd":[[1.85,12612.44]],"ltp":1.85,"batl":[[2,1.87,75.93],[1,1.86,146.37],[0,1.85,22.63]],"id":51922}],"tv":93068.78}],"ArrivalTime":1710507977647}
{"op":"mcm","id":2,"clk":"APggANArAJov","pt":1710507977845,"mc":[{"id":"1.226122413","rc":[{"tv":7222.5,"batb":[[0,8.2,14.07]],"trd":[[8.2,411.61]],"id":41122648},{"batl":[[2,1.87,77.93]],"id":51922}],"tv":93083.12}],"ArrivalTime":1710507977852}
{"op":"mcm","id":2,"clk":"AP4gANgrAKcv","pt":1710507977945,"mc":[{"id":"1.226122413","rc":[{"batl":[[0,8.4,27.79]],"id":41122648},{"batb":[[2,4.4,192.92],[1,4.5,262.13],[0,4.6,13.07]],"batl":[[1,4.8,137.49]],"id":50466254}]}],"ArrivalTime":1710507977951}
{"op":"mcm","id":2,"clk":"AIQhAOQrALMv","pt":1710507978050,"mc":[{"id":"1.226122413","rc":[{"batb":[],"batl":[[0,4.7,65.01]],"id":50466254}]}],"ArrivalTime":1710507978057}
{"op":"mcm","id":2,"clk":"AIshAPIrAMAv","pt":1710507978158,"mc":[{"id":"1.226122413","rc":[{"batb":[],"batl":[[0,8.4,37.55]],"id":41122648}]}],"ArrivalTime":1710507978165}
{"op":"mcm","id":2,"clk":"AJUhAP8rANIv","pt":1710507978356,"mc":[{"id":"1.226122413","rc":[{"tv":65907.55,"trd":[[1.85,12615.76]],"batl":[[0,1.85,20.97]],"id":51922}],"tv":93086.44}],"ArrivalTime":1710507978363}
{"op":"mcm","id":2,"clk":"AJ4hAIosAN8v","pt":1710507978463,"mc":[{"id":"1.226122413","rc":[{"batb":[[2,22,19.51],[1,23,19.77],[0,24,3.92]],"id":106596}]}],"ArrivalTime":1710507978470}
{"op":"mcm","id":2,"clk":"AKshAJAsAO8v","pt":1710507978570,"mc":[{"id":"1.226122413","rc":[{"tv":1730.37,"batb":[[0,25,5.19]],"trd":[[25,328.5]],"id":55632148},{"batl":[[2,1.87,80.23]],"id":51922}],"tv":93104.44}],"ArrivalTime":1710507978578}
{"op":"mcm","id":2,"clk":"ALIhAJIsAPov","pt":1710507978665,"mc":[{"id":"1.226122413","rc":[{"batl":[[0,27,13.06]],"id":55632148},{"batb":[[2,22,22.64],[0,24,8.05]],"id":106596}]}],"ArrivalTime":1710507978672}
{"op":"mcm","id":2,"clk":"ALYhAJ4sAIgw","pt":1710507978770,"mc":[{"id":"1.226122413","rc":[{"batb":[[0,25,13.81]],"id":55632148},{"tv":65949.49,"batb":[],"trd":[[1.85,12657.7]],"batl":[[2,1.88,355.64],[1,1.87,80.23],[0,1.86,146.37]],"id":51922}],"tv":93146.38}],"ArrivalTime":1710507978777}
{"op":"mcm","id":2,"clk":"AL4hAKUsAI8w","pt":1710507978823,"mc":[{"id":"1.226122413","rc":[{"batl":[[2,28,5.49],[1,27,6.4],[0,26,24.44]],"id":106596}]}],"ArrivalTime":1710507978829}
{"op":"mcm","id":2,"clk":"AMEhAKssAJsw","pt":1710507978927,"mc":[{"id":"1.226122413","rc":[{"batl":[[2,28,26.26],[1,27,13.06],[0,26,3.69]],"id":55632148},{"tv":66005.61,"batb":[[0,1.84,175.35]],"trd":[[1.84,11972.17]],"ltp":1.84,"id":51922},{"tv":13078.96,"batb":[[0,4.6,4.21]],"trd":[[4.6,1111.03]],"id":50466254},{"batb":[[0,24,11.05]],"batl":[[0,26,20.44]],"id":106596}],"tv":93220.22}],"ArrivalTime":1710507978934}
{"op":"mcm","id":2,"clk":"AMchALosAKUw","pt":1710507979032,"mc":[{"id":"1.226122413","rc":[{"batb":[[0,25,9.45]],"id":55632148},{"tv":13087.38,"batb":[[2,4.3,249.02],[1,4.4,192.92],[0,4.5,262.13]],"trd":[[4.6,1119.45]],"batl":[[2,4.8,137.49],[1,4.7,65.01],[0,4.6,2.3]],"id":50466254}],"tv":93228.64}],"ArrivalTime":1710507979039}
{"op":"mcm","id":2,"clk":"AM0hAL4sALAw","pt":1710507979138,"mc":[{"id":"1.226122413","rc":[{"batl":[[2,1.88,357.91]],"id":51922},{"batb":[[1,4.4,188.92]],"batl":[],"id":50466254}]}],"ArrivalTime":1710507979144}
{"op":"mcm","id":2,"clk":"ANEhAM8sALww","pt":1710507979242,"mc":[{"id":"1.226122413","rc":[{"batb":[[2,23,19.76]],"batl":[],"id":55632148},{"batb":[[2,30,34.59]],"id":49744721},{"batb":[[0,4.5,266.13]],"id":50466254}]}],"ArrivalTime":1710507979248}
{"op":"mcm","id":2,"clk":"ANghANQsAMQw","pt":1710507979342,"mc":[{"id":"1.226122413","rc":[{"tv":1737.75,"batb":[[2,24,20.1],[1,25,9.45],[0,26,3.81]],"trd":[[26,277.1]],"ltp":26,"batl":[[2,29,5.3],[1,28,26.26],[0,27,13.06]],"id":55632148},{"batb":[[0,1.84,177.35]],"id":51922},{"batb":[[2,30,26.46]],"id":49744721}],"tv":93236.02}],"ArrivalTime":1710507979349}
{"op":"mcm","id":2,"clk":"AN8hANgsANEw","pt":1710507979445,"mc":[{"id":"1.226122413","rc":[{"tv":1745.37,"batb":[[2,23,13.81],[1,24,20.1],[0,25,9.45]],"trd":[[26,284.72]],"id":55632148},{"batb":[[0,24,13.05]],"id":106596}],"tv":93243.64}],"ArrivalTime":1710507979452}
{"op":"mcm","id":2,"clk":"AOIhAOIsAN4w","pt":1710507979547,"mc":[{"id":"1.226122413","rc":[{"batl":[[2,29,5.94],[1,28,26.95],[0,27,13.8]],"id":55632148}]}],"ArrivalTime":1710507979554}
{"op":"mcm","id":2,"clk":"AO8hAPksAO8w","pt":1710507979749,"mc":[{"id":"1.226122413","rc":[{"batl":[[2,29,5.3],[1,28,26.26],[0,27,13.06]],"id":55632148}]}],"ArrivalTime":1710507979756}
{"op":"mcm","id":2,"clk":"APYhAIYtAPkw","pt":1710507979852,"mc":[{"id":"1.226122413","rc":[{"batb":[[2,1.83,247.84],[1,1.84,177.35],[0,1.85,2]],"id":51922}]}],"ArrivalTime":1710507979859}
{"op":"mcm","id":2,"clk":"AP0hAJYtAIEx","pt":1710507979961,"mc":[{"id":"1.226122413","rc":[{"batl":[[2,29,5.94]],"id":55632148}]}],"ArrivalTime":1710507979967}
{"op":"mcm","id":2,"clk":"AIMiAKItAIsx","pt":1710507980069,"mc":[{"id":"1.226122413","rc":[{"tv":66009.61,"batb":[[2,1.82,238.92],[1,1.83,247.84],[0,1.84,177.35]],"trd":[[1.85,12661.7]],"ltp":1.85,"batl":[[2,1.87,80.23],[1,1.86,146.37],[0,1.85,21.2]],"id":51922}],"tv":93247.64}],"ArrivalTime":1710507980076}
{"op":"mcm","id":2,"clk":"AJYiALItAJwx","pt":1710507980280,"mc":[{"id":"1.226122413","rc":[{"tv":66052.01,"batb":[[2,1.83,247.84],[1,1.84,177.35],[0,1.85,57.48]],"trd":[[1.85,12704.1]],"batl":[[2,1.88,357.91],[1,1.87,80.23],[0,1.86,146.37]],"id":51922}],"tv":93290.04}],"ArrivalTime":1710507980287}
{"op":"mcm","id":2,"clk":"AJkiALktAKYx","pt":1710507980379,"mc":[{"id":"1.226122413","rc":[{"batl":[[0,1.86,107.77]],"id":51922}]}],"ArrivalTime":1710507980386}
{"op":"mcm","id":2,"clk":"AKQiAM0tALcx","pt":1710507980584,"mc":[{"id":"1.226122413","rc":[{"tv":7226.5,"batb":[[0,8.2,12.07]],"trd":[[8.2,415.61]],"id":41122648}],"tv":93294.04}],"ArrivalTime":1710507980591}
{"op":"mcm","id":2,"clk":"ALAiANktAM4x","pt":1710507980802,"mc":[{"id":"1.226122413","rc":[{"batl":[[1,1.87,82.23]],"id":51922}]}],"ArrivalTime":1710507980809}
{"op":"mcm","id":2,"clk":"AMYiAPctAPAx","pt":1710507981207,"mc":[{"id":"1.226122413","rc":[{"tv":329.23,"trd":[[300,25.39]],"batl":[[0,300,4.18]],"id":54370634},{"batb":[[2,1.82,238.92],[1,1.83,247.84],[0,1.84,177.35]],"id":51922}],"tv":93296.04}],"ArrivalTime":1710507981214}
{"op":"mcm","id":2,"clk":"AM4iAIguAP8x","pt":1710507981411,"mc":[{"id":"1.226122413","rc":[{"batb":[[2,260,4.1],[1,270,1.19],[0,280,1.02]],"id":54370634},{"tv":66068.01,"batb":[[0,1.84,184.35]],"trd":[[1.84,11988.17]],"ltp":1.84,"id":51922}],"tv":93312.04}],"ArrivalTime":1710507981418}
{"op":"mcm","id":2,"clk":"ANYiAJguAJMy","pt":1710507981567,"mc":[{"id":"1.226122413","rc":[{"batb":[[1,270,2.72]],"id":54370634},{"batb":[[0,1.84,214.35]],"id":51922}]}],"ArrivalTime":1710507981574}
{"op":"mcm","id":2,"clk":"ANwiAKUuAJ4y","pt":1710507981677,"mc":[{"id":"1.226122413","rc":[{"batb":[[0,1.84,229.35]],"id":51922}]}],"ArrivalTime":1710507981684}
{"op":"mcm","id":2,"clk":"AOUiALouALMy","pt":1710507981883,"mc":[{"id":"1.226122413","rc":[{"batb":[[2,1.83,247.84],[1,1.84,229.35],[0,1.85,2]],"id":51922},{"batb":[[0,4.5,266.65]],"id":50466254}]}],"ArrivalTime":1710507981890}
{"op":"mcm","id":2,"clk":"AO8iAMEuAMEy","pt":1710507981992,"mc":[{"id":"1.226122413","rc":[{"batb":[],"batl":[[2,4.8,140.29]],"id":50466254}]}],"ArrivalTime":1710507981999}
{"op":"mcm","id":2,"clk":"APUiAMUuAMcy","pt":1710507982090,"mc":[{"id":"1.226122413","rc":[{"batl":[[1,1.87,84.23]],"id":51922},{"tv":1783.58,"batb":[[0,24,5.33]],"trd":[[24,146.21]],"id":106596}],"tv":93327.48}],"ArrivalTime":1710507982097}
{"op":"mcm","id":2,"clk":"APsiAMwuANMy","pt":1710507982194,"mc":[{"id":"1.226122413","rc":[{"batb":[],"batl":[[2,4.8,137.49]],"id":50466254},{"batl":[[2,27,6.4],[1,26,24.39],[0,25,10]],"id":106596}]}],"ArrivalTime":1710507982201}
{"op":"mcm","id":2,"clk":"AP8iANsuAOMy","pt":1710507982324,"mc":[{"id":"1.226122413","rc":[{"batb":[[0,8.2,12.31]],"id":41122648},{"batl":[[0,25,11.18]],"id":106596}]}],"ArrivalTime":1710507982331}
{"op":"mcm","id":2,"clk":"AIUjAN4uAOgy","pt":1710507982374,"mc":[{"id":"1.226122413","rc":[{"batl":[[1,1.87,86.23]],"id":51922}]}],"ArrivalTime":1710507982381}
{"op":"mcm","id":2,"clk":"AIojAOcuAPQy","pt":1710507982481,"mc":[{"id":"1.226122413","rc":[{"batb":[[2,7.8,85.35]],"id":41122648},{"batl":[[0,1.86,122.77]],"id":51922}]}],"ArrivalTime":1710507982488}
{"op":"mcm","id":2,"clk":"AJQjAP0uAIsz","pt":1710507982679,"mc":[{"id":"1.226122413","rc":[{"batl":[[0,1.86,125.1]],"id":51922}]}],"ArrivalTime":1710507982686}
{"op":"mcm","id":2,"clk":"AJkjAIYvAJoz","pt":1710507982798,"mc":[{"id":"1.226122413","rc":[{"batb":[[1,1.84,279.35]],"batl":[[0,1.86,126.1]],"id":51922}]}],"ArrivalTime":1710507982805}
{"op":"mcm","id":2,"clk":"AKgjAJovALAz","pt":1710507983008,"mc":[{"id":"1.226122413","rc":[{"tv":334.23,"batb":[[2,250,4],[1,260,4.1],[0,270,1.24]],"trd":[[280,9.7],[270,6.35]],"ltp":270,"id":54370634}],"tv":93332.48}],"ArrivalTime":1710507983015}
{"op":"mcm","id":2,"clk":"ALYjALMvAMwz","pt":1710507983212,"mc":[{"id":"1.226122413","rc":[{"batb":[[2,260,4.1],[1,270,1.24],[0,280,1.03]],"id":54370634},{"tv":13124.28,"batb":[[0,4.5,248.19]],"trd":[[4.5,2302.15]],"ltp":4.5,"id":50466254},{"batl":[[0,25,14.27]],"id":106596}],"tv":93369.38}],"ArrivalTime":1710507983219}
{"op":"mcm","id":2,"clk":"ALojAL0vANQz","pt":1710507983314,"mc":[{"id":"1.226122413","rc":[{"batb":[[2,1.83,249.84]],"id":51922}]}],"ArrivalTime":1710507983320}
{"op":"mcm","id":2,"clk":"AL4jAMYvAOAz","pt":1710507983424,"mc":[{"id":"1.226122413","rc":[{"batb":[[0,1.85,56.73]],"id":51922},{"batl":[[0,4.6,48.05]],"id":50466254},{"batl":[[0,25,21.47]],"id":106596}]}],"ArrivalTime":1710507983430}
{"op":"mcm","id":2,"clk":"AMojANovAPIz","pt":1710507983576,"mc":[{"id":"1.226122413","rc":[{"tv":66102.65,"batb":[[0,1.85,95.17]],"trd":[[1.86,7314.72]],"ltp":1.86,"batl":[[0,1.86,81.9]],"id":51922},{"batb":[[0,24,5]],"id":106596}],"tv":93404.02}],"ArrivalTime":1710507983583}
{"op":"mcm","id":2,"clk":"ANgjAOgvAIc0","pt":1710507983776,"mc":[{"id":"1.226122413","rc":[{"batb":[[1,270,2.31]],"id":54370634},{"tv":66111.65,"batb":[[0,1.85,117.62]],"trd":[[1.85,12713.1]],"ltp":1.85,"id":51922}],"tv":93413.02}],"ArrivalTime":1710507983783}
{"op":"mcm","id":2,"clk":"AN0jAPIvAJE0","pt":1710507983879,"mc":[{"id":"1.226122413","rc":[{"batb":[[0,1.85,127.62]],"id":51922},{"batl":[[0,160,6.05]],"id":66251581}]}],"ArrivalTime":1710507983886}
{"op":"mcm","id":2,"clk":"AOIjAP4vAKA0","pt":1710507983989,"mc":[{"id":"1.226122413","rc":[{"batb":[[0,1.85,129.62]],"id":51922}]}],"ArrivalTime":1710507983996}
{"op":"mcm","id":2,"clk":"AP0jAKQwAMs0","pt":1710507984415,"mc":[{"id":"1.226122413","rc":[{"batb":[[0,4.5,250.19]],"id":50466254}]}],"ArrivalTime":1710507984422}
{"op":"mcm","id":2,"clk":"AKMkAN8wAJk1","pt":1710507985114,"mc":[{"id":"1.226122413","rc":[{"batb":[[1,8,93.8]],"batl":[],"id":41122648},{"batb":[[1,24,23.1],[0,25,15.2]],"batl":[[1,28,23.8]],"id":55632148},{"tv":66121.65,"batb":[[1,1.84,280.35]],"trd":[[1.86,7324.72]],"ltp":1.86,"batl":[[0,1.86,74.29]],"id":51922},{"batb":[[2,30,20.37],[1,32,23.33]],"id":49744721},{"batb":[[1,4.4,164.52]],"id":50466254}],"tv":93423.02,"con":true}],"ArrivalTime":1710507985123}
{"op":"mcm","id":2,"clk":"AKkkAOowAKI1","pt":1710507985181,"mc":[{"id":"1.226122413","rc":[{"batb":[[0,1.85,144.62]],"id":51922}]}],"ArrivalTime":1710507985188}
{"op":"mcm","id":2,"clk":"ALAkAPMwALM1","pt":1710507985282,"mc":[{"id":"1.226122413","rc":[{"batl":[[1,1.87,88.23]],"id":51922}]}],"ArrivalTime":1710507985289}
{"op":"mcm","id":2,"clk":"ALokAIoxAMo1","pt":1710507985483,"mc":[{"id":"1.226122413","rc":[{"batb":[[1,170,18],[0,180,6.93]],"id":41200638},{"batl":[[1,28,27.86]],"id":55632148},{"tv":2270.66,"batb":[[1,32,27.99],[0,34,32.18]],"trd":[[38,20.12]],"batl":[[0,38,2.97]],"id":49744721},{"batb":[[1,23,27.39],[0,24,12.62]],"id":106596}],"tv":93427.78}],"ArrivalTime":1710507985490}
{"op":"mcm","id":2,"clk":"AMIkAJExANc1","pt":1710507985597,"mc":[{"id":"1.226122413","rc":[{"tv":7230.5,"batb":[[0,8.2,10.31]],"trd":[[8.2,419.61]],"id":41122648},{"batl":[[1,1.87,91.32]],"id":51922}],"tv":93431.78}],"ArrivalTime":1710507985604}
{"op":"mcm","id":2,"clk":"AMokAJoxAOY1","pt":1710507985696,"mc":[{"id":"1.226122413","rc":[{"tv":66270.23,"batb":[[2,1.84,280.35],[1,1.85,169.62],[0,1.86,6.71]],"trd":[[1.86,7473.3]],"batl":[[2,1.89,162.79],[1,1.88,357.91],[0,1.87,94.41]],"id":51922},{"batb":[[2,32,27.99],[1,34,32.18],[0,36,3.7]],"batl":[[1,40,5.67],[0,38,3.34]],"id":49744721}],"tv":93580.36}],"ArrivalTime":1710507985703}
{"op":"mcm","id":2,"clk":"AM8kAKQxAOs1","pt":1710507985804,"mc":[{"id":"1.226122413","rc":[{"batl":[[0,4.6,61.3]],"id":50466254}]}],"ArrivalTime":1710507985811}
{"op":"mcm","id":2,"clk":"ANQkAK4xAPY1","pt":1710507985902,"mc":[{"id":"1.226122413","rc":[{"batb":[[2,7.8,83.41],[0,8.2,8.48]],"id":41122648},{"batb":[[1,1.85,220.62]],"id":51922},{"batb":[[0,36,13.24]],"id":49744721}]}],"ArrivalTime":1710507985909}
{"op":"mcm","id":2,"clk":"ANskALkxAIM2","pt":1710507986011,"mc":[{"id":"1.226122413","rc":[{"batl":[[2,29,5.3]],"id":55632148}]}],"ArrivalTime":1710507986018}
{"op":"mcm","id":2,"clk":"AOEkAMExAJA2","pt":1710507986114,"mc":[{"id":"1.226122413","rc":[{"batb":[[0,36,16.18]],"id":49744721}]}],"ArrivalTime":1710507986121}
{"op":"mcm","id":2,"clk":"AO0kANIxAJ42","pt":1710507986317,"mc":[{"id":"1.226122413","rc":[{"batl":[[0,1.87,97.41]],"id":51922}]}],"ArrivalTime":1710507986325}
{"op":"mcm","id":2,"clk":"APYkANoxAKo2","pt":1710507986369,"mc":[{"id":"1.226122413","rc":[{"batl":[[2,370,3.67]],"id":54370634}]}],"ArrivalTime":1710507986376}
{"op":"mcm","id":2,"clk":"AIIlAOYxALQ2","pt":1710507986470,"mc":[{"id":"1.226122413","rc":[{"batb":[[1,1.85,234.62]],"id":51922}]}],"ArrivalTime":1710507986477}
{"op":"mcm","id":2,"clk":"AIolAO0xAL02","pt":1710507986574,"mc":[{"id":"1.226122413","rc":[{"tv":7240.5,"batb":[[0,8.2,14.11]],"trd":[[8.2,429.61]],"id":41122648}],"tv":93590.36}],"ArrivalTime":1710507986581}
{"op":"mcm","id":2,"clk":"AJolAP8xAM02","pt":1710507986777,"mc":[{"id":"1.226122413","rc":[{"tv":66283.65,"batb":[[2,1.83,249.84],[1,1.84,280.35],[0,1.85,234.62]],"trd":[[1.86,7486.72]],"batl":[[2,1.88,357.91],[1,1.87,97.41],[0,1.86,8.29]],"id":51922}],"tv":93603.78}],"ArrivalTime":1710507986785}
{"op":"mcm","id":2,"clk":"AKAlAIkyANg2","pt":1710507986885,"mc":[{"id":"1.226122413","rc":[{"tv":66300.23,"trd":[[1.86,7503.3]],"batl":[[2,1.89,162.79],[1,1.88,357.91],[0,1.87,97.41]],"id":51922}],"tv":93620.36}],"ArrivalTime":1710507986892}
{"op":"mcm","id":2,"clk":"AKIlAJIyAOc2","pt":1710507986994,"mc":[{"id":"1.226122413","rc":[{"batb":[[1,8,90.27]],"id":41122648},{"batb":[[2,1.84,280.35],[1,1.85,234.62],[0,1.86,853.97]],"id":51922}]}],"ArrivalTime":1710507987001}
{"op":"mcm","id":2,"clk":"AKwlAJwyAOw2","pt":1710507987092,"mc":[{"id":"1.226122413","rc":[{"tv":66394.75,"trd":[[1.87,4506.96]],"ltp":1.87,"batl":[[0,1.87,50.15]],"id":51922}],"tv":93714.88}],"ArrivalTime":1710507987099}
{"op":"mcm","id":2,"clk":"ALQlAKcyAPs2","pt":1710507987204,"mc":[{"id":"1.226122413","rc":[{"batb":[[0,8.2,18.87]],"id":41122648},{"batl":[[2,28,27.86],[1,27,13.06],[0,26,3.81]],"id":55632148},{"batb":[[0,1.86,930.68]],"batl":[[0,1.87,75.38]],"id":51922},{"batb":[[0,24,9.62]],"id":106596}]}],"ArrivalTime":1710507987211}
{"op":"mcm","id":2,"clk":"AL8lALwyAIw3","pt":1710507987405,"mc":[{"id":"1.226122413","rc":[{"batb":[[0,25,9.45]],"id":55632148},{"batb":[[1,1.85,236.62]],"batl":[],"id":51922}]}],"ArrivalTime":1710507987412}
{"op":"mcm","id":2,"clk":"AMMlAMoyAJY3","pt":1710507987508,"mc":[{"id":"1.226122413","rc":[{"tv":66467.3,"batb":[],"trd":[[1.87,4579.51]],"batl":[[0,1.87,39.1]],"id":51922},{"batb":[[1,120,2.22]],"id":66251581}],"tv":93787.43}],"ArrivalTime":1710507987515}
{"op":"mcm","id":2,"clk":"AMklAM0yAJ83","pt":1710507987620,"mc":[{"id":"1.226122413","rc":[{"batb":[[1,1.85,238.97]],"batl":[[2,1.89,155.83]],"id":51922}]}],"ArrivalTime":1710507987627}
{"op":"mcm","id":2,"clk":"ANQlAOEyALU3","pt":1710507987828,"mc":[{"id":"1.226122413","rc":[{"tv":66509.85,"batb":[[1,1.85,363.35],[0,1.86,912.41]],"trd":[[1.86,7545.85]],"ltp":1.86,"id":51922}],"tv":93829.98}],"ArrivalTime":1710507987835}
{"op":"mcm","id":2,"clk":"ANslAOYyALU3","pt":1710507987919,"mc":[{"id":"1.226122413","rc":[{"tv":66588.05,"batb":[[2,1.85,363.35],[1,1.86,912.41],[0,1.87,38.05]],"trd":[[1.87,4657.71]],"ltp":1.87,"batl":[[2,1.9,70.1],[1,1.89,155.83],[0,1.88,357.91]],"id":51922}],"tv":93908.18}],"ArrivalTime":1710507987926}
{"op":"mcm","id":2,"clk":"AOAlAOsyAL03","pt":1710507988022,"mc":[{"id":"1.226122413","rc":[{"batb":[[0,8.2,8.24]],"id":41122648}]}],"ArrivalTime":1710507988029}
{"op":"mcm","id":2,"clk":"AOglAPAyAMI3","pt":1710507988077,"mc":[{"id":"1.226122413","rc":[{"tv":7249.04,"batb":[[2,7.6,72.26],[1,7.8,83.41],[0,8,90.27]],"trd":[[8.2,438.15]],"id":41122648},{"tv":66664.15,"batb":[[2,1.84,280.35],[1,1.85,363.35],[0,1.86,969.62]],"trd":[[1.87,4733.81]],"batl":[[2,1.89,155.83],[1,1.88,357.91],[0,1.87,53.69]],"id":51922},{"batb":[[0,4.5,231.71]],"id":50466254}],"tv":93992.82}],"ArrivalTime":1710507988084}
{"op":"mcm","id":2,"clk":"AOwlAPgyAMo3","pt":1710507988174,"mc":[{"id":"1.226122413","rc":[{"tv":13133.3,"batb":[],"trd":[[4.6,1128.47]],"ltp":4.6,"batl":[[0,4.6,56.79]],"id":50466254}],"tv":94001.84}],"ArrivalTime":1710507988181}
{"op":"mcm","id":2,"clk":"APIlAIIzANY3","pt":1710507988281,"mc":[{"id":"1.226122413","rc":[{"batb":[[1,24,16.1]],"id":55632148},{"tv":66684.15,"batb":[[0,1.86,959.62]],"trd":[[1.86,7565.85]],"ltp":1.86,"batl":[],"id":51922},{"tv":13153.3,"batb":[[0,4.5,221.71]],"trd":[[4.5,2322.15]],"ltp":4.5,"batl":[[1,4.7,80.01]],"id":50466254}],"tv":94041.84}],"ArrivalTime":1710507988289}
{"op":"mcm","id":2,"clk":"APUlAIwzAOM3","pt":1710507988387,"mc":[{"id":"1.226122413","rc":[{"batb":[[0,4.5,223.71]],"id":50466254}]}],"ArrivalTime":1710507988394}
{"op":"mcm","id":2,"clk":"AIUmAKAzAPU3","pt":1710507988596,"mc":[{"id":"1.226122413","rc":[{"batb":[[1,24,18.83]],"id":55632148},{"tv":66791.53,"batb":[[2,1.85,365.35],[1,1.86,136.92],[0,1.87,31.71]],"trd":[[1.87,4841.19]],"ltp":1.87,"batl":[[2,1.9,70.1],[1,1.89,155.83],[0,1.88,357.91]],"id":51922},{"tv":452.25,"trd":[[150,25.1]],"ltp":150,"batl":[[0,160,5.95]],"id":66251581}],"tv":94149.42}],"ArrivalTime":1710507988603}
{"op":"mcm","id":2,"clk":"AJAmAK8zAIE4","pt":1710507988700,"mc":[{"id":"1.226122413","rc":[{"tv":66854.95,"batb":[[2,1.84,280.35],[1,1.85,365.35],[0,1.86,136.92]],"trd":[[1.87,4904.61]],"batl":[[2,1.89,155.83],[1,1.88,357.91],[0,1.87,43.22]],"id":51922}],"tv":94212.84}],"ArrivalTime":1710507988708}
{"op":"mcm","id":2,"clk":"AJkmALYzAIg4","pt":1710507988808,"mc":[{"id":"1.226122413","rc":[{"tv":336.23,"batb":[[2,250,4],[1,260,4.1],[0,270,2.34]],"trd":[[280,11.7]],"ltp":280,"id":54370634},{"tv":66894.95,"batb":[[0,1.86,116.92]],"trd":[[1.86,7605.85]],"ltp":1.86,"batl":[[0,1.87,131.15]],"id":51922},{"batl":[[2,170,2.61],[1,160,5.2],[0,150,2.94]],"id":66251581}],"tv":94254.84}],"ArrivalTime":1710507988815}
{"op":"mcm","id":2,"clk":"AKAmAMIzAI84","pt":1710507988908,"mc":[{"id":"1.226122413","rc":[{"batb":[[0,1.86,65.92]],"id":51922},{"batb":[[0,4.5,232.59]],"id":50466254}]}],"ArrivalTime":1710507988915}
{"op":"mcm","id":2,"clk":"AKgmAMozAJ84","pt":1710507989015,"mc":[{"id":"1.226122413","rc":[{"batb":[[0,270,2.61]],"id":54370634},{"tv":67065.74,"batb":[[0,1.86,40.5]],"trd":[[1.87,5075.4]],"ltp":1.87,"batl":[[0,1.87,70.83]],"id":51922},{"batb":[[0,4.5,259.04]],"id":50466254},{"batb":[[2,110,1.82]],"id":66251581}],"tv":94425.63}],"ArrivalTime":1710507989022}
{"op":"mcm","id":2,"clk":"ALAmANQzAJ84","pt":1710507989117,"mc":[{"id":"1.226122413","rc":[{"batb":[[0,8,87.5]],"id":41122648},{"tv":67259.84,"trd":[[1.87,5217.06],[1.88,4372.09]],"ltp":1.88,"batl":[[2,1.9,70.1],[1,1.89,155.83],[0,1.88,331.69]],"id":51922}],"tv":94619.73}],"ArrivalTime":1710507989125}
{"op":"mcm","id":2,"clk":"ALcmAN0zAKo4","pt":1710507989220,"mc":[{"id":"1.226122413","rc":[{"batb":[[0,1.86,78.46]],"id":51922}]}],"ArrivalTime":1710507989228}
{"op":"mcm","id":2,"clk":"ALsmAOIzALk4","pt":1710507989321,"mc":[{"id":"1.226122413","rc":[{"tv":389.46,"trd":[[200,70.16],[190,37.33]],"ltp":200,"batl":[[2,220,1.69],[1,210,5.76],[0,200,7.13]],"id":41200638},{"batb":[[1,24,16.1]],"id":55632148},{"batb":[[2,1.85,365.35],[1,1.86,103.66],[0,1.87,5.25]],"id":51922},{"batl":[[2,160,5.2],[1,150,2.94],[0,140,1.27]],"id":66251581}],"tv":94639.73}],"ArrivalTime":1710507989328}
{"op":"mcm","id":2,"clk":"AMEmAO0zAMA4","pt":1710507989427,"mc":[{"id":"1.226122413","rc":[{"batl":[[2,42,7.94]],"id":49744721},{"batb":[[1,120,3.76],[0,130,5.13]],"id":66251581}]}],"ArrivalTime":1710507989434}
{"op":"mcm","id":2,"clk":"AMYmAPQzANA4","pt":1710507989482,"mc":[{"id":"1.226122413","rc":[{"tv":338.23,"trd":[[300,27.39]],"ltp":300,"batl":[[0,300,3.18]],"id":54370634},{"batb":[[0,180,7.58]],"batl":[[0,200,5.53]],"id":41200638},{"tv":67370.34,"batb":[[2,1.84,280.35],[1,1.85,367.7],[0,1.86,103.66]],"trd":[[1.87,5327.56]],"ltp":1.87,"batl":[[2,1.89,155.83],[1,1.88,331.69],[0,1.87,6.16]],"id":51922},{"batb":[[0,4.5,232.59]],"id":50466254},{"tv":454.25,"batb":[[0,130,4.13]],"trd":[[130,85.85]],"ltp":130,"batl":[[2,170,2.61],[1,160,6.6]],"id":66251581}],"tv":94754.23}],"ArrivalTime":1710507989490}
{"op":"mcm","id":2,"clk":"AM4mAPozANs4","pt":1710507989580,"mc":[{"id":"1.226122413","rc":[{"batl":[[1,160,7.05]],"id":66251581}]}],"ArrivalTime":1710507989588}
{"op":"mcm","id":2,"clk":"ANcmAIE0AOc4","pt":1710507989720,"mc":[{"id":"1.226122413","rc":[{"tv":454.81,"batb":[[1,120,4.15],[0,130,4.46]],"trd":[[140,58.22]],"ltp":140,"batl":[[1,160,4.95],[0,150,1.86]],"id":66251581}],"tv":94754.79}],"ArrivalTime":1710507989727}
{"op":"mcm","id":2,"clk":"AN4mAIc0API4","pt":1710507989794,"mc":[{"id":"1.226122413","rc":[{"tv":7289.03,"trd":[[8.4,792.05]],"ltp":8.4,"batl":[[0,8.4,17.55]],"id":41122648},{"batb":[[0,1.86,115.11]],"id":51922}],"tv":94794.78}],"ArrivalTime":1710507989801}
{"op":"mcm","id":2,"clk":"AOMmAIs0AP44","pt":1710507989893,"mc":[{"id":"1.226122413","rc":[{"batb":[[2,7.8,83.41],[1,8,87.5],[0,8.2,11.11]],"batl":[[0,8.4,28.39]],"id":41122648},{"batb":[],"batl":[[2,1.9,70.1],[1,1.89,155.83],[0,1.88,331.69]],"id":51922},{"batb":[[2,110,1.36],[1,120,3.76],[0,130,4.13]],"batl":[[0,150,1.41]],"id":66251581}]}],"ArrivalTime":1710507989900}
{"op":"mcm","id":2,"clk":"AOsmAJE0AI45","pt":1710507989992,"mc":[{"id":"1.226122413","rc":[{"batb":[],"batl":[[0,8.4,34.97]],"id":41122648}]}],"ArrivalTime":1710507989999}
{"op":"mcm","id":2,"clk":"APQmAJw0AJg5","pt":1710507990095,"mc":[{"id":"1.226122413","rc":[{"batb":[[1,8,76.33]],"id":41122648},{"batb":[[0,130,3.46]],"id":66251581}]}],"ArrivalTime":1710507990102}
{"op":"mcm","id":2,"clk":"APkmAKM0AJ45","pt":1710507990201,"mc":[{"id":"1.226122413","rc":[{"batb":[[1,1.85,369.7],[0,1.86,117.11]],"id":51922}]}],"ArrivalTime":1710507990208}
{"op":"mcm","id":2,"clk":"AIAnAK00AKY5","pt":1710507990303,"mc":[{"id":"1.226122413","rc":[{"tv":7304.48,"batb":[[0,8.2,3.39]],"trd":[[8.2,453.6]],"ltp":8.2,"id":41122648},{"tv":2278.08,"batb":[[0,36,12.47]],"trd":[[36,79.63]],"ltp":36,"id":49744721}],"tv":94817.65}],"ArrivalTime":1710507990310}
{"op":"mcm","id":2,"clk":"AIknALk0AK05","pt":1710507990408,"mc":[{"id":"1.226122413","rc":[{"batb":[[0,1.86,119.11]],"id":51922},{"batb":[[0,36,14.13]],"id":49744721},{"tv":472.75,"batb":[[2,120,3.76],[1,130,3.46],[0,170,1.03]],"trd":[[170,22.81],[160,15.92],[150,25.94],[140,60.2]],"ltp":170,"batl":[[2,210,1],[1,200,1.27],[0,190,3.94]],"id":66251581}],"tv":94835.59}],"ArrivalTime":1710507990415}
{"op":"mcm","id":2,"clk":"AJEnAMA0ALY5","pt":1710507990513,"mc":[{"id":"1.226122413","rc":[{"tv":7308.48,"batb":[[2,7.6,72.26],[1,7.8,83.41],[0,8,76.33]],"trd":[[8.2,457.6]],"id":41122648},{"tv":394.94,"batb":[[0,180,4.84]],"trd":[[190,38.63],[180,19.49]],"ltp":180,"id":41200638},{"batb":[[1,1.85,245.32]],"id":51922},{"tv":2280.8,"batb":[[0,36,12.77]],"trd":[[36,82.35]],"id":49744721},{"tv":476.89,"batb":[[2,110,1.36],[1,120,3.76],[0,130,1.75]],"trd":[[170,24.87],[130,87.93]],"ltp":130,"batl":[],"id":66251581}],"tv":94851.93}],"ArrivalTime":1710507990520}
{"op":"mcm","id":2,"clk":"AJonAMk0AMI5","pt":1710507990620,"mc":[{"id":"1.226122413","rc":[{"batb":[[2,1.85,245.32],[1,1.86,119.11],[0,1.87,85.4]],"batl":[],"id":51922},{"batb":[[0,36,11.11]],"id":49744721},{"batb":[[0,140,3.24]],"batl":[[2,170,5.58],[1,160,2.19],[0,150,2.34]],"id":66251581}]}],"ArrivalTime":1710507990627}
{"op":"mcm","id":2,"clk":"AJ0nAM80AMg5","pt":1710507990725,"mc":[{"id":"1.226122413","rc":[{"batb":[[2,120,3.76],[1,130,1]],"id":66251581}]}],"ArrivalTime":1710507990732}
{"op":"mcm","id":2,"clk":"AKUnANQ0ANE5","pt":1710507990827,"mc":[{"id":"1.226122413","rc":[{"batb":[],"batl":[[0,4.6,77.81]],"id":50466254},{"batb":[[2,120,4.15],[1,130,3.55],[0,140,3.52]],"id":66251581}]}],"ArrivalTime":1710507990834}
{"op":"mcm","id":2,"clk":"ALUnAOY0AOk5","pt":1710507990994,"mc":[{"id":"1.226122413","rc":[{"batl":[[0,8.4,36.97]],"id":41122648},{"tv":2284.8,"batb":[[0,36,9.11]],"trd":[[36,86.35]],"id":49744721},{"batb":[[2,130,1.33],[1,140,3.52],[0,150,1.78]],"batl":[[2,190,3.94],[1,170,5.58],[0,160,2.19]],"id":66251581}],"tv":94855.93}],"ArrivalTime":1710507991002}
{"op":"mcm","id":2,"clk":"ALsnAO00APU5","pt":1710507991089,"mc":[{"id":"1.226122413","rc":[{"tv":348.58,"batb":[[2,260,4.1],[1,270,2.61],[0,330,4.82]],"trd":[[330,32.48],[300,33.74]],"ltp":330,"batl":[[2,420,1.77],[1,410,1.27],[0,370,3.67]],"id":54370634},{"tv":477.31,"batb":[[1,140,5.27],[0,150,2.02]],"trd":[[160,16.34]],"ltp":160,"batl":[[2,190,3.36],[0,160,1.98]],"id":66251581}],"tv":94866.7}],"ArrivalTime":1710507991096}
{"op":"mcm","id":2,"clk":"AMEnAPs0AII6","pt":1710507991194,"mc":[{"id":"1.226122413","rc":[{"tv":354.58,"batb":[[0,330,1.82]],"trd":[[330,38.48]],"id":54370634},{"tv":477.47,"batb":[[2,120,4.15],[1,130,1.33],[0,140,5.1]],"trd":[[150,26.1]],"ltp":150,"batl":[[1,170,1.03]],"id":66251581}],"tv":94872.86}],"ArrivalTime":1710507991201}
{"op":"mcm","id":2,"clk":"AMUnAIg1AI46","pt":1710507991299,"mc":[{"id":"1.226122413","rc":[{"tv":354.8,"batb":[[2,270,1.37],[1,320,1.54],[0,330,1.71]],"trd":[[330,38.7]],"batl":[],"id":54370634},{"batb":[[1,1.86,173.11]],"id":51922},{"batb":[[0,140,5.29]],"id":66251581}],"tv":94873.08}],"ArrivalTime":1710507991306}
{"op":"mcm","id":2,"clk":"AMwnAJQ1AJI6","pt":1710507991405,"mc":[{"id":"1.226122413","rc":[{"tv":67420.34,"batb":[[0,1.87,117.99]],"trd":[[1.87,5377.56]],"id":51922},{"batb":[[0,140,5.85]],"id":66251581}],"tv":94923.08}],"ArrivalTime":1710507991412}
{"op":"mcm","id":2,"clk":"ANInAJ81AJo6","pt":1710507991510,"mc":[{"id":"1.226122413","rc":[{"tv":67428.92,"batb":[[0,1.87,113.71]],"trd":[[1.87,5386.14]],"id":51922},{"batb":[[2,130,1.33],[1,140,5.29],[0,150,1.72]],"id":66251581}],"tv":94931.66}],"ArrivalTime":1710507991519}
{"op":"mcm","id":2,"clk":"ANYnAKY1AKc6","pt":1710507991608,"mc":[{"id":"1.226122413","rc":[{"tv":355.02,"batb":[[0,330,1.6]],"trd":[[330,38.92]],"id":54370634},{"batb":[[0,36,7.48]],"id":49744721}],"tv":94931.88}],"ArrivalTime":1710507991615}
{"op":"mcm","id":2,"clk":"AN4nALM1ALQ6","pt":1710507991710,"mc":[{"id":"1.226122413","rc":[{"batb":[[2,1.85,243.32]],"id":51922},{"batb":[[0,150,1.96]],"batl":[[2,200,1.27],[1,190,3.36],[0,170,1.03]],"id":66251581}]}],"ArrivalTime":1710507991717}
{"op":"mcm","id":2,"clk":"AOUnALg1ALw6","pt":1710507991816,"mc":[{"id":"1.226122413","rc":[{"batb":[[2,270,1.74]],"batl":[[2,420,2.09],[1,400,1.23],[0,370,2.82]],"id":54370634},{"batb":[[1,1.86,175.11],[0,1.87,56.11]],"id":51922}]}],"ArrivalTime":1710507991823}
{"op":"mcm","id":2,"clk":"APQnAMw1ANE6","pt":1710507991928,"mc":[{"id":"1.226122413","rc":[{"batb":[[1,1.86,177.11]],"id":51922},{"batb":[[2,130,1],[1,140,5.01],[0,150,2.72]],"id":66251581}]}],"ArrivalTime":1710507991935}
{"op":"mcm","id":2,"clk":"AJcoAPc1AP86","pt":1710507992442,"mc":[{"id":"1.226122413","rc":[{"tv":68092.28,"batb":[[2,1.86,177.11],[1,1.87,56.11],[0,1.88,522.31]],"trd":[[1.88,5035.45]],"ltp":1.88,"batl":[[2,1.91,79.7],[1,1.9,70.1],[0,1.89,155.83]],"id":51922},{"batb":[[2,130,1.33]],"id":66251581}],"tv":95595.24}],"ArrivalTime":1710507992449}
{"op":"mcm","id":2,"clk":"AJsoAIM2AIY7","pt":1710507992495,"mc":[{"id":"1.226122413","rc":[{"batb":[[1,1.87,113.66]],"id":51922}]}],"ArrivalTime":1710507992502}
{"op":"mcm","id":2,"clk":"AKQoAI02AI87","pt":1710507992653,"mc":[{"id":"1.226122413","rc":[{"batb":[],"batl":[[2,8.6,28.61],[1,8.4,36.97],[0,8.2,11.58]],"id":41122648},{"batb":[[0,25,3.83]],"batl":[[0,26,10.73]],"id":55632148},{"tv":68115.02,"batb":[[2,1.86,170.9],[1,1.87,168.2],[0,1.88,600.02]],"trd":[[1.88,5051.85],[1.89,2409.66]],"batl":[[2,1.91,129.7],[0,1.89,192.18]],"id":51922},{"batb":[[0,4.5,165.16]],"id":50466254},{"batb":[[2,130,1]],"id":66251581},{"batl":[[0,25,25.48]],"id":106596}],"tv":95617.98}],"ArrivalTime":1710507992660}
{"op":"mcm","id":2,"clk":"AKkoAJI2AJY7","pt":1710507992697,"mc":[{"id":"1.226122413","rc":[{"batb":[[0,8,64.58]],"batl":[[1,8.4,49.44]],"id":41122648},{"batb":[[2,22,19.67],[1,23,13.81],[0,24,16.1]],"id":55632148},{"batl":[[1,1.9,127.86]],"id":51922}]}],"ArrivalTime":1710507992704}
{"op":"mcm","id":2,"clk":"AKwoAJw2AJ47","pt":1710507992800,"mc":[{"id":"1.226122413","rc":[{"batb":[[0,8,56.58]],"id":41122648},{"batb":[[0,24,15.1]],"batl":[[2,27,13.8],[1,26,10.73],[0,25,8.08]],"id":55632148},{"tv":13209.62,"batb":[[0,4.5,137]],"trd":[[4.5,2378.47]],"id":50466254}],"tv":95674.3}],"ArrivalTime":1710507992808}
{"op":"mcm","id":2,"clk":"ALQoAKM2AKw7","pt":1710507992905,"mc":[{"id":"1.226122413","rc":[{"batl":[[2,27,13.06]],"id":55632148}]}],"ArrivalTime":1710507992912}
{"op":"mcm","id":2,"clk":"ALooAK02ALI7","pt":1710507993007,"mc":[{"id":"1.226122413","rc":[{"batb":[[0,8,44.3]],"batl":[[0,8.2,18.98]],"id":41122648},{"batl":[[1,26,13.43]],"id":55632148},{"batb":[[1,1.87,195.69]],"batl":[[1,1.9,117.58]],"id":51922},{"tv":13219.96,"batb":[[0,4.5,131.83]],"trd":[[4.5,2388.81]],"id":50466254}],"tv":95684.64}],"ArrivalTime":1710507993014}
{"op":"mcm","id":2,"clk":"AL8oALQ2ALk7","pt":1710507993106,"mc":[{"id":"1.226122413","rc":[{"tv":68138,"trd":[[1.89,2432.64]],"ltp":1.89,"batl":[[0,1.89,180.69]],"id":51922}],"tv":95707.62}],"ArrivalTime":1710507993113}
{"op":"mcm","id":2,"clk":"AMcoAL82AMU7","pt":1710507993213,"mc":[{"id":"1.226122413","rc":[{"batl":[[1,8.4,47.44]],"id":41122648},{"tv":68188,"batb":[[1,1.87,201.86]],"trd":[[1.89,2482.64]],"batl":[[0,1.89,97.69]],"id":51922},{"batl":[[2,210,1],[1,200,1.81]],"id":66251581}],"tv":95757.62}],"ArrivalTime":1710507993220}
{"op":"mcm","id":2,"clk":"AM4oAMg2ANI7","pt":1710507993321,"mc":[{"id":"1.226122413","rc":[{"batl":[[2,250,1.14],[1,210,3.82],[0,200,1.81]],"id":66251581},{"batl":[[0,25,31.2]],"id":106596}]}],"ArrivalTime":1710507993328}
{"op":"mcm","id":2,"clk":"ANEoAM82AN07","pt":1710507993451,"mc":[{"id":"1.226122413","rc":[{"batb":[[2,140,5.29],[1,150,2.72],[0,160,1.06]],"batl":[],"id":66251581}]}],"ArrivalTime":1710507993458}
{"op":"mcm","id":2,"clk":"ANgoANY2AOw7","pt":1710507993526,"mc":[{"id":"1.226122413","rc":[{"batb":[[2,7.6,74.3]],"id":41122648}]}],"ArrivalTime":1710507993533}
{"op":"mcm","id":2,"clk":"AOIoAOA2API7","pt":1710507993634,"mc":[{"id":"1.226122413","rc":[{"batb":[[2,270,2.12]],"id":54370634},{"tv":68192,"batb":[[1,1.87,207.06],[0,1.88,598.02]],"trd":[[1.88,5055.85]],"ltp":1.88,"batl":[],"id":51922},{"tv":479.59,"batb":[[2,130,1],[1,140,5.01],[0,150,2.72]],"trd":[[160,18.46]],"ltp":160,"id":66251581}],"tv":95763.74}],"ArrivalTime":1710507993641}
{"op":"mcm","id":2,"clk":"AOooAOY2APw7","pt":1710507993682,"mc":[{"id":"1.226122413","rc":[{"batb":[[0,1.88,648.02]],"batl":[[0,1.89,99.69]],"id":51922}]}],"ArrivalTime":1710507993690}
{"op":"mcm","id":2,"clk":"APIoAO82AIc8","pt":1710507993786,"mc":[{"id":"1.226122413","rc":[{"batb":[[0,150,2.82]],"batl":[],"id":66251581}]}],"ArrivalTime":1710507993794}
{"op":"mcm","id":2,"clk":"AIApAIM3AJc8","pt":1710507993994,"mc":[{"id":"1.226122413","rc":[{"batb":[[0,8,54.3]],"batl":[[0,8.2,20.2]],"id":41122648},{"tv":68362.8,"trd":[[1.89,2653.44]],"ltp":1.89,"batl":[[1,1.9,167.58],[0,1.89,14.29]],"id":51922}],"tv":95934.54}],"ArrivalTime":1710507994001}
{"op":"mcm","id":2,"clk":"AIkpAI03AJ88","pt":1710507994094,"mc":[{"id":"1.226122413","rc":[{"tv":68391.37,"batb":[[2,1.87,207.06],[1,1.88,648.02],[0,1.89,55.12]],"trd":[[1.89,2682.01]],"batl":[[2,1.92,309.68],[1,1.91,129.7],[0,1.9,167.58]],"id":51922},{"batl":[[0,200,2.84]],"id":66251581}],"tv":95963.11}],"ArrivalTime":1710507994101}
{"op":"mcm","id":2,"clk":"AI4pAJY3AKg8","pt":1710507994196,"mc":[{"id":"1.226122413","rc":[{"tv":68461.38,"batb":[[2,1.86,182.73],[1,1.87,207.06],[0,1.88,648.02]],"trd":[[1.89,2752.02]],"batl":[],"id":51922},{"batl":[[0,38,7.39]],"id":49744721},{"batl":[[2,4.8,140.29],[0,4.6,92.41]],"id":50466254},{"batb":[[1,23,23.4]],"id":106596}],"tv":96033.12}],"ArrivalTime":1710507994203}
{"op":"mcm","id":2,"clk":"AJYpAKA3AK88","pt":1710507994297,"mc":[{"id":"1.226122413","rc":[{"batb":[[2,7.6,72.26]],"id":41122648},{"tv":398.94,"batb":[[0,180,2.84]],"trd":[[180,23.49]],"id":41200638},{"batb":[[0,24,12.1]],"id":55632148},{"batb":[[2,1.87,207.06],[1,1.88,188.91],[0,1.89,59.62]],"id":51922},{"tv":1785.9,"batb":[[0,24,8.46]],"trd":[[24,148.53]],"id":106596}],"tv":96039.44}],"ArrivalTime":1710507994305}
{"op":"mcm","id":2,"clk":"AJ8pAKU3ALs8","pt":1710507994398,"mc":[{"id":"1.226122413","rc":[{"tv":68631.38,"batb":[[2,1.86,184.73],[1,1.87,207.06],[0,1.88,163.53]],"trd":[[1.88,5106.61],[1.89,2871.26]],"ltp":1.88,"batl":[[0,1.9,241.11]],"id":51922},{"batl":[[2,4.8,137.49]],"id":50466254}],"tv":96209.44}],"ArrivalTime":1710507994405}
{"op":"mcm","id":2,"clk":"AKcpAK43AMc8","pt":1710507994508,"mc":[{"id":"1.226122413","rc":[{"batl":[[2,430,2.24],[1,420,2.09],[0,400,1.23]],"id":54370634},{"batl":[[0,25,13.79]],"id":55632148},{"batb":[[1,1.87,209.06],[0,1.88,135.93]],"batl":[],"id":51922},{"batl":[[2,42,10.38]],"id":49744721},{"batb":[[0,150,5.33]],"id":66251581}]}],"ArrivalTime":1710507994515}
{"op":"mcm","id":2,"clk":"AKspALU3ANI8","pt":1710507994611,"mc":[{"id":"1.226122413","rc":[{"tv":355.16,"batb":[[0,330,1.53]],"trd":[[330,39.06]],"batl":[[2,420,1.77],[1,410,3.14]],"id":54370634},{"batb":[[0,8,61.72]],"batl":[[0,8.2,12.8]],"id":41122648},{"tv":403.96,"batb":[[2,140,5.8],[1,160,3.39],[0,170,18.33]],"trd":[[180,28.51]],"id":41200638},{"tv":68797.24,"batb":[[2,1.85,243.32],[1,1.86,184.73],[0,1.87,211.06]],"trd":[[1.88,5272.47]],"batl":[[2,1.9,241.11],[1,1.89,59.63],[0,1.88,42.07]],"id":51922},{"tv":2289.08,"batb":[[0,36,5.34]],"trd":[[36,90.63]],"id":49744721}],"tv":96384.74}],"ArrivalTime":1710507994618}
{"op":"mcm","id":2,"clk":"ALMpAL03AOA8","pt":1710507994715,"mc":[{"id":"1.226122413","rc":[{"batb":[[1,7.8,93.41]],"id":41122648},{"tv":68817.24,"batb":[[0,1.87,201.06]],"trd":[[1.87,5406.14]],"ltp":1.87,"batl":[[2,1.9,243.11]],"id":51922},{"batl":[[0,4.6,77.81]],"id":50466254},{"tv":481.3,"batb":[[0,150,4.48]],"trd":[[160,18.66],[150,27.61]],"ltp":150,"id":66251581}],"tv":96406.45}],"ArrivalTime":1710507994722}
{"op":"mcm","id":2,"clk":"ALspAMI3AOw8","pt":1710507994814,"mc":[{"id":"1.226122413","rc":[{"batb":[[2,7.6,74.3],[0,8,69.72]],"id":41122648},{"batb":[[2,150,1.87],[0,170,23.97]],"id":41200638},{"batb":[[0,24,15.1]],"id":55632148},{"batb":[[0,1.87,173.57]],"batl":[[1,1.89,87.8],[0,1.88,167.07]],"id":51922},{"batb":[[0,36,7.63]],"id":49744721},{"batb":[[0,4.5,146.83]],"id":50466254}]}],"ArrivalTime":1710507994822}
{"op":"mcm","id":2,"clk":"AMgpAMc3APY8","pt":1710507994920,"mc":[{"id":"1.226122413","rc":[{"batl":[[0,8.2,11.58]],"id":41122648},{"batl":[[0,25,8.08]],"id":55632148},{"tv":68917.24,"batb":[[0,1.87,119.03]],"trd":[[1.88,5372.47]],"ltp":1.88,"batl":[[0,1.88,217.07]],"id":51922},{"batb":[[0,4.5,191.98]],"id":50466254},{"batl":[[2,210,3.82],[1,200,2.3],[0,190,1.02]],"id":66251581}],"tv":96506.45}],"ArrivalTime":1710507994927}
{"op":"mcm","id":2,"clk":"ANMpANc3AIo9","pt":1710507995041,"mc":[{"id":"1.226122413","rc":[{"batb":[[0,8,78.06]],"id":41122648},{"batl":[[0,200,5.6]],"id":41200638},{"tv":69008.57,"batb":[[0,1.87,73.37]],"trd":[[1.87,5497.47]],"ltp":1.87,"batl":[[0,1.88,351.68]],"id":51922}],"tv":96597.78}],"ArrivalTime":1710507995048}
{"op":"mcm","id":2,"clk":"ANcpANs3AI49","pt":1710507995140,"mc":[{"id":"1.226122413","rc":[{"tv":13603.93,"batb":[[0,4.5,21.75]],"trd":[[4.5,2772.78]],"id":50466254}],"tv":96981.75}],"ArrivalTime":1710507995147}
{"op":"mcm","id":2,"clk":"AOIpAOM3AJQ9","pt":1710507995181,"mc":[{"id":"1.226122413","rc":[{"tv":69155.3,"batb":[[2,1.84,292.66],[1,1.85,243.32],[0,1.86,184.73]],"trd":[[1.87,5644.2]],"batl":[[2,1.89,87.8],[1,1.88,480],[0,1.87,55.43]],"id":51922}],"tv":97128.48}],"ArrivalTime":1710507995188}
{"op":"mcm","id":2,"clk":"AOYpAOg3AKA9","pt":1710507995294,"mc":[{"id":"1.226122413","rc":[{"batl":[[2,8.8,26.49],[1,8.6,28.61],[0,8.4,47.44]],"id":41122648},{"batl":[[2,28,27.86],[1,27,13.06],[0,26,13.43]],"id":55632148},{"tv":69255,"batb":[[0,1.86,130.73]],"trd":[[1.87,5743.9]],"batl":[[0,1.87,5.59]],"id":51922},{"batl":[[0,38,3.34]],"id":49744721},{"tv":13677.43,"batb":[[2,4.2,177.91],[1,4.3,249.02],[0,4.4,148.04]],"trd":[[4.5,2846.28]],"batl":[[2,4.7,80.01],[1,4.6,77.81],[0,4.5,29.96]],"id":50466254}],"tv":97301.68}],"ArrivalTime":1710507995302}
{"op":"mcm","id":2,"clk":"AOspAPs3AKw9","pt":1710507995399,"mc":[{"id":"1.226122413","rc":[{"batb":[[2,7.6,72.26]],"batl":[[0,8.4,34.97]],"id":41122648},{"batb":[[2,1.84,163.05]],"batl":[[1,1.88,497]],"id":51922},{"batb":[[2,4.2,181.73],[0,4.4,167.81]],"id":50466254}]}],"ArrivalTime":1710507995406}
{"op":"mcm","id":2,"clk":"APIpAIE4ALg9","pt":1710507995499,"mc":[{"id":"1.226122413","rc":[{"batb":[[0,8,95.41]],"id":41122648},{"tv":69266.17,"batb":[[2,1.85,243.32],[1,1.86,130.73],[0,1.87,59.77]],"trd":[[1.87,5755.07]],"batl":[[2,1.9,243.11],[1,1.89,87.8],[0,1.88,497]],"id":51922},{"batl":[[1,40,10.01]],"id":49744721},{"batb":[[2,4.2,177.91],[0,4.4,189.51]],"batl":[],"id":50466254}],"tv":97312.85}],"ArrivalTime":1710507995506}
{"op":"mcm","id":2,"clk":"APwpAI84AMQ9","pt":1710507995609,"mc":[{"id":"1.226122413","rc":[{"batl":[[0,8.4,38.2]],"id":41122648},{"batl":[[2,1.9,246.11]],"id":51922},{"batb":[[0,4.4,169.74]],"id":50466254},{"tv":1797.36,"batb":[[0,24,2.73]],"trd":[[24,159.99]],"id":106596}],"tv":97324.31}],"ArrivalTime":1710507995616}
{"op":"mcm","id":2,"clk":"AIMqAJk4AM49","pt":1710507995706,"mc":[{"id":"1.226122413","rc":[{"batl":[[2,430,2.24],[1,420,1.77],[0,410,3.92]],"id":54370634},{"batb":[[0,1.87,63.06]],"id":51922},{"batb":[],"batl":[[2,4.8,137.49],[1,4.7,80.01],[0,4.6,77.81]],"id":50466254}]}],"ArrivalTime":1710507995713}
{"op":"mcm","id":2,"clk":"AIsqAKE4ANk9","pt":1710507995810,"mc":[{"id":"1.226122413","rc":[{"batb":[[2,7.6,82.26]],"id":41122648}]}],"ArrivalTime":1710507995817}
{"op":"mcm","id":2,"clk":"AJIqAKo4ANw9","pt":1710507995914,"mc":[{"id":"1.226122413","rc":[{"batb":[[0,1.87,68.26]],"id":51922}]}],"ArrivalTime":1710507995922}
{"op":"mcm","id":2,"clk":"AJ0qALg4AO09","pt":1710507996021,"mc":[{"id":"1.226122413","rc":[{"tv":7318.78,"trd":[[8.4,802.35]],"ltp":8.4,"batl":[[0,8.4,33.05]],"id":41122648},{"tv":69276.91,"batb":[[0,1.87,62.89]],"trd":[[1.87,5765.81]],"id":51922}],"tv":97345.35}],"ArrivalTime":1710507996029}
{"op":"mcm","id":2,"clk":"AKMqAMA4APA9","pt":1710507996120,"mc":[{"id":"1.226122413","rc":[{"tv":69286.91,"batb":[[0,1.87,57.89]],"trd":[[1.87,5775.81]],"id":51922},{"tv":2293.08,"batb":[[0,36,5.63]],"trd":[[36,94.63]],"id":49744721}],"tv":97359.35}],"ArrivalTime":1710507996128}
{"op":"mcm","id":2,"clk":"AK4qAMU4APo9","pt":1710507996235,"mc":[{"id":"1.226122413","rc":[{"batb":[[2,7.8,93.41],[1,8,95.41],[0,8.2,12.26]],"batl":[[1,8.6,29.12],[0,8.4,30.41]],"id":41122648},{"tv":1753.37,"trd":[[26,292.72]],"batl":[[0,26,9.43]],"id":55632148},{"batb":[[0,1.87,8.49]],"id":51922}],"tv":97367.35}],"ArrivalTime":1710507996242}
{"op":"mcm","id":2,"clk":"ALQqAM84AIA+","pt":1710507996326,"mc":[{"id":"1.226122413","rc":[{"batl":[[0,410,3.4]],"id":54370634},{"batl":[[1,8.6,45.48]],"id":41122648},{"batb":[[2,23,13.81],[1,24,15.1],[0,25,4.21]],"batl":[[1,27,18.22]],"id":55632148},{"tv":69308.67,"batb":[[2,1.84,163.05],[1,1.85,243.32],[0,1.86,130.73]],"trd":[[1.87,5797.57]],"batl":[[2,1.89,87.8],[1,1.88,497],[0,1.87,8.94]],"id":51922}],"tv":97389.11}],"ArrivalTime":1710507996334}
{"op":"mcm","id":2,"clk":"ALwqANU4AIw+","pt":1710507996383,"mc":[{"id":"1.226122413","rc":[{"batb":[[0,25,4.64]],"batl":[[0,26,13.47]],"id":55632148},{"tv":13683.43,"trd":[[4.6,1130.47],[4.5,2850.28]],"ltp":4.6,"batl":[[0,4.6,76.81]],"id":50466254}],"tv":97395.11}],"ArrivalTime":1710507996391}
{"op":"mcm","id":2,"clk":"AMMqAOE4AJ4+","pt":1710507996546,"mc":[{"id":"1.226122413","rc":[{"batl":[[2,28,28.55],[1,27,16.2]],"id":55632148},{"batl":[[2,1.9,246.11],[1,1.89,87.8],[0,1.88,497]],"id":51922},{"tv":1811.36,"batb":[[2,21,58.88],[1,22,22.64],[0,23,19.13]],"trd":[[24,165.45],[23,60.58]],"ltp":23,"id":106596}],"tv":97409.11}],"ArrivalTime":1710507996553}
{"op":"mcm","id":2,"clk":"AMoqAOU4AKQ+","pt":1710507996582,"mc":[{"id":"1.226122413","rc":[{"batl":[[2,420,1.77],[1,410,3.14],[0,400,1.26]],"id":54370634},{"tv":69341.55,"batb":[[0,1.86,112.29]],"trd":[[1.86,7638.73]],"ltp":1.86,"id":51922},{"tv":2308.52,"batb":[[2,30,19.3],[1,32,27.99],[0,34,30.09]],"trd":[[36,105.89],[34,131.03]],"ltp":34,"id":49744721},{"tv":13689.17,"trd":[[4.6,1136.21]],"batl":[[0,4.6,73.94]],"id":50466254},{"batl":[[2,26,24.39],[1,25,31.2],[0,24,5]],"id":106596}],"tv":97463.17}],"ArrivalTime":1710507996593}
{"op":"mcm","id":2,"clk":"ANEqAO04AKs+","pt":1710507996683,"mc":[{"id":"1.226122413","rc":[{"tv":7327.26,"batb":[[0,8.2,8.02]],"trd":[[8.2,466.08]],"ltp":8.2,"id":41122648},{"batl":[[1,27,16.94]],"id":55632148},{"batb":[[2,1.85,243.32],[1,1.86,112.29],[0,1.87,87.4]],"batl":[],"id":51922},{"batl":[[1,200,2.56],[0,180,2.76]],"id":66251581},{"batb":[[1,22,23.77],[0,23,20.17]],"batl":[[0,24,12.5]],"id":106596}],"tv":97471.65}],"ArrivalTime":1710507996691}
{"op":"mcm","id":2,"clk":"ANcqAPU4ALQ+","pt":1710507996792,"mc":[{"id":"1.226122413","rc":[{"batb":[[1,160,3.2]],"id":41200638},{"batl":[[1,1.89,137.8],[0,1.88,531.01]],"id":51922},{"batl":[[0,4.6,173.94]],"id":50466254},{"batb":[[0,23,19.17]],"id":106596}]}],"ArrivalTime":1710507996800}
{"op":"mcm","id":2,"clk":"AOEqAIE5AL8+","pt":1710507996900,"mc":[{"id":"1.226122413","rc":[{"batb":[[0,1.87,147.65]],"batl":[[1,1.89,306.07]],"id":51922}]}],"ArrivalTime":1710507996907}
{"op":"mcm","id":2,"clk":"AOUqAIc5AMw+","pt":1710507996999,"mc":[{"id":"1.226122413","rc":[{"batl":[[0,1.88,502.69]],"id":51922}]}],"ArrivalTime":1710507997006}
{"op":"mcm","id":2,"clk":"APIqAI45ANM+","pt":1710507997102,"mc":[{"id":"1.226122413","rc":[{"tv":69345.55,"batb":[[0,1.87,149.65]],"trd":[[1.88,5376.47]],"ltp":1.88,"batl":[[0,1.88,500.69]],"id":51922}],"tv":97475.65}],"ArrivalTime":1710507997110}
{"op":"mcm","id":2,"clk":"AP8qAJs5AOo+","pt":1710507997331,"mc":[{"id":"1.226122413","rc":[{"batl":[[0,38,8.97]],"id":49744721},{"batb":[[1,22,20.64]],"id":106596}]}],"ArrivalTime":1710507997338}
{"op":"mcm","id":2,"clk":"AIkrAKM5APM+","pt":1710507997405,"mc":[{"id":"1.226122413","rc":[{"batb":[[2,1.85,266.22]],"batl":[[1,1.89,137.8]],"id":51922},{"tv":490.26,"batb":[[2,120,3.76],[1,130,1],[0,140,5.01]],"trd":[[150,36.57]],"batl":[[2,200,2.56],[1,180,2.76],[0,150,1.25]],"id":66251581}],"tv":97484.61}],"ArrivalTime":1710507997412}
{"op":"mcm","id":2,"clk":"AJIrAK85APk+","pt":1710507997497,"mc":[{"id":"1.226122413","rc":[{"batb":[[0,170,25.01]],"id":41200638},{"batb":[[1,1.86,173.29]],"id":51922},{"tv":492.75,"batb":[[2,130,1.33],[1,140,5.29],[0,150,2.17]],"trd":[[150,39.06]],"batl":[[0,160,1.01]],"id":66251581}],"tv":97487.1}],"ArrivalTime":1710507997505}
{"op":"mcm","id":2,"clk":"AJwrALM5AIY/","pt":1710507997605,"mc":[{"id":"1.226122413","rc":[{"tv":69355.55,"batb":[[0,1.87,172.35]],"trd":[[1.87,5807.57]],"ltp":1.87,"batl":[],"id":51922},{"batl":[[0,38,11.12]],"id":49744721},{"tv":13691.17,"trd":[[4.6,1138.21]],"batl":[[0,4.6,172.94]],"id":50466254},{"batb":[[2,120,4.15],[1,130,1.33],[0,140,7.82]],"batl":[[1,180,2.28]],"id":66251581},{"batb":[[0,23,18.13]],"id":106596}],"tv":97499.1}],"ArrivalTime":1710507997612}
{"op":"mcm","id":2,"clk":"AKYrALw5AJE/","pt":1710507997703,"mc":[{"id":"1.226122413","rc":[{"batb":[[2,130,1.33],[1,140,7.3],[0,150,2.08]],"batl":[],"id":66251581}]}],"ArrivalTime":1710507997710}
{"op":"mcm","id":2,"clk":"AKsrAMQ5AJ8/","pt":1710507997809,"mc":[{"id":"1.226122413","rc":[{"batl":[[1,40,15.35]],"id":49744721},{"batb":[[2,130,1]],"batl":[[2,210,1],[1,200,2.56],[0,180,2.28]],"id":66251581}]}],"ArrivalTime":1710507997816}
{"op":"mcm","id":2,"clk":"ALErAMw5AKQ/","pt":1710507997908,"mc":[{"id":"1.226122413","rc":[{"batl":[[1,27,13.8]],"id":55632148},{"batb":[[2,130,1.33],[0,150,4.26]],"id":66251581},{"batb":[[0,23,19.17]],"id":106596}]}],"ArrivalTime":1710507997916}
{"op":"mcm","id":2,"clk":"ALgrANI5AKo/","pt":1710507998010,"mc":[{"id":"1.226122413","rc":[{"batl":[[0,1.88,503.69]],"id":51922},{"batb":[[2,130,1],[1,140,5.01]],"id":66251581}]}],"ArrivalTime":1710507998017}
{"op":"mcm","id":2,"clk":"AL4rAN05ALg/","pt":1710507998117,"mc":[{"id":"1.226122413","rc":[{"batl":[[0,1.88,508.69]],"id":51922}]}],"ArrivalTime":1710507998124}
{"op":"mcm","id":2,"clk":"AMQrAOQ5AMI/","pt":1710507998219,"mc":[{"id":"1.226122413","rc":[{"batb":[[1,1.86,163.79]],"id":51922}]}],"ArrivalTime":1710507998226}
{"op":"mcm","id":2,"clk":"AMgrAOk5AM0/","pt":1710507998317,"mc":[{"id":"1.226122413","rc":[{"tv":69374.55,"trd":[[1.88,5395.47]],"ltp":1.88,"batl":[[0,1.88,499.19]],"id":51922}],"tv":97518.1}],"ArrivalTime":1710507998325}
{"op":"mcm","id":2,"clk":"AM4rAPM5ANU/","pt":1710507998427,"mc":[{"id":"1.226122413","rc":[{"batl":[[1,8.6,29.12]],"id":41122648},{"batl":[[0,38,5.49]],"id":49744721}]}],"ArrivalTime":1710507998435}
{"op":"mcm","id":2,"clk":"AOErAJI6APk/","pt":1710507998834,"mc":[{"id":"1.226122413","rc":[{"batl":[[1,1.89,138.8]],"id":51922}]}],"ArrivalTime":1710507998841}
{"op":"mcm","id":2,"clk":"AOUrAJ46AP0/","pt":1710507998888,"mc":[{"id":"1.226122413","rc":[{"batb":[[1,1.86,165.79]],"id":51922}]}],"ArrivalTime":1710507998896}
{"op":"mcm","id":2,"clk":"AOkrAKY6AIVA","pt":1710507998991,"mc":[{"id":"1.226122413","rc":[{"tv":1755.37,"batb":[[2,22,19.67],[1,23,13.81],[0,24,14.53]],"trd":[[25,329.36],[24,213.79]],"ltp":24,"id":55632148},{"tv":69458.51,"batb":[[0,1.87,135.35]],"trd":[[1.87,5881.57],[1.88,5405.43]],"ltp":1.87,"batl":[[0,1.88,494.21]],"id":51922},{"tv":1813.36,"batb":[[0,23,18.17]],"trd":[[23,62.58]],"id":106596}],"tv":97606.06}],"ArrivalTime":1710507998999}
{"op":"mcm","id":2,"clk":"AO0rAKs6AI5A","pt":1710507999091,"mc":[{"id":"1.226122413","rc":[{"batl":[[2,28,27.86],[1,27,13.06]],"id":55632148}]}],"ArrivalTime":1710507999099}
{"op":"mcm","id":2,"clk":"APIrALQ6AJdA","pt":1710507999195,"mc":[{"id":"1.226122413","rc":[{"tv":69490.51,"batb":[[0,1.87,119.34]],"trd":[[1.87,5913.57]],"id":51922},{"batb":[[0,23,23.52]],"id":106596}],"tv":97638.06}],"ArrivalTime":1710507999202}
{"op":"mcm","id":2,"clk":"APYrALw6AKJA","pt":1710507999296,"mc":[{"id":"1.226122413","rc":[{"tv":1817.36,"trd":[[24,169.45]],"ltp":24,"batl":[[0,24,10.5]],"id":106596}],"tv":97642.06}],"ArrivalTime":1710507999304}
{"op":"mcm","id":2,"clk":"APsrAMM6AKxA","pt":1710507999403,"mc":[{"id":"1.226122413","rc":[{"tv":69554.52,"batb":[[2,1.84,163.05],[1,1.85,266.22],[0,1.86,165.18]],"trd":[[1.87,5976.36],[1.86,7639.95]],"ltp":1.86,"id":51922}],"tv":97706.07}],"ArrivalTime":1710507999410}
{"op":"mcm","id":2,"clk":"AIEsAMw6AL5A","pt":1710507999520,"mc":[{"id":"1.226122413","rc":[{"tv":1818.72,"trd":[[24,170.81]],"batl":[[0,24,9.82]],"id":106596}],"tv":97707.43}],"ArrivalTime":1710507999527}
{"op":"mcm","id":2,"clk":"AIksANI6AMdA","pt":1710507999619,"mc":[{"id":"1.226122413","rc":[{"tv":69650.52,"batb":[[0,1.86,117.17]],"trd":[[1.86,7735.95]],"batl":[[2,1.89,138.8],[1,1.88,522.38],[0,1.87,1.31]],"id":51922},{"batl":[[2,42,7.94],[1,40,17.91],[0,38,3.34]],"id":49744721},{"batl":[[1,4.7,78.01]],"id":50466254},{"batb":[[0,150,2.08]],"id":66251581},{"tv":1823.22,"batb":[[0,23,24.52]],"trd":[[24,175.31]],"batl":[[0,24,7.57]],"id":106596}],"tv":97807.93}],"ArrivalTime":1710507999627}
{"op":"mcm","id":2,"clk":"AI0sANs6AM5A","pt":1710507999715,"mc":[{"id":"1.226122413","rc":[{"batb":[[0,8.2,16.23]],"id":41122648},{"tv":69653.14,"batb":[[2,1.85,266.22],[1,1.86,117.17],[0,1.87,27.87]],"trd":[[1.87,5978.98]],"ltp":1.87,"batl":[[2,1.9,246.11],[1,1.89,138.8],[0,1.88,522.38]],"id":51922}],"tv":97810.55}],"ArrivalTime":1710507999723}
{"op":"mcm","id":2,"clk":"AJMsAN86ANdA","pt":1710507999821,"mc":[{"id":"1.226122413","rc":[{"tv":69749.14,"batb":[[2,1.84,163.05],[1,1.85,266.22],[0,1.86,98.19]],"trd":[[1.87,6034.72],[1.86,7776.21]],"ltp":1.86,"batl":[[2,1.89,138.8],[1,1.88,542.38],[0,1.87,89.68]],"id":51922},{"batb":[[1,140,7.3]],"id":66251581},{"tv":1824.54,"trd":[[24,176.63]],"batl":[[0,24,6.91]],"id":106596}],"tv":97907.87}],"ArrivalTime":1710507999828}
{"op":"mcm","id":2,"clk":"AJksAOk6AORA","pt":1710507999922,"mc":[{"id":"1.226122413","rc":[{"batl":[[0,1.87,167.12]],"id":51922}]}],"ArrivalTime":1710507999929}
{"op":"mcm","id":2,"clk":"AJ8sAO86AOlA","pt":1710508000025,"mc":[{"id":"1.226122413","rc":[{"tv":69845.14,"batb":[[0,1.86,50.19]],"trd":[[1.86,7872.21]],"batl":[[0,1.87,205.12]],"id":51922}],"tv":98003.87}],"ArrivalTime":1710508000033}
{"op":"mcm","id":2,"clk":"AKMsAPo6APJA","pt":1710508000133,"mc":[{"id":"1.226122413","rc":[{"tv":357.16,"trd":[[400,25.6]],"ltp":400,"batl":[[2,430,2.24],[1,420,1.77],[0,410,3.4]],"id":54370634},{"tv":69862.94,"trd":[[1.87,6052.52]],"ltp":1.87,"batl":[[0,1.87,196.22]],"id":51922}],"tv":98023.67}],"ArrivalTime":1710508000141}
{"op":"mcm","id":2,"clk":"AKksAP06APxA","pt":1710508000187,"mc":[{"id":"1.226122413","rc":[{"tv":69963.33,"batb":[[2,1.83,156.31],[1,1.84,163.05],[0,1.85,266.22]],"trd":[[1.86,7972.6]],"ltp":1.86,"batl":[[2,1.88,542.38],[1,1.87,196.22],[0,1.86,33.74]],"id":51922},{"batb":[[0,4.4,148.04]],"id":50466254}],"tv":98124.06}],"ArrivalTime":1710508000195}
{"op":"mcm","id":2,"clk":"AK8sAIc7AItB","pt":1710508000352,"mc":[{"id":"1.226122413","rc":[{"batb":[[0,8.2,24.23]],"id":41122648},{"tv":69968.51,"batb":[[2,1.83,192.31]],"trd":[[1.86,7977.78]],"batl":[[2,1.89,138.8],[1,1.88,542.38],[0,1.87,221.22]],"id":51922}],"tv":98129.24}],"ArrivalTime":1710508000359}
{"op":"mcm","id":2,"clk":"ALUsAI07AJFB","pt":1710508000390,"mc":[{"id":"1.226122413","rc":[{"batb":[],"batl":[[2,1.88,547.38],[1,1.87,221.22],[0,1.86,3]],"id":51922},{"batl":[[2,4.7,78.01],[1,4.6,172.94],[0,4.5,1]],"id":50466254}]}],"ArrivalTime":1710508000397}
{"op":"mcm","id":2,"clk":"AL0sAJM7AJtB","pt":1710508000497,"mc":[{"id":"1.226122413","rc":[{"batb":[[0,8.2,32.9]],"batl":[[0,8.4,23.83]],"id":41122648},{"batb":[[2,23,13.81],[1,24,14.53],[0,25,3.55]],"id":55632148},{"tv":69974.51,"batb":[],"trd":[[1.86,7983.78]],"batl":[[2,1.89,138.8],[1,1.88,547.38],[0,1.87,248.22]],"id":51922},{"batb":[[2,30,17.71]],"id":49744721},{"batb":[[0,4.4,162.77]],"batl":[],"id":50466254}],"tv":98135.24}],"ArrivalTime":1710508000504}
{"op":"mcm","id":2,"clk":"AMQsAJs7AKZB","pt":1710508000599,"mc":[{"id":"1.226122413","rc":[{"batl":[[0,8.4,12.99]],"id":41122648},{"batb":[[0,25,7.64]],"batl":[[2,28,28.55]],"id":55632148},{"batb":[[1,32,21.8]],"id":49744721},{"tv":1829.54,"trd":[[24,181.63]],"batl":[[0,24,4.41]],"id":106596}],"tv":98140.24}],"ArrivalTime":1710508000607}
{"op":"mcm","id":2,"clk":"AMgsAKM7AKtB","pt":1710508000700,"mc":[{"id":"1.226122413","rc":[{"batb":[[2,7.8,78.7]],"id":41122648},{"batl":[[0,38,7.32]],"id":49744721}]}],"ArrivalTime":1710508000707}
{"op":"mcm","id":2,"clk":"AM4sAKs7ALdB","pt":1710508000810,"mc":[{"id":"1.226122413","rc":[{"batb":[[0,330,2.4]],"batl":[[1,420,1.15]],"id":54370634},{"tv":1830.34,"trd":[[24,182.43]],"batl":[[0,24,4.01]],"id":106596}],"tv":98141.04}],"ArrivalTime":1710508000818}
{"op":"mcm","id":2,"clk":"ANIsALM7AMFB","pt":1710508000910,"mc":[{"id":"1.226122413","rc":[{"batb":[[1,8,111.25]],"id":41122648},{"batl":[[0,26,10.77]],"id":55632148}]}],"ArrivalTime":1710508000917}
{"op":"mcm","id":2,"clk":"ANcsAL07AMtB","pt":1710508001020,"mc":[{"id":"1.226122413","rc":[{"batl":[[1,1.88,549.38]],"id":51922}]}],"ArrivalTime":1710508001027}
{"op":"mcm","id":2,"clk":"ANosAMU7ANJB","pt":1710508001151,"mc":[{"id":"1.226122413","rc":[{"batl":[[0,1.87,348.22]],"id":51922}]}],"ArrivalTime":1710508001158}
{"op":"mcm","id":2,"clk":"AOEsAM47AN1B","pt":1710508001202,"mc":[{"id":"1.226122413","rc":[{"batb":[[1,140,5.01]],"id":66251581}]}],"ArrivalTime":1710508001210}
{"op":"mcm","id":2,"clk":"AOQsANY7AOxB","pt":1710508001309,"mc":[{"id":"1.226122413","rc":[{"tv":69983.05,"trd":[[1.87,6061.06]],"ltp":1.87,"batl":[[0,1.87,343.95]],"id":51922}],"tv":98149.58}],"ArrivalTime":1710508001317}
{"op":"mcm","id":2,"clk":"AO8sAO07AIBC","pt":1710508001518,"mc":[{"id":"1.226122413","rc":[{"tv":7347.26,"trd":[[8.4,822.35]],"ltp":8.4,"batl":[[0,8.4,2.99]],"id":41122648},{"tv":1763.01,"trd":[[26,300.36]],"ltp":26,"batl":[[0,26,6.95]],"id":55632148},{"tv":70003.05,"trd":[[1.87,6081.06]],"batl":[[0,1.87,338.95]],"id":51922},{"tv":2311.52,"trd":[[38,23.12]],"ltp":38,"batl":[[0,38,5.82]],"id":49744721},{"tv":1836.56,"trd":[[24,188.65]],"batl":[[2,27,6.4],[1,26,24.39],[0,25,32.1]],"id":106596}],"tv":98206.44}],"ArrivalTime":1710508001526}
{"op":"mcm","id":2,"clk":"APosAPQ7AIpC","pt":1710508001624,"mc":[{"id":"1.226122413","rc":[{"batl":[[0,25,31.2]],"id":106596}]}],"ArrivalTime":1710508001632}
{"op":"mcm","id":2,"clk":"AIMtAPs7AJVC","pt":1710508001724,"mc":[{"id":"1.226122413","rc":[{"batb":[[0,8.2,47.34]],"id":41122648},{"batl":[[0,26,4.04]],"id":55632148},{"batl":[[1,1.88,564.38]],"id":51922},{"batl":[[0,38,9.25]],"id":49744721},{"batl":[[0,4.5,2]],"id":50466254},{"batb":[[2,21,57.62],[1,22,19.51],[0,23,23.48]],"id":106596}]}],"ArrivalTime":1710508001732}
{"op":"mcm","id":2,"clk":"AI4tAJA8AKZC","pt":1710508001935,"mc":[{"id":"1.226122413","rc":[{"batb":[[0,25,10.38]],"id":55632148},{"tv":71710.91,"trd":[[1.87,6758.98],[1.88,6435.37]],"ltp":1.88,"batl":[[2,1.9,172.58],[1,1.89,138.8],[0,1.88,49.44]],"id":51922}],"tv":99914.3}],"ArrivalTime":1710508001942}
{"op":"mcm","id":2,"clk":"AJEtAJw8ALFC","pt":1710508002002,"mc":[{"id":"1.226122413","rc":[{"batb":[[2,1.84,163.05],[1,1.85,266.22],[0,1.86,64.08]],"id":51922}]}],"ArrivalTime":1710508002010}
{"op":"mcm","id":2,"clk":"AJgtAKU8ALtC","pt":1710508002095,"mc":[{"id":"1.226122413","rc":[{"batb":[[0,8.2,37.91]],"batl":[[1,8.6,25.41]],"id":41122648},{"batb":[[0,25,7.64]],"batl":[[1,27,13.8]],"id":55632148},{"tv":71961.83,"batb":[[0,1.86,175.5]],"trd":[[1.87,6814.52],[1.86,8128.24],[1.88,6486.29]],"batl":[[0,1.88,81.25]],"id":51922},{"batl":[[0,38,11.62]],"id":49744721},{"batb":[],"batl":[[0,4.5,44.85]],"id":50466254}],"tv":100165.22}],"ArrivalTime":1710508002102}
{"op":"mcm","id":2,"clk":"AKAtAKo8AMZC","pt":1710508002194,"mc":[{"id":"1.226122413","rc":[{"batb":[[2,1.85,266.22],[1,1.86,175.5],[0,1.87,107.05]],"id":51922}]}],"ArrivalTime":1710508002202}
{"op":"mcm","id":2,"clk":"AKQtALA8ANJC","pt":1710508002309,"mc":[{"id":"1.226122413","rc":[{"tv":71999.43,"batb":[[1,1.86,270.44]],"trd":[[1.88,6523.89]],"batl":[[1,1.89,110.63],[0,1.88,62.45]],"id":51922},{"batb":[[0,4.4,145.57]],"batl":[[0,4.5,85.01]],"id":50466254}],"tv":100202.82}],"ArrivalTime":1710508002316}
{"op":"mcm","id":2,"clk":"AK0tALo8AN1C","pt":1710508002413,"mc":[{"id":"1.226122413","rc":[{"batb":[[1,24,16.03]],"id":55632148},{"batb":[[0,1.87,134.82]],"id":51922},{"batb":[[2,21,49.27]],"id":106596}]}],"ArrivalTime":1710508002420}
{"op":"mcm","id":2,"clk":"ALItAL88AOlC","pt":1710508002509,"mc":[{"id":"1.226122413","rc":[{"tv":72124.33,"batb":[[0,1.87,138.99]],"trd":[[1.88,6648.79]],"batl":[[2,1.91,132.28],[1,1.9,172.58],[0,1.89,110.63]],"id":51922},{"batb":[[0,4.4,130.84]],"id":50466254}],"tv":100327.72}],"ArrivalTime":1710508002517}
{"op":"mcm","id":2,"clk":"ALstAMk8APZC","pt":1710508002625,"mc":[{"id":"1.226122413","rc":[{"batl":[[0,8.4,11.22]],"id":41122648},{"batl":[[2,1.9,172.58],[1,1.89,110.63],[0,1.88,2]],"id":51922}]}],"ArrivalTime":1710508002632}
{"op":"mcm","id":2,"clk":"AMEtAMw8APxC","pt":1710508002711,"mc":[{"id":"1.226122413","rc":[{"tv":72143.33,"batb":[[2,1.85,541.33]],"trd":[[1.88,6652.79],[1.89,2886.26]],"ltp":1.89,"batl":[[2,1.91,132.28],[1,1.9,172.58],[0,1.89,103.13]],"id":51922}],"tv":100346.72}],"ArrivalTime":1710508002719}
{"op":"mcm","id":2,"clk":"AMgtANg8AIND","pt":1710508002821,"mc":[{"id":"1.226122413","rc":[{"tv":72147.33,"batb":[[2,1.86,313.14],[1,1.87,138.99],[0,1.88,27.66]],"trd":[[1.88,6656.79]],"ltp":1.88,"id":51922}],"tv":100350.72}],"ArrivalTime":1710508002829}
{"op":"mcm","id":2,"clk":"ANItAN48AI1D","pt":1710508002920,"mc":[{"id":"1.226122413","rc":[{"tv":72157.33,"batb":[[0,1.88,22.66]],"trd":[[1.88,6666.79]],"id":51922},{"tv":13700.57,"trd":[[4.5,2859.68]],"ltp":4.5,"batl":[[0,4.5,80.31]],"id":50466254}],"tv":100370.12}],"ArrivalTime":1710508002928}
{"op":"mcm","id":2,"clk":"ANYtAOQ8AJhD","pt":1710508003027,"mc":[{"id":"1.226122413","rc":[{"batb":[[0,8.2,23.47]],"id":41122648}]}],"ArrivalTime":1710508003034}
{"op":"mcm","id":2,"clk":"AOMtAPo8ALlD","pt":1710508003288,"mc":[{"id":"1.226122413","rc":[{"batb":[[2,1.86,318.16]],"id":51922}]}],"ArrivalTime":1710508003295}
{"op":"mcm","id":2,"clk":"AOgtAII9AMRD","pt":1710508003388,"mc":[{"id":"1.226122413","rc":[{"batl":[[0,8.4,23.85]],"id":41122648},{"batb":[[1,1.87,139.84],[0,1.88,49.87]],"batl":[],"id":51922}]}],"ArrivalTime":1710508003396}
{"op":"mcm","id":2,"clk":"AOwtAI09ANBD","pt":1710508003492,"mc":[{"id":"1.226122413","rc":[{"batl":[[0,8.4,30.88]],"id":41122648}]}],"ArrivalTime":1710508003500}
{"op":"mcm","id":2,"clk":"APItAKA9ANtD","pt":1710508003594,"mc":[{"id":"1.226122413","rc":[{"tv":7361.02,"batb":[[0,8.2,9.14]],"trd":[[8.2,479.84]],"ltp":8.2,"id":41122648},{"batl":[[0,1.89,108.28]],"id":51922}],"tv":100383.88}],"ArrivalTime":1710508003602}
{"op":"mcm","id":2,"clk":"AIUuAK89AOpD","pt":1710508003699,"mc":[{"id":"1.226122413","rc":[{"batb":[[1,8,95.41],[0,8.2,16.5]],"id":41122648},{"batl":[[2,4.7,77.01]],"id":50466254}]}],"ArrivalTime":1710508003706}
{"op":"mcm","id":2,"clk":"AJEuALg9AO9D","pt":1710508003799,"mc":[{"id":"1.226122413","rc":[{"tv":7372.47,"batb":[[0,8.2,26.5]],"trd":[[8.4,833.8]],"ltp":8.4,"batl":[[0,8.4,25.15]],"id":41122648},{"batb":[[1,1.87,182.53]],"id":51922}],"tv":100395.33}],"ArrivalTime":1710508003806}
{"op":"mcm","id":2,"clk":"AJouAMc9AP5D","pt":1710508003912,"mc":[{"id":"1.226122413","rc":[{"tv":407.47,"batb":[[2,160,3.2],[1,170,25.01],[0,220,8.96]],"trd":[[220,27.18],[190,38.77]],"ltp":220,"batl":[[2,250,1.98],[1,240,6.79],[0,230,6]],"id":41200638}],"tv":100398.84}],"ArrivalTime":1710508003919}
{"op":"mcm","id":2,"clk":"AKAuANI9AIhE","pt":1710508004016,"mc":[{"id":"1.226122413","rc":[{"tv":412.03,"batb":[[0,220,6.68]],"trd":[[220,31.74]],"id":41200638},{"tv":72167.33,"batb":[[0,1.88,44.87]],"trd":[[1.88,6676.79]],"id":51922}],"tv":100413.4}],"ArrivalTime":1710508004023}
{"op":"mcm","id":2,"clk":"AKQuAN49AI5E","pt":1710508004124,"mc":[{"id":"1.226122413","rc":[{"batl":[[0,8.4,27.15]],"id":41122648},{"tv":418.05,"batb":[[2,170,19.37],[1,190,1.11],[0,220,3.77]],"trd":[[230,0.58],[220,37.56]],"batl":[[0,230,5.9]],"id":41200638}],"tv":100419.42}],"ArrivalTime":1710508004132}
{"op":"mcm","id":2,"clk":"AKguAOQ9AJxE","pt":1710508004221,"mc":[{"id":"1.226122413","rc":[{"batb":[[2,190,1.11],[1,210,1.54],[0,220,3.87]],"id":41200638}]}],"ArrivalTime":1710508004229}
{"op":"mcm","id":2,"clk":"AK4uAO49AKJE","pt":1710508004329,"mc":[{"id":"1.226122413","rc":[{"tv":422.31,"batb":[[2,200,1.97],[1,210,3.09],[0,220,1.74]],"trd":[[220,41.82]],"id":41200638},{"batb":[[1,1.87,243.53]],"batl":[],"id":51922}],"tv":100423.68}],"ArrivalTime":1710508004337}
{"op":"mcm","id":2,"clk":"ALUuAPQ9AK9E","pt":1710508004428,"mc":[{"id":"1.226122413","rc":[{"tv":72299.93,"batb":[[2,1.85,542.33],[1,1.86,318.16],[0,1.87,222.1]],"trd":[[1.87,6857.38],[1.88,6766.53]],"ltp":1.87,"batl":[[2,1.9,172.58],[1,1.89,108.28],[0,1.88,2]],"id":51922}],"tv":100556.28}],"ArrivalTime":1710508004436}
{"op":"mcm","id":2,"clk":"ALouAII+ALdE","pt":1710508004550,"mc":[{"id":"1.226122413","rc":[{"tv":422.63,"batb":[[1,210,1.55],[0,220,1.58]],"trd":[[220,42.14]],"id":41200638},{"tv":13704.57,"batb":[[0,4.4,128.84]],"trd":[[4.4,3195.83]],"ltp":4.4,"id":50466254}],"tv":100560.6}],"ArrivalTime":1710508004558}
{"op":"mcm","id":2,"clk":"AL4uAIk+AMVE","pt":1710508004632,"mc":[{"id":"1.226122413","rc":[{"batl":[[1,27,13.06]],"id":55632148},{"tv":72393.48,"trd":[[1.88,6860.08]],"ltp":1.88,"batl":[[1,1.89,134.95],[0,1.88,60.35]],"id":51922},{"batl":[[2,42,10.38],[1,40,15.35]],"id":49744721}],"tv":100654.15}],"ArrivalTime":1710508004640}
{"op":"mcm","id":2,"clk":"AMMuAJQ+ANNE","pt":1710508004734,"mc":[{"id":"1.226122413","rc":[{"batb":[[2,200,2.32]],"batl":[[1,240,5.25]],"id":41200638},{"batl":[[0,1.88,65.35]],"id":51922}]}],"ArrivalTime":1710508004742}
{"op":"mcm","id":2,"clk":"AMkuAJ4+ANpE","pt":1710508004795,"mc":[{"id":"1.226122413","rc":[{"batl":[[0,8.4,39.84]],"id":41122648},{"batl":[[0,26,8.14]],"id":55632148},{"batb":[[0,1.87,161.1]],"batl":[[0,1.88,122.06]],"id":51922},{"batl":[[0,38,14.43]],"id":49744721},{"batl":[[0,4.5,104]],"id":50466254}]}],"ArrivalTime":1710508004803}
{"op":"mcm","id":2,"clk":"ANwuAL0+APxE","pt":1710508005101,"mc":[{"id":"1.226122413","rc":[{"batl":[[1,1.89,140.95]],"id":51922}]}],"ArrivalTime":1710508005108}
{"op":"mcm","id":2,"clk":"AOEuAMI+AIdF","pt":1710508005205,"mc":[{"id":"1.226122413","rc":[{"batl":[[0,8.4,37.84]],"id":41122648},{"batl":[[2,1.9,178.58],[0,1.88,142.06]],"id":51922}]}],"ArrivalTime":1710508005212}
{"op":"mcm","id":2,"clk":"AOYuAMs+AIxF","pt":1710508005308,"mc":[{"id":"1.226122413","rc":[{"batl":[[1,1.89,146.95],[0,1.88,152.06]],"id":51922}]}],"ArrivalTime":1710508005315}
{"op":"mcm","id":2,"clk":"AOguANM+AJVF","pt":1710508005408,"mc":[{"id":"1.226122413","rc":[{"tv":72397.53,"batb":[[0,1.87,159.08]],"trd":[[1.87,6861.43]],"ltp":1.87,"batl":[[0,1.88,155.06]],"id":51922}],"tv":100658.2}],"ArrivalTime":1710508005416}
{"op":"mcm","id":2,"clk":"AOwuAN0+AJ9F","pt":1710508005510,"mc":[{"id":"1.226122413","rc":[{"batl":[[1,1.89,167.95]],"id":51922}]}],"ArrivalTime":1710508005517}
{"op":"mcm","id":2,"clk":"APEuAOg+AKVF","pt":1710508005623,"mc":[{"id":"1.226122413","rc":[{"batb":[[0,1.87,160.93]],"batl":[[1,1.89,173.95],[0,1.88,162.75]],"id":51922}]}],"ArrivalTime":1710508005631}
{"op":"mcm","id":2,"clk":"APUuAPU+AK1F","pt":1710508005718,"mc":[{"id":"1.226122413","rc":[{"tv":7376.47,"batb":[[0,8.2,24.5]],"trd":[[8.2,483.84]],"ltp":8.2,"id":41122648},{"tv":72420.43,"trd":[[1.88,6882.98]],"ltp":1.88,"batl":[[1,1.89,179.95],[0,1.88,151.3]],"id":51922}],"tv":100685.1}],"ArrivalTime":1710508005726}
{"op":"mcm","id":2,"clk":"AP4uAPo+ALtF","pt":1710508005826,"mc":[{"id":"1.226122413","rc":[{"tv":424.63,"batb":[[2,190,1.11],[1,200,2.32],[0,210,2.13]],"trd":[[220,44.14]],"id":41200638},{"tv":72479.67,"batb":[[0,1.87,131.31]],"trd":[[1.87,6920.67]],"ltp":1.87,"id":51922},{"tv":13710.13,"trd":[[4.5,2865.24]],"ltp":4.5,"batl":[[0,4.5,101.22]],"id":50466254}],"tv":100751.9}],"ArrivalTime":1710508005834}
{"op":"mcm","id":2,"clk":"AIIvAIw/AMNF","pt":1710508005939,"mc":[{"id":"1.226122413","rc":[{"batb":[[0,8.2,37.37]],"id":41122648},{"tv":1773.01,"trd":[[26,310.36]],"batl":[[0,26,3.14]],"id":55632148},{"batl":[[1,1.89,187.95]],"id":51922}],"tv":100761.9}],"ArrivalTime":1710508005947}
{"op":"mcm","id":2,"clk":"AIovAJA/AMlF","pt":1710508006048,"mc":[{"id":"1.226122413","rc":[{"tv":425.47,"batb":[[0,210,1.71]],"trd":[[220,44.98]],"batl":[],"id":41200638},{"batl":[[0,1.88,153.3]],"id":51922}],"tv":100762.74}],"ArrivalTime":1710508006056}
{"op":"mcm","id":2,"clk":"AJEvAJg/ANFF","pt":1710508006095,"mc":[{"id":"1.226122413","rc":[{"batb":[[0,8.2,44.34]],"batl":[[0,8.4,30.81]],"id":41122648},{"batb":[[0,25,10.28]],"id":55632148},{"batl":[[1,1.89,205.95]],"id":51922}]}],"ArrivalTime":1710508006102}
{"op":"mcm","id":2,"clk":"AJYvAKQ/ANpF","pt":1710508006251,"mc":[{"id":"1.226122413","rc":[{"tv":425.79,"batb":[[1,200,2.59],[0,210,1.55]],"trd":[[220,45.3]],"batl":[[0,230,6.14]],"id":41200638},{"tv":13710.17,"batb":[[0,4.4,128.82]],"trd":[[4.4,3195.87]],"ltp":4.4,"id":50466254}],"tv":100763.1}],"ArrivalTime":1710508006258}
{"op":"mcm","id":2,"clk":"AJ0vAK4/AN5F","pt":1710508006303,"mc":[{"id":"1.226122413","rc":[{"tv":72499.67,"batb":[[0,1.87,121.31]],"trd":[[1.87,6940.67]],"batl":[[1,1.89,211.95]],"id":51922}],"tv":100783.1}],"ArrivalTime":1710508006310}
{"op":"mcm","id":2,"clk":"AKMvALo/AOhF","pt":1710508006414,"mc":[{"id":"1.226122413","rc":[{"batb":[[2,180,2.4],[1,190,1.11],[0,200,3.59]],"id":41200638}]}],"ArrivalTime":1710508006422}
{"op":"mcm","id":2,"clk":"AKwvAMA/APNF","pt":1710508006513,"mc":[{"id":"1.226122413","rc":[{"batl":[[1,1.89,217.95],[0,1.88,165.3]],"id":51922}]}],"ArrivalTime":1710508006520}
{"op":"mcm","id":2,"clk":"AMMvAOU/AJRG","pt":1710508006845,"mc":[{"id":"1.226122413","rc":[{"batb":[[2,170,19.37]],"id":41200638},{"batl":[[0,1.88,177.3],[1,1.89,223.95]],"id":51922},{"tv":13718.35,"batb":[[0,4.4,124.73]],"trd":[[4.4,3204.05]],"id":50466254}],"tv":100791.28,"con":true}],"ArrivalTime":1710508006853}
{"op":"mcm","id":2,"clk":"AMsvAPI/AKNG","pt":1710508007034,"mc":[{"id":"1.226122413","rc":[{"batl":[[0,1.88,185.3]],"id":51922}]}],"ArrivalTime":1710508007042}
{"op":"mcm","id":2,"clk":"ANEvAP0/AKhG","pt":1710508007138,"mc":[{"id":"1.226122413","rc":[{"batl":[[0,1.88,191.3]],"id":51922}]}],"ArrivalTime":1710508007145}
{"op":"mcm","id":2,"clk":"ANovAIdAAKlG","pt":1710508007239,"mc":[{"id":"1.226122413","rc":[{"batl":[[0,1.88,193.3]],"id":51922}]}],"ArrivalTime":1710508007247}
{"op":"mcm","id":2,"clk":"AOAvAI1AALBG","pt":1710508007289,"mc":[{"id":"1.226122413","rc":[{"batl":[[2,1.9,184.58]],"id":51922}]}],"ArrivalTime":1710508007298}
{"op":"mcm","id":2,"clk":"AO4vAKBAAL5G","pt":1710508007503,"mc":[{"id":"1.226122413","rc":[{"tv":72503.45,"batb":[[0,1.87,119.42]],"trd":[[1.87,6944.45]],"batl":[[2,1.9,190.58],[0,1.88,213.3]],"id":51922}],"tv":100795.06}],"ArrivalTime":1710508007510}
{"op":"mcm","id":2,"clk":"APUvAKpAAMRG","pt":1710508007607,"mc":[{"id":"1.226122413","rc":[{"batl":[[0,1.88,218.3]],"id":51922}]}],"ArrivalTime":1710508007614}
{"op":"mcm","id":2,"clk":"APovALRAAMdG","pt":1710508007704,"mc":[{"id":"1.226122413","rc":[{"tv":72543.45,"batb":[[0,1.87,99.42]],"trd":[[1.87,6984.45]],"batl":[[2,1.9,196.58]],"id":51922}],"tv":100835.06}],"ArrivalTime":1710508007712}
{"op":"mcm","id":2,"clk":"AP8vALxAAM1G","pt":1710508007800,"mc":[{"id":"1.226122413","rc":[{"batb":[[2,7.8,68.7]],"id":41122648},{"batb":[[1,1.86,377.66]],"id":51922}]}],"ArrivalTime":1710508007807}
{"op":"mcm","id":2,"clk":"AIcwAMhAANdG","pt":1710508007910,"mc":[{"id":"1.226122413","rc":[{"batb":[[2,1.85,522.22]],"batl":[[2,1.9,202.58],[0,1.88,226.3]],"id":51922}]}],"ArrivalTime":1710508007918}
{"op":"mcm","id":2,"clk":"AIwwANFAAOFG","pt":1710508008013,"mc":[{"id":"1.226122413","rc":[{"batl":[[2,1.9,208.58]],"id":51922}]}],"ArrivalTime":1710508008021}
{"op":"mcm","id":2,"clk":"AJUwAOBAAPFG","pt":1710508008237,"mc":[{"id":"1.226122413","rc":[{"tv":72583.09,"batb":[[0,1.87,79.6]],"trd":[[1.87,7024.09]],"batl":[[2,1.9,214.58],[0,1.88,232.3]],"id":51922},{"tv":13728.35,"trd":[[4.5,2875.24]],"ltp":4.5,"batl":[[0,4.5,96.22]],"id":50466254}],"tv":100884.7}],"ArrivalTime":1710508008245}
{"op":"mcm","id":2,"clk":"AJcwAOdAAPhG","pt":1710508008319,"mc":[{"id":"1.226122413","rc":[{"batb":[[0,1.87,106.6]],"batl":[[0,1.88,238.3]],"id":51922}]}],"ArrivalTime":1710508008327}
{"op":"mcm","id":2,"clk":"AJwwAPJAAIJH","pt":1710508008419,"mc":[{"id":"1.226122413","rc":[{"batl":[[0,8.4,27.32]],"id":41122648},{"batl":[[0,1.88,240.3]],"id":51922}]}],"ArrivalTime":1710508008426}
{"op":"mcm","id":2,"clk":"AKEwAINBAI1H","pt":1710508008528,"mc":[{"id":"1.226122413","rc":[{"batl":[[0,1.88,246.3]],"id":51922},{"tv":494.75,"batb":[[0,150,1.08]],"trd":[[150,41.06]],"id":66251581}],"tv":100886.7}],"ArrivalTime":1710508008536}
{"op":"mcm","id":2,"clk":"AK4wAJJBAKBH","pt":1710508008742,"mc":[{"id":"1.226122413","rc":[{"tv":7388.37,"trd":[[8.4,845.7]],"ltp":8.4,"batl":[[0,8.4,21.37]],"id":41122648},{"batl":[[1,1.89,225.95],[0,1.88,252.3]],"id":51922},{"batl":[[2,200,2.56],[1,180,2.28],[0,170,4.01]],"id":66251581}],"tv":100898.6}],"ArrivalTime":1710508008749}
{"op":"mcm","id":2,"clk":"ALQwAJxBAKhH","pt":1710508008839,"mc":[{"id":"1.226122413","rc":[{"batl":[[2,270,1.19],[1,260,2.65],[0,250,2.22]],"id":41200638},{"tv":72593.09,"batb":[[0,1.87,101.6]],"trd":[[1.87,7034.09]],"batl":[],"id":51922}],"tv":100908.6}],"ArrivalTime":1710508008847}
{"op":"mcm","id":2,"clk":"ALwwAKxBALFH","pt":1710508008939,"mc":[{"id":"1.226122413","rc":[{"tv":72603.09,"batb":[[0,1.87,96.6]],"trd":[[1.87,7044.09]],"batl":[[0,1.88,258.3]],"id":51922},{"tv":13828.35,"batb":[[0,4.4,74.73]],"trd":[[4.4,3304.05]],"ltp":4.4,"id":50466254}],"tv":101018.6}],"ArrivalTime":1710508008949}
