{"op":"mcm","id":2,"clk":"APluANCZAQCRqgE=","pt":1710508130709,"mc":[{"id":"1.226122413","rc":[{"tv":448.23,"batb":[[2,400,2.88],[1,420,1.62],[0,430,3.5]],"trd":[[440,10.4]],"ltp":440,"id":54370634},{"tv":536.63,"batb":[[2,310,1.03],[1,360,2.52],[0,400,1.1]],"trd":[[500,2.89],[430,2.68],[420,4.06],[410,4.98]],"ltp":410,"id":41200638},{"batl":[[0,1.87,116.83]],"id":51922},{"tv":2909.74,"batb":[[0,50,72.76]],"trd":[[50,21.9]],"ltp":50,"id":49744721},{"tv":626.37,"batb":[[0,170,4.13]],"trd":[[170,43.54]],"ltp":170,"batl":[[2,200,3.18]],"id":66251581}],"tv":152266.48}],"ArrivalTime":1710508130716}
{"op":"mcm","id":2,"clk":"AIBvAN+ZAQCeqgE=","pt":1710508130812,"mc":[{"id":"1.226122413","rc":[{"batb":[[2,380,1.78]],"id":54370634},{"batb":[[2,1.84,136.71]],"batl":[[0,1.87,126.83]],"id":51922},{"tv":2910.76,"trd":[[55,3.22]],"ltp":55,"batl":[[0,55,8.45]],"id":49744721},{"batb":[[0,34,5.19]],"id":106596}],"tv":152267.5}],"ArrivalTime":1710508130820}
{"op":"mcm","id":2,"clk":"AIlvAOiZAQCnqgE=","pt":1710508130910,"mc":[{"id":"1.226122413","rc":[{"batb":[[0,430,5.5]],"id":54370634},{"tv":11728.54,"batb":[[0,5.9,62.57]],"trd":[[6,1291.77]],"batl":[[0,6,8.63]],"id":41122648},{"batb":[[2,350,1.62],[1,360,3.01],[0,410,2]],"id":41200638},{"batl":[[1,28,4.69]],"id":55632148},{"tv":110161.42,"batb":[[2,1.84,140.71],[0,1.86,14.83]],"trd":[[1.86,11768.62]],"ltp":1.86,"id":51922},{"batb":[[2,4.6,241.64],[0,4.8,36.7]],"id":50466254},{"batb":[[0,170,5.13]],"batl":[[0,180,2.79]],"id":66251581}],"tv":152295.5}],"ArrivalTime":1710508130917}
{"op":"mcm","id":2,"clk":"AJFvAO6ZAQCyqgE=","pt":1710508131013,"mc":[{"id":"1.226122413","rc":[{"batb":[[1,360,2.56]],"id":41200638},{"batb":[[2,1.84,144.71]],"id":51922},{"tv":2912.76,"batb":[[0,50,71.76]],"trd":[[50,23.9]],"ltp":50,"id":49744721},{"batb":[[0,4.8,61.7]],"id":50466254},{"batb":[[0,170,6.81]],"id":66251581}],"tv":152297.5}],"ArrivalTime":1710508131021}
{"op":"mcm","id":2,"clk":"AJhvAPyZAQDFqgE=","pt":1710508131127,"mc":[{"id":"1.226122413","rc":[{"batl":[[0,1.87,169.47]],"id":51922},{"batb":[],"batl":[[1,60,34.11]],"id":49744721},{"batb":[[1,32,16.86]],"id":106596}]}],"ArrivalTime":1710508131134}
{"op":"mcm","id":2,"clk":"AKBvAP+ZAQDNqgE=","pt":1710508131218,"mc":[{"id":"1.226122413","rc":[{"tv":11762.19,"trd":[[6,1309.03],[6.2,689.82]],"ltp":6.2,"batl":[[2,6.6,30.37],[1,6.4,39.5],[0,6.2,75.27]],"id":41122648},{"tv":2633.87,"trd":[[28,372.68],[27,387.86]],"ltp":28,"batl":[[2,30,11.47],[1,29,14.76],[0,28,2.16]],"id":55632148},{"batb":[[2,1.83,288.75],[1,1.84,144.71],[0,1.85,118.07]],"batl":[],"id":51922},{"batl":[[0,5,98.57]],"id":50466254}],"tv":152339.65}],"ArrivalTime":1710508131225}
{"op":"mcm","id":2,"clk":"AKpvAIWaAQDTqgE=","pt":1710508131327,"mc":[{"id":"1.226122413","rc":[{"batb":[[0,430,3.5]],"id":54370634},{"batb":[[0,5.9,24.02]],"batl":[],"id":41122648},{"batb":[[2,310,1.03],[1,350,1.62],[0,360,3.03]],"batl":[[1,620,1.57]],"id":41200638},{"batl":[[2,30,8.02]],"id":55632148},{"batb":[[2,1.83,310.1]],"batl":[],"id":51922},{"tv":20745.66,"batb":[[0,4.8,61.6]],"trd":[[4.8,1467.72]],"id":50466254},{"batb":[[0,170,3.65]],"batl":[],"id":66251581}],"tv":152339.85}],"ArrivalTime":1710508131334}
{"op":"mcm","id":2,"clk":"AK9vAIuaAQDeqgE=","pt":1710508131435,"mc":[{"id":"1.226122413","rc":[{"batl":[[2,750,1.71],[1,740,2.82],[0,730,2.76]],"id":54370634},{"batb":[[2,5.8,38.41],[1,5.9,34.02],[0,6,13.47]],"batl":[[0,6.2,61.14]],"id":41122648},{"batb":[[2,24,7],[1,25,12.5],[0,26,7.11]],"id":55632148},{"tv":110174.28,"batb":[[2,1.84,144.71],[1,1.85,118.07],[0,1.86,24.16]],"trd":[[1.87,10599.38]],"ltp":1.87,"batl":[[2,1.89,173.32],[0,1.87,173.04]],"id":51922},{"batb":[[1,4.7,98.7]],"batl":[[0,5,45.15]],"id":50466254}],"tv":152352.71}],"ArrivalTime":1710508131442}
{"op":"mcm","id":2,"clk":"ALJvAJWaAQDnqgE=","pt":1710508131555,"mc":[{"id":"1.226122413","rc":[{"batb":[[2,5.8,77.76]],"id":41122648},{"batb":[[2,300,1.62],[1,310,1.03],[0,360,2.93]],"id":41200638},{"batl":[[1,60,34.94]],"id":49744721},{"batb":[[0,170,1.97]],"id":66251581}]}],"ArrivalTime":1710508131564}
{"op":"mcm","id":2,"clk":"ALpvAJyaAQDwqgE=","pt":1710508131595,"mc":[{"id":"1.226122413","rc":[{"tv":11789.13,"batb":[[2,5.7,78.89],[1,5.8,52.58],[0,5.9,34.02]],"trd":[[6,1335.97]],"ltp":6,"batl":[[2,6.4,39.5],[1,6.2,74.19],[0,6,12.27]],"id":41122648},{"batb":[[1,1.85,128.18],[0,1.86,34.16]],"batl":[],"id":51922},{"tv":2919.04,"trd":[[55,9.5]],"ltp":55,"batl":[[0,55,5.31]],"id":49744721},{"tv":20765.66,"trd":[[5,1171.41]],"ltp":5,"batl":[[0,5,35.15]],"id":50466254},{"batb":[[1,160,7.18]],"id":66251581}],"tv":152405.93}],"ArrivalTime":1710508131603}
{"op":"mcm","id":2,"clk":"AMFvAKaaAQD4qgE=","pt":1710508131707,"mc":[{"id":"1.226122413","rc":[{"tv":11799.85,"batb":[[2,5.7,80.79],[0,5.9,28.66]],"trd":[[5.9,108.03]],"ltp":5.9,"id":41122648},{"tv":110192.5,"batb":[[0,1.86,5]],"trd":[[1.87,10607.6],[1.86,11778.62]],"batl":[[0,1.87,168.93]],"id":51922}],"tv":152434.87}],"ArrivalTime":1710508131714}
{"op":"mcm","id":2,"clk":"AMpvAKuaAQD+qgE=","pt":1710508131800,"mc":[{"id":"1.226122413","rc":[{"batb":[[1,5.8,38.41],[0,5.9,18.66]],"batl":[[1,6.2,95.54]],"id":41122648},{"batl":[[2,32,18.85],[1,30,8.02],[0,29,14.78]],"id":55632148},{"batl":[[0,55,9.17]],"id":49744721}]}],"ArrivalTime":1710508131807}
{"op":"mcm","id":2,"clk":"ANNvALSaAQCDqwE=","pt":1710508131901,"mc":[{"id":"1.226122413","rc":[{"batl":[[2,540,1.71],[1,530,2.56],[0,520,2.82]],"id":41200638},{"batb":[[1,1.85,133.2]],"id":51922},{"batb":[[0,50,72.92]],"id":49744721}]}],"ArrivalTime":1710508131908}
{"op":"mcm","id":2,"clk":"ANtvALeaAQCKqwE=","pt":1710508132005,"mc":[{"id":"1.226122413","rc":[{"batb":[[1,5.8,40.24],[0,5.9,4.41]],"id":41122648},{"tv":110194.5,"trd":[[1.87,10609.6]],"batl":[[0,1.87,157.93]],"id":51922}],"tv":152436.87}],"ArrivalTime":1710508132012}
{"op":"mcm","id":2,"clk":"AOBvAMSaAQCRqwE=","pt":1710508132104,"mc":[{"id":"1.226122413","rc":[{"tv":11801.15,"batb":[[1,5.8,38.41]],"trd":[[6,1337.27]],"ltp":6,"batl":[[0,6,11.63]],"id":41122648}],"tv":152438.17}],"ArrivalTime":1710508132111}
{"op":"mcm","id":2,"clk":"AOpvAMeaAQCeqwE=","pt":1710508132211,"mc":[{"id":"1.226122413","rc":[{"tv":2635.87,"batb":[[0,26,6.11]],"trd":[[26,452.79]],"ltp":26,"batl":[[1,30,7.76],[0,29,11.29]],"id":55632148},{"batb":[[0,1.86,7]],"id":51922},{"batl":[[0,5,21.13]],"id":50466254}],"tv":152440.17}],"ArrivalTime":1710508132218}
{"op":"mcm","id":2,"clk":"AOxvAM6aAQCjqwE=","pt":1710508132313,"mc":[{"id":"1.226122413","rc":[{"tv":110208.5,"batb":[[2,1.83,310.1],[1,1.84,144.71],[0,1.85,133.2]],"trd":[[1.86,11792.62]],"ltp":1.86,"batl":[[2,1.88,108.01],[1,1.87,157.93],[0,1.86,191]],"id":51922},{"tv":20785.66,"batb":[[0,4.8,51.6]],"trd":[[4.8,1487.72]],"ltp":4.8,"id":50466254}],"tv":152474.17}],"ArrivalTime":1710508132320}
{"op":"mcm","id":2,"clk":"APlvANyaAQCsqwE=","pt":1710508132419,"mc":[{"id":"1.226122413","rc":[{"batb":[[0,5.9,10.57]],"id":41122648},{"tv":110427.54,"trd":[[1.86,12011.66]],"batl":[[1,1.87,15.29],[0,1.86,81.48]],"id":51922}],"tv":152693.21}],"ArrivalTime":1710508132426}
{"op":"mcm","id":2,"clk":"APpvAOSaAQC3qwE=","pt":1710508132513,"mc":[{"id":"1.226122413","rc":[{"batb":[[1,5.8,40.24],[0,5.9,12.33]],"id":41122648},{"batb":[[0,26,8.11]],"id":55632148},{"batl":[[1,1.87,38.69]],"id":51922},{"batb":[[0,4.8,58.84]],"id":50466254}]}],"ArrivalTime":1710508132521}
{"op":"mcm","id":2,"clk":"AIZwAOqaAQC9qwE=","pt":1710508132646,"mc":[{"id":"1.226122413","rc":[{"tv":110640.52,"batb":[[2,1.84,144.71],[1,1.85,108.2],[0,1.86,69.39]],"trd":[[1.86,12174.62],[1.85,15274.92]],"ltp":1.85,"batl":[[2,1.89,173.32],[1,1.88,108.01],[0,1.87,80.59]],"id":51922}],"tv":152906.19}],"ArrivalTime":1710508132653}
{"op":"mcm","id":2,"clk":"AIhwAPeaAQDEqwE=","pt":1710508132719,"mc":[{"id":"1.226122413","rc":[{"batb":[[2,420,1.62],[1,430,3.5],[0,450,2]],"id":54370634},{"batb":[[0,5.9,25.94]],"id":41122648},{"batb":[[1,1.85,110.2]],"batl":[[0,1.87,57.19]],"id":51922},{"batb":[[0,50,71.7]],"id":49744721}]}],"ArrivalTime":1710508132726}
{"op":"mcm","id":2,"clk":"AJJwAIObAQDKqwE=","pt":1710508132784,"mc":[{"id":"1.226122413","rc":[{"batb":[[0,5.9,24.18]],"id":41122648},{"batb":[[2,1.83,310.1],[1,1.84,144.71],[0,1.85,110.2]],"id":51922}]}],"ArrivalTime":1710508132792}
{"op":"mcm","id":2,"clk":"AJlwAIibAQDSqwE=","pt":1710508132882,"mc":[{"id":"1.226122413","rc":[{"batl":[[1,530,1]],"id":41200638},{"batb":[[2,1.84,144.71],[1,1.85,110.2],[0,1.86,22.98]],"batl":[],"id":51922}]}],"ArrivalTime":1710508132889}
{"op":"mcm","id":2,"clk":"AJ9wAI6bAQDdqwE=","pt":1710508132985,"mc":[{"id":"1.226122413","rc":[{"batl":[[1,6.2,97.54],[0,6,88.86]],"id":41122648},{"batl":[[0,1.87,15.29]],"id":51922},{"tv":626.53,"batb":[[0,170,2.02]],"trd":[[170,43.7]],"id":66251581}],"tv":152906.35}],"ArrivalTime":1710508132992}
{"op":"mcm","id":2,"clk":"AKdwAJubAQDsqwE=","pt":1710508133093,"mc":[{"id":"1.226122413","rc":[{"tv":11805.37,"batb":[[0,5.9,10.57]],"trd":[[6,1341.49]],"batl":[[0,6,86.75]],"id":41122648},{"tv":2652.09,"batb":[[2,23,18.68],[1,24,7],[0,25,12.5]],"trd":[[26,469.01]],"id":55632148},{"tv":110660.52,"batb":[[2,1.84,146.28],[1,1.85,100.2],[0,1.86,50]],"trd":[[1.85,15294.92]],"id":51922}],"tv":152946.79}],"ArrivalTime":1710508133101}
{"op":"mcm","id":2,"clk":"AK5wAKObAQD0qwE=","pt":1710508133192,"mc":[{"id":"1.226122413","rc":[{"batb":[[2,430,2.65],[1,440,2.47]],"id":54370634},{"tv":110690.48,"batb":[[0,1.86,150]],"trd":[[1.87,10639.56]],"ltp":1.87,"batl":[[2,1.9,137.19],[1,1.89,173.32],[0,1.88,108.32]],"id":51922},{"batl":[[0,55,17.71]],"id":49744721},{"tv":20825.66,"batb":[[2,4.7,98.7],[1,4.8,38.84],[0,4.9,12.62]],"trd":[[4.8,1527.72]],"id":50466254}],"tv":153016.75}],"ArrivalTime":1710508133200}
{"op":"mcm","id":2,"clk":"ALZwAK+bAQD8qwE=","pt":1710508133302,"mc":[{"id":"1.226122413","rc":[{"tv":11826.5,"batb":[[2,5.6,70.5],[1,5.7,80.79],[0,5.8,40.24]],"trd":[[5.9,129.16]],"ltp":5.9,"batl":[[2,6.2,97.54],[1,6,86.75],[0,5.9,23.31]],"id":41122648},{"batb":[[2,24,7],[1,25,12.5],[0,26,3.05]],"batl":[[0,29,14.02]],"id":55632148},{"tv":110691.1,"batb":[[2,1.85,100.2],[1,1.86,172.98],[0,1.87,31.05]],"trd":[[1.87,10640.18]],"batl":[[0,1.88,64.86]],"id":51922},{"tv":2951.34,"batb":[[0,50,55.55]],"trd":[[50,56.2]],"ltp":50,"id":49744721}],"tv":153070.8}],"ArrivalTime":1710508133310}
{"op":"mcm","id":2,"clk":"AL9wALibAQCJrAE=","pt":1710508133403,"mc":[{"id":"1.226122413","rc":[{"batb":[[1,440,1.8]],"id":54370634},{"batl":[[2,520,2.82],[1,510,2.56],[0,490,1.71]],"id":41200638},{"batb":[[2,1.85,102.77]],"batl":[[0,1.88,106.05]],"id":51922},{"batb":[[1,48,22.02]],"id":49744721},{"batl":[[0,36,2.92]],"id":106596}]}],"ArrivalTime":1710508133410}
{"op":"mcm","id":2,"clk":"AMNwAMObAQCSrAE=","pt":1710508133508,"mc":[{"id":"1.226122413","rc":[{"batb":[[1,440,1.62],[0,450,2.3]],"id":54370634},{"batb":[[1,5.7,90.79],[0,5.8,70.59]],"batl":[[0,5.9,43.67]],"id":41122648},{"batb":[[0,360,2.81]],"id":41200638},{"tv":110753.2,"batb":[[2,1.84,152.28],[1,1.85,102.77],[0,1.86,281.98]],"trd":[[1.87,10702.28]],"batl":[[2,1.89,173.32],[1,1.88,81.49],[0,1.87,50.95]],"id":51922},{"batb":[[0,50,57.55]],"id":49744721},{"tv":20850.9,"batb":[[2,4.6,241.64],[1,4.7,98.7],[0,4.8,55.15]],"trd":[[4.9,586.28]],"ltp":4.9,"id":50466254}],"tv":153158.14}],"ArrivalTime":1710508133515}
{"op":"mcm","id":2,"clk":"AMpwAMybAQCerAE=","pt":1710508133616,"mc":[{"id":"1.226122413","rc":[{"batl":[[0,5.9,46.67]],"id":41122648},{"tv":110859.1,"batb":[[2,1.85,102.77],[1,1.86,281.98],[0,1.87,74.41]],"trd":[[1.87,10808.18]],"batl":[[2,1.9,137.19],[1,1.89,173.32],[0,1.88,81.49]],"id":51922},{"batl":[[0,36,2.07]],"id":106596}],"tv":153264.04}],"ArrivalTime":1710508133623}
{"op":"mcm","id":2,"clk":"ANRwANabAQCnrAE=","pt":1710508133717,"mc":[{"id":"1.226122413","rc":[{"tv":11934.82,"trd":[[5.9,179.02],[6,1399.95]],"ltp":6,"batl":[[2,6.4,39.5],[1,6.2,97.54],[0,6,57.51]],"id":41122648},{"batb":[[1,1.86,284.55]],"id":51922},{"batl":[[1,60,38.17]],"id":49744721},{"batb":[[2,4.7,98.7],[1,4.8,55.15],[0,4.9,1.85]],"id":50466254},{"tv":632.11,"trd":[[180,27.54]],"ltp":180,"batl":[[2,210,5.96],[1,200,3.18],[0,190,1.24]],"id":66251581}],"tv":153377.94}],"ArrivalTime":1710508133724}
{"op":"mcm","id":2,"clk":"AOBwAN6bAQCvrAE=","pt":1710508133842,"mc":[{"id":"1.226122413","rc":[{"batl":[[2,510,3.56],[1,490,1.71],[0,420,2]],"id":41200638},{"tv":110930.78,"batb":[[0,1.87,38.57]],"trd":[[1.87,10879.86]],"batl":[[0,1.88,40.3]],"id":51922},{"tv":20852.9,"batb":[[2,4.6,241.64],[1,4.7,98.7],[0,4.8,56]],"trd":[[4.9,588.28]],"batl":[[0,5,37.08]],"id":50466254},{"batl":[[0,36,2.92]],"id":106596}],"tv":153451.62}],"ArrivalTime":1710508133849}
{"op":"mcm","id":2,"clk":"AOxwAOSbAQC6rAE=","pt":1710508133925,"mc":[{"id":"1.226122413","rc":[{"batb":[[2,5.7,90.79],[1,5.8,79.1],[0,5.9,13.46]],"id":41122648},{"tv":2654.35,"batb":[[0,26,1.92]],"trd":[[26,471.27]],"id":55632148},{"tv":2959.34,"trd":[[55,17.5]],"ltp":55,"batl":[[0,55,13.71]],"id":49744721},{"tv":20854.6,"batb":[[1,4.7,95.56],[0,4.8,55.15]],"trd":[[4.9,589.98]],"batl":[[2,5.1,44.37],[1,5,37.08],[0,4.9,17.44]],"id":50466254},{"batl":[[0,190,1.53]],"id":66251581},{"tv":2513.28,"trd":[[36,18.67]],"ltp":36,"batl":[[0,36,2.64]],"id":106596}],"tv":153464.14}],"ArrivalTime":1710508133933}
{"op":"mcm","id":2,"clk":"APFwAO6bAQC/rAE=","pt":1710508134024,"mc":[{"id":"1.226122413","rc":[{"batb":[[0,450,2.95]],"id":54370634},{"batb":[[0,5.9,27.23]],"id":41122648},{"tv":110961,"batb":[],"trd":[[1.88,12892.52]],"ltp":1.88,"batl":[[0,1.88,25.19]],"id":51922},{"tv":20889.48,"batb":[[2,4.7,95.56],[1,4.8,55.15],[0,4.9,21.87]],"trd":[[4.9,624.86]],"batl":[[2,5.2,30.04],[1,5.1,44.37],[0,5,37.08]],"id":50466254}],"tv":153529.24}],"ArrivalTime":1710508134031}
{"op":"mcm","id":2,"clk":"APdwAPebAQDHrAE=","pt":1710508134128,"mc":[{"id":"1.226122413","rc":[{"batb":[[2,5.7,80.5],[1,5.8,80.93]],"id":41122648},{"tv":2656.45,"batb":[[2,23,18.68],[1,24,7],[0,25,13.37]],"trd":[[26,473.37]],"id":55632148},{"batl":[[0,1.88,66.2]],"id":51922},{"batl":[[0,36,1.79]],"id":106596}],"tv":153531.34}],"ArrivalTime":1710508134135}
{"op":"mcm","id":2,"clk":"AP9wAICcAQDRrAE=","pt":1710508134235,"mc":[{"id":"1.226122413","rc":[{"tv":450.09,"batb":[[0,450,2.02]],"trd":[[460,2.71]],"ltp":460,"id":54370634},{"tv":11953.72,"batb":[[0,5.9,17.78]],"trd":[[5.9,197.92]],"ltp":5.9,"batl":[[2,6.4,62.95],[0,6,60.39]],"id":41122648},{"batl":[[0,420,2.24]],"id":41200638},{"tv":2656.49,"batb":[[2,24,7],[1,25,13.37],[0,28,5.64]],"trd":[[28,372.72]],"ltp":28,"batl":[[0,29,14]],"id":55632148},{"tv":110976.37,"batb":[[0,1.87,109.53]],"trd":[[1.88,12907.89]],"batl":[[2,1.9,121.3],[1,1.89,154.49],[0,1.88,80.63]],"id":51922},{"tv":2960.18,"batb":[[0,50,60.77]],"trd":[[50,57.04]],"ltp":50,"id":49744721},{"tv":633.59,"batb":[[0,170,1.28]],"trd":[[170,45.18]],"ltp":170,"id":66251581}],"tv":153569.83}],"ArrivalTime":1710508134243}
{"op":"mcm","id":2,"clk":"AIpxAImcAQDerAE=","pt":1710508134344,"mc":[{"id":"1.226122413","rc":[{"batb":[[2,430,1.22]],"id":54370634},{"batb":[[1,5.8,79.1]],"id":41122648},{"batb":[[0,1.87,70.96]],"batl":[],"id":51922},{"batl":[[0,36,2.64]],"id":106596}]}],"ArrivalTime":1710508134351}
{"op":"mcm","id":2,"clk":"AI5xAJKcAQDkrAE=","pt":1710508134394,"mc":[{"id":"1.226122413","rc":[{"batb":[[1,5.8,80.93],[0,5.9,13.46]],"id":41122648},{"batl":[[2,510,1]],"id":41200638},{"tv":2667.78,"batb":[[1,25,12.5],[0,26,5.55]],"trd":[[28,384.01]],"batl":[[1,30,8.36],[0,29,11.91]],"id":55632148},{"batl":[[1,1.89,157.48]],"id":51922},{"batb":[[0,50,61.27]],"id":49744721},{"tv":20924.54,"batb":[[0,4.9,4.34]],"trd":[[4.9,659.92]],"id":50466254},{"batl":[[0,36,3.79]],"id":106596}],"tv":153616.18}],"ArrivalTime":1710508134401}
{"op":"mcm","id":2,"clk":"AJNxAJecAQDurAE=","pt":1710508134493,"mc":[{"id":"1.226122413","rc":[{"batb":[[0,450,2.19]],"id":54370634},{"batl":[[2,30,7.76],[1,29,11.27],[0,28,1.51]],"id":55632148},{"batb":[[0,1.87,82.96]],"batl":[[1,1.89,154.49]],"id":51922},{"tv":20933.22,"batb":[[2,4.6,241.64],[1,4.7,95.56],[0,4.8,55.15]],"trd":[[4.9,668.6]],"batl":[[2,5.1,44.37],[1,5,37.08],[0,4.9,16.31]],"id":50466254},{"batl":[[0,190,2.53]],"id":66251581}],"tv":153624.86}],"ArrivalTime":1710508134500}
{"op":"mcm","id":2,"clk":"AJpxAKWcAQD7rAE=","pt":1710508134611,"mc":[{"id":"1.226122413","rc":[{"batb":[[1,310,1.34],[0,360,2.54]],"batl":[[2,510,1.23],[1,490,1.94]],"id":41200638},{"batb":[[0,26,7.55]],"batl":[[1,29,14.3]],"id":55632148},{"batl":[[2,1.9,118.36],[0,1.88,43.28]],"id":51922},{"batb":[[2,4.6,244.73]],"batl":[],"id":50466254}]}],"ArrivalTime":1710508134618}
{"op":"mcm","id":2,"clk":"AKJxAKycAQD+rAE=","pt":1710508134701,"mc":[{"id":"1.226122413","rc":[{"batl":[[1,29,17.02]],"id":55632148},{"batb":[[0,1.87,84.96]],"id":51922}]}],"ArrivalTime":1710508134708}
{"op":"mcm","id":2,"clk":"AKhxALWcAQCErQE=","pt":1710508134808,"mc":[{"id":"1.226122413","rc":[{"batb":[[2,440,1.62],[1,450,2.19],[0,480,1.28]],"id":54370634},{"batb":[[2,310,1.34],[1,360,2.54],[0,370,2.42]],"id":41200638},{"batl":[[2,32,18.85],[1,30,7.76],[0,29,13.99]],"id":55632148},{"tv":111062.93,"batb":[[2,1.86,284.55],[1,1.87,84.96],[0,1.88,15.15]],"trd":[[1.88,12994.45]],"batl":[[2,1.91,147.06],[1,1.9,118.36],[0,1.89,69.09]],"id":51922}],"tv":153711.42}],"ArrivalTime":1710508134815}
{"op":"mcm","id":2,"clk":"ALBxAL2cAQCRrQE=","pt":1710508134915,"mc":[{"id":"1.226122413","rc":[{"batb":[[0,26,5.02]],"id":55632148},{"tv":111122.11,"trd":[[1.89,7218.12]],"ltp":1.89,"batl":[[0,1.89,39.5]],"id":51922},{"tv":2523.28,"batb":[[2,29,42.57],[1,30,24.7],[0,32,17.05]],"trd":[[34,144.23]],"ltp":34,"id":106596}],"tv":153780.6}],"ArrivalTime":1710508134922}
{"op":"mcm","id":2,"clk":"ALpxAMicAQCdrQE=","pt":1710508135021,"mc":[{"id":"1.226122413","rc":[{"batb":[[2,450,2.19],[1,470,1.62]],"id":54370634},{"batb":[[1,350,2.16]],"id":41200638},{"batb":[[0,26,3.02]],"batl":[],"id":55632148},{"tv":111156.41,"batb":[[2,1.85,83.77],[1,1.86,284.55],[0,1.87,166.4]],"trd":[[1.87,10883.86],[1.88,13024.75]],"ltp":1.87,"batl":[[2,1.9,118.36],[1,1.89,39.5],[0,1.88,8.31]],"id":51922},{"batb":[[2,4.6,241.64]],"batl":[],"id":50466254},{"batb":[[0,32,12.86]],"batl":[[0,36,4.64]],"id":106596}],"tv":153814.9}],"ArrivalTime":1710508135028}
{"op":"mcm","id":2,"clk":"AL1xANScAQClrQE=","pt":1710508135119,"mc":[{"id":"1.226122413","rc":[{"batb":[[1,5.8,79.1]],"id":41122648},{"tv":111164.41,"batb":[[0,1.87,162.4]],"trd":[[1.87,10891.86]],"id":51922},{"batb":[[2,30,24.7],[1,32,12.67],[0,34,2.62]],"batl":[[2,40,12.57],[1,38,4.35]],"id":106596}],"tv":153822.9}],"ArrivalTime":1710508135126}
{"op":"mcm","id":2,"clk":"AMhxANmcAQCurQE=","pt":1710508135216,"mc":[{"id":"1.226122413","rc":[{"tv":111181.03,"batb":[[2,1.86,284.55],[1,1.87,162.9],[0,1.88,30.24]],"trd":[[1.88,13041.37]],"ltp":1.88,"batl":[[2,1.91,147.06],[1,1.9,118.36],[0,1.89,39.5]],"id":51922},{"batb":[[2,4.6,244.73]],"batl":[],"id":50466254},{"batl":[[0,36,3.79]],"id":106596}],"tv":153839.52}],"ArrivalTime":1710508135224}
{"op":"mcm","id":2,"clk":"ANRxAOWcAQC4rQE=","pt":1710508135329,"mc":[{"id":"1.226122413","rc":[{"tv":11964.02,"batb":[[1,5.8,41.58],[0,5.9,8.31]],"trd":[[5.9,208.22]],"id":41122648},{"batb":[[0,370,4.42]],"id":41200638},{"batb":[[1,1.87,163.75]],"id":51922},{"tv":2530.6,"batb":[[2,29,42.57],[1,30,24.7],[0,32,11.63]],"trd":[[34,149.47],[32,208.69]],"ltp":32,"batl":[[2,40,13.25],[1,38,5.11]],"id":106596}],"tv":153857.14}],"ArrivalTime":1710508135336}
{"op":"mcm","id":2,"clk":"ANhxAO2cAQDCrQE=","pt":1710508135427,"mc":[{"id":"1.226122413","rc":[{"batb":[[2,450,2.17]],"id":54370634},{"batl":[[2,520,3.05]],"id":41200638},{"batb":[[1,1.87,166.33]],"id":51922},{"tv":2969.44,"batb":[[0,50,56.64]],"trd":[[50,66.3]],"id":49744721},{"batb":[[2,4.6,241.64]],"batl":[[1,5,62.08]],"id":50466254},{"batl":[[0,36,4.64]],"id":106596}],"tv":153866.4}],"ArrivalTime":1710508135434}
{"op":"mcm","id":2,"clk":"AOdxAPecAQDNrQE=","pt":1710508135536,"mc":[{"id":"1.226122413","rc":[{"batb":[[2,450,2.37],[0,480,1.5]],"id":54370634},{"batb":[[2,5.7,78.6],[1,5.8,39.75]],"id":41122648},{"batb":[[1,350,1.87]],"batl":[[1,490,2.2]],"id":41200638},{"batb":[[1,1.87,175.33]],"batl":[[2,1.91,142.06]],"id":51922},{"batb":[[0,50,57.86]],"id":49744721},{"tv":20938.22,"batb":[[1,4.7,105.02],[0,4.8,52.66]],"trd":[[4.8,1532.72]],"ltp":4.8,"id":50466254},{"batb":[[0,32,12.82]],"batl":[[2,40,12.57],[1,38,4.35],[0,36,3.79]],"id":106596}],"tv":153871.4}],"ArrivalTime":1710508135543}
{"op":"mcm","id":2,"clk":"AOxxAPqcAQDRrQE=","pt":1710508135641,"mc":[{"id":"1.226122413","rc":[{"tv":537.11,"trd":[[410,5.46]],"batl":[[0,420,2]],"id":41200638},{"batl":[[1,30,8.02]],"id":55632148},{"batl":[[0,4.9,18.36]],"id":50466254},{"batl":[[2,38,4.35],[1,36,6.07],[0,34,1.87]],"id":106596}],"tv":153871.88}],"ArrivalTime":1710508135648}
{"op":"mcm","id":2,"clk":"APJxAIGdAQDdrQE=","pt":1710508135686,"mc":[{"id":"1.226122413","rc":[{"tv":111181.23,"trd":[[1.89,7218.32]],"ltp":1.89,"batl":[[0,1.89,39.4]],"id":51922}],"tv":153872.08}],"ArrivalTime":1710508135693}
{"op":"mcm","id":2,"clk":"APtxAI2dAQDqrQE=","pt":1710508135795,"mc":[{"id":"1.226122413","rc":[{"tv":11968.78,"batb":[[0,5.9,5.93]],"trd":[[5.9,212.98]],"batl":[[1,6.2,100.54]],"id":41122648},{"batl":[[1,30,7.76]],"id":55632148},{"tv":111257.31,"batb":[[2,1.85,83.77],[1,1.86,284.55],[0,1.87,174.36]],"trd":[[1.87,10907.46],[1.88,13101.85]],"ltp":1.87,"id":51922},{"tv":20944.88,"trd":[[4.9,675.26]],"ltp":4.9,"batl":[[0,4.9,15.03]],"id":50466254},{"tv":2532.6,"batb":[[0,32,11.82]],"trd":[[32,210.69]],"batl":[[2,38,5.11]],"id":106596}],"tv":153961.58}],"ArrivalTime":1710508135802}
{"op":"mcm","id":2,"clk":"AIJyAJadAQD0rQE=","pt":1710508135898,"mc":[{"id":"1.226122413","rc":[{"batb":[[1,1.86,286.88]],"batl":[[2,1.91,139.16]],"id":51922}]}],"ArrivalTime":1710508135906}
{"op":"mcm","id":2,"clk":"AIZyAJ6dAQD+rQE=","pt":1710508136001,"mc":[{"id":"1.226122413","rc":[{"batb":[[2,450,2.2]],"id":54370634},{"batl":[[0,4.9,2.05]],"id":50466254},{"batb":[[0,32,16.15]],"batl":[[2,38,4.35]],"id":106596}]}],"ArrivalTime":1710508136008}
{"op":"mcm","id":2,"clk":"AIlyAKedAQCKrgE=","pt":1710508136106,"mc":[{"id":"1.226122413","rc":[{"batb":[[2,310,1.6]],"id":41200638},{"batl":[[0,4.9,12.26]],"id":50466254}]}],"ArrivalTime":1710508136113}
{"op":"mcm","id":2,"clk":"AJByAK6dAQCUrgE=","pt":1710508136203,"mc":[{"id":"1.226122413","rc":[{"batb":[[2,350,1.87],[1,370,4.42],[0,410,2]],"id":41200638},{"batl":[[0,4.9,22.26]],"id":50466254},{"batb":[[1,30,21.48]],"id":106596}]}],"ArrivalTime":1710508136210}
{"op":"mcm","id":2,"clk":"AJ1yALKdAQCgrgE=","pt":1710508136311,"mc":[{"id":"1.226122413","rc":[{"tv":11980.24,"batb":[[2,5.6,70.5],[1,5.7,78.6],[0,5.8,39.95]],"trd":[[5.9,224.44]],"id":41122648},{"tv":539.11,"batb":[[1,370,2.42],[0,410,1]],"trd":[[410,7.46]],"id":41200638},{"tv":2669.32,"batb":[[0,26,2.25]],"trd":[[26,474.91]],"ltp":26,"batl":[[2,32,15.62]],"id":55632148},{"batb":[[0,1.87,152.42]],"id":51922},{"batb":[[0,50,65.42]],"id":49744721}],"tv":153976.58}],"ArrivalTime":1710508136318}
{"op":"mcm","id":2,"clk":"AKNyALWdAQCqrgE=","pt":1710508136420,"mc":[{"id":"1.226122413","rc":[{"batb":[[2,460,2.74]],"batl":[[0,730,3.22]],"id":54370634},{"batb":[[2,5.6,68.52],[0,5.8,41.62]],"id":41122648},{"tv":542.53,"batb":[[2,310,1.6],[1,350,1.87],[0,370,1.71]],"trd":[[410,9.46],[370,13]],"ltp":370,"id":41200638},{"batl":[[0,29,4.72]],"id":55632148}],"tv":153980}],"ArrivalTime":1710508136427}
{"op":"mcm","id":2,"clk":"AKVyAMKdAQCyrgE=","pt":1710508136521,"mc":[{"id":"1.226122413","rc":[{"batl":[[2,890,1],[1,750,1.71]],"id":54370634},{"tv":11980.64,"batb":[[0,5.8,41.42]],"trd":[[5.9,224.84]],"batl":[[2,6.2,100.54],[1,6,60.39],[0,5.9,13.74]],"id":41122648},{"batl":[[0,420,2.1]],"id":41200638},{"tv":637.59,"trd":[[190,22.67],[180,28.12]],"ltp":190,"batl":[[2,260,1.55],[1,210,5.96],[0,200,3.71]],"id":66251581}],"tv":153984.4}],"ArrivalTime":1710508136529}
{"op":"mcm","id":2,"clk":"ALVyAMydAQC8rgE=","pt":1710508136635,"mc":[{"id":"1.226122413","rc":[{"batb":[[2,460,3.42]],"batl":[[2,750,1.71],[1,730,2.56],[0,710,3.48]],"id":54370634},{"batb":[[2,280,6.15],[1,310,1.6],[0,350,1.87]],"id":41200638},{"batb":[[0,1.87,152.92]],"id":51922},{"batl":[[2,40,12.57],[1,38,4.35],[0,36,6.07]],"id":106596}]}],"ArrivalTime":1710508136642}
{"op":"mcm","id":2,"clk":"ALhyANOdAQDHrgE=","pt":1710508136725,"mc":[{"id":"1.226122413","rc":[{"batb":[[2,5.6,70.5],[1,5.7,60.81],[0,5.8,29.75]],"id":41122648},{"batb":[[1,310,1.19],[0,340,2.28]],"id":41200638},{"batb":[[0,26,4.87]],"id":55632148},{"tv":111272.93,"batb":[[2,1.86,286.88],[1,1.87,152.42],[0,1.88,25.5]],"trd":[[1.89,7233.94]],"ltp":1.89,"batl":[[0,1.89,31.59]],"id":51922},{"batl":[[0,4.9,20.21]],"id":50466254},{"batb":[[2,160,7.18],[1,170,1.28],[0,180,1.15]],"batl":[[2,210,5.96],[1,200,3.18],[0,190,2.26]],"id":66251581}],"tv":154000.02}],"ArrivalTime":1710508136732}
{"op":"mcm","id":2,"clk":"AMZyANidAQDbrgE=","pt":1710508136846,"mc":[{"id":"1.226122413","rc":[{"tv":11985.38,"trd":[[5.9,229.58]],"batl":[[0,5.9,11.37]],"id":41122648},{"tv":111273.11,"batb":[[0,1.88,36.09]],"trd":[[1.88,13102.03]],"ltp":1.88,"id":51922},{"batb":[[2,4.6,244.73]],"id":50466254}],"tv":154004.94}],"ArrivalTime":1710508136854}
{"op":"mcm","id":2,"clk":"AMhyAOOdAQDirgE=","pt":1710508136888,"mc":[{"id":"1.226122413","rc":[{"batb":[[2,460,4.1]],"id":54370634},{"batb":[[2,280,5.73],[1,300,2.04],[0,310,1.85]],"batl":[[1,490,2.07]],"id":41200638},{"batb":[[0,26,7.3]],"batl":[],"id":55632148},{"tv":111277.11,"batb":[[1,1.87,175.17],[0,1.88,34.09]],"trd":[[1.88,13106.03]],"batl":[],"id":51922}],"tv":154008.94}],"ArrivalTime":1710508136895}
{"op":"mcm","id":2,"clk":"AM5yAOidAQDyrgE=","pt":1710508137045,"mc":[{"id":"1.226122413","rc":[{"batb":[[1,5.7,41.73]],"id":41122648},{"batb":[[0,310,1.6]],"id":41200638}]}],"ArrivalTime":1710508137052}
{"op":"mcm","id":2,"clk":"AOVyAPedAQD/rgE=","pt":1710508137198,"mc":[{"id":"1.226122413","rc":[{"tv":12044.88,"batb":[[2,5.5,32.25],[1,5.6,70.5],[0,5.7,41.73]],"trd":[[5.8,59.5]],"ltp":5.8,"id":41122648}],"tv":154068.44}],"ArrivalTime":1710508137205}
{"op":"mcm","id":2,"clk":"APByAP6dAQCIrwE=","pt":1710508137383,"mc":[{"id":"1.226122413","rc":[{"batb":[[2,5.6,70.5],[1,5.7,41.73],[0,5.8,46.74]],"batl":[[1,6,62.97],[0,5.9,35.15]],"id":41122648},{"batb":[[2,280,6.05]],"id":41200638},{"batb":[[0,1.88,71.5]],"batl":[[0,1.89,30.02]],"id":51922},{"batb":[[2,46,21.6]],"id":49744721},{"batb":[[2,150,3.74],[1,160,7.18],[0,170,1.28]],"id":66251581}]}],"ArrivalTime":1710508137391}
{"op":"mcm","id":2,"clk":"APJyAISeAQCNrwE=","pt":1710508137402,"mc":[{"id":"1.226122413","rc":[{"tv":12074,"batb":[[1,5.7,39.83],[0,5.8,32.18]],"trd":[[5.8,88.62]],"id":41122648},{"batb":[[0,310,1.34]],"id":41200638},{"tv":111281.11,"batb":[[0,1.88,69.5]],"trd":[[1.88,13110.03]],"batl":[],"id":51922}],"tv":154101.56}],"ArrivalTime":1710508137409}
{"op":"mcm","id":2,"clk":"APpyAI+eAQCVrwE=","pt":1710508137514,"mc":[{"id":"1.226122413","rc":[{"batb":[],"batl":[[2,890,1],[1,750,1.71]],"id":54370634},{"batb":[[2,5.5,56.08],[1,5.6,70.5],[0,5.7,87.39]],"batl":[],"id":41122648},{"batb":[[2,280,6.35]],"batl":[[2,490,2.07],[1,420,2],[0,410,2.66]],"id":41200638},{"batb":[[2,46,22.63]],"id":49744721}]}],"ArrivalTime":1710508137521}
{"op":"mcm","id":2,"clk":"AINzAJieAQCdrwE=","pt":1710508137620,"mc":[{"id":"1.226122413","rc":[{"batb":[[2,460,4.79]],"id":54370634},{"batb":[[1,5.6,88.6],[0,5.7,89.29]],"id":41122648},{"tv":111291.11,"batb":[[0,1.88,64.5]],"trd":[[1.88,13120.03]],"batl":[],"id":51922}],"tv":154111.56}],"ArrivalTime":1710508137628}
{"op":"mcm","id":2,"clk":"AIZzAJ6eAQClrwE=","pt":1710508137719,"mc":[{"id":"1.226122413","rc":[{"batb":[[0,5.7,41.73]],"batl":[[0,5.9,36.78]],"id":41122648},{"batl":[[2,420,2],[1,410,2.66],[0,400,1.75]],"id":41200638},{"batb":[[1,1.87,174.32]],"id":51922},{"batb":[[2,30,21.48],[1,32,16.15],[0,34,6.78]],"id":106596}]}],"ArrivalTime":1710508137726}
{"op":"mcm","id":2,"clk":"AI1zAKqeAQCyrwE=","pt":1710508137826,"mc":[{"id":"1.226122413","rc":[{"batb":[[0,5.7,74.48]],"batl":[[1,6,74.83],[0,5.9,61.78]],"id":41122648},{"batl":[[0,400,3.5]],"id":41200638},{"batl":[[0,29,2]],"id":55632148},{"tv":111292.81,"batb":[[2,1.86,186.88]],"trd":[[1.89,7235.64]],"ltp":1.89,"batl":[[0,1.89,29.17]],"id":51922},{"batl":[[0,4.9,22.21]],"id":50466254}],"tv":154113.26}],"ArrivalTime":1710508137833}
{"op":"mcm","id":2,"clk":"AJtzALOeAQC4rwE=","pt":1710508137946,"mc":[{"id":"1.226122413","rc":[{"batb":[[0,5.7,72.58]],"batl":[[2,6,74.83],[1,5.9,61.78],[0,5.8,14.33]],"id":41122648},{"batl":[[0,400,4.61]],"id":41200638},{"tv":2683.92,"batb":[[2,23,18.68],[1,24,7],[0,25,12.5]],"trd":[[26,489.51]],"batl":[],"id":55632148},{"tv":111300.69,"trd":[[1.89,7243.52]],"batl":[[0,1.89,25.23]],"id":51922},{"batb":[[2,4.6,241.64]],"batl":[[0,4.9,24.21]],"id":50466254},{"batb":[[0,34,9.23]],"batl":[[2,40,13.25],[1,38,5.11],[0,36,4.64]],"id":106596}],"tv":154135.74}],"ArrivalTime":1710508137954}
{"op":"mcm","id":2,"clk":"AJ5zALieAQC+rwE=","pt":1710508138024,"mc":[{"id":"1.226122413","rc":[{"batl":[[2,750,1.71],[1,710,2.82],[0,700,3.22]],"id":54370634},{"batb":[[2,5.5,74.5]],"id":41122648},{"batb":[[0,1.88,158.5]],"id":51922}]}],"ArrivalTime":1710508138031}
{"op":"mcm","id":2,"clk":"AKdzAMCeAQDNrwE=","pt":1710508138156,"mc":[{"id":"1.226122413","rc":[{"batb":[[2,460,5.47]],"id":54370634},{"tv":12086.1,"batb":[[0,5.7,74.48]],"trd":[[5.8,100.72]],"batl":[[1,5.9,71.78],[0,5.8,8.28]],"id":41122648},{"batb":[[2,24,7],[1,25,12.5],[0,26,3.09]],"batl":[],"id":55632148},{"tv":20946.58,"batb":[[2,4.6,244.73],[0,4.8,51.8]],"trd":[[4.8,1534.42]],"ltp":4.8,"id":50466254}],"tv":154149.54}],"ArrivalTime":1710508138163}
{"op":"mcm","id":2,"clk":"AKpzAMqeAQDRrwE=","pt":1710508138242,"mc":[{"id":"1.226122413","rc":[{"batb":[[0,5.7,72.58]],"id":41122648},{"tv":111351.16,"batb":[[2,1.87,174.32],[1,1.88,158.5],[0,1.89,20.4]],"trd":[[1.89,7293.99]],"batl":[[2,1.92,236.69],[1,1.91,139.16],[0,1.9,118.36]],"id":51922},{"tv":2973.44,"batb":[[0,50,63.42]],"trd":[[50,70.3]],"id":49744721},{"tv":642.11,"trd":[[190,27.19]],"batl":[[2,260,1.55],[1,210,5.96],[0,200,3.18]],"id":66251581}],"tv":154208.53}],"ArrivalTime":1710508138250}
{"op":"mcm","id":2,"clk":"AK5zANOeAQDbrwE=","pt":1710508138333,"mc":[{"id":"1.226122413","rc":[{"batl":[[0,5.8,15.59]],"id":41122648},{"batb":[[1,290,2.04]],"id":41200638},{"batb":[[0,26,5.09]],"batl":[],"id":55632148},{"batb":[[2,30,23.48]],"id":106596}]}],"ArrivalTime":1710508138340}
{"op":"mcm","id":2,"clk":"ALpzANmeAQDsrwE=","pt":1710508138457,"mc":[{"id":"1.226122413","rc":[{"tv":12086.78,"batb":[[1,5.6,98.6],[0,5.7,62.58]],"trd":[[5.8,101.4]],"batl":[[0,5.8,15.25]],"id":41122648},{"batl":[[2,450,1.71],[1,420,2]],"id":41200638},{"tv":111451.16,"batb":[[2,1.86,156.88],[1,1.87,204.32],[0,1.88,170.49]],"trd":[[1.88,13220.03]],"ltp":1.88,"batl":[[0,1.9,129.47]],"id":51922},{"tv":21049.05,"batb":[[2,4.5,126.78],[1,4.6,241.64],[0,4.7,105.59]],"trd":[[4.8,1636.89]],"batl":[],"id":50466254},{"batb":[[2,160,7.18],[1,170,1.28],[0,180,1.68]],"id":66251581}],"tv":154411.68}],"ArrivalTime":1710508138464}
{"op":"mcm","id":2,"clk":"ALxzAN6eAQDzrwE=","pt":1710508138497,"mc":[{"id":"1.226122413","rc":[{"batb":[[2,240,1.75],[1,280,7.77]],"batl":[],"id":41200638},{"batb":[[2,1.86,178.23],[1,1.87,219.32]],"id":51922},{"batb":[[1,32,20.36]],"id":106596}]}],"ArrivalTime":1710508138504}
{"op":"mcm","id":2,"clk":"AMdzAOaeAQCBsAE=","pt":1710508138610,"mc":[{"id":"1.226122413","rc":[{"tv":12105.98,"batb":[[1,5.6,80.5]],"trd":[[5.8,120.6]],"batl":[[0,5.8,5.65]],"id":41122648},{"batb":[[2,25,12.5],[1,26,5.09],[0,27,3.01]],"batl":[],"id":55632148},{"tv":111471.16,"batb":[[0,1.88,192.82]],"trd":[[1.9,6068.88]],"ltp":1.9,"batl":[[0,1.9,108.36]],"id":51922},{"batb":[[2,4.6,241.64],[1,4.7,105.02],[0,4.8,13.19]],"batl":[[0,4.9,40.5]],"id":50466254}],"tv":154450.88}],"ArrivalTime":1710508138617}
{"op":"mcm","id":2,"clk":"ANRzAPWeAQCJsAE=","pt":1710508138717,"mc":[{"id":"1.226122413","rc":[{"batb":[[0,480,1.66]],"id":54370634},{"batl":[[0,400,5.61]],"id":41200638},{"batb":[[1,26,7.42]],"batl":[],"id":55632148},{"tv":111503.17,"batb":[[0,1.88,176.82]],"trd":[[1.88,13252.04]],"ltp":1.88,"id":51922}],"tv":154482.89}],"ArrivalTime":1710508138724}
{"op":"mcm","id":2,"clk":"ANxzAIGfAQCUsAE=","pt":1710508138812,"mc":[{"id":"1.226122413","rc":[{"tv":2689.94,"batb":[[2,24,7],[1,25,12.5],[0,26,7.42]],"trd":[[27,393.88]],"ltp":27,"batl":[],"id":55632148},{"batb":[[0,1.88,201.82]],"batl":[],"id":51922},{"batb":[[0,4.8,12.62]],"id":50466254}],"tv":154488.91}],"ArrivalTime":1710508138819}
{"op":"mcm","id":2,"clk":"AN9zAIufAQCbsAE=","pt":1710508138917,"mc":[{"id":"1.226122413","rc":[{"tv":21054.93,"trd":[[4.9,681.14]],"ltp":4.9,"batl":[[0,4.9,37.56]],"id":50466254}],"tv":154494.79}],"ArrivalTime":1710508138924}
{"op":"mcm","id":2,"clk":"AOlzAJefAQCfsAE=","pt":1710508139013,"mc":[{"id":"1.226122413","rc":[{"batl":[[0,5.8,7.65]],"id":41122648},{"batb":[[0,310,1.19]],"id":41200638},{"tv":2691.94,"batb":[[0,26,6.42]],"trd":[[26,491.51]],"ltp":26,"batl":[],"id":55632148},{"batb":[[2,1.87,219.32],[1,1.88,201.82],[0,1.89,25]],"id":51922}],"tv":154496.79}],"ArrivalTime":1710508139020}
{"op":"mcm","id":2,"clk":"APJzAKKfAQCssAE=","pt":1710508139120,"mc":[{"id":"1.226122413","rc":[{"batl":[[0,1.9,113.36]],"id":51922}]}],"ArrivalTime":1710508139128}
{"op":"mcm","id":2,"clk":"APxzAKyfAQC2sAE=","pt":1710508139229,"mc":[{"id":"1.226122413","rc":[{"batb":[[1,1.88,204.39]],"id":51922},{"batb":[[2,160,7.37]],"id":66251581}]}],"ArrivalTime":1710508139236}
{"op":"mcm","id":2,"clk":"AIN0ALGfAQDCsAE=","pt":1710508139335,"mc":[{"id":"1.226122413","rc":[{"batb":[[1,5.6,78.52]],"id":41122648},{"tv":111511.17,"batb":[[0,1.89,21]],"trd":[[1.89,7301.99]],"ltp":1.89,"id":51922},{"batl":[[2,40,12.57],[1,38,4.35],[0,36,3.79]],"id":106596}],"tv":154504.79}],"ArrivalTime":1710508139342}
{"op":"mcm","id":2,"clk":"AIh0ALmfAQDHsAE=","pt":1710508139432,"mc":[{"id":"1.226122413","rc":[{"tv":12111.18,"trd":[[5.8,125.8]],"batl":[[0,5.8,5.05]],"id":41122648},{"batb":[[0,4.8,28.11]],"id":50466254}],"tv":154509.99}],"ArrivalTime":1710508139442}
{"op":"mcm","id":2,"clk":"AJF0AL+fAQDOsAE=","pt":1710508139533,"mc":[{"id":"1.226122413","rc":[{"tv":12112.8,"trd":[[5.8,127.42]],"batl":[[0,5.8,4.24]],"id":41122648}],"tv":154511.61}],"ArrivalTime":1710508139541}
{"op":"mcm","id":2,"clk":"AJZ0AMKfAQDXsAE=","pt":1710508139638,"mc":[{"id":"1.226122413","rc":[{"tv":12115.16,"trd":[[5.8,129.78]],"batl":[[0,5.8,3.06]],"id":41122648},{"batb":[[2,280,7.77],[1,310,1.03],[0,320,2.16]],"id":41200638},{"batb":[[0,26,6.54]],"id":55632148},{"tv":21070.31,"batb":[[0,4.8,20.42]],"trd":[[4.8,1652.27]],"ltp":4.8,"id":50466254}],"tv":154529.35}],"ArrivalTime":1710508139645}
{"op":"mcm","id":2,"clk":"AJ50AMqfAQDisAE=","pt":1710508139740,"mc":[{"id":"1.226122413","rc":[{"tv":12121.16,"trd":[[5.8,135.78]],"batl":[[2,6.2,98.54],[1,6,74.83],[0,5.9,71.84]],"id":41122648},{"batb":[[0,180,7.68]],"id":66251581}],"tv":154535.35}],"ArrivalTime":1710508139748}
{"op":"mcm","id":2,"clk":"AKR0ANOfAQDtsAE=","pt":1710508139798,"mc":[{"id":"1.226122413","rc":[{"tv":12121.28,"trd":[[5.8,135.9]],"batl":[[0,5.9,71.78]],"id":41122648},{"batb":[],"batl":[[0,29,4.89]],"id":55632148},{"tv":111528.45,"batb":[[0,1.89,15]],"trd":[[1.9,6074.16],[1.89,7313.99]],"batl":[[0,1.9,110.72]],"id":51922},{"tv":21085.69,"batb":[[0,4.8,13.78]],"trd":[[4.8,1667.65]],"batl":[],"id":50466254}],"tv":154568.13}],"ArrivalTime":1710508139805}
{"op":"mcm","id":2,"clk":"AK50ANmfAQD4sAE=","pt":1710508139910,"mc":[{"id":"1.226122413","rc":[{"batb":[[2,5.5,72.44]],"id":41122648},{"batb":[[2,300,2.04]],"id":41200638},{"tv":111949.89,"batb":[[0,1.89,4.28]],"trd":[[1.9,6474.16],[1.89,7335.43]],"batl":[[2,1.93,206.92],[1,1.92,236.69],[0,1.91,139.16]],"id":51922},{"batb":[[0,4.8,20.85]],"batl":[[0,4.9,39.61]],"id":50466254},{"batb":[[0,180,8.68]],"id":66251581}],"tv":154989.57}],"ArrivalTime":1710508139917}
{"op":"mcm","id":2,"clk":"ALR0AOCfAQCGsQE=","pt":1710508140012,"mc":[{"id":"1.226122413","rc":[{"batb":[],"batl":[[2,6,74.83],[1,5.9,71.78],[0,5.8,10.32]],"id":41122648},{"batl":[[2,32,24.16],[0,29,7.86]],"id":55632148},{"batb":[[0,1.89,41.27]],"batl":[[2,1.93,204.11],[0,1.91,150.15]],"id":51922},{"tv":21101.06,"batb":[[0,4.8,13.16]],"trd":[[4.8,1683.02]],"id":50466254}],"tv":155004.94}],"ArrivalTime":1710508140019}
{"op":"mcm","id":2,"clk":"ALl0AOufAQCUsQE=","pt":1710508140121,"mc":[{"id":"1.226122413","rc":[{"batb":[[2,1.88,204.39],[1,1.89,75.23],[0,1.9,33.65]],"id":51922}]}],"ArrivalTime":1710508140128}
{"op":"mcm","id":2,"clk":"AL50APOfAQCasQE=","pt":1710508140228,"mc":[{"id":"1.226122413","rc":[{"batb":[[2,5.5,73.29],[1,5.6,79.37]],"batl":[[2,6,77.87],[1,5.9,72.63]],"id":41122648},{"batb":[[2,1.88,205.25]],"batl":[[2,1.93,204.96],[1,1.92,237.55]],"id":51922},{"tv":21116.44,"batb":[[2,4.6,242.49],[1,4.7,105.88],[0,4.8,5.47]],"trd":[[4.8,1698.4]],"batl":[[2,5.1,45.22],[1,5,62.94]],"id":50466254},{"batl":[[1,210,7.49]],"id":66251581}],"tv":155020.32}],"ArrivalTime":1710508140235}
{"op":"mcm","id":2,"clk":"AMN0APqfAQClsQE=","pt":1710508140341,"mc":[{"id":"1.226122413","rc":[{"tv":452.09,"batb":[[2,410,1.06],[1,460,5.47],[0,470,2.28]],"trd":[[480,3.14]],"ltp":480,"id":54370634},{"batb":[[2,5.5,75.35]],"batl":[[1,5.9,84.32]],"id":41122648},{"batl":[[0,29,4.89]],"id":55632148},{"batb":[[2,1.88,225.25],[1,1.89,108.01]],"batl":[[2,1.93,207.77],[0,1.91,160.15]],"id":51922},{"batb":[[2,46,24.7]],"id":49744721},{"batl":[[0,4.9,52.17]],"id":50466254}],"tv":155022.32}],"ArrivalTime":1710508140349}
{"op":"mcm","id":2,"clk":"AMV0AIegAQCrsQE=","pt":1710508140425,"mc":[{"id":"1.226122413","rc":[{"tv":2692.18,"batb":[[0,26,6.42]],"trd":[[27,394.12]],"ltp":27,"batl":[[2,30,7.76],[1,29,4.89],[0,27,20.48]],"id":55632148},{"tv":111953.89,"trd":[[1.91,2936.53]],"ltp":1.91,"batl":[[1,1.92,257.55],[0,1.91,158.16]],"id":51922},{"tv":21131.81,"batb":[[2,4.5,127.63],[1,4.6,242.49],[0,4.7,103.67]],"trd":[[4.7,272.7],[4.8,1709.34]],"ltp":4.7,"batl":[[0,4.9,67.08]],"id":50466254}],"tv":155041.93}],"ArrivalTime":1710508140433}
{"op":"mcm","id":2,"clk":"AMx0AI+gAQC4sQE=","pt":1710508140526,"mc":[{"id":"1.226122413","rc":[{"batl":[[2,710,2.82],[1,700,3.22],[0,660,1.02]],"id":54370634},{"batb":[[0,320,2]],"id":41200638},{"tv":111955.89,"batb":[[0,1.9,134.69]],"trd":[[1.9,6476.16]],"ltp":1.9,"id":51922},{"batl":[[2,5,62.94],[1,4.9,67.08],[0,4.8,13.56]],"id":50466254}],"tv":155043.93}],"ArrivalTime":1710508140534}
{"op":"mcm","id":2,"clk":"AOx0ALygAQD0sQE=","pt":1710508141104,"mc":[{"id":"1.226122413","rc":[{"batb":[[2,420,1.04]],"batl":[[2,750,1.71],[1,710,3.48]],"id":54370634},{"tv":12132.28,"batb":[[0,5.7,75.13],[2,5.5,73.29],[1,5.6,97.76]],"trd":[[5.7,4],[5.8,142.9]],"ltp":5.7,"batl":[[0,5.8,6.82]],"id":41122648},{"tv":544.53,"batb":[],"trd":[[400,14.5]],"ltp":400,"batl":[[0,400,4.61]],"id":41200638},{"tv":2692.58,"batb":[[0,25,9.78],[2,23,18.68],[1,24,7]],"trd":[[27,394.52]],"batl":[[2,29,4.89],[1,28,2.9],[0,27,20.28]],"id":55632148},{"tv":112213.61,"batb":[[1,1.9,193.81],[2,1.89,175.01],[0,1.91,81.09]],"trd":[[1.92,221.71],[1.9,6496.16],[1.91,3067.01]],"ltp":1.92,"batl":[[2,1.94,79.75],[0,1.92,252.68],[1,1.93,243.65]],"id":51922},{"tv":21214.07,"batb":[[0,4.7,88.29],[2,4.5,127.63]],"trd":[[4.7,303.45],[4.8,1760.85]],"ltp":4.7,"batl":[[2,5,62.94],[1,4.9,65.03],[0,4.8,3.61]],"id":50466254},{"tv":2533,"trd":[[36,19.07]],"ltp":36,"batl":[[0,36,3.59]],"id":106596}],"tv":155397.71,"con":true}],"ArrivalTime":1710508141111}
{"op":"mcm","id":2,"clk":"AO50ALygAQD1sQE=","pt":1710508141109,"mc":[{"id":"1.226122413","rc":[{"batl":[[2,6,86.62]],"id":41122648},{"tv":112214.11,"batb":[[0,1.91,80.84]],"trd":[[1.91,3067.51]],"ltp":1.91,"batl":[[0,1.92,314.8]],"id":51922},{"tv":21295.44,"batb":[[0,4.7,47.6]],"trd":[[4.7,384.82]],"id":50466254}],"tv":155479.58}],"ArrivalTime":1710508141116}
{"op":"mcm","id":2,"clk":"APp0AMSgAQD7sQE=","pt":1710508141224,"mc":[{"id":"1.226122413","rc":[{"batl":[[2,890,1],[1,750,2.37]],"id":54370634},{"batb":[[1,5.6,79.37]],"batl":[[2,6,77.87]],"id":41122648},{"tv":112458.67,"batb":[[0,1.91,80.93]],"trd":[[1.92,466.27]],"ltp":1.92,"batl":[[0,1.92,193.02]],"id":51922}],"tv":155724.14}],"ArrivalTime":1710508141231}
{"op":"mcm","id":2,"clk":"AP10ANKgAQCJsgE=","pt":1710508141325,"mc":[{"id":"1.226122413","rc":[{"batl":[[2,750,1.94],[1,680,3.24]],"id":54370634},{"tv":12143.24,"trd":[[5.8,153.86]],"ltp":5.8,"batl":[[0,5.8,1.34]],"id":41122648},{"batb":[[1,1.9,267.81]],"id":51922},{"batb":[[0,4.7,74.88]],"batl":[[0,4.8,16.4]],"id":50466254}],"tv":155735.1}],"ArrivalTime":1710508141332}
{"op":"mcm","id":2,"clk":"AIR1ANagAQCcsgE=","pt":1710508141434,"mc":[{"id":"1.226122413","rc":[{"batl":[[1,680,3.48],[0,650,2.78]],"id":54370634},{"tv":12186.25,"batb":[[0,5.7,20.87]],"trd":[[5.7,47.01]],"ltp":5.7,"batl":[],"id":41122648},{"tv":112693.94,"batb":[[0,1.91,90.78]],"trd":[[1.91,3067.81],[1.92,701.24]],"batl":[[0,1.92,75.53]],"id":51922},{"tv":21315.74,"batb":[[0,4.7,74.73]],"trd":[[4.7,385.13],[4.8,1780.84]],"ltp":4.8,"batl":[[0,4.8,6.4]],"id":50466254},{"batb":[[0,180,10.17]],"batl":[],"id":66251581}],"tv":156033.68}],"ArrivalTime":1710508141442}
{"op":"mcm","id":2,"clk":"AId1AOOgAQCosgE=","pt":1710508141540,"mc":[{"id":"1.226122413","rc":[{"batl":[[0,650,5.34]],"id":54370634},{"batl":[[2,29,5.15]],"id":55632148},{"tv":112845,"batb":[[2,1.9,267.81],[1,1.91,90.78],[0,1.92,166.96]],"trd":[[1.92,852.3]],"batl":[[2,1.95,118.15],[1,1.94,79.75],[0,1.93,243.65]],"id":51922},{"tv":21465.18,"batb":[[2,4.4,166.69],[1,4.5,127.63],[0,4.6,242.49]],"trd":[[4.7,534.57]],"ltp":4.7,"batl":[[2,4.9,65.03],[1,4.8,6.4],[0,4.7,31.66]],"id":50466254}],"tv":156334.18}],"ArrivalTime":1710508141547}
{"op":"mcm","id":2,"clk":"AI51AO6gAQCusgE=","pt":1710508141640,"mc":[{"id":"1.226122413","rc":[{"batb":[[1,460,5.78]],"id":54370634},{"tv":12189.33,"batb":[[0,5.7,13]],"trd":[[5.7,50.09]],"batl":[[0,5.8,11.37]],"id":41122648},{"tv":2693.66,"batb":[[0,25,9.24]],"trd":[[25,463.45]],"ltp":25,"batl":[[2,29,10.74]],"id":55632148},{"batb":[[2,1.9,268.67],[1,1.91,113.05],[0,1.92,205.85]],"batl":[[1,1.94,117.4]],"id":51922},{"batl":[[1,4.8,23.4]],"id":50466254}],"tv":156338.34}],"ArrivalTime":1710508141647}
{"op":"mcm","id":2,"clk":"AJx1APagAQC5sgE=","pt":1710508141745,"mc":[{"id":"1.226122413","rc":[{"tv":113168.66,"batb":[[2,1.9,223.67],[1,1.91,115.62],[0,1.92,301]],"trd":[[1.93,464.09],[1.92,856.3]],"batl":[[2,1.95,153.09],[1,1.94,114.64],[0,1.93,35.01]],"id":51922},{"tv":21510.32,"batb":[[1,4.5,124.38]],"trd":[[4.7,579.71]],"batl":[[1,4.8,38.32],[0,4.7,26.6]],"id":50466254},{"batb":[[0,34,11.23]],"batl":[[2,40,13.25]],"id":106596}],"tv":156707.14}],"ArrivalTime":1710508141753}
{"op":"mcm","id":2,"clk":"AKF1AP6gAQC/sgE=","pt":1710508141844,"mc":[{"id":"1.226122413","rc":[{"batb":[[1,5.6,59.88],[0,5.7,8.46]],"batl":[[0,5.8,23.09]],"id":41122648},{"tv":2693.67,"trd":[[27,394.53]],"ltp":27,"batl":[[0,27,20.27]],"id":55632148},{"tv":113189.51,"batb":[[2,1.9,223.92],[0,1.92,262.11]],"trd":[[1.93,484.94]],"ltp":1.93,"batl":[[0,1.93,24.58]],"id":51922},{"tv":21513.2,"batb":[[0,4.6,241.05]],"trd":[[4.6,1462.22]],"ltp":4.6,"batl":[[2,4.9,65.88],[1,4.8,40.04]],"id":50466254}],"tv":156730.88}],"ArrivalTime":1710508141851}
{"op":"mcm","id":2,"clk":"AKp1AIahAQDQsgE=","pt":1710508141971,"mc":[{"id":"1.226122413","rc":[{"tv":113238.71,"batb":[[2,1.91,115.62],[1,1.92,292.11],[0,1.93,16.25]],"trd":[[1.93,534.14]],"batl":[[2,1.96,73.86],[1,1.95,153.09],[0,1.94,95.84]],"id":51922},{"batb":[[0,4.6,219.7]],"batl":[[0,4.7,28.98]],"id":50466254}],"tv":156780.08}],"ArrivalTime":1710508141978}
{"op":"mcm","id":2,"clk":"AK51AIyhAQDVsgE=","pt":1710508142005,"mc":[{"id":"1.226122413","rc":[{"batb":[[2,5.4,48.91],[1,5.5,54.87],[0,5.6,59.99]],"id":41122648},{"tv":113240.01,"batb":[[1,1.92,390.33],[0,1.93,93.87]],"trd":[[1.93,535.44]],"batl":[[0,1.94,58.19]],"id":51922},{"tv":2534,"batb":[[0,34,10.73]],"trd":[[34,150.47]],"ltp":34,"id":106596}],"tv":156782.38}],"ArrivalTime":1710508142013}
{"op":"mcm","id":2,"clk":"ALV1AJehAQDjsgE=","pt":1710508142117,"mc":[{"id":"1.226122413","rc":[{"tv":12229.33,"batb":[],"trd":[[5.8,193.86]],"ltp":5.8,"batl":[[0,5.8,3.09]],"id":41122648},{"tv":113278.22,"batb":[[2,1.91,186.98],[1,1.92,392.9],[0,1.93,121.19]],"trd":[[1.94,87.67]],"ltp":1.94,"batl":[[2,1.96,71.18],[0,1.94,39.08]],"id":51922}],"tv":156860.59}],"ArrivalTime":1710508142125}
{"op":"mcm","id":2,"clk":"AMF1AKOhAQDrsgE=","pt":1710508142214,"mc":[{"id":"1.226122413","rc":[{"batb":[[2,5.4,69.28]],"batl":[[2,5.9,84.32],[1,5.8,3.09],[0,5.7,9.41]],"id":41122648},{"tv":113358.09,"batb":[[2,1.92,392.9],[1,1.93,217.86],[0,1.94,4.12]],"trd":[[1.93,537.15],[1.94,165.83]],"batl":[[2,1.97,75.04],[1,1.96,71.18],[0,1.95,153.09]],"id":51922},{"batl":[[0,36,5.59]],"id":106596}],"tv":156940.46}],"ArrivalTime":1710508142221}
{"op":"mcm","id":2,"clk":"AM51AKyhAQD4sgE=","pt":1710508142327,"mc":[{"id":"1.226122413","rc":[{"batb":[],"batl":[[1,5.8,12.07]],"id":41122648},{"batb":[[0,1.94,31.62]],"batl":[[1,1.96,108.9]],"id":51922},{"batb":[],"batl":[[0,4.7,42]],"id":50466254}]}],"ArrivalTime":1710508142334}
{"op":"mcm","id":2,"clk":"ANl1ALGhAQD+sgE=","pt":1710508142425,"mc":[{"id":"1.226122413","rc":[{"batl":[[0,650,3.34]],"id":54370634},{"tv":113545.39,"batb":[[2,1.92,393.75],[1,1.93,223.59]],"trd":[[1.95,261.94]],"ltp":1.95,"batl":[[0,1.95,59.44]],"id":51922}],"tv":157127.76}],"ArrivalTime":1710508142433}
{"op":"mcm","id":2,"clk":"AOB1ALihAQCGswE=","pt":1710508142532,"mc":[{"id":"1.226122413","rc":[{"batl":[[2,680,3.48],[1,650,2.56],[0,630,3.6]],"id":54370634},{"tv":12240.35,"trd":[[5.7,61.11]],"ltp":5.7,"batl":[[0,5.7,3.9]],"id":41122648},{"batb":[[1,310,1.09]],"id":41200638},{"batb":[[1,1.93,226.16]],"id":51922},{"batl":[[0,55,14.56]],"id":49744721},{"batl":[[2,4.9,55.88]],"id":50466254}],"tv":157138.78}],"ArrivalTime":1710508142539}
{"op":"mcm","id":2,"clk":"AOt1AL6hAQCXswE=","pt":1710508142638,"mc":[{"id":"1.226122413","rc":[{"batb":[[0,5.6,49.09]],"batl":[[2,6,75.68],[1,5.9,86.55],[0,5.8,14.64]],"id":41122648},{"batl":[[2,28,2.9],[1,27,20.27],[0,26,1]],"id":55632148},{"batb":[[1,1.93,232.99],[0,1.94,67.11]],"batl":[[0,1.95,64.52]],"id":51922},{"tv":21533.2,"batb":[[0,4.6,196.64]],"trd":[[4.6,1482.22]],"batl":[],"id":50466254},{"batl":[[1,210,5.96]],"id":66251581},{"batb":[[1,32,16.15]],"id":106596}],"tv":157158.78}],"ArrivalTime":1710508142645}
{"op":"mcm","id":2,"clk":"AO91AMyhAQCgswE=","pt":1710508142743,"mc":[{"id":"1.226122413","rc":[{"tv":453.67,"batb":[[0,470,1.49]],"trd":[[480,4.46],[470,4.26]],"ltp":470,"id":54370634},{"batb":[[2,5.5,54.87],[1,5.6,49.09],[0,5.7,14.37]],"id":41122648},{"tv":113549.39,"batb":[],"trd":[[1.95,265.94]],"batl":[[0,1.95,62.52]],"id":51922}],"tv":157164.36}],"ArrivalTime":1710508142750}
{"op":"mcm","id":2,"clk":"APl1ANShAQCtswE=","pt":1710508142849,"mc":[{"id":"1.226122413","rc":[{"batb":[[1,5.6,61.53]],"id":41122648},{"batb":[[0,1.94,72.83]],"batl":[[0,1.95,41.47]],"id":51922},{"tv":2974.44,"batb":[[0,50,63.59]],"trd":[[55,18.5]],"ltp":55,"batl":[[0,55,14.06]],"id":49744721},{"tv":21552.28,"batb":[[2,4.4,163.27],[0,4.6,146.21]],"trd":[[4.6,1501.3]],"batl":[[0,4.7,57.11]],"id":50466254},{"batb":[[0,180,10.22]],"id":66251581}],"tv":157184.44}],"ArrivalTime":1710508142856}
{"op":"mcm","id":2,"clk":"AIJ2ANihAQC4swE=","pt":1710508142950,"mc":[{"id":"1.226122413","rc":[{"batb":[[2,5.4,88.27],[1,5.5,54.87],[0,5.6,61.53]],"id":41122648},{"tv":2695.73,"batb":[[0,25,8.21]],"trd":[[25,465.51]],"ltp":25,"id":55632148},{"batb":[],"batl":[[1,1.96,111.58]],"id":51922},{"batl":[[1,4.8,45.04]],"id":50466254},{"batl":[[1,210,7.49]],"id":66251581}],"tv":157186.5}],"ArrivalTime":1710508142957}
{"op":"mcm","id":2,"clk":"AIt2ANyhAQC9swE=","pt":1710508143047,"mc":[{"id":"1.226122413","rc":[{"tv":455.23,"batb":[[2,380,2.14],[1,420,1.04],[0,460,6.49]],"trd":[[470,5.82]],"id":54370634},{"tv":113553.39,"batb":[[1,1.93,257.99],[0,1.94,70.83]],"trd":[[1.94,169.83]],"ltp":1.94,"id":51922},{"tv":21555.72,"batb":[[2,4.4,170.95],[0,4.6,144.49]],"trd":[[4.6,1504.74]],"id":50466254}],"tv":157195.5}],"ArrivalTime":1710508143054}
{"op":"mcm","id":2,"clk":"AJN2AOWhAQDKswE=","pt":1710508143105,"mc":[{"id":"1.226122413","rc":[{"batl":[[2,750,1.94],[1,680,3.48]],"id":54370634},{"tv":2697.13,"batb":[[0,25,7.51]],"trd":[[25,466.91]],"id":55632148},{"tv":113761.95,"batb":[[0,1.94,8.02]],"trd":[[1.95,348.88],[1.94,295.45]],"batl":[[2,1.98,141.65],[1,1.97,75.04],[0,1.96,108.9]],"id":51922},{"batl":[[1,38,12.89]],"id":106596}],"tv":157405.46}],"ArrivalTime":1710508143112}
{"op":"mcm","id":2,"clk":"AJx2AO2hAQDUswE=","pt":1710508143215,"mc":[{"id":"1.226122413","rc":[{"batb":[[2,380,3.17]],"id":54370634},{"tv":113762.73,"batb":[[1,1.93,258.85],[0,1.94,5.73]],"trd":[[1.95,349.66]],"ltp":1.95,"batl":[[2,1.97,72.41],[1,1.96,108.9],[0,1.95,20.66]],"id":51922}],"tv":157406.24}],"ArrivalTime":1710508143222}
{"op":"mcm","id":2,"clk":"AKF2APKhAQDgswE=","pt":1710508143313,"mc":[{"id":"1.226122413","rc":[{"batb":[[0,460,5.78]],"id":54370634},{"batb":[[0,25,9.07]],"batl":[[0,26,4]],"id":55632148},{"tv":113789.53,"batb":[[2,1.91,186.98],[1,1.92,393.75],[0,1.93,258.85]],"trd":[[1.95,365],[1.94,306.91]],"batl":[[2,1.97,75.04],[0,1.95,12.99]],"id":51922},{"batb":[[1,4.5,132.07]],"id":50466254}],"tv":157433.04}],"ArrivalTime":1710508143320}
{"op":"mcm","id":2,"clk":"AKp2APqhAQDpswE=","pt":1710508143424,"mc":[{"id":"1.226122413","rc":[{"batb":[[2,380,2.93]],"id":54370634},{"batb":[[2,1.92,393.75],[1,1.93,258.85],[0,1.94,11.45]],"batl":[[2,1.97,72.41],[0,1.95,56.86]],"id":51922},{"batb":[[1,4.5,139.75]],"batl":[],"id":50466254}]}],"ArrivalTime":1710508143431}
{"op":"mcm","id":2,"clk":"ALF2AP2hAQDrswE=","pt":1710508143515,"mc":[{"id":"1.226122413","rc":[{"batl":[[2,890,1],[1,750,2.61]],"id":54370634},{"batl":[[1,27,23.05]],"id":55632148},{"tv":113800.79,"batb":[[2,1.92,416.66]],"trd":[[1.95,376.26]],"batl":[[0,1.95,51.24]],"id":51922},{"tv":21675.72,"trd":[[4.7,693.93],[4.8,1786.62]],"ltp":4.8,"batl":[[2,5,62.94],[1,4.9,55.88],[0,4.8,40.43]],"id":50466254}],"tv":157564.3}],"ArrivalTime":1710508143522}
{"op":"mcm","id":2,"clk":"ALp2AIyiAQDzswE=","pt":1710508143628,"mc":[{"id":"1.226122413","rc":[{"tv":456.8,"batb":[[0,460,4.99]],"trd":[[460,4.28]],"ltp":460,"batl":[[2,630,2.82],[1,620,3.34],[0,480,1]],"id":54370634},{"tv":12242.35,"trd":[[5.8,195.86]],"ltp":5.8,"batl":[[0,5.8,13.64]],"id":41122648},{"tv":113825.69,"batb":[[2,1.91,208.33],[1,1.92,416.66],[0,1.93,258.85]],"trd":[[1.95,378.26],[1.94,329.81]],"batl":[[2,1.97,75.04],[1,1.96,111.58],[0,1.95,87.38]],"id":51922},{"tv":21677.72,"batb":[],"trd":[[4.8,1788.62]],"batl":[[0,4.8,39.43]],"id":50466254},{"batb":[[1,32,20.36]],"id":106596}],"tv":157594.77}],"ArrivalTime":1710508143635}
{"op":"mcm","id":2,"clk":"AMV2AJKiAQD2swE=","pt":1710508143728,"mc":[{"id":"1.226122413","rc":[{"batl":[[2,5.9,86.55],[1,5.8,13.64],[0,5.7,10]],"id":41122648},{"batb":[[0,25,6.77]],"id":55632148},{"batb":[[2,1.91,227.5]],"batl":[],"id":51922},{"batb":[[0,4.6,169.92]],"id":50466254}]}],"ArrivalTime":1710508143735}
{"op":"mcm","id":2,"clk":"AM92AJmiAQCAtAE=","pt":1710508143830,"mc":[{"id":"1.226122413","rc":[{"tv":458.8,"trd":[[480,6.46]],"ltp":480,"batl":[[2,750,2.61],[1,630,2.82],[0,620,3.34]],"id":54370634},{"batb":[[0,1.93,236.94]],"batl":[[2,1.97,72.41],[1,1.96,108.9]],"id":51922},{"batb":[[2,4.5,147.44],[1,4.6,169.92],[0,4.7,10.31]],"batl":[],"id":50466254}],"tv":157596.77}],"ArrivalTime":1710508143838}
{"op":"mcm","id":2,"clk":"AN52AKOiAQCOtAE=","pt":1710508143942,"mc":[{"id":"1.226122413","rc":[{"tv":12292.35,"batb":[[0,5.6,57.42]],"trd":[[5.6,50]],"ltp":5.6,"id":41122648},{"tv":113925.69,"trd":[[1.95,452],[1.94,356.07]],"batl":[[0,1.95,50.51]],"id":51922},{"batl":[[1,4.9,53.88]],"id":50466254}],"tv":157746.77}],"ArrivalTime":1710508143950}
{"op":"mcm","id":2,"clk":"AOd2AK2iAQCXtAE=","pt":1710508144050,"mc":[{"id":"1.226122413","rc":[{"batb":[[2,380,2.69],[1,420,1.25]],"batl":[[2,630,2.82],[1,620,2.56],[0,610,1.92]],"id":54370634},{"batb":[[1,24,6]],"id":55632148},{"batb":[[2,1.91,277.5]],"batl":[[2,1.96,111.58],[1,1.95,50.51],[0,1.94,21.36]],"id":51922},{"tv":21681.72,"batb":[[0,4.7,20.93]],"trd":[[4.7,697.93]],"ltp":4.7,"batl":[[2,5,37.94],[1,4.9,73.88]],"id":50466254},{"batb":[[1,32,16.15]],"id":106596}],"tv":157750.77}],"ArrivalTime":1710508144058}
{"op":"mcm","id":2,"clk":"APB2ALeiAQChtAE=","pt":1710508144145,"mc":[{"id":"1.226122413","rc":[{"batb":[[1,5.5,46.16]],"batl":[[0,5.7,22.11]],"id":41122648},{"tv":113963.25,"trd":[[1.94,393.63]],"ltp":1.94,"batl":[[0,1.94,2.58]],"id":51922},{"batb":[[1,4.6,180.18]],"batl":[],"id":50466254},{"batb":[[2,160,37.37]],"id":66251581}],"tv":157788.33}],"ArrivalTime":1710508144152}
{"op":"mcm","id":2,"clk":"APR2AL6iAQCmtAE=","pt":1710508144256,"mc":[{"id":"1.226122413","rc":[{"batl":[[2,620,2.56],[1,610,3.06],[0,600,2.82]],"id":54370634},{"tv":113968.41,"trd":[[1.94,398.79]],"batl":[[2,1.97,75.04],[1,1.96,111.58],[0,1.95,73.23]],"id":51922}],"tv":157793.49}],"ArrivalTime":1710508144263}
{"op":"mcm","id":2,"clk":"AP52AMWiAQCutAE=","pt":1710508144352,"mc":[{"id":"1.226122413","rc":[{"batl":[[1,610,4.2]],"id":54370634},{"batb":[[2,1.91,258.33]],"id":51922},{"batb":[[1,4.6,187.86]],"id":50466254}]}],"ArrivalTime":1710508144359}
{"op":"mcm","id":2,"clk":"AIN3AM6iAQC3tAE=","pt":1710508144414,"mc":[{"id":"1.226122413","rc":[{"batl":[[1,610,4.95]],"id":54370634},{"batb":[[1,5.5,56.16],[0,5.6,47.42]],"batl":[[0,5.7,24.11]],"id":41122648},{"batl":[[2,1.96,111.58],[1,1.95,70.51],[0,1.94,21.93]],"id":51922},{"batb":[[0,4.7,20.95]],"id":50466254}]}],"ArrivalTime":1710508144421}
{"op":"mcm","id":2,"clk":"AId3ANiiAQC8tAE=","pt":1710508144511,"mc":[{"id":"1.226122413","rc":[{"batb":[[1,420,1.57],[0,460,5.31]],"id":54370634},{"batb":[[2,5.4,89.64]],"id":41122648},{"batl":[[0,400,4.84]],"id":41200638},{"batl":[[1,1.95,73.23]],"id":51922},{"batb":[[0,4.7,28.64]],"batl":[],"id":50466254}]}],"ArrivalTime":1710508144518}
{"op":"mcm","id":2,"clk":"AIx3AOCiAQDHtAE=","pt":1710508144617,"mc":[{"id":"1.226122413","rc":[{"batb":[[1,420,1.17],[0,440,1.02]],"batl":[[2,630,2.82]],"id":54370634},{"batb":[[0,5.6,36.87]],"id":41122648},{"tv":544.99,"trd":[[390,3.66]],"ltp":390,"batl":[[0,400,4.61]],"id":41200638},{"tv":113972.41,"batb":[[0,1.93,234.94]],"trd":[[1.93,541.15]],"ltp":1.93,"id":51922},{"batb":[[0,4.7,36.32]],"id":50466254}],"tv":157797.95}],"ArrivalTime":1710508144625}
{"op":"mcm","id":2,"clk":"AJJ3AO6iAQDQtAE=","pt":1710508144714,"mc":[{"id":"1.226122413","rc":[{"batl":[[1,5.8,21.49]],"id":41122648}]}],"ArrivalTime":1710508144722}
{"op":"mcm","id":2,"clk":"AJd3APaiAQDctAE=","pt":1710508144829,"mc":[{"id":"1.226122413","rc":[{"batb":[[2,340,1.09],[1,380,2.69],[0,420,1.58]],"id":54370634},{"batl":[[2,5.9,84.32]],"id":41122648},{"tv":114072.41,"batb":[[1,1.92,324.17],[0,1.93,184.94]],"trd":[[1.93,641.15]],"id":51922}],"tv":157897.95}],"ArrivalTime":1710508144836}
{"op":"mcm","id":2,"clk":"AKN3AP6iAQDjtAE=","pt":1710508144915,"mc":[{"id":"1.226122413","rc":[{"tv":460.06,"batb":[[1,380,2.47],[0,410,1.18]],"trd":[[480,7.11],[460,4.89]],"ltp":460,"batl":[[0,600,2.98]],"id":54370634},{"tv":114257.39,"batb":[],"trd":[[1.95,593.12],[1.94,442.65]],"ltp":1.95,"batl":[[2,1.97,75.04],[1,1.96,111.58],[0,1.95,2.67]],"id":51922},{"batb":[[0,4.7,49.16]],"id":50466254}],"tv":158084.19}],"ArrivalTime":1710508144922}
{"op":"mcm","id":2,"clk":"AKp3AIajAQD4tAE=","pt":1710508145028,"mc":[{"id":"1.226122413","rc":[{"batl":[[2,750,2.61]],"id":54370634},{"tv":12350.36,"batb":[[0,5.6,7.86]],"trd":[[5.6,108.01]],"batl":[[2,5.9,86.55]],"id":41122648},{"tv":114262.73,"batb":[],"trd":[[1.95,598.46]],"batl":[[0,1.95,2.57]],"id":51922}],"tv":158147.54}],"ArrivalTime":1710508145036}
{"op":"mcm","id":2,"clk":"ALR3AI6jAQD7tAE=","pt":1710508145129,"mc":[{"id":"1.226122413","rc":[{"tv":460.38,"batb":[[1,380,1.94],[0,400,1.13]],"trd":[[440,10.72]],"ltp":440,"batl":[[0,600,2.82]],"id":54370634},{"tv":114282.73,"batb":[[2,1.92,324.17],[1,1.93,184.94],[0,1.94,142.24]],"trd":[[1.94,462.65]],"ltp":1.94,"id":51922}],"tv":158167.86}],"ArrivalTime":1710508145136}
{"op":"mcm","id":2,"clk":"ALd3AJajAQCItQE=","pt":1710508145234,"mc":[{"id":"1.226122413","rc":[{"batb":[[1,380,2.18]],"batl":[[2,660,1.02],[1,600,2.82],[0,590,2.56]],"id":54370634},{"batb":[[2,5.3,70.02],[1,5.4,89.64],[0,5.5,64.17]],"batl":[[1,5.8,22.34],[0,5.7,35.78]],"id":41122648},{"batb":[[1,1.93,206.98]],"batl":[[0,1.95,29.54]],"id":51922},{"batl":[[1,210,5.96]],"id":66251581}]}],"ArrivalTime":1710508145241}
{"op":"mcm","id":2,"clk":"AMV3AJ6jAQCWtQE=","pt":1710508145345,"mc":[{"id":"1.226122413","rc":[{"batb":[[1,370,1.05],[0,380,4.05]],"id":54370634},{"batl":[[0,5.7,37.48]],"id":41122648},{"tv":114315.63,"batb":[[2,1.92,334.27],[0,1.94,137.24]],"trd":[[1.95,621.36],[1.94,472.65]],"ltp":1.95,"batl":[[1,1.96,108.9],[0,1.95,18.09]],"id":51922},{"batl":[[1,38,13.65]],"id":106596}],"tv":158200.76}],"ArrivalTime":1710508145352}
{"op":"mcm","id":2,"clk":"AMZ3AKSjAQCftQE=","pt":1710508145443,"mc":[{"id":"1.226122413","rc":[{"batl":[[0,590,3.74]],"id":54370634},{"tv":12350.53,"batb":[],"trd":[[5.7,61.28]],"ltp":5.7,"batl":[[0,5.7,37.39]],"id":41122648},{"tv":114316.03,"batb":[[0,1.94,207.04]],"trd":[[1.94,473.05]],"ltp":1.94,"batl":[[2,1.97,72.41]],"id":51922},{"batl":[[1,210,7.49]],"id":66251581}],"tv":158201.33}],"ArrivalTime":1710508145450}
{"op":"mcm","id":2,"clk":"AM13ALCjAQCntQE=","pt":1710508145541,"mc":[{"id":"1.226122413","rc":[{"batl":[[0,590,4.92]],"id":54370634},{"batb":[[1,5.4,91.02]],"id":41122648},{"tv":114322.19,"trd":[[1.95,627.52]],"ltp":1.95,"batl":[[0,1.95,15.01]],"id":51922}],"tv":158207.49}],"ArrivalTime":1710508145548}
{"op":"mcm","id":2,"clk":"ANh3ALSjAQC0tQE=","pt":1710508145649,"mc":[{"id":"1.226122413","rc":[{"batl":[[0,590,6.1]],"id":54370634},{"batb":[[1,5.4,106.23]],"id":41122648}]}],"ArrivalTime":1710508145656}
{"op":"mcm","id":2,"clk":"ANl3ALujAQC7tQE=","pt":1710508145751,"mc":[{"id":"1.226122413","rc":[{"batl":[[0,590,6.27]],"id":54370634},{"tv":12350.65,"batb":[[1,5.4,85.87]],"trd":[[5.7,61.4]],"batl":[[0,5.7,37.33]],"id":41122648}],"tv":158207.61}],"ArrivalTime":1710508145758}
{"op":"mcm","id":2,"clk":"AON3AMWjAQDKtQE=","pt":1710508145856,"mc":[{"id":"1.226122413","rc":[{"batl":[[0,590,7.81]],"id":54370634},{"batb":[[2,23,14.41]],"id":55632148},{"tv":114352.21,"trd":[[1.95,657.54]],"batl":[[2,1.98,144.23],[1,1.97,72.41],[0,1.96,108.9]],"id":51922}],"tv":158237.63}],"ArrivalTime":1710508145863}
{"op":"mcm","id":2,"clk":"AOd3AM2jAQDQtQE=","pt":1710508145908,"mc":[{"id":"1.226122413","rc":[{"batb":[[2,370,1.05],[1,380,3.21],[0,390,1.84]],"batl":[],"id":54370634},{"batb":[[1,5.4,84.49]],"id":41122648}]}],"ArrivalTime":1710508145915}
{"op":"mcm","id":2,"clk":"AO93ANajAQDVtQE=","pt":1710508146013,"mc":[{"id":"1.226122413","rc":[{"batb":[[0,390,1.91]],"batl":[[0,590,3.34]],"id":54370634},{"batb":[[2,5.3,90.61],[0,5.5,54.3]],"id":41122648},{"batb":[[2,1.93,206.98],[1,1.94,282.04],[0,1.95,37.69]],"batl":[[2,1.98,141.64]],"id":51922},{"batb":[[1,32,24.57]],"id":106596}]}],"ArrivalTime":1710508146020}
{"op":"mcm","id":2,"clk":"APl3AOGjAQDgtQE=","pt":1710508146115,"mc":[{"id":"1.226122413","rc":[{"batl":[[2,5.8,22.34],[1,5.7,37.33],[0,5.6,11.22]],"id":41122648},{"tv":114380.23,"batb":[[1,1.94,284.61],[0,1.95,35.69]],"trd":[[1.95,661.54],[1.96,187.27]],"ltp":1.96,"batl":[[0,1.96,96.89]],"id":51922},{"batb":[],"batl":[[0,4.8,40.08]],"id":50466254}],"tv":158265.65}],"ArrivalTime":1710508146122}
{"op":"mcm","id":2,"clk":"AIF4AOqjAQDqtQE=","pt":1710508146227,"mc":[{"id":"1.226122413","rc":[{"batb":[[2,5.3,92.86]],"id":41122648},{"tv":114451.61,"batb":[[2,1.92,288.27],[1,1.93,206.98],[0,1.94,284.61]],"trd":[[1.95,732.92]],"ltp":1.95,"batl":[[1,1.97,109.86]],"id":51922}],"tv":158337.03}],"ArrivalTime":1710508146234}
{"op":"mcm","id":2,"clk":"AIR4APqjAQD4tQE=","pt":1710508146323,"mc":[{"id":"1.226122413","rc":[{"tv":12448.05,"batb":[[0,5.5,5.6]],"trd":[[5.5,97.4]],"ltp":5.5,"id":41122648},{"batb":[[0,1.94,307.23]],"batl":[],"id":51922}],"tv":158434.43}],"ArrivalTime":1710508146330}
{"op":"mcm","id":2,"clk":"AIx4AIWkAQCAtgE=","pt":1710508146436,"mc":[{"id":"1.226122413","rc":[{"batl":[[2,600,2.82],[1,590,2.56],[0,580,1.78]],"id":54370634},{"tv":12459.25,"batb":[[2,5.2,45.69],[1,5.3,92.86],[0,5.4,90.19]],"trd":[[5.5,108.6]],"batl":[[1,5.7,45.17]],"id":41122648},{"batb":[[2,280,7.66],[1,300,2.04],[0,310,3.11]],"id":41200638},{"batb":[[2,1.93,206.98],[1,1.94,307.23],[0,1.95,85.4]],"id":51922},{"tv":21752.96,"batb":[[1,4.6,189.91]],"trd":[[4.8,1859.86]],"ltp":4.8,"batl":[[0,4.8,4.46]],"id":50466254}],"tv":158516.87}],"ArrivalTime":1710508146443}
{"op":"mcm","id":2,"clk":"AJF4AJOkAQCHtgE=","pt":1710508146537,"mc":[{"id":"1.226122413","rc":[{"batb":[[2,340,1.09],[1,370,1.05],[0,380,3.59]],"batl":[[2,590,2.56],[1,580,1],[0,560,1.11]],"id":54370634},{"tv":12568.91,"batb":[[0,5.4,100.19]],"trd":[[5.7,138.96],[5.5,118.26],[5.6,130.45]],"ltp":5.7,"batl":[[1,5.7,7.25],[0,5.6,11.45]],"id":41122648},{"tv":21824.18,"batb":[[2,4.6,189.91],[1,4.7,49.16],[0,4.8,10.37]],"trd":[[4.9,743.44],[4.8,1868.78]],"ltp":4.9,"batl":[[2,5.1,45.22],[1,5,37.94],[0,4.9,42.73]],"id":50466254}],"tv":158697.75}],"ArrivalTime":1710508146544}
{"op":"mcm","id":2,"clk":"AJZ4AJykAQCOtgE=","pt":1710508146647,"mc":[{"id":"1.226122413","rc":[{"batb":[[2,5.2,83.52],[1,5.3,106.06],[0,5.4,79.28]],"batl":[[2,5.7,7.25],[1,5.6,11.45],[0,5.5,14.89]],"id":41122648},{"tv":114519.69,"batb":[[0,1.95,51.36]],"trd":[[1.95,801]],"batl":[[0,1.96,59.17]],"id":51922},{"tv":21844.92,"batb":[[2,4.5,150.69],[1,4.6,189.91],[0,4.7,63.43]],"trd":[[4.8,1889.52]],"ltp":4.8,"batl":[[2,5,37.94],[1,4.9,42.73],[0,4.8,2.41]],"id":50466254}],"tv":158786.57}],"ArrivalTime":1710508146655}
{"op":"mcm","id":2,"clk":"AJ14AKqkAQCatgE=","pt":1710508146753,"mc":[{"id":"1.226122413","rc":[{"batb":[[2,360,1.48],[0,380,2.56]],"id":54370634},{"tv":12572.27,"batb":[[2,5.2,81.18],[0,5.4,58.91]],"trd":[[5.5,121.62]],"ltp":5.5,"batl":[[1,5.6,26.09],[0,5.5,13.21]],"id":41122648},{"batb":[[1,24,9],[0,25,3.77]],"id":55632148},{"tv":114622.41,"batb":[[2,1.92,309.62],[1,1.93,206.98],[0,1.94,284.61]],"trd":[[1.95,903.72]],"batl":[],"id":51922},{"tv":21906.98,"batb":[[2,4.6,189.91],[1,4.7,63.43],[0,4.8,12.61]],"trd":[[4.8,1951.58]],"batl":[[2,5.1,45.22],[1,5,37.94],[0,4.9,60.61]],"id":50466254},{"batl":[[0,200,9.16]],"id":66251581}],"tv":158954.71}],"ArrivalTime":1710508146760}
{"op":"mcm","id":2,"clk":"AJ94ALCkAQCmtgE=","pt":1710508146846,"mc":[{"id":"1.226122413","rc":[{"tv":12598.69,"batb":[[2,5.3,108.31],[1,5.4,74.09],[0,5.5,23.99]],"trd":[[5.5,148.04]],"batl":[[2,5.8,22.34],[1,5.7,9.82],[0,5.6,26.09]],"id":41122648},{"batl":[[0,1.96,96.79]],"id":51922},{"tv":2974.64,"batb":[[0,50,63.49]],"trd":[[50,70.5]],"ltp":50,"id":49744721},{"batb":[[0,4.8,26.91]],"batl":[],"id":50466254}],"tv":158981.33}],"ArrivalTime":1710508146853}
{"op":"mcm","id":2,"clk":"AKl4AL+kAQCvtgE=","pt":1710508146962,"mc":[{"id":"1.226122413","rc":[{"batb":[[0,380,3.59]],"batl":[[1,580,3.82],[0,560,1.82]],"id":54370634},{"batb":[[0,4.8,43.14]],"batl":[],"id":50466254}]}],"ArrivalTime":1710508146969}
{"op":"mcm","id":2,"clk":"AKp4AMikAQC5tgE=","pt":1710508147046,"mc":[{"id":"1.226122413","rc":[{"batb":[[2,370,1.05],[1,380,3.21],[0,400,2.38]],"id":54370634},{"batb":[[2,5.3,106.06],[0,5.5,38.86]],"batl":[[1,5.7,21.11],[0,5.6,14.64]],"id":41122648},{"batb":[[1,1.93,200.14]],"batl":[[2,1.97,109.86],[1,1.96,96.79],[0,1.95,22.15]],"id":51922}]}],"ArrivalTime":1710508147053}
{"op":"mcm","id":2,"clk":"ALR4ANOkAQDBtgE=","pt":1710508147158,"mc":[{"id":"1.226122413","rc":[{"batb":[[1,5.4,63.8]],"batl":[[1,5.7,21.22]],"id":41122648},{"batl":[[0,1.95,23.15]],"id":51922}]}],"ArrivalTime":1710508147165}
{"op":"mcm","id":2,"clk":"ALt4AN2kAQDNtgE=","pt":1710508147249,"mc":[{"id":"1.226122413","rc":[{"batl":[[2,600,2.82]],"id":54370634},{"tv":12601.83,"batb":[[2,5.3,108.31],[0,5.5,37.29]],"trd":[[5.5,151.18]],"id":41122648},{"tv":545.45,"trd":[[320,15.29]],"ltp":320,"batl":[[0,400,5.38]],"id":41200638},{"batb":[[2,1.92,333.62],[0,1.94,209.61]],"batl":[],"id":51922},{"batb":[[0,4.8,50.83]],"id":50466254}],"tv":158984.93}],"ArrivalTime":1710508147256}
{"op":"mcm","id":2,"clk":"AL94AOOkAQDTtgE=","pt":1710508147309,"mc":[{"id":"1.226122413","rc":[{"batb":[[2,4.6,150.73]],"id":50466254},{"batb":[[1,32,18.26]],"id":106596}]}],"ArrivalTime":1710508147316}
{"op":"mcm","id":2,"clk":"AMR4APGkAQDbtgE=","pt":1710508147415,"mc":[{"id":"1.226122413","rc":[{"tv":546.99,"batb":[[0,310,3.59]],"trd":[[320,16.83]],"batl":[[0,400,1]],"id":41200638},{"tv":114636.07,"batb":[[1,1.93,218.97]],"trd":[[1.95,917.38]],"batl":[[0,1.95,16.32]],"id":51922},{"batb":[[0,4.8,76.66]],"id":50466254},{"batb":[[1,32,16.15]],"id":106596}],"tv":159000.13}],"ArrivalTime":1710508147422}
{"op":"mcm","id":2,"clk":"AMx4APekAQDntgE=","pt":1710508147529,"mc":[{"id":"1.226122413","rc":[{"batb":[[1,5.4,65.95]],"id":41122648},{"batb":[[2,1.92,168.66]],"batl":[],"id":51922},{"batb":[[2,4.6,153.82]],"id":50466254}]}],"ArrivalTime":1710508147536}
{"op":"mcm","id":2,"clk":"ANJ4AIKlAQDztgE=","pt":1710508147641,"mc":[{"id":"1.226122413","rc":[{"batl":[[2,580,3.82],[1,560,1.45],[0,520,1.05]],"id":54370634},{"tv":12625.09,"batb":[[0,5.5,25.66]],"trd":[[5.5,174.44]],"id":41122648},{"batl":[[2,480,3.17],[1,450,1.71],[0,420,2]],"id":41200638},{"batb":[[1,1.93,381.51]],"id":51922},{"tv":21908.98,"batb":[[0,4.8,83.35]],"trd":[[4.8,1953.58]],"id":50466254},{"batl":[[1,210,5.96]],"id":66251581},{"batb":[[0,34,8.28]],"id":106596}],"tv":159025.39}],"ArrivalTime":1710508147648}
{"op":"mcm","id":2,"clk":"ANd4AI2lAQCCtwE=","pt":1710508147736,"mc":[{"id":"1.226122413","rc":[{"batl":[[2,560,1.11],[1,550,2.9]],"id":54370634},{"batl":[[2,5.8,24.61]],"id":41122648},{"batl":[[2,450,1.71],[1,420,2],[0,410,1]],"id":41200638},{"batb":[[1,1.93,218.97]],"id":51922}]}],"ArrivalTime":1710508147743}
{"op":"mcm","id":2,"clk":"ANh4AJalAQCFtwE=","pt":1710508147827,"mc":[{"id":"1.226122413","rc":[{"tv":12646.75,"batb":[[2,5.2,104.36],[1,5.3,108.31],[0,5.4,65.91]],"trd":[[5.4,0.08],[5.5,196.02]],"ltp":5.4,"batl":[[0,5.6,25.93]],"id":41122648},{"tv":21909.21,"batb":[[0,4.8,83.24]],"trd":[[4.8,1953.81]],"id":50466254},{"batl":[[1,210,7.49]],"id":66251581},{"batl":[[0,36,7.84]],"id":106596}],"tv":159047.28}],"ArrivalTime":1710508147835}
{"op":"mcm","id":2,"clk":"AON4AKKlAQCOtwE=","pt":1710508147931,"mc":[{"id":"1.226122413","rc":[{"tv":115063.06,"batb":[[1,1.93,215.08],[0,1.94,2]],"trd":[[1.93,648.92],[1.94,892.27]],"ltp":1.93,"id":51922}],"tv":159474.27}],"ArrivalTime":1710508147941}
{"op":"mcm","id":2,"clk":"AOl4AKqlAQCUtwE=","pt":1710508148046,"mc":[{"id":"1.226122413","rc":[{"batb":[[0,5.4,63.76]],"batl":[[0,5.6,37.15]],"id":41122648},{"tv":115083.74,"batb":[],"trd":[[1.95,938.06]],"ltp":1.95,"batl":[[0,1.95,5.98]],"id":51922},{"tv":21917.21,"batb":[[0,4.8,79.24]],"trd":[[4.8,1961.81]],"id":50466254},{"tv":2534.44,"batb":[[0,34,8.06]],"trd":[[34,150.91]],"id":106596}],"tv":159503.39}],"ArrivalTime":1710508148053}
{"op":"mcm","id":2,"clk":"AO94ALOlAQCatwE=","pt":1710508148142,"mc":[{"id":"1.226122413","rc":[{"tv":461.8,"trd":[[510,1.42]],"ltp":510,"batl":[[2,580,3.82],[1,560,1.11],[0,550,3.24]],"id":54370634},{"batb":[[1,5.3,106.06],[0,5.4,75.02]],"batl":[[2,5.8,16.77],[1,5.7,14.83]],"id":41122648},{"tv":115087.95,"batb":[[2,1.91,258.33],[1,1.92,168.66],[0,1.93,192.94]],"trd":[[1.93,649.13],[1.94,896.27]],"ltp":1.93,"batl":[[2,1.96,96.79],[1,1.95,79.21],[0,1.94,83.01]],"id":51922}],"tv":159509.02}],"ArrivalTime":1710508148149}
{"op":"mcm","id":2,"clk":"APF4ALqlAQCgtwE=","pt":1710508148254,"mc":[{"id":"1.226122413","rc":[{"tv":464.2,"batb":[[2,370,1.29]],"trd":[[550,1.04],[540,0.68],[520,2.68]],"ltp":550,"batl":[[2,580,2.82],[0,550,2.04]],"id":54370634},{"tv":12650.75,"trd":[[5.6,134.45]],"ltp":5.6,"batl":[[0,5.6,35.15]],"id":41122648},{"batb":[[1,1.92,147.31]],"batl":[[1,1.95,96.22]],"id":51922},{"batb":[[1,4.7,66.37],[0,4.8,91.24]],"id":50466254}],"tv":159515.42}],"ArrivalTime":1710508148261}
{"op":"mcm","id":2,"clk":"APh4AMGlAQCrtwE=","pt":1710508148354,"mc":[{"id":"1.226122413","rc":[{"batl":[[2,560,1.11],[1,550,2.04],[0,540,1]],"id":54370634},{"batb":[[2,5.2,102.02]],"batl":[[0,5.6,23.93]],"id":41122648},{"batb":[[0,25,7.4]],"id":55632148},{"tv":115187.95,"batb":[[0,1.93,115.62]],"trd":[[1.93,749.13]],"id":51922}],"tv":159615.42}],"ArrivalTime":1710508148361}
{"op":"mcm","id":2,"clk":"AP14AMqlAQC0twE=","pt":1710508148408,"mc":[{"id":"1.226122413","rc":[{"batb":[[2,5.2,104.36],[1,5.3,108.31]],"id":41122648},{"batl":[[0,26,8.44]],"id":55632148},{"tv":115189.95,"batb":[[0,1.93,114.62]],"trd":[[1.93,751.13]],"id":51922}],"tv":159617.42}],"ArrivalTime":1710508148415}
{"op":"mcm","id":2,"clk":"AIN5ANalAQC4twE=","pt":1710508148511,"mc":[{"id":"1.226122413","rc":[{"batb":[[1,380,3.52]],"batl":[],"id":54370634},{"batb":[[2,5.3,108.31],[1,5.4,75.02],[0,5.5,11.83]],"id":41122648},{"batl":[[1,420,2.3]],"id":41200638},{"batb":[[1,32,20.36]],"id":106596}]}],"ArrivalTime":1710508148518}
{"op":"mcm","id":2,"clk":"AJB5AN+lAQDGtwE=","pt":1710508148628,"mc":[{"id":"1.226122413","rc":[{"batl":[[0,540,1.78]],"id":54370634},{"tv":12695.67,"batb":[[2,5.2,104.36],[1,5.3,108.35],[0,5.4,77.17]],"trd":[[5.5,240.94]],"ltp":5.5,"batl":[[2,5.7,14.83],[1,5.6,23.93],[0,5.5,18.7]],"id":41122648},{"batl":[[1,38,12.89]],"id":106596}],"tv":159662.34}],"ArrivalTime":1710508148635}
{"op":"mcm","id":2,"clk":"AKh5AO6lAQDotwE=","pt":1710508149020,"mc":[{"id":"1.226122413","rc":[{"batl":[[1,5.6,35.55]],"id":41122648},{"tv":115607.95,"batb":[[2,1.9,342.97],[1,1.91,258.33],[0,1.92,61.93]],"trd":[[1.93,980.37],[1.94,914.27],[1.92,1027.06]],"ltp":1.94,"batl":[[0,1.94,74.01]],"id":51922},{"batb":[[2,4.6,138.45],[1,4.7,51],[0,4.8,68.18]],"batl":[[0,4.9,42.73]],"id":50466254},{"batl":[[0,36,5.59],[1,38,13.65]],"id":106596}],"tv":160080.34,"con":true}],"ArrivalTime":1710508149027}
{"op":"mcm","id":2,"clk":"AK55AP+lAQDttwE=","pt":1710508149035,"mc":[{"id":"1.226122413","rc":[{"tv":12721.01,"trd":[[5.5,266.28]],"batl":[[0,5.5,6.03]],"id":41122648},{"batl":[[0,4.9,27.82]],"id":50466254}],"tv":160105.68}],"ArrivalTime":1710508149042}
{"op":"mcm","id":2,"clk":"ALR5AIimAQD9twE=","pt":1710508149139,"mc":[{"id":"1.226122413","rc":[{"tv":12749.6,"trd":[[5.5,289.87],[5.6,139.45]],"ltp":5.6,"batl":[[2,5.8,16.77],[1,5.7,14.83],[0,5.6,21.76]],"id":41122648},{"batb":[[1,1.91,208.33],[0,1.92,84.05]],"batl":[[2,1.95,96.22],[1,1.94,95.9],[0,1.93,41.54]],"id":51922},{"tv":22081.43,"batb":[[2,4.5,127.63],[1,4.6,138.45],[0,4.7,51]],"trd":[[4.8,2126.03]],"batl":[[2,5,37.94],[1,4.9,20.85],[0,4.8,167.89]],"id":50466254},{"tv":642.61,"trd":[[200,28.26]],"ltp":200,"batl":[[0,200,8.91]],"id":66251581},{"batb":[[0,34,10.46]],"batl":[[1,38,12.89]],"id":106596}],"tv":160298.99}],"ArrivalTime":1710508149146}
{"op":"mcm","id":2,"clk":"ALp5AJKmAQCEuAE=","pt":1710508149241,"mc":[{"id":"1.226122413","rc":[{"batb":[[0,400,3.1]],"id":54370634},{"batb":[[2,5.3,108.35],[1,5.4,77.17],[0,5.5,1.51]],"id":41122648},{"batb":[[0,310,3.89]],"id":41200638},{"tv":115707.95,"trd":[[1.93,1063.45],[1.94,931.19]],"batl":[[2,1.96,96.79],[1,1.95,96.22],[0,1.94,125.03]],"id":51922}],"tv":160398.99}],"ArrivalTime":1710508149248}
{"op":"mcm","id":2,"clk":"AL55AJimAQCNuAE=","pt":1710508149354,"mc":[{"id":"1.226122413","rc":[{"batb":[[2,380,3.52],[1,390,1.63]],"id":54370634},{"tv":12780.65,"batb":[[2,5.3,118.35],[1,5.4,75.02],[0,5.5,15.17]],"trd":[[5.5,313.86],[5.6,146.51]],"ltp":5.5,"batl":[[0,5.6,6.61]],"id":41122648},{"batb":[[0,310,3.41]],"batl":[[0,410,1.23]],"id":41200638},{"batb":[[0,25,10.01]],"id":55632148},{"batb":[[2,1.91,183.83],[1,1.92,123.05],[0,1.93,4.61]],"batl":[[0,1.94,181.2]],"id":51922},{"tv":22106.53,"batb":[[0,4.7,36.73]],"trd":[[4.8,2151.13]],"batl":[[1,4.9,23.43],[0,4.8,187.2]],"id":50466254},{"batb":[[1,32,22.36]],"id":106596}],"tv":160455.14}],"ArrivalTime":1710508149361}
{"op":"mcm","id":2,"clk":"AMB5AKCmAQCWuAE=","pt":1710508149453,"mc":[{"id":"1.226122413","rc":[{"batb":[[0,5.5,47]],"id":41122648},{"batb":[[0,310,3.92]],"batl":[[2,420,2.3],[1,410,1],[0,400,1.98]],"id":41200638},{"batb":[[1,24,10]],"id":55632148},{"tv":115717.17,"batb":[[2,1.9,356.36],[1,1.91,162.48],[0,1.92,123.05]],"trd":[[1.93,1072.67]],"ltp":1.93,"batl":[[2,1.95,96.22],[1,1.94,159.31],[0,1.93,15.39]],"id":51922}],"tv":160464.36}],"ArrivalTime":1710508149460}
{"op":"mcm","id":2,"clk":"AMh5AKimAQCduAE=","pt":1710508149549,"mc":[{"id":"1.226122413","rc":[{"batb":[[0,400,3.14]],"id":54370634},{"tv":12781.27,"batb":[[1,5.4,77.17],[0,5.5,49.42]],"trd":[[5.5,314.48]],"batl":[[2,5.9,49.32],[1,5.8,16.77],[0,5.7,11.39]],"id":41122648},{"tv":547.45,"batb":[[0,310,3.97]],"trd":[[400,14.96]],"ltp":400,"batl":[[0,400,3.5]],"id":41200638},{"batb":[[0,25,13.22]],"id":55632148},{"tv":115939.57,"batb":[[1,1.91,214.15],[0,1.92,129.66]],"trd":[[1.93,1103.45],[1.94,1120.41],[1.92,1029.46]],"ltp":1.92,"batl":[[1,1.94,64.7],[0,1.93,93.79]],"id":51922},{"batb":[[0,50,63.79]],"id":49744721},{"batb":[[1,4.6,135.36],[0,4.7,36.98]],"id":50466254},{"batb":[[0,180,10.3]],"id":66251581},{"batb":[[0,34,10.9]],"id":106596}],"tv":160687.84}],"ArrivalTime":1710508149556}
{"op":"mcm","id":2,"clk":"ANF5AKymAQCluAE=","pt":1710508149648,"mc":[{"id":"1.226122413","rc":[{"tv":12787.27,"batb":[[2,5.4,77.17],[1,5.5,49.42],[0,5.6,10.08]],"trd":[[5.6,152.51]],"ltp":5.6,"batl":[],"id":41122648},{"tv":549.57,"trd":[[400,17.08]],"batl":[[0,400,2.44]],"id":41200638},{"tv":116001.14,"trd":[[1.93,1165.02]],"ltp":1.93,"batl":[[1,1.94,56.17],[0,1.93,63]],"id":51922},{"batb":[[1,4.6,138.45]],"id":50466254}],"tv":160757.53}],"ArrivalTime":1710508149655}
{"op":"mcm","id":2,"clk":"ANV5ALamAQCuuAE=","pt":1710508149757,"mc":[{"id":"1.226122413","rc":[{"tv":464.22,"batb":[[0,400,3.13]],"trd":[[430,4.43]],"ltp":430,"id":54370634},{"tv":12788.3,"batb":[[2,5.4,75.02],[0,5.6,9.57]],"trd":[[5.6,153.54]],"id":41122648},{"batl":[[0,400,3.17]],"id":41200638},{"tv":116009.12,"batb":[[1,1.91,162.48]],"trd":[[1.93,1173]],"batl":[[2,1.95,136.22],[0,1.93,19.32]],"id":51922},{"batb":[[0,4.7,28.67]],"batl":[[1,4.9,36.93]],"id":50466254}],"tv":160766.56}],"ArrivalTime":1710508149764}
{"op":"mcm","id":2,"clk":"ANd5AL2mAQC8uAE=","pt":1710508149811,"mc":[{"id":"1.226122413","rc":[{"batb":[[0,5.6,45.79]],"id":41122648},{"batl":[[2,450,1.71],[1,420,2.3]],"id":41200638},{"tv":116044.48,"trd":[[1.93,1208.36]],"batl":[[0,1.93,1.64]],"id":51922},{"tv":2536.44,"batb":[[0,34,9.9]],"trd":[[34,152.91]],"id":106596}],"tv":160803.92}],"ArrivalTime":1710508149818}
{"op":"mcm","id":2,"clk":"AN95AMCmAQDIuAE=","pt":1710508149917,"mc":[{"id":"1.226122413","rc":[{"batl":[[2,420,2.3],[1,400,3.17],[0,390,1]],"id":41200638},{"tv":116250.41,"batb":[[1,1.91,167.68],[0,1.92,47.65]],"trd":[[1.93,1250.28],[1.92,1193.47]],"ltp":1.92,"batl":[[0,1.93,5.68]],"id":51922},{"batl":[[1,4.9,46.83]],"id":50466254}],"tv":161009.85}],"ArrivalTime":1710508149924}
{"op":"mcm","id":2,"clk":"AOV5AMemAQDRuAE=","pt":1710508150017,"mc":[{"id":"1.226122413","rc":[{"batl":[[1,5.8,14.5]],"id":41122648},{"tv":549.61,"batb":[[0,310,2.92]],"trd":[[340,8.12]],"ltp":340,"id":41200638},{"batb":[[1,1.91,168.55]],"batl":[[2,1.95,137.22],[0,1.93,24.51]],"id":51922}],"tv":161009.89}],"ArrivalTime":1710508150024}
{"op":"mcm","id":2,"clk":"AOp5ANOmAQDguAE=","pt":1710508150123,"mc":[{"id":"1.226122413","rc":[{"batb":[[2,300,2.04],[1,310,2.13],[0,320,1.82]],"id":41200638},{"batb":[[1,170,1.15]],"id":66251581}]}],"ArrivalTime":1710508150131}
{"op":"mcm","id":2,"clk":"AO95ANmmAQDtuAE=","pt":1710508150228,"mc":[{"id":"1.226122413","rc":[{"batl":[[2,580,2.82],[1,560,1.11]],"id":54370634},{"tv":116299.43,"trd":[[1.93,1299.3]],"ltp":1.93,"batl":[[2,1.96,96.79],[1,1.95,137.22],[0,1.94,57.73]],"id":51922},{"batl":[[1,210,5.96]],"id":66251581}],"tv":161058.91}],"ArrivalTime":1710508150235}
{"op":"mcm","id":2,"clk":"APV5AOCmAQD1uAE=","pt":1710508150335,"mc":[{"id":"1.226122413","rc":[{"batl":[[2,5.9,51.55]],"id":41122648},{"batb":[[0,1.92,104.61]],"id":51922},{"batb":[[1,4.6,135.36]],"id":50466254}]}],"ArrivalTime":1710508150342}
{"op":"mcm","id":2,"clk":"APd5AOmmAQCAuQE=","pt":1710508150434,"mc":[{"id":"1.226122413","rc":[{"batb":[[0,400,3.96]],"id":54370634},{"batb":[[0,5.6,105.42]],"batl":[[1,5.8,22.34]],"id":41122648},{"batb":[[0,320,2.85]],"id":41200638},{"batb":[[0,25,26.55]],"id":55632148},{"batb":[[0,1.92,279.01]],"batl":[[2,1.95,137.22],[1,1.94,57.73],[0,1.93,51.49]],"id":51922},{"batb":[[0,50,70.45]],"id":49744721},{"tv":22116.53,"batb":[[0,4.7,94.56]],"trd":[[4.7,707.93]],"ltp":4.7,"batl":[],"id":50466254},{"batb":[[0,180,12.14]],"id":66251581},{"batb":[[0,34,19.69]],"id":106596}],"tv":161068.91}],"ArrivalTime":1710508150441}
{"op":"mcm","id":2,"clk":"AP95AOymAQCGuQE=","pt":1710508150531,"mc":[{"id":"1.226122413","rc":[{"batb":[[0,400,4.79]],"id":54370634},{"batb":[[0,5.6,165.05]],"id":41122648},{"batb":[[0,320,3.88]],"id":41200638},{"batb":[[0,25,39.88]],"id":55632148},{"batb":[[0,1.92,453.41]],"batl":[[1,1.94,59.73]],"id":51922},{"batb":[[0,50,77.11]],"id":49744721},{"batb":[[0,4.7,165.45]],"id":50466254},{"batb":[[0,180,13.98]],"batl":[[1,210,7.49]],"id":66251581},{"batb":[[0,34,29.48]],"id":106596}]}],"ArrivalTime":1710508150538}
{"op":"mcm","id":2,"clk":"AIF6APSmAQCTuQE=","pt":1710508150637,"mc":[{"id":"1.226122413","rc":[{"batl":[[2,720,1.4],[1,580,2.82],[0,560,1.89]],"id":54370634},{"tv":12811.07,"batb":[[2,5.5,49.42],[1,5.6,165.05],[0,5.7,12.37]],"trd":[[5.7,161.73]],"ltp":5.7,"batl":[[2,6,18.17],[1,5.9,51.55],[0,5.8,22.34]],"id":41122648},{"tv":549.85,"trd":[[390,3.9]],"ltp":390,"batl":[[2,450,1.71],[1,420,2.3],[0,400,4.05]],"id":41200638},{"batb":[[0,50,78.62]],"id":49744721},{"batb":[[1,4.6,138.45],[0,4.7,184.37]],"id":50466254}],"tv":161091.92}],"ArrivalTime":1710508150644}
{"op":"mcm","id":2,"clk":"AIl6AP6mAQCZuQE=","pt":1710508150743,"mc":[{"id":"1.226122413","rc":[{"batl":[[2,570,1],[1,560,1.11],[0,530,3.34]],"id":54370634},{"tv":12835.17,"trd":[[5.8,219.96]],"ltp":5.8,"batl":[[0,5.8,10.29]],"id":41122648},{"tv":116365.83,"trd":[[1.93,1365.7]],"batl":[[0,1.93,18.29]],"id":51922},{"batb":[[0,4.7,198.27]],"batl":[[0,4.8,173.26]],"id":50466254}],"tv":161182.42}],"ArrivalTime":1710508150750}
{"op":"mcm","id":2,"clk":"AI96AIinAQCquQE=","pt":1710508150854,"mc":[{"id":"1.226122413","rc":[{"batb":[[0,5.7,47.91]],"id":41122648},{"batb":[[1,310,3.13]],"id":41200638},{"batb":[[1,4.6,135.36]],"id":50466254}]}],"ArrivalTime":1710508150861}
{"op":"mcm","id":2,"clk":"AJJ6AJGnAQC0uQE=","pt":1710508150948,"mc":[{"id":"1.226122413","rc":[{"batb":[[0,320,4.11]],"id":41200638},{"tv":116368.19,"trd":[[1.93,1368.06]],"batl":[[0,1.93,17.11]],"id":51922}],"tv":161184.78}],"ArrivalTime":1710508150955}
{"op":"mcm","id":2,"clk":"AJd6AKGnAQC+uQE=","pt":1710508151012,"mc":[{"id":"1.226122413","rc":[{"tv":12847.95,"batb":[[0,5.7,58.85]],"trd":[[5.8,232.74]],"batl":[[0,5.8,3.91]],"id":41122648}],"tv":161197.56}],"ArrivalTime":1710508151019}
{"op":"mcm","id":2,"clk":"AKN6AKenAQDOuQE=","pt":1710508151161,"mc":[{"id":"1.226122413","rc":[{"batb":[[2,5.5,69.55]],"id":41122648},{"tv":644.61,"batb":[[0,180,12.98]],"trd":[[180,30.12]],"ltp":180,"id":66251581}],"tv":161199.56}],"ArrivalTime":1710508151168}
{"op":"mcm","id":2,"clk":"AKZ6ALGnAQDSuQE=","pt":1710508151211,"mc":[{"id":"1.226122413","rc":[{"batl":[[2,580,2.82]],"id":54370634},{"tv":22126.53,"trd":[[4.8,2161.13]],"ltp":4.8,"batl":[[0,4.8,168.26]],"id":50466254}],"tv":161209.56}],"ArrivalTime":1710508151219}
{"op":"mcm","id":2,"clk":"ALB6ALanAQDeuQE=","pt":1710508151323,"mc":[{"id":"1.226122413","rc":[{"batl":[[2,560,1.11],[1,530,2.56],[0,520,1.78]],"id":54370634},{"tv":12855.76,"batb":[[2,5.6,165.05],[1,5.7,58.85],[0,5.8,5.28]],"trd":[[5.8,240.55]],"batl":[[2,6.2,25.04],[1,6,18.17],[0,5.9,51.55]],"id":41122648},{"tv":116370.19,"batb":[[0,1.92,452.41]],"trd":[[1.92,1195.47]],"ltp":1.92,"id":51922}],"tv":161219.37}],"ArrivalTime":1710508151330}
{"op":"mcm","id":2,"clk":"ALJ6AL+nAQDouQE=","pt":1710508151422,"mc":[{"id":"1.226122413","rc":[{"batb":[[0,5.8,7.63]],"id":41122648},{"batl":[[1,1.94,64.73]],"id":51922}]}],"ArrivalTime":1710508151429}
{"op":"mcm","id":2,"clk":"ALh6AM2nAQDyuQE=","pt":1710508151532,"mc":[{"id":"1.226122413","rc":[{"batb":[[0,5.8,3.35]],"batl":[[0,5.9,49.92]],"id":41122648},{"batb":[[2,310,1.11],[1,320,6.28],[0,370,2]],"id":41200638},{"tv":116390.19,"batb":[[0,1.92,472.51]],"trd":[[1.93,1388.06]],"ltp":1.93,"batl":[[0,1.93,7.11]],"id":51922},{"tv":22146.53,"batb":[[0,4.7,184.37]],"trd":[[4.8,2181.13]],"batl":[[0,4.8,158.26]],"id":50466254},{"batb":[[0,180,11.49]],"id":66251581}],"tv":161259.37}],"ArrivalTime":1710508151539}
{"op":"mcm","id":2,"clk":"AMB6ANOnAQD8uQE=","pt":1710508151633,"mc":[{"id":"1.226122413","rc":[{"batl":[[0,5.9,36.94]],"id":41122648},{"batb":[[1,320,4.11]],"id":41200638},{"tv":2704.73,"trd":[[26,499.11]],"ltp":26,"batl":[[0,26,4.64]],"id":55632148},{"tv":116394.23,"batb":[],"trd":[[1.93,1392.1]],"batl":[[0,1.93,5.09]],"id":51922},{"tv":2979.42,"trd":[[55,23.28]],"ltp":55,"batl":[[0,55,11.67]],"id":49744721},{"tv":2541.48,"trd":[[36,24.11]],"ltp":36,"batl":[[0,36,3.07]],"id":106596}],"tv":161280.83}],"ArrivalTime":1710508151640}
{"op":"mcm","id":2,"clk":"AMJ6AN2nAQCJugE=","pt":1710508151740,"mc":[{"id":"1.226122413","rc":[{"batl":[[2,580,2.82],[1,560,1.11]],"id":54370634},{"tv":12862.46,"batb":[[2,5.5,70.5],[1,5.6,165.05],[0,5.7,58.85]],"trd":[[5.8,247.25]],"id":41122648},{"batl":[[0,1.93,7.09]],"id":51922},{"batb":[[2,4.5,135.32]],"id":50466254},{"batb":[[0,180,12.65]],"id":66251581}],"tv":161287.53}],"ArrivalTime":1710508151747}
{"op":"mcm","id":2,"clk":"AMl6AOmnAQCTugE=","pt":1710508151838,"mc":[{"id":"1.226122413","rc":[{"batb":[[2,5.5,90.42]],"id":41122648},{"batb":[[2,320,3.88],[1,360,1.86]],"id":41200638},{"tv":116406.23,"batb":[[0,1.92,433.67]],"trd":[[1.93,1404.1]],"batl":[[2,1.95,150.88],[1,1.94,102.63],[0,1.93,1.09]],"id":51922},{"batb":[[1,48,24.02]],"id":49744721}],"tv":161299.53}],"ArrivalTime":1710508151845}
{"op":"mcm","id":2,"clk":"ANF6APmnAQCkugE=","pt":1710508151940,"mc":[{"id":"1.226122413","rc":[{"tv":549.97,"batb":[[0,370,1.94]],"trd":[[370,13.12]],"ltp":370,"id":41200638},{"tv":2714.01,"batb":[[2,24,10],[1,25,39.88],[0,26,5.96]],"trd":[[26,508.39]],"batl":[[2,29,10.74],[1,28,2.9],[0,27,23.05]],"id":55632148},{"batb":[[0,1.92,441.13]],"batl":[],"id":51922},{"batl":[[0,4.8,172.03]],"id":50466254},{"batl":[[0,36,5.02]],"id":106596}],"tv":161308.93}],"ArrivalTime":1710508151948}
{"op":"mcm","id":2,"clk":"ANV6AP+nAQCzugE=","pt":1710508152040,"mc":[{"id":"1.226122413","rc":[{"batb":[[2,320,4.02]],"id":41200638},{"batl":[[0,1.93,7.09]],"id":51922},{"batb":[[1,4.6,143.05]],"id":50466254},{"batb":[[0,180,6.65]],"id":66251581}]}],"ArrivalTime":1710508152047}
{"op":"mcm","id":2,"clk":"ANt6AIuoAQC5ugE=","pt":1710508152141,"mc":[{"id":"1.226122413","rc":[{"batb":[[2,23,14.41],[1,24,10],[0,25,39.88]],"batl":[[2,29,11.38],[1,28,3.59],[0,27,20.27]],"id":55632148},{"batl":[[0,55,13.67]],"id":49744721},{"batb":[[0,4.7,176.75]],"id":50466254},{"tv":656.6,"trd":[[200,40.25]],"ltp":200,"batl":[[0,200,2.91]],"id":66251581},{"batl":[[2,40,12.57]],"id":106596}],"tv":161320.92}],"ArrivalTime":1710508152148}
{"op":"mcm","id":2,"clk":"AN96AJOoAQDMugE=","pt":1710508152250,"mc":[{"id":"1.226122413","rc":[{"batb":[[0,5.7,59.23]],"id":41122648},{"tv":550.35,"batb":[[0,370,1.75]],"trd":[[370,13.5]],"id":41200638},{"tv":116433.37,"batb":[[1,1.91,175.38],[0,1.92,432.76]],"trd":[[1.92,1222.61]],"ltp":1.92,"batl":[[0,1.93,13.09]],"id":51922},{"batl":[[2,5,37.92]],"id":50466254},{"batl":[[2,210,7.49],[1,200,2.91],[0,190,1.35]],"id":66251581}],"tv":161348.44}],"ArrivalTime":1710508152257}
{"op":"mcm","id":2,"clk":"AOh6AJaoAQDRugE=","pt":1710508152298,"mc":[{"id":"1.226122413","rc":[{"tv":465.78,"batb":[[2,390,1.63],[1,400,4.73],[0,420,2.06]],"trd":[[480,8.67]],"ltp":480,"batl":[[0,520,1]],"id":54370634},{"batb":[[0,5.7,67.21]],"id":41122648},{"batl":[[2,29,10.74],[1,28,2.9]],"id":55632148},{"batl":[[1,200,4.19]],"id":66251581},{"batl":[[2,40,13.25]],"id":106596}],"tv":161350}],"ArrivalTime":1710508152305}
{"op":"mcm","id":2,"clk":"AOp6AJ2oAQDZugE=","pt":1710508152412,"mc":[{"id":"1.226122413","rc":[{"tv":467.22,"trd":[[520,4.12]],"ltp":520,"batl":[[2,720,1.4],[1,580,2.82],[0,560,1.39]],"id":54370634},{"batb":[[0,5.7,167.21]],"id":41122648},{"tv":550.69,"batb":[[2,320,4.28],[0,370,1.58]],"trd":[[370,13.84]],"id":41200638},{"batl":[[0,1.93,19.09]],"id":51922},{"batb":[[0,4.7,184.43]],"id":50466254}],"tv":161351.78}],"ArrivalTime":1710508152419}
{"op":"mcm","id":2,"clk":"APB6AKaoAQDjugE=","pt":1710508152506,"mc":[{"id":"1.226122413","rc":[{"tv":2726.02,"batb":[[0,25,33.88]],"trd":[[25,478.92]],"ltp":25,"id":55632148},{"tv":659.3,"batb":[[2,170,1.15],[1,180,6.65],[0,190,1.88]],"trd":[[190,29.89]],"ltp":190,"batl":[[2,260,1.55],[1,210,7.49],[0,200,4.19]],"id":66251581}],"tv":161366.49}],"ArrivalTime":1710508152513}
{"op":"mcm","id":2,"clk":"APt6ALGoAQDougE=","pt":1710508152618,"mc":[{"id":"1.226122413","rc":[{"batb":[[2,400,4.01],[1,410,2.35]],"id":54370634},{"batb":[[0,5.7,181.55]],"batl":[[0,5.9,25.25]],"id":41122648},{"batb":[[0,1.92,417.58]],"batl":[[0,1.93,25.09]],"id":51922},{"tv":665.06,"batb":[[2,160,37.37],[1,170,1.15],[0,180,6.65]],"trd":[[190,35.65]],"batl":[[2,210,7.49],[1,200,4.19],[0,190,2.13]],"id":66251581},{"batl":[[2,40,12.57]],"id":106596}],"tv":161372.25}],"ArrivalTime":1710508152625}
{"op":"mcm","id":2,"clk":"AP56ALeoAQD1ugE=","pt":1710508152721,"mc":[{"id":"1.226122413","rc":[{"batb":[[1,410,1.63]],"id":54370634},{"batl":[[0,5.9,23.02]],"id":41122648},{"tv":116475.15,"batb":[[2,1.9,353.86]],"trd":[[1.93,1445.88]],"ltp":1.93,"batl":[[1,1.94,104.63],[0,1.93,4.2]],"id":51922},{"batl":[[2,210,5.96],[0,190,3.58]],"id":66251581},{"batl":[[2,40,13.25]],"id":106596}],"tv":161414.03}],"ArrivalTime":1710508152728}
{"op":"mcm","id":2,"clk":"AIV7AMWoAQD9ugE=","pt":1710508152826,"mc":[{"id":"1.226122413","rc":[{"tv":12874.92,"trd":[[5.9,242.04]],"ltp":5.9,"batl":[[2,6.2,27.16],[0,5.9,16.79]],"id":41122648},{"batb":[[2,320,3.25]],"id":41200638},{"batl":[[1,1.94,110.63],[0,1.93,10.2]],"id":51922},{"batb":[[0,4.7,192.12]],"id":50466254},{"batl":[[2,210,7.49],[0,190,4.93]],"id":66251581}],"tv":161426.49}],"ArrivalTime":1710508152833}
{"op":"mcm","id":2,"clk":"AI57AMqoAQCJuwE=","pt":1710508152918,"mc":[{"id":"1.226122413","rc":[{"batb":[[2,330,1.71]],"id":41200638},{"batb":[],"batl":[[2,1.95,148.88],[0,1.93,54.6]],"id":51922},{"batb":[[1,170,3.46]],"id":66251581}]}],"ArrivalTime":1710508152925}
{"op":"mcm","id":2,"clk":"AJR7ANaoAQCWuwE=","pt":1710508153032,"mc":[{"id":"1.226122413","rc":[{"batb":[[2,330,1.57]],"batl":[[0,400,3.17]],"id":41200638},{"batl":[[1,1.94,119.63]],"id":51922}]}],"ArrivalTime":1710508153038}
{"op":"mcm","id":2,"clk":"AKJ7ANqoAQCmuwE=","pt":1710508153135,"mc":[{"id":"1.226122413","rc":[{"batb":[[2,5.6,165.05],[1,5.7,181.17],[0,5.8,10.72]],"id":41122648},{"tv":116495.15,"batb":[[2,1.9,437.86]],"trd":[[1.93,1465.88]],"batl":[[0,1.93,44.6]],"id":51922},{"batb":[[0,4.7,199.8]],"id":50466254}],"tv":161446.49}],"ArrivalTime":1710508153143}
{"op":"mcm","id":2,"clk":"AKR7AOGoAQC1uwE=","pt":1710508153240,"mc":[{"id":"1.226122413","rc":[{"batl":[[0,560,1.11]],"id":54370634},{"tv":12875.15,"batb":[[0,5.8,10.61]],"trd":[[5.8,247.48]],"ltp":5.8,"id":41122648},{"batb":[[0,1.92,438.58]],"batl":[[1,1.94,131.63],[0,1.93,50.6]],"id":51922}],"tv":161446.72}],"ArrivalTime":1710508153247}
{"op":"mcm","id":2,"clk":"AKx7AOmoAQDAuwE=","pt":1710508153337,"mc":[{"id":"1.226122413","rc":[{"batl":[[1,580,3.1]],"id":54370634},{"batl":[[2,1.95,150.88],[0,1.93,84.46]],"id":51922},{"batl":[[2,40,12.57]],"id":106596}]}],"ArrivalTime":1710508153344}
{"op":"mcm","id":2,"clk":"ALR7AO2oAQDPuwE=","pt":1710508153442,"mc":[{"id":"1.226122413","rc":[{"batb":[[0,420,2.74]],"id":54370634},{"tv":116496,"batb":[[0,1.92,438.15]],"trd":[[1.92,1223.46]],"ltp":1.92,"batl":[[2,1.95,156.88],[1,1.94,137.63]],"id":51922},{"batb":[[1,170,1.15]],"id":66251581}],"tv":161447.57}],"ArrivalTime":1710508153449}
{"op":"mcm","id":2,"clk":"AL17APioAQDVuwE=","pt":1710508153545,"mc":[{"id":"1.226122413","rc":[{"batl":[[0,27,22.71]],"id":55632148},{"batb":[[2,1.9,382.86]],"id":51922}]}],"ArrivalTime":1710508153551}
{"op":"mcm","id":2,"clk":"AMh7AIapAQDluwE=","pt":1710508153649,"mc":[{"id":"1.226122413","rc":[{"tv":116606,"batb":[[1,1.91,182.38]],"trd":[[1.93,1575.88]],"ltp":1.93,"batl":[[2,1.95,162.88],[1,1.94,143.63],[0,1.93,29.46]],"id":51922},{"tv":2979.52,"trd":[[55,23.38]],"batl":[[0,55,13.62]],"id":49744721},{"batl":[[0,4.8,174.86]],"id":50466254}],"tv":161557.67}],"ArrivalTime":1710508153656}
{"op":"mcm","id":2,"clk":"AMl7AIupAQDsuwE=","pt":1710508153701,"mc":[{"id":"1.226122413","rc":[{"tv":116706,"batb":[],"trd":[[1.93,1634.8],[1.94,1161.49]],"ltp":1.94,"batl":[[2,1.96,146.79],[1,1.95,162.88],[0,1.94,123.09]],"id":51922},{"tv":674.92,"batb":[[0,180,7.45]],"trd":[[190,45.51]],"batl":[[2,260,1.55],[1,210,7.49],[0,200,4.19]],"id":66251581}],"tv":161667.53}],"ArrivalTime":1710508153707}
{"op":"mcm","id":2,"clk":"AMt7AJWpAQD5uwE=","pt":1710508153801,"mc":[{"id":"1.226122413","rc":[{"batb":[[1,360,1.63]],"id":41200638},{"batb":[[2,1.91,182.38],[1,1.92,458.98],[0,1.93,72.92]],"batl":[[1,1.95,168.88]],"id":51922}]}],"ArrivalTime":1710508153808}
{"op":"mcm","id":2,"clk":"ANJ7AKKpAQD+uwE=","pt":1710508153906,"mc":[{"id":"1.226122413","rc":[{"tv":471.22,"batb":[[2,380,3.75],[1,400,4.01],[0,410,2.37]],"trd":[[430,5.91],[420,4.39]],"ltp":420,"id":54370634},{"tv":12896.36,"batb":[[2,5.5,89.47],[1,5.6,165.05],[0,5.7,181.17]],"trd":[[5.8,268.69]],"batl":[[1,6,19.77]],"id":41122648},{"tv":116751.2,"batb":[[1,1.92,519.98],[0,1.93,50.32]],"trd":[[1.93,1680]],"ltp":1.93,"batl":[[2,1.96,121.79],[1,1.95,174.88]],"id":51922},{"batb":[[0,4.7,186.97]],"id":50466254},{"batb":[[0,34,27.48]],"batl":[[2,40,13.25]],"id":106596}],"tv":161737.94}],"ArrivalTime":1710508153913}
{"op":"mcm","id":2,"clk":"ANl7AK6pAQCJvAE=","pt":1710508154010,"mc":[{"id":"1.226122413","rc":[{"batl":[[2,6,19.77],[1,5.9,16.79],[0,5.8,4.9]],"id":41122648},{"batb":[[0,370,1.7]],"id":41200638},{"tv":116997.37,"batb":[[2,1.91,301.05]],"trd":[[1.94,1407.66]],"ltp":1.94,"batl":[[2,1.97,135.44],[1,1.96,121.79],[0,1.95,180.88]],"id":51922}],"tv":161984.11}],"ArrivalTime":1710508154017}
{"op":"mcm","id":2,"clk":"AON7ALipAQCYvAE=","pt":1710508154123,"mc":[{"id":"1.226122413","rc":[{"batb":[[1,400,4.47]],"batl":[[2,620,1.08],[1,580,3.25]],"id":54370634},{"tv":12928.08,"batb":[[2,5.6,165.05],[1,5.7,181.17],[0,5.8,19.03]],"trd":[[5.8,300.41]],"batl":[[2,6.2,27.16],[1,6,19.77],[0,5.9,31.59]],"id":41122648},{"batb":[[0,1.93,86.08]],"batl":[],"id":51922},{"batb":[[1,32,18.15],[0,34,29.48]],"id":106596}],"tv":162015.83}],"ArrivalTime":1710508154130}
{"op":"mcm","id":2,"clk":"AO17AMSpAQChvAE=","pt":1710508154242,"mc":[{"id":"1.226122413","rc":[{"batb":[[2,5.6,167.03]],"id":41122648},{"tv":550.81,"batb":[[0,370,1.87]],"trd":[[380,1.16]],"ltp":380,"id":41200638},{"batb":[[0,1.93,146.57]],"batl":[[0,1.95,186.88]],"id":51922},{"tv":22164.53,"batb":[[2,4.5,132.07],[0,4.7,168.05]],"trd":[[4.8,2199.13]],"batl":[[0,4.8,165.86]],"id":50466254}],"tv":162033.95}],"ArrivalTime":1710508154250}
{"op":"mcm","id":2,"clk":"APF7AMqpAQCrvAE=","pt":1710508154320,"mc":[{"id":"1.226122413","rc":[{"batl":[[2,750,2.48],[1,610,1.36]],"id":54370634},{"tv":12948.67,"batb":[[2,5.6,165.05],[0,5.8,8.73]],"trd":[[5.8,321]],"id":41122648},{"tv":22182.53,"trd":[[4.8,2217.13]],"batl":[[0,4.8,156.86]],"id":50466254}],"tv":162072.54}],"ArrivalTime":1710508154327}
{"op":"mcm","id":2,"clk":"APx7ANOpAQCzvAE=","pt":1710508154424,"mc":[{"id":"1.226122413","rc":[{"batl":[[2,610,1.36],[1,560,1.11],[0,550,5.38]],"id":54370634},{"batb":[[2,5.5,89.47],[1,5.6,165.05],[0,5.7,181.17]],"batl":[[1,6,27.61]],"id":41122648},{"batb":[[2,1.91,471.84],[1,1.92,521.98]],"id":51922},{"batb":[[0,4.7,191.07]],"id":50466254},{"tv":675.16,"batb":[[0,180,7.33]],"trd":[[190,45.75]],"id":66251581}],"tv":162072.78}],"ArrivalTime":1710508154432}
{"op":"mcm","id":2,"clk":"AP97ANupAQC2vAE=","pt":1710508154524,"mc":[{"id":"1.226122413","rc":[{"batl":[[0,1.95,173.22]],"id":51922},{"tv":2543.28,"batb":[[0,34,26.58]],"trd":[[34,154.71]],"ltp":34,"batl":[[0,36,5.92]],"id":106596}],"tv":162074.58}],"ArrivalTime":1710508154531}
{"op":"mcm","id":2,"clk":"AIV8AOKpAQDAvAE=","pt":1710508154650,"mc":[{"id":"1.226122413","rc":[{"tv":117024.69,"batb":[[0,1.93,132.91]],"trd":[[1.93,1707.32]],"ltp":1.93,"batl":[[0,1.95,179.22]],"id":51922},{"tv":2543.78,"batb":[[0,34,26.33]],"trd":[[34,155.21]],"id":106596}],"tv":162102.4}],"ArrivalTime":1710508154657}
{"op":"mcm","id":2,"clk":"AIt8AO+pAQDJvAE=","pt":1710508154733,"mc":[{"id":"1.226122413","rc":[{"tv":12949.81,"trd":[[5.9,243.18]],"ltp":5.9,"batl":[[0,5.9,31.02]],"id":41122648},{"tv":550.87,"batb":[[0,370,1.84]],"trd":[[380,1.22]],"id":41200638},{"batb":[[1,170,3.35]],"id":66251581}],"tv":162103.6}],"ArrivalTime":1710508154740}
{"op":"mcm","id":2,"clk":"AIx8APWpAQDRvAE=","pt":1710508154831,"mc":[{"id":"1.226122413","rc":[{"batb":[[0,5.7,181.74]],"id":41122648},{"batb":[],"batl":[[0,1.95,185.22]],"id":51922},{"tv":675.36,"batb":[[0,180,7.23]],"trd":[[190,45.95]],"id":66251581},{"batb":[[1,32,22.22]],"id":106596}],"tv":162103.8}],"ArrivalTime":1710508154838}
{"op":"mcm","id":2,"clk":"AJF8APypAQDbvAE=","pt":1710508154942,"mc":[{"id":"1.226122413","rc":[{"tv":12950.03,"batb":[[0,5.7,181.63]],"trd":[[5.8,321.22]],"ltp":5.8,"id":41122648},{"tv":551.01,"batb":[[0,370,1.77]],"trd":[[380,1.36]],"id":41200638},{"tv":2726.24,"batb":[[0,25,33.77]],"trd":[[25,479.14]],"id":55632148},{"batb":[[0,1.93,140.33]],"id":51922},{"tv":22182.75,"batb":[[0,4.7,190.96]],"trd":[[4.7,708.15]],"ltp":4.7,"id":50466254},{"tv":675.72,"batb":[[0,180,7.05]],"trd":[[190,46.31]],"id":66251581}],"tv":162104.96}],"ArrivalTime":1710508154949}
{"op":"mcm","id":2,"clk":"AJZ8AIeqAQDkvAE=","pt":1710508155034,"mc":[{"id":"1.226122413","rc":[{"tv":12968.04,"batb":[[0,5.7,172.62]],"trd":[[5.7,178.82],[5.8,322.14]],"ltp":5.7,"batl":[[2,6.2,25.04]],"id":41122648},{"tv":117028.69,"batb":[[0,1.93,138.33]],"trd":[[1.93,1711.32]],"batl":[[2,1.96,121.79],[1,1.95,191.22],[0,1.94,10]],"id":51922},{"tv":22242.75,"batb":[[0,4.7,160.96]],"trd":[[4.7,768.15]],"id":50466254},{"tv":675.94,"batb":[[0,180,6.94]],"trd":[[190,46.53]],"batl":[[1,210,5.96]],"id":66251581}],"tv":162187.19}],"ArrivalTime":1710508155041}
{"op":"mcm","id":2,"clk":"AJh8AJSqAQD3vAE=","pt":1710508155142,"mc":[{"id":"1.226122413","rc":[{"batb":[[2,400,4.47],[1,410,1.63],[0,420,1.64]],"id":54370634},{"tv":557.35,"trd":[[400,23.42]],"ltp":400,"batl":[[2,480,3.17],[1,450,1.71],[0,420,2.3]],"id":41200638},{"tv":2730.24,"batb":[[0,25,31.77]],"trd":[[25,483.14]],"id":55632148},{"batl":[[2,1.96,160.47],[1,1.95,197.22]],"id":51922},{"tv":676.52,"batb":[[0,180,6.65]],"trd":[[190,47.11]],"batl":[[0,200,4.27]],"id":66251581}],"tv":162198.11}],"ArrivalTime":1710508155150}
{"op":"mcm","id":2,"clk":"AJ58AJuqAQCDvQE=","pt":1710508155246,"mc":[{"id":"1.226122413","rc":[{"batb":[],"batl":[[1,6,29.8]],"id":41122648},{"tv":117028.91,"batb":[[2,1.91,461.84],[0,1.93,138.22]],"trd":[[1.93,1711.54]],"batl":[[1,1.95,199.94]],"id":51922},{"tv":22246.75,"batb":[[2,4.5,135.32],[0,4.7,135.94]],"trd":[[4.7,772.15]],"id":50466254},{"batl":[[2,220,1.46]],"id":66251581},{"batb":[[0,34,28.33]],"id":106596}],"tv":162202.33}],"ArrivalTime":1710508155253}
{"op":"mcm","id":2,"clk":"AKJ8AKCqAQCNvQE=","pt":1710508155300,"mc":[{"id":"1.226122413","rc":[{"batb":[[2,24,10],[1,25,34.77],[0,26,2]],"id":55632148},{"tv":117048.91,"batb":[[2,1.92,521.98],[1,1.93,138.22],[0,1.94,33.62]],"trd":[[1.94,1427.66]],"ltp":1.94,"batl":[[2,1.97,138.07],[1,1.96,160.47],[0,1.95,205.94]],"id":51922},{"tv":2981.52,"batb":[[0,50,77.62]],"trd":[[50,72.5]],"ltp":50,"id":49744721},{"batb":[[1,170,1.15]],"id":66251581}],"tv":162224.33}],"ArrivalTime":1710508155309}
{"op":"mcm","id":2,"clk":"AKd8ALCqAQCevQE=","pt":1710508155414,"mc":[{"id":"1.226122413","rc":[{"batl":[[2,610,1.08]],"id":54370634},{"tv":2734.24,"batb":[[2,23,14.41],[1,24,10],[0,25,34.77]],"trd":[[26,512.39]],"ltp":26,"batl":[[2,28,3.59],[1,27,22.71],[0,26,2.64]],"id":55632148},{"tv":117058.91,"batb":[[1,1.93,201.22],[0,1.94,68.05]],"trd":[[1.94,1437.66]],"id":51922},{"batb":[[2,4.5,132.07]],"id":50466254},{"batb":[[0,34,26.33]],"id":106596}],"tv":162238.33}],"ArrivalTime":1710508155421}
{"op":"mcm","id":2,"clk":"ALB8ALiqAQCqvQE=","pt":1710508155514,"mc":[{"id":"1.226122413","rc":[{"batl":[[0,550,5.66]],"id":54370634},{"tv":12974.03,"batb":[[0,5.7,169.63]],"trd":[[5.7,184.81]],"id":41122648},{"batl":[[2,29,10.74],[1,28,2.9],[0,27,22.71]],"id":55632148},{"batl":[[0,1.95,211.94]],"id":51922},{"batl":[[0,4.8,34.52]],"id":50466254}],"tv":162244.32}],"ArrivalTime":1710508155521}
{"op":"mcm","id":2,"clk":"ALd8AMiqAQCyvQE=","pt":1710508155618,"mc":[{"id":"1.226122413","rc":[{"tv":12979.15,"trd":[[5.8,327.26]],"ltp":5.8,"batl":[[2,6,29.8],[1,5.9,31.02],[0,5.8,3.25]],"id":41122648},{"batb":[[0,25,33.77]],"batl":[],"id":55632148},{"tv":117068.91,"batb":[[0,1.94,63.05]],"trd":[[1.94,1447.66]],"id":51922},{"tv":22491.42,"batb":[[2,4.5,135.32],[0,4.7,37.7]],"trd":[[4.7,1016.82]],"batl":[[0,4.8,33.8]],"id":50466254},{"batb":[[1,32,18.15]],"id":106596}],"tv":162504.11}],"ArrivalTime":1710508155625}
{"op":"mcm","id":2,"clk":"AL98ANSqAQC+vQE=","pt":1710508155734,"mc":[{"id":"1.226122413","rc":[{"tv":117069.99,"batb":[[0,1.94,62.51]],"trd":[[1.94,1448.74]],"batl":[[2,1.97,174.07]],"id":51922},{"tv":22518.64,"batb":[[2,4.4,198.1],[1,4.5,135.32],[0,4.6,143.07]],"trd":[[4.7,1044.04]],"id":50466254},{"batl":[[0,200,5.05]],"id":66251581}],"tv":162532.41}],"ArrivalTime":1710508155741}
{"op":"mcm","id":2,"clk":"AMl8AOGqAQDKvQE=","pt":1710508155829,"mc":[{"id":"1.226122413","rc":[{"batl":[[0,550,5.91]],"id":54370634},{"batb":[[2,1.92,514.52]],"batl":[[0,1.95,189.95]],"id":51922},{"batb":[[1,48,20.16]],"id":49744721},{"tv":22518.68,"batb":[[0,4.6,143.05]],"trd":[[4.7,1044.08]],"id":50466254}],"tv":162532.45}],"ArrivalTime":1710508155836}
{"op":"mcm","id":2,"clk":"AMp8AOeqAQDRvQE=","pt":1710508155927,"mc":[{"id":"1.226122413","rc":[{"batl":[[0,1.95,187.23]],"id":51922},{"batb":[[2,4.4,211.1],[1,4.5,132.07]],"batl":[[2,4.9,46.83],[1,4.8,33.8],[0,4.7,32.08]],"id":50466254},{"batb":[[0,34,28.33]],"id":106596}]}],"ArrivalTime":1710508155934}
{"op":"mcm","id":2,"clk":"AM98APCqAQDZvQE=","pt":1710508156030,"mc":[{"id":"1.226122413","rc":[{"tv":117121.48,"batb":[[0,1.94,36.77]],"trd":[[1.94,1500.23]],"id":51922},{"tv":22628.67,"batb":[[1,4.5,135.32]],"trd":[[4.7,1126.23],[4.8,2244.97]],"ltp":4.8,"batl":[[2,5,37.92],[1,4.9,46.83],[0,4.8,19.88]],"id":50466254}],"tv":162693.93}],"ArrivalTime":1710508156037}
{"op":"mcm","id":2,"clk":"ANJ8AP2qAQDovQE=","pt":1710508156140,"mc":[{"id":"1.226122413","rc":[{"batb":[[0,25,36.77]],"id":55632148},{"batb":[[0,1.94,64.86]],"batl":[],"id":51922},{"tv":22641.39,"batb":[[1,4.5,132.07],[0,4.6,136.69]],"trd":[[4.6,1517.46]],"ltp":4.6,"batl":[[0,4.8,22.45]],"id":50466254}],"tv":162706.65}],"ArrivalTime":1710508156147}
{"op":"mcm","id":2,"clk":"ANd8AISrAQDwvQE=","pt":1710508156233,"mc":[{"id":"1.226122413","rc":[{"batl":[[2,6.2,25.04],[1,6,29.8],[0,5.9,31.02]],"id":41122648},{"tv":561.35,"batb":[[2,320,2.57],[1,330,1.57],[0,360,1.4]],"trd":[[380,1.74],[370,17],[360,8.68]],"ltp":360,"id":41200638},{"batb":[[0,25,34.77]],"id":55632148},{"tv":22644.69,"trd":[[4.7,1129.53]],"ltp":4.7,"batl":[[2,4.9,46.83],[1,4.8,33.78],[0,4.7,22.54]],"id":50466254}],"tv":162713.95}],"ArrivalTime":1710508156239}
{"op":"mcm","id":2,"clk":"AN18AI6rAQD/vQE=","pt":1710508156343,"mc":[{"id":"1.226122413","rc":[{"tv":13318.41,"batb":[[2,5.4,70.4],[1,5.5,89.47],[0,5.6,165.05]],"trd":[[5.7,524.07]],"ltp":5.7,"id":41122648},{"tv":117132.31,"batb":[[0,1.94,84.44]],"trd":[[1.94,1511.06]],"batl":[[1,1.96,170.47]],"id":51922}],"tv":163064.04}],"ArrivalTime":1710508156350}
{"op":"mcm","id":2,"clk":"AOx8AJWrAQCLvgE=","pt":1710508156454,"mc":[{"id":"1.226122413","rc":[{"batb":[[1,330,1.03],[0,340,2.17]],"batl":[[0,420,2]],"id":41200638},{"tv":22648.79,"batb":[[1,4.5,135.32],[0,4.6,134.64]],"trd":[[4.6,1521.56]],"ltp":4.6,"id":50466254},{"tv":2545.78,"batb":[[0,34,27.33]],"trd":[[34,157.21]],"id":106596}],"tv":163070.14}],"ArrivalTime":1710508156461}
{"op":"mcm","id":2,"clk":"APB8AJ6rAQCOvgE=","pt":1710508156548,"mc":[{"id":"1.226122413","rc":[{"batb":[[2,380,3.75],[1,400,4.47],[0,410,2.53]],"id":54370634},{"batb":[],"batl":[[2,6,29.8],[1,5.9,31.02],[0,5.8,37.71]],"id":41122648},{"batl":[[2,1.97,138.07],[1,1.96,131.79],[0,1.95,114]],"id":51922},{"batb":[[2,4.4,181.69]],"id":50466254},{"batb":[[2,160,35.15]],"id":66251581}]}],"ArrivalTime":1710508156555}
{"op":"mcm","id":2,"clk":"APZ8AKSrAQCbvgE=","pt":1710508156647,"mc":[{"id":"1.226122413","rc":[{"batb":[[2,330,1.3],[1,340,2.17],[0,350,5.27]],"batl":[],"id":41200638},{"tv":678.24,"batb":[[2,170,1.15],[1,180,6.65],[0,190,1.36]],"trd":[[190,48.83]],"batl":[[0,200,4.19]],"id":66251581}],"tv":163071.86}],"ArrivalTime":1710508156654}
{"op":"mcm","id":2,"clk":"AP18AK6rAQClvgE=","pt":1710508156707,"mc":[{"id":"1.226122413","rc":[{"tv":13336.73,"batb":[[2,5.4,72.55],[0,5.6,144.55]],"trd":[[5.6,171.86]],"ltp":5.6,"batl":[[2,5.9,31.02],[1,5.8,37.71],[0,5.7,16.68]],"id":41122648},{"tv":117172.09,"batb":[[1,1.93,203.22]],"trd":[[1.95,977.84]],"ltp":1.95,"batl":[[1,1.96,109.77],[0,1.95,94.11]],"id":51922},{"batb":[[1,4.5,132.07]],"id":50466254}],"tv":163129.96}],"ArrivalTime":1710508156714}
{"op":"mcm","id":2,"clk":"AIN9ALSrAQCtvgE=","pt":1710508156809,"mc":[{"id":"1.226122413","rc":[{"batl":[[2,560,1.37],[1,550,5.91],[0,510,1.04]],"id":54370634},{"batb":[[1,5.5,91.53],[0,5.6,144.14]],"id":41122648},{"tv":117341.05,"trd":[[1.95,1146.8]],"batl":[[0,1.95,9.63]],"id":51922},{"batb":[[1,4.5,135.32]],"id":50466254},{"tv":679.81,"batb":[[0,190,1.58]],"trd":[[190,50.4]],"id":66251581}],"tv":163300.49}],"ArrivalTime":1710508156816}
{"op":"mcm","id":2,"clk":"AIh9AL6rAQC3vgE=","pt":1710508156914,"mc":[{"id":"1.226122413","rc":[{"batl":[[0,5.7,27.15]],"id":41122648},{"tv":2734.74,"batb":[[0,25,34.52]],"trd":[[25,483.64]],"ltp":25,"id":55632148},{"tv":117360.31,"batb":[[2,1.93,203.22],[1,1.94,99],[0,1.95,209.52]],"trd":[[1.95,1166.06]],"batl":[[2,1.98,246.38],[1,1.97,138.07],[0,1.96,109.77]],"id":51922},{"batb":[[1,4.5,132.07]],"id":50466254},{"batb":[[0,190,2.92]],"id":66251581}],"tv":163320.25}],"ArrivalTime":1710508156921}
{"op":"mcm","id":2,"clk":"AJJ9AMSrAQDHvgE=","pt":1710508157020,"mc":[{"id":"1.226122413","rc":[{"tv":13388.69,"batb":[[0,5.6,118.16]],"trd":[[5.6,223.82]],"batl":[[0,5.7,38.23]],"id":41122648},{"tv":117364.31,"batb":[[1,1.94,116.53],[0,1.95,207.52]],"trd":[[1.95,1170.06]],"id":51922},{"batb":[[2,170,3.36]],"id":66251581},{"batl":[[1,38,13.65]],"id":106596}],"tv":163376.21}],"ArrivalTime":1710508157028}
{"op":"mcm","id":2,"clk":"AJN9AMyrAQDPvgE=","pt":1710508157119,"mc":[{"id":"1.226122413","rc":[{"tv":13401.94,"batb":[[0,5.6,112.54]],"trd":[[5.6,237.07]],"id":41122648},{"batl":[[2,450,1.71],[1,420,2],[0,410,1]],"id":41200638},{"batl":[[0,27,23.8]],"id":55632148},{"tv":117369.47,"batb":[[0,1.95,244.22]],"trd":[[1.95,1175.22]],"batl":[[0,1.96,77.41]],"id":51922},{"batb":[[1,180,8.88]],"id":66251581}],"tv":163394.62}],"ArrivalTime":1710508157126}
{"op":"mcm","id":2,"clk":"AJl9ANSrAQDUvgE=","pt":1710508157224,"mc":[{"id":"1.226122413","rc":[{"batl":[[1,550,3.35]],"id":54370634},{"tv":13418.68,"batb":[[0,5.6,115.17]],"trd":[[5.6,253.81]],"id":41122648},{"batb":[[1,1.94,183.53]],"batl":[[2,1.98,243.79],[1,1.97,145.44]],"id":51922}],"tv":163411.36}],"ArrivalTime":1710508157231}
{"op":"mcm","id":2,"clk":"AJ99AN6rAQDdvgE=","pt":1710508157330,"mc":[{"id":"1.226122413","rc":[{"tv":13457.93,"batb":[[0,5.6,95.54]],"trd":[[5.6,293.06]],"batl":[[0,5.7,43.23]],"id":41122648},{"tv":117448.27,"batb":[[0,1.95,204.82]],"trd":[[1.95,1254.02]],"id":51922},{"tv":22664.17,"trd":[[4.7,1144.91]],"ltp":4.7,"batl":[[0,4.7,14.85]],"id":50466254},{"tv":2567.78,"trd":[[38,13.29],[36,35.95]],"ltp":38,"batl":[[2,42,12],[1,40,13.25],[0,38,8.57]],"id":106596}],"tv":163566.79}],"ArrivalTime":1710508157337}
{"op":"mcm","id":2,"clk":"AKd9AOirAQDsvgE=","pt":1710508157448,"mc":[{"id":"1.226122413","rc":[{"tv":117482.6,"batb":[[2,1.93,222.04],[0,1.95,268.98]],"trd":[[1.95,1254.12],[1.96,221.5]],"batl":[[2,1.98,167.22],[0,1.96,60.29]],"id":51922},{"batl":[[2,260,1.55]],"id":66251581}],"tv":163601.12}],"ArrivalTime":1710508157455}
{"op":"mcm","id":2,"clk":"AKx9APKrAQD1vgE=","pt":1710508157531,"mc":[{"id":"1.226122413","rc":[{"batb":[[1,1.94,190.91]],"id":51922},{"tv":22679.54,"trd":[[4.7,1160.28]],"batl":[[0,4.7,7.16]],"id":50466254},{"batb":[[0,190,1.58]],"batl":[],"id":66251581},{"batb":[[2,32,18.15],[1,34,29.79],[0,36,2.33]],"batl":[[1,40,12.57],[0,38,7.81]],"id":106596}],"tv":163616.49}],"ArrivalTime":1710508157539}
{"op":"mcm","id":2,"clk":"ALV9AParAQCDvwE=","pt":1710508157633,"mc":[{"id":"1.226122413","rc":[{"tv":13574.12,"batb":[[0,5.6,37.45]],"trd":[[5.6,409.25]],"batl":[[2,5.9,33.25]],"id":41122648},{"batb":[[1,1.94,191.76]],"id":51922},{"batl":[[2,220,1.46]],"id":66251581},{"batl":[[0,38,10.01]],"id":106596}],"tv":163732.68}],"ArrivalTime":1710508157640}
{"op":"mcm","id":2,"clk":"ALl9AICsAQCPvwE=","pt":1710508157751,"mc":[{"id":"1.226122413","rc":[{"batb":[[1,5.5,71.4]],"id":41122648},{"tv":117543.88,"batb":[[0,1.95,426.7]],"trd":[[1.95,1315.4]],"id":51922},{"tv":22693.86,"batb":[[2,4.5,132.07],[1,4.6,134.64],[0,4.7,3.42]],"trd":[[4.7,1174.6]],"batl":[[2,5,37.92],[1,4.9,46.83],[0,4.8,33.78]],"id":50466254},{"tv":2572.44,"batb":[[0,36,2.63]],"trd":[[36,40.61]],"ltp":36,"batl":[[1,40,13.25],[0,38,10.77]],"id":106596}],"tv":163812.94}],"ArrivalTime":1710508157757}
{"op":"mcm","id":2,"clk":"AL99AISsAQCXvwE=","pt":1710508157845,"mc":[{"id":"1.226122413","rc":[{"tv":13649.01,"batb":[[2,5.3,118.35],[1,5.4,72.55],[0,5.5,59.57]],"trd":[[5.6,484.14]],"batl":[[2,5.8,37.71],[1,5.7,43.23],[0,5.6,19.14]],"id":41122648},{"tv":117563.88,"batb":[],"trd":[[1.96,241.5]],"ltp":1.96,"batl":[[0,1.96,50.29]],"id":51922},{"tv":679.91,"batb":[[0,190,1.53]],"trd":[[190,50.5]],"id":66251581},{"batb":[[0,36,3.4]],"id":106596}],"tv":163907.93}],"ArrivalTime":1710508157853}
{"op":"mcm","id":2,"clk":"AMZ9AJCsAQChvwE=","pt":1710508157951,"mc":[{"id":"1.226122413","rc":[{"tv":475.5,"trd":[[510,3.5],[550,2.18],[540,1.74]],"ltp":550,"batl":[[2,610,1.08],[1,560,1.37],[0,550,2.25]],"id":54370634},{"batb":[[0,5.5,57.51]],"id":41122648},{"batl":[[2,1.98,169.81]],"id":51922},{"tv":22700.7,"batb":[[2,4.4,181.69],[1,4.5,132.07],[0,4.6,134.64]],"trd":[[4.7,1181.44]],"id":50466254},{"tv":680.97,"batb":[[2,160,35.15],[1,170,3.36],[0,180,8.88]],"trd":[[190,51.56]],"batl":[[0,200,4.66]],"id":66251581},{"tv":2572.8,"batb":[[0,36,3.22]],"trd":[[36,40.97]],"id":106596}],"tv":163920.47}],"ArrivalTime":1710508157958}
{"op":"mcm","id":2,"clk":"AM59AJusAQCpvwE=","pt":1710508158052,"mc":[{"id":"1.226122413","rc":[{"tv":13710.36,"batb":[[0,5.5,28.9]],"trd":[[5.5,375.83]],"ltp":5.5,"batl":[[0,5.6,61.75]],"id":41122648},{"tv":117658.94,"trd":[[1.96,336.56]],"batl":[[0,1.96,2.76]],"id":51922}],"tv":164076.88}],"ArrivalTime":1710508158058}
{"op":"mcm","id":2,"clk":"ANV9AKGsAQC1vwE=","pt":1710508158151,"mc":[{"id":"1.226122413","rc":[{"batb":[[1,5.4,52.17],[0,5.5,8.98]],"id":41122648},{"batb":[[2,320,3.12]],"batl":[[0,410,1.23]],"id":41200638},{"batl":[[2,1.98,167.22]],"id":51922},{"batl":[[2,4.9,46.83],[1,4.8,33.78],[0,4.7,23.75]],"id":50466254}]}],"ArrivalTime":1710508158158}
{"op":"mcm","id":2,"clk":"ANp9AKqsAQDFvwE=","pt":1710508158263,"mc":[{"id":"1.226122413","rc":[{"batb":[[1,400,3.7]],"batl":[[0,550,2.63]],"id":54370634},{"tv":13728.32,"batb":[[2,5.2,79.36],[1,5.3,118.35],[0,5.4,39.63]],"trd":[[5.5,393.79]],"batl":[[2,5.7,43.23],[1,5.6,73.02],[0,5.5,14.32]],"id":41122648},{"batb":[[2,340,2.17],[1,350,5.27],[0,360,2]],"batl":[[1,420,2.3]],"id":41200638},{"tv":117678.94,"batb":[[2,1.94,191.76],[1,1.95,426.7],[0,1.96,7.31]],"trd":[[1.96,342.08],[1.97,174.23]],"ltp":1.97,"batl":[[2,1.99,96.9],[1,1.98,167.22],[0,1.97,138.2]],"id":51922},{"tv":22900.71,"batb":[[0,4.6,34.63]],"trd":[[4.6,1721.57]],"ltp":4.6,"id":50466254},{"batb":[[1,170,1.15]],"id":66251581}],"tv":164314.85}],"ArrivalTime":1710508158270}
{"op":"mcm","id":2,"clk":"AON9ALOsAQDPvwE=","pt":1710508158344,"mc":[{"id":"1.226122413","rc":[{"tv":13778.32,"trd":[[5.5,422.43],[5.6,505.5]],"ltp":5.6,"batl":[[1,5.6,62.34],[0,5.5,15.69]],"id":41122648},{"batl":[[0,27,21.36]],"id":55632148},{"tv":117702.94,"batb":[[1,1.95,496.7],[0,1.96,5.31]],"trd":[[1.96,346.08],[1.97,194.23]],"ltp":1.96,"batl":[[0,1.97,104.13]],"id":51922},{"batb":[[1,4.5,135.32],[0,4.6,37.72]],"id":50466254},{"batb":[[0,180,6.65]],"id":66251581},{"tv":2574.8,"batb":[[0,36,2.22]],"trd":[[36,42.97]],"id":106596}],"tv":164390.85}],"ArrivalTime":1710508158351}
{"op":"mcm","id":2,"clk":"AOd9ALusAQDbvwE=","pt":1710508158420,"mc":[{"id":"1.226122413","rc":[{"tv":13798.32,"batb":[[2,5.2,90.36],[0,5.4,27.48]],"trd":[[5.4,20.08]],"ltp":5.4,"batl":[[0,5.5,45.77]],"id":41122648},{"batb":[[1,350,6.27]],"id":41200638},{"batl":[[2,29,11.38]],"id":55632148},{"tv":117702.97,"batb":[[0,1.96,44.99]],"trd":[[1.96,346.11]],"batl":[[1,1.98,206.52],[0,1.97,66.68]],"id":51922},{"batb":[[0,4.6,43.53]],"batl":[[1,4.8,34.64],[0,4.7,38.13]],"id":50466254}],"tv":164410.88}],"ArrivalTime":1710508158428}
{"op":"mcm","id":2,"clk":"APB9AMOsAQDlvwE=","pt":1710508158526,"mc":[{"id":"1.226122413","rc":[{"tv":475.6,"batb":[[0,410,2.48]],"trd":[[420,4.49]],"ltp":420,"id":54370634},{"tv":13818.32,"trd":[[5.5,442.43]],"ltp":5.5,"batl":[[1,5.6,62.7],[0,5.5,35.77]],"id":41122648},{"batl":[[2,480,3.17],[1,450,1.71],[0,420,2.53]],"id":41200638},{"batb":[[1,1.95,499.27],[0,1.96,65.89]],"batl":[[0,1.97,82.14]],"id":51922},{"tv":22981.59,"batb":[[2,4.3,118.12],[1,4.4,181.69],[0,4.5,135.32]],"trd":[[4.6,1802.45]],"batl":[[2,4.8,34.64],[1,4.7,38.13],[0,4.6,19.97]],"id":50466254}],"tv":164511.86}],"ArrivalTime":1710508158533}
{"op":"mcm","id":2,"clk":"APV9AMisAQDqvwE=","pt":1710508158628,"mc":[{"id":"1.226122413","rc":[{"tv":13823.98,"batb":[[1,5.3,97.76],[0,5.4,29.63]],"trd":[[5.5,448.09]],"batl":[[1,5.6,63.56],[0,5.5,47.94]],"id":41122648},{"tv":2734.84,"batb":[[0,25,34.47]],"trd":[[25,483.74]],"id":55632148},{"tv":117746.85,"batb":[[1,1.95,539.27],[0,1.96,100.73]],"trd":[[1.97,238.11]],"ltp":1.97,"batl":[[0,1.97,44.74]],"id":51922},{"batb":[[0,4.5,192.67]],"batl":[[1,4.7,40.7]],"id":50466254},{"tv":681.91,"batb":[[2,170,1.15],[1,180,6.65],[0,190,1.64]],"trd":[[190,52.5]],"batl":[[0,200,4.19]],"id":66251581}],"tv":164562.44}],"ArrivalTime":1710508158635}
{"op":"mcm","id":2,"clk":"AP19AM+sAQDwvwE=","pt":1710508158727,"mc":[{"id":"1.226122413","rc":[{"batb":[[0,410,2.52]],"id":54370634},{"batb":[[0,5.4,52.99]],"id":41122648},{"batb":[[0,360,2.04]],"id":41200638},{"batb":[[0,25,35.07]],"id":55632148},{"tv":117764.47,"batb":[[2,1.94,155.76],[0,1.96,178.01]],"trd":[[1.96,356.11],[1.97,245.73]],"batl":[[1,1.98,182.89],[0,1.97,40.93]],"id":51922},{"batb":[[0,50,77.92]],"id":49744721},{"batb":[[0,4.5,117.3]],"id":50466254},{"batb":[[1,180,6.73]],"id":66251581},{"batb":[[0,36,5.22]],"batl":[],"id":106596}],"tv":164580.06}],"ArrivalTime":1710508158736}
{"op":"mcm","id":2,"clk":"AIV+ANysAQD+vwE=","pt":1710508158840,"mc":[{"id":"1.226122413","rc":[{"tv":13843.98,"trd":[[5.5,468.09]],"batl":[[0,5.5,37.94]],"id":41122648},{"batl":[[2,29,10.74]],"id":55632148},{"tv":117846.33,"batb":[[0,1.96,203.01]],"trd":[[1.97,327.59]],"batl":[[2,2,490.57],[1,1.99,136.09],[0,1.98,133.3]],"id":51922},{"tv":22981.61,"trd":[[4.6,1802.47]],"batl":[[0,4.6,38.58]],"id":50466254},{"batb":[[0,190,2.64]],"id":66251581},{"batb":[[2,32,25.82]],"batl":[[2,42,11.39],[1,40,12.57],[0,38,10.01]],"id":106596}],"tv":164681.94}],"ArrivalTime":1710508158847}
{"op":"mcm","id":2,"clk":"AI9+AOesAQCGwAE=","pt":1710508158941,"mc":[{"id":"1.226122413","rc":[{"tv":561.8,"trd":[[400,23.87]],"ltp":400,"batl":[[0,420,2.3]],"id":41200638},{"batb":[[0,25,36.71]],"id":55632148},{"tv":685.91,"batb":[[2,160,35.15],[1,170,1.15],[0,180,7.37]],"trd":[[190,56.5]],"id":66251581}],"tv":164686.39}],"ArrivalTime":1710508158947}
{"op":"mcm","id":2,"clk":"AJV+AOusAQCMwAE=","pt":1710508159035,"mc":[{"id":"1.226122413","rc":[{"tv":13844.94,"batb":[[0,5.4,50.36]],"trd":[[5.4,21.04]],"ltp":5.4,"id":41122648},{"tv":117847.79,"batb":[[2,1.95,539.27],[1,1.96,203.01],[0,1.97,38.98]],"trd":[[1.97,329.05]],"batl":[[0,1.98,148.61]],"id":51922},{"batl":[[1,60,29.63]],"id":49744721},{"batb":[[2,32,33.49]],"id":106596}],"tv":164688.81}],"ArrivalTime":1710508159042}
{"op":"mcm","id":2,"clk":"AKJ+APSsAQCZwAE=","pt":1710508159153,"mc":[{"id":"1.226122413","rc":[{"tv":117851.69,"batb":[[1,1.96,223.01]],"trd":[[1.98,100.28]],"ltp":1.98,"batl":[[0,1.98,146.66]],"id":51922},{"batb":[[1,4.4,175.17],[0,4.5,114.05]],"batl":[],"id":50466254}],"tv":164692.71}],"ArrivalTime":1710508159160}
{"op":"mcm","id":2,"clk":"AKN+APysAQChwAE=","pt":1710508159244,"mc":[{"id":"1.226122413","rc":[{"tv":13874.94,"batb":[[0,5.4,35.36]],"trd":[[5.4,51.04]],"id":41122648},{"batb":[[0,1.97,59.78]],"id":51922},{"tv":22981.65,"trd":[[4.6,1802.51]],"batl":[[0,4.6,45.04]],"id":50466254}],"tv":164722.75}],"ArrivalTime":1710508159251}
{"op":"mcm","id":2,"clk":"AKl+AIStAQCowAE=","pt":1710508159348,"mc":[{"id":"1.226122413","rc":[{"batb":[[2,400,3.7],[1,410,1.67],[0,420,1.27]],"id":54370634},{"batb":[[1,24,17.72]],"id":55632148},{"tv":118035.87,"batb":[[0,1.97,57.69]],"trd":[[1.97,333.23],[1.98,280.28]],"batl":[[0,1.98,41.36]],"id":51922},{"batb":[[1,170,3.37]],"id":66251581}],"tv":164906.93}],"ArrivalTime":1710508159355}
{"op":"mcm","id":2,"clk":"AK9+AI2tAQCwwAE=","pt":1710508159458,"mc":[{"id":"1.226122413","rc":[{"batb":[[0,420,1.98]],"id":54370634},{"batl":[[2,29,11.38]],"id":55632148},{"tv":118083.25,"batb":[],"trd":[[1.98,327.66]],"batl":[[0,1.98,17.67]],"id":51922}],"tv":164954.31}],"ArrivalTime":1710508159465}
{"op":"mcm","id":2,"clk":"ALV+AJKtAQC7wAE=","pt":1710508159506,"mc":[{"id":"1.226122413","rc":[{"batl":[[2,560,1.37],[1,550,2.25],[0,540,2.94]],"id":54370634},{"batb":[[0,1.97,92.28]],"batl":[[0,1.98,32.98]],"id":51922},{"batl":[[1,4.7,41.11]],"id":50466254}]}],"ArrivalTime":1710508159513}
{"op":"mcm","id":2,"clk":"AL5+AJ6tAQDFwAE=","pt":1710508159663,"mc":[{"id":"1.226122413","rc":[{"batb":[[1,5.3,95.51]],"id":41122648},{"tv":118136.97,"batb":[],"trd":[[1.98,381.38]],"batl":[[0,1.98,6.12]],"id":51922},{"batb":[[0,4.5,106.36]],"id":50466254}],"tv":165008.03}],"ArrivalTime":1710508159670}
{"op":"mcm","id":2,"clk":"AMR+AKqtAQDLwAE=","pt":1710508159711,"mc":[{"id":"1.226122413","rc":[{"tv":118143.55,"trd":[[1.98,387.96]],"batl":[[0,1.98,10.83]],"id":51922}],"tv":165014.61}],"ArrivalTime":1710508159718}
{"op":"mcm","id":2,"clk":"AMd+AK+tAQDWwAE=","pt":1710508159819,"mc":[{"id":"1.226122413","rc":[{"batb":[[0,420,3.98]],"id":54370634},{"batb":[[1,5.3,97.76],[0,5.4,24.74]],"batl":[[0,5.5,48.24]],"id":41122648},{"batb":[[2,1.95,375.91]],"batl":[[0,1.98,8]],"id":51922},{"batl":[[2,260,1.55]],"id":66251581}]}],"ArrivalTime":1710508159826}
{"op":"mcm","id":2,"clk":"AM1+ALatAQDcwAE=","pt":1710508159914,"mc":[{"id":"1.226122413","rc":[{"tv":13904.94,"batb":[[1,5.3,95.51],[0,5.4,9.74]],"trd":[[5.4,81.04]],"batl":[[2,5.7,45.54]],"id":41122648},{"batb":[[0,1.97,112.28]],"id":51922},{"batl":[[2,220,1.46]],"id":66251581}],"tv":165044.61}],"ArrivalTime":1710508159921}
{"op":"mcm","id":2,"clk":"ANJ+AL6tAQDkwAE=","pt":1710508160026,"mc":[{"id":"1.226122413","rc":[{"batl":[[0,5.5,59.64]],"id":41122648},{"tv":118159.55,"batb":[[2,1.96,223.01],[1,1.97,188.28],[0,1.98,162.88]],"trd":[[1.98,403.96]],"batl":[[2,2.02,69.11],[1,2,490.57],[0,1.99,136.09]],"id":51922},{"batb":[[1,4.4,158.53]],"id":50466254}],"tv":165060.61}],"ArrivalTime":1710508160033}
{"op":"mcm","id":2,"clk":"ANx+AMitAQDwwAE=","pt":1710508160128,"mc":[{"id":"1.226122413","rc":[{"batb":[[0,5.4,2.78]],"batl":[],"id":41122648},{"tv":118225.07,"batb":[[0,1.98,130.12]],"trd":[[1.98,469.48]],"batl":[[0,1.99,71.9]],"id":51922},{"batb":[[1,4.4,155.11]],"id":50466254},{"tv":2576.8,"batb":[[0,36,4.22]],"trd":[[36,44.97]],"batl":[[2,42,12]],"id":106596}],"tv":165128.13}],"ArrivalTime":1710508160135}
{"op":"mcm","id":2,"clk":"AN5+ANOtAQD3wAE=","pt":1710508160227,"mc":[{"id":"1.226122413","rc":[{"batl":[[0,540,2.56]],"id":54370634},{"batb":[[1,5.3,74.65]],"id":41122648},{"batl":[[0,420,2]],"id":41200638},{"batb":[[2,23,17.41]],"id":55632148},{"tv":118332.45,"batb":[[1,1.97,194.01],[0,1.98,161.66]],"trd":[[1.98,485.48],[1.99,241.52]],"batl":[[2,2.04,53.33],[1,2.02,69.11],[0,2,529.72]],"id":51922},{"tv":22995.65,"batb":[[0,4.5,99.36]],"trd":[[4.5,3356.08]],"ltp":4.5,"id":50466254}],"tv":165249.51}],"ArrivalTime":1710508160234}
{"op":"mcm","id":2,"clk":"AOF+AN+tAQCCwQE=","pt":1710508160334,"mc":[{"id":"1.226122413","rc":[{"tv":477.6,"batb":[[0,420,2.98]],"trd":[[450,5.44],[420,5.07]],"batl":[[2,550,2.25],[1,540,2.56],[0,530,1.32]],"id":54370634},{"tv":13910.5,"batb":[[2,5.1,49.06],[1,5.2,88.02],[0,5.3,74.65]],"trd":[[5.4,86.6]],"batl":[[2,5.6,63.56],[1,5.5,59.64],[0,5.4,23.27]],"id":41122648},{"tv":118352.45,"batb":[[2,1.97,194.01],[1,1.98,161.66],[0,1.99,29.74]],"trd":[[1.99,261.52]],"ltp":1.99,"id":51922}],"tv":165277.07}],"ArrivalTime":1710508160341}
{"op":"mcm","id":2,"clk":"AOl+AOStAQCMwQE=","pt":1710508160437,"mc":[{"id":"1.226122413","rc":[{"batl":[[0,530,2.64]],"id":54370634},{"tv":118500.05,"batb":[[1,1.98,182]],"trd":[[2,369.27]],"ltp":2,"batl":[[1,2.02,108.37],[0,2,455.92]],"id":51922},{"batb":[[2,4.3,158.34]],"batl":[],"id":50466254}],"tv":165424.67}],"ArrivalTime":1710508160443}
{"op":"mcm","id":2,"clk":"AO9+AOatAQCRwQE=","pt":1710508160535,"mc":[{"id":"1.226122413","rc":[{"batl":[[0,530,3.96]],"id":54370634},{"batb":[[1,5.2,90.36],[0,5.3,76.9]],"batl":[[2,5.6,66.06],[0,5.4,24.85]],"id":41122648},{"batb":[[0,360,2.34]],"id":41200638},{"batl":[[2,29,10.74]],"id":55632148}]}],"ArrivalTime":1710508160542}
{"op":"mcm","id":2,"clk":"APd+APKtAQCbwQE=","pt":1710508160644,"mc":[{"id":"1.226122413","rc":[{"batl":[[2,560,1.37],[1,550,2.25],[0,530,4.42]],"id":54370634},{"tv":118522.45,"batb":[[0,1.99,18.54]],"trd":[[1.99,283.92]],"ltp":1.99,"batl":[[0,2,391.07]],"id":51922}],"tv":165447.07}],"ArrivalTime":1710508160651}
{"op":"mcm","id":2,"clk":"APt+APqtAQCkwQE=","pt":1710508160748,"mc":[{"id":"1.226122413","rc":[{"tv":2773.56,"batb":[[0,25,17.35]],"trd":[[25,522.46]],"batl":[],"id":55632148},{"batb":[[1,1.98,202],[0,1.99,28.54]],"id":51922}],"tv":165485.79}],"ArrivalTime":1710508160755}
{"op":"mcm","id":2,"clk":"AP5+AP+tAQCrwQE=","pt":1710508160845,"mc":[{"id":"1.226122413","rc":[{"tv":562.4,"batb":[[0,360,2.04]],"trd":[[370,17.6]],"ltp":370,"batl":[[0,420,2.7]],"id":41200638}],"tv":165486.39}],"ArrivalTime":1710508160852}
{"op":"mcm","id":2,"clk":"AIF/AImuAQC1wQE=","pt":1710508160947,"mc":[{"id":"1.226122413","rc":[{"batb":[[0,25,23.34]],"batl":[[2,28,2.9],[1,27,28.41],[0,26,4.54]],"id":55632148},{"batb":[[0,1.99,48.79]],"batl":[],"id":51922}]}],"ArrivalTime":1710508160954}
{"op":"mcm","id":2,"clk":"AIl/AJGuAQDAwQE=","pt":1710508161050,"mc":[{"id":"1.226122413","rc":[{"tv":13932.5,"trd":[[5.4,108.6]],"batl":[[0,5.4,13.85]],"id":41122648},{"tv":562.74,"trd":[[370,17.94]],"batl":[[0,420,2.53]],"id":41200638},{"tv":118522.65,"batb":[[0,1.99,48.69]],"trd":[[1.99,284.12]],"id":51922},{"tv":2580.8,"batb":[[0,36,2.22]],"trd":[[36,48.97]],"id":106596}],"tv":165512.93}],"ArrivalTime":1710508161057}
{"op":"mcm","id":2,"clk":"AJJ/AJquAQDNwQE=","pt":1710508161157,"mc":[{"id":"1.226122413","rc":[{"tv":562.82,"trd":[[370,18.02]],"batl":[[0,420,2.49]],"id":41200638},{"tv":118877.17,"batb":[[0,1.99,26.69]],"trd":[[1.99,328.12],[2,679.79]],"ltp":2,"batl":[[0,2,235.81]],"id":51922}],"tv":165867.53}],"ArrivalTime":1710508161164}
{"op":"mcm","id":2,"clk":"AJh/AJ6uAQDawQE=","pt":1710508161261,"mc":[{"id":"1.226122413","rc":[{"batb":[[1,5.2,69.52]],"batl":[[0,5.4,31.37]],"id":41122648},{"tv":2781.56,"trd":[[26,520.39]],"ltp":26,"batl":[[2,29,10.74],[1,28,2.9],[0,27,28.95]],"id":55632148},{"tv":118939.65,"batb":[[2,1.96,199.73],[1,1.97,194.01],[0,1.98,275.68]],"trd":[[1.98,492.1],[1.99,381.5],[2,682.27]],"ltp":1.98,"batl":[[0,2,274.75]],"id":51922},{"batb":[[0,36,4.85]],"id":106596}],"tv":165938.01}],"ArrivalTime":1710508161268}
{"op":"mcm","id":2,"clk":"AJ1/AKKuAQDlwQE=","pt":1710508161314,"mc":[{"id":"1.226122413","rc":[{"tv":563.22,"trd":[[370,18.42]],"batl":[[0,420,2.29]],"id":41200638},{"tv":118944.41,"batb":[[2,1.97,194.01],[1,1.98,278.26],[0,1.99,52.08]],"trd":[[1.99,386.26]],"ltp":1.99,"batl":[],"id":51922}],"tv":165943.17}],"ArrivalTime":1710508161321}
{"op":"mcm","id":2,"clk":"AKZ/AKuuAQDywQE=","pt":1710508161427,"mc":[{"id":"1.226122413","rc":[{"batb":[[2,5.1,70.15],[0,5.3,74.65]],"batl":[],"id":41122648},{"batl":[[1,28,5.85]],"id":55632148},{"batb":[[0,1.99,71.77]],"batl":[[2,2.04,48.57]],"id":51922},{"tv":23016.52,"batb":[[0,4.5,57.7]],"trd":[[4.6,1819.38],[4.5,3360.08]],"ltp":4.6,"batl":[[0,4.6,36.6]],"id":50466254}],"tv":165964.04}],"ArrivalTime":1710508161434}
{"op":"mcm","id":2,"clk":"AK5/ALeuAQD4wQE=","pt":1710508161529,"mc":[{"id":"1.226122413","rc":[{"tv":13951.5,"batb":[],"trd":[[5.4,127.6]],"batl":[[0,5.4,24.37]],"id":41122648},{"tv":563.46,"trd":[[370,18.66]],"batl":[[0,420,2.17]],"id":41200638},{"batb":[[0,1.99,103.2]],"batl":[[2,2.04,53.33],[0,2,234.57]],"id":51922}],"tv":165983.28}],"ArrivalTime":1710508161536}
{"op":"mcm","id":2,"clk":"ALd/ALquAQCAwgE=","pt":1710508161625,"mc":[{"id":"1.226122413","rc":[{"batl":[[1,450,1.84]],"id":41200638},{"batl":[[1,28,11.68]],"id":55632148},{"tv":119413.56,"batb":[[2,1.98,278.26],[1,1.99,103.2],[0,2,89.64]],"trd":[[2,1151.42]],"ltp":2,"batl":[[2,2.06,48.62],[1,2.04,53.33],[0,2.02,108.37]],"id":51922}],"tv":166452.43}],"ArrivalTime":1710508161631}
{"op":"mcm","id":2,"clk":"AMB/AMKuAQCPwgE=","pt":1710508161738,"mc":[{"id":"1.226122413","rc":[{"tv":14100.8,"batb":[[2,5,50.68],[1,5.1,91.23],[0,5.2,67.18]],"trd":[[5.3,149.3]],"ltp":5.3,"id":41122648},{"tv":119493.8,"batb":[[1,1.99,105.77],[0,2,49.57]],"trd":[[2,1231.66]],"batl":[[1,2.04,88.1]],"id":51922},{"batl":[[0,4.6,38.82]],"id":50466254}],"tv":166681.97}],"ArrivalTime":1710508161745}
{"op":"mcm","id":2,"clk":"AMZ/AM2uAQCawgE=","pt":1710508161847,"mc":[{"id":"1.226122413","rc":[{"batb":[[0,5.2,85.34]],"batl":[[0,5.4,34.32]],"id":41122648},{"tv":563.68,"trd":[[370,18.88]],"batl":[[0,420,2.06]],"id":41200638},{"tv":119499.98,"batb":[[1,1.99,131.5],[0,2,67.94]],"trd":[[2.02,31.38]],"ltp":2.02,"batl":[[0,2.02,66.02]],"id":51922},{"tv":23018.52,"batb":[[0,4.5,31.89]],"trd":[[4.6,1821.38]],"batl":[[0,4.6,51.63]],"id":50466254}],"tv":166690.37}],"ArrivalTime":1710508161854}
{"op":"mcm","id":2,"clk":"AM1/ANOuAQCiwgE=","pt":1710508161948,"mc":[{"id":"1.226122413","rc":[{"batb":[[1,5.1,88.79]],"batl":[[2,5.5,60.5],[1,5.4,47.85],[0,5.3,17.8]],"id":41122648},{"batb":[[2,1.98,231.26],[1,1.99,141.5],[0,2,178.22]],"batl":[[2,2.06,43.99]],"id":51922},{"tv":23038.52,"trd":[[4.6,1841.38]],"batl":[[0,4.6,41.63]],"id":50466254}],"tv":166710.37}],"ArrivalTime":1710508161955}
{"op":"mcm","id":2,"clk":"ANZ/ANyuAQCtwgE=","pt":1710508162050,"mc":[{"id":"1.226122413","rc":[{"batb":[[1,5.1,67.71],[0,5.2,47.51]],"id":41122648},{"tv":563.8,"trd":[[370,19]],"batl":[[0,420,2]],"id":41200638},{"tv":119599.98,"batb":[[0,2,147.82]],"trd":[[2,1331.66]],"ltp":2,"batl":[[2,2.06,75.53]],"id":51922},{"tv":2988.26,"batb":[[0,50,74.55]],"trd":[[50,79.24]],"batl":[[1,60,31.75]],"id":49744721}],"tv":166817.23}],"ArrivalTime":1710508162056}
{"op":"mcm","id":2,"clk":"AOF/AOauAQC2wgE=","pt":1710508162153,"mc":[{"id":"1.226122413","rc":[{"batl":[[2,550,2.25],[1,530,4.42],[0,520,2.82]],"id":54370634},{"batb":[[1,5.1,88.65],[0,5.2,37.5]],"batl":[[0,5.3,27.91]],"id":41122648},{"tv":119610.94,"batb":[],"trd":[[2.02,42.34]],"ltp":2.02,"batl":[[2,2.06,43.99],[0,2.02,46.52]],"id":51922},{"batl":[[0,4.6,39.41]],"id":50466254},{"batl":[[2,260,1.55]],"id":66251581}],"tv":166828.19}],"ArrivalTime":1710508162160}
{"op":"mcm","id":2,"clk":"AOh/AOmuAQDBwgE=","pt":1710508162278,"mc":[{"id":"1.226122413","rc":[{"batb":[[2,5,87.85],[0,5.2,19.34]],"id":41122648}]}],"ArrivalTime":1710508162285}
{"op":"mcm","id":2,"clk":"APB/APSuAQDNwgE=","pt":1710508162361,"mc":[{"id":"1.226122413","rc":[{"tv":478.62,"batb":[[2,400,4.16]],"trd":[[520,5.14]],"ltp":520,"batl":[[0,520,2.31]],"id":54370634},{"tv":14101.56,"trd":[[5.3,150.06]],"batl":[[2,5.5,62.89],[0,5.3,27.53]],"id":41122648},{"batb":[[2,1.98,271.26]],"batl":[[0,2.02,39.65]],"id":51922},{"batl":[[2,220,1.46]],"id":66251581}],"tv":166829.97}],"ArrivalTime":1710508162368}
{"op":"mcm","id":2,"clk":"APp/AP+uAQDawgE=","pt":1710508162421,"mc":[{"id":"1.226122413","rc":[{"tv":14121.56,"batb":[[1,5.1,109.73]],"trd":[[5.3,170.06]],"batl":[[0,5.3,23.26]],"id":41122648},{"batb":[[1,1.99,156.5]],"batl":[],"id":51922},{"tv":694.93,"batb":[[0,180,1.7]],"trd":[[190,57.78],[180,37.86]],"ltp":180,"id":66251581}],"tv":166858.99}],"ArrivalTime":1710508162427}
{"op":"mcm","id":2,"clk":"AICAAQCFrwEA5cIB","pt":1710508162527,"mc":[{"id":"1.226122413","rc":[{"batl":[[0,420,2.23]],"id":41200638},{"tv":3001.06,"batb":[[0,50,68.15]],"trd":[[50,92.04]],"id":49744721},{"tv":698.33,"batb":[[0,180,1.18]],"trd":[[180,41.26]],"batl":[[2,210,5.96],[1,200,4.19],[0,190,1.53]],"id":66251581},{"tv":2588.34,"batb":[[0,36,1.08]],"trd":[[36,56.51]],"id":106596}],"tv":166882.73}],"ArrivalTime":1710508162534}
{"op":"mcm","id":2,"clk":"AIeAAQCQrwEA88IB","pt":1710508162619,"mc":[{"id":"1.226122413","rc":[{"batb":[[1,5.1,88.65]],"id":41122648},{"tv":119611.5,"trd":[[2.02,42.9]],"batl":[[1,2.04,105.18],[0,2.02,39.37]],"id":51922},{"batb":[[0,4.5,33.89]],"id":50466254},{"batb":[[0,180,2.63]],"id":66251581},{"tv":2590.5,"batb":[[2,30,26.57],[1,32,33.49],[0,34,29.79]],"trd":[[36,58.67]],"batl":[[2,40,12.57],[1,38,10.01],[0,36,2.4]],"id":106596}],"tv":166885.45}],"ArrivalTime":1710508162626}
{"op":"mcm","id":2,"clk":"AI2AAQCUrwEA+8IB","pt":1710508162727,"mc":[{"id":"1.226122413","rc":[{"batb":[[2,400,2.16]],"id":54370634},{"batb":[[0,5.2,17]],"id":41122648},{"batl":[[2,65,6.31]],"id":49744721},{"batb":[[0,4.5,57.99]],"id":50466254},{"batb":[[1,170,1.15],[0,180,2.8]],"batl":[[0,190,1.61]],"id":66251581}]}],"ArrivalTime":1710508162734}
{"op":"mcm","id":2,"clk":"AJWAAQCarwEAg8MB","pt":1710508162832,"mc":[{"id":"1.226122413","rc":[{"batb":[[1,5.1,67.56]],"id":41122648},{"tv":119611.98,"batb":[],"trd":[[2.02,43.38]],"batl":[[0,2.02,39.13]],"id":51922},{"tv":701.15,"batb":[[0,180,1.39]],"trd":[[180,44.08]],"id":66251581}],"tv":166888.75}],"ArrivalTime":1710508162839}
{"op":"mcm","id":2,"clk":"AMeAAQDKrwEAvcMB","pt":1710508163465,"mc":[{"id":"1.226122413","rc":[{"batl":[[2,560,1.37]],"id":54370634},{"tv":14171.57,"batb":[[0,5.2,41.45],[1,5.1,46.21]],"trd":[[5.2,38],[5.3,210.06]],"ltp":5.2,"batl":[[0,5.3,20.65],[1,5.4,67.85]],"id":41122648},{"tv":566.4,"batb":[[2,320,3.12],[1,340,2.17],[0,350,7.01]],"trd":[[360,11.28]],"ltp":360,"batl":[],"id":41200638},{"tv":2785.56,"batb":[[0,25,21.34]],"trd":[[25,526.46]],"ltp":25,"id":55632148},{"tv":119763.93,"batb":[[0,2,86.02]],"trd":[[2,1471.65],[2.02,55.34]],"ltp":2,"batl":[[0,2.02,52.95],[2,2.06,61.07]],"id":51922},{"tv":23040.32,"batb":[[0,4.5,70.86],[2,4.3,118.12]],"trd":[[4.5,3361.88]],"ltp":4.5,"batl":[[0,4.6,35.6]],"id":50466254},{"batb":[[0,170,3.67],[2,150,4.08],[1,160,35.15]],"batl":[],"id":66251581},{"tv":2592.2,"trd":[[36,60.37]],"batl":[[1,38,12.54],[0,36,1.55]],"id":106596}],"tv":167100.81,"con":true}],"ArrivalTime":1710508163472}
{"op":"mcm","id":2,"clk":"AMmAAQDOrwEAw8MB","pt":1710508163552,"mc":[{"id":"1.226122413","rc":[{"batl":[[1,5.4,68.71],[0,5.3,30.54]],"id":41122648},{"batb":[[0,2,241.04]],"id":51922}]}],"ArrivalTime":1710508163558}
{"op":"mcm","id":2,"clk":"AM6AAQDXrwEAz8MB","pt":1710508163654,"mc":[{"id":"1.226122413","rc":[{"batb":[[0,2,241.32]],"batl":[],"id":51922},{"tv":3014.8,"trd":[[55,37.12]],"ltp":55,"batl":[[0,55,6.76]],"id":49744721}],"tv":167114.55}],"ArrivalTime":1710508163661}
{"op":"mcm","id":2,"clk":"ANKAAQDcrwEA1cMB","pt":1710508163749,"mc":[{"id":"1.226122413","rc":[{"batl":[[2,450,1.84],[1,420,2],[0,410,1.23]],"id":41200638},{"batl":[[0,2.02,33.15]],"id":51922},{"batb":[[0,50,60.59]],"id":49744721},{"batb":[[1,160,34.96],[0,170,1.32]],"id":66251581}]}],"ArrivalTime":1710508163756}
{"op":"mcm","id":2,"clk":"ANmAAQDkrwEA4MMB","pt":1710508163811,"mc":[{"id":"1.226122413","rc":[{"tv":14176.72,"batb":[[1,5.1,47.78],[0,5.2,38.87]],"trd":[[5.2,43.15]],"batl":[],"id":41122648},{"batl":[[0,2.02,44.15]],"id":51922},{"batl":[[0,55,13.7]],"id":49744721}],"tv":167119.7}],"ArrivalTime":1710508163817}
{"op":"mcm","id":2,"clk":"AOKAAQDrrwEA68MB","pt":1710508163911,"mc":[{"id":"1.226122413","rc":[{"batb":[[0,420,3.59]],"batl":[],"id":54370634},{"batl":[[2,65,5.65]],"id":49744721},{"tv":23042.32,"batb":[[0,4.5,69.86]],"trd":[[4.5,3363.88]],"id":50466254},{"batb":[[0,170,3.67]],"id":66251581}],"tv":167121.7}],"ArrivalTime":1710508163918}
{"op":"mcm","id":2,"clk":"AOyAAQD9rwEA/8MB","pt":1710508164117,"mc":[{"id":"1.226122413","rc":[{"tv":14178.28,"batb":[[0,5.2,38.09]],"trd":[[5.2,44.71]],"id":41122648},{"tv":119963.93,"batb":[[0,2,141.32]],"trd":[[2,1671.65]],"batl":[[2,2.06,61.99]],"id":51922},{"batb":[[0,50,65.69]],"id":49744721}],"tv":167323.26}],"ArrivalTime":1710508164124}
{"op":"mcm","id":2,"clk":"APKAAQCIsAEAh8QB","pt":1710508164219,"mc":[{"id":"1.226122413","rc":[{"tv":479.42,"batb":[[0,420,3.18]],"trd":[[440,11.52]],"ltp":440,"id":54370634},{"batb":[[2,5,89.42]],"id":41122648},{"batb":[[0,170,7.81]],"id":66251581}],"tv":167324.06}],"ArrivalTime":1710508164226}
{"op":"mcm","id":2,"clk":"APiAAQCYsAEAlMQB","pt":1710508164340,"mc":[{"id":"1.226122413","rc":[{"tv":14192.88,"batb":[[0,5.2,40.43]],"trd":[[5.3,224.66]],"ltp":5.3,"batl":[[0,5.3,23.24]],"id":41122648},{"tv":567.88,"batb":[[0,350,6.27]],"trd":[[360,12.76]],"batl":[[0,410,1.49]],"id":41200638},{"batb":[[0,2,207.32]],"batl":[[0,2.02,64.2]],"id":51922}],"tv":167340.14}],"ArrivalTime":1710508164347}
{"op":"mcm","id":2,"clk":"AP6AAQCasAEAmsQB","pt":1710508164423,"mc":[{"id":"1.226122413","rc":[{"batl":[[2,580,1.22]],"id":54370634},{"batb":[[0,5.2,59.71]],"id":41122648},{"batb":[[0,2,227.57]],"id":51922}]}],"ArrivalTime":1710508164430}
{"op":"mcm","id":2,"clk":"AIOBAQCosAEApcQB","pt":1710508164539,"mc":[{"id":"1.226122413","rc":[{"batb":[[1,5.1,45.34],[0,5.2,57.37]],"batl":[[2,5.5,60.5]],"id":41122648},{"tv":568.4,"trd":[[360,13.28]],"batl":[[0,410,1.23]],"id":41200638},{"tv":120150.91,"batb":[[2,1.98,278.94],[0,2,134.08]],"trd":[[2,1858.63]],"batl":[[0,2.02,103.32]],"id":51922},{"batl":[[0,4.6,35.7]],"id":50466254}],"tv":167527.64}],"ArrivalTime":1710508164546}
{"op":"mcm","id":2,"clk":"AIiBAQCusAEAq8QB","pt":1710508164633,"mc":[{"id":"1.226122413","rc":[{"batb":[[0,5.2,38.48]],"id":41122648},{"tv":569.38,"trd":[[410,10.44]],"ltp":410,"batl":[[2,480,3.17],[1,450,1.84],[0,420,2.74]],"id":41200638},{"batb":[[2,4.3,116.12]],"id":50466254},{"batb":[[0,170,5.46]],"id":66251581}],"tv":167528.62}],"ArrivalTime":1710508164640}
{"op":"mcm","id":2,"clk":"AI2BAQC4sAEAtcQB","pt":1710508164746,"mc":[{"id":"1.226122413","rc":[{"batb":[[1,1.99,166.5]],"batl":[[1,2.04,111.16]],"id":51922}]}],"ArrivalTime":1710508164753}
{"op":"mcm","id":2,"clk":"AJCBAQDBsAEAvMQB","pt":1710508164843,"mc":[{"id":"1.226122413","rc":[{"batl":[[2,5.5,62.89]],"id":41122648},{"batb":[[0,2,145.08]],"id":51922},{"batl":[[2,210,7.49]],"id":66251581}]}],"ArrivalTime":1710508164850}
{"op":"mcm","id":2,"clk":"AJeBAQDNsAEAwsQB","pt":1710508164939,"mc":[{"id":"1.226122413","rc":[{"tv":14193.68,"batb":[[0,5.2,38.08]],"trd":[[5.2,45.51]],"ltp":5.2,"batl":[[2,5.5,66.89]],"id":41122648},{"tv":2785.88,"batb":[[0,25,21.18]],"trd":[[25,526.78]],"id":55632148}],"tv":167529.74}],"ArrivalTime":1710508164946}
{"op":"mcm","id":2,"clk":"AKGBAQDYsAEA2MQB","pt":1710508165059,"mc":[{"id":"1.226122413","rc":[{"tv":120176.91,"batb":[[0,2,135.08]],"trd":[[2.02,61.34],[2,1878.63]],"batl":[[0,2.02,100.32]],"id":51922}],"tv":167555.74}],"ArrivalTime":1710508165066}
{"op":"mcm","id":2,"clk":"AK2BAQDqsAEA5sQB","pt":1710508165263,"mc":[{"id":"1.226122413","rc":[{"batb":[[1,340,1.89]],"id":41200638},{"tv":120196.91,"batb":[[0,2,125.08]],"trd":[[2,1898.63]],"id":51922},{"batl":[[0,4.6,35.2]],"id":50466254}],"tv":167575.74}],"ArrivalTime":1710508165270}
{"op":"mcm","id":2,"clk":"ALOBAQDxsAEA7cQB","pt":1710508165307,"mc":[{"id":"1.226122413","rc":[{"tv":120198.07,"batb":[[0,2,124.5]],"trd":[[2,1899.79]],"id":51922},{"tv":3018.8,"batb":[[0,50,63.69]],"trd":[[50,96.04]],"ltp":50,"id":49744721},{"batb":[[2,160,34.96],[1,170,5.29],[0,180,1.52]],"id":66251581}],"tv":167580.9}],"ArrivalTime":1710508165313}
{"op":"mcm","id":2,"clk":"ALqBAQD9sAEA9cQB","pt":1710508165466,"mc":[{"id":"1.226122413","rc":[{"batb":[[2,5,101.42],[1,5.1,57.34]],"id":41122648},{"batb":[[0,350,6.57]],"id":41200638},{"batb":[[1,1.99,214.5],[0,2,127.5]],"id":51922},{"batb":[[2,4.3,129.12],[1,4.4,158.53]],"batl":[[0,4.6,58.18]],"id":50466254},{"batb":[[0,180,2.52]],"id":66251581}]}],"ArrivalTime":1710508165473}
{"op":"mcm","id":2,"clk":"AMmBAQCOsQEAg8UB","pt":1710508165621,"mc":[{"id":"1.226122413","rc":[{"tv":14216.9,"trd":[[5.3,247.88]],"ltp":5.3,"batl":[[0,5.3,11.63]],"id":41122648},{"tv":2803.38,"batb":[[0,25,12.43]],"trd":[[25,544.28]],"id":55632148},{"tv":120203.39,"batb":[[0,2,124.84]],"trd":[[2,1905.11]],"batl":[[0,2.02,102.32]],"id":51922},{"tv":3029.51,"trd":[[55,47.83]],"ltp":55,"batl":[[0,55,8.34]],"id":49744721}],"tv":167637.65}],"ArrivalTime":1710508165627}
{"op":"mcm","id":2,"clk":"ANGBAQCUsQEAjsUB","pt":1710508165722,"mc":[{"id":"1.226122413","rc":[{"batb":[[1,1.99,314.5]],"batl":[],"id":51922},{"batl":[[0,36,1.66]],"id":106596}]}],"ArrivalTime":1710508165729}
{"op":"mcm","id":2,"clk":"ANaBAQCasQEAlMUB","pt":1710508165827,"mc":[{"id":"1.226122413","rc":[{"batb":[[1,5.1,59.78],[0,5.2,50.19]],"id":41122648},{"batb":[[1,4.4,155.11]],"id":50466254}]}],"ArrivalTime":1710508165834}
{"op":"mcm","id":2,"clk":"AN6BAQCgsQEAn8UB","pt":1710508165929,"mc":[{"id":"1.226122413","rc":[{"batb":[[1,5.1,57.34],[0,5.2,47.85]],"batl":[[0,5.3,14.65]],"id":41122648},{"batb":[[0,50,67.98]],"id":49744721}]}],"ArrivalTime":1710508165936}
{"op":"mcm","id":2,"clk":"AOKBAQCjsQEAqMUB","pt":1710508166033,"mc":[{"id":"1.226122413","rc":[{"batb":[[1,5.1,59.78]],"batl":[[0,5.3,12.91]],"id":41122648},{"tv":120237.55,"batb":[[0,2,107.76]],"trd":[[2,1939.27]],"id":51922}],"tv":167671.81}],"ArrivalTime":1710508166040}
{"op":"mcm","id":2,"clk":"AOiBAQCnsQEArsUB","pt":1710508166136,"mc":[{"id":"1.226122413","rc":[{"batb":[[2,5,122.77]],"id":41122648},{"tv":120249.55,"batb":[[2,1.98,160.14],[0,2,101.76]],"trd":[[2,1951.27]],"batl":[[0,2.02,82.27]],"id":51922}],"tv":167683.81}],"ArrivalTime":1710508166143}
{"op":"mcm","id":2,"clk":"APCBAQCwsQEAusUB","pt":1710508166244,"mc":[{"id":"1.226122413","rc":[{"batb":[[1,5.1,57.34]],"batl":[[0,5.3,3.02]],"id":41122648},{"batl":[[2,450,1.84],[1,420,2.74],[0,400,1.8]],"id":41200638},{"tv":120255.55,"batb":[[0,2,98.76]],"trd":[[2,1957.27]],"id":51922},{"tv":2598.2,"batb":[[0,34,26.79]],"trd":[[34,163.21]],"ltp":34,"id":106596}],"tv":167695.81}],"ArrivalTime":1710508166250}
{"op":"mcm","id":2,"clk":"APyBAQC9sQEAwsUB","pt":1710508166343,"mc":[{"id":"1.226122413","rc":[{"batl":[[0,5.3,33.51]],"id":41122648},{"batl":[[2,28,11.68],[1,27,28.41],[0,26,2.96]],"id":55632148},{"batb":[[2,1.98,255.97],[0,2,189.14]],"batl":[[0,2.02,102.72]],"id":51922},{"batl":[[0,55,10.73]],"id":49744721},{"batb":[[0,180,4.6]],"id":66251581}]}],"ArrivalTime":1710508166350}
{"op":"mcm","id":2,"clk":"AIKCAQDHsQEAycUB","pt":1710508166444,"mc":[{"id":"1.226122413","rc":[{"tv":14239.72,"trd":[[5.3,270.7]],"batl":[[0,5.3,22.1]],"id":41122648},{"tv":120306.57,"trd":[[2.02,112.36]],"ltp":2.02,"batl":[[0,2.02,77.21]],"id":51922},{"batl":[[1,4.7,141.11]],"id":50466254},{"tv":710.35,"batb":[[2,150,4.08],[1,160,34.96],[0,170,5.29]],"trd":[[180,53.28]],"batl":[[2,200,4.19],[1,190,1.61],[0,180,6.4]],"id":66251581}],"tv":167778.85}],"ArrivalTime":1710508166451}
{"op":"mcm","id":2,"clk":"AIiCAQDQsQEA0cUB","pt":1710508166555,"mc":[{"id":"1.226122413","rc":[{"batb":[[2,5,120.21]],"batl":[[0,5.3,31.7]],"id":41122648},{"batb":[[0,350,8.57]],"id":41200638},{"tv":120460.99,"trd":[[2.02,266.78]],"batl":[[2,2.08,60.34],[1,2.06,61.99],[0,2.04,111.16]],"id":51922},{"tv":3029.67,"batb":[[0,50,67.9]],"trd":[[50,96.2]],"ltp":50,"id":49744721},{"batb":[[0,170,1.15]],"id":66251581}],"tv":167933.43}],"ArrivalTime":1710508166562}
{"op":"mcm","id":2,"clk":"AI2CAQDasQEA1cUB","pt":1710508166649,"mc":[{"id":"1.226122413","rc":[{"tv":14243.72,"batb":[[0,5.2,45.85]],"trd":[[5.2,49.51]],"ltp":5.2,"batl":[[0,5.3,43.45]],"id":41122648},{"tv":2804.94,"batb":[[2,23,16.45],[0,25,11.65]],"trd":[[25,545.84]],"id":55632148},{"tv":120511.99,"batb":[[0,2,184.97]],"trd":[[2.02,267.9],[2,2007.15]],"ltp":2,"batl":[[2,2.06,61.99],[1,2.04,111.16],[0,2.02,16.47]],"id":51922},{"tv":23100.88,"batb":[[0,4.5,45.57]],"trd":[[4.6,1851.36],[4.5,3412.46]],"ltp":4.6,"batl":[[0,4.6,65.88]],"id":50466254},{"batl":[[1,190,1.93],[0,180,7.72]],"id":66251581}],"tv":168048.55}],"ArrivalTime":1710508166658}
{"op":"mcm","id":2,"clk":"AJGCAQDnsQEA38UB","pt":1710508166752,"mc":[{"id":"1.226122413","rc":[{"tv":14247.72,"batb":[[2,5,122.77],[0,5.2,34.08]],"trd":[[5.2,53.51]],"id":41122648},{"batl":[[1,420,2]],"id":41200638},{"batb":[[0,25,4.02]],"id":55632148},{"tv":120564.93,"batb":[[2,1.99,314.5],[1,2,94.59],[0,2.02,41.97]],"trd":[[2.04,62.66],[2.02,300.84]],"ltp":2.04,"batl":[[2,2.08,55.84],[1,2.06,61.99],[0,2.04,101.16]],"id":51922},{"batb":[[2,4.3,125.51],[0,4.5,31.8]],"id":50466254},{"tv":727.79,"batb":[[2,140,3.81],[1,150,4.08],[0,160,34.96]],"trd":[[180,68.72],[170,47.18]],"ltp":170,"batl":[[2,210,7.49],[1,200,4.19],[0,190,1.93]],"id":66251581}],"tv":168122.93}],"ArrivalTime":1710508166759}
{"op":"mcm","id":2,"clk":"AJaCAQD4sQEA6cUB","pt":1710508166881,"mc":[{"id":"1.226122413","rc":[{"tv":14251.72,"batb":[[0,5.2,22.39]],"trd":[[5.3,274.7]],"ltp":5.3,"batl":[[0,5.3,41.45]],"id":41122648},{"batb":[[0,350,8.8]],"id":41200638},{"batb":[[0,2.02,73.33]],"batl":[],"id":51922},{"tv":23102.88,"batb":[[0,4.5,6.7]],"trd":[[4.5,3414.46]],"ltp":4.5,"id":50466254}],"tv":168128.93}],"ArrivalTime":1710508166888}
{"op":"mcm","id":2,"clk":"AJyCAQCAsgEA9MUB","pt":1710508166967,"mc":[{"id":"1.226122413","rc":[{"batb":[[0,5.2,11.39]],"id":41122648},{"batl":[[2,28,12.37]],"id":55632148},{"tv":120628.85,"batb":[[2,1.99,295.5],[1,2,184.97],[0,2.02,135.97]],"trd":[[2.04,126.58]],"batl":[[2,2.08,60.34],[1,2.06,99.57],[0,2.04,31.67]],"id":51922},{"tv":23139.24,"batb":[[2,4.2,168.56],[1,4.3,125.51],[0,4.4,155.11]],"trd":[[4.5,3450.82]],"batl":[[2,4.7,145.11],[1,4.6,65.88],[0,4.5,12.93]],"id":50466254},{"batb":[[2,150,4.08],[1,160,39.1],[0,170,1.4]],"id":66251581}],"tv":168229.21}],"ArrivalTime":1710508166973}
{"op":"mcm","id":2,"clk":"AKWCAQCGsgEA9sUB","pt":1710508167020,"mc":[{"id":"1.226122413","rc":[{"batl":[[2,5.5,64.5]],"id":41122648},{"tv":2812.98,"batb":[[2,22,32.54],[1,23,16.45],[0,24,17.72]],"trd":[[25,553.88]],"batl":[[2,27,28.41],[1,26,2.96],[0,25,3.98]],"id":55632148},{"batb":[[1,2,187.54],[0,2.02,145.97]],"id":51922},{"batl":[[0,4.5,14.49]],"id":50466254},{"batb":[],"batl":[[2,210,5.96]],"id":66251581}],"tv":168237.25}],"ArrivalTime":1710508167027}
{"op":"mcm","id":2,"clk":"AKuCAQCWsgEAhsYB","pt":1710508167181,"mc":[{"id":"1.226122413","rc":[{"tv":14274.5,"batb":[[2,4.9,137.72],[1,5,122.77],[0,5.1,57.34]],"trd":[[5.2,76.29]],"ltp":5.2,"batl":[[2,5.5,66.89],[0,5.3,53.95]],"id":41122648},{"batb":[[1,23,19.45]],"batl":[[1,26,3.48],[0,25,8.74]],"id":55632148},{"tv":120651.75,"batb":[[1,2,97.16]],"trd":[[2.04,149.48]],"batl":[[2,2.08,55.84],[0,2.04,20.22]],"id":51922},{"tv":23165.1,"batb":[[2,4.2,181.56],[1,4.3,129.12],[0,4.4,133.76]],"trd":[[4.5,3476.68]],"batl":[[2,4.7,145.96],[0,4.5,47.84]],"id":50466254},{"batb":[[0,170,2.4]],"batl":[[1,200,5.79]],"id":66251581}],"tv":168308.79}],"ArrivalTime":1710508167188}
{"op":"mcm","id":2,"clk":"ALmCAQCbsgEAkcYB","pt":1710508167226,"mc":[{"id":"1.226122413","rc":[{"tv":23205.1,"batb":[[1,4.3,125.51]],"trd":[[4.5,3516.68]],"batl":[[0,4.5,27.84]],"id":50466254}],"tv":168348.79}],"ArrivalTime":1710508167233}
{"op":"mcm","id":2,"clk":"ALuCAQCksgEAnMYB","pt":1710508167325,"mc":[{"id":"1.226122413","rc":[{"tv":484.04,"trd":[[520,9.76]],"ltp":520,"batl":[[2,610,1.22],[1,580,1.22],[0,530,4.42]],"id":54370634},{"batb":[[1,5,120.21]],"batl":[[0,5.3,33.85]],"id":41122648},{"batl":[[2,440,2.95]],"id":41200638},{"batb":[[1,23,24.62]],"batl":[[0,25,11.24]],"id":55632148},{"tv":120751.75,"batb":[[0,2.02,594.48]],"trd":[[2.02,400.84]],"ltp":2.02,"batl":[],"id":51922},{"batl":[[0,4.5,51.49]],"id":50466254},{"batb":[[2,160,39.1],[1,170,2.4],[0,180,1.3]],"id":66251581}],"tv":168453.41}],"ArrivalTime":1710508167332}
{"op":"mcm","id":2,"clk":"AMCCAQCrsgEAo8YB","pt":1710508167435,"mc":[{"id":"1.226122413","rc":[{"tv":486.05,"batb":[[0,420,2.22]],"trd":[[440,11.93],[420,6.67]],"ltp":420,"id":54370634},{"batb":[[2,5,120.21],[1,5.1,57.34],[0,5.2,2.88]],"id":41122648},{"batb":[[0,350,8.84]],"id":41200638},{"batb":[[0,24,18.34]],"id":55632148},{"tv":120788.69,"batb":[[2,1.99,316.85],[0,2.02,601.91]],"trd":[[2.04,186.42]],"ltp":2.04,"batl":[[0,2.04,1.75]],"id":51922},{"batb":[[0,50,68.2]],"id":49744721},{"batb":[[0,4.4,137.17]],"batl":[[1,4.6,68.45]],"id":50466254},{"tv":729.79,"batb":[[2,150,4.08],[1,160,39.1],[0,170,2.79]],"trd":[[180,70.72]],"ltp":180,"id":66251581},{"batb":[[0,34,27.23]],"id":106596}],"tv":168494.36}],"ArrivalTime":1710508167442}
{"op":"mcm","id":2,"clk":"AMqCAQC6sgEArcYB","pt":1710508167534,"mc":[{"id":"1.226122413","rc":[{"tv":486.06,"trd":[[530,0.01]],"ltp":530,"batl":[[0,530,4.41]],"id":54370634},{"tv":14280.95,"batb":[[2,4.9,137.72],[1,5,122.77],[0,5.1,57.34]],"trd":[[5.2,82.74]],"batl":[[2,5.4,68.71],[1,5.3,33.85],[0,5.2,16.92]],"id":41122648},{"tv":569.39,"trd":[[400,23.88]],"ltp":400,"batl":[[0,400,1.79]],"id":41200638},{"tv":2813.74,"trd":[[25,554.64]],"batl":[[0,25,10.79]],"id":55632148},{"tv":120790.44,"trd":[[2.04,188.17]],"batl":[[2,2.1,148.84],[1,2.08,55.84],[0,2.06,99.57]],"id":51922},{"tv":3029.73,"trd":[[55,47.89]],"ltp":55,"batl":[[0,55,10.67]],"id":49744721},{"tv":23205.89,"batb":[[0,4.4,139.17]],"trd":[[4.5,3517.47]],"batl":[[0,4.5,50.7]],"id":50466254},{"tv":729.81,"trd":[[190,57.8]],"ltp":190,"batl":[[0,190,1.91]],"id":66251581},{"tv":2598.3,"trd":[[36,60.47]],"ltp":36,"batl":[[0,36,1.56]],"id":106596}],"tv":168504.31}],"ArrivalTime":1710508167541}
{"op":"mcm","id":2,"clk":"ANCCAQDAsgEAt8YB","pt":1710508167636,"mc":[{"id":"1.226122413","rc":[{"batb":[[1,5,101.42]],"batl":[[2,5.4,71.71]],"id":41122648},{"tv":570.44,"batb":[[0,350,8.31]],"trd":[[370,19.45],[360,13.88]],"ltp":360,"batl":[[0,400,2.51]],"id":41200638},{"batb":[[2,2,97.16],[1,2.02,601.91],[0,2.04,20.18]],"batl":[],"id":51922},{"tv":23261.93,"trd":[[4.5,3573.51]],"batl":[[2,4.7,149.06],[0,4.5,29.17]],"id":50466254}],"tv":168561.4}],"ArrivalTime":1710508167643}
{"op":"mcm","id":2,"clk":"ANmCAQDKsgEAv8YB","pt":1710508167741,"mc":[{"id":"1.226122413","rc":[{"batb":[[1,5,118.61]],"id":41122648},{"batb":[[0,24,9.62]],"batl":[],"id":55632148},{"batb":[[1,2.02,531.46],[0,2.04,42.5]],"batl":[],"id":51922},{"tv":23274.91,"batb":[[2,4.3,125.51],[1,4.4,139.17],[0,4.5,44.78]],"trd":[[4.5,3586.49]],"batl":[[2,4.8,34.64],[1,4.7,149.06],[0,4.6,68.45]],"id":50466254}],"tv":168574.38}],"ArrivalTime":1710508167748}
{"op":"mcm","id":2,"clk":"AOeCAQDVsgEAzMYB","pt":1710508167865,"mc":[{"id":"1.226122413","rc":[{"batb":[[2,4.9,149.72],[0,5.1,38.84]],"id":41122648},{"batb":[[0,24,6.76]],"id":55632148},{"batb":[[1,2.02,544.03],[0,2.04,197.75]],"batl":[],"id":51922}]}],"ArrivalTime":1710508167872}
{"op":"mcm","id":2,"clk":"AOiCAQDbsgEA1cYB","pt":1710508167947,"mc":[{"id":"1.226122413","rc":[{"batb":[[1,5,116.05]],"batl":[[0,5.2,26.56]],"id":41122648},{"batb":[[1,2.02,568.32]],"batl":[[1,2.08,92.62]],"id":51922},{"batb":[[0,4.5,57.78]],"id":50466254}]}],"ArrivalTime":1710508167954}
{"op":"mcm","id":2,"clk":"APGCAQDhsgEA4cYB","pt":1710508168053,"mc":[{"id":"1.226122413","rc":[{"batb":[[0,5.1,24.09]],"batl":[[2,5.4,84.21],[0,5.2,34.29]],"id":41122648},{"tv":574.44,"batb":[[0,350,6.31]],"trd":[[350,7.08]],"ltp":350,"batl":[],"id":41200638},{"batb":[[2,22,24.16]],"batl":[],"id":55632148},{"tv":120800.44,"batb":[[2,2,116.87],[1,2.02,618.32],[0,2.04,192.75]],"trd":[[2.04,198.17]],"batl":[[2,2.1,153.33]],"id":51922},{"batl":[[0,55,12.14]],"id":49744721},{"batb":[[0,4.5,13]],"batl":[],"id":50466254},{"batl":[[2,40,14.67]],"id":106596}],"tv":168588.38}],"ArrivalTime":1710508168060}
{"op":"mcm","id":2,"clk":"AP+CAQD1sgEA8MYB","pt":1710508168270,"mc":[{"id":"1.226122413","rc":[{"batb":[[1,5,78.88],[0,5.1,13.81]],"id":41122648},{"batl":[[1,420,2.28]],"id":41200638},{"batl":[[0,2.06,79.04]],"id":51922},{"batb":[[2,4.2,202.91],[1,4.3,125.51],[0,4.4,139.17]],"id":50466254}]}],"ArrivalTime":1710508168276}
{"op":"mcm","id":2,"clk":"AIaDAQCDswEA8sYB","pt":1710508168365,"mc":[{"id":"1.226122413","rc":[{"tv":120830.44,"trd":[[2.06,65.02]],"ltp":2.06,"batl":[[0,2.06,66.04]],"id":51922},{"tv":3034.85,"trd":[[55,53.01]],"batl":[[0,55,9.58]],"id":49744721}],"tv":168623.5}],"ArrivalTime":1710508168372}
{"op":"mcm","id":2,"clk":"AIuDAQCOswEA+sYB","pt":1710508168466,"mc":[{"id":"1.226122413","rc":[{"batb":[[0,420,2.57]],"id":54370634},{"tv":576.44,"batb":[[0,350,5.31]],"trd":[[350,9.08]],"id":41200638},{"batl":[[0,2.06,28.46]],"id":51922},{"batb":[[2,4.2,199.09]],"batl":[],"id":50466254}],"tv":168625.5}],"ArrivalTime":1710508168473}
{"op":"mcm","id":2,"clk":"AJGDAQCZswEAhMcB","pt":1710508168523,"mc":[{"id":"1.226122413","rc":[{"batl":[[2,2.1,53.33],[0,2.06,35.58]],"id":51922}]}],"ArrivalTime":1710508168530}
{"op":"mcm","id":2,"clk":"AJWDAQCiswEAjccB","pt":1710508168620,"mc":[{"id":"1.226122413","rc":[{"tv":14287.87,"batb":[[1,5,57.53],[0,5.1,11.06]],"trd":[[5.2,84.16],[5.1,5.5]],"ltp":5.1,"batl":[[0,5.2,33.58]],"id":41122648},{"tv":121030.44,"batb":[[2,2,138.22],[1,2.02,501.86],[0,2.04,103.75]],"trd":[[2.04,398.17]],"ltp":2.04,"id":51922}],"tv":168832.42}],"ArrivalTime":1710508168627}
{"op":"mcm","id":2,"clk":"AJyDAQCuswEAmccB","pt":1710508168741,"mc":[{"id":"1.226122413","rc":[{"tv":14294.13,"batb":[[0,5.1,7.93]],"trd":[[5.1,11.76]],"id":41122648},{"tv":2814.44,"trd":[[25,555.34]],"batl":[[0,25,10.44]],"id":55632148},{"tv":121030.52,"trd":[[2.06,65.1]],"ltp":2.06,"batl":[[0,2.06,105.05]],"id":51922}],"tv":168839.46}],"ArrivalTime":1710508168748}
{"op":"mcm","id":2,"clk":"AKSDAQCyswEAoscB","pt":1710508168853,"mc":[{"id":"1.226122413","rc":[{"batb":[[2,4.8,36.14],[1,4.9,149.72],[0,5,57.53]],"id":41122648},{"batb":[[2,320,2.61]],"id":41200638},{"tv":121244.62,"batb":[[2,2.02,501.86],[1,2.04,103.75],[0,2.06,22.14]],"trd":[[2.06,279.2]],"batl":[[2,2.12,26.47],[1,2.1,53.33],[0,2.08,92.62]],"id":51922},{"batl":[[2,4.7,149.06],[1,4.6,68.45],[0,4.5,2]],"id":50466254}],"tv":169053.56}],"ArrivalTime":1710508168860}
{"op":"mcm","id":2,"clk":"AKqDAQC5swEAqccB","pt":1710508168932,"mc":[{"id":"1.226122413","rc":[{"tv":14308.41,"trd":[[5.2,98.44]],"ltp":5.2,"batl":[[2,5.3,33.85],[1,5.2,26.44],[0,5.1,12.5]],"id":41122648},{"batl":[[1,26,9.1],[0,25,11.05]],"id":55632148},{"tv":121288.9,"batb":[[2,2,157.95],[1,2.02,501.86],[0,2.04,216.62]],"trd":[[2.06,323.48]],"batl":[[2,2.1,53.33],[1,2.08,92.62],[0,2.06,1.71]],"id":51922},{"tv":741.81,"trd":[[200,48.43],[190,61.62]],"ltp":200,"batl":[[2,230,2],[1,210,5.96],[0,200,1.7]],"id":66251581},{"tv":2600.3,"batb":[[0,34,26.23]],"trd":[[34,165.21]],"ltp":34,"id":106596}],"tv":169126.12}],"ArrivalTime":1710508168939}
{"op":"mcm","id":2,"clk":"ALODAQDJswEAs8cB","pt":1710508169047,"mc":[{"id":"1.226122413","rc":[{"tv":14333.41,"batb":[[2,4.9,147.04],[1,5,60.09],[0,5.1,8.22]],"trd":[[5.1,36.76]],"ltp":5.1,"batl":[[2,5.4,84.21],[1,5.3,33.85],[0,5.2,31.28]],"id":41122648},{"tv":576.48,"batb":[[0,350,5.29]],"trd":[[350,9.12]],"id":41200638},{"tv":121312.3,"batb":[[2,2.02,501.86],[1,2.04,136.56],[0,2.06,28.71]],"trd":[[2.06,346.88]],"batl":[[2,2.12,26.47],[1,2.1,53.33],[0,2.08,92.62]],"id":51922},{"batl":[[0,55,11.58]],"id":49744721},{"tv":23278.91,"batb":[[2,4.3,129.12],[1,4.4,139.17],[0,4.5,27.7]],"trd":[[4.5,3590.49]],"batl":[[2,4.8,34.64],[1,4.7,149.06],[0,4.6,68.45]],"id":50466254},{"batb":[[1,160,34.96]],"batl":[[0,200,1.6]],"id":66251581}],"tv":169178.56}],"ArrivalTime":1710508169054}
{"op":"mcm","id":2,"clk":"ALSDAQDRswEAvMcB","pt":1710508169137,"mc":[{"id":"1.226122413","rc":[{"batb":[[2,4.9,149.72]],"id":41122648},{"tv":576.88,"trd":[[360,14.28]],"ltp":360,"batl":[[0,400,2.31]],"id":41200638},{"batb":[[2,160,34.96],[1,170,2.49],[0,180,1.28]],"id":66251581},{"batb":[[0,34,27.73]],"id":106596}],"tv":169178.96}],"ArrivalTime":1710508169144}
{"op":"mcm","id":2,"clk":"AL+DAQDdswEAxMcB","pt":1710508169246,"mc":[{"id":"1.226122413","rc":[{"batb":[[2,410,1.67],[1,420,2.57],[0,440,2.72]],"id":54370634},{"batb":[[2,4.8,120.28],[1,4.9,147.04],[0,5,57.53]],"batl":[[0,5.2,42.35]],"id":41122648},{"tv":2820.16,"batb":[[0,24,3.9]],"trd":[[24,305.09]],"ltp":24,"batl":[[0,25,11.24]],"id":55632148},{"tv":121379.72,"batb":[[2,2.02,562.21],[1,2.04,131.56],[0,2.06,87.75]],"trd":[[2.04,408.17],[2.06,404.3]],"ltp":2.04,"batl":[[2,2.12,30.73]],"id":51922},{"tv":23285.99,"batb":[[2,4.2,199.09],[1,4.3,125.51],[0,4.4,139.17]],"trd":[[4.6,1858.44]],"ltp":4.6,"batl":[[0,4.6,64.91]],"id":50466254},{"batb":[[1,170,2.79],[0,190,4.04]],"id":66251581}],"tv":169259.18}],"ArrivalTime":1710508169252}
{"op":"mcm","id":2,"clk":"AMGDAQDmswEA0McB","pt":1710508169350,"mc":[{"id":"1.226122413","rc":[{"batb":[[2,4.8,117.48]],"batl":[],"id":41122648},{"tv":121379.74,"batb":[[0,2.06,117.74]],"trd":[[2.06,404.32]],"ltp":2.06,"batl":[[2,2.12,26.47]],"id":51922},{"batb":[[2,170,2.49],[1,180,1.33],[0,190,5.23]],"batl":[[2,240,3.29],[1,230,2],[0,210,5.96]],"id":66251581}],"tv":169259.2}],"ArrivalTime":1710508169357}
{"op":"mcm","id":2,"clk":"AMqDAQDwswEA2scB","pt":1710508169461,"mc":[{"id":"1.226122413","rc":[{"batb":[[2,420,2.22],[1,430,1.64]],"batl":[[2,670,1.13],[1,600,1.22]],"id":54370634},{"batb":[[0,5,47.25]],"batl":[[0,5.2,33.79]],"id":41122648},{"batb":[[0,24,3.99]],"id":55632148},{"tv":121542.78,"batb":[[2,2.02,527.57],[1,2.04,241.4],[0,2.06,91.22]],"trd":[[2.06,567.36]],"id":51922},{"batl":[[1,60,25.57]],"id":49744721},{"batb":[[1,180,2.97]],"batl":[[1,230,1.26]],"id":66251581}],"tv":169422.24}],"ArrivalTime":1710508169468}
{"op":"mcm","id":2,"clk":"ANGDAQD3swEA5McB","pt":1710508169557,"mc":[{"id":"1.226122413","rc":[{"batl":[[1,5.3,36.33]],"id":41122648},{"batl":[[0,400,2.54]],"id":41200638},{"batl":[[2,230,1.26],[1,220,1.46],[0,210,4.93]],"id":66251581}]}],"ArrivalTime":1710508169564}
{"op":"mcm","id":2,"clk":"ANmDAQD+swEA7scB","pt":1710508169661,"mc":[{"id":"1.226122413","rc":[{"tv":14347.69,"batb":[[0,5,73.17]],"trd":[[5.1,51.04]],"batl":[[2,5.3,36.33],[1,5.2,33.28],[0,5.1,2.62]],"id":41122648},{"batl":[[2,27,29.15],[1,26,9.9],[0,25,12.11]],"id":55632148},{"tv":121645.81,"batb":[[0,2.06,39.7]],"trd":[[2.06,670.39]],"batl":[[0,2.08,142.62]],"id":51922}],"tv":169539.55}],"ArrivalTime":1710508169667}
{"op":"mcm","id":2,"clk":"AOSDAQCOtAEA+8cB","pt":1710508169777,"mc":[{"id":"1.226122413","rc":[{"tv":14447.69,"batb":[[0,5,23.18]],"trd":[[5,100]],"ltp":5,"id":41122648}],"tv":169639.55}],"ArrivalTime":1710508169783}
{"op":"mcm","id":2,"clk":"AOaDAQCUtAEAgcgB","pt":1710508169872,"mc":[{"id":"1.226122413","rc":[{"tv":14452.93,"batb":[[2,4.9,149.72],[1,5,23.18],[0,5.1,13.8]],"trd":[[5.1,56.28]],"ltp":5.1,"batl":[[2,5.4,81.44],[1,5.3,36.33],[0,5.2,33.28]],"id":41122648},{"batb":[[0,2.06,89.44]],"id":51922},{"batb":[[0,4.4,141.15]],"id":50466254}],"tv":169644.79}],"ArrivalTime":1710508169879}
{"op":"mcm","id":2,"clk":"AO2DAQCZtAEAisgB","pt":1710508169978,"mc":[{"id":"1.226122413","rc":[{"tv":14477.43,"batb":[[2,4.9,167.07],[1,5,23.11],[0,5.1,1.55]],"trd":[[5.1,80.78]],"batl":[[2,5.4,96.44]],"id":41122648},{"tv":121655.07,"batb":[[0,2.06,117.01]],"trd":[[2.06,679.65]],"batl":[],"id":51922},{"batl":[[2,4.7,149.06],[1,4.6,64.91],[0,4.5,1]],"id":50466254}],"tv":169678.55}],"ArrivalTime":1710508169985}
{"op":"mcm","id":2,"clk":"APuDAQCqtAEAmsgB","pt":1710508170096,"mc":[{"id":"1.226122413","rc":[{"tv":14480.53,"batb":[[2,4.8,120.28],[1,4.9,164.39],[0,5,49.74]],"trd":[[5.1,83.88]],"batl":[[2,5.3,36.33],[1,5.2,38.38],[0,5.1,5.91]],"id":41122648},{"tv":121655.29,"batb":[[0,2.06,116.9]],"trd":[[2.06,679.87]],"batl":[[0,2.08,132.34]],"id":51922}],"tv":169681.87}],"ArrivalTime":1710508170103}
{"op":"mcm","id":2,"clk":"AP2DAQCxtAEAoMgB","pt":1710508170143,"mc":[{"id":"1.226122413","rc":[{"batb":[[0,440,3.05]],"id":54370634},{"batl":[[0,5.1,11.64]],"id":41122648},{"tv":577.92,"trd":[[360,15.32]],"batl":[[0,400,2.02]],"id":41200638},{"tv":121665.77,"batb":[[0,2.06,111.66]],"trd":[[2.06,690.35]],"id":51922},{"batb":[[2,4.2,202.91],[0,4.4,146.15]],"id":50466254}],"tv":169693.39}],"ArrivalTime":1710508170150}
{"op":"mcm","id":2,"clk":"AIKEAQC4tAEArcgB","pt":1710508170241,"mc":[{"id":"1.226122413","rc":[{"batb":[[1,4.9,167.07]],"batl":[[2,5.3,73.65]],"id":41122648},{"tv":578.37,"batb":[[2,320,3.19]],"trd":[[390,4.35]],"ltp":390,"batl":[[0,400,1.79]],"id":41200638},{"batb":[[2,22,56.69]],"id":55632148},{"tv":121695.77,"batb":[[0,2.06,134.84]],"trd":[[2.08,252.13]],"ltp":2.08,"batl":[[0,2.08,117.34]],"id":51922},{"batb":[[2,46,26.21]],"batl":[[2,65,11.73]],"id":49744721},{"tv":23287.99,"batb":[[2,4.3,125.51],[1,4.4,146.15],[0,4.5,28.59]],"trd":[[4.5,3592.49]],"ltp":4.5,"batl":[[2,4.8,34.64],[1,4.7,149.06],[0,4.6,64.91]],"id":50466254},{"batb":[[2,170,2.81]],"id":66251581},{"batb":[[2,30,45.83]],"id":106596}],"tv":169725.84}],"ArrivalTime":1710508170249}
{"op":"mcm","id":2,"clk":"AI6EAQDJtAEAwMgB","pt":1710508170500,"mc":[{"id":"1.226122413","rc":[{"batb":[[0,5,82.14]],"batl":[[0,5.1,21.1]],"id":41122648},{"batb":[[2,22,55.34]],"id":55632148},{"tv":121785.17,"batb":[[0,2.06,112.42],[1,2.04,260.23]],"trd":[[2.06,779.75]],"ltp":2.06,"batl":[[0,2.08,125.34]],"id":51922},{"batb":[[0,4.5,65.99]],"batl":[],"id":50466254}],"tv":169815.24,"con":true}],"ArrivalTime":1710508170507}
{"op":"mcm","id":2,"clk":"AJGEAQDQtAEAyMgB","pt":1710508170551,"mc":[{"id":"1.226122413","rc":[{"tv":121798.35,"batb":[[2,2.02,517.57],[0,2.06,107.83]],"trd":[[2.08,256.13],[2.06,788.93]],"batl":[[0,2.08,135.39]],"id":51922}],"tv":169828.42}],"ArrivalTime":1710508170557}
{"op":"mcm","id":2,"clk":"AJyEAQDatAEAzsgB","pt":1710508170652,"mc":[{"id":"1.226122413","rc":[{"tv":121818.51,"batb":[[0,2.06,107.75]],"trd":[[2.08,276.13],[2.06,789.09]],"ltp":2.08,"batl":[[0,2.08,125.39]],"id":51922},{"tv":23337.99,"trd":[[4.6,1908.44]],"ltp":4.6,"batl":[[0,4.6,39.91]],"id":50466254}],"tv":169898.58}],"ArrivalTime":1710508170659}
{"op":"mcm","id":2,"clk":"AJ2EAQDptAEA1cgB","pt":1710508170750,"mc":[{"id":"1.226122413","rc":[{"batb":[[0,440,3.3]],"id":54370634},{"tv":14487.53,"batb":[[0,5,78.64]],"trd":[[5,107]],"ltp":5,"batl":[[0,5.1,33.34]],"id":41122648},{"batb":[[0,350,5.54]],"id":41200638},{"tv":2824.16,"trd":[[25,559.34]],"ltp":25,"batl":[[0,25,10.11]],"id":55632148},{"tv":121866.37,"batb":[[0,2.06,51.62]],"trd":[[2.06,836.95]],"ltp":2.06,"id":51922},{"tv":23381.43,"batb":[[0,4.5,62.18]],"trd":[[4.6,1917.66],[4.5,3626.71]],"ltp":4.5,"batl":[[0,4.6,35.3]],"id":50466254},{"tv":742.31,"trd":[[210,0.68]],"ltp":210,"batl":[[0,210,4.68]],"id":66251581},{"tv":2602.3,"trd":[[36,62.47]],"ltp":36,"batl":[[2,42,11.39],[1,40,14.67],[0,38,13.1]],"id":106596}],"tv":170003.38}],"ArrivalTime":1710508170757}
{"op":"mcm","id":2,"clk":"AKmEAQDstAEA4cgB","pt":1710508170861,"mc":[{"id":"1.226122413","rc":[{"tv":14491.31,"batb":[[0,5,61.66]],"trd":[[5.1,87.66]],"ltp":5.1,"batl":[[0,5.1,31.45]],"id":41122648},{"tv":121947.99,"batb":[[0,2.06,15.81]],"trd":[[2.06,918.57]],"batl":[[0,2.08,130.39]],"id":51922},{"batb":[[2,4.3,207.11]],"id":50466254}],"tv":170088.78}],"ArrivalTime":1710508170868}
{"op":"mcm","id":2,"clk":"AK+EAQD6tAEA7MgB","pt":1710508170961,"mc":[{"id":"1.226122413","rc":[{"tv":14496.31,"batb":[[0,5,49.51]],"trd":[[5,112]],"ltp":5,"id":41122648},{"batb":[[0,24,6.79]],"batl":[[0,25,13.33]],"id":55632148},{"tv":121949.99,"batb":[[1,2.04,280.42],[0,2.06,14.81]],"trd":[[2.06,920.57]],"id":51922},{"batb":[[2,4.3,129.12]],"batl":[],"id":50466254},{"tv":744.71,"batb":[],"trd":[[210,3.08]],"batl":[[0,210,3.48]],"id":66251581}],"tv":170098.18}],"ArrivalTime":1710508170968}
{"op":"mcm","id":2,"clk":"AMCEAQCGtQEA+cgB","pt":1710508171080,"mc":[{"id":"1.226122413","rc":[{"batb":[[2,430,1.64],[1,440,2.72],[0,450,1.12]],"id":54370634},{"tv":14496.51,"batb":[],"trd":[[5.1,87.86]],"ltp":5.1,"batl":[[0,5.1,31.35]],"id":41122648},{"batb":[[0,350,6.22]],"id":41200638},{"tv":122171.92,"batb":[[2,2,162.22],[1,2.02,517.57],[0,2.04,280.42]],"trd":[[2.08,462.07],[2.06,956.56]],"ltp":2.08,"batl":[[2,2.12,30.73],[1,2.1,57.71],[0,2.08,37.42]],"id":51922},{"batb":[[1,4.4,148.15],[0,4.5,76.56]],"id":50466254}],"tv":170320.31}],"ArrivalTime":1710508171087}
{"op":"mcm","id":2,"clk":"AMaEAQCLtQEAhMkB","pt":1710508171179,"mc":[{"id":"1.226122413","rc":[{"tv":14527.96,"trd":[[5.1,119.31]],"batl":[[0,5.1,15.63]],"id":41122648},{"tv":122173.9,"batb":[[2,2.02,517.57],[1,2.04,260.23],[0,2.06,9.01]],"trd":[[2.06,958.54]],"ltp":2.06,"id":51922},{"tv":2611.49,"trd":[[38,21.35],[36,63.6]],"ltp":38,"batl":[[0,38,8.51]],"id":106596}],"tv":170362.93}],"ArrivalTime":1710508171187}
{"op":"mcm","id":2,"clk":"AM+EAQCUtQEAkMkB","pt":1710508171331,"mc":[{"id":"1.226122413","rc":[{"tv":14565.96,"batb":[[0,5,30.51]],"trd":[[5,150]],"ltp":5,"id":41122648},{"batl":[[0,25,12.46]],"id":55632148},{"tv":122180.09,"batb":[[2,2.02,560.27],[0,2.06,41.44]],"trd":[[2.08,463.1],[2.06,963.7]],"batl":[[1,2.1,53.33],[0,2.08,71.55]],"id":51922},{"tv":23383.79,"batb":[[0,4.5,61]],"trd":[[4.5,3629.07]],"batl":[[1,4.7,49.06]],"id":50466254},{"batl":[[0,38,10.51]],"id":106596}],"tv":170409.48}],"ArrivalTime":1710508171338}
{"op":"mcm","id":2,"clk":"ANqEAQCctQEAlskB","pt":1710508171383,"mc":[{"id":"1.226122413","rc":[{"batb":[[1,440,3.72]],"id":54370634},{"tv":14568,"batb":[[0,5,47.55]],"trd":[[5.1,121.35]],"ltp":5.1,"batl":[[0,5.1,20.52]],"id":41122648},{"tv":2826.16,"batb":[[0,24,5.79]],"trd":[[24,307.09]],"ltp":24,"id":55632148},{"batb":[[2,2.02,570.27],[0,2.06,85.08]],"id":51922},{"tv":23758.98,"batb":[[2,4.2,260.1],[1,4.3,129.12],[0,4.4,55.27]],"trd":[[4.4,4472.73],[4.6,1985.1],[4.5,3751.06]],"ltp":4.4,"batl":[[0,4.6,1.59]],"id":50466254},{"batb":[[0,34,30.78]],"id":106596}],"tv":170788.71}],"ArrivalTime":1710508171389}
{"op":"mcm","id":2,"clk":"AOGEAQCgtQEAqckB","pt":1710508171441,"mc":[{"id":"1.226122413","rc":[{"batb":[[1,23,25],[0,24,10.37]],"batl":[[0,25,13.33]],"id":55632148},{"tv":122182.47,"batb":[[0,2.06,83.89]],"trd":[[2.06,966.08]],"batl":[[1,2.1,57.71],[0,2.08,72.55]],"id":51922},{"tv":23759.01,"batb":[[1,4.3,154.5],[0,4.4,55.25]],"trd":[[4.4,4472.76]],"batl":[[2,4.7,49.06],[1,4.6,101.59],[0,4.5,64.09]],"id":50466254}],"tv":170791.12}],"ArrivalTime":1710508171447}
{"op":"mcm","id":2,"clk":"AOmEAQCqtQEAsMkB","pt":1710508171542,"mc":[{"id":"1.226122413","rc":[{"tv":486.16,"batb":[],"trd":[[530,0.11]],"batl":[[0,530,4.36]],"id":54370634},{"tv":14604.18,"batb":[[0,5,29.46]],"trd":[[5,186.18]],"ltp":5,"id":41122648},{"tv":582.37,"trd":[[420,4.48],[400,27.46]],"ltp":420,"batl":[[2,450,1.71],[1,440,2.95],[0,420,2.07]],"id":41200638},{"tv":122212.47,"batb":[[0,2.06,101.58]],"trd":[[2.08,483.1],[2.06,976.08]],"ltp":2.08,"batl":[[1,2.1,91.84],[0,2.08,62.55]],"id":51922},{"tv":23787.61,"batb":[[1,4.3,152.89],[0,4.4,55.18]],"trd":[[4.4,4472.9],[4.5,3779.52]],"batl":[[1,4.6,115.52],[0,4.5,58.43]],"id":50466254},{"batb":[[2,32,33.49],[1,34,30.78],[0,36,4.25]],"id":106596}],"tv":170890}],"ArrivalTime":1710508171549}
{"op":"mcm","id":2,"clk":"AO+EAQCvtQEAwckB","pt":1710508171696,"mc":[{"id":"1.226122413","rc":[{"tv":14606.44,"batb":[[0,5,49.87]],"trd":[[5,188.3],[5.1,121.49]],"ltp":5.1,"batl":[[0,5.1,20.45]],"id":41122648},{"batb":[[0,350,4.22]],"id":41200638},{"batl":[[0,25,12.46]],"id":55632148},{"tv":122220.23,"batb":[[1,2.04,279.06],[0,2.06,97.93]],"trd":[[2.08,483.56],[2.06,983.38]],"ltp":2.06,"batl":[[2,2.12,26.47],[1,2.1,87.46],[0,2.08,15.63]],"id":51922},{"tv":23898.13,"batb":[[2,4.1,117.4],[1,4.2,260.1],[0,4.3,152.89]],"trd":[[4.4,4583.42]],"batl":[[2,4.6,115.52],[1,4.5,58.43],[0,4.4,24.8]],"id":50466254},{"batb":[[0,190,6.46]],"batl":[],"id":66251581},{"batl":[[2,42,12],[1,40,15.35],[0,38,8.74]],"id":106596}],"tv":171010.54}],"ArrivalTime":1710508171703}
{"op":"mcm","id":2,"clk":"APCEAQC1tQEAx8kB","pt":1710508171750,"mc":[{"id":"1.226122413","rc":[{"batb":[],"batl":[[0,2.08,17.63]],"id":51922},{"batb":[[2,4.1,106.08]],"id":50466254},{"tv":744.77,"batb":[[0,190,6.43]],"trd":[[190,61.68]],"ltp":190,"id":66251581},{"batb":[[0,36,9.12]],"id":106596}],"tv":171010.6}],"ArrivalTime":1710508171757}
{"op":"mcm","id":2,"clk":"AP2EAQC9tQEA0skB","pt":1710508171870,"mc":[{"id":"1.226122413","rc":[{"batb":[[0,5,52.43]],"id":41122648},{"batb":[[0,350,1.97]],"batl":[[2,440,2.95],[1,420,2.07],[0,410,1.71]],"id":41200638},{"tv":122255.53,"batb":[[2,2.04,279.06],[1,2.06,182.74],[0,2.08,32.31]],"trd":[[2.08,518.86]],"ltp":2.08,"batl":[[2,2.14,63.87],[1,2.12,26.47],[0,2.1,87.46]],"id":51922},{"batb":[[2,4.1,87.82],[0,4.3,156.5]],"batl":[[2,4.6,116.37],[1,4.5,61],[0,4.4,28.92]],"id":50466254},{"batb":[[0,36,11.8]],"batl":[[2,42,11.39],[1,40,14.67],[0,38,7.98]],"id":106596}],"tv":171045.9}],"ArrivalTime":1710508171877}
{"op":"mcm","id":2,"clk":"AICFAQDKtQEA2MkB","pt":1710508171960,"mc":[{"id":"1.226122413","rc":[{"batl":[[2,5.3,71.17]],"id":41122648},{"tv":122255.57,"batb":[[0,2.08,32.29]],"trd":[[2.08,518.9]],"batl":[[0,2.1,70.38]],"id":51922},{"batb":[[0,4.3,135.15]],"batl":[[1,4.5,75.16]],"id":50466254},{"batl":[[2,240,3.29],[1,230,1.26]],"id":66251581}],"tv":171045.94}],"ArrivalTime":1710508171967}
{"op":"mcm","id":2,"clk":"AI2FAQDYtQEA5MkB","pt":1710508172069,"mc":[{"id":"1.226122413","rc":[{"batb":[[1,4.9,169.64],[0,5,49.87]],"id":41122648},{"batb":[],"batl":[[0,410,2.67]],"id":41200638},{"batl":[[0,25,13.33]],"id":55632148},{"tv":122414.34,"batb":[[2,2.04,255.2],[0,2.08,95.42]],"trd":[[2.08,536.9],[2.1,222.36]],"batl":[[2,2.16,48.18],[1,2.14,63.87],[0,2.12,26.47]],"id":51922},{"tv":23955.97,"batb":[[0,4.3,131.54]],"trd":[[4.4,4641.26]],"batl":[[2,4.7,49.06],[1,4.6,116.37],[0,4.5,75.16]],"id":50466254}],"tv":171262.55}],"ArrivalTime":1710508172076}
{"op":"mcm","id":2,"clk":"AJaFAQDgtQEA7ckB","pt":1710508172190,"mc":[{"id":"1.226122413","rc":[{"tv":488.65,"batb":[[2,420,2.67],[1,430,1.64],[0,440,3.6]],"trd":[[460,6.47],[450,6.1],[440,12.18]],"ltp":440,"id":54370634},{"tv":14622.44,"trd":[[5.1,137.49]],"batl":[[2,5.3,73.65],[0,5.1,12.45]],"id":41122648},{"tv":23965.97,"batb":[[0,4.3,126.54]],"trd":[[4.3,4206.81]],"ltp":4.3,"batl":[],"id":50466254},{"batl":[[2,230,1.26],[1,220,1.46]],"id":66251581}],"tv":171291.04}],"ArrivalTime":1710508172197}
{"op":"mcm","id":2,"clk":"AJ6FAQDltQEA88kB","pt":1710508172276,"mc":[{"id":"1.226122413","rc":[{"tv":488.69,"trd":[[530,0.15]],"ltp":530,"batl":[[0,530,4.34]],"id":54370634},{"batb":[[1,4.9,166.96],[0,5,40.4]],"id":41122648},{"batb":[[2,2.06,185.31],[1,2.08,95.42],[0,2.1,50]],"batl":[[2,2.16,44.15],[0,2.12,59.67]],"id":51922},{"tv":23985.96,"batb":[[2,4.1,83.78],[1,4.2,256.28]],"trd":[[4.4,4661.25]],"ltp":4.4,"batl":[[2,4.6,116.37],[1,4.5,75.16],[0,4.4,21.38]],"id":50466254}],"tv":171311.07}],"ArrivalTime":1710508172283}
{"op":"mcm","id":2,"clk":"AKGFAQDutQEA/skB","pt":1710508172370,"mc":[{"id":"1.226122413","rc":[{"batb":[[2,430,1.64],[1,440,3.67],[0,530,2]],"batl":[[2,730,1.47],[1,670,1.13],[0,600,1.22]],"id":54370634},{"batb":[[2,4.8,122.86]],"batl":[[0,5.1,14.45]],"id":41122648},{"batl":[[0,410,3.67]],"id":41200638},{"batb":[[0,24,5.79]],"id":55632148},{"batb":[],"batl":[[1,4.5,100.16]],"id":50466254}]}],"ArrivalTime":1710508172377}
{"op":"mcm","id":2,"clk":"AKmFAQD6tQEAicoB","pt":1710508172480,"mc":[{"id":"1.226122413","rc":[{"batl":[[0,5.1,26.95]],"id":41122648},{"batb":[[2,340,1.89],[1,350,1.04],[0,370,1.16]],"batl":[[1,420,1.79]],"id":41200638},{"tv":122483.08,"batb":[[1,2.08,97.99],[0,2.1,15.63]],"trd":[[2.1,291.1]],"ltp":2.1,"batl":[[2,2.16,48.18]],"id":51922},{"batb":[[2,4.1,87.82]],"batl":[[0,4.4,55.76]],"id":50466254}],"tv":171379.81}],"ArrivalTime":1710508172487}
{"op":"mcm","id":2,"clk":"AKqFAQCEtgEAjsoB","pt":1710508172536,"mc":[{"id":"1.226122413","rc":[{"tv":489.27,"batb":[[0,530,1.71]],"trd":[[530,0.73]],"id":54370634},{"tv":14703.24,"batb":[[1,4.9,169.64],[0,5,2.56]],"trd":[[5,269.1]],"ltp":5,"id":41122648},{"tv":122503.08,"batb":[[0,2.1,38.9]],"trd":[[2.1,311.1]],"id":51922},{"tv":2611.69,"batb":[[0,36,11.7]],"trd":[[36,63.8]],"ltp":36,"id":106596}],"tv":171481.39}],"ArrivalTime":1710508172542}
{"op":"mcm","id":2,"clk":"ALKFAQCJtgEAl8oB","pt":1710508172633,"mc":[{"id":"1.226122413","rc":[{"tv":14739.78,"batb":[[2,4.7,57.58],[1,4.8,122.86],[0,4.9,169.64]],"trd":[[5,305.64]],"batl":[[2,5.2,38.38],[1,5.1,34.97],[0,5,23.23]],"id":41122648},{"batl":[[2,65,5.65]],"id":49744721},{"batb":[[1,4.2,225.17],[0,4.3,101.16]],"id":50466254}],"tv":171517.93}],"ArrivalTime":1710508172642}
{"op":"mcm","id":2,"clk":"ALiFAQCKtgEApMoB","pt":1710508172742,"mc":[{"id":"1.226122413","rc":[{"batb":[[2,440,3.67],[1,520,1.64]],"id":54370634},{"batb":[[2,4.7,69.58]],"batl":[[2,5.2,40.88]],"id":41122648},{"batb":[[2,350,1.04],[1,360,1.64]],"id":41200638},{"batb":[[0,24,10.3]],"id":55632148},{"tv":122505.4,"batb":[[0,2.1,88.38]],"trd":[[2.1,313.42]],"batl":[[2,2.16,44.15]],"id":51922},{"batb":[[0,50,71.2]],"id":49744721},{"batb":[[2,4.1,83.78]],"batl":[],"id":50466254}],"tv":171520.25}],"ArrivalTime":1710508172749}
{"op":"mcm","id":2,"clk":"AMCFAQCdtgEAr8oB","pt":1710508172848,"mc":[{"id":"1.226122413","rc":[{"tv":489.85,"batb":[[2,440,2.87],[0,530,1.42]],"trd":[[530,1.31]],"id":54370634},{"batb":[[0,4.9,145.61]],"batl":[[0,5,40.27]],"id":41122648},{"batb":[[2,22,24.16]],"id":55632148},{"batb":[[0,4.3,126.62]],"id":50466254}],"tv":171520.83}],"ArrivalTime":1710508172854}
{"op":"mcm","id":2,"clk":"AMaFAQCjtgEAtsoB","pt":1710508172957,"mc":[{"id":"1.226122413","rc":[{"batl":[[2,5.2,78.92]],"id":41122648},{"batb":[[0,2.1,110.29]],"id":51922},{"batl":[[2,65,11.73]],"id":49744721},{"batb":[[2,4.1,142.36]],"id":50466254},{"batl":[[0,38,5.98]],"id":106596}]}],"ArrivalTime":1710508172963}
{"op":"mcm","id":2,"clk":"AMqFAQC2tgEAw8oB","pt":1710508173053,"mc":[{"id":"1.226122413","rc":[{"tv":490.19,"batb":[[0,530,1.25]],"trd":[[530,1.65]],"id":54370634},{"tv":14743.78,"batb":[[1,4.8,100.95]],"trd":[[5,309.64]],"batl":[[0,5,47.72]],"id":41122648},{"tv":122505.5,"batb":[[0,2.1,110.24]],"trd":[[2.1,313.52]],"batl":[],"id":51922}],"tv":171525.27}],"ArrivalTime":1710508173060}
{"op":"mcm","id":2,"clk":"ANKFAQDAtgEAycoB","pt":1710508173154,"mc":[{"id":"1.226122413","rc":[{"batb":[[2,440,3.27]],"id":54370634},{"batb":[[0,4.9,130.83]],"batl":[[2,5.2,74.92]],"id":41122648},{"batb":[],"batl":[[0,410,2.67]],"id":41200638},{"batb":[[2,22,55.34]],"id":55632148},{"tv":122520.66,"batb":[[0,2.1,102.66]],"trd":[[2.1,328.68]],"batl":[],"id":51922},{"batb":[[2,32,51.55]],"id":106596}],"tv":171540.43}],"ArrivalTime":1710508173161}
{"op":"mcm","id":2,"clk":"ANqFAQDItgEA0MoB","pt":1710508173255,"mc":[{"id":"1.226122413","rc":[{"batb":[],"batl":[[2,750,1.71],[1,730,1.82],[0,610,1.56]],"id":54370634},{"batb":[[1,4.8,98.15]],"batl":[[0,5,61]],"id":41122648},{"tv":122526.66,"batb":[[0,2.1,99.66]],"trd":[[2.1,334.68]],"batl":[[0,2.12,40.92]],"id":51922}],"tv":171546.43}],"ArrivalTime":1710508173262}
{"op":"mcm","id":2,"clk":"AOKFAQDTtgEA2coB","pt":1710508173363,"mc":[{"id":"1.226122413","rc":[{"batl":[[2,730,1.47],[1,670,1.08]],"id":54370634},{"tv":14748.7,"batb":[[2,4.7,94.35]],"trd":[[5,314.56]],"batl":[[0,5,58.54]],"id":41122648},{"tv":122537.82,"batb":[[0,2.1,94.08]],"trd":[[2.1,345.84]],"batl":[],"id":51922},{"tv":23992.24,"trd":[[4.4,4667.53]],"batl":[[0,4.4,52.62]],"id":50466254}],"tv":171568.79}],"ArrivalTime":1710508173369}
{"op":"mcm","id":2,"clk":"AOWFAQDctgEA48oB","pt":1710508173461,"mc":[{"id":"1.226122413","rc":[{"batb":[[2,440,3.45]],"id":54370634},{"tv":14762,"batb":[[2,4.7,91.41],[0,4.9,100.48]],"trd":[[4.9,10.7],[5,317.16]],"batl":[[0,5,57.24]],"id":41122648},{"tv":2828.24,"trd":[[25,561.42]],"ltp":25,"batl":[[0,25,12.29]],"id":55632148},{"tv":122705.82,"batb":[[0,2.1,10.08]],"trd":[[2.1,513.84]],"id":51922},{"tv":23994.36,"batb":[[1,4.2,519.17]],"trd":[[4.4,4669.65]],"batl":[[0,4.4,51.56]],"id":50466254}],"tv":171754.29}],"ArrivalTime":1710508173468}
{"op":"mcm","id":2,"clk":"APOFAQDrtgEA7coB","pt":1710508173571,"mc":[{"id":"1.226122413","rc":[{"batl":[[2,450,1.84]],"id":41200638}]}],"ArrivalTime":1710508173578}
{"op":"mcm","id":2,"clk":"APaFAQDvtgEA9soB","pt":1710508173668,"mc":[{"id":"1.226122413","rc":[{"tv":122709.82,"batb":[[2,2.04,310.44],[1,2.06,204.14],[0,2.08,97.99]],"trd":[[2.1,517.84]],"batl":[[0,2.12,62.34]],"id":51922}],"tv":171758.29}],"ArrivalTime":1710508173675}
{"op":"mcm","id":2,"clk":"AIGGAQDztgEA/soB","pt":1710508173779,"mc":[{"id":"1.226122413","rc":[{"batb":[[2,4.7,94.35],[1,4.8,76.25]],"id":41122648},{"tv":122710.1,"batb":[[2,2.06,204.14],[1,2.08,97.99],[0,2.1,74.75]],"trd":[[2.1,518.12]],"batl":[[0,2.12,62.2]],"id":51922}],"tv":171758.57}],"ArrivalTime":1710508173785}
{"op":"mcm","id":2,"clk":"AISGAQD7tgEAhssB","pt":1710508173839,"mc":[{"id":"1.226122413","rc":[{"batl":[[0,25,11.42]],"id":55632148},{"tv":122717.35,"batb":[[1,2.08,159.99]],"trd":[[2.12,73.11]],"ltp":2.12,"batl":[[0,2.12,58.57]],"id":51922},{"tv":2619.01,"trd":[[38,28.67]],"ltp":38,"batl":[[0,38,2.32]],"id":106596}],"tv":171773.14}],"ArrivalTime":1710508173845}
{"op":"mcm","id":2,"clk":"AIuGAQCFtwEAissB","pt":1710508173937,"mc":[{"id":"1.226122413","rc":[{"batb":[[2,4.7,91.41]],"id":41122648},{"tv":2828.86,"trd":[[25,562.04]],"batl":[[0,25,11.11]],"id":55632148},{"tv":122752.97,"batb":[[0,2.1,56.94]],"trd":[[2.1,553.74]],"ltp":2.1,"id":51922},{"tv":3035.03,"trd":[[55,53.19]],"batl":[[0,55,11.49]],"id":49744721}],"tv":171809.56}],"ArrivalTime":1710508173944}
{"op":"mcm","id":2,"clk":"AJWGAQCItwEAmssB","pt":1710508174050,"mc":[{"id":"1.226122413","rc":[{"tv":14764.24,"batb":[[0,4.9,99.36]],"trd":[[4.9,12.94]],"ltp":4.9,"id":41122648},{"tv":583.47,"batb":[],"trd":[[410,11.54]],"ltp":410,"batl":[[0,410,2.12]],"id":41200638},{"batb":[],"batl":[[0,25,11.98]],"id":55632148}],"tv":171812.9}],"ArrivalTime":1710508174056}
{"op":"mcm","id":2,"clk":"AJeGAQCUtwEAossB","pt":1710508174149,"mc":[{"id":"1.226122413","rc":[{"tv":122768.77,"batb":[[0,2.1,49.04]],"trd":[[2.1,569.54]],"id":51922},{"batb":[[0,36,15.57]],"id":106596}],"tv":171828.7}],"ArrivalTime":1710508174155}
{"op":"mcm","id":2,"clk":"AKCGAQCdtwEArMsB","pt":1710508174245,"mc":[{"id":"1.226122413","rc":[{"batl":[[2,5.2,76.92]],"id":41122648},{"tv":122788.78,"batb":[],"trd":[[2.12,93.12]],"ltp":2.12,"batl":[[0,2.12,48.57]],"id":51922},{"batl":[[1,4.5,115.16]],"id":50466254}],"tv":171848.71}],"ArrivalTime":1710508174252}
{"op":"mcm","id":2,"clk":"AKmGAQCntwEAs8sB","pt":1710508174347,"mc":[{"id":"1.226122413","rc":[{"tv":122847.84,"batb":[[0,2.1,50.76]],"trd":[[2.1,628.6]],"ltp":2.1,"id":51922},{"batl":[[2,240,3.29],[1,230,1.26]],"id":66251581}],"tv":171907.77}],"ArrivalTime":1710508174354}
{"op":"mcm","id":2,"clk":"ALCGAQCutwEAvssB","pt":1710508174453,"mc":[{"id":"1.226122413","rc":[{"batl":[[2,5.2,79.45]],"id":41122648},{"tv":122867.84,"batb":[[0,2.1,50.9]],"trd":[[2.1,648.6]],"batl":[[0,2.12,82.25]],"id":51922}],"tv":171927.77}],"ArrivalTime":1710508174460}
{"op":"mcm","id":2,"clk":"ALeGAQC6twEAy8sB","pt":1710508174557,"mc":[{"id":"1.226122413","rc":[{"tv":14789.24,"batb":[[0,4.9,86.86]],"trd":[[4.9,37.94]],"id":41122648},{"batb":[[0,2.1,19.65]],"id":51922},{"tv":3037.03,"batb":[[0,50,70.2]],"trd":[[50,98.2]],"ltp":50,"id":49744721},{"batl":[[2,230,1.26],[1,220,1.46]],"id":66251581}],"tv":171954.77}],"ArrivalTime":1710508174564}
{"op":"mcm","id":2,"clk":"ALyGAQDItwEA1csB","pt":1710508174663,"mc":[{"id":"1.226122413","rc":[{"tv":14789.32,"batb":[[0,4.9,86.82]],"trd":[[4.9,38.02]],"batl":[[0,5,69.6]],"id":41122648},{"tv":587.46,"batb":[[2,320,2.34],[1,330,1.11],[0,350,1.84]],"trd":[[380,2.19],[370,21.31],[360,17]],"ltp":360,"id":41200638},{"tv":122924.62,"batb":[[2,2.04,313.15],[1,2.06,225.49],[0,2.08,159.99]],"trd":[[2.1,705.38]],"batl":[[0,2.12,155.7]],"id":51922}],"tv":172015.62}],"ArrivalTime":1710508174669}
{"op":"mcm","id":2,"clk":"AMKGAQDTtwEA4csB","pt":1710508174765,"mc":[{"id":"1.226122413","rc":[{"tv":122926.62,"batb":[[0,2.08,158.99]],"trd":[[2.08,538.9]],"ltp":2.08,"id":51922},{"tv":23994.44,"batb":[[0,4.3,126.58]],"trd":[[4.3,4206.89]],"ltp":4.3,"id":50466254}],"tv":172017.7}],"ArrivalTime":1710508174771}
{"op":"mcm","id":2,"clk":"AMmGAQDatwEA5ssB","pt":1710508174873,"mc":[{"id":"1.226122413","rc":[{"batb":[[2,420,3.1]],"id":54370634},{"batb":[[2,4.7,94.35]],"id":41122648},{"batb":[[2,310,7.21],[1,320,2.87]],"id":41200638},{"tv":2829.58,"batb":[[0,24,9.94]],"trd":[[24,307.81]],"ltp":24,"batl":[[0,25,11.11]],"id":55632148},{"tv":122927.86,"batb":[[0,2.08,158.37]],"trd":[[2.08,540.14]],"batl":[],"id":51922}],"tv":172019.66}],"ArrivalTime":1710508174880}
{"op":"mcm","id":2,"clk":"AM+GAQDjtwEA78sB","pt":1710508174970,"mc":[{"id":"1.226122413","rc":[{"tv":14789.58,"batb":[[0,4.9,86.69]],"trd":[[4.9,38.28]],"id":41122648},{"batb":[[1,2.06,204.14]],"id":51922},{"tv":23994.7,"batb":[[0,4.3,126.45]],"trd":[[4.3,4207.15]],"batl":[],"id":50466254}],"tv":172020.18}],"ArrivalTime":1710508174976}
{"op":"mcm","id":2,"clk":"ANqGAQDvtwEA+MsB","pt":1710508175095,"mc":[{"id":"1.226122413","rc":[{"batb":[[0,530,1.28]],"id":54370634},{"batb":[[0,4.9,89.75]],"id":41122648},{"batb":[[2,310,7.5],[1,320,3.16],[0,350,1.88]],"id":41200638},{"batb":[[0,24,10.56]],"id":55632148},{"tv":122959.12,"batb":[[0,2.08,149.95]],"trd":[[2.08,571.4]],"id":51922},{"batb":[[0,50,70.5]],"id":49744721},{"batb":[[2,4.1,146.4],[0,4.3,129.94]],"id":50466254},{"batb":[[0,190,6.51]],"id":66251581},{"batb":[[0,36,15.99]],"id":106596}],"tv":172051.44}],"ArrivalTime":1710508175101}
{"op":"mcm","id":2,"clk":"ANuGAQDwtwEAg8wB","pt":1710508175132,"mc":[{"id":"1.226122413","rc":[{"batl":[[2,27,28.41],[1,26,9.1]],"id":55632148},{"batb":[],"batl":[[0,2.12,158.05]],"id":51922},{"batl":[[0,4.4,37.73]],"id":50466254}]}],"ArrivalTime":1710508175138}
{"op":"mcm","id":2,"clk":"AN+GAQD5twEAiMwB","pt":1710508175236,"mc":[{"id":"1.226122413","rc":[{"batl":[[2,750,1.71],[1,730,1.67],[0,650,1.66]],"id":54370634},{"batl":[[2,5.2,41.41],[0,5,57.24]],"id":41122648},{"batb":[[1,320,2.87]],"id":41200638},{"batb":[[1,23,25.39]],"id":55632148},{"tv":123036.6,"batb":[[0,2.08,121.21]],"trd":[[2.08,628.88],[2.1,725.38]],"batl":[[2,2.14,73.87],[1,2.12,158.05],[0,2.1,15.63]],"id":51922},{"batl":[[2,65,5.65]],"id":49744721},{"batb":[[2,4.1,87.82]],"batl":[],"id":50466254}],"tv":172128.92}],"ArrivalTime":1710508175244}
{"op":"mcm","id":2,"clk":"AOaGAQD/twEAjswB","pt":1710508175342,"mc":[{"id":"1.226122413","rc":[{"batl":[[2,730,1.47],[1,670,1.08],[0,610,1.56]],"id":54370634},{"batb":[[1,4.8,79.05]],"batl":[[2,5.2,79.45]],"id":41122648},{"batb":[],"batl":[[2,420,1.79],[1,410,2.12],[0,400,1]],"id":41200638},{"batb":[],"batl":[[0,2.1,47.28]],"id":51922},{"batb":[[2,4.1,146.4],[1,4.2,522.99]],"id":50466254}]}],"ArrivalTime":1710508175349}
{"op":"mcm","id":2,"clk":"AO6GAQCCuAEAmMwB","pt":1710508175440,"mc":[{"id":"1.226122413","rc":[{"tv":2834.73,"batb":[[2,22,24.16]],"trd":[[25,567.19]],"ltp":25,"batl":[[0,25,8.54]],"id":55632148},{"tv":123056.6,"batb":[[0,2.08,111.21]],"trd":[[2.08,648.88]],"id":51922},{"batl":[[2,65,11.73]],"id":49744721},{"batb":[[2,32,33.49]],"id":106596}],"tv":172154.07}],"ArrivalTime":1710508175447}
{"op":"mcm","id":2,"clk":"APSGAQCRuAEAnMwB","pt":1710508175544,"mc":[{"id":"1.226122413","rc":[{"batb":[[0,4.9,99.48]],"id":41122648},{"batb":[[2,22,55.34]],"id":55632148},{"batl":[[1,2.12,158.17],[0,2.1,52.28]],"id":51922},{"batl":[[1,4.5,115.27]],"id":50466254}]}],"ArrivalTime":1710508175551}
{"op":"mcm","id":2,"clk":"APiGAQCZuAEApMwB","pt":1710508175647,"mc":[{"id":"1.226122413","rc":[{"batl":[[1,5.1,35.15],[0,5,87.26]],"id":41122648},{"tv":2847.88,"batb":[[0,24,10.92]],"trd":[[25,580.34]],"batl":[[1,26,9.13],[0,25,1.96]],"id":55632148},{"batb":[[0,2.08,116.21]],"id":51922},{"batl":[[1,60,25.58]],"id":49744721},{"batb":[[2,32,57.4]],"batl":[[1,40,14.69]],"id":106596}],"tv":172167.22}],"ArrivalTime":1710508175654}
{"op":"mcm","id":2,"clk":"AP6GAQCguAEAq8wB","pt":1710508175746,"mc":[{"id":"1.226122413","rc":[{"tv":589.46,"batb":[[2,320,2.87],[1,350,1.88],[0,400,4.73]],"trd":[[400,29.46]],"ltp":400,"batl":[[2,450,1.84],[1,420,1.79],[0,410,2.12]],"id":41200638},{"tv":2851.8,"batb":[[2,23,25.39],[1,24,10.92],[0,25,1.3]],"trd":[[25,584.26]],"batl":[[2,28,12.37],[1,27,28.41],[0,26,9.13]],"id":55632148},{"batl":[[2,2.14,79.84],[0,2.1,63.28]],"id":51922},{"tv":24028.78,"batb":[[0,4.3,112.9]],"trd":[[4.3,4241.23]],"id":50466254},{"batb":[[0,190,12.24]],"id":66251581}],"tv":172207.22}],"ArrivalTime":1710508175752}
{"op":"mcm","id":2,"clk":"AIOHAQCnuAEAtcwB","pt":1710508175857,"mc":[{"id":"1.226122413","rc":[{"batb":[[2,470,3.01]],"id":54370634},{"batb":[[0,4.9,89.75]],"id":41122648},{"tv":591.46,"batb":[[0,400,3.73]],"trd":[[400,31.46]],"id":41200638},{"tv":2854.4,"batb":[[2,22,55.34],[1,23,25.39],[0,24,10.92]],"trd":[[25,586.86]],"batl":[[2,27,29.15],[1,26,9.93],[0,25,7.48]],"id":55632148},{"tv":123074.86,"batb":[[0,2.08,157.08]],"trd":[[2.08,667.14]],"batl":[[0,2.1,113.28]],"id":51922},{"tv":24104.24,"trd":[[4.4,4745.11]],"ltp":4.4,"batl":[[2,4.7,49.06],[1,4.6,116.37],[0,4.5,115.27]],"id":50466254}],"tv":172305.54}],"ArrivalTime":1710508175864}
{"op":"mcm","id":2,"clk":"AIiHAQCvuAEAvswB","pt":1710508175959,"mc":[{"id":"1.226122413","rc":[{"batl":[[2,730,1.05],[1,720,1.35]],"id":54370634},{"batb":[[2,310,7.21],[1,320,2.95]],"id":41200638},{"tv":2861.68,"trd":[[25,594.14]],"batl":[[1,26,9.39],[0,25,3.84]],"id":55632148},{"tv":123111.62,"batb":[[0,2.08,169.14]],"trd":[[2.1,762.14]],"ltp":2.1,"batl":[[0,2.1,94.91]],"id":51922}],"tv":172349.58}],"ArrivalTime":1710508175966}
{"op":"mcm","id":2,"clk":"AI6HAQC4uAEAxswB","pt":1710508176059,"mc":[{"id":"1.226122413","rc":[{"tv":14830.8,"batb":[[1,4.8,76.25],[0,4.9,69.14]],"trd":[[4.9,79.5]],"id":41122648},{"batb":[[2,320,2.95],[1,360,2]],"id":41200638},{"batb":[[2,22,56.69]],"batl":[[2,27,28.41],[1,26,8.59],[0,25,2.97]],"id":55632148},{"batb":[[2,4.2,519.17],[1,4.3,121.24],[0,4.4,13.64]],"id":50466254}],"tv":172390.8}],"ArrivalTime":1710508176066}
{"op":"mcm","id":2,"clk":"AJuHAQDEuAEA0cwB","pt":1710508176172,"mc":[{"id":"1.226122413","rc":[{"tv":14834.34,"batb":[[0,4.9,67.37]],"trd":[[4.9,83.04]],"batl":[],"id":41122648},{"batb":[[0,24,16.42]],"batl":[[0,25,3.42]],"id":55632148},{"batb":[[0,2.08,171.14]],"id":51922}],"tv":172394.34}],"ArrivalTime":1710508176178}
{"op":"mcm","id":2,"clk":"AJ+HAQDKuAEA28wB","pt":1710508176265,"mc":[{"id":"1.226122413","rc":[{"batb":[[1,4.8,54.05]],"id":41122648},{"tv":591.91,"batb":[[0,400,3.5]],"trd":[[400,31.91]],"id":41200638},{"batl":[[2,28,12.37],[1,27,28.41],[0,26,9.04]],"id":55632148},{"tv":123131.62,"batb":[[0,2.08,161.14]],"trd":[[2.08,687.14]],"ltp":2.08,"batl":[[0,2.1,66]],"id":51922},{"tv":3041.03,"trd":[[55,57.19]],"ltp":55,"batl":[[0,55,9.49]],"id":49744721}],"tv":172418.79}],"ArrivalTime":1710508176272}
{"op":"mcm","id":2,"clk":"AKSHAQDSuAEA5MwB","pt":1710508176376,"mc":[{"id":"1.226122413","rc":[{"tv":123173.04,"batb":[[0,2.08,140.94]],"trd":[[2.08,727.54],[2.1,763.16]],"ltp":2.1,"batl":[[0,2.1,65.49]],"id":51922},{"batl":[[0,4.5,117.27]],"id":50466254}],"tv":172460.21}],"ArrivalTime":1710508176382}
{"op":"mcm","id":2,"clk":"AKyHAQDWuAEA8MwB","pt":1710508176484,"mc":[{"id":"1.226122413","rc":[{"tv":14969.08,"batb":[[2,4.6,101.08],[1,4.7,94.35],[0,4.8,54.05]],"trd":[[4.9,217.78]],"batl":[[0,5,87.3]],"id":41122648},{"batb":[[2,340,1.18]],"id":41200638},{"tv":2862.58,"batb":[[2,23,25.39],[1,24,16.42],[0,25,3.66]],"trd":[[25,595.04]],"batl":[[2,28,11.68],[0,26,8.59]],"id":55632148},{"tv":123373.04,"trd":[[2.1,894.14],[2.12,162.14]],"ltp":2.12,"batl":[[2,2.16,58.18],[1,2.14,79.84],[0,2.12,123.66]],"id":51922},{"tv":24104.32,"batb":[[0,4.4,13.6]],"trd":[[4.4,4745.19]],"batl":[],"id":50466254}],"tv":172795.93}],"ArrivalTime":1710508176490}
{"op":"mcm","id":2,"clk":"ALWHAQDeuAEA+8wB","pt":1710508176586,"mc":[{"id":"1.226122413","rc":[{"tv":14973.07,"trd":[[4.9,217.85],[5,321.08]],"ltp":5,"batl":[[0,5,85.3]],"id":41122648},{"tv":123936.82,"batb":[[1,2.06,65.08],[0,2.08,22.26]],"trd":[[2.08,1009.42],[2.1,897.92],[2.06,1261.5]],"ltp":2.1,"batl":[[2,2.14,79.84],[1,2.12,123.66],[0,2.1,29.75]],"id":51922},{"tv":24106.34,"trd":[[4.5,3781.54]],"ltp":4.5,"batl":[[0,4.5,117.26]],"id":50466254}],"tv":173365.72}],"ArrivalTime":1710508176592}
{"op":"mcm","id":2,"clk":"ALqHAQDiuAEAg80B","pt":1710508176684,"mc":[{"id":"1.226122413","rc":[{"batb":[[2,4.6,109.99],[1,4.7,91.41],[0,4.8,39.03]],"batl":[[2,5.1,35.15],[1,5,87.87],[0,4.9,31.14]],"id":41122648},{"tv":593.87,"trd":[[410,13.5]],"ltp":410,"batl":[[0,410,1.14]],"id":41200638},{"tv":2864.32,"batb":[[0,25,6.43]],"trd":[[25,596.78]],"batl":[[1,27,29.15],[0,26,6.45]],"id":55632148},{"batb":[[0,2.08,38.2]],"batl":[[2,2.16,54.15],[1,2.14,79.84],[0,2.12,154.89]],"id":51922}],"tv":173369.42}],"ArrivalTime":1710508176690}
{"op":"mcm","id":2,"clk":"AMGHAQDsuAEAj80B","pt":1710508176789,"mc":[{"id":"1.226122413","rc":[{"tv":15050.99,"batb":[[2,4.6,132.49]],"trd":[[4.9,280.13],[5,336.72]],"batl":[[2,5.2,79.45],[1,5.1,35.15],[0,5,80.05]],"id":41122648},{"batb":[[0,25,8.94]],"id":55632148},{"tv":123996.82,"batb":[[2,2.04,291.8],[1,2.06,87.66],[0,2.08,8.2]],"trd":[[2.08,1069.42]],"ltp":2.08,"batl":[[2,2.14,79.84],[1,2.12,154.89],[0,2.1,135.76]],"id":51922},{"batb":[[0,190,11.01]],"id":66251581},{"batl":[[2,44,21.16],[1,42,11.39],[0,40,14.81]],"id":106596}],"tv":173507.34}],"ArrivalTime":1710508176795}
{"op":"mcm","id":2,"clk":"AMyHAQDyuAEAmM0B","pt":1710508176899,"mc":[{"id":"1.226122413","rc":[{"batb":[],"batl":[[2,750,1.71],[1,730,1.67],[0,650,1.51]],"id":54370634},{"tv":15058.57,"batb":[[2,4.6,135.58],[1,4.7,94.35],[0,4.8,35.24]],"trd":[[4.8,7.58]],"ltp":4.8,"batl":[[2,5.2,76.92]],"id":41122648},{"batl":[[1,27,28.41],[0,26,5.65]],"id":55632148},{"tv":124008.82,"batb":[[0,2.08,2.2]],"trd":[[2.08,1081.42]],"id":51922},{"batl":[[2,240,3.29],[1,230,1.26]],"id":66251581},{"batl":[[0,40,13.47]],"id":106596}],"tv":173526.92}],"ArrivalTime":1710508176906}
{"op":"mcm","id":2,"clk":"AM6HAQCBuQEAnc0B","pt":1710508176945,"mc":[{"id":"1.226122413","rc":[{"batb":[[0,530,1.73]],"id":54370634},{"batb":[[0,4.8,95.9]],"id":41122648},{"batb":[[0,400,4.09]],"id":41200638},{"batb":[[0,25,18.64]],"id":55632148},{"tv":124093.98,"batb":[[1,2.06,116.66],[0,2.08,76.65]],"trd":[[2.08,1166.58]],"batl":[[2,2.14,83.97]],"id":51922},{"batb":[[0,50,75.34]],"id":49744721},{"batb":[[0,4.4,68.74]],"id":50466254},{"batb":[[0,190,12.27]],"id":66251581},{"batb":[[0,36,25.67]],"id":106596}],"tv":173612.08}],"ArrivalTime":1710508176952}
{"op":"mcm","id":2,"clk":"ANWHAQCHuQEAqc0B","pt":1710508177051,"mc":[{"id":"1.226122413","rc":[{"batb":[[0,530,2.12]],"batl":[[2,730,1.67],[1,650,1.51],[0,580,1.2]],"id":54370634},{"tv":15078.57,"batb":[[1,4.7,91.41],[0,4.8,129.97]],"trd":[[4.8,27.58]],"batl":[[1,5.1,37.73]],"id":41122648},{"batb":[[1,360,2.24],[0,400,4.6]],"id":41200638},{"batb":[[0,25,27.07]],"id":55632148},{"tv":124101.9,"batb":[[0,2.08,174.04]],"trd":[[2.08,1174.5]],"id":51922},{"batb":[[0,50,79.55]],"id":49744721},{"batb":[[0,4.4,130.18]],"id":50466254},{"batb":[[0,190,13.37]],"batl":[[2,230,1.26],[1,220,1.46]],"id":66251581},{"tv":2619.25,"batb":[[2,34,30.78],[1,36,25.67],[0,38,5.41]],"trd":[[38,28.91]],"batl":[[0,40,13.35]],"id":106596}],"tv":173640.24}],"ArrivalTime":1710508177057}
{"op":"mcm","id":2,"clk":"ANuHAQCOuQEAtM0B","pt":1710508177156,"mc":[{"id":"1.226122413","rc":[{"tv":490.47,"batb":[],"trd":[[580,0.28]],"ltp":580,"batl":[[0,580,1.06]],"id":54370634},{"batb":[[1,4.7,69.21]],"batl":[[0,5,80.24]],"id":41122648},{"tv":124105.9,"batb":[[0,2.08,183.04]],"trd":[[2.08,1178.5]],"id":51922},{"batb":[[0,4.4,156.4]],"id":50466254},{"batb":[],"batl":[[2,44,21.72],[0,40,9.05]],"id":106596}],"tv":173644.52}],"ArrivalTime":1710508177163}
{"op":"mcm","id":2,"clk":"AOSHAQCZuQEAus0B","pt":1710508177260,"mc":[{"id":"1.226122413","rc":[{"batb":[[2,470,2.81]],"id":54370634},{"tv":124130.8,"batb":[[0,2.08,170.59]],"trd":[[2.08,1203.4]],"batl":[[0,2.1,172.36]],"id":51922},{"batb":[[1,4.3,128.75]],"batl":[],"id":50466254},{"batb":[[0,38,10.01]],"id":106596}],"tv":173669.42}],"ArrivalTime":1710508177267}
{"op":"mcm","id":2,"clk":"AO2HAQCfuQEAxs0B","pt":1710508177363,"mc":[{"id":"1.226122413","rc":[{"batl":[[0,580,2.26]],"id":54370634},{"batb":[[0,4.8,138.44]],"id":41122648},{"batb":[[2,360,2.24],[1,390,1.64]],"id":41200638},{"batb":[[0,2.08,199.59]],"id":51922}]}],"ArrivalTime":1710508177369}
{"op":"mcm","id":2,"clk":"APeHAQCquQEA080B","pt":1710508177482,"mc":[{"id":"1.226122413","rc":[{"batl":[[0,580,3.46]],"id":54370634},{"batl":[[2,5.2,38.88]],"id":41122648},{"tv":124142.68,"batb":[],"trd":[[2.1,909.8]],"ltp":2.1,"batl":[[0,2.1,166.42]],"id":51922},{"tv":2639.27,"batb":[[2,32,52.84],[1,34,30.78],[0,36,25.67]],"trd":[[38,48.93]],"batl":[[1,42,17.71]],"id":106596}],"tv":173701.32}],"ArrivalTime":1710508177488}
{"op":"mcm","id":2,"clk":"APmHAQCwuQEA380B","pt":1710508177574,"mc":[{"id":"1.226122413","rc":[{"batl":[[0,580,4.15]],"id":54370634},{"tv":15079.41,"batb":[[2,4.6,132.49]],"trd":[[4.9,280.97]],"ltp":4.9,"batl":[[1,5.1,35.73],[0,5,80.82]],"id":41122648},{"tv":124145.88,"batb":[[0,2.08,197.99]],"trd":[[2.08,1206.6]],"ltp":2.08,"id":51922},{"batl":[[2,44,21.16]],"id":106596}],"tv":173705.36}],"ArrivalTime":1710508177581}
{"op":"mcm","id":2,"clk":"AICIAQC5uQEA680B","pt":1710508177674,"mc":[{"id":"1.226122413","rc":[{"batb":[[2,470,3.02]],"id":54370634},{"batl":[[1,5.1,74.52]],"id":41122648},{"tv":124158.54,"batb":[[0,2.08,191.66]],"trd":[[2.08,1219.26]],"batl":[[2,2.14,79.84]],"id":51922},{"batl":[[2,65,5.65]],"id":49744721},{"batb":[[2,4.2,576.36]],"id":50466254}],"tv":173718.02}],"ArrivalTime":1710508177681}
{"op":"mcm","id":2,"clk":"AIKIAQDAuQEA880B","pt":1710508177784,"mc":[{"id":"1.226122413","rc":[{"batl":[[0,2.1,129.82]],"id":51922}]}],"ArrivalTime":1710508177790}
{"op":"mcm","id":2,"clk":"AIqIAQDKuQEA/80B","pt":1710508177873,"mc":[{"id":"1.226122413","rc":[{"batl":[[2,2.14,83.97]],"id":51922},{"batl":[[2,65,11.73]],"id":49744721},{"batb":[[2,32,34.78]],"id":106596}]}],"ArrivalTime":1710508177879}
{"op":"mcm","id":2,"clk":"AJGIAQDQuQEAjM4B","pt":1710508177943,"mc":[{"id":"1.226122413","rc":[{"batb":[[2,360,2.47]],"id":41200638},{"tv":124422.88,"batb":[[2,2.04,278.18],[1,2.06,97.83],[0,2.08,189.31]],"trd":[[2.08,1223.96],[2.1,1169.44]],"batl":[[2,2.16,58.18],[1,2.14,83.97],[0,2.12,154.89]],"id":51922},{"batb":[[0,4.4,170.94]],"id":50466254}],"tv":173982.36}],"ArrivalTime":1710508177949}
{"op":"mcm","id":2,"clk":"AJqIAQDVuQEAlM4B","pt":1710508178093,"mc":[{"id":"1.226122413","rc":[{"tv":494.71,"batb":[[2,420,2.45],[1,470,3.02],[0,520,1.64]],"trd":[[560,5.24],[530,5.77]],"ltp":530,"batl":[[0,580,4.73]],"id":54370634},{"batl":[[2,5.1,74.52],[1,5,80.24],[0,4.9,31.31]],"id":41122648},{"batb":[[2,23,55.22]],"id":55632148},{"batl":[[1,2.14,79.84]],"id":51922},{"batb":[[2,4.2,568.67],[0,4.4,144.72]],"id":50466254},{"batl":[[0,40,4.83]],"id":106596}],"tv":173986.6}],"ArrivalTime":1710508178099}
{"op":"mcm","id":2,"clk":"AJ6IAQDhuQEAoc4B","pt":1710508178148,"mc":[{"id":"1.226122413","rc":[{"batl":[[0,4.9,41.86]],"id":41122648},{"tv":124448.88,"batb":[[0,2.08,222.94]],"trd":[[2.08,1249.96]],"batl":[[1,2.14,73.87],[0,2.12,191.14]],"id":51922},{"batb":[[1,34,47.77]],"batl":[[1,42,11.39]],"id":106596}],"tv":174012.6}],"ArrivalTime":1710508178156}
{"op":"mcm","id":2,"clk":"AKWIAQDpuQEAps4B","pt":1710508178246,"mc":[{"id":"1.226122413","rc":[{"tv":497.99,"batb":[[1,470,2.43],[0,490,1.82]],"trd":[[520,13.04]],"ltp":520,"batl":[[2,650,1.51],[1,580,4.15],[0,530,1.27]],"id":54370634},{"batb":[[2,4.6,135.58],[0,4.8,128.44]],"id":41122648},{"batl":[[2,2.16,54.15]],"id":51922},{"batb":[[0,4.4,131.22]],"id":50466254},{"batb":[[0,36,25.8]],"id":106596}],"tv":174015.88}],"ArrivalTime":1710508178252}
{"op":"mcm","id":2,"clk":"AKyIAQDyuQEAsM4B","pt":1710508178356,"mc":[{"id":"1.226122413","rc":[{"batb":[[0,490,2]],"id":54370634},{"tv":124453.58,"batb":[[2,2.04,299.53],[0,2.08,220.59]],"trd":[[2.08,1254.66]],"id":51922}],"tv":174020.58}],"ArrivalTime":1710508178363}
{"op":"mcm","id":2,"clk":"ALKIAQD8uQEAt84B","pt":1710508178456,"mc":[{"id":"1.226122413","rc":[{"batb":[[2,420,2.89]],"id":54370634},{"batl":[[0,2.12,154.89]],"id":51922},{"tv":3043.03,"batb":[[0,50,78.55]],"trd":[[50,100.2]],"ltp":50,"id":49744721},{"batb":[[0,4.4,116.68]],"batl":[[2,4.7,48.66]],"id":50466254}],"tv":174022.58}],"ArrivalTime":1710508178462}
{"op":"mcm","id":2,"clk":"ALuIAQCGugEAvM4B","pt":1710508178560,"mc":[{"id":"1.226122413","rc":[{"batb":[[2,400,1.99],[1,420,2.89],[0,470,2.79]],"batl":[],"id":54370634},{"tv":15086.69,"trd":[[4.9,288.25]],"batl":[[0,4.9,38.22]],"id":41122648},{"batb":[[2,23,56.17]],"id":55632148},{"tv":124519.3,"batb":[[0,2.08,187.73]],"trd":[[2.08,1320.38]],"id":51922},{"batb":[[0,4.4,143.23]],"id":50466254},{"batl":[[1,42,17.72]],"id":106596}],"tv":174095.58}],"ArrivalTime":1710508178566}
{"op":"mcm","id":2,"clk":"AMOIAQCRugEAyM4B","pt":1710508178655,"mc":[{"id":"1.226122413","rc":[{"batb":[[1,420,2.67],[0,470,2.61]],"batl":[[2,720,1.35]],"id":54370634},{"batl":[[1,42,19.05]],"id":106596}]}],"ArrivalTime":1710508178662}
{"op":"mcm","id":2,"clk":"AMyIAQChugEA0M4B","pt":1710508178774,"mc":[{"id":"1.226122413","rc":[{"batb":[[1,420,2.9],[0,470,2.87]],"batl":[[2,650,1.51]],"id":54370634},{"batl":[[0,4.9,33.38]],"id":41122648},{"tv":124521.04,"batb":[[0,2.08,186.86]],"trd":[[2.08,1322.12]],"id":51922}],"tv":174097.32}],"ArrivalTime":1710508178781}
{"op":"mcm","id":2,"clk":"ANKIAQCougEA2c4B","pt":1710508178875,"mc":[{"id":"1.226122413","rc":[{"batl":[[2,730,1.67],[1,650,1.51]],"id":54370634},{"tv":124537.04,"batb":[[0,2.08,178.86]],"trd":[[2.08,1338.12]],"id":51922}],"tv":174113.32}],"ArrivalTime":1710508178883}
{"op":"mcm","id":2,"clk":"ANiIAQCwugEA6s4B","pt":1710508178972,"mc":[{"id":"1.226122413","rc":[{"batb":[[1,420,2.65],[0,470,2.69]],"batl":[],"id":54370634},{"batb":[[0,4.8,129.44]],"batl":[[1,5,66.96]],"id":41122648},{"tv":124545.64,"batb":[[1,2.06,147.83],[0,2.08,174.56]],"trd":[[2.08,1346.72]],"batl":[],"id":51922},{"batl":[[2,44,22.42]],"id":106596}],"tv":174121.92}],"ArrivalTime":1710508178979}
{"op":"mcm","id":2,"clk":"AOGIAQC4ugEA7s4B","pt":1710508179073,"mc":[{"id":"1.226122413","rc":[{"batb":[[2,400,2.47]],"batl":[[2,650,1.51],[1,570,1]],"id":54370634},{"batl":[[1,5,59.27]],"id":41122648}]}],"ArrivalTime":1710508179080}
{"op":"mcm","id":2,"clk":"AOuIAQDDugEAgc8B","pt":1710508179190,"mc":[{"id":"1.226122413","rc":[{"tv":15102.06,"batb":[[0,4.8,121.76]],"trd":[[4.8,42.95]],"ltp":4.8,"batl":[[0,4.9,35.38]],"id":41122648},{"tv":124572.84,"batb":[[0,2.08,160.96]],"trd":[[2.08,1373.92]],"id":51922}],"tv":174164.49}],"ArrivalTime":1710508179197}
{"op":"mcm","id":2,"clk":"AOyIAQDOugEAis8B","pt":1710508179281,"mc":[{"id":"1.226122413","rc":[{"batl":[[0,4.9,47.88]],"id":41122648},{"tv":2874.32,"batb":[[0,25,22.07]],"trd":[[25,606.78]],"batl":[[2,28,12.37]],"id":55632148},{"tv":124642.84,"batb":[],"trd":[[2.1,1173.44],[2.12,228.14]],"ltp":2.12,"batl":[[0,2.12,121.89]],"id":51922},{"batb":[],"batl":[[0,4.5,130.26]],"id":50466254},{"batb":[[0,36,27.51]],"id":106596}],"tv":174244.49}],"ArrivalTime":1710508179287}
{"op":"mcm","id":2,"clk":"APOIAQDWugEAlc8B","pt":1710508179389,"mc":[{"id":"1.226122413","rc":[{"batl":[[2,5.1,71.94],[0,4.9,66.22]],"id":41122648},{"batl":[[2,2.14,73.87],[1,2.12,48.44],[0,2.1,2]],"id":51922},{"batl":[[2,260,1.55],[1,230,1.26]],"id":66251581}]}],"ArrivalTime":1710508179396}
{"op":"mcm","id":2,"clk":"APqIAQDkugEAnc8B","pt":1710508179482,"mc":[{"id":"1.226122413","rc":[{"batb":[[2,420,2.25],[1,430,6.13]],"id":54370634},{"tv":2882.32,"batb":[[0,25,22.26]],"trd":[[25,614.78]],"batl":[[0,26,7.92]],"id":55632148},{"tv":124678.82,"batb":[[0,2.08,142.97]],"trd":[[2.08,1409.9]],"ltp":2.08,"batl":[[1,2.12,71.91]],"id":51922},{"tv":3043.63,"batb":[[0,50,78.25]],"trd":[[50,100.8]],"batl":[[2,65,23.18]],"id":49744721}],"tv":174289.07}],"ArrivalTime":1710508179488}
{"op":"mcm","id":2,"clk":"AIWJAQDrugEAq88B","pt":1710508179598,"mc":[{"id":"1.226122413","rc":[{"batl":[[0,530,2.27]],"id":54370634},{"tv":15123.7,"batb":[[1,4.7,72.15],[0,4.8,110.94]],"trd":[[4.8,64.59]],"batl":[[2,5.1,74.52]],"id":41122648},{"batb":[[2,360,2.24]],"id":41200638},{"tv":124697.43,"batb":[[2,2.06,147.83],[1,2.08,142.97],[0,2.1,26.93]],"trd":[[2.1,1191.93],[2.12,228.26]],"ltp":2.1,"batl":[[2,2.16,54.15],[1,2.14,73.87],[0,2.12,71.85]],"id":51922},{"tv":3044.23,"batb":[[0,50,77.95]],"trd":[[50,101.4]],"batl":[],"id":49744721},{"batb":[[2,4.2,572.49]],"id":50466254},{"batl":[[1,230,2.65]],"id":66251581}],"tv":174329.92}],"ArrivalTime":1710508179604}
{"op":"mcm","id":2,"clk":"AIeJAQD2ugEAts8B","pt":1710508179644,"mc":[{"id":"1.226122413","rc":[{"batb":[[0,4.8,111.37]],"id":41122648},{"tv":596.15,"batb":[[0,400,5.34]],"trd":[[410,15.78]],"batl":[[2,480,3.17],[1,450,1.84],[0,420,1.79]],"id":41200638},{"batb":[[0,25,27.94]],"id":55632148},{"tv":124847.32,"batb":[[2,2.04,299.53],[1,2.06,147.83],[0,2.08,94.96]],"trd":[[2.08,1505.92],[2.1,1245.8]],"ltp":2.08,"id":51922},{"tv":24107.52,"batb":[[0,4.4,142.64]],"trd":[[4.4,4746.37]],"ltp":4.4,"id":50466254},{"tv":2639.87,"batb":[[0,36,27.21]],"trd":[[36,64.4]],"ltp":36,"id":106596}],"tv":174483.87}],"ArrivalTime":1710508179651}
{"op":"mcm","id":2,"clk":"AJCJAQD9ugEAwc8B","pt":1710508179749,"mc":[{"id":"1.226122413","rc":[{"batl":[[2,730,1.67],[1,650,1.51]],"id":54370634},{"tv":15166.08,"batb":[[1,4.7,88.4],[0,4.8,90.18]],"trd":[[4.8,106.97]],"batl":[[1,5,71.77]],"id":41122648},{"tv":601.21,"batb":[[2,390,1.64],[1,400,4.6],[0,420,1.58]],"trd":[[420,8.06],[410,17.26]],"ltp":420,"batl":[[2,490,1.71],[1,480,3.17],[0,450,1.84]],"id":41200638},{"batl":[[1,27,29.15]],"id":55632148},{"tv":124918.58,"batb":[[0,2.08,66.9]],"trd":[[2.08,1577.18]],"batl":[[2,2.14,73.87],[1,2.12,71.85],[0,2.1,5]],"id":51922},{"tv":24114.64,"batb":[[2,4.2,568.67],[0,4.4,116.09]],"trd":[[4.5,3788.66]],"ltp":4.5,"batl":[[0,4.5,126.7]],"id":50466254}],"tv":174609.69}],"ArrivalTime":1710508179756}
{"op":"mcm","id":2,"clk":"AJiJAQCHuwEAyM8B","pt":1710508179855,"mc":[{"id":"1.226122413","rc":[{"batb":[[1,4.7,91.34]],"id":41122648},{"tv":603.59,"batb":[[2,360,2.24],[1,390,1.64],[0,400,4.99]],"trd":[[420,10.44]],"id":41200638},{"batl":[[1,27,28.41]],"id":55632148},{"tv":124918.74,"batb":[[0,2.08,66.82]],"trd":[[2.08,1577.34]],"batl":[[0,2.1,46.44]],"id":51922},{"batb":[[2,4.2,572.49]],"batl":[],"id":50466254}],"tv":174612.23}],"ArrivalTime":1710508179862}
{"op":"mcm","id":2,"clk":"AKiJAQCZuwEA1c8B","pt":1710508179973,"mc":[{"id":"1.226122413","rc":[{"batb":[[0,4.8,109.01]],"batl":[[2,5.1,35.73]],"id":41122648},{"tv":609.87,"batb":[[0,400,2.97]],"trd":[[420,13.45],[400,35.18]],"ltp":400,"id":41200638},{"batb":[[2,4.2,515.3],[0,4.4,142.96]],"batl":[[0,4.5,127.27]],"id":50466254}],"tv":174618.51}],"ArrivalTime":1710508179980}
{"op":"mcm","id":2,"clk":"AKqJAQCfuwEA388B","pt":1710508180057,"mc":[{"id":"1.226122413","rc":[{"tv":15201.46,"batb":[[0,4.8,91.32]],"trd":[[4.8,142.35]],"id":41122648},{"tv":124927.24,"batb":[[0,2.08,62.57]],"trd":[[2.08,1585.84]],"batl":[],"id":51922}],"tv":174662.39}],"ArrivalTime":1710508180067}
{"op":"mcm","id":2,"clk":"AL2JAQCwuwEA8M8B","pt":1710508180170,"mc":[{"id":"1.226122413","rc":[{"tv":514.51,"batb":[[2,430,6.13],[1,470,2.69],[0,910,1.94]],"trd":[[900,0.2],[890,2],[750,3.42],[730,2.1],[720,0.84],[670,0.4],[650,1.46],[630,1.56],[530,8.93],[520,14.42]],"ltp":900,"batl":[[2,0,0],[1,0,0],[0,1000,14.21]],"id":54370634},{"tv":15218.46,"batb":[[0,4.8,82.82]],"trd":[[4.8,159.35]],"batl":[[2,5.1,62.02]],"id":41122648},{"tv":630.28,"batb":[],"trd":[[490,3.42],[480,6.09],[460,2.04],[450,3.64],[440,3.02],[610,2.1],[620,1.1],[550,0.34],[540,3.42]],"ltp":620,"batl":[[2,800,3.34],[1,660,1.71],[0,650,1.48]],"id":41200638},{"batb":[[1,2.06,166.66]],"id":51922},{"batl":[[2,65,17.1]],"id":49744721},{"batb":[[2,4.2,572.49],[0,4.4,157.91]],"batl":[[2,4.7,44.66]],"id":50466254}],"tv":174716.32}],"ArrivalTime":1710508180177}
{"op":"mcm","id":2,"clk":"AMOJAQC2uwEA+s8B","pt":1710508180275,"mc":[{"id":"1.226122413","rc":[{"batb":[[2,420,2.25],[1,430,6.13]],"batl":[[0,1000,15.21]],"id":54370634},{"tv":15236.46,"batb":[[0,4.8,73.82]],"trd":[[4.8,177.35]],"id":41122648},{"tv":125009.08,"batb":[[1,2.06,171.86],[0,2.08,21.65]],"trd":[[2.08,1667.68]],"id":51922},{"tv":24122.64,"batb":[[0,4.4,153.91]],"trd":[[4.4,4754.37]],"ltp":4.4,"id":50466254},{"batb":[[2,34,47.77],[1,36,27.21],[0,38,2.98]],"id":106596}],"tv":174824.16}],"ArrivalTime":1710508180281}
{"op":"mcm","id":2,"clk":"AMqJAQDBuwEAgtAB","pt":1710508180379,"mc":[{"id":"1.226122413","rc":[{"tv":518.39,"batb":[[1,430,5.93],[0,450,2.62]],"trd":[[910,3.88]],"ltp":910,"batl":[[1,1000,15.91],[0,980,1.94]],"id":54370634},{"tv":15241.6,"batb":[[0,4.8,80.38]],"trd":[[4.9,293.39]],"ltp":4.9,"batl":[[0,4.9,63.65]],"id":41122648},{"batb":[[2,360,2.79]],"batl":[[2,660,1.71],[1,650,1.48],[0,610,2]],"id":41200638},{"batb":[[2,23,26.34]],"id":55632148},{"tv":125019.66,"batb":[[0,2.08,16.36]],"trd":[[2.08,1678.26]],"id":51922},{"batl":[[2,65,23.18]],"id":49744721}],"tv":174843.76}],"ArrivalTime":1710508180386}
{"op":"mcm","id":2,"clk":"AMuJAQDKuwEAitAB","pt":1710508180475,"mc":[{"id":"1.226122413","rc":[{"batl":[[2,1000,15.11],[1,990,1.5]],"id":54370634},{"tv":15271.88,"batb":[[0,4.8,65.24]],"trd":[[4.8,207.63]],"ltp":4.8,"id":41122648},{"batl":[[1,650,1.62]],"id":41200638},{"tv":2882.92,"batb":[[0,25,27.64]],"trd":[[25,615.38]],"id":55632148},{"tv":125021.97,"batb":[[0,2.08,60.85]],"trd":[[2.08,1680.57]],"id":51922},{"batb":[[1,4.3,115.88],[0,4.4,164.9]],"batl":[[0,4.5,114.11]],"id":50466254},{"batb":[[0,38,7.69]],"batl":[[1,42,12.72]],"id":106596}],"tv":174876.95}],"ArrivalTime":1710508180482}
{"op":"mcm","id":2,"clk":"ANmJAQDUuwEAmNAB","pt":1710508180595,"mc":[{"id":"1.226122413","rc":[{"batb":[[2,430,5.73],[1,440,1.84]],"batl":[[1,990,2.2]],"id":54370634},{"tv":15273.88,"batb":[[0,4.8,58.68]],"trd":[[4.9,295.39]],"ltp":4.9,"batl":[[0,4.9,62.65]],"id":41122648},{"tv":2883.52,"batb":[[2,23,56.17],[0,25,27.34]],"trd":[[25,615.98]],"batl":[[1,27,8.14]],"id":55632148},{"tv":125022.28,"batb":[[0,2.08,60.7]],"trd":[[2.08,1680.88]],"id":51922},{"tv":24128.64,"batb":[[0,4.4,174.77]],"trd":[[4.4,4760.37]],"id":50466254},{"batb":[[2,34,30.78]],"id":106596}],"tv":174885.86}],"ArrivalTime":1710508180602}
{"op":"mcm","id":2,"clk":"AN2JAQDauwEAntAB","pt":1710508180684,"mc":[{"id":"1.226122413","rc":[{"batb":[[0,450,2.82]],"batl":[[0,980,2.03]],"id":54370634},{"batl":[[2,5.1,56.11],[1,5,69.32],[0,4.9,52.1]],"id":41122648},{"tv":2924.07,"batb":[[0,25,7.06]],"trd":[[25,656.53]],"batl":[[2,28,9.47],[1,27,4.91]],"id":55632148},{"tv":125025.77,"batb":[[2,2.04,275.45],[1,2.06,149.28],[0,2.08,35.16]],"trd":[[2.08,1684.37]],"batl":[[0,2.1,63.33]],"id":51922},{"batl":[[2,65,20.67],[1,60,23.65]],"id":49744721},{"tv":24138.86,"batb":[[2,4.2,555.17],[1,4.3,101.38],[0,4.4,154.71]],"trd":[[4.4,4770.59]],"batl":[[1,4.6,16.93],[0,4.5,117.77]],"id":50466254},{"batl":[[2,44,19.91],[1,42,10.1]],"id":106596}],"tv":174940.12}],"ArrivalTime":1710508180691}
