{"op":"mcm","id":2,"clk":"AOSJAQDnuwEAq9AB","pt":1710508180801,"mc":[{"id":"1.226122413","rc":[{"batb":[],"batl":[[1,990,2.9]],"id":54370634},{"tv":15296.2,"batb":[[1,4.7,88.4],[0,4.8,103.33]],"trd":[[4.9,317.71]],"batl":[[0,4.9,40.94]],"id":41122648},{"batl":[[1,650,1.48],[0,610,2.15]],"id":41200638},{"tv":2938.19,"batb":[[2,22,25.51],[1,23,56.17],[0,24,16.42]],"trd":[[25,670.65]],"id":55632148},{"batl":[[1,2.12,77.83]],"id":51922},{"tv":3063.21,"trd":[[55,76.17]],"ltp":55,"batl":[[2,70,2.48],[1,65,20.67],[0,60,23.65]],"id":49744721},{"tv":24348.34,"batb":[[0,4.4,49.97]],"trd":[[4.4,4980.07]],"id":50466254},{"batl":[[0,210,5.48]],"id":66251581},{"tv":2655.25,"batb":[[2,32,34.78],[1,34,47.77],[0,36,27.21]],"trd":[[38,64.31]],"ltp":38,"id":106596}],"tv":175220.4}],"ArrivalTime":1710508180807}
{"op":"mcm","id":2,"clk":"AOqJAQDsuwEAtdAB","pt":1710508180848,"mc":[{"id":"1.226122413","rc":[{"batb":[[2,370,1],[0,400,3.43]],"batl":[[1,650,1.8],[0,610,2.31]],"id":41200638}]}],"ArrivalTime":1710508180854}
{"op":"mcm","id":2,"clk":"AO+JAQD7uwEAxNAB","pt":1710508180966,"mc":[{"id":"1.226122413","rc":[{"batb":[],"batl":[[1,990,3.6]],"id":54370634},{"tv":15413.56,"batb":[[1,4.7,91.34],[0,4.8,47.32]],"trd":[[4.8,324.99]],"ltp":4.8,"batl":[[0,4.9,22.6]],"id":41122648},{"tv":630.32,"trd":[[600,0.04]],"ltp":600,"batl":[[0,610,2.29]],"id":41200638},{"batb":[[0,24,17.1]],"batl":[[2,28,8.78]],"id":55632148},{"tv":3064.59,"batb":[[2,48,20.16],[1,50,77.95],[0,55,2.32]],"trd":[[60,1.38]],"ltp":60,"batl":[[0,60,22.96]],"id":49744721},{"tv":24360.1,"batb":[[0,4.4,46.74]],"trd":[[4.4,4991.83]],"id":50466254},{"tv":2659.47,"batb":[[0,36,27.97]],"trd":[[40,5.8]],"ltp":40,"batl":[[0,40,2.72]],"id":106596}],"tv":175355.16}],"ArrivalTime":1710508180972}
{"op":"mcm","id":2,"clk":"APWJAQCGvAEA0NAB","pt":1710508181072,"mc":[{"id":"1.226122413","rc":[{"tv":15458.76,"batb":[[2,4.7,91.34],[1,4.8,47.32],[0,4.9,13.54]],"trd":[[4.9,362.91]],"ltp":4.9,"batl":[[2,5.2,27.24],[1,5.1,56.11],[0,5,69.32]],"id":41122648},{"batl":[[2,650,1.8],[1,610,2.15],[0,600,2.7]],"id":41200638},{"tv":2972.39,"batb":[[2,21,82.93],[1,22,25.51],[0,23,56.18]],"trd":[[25,672.01],[24,340.65]],"ltp":24,"batl":[[2,27,4.91],[1,26,7.92],[0,25,3.56]],"id":55632148},{"batb":[],"batl":[[0,2.1,57.44]],"id":51922},{"tv":3069.23,"batb":[[2,46,26.21],[1,48,20.16],[0,50,77.95]],"trd":[[55,80.81]],"ltp":55,"batl":[[1,65,26]],"id":49744721},{"batb":[[0,4.4,26.51]],"id":50466254},{"tv":2684.07,"batb":[[0,36,15.67]],"trd":[[38,65.83],[36,87.48]],"ltp":36,"id":106596}],"tv":175463.8}],"ArrivalTime":1710508181079}
{"op":"mcm","id":2,"clk":"APyJAQCJvAEA2NAB","pt":1710508181163,"mc":[{"id":"1.226122413","rc":[{"tv":15485.84,"batb":[[2,4.6,135.58],[1,4.7,104.47],[0,4.8,51.91]],"trd":[[4.9,389.99]],"batl":[[2,5.1,56.11],[1,5,69.32],[0,4.9,17.56]],"id":41122648},{"batb":[[2,22,25.51],[1,23,56.17],[0,24,1.01]],"batl":[],"id":55632148},{"tv":125026.12,"batb":[[0,2.08,66.39]],"trd":[[2.08,1684.72]],"id":51922},{"tv":3071.09,"batb":[[2,48,19.76],[1,50,77.95],[0,55,10.97]],"trd":[[55,82.67]],"batl":[[1,65,26.66],[0,60,23.74]],"id":49744721},{"tv":24595.65,"batb":[[0,4.4,34.52]],"trd":[[4.5,4024.21]],"ltp":4.5,"batl":[[2,4.8,27.31],[1,4.7,44.66],[0,4.6,16.93]],"id":50466254},{"tv":2684.67,"batb":[[0,36,15.37]],"trd":[[36,88.08]],"batl":[[0,40,3.05]],"id":106596}],"tv":175729.24}],"ArrivalTime":1710508181169}
{"op":"mcm","id":2,"clk":"AIWKAQCYvAEA49AB","pt":1710508181278,"mc":[{"id":"1.226122413","rc":[{"tv":15489.58,"batb":[[1,4.7,101.53],[0,4.8,83.69]],"trd":[[4.9,393.73]],"batl":[[0,4.9,15.69]],"id":41122648},{"batb":[[2,22,24.16],[0,24,4.65]],"batl":[],"id":55632148},{"tv":125031.48,"batb":[[0,2.08,63.71]],"trd":[[2.08,1690.08]],"batl":[],"id":51922},{"batl":[[0,60,21.62]],"id":49744721},{"batb":[[0,4.4,61.47]],"batl":[],"id":50466254},{"batb":[[0,36,19.23]],"batl":[[2,42,10.1],[1,40,3.05],[0,38,2.73]],"id":106596}],"tv":175738.34}],"ArrivalTime":1710508181285}
{"op":"mcm","id":2,"clk":"AIaKAQCcvAEA6NAB","pt":1710508181368,"mc":[{"id":"1.226122413","rc":[{"tv":518.41,"trd":[[980,0.02]],"ltp":980,"batl":[[1,990,4.04],[0,980,2.02]],"id":54370634},{"tv":15489.88,"trd":[[4.9,394.03]],"batl":[[0,4.9,16.69]],"id":41122648},{"batl":[[1,610,2],[0,600,2.84]],"id":41200638},{"tv":2977.49,"batb":[[0,24,1.12]],"trd":[[25,672.05],[24,345.71]],"batl":[[0,25,3.54]],"id":55632148},{"tv":125051.5,"trd":[[2.1,1265.82]],"ltp":2.1,"batl":[[0,2.1,47.43]],"id":51922},{"tv":3075.09,"batb":[[0,55,9.44]],"trd":[[55,86.67]],"batl":[[2,70,3.04],[1,65,26],[0,60,20.84]],"id":49744721},{"batb":[[2,4.3,101.38],[1,4.4,61.47],[0,4.5,53.3]],"batl":[[1,4.7,49.73],[0,4.6,17.49]],"id":50466254},{"tv":2684.71,"trd":[[38,65.87]],"ltp":38,"batl":[[0,38,2.71]],"id":106596}],"tv":175767.82}],"ArrivalTime":1710508181374}
{"op":"mcm","id":2,"clk":"AJSKAQCmvAEA89AB","pt":1710508181479,"mc":[{"id":"1.226122413","rc":[{"batb":[[2,22,21.15],[1,23,53.29]],"batl":[],"id":55632148},{"batb":[[1,2.06,169.27]],"batl":[],"id":51922},{"batb":[[0,55,10.06]],"id":49744721},{"tv":24622.75,"batb":[[0,4.5,59.39]],"trd":[[4.5,4051.31]],"batl":[],"id":50466254},{"tv":2686.23,"trd":[[38,67.39]],"batl":[[0,38,1.95]],"id":106596}],"tv":175796.44}],"ArrivalTime":1710508181485}
{"op":"mcm","id":2,"clk":"AJWKAQCxvAEA+NAB","pt":1710508181577,"mc":[{"id":"1.226122413","rc":[{"tv":15505.88,"trd":[[4.9,410.03]],"batl":[[0,4.9,21.34]],"id":41122648},{"batb":[[2,21,82.93],[1,22,21.15],[0,23,53.29]],"id":55632148},{"tv":125054.7,"batb":[[0,2.08,73.11]],"trd":[[2.08,1693.28]],"ltp":2.08,"id":51922},{"batb":[[0,55,9.93]],"id":49744721},{"batb":[[0,4.5,58.68]],"batl":[[0,4.6,37.06]],"id":50466254},{"batl":[[1,40,2.72]],"id":106596}],"tv":175815.64}],"ArrivalTime":1710508181584}
{"op":"mcm","id":2,"clk":"AKKKAQDAvAEAhNEB","pt":1710508181679,"mc":[{"id":"1.226122413","rc":[{"batb":[[2,440,1.84],[1,450,2.82],[0,460,3.43]],"id":54370634},{"batb":[[2,400,3.43],[1,410,2.14],[0,430,3.15]],"id":41200638},{"tv":125084,"batb":[[0,2.08,58.46]],"trd":[[2.08,1722.58]],"batl":[],"id":51922},{"batb":[[0,55,4.55]],"id":49744721},{"batb":[[2,4.3,104.99]],"id":50466254}],"tv":175844.94}],"ArrivalTime":1710508181686}
{"op":"mcm","id":2,"clk":"AKOKAQDLvAEAi9EB","pt":1710508181806,"mc":[{"id":"1.226122413","rc":[{"batl":[[2,1000,15.21]],"id":54370634},{"batb":[[1,410,2.39]],"id":41200638},{"batl":[[2,27,16.36]],"id":55632148},{"tv":125117.88,"batb":[[2,2.04,317.18],[1,2.06,149.28],[0,2.08,57.97]],"trd":[[2.08,1723.56],[2.1,1298.72]],"batl":[[0,2.1,30.98]],"id":51922}],"tv":175878.82}],"ArrivalTime":1710508181813}
{"op":"mcm","id":2,"clk":"ALKKAQDYvAEAltEB","pt":1710508181897,"mc":[{"id":"1.226122413","rc":[{"batb":[[2,400,1.56]],"batl":[[2,610,2],[1,600,2.84],[0,590,1.18]],"id":41200638},{"tv":2977.85,"trd":[[25,672.41]],"ltp":25,"batl":[[0,25,3.36]],"id":55632148},{"tv":125127.88,"batb":[[2,2.04,297.48]],"trd":[[2.1,1308.72]],"ltp":2.1,"batl":[[2,2.14,78],[1,2.12,82.09],[0,2.1,25.98]],"id":51922},{"batl":[[0,60,22.84]],"id":49744721}],"tv":175889.18}],"ArrivalTime":1710508181903}
{"op":"mcm","id":2,"clk":"ALSKAQDlvAEAntEB","pt":1710508181997,"mc":[{"id":"1.226122413","rc":[{"batb":[[1,450,2.62],[0,460,3.61]],"id":54370634},{"batl":[[2,5.1,53.53]],"id":41122648},{"tv":125128.08,"batb":[[0,2.08,57.88]],"trd":[[2.08,1723.74],[2.1,1308.74]],"ltp":2.08,"batl":[[0,2.1,25.97]],"id":51922},{"tv":3076.39,"batb":[],"trd":[[60,2.68]],"ltp":60,"batl":[[0,60,22.19]],"id":49744721},{"tv":24648.87,"batb":[[0,4.5,45.62]],"trd":[[4.5,4077.43]],"batl":[[1,4.7,50.27]],"id":50466254},{"batl":[[1,230,1.26]],"id":66251581},{"tv":2690.13,"batb":[[1,34,64.42]],"trd":[[38,71.29]],"batl":[[2,44,19.91],[1,42,10.1],[0,40,2.72]],"id":106596}],"tv":175920.7}],"ArrivalTime":1710508182004}
{"op":"mcm","id":2,"clk":"ALyKAQDuvAEApdEB","pt":1710508182050,"mc":[{"id":"1.226122413","rc":[{"batb":[[2,4.6,132.49]],"id":41122648},{"batb":[[2,400,1.81]],"batl":[[1,600,2.7],[0,590,2.5]],"id":41200638},{"batl":[[0,25,8.23]],"id":55632148},{"batl":[[0,2.1,32.29]],"id":51922},{"tv":3086.39,"batb":[[2,46,28.2],[1,48,19.76],[0,50,56.37]],"trd":[[55,95.77],[50,102.3]],"ltp":50,"id":49744721},{"batb":[[2,4.3,101.38]],"id":50466254},{"batb":[[1,34,47.77]],"id":106596}],"tv":175930.7}],"ArrivalTime":1710508182057}
{"op":"mcm","id":2,"clk":"AMiKAQD4vAEAtNEB","pt":1710508182157,"mc":[{"id":"1.226122413","rc":[{"batb":[[1,450,3.62]],"batl":[[2,990,4.04],[1,980,1.93],[0,970,2]],"id":54370634},{"tv":15506.3,"batb":[[0,4.8,83.48]],"trd":[[4.8,325.41]],"ltp":4.8,"batl":[[2,5.1,56.11]],"id":41122648},{"batb":[],"batl":[[0,590,3.68]],"id":41200638},{"tv":2977.94,"batb":[[0,23,53.25]],"trd":[[23,148.41]],"ltp":23,"batl":[],"id":55632148},{"tv":125133,"batb":[[0,2.08,69.94]],"trd":[[2.08,1728.66]],"id":51922},{"batl":[[2,70,2.48]],"id":49744721},{"tv":24649.33,"batb":[[2,4.3,104.99],[1,4.4,87.22],[0,4.5,45.39]],"trd":[[4.5,4077.89]],"batl":[[2,4.8,27.84]],"id":50466254},{"batl":[[1,230,2.65]],"id":66251581},{"batb":[[0,36,19.99]],"id":106596}],"tv":175936.59}],"ArrivalTime":1710508182164}
{"op":"mcm","id":2,"clk":"AM2KAQD/vAEAvNEB","pt":1710508182257,"mc":[{"id":"1.226122413","rc":[{"batb":[[0,460,3.87]],"batl":[[2,1000,15.31]],"id":54370634},{"batl":[[2,27,16.97]],"id":55632148},{"batb":[],"batl":[[2,2.14,73.87],[1,2.12,77.83],[0,2.1,38.02]],"id":51922},{"batb":[[0,50,57.88]],"batl":[[2,65,26],[1,60,22.19],[0,55,6.53]],"id":49744721}]}],"ArrivalTime":1710508182263}
{"op":"mcm","id":2,"clk":"ANSKAQCKvQEAw9EB","pt":1710508182362,"mc":[{"id":"1.226122413","rc":[{"batb":[[1,4.7,105.59]],"batl":[[2,5.1,17.32]],"id":41122648},{"batl":[[0,590,4.49]],"id":41200638},{"batl":[[2,26,7.92],[1,25,11.24],[0,24,4.55]],"id":55632148},{"tv":125148.88,"batb":[[0,2.08,62]],"trd":[[2.08,1744.54]],"id":51922},{"batl":[[1,60,20.19],[0,55,12.9]],"id":49744721}],"tv":175952.47}],"ArrivalTime":1710508182368}
{"op":"mcm","id":2,"clk":"ANmKAQCRvQEAz9EB","pt":1710508182462,"mc":[{"id":"1.226122413","rc":[{"batl":[[2,650,1.8],[1,610,2.14]],"id":41200638},{"tv":125149.48,"batb":[[0,2.08,61.7]],"trd":[[2.08,1745.14]],"id":51922},{"batb":[[0,50,56.37]],"id":49744721},{"batb":[[2,4.3,101.38]],"id":50466254}],"tv":175953.07}],"ArrivalTime":1710508182469}
{"op":"mcm","id":2,"clk":"AN2KAQCYvQEA3NEB","pt":1710508182567,"mc":[{"id":"1.226122413","rc":[{"batb":[],"batl":[[2,980,1.93],[1,970,2],[0,950,2.82]],"id":54370634},{"batb":[],"batl":[[2,5.1,56.11],[0,4.9,23.61]],"id":41122648},{"batb":[[2,400,2.04]],"id":41200638},{"batb":[[0,2.08,66.9]],"id":51922},{"tv":3099.45,"trd":[[55,108.83]],"ltp":55,"batl":[[2,65,19.92],[0,55,6.37]],"id":49744721},{"batb":[[0,4.5,71.15]],"batl":[],"id":50466254}],"tv":175966.13}],"ArrivalTime":1710508182573}
{"op":"mcm","id":2,"clk":"AOSKAQCmvQEA59EB","pt":1710508182673,"mc":[{"id":"1.226122413","rc":[{"tv":125149.68,"batb":[[0,2.08,237.7]],"trd":[[2.1,1308.94]],"ltp":2.1,"batl":[[0,2.1,37.92]],"id":51922},{"tv":3104.87,"trd":[[55,114.25]],"batl":[[0,55,3.66]],"id":49744721},{"batb":[[2,4.3,157.24]],"id":50466254},{"tv":2691.65,"batb":[[0,36,19.23]],"trd":[[38,72.81]],"batl":[[1,42,16.02]],"id":106596}],"tv":175973.27}],"ArrivalTime":1710508182680}
{"op":"mcm","id":2,"clk":"AOyKAQCvvQEA8dEB","pt":1710508182779,"mc":[{"id":"1.226122413","rc":[{"batb":[[1,410,4.39]],"id":41200638},{"batb":[[0,23,23.42]],"id":55632148},{"tv":125149.87,"batb":[[2,2.04,245.62],[0,2.08,237.61]],"trd":[[2.08,1745.33]],"ltp":2.08,"id":51922},{"batl":[[2,70,2.48],[1,65,19.92],[0,60,20.19]],"id":49744721}],"tv":175973.46}],"ArrivalTime":1710508182785}
{"op":"mcm","id":2,"clk":"APCKAQC2vQEA99EB","pt":1710508182881,"mc":[{"id":"1.226122413","rc":[{"batb":[[2,21,79.73]],"batl":[],"id":55632148},{"tv":125225.87,"batb":[[0,2.08,237.53]],"trd":[[2.08,1745.49],[2.1,1384.78]],"ltp":2.1,"batl":[[2,2.16,58.18],[1,2.14,73.87],[0,2.12,77.83]],"id":51922},{"batl":[[1,65,26]],"id":49744721},{"batb":[[2,4.3,165.08],[0,4.5,81.37]],"id":50466254},{"tv":744.83,"batb":[[0,190,13.34]],"trd":[[200,48.49]],"ltp":200,"id":66251581}],"tv":176049.52}],"ArrivalTime":1710508182888}
{"op":"mcm","id":2,"clk":"AJ+LAQDmvQEAptIB","pt":1710508183428,"mc":[{"id":"1.226122413","rc":[{"batl":[[2,950,2.82],[1,940,2.56],[0,890,2.82]],"id":54370634},{"tv":15511.3,"batb":[[0,4.8,59.53]],"trd":[[4.8,330.41]],"batl":[[0,4.9,25.66]],"id":41122648},{"batb":[[0,430,5.13]],"batl":[[2,610,2.17],[1,590,4.35],[0,580,3.73]],"id":41200638},{"batb":[[0,23,11.68],[2,21,111.05]],"batl":[[2,26,9.67]],"id":55632148},{"tv":125340.61,"batb":[[2,2.04,265.7],[1,2.06,149.28],[0,2.08,210.37]],"trd":[[2.1,1417.18],[2.08,1827.83]],"ltp":2.1,"batl":[[2,2.14,73.87],[1,2.12,184.41],[0,2.1,31.37]],"id":51922},{"batl":[[1,65,26.36]],"id":49744721},{"tv":24723.07,"batb":[[0,4.5,92.99]],"trd":[[4.6,2056.34],[4.5,4080.39]],"batl":[[0,4.6,1.44]],"id":50466254},{"batl":[[1,230,2.75],[0,210,6.55]],"id":66251581},{"tv":2693.18,"batb":[[1,34,47.77],[0,36,19.23]],"trd":[[38,74.34]],"batl":[[0,38,2.74],[2,42,10.1],[1,40,3.29]],"id":106596}],"tv":176244.53,"con":true}],"ArrivalTime":1710508183435}
{"op":"mcm","id":2,"clk":"AKiLAQDmvQEAq9IB","pt":1710508183462,"mc":[{"id":"1.226122413","rc":[{"batb":[],"batl":[[1,5,73.73],[0,4.9,23.61]],"id":41122648},{"batb":[[1,410,2.25]],"id":41200638},{"batl":[[2,26,15.01]],"id":55632148},{"batl":[[1,2.12,194.7]],"id":51922},{"tv":24725.95,"batb":[[2,4.4,87.22],[1,4.5,92.99],[0,4.6,18.45]],"trd":[[4.6,2059.22]],"ltp":4.6,"batl":[[2,4.9,37.44],[1,4.8,27.84],[0,4.7,54.97]],"id":50466254}],"tv":176247.41}],"ArrivalTime":1710508183469}
{"op":"mcm","id":2,"clk":"AKqLAQDzvQEAs9IB","pt":1710508183567,"mc":[{"id":"1.226122413","rc":[{"tv":15513.01,"batb":[[0,4.8,58.68]],"trd":[[4.8,332.12]],"id":41122648},{"batb":[[0,23,16.45]],"id":55632148},{"tv":125348.46,"batb":[[0,2.08,206.45]],"trd":[[2.08,1835.68]],"ltp":2.08,"batl":[[2,2.14,78],[1,2.12,301.28],[0,2.1,60.67]],"id":51922},{"tv":3106.13,"trd":[[55,115.51]],"batl":[[2,65,26.36],[1,60,20.19],[0,55,1.93]],"id":49744721},{"tv":24762.86,"batb":[[2,4.3,168.69],[1,4.4,87.22],[0,4.5,92.99]],"trd":[[4.6,2096.13]],"batl":[],"id":50466254},{"tv":2694.7,"trd":[[38,75.86]],"batl":[[0,38,1.98]],"id":106596}],"tv":176296.66}],"ArrivalTime":1710508183574}
{"op":"mcm","id":2,"clk":"ALKLAQD6vQEAwtIB","pt":1710508183670,"mc":[{"id":"1.226122413","rc":[{"batb":[[0,2.08,191.93]],"id":51922},{"batb":[],"batl":[[0,4.7,31.22]],"id":50466254},{"tv":2704.7,"batb":[[0,36,14.23]],"trd":[[36,98.08]],"ltp":36,"id":106596}],"tv":176306.66}],"ArrivalTime":1710508183677}
{"op":"mcm","id":2,"clk":"AL2LAQCFvgEAy9IB","pt":1710508183769,"mc":[{"id":"1.226122413","rc":[{"tv":125368.46,"batb":[[0,2.08,193.39]],"trd":[[2.08,1855.68]],"batl":[[2,2.14,73.87],[0,2.1,66.29]],"id":51922},{"tv":3109.99,"trd":[[55,119.37]],"batl":[[2,70,2.48],[1,65,26.36],[0,60,20.19]],"id":49744721},{"batb":[[2,4.3,186.43]],"batl":[],"id":50466254}],"tv":176330.52}],"ArrivalTime":1710508183775}
{"op":"mcm","id":2,"clk":"AL6LAQCPvgEA0tIB","pt":1710508183871,"mc":[{"id":"1.226122413","rc":[{"batb":[],"batl":[[2,970,2],[1,950,2.82],[0,890,2.92]],"id":54370634},{"tv":15519.21,"batb":[[0,4.8,55.58]],"trd":[[4.8,338.32]],"id":41122648},{"batl":[[2,26,15.81],[1,25,12.11],[0,24,5.5]],"id":55632148},{"tv":24763.24,"batb":[[0,4.5,92.8]],"trd":[[4.5,4080.77]],"ltp":4.5,"batl":[[2,4.8,27.84],[1,4.7,31.22],[0,4.6,3.59]],"id":50466254},{"batb":[[0,36,15.03]],"id":106596}],"tv":176337.1}],"ArrivalTime":1710508183878}
{"op":"mcm","id":2,"clk":"AMSLAQCZvgEA2dIB","pt":1710508183974,"mc":[{"id":"1.226122413","rc":[{"tv":2978.54,"trd":[[24,346.31]],"ltp":24,"batl":[[1,25,12.73],[0,24,5.2]],"id":55632148},{"batb":[],"batl":[[1,2.12,407.86]],"id":51922},{"batb":[[0,50,57]],"id":49744721}],"tv":176337.7}],"ArrivalTime":1710508183981}
{"op":"mcm","id":2,"clk":"AMqLAQCkvgEA69IB","pt":1710508184084,"mc":[{"id":"1.226122413","rc":[{"tv":518.61,"trd":[[530,9.13]],"ltp":530,"batl":[[0,890,2.82]],"id":54370634},{"tv":125368.85,"batb":[[0,2.08,193.19]],"trd":[[2.08,1856.07]],"id":51922},{"tv":24779.36,"batb":[[2,4.3,190.04],[1,4.4,90.64]],"trd":[[4.6,2112.25]],"ltp":4.6,"batl":[[0,4.6,29.01]],"id":50466254},{"tv":2708.66,"batb":[[2,34,47.77],[1,36,15.03],[0,38,1.02]],"trd":[[38,79.82]],"ltp":38,"batl":[[2,44,19.91],[1,42,10.1],[0,40,3.29]],"id":106596}],"tv":176358.37}],"ArrivalTime":1710508184090}
{"op":"mcm","id":2,"clk":"ANWLAQCtvgEA79IB","pt":1710508184182,"mc":[{"id":"1.226122413","rc":[{"tv":15529.21,"trd":[[4.9,420.03]],"ltp":4.9,"batl":[[0,4.9,18.61]],"id":41122648},{"tv":3111.99,"batb":[[0,50,56]],"trd":[[55,120.63],[50,103.04]],"ltp":50,"id":49744721}],"tv":176370.37}],"ArrivalTime":1710508184189}
{"op":"mcm","id":2,"clk":"AN6LAQC5vgEA+9IB","pt":1710508184283,"mc":[{"id":"1.226122413","rc":[{"batb":[[0,38,3.67]],"batl":[[2,44,20.47],[1,42,10.71]],"id":106596}]}],"ArrivalTime":1710508184289}
{"op":"mcm","id":2,"clk":"AOuLAQDDvgEAgtMB","pt":1710508184416,"mc":[{"id":"1.226122413","rc":[{"batb":[],"batl":[[2,950,2.82],[1,890,2.82],[0,850,2]],"id":54370634},{"tv":125417.27,"batb":[[2,2.04,285.78],[0,2.08,168.98]],"trd":[[2.08,1904.49]],"batl":[[1,2.12,514.44]],"id":51922},{"batb":[[0,50,56.63]],"batl":[[2,70,4.45]],"id":49744721},{"batb":[[0,4.5,93.36]],"id":50466254},{"tv":745.21,"batb":[[1,180,4],[0,190,13.15]],"trd":[[200,48.75],[190,61.8]],"ltp":190,"batl":[],"id":66251581},{"tv":2710.56,"batb":[[0,38,2.72]],"trd":[[38,81.72]],"batl":[[1,42,15.92]],"id":106596}],"tv":176421.07}],"ArrivalTime":1710508184422}
{"op":"mcm","id":2,"clk":"AO2LAQDKvgEAhtMB","pt":1710508184501,"mc":[{"id":"1.226122413","rc":[{"batl":[[2,890,2.82],[1,880,2.56]],"id":54370634},{"batl":[[2,5.1,53.53]],"id":41122648},{"tv":125417.38,"batb":[[0,2.08,168.93]],"trd":[[2.08,1904.6]],"batl":[],"id":51922},{"batb":[[1,4.4,87.22]],"id":50466254},{"batl":[[1,230,1.36]],"id":66251581},{"batl":[[2,44,19.91],[1,42,15.31]],"id":106596}],"tv":176421.18}],"ArrivalTime":1710508184508}
{"op":"mcm","id":2,"clk":"APeLAQDOvgEAjdMB","pt":1710508184556,"mc":[{"id":"1.226122413","rc":[{"tv":15566.42,"batb":[[2,4.7,105.59],[1,4.8,55.58],[0,4.9,11.4]],"trd":[[4.9,457.24]],"batl":[[2,5.2,24.74],[1,5.1,53.53],[0,5,73.73]],"id":41122648},{"batb":[[2,360,1.33],[1,400,2.29]],"id":41200638},{"batb":[],"batl":[[0,2.1,84.93]],"id":51922},{"tv":24779.96,"batb":[[0,4.5,93.06]],"trd":[[4.5,4081.37]],"ltp":4.5,"id":50466254}],"tv":176458.99}],"ArrivalTime":1710508184562}
{"op":"mcm","id":2,"clk":"AP6LAQDXvgEAk9MB","pt":1710508184656,"mc":[{"id":"1.226122413","rc":[{"batb":[[1,4.8,73.96]],"batl":[[1,5.1,56.11]],"id":41122648},{"batb":[[2,400,2.04],[1,430,5.13],[0,440,2]],"id":41200638},{"tv":2992.09,"batb":[[0,23,9.67]],"trd":[[23,161.96]],"ltp":23,"id":55632148},{"batb":[[2,2.04,245.62],[0,2.08,173.93]],"batl":[[2,2.14,78],[0,2.1,99.93]],"id":51922},{"batl":[[0,4.6,42.32]],"id":50466254},{"batl":[[2,230,1.36],[1,220,1.46]],"id":66251581},{"tv":2715.7,"batb":[[2,32,37.67],[1,34,47.77],[0,36,15.18]],"trd":[[38,86.86]],"batl":[[1,42,10.1]],"id":106596}],"tv":176477.68}],"ArrivalTime":1710508184663}
{"op":"mcm","id":2,"clk":"AImMAQDevgEAmtMB","pt":1710508184765,"mc":[{"id":"1.226122413","rc":[{"tv":15589.22,"batb":[[2,4.6,132.49],[1,4.7,88.4],[0,4.8,73.96]],"trd":[[4.9,480.04]],"batl":[[2,5.1,56.11],[1,5,73.73],[0,4.9,3.16]],"id":41122648},{"batb":[[0,23,4.9]],"id":55632148},{"batb":[[1,2.06,179.68]],"batl":[[1,2.12,621.02]],"id":51922},{"tv":24780.36,"batb":[[0,4.5,92.86]],"trd":[[4.5,4081.77]],"id":50466254}],"tv":176500.88}],"ArrivalTime":1710508184772}
{"op":"mcm","id":2,"clk":"AI+MAQDyvgEApdMB","pt":1710508184872,"mc":[{"id":"1.226122413","rc":[{"batl":[[0,850,2.78]],"id":54370634},{"batl":[[2,5.1,17.32]],"id":41122648},{"tv":3001.88,"batb":[[2,20,13.36],[1,21,111.05],[0,22,21.15]],"trd":[[23,171.75]],"batl":[[0,24,5.77]],"id":55632148},{"tv":125419.15,"batb":[[0,2.08,173.04]],"trd":[[2.08,1906.37]],"batl":[[2,2.14,73.87]],"id":51922},{"batb":[[2,4.3,134.18]],"id":50466254},{"batb":[[0,36,15.03]],"id":106596}],"tv":176512.44}],"ArrivalTime":1710508184878}
{"op":"mcm","id":2,"clk":"AJeMAQD2vgEAq9MB","pt":1710508184969,"mc":[{"id":"1.226122413","rc":[{"tv":15596.26,"batb":[[0,4.8,70.46]],"trd":[[4.9,480.08],[4.8,345.32]],"batl":[[0,4.9,3.14]],"id":41122648},{"batb":[[2,400,2.26]],"id":41200638},{"batl":[[1,25,11.86],[0,24,4.82]],"id":55632148},{"tv":24784.36,"batb":[[0,4.5,90.86]],"trd":[[4.5,4085.77]],"batl":[],"id":50466254}],"tv":176523.48}],"ArrivalTime":1710508184976}
{"op":"mcm","id":2,"clk":"AKKMAQCDvwEAs9MB","pt":1710508185075,"mc":[{"id":"1.226122413","rc":[{"batb":[[1,450,1.2]],"id":54370634},{"batb":[[1,430,3.15]],"id":41200638},{"batb":[[1,21,116.15],[0,22,20.15]],"id":55632148},{"batl":[[1,65,20.28]],"id":49744721}]}],"ArrivalTime":1710508185082}
{"op":"mcm","id":2,"clk":"AKuMAQCLvwEAvNMB","pt":1710508185177,"mc":[{"id":"1.226122413","rc":[{"batb":[[2,450,1.2],[1,460,3.87],[0,480,2.43]],"id":54370634},{"tv":15605.4,"batb":[[0,4.8,79.16]],"trd":[[4.9,489.22]],"batl":[[2,5.1,56.11],[0,4.9,2.47]],"id":41122648},{"tv":3003.02,"trd":[[23,172.89]],"batl":[[1,25,8.85],[0,24,8.06]],"id":55632148},{"tv":125570.03,"batb":[],"trd":[[2.1,1568.06]],"ltp":2.1,"batl":[[1,2.12,615.04],[0,2.1,24.49]],"id":51922},{"tv":24784.74,"batb":[[2,4.3,190.04],[0,4.5,90.67]],"trd":[[4.5,4086.15]],"id":50466254}],"tv":176685.02}],"ArrivalTime":1710508185183}
{"op":"mcm","id":2,"clk":"ALSMAQCZvwEAxdMB","pt":1710508185290,"mc":[{"id":"1.226122413","rc":[{"tv":15610.34,"batb":[[0,4.8,70.46]],"trd":[[4.9,494.16]],"batl":[[2,5.2,24.74],[1,5.1,56.11],[0,5,71.73]],"id":41122648},{"batb":[[2,400,2.74]],"batl":[[0,580,3.96]],"id":41200638},{"batb":[[1,21,83.48],[0,22,15.88]],"id":55632148},{"tv":125582.34,"batb":[[0,2.08,172.89]],"trd":[[2.08,1906.68],[2.1,1580.06]],"ltp":2.08,"batl":[[2,2.14,78],[1,2.12,619.3],[0,2.1,18.49]],"id":51922},{"batb":[],"batl":[[2,70,10.1]],"id":49744721},{"tv":24869.38,"batb":[[2,4.4,87.22],[1,4.5,90.67],[0,4.6,12.78]],"trd":[[4.6,2196.89]],"ltp":4.6,"batl":[[2,4.9,39.94],[1,4.8,27.84],[0,4.7,31.22]],"id":50466254}],"tv":176786.91}],"ArrivalTime":1710508185297}
{"op":"mcm","id":2,"clk":"ALuMAQCcvwEAzdMB","pt":1710508185386,"mc":[{"id":"1.226122413","rc":[{"batb":[[2,460,3.61],[1,470,1.91]],"batl":[[2,950,2.82],[1,890,2.82]],"id":54370634},{"tv":15614.34,"batb":[[0,4.8,68.46]],"trd":[[4.8,349.32]],"ltp":4.8,"batl":[[2,5.1,56.11],[1,5,71.73],[0,4.9,17.97]],"id":41122648},{"tv":3010.32,"trd":[[23,180.19]],"batl":[[2,25,8.85],[1,24,8.06],[0,23,1.03]],"id":55632148},{"batb":[],"batl":[[0,2.1,54.23]],"id":51922},{"batb":[[2,4.4,90.64]],"id":50466254},{"batl":[[2,42,10.1],[1,40,3.29],[0,38,2.71]],"id":106596}],"tv":176798.21}],"ArrivalTime":1710508185393}
{"op":"mcm","id":2,"clk":"AMGMAQClvwEA1tMB","pt":1710508185493,"mc":[{"id":"1.226122413","rc":[{"batb":[[2,460,3.43],[0,480,2.6]],"id":54370634},{"batb":[],"batl":[[0,4.9,30.56]],"id":41122648},{"batb":[[1,21,116.15],[0,22,12.16]],"batl":[[1,24,8.7]],"id":55632148},{"tv":125741.59,"batb":[[0,2.08,93.26]],"trd":[[2.08,2065.93]],"batl":[[1,2.12,615.04],[0,2.1,86.02]],"id":51922},{"batb":[[1,4.5,93.25],[0,4.6,33.43]],"batl":[[1,4.8,39.43]],"id":50466254},{"batb":[[1,34,30.78]],"id":106596}],"tv":176957.46}],"ArrivalTime":1710508185500}
{"op":"mcm","id":2,"clk":"AMqMAQCuvwEA3tMB","pt":1710508185593,"mc":[{"id":"1.226122413","rc":[{"batb":[[1,4.7,73.08],[0,4.8,70.89]],"id":41122648},{"batb":[[1,21,119.15]],"batl":[[2,25,9.72]],"id":55632148},{"tv":125742.29,"batb":[[0,2.08,92.91]],"trd":[[2.08,2066.63]],"id":51922},{"tv":24872.2,"batb":[[0,4.6,34.84]],"trd":[[4.7,1184.26]],"ltp":4.7,"batl":[[0,4.7,29.81]],"id":50466254},{"tv":2716.32,"batb":[[0,36,11.77]],"trd":[[36,98.7]],"ltp":36,"batl":[[1,40,3.6]],"id":106596}],"tv":176961.6}],"ArrivalTime":1710508185600}
{"op":"mcm","id":2,"clk":"ANSMAQC4vwEA5tMB","pt":1710508185702,"mc":[{"id":"1.226122413","rc":[{"batb":[[0,480,3.26]],"id":54370634},{"batb":[[1,4.7,77.62]],"id":41122648},{"batb":[[0,22,17.07]],"id":55632148},{"tv":125753.51,"batb":[[0,2.08,136.22]],"trd":[[2.08,2077.85]],"batl":[[0,2.1,92]],"id":51922},{"tv":3112.03,"trd":[[60,2.72]],"ltp":60,"batl":[[0,60,25.9]],"id":49744721},{"batb":[[2,4.4,93.21],[1,4.5,96.5],[0,4.6,58.73]],"batl":[],"id":50466254},{"batb":[[2,32,55.73],[0,36,10.97]],"id":106596}],"tv":176972.86}],"ArrivalTime":1710508185709}
{"op":"mcm","id":2,"clk":"ANuMAQC/vwEA79MB","pt":1710508185756,"mc":[{"id":"1.226122413","rc":[{"batb":[],"batl":[[0,850,3.56]],"id":54370634},{"batb":[[2,430,3.15],[1,440,2],[0,470,1.16]],"id":41200638},{"tv":125757.5,"batb":[[0,2.08,134.23]],"trd":[[2.08,2081.84]],"batl":[[0,2.1,99.05]],"id":51922},{"batb":[[0,4.6,87.48]],"batl":[[0,4.7,31.84]],"id":50466254}],"tv":176976.85}],"ArrivalTime":1710508185763}
{"op":"mcm","id":2,"clk":"AOWMAQDGvwEA9dMB","pt":1710508185855,"mc":[{"id":"1.226122413","rc":[{"batl":[[2,5.1,68.8]],"id":41122648},{"tv":632.32,"batb":[[2,400,2.74],[1,430,3.15],[0,440,2.16]],"trd":[[470,2]],"ltp":470,"id":41200638},{"tv":125768.7,"batb":[[0,2.08,128.62]],"trd":[[2.08,2093.04]],"id":51922},{"batb":[[2,48,19.76],[1,50,56],[0,55,3.7]],"id":49744721},{"tv":24874.42,"batb":[[0,4.6,86.37]],"trd":[[4.6,2199.11]],"ltp":4.6,"id":50466254}],"tv":176992.27}],"ArrivalTime":1710508185861}
{"op":"mcm","id":2,"clk":"AOuMAQDLvwEA/9MB","pt":1710508185961,"mc":[{"id":"1.226122413","rc":[{"batb":[],"batl":[[2,850,2.78],[1,840,2.56],[0,810,3.6]],"id":54370634},{"batl":[[2,25,8.85]],"id":55632148},{"tv":125768.9,"trd":[[2.1,1580.26]],"ltp":2.1,"batl":[[0,2.1,98.95]],"id":51922},{"batb":[[0,55,8.35]],"batl":[[2,70,10.66],[1,65,20.94],[0,60,26.68]],"id":49744721},{"batb":[[0,190,12.74]],"id":66251581}],"tv":176992.47}],"ArrivalTime":1710508185968}
{"op":"mcm","id":2,"clk":"APWMAQDTvwEAhdQB","pt":1710508186062,"mc":[{"id":"1.226122413","rc":[{"batl":[[2,5.1,56.11]],"id":41122648},{"tv":125828.9,"batb":[[0,2.08,98.62]],"trd":[[2.08,2153.04]],"ltp":2.08,"id":51922}],"tv":177052.47}],"ArrivalTime":1710508186069}
{"op":"mcm","id":2,"clk":"APuMAQDcvwEAkNQB","pt":1710508186164,"mc":[{"id":"1.226122413","rc":[{"batb":[[0,480,3.92]],"id":54370634},{"tv":15616.41,"batb":[[0,4.8,69.85]],"trd":[[4.8,351.39]],"id":41122648},{"batl":[[0,580,4.29]],"id":41200638},{"batl":[[2,25,14.51],[1,24,9.09]],"id":55632148},{"batl":[[0,2.1,286.93]],"id":51922}],"tv":177054.54}],"ArrivalTime":1710508186170}
{"op":"mcm","id":2,"clk":"AISNAQDkvwEAltQB","pt":1710508186271,"mc":[{"id":"1.226122413","rc":[{"tv":15617.43,"batb":[[0,4.8,70.69]],"trd":[[4.9,495.18]],"ltp":4.9,"batl":[[0,4.9,30.05]],"id":41122648},{"batl":[[2,25,23.23]],"id":55632148},{"tv":126026.55,"batb":[[2,2.02,706.55],[1,2.04,245.62],[0,2.06,179.68]],"trd":[[2.08,2350.29],[2.1,1580.66]],"batl":[[2,2.12,615.04],[1,2.1,286.73],[0,2.08,136.19]],"id":51922},{"tv":3116.03,"batb":[[1,50,56.06],[0,55,6.35]],"trd":[[55,124.63]],"ltp":55,"id":49744721},{"tv":24875.12,"batb":[[2,4.4,95.71],[0,4.6,86.02]],"trd":[[4.6,2199.81]],"id":50466254},{"tv":2716.42,"trd":[[38,86.96]],"ltp":38,"batl":[[0,38,2.66]],"id":106596}],"tv":177258.01}],"ArrivalTime":1710508186277}
{"op":"mcm","id":2,"clk":"AIyNAQDtvwEAotQB","pt":1710508186375,"mc":[{"id":"1.226122413","rc":[{"batb":[[0,440,2.26]],"id":41200638},{"tv":3010.7,"trd":[[23,180.57]],"batl":[[2,26,15.81],[1,25,31.95],[0,24,9.93]],"id":55632148},{"batl":[[1,2.1,297.73]],"id":51922},{"tv":3118.03,"batb":[[0,55,5.45]],"trd":[[55,126.63]],"id":49744721}],"tv":177260.39}],"ArrivalTime":1710508186382}
{"op":"mcm","id":2,"clk":"AJONAQD7vwEArtQB","pt":1710508186480,"mc":[{"id":"1.226122413","rc":[{"batb":[[1,2.04,224.27]],"batl":[[0,2.08,146.98]],"id":51922},{"batb":[[0,55,6.09]],"id":49744721},{"batb":[[0,190,12.84]],"id":66251581}]}],"ArrivalTime":1710508186487}
{"op":"mcm","id":2,"clk":"AJWNAQD/vwEAtNQB","pt":1710508186578,"mc":[{"id":"1.226122413","rc":[{"batb":[[1,470,2.01]],"id":54370634},{"tv":15758.81,"batb":[[2,4.5,123.45],[1,4.6,132.49],[0,4.7,77.62]],"trd":[[4.8,492.77]],"ltp":4.8,"batl":[[0,4.9,42.55]],"id":41122648},{"batb":[[2,400,2.49]],"id":41200638},{"tv":3010.9,"trd":[[23,180.77]],"batl":[[2,25,31.95],[1,24,9.09],[0,23,1.27]],"id":55632148},{"tv":126064.1,"batb":[[0,2.06,160.99]],"trd":[[2.08,2350.46],[2.06,1298.88]],"batl":[[1,2.1,303.07],[0,2.08,147.64]],"id":51922},{"batb":[[0,55,6.2]],"id":49744721},{"batb":[[0,4.6,86.33]],"batl":[],"id":50466254},{"tv":2716.62,"trd":[[38,87.16]],"batl":[[0,38,2.56]],"id":106596}],"tv":177439.72}],"ArrivalTime":1710508186585}
{"op":"mcm","id":2,"clk":"AJuNAQCEwAEAv9QB","pt":1710508186682,"mc":[{"id":"1.226122413","rc":[{"batb":[[2,430,6.82]],"id":54370634},{"tv":15759.02,"trd":[[4.9,495.39]],"ltp":4.9,"batl":[[0,4.9,42.45]],"id":41122648},{"batb":[[0,440,2.37]],"id":41200638},{"tv":126075.54,"batb":[[0,2.06,160.97]],"trd":[[2.08,2361.86],[2.06,1298.92]],"batl":[[2,2.12,619.3],[0,2.08,141.94]],"id":51922},{"batb":[[1,4.5,93.25]],"id":50466254},{"batb":[[0,190,13.05]],"id":66251581},{"tv":2716.83,"trd":[[38,87.37]],"batl":[[0,38,2.46]],"id":106596}],"tv":177451.58}],"ArrivalTime":1710508186689}
{"op":"mcm","id":2,"clk":"AJ+NAQCLwAEAxdQB","pt":1710508186786,"mc":[{"id":"1.226122413","rc":[{"tv":15795.58,"batb":[[2,4.5,120.2],[1,4.6,117.27],[0,4.7,78.37]],"trd":[[4.8,529.33]],"ltp":4.8,"batl":[[2,5.1,58.6]],"id":41122648},{"tv":126075.75,"trd":[[2.08,2362.07]],"batl":[[0,2.08,141.84]],"id":51922},{"batl":[[0,60,28.68]],"id":49744721},{"batb":[[0,36,11.07]],"batl":[[2,44,19.91],[1,42,10.1],[0,40,3.6]],"id":106596}],"tv":177488.35}],"ArrivalTime":1710508186793}
{"op":"mcm","id":2,"clk":"AKSNAQCWwAEA0tQB","pt":1710508186891,"mc":[{"id":"1.226122413","rc":[{"batb":[[1,470,2.12],[0,480,3.95]],"id":54370634},{"tv":15804.52,"batb":[[2,4.6,117.27],[1,4.7,80.81],[0,4.8,1.86]],"trd":[[4.9,504.33]],"ltp":4.9,"batl":[[0,4.9,37.98]],"id":41122648},{"batb":[[0,440,2.5]],"id":41200638},{"tv":3011.11,"batb":[[0,22,17.75]],"trd":[[23,180.98]],"batl":[[0,23,3.17]],"id":55632148},{"tv":126359.91,"batb":[[0,2.06,168.21]],"trd":[[2.08,2646.15],[2.06,1299]],"ltp":2.06,"batl":[[0,2.08,12.8]],"id":51922},{"batb":[[0,55,6.47]],"id":49744721},{"batb":[[0,4.6,89.69]],"id":50466254},{"batb":[[0,190,13.13]],"batl":[[2,260,1.55],[1,230,1.36]],"id":66251581},{"batb":[[0,36,11.6]],"id":106596}],"tv":177781.66}],"ArrivalTime":1710508186898}
{"op":"mcm","id":2,"clk":"AKmNAQCjwAEA29QB","pt":1710508186953,"mc":[{"id":"1.226122413","rc":[{"batb":[[2,470,2.22],[1,480,3.95],[0,490,2]],"batl":[[2,950,2.82],[1,850,2.78]],"id":54370634},{"tv":15808.45,"batb":[[2,4.5,120.2],[1,4.6,117.27],[0,4.7,80.81]],"trd":[[4.8,533.26]],"ltp":4.8,"batl":[[2,5,71.73],[1,4.9,37.98],[0,4.8,8.55]],"id":41122648},{"tv":3011.31,"trd":[[23,181.18]],"batl":[[0,23,3.07]],"id":55632148},{"tv":126360.11,"batb":[],"trd":[[2.08,2646.35]],"ltp":2.08,"batl":[[0,2.08,20.12]],"id":51922},{"batb":[[0,55,6.67]],"id":49744721},{"batb":[[0,190,13.23]],"id":66251581}],"tv":177785.99}],"ArrivalTime":1710508186960}
{"op":"mcm","id":2,"clk":"AK+NAQCrwAEA5tQB","pt":1710508187054,"mc":[{"id":"1.226122413","rc":[{"batb":[[2,470,2.32]],"id":54370634},{"tv":15883.56,"batb":[[2,4.6,117.27],[1,4.7,80.81],[0,4.8,5.1]],"trd":[[4.9,562.34],[4.8,550.36]],"ltp":4.9,"batl":[[2,5.1,56.02],[1,5,71.73],[0,4.9,37.38]],"id":41122648},{"batb":[[1,430,4.15]],"id":41200638},{"tv":126373.13,"batb":[[0,2.06,161.7]],"trd":[[2.06,1312.02]],"ltp":2.06,"batl":[[0,2.08,88.98]],"id":51922},{"batb":[[1,4.5,96.5]],"id":50466254},{"batb":[[0,190,13.34]],"batl":[[1,230,2.75]],"id":66251581},{"batl":[[1,42,15.3]],"id":106596}],"tv":177874.12}],"ArrivalTime":1710508187060}
{"op":"mcm","id":2,"clk":"ALmNAQC1wAEA8NQB","pt":1710508187206,"mc":[{"id":"1.226122413","rc":[{"batb":[[1,480,4.77]],"id":54370634},{"tv":15883.76,"batb":[[0,4.8,17.65]],"trd":[[4.9,562.54]],"batl":[[0,4.9,37.28]],"id":41122648},{"batb":[[0,440,2.6]],"id":41200638},{"tv":3011.51,"trd":[[23,181.38]],"batl":[[0,23,2.97]],"id":55632148},{"tv":126432.31,"batb":[[0,2.06,132.21]],"trd":[[2.08,2646.55],[2.06,1371]],"batl":[[0,2.08,113.88]],"id":51922},{"tv":24880.78,"batb":[[0,4.6,89.9]],"trd":[[4.7,1189.92]],"ltp":4.7,"batl":[[0,4.7,29]],"id":50466254},{"batb":[[0,190,13.44]],"id":66251581},{"batb":[[0,36,11.7]],"id":106596}],"tv":177939.36}],"ArrivalTime":1710508187213}
{"op":"mcm","id":2,"clk":"AMCNAQC8wAEA99QB","pt":1710508187256,"mc":[{"id":"1.226122413","rc":[{"batb":[[2,470,2.53],[1,480,5.42],[0,490,2.15]],"id":54370634},{"tv":15887.96,"batb":[[0,4.8,15.65]],"trd":[[4.9,562.74],[4.8,554.36]],"batl":[[1,5,59.23],[0,4.9,37.18]],"id":41122648},{"batb":[[0,440,2.71]],"id":41200638},{"tv":3011.92,"trd":[[23,181.79]],"batl":[[0,23,2.77]],"id":55632148},{"batb":[[0,55,6.78]],"id":49744721},{"batb":[[0,4.6,90]],"id":50466254}],"tv":177943.97}],"ArrivalTime":1710508187262}
{"op":"mcm","id":2,"clk":"AMmNAQDEwAEA/9QB","pt":1710508187366,"mc":[{"id":"1.226122413","rc":[{"tv":15889.96,"batb":[],"trd":[[4.9,564.74]],"batl":[[2,5.1,58.6],[0,4.9,42.86]],"id":41122648},{"batl":[[1,2.1,358.71]],"id":51922},{"batb":[[0,55,6.88]],"id":49744721},{"tv":24902.47,"batb":[[1,4.5,93.25]],"trd":[[4.7,1211.61]],"batl":[[0,4.7,18.16]],"id":50466254},{"batb":[[0,36,11.8]],"batl":[[1,42,10.1]],"id":106596}],"tv":177967.66}],"ArrivalTime":1710508187372}
{"op":"mcm","id":2,"clk":"AM2NAQDUwAEAi9UB","pt":1710508187473,"mc":[{"id":"1.226122413","rc":[{"batb":[[2,470,2.8]],"id":54370634},{"batl":[[2,5.1,19.81]],"id":41122648},{"batb":[[2,430,4.15],[1,440,2.03],[0,450,1.16]],"id":41200638},{"tv":126471.01,"batb":[[0,2.06,112.86]],"trd":[[2.06,1409.7]],"id":51922},{"batb":[[2,48,15.86],[0,55,6.98]],"batl":[[2,70,5.01]],"id":49744721},{"batb":[[2,4.4,128.66]],"id":50466254},{"batb":[[0,190,13.54]],"id":66251581},{"batb":[[0,36,11.91]],"id":106596}],"tv":178006.36}],"ArrivalTime":1710508187480}
{"op":"mcm","id":2,"clk":"ANWNAQDewAEAlNUB","pt":1710508187575,"mc":[{"id":"1.226122413","rc":[{"batb":[[2,470,3.11]],"batl":[[2,850,2.78],[1,810,2.82],[0,800,3.35]],"id":54370634},{"batb":[[0,450,1.36]],"id":41200638},{"tv":126483.51,"batb":[[0,2.06,106.61]],"trd":[[2.06,1422.2]],"batl":[[0,2.08,123.88]],"id":51922},{"batb":[[1,50,59.96]],"id":49744721},{"tv":24902.5,"batb":[[0,4.6,89.98]],"trd":[[4.6,2199.84]],"ltp":4.6,"id":50466254}],"tv":178018.89}],"ArrivalTime":1710508187582}
{"op":"mcm","id":2,"clk":"ANuNAQDswAEAn9UB","pt":1710508187680,"mc":[{"id":"1.226122413","rc":[{"batb":[[1,480,6.08],[0,490,2.52]],"batl":[[2,950,2.82],[1,850,2.78]],"id":54370634},{"batb":[[2,4.6,120.04]],"batl":[[2,5.1,58.6]],"id":41122648},{"tv":3014.22,"batb":[[1,21,86.48],[0,22,16.6]],"trd":[[22,19.22]],"ltp":22,"batl":[],"id":55632148},{"batl":[[1,2.1,367.71]],"id":51922},{"tv":3120.03,"batb":[[0,55,5.98]],"trd":[[55,128.63]],"batl":[[2,70,10.66]],"id":49744721},{"batb":[[2,4.4,183.25]],"id":50466254}],"tv":178023.19}],"ArrivalTime":1710508187687}
{"op":"mcm","id":2,"clk":"AOSNAQD6wAEArtUB","pt":1710508187790,"mc":[{"id":"1.226122413","rc":[{"batb":[[0,490,2.73]],"batl":[[2,850,2.78],[1,800,3.35],[0,720,2.82]],"id":54370634},{"batb":[[2,4.6,95.04]],"id":41122648},{"batl":[[1,2.1,361.73],[0,2.08,134.88]],"id":51922},{"tv":24904.24,"batb":[[1,4.5,96.5],[0,4.6,89.11]],"trd":[[4.6,2201.58]],"batl":[[0,4.7,22.02]],"id":50466254},{"batb":[[0,190,13.75]],"id":66251581}],"tv":178024.93}],"ArrivalTime":1710508187797}
{"op":"mcm","id":2,"clk":"AOyNAQD/wAEAs9UB","pt":1710508187881,"mc":[{"id":"1.226122413","rc":[{"batb":[[0,450,1.57]],"id":41200638},{"tv":2717.84,"batb":[[2,32,37.67],[0,36,11.39]],"trd":[[38,88.38]],"id":106596}],"tv":178025.94}],"ArrivalTime":1710508187888}
{"op":"mcm","id":2,"clk":"APGNAQCJwQEAv9UB","pt":1710508187985,"mc":[{"id":"1.226122413","rc":[{"batb":[[1,480,6.73]],"id":54370634},{"batb":[],"batl":[[0,580,1.73]],"id":41200638},{"batb":[[2,20,47.66]],"id":55632148},{"batl":[[0,2.08,138.44]],"id":51922}]}],"ArrivalTime":1710508187991}
{"op":"mcm","id":2,"clk":"APeNAQCRwQEAxdUB","pt":1710508188088,"mc":[{"id":"1.226122413","rc":[{"batb":[[1,4.7,76.27]],"id":41122648},{"batb":[[0,22,20.87]],"id":55632148},{"batb":[[1,34,47.77]],"id":106596}]}],"ArrivalTime":1710508188094}
{"op":"mcm","id":2,"clk":"AISOAQCiwQEA29UB","pt":1710508188297,"mc":[{"id":"1.226122413","rc":[{"batb":[[1,480,7.39]],"id":54370634},{"tv":15890.75,"batb":[[0,4.8,15.25]],"trd":[[4.8,555.15]],"ltp":4.8,"id":41122648},{"tv":126485.51,"batb":[[0,2.06,105.61]],"trd":[[2.06,1424.2]],"batl":[[2,2.12,615.04],[0,2.08,144.42]],"id":51922},{"batl":[[2,70,10.1],[1,65,20.28],[0,60,27.9]],"id":49744721},{"batb":[[2,4.4,179.83],[1,4.5,93.25]],"id":50466254}],"tv":178028.73}],"ArrivalTime":1710508188303}
{"op":"mcm","id":2,"clk":"AIeOAQCuwQEA39UB","pt":1710508188349,"mc":[{"id":"1.226122413","rc":[{"tv":15890.97,"batb":[[0,4.8,15.14]],"trd":[[4.8,555.37]],"id":41122648},{"tv":747.23,"batb":[[0,190,12.73]],"trd":[[200,50.59],[190,61.98]],"id":66251581}],"tv":178030.97}],"ArrivalTime":1710508188356}
{"op":"mcm","id":2,"clk":"AI6OAQC2wQEA5tUB","pt":1710508188456,"mc":[{"id":"1.226122413","rc":[{"batl":[[0,4.9,46.48]],"id":41122648},{"tv":126629.23,"trd":[[2.08,2790.27]],"ltp":2.08,"batl":[[0,2.08,111.13]],"id":51922}],"tv":178174.69}],"ArrivalTime":1710508188462}
{"op":"mcm","id":2,"clk":"AJiOAQDCwQEA8dUB","pt":1710508188559,"mc":[{"id":"1.226122413","rc":[{"batl":[[1,800,3.73],[0,720,3.01]],"id":54370634},{"tv":15937.67,"batb":[[2,4.5,143.03],[1,4.6,95.04],[0,4.7,68.06]],"trd":[[4.7,16.42],[4.8,585.65]],"ltp":4.7,"batl":[[0,4.9,59.03]],"id":41122648},{"tv":126937.88,"batb":[[2,2,216.48],[1,2.02,706.55],[0,2.04,156.73]],"trd":[[2.04,505.61],[2.06,1635.41]],"ltp":2.04,"batl":[[2,2.1,361.73],[1,2.08,114.98],[0,2.06,33.07]],"id":51922},{"tv":24951.96,"batb":[[2,4.4,212.78],[0,4.6,65.25]],"trd":[[4.6,2249.3]],"batl":[[0,4.7,35.12]],"id":50466254}],"tv":178577.76}],"ArrivalTime":1710508188566}
{"op":"mcm","id":2,"clk":"AKCOAQDMwQEA99UB","pt":1710508188662,"mc":[{"id":"1.226122413","rc":[{"batl":[[1,800,1.16]],"id":54370634},{"tv":15938.15,"batb":[[2,4.6,95.04],[1,4.7,68.06],[0,4.8,25.9]],"trd":[[4.8,586.13]],"ltp":4.8,"id":41122648},{"batb":[[1,440,3.03]],"id":41200638},{"tv":3019.84,"batb":[[0,22,20.82]],"trd":[[23,187.31],[22,19.32]],"ltp":23,"batl":[[2,26,15.01],[1,25,31.95],[0,24,9.1]],"id":55632148},{"tv":127004.03,"batb":[[0,2.04,219.57]],"trd":[[2.06,1701.56]],"ltp":2.06,"batl":[[2,2.12,615.04],[1,2.1,361.73],[0,2.08,115.54]],"id":51922},{"tv":24952.48,"batb":[[0,4.6,93.79]],"trd":[[4.6,2249.82]],"batl":[],"id":50466254}],"tv":178650.53}],"ArrivalTime":1710508188669}
{"op":"mcm","id":2,"clk":"AKWOAQDYwQEAhdYB","pt":1710508188772,"mc":[{"id":"1.226122413","rc":[{"batb":[[1,480,8.05]],"id":54370634},{"batb":[[2,4.6,92.27],[0,4.8,43.77]],"batl":[[0,4.9,46.48]],"id":41122648},{"tv":3019.86,"trd":[[23,187.33]],"batl":[[0,24,9.09]],"id":55632148},{"tv":127133.47,"trd":[[2.06,1831]],"batl":[[0,2.08,155.17]],"id":51922},{"batb":[[0,55,12.43]],"id":49744721},{"batb":[[2,34,47.77],[1,36,11.39],[0,38,2.63]],"id":106596}],"tv":178779.99}],"ArrivalTime":1710508188778}
{"op":"mcm","id":2,"clk":"AKuOAQDjwQEAjtYB","pt":1710508188875,"mc":[{"id":"1.226122413","rc":[{"tv":15940.15,"batb":[[0,4.8,42.78]],"trd":[[4.8,588.13]],"id":41122648},{"batb":[[2,21,86.48],[1,22,20.82],[0,23,3.65]],"id":55632148},{"batb":[[0,2.04,226.92]],"id":51922},{"tv":3173.79,"trd":[[60,56.48]],"ltp":60,"batl":[[0,60,1.02]],"id":49744721}],"tv":178835.75}],"ArrivalTime":1710508188882}
{"op":"mcm","id":2,"clk":"AK+OAQDywQEAmdYB","pt":1710508188973,"mc":[{"id":"1.226122413","rc":[{"batb":[[0,490,2.76]],"id":54370634},{"batb":[[2,4.6,95.04],[0,4.8,45.9]],"id":41122648},{"batb":[[0,450,1.6]],"id":41200638},{"batb":[[1,22,21.5]],"id":55632148},{"tv":127133.55,"batb":[[0,2.04,226.88]],"trd":[[2.04,505.69]],"ltp":2.04,"batl":[],"id":51922},{"batb":[[0,55,12.7]],"id":49744721},{"batb":[[0,4.6,97.05]],"id":50466254},{"tv":757.22,"batb":[[0,190,7.82]],"trd":[[190,71.97]],"id":66251581},{"batb":[[1,36,11.81],[0,38,5.28]],"id":106596}],"tv":178845.82}],"ArrivalTime":1710508188980}
{"op":"mcm","id":2,"clk":"ALWOAQCDwgEApdYB","pt":1710508189078,"mc":[{"id":"1.226122413","rc":[{"batl":[[2,800,1.16],[1,720,3.01],[0,710,2.56]],"id":54370634},{"batl":[[2,590,4.35],[1,580,1.17],[0,570,3.37]],"id":41200638},{"tv":3027.16,"batb":[[2,20,47.66],[1,21,86.48],[0,22,21.5]],"trd":[[23,194.63]],"id":55632148},{"batb":[[2,2,237.12]],"id":51922},{"tv":3174.09,"batb":[[0,55,17.85]],"trd":[[60,56.78]],"batl":[[2,75,3.43],[1,70,10.1],[0,65,25.63]],"id":49744721},{"tv":2728.36,"batb":[[2,32,37.67],[1,34,47.77],[0,36,11.83]],"trd":[[38,98.9]],"id":106596}],"tv":178863.94}],"ArrivalTime":1710508189084}
{"op":"mcm","id":2,"clk":"AL6OAQCNwgEArtYB","pt":1710508189179,"mc":[{"id":"1.226122413","rc":[{"batb":[[0,4.8,28.03]],"id":41122648},{"batb":[[2,20,52.39]],"id":55632148},{"tv":24954.48,"batb":[[0,4.6,96.05]],"trd":[[4.6,2251.82]],"batl":[],"id":50466254}],"tv":178865.94}],"ArrivalTime":1710508189186}
{"op":"mcm","id":2,"clk":"AMCOAQCWwgEAttYB","pt":1710508189287,"mc":[{"id":"1.226122413","rc":[{"tv":15946.43,"batb":[[0,4.8,24.88]],"trd":[[4.8,594.41]],"batl":[[2,5.1,56.11]],"id":41122648},{"batl":[[2,610,2.17],[1,590,4.52]],"id":41200638},{"tv":3034,"batb":[[0,22,21.73]],"trd":[[23,201.47]],"id":55632148},{"tv":127137.47,"batb":[[0,2.04,224.92]],"trd":[[2.04,509.61]],"batl":[[0,2.08,155.45]],"id":51922},{"batb":[[0,55,18.46]],"id":49744721},{"batl":[[0,4.7,35.66]],"id":50466254},{"batb":[[0,190,9.56]],"id":66251581},{"batb":[[2,34,47.77],[1,36,11.81],[0,38,2]],"id":106596}],"tv":178882.98}],"ArrivalTime":1710508189294}
{"op":"mcm","id":2,"clk":"AMqOAQCewgEAwdYB","pt":1710508189392,"mc":[{"id":"1.226122413","rc":[{"batb":[[0,4.8,42.66]],"id":41122648},{"batl":[[2,590,4.52],[1,570,3.04],[0,560,1.33]],"id":41200638},{"tv":127142.71,"batb":[[0,2.04,222.3]],"trd":[[2.04,514.85]],"batl":[],"id":51922},{"tv":3175.31,"batb":[[0,55,19.43]],"trd":[[60,58]],"batl":[[0,65,20.3]],"id":49744721},{"batb":[[0,190,10.56]],"batl":[[1,230,1.36]],"id":66251581}],"tv":178889.44}],"ArrivalTime":1710508189399}
{"op":"mcm","id":2,"clk":"AM+OAQCrwgEAy9YB","pt":1710508189499,"mc":[{"id":"1.226122413","rc":[{"tv":523.73,"batb":[[2,480,8.05],[1,490,2.76],[0,710,3.16]],"trd":[[710,5.12]],"ltp":710,"batl":[[2,850,2.78],[1,800,1.16],[0,720,3.01]],"id":54370634},{"tv":15946.81,"batb":[[0,4.8,42.48]],"trd":[[4.8,594.79]],"batl":[[2,5.1,58.61]],"id":41122648},{"batl":[[0,560,1]],"id":41200638},{"batl":[[2,70,10.1],[1,65,20.3],[0,60,5.71]],"id":49744721},{"batb":[[2,4.4,245.74]],"id":50466254},{"batl":[[0,40,5.6]],"id":106596}],"tv":178894.94}],"ArrivalTime":1710508189508}
{"op":"mcm","id":2,"clk":"ANaOAQC3wgEA0NYB","pt":1710508189551,"mc":[{"id":"1.226122413","rc":[{"batl":[[2,5.1,56.03]],"id":41122648},{"batb":[[0,22,22.73]],"id":55632148},{"tv":127143.91,"batb":[[0,2.04,221.7]],"trd":[[2.04,516.05]],"id":51922},{"tv":3176.57,"batb":[[0,55,21.01]],"trd":[[60,59.26]],"batl":[[1,65,22.3],[0,60,5.08]],"id":49744721},{"tv":24956.14,"batb":[[0,4.6,95.22]],"trd":[[4.6,2253.48]],"id":50466254},{"batl":[[2,230,1.36],[1,220,1.46]],"id":66251581}],"tv":178899.06}],"ArrivalTime":1710508189558}
{"op":"mcm","id":2,"clk":"ANuOAQC9wgEA29YB","pt":1710508189704,"mc":[{"id":"1.226122413","rc":[{"tv":533.71,"batb":[[2,490,2.76],[1,710,1.18],[0,730,1.69]],"trd":[[710,9.08],[720,6.86]],"ltp":720,"batl":[[2,950,2.82],[1,850,2.78],[0,800,1.16]],"id":54370634},{"batb":[[0,4.8,48.81]],"batl":[[2,5.1,58.61]],"id":41122648},{"batb":[[2,21,86.48],[1,22,22.5],[0,23,4.5]],"id":55632148},{"tv":24956.18,"batb":[[0,4.6,95.2]],"trd":[[4.6,2253.52]],"id":50466254},{"tv":2732.36,"batb":[[2,32,37.67],[1,34,47.77],[0,36,11.81]],"trd":[[38,102.9]],"id":106596}],"tv":178913.08}],"ArrivalTime":1710508189711}
{"op":"mcm","id":2,"clk":"AOWOAQDHwgEA5NYB","pt":1710508189759,"mc":[{"id":"1.226122413","rc":[{"batb":[[2,490,2.94]],"id":54370634},{"batb":[[0,4.8,50.81]],"id":41122648},{"tv":127145.9,"trd":[[2.06,1832.99]],"ltp":2.06,"batl":[[2,2.1,361.73],[1,2.08,155.45],[0,2.06,143.23]],"id":51922}],"tv":178915.07}],"ArrivalTime":1710508189766}
{"op":"mcm","id":2,"clk":"AOqOAQDSwgEA7dYB","pt":1710508189861,"mc":[{"id":"1.226122413","rc":[{"tv":534.09,"batb":[[0,730,2.6]],"trd":[[740,0.38]],"ltp":740,"batl":[[2,970,2],[1,950,2.82],[0,850,3.75]],"id":54370634},{"batl":[[2,5.1,19.82]],"id":41122648},{"batb":[[1,2.02,739.69],[0,2.04,231.7]],"batl":[[0,2.06,175.73]],"id":51922},{"batl":[[2,75,3.43],[1,70,4.45],[0,65,22.3]],"id":49744721},{"batb":[[2,4.4,191.15]],"id":50466254}],"tv":178915.45}],"ArrivalTime":1710508189868}
{"op":"mcm","id":2,"clk":"AO+OAQDYwgEA99YB","pt":1710508189966,"mc":[{"id":"1.226122413","rc":[{"tv":15947.33,"batb":[[0,4.8,50.56]],"trd":[[4.9,564.76],[4.8,595.29]],"batl":[[2,5.1,17.32],[0,4.9,46.47]],"id":41122648},{"tv":3043,"batb":[[2,20,52.39],[1,21,86.48],[0,22,22.5]],"trd":[[23,210.47]],"batl":[[1,25,25.46]],"id":55632148},{"tv":127156.01,"batb":[[0,2.04,226.7]],"trd":[[2.04,526.05],[2.06,1833.1]],"ltp":2.04,"batl":[[0,2.06,175.67]],"id":51922},{"batb":[[2,50,58.74],[1,55,21.01],[0,60,5.69]],"batl":[[0,65,19.16]],"id":49744721},{"tv":24963.52,"batb":[[0,4.6,91.53]],"trd":[[4.6,2260.86]],"batl":[[2,4.9,40.45]],"id":50466254}],"tv":178942.42}],"ArrivalTime":1710508189973}
{"op":"mcm","id":2,"clk":"APWOAQDiwgEAhtcB","pt":1710508190070,"mc":[{"id":"1.226122413","rc":[{"tv":535.45,"batb":[[0,730,1.92]],"trd":[[740,1.74]],"id":54370634},{"tv":15956.81,"batb":[[0,4.8,45.84]],"trd":[[4.9,564.8],[4.8,604.73]],"batl":[[2,5.1,56.11],[0,4.9,46.45]],"id":41122648},{"tv":127176.59,"batb":[[2,2,257.86],[0,2.04,216.4]],"trd":[[2.04,546.63]],"id":51922},{"batb":[[0,60,6.32]],"batl":[[1,70,10.1]],"id":49744721},{"tv":24967.58,"batb":[[2,4.4,245.74],[0,4.6,89.5]],"trd":[[4.6,2264.92]],"id":50466254}],"tv":178977.9}],"ArrivalTime":1710508190077}
{"op":"mcm","id":2,"clk":"APyOAQDwwgEAkNcB","pt":1710508190169,"mc":[{"id":"1.226122413","rc":[{"tv":535.91,"batb":[[2,710,1.18],[1,720,1.65],[0,730,1.69]],"trd":[[740,2.2]],"batl":[[2,950,2.82],[1,850,2.78],[0,800,1.65]],"id":54370634},{"tv":16048.49,"batb":[[2,4.5,143.03],[1,4.6,95.04],[0,4.7,68.06]],"trd":[[4.8,696.41]],"batl":[[2,5,59.23],[1,4.9,46.45],[0,4.8,1.99]],"id":41122648},{"tv":633.32,"trd":[[560,1]],"ltp":560,"batl":[[2,610,2.17],[1,590,4.52],[0,570,3.54]],"id":41200638},{"batb":[[2,21,86.48],[1,22,22.5],[0,23,3.65]],"id":55632148},{"tv":127184.05,"batb":[[0,2.04,212.67]],"trd":[[2.04,554.09]],"id":51922},{"batb":[[2,50,54.74],[0,60,10.32]],"id":49744721},{"batb":[[1,4.5,101.09],[0,4.6,99]],"id":50466254}],"tv":179078.5}],"ArrivalTime":1710508190176}
{"op":"mcm","id":2,"clk":"AJWPAQCBwwEAq9cB","pt":1710508190421,"mc":[{"id":"1.226122413","rc":[{"batb":[[2,490,3.19],[1,710,1.18],[0,720,1.65]],"batl":[],"id":54370634},{"batb":[[2,4.5,158.03]],"batl":[[0,4.8,19.49],[2,5,59.04]],"id":41122648},{"batl":[[2,650,1.97]],"id":41200638},{"tv":3050.3,"batb":[[2,20,18.09],[1,21,86.48],[0,22,22.5]],"trd":[[23,217.77]],"id":55632148},{"tv":127270.34,"batb":[[0,2.04,242.6],[2,2,278.52]],"trd":[[2.04,559.73],[2.06,1913.75]],"ltp":2.06,"batl":[[0,2.06,155.34]],"id":51922},{"batb":[],"batl":[[1,70,14.79]],"id":49744721},{"tv":24973.22,"batb":[[0,4.6,96.5]],"trd":[[4.6,2269.92],[4.7,1212.25]],"ltp":4.6,"batl":[[0,4.7,35.34]],"id":50466254},{"batb":[[1,34,30.78]],"id":106596}],"tv":179177.73,"con":true}],"ArrivalTime":1710508190428}
{"op":"mcm","id":2,"clk":"AJ2PAQCJwwEAsNcB","pt":1710508190491,"mc":[{"id":"1.226122413","rc":[{"batl":[[2,1000,14.34],[1,950,3.6]],"id":54370634},{"tv":16049.75,"batb":[[0,4.7,68.04]],"trd":[[4.7,16.46],[4.8,697.63]],"ltp":4.7,"batl":[[0,4.8,18.88]],"id":41122648},{"batb":[],"batl":[[2,25,25.46],[1,24,9.09],[0,23,2]],"id":55632148},{"tv":127437.52,"batb":[[0,2.04,160.59]],"trd":[[2.04,723.75],[2.06,1916.91]],"ltp":2.04,"batl":[[0,2.06,153.76]],"id":51922},{"batl":[[0,4.7,44.58]],"id":50466254},{"tv":757.52,"trd":[[210,3.38]],"ltp":210,"batl":[[0,210,6.4]],"id":66251581}],"tv":179346.47}],"ArrivalTime":1710508190498}
{"op":"mcm","id":2,"clk":"AKCPAQCPwwEAvNcB","pt":1710508190590,"mc":[{"id":"1.226122413","rc":[{"tv":542.19,"batb":[[2,480,7.7],[1,490,3.31],[0,740,1.78]],"trd":[[740,3.56],[720,10.16],[710,10.7]],"batl":[[1,950,2.82],[0,850,1.56]],"id":54370634},{"tv":16078.93,"batb":[[1,4.6,92.27]],"trd":[[4.8,726.81]],"ltp":4.8,"batl":[[0,4.8,4.29]],"id":41122648},{"batl":[[2,590,4.52],[1,570,3.54],[0,550,3.14]],"id":41200638},{"tv":3054.3,"trd":[[23,221.77]],"batl":[[2,26,15.01],[1,25,25.46],[0,24,9.09]],"id":55632148},{"tv":127451.36,"batb":[[0,2.04,153.67]],"trd":[[2.04,737.59]],"batl":[[1,2.08,149.75],[0,2.06,155.76]],"id":51922},{"tv":24977.82,"batb":[[0,4.6,94.2]],"trd":[[4.6,2274.52]],"id":50466254},{"tv":771.52,"trd":[[220,1.2],[210,16.18]],"ltp":220,"batl":[[2,270,2.82],[1,260,1.55],[0,230,2.22]],"id":66251581},{"tv":2734.76,"batb":[],"trd":[[38,105.3]],"batl":[[2,42,10.1],[1,40,5.6],[0,38,1.6]],"id":106596}],"tv":179420.77}],"ArrivalTime":1710508190596}
{"op":"mcm","id":2,"clk":"AKiPAQCcwwEAwdcB","pt":1710508190695,"mc":[{"id":"1.226122413","rc":[{"tv":16080.93,"trd":[[4.8,728.81]],"batl":[[0,4.8,6.94]],"id":41122648},{"batb":[[2,20,52.39]],"id":55632148},{"tv":127462.44,"batb":[[1,2.02,760.08],[0,2.04,150.75]],"trd":[[2.04,743.43],[2.06,1922.15]],"batl":[[1,2.08,449.75],[0,2.06,163.14]],"id":51922},{"batb":[[1,55,19.43]],"id":49744721},{"tv":25040.8,"batb":[[2,4.5,101.09],[1,4.6,94.2],[0,4.7,35.54]],"trd":[[4.7,1275.23]],"ltp":4.7,"batl":[[2,5,51.32],[1,4.9,40.45],[0,4.8,39.43]],"id":50466254},{"batb":[[1,34,47.77]],"id":106596}],"tv":179496.83}],"ArrivalTime":1710508190702}
{"op":"mcm","id":2,"clk":"AK+PAQCdwwEAy9cB","pt":1710508190801,"mc":[{"id":"1.226122413","rc":[{"batb":[[2,490,3.31],[1,730,1.65]],"id":54370634},{"tv":16099.41,"batb":[[2,4.6,95.06],[1,4.7,68.04],[0,4.8,28.66]],"trd":[[4.8,747.29]],"batl":[[2,5.1,58.62],[1,5,59.04],[0,4.9,46.45]],"id":41122648},{"batb":[[2,21,86.48],[1,22,22.5],[0,23,3.65]],"id":55632148},{"tv":127505.16,"batb":[[0,2.04,145.32]],"trd":[[2.04,754.3],[2.06,1954]],"batl":[[1,2.08,455.89],[0,2.06,147.22]],"id":51922},{"tv":25041,"batb":[[0,4.7,35.44]],"trd":[[4.7,1275.43]],"id":50466254},{"batb":[[2,180,4],[1,190,10.56],[0,200,1.64]],"batl":[[0,230,3.65]],"id":66251581}],"tv":179558.23}],"ArrivalTime":1710508190807}
{"op":"mcm","id":2,"clk":"ALaPAQCpwwEA1dcB","pt":1710508190907,"mc":[{"id":"1.226122413","rc":[{"batl":[[2,1000,15.34]],"id":54370634},{"tv":16107.36,"batb":[[0,4.8,26.72]],"trd":[[4.9,565.19],[4.8,754.85]],"batl":[[0,4.9,46.26]],"id":41122648},{"batl":[[0,24,13.36]],"id":55632148},{"tv":127544.88,"batb":[[1,2.02,770.28],[0,2.04,101.85]],"trd":[[2.04,775.74],[2.06,1972.28]],"batl":[[0,2.06,138.08]],"id":51922},{"batb":[[2,50,47.01]],"id":49744721},{"batb":[[0,4.7,59.44]],"batl":[[0,4.8,48.21]],"id":50466254}],"tv":179605.9}],"ArrivalTime":1710508190914}
{"op":"mcm","id":2,"clk":"AL6PAQCvwwEA49cB","pt":1710508191010,"mc":[{"id":"1.226122413","rc":[{"tv":543.51,"batb":[[2,660,1.05],[0,740,1.24]],"trd":[[790,0.24],[740,4.64]],"id":54370634},{"batb":[[1,4.7,88.78]],"id":41122648},{"batb":[[0,450,2.43]],"id":41200638},{"batb":[[1,22,26.93]],"id":55632148},{"tv":127786.38,"batb":[[2,1.99,116.13],[1,2,278.52],[0,2.02,749.79]],"trd":[[2.04,1017.04],[2.02,401.04]],"batl":[[2,2.08,455.89],[1,2.06,138.08],[0,2.04,33.8]],"id":51922},{"batb":[[1,55,17.85],[0,60,12.96]],"id":49744721},{"batb":[[0,4.7,80.18]],"id":50466254},{"batb":[[0,200,2.1]],"batl":[[2,260,1.55],[1,230,2.79],[0,220,2.35]],"id":66251581},{"batb":[[0,36,14.52]],"batl":[[0,38,4.16]],"id":106596}],"tv":179848.72}],"ArrivalTime":1710508191017}
{"op":"mcm","id":2,"clk":"AMOPAQC0wwEA7NcB","pt":1710508191063,"mc":[{"id":"1.226122413","rc":[{"batl":[[2,1000,14.72]],"id":54370634},{"tv":3056.76,"batb":[[0,23,2.42]],"trd":[[23,224.23]],"id":55632148},{"tv":128086.4,"batb":[[0,2.02,748.86]],"trd":[[2.04,1084.64],[2.06,2182.84],[2.02,422.9]],"ltp":2.02,"batl":[[2,2.1,361.73],[1,2.08,455.89],[0,2.06,32.8]],"id":51922},{"batl":[[1,70,10.34]],"id":49744721},{"batl":[[2,260,1.12]],"id":66251581}],"tv":180151.2}],"ArrivalTime":1710508191069}
{"op":"mcm","id":2,"clk":"AMmPAQC/wwEA+dcB","pt":1710508191174,"mc":[{"id":"1.226122413","rc":[{"tv":544.01,"batb":[[2,490,2.39],[1,660,1.05]],"trd":[[800,0.5]],"ltp":800,"batl":[[0,850,1.31]],"id":54370634},{"batb":[[0,4.8,29.17]],"batl":[[2,5.1,56.11],[0,4.9,58.88]],"id":41122648},{"tv":635.82,"trd":[[550,2.84]],"ltp":550,"batl":[[0,550,2.74]],"id":41200638},{"tv":128162.6,"batb":[[1,2,299.11],[0,2.02,748.3]],"trd":[[2.04,1159.72],[2.02,424.02]],"batl":[[2,2.08,455.89],[1,2.06,32.8],[0,2.04,90.25]],"id":51922},{"tv":3190.87,"batb":[[0,60,5.81]],"trd":[[60,73.56]],"id":49744721},{"tv":25041.08,"batb":[],"trd":[[4.8,2245.05]],"ltp":4.8,"batl":[[0,4.8,30.4]],"id":50466254},{"tv":771.72,"batb":[[2,190,10.56],[1,200,1.64],[0,210,2.01]],"trd":[[220,1.4]],"batl":[[0,220,2.25]],"id":66251581}],"tv":180244.98}],"ArrivalTime":1710508191181}
{"op":"mcm","id":2,"clk":"ANCPAQDGwwEAgtgB","pt":1710508191280,"mc":[{"id":"1.226122413","rc":[{"batb":[],"batl":[[2,1000,14.34]],"id":54370634},{"tv":128198.53,"batb":[[0,2.02,748.07]],"trd":[[2.04,1195.19],[2.02,424.48]],"ltp":2.04,"batl":[[0,2.04,72.68]],"id":51922},{"tv":25041.3,"batb":[[0,4.7,80.07]],"trd":[[4.7,1275.65]],"ltp":4.7,"batl":[],"id":50466254}],"tv":180281.13}],"ArrivalTime":1710508191286}
{"op":"mcm","id":2,"clk":"ANOPAQDKwwEAi9gB","pt":1710508191373,"mc":[{"id":"1.226122413","rc":[{"batl":[[2,1000,14.72]],"id":54370634},{"tv":128237.55,"batb":[[2,1.99,137.16],[0,2.02,729.59]],"trd":[[2.04,1197.25],[2.02,461.44]],"batl":[[0,2.04,103.78]],"id":51922},{"tv":25041.46,"batb":[[0,4.7,79.99]],"trd":[[4.7,1275.81]],"id":50466254},{"batb":[[1,200,2.64]],"batl":[[2,270,2.82],[1,260,1.12],[0,230,3.55]],"id":66251581}],"tv":180320.31}],"ArrivalTime":1710508191379}
{"op":"mcm","id":2,"clk":"ANePAQDPwwEAk9gB","pt":1710508191497,"mc":[{"id":"1.226122413","rc":[{"batb":[[0,4.8,41.73]],"id":41122648},{"tv":128269.07,"batb":[[0,2.02,725.01]],"trd":[[2.04,1219.61],[2.02,470.6]],"batl":[[1,2.06,35.37],[0,2.04,92.6]],"id":51922},{"batb":[[0,60,6.47]],"id":49744721},{"tv":773.24,"batb":[[2,200,2.64],[1,210,2.01],[0,220,1.47]],"trd":[[220,2.92]],"batl":[[2,260,1.08],[1,240,1.38],[0,230,2.79]],"id":66251581}],"tv":180353.35}],"ArrivalTime":1710508191503}
{"op":"mcm","id":2,"clk":"AN2PAQDZwwEApdgB","pt":1710508191587,"mc":[{"id":"1.226122413","rc":[{"tv":546.49,"batb":[[2,470,1.2],[1,480,2.46],[0,490,2.85]],"trd":[[740,7.12]],"ltp":740,"id":54370634},{"tv":16128.44,"batb":[[0,4.8,54.63]],"trd":[[4.9,586.27]],"ltp":4.9,"batl":[[0,4.9,48.34]],"id":41122648},{"batb":[[0,450,2.56]],"batl":[[1,570,3.04]],"id":41200638},{"batb":[[0,23,5.11]],"id":55632148},{"tv":128269.37,"batb":[[1,2,237.07],[0,2.02,734.26]],"trd":[[2.04,1219.81],[2.02,470.7]],"batl":[[0,2.04,177.9]],"id":51922},{"batb":[[0,60,7.5]],"id":49744721},{"batb":[[0,4.7,103.17]],"batl":[],"id":50466254},{"tv":774.04,"batb":[[1,210,2.3],[0,220,1.07]],"trd":[[220,3.72]],"id":66251581},{"batb":[[0,36,16.24]],"id":106596}],"tv":180378.01}],"ArrivalTime":1710508191594}
{"op":"mcm","id":2,"clk":"AOePAQDfwwEArNgB","pt":1710508191694,"mc":[{"id":"1.226122413","rc":[{"batb":[[2,430,5.76],[1,470,1.23],[0,490,3.17]],"id":54370634},{"tv":16131.44,"trd":[[4.9,589.27]],"batl":[[0,4.9,46.84]],"id":41122648},{"batb":[[0,450,2.4]],"batl":[[0,550,3.24]],"id":41200638},{"tv":128427.32,"batb":[[0,2.02,689.29]],"trd":[[2.02,628.65]],"ltp":2.02,"batl":[],"id":51922},{"batb":[[0,60,12.9]],"id":49744721},{"tv":776.18,"batb":[[2,190,10.56],[1,200,2.64],[0,210,3.3]],"trd":[[220,5.86]],"batl":[[0,230,1.36]],"id":66251581}],"tv":180541.1}],"ArrivalTime":1710508191700}
{"op":"mcm","id":2,"clk":"AOiPAQDjwwEAs9gB","pt":1710508191797,"mc":[{"id":"1.226122413","rc":[{"batb":[[2,470,1.23],[1,490,2.39],[0,520,3.21]],"batl":[[1,950,3.6],[0,800,1.41]],"id":54370634},{"batb":[[0,4.8,71.94]],"batl":[[0,4.9,50.58]],"id":41122648},{"tv":636.14,"trd":[[540,3.74]],"ltp":540,"batl":[[0,550,3.08]],"id":41200638},{"tv":128427.69,"batb":[[0,2.02,689.1]],"trd":[[2.02,629.02]],"id":51922},{"batl":[[0,65,17.16]],"id":49744721},{"tv":25041.48,"batb":[[0,4.7,103.16]],"trd":[[4.7,1275.83]],"batl":[],"id":50466254},{"batb":[[1,200,3.69]],"id":66251581}],"tv":180541.81}],"ArrivalTime":1710508191804}
{"op":"mcm","id":2,"clk":"AO6PAQDowwEAwdgB","pt":1710508191894,"mc":[{"id":"1.226122413","rc":[{"batb":[[0,520,2.95]],"id":54370634},{"batl":[[2,5.1,53.53]],"id":41122648},{"batl":[[0,550,3.31]],"id":41200638},{"batb":[[1,2,242.87],[0,2.02,655.96]],"batl":[[2,2.08,459.11]],"id":51922},{"batb":[[1,4.6,99.2]],"id":50466254}]}],"ArrivalTime":1710508191901}
{"op":"mcm","id":2,"clk":"APuPAQDtwwEAytgB","pt":1710508191997,"mc":[{"id":"1.226122413","rc":[{"tv":546.65,"batb":[[0,520,2.55]],"trd":[[780,0.16]],"ltp":780,"batl":[[2,950,2.82],[1,850,1.31],[0,790,1.76]],"id":54370634},{"tv":16135.44,"batb":[[0,4.8,69.95]],"trd":[[4.8,758.85]],"ltp":4.8,"id":41122648},{"tv":128513.29,"batb":[[0,2.02,655.86]],"trd":[[2.04,1305.21],[2.02,629.22]],"ltp":2.04,"batl":[[2,2.08,453.14],[0,2.04,135.2]],"id":51922},{"tv":25041.52,"batb":[[0,4.7,103.14]],"trd":[[4.7,1275.87]],"batl":[],"id":50466254}],"tv":180631.61}],"ArrivalTime":1710508192003}
{"op":"mcm","id":2,"clk":"AP6PAQD3wwEA39gB","pt":1710508192112,"mc":[{"id":"1.226122413","rc":[{"batl":[[0,790,2.64]],"id":54370634},{"tv":16139.56,"batb":[[0,4.8,69.88]],"trd":[[4.9,593.27],[4.8,758.97]],"batl":[[2,5.1,56.11],[0,4.9,48.58]],"id":41122648},{"tv":637.33,"trd":[[550,2.9],[540,4.87]],"ltp":550,"batl":[[0,550,2.71]],"id":41200638},{"tv":128520.83,"batb":[[0,2.02,654.09]],"trd":[[2.04,1309.21],[2.02,632.76]],"ltp":2.02,"batl":[[0,2.04,133.2]],"id":51922},{"tv":25045.52,"trd":[[4.8,2249.05]],"ltp":4.8,"batl":[[0,4.8,28.4]],"id":50466254}],"tv":180648.46}],"ArrivalTime":1710508192121}
{"op":"mcm","id":2,"clk":"AIaQAQD6wwEA5dgB","pt":1710508192205,"mc":[{"id":"1.226122413","rc":[{"batb":[[2,470,1.65],[1,490,2.57]],"batl":[[0,790,3.52]],"id":54370634},{"tv":16225.16,"batb":[[0,4.8,27.08]],"trd":[[4.8,844.57]],"id":41122648},{"tv":637.93,"trd":[[550,3.5]],"batl":[[0,550,2.42]],"id":41200638},{"tv":128521.22,"batb":[[0,2.02,686.78]],"trd":[[2.02,633.15]],"id":51922},{"tv":3192.87,"batb":[[0,60,11.9]],"trd":[[60,75.56]],"id":49744721},{"tv":25045.58,"batb":[[2,4.5,100.53],[0,4.7,103.11]],"trd":[[4.7,1275.93]],"ltp":4.7,"id":50466254},{"batb":[[2,200,3.69],[1,210,3.3],[0,220,1.44]],"id":66251581}],"tv":180737.11}],"ArrivalTime":1710508192211}
{"op":"mcm","id":2,"clk":"AI2QAQCGxAEA8NgB","pt":1710508192319,"mc":[{"id":"1.226122413","rc":[{"batl":[[0,790,4.18]],"id":54370634},{"tv":16227.4,"batb":[[0,4.8,8.65]],"trd":[[4.8,846.81]],"batl":[[2,5.1,17.32]],"id":41122648},{"batb":[[0,2.02,696.78]],"batl":[[2,2.08,463.14]],"id":51922},{"batl":[[1,70,4.69]],"id":49744721},{"batb":[[0,4.7,123.11]],"batl":[[2,5,101.32]],"id":50466254},{"tv":779.06,"batb":[[2,190,10.56],[1,200,3.69],[0,210,3.3]],"trd":[[220,8.74]],"batl":[[0,230,1.92]],"id":66251581}],"tv":180742.23}],"ArrivalTime":1710508192325}
{"op":"mcm","id":2,"clk":"AJKQAQCLxAEA+dgB","pt":1710508192361,"mc":[{"id":"1.226122413","rc":[{"batb":[[0,520,2.67]],"id":54370634},{"tv":16227.42,"batb":[[0,4.8,23.64]],"trd":[[4.8,846.83]],"batl":[[0,4.9,44.96]],"id":41122648},{"batl":[[2,590,4.84]],"id":41200638},{"tv":128522.44,"batb":[[0,2.02,696.17]],"trd":[[2.02,634.37]],"id":51922},{"batb":[[2,50,48.52]],"id":49744721},{"batb":[[0,4.7,128.11]],"batl":[],"id":50466254}],"tv":180743.47}],"ArrivalTime":1710508192367}
{"op":"mcm","id":2,"clk":"AJ+QAQCWxAEAgNkB","pt":1710508192515,"mc":[{"id":"1.226122413","rc":[{"batl":[[2,850,1.31],[1,790,4.18],[0,780,2.13]],"id":54370634},{"tv":16227.62,"batb":[[2,4.6,72.56]],"trd":[[4.9,593.47]],"ltp":4.9,"batl":[[2,5.1,56.11],[0,4.9,44.86]],"id":41122648},{"tv":3056.78,"batb":[[0,23,5.1]],"trd":[[23,224.25]],"id":55632148},{"tv":128522.6,"batb":[[1,2,243.66],[0,2.02,696.09]],"trd":[[2.02,634.53]],"batl":[[1,2.06,102.95]],"id":51922},{"batl":[[2,75,8.7]],"id":49744721},{"tv":25102.38,"batb":[[2,4.6,99.2],[1,4.7,128.11],[0,4.8,21.55]],"trd":[[4.8,2305.85]],"ltp":4.8,"batl":[[2,5.1,31.41],[1,5,101.32],[0,4.9,40.45]],"id":50466254},{"batl":[[0,230,3.3]],"id":66251581}],"tv":180800.65}],"ArrivalTime":1710508192522}
{"op":"mcm","id":2,"clk":"AKGQAQCdxAEAg9kB","pt":1710508192565,"mc":[{"id":"1.226122413","rc":[{"batl":[[0,780,2.98]],"id":54370634},{"tv":16229.38,"batb":[[0,4.8,23.61]],"trd":[[4.9,595.17],[4.8,846.89]],"batl":[[0,4.9,40.27]],"id":41122648},{"tv":128525.54,"batb":[[0,2.02,695.73]],"trd":[[2.04,1311.43],[2.02,635.25]],"batl":[[0,2.04,132.09]],"id":51922},{"batb":[[2,4.6,108.2],[1,4.7,128.96]],"id":50466254},{"batb":[[2,190,10.93]],"id":66251581}],"tv":180805.35}],"ArrivalTime":1710508192572}
{"op":"mcm","id":2,"clk":"AKiQAQCkxAEAkdkB","pt":1710508192679,"mc":[{"id":"1.226122413","rc":[{"tv":547.85,"trd":[[780,1.36]],"batl":[[0,780,2.38]],"id":54370634},{"tv":16229.42,"batb":[[0,4.8,23.59]],"trd":[[4.8,846.93]],"ltp":4.8,"id":41122648},{"tv":128530.64,"batb":[[0,2.02,695.63]],"trd":[[2.04,1316.33],[2.02,635.45]],"ltp":2.04,"batl":[[0,2.04,129.64]],"id":51922},{"tv":25107.7,"batb":[[0,4.8,45.54]],"trd":[[4.8,2311.17]],"batl":[[0,4.9,61.56]],"id":50466254},{"tv":781.06,"batb":[[0,210,2.3]],"trd":[[210,18.18]],"ltp":210,"id":66251581}],"tv":180819.01}],"ArrivalTime":1710508192685}
{"op":"mcm","id":2,"clk":"ALCQAQCtxAEAmdkB","pt":1710508192788,"mc":[{"id":"1.226122413","rc":[{"batb":[[0,4.8,34.74]],"id":41122648},{"batl":[[1,2.06,150.52]],"id":51922},{"tv":25108.7,"batb":[[0,4.8,45.04]],"trd":[[4.8,2312.17]],"batl":[[0,4.9,70.8]],"id":50466254}],"tv":180820.01}],"ArrivalTime":1710508192795}
{"op":"mcm","id":2,"clk":"ALaQAQC2xAEAotkB","pt":1710508192889,"mc":[{"id":"1.226122413","rc":[{"tv":128535.72,"batb":[[0,2.02,703.09]],"trd":[[2.02,640.53]],"ltp":2.02,"batl":[[0,2.04,158.49]],"id":51922},{"tv":25108.8,"batb":[[1,4.7,129.49],[0,4.8,44.99]],"trd":[[4.8,2312.27]],"batl":[],"id":50466254},{"batl":[[0,230,11.84]],"id":66251581},{"batb":[[1,34,30.78]],"id":106596}],"tv":180825.19}],"ArrivalTime":1710508192895}
{"op":"mcm","id":2,"clk":"ALqQAQC6xAEAp9kB","pt":1710508192998,"mc":[{"id":"1.226122413","rc":[{"tv":16229.52,"batb":[[0,4.8,34.69]],"trd":[[4.8,847.03]],"id":41122648},{"tv":128537.04,"batb":[[0,2.02,703]],"trd":[[2.04,1317.47],[2.02,640.71]],"batl":[[1,2.06,222.96],[0,2.04,157.92]],"id":51922},{"tv":3196.87,"batb":[[0,60,9.9]],"trd":[[60,79.56]],"id":49744721},{"batb":[],"batl":[[0,4.9,68.3]],"id":50466254}],"tv":180830.61}],"ArrivalTime":1710508193005}
{"op":"mcm","id":2,"clk":"AMaQAQDDxAEAtNkB","pt":1710508193104,"mc":[{"id":"1.226122413","rc":[{"batb":[[0,450,7.4]],"id":41200638},{"tv":128537.36,"batb":[[1,2,223.07],[0,2.02,738.98]],"trd":[[2.02,641.03]],"id":51922},{"tv":3197.07,"batb":[[0,60,9.8]],"trd":[[60,79.76]],"id":49744721},{"tv":25118.8,"batb":[],"trd":[[4.9,753.44]],"ltp":4.9,"batl":[[0,4.9,63.29]],"id":50466254},{"tv":805.06,"trd":[[240,0.32],[230,22.56],[220,9.86]],"ltp":240,"batl":[[1,240,1.22],[0,220,1.4]],"id":66251581},{"tv":2734.96,"batb":[[2,32,55.73],[0,36,16.14]],"trd":[[36,98.9]],"ltp":36,"batl":[],"id":106596}],"tv":180865.33}],"ArrivalTime":1710508193111}
{"op":"mcm","id":2,"clk":"ANGQAQDHxAEAv9kB","pt":1710508193200,"mc":[{"id":"1.226122413","rc":[{"tv":639.12,"trd":[[550,4.69]],"batl":[[0,550,1.82]],"id":41200638},{"batb":[[2,21,119.15]],"id":55632148},{"tv":25118.82,"batb":[[0,4.8,44.98]],"trd":[[4.8,2312.29]],"ltp":4.8,"id":50466254}],"tv":180866.54}],"ArrivalTime":1710508193207}
{"op":"mcm","id":2,"clk":"ANiQAQDQxAEAytkB","pt":1710508193304,"mc":[{"id":"1.226122413","rc":[{"tv":643.54,"batb":[[2,430,1],[0,450,5.18]],"trd":[[490,3.68],[470,2.42],[450,7.38]],"ltp":450,"id":41200638},{"tv":128545.06,"batb":[[0,2.02,759.37]],"trd":[[2.04,1325.17]],"ltp":2.04,"batl":[[0,2.04,154.07]],"id":51922},{"tv":25120.82,"batb":[],"trd":[[4.9,755.44]],"ltp":4.9,"batl":[[0,4.9,62.29]],"id":50466254},{"batl":[[2,270,3.65],[1,250,2.1]],"id":66251581},{"tv":2739.36,"batb":[[2,32,56.08],[0,36,13.94]],"trd":[[36,103.3]],"id":106596}],"tv":180885.06}],"ArrivalTime":1710508193311}
{"op":"mcm","id":2,"clk":"AN2QAQDYxAEA0tkB","pt":1710508193409,"mc":[{"id":"1.226122413","rc":[{"tv":128637.38,"batb":[[0,2.02,713.21]],"trd":[[2.02,733.35]],"ltp":2.02,"id":51922},{"batl":[[1,70,2.35]],"id":49744721},{"batb":[],"batl":[[0,4.9,64.75]],"id":50466254},{"batb":[],"batl":[[2,250,1.47],[1,240,1.26]],"id":66251581}],"tv":180977.38}],"ArrivalTime":1710508193415}
{"op":"mcm","id":2,"clk":"AOOQAQDixAEA29kB","pt":1710508193507,"mc":[{"id":"1.226122413","rc":[{"tv":647.17,"batb":[[0,450,5.84]],"trd":[[550,8.32]],"ltp":550,"batl":[[2,650,1.16],[1,620,1.3],[0,570,3.04]],"id":41200638},{"batb":[[0,23,5.49]],"id":55632148},{"tv":128638.18,"batb":[[0,2.02,692.42]],"trd":[[2.02,734.15]],"id":51922},{"batb":[[2,200,3.69],[1,210,7],[0,220,8.92]],"batl":[[2,260,2],[1,250,1.47],[0,240,1.26]],"id":66251581},{"tv":2746.8,"trd":[[38,112.74]],"ltp":38,"batl":[[2,44,19.91],[1,42,10.1],[0,40,6.04]],"id":106596}],"tv":180989.25}],"ArrivalTime":1710508193514}
{"op":"mcm","id":2,"clk":"AOiQAQDoxAEA3dkB","pt":1710508193551,"mc":[{"id":"1.226122413","rc":[{"batb":[[0,4.8,47.24]],"batl":[[0,4.9,27.65]],"id":41122648},{"batb":[[0,23,10.45]],"batl":[[0,24,12.72]],"id":55632148},{"batb":[[0,2.02,659.54]],"id":51922},{"batb":[[2,50,50.02]],"batl":[[2,75,13.43]],"id":49744721},{"batb":[[2,4.6,133.95]],"id":50466254},{"batb":[[0,220,10.3]],"batl":[[2,270,2.82],[1,260,2],[0,250,2.1]],"id":66251581}]}],"ArrivalTime":1710508193557}
{"op":"mcm","id":2,"clk":"APWQAQDvxAEA6NkB","pt":1710508193723,"mc":[{"id":"1.226122413","rc":[{"batb":[[0,520,2.55]],"id":54370634},{"batb":[[0,4.8,64.28]],"id":41122648},{"tv":648.49,"batb":[[0,450,5.18]],"trd":[[550,9.64]],"batl":[[0,570,3.7]],"id":41200638},{"tv":128638.67,"batb":[[1,2,243.66]],"trd":[[2.04,1325.66]],"ltp":2.04,"batl":[[0,2.04,153.83]],"id":51922},{"tv":25121.34,"batb":[[0,4.8,44.72]],"trd":[[4.8,2312.81]],"ltp":4.8,"id":50466254},{"batb":[[2,210,9],[1,220,10.3],[0,230,1.31]],"id":66251581},{"batl":[[0,40,5.6]],"id":106596}],"tv":180991.58}],"ArrivalTime":1710508193729}
{"op":"mcm","id":2,"clk":"APeQAQD1xAEA8NkB","pt":1710508193776,"mc":[{"id":"1.226122413","rc":[{"tv":3060.76,"batb":[[0,23,8.46]],"trd":[[23,228.23]],"id":55632148},{"tv":128827.35,"batb":[[2,1.99,116.13],[0,2.02,565.2]],"trd":[[2.02,922.83]],"ltp":2.02,"batl":[[0,2.04,154.37]],"id":51922},{"batb":[[2,50,49.96]],"id":49744721},{"tv":25122.42,"batb":[[2,4.6,105.2],[0,4.8,71.78]],"trd":[[4.8,2313.89]],"id":50466254}],"tv":181185.32}],"ArrivalTime":1710508193783}
{"op":"mcm","id":2,"clk":"AIeRAQD+xAEA+NkB","pt":1710508193882,"mc":[{"id":"1.226122413","rc":[{"batb":[[2,440,3.03],[1,450,5.18],[0,470,2.88]],"id":41200638},{"tv":128830.66,"batb":[[0,2.02,563.75]],"trd":[[2.04,1326.07],[2.02,925.73]],"ltp":2.04,"batl":[[0,2.04,154.16]],"id":51922},{"tv":807.68,"batb":[[2,200,3.69],[1,210,9],[0,220,10.3]],"trd":[[230,25.18]],"ltp":230,"batl":[],"id":66251581}],"tv":181191.25}],"ArrivalTime":1710508193889}
{"op":"mcm","id":2,"clk":"AIqRAQCExQEA/tkB","pt":1710508193982,"mc":[{"id":"1.226122413","rc":[{"batb":[[0,470,3.11]],"id":41200638},{"batb":[[0,2.02,529.75]],"batl":[[2,2.08,408.54]],"id":51922},{"batb":[[0,60,13.73]],"id":49744721},{"tv":25138.88,"batb":[[0,4.8,71.24]],"trd":[[4.9,770.82],[4.8,2314.97]],"ltp":4.9,"batl":[[0,4.9,57.06]],"id":50466254},{"batb":[[2,200,3.09],[0,220,11.3]],"batl":[],"id":66251581}],"tv":181207.71}],"ArrivalTime":1710508193989}
{"op":"mcm","id":2,"clk":"AI+RAQCNxQEAidoB","pt":1710508194087,"mc":[{"id":"1.226122413","rc":[{"tv":16264.52,"batb":[[0,4.8,46.78]],"trd":[[4.8,882.03]],"id":41122648},{"batb":[[2,450,5],[1,460,1.65]],"batl":[[2,620,1.3],[1,570,3.7],[0,540,1.29]],"id":41200638},{"batb":[[0,23,11.04]],"id":55632148},{"tv":128836.98,"batb":[[1,2,294.16],[0,2.02,526.59]],"trd":[[2.02,932.05]],"ltp":2.02,"id":51922},{"tv":25178.47,"batb":[[0,4.8,61.24]],"trd":[[4.9,790.41],[4.8,2334.97]],"ltp":4.8,"batl":[[0,4.9,47.27]],"id":50466254},{"batb":[[2,210,9],[1,220,11.3],[0,230,1.31]],"id":66251581}],"tv":181288.62}],"ArrivalTime":1710508194093}
{"op":"mcm","id":2,"clk":"AJWRAQCUxQEAkNoB","pt":1710508194188,"mc":[{"id":"1.226122413","rc":[{"batl":[[2,950,3.35]],"id":54370634},{"batl":[[0,540,2.58]],"id":41200638},{"tv":128889.39,"batb":[[0,2.02,513.69]],"trd":[[2.04,1352.68],[2.02,957.85]],"ltp":2.04,"batl":[[1,2.06,216.98],[0,2.04,150.86]],"id":51922},{"batl":[[0,4.9,50.28]],"id":50466254}],"tv":181341.03}],"ArrivalTime":1710508194194}
{"op":"mcm","id":2,"clk":"AJqRAQCcxQEAl9oB","pt":1710508194295,"mc":[{"id":"1.226122413","rc":[{"batb":[[0,520,2.43]],"batl":[[2,910,1.31]],"id":54370634},{"tv":16264.72,"batb":[[0,4.8,29.79]],"trd":[[4.9,595.37]],"ltp":4.9,"batl":[[0,4.9,27.55]],"id":41122648},{"batl":[[1,570,3.86]],"id":41200638},{"batb":[[0,2.02,513.74]],"batl":[],"id":51922},{"batb":[[0,60,13.78]],"id":49744721},{"tv":25193.85,"trd":[[4.9,805.79]],"ltp":4.9,"batl":[[0,4.9,42.59]],"id":50466254},{"batb":[],"batl":[[1,260,1.17]],"id":66251581}],"tv":181356.61}],"ArrivalTime":1710508194302}
{"op":"mcm","id":2,"clk":"AKCRAQCoxQEAodoB","pt":1710508194395,"mc":[{"id":"1.226122413","rc":[{"batl":[[2,790,4.18],[1,780,2.38],[0,720,1]],"id":54370634},{"batl":[[2,5.1,53.53]],"id":41122648},{"batl":[[0,540,3.87]],"id":41200638},{"tv":128889.75,"batb":[[0,2.02,513.56]],"trd":[[2.02,958.21]],"ltp":2.02,"id":51922}],"tv":181356.97}],"ArrivalTime":1710508194401}
{"op":"mcm","id":2,"clk":"AKSRAQCzxQEAqtoB","pt":1710508194496,"mc":[{"id":"1.226122413","rc":[{"tv":16328.22,"batb":[[2,4.5,158.03],[1,4.6,72.56],[0,4.7,86.82]],"trd":[[4.7,20.38],[4.8,941.61]],"ltp":4.7,"batl":[[0,4.9,37.83]],"id":41122648},{"batb":[[2,460,4.79],[1,470,2.88],[0,480,1.21]],"batl":[[0,540,4.41]],"id":41200638},{"tv":128954.15,"batb":[[0,2.02,481.36]],"trd":[[2.02,1022.61]],"id":51922},{"batb":[[2,50,51.46]],"id":49744721},{"tv":25258.41,"batb":[[2,4.6,96.2],[1,4.7,132.07],[0,4.8,29]],"trd":[[4.8,2399.53]],"ltp":4.8,"batl":[[0,4.9,48.53]],"id":50466254},{"batl":[[1,42,16.6]],"id":106596}],"tv":181549.43}],"ArrivalTime":1710508194503}
{"op":"mcm","id":2,"clk":"AKmRAQC9xQEAstoB","pt":1710508194602,"mc":[{"id":"1.226122413","rc":[{"batb":[[0,520,3.31]],"batl":[[2,910,1.31]],"id":54370634},{"batl":[[2,5,59.04],[1,4.9,37.83],[0,4.8,37]],"id":41122648},{"tv":3065.91,"batb":[[0,23,8.47]],"trd":[[23,233.38]],"batl":[[0,24,13.45]],"id":55632148},{"tv":129114.79,"batb":[[0,2.02,401.04]],"trd":[[2.02,1183.25]],"batl":[[0,2.04,157.51]],"id":51922},{"batb":[[2,50,51.26]],"id":49744721},{"batb":[],"batl":[[1,5,85.37],[0,4.9,42.78]],"id":50466254}],"tv":181715.22}],"ArrivalTime":1710508194608}
{"op":"mcm","id":2,"clk":"AK+RAQDDxQEAu9oB","pt":1710508194703,"mc":[{"id":"1.226122413","rc":[{"tv":16351.58,"batb":[[1,4.6,69.77]],"trd":[[4.8,964.97]],"ltp":4.8,"batl":[[1,4.9,39.88],[0,4.8,42.24]],"id":41122648},{"batb":[[1,470,3.88]],"batl":[[1,570,1.05]],"id":41200638},{"tv":129115.19,"batb":[[0,2.02,435.84]],"trd":[[2.02,1183.65]],"batl":[[2,2.08,397.54]],"id":51922},{"tv":25260.41,"batb":[[0,4.8,70.84]],"trd":[[4.8,2401.53]],"id":50466254}],"tv":181740.98}],"ArrivalTime":1710508194709}
{"op":"mcm","id":2,"clk":"ALaRAQDSxQEAxNoB","pt":1710508194780,"mc":[{"id":"1.226122413","rc":[{"tv":16394.02,"batb":[[0,4.7,67.17]],"trd":[[4.7,59.68],[4.8,968.11]],"ltp":4.7,"batl":[[0,4.8,40.67]],"id":41122648},{"batb":[[0,480,1.94]],"id":41200638},{"batb":[],"batl":[[0,2.04,168.51]],"id":51922},{"batb":[[2,50,51.49]],"batl":[[2,75,8.16]],"id":49744721}],"tv":181783.42}],"ArrivalTime":1710508194787}
{"op":"mcm","id":2,"clk":"ALyRAQDXxQEAyNoB","pt":1710508194886,"mc":[{"id":"1.226122413","rc":[{"tv":549.05,"trd":[[720,11.36]],"ltp":720,"batl":[[2,950,2.82],[1,910,1.31],[0,780,2.78]],"id":54370634},{"batb":[[0,4.7,70.67]],"batl":[[1,4.9,42.45],[0,4.8,53.45]],"id":41122648},{"batb":[[0,23,12.47]],"id":55632148},{"tv":129116.65,"batb":[[0,2.02,435.11]],"trd":[[2.02,1185.11]],"batl":[[0,2.04,174.49]],"id":51922},{"batl":[[0,4.9,21.67]],"id":50466254},{"batl":[[1,42,13.35]],"id":106596}],"tv":181786.08}],"ArrivalTime":1710508194892}
{"op":"mcm","id":2,"clk":"AMGRAQDfxQEA1NoB","pt":1710508194994,"mc":[{"id":"1.226122413","rc":[{"tv":16394.72,"batb":[[1,4.6,87.4],[0,4.7,70.32]],"trd":[[4.7,60.38]],"batl":[[2,5,98.6]],"id":41122648},{"tv":3065.93,"batb":[[0,23,12.46]],"trd":[[23,233.4]],"id":55632148},{"tv":3197.09,"batb":[[0,60,13.77]],"trd":[[60,79.78]],"batl":[[2,75,13.43]],"id":49744721},{"batb":[[2,4.6,148.42]],"id":50466254}],"tv":181786.82}],"ArrivalTime":1710508195000}
{"op":"mcm","id":2,"clk":"AMaRAQDkxQEA29oB","pt":1710508195102,"mc":[{"id":"1.226122413","rc":[{"batb":[[2,470,2.03]],"id":54370634},{"batb":[[0,4.7,76.69]],"id":41122648},{"tv":648.51,"trd":[[540,4.89]],"ltp":540,"batl":[[0,540,4.4]],"id":41200638},{"batl":[[0,24,12.72]],"id":55632148},{"tv":129136.65,"batb":[[0,2.02,425.11]],"trd":[[2.02,1205.11]],"batl":[[0,2.04,177.49]],"id":51922},{"tv":811.96,"batb":[[2,200,6.23],[1,210,9],[0,220,10.48]],"trd":[[230,27.8],[220,11.52]],"ltp":220,"batl":[],"id":66251581}],"tv":181811.12}],"ArrivalTime":1710508195109}
{"op":"mcm","id":2,"clk":"ANKRAQDyxQEA49oB","pt":1710508195203,"mc":[{"id":"1.226122413","rc":[{"batl":[[2,930,1.34]],"id":54370634},{"batl":[[2,5,101.25]],"id":41122648},{"tv":129136.95,"batb":[[0,2.02,425.01]],"trd":[[2.04,1352.78],[2.02,1205.31]],"batl":[[0,2.04,177.44]],"id":51922},{"tv":25262.53,"batb":[[0,4.8,69.78]],"trd":[[4.8,2403.65]],"id":50466254},{"tv":2746.82,"batb":[[0,36,13.93]],"trd":[[36,103.32]],"ltp":36,"id":106596}],"tv":181813.56}],"ArrivalTime":1710508195210}
{"op":"mcm","id":2,"clk":"ANuRAQD4xQEA6NoB","pt":1710508195311,"mc":[{"id":"1.226122413","rc":[{"batb":[[1,4.6,81.05]],"batl":[],"id":41122648},{"batl":[[0,24,12.33]],"id":55632148},{"tv":129506.48,"batb":[[2,1.99,110.4],[0,2.02,417.68]],"trd":[[2.04,1707.65],[2.02,1219.97]],"ltp":2.04,"batl":[[2,2.1,354.68],[1,2.08,387.54],[0,2.06,216.98]],"id":51922},{"batb":[[2,210,9],[1,220,10.48],[0,230,1.34]],"batl":[],"id":66251581}],"tv":182183.09}],"ArrivalTime":1710508195318}
{"op":"mcm","id":2,"clk":"AOGRAQCBxgEA79oB","pt":1710508195410,"mc":[{"id":"1.226122413","rc":[{"tv":3068.33,"batb":[[2,21,86.48]],"trd":[[24,348.71]],"ltp":24,"batl":[[0,24,11.13]],"id":55632148},{"batb":[[2,2,294.16],[1,2.02,417.68],[0,2.04,38.57]],"id":51922},{"tv":25305.88,"batb":[[2,4.7,132.07],[1,4.8,69.78],[0,4.9,6.96]],"trd":[[4.9,849.14]],"ltp":4.9,"batl":[[2,5.2,50.39],[1,5.1,31.41],[0,5,85.37]],"id":50466254},{"tv":2749.1,"batb":[[2,32,38.02],[0,36,12.79]],"trd":[[36,105.6]],"batl":[[2,42,13.35],[1,40,5.6],[0,38,1.02]],"id":106596}],"tv":182231.12}],"ArrivalTime":1710508195416}
{"op":"mcm","id":2,"clk":"AOeRAQCKxgEA9NoB","pt":1710508195463,"mc":[{"id":"1.226122413","rc":[{"batl":[[0,780,1.93]],"id":54370634},{"tv":16398.72,"batb":[[0,4.7,55.5]],"trd":[[4.7,64.38]],"id":41122648},{"tv":129590.22,"batb":[[2,1.99,110.4],[1,2,294.16],[0,2.02,450.12]],"trd":[[2.04,1784.79],[2.02,1226.57]],"ltp":2.02,"id":51922},{"tv":25319.79,"batb":[[2,4.6,148.42],[1,4.7,132.07],[0,4.8,69.78]],"trd":[[4.9,863.05]],"batl":[[2,5.1,31.41],[1,5,85.37],[0,4.9,26.32]],"id":50466254},{"batl":[[2,280,1.62]],"id":66251581}],"tv":182332.77}],"ArrivalTime":1710508195469}
{"op":"mcm","id":2,"clk":"APeRAQCVxgEAg9sB","pt":1710508195629,"mc":[{"id":"1.226122413","rc":[{"tv":16408.72,"batb":[[2,4.5,146.08]],"trd":[[4.8,978.11]],"ltp":4.8,"batl":[[0,4.8,48.45]],"id":41122648},{"batl":[[2,650,1.97],[1,580,1.38]],"id":41200638},{"tv":3069.15,"batb":[[2,21,119.15],[0,23,12.05]],"trd":[[23,234.22]],"ltp":23,"batl":[[0,24,11.64]],"id":55632148},{"tv":129629.47,"trd":[[2.06,2222.09]],"ltp":2.06,"batl":[[0,2.06,197.36]],"id":51922},{"tv":25339.99,"batb":[[0,4.8,87.35]],"trd":[[4.9,863.25],[4.8,2423.65]],"batl":[[0,4.9,32.71]],"id":50466254},{"batb":[[2,32,56.08]],"batl":[[0,38,3.78]],"id":106596}],"tv":182403.04}],"ArrivalTime":1710508195635}
{"op":"mcm","id":2,"clk":"APyRAQCexgEAjdsB","pt":1710508195682,"mc":[{"id":"1.226122413","rc":[{"tv":16474.58,"batb":[[0,4.7,22.57]],"trd":[[4.7,130.24]],"ltp":4.7,"batl":[[2,5,71.23]],"id":41122648},{"tv":129629.67,"batb":[[0,2.02,450.02]],"trd":[[2.02,1226.77]],"ltp":2.02,"batl":[[0,2.06,190.9]],"id":51922},{"tv":25341.99,"batb":[[0,4.8,92.35]],"trd":[[4.9,865.25]],"batl":[[0,4.9,31.71]],"id":50466254}],"tv":182471.1}],"ArrivalTime":1710508195689}
{"op":"mcm","id":2,"clk":"AIiSAQCuxgEAndsB","pt":1710508195851,"mc":[{"id":"1.226122413","rc":[{"batb":[[1,4.6,59.7]],"batl":[],"id":41122648},{"batl":[[2,26,12.2],[1,25,16.74]],"id":55632148},{"batb":[[1,2,334.16]],"batl":[[2,2.08,387.54],[1,2.06,190.9],[0,2.04,2]],"id":51922}]}],"ArrivalTime":1710508195857}
{"op":"mcm","id":2,"clk":"AIuSAQC2xgEApNsB","pt":1710508195892,"mc":[{"id":"1.226122413","rc":[{"tv":16475.6,"batb":[[0,4.7,37.45]],"trd":[[4.7,130.48],[4.8,978.89]],"batl":[[0,4.8,48.06]],"id":41122648},{"tv":3069.2,"batb":[[0,23,12.02]],"trd":[[23,234.27]],"id":55632148},{"tv":129787.03,"batb":[[0,2.02,371.34]],"trd":[[2.02,1384.13]],"batl":[],"id":51922},{"tv":25342.97,"batb":[[0,4.8,92.24]],"trd":[[4.9,866.01],[4.8,2423.87]],"ltp":4.8,"batl":[[0,4.9,31.33]],"id":50466254},{"batb":[[1,220,2.38]],"batl":[],"id":66251581},{"tv":2749.13,"batb":[[0,36,12.77]],"trd":[[36,105.63]],"id":106596}],"tv":182630.54}],"ArrivalTime":1710508195898}
{"op":"mcm","id":2,"clk":"AI6SAQC4xgEArNsB","pt":1710508195988,"mc":[{"id":"1.226122413","rc":[{"batb":[[0,4.7,45.97]],"id":41122648},{"batl":[[1,25,18.97]],"id":55632148},{"batl":[[0,2.04,35.1]],"id":51922},{"batb":[[2,50,52.59]],"id":49744721},{"tv":25348.97,"batb":[[0,4.8,89.24]],"trd":[[4.8,2429.87]],"batl":[[2,5.2,50.39],[1,5.1,31.41],[0,5,85.37]],"id":50466254},{"tv":2752.67,"trd":[[38,116.28]],"ltp":38,"batl":[[0,38,2.01]],"id":106596}],"tv":182640.08}],"ArrivalTime":1710508195995}
{"op":"mcm","id":2,"clk":"AJiSAQDCxgEAuNsB","pt":1710508196091,"mc":[{"id":"1.226122413","rc":[{"batb":[[1,490,2.84]],"id":54370634},{"tv":648.69,"batb":[[0,480,1.85]],"trd":[[500,3.07]],"ltp":500,"id":41200638},{"tv":3073.2,"batb":[[0,23,10.02]],"trd":[[23,238.27]],"id":55632148},{"tv":129803.03,"batb":[[0,2.02,346.6]],"trd":[[2.04,1800.79]],"ltp":2.04,"batl":[[1,2.06,197.91],[0,2.04,27.1]],"id":51922},{"batl":[[1,70,2.44]],"id":49744721},{"batl":[[2,44,19.91],[1,42,16.2],[0,40,5.6]],"id":106596}],"tv":182660.26}],"ArrivalTime":1710508196097}
{"op":"mcm","id":2,"clk":"AKGSAQDKxgEAxtsB","pt":1710508196196,"mc":[{"id":"1.226122413","rc":[{"tv":16495.72,"batb":[[0,4.7,35.97]],"trd":[[4.7,150.48],[4.8,979.01]],"ltp":4.8,"batl":[[0,4.8,48]],"id":41122648},{"batl":[[2,600,1.85]],"id":41200638},{"batb":[[2,4.7,132.07],[1,4.8,89.24],[0,4.9,29.14]],"batl":[],"id":50466254},{"tv":812.13,"batb":[[0,230,1.25]],"trd":[[230,27.97]],"ltp":230,"id":66251581}],"tv":182680.55}],"ArrivalTime":1710508196204}
{"op":"mcm","id":2,"clk":"AKeSAQDTxgEAy9sB","pt":1710508196300,"mc":[{"id":"1.226122413","rc":[{"batb":[[2,490,2.84],[1,510,2.51]],"batl":[[0,780,1.96]],"id":54370634},{"tv":16515.72,"batb":[[0,4.7,25.97]],"trd":[[4.7,170.48]],"ltp":4.7,"id":41122648},{"batl":[[0,65,17.19]],"id":49744721},{"batl":[[0,250,2.13]],"id":66251581}],"tv":182700.55}],"ArrivalTime":1710508196306}
{"op":"mcm","id":2,"clk":"ALGSAQDcxgEA1tsB","pt":1710508196415,"mc":[{"id":"1.226122413","rc":[{"tv":25350.97,"batb":[[0,4.9,28.14]],"trd":[[4.9,868.01]],"ltp":4.9,"id":50466254}],"tv":182702.55}],"ArrivalTime":1710508196421}
{"op":"mcm","id":2,"clk":"ALOSAQDfxgEA39sB","pt":1710508196501,"mc":[{"id":"1.226122413","rc":[{"batb":[],"batl":[[2,950,2.82],[1,930,1.34],[0,910,1.74]],"id":54370634},{"tv":129863.14,"batb":[[0,2.02,316.6]],"trd":[[2.06,2222.2],[2.02,1444.13]],"ltp":2.02,"batl":[[2,2.1,359.34],[1,2.08,387.54],[0,2.06,197.85]],"id":51922},{"tv":25352.97,"batb":[[0,4.9,49.79]],"trd":[[4.9,870.01]],"batl":[[0,5,89.17]],"id":50466254},{"batl":[[1,42,12.95]],"id":106596}],"tv":182764.66}],"ArrivalTime":1710508196508}
{"op":"mcm","id":2,"clk":"ALmSAQDmxgEA59sB","pt":1710508196609,"mc":[{"id":"1.226122413","rc":[{"batl":[[2,930,1.34],[1,910,1.31],[0,770,1.28]],"id":54370634},{"batb":[[0,4.7,23.52]],"batl":[[2,5,66.23]],"id":41122648},{"batl":[[2,2.08,387.54],[1,2.06,197.85],[0,2.04,5.34]],"id":51922},{"tv":25370.73,"batb":[[0,4.9,40.91]],"trd":[[4.9,887.77]],"id":50466254}],"tv":182782.42}],"ArrivalTime":1710508196615}
{"op":"mcm","id":2,"clk":"AMKSAQDwxgEA9NsB","pt":1710508196712,"mc":[{"id":"1.226122413","rc":[{"tv":549.22,"batb":[[2,490,3.04],[0,520,5.76]],"trd":[[530,9.3]],"ltp":530,"id":54370634},{"tv":16562.76,"batb":[[2,4.4,54.61],[1,4.5,146.08],[0,4.6,59.7]],"trd":[[4.7,217.52]],"batl":[[2,4.9,42.45],[1,4.8,48],[0,4.7,4.74]],"id":41122648},{"tv":129864.72,"batb":[[0,2.02,352.66]],"trd":[[2.02,1445.71]],"id":51922},{"tv":2752.87,"batb":[[0,36,12.67]],"trd":[[36,105.83]],"ltp":36,"id":106596}],"tv":182831.41}],"ArrivalTime":1710508196718}
{"op":"mcm","id":2,"clk":"AMmSAQD1xgEA+dsB","pt":1710508196816,"mc":[{"id":"1.226122413","rc":[{"tv":129916.78,"batb":[[0,2.02,326.73]],"trd":[[2.04,1800.99],[2.02,1497.57]],"batl":[[0,2.04,5.24]],"id":51922},{"batb":[[0,4.9,41.73]],"batl":[[0,5,85.17]],"id":50466254}],"tv":182883.47}],"ArrivalTime":1710508196822}
{"op":"mcm","id":2,"clk":"ANCSAQCBxwEAgtwB","pt":1710508196874,"mc":[{"id":"1.226122413","rc":[{"tv":16567.63,"batb":[[2,4.4,97.78],[0,4.6,58.83]],"trd":[[4.7,220.65],[4.6,1.74]],"batl":[[0,4.7,20.05]],"id":41122648},{"batb":[[0,4.9,62.19]],"id":50466254},{"batl":[[0,40,6.08]],"id":106596}],"tv":182888.34}],"ArrivalTime":1710508196880}
{"op":"mcm","id":2,"clk":"ANiSAQCJxwEAjdwB","pt":1710508196976,"mc":[{"id":"1.226122413","rc":[{"batb":[[2,490,1.04]],"id":54370634},{"batl":[[2,4.9,45.14]],"id":41122648},{"batb":[[0,2.02,289.88]],"batl":[],"id":51922},{"tv":25371.75,"batb":[[0,4.9,61.68]],"trd":[[4.9,888.79]],"id":50466254}],"tv":182889.36}],"ArrivalTime":1710508196983}
{"op":"mcm","id":2,"clk":"AN2SAQCOxwEAldwB","pt":1710508197078,"mc":[{"id":"1.226122413","rc":[{"batb":[[2,510,2.51],[1,520,5.76],[0,540,2]],"id":54370634},{"tv":16567.75,"batb":[[2,4.4,144.1]],"trd":[[4.7,220.77]],"batl":[[0,4.7,19.99]],"id":41122648},{"batl":[[1,2.06,167.85]],"id":51922},{"batb":[[2,4.7,131.16]],"id":50466254}],"tv":182889.48}],"ArrivalTime":1710508197084}
{"op":"mcm","id":2,"clk":"AOWSAQCgxwEAotwB","pt":1710508197182,"mc":[{"id":"1.226122413","rc":[{"tv":130133.67,"batb":[[0,2.02,181.44]],"trd":[[2.02,1714.46]],"batl":[[1,2.06,107.85]],"id":51922},{"batl":[[2,75,8.16]],"id":49744721}],"tv":183106.37}],"ArrivalTime":1710508197188}
{"op":"mcm","id":2,"clk":"APCSAQCtxwEArNwB","pt":1710508197290,"mc":[{"id":"1.226122413","rc":[{"tv":130253.67,"batb":[[0,2.02,127.42]],"trd":[[2.02,1834.46]],"batl":[[0,2.04,38.47]],"id":51922},{"tv":25398.35,"batb":[[0,4.9,70.97]],"trd":[[4.9,894.97],[5,1191.83]],"batl":[[0,5,74.96]],"id":50466254}],"tv":183252.97}],"ArrivalTime":1710508197297}
{"op":"mcm","id":2,"clk":"APiSAQCvxwEAstwB","pt":1710508197390,"mc":[{"id":"1.226122413","rc":[{"batl":[[2,4.9,85.51]],"id":41122648},{"tv":649.89,"trd":[[540,6.09]],"ltp":540,"batl":[[0,540,3.8]],"id":41200638},{"batb":[[0,2.02,257.55]],"id":51922},{"batl":[[2,75,13.43]],"id":49744721},{"batb":[[2,4.7,182.26]],"batl":[[0,5,75.46]],"id":50466254},{"batb":[[2,32,56.43]],"id":106596}],"tv":183254.17}],"ArrivalTime":1710508197401}
{"op":"mcm","id":2,"clk":"AP2SAQC4xwEAu9wB","pt":1710508197503,"mc":[{"id":"1.226122413","rc":[{"batb":[[1,520,4.97]],"id":54370634},{"batl":[[0,24,10.89]],"id":55632148},{"tv":130297.89,"batb":[[0,2.02,735.44]],"trd":[[2.02,1878.68]],"batl":[],"id":51922},{"batb":[[0,4.9,215.65]],"batl":[[1,5.1,18.63]],"id":50466254},{"batl":[[1,42,16.26]],"id":106596}],"tv":183298.39}],"ArrivalTime":1710508197511}
{"op":"mcm","id":2,"clk":"AIKTAQC+xwEAxNwB","pt":1710508197601,"mc":[{"id":"1.226122413","rc":[{"batb":[[2,510,2.69]],"id":54370634},{"batl":[[1,4.8,63]],"id":41122648},{"batl":[[0,5,85.48]],"id":50466254}]}],"ArrivalTime":1710508197608}
{"op":"mcm","id":2,"clk":"AIaTAQDGxwEAzNwB","pt":1710508197703,"mc":[{"id":"1.226122413","rc":[{"tv":16582.25,"batb":[[0,4.6,51.58]],"trd":[[4.6,16.24]],"ltp":4.6,"batl":[[2,4.9,88.23]],"id":41122648},{"tv":130330.69,"batb":[[0,2.02,719.04]],"trd":[[2.02,1911.48]],"id":51922},{"tv":25412.23,"batb":[[0,4.9,208.71]],"trd":[[4.9,908.85]],"id":50466254},{"tv":2752.99,"batb":[[0,36,12.61]],"trd":[[36,105.95]],"id":106596}],"tv":183359.69}],"ArrivalTime":1710508197710}
{"op":"mcm","id":2,"clk":"AIuTAQDTxwEA1NwB","pt":1710508197805,"mc":[{"id":"1.226122413","rc":[{"batb":[[2,510,2.71]],"id":54370634},{"batb":[[1,4.5,126.28]],"id":41122648},{"batb":[[2,21,86.48],[1,22,27.43]],"id":55632148},{"batb":[[1,2,338.99]],"batl":[],"id":51922},{"batb":[[1,55,18.04]],"id":49744721},{"tv":25445.97,"batb":[[1,4.8,92.03],[0,4.9,191.84]],"trd":[[4.9,942.59]],"batl":[[1,5.1,19.12]],"id":50466254},{"batb":[[1,34,31.1]],"id":106596}],"tv":183393.43}],"ArrivalTime":1710508197812}
{"op":"mcm","id":2,"clk":"AJeTAQDZxwEA3twB","pt":1710508197909,"mc":[{"id":"1.226122413","rc":[{"batl":[[0,4.7,43.81]],"id":41122648},{"tv":653.6,"batb":[[2,450,5.2],[1,460,4.79],[0,470,3.88]],"trd":[[500,3.35],[480,9.52]],"ltp":480,"batl":[[0,540,3.95]],"id":41200638},{"batl":[[1,5.1,38.17]],"id":50466254},{"batb":[[2,32,38.37]],"id":106596}],"tv":183397.14}],"ArrivalTime":1710508197915}
{"op":"mcm","id":2,"clk":"AJuTAQDixwEA6NwB","pt":1710508198035,"mc":[{"id":"1.226122413","rc":[{"batb":[[2,21,119.15]],"id":55632148},{"tv":25446.19,"trd":[[5,1192.05]],"ltp":5,"batl":[[0,5,85.37]],"id":50466254}],"tv":183397.36}],"ArrivalTime":1710508198042}
{"op":"mcm","id":2,"clk":"AKWTAQDoxwEA9NwB","pt":1710508198122,"mc":[{"id":"1.226122413","rc":[{"tv":653.9,"batb":[[0,470,4.42]],"trd":[[480,9.82]],"batl":[[2,650,1.83],[1,600,1.85],[0,580,1.38]],"id":41200638},{"tv":130330.89,"batb":[[0,2.02,718.94]],"trd":[[2.02,1911.68]],"id":51922},{"batb":[[2,32,56.43]],"id":106596}],"tv":183397.86}],"ArrivalTime":1710508198128}
{"op":"mcm","id":2,"clk":"AKuTAQDvxwEA/9wB","pt":1710508198224,"mc":[{"id":"1.226122413","rc":[{"tv":3079.2,"batb":[[0,23,7.02]],"trd":[[23,244.27]],"id":55632148},{"batl":[[2,280,4.44]],"id":66251581}],"tv":183403.86}],"ArrivalTime":1710508198231}
{"op":"mcm","id":2,"clk":"ALSTAQD6xwEAid0B","pt":1710508198328,"mc":[{"id":"1.226122413","rc":[{"tv":16582.45,"trd":[[4.7,220.97]],"ltp":4.7,"batl":[[0,4.7,43.71]],"id":41122648},{"tv":130336.89,"batb":[[0,2.02,715.94]],"trd":[[2.02,1917.68]],"id":51922},{"batb":[[2,4.7,181.4]],"batl":[[1,5.1,38.66]],"id":50466254}],"tv":183410.06}],"ArrivalTime":1710508198334}
{"op":"mcm","id":2,"clk":"ALmTAQCHyAEAj90B","pt":1710508198432,"mc":[{"id":"1.226122413","rc":[{"batl":[[0,24,13.08]],"id":55632148},{"tv":130515.94,"batb":[[0,2.02,626.41]],"trd":[[2.02,2096.73]],"id":51922},{"batb":[[2,50,48.89]],"id":49744721},{"tv":25447.9,"batb":[],"trd":[[5,1193.76]],"batl":[[2,5.2,51.35],[0,5,84.52]],"id":50466254},{"tv":2753.01,"trd":[[38,116.3]],"ltp":38,"batl":[[0,40,6.07]],"id":106596}],"tv":183590.84}],"ArrivalTime":1710508198439}
{"op":"mcm","id":2,"clk":"AMCTAQCLyAEAlN0B","pt":1710508198478,"mc":[{"id":"1.226122413","rc":[{"batl":[[2,950,2.82],[1,930,1.34],[0,910,1.74]],"id":54370634},{"batb":[[0,2.02,664.98]],"batl":[[0,2.04,48.47]],"id":51922},{"batb":[[1,55,21.74]],"id":49744721}]}],"ArrivalTime":1710508198485}
{"op":"mcm","id":2,"clk":"AMWTAQCWyAEAn90B","pt":1710508198588,"mc":[{"id":"1.226122413","rc":[{"batl":[[2,650,1.67]],"id":41200638},{"tv":130612.88,"batb":[[2,2,338.99],[1,2.02,684.23],[0,2.04,39.53]],"trd":[[2.04,1897.93]],"ltp":2.04,"batl":[[2,2.1,361.97],[1,2.08,387.54],[0,2.06,107.85]],"id":51922},{"tv":3197.11,"trd":[[65,0.02]],"ltp":65,"batl":[[0,65,17.18]],"id":49744721},{"batb":[[0,4.9,196.84]],"batl":[[0,5,74.5]],"id":50466254}],"tv":183687.8}],"ArrivalTime":1710508198594}
{"op":"mcm","id":2,"clk":"AM6TAQCeyAEApd0B","pt":1710508198689,"mc":[{"id":"1.226122413","rc":[{"batb":[],"batl":[[0,4.7,56.72]],"id":41122648},{"batl":[[2,600,1.85],[1,590,2.13]],"id":41200638},{"tv":130691.94,"batb":[[2,1.99,110.4],[1,2,338.99],[0,2.02,721.8]],"trd":[[2.04,1976.99]],"batl":[[2,2.1,531.05],[0,2.06,126.68]],"id":51922},{"batb":[[0,4.9,193.96]],"id":50466254}],"tv":183766.86}],"ArrivalTime":1710508198695}
{"op":"mcm","id":2,"clk":"AN+TAQCoyAEArt0B","pt":1710508198802,"mc":[{"id":"1.226122413","rc":[{"batb":[[0,540,2.77]],"id":54370634},{"tv":16584.55,"batb":[[1,4.5,143.72],[0,4.6,33.95]],"trd":[[4.7,223.07]],"batl":[[0,4.7,55.67]],"id":41122648},{"batb":[[0,23,3.02]],"batl":[[0,24,13.87]],"id":55632148},{"batl":[[2,2.08,393.54],[1,2.06,119.67],[0,2.04,16.27]],"id":51922},{"tv":25455.66,"batb":[[0,4.9,190.08]],"trd":[[4.9,950.35]],"ltp":4.9,"batl":[[0,5,87.99]],"id":50466254}],"tv":183776.72}],"ArrivalTime":1710508198808}
{"op":"mcm","id":2,"clk":"AOKTAQCvyAEAtd0B","pt":1710508198893,"mc":[{"id":"1.226122413","rc":[{"tv":16589.43,"batb":[[0,4.6,31.51]],"trd":[[4.6,21.12]],"ltp":4.6,"batl":[[1,4.8,80]],"id":41122648},{"batl":[[2,5.2,60.23]],"id":50466254}],"tv":183781.6}],"ArrivalTime":1710508198900}
{"op":"mcm","id":2,"clk":"AOuTAQC8yAEAvt0B","pt":1710508199004,"mc":[{"id":"1.226122413","rc":[{"tv":16591.63,"batb":[[0,4.6,30.63]],"trd":[[4.6,23.32]],"batl":[],"id":41122648},{"tv":653.96,"batb":[[0,470,4.39]],"trd":[[480,9.88]],"id":41200638},{"tv":25458.42,"batb":[[0,4.9,188.7]],"trd":[[4.9,953.11]],"batl":[[2,5.2,51.35]],"id":50466254}],"tv":183786.62}],"ArrivalTime":1710508199011}
{"op":"mcm","id":2,"clk":"APOTAQDByAEAxt0B","pt":1710508199113,"mc":[{"id":"1.226122413","rc":[{"tv":16592.29,"batb":[[0,4.6,30.3]],"trd":[[4.6,23.98]],"id":41122648},{"tv":130749.12,"batb":[[0,2.02,720.21]],"trd":[[2.04,2009.53],[2.06,2243.66],[2.02,2099.91]],"ltp":2.02,"batl":[[2,2.1,531.05],[1,2.08,393.54],[0,2.06,108.94]],"id":51922},{"tv":25489.22,"batb":[[0,4.9,197.3]],"trd":[[4.9,953.91],[5,1223.76]],"batl":[[0,5,72.98]],"id":50466254}],"tv":183875.26}],"ArrivalTime":1710508199119}
{"op":"mcm","id":2,"clk":"APWTAQDIyAEAzd0B","pt":1710508199201,"mc":[{"id":"1.226122413","rc":[{"batb":[[0,4.6,47.35]],"id":41122648},{"batb":[],"batl":[[2,650,1.67],[1,600,1.85],[0,590,2.85]],"id":41200638},{"batb":[[0,23,13.56]],"id":55632148},{"tv":130751.12,"trd":[[2.04,2011.53]],"ltp":2.04,"batl":[[2,2.08,393.54],[1,2.06,108.94],[0,2.04,6.21]],"id":51922},{"batb":[[0,36,15.08]],"id":106596}],"tv":183877.26}],"ArrivalTime":1710508199208}
{"op":"mcm","id":2,"clk":"APuTAQDSyAEA1t0B","pt":1710508199316,"mc":[{"id":"1.226122413","rc":[{"batb":[[1,520,2.54]],"batl":[[1,930,2.12],[0,900,2.45]],"id":54370634},{"batb":[[2,4.4,132.06]],"batl":[[2,4.9,85.54]],"id":41122648},{"tv":130763.54,"batb":[[2,2,338.99],[1,2.02,720.21],[0,2.04,10.06]],"trd":[[2.04,2023.95]],"batl":[[2,2.1,531.05],[1,2.08,393.54],[0,2.06,108.94]],"id":51922},{"tv":25499.22,"batb":[[1,4.8,92.89]],"trd":[[5,1233.76]],"ltp":5,"batl":[[0,5,54.49]],"id":50466254}],"tv":183899.68}],"ArrivalTime":1710508199323}
{"op":"mcm","id":2,"clk":"AIWUAQDfyAEA390B","pt":1710508199410,"mc":[{"id":"1.226122413","rc":[{"tv":3203.11,"batb":[[0,60,10.77]],"trd":[[60,85.78]],"ltp":60,"id":49744721}],"tv":183905.68}],"ArrivalTime":1710508199416}
{"op":"mcm","id":2,"clk":"AI2UAQDoyAEA690B","pt":1710508199514,"mc":[{"id":"1.226122413","rc":[{"batl":[[2,4.9,88.23]],"id":41122648},{"batb":[[1,22,23.16]],"id":55632148},{"batl":[[0,2.06,118.27]],"id":51922},{"tv":25526.22,"batb":[[0,4.9,196.3]],"trd":[[4.9,955.91],[5,1258.76]],"batl":[[0,5,54.34]],"id":50466254}],"tv":183932.68}],"ArrivalTime":1710508199521}
{"op":"mcm","id":2,"clk":"AJaUAQDtyAEA890B","pt":1710508199616,"mc":[{"id":"1.226122413","rc":[{"batl":[[2,930,2.12],[1,900,2.02],[0,790,1.28]],"id":54370634},{"batb":[[0,4.6,30.3]],"id":41122648},{"tv":3079.42,"batb":[[0,23,13.45]],"trd":[[23,244.49]],"id":55632148},{"tv":130769.1,"batb":[[1,2.02,729.21],[0,2.04,7.28]],"trd":[[2.04,2029.51]],"id":51922},{"batb":[[0,60,5.37]],"id":49744721},{"tv":25534.26,"trd":[[5,1266.8]],"batl":[[0,5,50.32]],"id":50466254}],"tv":183946.5}],"ArrivalTime":1710508199622}
{"op":"mcm","id":2,"clk":"AJ2UAQD0yAEA/t0B","pt":1710508199675,"mc":[{"id":"1.226122413","rc":[{"batl":[[2,4.9,47.86]],"id":41122648},{"batl":[[0,2.06,137.1]],"id":51922},{"batb":[[0,60,5.32]],"batl":[[2,75,8.16]],"id":49744721},{"tv":25560.74,"batb":[[2,4.7,130.3],[1,4.8,79.1]],"trd":[[5,1293.28]],"batl":[[0,5,37.08]],"id":50466254},{"batb":[[2,210,7]],"id":66251581}],"tv":183972.98}],"ArrivalTime":1710508199681}
{"op":"mcm","id":2,"clk":"AKWUAQD/yAEAit4B","pt":1710508199782,"mc":[{"id":"1.226122413","rc":[{"tv":25560.76,"batb":[[1,4.8,80.13],[0,4.9,196.29]],"trd":[[4.9,955.93]],"ltp":4.9,"batl":[[0,5,24.73]],"id":50466254},{"batl":[[2,260,1.17],[1,250,1.47],[0,240,1.82]],"id":66251581},{"tv":2758.11,"trd":[[40,9.96],[38,117.24]],"ltp":40,"batl":[[0,40,3.53]],"id":106596}],"tv":183978.1}],"ArrivalTime":1710508199788}
{"op":"mcm","id":2,"clk":"AKuUAQCJyQEAkd4B","pt":1710508199882,"mc":[{"id":"1.226122413","rc":[{"batb":[[2,520,2.54],[1,540,2.77],[0,560,5.66]],"id":54370634},{"batl":[[2,4.9,88.23]],"id":41122648},{"batl":[[2,650,1.92]],"id":41200638},{"tv":3079.66,"batb":[[0,23,13.33]],"trd":[[23,244.73]],"id":55632148},{"tv":3203.35,"batb":[[0,60,5.2]],"trd":[[60,86.02]],"batl":[[2,75,13.43]],"id":49744721},{"batb":[[2,4.7,181.4]],"id":50466254},{"tv":2758.35,"batb":[[0,36,14.96]],"trd":[[36,106.19]],"ltp":36,"id":106596}],"tv":183978.82}],"ArrivalTime":1710508199888}
{"op":"mcm","id":2,"clk":"ALeUAQCUyQEAn94B","pt":1710508199984,"mc":[{"id":"1.226122413","rc":[{"batb":[[0,4.6,33.3]],"id":41122648},{"tv":130945.12,"batb":[[0,2.04,17.28]],"trd":[[2.06,2419.68]],"ltp":2.06,"batl":[[0,2.06,49.08]],"id":51922},{"batb":[[2,200,6.23],[1,210,7],[0,220,4.38]],"id":66251581},{"batl":[[0,40,13.07]],"id":106596}],"tv":184154.84}],"ArrivalTime":1710508199990}
{"op":"mcm","id":2,"clk":"AL6UAQChyQEApN4B","pt":1710508200100,"mc":[{"id":"1.226122413","rc":[{"batb":[[0,4.6,41.72]],"id":41122648},{"tv":3087.65,"trd":[[24,356.7]],"ltp":24,"batl":[[0,24,9.87]],"id":55632148},{"tv":131043.29,"batb":[[2,2.02,729.21],[1,2.04,17.28],[0,2.06,95.91]],"trd":[[2.06,2517.85]],"batl":[[2,2.12,586.31],[1,2.1,531.05],[0,2.08,393.54]],"id":51922},{"tv":25581.42,"batb":[[0,4.9,185.96]],"trd":[[4.9,976.59]],"id":50466254}],"tv":184281.66}],"ArrivalTime":1710508200107}
{"op":"mcm","id":2,"clk":"AM6UAQCryQEAst4B","pt":1710508200254,"mc":[{"id":"1.226122413","rc":[{"tv":549.31,"batb":[[2,520,2.73],[0,560,5.58]],"trd":[[560,5.33]],"ltp":560,"id":54370634},{"tv":16713.71,"trd":[[4.7,344.49]],"ltp":4.7,"batl":[[2,5,26.67],[1,4.9,88.23],[0,4.8,80]],"id":41122648},{"tv":654.06,"batb":[[0,470,4.52]],"trd":[[480,9.98]],"id":41200638},{"tv":3109.37,"batb":[[2,22,23.16],[1,23,13.33],[0,24,6.41]],"trd":[[24,378.42]],"batl":[[2,27,21.75],[1,26,12.2],[0,25,18.97]],"id":55632148},{"tv":131298.51,"batb":[[2,2,338.99],[1,2.02,729.21],[0,2.06,24.08]],"trd":[[2.04,2069.91],[2.06,2732.67]],"id":51922},{"tv":3208.24,"batb":[[0,60,2.41]],"trd":[[60,90.81],[65,0.12]],"ltp":65,"batl":[[0,65,17.13]],"id":49744721},{"tv":25839.83,"batb":[[0,4.9,51.92]],"trd":[[4.9,1235]],"id":50466254},{"tv":812.35,"batb":[[0,220,4.16]],"trd":[[220,11.74]],"ltp":220,"id":66251581},{"tv":2785.53,"batb":[[2,30,24.31],[1,32,56.43],[0,34,31.81]],"trd":[[36,133.37]],"id":106596}],"tv":184970.91}],"ArrivalTime":1710508200260}
{"op":"mcm","id":2,"clk":"ANOUAQC3yQEAwd4B","pt":1710508200376,"mc":[{"id":"1.226122413","rc":[{"batl":[[2,900,1.49],[1,800,1.86]],"id":54370634},{"batb":[[0,4.6,29.72]],"batl":[[2,4.9,95.23],[1,4.8,96],[0,4.7,17]],"id":41122648},{"tv":3115.43,"batb":[[0,24,3.37]],"trd":[[24,384.48]],"batl":[[0,25,21.97]],"id":55632148},{"tv":131346.67,"batb":[[0,2.04,81.84]],"trd":[[2.06,2780.83]],"batl":[[2,2.1,546.05],[1,2.08,408.35],[0,2.06,8.84]],"id":51922},{"tv":3213.06,"batb":[[2,48,11.54],[1,50,48.89],[0,55,21.74]],"trd":[[60,95.63]],"ltp":60,"batl":[[2,70,2.44],[1,65,17.13],[0,60,7.14]],"id":49744721},{"batb":[],"batl":[[2,5.2,58.35],[1,5.1,45.66],[0,5,46.11]],"id":50466254},{"batb":[[1,32,38.37]],"batl":[[1,42,11.1],[0,40,14.07]],"id":106596}],"tv":185029.95}],"ArrivalTime":1710508200382}
{"op":"mcm","id":2,"clk":"ANSUAQC/yQEAyd4B","pt":1710508200410,"mc":[{"id":"1.226122413","rc":[{"tv":16719.59,"batb":[[2,4.4,135.12],[1,4.5,146.97],[0,4.6,49.94]],"trd":[[4.7,350.37]],"batl":[[0,4.7,19.97]],"id":41122648},{"tv":3122.17,"batb":[[2,21,86.48],[1,22,23.16],[0,23,13.33]],"trd":[[24,391.22]],"batl":[[2,26,13],[1,25,22.84],[0,24,6.97]],"id":55632148},{"tv":131386.35,"batb":[[2,2.02,729.21],[1,2.04,81.84],[0,2.06,12.42]],"trd":[[2.06,2820.51]],"batl":[[2,2.12,601.31],[1,2.1,541.05],[0,2.08,408.35]],"id":51922},{"tv":3213.52,"trd":[[60,96.09]],"batl":[[0,60,6.91]],"id":49744721},{"tv":25865.55,"batb":[[0,4.9,29.56]],"trd":[[4.9,1260.72]],"batl":[[0,5,66.98]],"id":50466254},{"batb":[[2,200,5.86],[0,220,3.16]],"id":66251581},{"batb":[[1,32,37.08]],"batl":[[2,42,11.71],[1,40,14.75],[0,38,12.64]],"id":106596}],"tv":185108.43}],"ArrivalTime":1710508200416}
{"op":"mcm","id":2,"clk":"AOKUAQDHyQEA0d4B","pt":1710508200547,"mc":[{"id":"1.226122413","rc":[{"tv":16719.63,"batb":[[0,4.6,65.94]],"trd":[[4.7,350.41]],"batl":[[0,4.7,41.83]],"id":41122648},{"tv":3124.17,"batb":[[1,22,54.34]],"trd":[[24,393.22]],"batl":[[2,26,16],[1,25,25.75],[0,24,5.97]],"id":55632148},{"tv":131424.6,"batb":[[2,2,318.4],[1,2.02,729.21],[0,2.04,40.51]],"trd":[[2.04,2079.91],[2.06,2848.76]],"ltp":2.04,"batl":[[2,2.1,541.05],[1,2.08,408.35],[0,2.06,58.36]],"id":51922},{"batl":[[0,60,7.91]],"id":49744721},{"tv":25924.67,"batb":[[2,4.6,117.55],[1,4.7,181.4],[0,4.8,79.1]],"trd":[[4.9,1319.84]],"id":50466254},{"batb":[[0,34,29]],"batl":[[0,38,15.43]],"id":106596}],"tv":185207.84}],"ArrivalTime":1710508200553}
{"op":"mcm","id":2,"clk":"AO2UAQDUyQEA594B","pt":1710508200685,"mc":[{"id":"1.226122413","rc":[{"batb":[[2,520,2.9],[1,540,2]],"id":54370634},{"batb":[[2,4.4,128.25],[1,4.5,136.69]],"batl":[[2,4.9,92.51],[0,4.7,49.88]],"id":41122648},{"batl":[[2,600,1.85],[1,590,2.13],[0,580,1.57]],"id":41200638},{"tv":3126.25,"batb":[[0,23,12.29]],"trd":[[23,246.81]],"ltp":23,"batl":[[2,26,15.39],[1,25,25.13],[0,24,6.92]],"id":55632148},{"batb":[[1,2.02,750.56]],"batl":[[2,2.1,535.5],[1,2.08,402.21],[0,2.06,68.36]],"id":51922},{"batb":[[2,48,9.75],[1,50,47.96],[0,55,21.1]],"batl":[],"id":49744721},{"batb":[],"batl":[[2,5.2,48.61],[1,5.1,49.24]],"id":50466254},{"tv":2786.95,"batb":[[2,30,21.98],[1,32,34.13],[0,34,45.28]],"trd":[[36,134.79]],"batl":[[2,40,14.07],[1,38,15.67],[0,36,2.55]],"id":106596}],"tv":185211.34}],"ArrivalTime":1710508200691}
{"op":"mcm","id":2,"clk":"APaUAQDeyQEA8d4B","pt":1710508200736,"mc":[{"id":"1.226122413","rc":[{"batb":[[0,560,5.7]],"id":54370634},{"tv":3134.25,"trd":[[24,401.22]],"ltp":24,"batl":[[0,24,2.92]],"id":55632148},{"tv":131425.92,"batb":[[0,2.04,78.18]],"trd":[[2.04,2081.23]],"batl":[],"id":51922},{"batl":[[0,60,6.91]],"id":49744721},{"batb":[[1,4.7,182.44]],"batl":[[2,5.1,49.24],[1,5,64.98],[0,4.9,21.25]],"id":50466254}],"tv":185220.66}],"ArrivalTime":1710508200742}
{"op":"mcm","id":2,"clk":"APyUAQDpyQEA/N4B","pt":1710508200844,"mc":[{"id":"1.226122413","rc":[{"batl":[[0,4.7,35.84]],"id":41122648},{"tv":3144.31,"batb":[[0,23,7.26]],"trd":[[23,256.87]],"ltp":23,"id":55632148},{"tv":131426.72,"trd":[[2.06,2849.56]],"ltp":2.06,"batl":[[0,2.06,67.96]],"id":51922},{"batl":[[1,38,12.88]],"id":106596}],"tv":185231.52}],"ArrivalTime":1710508200850}
{"op":"mcm","id":2,"clk":"AIiVAQDyyQEAh98B","pt":1710508200955,"mc":[{"id":"1.226122413","rc":[{"tv":551.31,"batb":[[0,560,4.71]],"trd":[[560,7.33]],"id":54370634},{"batb":[[1,4.5,186.69]],"batl":[[0,4.7,33.68]],"id":41122648},{"batb":[[0,23,12]],"id":55632148},{"tv":131457.04,"batb":[[0,2.04,63.02]],"trd":[[2.04,2111.55]],"ltp":2.04,"batl":[[0,2.06,73.94]],"id":51922},{"tv":2788.85,"batb":[[0,34,44.33]],"trd":[[34,167.11]],"ltp":34,"batl":[[1,38,13.64],[0,36,3.4]],"id":106596}],"tv":185265.74}],"ArrivalTime":1710508200962}
{"op":"mcm","id":2,"clk":"AI6VAQD8yQEAj98B","pt":1710508201053,"mc":[{"id":"1.226122413","rc":[{"batl":[[0,4.7,27.77]],"id":41122648},{"batb":[[0,23,23.79]],"id":55632148},{"tv":131463.04,"batb":[[0,2.04,194.89]],"trd":[[2.04,2117.55]],"id":51922},{"batb":[[1,4.7,183.47]],"id":50466254},{"batl":[[2,40,14.75]],"id":106596}],"tv":185271.74}],"ArrivalTime":1710508201060}
{"op":"mcm","id":2,"clk":"AJWVAQD/yQEAmt8B","pt":1710508201156,"mc":[{"id":"1.226122413","rc":[{"tv":16719.81,"batb":[[2,4.4,125.19],[0,4.6,65.85]],"trd":[[4.6,24.16]],"ltp":4.6,"id":41122648},{"tv":131548.64,"batb":[[0,2.04,403.79]],"trd":[[2.04,2117.75],[2.06,2934.96]],"ltp":2.06,"batl":[[0,2.06,31.24]],"id":51922},{"batl":[[2,5.1,45.66]],"id":50466254}],"tv":185357.52}],"ArrivalTime":1710508201163}
{"op":"mcm","id":2,"clk":"AJmVAQCJygEAod8B","pt":1710508201207,"mc":[{"id":"1.226122413","rc":[{"batb":[[0,560,4.58]],"id":54370634},{"tv":16755.51,"trd":[[4.7,386.11]],"ltp":4.7,"batl":[[0,4.7,15.96]],"id":41122648},{"tv":3150.15,"trd":[[24,407.06]],"ltp":24,"batl":[[2,27,21.14],[1,26,15.39],[0,25,25.13]],"id":55632148},{"batl":[[0,2.06,15.98]],"id":51922},{"tv":3215.46,"trd":[[60,98.03]],"batl":[[0,60,5.94]],"id":49744721},{"tv":25956.83,"batb":[[0,4.8,63.02]],"trd":[[4.8,2462.03]],"ltp":4.8,"id":50466254},{"tv":2791.63,"trd":[[36,137.57]],"ltp":36,"batl":[[1,38,12.88],[0,36,4.16]],"id":106596}],"tv":185435.94}],"ArrivalTime":1710508201214}
{"op":"mcm","id":2,"clk":"AKGVAQCSygEAqd8B","pt":1710508201329,"mc":[{"id":"1.226122413","rc":[{"batl":[[2,930,2.12]],"id":54370634},{"batl":[[2,2.1,525.5]],"id":51922},{"batl":[[0,4.9,31.25]],"id":50466254}]}],"ArrivalTime":1710508201335}
{"op":"mcm","id":2,"clk":"AKSVAQCeygEAsd8B","pt":1710508201413,"mc":[{"id":"1.226122413","rc":[{"batb":[[2,22,54.34],[1,23,23.79],[0,24,3.34]],"batl":[[2,27,21.88],[0,25,22.22]],"id":55632148},{"tv":131744.86,"batb":[[0,2.04,305.68]],"trd":[[2.04,2313.97]],"ltp":2.04,"id":51922},{"batb":[[0,4.8,58.02]],"batl":[[0,4.9,36.17]],"id":50466254},{"tv":2797.53,"batb":[[0,34,41.38]],"trd":[[34,173.01]],"ltp":34,"batl":[[1,38,13.64],[0,36,5.01]],"id":106596}],"tv":185638.06}],"ArrivalTime":1710508201420}
{"op":"mcm","id":2,"clk":"AK6VAQCiygEAu98B","pt":1710508201521,"mc":[{"id":"1.226122413","rc":[{"batl":[[2,950,2.82],[1,930,2.12],[0,800,2.29]],"id":54370634},{"tv":16765.51,"batb":[[0,4.6,60.85]],"trd":[[4.6,34.16]],"ltp":4.6,"id":41122648},{"tv":131821.68,"batb":[],"trd":[[2.08,2835.13],[2.06,2966.92]],"ltp":2.08,"batl":[[2,2.12,577.84],[1,2.1,525.5],[0,2.08,379.78]],"id":51922},{"tv":26004.83,"batb":[[2,4.6,91.8]],"trd":[[4.9,1367.84]],"ltp":4.9,"batl":[[0,4.9,12.17]],"id":50466254},{"tv":2803.05,"batb":[[0,34,42.93]],"trd":[[36,143.09]],"ltp":36,"batl":[[0,36,2.25]],"id":106596}],"tv":185778.4}],"ArrivalTime":1710508201527}
{"op":"mcm","id":2,"clk":"ALaVAQCrygEAxN8B","pt":1710508201630,"mc":[{"id":"1.226122413","rc":[{"batb":[[2,510,2.91],[1,520,2.9]],"id":54370634},{"batb":[],"batl":[[2,650,1.51],[1,600,1.71],[0,580,1.25]],"id":41200638},{"batb":[],"batl":[[2,27,17.1],[1,26,10.11],[0,25,16.56]],"id":55632148},{"tv":131827.68,"batb":[[0,2.04,302.68]],"trd":[[2.04,2319.97]],"ltp":2.04,"batl":[[2,2.1,525.5],[1,2.08,379.78],[0,2.06,21.51]],"id":51922},{"tv":3217.46,"batb":[[0,55,20.1]],"trd":[[55,130.63]],"ltp":55,"id":49744721},{"tv":26056.31,"trd":[[4.9,1392.18],[5,1320.42]],"ltp":5,"batl":[[2,5.2,46.27],[1,5.1,45.66],[0,5,51.41]],"id":50466254},{"batb":[[2,200,4.94]],"batl":[],"id":66251581},{"batl":[[1,38,12.88],[0,36,1.4]],"id":106596}],"tv":185837.88}],"ArrivalTime":1710508201636}
{"op":"mcm","id":2,"clk":"AMCVAQCyygEA0t8B","pt":1710508201735,"mc":[{"id":"1.226122413","rc":[{"batb":[[0,560,5.31]],"id":54370634},{"tv":16775.51,"batb":[[0,4.6,55.85]],"trd":[[4.6,44.16]],"id":41122648},{"tv":132572.86,"batb":[[1,2.02,721.17],[0,2.04,34.92]],"trd":[[2.04,3004.97],[2.06,2968.32],[2.02,2158.69]],"batl":[[0,2.06,20.81]],"id":51922},{"batb":[[2,4.6,92.84]],"batl":[[2,5.1,45.66],[1,5,51.41],[0,4.9,4.5]],"id":50466254}],"tv":186593.06}],"ArrivalTime":1710508201741}
{"op":"mcm","id":2,"clk":"AMGVAQC/ygEA3t8B","pt":1710508201831,"mc":[{"id":"1.226122413","rc":[{"batb":[[2,470,1.65],[1,510,3.08]],"id":54370634},{"tv":16776.37,"batb":[],"trd":[[4.7,386.97]],"ltp":4.7,"batl":[[2,4.9,89.82],[0,4.7,15.53]],"id":41122648},{"tv":132593.75,"batb":[[0,2.04,32.25]],"trd":[[2.04,3025.86]],"id":51922},{"batb":[[0,55,22.78]],"id":49744721},{"batb":[],"batl":[[0,4.9,9.32]],"id":50466254},{"batb":[[0,34,41.38]],"batl":[],"id":106596}],"tv":186614.81}],"ArrivalTime":1710508201838}
{"op":"mcm","id":2,"clk":"ANKVAQDKygEA6d8B","pt":1710508201934,"mc":[{"id":"1.226122413","rc":[{"tv":16786.37,"batb":[[0,4.6,50.85]],"trd":[[4.6,54.16]],"ltp":4.6,"batl":[[1,4.8,79]],"id":41122648},{"batl":[[2,600,1.71],[1,580,1.25],[0,540,2.13]],"id":41200638},{"tv":3151.07,"batb":[[0,24,7.45]],"trd":[[24,407.98]],"id":55632148},{"tv":132595.84,"batb":[[0,2.04,71.26]],"trd":[[2.04,3027.85],[2.06,2968.42]],"ltp":2.06,"batl":[[0,2.06,20.76]],"id":51922},{"tv":3218.9,"batb":[[0,55,24.84]],"trd":[[60,99.47]],"ltp":60,"batl":[[0,60,5.22]],"id":49744721},{"tv":26074.96,"batb":[[2,4.7,183.47],[1,4.8,58.02],[0,4.9,7.17]],"trd":[[4.9,1410.83]],"ltp":4.9,"batl":[[2,5.2,46.27],[1,5.1,45.66],[0,5,51.41]],"id":50466254}],"tv":186647.91}],"ArrivalTime":1710508201940}
{"op":"mcm","id":2,"clk":"ANqVAQDQygEA898B","pt":1710508202040,"mc":[{"id":"1.226122413","rc":[{"tv":551.57,"batb":[[2,470,1.85]],"trd":[[720,11.62]],"ltp":720,"batl":[[0,800,2.16]],"id":54370634},{"tv":16820.37,"batb":[[0,4.6,54.81]],"trd":[[4.6,88.16]],"batl":[[2,4.9,92.51]],"id":41122648},{"tv":654.42,"trd":[[540,6.45]],"ltp":540,"batl":[[0,540,1.96]],"id":41200638},{"batb":[[0,24,11.47]],"id":55632148},{"tv":132683.12,"batb":[[0,2.04,74.89]],"trd":[[2.04,3115.13]],"ltp":2.04,"id":51922},{"batb":[[0,55,26.59]],"id":49744721},{"tv":26075.06,"batb":[[1,4.8,78.11],[0,4.9,15.47]],"trd":[[5,1320.52]],"ltp":5,"batl":[[0,5,51.36]],"id":50466254},{"batb":[[0,220,3.6]],"id":66251581},{"batb":[[0,34,44.22]],"id":106596}],"tv":186769.91}],"ArrivalTime":1710508202047}
{"op":"mcm","id":2,"clk":"AOKVAQDaygEA9t8B","pt":1710508202150,"mc":[{"id":"1.226122413","rc":[{"tv":16820.83,"batb":[[0,4.6,54.58]],"trd":[[4.6,88.62]],"id":41122648},{"batl":[[1,580,1.08],[0,540,2.13]],"id":41200638},{"batb":[],"batl":[[1,26,12.25]],"id":55632148},{"batb":[[0,2.04,91.97]],"batl":[[0,2.06,46.09]],"id":51922},{"tv":26089.4,"batb":[[0,4.9,33.63]],"trd":[[4.9,1425.17]],"ltp":4.9,"id":50466254},{"tv":2803.23,"trd":[[36,143.27]],"batl":[[0,36,1.31]],"id":106596}],"tv":186784.89}],"ArrivalTime":1710508202156}
{"op":"mcm","id":2,"clk":"AOmVAQDgygEAgeAB","pt":1710508202250,"mc":[{"id":"1.226122413","rc":[{"batb":[[1,510,2.88]],"id":54370634},{"batl":[[2,4.9,52.14]],"id":41122648},{"tv":132769.72,"batb":[[0,2.04,48.67]],"trd":[[2.04,3201.73]],"id":51922},{"tv":3238.92,"batb":[[0,55,16.57]],"trd":[[55,150.65]],"ltp":55,"batl":[[1,65,18.13]],"id":49744721},{"batb":[[2,4.7,132.37],[0,4.9,54.77]],"id":50466254},{"batb":[[1,32,26.46]],"id":106596}],"tv":186891.51}],"ArrivalTime":1710508202257}
{"op":"mcm","id":2,"clk":"APGVAQDvygEAi+AB","pt":1710508202312,"mc":[{"id":"1.226122413","rc":[{"tv":16851.89,"batb":[[0,4.6,61.23]],"trd":[[4.7,418.03]],"ltp":4.7,"batl":[[2,5,24.02],[1,4.9,52.14],[0,4.8,79]],"id":41122648},{"tv":132773.72,"batb":[[0,2.04,46.67]],"trd":[[2.04,3205.73]],"batl":[],"id":51922},{"tv":26091.4,"batb":[[0,4.9,53.77]],"trd":[[4.9,1427.17]],"batl":[],"id":50466254}],"tv":186928.57}],"ArrivalTime":1710508202319}
{"op":"mcm","id":2,"clk":"AP6VAQD4ygEAleAB","pt":1710508202468,"mc":[{"id":"1.226122413","rc":[{"batb":[[2,470,2.06]],"id":54370634},{"batl":[[1,4.9,92.51]],"id":41122648},{"batb":[[0,55,19.57]],"batl":[[2,70,8.09],[0,60,18.56]],"id":49744721},{"tv":26158.94,"batb":[[2,4.7,183.47],[0,4.9,20]],"trd":[[4.9,1494.71]],"id":50466254},{"tv":813.05,"batb":[[0,220,3.25]],"trd":[[220,12.44]],"id":66251581},{"batl":[[2,40,17.09]],"id":106596}],"tv":186996.81}],"ArrivalTime":1710508202475}
{"op":"mcm","id":2,"clk":"AP+VAQCFywEAn+AB","pt":1710508202514,"mc":[{"id":"1.226122413","rc":[{"batl":[[2,4.9,92.51],[1,4.8,79],[0,4.7,8.62]],"id":41122648},{"batl":[[2,650,1.51],[1,600,1.94]],"id":41200638},{"tv":3151.85,"batb":[[0,24,11.08]],"trd":[[24,408.76]],"id":55632148},{"tv":132814.46,"batb":[[0,2.04,26.3]],"trd":[[2.04,3246.47]],"id":51922},{"batl":[[0,60,19.56]],"id":49744721},{"tv":26164.98,"batb":[[0,4.9,16.98]],"trd":[[4.9,1500.75]],"batl":[[0,5,51.86]],"id":50466254},{"batl":[[0,36,2.64]],"id":106596}],"tv":187044.37}],"ArrivalTime":1710508202521}
{"op":"mcm","id":2,"clk":"AJSWAQCHywEAqeAB","pt":1710508202627,"mc":[{"id":"1.226122413","rc":[{"tv":16861.89,"batb":[[0,4.6,56.23]],"trd":[[4.6,98.62]],"ltp":4.6,"id":41122648},{"batb":[[2,4.6,92.84],[1,4.7,183.47],[0,4.8,78.11]],"id":50466254},{"batb":[[1,32,18.8]],"id":106596}],"tv":187054.37}],"ArrivalTime":1710508202634}
{"op":"mcm","id":2,"clk":"AJyWAQCQywEAteAB","pt":1710508202727,"mc":[{"id":"1.226122413","rc":[{"batl":[[0,4.7,14.12]],"id":41122648},{"tv":132818.43,"batb":[[2,2,319.4],[0,2.04,26.82]],"trd":[[2.04,3250.44]],"batl":[[0,2.06,47.31]],"id":51922},{"batb":[],"batl":[[0,5,52.84]],"id":50466254},{"tv":2805.22,"batb":[[0,34,43.22]],"trd":[[34,175]],"ltp":34,"batl":[[0,36,3.74]],"id":106596}],"tv":187060.33}],"ArrivalTime":1710508202734}
{"op":"mcm","id":2,"clk":"AKiWAQCdywEAweAB","pt":1710508202846,"mc":[{"id":"1.226122413","rc":[{"tv":16867.77,"batb":[[0,4.6,59.32]],"trd":[[4.7,423.91]],"ltp":4.7,"batl":[[0,4.7,11.18]],"id":41122648},{"tv":133013.04,"batb":[[0,2.04,14.69]],"trd":[[2.04,3345.04],[2.06,3068.43]],"batl":[[2,2.12,577.84],[1,2.1,525.5],[0,2.08,379.78]],"id":51922},{"batb":[[2,4.6,87.84]],"batl":[[2,5.2,21.27]],"id":50466254}],"tv":187260.82}],"ArrivalTime":1710508202852}
{"op":"mcm","id":2,"clk":"AK6WAQClywEAx+AB","pt":1710508202937,"mc":[{"id":"1.226122413","rc":[{"tv":16898.17,"batb":[[0,4.6,44.12]],"trd":[[4.6,129.02]],"ltp":4.6,"batl":[[2,4.9,101.73]],"id":41122648},{"batb":[[2,22,23.16]],"id":55632148},{"batb":[[2,2,318.42]],"id":51922},{"batb":[[2,4.6,88.87]],"id":50466254},{"batb":[[1,32,26.47]],"id":106596}],"tv":187291.22}],"ArrivalTime":1710508202943}
{"op":"mcm","id":2,"clk":"ALSWAQC1ywEA0OAB","pt":1710508203041,"mc":[{"id":"1.226122413","rc":[{"tv":551.87,"trd":[[720,11.92]],"batl":[[0,800,2.01]],"id":54370634},{"batb":[[0,4.6,67.51]],"id":41122648},{"batb":[[0,470,4.73]],"id":41200638},{"batb":[[0,24,15.56]],"batl":[[0,25,20.58]],"id":55632148},{"tv":133032.82,"batb":[[0,2.04,90.03]],"trd":[[2.04,3364.82]],"batl":[[2,2.1,525.5],[1,2.08,379.78],[0,2.06,57.25]],"id":51922},{"batb":[[0,55,21.53]],"batl":[],"id":49744721},{"batb":[[0,4.8,100.52]],"batl":[[1,5.1,46.15]],"id":50466254},{"batb":[[0,220,3.74]],"id":66251581},{"batb":[[0,34,46.38]],"batl":[[0,36,2.41]],"id":106596}],"tv":187311.3}],"ArrivalTime":1710508203048}
{"op":"mcm","id":2,"clk":"ALuWAQC9ywEA2OAB","pt":1710508203092,"mc":[{"id":"1.226122413","rc":[{"batl":[[2,930,2.12],[1,800,1.86],[0,790,2.97]],"id":54370634},{"batb":[[0,4.6,84.8]],"id":41122648},{"batb":[[2,22,54.34]],"id":55632148},{"tv":133098.82,"batb":[[2,2,318.4]],"trd":[[2.06,3134.43]],"ltp":2.06,"batl":[[0,2.06,24.25]],"id":51922},{"tv":26167.16,"batb":[[0,4.8,99.43]],"trd":[[4.8,2464.21]],"ltp":4.8,"id":50466254},{"batb":[[0,34,29.39]],"id":106596}],"tv":187379.48}],"ArrivalTime":1710508203099}
{"op":"mcm","id":2,"clk":"AMSWAQDFywEA4OAB","pt":1710508203227,"mc":[{"id":"1.226122413","rc":[{"batl":[[1,4.8,81.28],[0,4.7,12.61]],"id":41122648},{"batb":[[1,460,4.82],[0,470,4.32]],"batl":[[2,600,1.94],[1,540,2.13],[0,530,1.32]],"id":41200638},{"tv":3152.87,"batb":[[0,24,15.05]],"trd":[[24,409.78]],"id":55632148},{"tv":133104.72,"batb":[[2,2,322.27],[1,2.02,723.07],[0,2.04,125.03]],"trd":[[2.06,3140.33]],"batl":[[0,2.06,21.3]],"id":51922},{"tv":26324.05,"batb":[[0,4.8,20.99]],"trd":[[4.8,2621.1]],"batl":[[1,5.1,48.27]],"id":50466254},{"batb":[[1,210,7.06]],"id":66251581},{"batb":[[2,30,41.24]],"id":106596}],"tv":187543.29}],"ArrivalTime":1710508203234}
{"op":"mcm","id":2,"clk":"AMqWAQDRywEA5uAB","pt":1710508203303,"mc":[{"id":"1.226122413","rc":[{"tv":133109.04,"trd":[[2.06,3144.65]],"batl":[[0,2.06,19.14]],"id":51922},{"tv":26326.15,"batb":[[0,4.8,19.94]],"trd":[[4.8,2623.2]],"id":50466254}],"tv":187549.71}],"ArrivalTime":1710508203309}
{"op":"mcm","id":2,"clk":"AM+WAQDZywEA8OAB","pt":1710508203407,"mc":[{"id":"1.226122413","rc":[{"batl":[[2,4.9,92.51]],"id":41122648},{"batl":[[1,540,1.96],[0,530,2.79]],"id":41200638},{"batb":[[0,2.04,167.18]],"id":51922},{"batb":[[0,4.8,57.74]],"batl":[[2,5.1,48.27],[1,5,54.38],[0,4.9,21.49]],"id":50466254}]}],"ArrivalTime":1710508203414}
{"op":"mcm","id":2,"clk":"ANiWAQDhywEA+OAB","pt":1710508203504,"mc":[{"id":"1.226122413","rc":[{"tv":16916.81,"trd":[[4.7,442.55]],"ltp":4.7,"batl":[[0,4.7,3.29]],"id":41122648},{"tv":3153.49,"trd":[[25,673.03]],"ltp":25,"batl":[[0,25,20.27]],"id":55632148},{"tv":133111.04,"batb":[[0,2.04,166.18]],"trd":[[2.04,3366.82]],"ltp":2.04,"id":51922},{"tv":3239.34,"batb":[[0,55,21.32]],"trd":[[55,151.07]],"id":49744721},{"tv":26336.57,"batb":[[0,4.8,52.53]],"trd":[[4.8,2633.62]],"id":50466254},{"tv":813.37,"batb":[[0,220,3.58]],"trd":[[220,12.76]],"id":66251581}],"tv":187582.13}],"ArrivalTime":1710508203510}
{"op":"mcm","id":2,"clk":"AN6WAQDuywEAgOEB","pt":1710508203615,"mc":[{"id":"1.226122413","rc":[{"batl":[[0,530,4.11]],"id":41200638},{"batb":[[2,2,343.94],[1,2.02,703.82]],"id":51922},{"tv":26337.03,"batb":[[0,4.8,52.3]],"trd":[[4.8,2634.08]],"batl":[],"id":50466254},{"batl":[[1,38,13.64],[0,36,3.26]],"id":106596}],"tv":187582.59}],"ArrivalTime":1710508203622}
{"op":"mcm","id":2,"clk":"AOaWAQD8ywEAh+EB","pt":1710508203723,"mc":[{"id":"1.226122413","rc":[{"batl":[[0,530,4.2]],"id":41200638},{"tv":133121.04,"batb":[[0,2.04,161.18]],"trd":[[2.04,3376.82]],"id":51922},{"batb":[[1,50,47.73]],"id":49744721}],"tv":187592.59}],"ArrivalTime":1710508203729}
{"op":"mcm","id":2,"clk":"AO2WAQCFzAEAkOEB","pt":1710508203830,"mc":[{"id":"1.226122413","rc":[{"tv":133121.51,"batb":[],"trd":[[2.06,3145.12]],"ltp":2.06,"batl":[[0,2.06,18.9]],"id":51922}],"tv":187593.06}],"ArrivalTime":1710508203836}
{"op":"mcm","id":2,"clk":"APWWAQCLzAEAluEB","pt":1710508203930,"mc":[{"id":"1.226122413","rc":[{"tv":133161.51,"batb":[[0,2.04,183.88]],"trd":[[2.04,3416.82]],"ltp":2.04,"batl":[[0,2.06,214.98]],"id":51922}],"tv":187633.06}],"ArrivalTime":1710508203936}
{"op":"mcm","id":2,"clk":"APqWAQCVzAEAnuEB","pt":1710508204032,"mc":[{"id":"1.226122413","rc":[{"tv":3154.39,"batb":[[0,24,14.6]],"trd":[[24,410.68]],"ltp":24,"id":55632148},{"batl":[[0,2.06,217.48]],"id":51922}],"tv":187633.96}],"ArrivalTime":1710508204038}
{"op":"mcm","id":2,"clk":"AJ2XAQDJzAEAweEB","pt":1710508204513,"mc":[{"id":"1.226122413","rc":[{"batb":[[2,510,2.88],[1,560,4.58],[0,570,1.26]],"id":54370634},{"tv":16926.81,"batb":[[0,4.6,79.8]],"trd":[[4.6,139.02]],"ltp":4.6,"batl":[[0,4.7,8.29],[2,4.9,89.82]],"id":41122648},{"tv":656.42,"batb":[],"trd":[[530,2]],"ltp":530,"batl":[[0,530,3.2]],"id":41200638},{"batb":[],"batl":[[2,27,5.65]],"id":55632148},{"tv":133257.37,"batb":[[2,2,268.77],[0,2.04,129.4],[1,2.02,766.91]],"trd":[[2.04,3462.48],[2.06,3195.32]],"ltp":2.06,"batl":[[0,2.06,229.74],[1,2.08,380.78]],"id":51922},{"tv":3239.92,"trd":[[60,100.05]],"ltp":60,"batl":[[1,65,6.74],[0,60,19.27]],"id":49744721},{"tv":26495.9,"batb":[[2,4.5,101.16],[1,4.6,89.9],[0,4.7,168.79]],"trd":[[4.7,1305.29],[4.8,2763.59]],"ltp":4.7,"batl":[[2,5.2,21.75],[1,5.1,48.27],[0,5,55.03]],"id":50466254},{"tv":2806.22,"batb":[[2,30,61.34]],"trd":[[36,144.27]],"ltp":36,"batl":[[0,36,2.76]],"id":106596}],"tv":187902.27,"con":true}],"ArrivalTime":1710508204519}
{"op":"mcm","id":2,"clk":"AKqXAQDPzAEAzuEB","pt":1710508204618,"mc":[{"id":"1.226122413","rc":[{"batb":[[0,4.6,87.38]],"batl":[[2,4.9,52.14]],"id":41122648},{"batl":[[0,25,17.27]],"id":55632148},{"batb":[[0,2.04,173.16]],"batl":[[0,2.06,245.74]],"id":51922},{"batl":[[2,70,2.44],[0,60,20.27]],"id":49744721},{"batb":[[0,4.7,195.29]],"batl":[[2,5.1,48.27],[1,5,54.38],[0,4.9,15.34]],"id":50466254}]}],"ArrivalTime":1710508204624}
{"op":"mcm","id":2,"clk":"ALGXAQDazAEA2eEB","pt":1710508204706,"mc":[{"id":"1.226122413","rc":[{"tv":656.84,"batb":[[0,470,4.11]],"trd":[[510,2.54]],"ltp":510,"batl":[[2,540,1.96],[1,530,3.2],[0,510,1.92]],"id":41200638},{"tv":133262.33,"batb":[],"trd":[[2.06,3200.28]],"batl":[[0,2.06,243.26]],"id":51922},{"batb":[],"batl":[[0,4.9,36.03]],"id":50466254},{"batb":[[2,30,41.24]],"id":106596}],"tv":187907.65}],"ArrivalTime":1710508204712}
{"op":"mcm","id":2,"clk":"ALuXAQDezAEA4+EB","pt":1710508204812,"mc":[{"id":"1.226122413","rc":[{"batb":[[2,510,3.04],[0,570,1.29]],"id":54370634},{"batb":[[0,4.6,90.64]],"id":41122648},{"batb":[[0,470,4.14]],"id":41200638},{"batb":[[0,24,15.22]],"id":55632148},{"tv":133825.79,"batb":[[0,2.04,182.04]],"trd":[[2.04,3539.42],[2.06,3686.8]],"ltp":2.04,"batl":[[2,2.12,579.91],[1,2.1,525.5],[0,2.08,380.78]],"id":51922},{"batb":[[0,55,21.59]],"batl":[[2,70,8.09]],"id":49744721},{"batb":[[2,4.6,89.9],[1,4.7,147.38],[0,4.8,15.33]],"id":50466254},{"batb":[[0,220,3.65]],"id":66251581},{"batb":[[0,34,29.83]],"id":106596}],"tv":188471.11}],"ArrivalTime":1710508204818}
{"op":"mcm","id":2,"clk":"AMCXAQDlzAEA7eEB","pt":1710508204911,"mc":[{"id":"1.226122413","rc":[{"tv":16964.17,"batb":[[0,4.6,80.25]],"trd":[[4.7,459.13],[4.6,159.8]],"batl":[[2,5,31.02],[1,4.9,52.14],[0,4.8,81.28]],"id":41122648},{"tv":3161.11,"trd":[[25,679.75]],"ltp":25,"batl":[[0,25,13.91]],"id":55632148},{"tv":133897.01,"batb":[[0,2.04,146.43]],"trd":[[2.04,3610.64]],"batl":[],"id":51922},{"tv":26500.13,"batb":[],"trd":[[4.9,1504.98]],"ltp":4.9,"batl":[[0,4.9,33.92]],"id":50466254},{"tv":813.63,"batb":[[0,220,3.52]],"trd":[[220,13.02]],"id":66251581}],"tv":188590.9}],"ArrivalTime":1710508204917}
{"op":"mcm","id":2,"clk":"AMuXAQDwzAEA+OEB","pt":1710508205011,"mc":[{"id":"1.226122413","rc":[{"batb":[[0,2.04,146.48]],"batl":[[0,2.08,399.61]],"id":51922},{"tv":26527.43,"batb":[[2,4.6,90.94],[1,4.7,145.31],[0,4.8,22.71]],"trd":[[4.8,2790.89]],"ltp":4.8,"batl":[[0,4.9,43.92]],"id":50466254}],"tv":188618.2}],"ArrivalTime":1710508205017}
{"op":"mcm","id":2,"clk":"ANeXAQD9zAEAgeIB","pt":1710508205119,"mc":[{"id":"1.226122413","rc":[{"batb":[[2,510,3.42]],"id":54370634},{"tv":16988.43,"trd":[[4.7,483.39]],"ltp":4.7,"batl":[[2,4.9,52.14],[1,4.8,81.28],[0,4.7,1.93]],"id":41122648},{"tv":133901.81,"batb":[[0,2.04,146.65]],"trd":[[2.04,3615.34],[2.06,3686.9]],"id":51922},{"tv":3240.4,"batb":[[0,55,21.35]],"trd":[[55,151.55]],"ltp":55,"id":49744721}],"tv":188647.74}],"ArrivalTime":1710508205126}
{"op":"mcm","id":2,"clk":"AN2XAQCEzQEAh+IB","pt":1710508205221,"mc":[{"id":"1.226122413","rc":[{"batb":[[0,4.6,88.67]],"batl":[[2,4.9,92.51]],"id":41122648},{"batb":[[2,460,4.82],[1,470,3.91],[0,480,3.37]],"batl":[],"id":41200638},{"batb":[[0,2.04,190.53]],"batl":[[2,2.1,525.5],[1,2.08,399.61],[0,2.06,47.85]],"id":51922},{"batl":[[0,60,21.27]],"id":49744721},{"batb":[[2,4.6,143.16],[0,4.8,36.03]],"id":50466254}]}],"ArrivalTime":1710508205228}
{"op":"mcm","id":2,"clk":"AOKXAQCMzQEAjOIB","pt":1710508205328,"mc":[{"id":"1.226122413","rc":[{"batb":[[2,470,1.65],[1,510,3.42]],"id":54370634},{"batl":[[0,25,9.89]],"id":55632148},{"tv":133937.44,"batb":[[1,2.02,746.52],[0,2.04,172.72]],"trd":[[2.04,3650.97]],"batl":[[0,2.06,87.85]],"id":51922},{"batb":[[1,4.7,135.31]],"batl":[[0,4.9,41.87]],"id":50466254}],"tv":188683.37}],"ArrivalTime":1710508205334}
{"op":"mcm","id":2,"clk":"AOeXAQCWzQEAl+IB","pt":1710508205438,"mc":[{"id":"1.226122413","rc":[{"batl":[[2,830,5.73]],"id":54370634},{"batb":[],"batl":[[2,4.9,101.73]],"id":41122648},{"tv":658.83,"batb":[[0,480,2.37]],"trd":[[490,4.13],[480,11.52]],"ltp":480,"batl":[],"id":41200638},{"batb":[[2,22,23.16]],"id":55632148},{"tv":133947.04,"batb":[[0,2.04,167.92]],"trd":[[2.04,3660.57]],"batl":[[0,2.06,98.64]],"id":51922},{"batb":[[2,30,21.98]],"batl":[[2,40,28.54]],"id":106596}],"tv":188694.96}],"ArrivalTime":1710508205444}
{"op":"mcm","id":2,"clk":"AOuXAQCjzQEAoOIB","pt":1710508205536,"mc":[{"id":"1.226122413","rc":[{"batb":[[2,510,2.71],[1,530,5.29]],"id":54370634},{"tv":133961.44,"batb":[[0,2.04,160.72]],"trd":[[2.04,3674.97]],"id":51922},{"batl":[[0,60,20.27]],"id":49744721},{"batl":[[0,4.9,31.87]],"id":50466254},{"tv":2807.2,"trd":[[36,145.25]],"batl":[[0,36,2.27]],"id":106596}],"tv":188710.34}],"ArrivalTime":1710508205544}
{"op":"mcm","id":2,"clk":"APOXAQCozQEAqOIB","pt":1710508205640,"mc":[{"id":"1.226122413","rc":[{"batb":[[1,530,4.91]],"id":54370634},{"tv":3171.41,"batb":[[2,22,54.34],[0,24,10.07]],"trd":[[24,420.98]],"ltp":24,"id":55632148},{"tv":133971.04,"batb":[[1,2.02,766.91],[0,2.04,155.92]],"trd":[[2.04,3684.57]],"batl":[[1,2.08,418.44],[0,2.06,108.64]],"id":51922},{"batb":[[2,30,41.24]],"id":106596}],"tv":188730.24}],"ArrivalTime":1710508205646}
{"op":"mcm","id":2,"clk":"APiXAQC0zQEAseIB","pt":1710508205738,"mc":[{"id":"1.226122413","rc":[{"batl":[[2,4.9,92.51]],"id":41122648}]}],"ArrivalTime":1710508205744}
{"op":"mcm","id":2,"clk":"AP2XAQC/zQEAuOIB","pt":1710508205802,"mc":[{"id":"1.226122413","rc":[{"batl":[[2,600,1.94]],"id":41200638},{"batb":[[0,24,13.07]],"id":55632148}]}],"ArrivalTime":1710508205808}
{"op":"mcm","id":2,"clk":"AIGYAQDGzQEAwOIB","pt":1710508205895,"mc":[{"id":"1.226122413","rc":[{"tv":26537.42,"batb":[[2,4.6,144.19]],"trd":[[4.9,1514.97]],"ltp":4.9,"batl":[[0,4.9,26.87]],"id":50466254}],"tv":188740.23}],"ArrivalTime":1710508205901}
{"op":"mcm","id":2,"clk":"AIiYAQDQzQEAyuIB","pt":1710508206011,"mc":[{"id":"1.226122413","rc":[{"tv":16992.29,"trd":[[4.7,487.25]],"batl":[[2,5,31.02],[1,4.9,92.51],[0,4.8,81.28]],"id":41122648},{"tv":667.37,"batb":[[2,450,5.2],[1,460,1.68],[0,470,2]],"trd":[[480,16.25],[470,6.23]],"ltp":470,"id":41200638},{"tv":3177.99,"trd":[[25,686.33]],"ltp":25,"batl":[[0,25,6.6]],"id":55632148},{"batl":[[0,4.9,32.18]],"id":50466254},{"tv":813.73,"batb":[[0,220,3.47]],"trd":[[220,13.12]],"id":66251581}],"tv":188759.31}],"ArrivalTime":1710508206017}
{"op":"mcm","id":2,"clk":"AI2YAQDZzQEA0uIB","pt":1710508206122,"mc":[{"id":"1.226122413","rc":[{"tv":17018.49,"trd":[[4.8,1005.21]],"ltp":4.8,"batl":[[0,4.8,68.18]],"id":41122648},{"batb":[],"batl":[[1,2.08,421.53]],"id":51922}],"tv":188785.51}],"ArrivalTime":1710508206129}
{"op":"mcm","id":2,"clk":"AJWYAQDkzQEA3+IB","pt":1710508206265,"mc":[{"id":"1.226122413","rc":[{"batl":[[2,4.9,92.51],[1,4.8,68.18],[0,4.7,17.14]],"id":41122648},{"tv":667.39,"batb":[],"trd":[[510,2.56]],"ltp":510,"batl":[[0,510,1.91]],"id":41200638},{"batb":[[0,2.04,161.9]],"batl":[[1,2.08,411.53],[0,2.06,124.64]],"id":51922},{"tv":26539.82,"batb":[[0,4.8,34.83]],"trd":[[4.8,2793.29]],"ltp":4.8,"id":50466254},{"tv":813.75,"trd":[[240,0.34]],"ltp":240,"batl":[[0,240,1.81]],"id":66251581}],"tv":188787.95}],"ArrivalTime":1710508206271}
{"op":"mcm","id":2,"clk":"AJ2YAQDrzQEA6OIB","pt":1710508206318,"mc":[{"id":"1.226122413","rc":[{"tv":17034.89,"trd":[[4.7,503.65]],"ltp":4.7,"batl":[[0,4.7,8.94]],"id":41122648},{"tv":134071.04,"batb":[[0,2.04,111.9]],"trd":[[2.04,3784.57]],"id":51922},{"tv":813.87,"trd":[[240,0.46]],"batl":[[0,240,1.75]],"id":66251581}],"tv":188904.47}],"ArrivalTime":1710508206324}
{"op":"mcm","id":2,"clk":"AKOYAQDxzQEA8OIB","pt":1710508206421,"mc":[{"id":"1.226122413","rc":[{"batb":[[2,530,4.91],[1,550,1.29]],"id":54370634},{"tv":17066.77,"batb":[[2,4.5,186.69],[1,4.6,88.67],[0,4.7,8.78]],"trd":[[4.7,521.53],[4.8,1019.21]],"ltp":4.8,"batl":[[2,5,31.02],[1,4.9,92.51],[0,4.8,61.18]],"id":41122648},{"batb":[[0,470,3.29]],"id":41200638},{"tv":26549.82,"batb":[[0,4.8,29.83]],"trd":[[4.8,2803.29]],"id":50466254},{"batb":[[2,200,4.99],[0,220,4.76]],"id":66251581}],"tv":188946.35}],"ArrivalTime":1710508206428}
{"op":"mcm","id":2,"clk":"AK2YAQD6zQEA+eIB","pt":1710508206520,"mc":[{"id":"1.226122413","rc":[{"tv":553.58,"batb":[[2,510,2.91],[1,530,4.91],[0,550,1.73]],"trd":[[570,1.71]],"ltp":570,"id":54370634},{"batb":[[0,4.7,10.99]],"id":41122648},{"batb":[[1,460,6.04]],"id":41200638},{"tv":3183.99,"batb":[[0,24,10.07]],"trd":[[24,426.98]],"ltp":24,"id":55632148},{"batb":[[0,4.8,42.42]],"batl":[],"id":50466254}],"tv":188954.06}],"ArrivalTime":1710508206526}
{"op":"mcm","id":2,"clk":"ALSYAQCFzgEAgOMB","pt":1710508206621,"mc":[{"id":"1.226122413","rc":[{"tv":17078.57,"batb":[[0,4.7,27.16]],"trd":[[4.7,527.73],[4.8,1024.81]],"ltp":4.7,"batl":[[0,4.8,46.06]],"id":41122648},{"batl":[[0,60,21.27]],"id":49744721},{"batl":[[0,4.9,32.69]],"id":50466254}],"tv":188965.86}],"ArrivalTime":1710508206627}
{"op":"mcm","id":2,"clk":"ALyYAQCPzgEAiuMB","pt":1710508206738,"mc":[{"id":"1.226122413","rc":[{"batb":[[2,460,6.04],[1,470,3.29],[0,480,1.51]],"batl":[[2,650,1.51],[1,600,2.09]],"id":41200638},{"tv":3204.13,"batb":[[0,24,4.51]],"trd":[[24,447.12]],"id":55632148},{"tv":134081.04,"batb":[[0,2.04,94.78]],"trd":[[2.04,3794.57]],"batl":[[1,2.08,414.62]],"id":51922},{"tv":26571.82,"batb":[[0,4.8,31.42]],"trd":[[4.8,2825.29]],"batl":[[0,4.9,33.2]],"id":50466254}],"tv":189018}],"ArrivalTime":1710508206744}
{"op":"mcm","id":2,"clk":"AMOYAQCdzgEAleMB","pt":1710508206849,"mc":[{"id":"1.226122413","rc":[{"tv":17083.95,"batb":[[0,4.7,24.47]],"trd":[[4.7,533.11]],"batl":[[1,4.9,89.82]],"id":41122648}],"tv":189023.38}],"ArrivalTime":1710508206855}
{"op":"mcm","id":2,"clk":"AMyYAQClzgEAoOMB","pt":1710508206939,"mc":[{"id":"1.226122413","rc":[{"batb":[[0,4.7,33.48]],"id":41122648},{"tv":3213.15,"batb":[[0,24,3]],"trd":[[24,456.14]],"id":55632148}],"tv":189032.4}],"ArrivalTime":1710508206945}
{"op":"mcm","id":2,"clk":"ANSYAQCuzgEAq+MB","pt":1710508207042,"mc":[{"id":"1.226122413","rc":[{"batl":[[2,5,33.65]],"id":41122648},{"tv":670.41,"batb":[[2,450,5.2],[1,460,6.04],[0,470,3.29]],"trd":[[480,19.27]],"ltp":480,"batl":[[0,510,2.74]],"id":41200638},{"tv":134108.98,"batb":[[0,2.04,89.78]],"trd":[[2.04,3804.57],[2.06,3704.84]],"ltp":2.06,"batl":[[0,2.06,115.67]],"id":51922},{"batl":[[2,70,2.44]],"id":49744721},{"tv":26581.82,"trd":[[4.9,1524.97]],"ltp":4.9,"batl":[[0,4.9,28.71]],"id":50466254},{"tv":817.87,"batb":[[0,220,2.76]],"trd":[[220,17.12]],"ltp":220,"id":66251581}],"tv":189077.36}],"ArrivalTime":1710508207048}
{"op":"mcm","id":2,"clk":"AN6YAQC4zgEAueMB","pt":1710508207143,"mc":[{"id":"1.226122413","rc":[{"batb":[[0,4.7,53.2]],"id":41122648},{"tv":3222.85,"batb":[[2,21,92.39],[1,22,54.34],[0,23,23.79]],"trd":[[24,465.84]],"batl":[[2,26,12.25],[1,25,10.94],[0,24,2.54]],"id":55632148},{"batl":[[0,36,2.35]],"id":106596}],"tv":189087.06}],"ArrivalTime":1710508207150}
{"op":"mcm","id":2,"clk":"AOWYAQDEzgEAweMB","pt":1710508207212,"mc":[{"id":"1.226122413","rc":[{"batb":[[2,510,3.08]],"id":54370634},{"batl":[[2,70,8.09]],"id":49744721},{"batb":[[2,4.6,145.22]],"id":50466254},{"batb":[[0,220,3.85]],"id":66251581}]}],"ArrivalTime":1710508207218}
{"op":"mcm","id":2,"clk":"AOqYAQDMzgEAyOMB","pt":1710508207311,"mc":[{"id":"1.226122413","rc":[{"tv":17085.31,"trd":[[4.8,1026.17]],"ltp":4.8,"batl":[[0,4.8,45.38]],"id":41122648},{"tv":3230.01,"batb":[[0,23,31.46]],"trd":[[24,470.92],[23,258.95]],"batl":[[2,27,5.65],[1,26,12.25],[0,25,11.89]],"id":55632148},{"tv":134113.52,"batb":[[0,2.04,87.51]],"trd":[[2.04,3809.11]],"ltp":2.04,"id":51922},{"tv":26585.82,"batb":[[0,4.8,29.42]],"trd":[[4.8,2829.29]],"ltp":4.8,"id":50466254},{"tv":821.49,"batb":[[0,220,4.04]],"trd":[[240,3.96],[220,17.24]],"ltp":240,"batl":[[2,280,3.82],[1,260,1.17],[0,250,1.47]],"id":66251581}],"tv":189107.74}],"ArrivalTime":1710508207317}
{"op":"mcm","id":2,"clk":"APOYAQDbzgEAz+MB","pt":1710508207421,"mc":[{"id":"1.226122413","rc":[{"batl":[[1,4.9,49.45]],"id":41122648},{"tv":672.07,"trd":[[480,20.93]],"batl":[[0,510,1.91]],"id":41200638},{"tv":134114.56,"batb":[[0,2.04,86.99]],"trd":[[2.04,3810.15]],"id":51922},{"batb":[[2,4.6,93]],"id":50466254},{"tv":821.99,"batb":[[0,220,3.79]],"trd":[[240,4.46]],"id":66251581}],"tv":189110.94}],"ArrivalTime":1710508207427}
{"op":"mcm","id":2,"clk":"APqYAQDkzgEA1+MB","pt":1710508207515,"mc":[{"id":"1.226122413","rc":[{"batb":[],"batl":[[2,26,12.25],[1,25,14.94],[0,24,2.2]],"id":55632148},{"tv":134124.56,"batb":[[1,2.02,543.51],[0,2.04,81.99]],"trd":[[2.04,3820.15]],"batl":[[1,2.08,376.96]],"id":51922},{"tv":26589.82,"batb":[[1,4.7,211.56],[0,4.8,27.42]],"trd":[[4.8,2833.29]],"id":50466254}],"tv":189124.94}],"ArrivalTime":1710508207522}
{"op":"mcm","id":2,"clk":"AIOZAQDvzgEA4eMB","pt":1710508207615,"mc":[{"id":"1.226122413","rc":[{"tv":17098.61,"batb":[[0,4.7,46.55]],"trd":[[4.7,546.41]],"ltp":4.7,"batl":[[2,5,73.21]],"id":41122648},{"batb":[[2,4.6,145.22]],"batl":[[0,4.9,29.73]],"id":50466254},{"batb":[[2,210,7.06],[1,220,3.79],[0,230,1.04]],"id":66251581}],"tv":189138.24}],"ArrivalTime":1710508207621}
{"op":"mcm","id":2,"clk":"AIWZAQD0zgEA6eMB","pt":1710508207717,"mc":[{"id":"1.226122413","rc":[{"batl":[[2,600,1.94],[1,550,5.88]],"id":41200638},{"batb":[],"batl":[[1,2.08,370.78]],"id":51922}]}],"ArrivalTime":1710508207723}
{"op":"mcm","id":2,"clk":"AJGZAQCBzwEA8OMB","pt":1710508207822,"mc":[{"id":"1.226122413","rc":[{"batb":[[0,4.7,49.56]],"id":41122648},{"batb":[[1,22,23.16]],"id":55632148},{"batb":[[0,2.04,158.99]],"id":51922},{"batl":[[0,4.9,33.74]],"id":50466254},{"batb":[[2,30,21.98]],"id":106596}]}],"ArrivalTime":1710508207829}
{"op":"mcm","id":2,"clk":"AJiZAQCIzwEA+OMB","pt":1710508207920,"mc":[{"id":"1.226122413","rc":[{"batl":[[2,590,3.05]],"id":41200638}]}],"ArrivalTime":1710508207927}
{"op":"mcm","id":2,"clk":"AJ2ZAQCNzwEAheQB","pt":1710508208023,"mc":[{"id":"1.226122413","rc":[{"batb":[[2,21,125.06]],"id":55632148},{"batb":[[2,30,41.24]],"id":106596}]}],"ArrivalTime":1710508208030}
{"op":"mcm","id":2,"clk":"AKSZAQCczwEAkeQB","pt":1710508208138,"mc":[{"id":"1.226122413","rc":[{"batl":[[2,590,2.82]],"id":41200638},{"tv":134442.54,"batb":[[2,1.99,77.5],[1,2,268.77],[0,2.02,543.51]],"trd":[[2.04,4138.13]],"batl":[[2,2.08,370.78],[1,2.06,115.67],[0,2.04,41.01]],"id":51922},{"tv":26609.82,"batb":[[0,4.8,17.42]],"trd":[[4.8,2853.29]],"id":50466254}],"tv":189476.22}],"ArrivalTime":1710508208144}
{"op":"mcm","id":2,"clk":"AKaZAQCkzwEAmuQB","pt":1710508208236,"mc":[{"id":"1.226122413","rc":[{"batb":[[1,460,1.68]],"id":41200638},{"tv":134524.56,"batb":[[2,2,268.77],[1,2.02,523.12],[0,2.04,8.99]],"trd":[[2.04,4220.15]],"batl":[[2,2.1,525.5],[1,2.08,370.78],[0,2.06,115.67]],"id":51922}],"tv":189558.24}],"ArrivalTime":1710508208242}
{"op":"mcm","id":2,"clk":"ALKZAQCtzwEAqOQB","pt":1710508208351,"mc":[{"id":"1.226122413","rc":[{"batb":[[0,4.7,75.18]],"batl":[[0,4.8,33.38]],"id":41122648},{"batl":[[2,27,5.65],[1,26,12.25],[0,25,15.89]],"id":55632148},{"tv":134571.38,"batb":[[2,1.99,77.5],[1,2,268.77],[0,2.02,523.12]],"trd":[[2.04,4266.97]],"batl":[[2,2.08,370.78],[1,2.06,115.67],[0,2.04,23.25]],"id":51922},{"batl":[[0,60,20.27]],"id":49744721},{"batb":[[0,4.8,47.33]],"batl":[[0,4.9,32.56]],"id":50466254},{"batb":[[1,220,4.79]],"id":66251581}],"tv":189605.06}],"ArrivalTime":1710508208357}
{"op":"mcm","id":2,"clk":"ALiZAQC1zwEAuOQB","pt":1710508208398,"mc":[{"id":"1.226122413","rc":[{"tv":26629.82,"batb":[[0,4.8,37.33]],"trd":[[4.8,2873.29]],"id":50466254}],"tv":189625.06}],"ArrivalTime":1710508208404}
{"op":"mcm","id":2,"clk":"AL2ZAQC/zwEAwuQB","pt":1710508208551,"mc":[{"id":"1.226122413","rc":[{"tv":17120.39,"trd":[[4.8,1047.95]],"ltp":4.8,"batl":[[0,4.8,22.5]],"id":41122648},{"tv":3231.91,"batb":[[2,22,23.16],[1,23,31.46],[0,24,2.38]],"trd":[[24,472.82]],"batl":[[0,25,14.94]],"id":55632148},{"batb":[[1,2,289.36]],"batl":[[1,2.06,118.24]],"id":51922},{"tv":3242.4,"batb":[[0,55,20.35]],"trd":[[55,153.55]],"id":49744721},{"tv":26653.82,"batb":[[2,4.6,149.41],[1,4.7,191.56],[0,4.8,27.33]],"trd":[[4.9,1528.97],[4.8,2893.29]],"batl":[[0,4.9,30.56]],"id":50466254},{"tv":822.73,"batb":[[2,200,5.39],[1,210,7.06],[0,220,5.46]],"trd":[[230,28.71]],"ltp":230,"id":66251581}],"tv":189675.48}],"ArrivalTime":1710508208557}
{"op":"mcm","id":2,"clk":"AMOZAQDIzwEA1eQB","pt":1710508208721,"mc":[{"id":"1.226122413","rc":[{"tv":134769.38,"batb":[[0,2.02,424.12]],"trd":[[2.02,2356.69]],"ltp":2.02,"id":51922}],"tv":189873.48}],"ArrivalTime":1710508208727}
{"op":"mcm","id":2,"clk":"AMuZAQDMzwEA2+QB","pt":1710508208771,"mc":[{"id":"1.226122413","rc":[{"batb":[[1,4.6,91.24]],"batl":[],"id":41122648},{"tv":3233.91,"batb":[[0,24,1.38]],"trd":[[24,474.82]],"id":55632148},{"batb":[[2,1.99,171.37]],"id":51922},{"batb":[[0,55,24.73]],"id":49744721}],"tv":189875.48}],"ArrivalTime":1710508208777}
{"op":"mcm","id":2,"clk":"AM+ZAQDTzwEA5eQB","pt":1710508208818,"mc":[{"id":"1.226122413","rc":[{"tv":26673.82,"batb":[[0,4.8,29.84]],"trd":[[4.8,2913.29]],"id":50466254}],"tv":189895.48}],"ArrivalTime":1710508208824}
{"op":"mcm","id":2,"clk":"ANSZAQDizwEA8eQB","pt":1710508208933,"mc":[{"id":"1.226122413","rc":[{"tv":17220.4,"batb":[[0,4.7,39.53]],"trd":[[4.7,646.42]],"ltp":4.7,"batl":[],"id":41122648},{"batb":[[0,24,3.51]],"id":55632148},{"tv":134869.38,"batb":[[0,2.02,374.12]],"trd":[[2.02,2456.69]],"batl":[],"id":51922},{"batb":[[2,200,3.54]],"batl":[[2,280,1]],"id":66251581},{"batl":[[2,40,29.54]],"id":106596}],"tv":190095.49}],"ArrivalTime":1710508208939}
{"op":"mcm","id":2,"clk":"ANeZAQDqzwEA+OQB","pt":1710508209025,"mc":[{"id":"1.226122413","rc":[{"tv":17232.35,"batb":[[0,4.7,33.55]],"trd":[[4.7,658.37]],"batl":[[0,4.8,21.28]],"id":41122648},{"batb":[[0,2.02,352.77]],"batl":[],"id":51922}],"tv":190107.44}],"ArrivalTime":1710508209031}
{"op":"mcm","id":2,"clk":"AOCZAQDwzwEAgOUB","pt":1710508209084,"mc":[{"id":"1.226122413","marketDefinition":{"bspMarket":true,"turnInPlayEnabled":true,"persistenceEnabled":true,"marketBaseRate":5,"bettingType":"ODDS","status":"SUSPENDED","venue":"Fakenham","timezone":"Europe/London","regulators":["MR_INT"],"marketType":"WIN","numberOfWinners":1,"countryCode":"GB","inPlay":false,"betDelay":0,"numberOfActiveRunners":9,"eventId":"33106089","crossMatching":true,"runnersVoidable":false,"suspendTime":"2024-03-15T13:10:00Z","discountAllowed":true,"runners":[{"status":"ACTIVE","sortPriority":1,"id":51922,"adjustmentFactor":52.91},{"status":"ACTIVE","sortPriority":2,"id":50466254,"adjustmentFactor":22.828},{"status":"ACTIVE","sortPriority":3,"id":41122648,"adjustmentFactor":9.588},{"status":"ACTIVE","sortPriority":4,"id":49744721,"adjustmentFactor":4.794},{"status":"ACTIVE","sortPriority":5,"id":55632148,"adjustmentFactor":3.995},{"status":"ACTIVE","sortPriority":6,"id":106596,"adjustmentFactor":3.995},{"status":"ACTIVE","sortPriority":7,"id":66251581,"adjustmentFactor":0.959},{"status":"ACTIVE","sortPriority":8,"id":41200638,"adjustmentFactor":0.533},{"status":"ACTIVE","sortPriority":9,"id":54370634,"adjustmentFactor":0.399},{"status":"REMOVED","sortPriority":10,"removalDate":"2024-03-15T09:18:23Z","id":47855509,"adjustmentFactor":10.417}],"version":5797191169,"eventTypeId":"7","complete":true,"openDate":"2024-03-15T13:10:00Z","marketTime":"2024-03-15T13:10:00Z","bspReconciled":false}}],"ArrivalTime":1710508209090}
{"op":"mcm","id":2,"clk":"AICaAQCa0AEArOUB","pt":1710508209564,"mc":[{"id":"1.226122413","rc":[{"tv":570.94,"batb":[[2,400,4.07],[1,470,1.6],[0,550,1.29]],"trd":[[510,9.32],[500,1.08],[490,2.61],[570,2.59],[540,2.06],[530,18.8],[520,14.76]],"ltp":490,"id":54370634},{"tv":17845.07,"trd":[[5.4,247.97],[5.7,546.23],[5.2,153.12],[4.9,631.97],[5.3,378.99],[5.5,516.2],[5,389.95],[5.8,341.87],[5.1,166.61],[5.6,592.49],[4.8,1090.51]],"ltp":5.8,"batl":[[2,5.8,33.91],[1,5,46.6],[0,4.9,31.15]],"id":41122648},{"tv":687.45,"batb":[[2,410,1.13],[1,450,1.19],[0,470,1.29]],"trd":[[470,10.23],[460,5.4],[450,15.4]],"ltp":450,"id":41200638},{"tv":3296.29,"trd":[[29,220.99],[28,389.91],[27,405.83],[26,536.81],[25,713.67]],"ltp":29,"batl":[[2,29,17.52],[1,26,4.04],[0,25,1.27]],"id":55632148},{"tv":136731.08,"trd":[[2.08,3568.45],[2.1,2235.72],[2.12,496.35],[2.04,4313.47],[2.06,3863.57]],"ltp":2.12,"batl":[[2,2.1,187.98],[1,2.08,4.12],[0,2.06,38.88]],"id":51922},{"tv":3289.45,"trd":[[60,121.29],[75,8.16],[70,4.89],[65,12.88]],"ltp":75,"batl":[[2,75,2.14],[1,70,6.01],[0,60,9.65]],"id":49744721},{"tv":26771.39,"trd":[[4.9,1579.47],[5,1367.59]],"ltp":5,"batl":[[1,5,30.85],[0,4.9,5.31]],"id":50466254},{"tv":824.27,"batb":[[0,220,4.69]],"trd":[[230,30.05],[220,17.44]],"ltp":220,"id":66251581}],"tv":192823.14}],"ArrivalTime":1710508209571}
{"op":"mcm","id":2,"clk":"ALaaAQDi0AEA8uUB","pt":1710508210590,"mc":[{"id":"1.226122413","marketDefinition":{"bspMarket":true,"turnInPlayEnabled":true,"persistenceEnabled":true,"marketBaseRate":5,"bettingType":"ODDS","status":"SUSPENDED","venue":"Fakenham","timezone":"Europe/London","regulators":["MR_INT"],"marketType":"WIN","numberOfWinners":1,"countryCode":"GB","inPlay":false,"betDelay":0,"numberOfActiveRunners":9,"eventId":"33106089","crossMatching":true,"runnersVoidable":false,"suspendTime":"2024-03-15T13:10:00Z","discountAllowed":true,"runners":[{"status":"ACTIVE","sortPriority":1,"id":51922,"adjustmentFactor":52.91,"bsp":2.090092499238763},{"status":"ACTIVE","sortPriority":2,"id":50466254,"adjustmentFactor":22.828,"bsp":4.948233892181015},{"status":"ACTIVE","sortPriority":3,"id":41122648,"adjustmentFactor":9.588,"bsp":5.3011531434967765},{"status":"ACTIVE","sortPriority":4,"id":49744721,"adjustmentFactor":4.794,"bsp":65},{"status":"ACTIVE","sortPriority":5,"id":55632148,"adjustmentFactor":3.995,"bsp":26},{"status":"ACTIVE","sortPriority":6,"id":106596,"adjustmentFactor":3.995,"bsp":35.04635245418428},{"status":"ACTIVE","sortPriority":7,"id":66251581,"adjustmentFactor":0.959,"bsp":228.70886223447974},{"status":"ACTIVE","sortPriority":8,"id":41200638,"adjustmentFactor":0.533,"bsp":457.3906867427438},{"status":"ACTIVE","sortPriority":9,"id":54370634,"adjustmentFactor":0.399,"bsp":524.3944754604236},{"status":"REMOVED","sortPriority":10,"removalDate":"2024-03-15T09:18:23Z","id":47855509,"adjustmentFactor":10.417}],"version":5797191197,"eventTypeId":"7","complete":true,"openDate":"2024-03-15T13:10:00Z","marketTime":"2024-03-15T13:10:00Z","bspReconciled":false},"rc":[{"batb":[[2,380,2.42],[1,400,2.41],[0,470,1.6]],"batl":[],"id":54370634},{"batb":[[2,4.5,122.64],[1,4.6,42.21]],"batl":[[2,6,39.25],[1,5.9,11.65],[0,5.8,33.73]],"id":41122648},{"batb":[[2,370,2.46],[1,410,1.13],[0,450,1.19]],"batl":[],"id":41200638},{"batb":[[2,22,17.06],[1,23,16.45]],"batl":[[2,32,23.88],[1,30,1.01],[0,29,1.29]],"id":55632148},{"batb":[],"batl":[[2,2.16,2.57],[1,2.14,22.57],[0,2.12,435.45]],"id":51922},{"batb":[[1,50,24.86],[0,55,12.32]],"batl":[[2,85,1.21],[1,80,3.03],[0,75,1.74]],"id":49744721},{"batb":[[2,4.6,97.19],[1,4.7,131.14]],"batl":[[2,5.2,21.75],[1,5.1,45.27],[0,5,30.85]],"id":50466254},{"batb":[[1,210,6.77],[0,220,2.47]],"batl":[],"id":66251581},{"batb":[[2,30,18.09],[1,32,19.77],[0,34,8.71]],"batl":[[2,40,19.91],[1,38,10.85]],"id":106596}]}],"ArrivalTime":1710508210596}
{"op":"mcm","id":2,"clk":"ALmaAQDn0AEA9+UB","pt":1710508210884,"mc":[{"id":"1.226122413","marketDefinition":{"bspMarket":true,"turnInPlayEnabled":true,"persistenceEnabled":true,"marketBaseRate":5,"bettingType":"ODDS","status":"SUSPENDED","venue":"Fakenham","timezone":"Europe/London","regulators":["MR_INT"],"marketType":"WIN","numberOfWinners":1,"countryCode":"GB","inPlay":false,"betDelay":0,"numberOfActiveRunners":9,"eventId":"33106089","crossMatching":true,"runnersVoidable":false,"suspendTime":"2024-03-15T13:10:00Z","discountAllowed":true,"runners":[{"status":"ACTIVE","sortPriority":1,"id":51922,"adjustmentFactor":52.91,"bsp":2.090092499238763},{"status":"ACTIVE","sortPriority":2,"id":50466254,"adjustmentFactor":22.828,"bsp":4.948233892181015},{"status":"ACTIVE","sortPriority":3,"id":41122648,"adjustmentFactor":9.588,"bsp":5.3011531434967765},{"status":"ACTIVE","sortPriority":4,"id":49744721,"adjustmentFactor":4.794,"bsp":65},{"status":"ACTIVE","sortPriority":5,"id":55632148,"adjustmentFactor":3.995,"bsp":26},{"status":"ACTIVE","sortPriority":6,"id":106596,"adjustmentFactor":3.995,"bsp":35.04635245418428},{"status":"ACTIVE","sortPriority":7,"id":66251581,"adjustmentFactor":0.959,"bsp":228.70886223447974},{"status":"ACTIVE","sortPriority":8,"id":41200638,"adjustmentFactor":0.533,"bsp":457.3906867427438},{"status":"ACTIVE","sortPriority":9,"id":54370634,"adjustmentFactor":0.399,"bsp":524.3944754604236},{"status":"REMOVED","sortPriority":10,"removalDate":"2024-03-15T09:18:23Z","id":47855509,"adjustmentFactor":10.417}],"version":5797191231,"eventTypeId":"7","complete":true,"openDate":"2024-03-15T13:10:00Z","marketTime":"2024-03-15T13:10:00Z","bspReconciled":true},"rc":[]}],"ArrivalTime":1710508210890}
{"op":"mcm","id":2,"clk":"AL6aAQDu0AEA/eUB","pt":1710508210905,"mc":[{"id":"1.226122413","marketDefinition":{"bspMarket":true,"turnInPlayEnabled":true,"persistenceEnabled":true,"marketBaseRate":5,"bettingType":"ODDS","status":"OPEN","venue":"Fakenham","timezone":"Europe/London","regulators":["MR_INT"],"marketType":"WIN","numberOfWinners":1,"countryCode":"GB","inPlay":true,"betDelay":1,"numberOfActiveRunners":9,"eventId":"33106089","crossMatching":true,"runnersVoidable":false,"suspendTime":"2024-03-15T13:10:00Z","discountAllowed":true,"runners":[{"status":"ACTIVE","sortPriority":1,"id":51922,"adjustmentFactor":52.91,"bsp":2.090092499238763},{"status":"ACTIVE","sortPriority":2,"id":50466254,"adjustmentFactor":22.828,"bsp":4.948233892181015},{"status":"ACTIVE","sortPriority":3,"id":41122648,"adjustmentFactor":9.588,"bsp":5.3011531434967765},{"status":"ACTIVE","sortPriority":4,"id":49744721,"adjustmentFactor":4.794,"bsp":65},{"status":"ACTIVE","sortPriority":5,"id":55632148,"adjustmentFactor":3.995,"bsp":26},{"status":"ACTIVE","sortPriority":6,"id":106596,"adjustmentFactor":3.995,"bsp":35.04635245418428},{"status":"ACTIVE","sortPriority":7,"id":66251581,"adjustmentFactor":0.959,"bsp":228.70886223447974},{"status":"ACTIVE","sortPriority":8,"id":41200638,"adjustmentFactor":0.533,"bsp":457.3906867427438},{"status":"ACTIVE","sortPriority":9,"id":54370634,"adjustmentFactor":0.399,"bsp":524.3944754604236},{"status":"REMOVED","sortPriority":10,"removalDate":"2024-03-15T09:18:23Z","id":47855509,"adjustmentFactor":10.417}],"version":5797191241,"eventTypeId":"7","complete":true,"openDate":"2024-03-15T13:10:00Z","marketTime":"2024-03-15T13:10:00Z","bspReconciled":true}}],"ArrivalTime":1710508210911}
{"op":"mcm","id":2,"clk":"ANKaAQCE0QEAlOYB","pt":1710508211190,"mc":[{"id":"1.226122413","rc":[{"batb":[[2,250,3.37],[1,400,2.29],[0,470,1.36]],"batl":[[2,0,0],[1,0,0],[0,790,2.82]],"id":54370634},{"batb":[[2,4.2,9.43],[1,4.3,3.83],[0,4.5,50]],"batl":[[2,8.6,4.83],[1,7.2,1.4],[0,6.4,1.29]],"id":41122648},{"batb":[[2,190,6],[1,200,1],[0,220,6.43]],"batl":[[2,0,0],[1,590,2.82]],"id":41200638},{"batb":[[2,19.5,2.59],[1,21,24],[0,24,2.13]],"batl":[[2,34,2],[1,32,4.13]],"id":55632148},{"batb":[[2,1.99,12.58],[1,2,87.02],[0,2.02,9]],"batl":[[2,2.2,24],[1,2.18,29.33],[0,2.14,20]],"id":51922},{"batb":[[2,46,10],[1,50,4.97],[0,55,3.7]],"batl":[[2,960,0.22],[1,800,1.29],[0,370,1.05]],"id":49744721},{"batb":[[2,4.3,4],[1,4.5,10.22],[0,4.6,10.22]],"batl":[[2,5.5,11.39],[1,5.3,1.56],[0,5.1,1]],"id":50466254},{"batb":[[2,100,1.32],[1,110,1.67],[0,160,30.19]],"batl":[[2,0,0],[1,990,0.29],[0,300,3.07]],"id":66251581},{"batb":[[2,23,2.54],[1,26,3.4],[0,30,9.07]],"batl":[[2,80,1.62],[1,50,3.85],[0,44,3.97]],"id":106596}]}],"ArrivalTime":1710508211197}
{"op":"mcm","id":2,"clk":"AJybAQDu0QEA/eYB","pt":1710508211847,"mc":[{"id":"1.226122413","rc":[{"batb":[[2,4.5,10.22],[1,4.6,10.22],[0,4.9,2]],"id":50466254}]}],"ArrivalTime":1710508211853}
{"op":"mcm","id":2,"clk":"AKmbAQD+0QEAmOcB","pt":1710508211998,"mc":[{"id":"1.226122413","rc":[{"batl":[[2,1000,0.52]],"id":49744721},{"batl":[[0,44,4.28]],"id":106596}]}],"ArrivalTime":1710508212004}
{"op":"mcm","id":2,"clk":"ALObAQCD0gEAp+cB","pt":1710508212142,"mc":[{"id":"1.226122413","rc":[{"batl":[[0,790,3.02]],"id":54370634},{"batl":[[2,7.2,1.4],[1,6.4,1.29],[0,4.6,88]],"id":41122648},{"batb":[[2,21,24],[1,24,2.13],[0,25,1]],"batl":[],"id":55632148},{"batl":[[1,800,1.38],[0,250,1.11]],"id":49744721},{"batl":[[2,80,1.92]],"id":106596}]}],"ArrivalTime":1710508212148}
{"op":"mcm","id":2,"clk":"ALqbAQCM0gEAsOcB","pt":1710508212202,"mc":[{"id":"1.226122413","rc":[{"batl":[[0,720,0.2]],"id":54370634},{"batl":[[2,2.18,29.33],[1,2.14,20],[0,2.04,15]],"id":51922},{"batl":[[0,44,3.97]],"id":106596}]}],"ArrivalTime":1710508212209}
{"op":"mcm","id":2,"clk":"AMGbAQCW0gEAvucB","pt":1710508212310,"mc":[{"id":"1.226122413","rc":[{"batl":[[2,6.4,1.19],[1,6,2.1]],"id":41122648},{"batb":[[2,200,1],[1,220,6],[0,250,3.57]],"batl":[[2,970,0.12]],"id":41200638},{"batl":[[2,1000,1.2],[1,700,1]],"id":49744721},{"batl":[[2,5.3,1.56],[1,5.1,1],[0,5,2]],"id":50466254},{"batl":[[1,990,0.41]],"id":66251581}]}],"ArrivalTime":1710508212316}
{"op":"mcm","id":2,"clk":"AMmbAQCd0gEAx+cB","pt":1710508212414,"mc":[{"id":"1.226122413","rc":[{"tv":3300.29,"batb":[[2,19.5,2.59],[1,21,24.96],[0,24,1.14]],"trd":[[25,715.67],[24,476.82]],"ltp":24,"id":55632148},{"tv":136771.08,"batb":[[2,1.97,12.62],[1,1.99,12.58],[0,2,76.02]],"trd":[[2.02,2474.69],[2,2029.15]],"ltp":2,"id":51922}],"tv":192867.14}],"ArrivalTime":1710508212421}
{"op":"mcm","id":2,"clk":"ANabAQCl0gEA1ecB","pt":1710508212526,"mc":[{"id":"1.226122413","rc":[{"tv":570.96,"trd":[[720,11.94]],"ltp":720,"batl":[[0,720,0.68]],"id":54370634},{"tv":17848.27,"trd":[[4.6,163]],"ltp":4.6,"batl":[[2,6,2.1],[1,5.3,3],[0,4.6,84.8]],"id":41122648},{"tv":687.47,"trd":[[510,2.58]],"ltp":510,"batl":[[0,510,2.39]],"id":41200638},{"tv":3300.86,"trd":[[26,537.38]],"ltp":26,"batl":[[2,32,4.13],[1,29,1.29],[0,26,1.43]],"id":55632148},{"tv":136778.29,"batb":[[0,2,25.52]],"trd":[[2.04,4320.68]],"ltp":2.04,"batl":[[0,2.04,12.79]],"id":51922},{"tv":3289.65,"trd":[[75,8.36]],"batl":[[2,700,1],[1,250,1.11],[0,65,1.3]],"id":49744721},{"tv":26778.39,"batb":[[2,4.3,4],[1,4.5,10.22],[0,4.6,10.22]],"trd":[[4.9,1586.47]],"ltp":4.9,"id":50466254},{"tv":824.33,"trd":[[250,0.06]],"ltp":250,"batl":[[0,300,3.51]],"id":66251581},{"tv":2807.63,"trd":[[34,175.43]],"ltp":34,"batl":[[2,50,3.85],[1,44,3.97],[0,34,1.57]],"id":106596}],"tv":192885.85}],"ArrivalTime":1710508212533}
{"op":"mcm","id":2,"clk":"ANqbAQCn0gEA3ecB","pt":1710508212623,"mc":[{"id":"1.226122413","rc":[{"batl":[[2,360,1.08],[1,130,2.7]],"id":49744721},{"batl":[[2,990,0.41],[1,300,2.82],[0,290,3.18]],"id":66251581}]}],"ArrivalTime":1710508212629}
{"op":"mcm","id":2,"clk":"AOGbAQCu0gEA5+cB","pt":1710508212729,"mc":[{"id":"1.226122413","rc":[{"batl":[[2,360,3.39]],"id":49744721}]}],"ArrivalTime":1710508212735}
{"op":"mcm","id":2,"clk":"AOibAQC30gEA8+cB","pt":1710508212837,"mc":[{"id":"1.226122413","rc":[{"batl":[[2,240,3.21]],"id":49744721},{"batl":[[2,44,3.89],[1,42,2.64]],"id":106596}]}],"ArrivalTime":1710508212844}
{"op":"mcm","id":2,"clk":"APGbAQC80gEA/ecB","pt":1710508212940,"mc":[{"id":"1.226122413","rc":[{"tv":17848.38,"trd":[[4.6,163.11]],"batl":[[0,4.6,84.69]],"id":41122648},{"tv":3300.88,"trd":[[26,537.4]],"batl":[[0,26,1.41]],"id":55632148},{"tv":136798.53,"trd":[[2.04,4340.92]],"batl":[[2,2.14,20],[1,2.06,5],[0,2.04,2.55]],"id":51922},{"tv":3289.66,"trd":[[65,12.89]],"ltp":65,"batl":[[0,65,1.29]],"id":49744721},{"tv":26778.49,"trd":[[4.9,1586.57]],"id":50466254},{"batl":[[0,290,5.74]],"id":66251581},{"tv":2807.64,"batb":[[2,24,2.51]],"trd":[[34,175.44]],"batl":[[0,34,1.56]],"id":106596}],"tv":192906.34}],"ArrivalTime":1710508212946}
{"op":"mcm","id":2,"clk":"APmbAQDJ0gEAhugB","pt":1710508213042,"mc":[{"id":"1.226122413","rc":[{"tv":570.99,"trd":[[520,14.79]],"ltp":520,"batl":[[0,720,0.65]],"id":54370634},{"tv":17851.66,"trd":[[4.6,166.39]],"batl":[[0,4.6,81.41]],"id":41122648},{"tv":687.5,"trd":[[450,15.43]],"ltp":450,"batl":[[2,590,2.82],[1,510,1.89],[0,500,5.34]],"id":41200638},{"tv":3301.46,"batb":[[2,21,24],[1,23,3.1]],"trd":[[26,537.98]],"batl":[[2,34,2],[1,32,4.13],[0,29,2.12]],"id":55632148},{"tv":136810.41,"batb":[[0,2,25.32]],"trd":[[2.04,4344.92],[2.02,2482.17],[2,2029.55]],"ltp":2,"batl":[[2,2.18,29.33],[1,2.14,20],[0,2.06,5.55]],"id":51922},{"tv":3289.89,"trd":[[65,13.12]],"batl":[[0,65,1.06]],"id":49744721},{"tv":26781.49,"trd":[[5,1369.59],[5.1,980.63]],"ltp":5.1,"batl":[[2,5.8,3.56],[1,5.5,11.39],[0,5.3,1.56]],"id":50466254},{"tv":824.4,"trd":[[220,17.51]],"ltp":220,"batl":[[0,290,5.67]],"id":66251581},{"tv":2808.08,"trd":[[34,175.88]],"batl":[[0,34,1.12]],"id":106596}],"tv":192925.88}],"ArrivalTime":1710508213048}
{"op":"mcm","id":2,"clk":"AICcAQDP0gEAj+gB","pt":1710508213142,"mc":[{"id":"1.226122413","rc":[{"tv":136825.79,"batb":[[0,2,17.63]],"trd":[[2,2044.93]],"id":51922},{"tv":2810.48,"batb":[[2,26,3.4],[1,30,9.07],[0,36,23.8]],"trd":[[36,145.41],[34,178.12]],"ltp":36,"batl":[[2,50,3.85],[1,44,3.89],[0,42,2.56]],"id":106596}],"tv":192943.66}],"ArrivalTime":1710508213148}
{"op":"mcm","id":2,"clk":"AIicAQDV0gEAl+gB","pt":1710508213201,"mc":[{"id":"1.226122413","rc":[{"batb":[],"batl":[[0,780,3.21]],"id":54370634},{"batb":[[2,4.5,10.22],[1,4.6,14.4],[0,5.1,33]],"id":50466254},{"batb":[[2,100,3.38]],"id":66251581}]}],"ArrivalTime":1710508213207}
{"op":"mcm","id":2,"clk":"AJGcAQDd0gEAoegB","pt":1710508213308,"mc":[{"id":"1.226122413","rc":[{"batl":[[0,780,3.63]],"id":54370634},{"batl":[[2,510,1.89],[1,500,5.34],[0,430,2.13]],"id":41200638},{"batb":[[2,22,2.56],[0,24,2.06]],"batl":[[2,32,4],[1,30,2.13],[0,29,4.68]],"id":55632148},{"batb":[[0,2,18.63]],"batl":[[2,2.14,20],[1,2.06,5.55],[0,2.02,8.86]],"id":51922},{"batb":[[2,50,4.97],[1,55,3.7],[0,60,2.56]],"batl":[],"id":49744721},{"batl":[[2,990,0.29]],"id":66251581},{"batb":[[2,30,8.37],[1,32,1.7]],"id":106596}]}],"ArrivalTime":1710508213314}
{"op":"mcm","id":2,"clk":"AJScAQDj0gEAq+gB","pt":1710508213397,"mc":[{"id":"1.226122413","rc":[{"tv":17916.52,"trd":[[4.6,231.25]],"batl":[[0,4.6,48.98]],"id":41122648},{"tv":3303.12,"batb":[[0,24,5.57]],"trd":[[26,539.64]],"batl":[[0,29,3.85]],"id":55632148}],"tv":193010.18}],"ArrivalTime":1710508213403}
{"op":"mcm","id":2,"clk":"AJ2cAQD10gEAtOgB","pt":1710508213502,"mc":[{"id":"1.226122413","rc":[{"tv":3305.11,"batb":[[2,23,3.1],[1,24,5.49],[0,25,2.56]],"trd":[[26,539.69],[24,478.76]],"ltp":24,"id":55632148},{"tv":136856.54,"batb":[[0,2,2.27]],"trd":[[2,2075.68]],"id":51922},{"batl":[[0,290,6.01]],"id":66251581}],"tv":193042.92}],"ArrivalTime":1710508213509}
{"op":"mcm","id":2,"clk":"AKOcAQD+0gEAvOgB","pt":1710508213609,"mc":[{"id":"1.226122413","rc":[{"tv":17919.66,"trd":[[4.6,234.39]],"batl":[[0,4.6,47.41]],"id":41122648},{"batl":[[2,510,2.09]],"id":41200638},{"tv":136876.88,"batb":[[2,1.99,12.58],[1,2,2.27],[0,2.04,41.09]],"trd":[[2.04,4346.02],[2.06,3865.09],[2.02,2499.89]],"ltp":2.06,"batl":[[2,2.18,29.33],[1,2.14,20],[0,2.06,4.24]],"id":51922}],"tv":193066.4}],"ArrivalTime":1710508213615}
{"op":"mcm","id":2,"clk":"AKicAQCI0wEAyOgB","pt":1710508213713,"mc":[{"id":"1.226122413","rc":[{"batb":[[0,470,1.39]],"id":54370634},{"tv":17923.66,"trd":[[4.6,238.39]],"batl":[[0,4.6,45.41]],"id":41122648},{"batl":[[1,500,3.03]],"id":41200638},{"batb":[[1,24,6.41]],"batl":[[2,30,2.13],[1,29,3.85],[0,26,2.56]],"id":55632148},{"tv":136898.52,"batb":[[2,2,2.25],[1,2.02,2],[0,2.04,30.27]],"trd":[[2.04,4367.66]],"ltp":2.04,"id":51922},{"batl":[[2,220,1.35]],"id":49744721},{"batb":[[2,4.6,14.4],[1,4.7,2]],"id":50466254},{"batl":[[2,300,2.82],[1,290,5.58],[0,220,1.43]],"id":66251581}],"tv":193092.04}],"ArrivalTime":1710508213722}
{"op":"mcm","id":2,"clk":"ALCcAQCP0wEA1OgB","pt":1710508213814,"mc":[{"id":"1.226122413","rc":[{"batl":[[0,780,3.97]],"id":54370634},{"tv":17927.38,"trd":[[4.6,242.11]],"batl":[[0,4.6,43.55]],"id":41122648},{"batl":[[2,590,2.82],[1,510,2.9]],"id":41200638},{"batb":[[0,25,3.45]],"batl":[[2,30,4.26]],"id":55632148},{"tv":136937.9,"batb":[[0,2.04,10.58]],"trd":[[2.04,4407.04]],"id":51922},{"tv":26797.49,"batb":[[0,5.1,25]],"trd":[[5.1,996.63]],"id":50466254},{"batl":[[2,990,0.29]],"id":66251581},{"batb":[[2,32,1.7],[1,34,2.13]],"batl":[[0,42,2.98]],"id":106596}],"tv":193151.14}],"ArrivalTime":1710508213820}
{"op":"mcm","id":2,"clk":"ALycAQCe0wEA3+gB","pt":1710508213926,"mc":[{"id":"1.226122413","rc":[{"tv":136968.67,"batb":[[2,1.96,5.2],[1,1.97,12.62],[0,1.99,12.02]],"trd":[[2.04,4428.19],[2.02,2503.89],[1.99,387.38],[2,2080.18]],"ltp":1.99,"id":51922}],"tv":193181.91}],"ArrivalTime":1710508213932}
{"op":"mcm","id":2,"clk":"AMWcAQCh0wEA6OgB","pt":1710508214017,"mc":[{"id":"1.226122413","rc":[{"tv":26817.49,"batb":[[0,5.1,15]],"trd":[[5.1,1016.63]],"id":50466254},{"batb":[[0,36,25.93]],"id":106596}],"tv":193201.91}],"ArrivalTime":1710508214023}
{"op":"mcm","id":2,"clk":"ANScAQCu0wEA9ugB","pt":1710508214131,"mc":[{"id":"1.226122413","rc":[{"tv":571.51,"trd":[[520,15.31]],"batl":[[0,780,3.71]],"id":54370634},{"batb":[[0,25,4.34]],"id":55632148},{"batl":[[2,2.14,20],[1,2.06,4.24],[0,2,15.09]],"id":51922},{"tv":26844.37,"batb":[[2,4.7,2],[1,5,1.26],[0,5.1,1.56]],"trd":[[5.1,1043.51]],"id":50466254},{"batl":[[2,290,5.39],[1,280,2.5]],"id":66251581}],"tv":193229.31}],"ArrivalTime":1710508214138}
{"op":"mcm","id":2,"clk":"ANecAQC90wEA/ugB","pt":1710508214230,"mc":[{"id":"1.226122413","rc":[{"tv":137014.21,"batb":[[2,1.97,12.62],[1,1.99,10.47],[0,2.04,6.82]],"trd":[[1.99,390.48],[2,2122.62]],"batl":[[1,2.1,5],[0,2.06,4.24]],"id":51922},{"batb":[[2,4.6,14.4],[1,4.7,2]],"id":50466254},{"batl":[[2,290,2.83]],"id":66251581},{"batb":[[2,34,2.13],[1,36,25.93],[0,38,2.13]],"id":106596}],"tv":193274.85}],"ArrivalTime":1710508214236}
{"op":"mcm","id":2,"clk":"ANycAQDC0wEAi+kB","pt":1710508214345,"mc":[{"id":"1.226122413","rc":[{"batl":[[0,4.6,46.55]],"id":41122648},{"batb":[[0,25,5.23]],"id":55632148},{"tv":137029.58,"batb":[[2,1.96,5.2],[1,1.97,12.62],[0,1.99,9.6]],"trd":[[2.04,4441.83],[1.99,392.21]],"id":51922},{"batb":[[1,4.7,6],[0,5.1,4]],"id":50466254}],"tv":193290.22}],"ArrivalTime":1710508214351}
{"op":"mcm","id":2,"clk":"AOWcAQDQ0wEAkekB","pt":1710508214436,"mc":[{"id":"1.226122413","rc":[{"tv":571.53,"batb":[[0,470,1.37]],"trd":[[510,9.34]],"ltp":510,"id":54370634},{"tv":17954.84,"batb":[[0,4.5,35.35]],"trd":[[4.5,27.46]],"ltp":4.5,"id":41122648},{"tv":687.53,"batb":[[0,250,3.54]],"trd":[[270,12.15]],"ltp":270,"id":41200638},{"tv":3305.44,"batb":[[0,25,4.89]],"trd":[[25,716]],"ltp":25,"id":55632148},{"tv":137062.95,"batb":[[0,1.99,1.91]],"trd":[[2.06,3877.58],[1.99,407.59],[2,2128.12]],"ltp":2.06,"batl":[[2,2.18,29.33],[1,2.14,20],[0,2.1,5]],"id":51922},{"tv":3290.02,"batb":[[0,60,2.43]],"trd":[[60,121.42]],"ltp":60,"batl":[[2,130,2.49],[1,110,2.21]],"id":49744721},{"tv":26845.99,"batb":[[0,5.1,2.38]],"trd":[[5.1,1045.13]],"id":50466254},{"tv":824.45,"batb":[[0,160,30.14]],"trd":[[160,30.87]],"ltp":160,"batl":[[2,290,3.25]],"id":66251581},{"tv":2810.7,"batb":[[0,38,1.92]],"trd":[[38,117.46]],"ltp":38,"id":106596}],"tv":193353.45}],"ArrivalTime":1710508214442}
{"op":"mcm","id":2,"clk":"AOacAQDZ0wEAmukB","pt":1710508214541,"mc":[{"id":"1.226122413","rc":[{"batl":[[2,510,2.09],[1,500,1.23]],"id":41200638},{"batb":[[2,1.97,12.62],[1,1.99,1.91],[0,2,3.03]],"id":51922},{"tv":26850.75,"batb":[[2,4.5,10.22],[1,4.6,14.4],[0,4.7,4]],"trd":[[5.1,1049.89]],"batl":[[2,5.5,11.39],[1,5.3,1.56],[0,4.8,10.78]],"id":50466254},{"batl":[[1,280,3.99]],"id":66251581}],"tv":193358.21}],"ArrivalTime":1710508214547}
{"op":"mcm","id":2,"clk":"APGcAQDl0wEAoekB","pt":1710508214643,"mc":[{"id":"1.226122413","rc":[{"tv":571.57,"batb":[[2,380,1.34]],"trd":[[520,15.35]],"ltp":520,"batl":[[0,780,3.67]],"id":54370634},{"tv":17963.79,"trd":[[4.6,251.06]],"ltp":4.6,"batl":[[0,4.6,39.6]],"id":41122648},{"tv":687.58,"trd":[[430,2.73]],"ltp":430,"batl":[[2,590,3.02],[1,500,2.72],[0,430,2.08]],"id":41200638},{"tv":3311.44,"batb":[[0,25,2.33]],"trd":[[26,540.57],[25,721.12]],"batl":[[0,26,1.68]],"id":55632148},{"tv":137074.12,"trd":[[2.04,4453]],"ltp":2.04,"id":51922},{"tv":3290.37,"trd":[[65,13.47]],"ltp":65,"batl":[[2,220,1.35],[1,130,3.34],[0,110,2.92]],"id":49744721},{"tv":26855.5,"trd":[[4.8,2918.04]],"ltp":4.8,"batl":[[0,4.8,6.03]],"id":50466254},{"tv":824.55,"trd":[[220,17.61]],"ltp":220,"batl":[[0,220,1.33]],"id":66251581},{"tv":2811.25,"trd":[[42,0.55]],"ltp":42,"batl":[[0,42,2.43]],"id":106596}],"tv":193390.17}],"ArrivalTime":1710508214649}
{"op":"mcm","id":2,"clk":"APqcAQDs0wEAqekB","pt":1710508214749,"mc":[{"id":"1.226122413","rc":[{"tv":571.66,"trd":[[520,15.44]],"batl":[[1,780,3.5],[0,710,1.57]],"id":54370634},{"tv":18133.47,"batb":[[2,3.2,1],[1,3.4,10.86],[0,3.7,2]],"trd":[[3.75,10.05],[4.2,23.24],[3.95,7.44],[4.6,251.07],[3.85,8.22],[4.3,10.1],[4.5,98.16],[4,46]],"ltp":3.75,"batl":[[2,5.3,3],[1,4.6,39.59],[0,3.75,1.06]],"id":41122648},{"tv":687.68,"trd":[[430,2.83]],"batl":[[2,500,2.25],[1,490,1.32],[0,430,1.98]],"id":41200638},{"tv":3313.12,"batb":[[0,25,3.22]],"trd":[[26,542.25]],"ltp":26,"batl":[[2,32,4],[1,30,4.26],[0,29,4.59]],"id":55632148},{"tv":137102.65,"batb":[[0,2,4.69]],"trd":[[2.1,2240.72],[2.14,150.51],[2.04,4453.03],[2.06,3885.52]],"ltp":2.14,"batl":[[2,2.2,24],[1,2.18,29.33],[0,2.14,4.44]],"id":51922},{"tv":3291.04,"trd":[[65,14.14]],"batl":[[0,110,2.25]],"id":49744721},{"tv":26864.3,"trd":[[5.3,24.02],[5.5,1.21],[4.8,2924.07]],"ltp":5.5,"batl":[[2,7,1.8],[1,5.8,3.56],[0,5.5,10.18]],"id":50466254},{"tv":824.75,"trd":[[220,17.81]],"batl":[[0,220,1.13]],"id":66251581},{"tv":2812.29,"trd":[[42,1.59]],"batl":[[0,42,1.39]],"id":106596}],"tv":193600.96}],"ArrivalTime":1710508214755}
{"op":"mcm","id":2,"clk":"AISdAQD00wEAsekB","pt":1710508214859,"mc":[{"id":"1.226122413","rc":[{"tv":571.67,"trd":[[520,15.45]],"batl":[[0,710,1.56]],"id":54370634},{"tv":18134.65,"trd":[[3.75,11.11],[4.6,251.19]],"ltp":4.6,"batl":[[2,6,2.1],[1,5.3,3],[0,4.6,39.47]],"id":41122648},{"tv":687.69,"batb":[[1,220,6.08]],"trd":[[430,2.84]],"batl":[[0,430,2.82]],"id":41200638},{"tv":3313.28,"trd":[[29,221.15]],"ltp":29,"batl":[[0,29,4.43]],"id":55632148},{"tv":137120.45,"batb":[[2,1.96,5.2],[1,1.97,12.62],[0,1.99,1.91]],"trd":[[2.08,3572.45],[2.1,2241.38],[2.12,497.62],[2,2139.99]],"ltp":2,"batl":[[2,2.18,29.33],[1,2.14,4.44],[0,2.12,11.98]],"id":51922},{"tv":3291.11,"trd":[[85,0.03],[65,14.18]],"ltp":85,"batl":[[2,130,2.49],[1,120,2.98],[0,110,2.19]],"id":49744721},{"tv":26865.13,"trd":[[5.5,1.93],[4.8,2924.18]],"ltp":4.8,"batl":[[2,5.8,3.56],[1,5.5,9.46],[0,4.8,13.05]],"id":50466254},{"tv":824.77,"trd":[[220,17.83]],"batl":[[1,280,1.68],[0,220,1.11]],"id":66251581},{"tv":2812.39,"trd":[[42,1.69]],"batl":[[0,42,1.29]],"id":106596}],"tv":193621.14}],"ArrivalTime":1710508214866}
{"op":"mcm","id":2,"clk":"AIadAQD80wEAvekB","pt":1710508214898,"mc":[{"id":"1.226122413","rc":[{"tv":18138.65,"trd":[[4.6,255.19]],"batl":[[0,4.6,37.47]],"id":41122648},{"batl":[[2,490,1.32],[1,430,1.97],[0,420,2.98]],"id":41200638},{"batl":[[2,2.14,4.44],[1,2.12,11.98],[0,2.04,1.5]],"id":51922},{"batb":[[1,36,23.8]],"id":106596}],"tv":193625.14}],"ArrivalTime":1710508214904}
{"op":"mcm","id":2,"clk":"AI+dAQCC1AEAxekB","pt":1710508215007,"mc":[{"id":"1.226122413","rc":[{"tv":18141.87,"trd":[[4.6,258.41]],"batl":[[0,4.6,35.85]],"id":41122648},{"tv":137123.49,"batb":[[2,1.97,12.62],[1,1.99,1.91],[0,2.04,48.5]],"trd":[[2.04,4456.03],[2,2140.03]],"ltp":2.04,"batl":[[2,2.18,29.33],[1,2.14,4.44],[0,2.12,11.98]],"id":51922},{"tv":26867.21,"trd":[[4.8,2926.26]],"batl":[[0,4.8,12]],"id":50466254}],"tv":193633.48}],"ArrivalTime":1710508215013}
{"op":"mcm","id":2,"clk":"AJidAQCT1AEAz+kB","pt":1710508215127,"mc":[{"id":"1.226122413","rc":[{"tv":137142.86,"batb":[[0,2.04,39.59]],"trd":[[2.04,4475.4]],"id":51922},{"batb":[[1,4.6,14.94]],"batl":[[2,5.5,9.46],[1,5.1,3.12]],"id":50466254}],"tv":193652.85}],"ArrivalTime":1710508215134}
{"op":"mcm","id":2,"clk":"AJ6dAQCd1AEA2ekB","pt":1710508215215,"mc":[{"id":"1.226122413","rc":[{"batl":[[0,420,5.29]],"id":41200638},{"tv":137144.86,"batb":[[2,1.98,33],[0,2.04,38.59]],"trd":[[2.04,4477.4]],"id":51922},{"batb":[[0,4.7,2]],"batl":[[2,5.8,3.56],[1,5.5,9.46]],"id":50466254},{"batb":[[2,32,1.7]],"id":106596}],"tv":193654.85}],"ArrivalTime":1710508215221}
{"op":"mcm","id":2,"clk":"AKidAQCo1AEA5OkB","pt":1710508215315,"mc":[{"id":"1.226122413","rc":[{"tv":18147.05,"trd":[[4.6,263.59]],"batl":[[0,4.6,33.77]],"id":41122648},{"batl":[[0,420,7.85]],"id":41200638},{"tv":137176.26,"batb":[[1,1.99,3.14],[0,2.04,22.89]],"trd":[[2.04,4508.8]],"id":51922},{"batb":[[0,38,4.06]],"id":106596}],"tv":193691.43}],"ArrivalTime":1710508215321}
{"op":"mcm","id":2,"clk":"AKudAQCu1AEA6ukB","pt":1710508215415,"mc":[{"id":"1.226122413","rc":[{"batl":[[1,780,0.94]],"id":54370634},{"tv":688.51,"batb":[[0,250,3.14]],"trd":[[270,12.97]],"ltp":270,"batl":[[0,420,8.45]],"id":41200638},{"tv":137201.94,"batb":[[0,2.04,10.05]],"trd":[[2.04,4534.48]],"id":51922},{"batl":[[1,5.5,10]],"id":50466254}],"tv":193717.93}],"ArrivalTime":1710508215421}
{"op":"mcm","id":2,"clk":"ALGdAQC41AEA8ekB","pt":1710508215529,"mc":[{"id":"1.226122413","rc":[{"batl":[[2,500,2.72]],"id":41200638},{"tv":137208.7,"batb":[[0,2.04,6.67]],"trd":[[2.04,4541.24]],"id":51922},{"batl":[[1,120,2.13]],"id":49744721},{"batb":[[0,38,6.19]],"id":106596}],"tv":193724.69}],"ArrivalTime":1710508215535}
{"op":"mcm","id":2,"clk":"ALydAQC+1AEA++kB","pt":1710508215627,"mc":[{"id":"1.226122413","rc":[{"tv":18147.51,"trd":[[4.5,98.62]],"ltp":4.5,"batl":[[0,4.6,33.31]],"id":41122648},{"tv":691.71,"batb":[[0,250,3.25]],"trd":[[420,13.46],[270,16.16]],"batl":[[2,500,2.38],[0,420,7.84]],"id":41200638},{"tv":3313.35,"trd":[[29,221.22]],"batl":[[0,29,4.36]],"id":55632148},{"tv":137223.05,"batb":[[2,1.97,12.62],[1,1.98,33],[0,1.99,3.14]],"trd":[[2.04,4554.58],[2.02,2504.9]],"ltp":2.02,"id":51922},{"tv":3291.13,"trd":[[85,0.05]],"batl":[[0,110,2.16]],"id":49744721},{"tv":26867.64,"trd":[[4.8,2926.69]],"batl":[[0,4.8,11.57]],"id":50466254},{"tv":826.78,"batb":[[0,160,29.14]],"trd":[[220,17.84],[160,32.87]],"ltp":160,"batl":[[2,290,2.91],[0,220,1.1]],"id":66251581},{"tv":2812.44,"trd":[[42,1.74]],"batl":[[0,42,1.24]],"id":106596}],"tv":193745.28}],"ArrivalTime":1710508215633}
{"op":"mcm","id":2,"clk":"AMSdAQDD1AEAguoB","pt":1710508215727,"mc":[{"id":"1.226122413","rc":[{"tv":571.69,"trd":[[520,15.47]],"batl":[[0,710,1.54]],"id":54370634},{"tv":18149.69,"trd":[[4.6,265.72],[4.5,98.67]],"ltp":4.6,"batl":[[1,5.3,15.81],[0,4.6,31.13]],"id":41122648},{"tv":691.73,"batb":[[2,220,6.08],[1,250,3.25],[0,290,1.58]],"trd":[[420,13.48]],"ltp":420,"batl":[[0,420,7.81]],"id":41200638},{"tv":3313.7,"trd":[[29,221.57]],"batl":[[0,29,4.01]],"id":55632148},{"tv":137228.05,"batb":[[2,1.99,3.14],[1,2,29],[0,2.04,4.28]],"trd":[[2.02,2505.01],[2,2144.92]],"ltp":2,"id":51922},{"tv":3291.24,"trd":[[85,0.16]],"batl":[[0,110,2.05]],"id":49744721},{"tv":26869.73,"trd":[[4.8,2928.78]],"batl":[[0,4.8,9.48]],"id":50466254},{"tv":826.82,"trd":[[220,17.88]],"ltp":220,"batl":[[0,220,1.91]],"id":66251581},{"tv":2812.68,"trd":[[42,1.98]],"batl":[[0,42,1]],"id":106596}],"tv":193755.33}],"ArrivalTime":1710508215733}
{"op":"mcm","id":2,"clk":"AMWdAQDI1AEAjOoB","pt":1710508215834,"mc":[{"id":"1.226122413","rc":[{"batb":[[2,250,3.37],[1,380,1.63]],"batl":[[1,780,1.14]],"id":54370634},{"batl":[[1,30,2.13]],"id":55632148},{"tv":137243.42,"batb":[[2,1.98,33],[1,1.99,3.14],[0,2,25.59]],"trd":[[2.04,4563.14],[2,2151.73]],"id":51922},{"batl":[[0,110,2.23]],"id":49744721},{"tv":26888.69,"batb":[[0,5,33.22]],"trd":[[4.8,2947.74]],"batl":[[2,7,1.8],[1,5.8,3.56],[0,5.5,10]],"id":50466254},{"batl":[[2,280,1.68],[1,220,1.06],[0,210,3.42]],"id":66251581}],"tv":193789.66}],"ArrivalTime":1710508215840}
{"op":"mcm","id":2,"clk":"AM6dAQDR1AEAluoB","pt":1710508215937,"mc":[{"id":"1.226122413","rc":[{"tv":18152.01,"batb":[[2,3.35,2],[0,3.7,2.73]],"trd":[[4.5,100.99]],"ltp":4.5,"batl":[[2,5.3,15.81],[1,4.7,2],[0,4.6,31.97]],"id":41122648},{"tv":137253.42,"batb":[[0,2,25.86]],"trd":[[2.04,4565.76],[2.02,2512.39]],"ltp":2.02,"id":51922},{"batb":[[0,60,2.46]],"id":49744721},{"batb":[[2,4.8,2.53],[1,4.9,2]],"id":50466254},{"batb":[[2,110,1.67],[1,160,29.14],[0,170,2]],"id":66251581},{"batb":[[0,38,6.24]],"id":106596}],"tv":193801.98}],"ArrivalTime":1710508215943}
{"op":"mcm","id":2,"clk":"ANSdAQDU1AEAneoB","pt":1710508216040,"mc":[{"id":"1.226122413","rc":[{"batb":[[1,380,1.67]],"id":54370634},{"tv":18153.79,"batb":[[2,3.75,2.73],[1,3.8,2],[0,3.95,2.09]],"trd":[[4.5,102.77]],"batl":[[0,4.6,31.13]],"id":41122648},{"tv":3313.72,"batb":[[0,25,3.28]],"trd":[[25,721.14]],"ltp":25,"id":55632148},{"tv":137269.02,"batb":[[0,2,18.18]],"trd":[[2.06,3885.74],[2.02,2512.94],[2,2166.56]],"ltp":2,"batl":[[2,2.14,4.44],[1,2.12,11.98],[0,2.04,23.91]],"id":51922},{"tv":3291.25,"batb":[[0,60,2.45]],"trd":[[65,14.19]],"ltp":65,"batl":[[0,110,2.05]],"id":49744721},{"tv":26888.78,"batb":[[2,4.8,4.53],[0,5,33.13]],"trd":[[5,1369.68]],"ltp":5,"id":50466254},{"tv":2812.69,"batb":[[0,38,6.23]],"trd":[[40,9.97]],"ltp":40,"id":106596}],"tv":193819.49}],"ArrivalTime":1710508216046}
{"op":"mcm","id":2,"clk":"AN2dAQDs1AEAquoB","pt":1710508216150,"mc":[{"id":"1.226122413","rc":[{"tv":18156.61,"batb":[[0,3.95,2]],"trd":[[4.4,2.64],[4.5,102.95]],"ltp":4.4,"batl":[[0,4.6,31.72]],"id":41122648},{"tv":137279.11,"batb":[[2,1.99,3.14],[1,2,19.65],[0,2.02,1.96]],"trd":[[2.04,4575.85]],"ltp":2.04,"batl":[[0,2.04,18.86]],"id":51922}],"tv":193832.4}],"ArrivalTime":1710508216156}
{"op":"mcm","id":2,"clk":"AOedAQD21AEAsuoB","pt":1710508216210,"mc":[{"id":"1.226122413","rc":[{"tv":18157.79,"batb":[[2,3.8,2],[1,3.95,2],[0,4.2,1.01]],"trd":[[4.4,3.82]],"batl":[[0,4.6,31.13]],"id":41122648},{"batl":[[0,420,5.51]],"id":41200638},{"batb":[[1,2,21.29]],"id":51922},{"batl":[[2,120,2.13],[1,110,2],[0,100,2.36]],"id":49744721}],"tv":193833.58}],"ArrivalTime":1710508216216}
{"op":"mcm","id":2,"clk":"AO+dAQD+1AEAu+oB","pt":1710508216331,"mc":[{"id":"1.226122413","rc":[{"batl":[[0,100,4.92]],"id":49744721}]}],"ArrivalTime":1710508216338}
{"op":"mcm","id":2,"clk":"APWdAQCE1QEAwOoB","pt":1710508216408,"mc":[{"id":"1.226122413","rc":[{"tv":18159.79,"batb":[[2,3.75,2.73],[1,3.8,2],[0,3.95,2.01]],"trd":[[4.2,23.32],[4.4,5.74]],"ltp":4.2,"batl":[[2,4.7,2],[1,4.6,31.13],[0,4.5,90.78]],"id":41122648},{"batb":[[2,250,3.25],[1,290,1.58],[0,300,1.71]],"id":41200638},{"tv":137320.65,"batb":[[2,1.98,33],[1,1.99,3.14],[0,2,3.25]],"trd":[[2.04,4577.39],[2.02,2516.86],[2,2202.64]],"batl":[[0,2.04,18.1]],"id":51922},{"batb":[[2,4.7,3.79],[1,4.8,4.53],[0,4.9,2]],"id":50466254}],"tv":193877.12}],"ArrivalTime":1710508216414}
{"op":"mcm","id":2,"clk":"AP2dAQCP1QEAx+oB","pt":1710508216512,"mc":[{"id":"1.226122413","rc":[{"batl":[[1,780,0.38]],"id":54370634},{"batl":[[2,500,1.96]],"id":41200638},{"batl":[[0,100,6.41]],"id":49744721}]}],"ArrivalTime":1710508216518}
{"op":"mcm","id":2,"clk":"AISeAQCU1QEAzuoB","pt":1710508216620,"mc":[{"id":"1.226122413","rc":[{"batb":[[2,3.8,2],[1,3.95,2],[0,4.1,1.3]],"id":41122648},{"batl":[[0,29,6.58]],"id":55632148},{"tv":137323.43,"batb":[],"trd":[[2.04,4580.17]],"batl":[[2,2.12,11.98],[1,2.04,18.7],[0,2.02,10]],"id":51922},{"tv":3293.25,"trd":[[100,1.9],[85,0.26]],"ltp":100,"batl":[[0,100,5.41]],"id":49744721},{"batb":[[2,4.7,4.92]],"id":50466254}],"tv":193881.9}],"ArrivalTime":1710508216625}
{"op":"mcm","id":2,"clk":"AIqeAQCb1QEA2OoB","pt":1710508216721,"mc":[{"id":"1.226122413","rc":[{"batb":[[0,4.1,2.38]],"batl":[],"id":41122648},{"batl":[[2,510,0.2],[1,500,1.96]],"id":41200638},{"batl":[[2,7,1.87]],"id":50466254}]}],"ArrivalTime":1710508216727}
{"op":"mcm","id":2,"clk":"AJGeAQCh1QEA5+oB","pt":1710508216827,"mc":[{"id":"1.226122413","rc":[{"batl":[[1,4.6,3]],"id":41122648},{"tv":137323.59,"batb":[[0,2,3.17]],"trd":[[2,2202.8]],"ltp":2,"id":51922},{"batb":[[2,46,10.17]],"batl":[[2,130,2.49]],"id":49744721},{"batl":[[2,990,0.29],[1,280,1.68],[0,220,1.91]],"id":66251581},{"batb":[[0,38,9.63]],"id":106596}],"tv":193882.06}],"ArrivalTime":1710508216833}
{"op":"mcm","id":2,"clk":"AJ+eAQCv1QEA8+oB","pt":1710508216933,"mc":[{"id":"1.226122413","rc":[{"batb":[[2,340,2]],"id":54370634},{"batb":[[2,3.8,2.05]],"id":41122648},{"batb":[[0,25,5.84]],"batl":[[0,29,6.6]],"id":55632148},{"tv":137363.59,"batb":[[2,1.96,55.2],[1,1.97,150.41],[0,1.98,19.31]],"trd":[[1.98,519.48],[1.99,413.87],[2,2209.14]],"ltp":1.98,"id":51922},{"batb":[[2,36,23.8],[1,38,8.69],[0,40,1.82]],"id":106596}],"tv":193922.06}],"ArrivalTime":1710508216940}
{"op":"mcm","id":2,"clk":"AKOeAQC51QEA+eoB","pt":1710508217027,"mc":[{"id":"1.226122413","rc":[{"batl":[[2,4.6,3],[1,4.5,90.78],[0,4.3,29]],"id":41122648},{"batl":[[2,220,1.53]],"id":49744721},{"batl":[[1,5.8,14.56]],"id":50466254}]}],"ArrivalTime":1710508217033}
{"op":"mcm","id":2,"clk":"ANqeAQDO1QEAiesB","pt":1710508217230,"mc":[{"id":"1.226122413","rc":[{"batb":[[2,3.85,2.05]],"id":41122648},{"batb":[[1,24,3.85],[0,25,5.91]],"id":55632148},{"batb":[[1,1.97,150.14]],"id":51922},{"batl":[[2,220,1.65],[0,100,5.59]],"id":49744721},{"tv":2814.69,"batb":[[2,38,8.69],[1,40,1.82],[0,42,1.5]],"trd":[[42,3.98]],"ltp":42,"batl":[[2,80,2.05],[1,50,3.85],[0,44,3.89]],"id":106596}],"tv":193924.06}],"ArrivalTime":1710508217236}
{"op":"mcm","id":2,"clk":"AOGeAQDV1QEAmesB","pt":1710508217340,"mc":[{"id":"1.226122413","rc":[{"batl":[[1,1000,2.09]],"id":54370634}]}],"ArrivalTime":1710508217346}
