{"op":"mcm","id":2,"clk":"AK\u002B1AQCxeAC\u002B5AE=","pt":1780316439117,"mc":[{"id":"1.258742455","rc":[{"batb":[],"atb":[[4.4,51.94]],"atl":[[5.3,27.15]],"batl":[],"id":99072898},{"atl":[[23,8.43]],"batl":[[0,23,8.43]],"id":99072900},{"batb":[[0,4.7,139.37]],"atb":[[4.8,0]],"id":10398159},{"batb":[[0,9,22.97]],"atb":[[9,22.97]],"id":98117699},{"batb":[[1,3.45,98.78]],"atb":[[3.45,98.78]],"id":88302242}]}],"rt":639159132391251899,"dt":639159132391252345}
{"op":"mcm","id":2,"clk":"ALK1AQC0eADI5AE=","pt":1780316439215,"mc":[{"id":"1.258742455","rc":[{"batb":[[0,21,21.92]],"atb":[[21,21.92]],"id":99072900},{"tv":8689.22,"batb":[[0,4.7,138.37]],"trd":[[4.7,1229.39]],"ltp":4.7,"atb":[[4.7,138.37]],"atl":[[5.3,38.25]],"batl":[],"id":10398159},{"batb":[[0,11,34.8]],"atb":[[11,34.8]],"id":97736949}],"tv":39927.17}],"rt":639159132392233241,"dt":639159132392233666}
{"op":"mcm","id":2,"clk":"ALe1AQC2eADN5AE=","pt":1780316439322,"mc":[{"id":"1.258742455","rc":[{"atl":[[4.9,38.59]],"batl":[[0,4.9,38.59]],"id":99072898},{"batb":[[0,48,6.53]],"atb":[[48,6.53]],"id":97008932},{"atl":[[23,9.31]],"batl":[[0,23,9.31]],"id":99072900},{"batb":[[0,95,4.2]],"atb":[[95,4.2]],"id":99072901},{"batb":[[0,4.7,103.77]],"atb":[[4.7,103.77]],"id":10398159},{"batb":[[0,50,21.05]],"atb":[[50,21.05]],"id":98464183},{"batb":[[0,9,8.27]],"atb":[[9,8.27]],"id":98117699},{"batb":[[0,11,20.96]],"atb":[[11,20.96]],"id":97736949}]}],"rt":639159132393307504,"dt":639159132393308127}
{"op":"mcm","id":2,"clk":"AMC1AQC6eADT5AE=","pt":1780316439421,"mc":[{"id":"1.258742455","rc":[{"batb":[[0,48,6.78]],"atb":[[48,6.78]],"id":97008932},{"batb":[[0,21,22.48]],"atb":[[21,22.48]],"id":99072900},{"batb":[[0,95,4.32]],"atb":[[95,4.32]],"id":99072901},{"batb":[[0,9,1.47]],"atb":[[9,1.47]],"id":98117699},{"batb":[],"atb":[[3.25,19.03]],"id":88302242},{"tv":2582.94,"batb":[[0,11,22.03]],"trd":[[11.5,56.81]],"ltp":11.5,"atb":[[11,22.03]],"atl":[[11.5,20.74]],"batl":[[0,11.5,20.74]],"id":97736949}],"tv":39927.58}],"rt":639159132394299110,"dt":639159132394299543}
{"op":"mcm","id":2,"clk":"AMS1AQC/eADb5AE=","pt":1780316439521,"mc":[{"id":"1.258742455","rc":[{"batb":[[0,3.5,18.3]],"atb":[[3.5,18.3]],"id":88302242}]}],"rt":639159132395289087,"dt":639159132395289433}
{"op":"mcm","id":2,"clk":"AM21AQDCeADi5AE=","pt":1780316439623,"mc":[{"id":"1.258742455","rc":[{"batb":[],"atb":[[3.3,69.68]],"id":88302242},{"batb":[[0,11,23.7]],"atb":[[11,23.7]],"id":97736949}]}],"rt":639159132396314417,"dt":639159132396314820}
{"op":"mcm","id":2,"clk":"ANS1AQDKeADo5AE=","pt":1780316439725,"mc":[{"id":"1.258742455","rc":[{"tv":2584.13,"trd":[[11.5,58]],"atl":[[11.5,20.15]],"batl":[[0,11.5,20.15]],"id":97736949}],"tv":39928.77}],"rt":639159132397335022,"dt":639159132397335378}
{"op":"mcm","id":2,"clk":"AOC1AQDPeAD05AE=","pt":1780316439931,"mc":[{"id":"1.258742455","rc":[{"tv":8647.55,"batb":[[1,4.7,94.68]],"trd":[[4.9,736.68]],"ltp":4.9,"atb":[[4.7,94.68]],"atl":[[4.9,37.57]],"batl":[[0,4.9,37.57]],"id":99072898}],"tv":39930.81}],"rt":639159132399387211,"dt":639159132399387700}
{"op":"mcm","id":2,"clk":"AOi1AQDTeAD55AE=","pt":1780316440039,"mc":[{"id":"1.258742455","rc":[{"batb":[[0,4.8,12.52]],"atb":[[4.8,12.52]],"id":99072898},{"atl":[[5.3,48.47]],"batl":[],"id":10398159}]}],"rt":639159132400470446,"dt":639159132400470864}
{"op":"mcm","id":2,"clk":"APa1AQDfeACK5QE=","pt":1780316440291,"mc":[{"id":"1.258742455","rc":[{"atl":[[140,0.45]],"batl":[],"id":99072901},{"batb":[[2,4.6,101.97],[1,4.7,103.77],[0,4.8,100]],"atb":[[4.8,100]],"id":10398159}]}],"rt":639159132402986599,"dt":639159132402986964}
{"op":"mcm","id":2,"clk":"AP\u002B1AQDheACT5QE=","pt":1780316440441,"mc":[{"id":"1.258742455","rc":[{"batb":[[0,4.8,134.34]],"atb":[[4.4,179],[4.3,134.24],[4.8,134.34]],"atl":[[4.9,51.79]],"batl":[[0,4.9,51.79]],"id":10398159},{"tv":2459.63,"batb":[[2,8.4,18.98],[1,8.6,22.61],[0,8.8,25.73]],"trd":[[9,149.74]],"atb":[[9,0]],"atl":[[9,4.16]],"batl":[[2,9.4,11.75],[1,9.2,10.9],[0,9,4.16]],"id":98117699}],"tv":39933.75}],"rt":639159132404491979,"dt":639159132404492508}
{"op":"mcm","id":2,"clk":"AIW2AQDoeACX5QE=","pt":1780316440546,"mc":[{"id":"1.258742455","rc":[{"atl":[[4.9,39.57]],"batl":[[0,4.9,39.57]],"id":99072898},{"batb":[],"atb":[[4.3,123.04]],"atl":[[4.9,43.73]],"batl":[[0,4.9,43.73]],"id":10398159},{"batb":[[2,3.35,149.82],[1,3.4,93.48],[0,3.45,99.52]],"atb":[[3.5,0.74]],"id":88302242}]}],"rt":639159132405538679,"dt":639159132405539135}
{"op":"mcm","id":2,"clk":"AKO2AQD4eAC55QE=","pt":1780316440605,"mc":[{"id":"1.258742455","rc":[{"atl":[[4.9,39.98],[5,107.78]],"batl":[[1,5,107.78],[0,4.9,39.98]],"id":10398159},{"atb":[[1.17,2.77]],"id":98117699}]}],"rt":639159132406134013,"dt":639159132406134379}
{"op":"mcm","id":2,"clk":"ALq2AQCLeQDM5QE=","pt":1780316440701,"mc":[{"id":"1.258742455","rc":[{"batb":[[1,46,11.63]],"atb":[[46,11.63]],"id":97008932},{"batb":[[1,4.7,78.54],[0,4.8,152.8]],"atb":[[4.7,78.54],[4.4,185],[4.8,152.8]],"atl":[[5.3,59.81]],"batl":[],"id":10398159},{"atb":[[1.17,2]],"id":98117699},{"batb":[[0,3.45,94.54]],"atb":[[3.45,93.8]],"id":88302242},{"batb":[[0,160,4.16]],"atb":[[160,4.16]],"id":99072897}]}],"rt":639159132407095537,"dt":639159132407095942}
{"op":"mcm","id":2,"clk":"AMO2AQCPeQDV5QE=","pt":1780316440804,"mc":[{"id":"1.258742455","rc":[{"atl":[[6,18.83]],"id":99072898},{"atl":[[4.9,16.07],[6,29.5]],"batl":[[0,4.9,16.07]],"id":10398159},{"tv":2461.17,"batb":[[0,8.8,24.72]],"trd":[[9,151.28]],"atb":[[8.8,24.72]],"atl":[[9,3.39]],"batl":[[0,9,3.39]],"id":98117699},{"atl":[[4,18.29]],"batl":[],"id":88302242}],"tv":39935.29}],"rt":639159132408130067,"dt":639159132408130587}
{"op":"mcm","id":2,"clk":"AMe2AQCTeQDa5QE=","pt":1780316440906,"mc":[{"id":"1.258742455","rc":[{"batb":[[1,46,13.36]],"atb":[[46,13.36]],"id":97008932},{"batb":[],"atb":[[8.2,19.44]],"id":98117699}]}],"rt":639159132409141969,"dt":639159132409142203}
{"op":"mcm","id":2,"clk":"ANC2AQCbeQDi5QE=","pt":1780316441019,"mc":[{"id":"1.258742455","rc":[{"batb":[[0,4.8,10.73]],"atb":[[4.8,10.73]],"id":99072898},{"atl":[[4.9,4.97]],"batl":[[0,4.9,4.97]],"id":10398159},{"atl":[[190,6.12]],"batl":[[0,190,6.46]],"id":99072897}]}],"rt":639159132410272746,"dt":639159132410273272}
{"op":"mcm","id":2,"clk":"ANG2AQCdeQDm5QE=","pt":1780316441114,"mc":[{"id":"1.258742455","rc":[{"batb":[[1,46,11.63]],"atb":[[46,11.63]],"id":97008932},{"batb":[],"atb":[[8,60.4]],"id":98117699},{"batb":[],"atb":[[3.3,63.68]],"id":88302242},{"batb":[],"atb":[[9.4,6.29],[9.2,42.98]],"id":97736949},{"atl":[[180,1.34]],"batl":[[2,210,1.3],[1,190,6.12],[0,180,1.34]],"id":99072897}]}],"rt":639159132411223014,"dt":639159132411223653}
{"op":"mcm","id":2,"clk":"ANy2AQCheQD05QE=","pt":1780316441214,"mc":[{"id":"1.258742455","rc":[{"batb":[[0,4.8,10.93]],"atb":[[4.8,10.93]],"atl":[[5.7,55.77],[5.6,10.21]],"batl":[],"id":99072898},{"atl":[[5.1,33.65]],"batl":[[2,5.1,33.65]],"id":10398159},{"atl":[[3.55,46.93],[3.6,94.12]],"batl":[[1,3.6,94.12],[0,3.55,46.93]],"id":88302242},{"batb":[],"atb":[[710,0],[690,2]],"id":10445502},{"batb":[[1,150,5.71]],"atb":[[150,5.71]],"id":99072897}]}],"rt":639159132412228727,"dt":639159132412229280}
{"op":"mcm","id":2,"clk":"AOO2AQCleQD55QE=","pt":1780316441316,"mc":[{"id":"1.258742455","rc":[{"batb":[[1,46,13.36]],"atb":[[46,13.36]],"id":97008932},{"tv":13882.77,"batb":[[0,3.45,94.25]],"trd":[[3.5,489.8]],"ltp":3.5,"atb":[[3.5,0.45],[3.25,25.03]],"atl":[[3.75,65.84]],"batl":[],"id":88302242}],"tv":39935.86}],"rt":639159132413259172,"dt":639159132413259569}
{"op":"mcm","id":2,"clk":"AOi2AQCoeQD/5QE=","pt":1780316441419,"mc":[{"id":"1.258742455","rc":[{"atl":[[4.9,5.38]],"batl":[[0,4.9,5.38]],"id":10398159},{"atl":[[9,0]],"batl":[[2,9.6,12.14],[1,9.4,11.75],[0,9.2,10.9]],"id":98117699},{"batb":[[0,11,24.34]],"atb":[[11,24.34]],"id":97736949}]}],"rt":639159132414274109,"dt":639159132414274705}
{"op":"mcm","id":2,"clk":"AO62AQCueQCF5gE=","pt":1780316441520,"mc":[{"id":"1.258742455","rc":[{"batb":[[0,4.8,11.31]],"atb":[[4.8,11.31]],"atl":[[5,36.59]],"batl":[[1,5,36.59]],"id":99072898},{"batb":[[0,4.8,155.28]],"atb":[[4.8,155.28]],"id":10398159},{"tv":2584.57,"batb":[[0,11,28.34]],"trd":[[11.5,58.44]],"atb":[[11,28.34]],"atl":[[11.5,19.93]],"batl":[[0,11.5,19.93]],"id":97736949}],"tv":39936.3}],"rt":639159132415284836,"dt":639159132415285481}
{"op":"mcm","id":2,"clk":"AIC3AQC\u002BeQCn5gE=","pt":1780316441623,"mc":[{"id":"1.258742455","rc":[{"batb":[[1,4.7,87.35]],"atb":[[4.7,87.35]],"atl":[[4.9,7.2]],"batl":[[0,4.9,7.2]],"id":10398159},{"tv":2461.27,"batb":[[2,8.6,22.61],[1,8.8,24.72],[0,9,4.44]],"trd":[[9,151.38]],"atb":[[9,4.44]],"id":98117699},{"atb":[[1.17,196.38]],"atl":[[3.6,95.55]],"batl":[[1,3.6,95.55]],"id":88302242},{"batb":[[0,160,4.48]],"atb":[[160,4.48]],"id":99072897}],"tv":39936.4}],"rt":639159132416310585,"dt":639159132416311265}
{"op":"mcm","id":2,"clk":"AIW3AQDBeQCy5gE=","pt":1780316441730,"mc":[{"id":"1.258742455","rc":[{"batb":[[0,4.8,3.7]],"atb":[[4.8,3.7]],"id":99072898},{"tv":2466.19,"batb":[[0,9,1.98]],"trd":[[9,156.3]],"atb":[[9,1.98]],"id":98117699},{"batb":[[0,3.45,74.36]],"atb":[[1.17,196.12],[3.45,73.91]],"id":88302242}],"tv":39941.32}],"rt":639159132417386378,"dt":639159132417386927}
{"op":"mcm","id":2,"clk":"AIq3AQDJeQC65gE=","pt":1780316441831,"mc":[{"id":"1.258742455","rc":[{"tv":8655.22,"batb":[[2,4.5,44.22],[1,4.6,76.34],[0,4.7,95.08]],"trd":[[4.8,380.6]],"ltp":4.8,"atb":[[4.8,0.4]],"id":99072898},{"atl":[[23,10.34]],"batl":[[0,23,10.34]],"id":99072900},{"tv":2468.39,"batb":[[2,8.4,18.98],[1,8.6,22.61],[0,8.8,25.6]],"trd":[[9,158.5]],"atb":[[9,0.88]],"id":98117699},{"batb":[[0,3.45,74.62]],"atb":[[3.5,0.71]],"id":88302242},{"batb":[[0,11,30]],"atb":[[11,30]],"id":97736949}],"tv":39951.19}],"rt":639159132418394229,"dt":639159132418394981}
{"op":"mcm","id":2,"clk":"AI\u002B3AQDNeQDE5gE=","pt":1780316441934,"mc":[{"id":"1.258742455","rc":[{"tv":2470.15,"batb":[[0,8.8,24.72]],"trd":[[9,160.26]],"atb":[[9,0],[8,54.4]],"atl":[[9,1.74]],"batl":[[2,9.4,11.75],[1,9.2,10.9],[0,9,1.74]],"id":98117699},{"tv":2585.7,"batb":[[0,11,34.54]],"trd":[[11.5,59.57]],"atb":[[11,34.54]],"atl":[[11.5,19.36]],"batl":[[0,11.5,19.36]],"id":97736949}],"tv":39954.08}],"rt":639159132419427013,"dt":639159132419427583}
{"op":"mcm","id":2,"clk":"AJW3AQDSeQDL5gE=","pt":1780316442039,"mc":[{"id":"1.258742455","rc":[{"batb":[[0,4.7,94.68]],"atb":[[4.8,0]],"atl":[[4.9,42]],"batl":[[0,4.9,42]],"id":99072898},{"batb":[[1,46,11.63]],"atb":[[46,11.63]],"id":97008932},{"batb":[[2,4.6,111.44]],"atb":[[4.6,111.44]],"id":10398159}]}],"rt":639159132420473890,"dt":639159132420474398}
{"op":"mcm","id":2,"clk":"AJq3AQDUeQDO5gE=","pt":1780316442137,"mc":[{"id":"1.258742455","rc":[{"atl":[[9,0]],"batl":[[2,9.6,12.14],[1,9.4,11.75],[0,9.2,10.9]],"id":98117699}]}],"rt":639159132421466210,"dt":639159132421466605}
{"op":"mcm","id":2,"clk":"AKS3AQDXeQDT5gE=","pt":1780316442241,"mc":[{"id":"1.258742455","rc":[{"atl":[[5.2,28.45]],"batl":[],"id":99072898},{"batb":[[1,46,13.36]],"atb":[[46,13.36]],"id":97008932},{"batb":[],"atb":[[8.2,25.44]],"id":98117699},{"batb":[],"atb":[[3.25,21.35]],"id":88302242},{"batb":[],"atb":[[9.8,12.58]],"id":97736949}]}],"rt":639159132422496367,"dt":639159132422496811}
{"op":"mcm","id":2,"clk":"AKq3AQDZeQDZ5gE=","pt":1780316442351,"mc":[{"id":"1.258742455","rc":[{"batb":[[0,4.8,153.28]],"atb":[[4.8,153.28]],"id":10398159},{"atl":[[9,0.22]],"batl":[[0,9.2,11.12]],"id":98117699},{"tv":13886.77,"batb":[[0,3.45,72.62]],"trd":[[3.5,491.22],[3.45,77.7]],"ltp":3.45,"atb":[[3.5,0],[3.45,72.62]],"id":88302242}],"tv":39958.08}],"rt":639159132423596480,"dt":639159132423596984}
{"op":"mcm","id":2,"clk":"ALe3AQDieQDj5gE=","pt":1780316442510,"mc":[{"id":"1.258742455","rc":[{"batb":[],"atb":[[4.4,45.94]],"id":99072898},{"batb":[[2,4.6,108.14]],"atb":[[4.6,108.14]],"id":10398159},{"tv":2492.65,"batb":[[0,8.8,13.47]],"trd":[[8.8,34.5]],"ltp":8.8,"atb":[[8.8,13.47]],"atl":[[9,0]],"batl":[[0,9.2,10.9]],"id":98117699},{"atl":[[3.55,53.17]],"batl":[[0,3.55,53.17]],"id":88302242}],"tv":39980.58}],"rt":639159132425185343,"dt":639159132425185873}
{"op":"mcm","id":2,"clk":"ANi3AQD2eQD35gE=","pt":1780316442607,"mc":[{"id":"1.258742455","rc":[{"tv":8658.68,"batb":[[2,4.6,76.34],[1,4.7,98.71],[0,4.8,13.57]],"trd":[[4.9,740.14]],"ltp":4.9,"atb":[[4.7,98.71],[4.8,13.57]],"atl":[[4.9,40.27]],"batl":[[0,4.9,40.27]],"id":99072898},{"batb":[],"atb":[[4.4,180.98]],"id":10398159},{"batb":[[0,8.8,16.33]],"atb":[[8.8,16.33]],"atl":[[9,3.9]],"batl":[[2,9.4,11.75],[1,9.2,10.9],[0,9,3.9]],"id":98117699}],"tv":39984.04}],"rt":639159132426154127,"dt":639159132426154623}
{"op":"mcm","id":2,"clk":"AN\u002B3AQD5eQD95gE=","pt":1780316442707,"mc":[{"id":"1.258742455","rc":[{"tv":8721.67,"batb":[[0,4.8,16.73]],"trd":[[4.9,803.13]],"atb":[[4.8,16.73]],"atl":[[5.4,33.24],[4.9,8.78],[5,34.11],[5.1,47.1]],"batl":[[2,5.1,47.1],[1,5,34.11],[0,4.9,8.78]],"id":99072898},{"batb":[[2,8.4,21.86],[0,8.8,14.53]],"atb":[[8.4,21.86],[8.8,14.53]],"atl":[[9,5.1]],"batl":[[0,9,5.1]],"id":98117699},{"batb":[[1,3.4,88.49]],"atb":[[3.4,88.49]],"id":88302242}],"tv":40047.03}],"rt":639159132427152691,"dt":639159132427153279}
{"op":"mcm","id":2,"clk":"AOa3AQCAegCB5wE=","pt":1780316442810,"mc":[{"id":"1.258742455","rc":[{"tv":8739.23,"batb":[[0,4.8,34.08]],"trd":[[4.9,820.69]],"atb":[[4.3,17.42],[4.8,34.08]],"atl":[[4.9,0],[5.3,29.64]],"batl":[[2,5.2,28.45],[1,5.1,47.1],[0,5,34.11]],"id":99072898},{"batb":[],"atb":[[17,59.8]],"id":99072900},{"atl":[[4.9,25.03]],"batl":[[0,4.9,25.03]],"id":10398159},{"batb":[],"atb":[[8.2,19.44]],"id":98117699}],"tv":40064.59}],"rt":639159132428177078,"dt":639159132428177527}
{"op":"mcm","id":2,"clk":"AOy3AQCEegCG5wE=","pt":1780316442910,"mc":[{"id":"1.258742455","rc":[{"batb":[[2,4.7,98.71],[1,4.8,41.65],[0,4.9,2.49]],"atb":[[4.9,2.49],[4.8,41.65]],"atl":[[5.4,30.74],[5.3,27.15],[5.5,35.08]],"batl":[],"id":99072898},{"atl":[[55,1.38]],"batl":[[0,55,1.38]],"id":98464183},{"batb":[[1,8.6,18.85]],"atb":[[8.6,18.85]],"atl":[[9,8.12]],"batl":[[0,9,8.12]],"id":98117699}]}],"rt":639159132429186061,"dt":639159132429186461}
{"op":"mcm","id":2,"clk":"APO3AQCKegCK5wE=","pt":1780316443017,"mc":[{"id":"1.258742455","rc":[{"atl":[[5.5,32.6],[5.6,12.67]],"batl":[],"id":99072898},{"atl":[[4.9,25.75]],"batl":[[0,4.9,25.75]],"id":10398159},{"tv":2508.43,"batb":[[2,8.2,19.44],[1,8.4,21.86],[0,8.6,18.85]],"trd":[[8.8,50.28]],"atb":[[8.8,0],[8,60.4]],"atl":[[8.8,10.13]],"batl":[[2,9.2,10.9],[1,9,8.12],[0,8.8,10.13]],"id":98117699},{"atl":[[3.5,16.38]],"batl":[[2,3.6,95.55],[1,3.55,53.17],[0,3.5,16.38]],"id":88302242}],"tv":40080.37}],"rt":639159132430254963,"dt":639159132430255458}
{"op":"mcm","id":2,"clk":"APq3AQCTegCP5wE=","pt":1780316443124,"mc":[{"id":"1.258742455","rc":[{"tv":8743.23,"batb":[[1,4.8,47.91],[0,4.9,13.82]],"trd":[[4.9,824.69]],"atb":[[4.9,13.82],[4.8,47.91]],"atl":[[5.2,26.57]],"batl":[[2,5.2,26.57]],"id":99072898},{"atl":[[4.9,7.92]],"batl":[[0,4.9,7.92]],"id":10398159},{"batb":[[2,8.2,22.37],[1,8.4,18.98],[0,8.6,17.85]],"atb":[[8.4,18.98],[8.2,22.37],[8.6,17.85],[8,69.21]],"atl":[[9.8,15.48]],"batl":[],"id":98117699},{"tv":13893.33,"trd":[[3.5,497.78]],"ltp":3.5,"atl":[[3.5,15.07]],"batl":[[0,3.5,15.07]],"id":88302242}],"tv":40090.93}],"rt":639159132431326968,"dt":639159132431327571}
{"op":"mcm","id":2,"clk":"AIG4AQCWegCT5wE=","pt":1780316443220,"mc":[{"id":"1.258742455","rc":[{"batb":[[0,4.9,18.27]],"atb":[[4.9,18.27]],"atl":[[5.3,21.15],[5,30.58]],"batl":[[0,5,30.58]],"id":99072898},{"batb":[[0,4.8,154.55]],"atb":[[4.8,154.55]],"atl":[[4.9,7.2]],"batl":[[0,4.9,7.2]],"id":10398159},{"atl":[[55,1.24]],"batl":[[0,55,1.24]],"id":98464183},{"batb":[[0,8.6,13.8]],"atb":[[7.8,24.45],[8.6,13.8],[8,56.52]],"atl":[[8.8,11.29],[10,17.5],[9,9.65]],"batl":[[1,9,9.65],[0,8.8,11.29]],"id":98117699},{"batb":[[0,3.45,67.54]],"atb":[[3.45,67.54]],"id":88302242}]}],"rt":639159132432289664,"dt":639159132432290287}
{"op":"mcm","id":2,"clk":"AIa4AQCZegCZ5wE=","pt":1780316443320,"mc":[{"id":"1.258742455","rc":[{"batb":[[1,8.4,23.05]],"atb":[[8.4,23.05]],"id":98117699},{"tv":13899.89,"trd":[[3.5,504.34]],"atl":[[3.5,31.57]],"batl":[[0,3.5,31.57]],"id":88302242}],"tv":40097.49}],"rt":639159132433287175,"dt":639159132433287610}
{"op":"mcm","id":2,"clk":"AI\u002B4AQCiegCe5wE=","pt":1780316443433,"mc":[{"id":"1.258742455","rc":[{"batb":[[0,4.9,19.29]],"atb":[[4.9,19.29],[4.3,11.42]],"atl":[[5.4,36.74],[5,29.87]],"batl":[[0,5,29.87]],"id":99072898},{"batb":[[0,8.6,9.94]],"atb":[[8.6,9.94]],"atl":[[8.8,14.35]],"batl":[[0,8.8,14.35]],"id":98117699}]}],"rt":639159132434413537,"dt":639159132434413966}
{"op":"mcm","id":2,"clk":"AJO4AQClegCj5wE=","pt":1780316443537,"mc":[{"id":"1.258742455","rc":[{"batb":[[0,4.9,35.1]],"atb":[[4.9,35.1]],"id":99072898},{"batb":[],"atb":[[8,50.52]],"atl":[[9.8,9.48]],"batl":[],"id":98117699},{"tv":13912.51,"batb":[[0,3.45,61.43]],"trd":[[3.5,516.96]],"atb":[[3.45,61.43]],"atl":[[3.75,59.84],[3.5,25.26],[3.55,50.79]],"batl":[[1,3.55,50.79],[0,3.5,25.26]],"id":88302242}],"tv":40110.11}],"rt":639159132435453803,"dt":639159132435454310}
{"op":"mcm","id":2,"clk":"AJq4AQCtegCp5wE=","pt":1780316443633,"mc":[{"id":"1.258742455","rc":[{"batb":[],"atb":[[4.4,30.14],[4.5,50.22]],"atl":[[5.7,58.2],[5.6,10.21]],"batl":[],"id":99072898},{"tv":13925.14,"trd":[[3.5,529.59]],"atl":[[3.5,18.95]],"batl":[[0,3.5,18.95]],"id":88302242},{"batb":[[0,11,35.19]],"atb":[[11,35.19]],"id":97736949}],"tv":40122.74}],"rt":639159132436415720,"dt":639159132436416271}
{"op":"mcm","id":2,"clk":"AKG4AQCxegCw5wE=","pt":1780316443738,"mc":[{"id":"1.258742455","rc":[{"batb":[[0,4.9,36.6]],"atb":[[4.9,36.6]],"atl":[[5,25.67],[5.6,12.64]],"batl":[[0,5,25.67]],"id":99072898},{"batb":[[0,8.6,7.64]],"atb":[[8.6,7.64]],"atl":[[8.8,14.98]],"batl":[[0,8.8,14.98]],"id":98117699},{"tv":13937.76,"batb":[[1,3.4,94.79],[0,3.45,63.98]],"trd":[[3.5,542.21]],"atb":[[3.4,94.79],[3.45,63.98]],"atl":[[3.5,14.92]],"batl":[[0,3.5,14.92]],"id":88302242},{"tv":2589.42,"batb":[[0,11,33.54]],"trd":[[11.5,59.99],[11,178.47]],"atb":[[11,33.54]],"atl":[[11.5,19.15]],"batl":[[0,11.5,19.15]],"id":97736949}],"tv":40139.08}],"rt":639159132437467646,"dt":639159132437468229}
{"op":"mcm","id":2,"clk":"AKi4AQC4egC45wE=","pt":1780316443837,"mc":[{"id":"1.258742455","rc":[{"atl":[[5,27.67]],"batl":[[0,5,27.67]],"id":99072898},{"atl":[[5,109.78]],"batl":[[1,5,109.78]],"id":10398159},{"batb":[],"atb":[[7.8,30.45]],"atl":[[9,11.65],[9.6,18.14]],"batl":[[1,9,11.65]],"id":98117699},{"tv":13950.38,"trd":[[3.5,554.83]],"atl":[[3.5,8.61],[3.7,223.22],[5,14.52]],"batl":[[0,3.5,8.61]],"id":88302242},{"tv":2593.42,"batb":[[0,11,27]],"trd":[[11,182.47]],"ltp":11,"atb":[[11,27]],"id":97736949}],"tv":40155.7}],"rt":639159132438453466,"dt":639159132438454042}
{"op":"mcm","id":2,"clk":"AK24AQC\u002BegDC5wE=","pt":1780316443946,"mc":[{"id":"1.258742455","rc":[{"tv":13965.78,"batb":[[0,3.45,62.59]],"trd":[[3.5,567.31],[3.55,893.27],[3.45,80.48]],"ltp":3.45,"atb":[[3.45,62.59]],"atl":[[3.5,0],[3.55,50.72]],"batl":[[2,3.65,45.58],[1,3.6,95.55],[0,3.55,50.72]],"id":88302242}],"tv":40171.1}],"rt":639159132439539804,"dt":639159132439540269}
{"op":"mcm","id":2,"clk":"ALW4AQDCegDG5wE=","pt":1780316444042,"mc":[{"id":"1.258742455","rc":[{"atl":[[5,29.59]],"batl":[[0,5,29.59]],"id":99072898},{"batb":[[2,4.6,101.97]],"atb":[[4.2,29.77],[4.6,101.97],[4.3,115.76]],"id":10398159},{"batb":[[2,8.2,19.44]],"atb":[[8.2,19.44],[8,54.52]],"id":98117699},{"tv":13978.4,"batb":[[0,3.45,74.95]],"trd":[[3.55,905.89]],"ltp":3.55,"atb":[[3.45,74.95]],"atl":[[3.55,44.41]],"batl":[[0,3.55,44.41]],"id":88302242}],"tv":40183.72}],"rt":639159132440504946,"dt":639159132440505452}
{"op":"mcm","id":2,"clk":"ALm4AQDLegDL5wE=","pt":1780316444146,"mc":[{"id":"1.258742455","rc":[{"batb":[[0,11,28.66]],"atb":[[11,28.66]],"id":97736949}]}],"rt":639159132441539077,"dt":639159132441539421}
{"op":"mcm","id":2,"clk":"AMG4AQDQegDS5wE=","pt":1780316444254,"mc":[{"id":"1.258742455","rc":[{"atl":[[55,1.38]],"batl":[[0,55,1.38]],"id":98464183},{"atl":[[8.8,7.72]],"batl":[[0,8.8,7.72]],"id":98117699},{"batb":[[2,3.4,94.79],[1,3.45,74.95],[0,3.5,2.19]],"atb":[[3.5,2.19]],"id":88302242}]}],"rt":639159132442624849,"dt":639159132442625290}
{"op":"mcm","id":2,"clk":"AMS4AQDTegDZ5wE=","pt":1780316444348,"mc":[{"id":"1.258742455","rc":[{"batb":[[0,4.9,35.1]],"atb":[[4.9,35.1]],"atl":[[5.5,35.03]],"batl":[],"id":99072898},{"atl":[[3.7,217.22]],"batl":[],"id":88302242}]}],"rt":639159132443558353,"dt":639159132443558764}
{"op":"mcm","id":2,"clk":"AM24AQDVegDg5wE=","pt":1780316444449,"mc":[{"id":"1.258742455","rc":[{"atl":[[5,30.57]],"batl":[[0,5,30.57]],"id":99072898},{"batb":[[1,4.7,78.54],[0,4.8,168.42]],"atb":[[4.7,78.54],[4.8,168.42]],"atl":[[4.9,5.38],[5,112.3]],"batl":[[1,5,112.3],[0,4.9,5.38]],"id":10398159},{"tv":2523.71,"batb":[[2,8,54.52],[1,8.2,19.44],[0,8.4,23.05]],"trd":[[8.6,15.28]],"ltp":8.6,"atb":[[8.6,0]],"atl":[[9.4,11.4],[9.2,9.89],[8.6,3.69],[9.6,14.75]],"batl":[[2,9,11.65],[1,8.8,7.72],[0,8.6,3.69]],"id":98117699},{"tv":13995.28,"batb":[[0,3.5,19.82]],"trd":[[3.55,922.77]],"atb":[[3.5,19.82]],"atl":[[3.55,35.97]],"batl":[[0,3.55,35.97]],"id":88302242},{"tv":2594.62,"trd":[[11.5,61.19]],"ltp":11.5,"atl":[[11.5,18.55]],"batl":[[0,11.5,18.55]],"id":97736949}],"tv":40217.08}],"rt":639159132444571657,"dt":639159132444572299}
{"op":"mcm","id":2,"clk":"AM\u002B4AQDYegDp5wE=","pt":1780316444507,"mc":[{"id":"1.258742455","rc":[{"batb":[[0,4.9,35.13]],"atb":[[4.9,35.13]],"id":99072898},{"tv":2529.83,"batb":[[2,8,50.52]],"trd":[[8.6,21.4]],"atb":[[7.8,34.52],[8,50.52]],"atl":[[8.6,0.63]],"batl":[[2,9.2,9.89],[1,9,11.65],[0,8.8,8.35]],"id":98117699},{"tv":14026.12,"trd":[[3.55,953.61]],"atl":[[3.75,65.84],[3.55,21.37]],"batl":[[0,3.55,21.37]],"id":88302242}],"tv":40254.04}],"rt":639159132445152375,"dt":639159132445152848}
{"op":"mcm","id":2,"clk":"ANS4AQDeegDt5wE=","pt":1780316444654,"mc":[{"id":"1.258742455","rc":[{"batb":[[0,4.9,19.32]],"atb":[[4.9,19.32]],"id":99072898},{"atb":[[4.4,1.47]],"id":97008932},{"atl":[[5.3,49.59]],"batl":[],"id":10398159},{"atl":[[55,1.49]],"batl":[[0,55,1.49]],"id":98464183},{"tv":2531.09,"batb":[[0,8.4,17.28]],"trd":[[8.6,22.66]],"atb":[[8.4,17.28],[7.8,47.36]],"atl":[[8.6,0]],"batl":[[0,8.8,7.72]],"id":98117699},{"tv":14026.7,"batb":[[1,3.45,80.6],[0,3.5,19.53]],"trd":[[3.5,567.89]],"ltp":3.5,"atb":[[3.5,19.53],[3.25,15.35],[3.45,80.6]],"atl":[[3.55,39.09]],"batl":[[0,3.55,39.09]],"id":88302242}],"tv":40255.88}],"rt":639159132446618265,"dt":639159132446618833}
{"op":"mcm","id":2,"clk":"AOC4AQDjegD45wE=","pt":1780316444717,"mc":[{"id":"1.258742455","rc":[{"atl":[[5,32.29]],"batl":[[0,5,32.29]],"id":99072898},{"batb":[[0,11,27.23]],"atb":[[11,27.23]],"id":97736949},{"batb":[[2,140,3.74]],"atb":[[140,3.74]],"id":99072897}]}],"rt":639159132447254706,"dt":639159132447255229}
{"op":"mcm","id":2,"clk":"AOm4AQDqegCA6AE=","pt":1780316444825,"mc":[{"id":"1.258742455","rc":[{"batb":[[0,4.9,16.11]],"atb":[[4.9,16.11]],"atl":[[5.2,24.57],[5,26.29],[5.1,43.1]],"batl":[[2,5.2,24.57],[1,5.1,43.1],[0,5,26.29]],"id":99072898},{"atl":[[4.9,5.77]],"batl":[[0,4.9,5.77]],"id":10398159},{"batb":[],"atb":[[7.8,30.78]],"atl":[[8.6,3.93]],"batl":[[2,9,11.65],[1,8.8,7.72],[0,8.6,3.93]],"id":98117699},{"tv":14065.76,"batb":[[2,3.35,149.82],[1,3.4,94.79],[0,3.45,80.6]],"trd":[[3.5,606.95]],"atb":[[3.3,69.68],[3.5,0]],"atl":[[3.65,49.01],[3.5,23.72],[3.55,50.74],[3.6,91.95]],"batl":[[2,3.6,91.95],[1,3.55,50.74],[0,3.5,23.72]],"id":88302242}],"tv":40294.94}],"rt":639159132448326357,"dt":639159132448326968}
{"op":"mcm","id":2,"clk":"APG4AQDvegCJ6AE=","pt":1780316444920,"mc":[{"id":"1.258742455","rc":[{"batb":[[0,4.9,31.92]],"atb":[[4.9,31.92]],"id":99072898},{"batb":[[0,8.4,18.31]],"atb":[[8.4,18.31],[7.8,24.78]],"id":98117699},{"tv":14066.8,"trd":[[3.5,607.99]],"atl":[[3.5,23.2]],"batl":[[0,3.5,23.2]],"id":88302242},{"batb":[[0,11,27.63]],"atb":[[11,27.63]],"id":97736949}],"tv":40295.98}],"rt":639159132449286549,"dt":639159132449286985}
{"op":"mcm","id":2,"clk":"APi4AQDxegCS6AE=","pt":1780316445018,"mc":[{"id":"1.258742455","rc":[{"batb":[[0,4.9,41.89]],"atb":[[4.9,41.89]],"atl":[[5,13.99]],"batl":[[0,5,13.99]],"id":99072898},{"atl":[[27,8.8]],"batl":[],"id":99072900},{"atl":[[55,1.24]],"batl":[[0,55,1.24]],"id":98464183},{"tv":2535.43,"trd":[[8.6,27]],"atl":[[8.6,1.76]],"batl":[[0,8.6,1.76]],"id":98117699},{"tv":14113.19,"batb":[[2,3.4,94.79],[1,3.45,80.6],[0,3.5,13.16]],"trd":[[3.5,654.38]],"atb":[[3.5,13.16]],"atl":[[3.75,59.84],[3.5,0],[3.6,95.4]],"batl":[[2,3.65,49.01],[1,3.6,95.4],[0,3.55,50.74]],"id":88302242}],"tv":40346.71}],"rt":639159132450264056,"dt":639159132450264626}
{"op":"mcm","id":2,"clk":"AIG5AQD2egCY6AE=","pt":1780316445122,"mc":[{"id":"1.258742455","rc":[{"atb":[[24,3.49]],"id":97008932},{"batb":[],"atb":[[7.6,130.31]],"id":98117699},{"batb":[[1,3.45,78.05]],"atb":[[3.45,78.05]],"atl":[[3.7,223.78]],"batl":[],"id":88302242}]}],"rt":639159132451299157,"dt":639159132451299555}
{"op":"mcm","id":2,"clk":"AIm5AQD6egCc6AE=","pt":1780316445221,"mc":[{"id":"1.258742455","rc":[{"batb":[],"atb":[[4.4,19.57]],"id":99072898},{"atl":[[55,1.49]],"batl":[[0,55,1.49]],"id":98464183},{"tv":2538.79,"trd":[[8.6,30.36]],"atl":[[8.6,3.37],[9.6,8.75]],"batl":[[0,8.6,3.37]],"id":98117699},{"tv":14115.19,"batb":[[0,3.5,14.84]],"trd":[[3.55,955.61]],"ltp":3.55,"atb":[[3.5,14.84]],"atl":[[3.55,49.74],[3.7,217.22]],"batl":[[0,3.55,49.74]],"id":88302242},{"batb":[[0,11,27.23]],"atb":[[11,27.23]],"id":97736949}],"tv":40352.07}],"rt":639159132452293461,"dt":639159132452294107}
{"op":"mcm","id":2,"clk":"AJG5AQD6egCh6AE=","pt":1780316445323,"mc":[{"id":"1.258742455","rc":[{"batb":[[0,4.9,43.05]],"atb":[[4.9,43.05]],"id":99072898},{"batb":[[2,8,53.81]],"atb":[[8,53.81]],"id":98117699},{"atl":[[3.7,223.22]],"batl":[],"id":88302242}]}],"rt":639159132453305807,"dt":639159132453306206}
{"op":"mcm","id":2,"clk":"AJW5AQD9egCo6AE=","pt":1780316445424,"mc":[{"id":"1.258742455","rc":[{"tv":8746.19,"trd":[[5,223.43]],"ltp":5,"atl":[[5,12.51]],"batl":[[0,5,12.51]],"id":99072898},{"tv":2541.13,"trd":[[8.6,32.7]],"atl":[[9.4,17.4],[8.6,2.2]],"batl":[[0,8.6,2.2]],"id":98117699},{"batb":[[0,11,27.44]],"atb":[[11,27.44]],"id":97736949},{"atb":[[2,27.01]],"id":99072897}],"tv":40357.37}],"rt":639159132454327335,"dt":639159132454327888}
{"op":"mcm","id":2,"clk":"AJe5AQCCewCu6AE=","pt":1780316445528,"mc":[{"id":"1.258742455","rc":[{"tv":2544.91,"trd":[[8.6,36.48]],"atl":[[8.6,0.31]],"batl":[[2,9.2,9.89],[1,9,11.65],[0,8.8,8.03]],"id":98117699}],"tv":40361.15}],"rt":639159132455365498,"dt":639159132455365882}
{"op":"mcm","id":2,"clk":"AJ65AQCHewC46AE=","pt":1780316445636,"mc":[{"id":"1.258742455","rc":[{"atl":[[8.6,2.14]],"batl":[[2,9,11.65],[1,8.8,7.72],[0,8.6,2.14]],"id":98117699}]}],"rt":639159132456437993,"dt":639159132456438357}
{"op":"mcm","id":2,"clk":"AKS5AQCJewDA6AE=","pt":1780316445735,"mc":[{"id":"1.258742455","rc":[{"atl":[[55,1.65]],"batl":[[0,55,1.65]],"id":98464183},{"batb":[[0,11,27.23]],"atb":[[11,27.23]],"id":97736949}]}],"rt":639159132457429562,"dt":639159132457429930}
{"op":"mcm","id":2,"clk":"AKy5AQCNewDF6AE=","pt":1780316445841,"mc":[{"id":"1.258742455","rc":[{"batb":[[1,4.8,48.91]],"atb":[[4.8,48.91]],"id":99072898},{"batb":[[1,4.7,79.54]],"atb":[[4.7,79.54]],"id":10398159},{"batb":[],"atb":[[7.6,131.31],[7.4,42.05]],"id":98117699},{"atl":[[3.7,217.22]],"batl":[],"id":88302242},{"batb":[[0,11,27.56]],"atb":[[11,27.56]],"id":97736949}]}],"rt":639159132458489889,"dt":639159132458490348}
{"op":"mcm","id":2,"clk":"AK\u002B5AQCTewDI6AE=","pt":1780316445939,"mc":[{"id":"1.258742455","rc":[{"batb":[[0,95,3.26]],"atb":[[95,3.26]],"id":99072901}]}],"rt":639159132459468542,"dt":639159132459468899}
{"op":"mcm","id":2,"clk":"ALi5AQCVewDO6AE=","pt":1780316446043,"mc":[{"id":"1.258742455","rc":[{"atl":[[28,15.04]],"batl":[],"id":99072900},{"atl":[[3.75,65.84],[3.6,91.95]],"batl":[[1,3.6,91.95]],"id":88302242}]}],"rt":639159132460511191,"dt":639159132460511560}
{"op":"mcm","id":2,"clk":"AL65AQCcewDV6AE=","pt":1780316446144,"mc":[{"id":"1.258742455","rc":[{"atl":[[8.8,8.62]],"batl":[[1,8.8,8.62]],"id":98117699}]}],"rt":639159132461518822,"dt":639159132461519215}
{"op":"mcm","id":2,"clk":"AMO5AQCoewDc6AE=","pt":1780316446247,"mc":[{"id":"1.258742455","rc":[{"atl":[[11.5,6.38],[10.5,27.58]],"batl":[],"id":98117699}]}],"rt":639159132462560002,"dt":639159132462560380}
{"op":"mcm","id":2,"clk":"AMm5AQCsewDj6AE=","pt":1780316446350,"mc":[{"id":"1.258742455","rc":[{"atl":[[5.7,12.06],[5.2,27.03],[5.8,57.78]],"batl":[[2,5.2,27.03]],"id":99072898},{"batb":[],"atb":[[7.6,136.28]],"id":98117699}]}],"rt":639159132463584353,"dt":639159132463584707}
{"op":"mcm","id":2,"clk":"ANO5AQC1ewDp6AE=","pt":1780316446455,"mc":[{"id":"1.258742455","rc":[{"tv":8748.23,"trd":[[5,225.47]],"atl":[[5,11.49]],"batl":[[0,5,11.49]],"id":99072898}],"tv":40363.19}],"rt":639159132464633348,"dt":639159132464633730}
{"op":"mcm","id":2,"clk":"ANe5AQC8ewDw6AE=","pt":1780316446513,"mc":[{"id":"1.258742455","rc":[{"atl":[[5,10.51]],"batl":[[0,5,10.51]],"id":99072898},{"atl":[[55,2.65]],"batl":[[0,55,2.65]],"id":98464183}]}],"rt":639159132465211295,"dt":639159132465211684}
{"op":"mcm","id":2,"clk":"AOi5AQDPewCK6QE=","pt":1780316446610,"mc":[{"id":"1.258742455","rc":[{"batb":[],"atb":[[19,20.14]],"id":99072900}]}],"rt":639159132466183349,"dt":639159132466183720}
{"op":"mcm","id":2,"clk":"AO65AQDTewCS6QE=","pt":1780316446716,"mc":[{"id":"1.258742455","rc":[{"batb":[[0,4.9,44.32]],"atb":[[4.9,44.32]],"id":99072898},{"atl":[[55,2.89]],"batl":[[0,55,2.89]],"id":98464183}]}],"rt":639159132467237829,"dt":639159132467238241}
{"op":"mcm","id":2,"clk":"AIe6AQDnewCv6QE=","pt":1780316447228,"mc":[{"id":"1.258742455","rc":[{"batb":[[0,4.9,47.32]],"atb":[[4.9,47.32]],"id":99072898}]}],"rt":639159132472359437,"dt":639159132472359811}
{"op":"mcm","id":2,"clk":"AIq6AQDwewC06QE=","pt":1780316447337,"mc":[{"id":"1.258742455","rc":[{"batb":[],"atb":[[16.5,16.28]],"atl":[[29,4.88]],"batl":[],"id":99072900},{"batb":[],"atb":[[7.6,131.31]],"id":98117699},{"atb":[[4.4,1.47]],"id":97736949},{"batb":[],"atb":[[700,3.29]],"id":10445502}]}],"rt":639159132473454048,"dt":639159132473454427}
{"op":"mcm","id":2,"clk":"AJS6AQD4ewC86QE=","pt":1780316447435,"mc":[{"id":"1.258742455","rc":[{"batb":[[1,4.8,50.38],[0,4.9,48.54]],"atb":[[4.9,48.54],[4.8,50.38]],"atl":[[5,17.52]],"batl":[[0,5,17.52]],"id":99072898},{"batb":[[0,48,7.58]],"atb":[[48,7.58]],"atl":[[1000,0.39]],"id":97008932},{"batb":[[0,4.8,169.66]],"atb":[[4.8,169.66]],"id":10398159},{"batb":[[0,50,21.29]],"atb":[[50,21.29]],"id":98464183},{"tv":2549.19,"batb":[[0,8.4,20.27]],"trd":[[8.6,40.76]],"atb":[[8.4,19.74],[8.6,0.53]],"atl":[[8.6,0]],"batl":[[2,9.2,9.89],[1,9,11.65],[0,8.8,8.62]],"id":98117699},{"batb":[[0,3.5,16.55]],"atb":[[1.17,196.89],[3.5,16.55],[3.35,164.82]],"id":88302242},{"batb":[[0,1000,92.08]],"atb":[[1000,92.08],[690,0]],"id":10445502},{"batb":[[0,160,4.55]],"atb":[[160,4.55]],"id":99072897}],"tv":40367.47}],"rt":639159132474427241,"dt":639159132474428178}
{"op":"mcm","id":2,"clk":"AJq6AQCFfADE6QE=","pt":1780316447541,"mc":[{"id":"1.258742455","rc":[{"atl":[[1000,0.22]],"id":97008932},{"batb":[[0,8.4,21.75]],"atb":[[8.4,21.22]],"id":98117699},{"atb":[[1.17,196.12]],"id":88302242}]}],"rt":639159132475492944,"dt":639159132475493311}
{"op":"mcm","id":2,"clk":"ALa6AQCVfADY6QE=","pt":1780316447646,"mc":[{"id":"1.258742455","rc":[{"atl":[[55,23.23]],"batl":[[1,55,23.23]],"id":97008932},{"tv":2550.25,"batb":[[0,8.4,21.22]],"trd":[[8.6,41.82]],"atb":[[8.6,0]],"atl":[[8.6,2.76]],"batl":[[2,9,11.65],[1,8.8,8.62],[0,8.6,2.76]],"id":98117699},{"batb":[[0,3.5,17.32]],"atb":[[3.5,17.32]],"id":88302242}],"tv":40368.53}],"rt":639159132476540671,"dt":639159132476541093}
{"op":"mcm","id":2,"clk":"ALy6AQCgfADf6QE=","pt":1780316447752,"mc":[{"id":"1.258742455","rc":[{"atl":[[9.4,11.4]],"batl":[],"id":98117699}]}],"rt":639159132477597091,"dt":639159132477597457}
{"op":"mcm","id":2,"clk":"AMG6AQCmfADm6QE=","pt":1780316447808,"mc":[{"id":"1.258742455","rc":[{"batb":[],"atb":[[18.5,16.86]],"id":99072900},{"tv":8691.82,"batb":[[0,4.8,168.36]],"trd":[[4.8,557.18]],"ltp":4.8,"atb":[[4.8,168.36]],"id":10398159},{"batb":[[2,8,57.1]],"atb":[[8,57.1]],"id":98117699}],"tv":40371.13}],"rt":639159132478165453,"dt":639159132478165869}
{"op":"mcm","id":2,"clk":"AMu6AQCzfADv6QE=","pt":1780316447916,"mc":[{"id":"1.258742455","rc":[{"atl":[[9.2,24.99],[9.6,14.75]],"batl":[],"id":98117699}]}],"rt":639159132479243334,"dt":639159132479243650}
{"op":"mcm","id":2,"clk":"AN\u002B6AQDXfACK6gE=","pt":1780316448320,"mc":[{"id":"1.258742455","rc":[{"tv":8748.35,"trd":[[5,225.59]],"atl":[[5,17.46]],"batl":[[0,5,17.46]],"id":99072898},{"atl":[[9.8,6.74]],"batl":[],"id":98117699}],"tv":40371.25}],"rt":639159132483277406,"dt":639159132483277830}
{"op":"mcm","id":2,"clk":"AOS6AQDcfACR6gE=","pt":1780316448422,"mc":[{"id":"1.258742455","rc":[{"atl":[[4.9,25.04]],"batl":[[0,4.9,25.04]],"id":10398159},{"atl":[[9.6,8.75]],"batl":[],"id":98117699}]}],"rt":639159132484323869,"dt":639159132484324315}
{"op":"mcm","id":2,"clk":"AOq6AQDkfACW6gE=","pt":1780316448526,"mc":[{"id":"1.258742455","rc":[{"atl":[[30,3.86]],"batl":[],"id":99072900},{"atl":[[4.9,26.01]],"batl":[[0,4.9,26.01]],"id":10398159},{"batb":[],"atb":[[7.8,24.14]],"atl":[[8.8,9.82]],"batl":[[1,8.8,9.82]],"id":98117699},{"batb":[[0,11,27.77]],"atb":[[9.4,5.76],[11,27.77]],"id":97736949}]}],"rt":639159132485342074,"dt":639159132485342516}
{"op":"mcm","id":2,"clk":"AIC7AQD3fACu6gE=","pt":1780316448629,"mc":[{"id":"1.258742455","rc":[{"atl":[[9.4,17.4]],"batl":[],"id":98117699}]}],"rt":639159132486376755,"dt":639159132486377078}
{"op":"mcm","id":2,"clk":"AIq7AQD\u002BfAC26gE=","pt":1780316448732,"mc":[{"id":"1.258742455","rc":[{"batb":[],"atb":[[4.2,116.79]],"id":99072898},{"batb":[],"atb":[[4,25.82]],"id":10398159},{"tv":2556.25,"batb":[[0,8.4,19.22]],"trd":[[8.4,6.38],[8.6,43.82]],"atb":[[8.4,19.22],[7.2,20.74]],"atl":[[8.6,1.76]],"batl":[[0,8.6,1.76]],"id":98117699},{"tv":14131.95,"trd":[[3.55,972.37]],"atl":[[3.55,41.36]],"batl":[[0,3.55,41.36]],"id":88302242},{"batb":[],"atb":[[9.8,13.09]],"id":97736949}],"tv":40394.01}],"rt":639159132487406051,"dt":639159132487406587}
{"op":"mcm","id":2,"clk":"AI\u002B7AQCFfQC96gE=","pt":1780316448839,"mc":[{"id":"1.258742455","rc":[{"batb":[],"atb":[[42,13.37]],"id":97008932},{"batb":[],"atb":[[17,59.51]],"id":99072900},{"batb":[],"atb":[[4.3,139.57]],"id":10398159},{"atl":[[8.6,1.84]],"batl":[[0,8.6,1.84]],"id":98117699},{"atb":[[3,6.8]],"id":88302242}]}],"rt":639159132488473563,"dt":639159132488474026}
{"op":"mcm","id":2,"clk":"AJG7AQCJfQDE6gE=","pt":1780316448938,"mc":[{"id":"1.258742455","rc":[{"batb":[],"atb":[[4.2,117.98]],"id":99072898},{"batb":[],"atb":[[4.1,108.95]],"id":10398159},{"tv":918.59,"trd":[[55,119.85]],"atl":[[55,0.89]],"batl":[[2,70,12.81],[1,65,25.59],[0,60,6.51]],"id":98464183},{"batb":[[0,3.5,17.65]],"atb":[[3.5,17.65]],"id":88302242},{"batb":[[0,160,4.72]],"atb":[[160,4.72]],"id":99072897}],"tv":40398.01}],"rt":639159132489462181,"dt":639159132489462649}
{"op":"mcm","id":2,"clk":"AJi7AQCSfQDM6gE=","pt":1780316449044,"mc":[{"id":"1.258742455","rc":[{"batb":[],"atb":[[18,15.85]],"atl":[[26,10.79]],"batl":[],"id":99072900},{"batb":[[0,50,22.65]],"atb":[[50,22.65]],"id":98464183},{"batb":[],"atb":[[7.4,45.63]],"id":98117699},{"tv":14149.33,"batb":[[0,3.5,8.96]],"trd":[[3.5,671.76]],"ltp":3.5,"atb":[[3.5,8.96]],"id":88302242}],"tv":40415.39}],"rt":639159132490519831,"dt":639159132490520254}
{"op":"mcm","id":2,"clk":"AJy7AQCYfQDR6gE=","pt":1780316449144,"mc":[{"id":"1.258742455","rc":[{"batb":[],"atb":[[42,13.49]],"id":97008932},{"batb":[],"atb":[[18.5,17.13]],"id":99072900},{"atl":[[130,2.65]],"batl":[[2,130,2.65]],"id":99072901},{"atl":[[60,7.13],[55,0.65]],"batl":[[0,60,7.78]],"id":98464183},{"batb":[],"atb":[[7.4,62.72]],"atl":[[9.4,32.32],[10,3.85],[8.6,2.18]],"batl":[[0,8.6,2.18]],"id":98117699},{"batb":[[0,3.5,8.63]],"atb":[[3.5,8.63],[3,8.47]],"id":88302242}]}],"rt":639159132491523703,"dt":639159132491524245}
{"op":"mcm","id":2,"clk":"AKC7AQCffQDY6gE=","pt":1780316449246,"mc":[{"id":"1.258742455","rc":[{"batb":[[0,4.9,55.77]],"atb":[[4.9,55.77]],"id":99072898}]}],"rt":639159132492543660,"dt":639159132492544011}
{"op":"mcm","id":2,"clk":"AKu7AQCsfQDr6gE=","pt":1780316449448,"mc":[{"id":"1.258742455","rc":[{"atl":[[5,12.65]],"batl":[[0,5,12.65]],"id":99072898}]}],"rt":639159132494563707,"dt":639159132494564057}
{"op":"mcm","id":2,"clk":"AK67AQCxfQD36gE=","pt":1780316449553,"mc":[{"id":"1.258742455","rc":[{"batb":[[0,4.8,172.36]],"atb":[[4.8,172.36]],"id":10398159}]}],"rt":639159132495606746,"dt":639159132495607120}
{"op":"mcm","id":2,"clk":"ANC7AQDZfQCd6wE=","pt":1780316449662,"mc":[{"id":"1.258742455","rc":[{"batb":[],"atb":[[18,17.45]],"atl":[[32,4.18]],"batl":[],"id":99072900},{"batb":[[0,95,4.22]],"atb":[[95,4.22]],"id":99072901},{"atl":[[60,5.62]],"batl":[[0,60,6.27]],"id":98464183},{"atl":[[3.6,95.36]],"batl":[[1,3.6,95.36]],"id":88302242},{"atl":[[13,15.71]],"batl":[],"id":97736949},{"atl":[[190,7.15]],"batl":[[1,190,7.15]],"id":99072897}]}],"rt":639159132496704332,"dt":639159132496704814}
{"op":"mcm","id":2,"clk":"ANu7AQDofQCz6wE=","pt":1780316449707,"mc":[{"id":"1.258742455","rc":[{"atl":[[8.6,2.44]],"batl":[[0,8.6,2.44]],"id":98117699},{"atl":[[3.55,56.36]],"batl":[[0,3.55,56.36]],"id":88302242}]}],"rt":639159132497156250,"dt":639159132497156700}
{"op":"mcm","id":2,"clk":"AOO7AQDtfQC76wE=","pt":1780316449811,"mc":[{"id":"1.258742455","rc":[{"atl":[[4.9,6.74]],"batl":[[0,4.9,6.74]],"id":10398159}]}],"rt":639159132498193486,"dt":639159132498193826}
{"op":"mcm","id":2,"clk":"AOa7AQDxfQDC6wE=","pt":1780316449914,"mc":[{"id":"1.258742455","rc":[{"atl":[[5.4,37.84]],"batl":[],"id":10398159}]}],"rt":639159132499224959,"dt":639159132499225296}
{"op":"mcm","id":2,"clk":"AOu7AQD2fQDR6wE=","pt":1780316450031,"mc":[{"id":"1.258742455","rc":[{"atl":[[4.9,5.77]],"batl":[[0,4.9,5.77]],"id":10398159}]}],"rt":639159132500396557,"dt":639159132500396947}
{"op":"mcm","id":2,"clk":"AO67AQD3fQDY6wE=","pt":1780316450125,"mc":[{"id":"1.258742455","rc":[{"atl":[[27,14.93]],"batl":[],"id":99072900}]}],"rt":639159132501331491,"dt":639159132501331839}
{"op":"mcm","id":2,"clk":"APK7AQD9fQDh6wE=","pt":1780316450231,"mc":[{"id":"1.258742455","rc":[{"batb":[],"atb":[[17.5,19.89]],"atl":[[34,13.69]],"batl":[],"id":99072900}]}],"rt":639159132502390463,"dt":639159132502390791}
{"op":"mcm","id":2,"clk":"APi7AQCAfgDr6wE=","pt":1780316450328,"mc":[{"id":"1.258742455","rc":[{"atl":[[1000,7.41]],"id":99072898}]}],"rt":639159132503366202,"dt":639159132503366641}
{"op":"mcm","id":2,"clk":"AP27AQCHfgD16wE=","pt":1780316450434,"mc":[{"id":"1.258742455","rc":[{"atl":[[9,12.82]],"batl":[[2,9,12.82]],"id":98117699}]}],"rt":639159132504418317,"dt":639159132504418959}
{"op":"mcm","id":2,"clk":"AIK8AQCMfgD76wE=","pt":1780316450536,"mc":[{"id":"1.258742455","rc":[{"atl":[[1000,6.41],[5,10.07]],"batl":[[0,5,10.07]],"id":99072898},{"batb":[[0,4.8,160.6]],"atb":[[4.8,160.6]],"atl":[[5,110.2]],"batl":[[1,5,110.2]],"id":10398159},{"atl":[[1000,6.42]],"id":98117699},{"atl":[[1000,3.15],[3.6,94.13]],"batl":[[1,3.6,94.13]],"id":88302242},{"batb":[[0,11,25.82]],"atb":[[11,25.82]],"id":97736949}]}],"rt":639159132505440393,"dt":639159132505441238}
{"op":"mcm","id":2,"clk":"AKi8AQCsfgCY7AE=","pt":1780316450644,"mc":[{"id":"1.258742455","rc":[{"atl":[[1000,6.25]],"id":98117699},{"batb":[[1,3.45,103.99]],"atb":[[3.45,103.99]],"atl":[[1000,3]],"id":88302242}]}],"rt":639159132506525775,"dt":639159132506526154}
{"op":"mcm","id":2,"clk":"AK\u002B8AQC2fgCr7AE=","pt":1780316450741,"mc":[{"id":"1.258742455","rc":[{"atl":[[1000,6.25]],"id":99072898},{"batb":[[2,8,58.67]],"atb":[[8,58.67]],"atl":[[8.6,2.61]],"batl":[[0,8.6,2.61]],"id":98117699},{"atl":[[3.55,56.51]],"batl":[[0,3.55,56.51]],"id":88302242},{"batb":[[0,11,25.28]],"atb":[[11,25.28]],"id":97736949}]}],"rt":639159132507496590,"dt":639159132507497051}
{"op":"mcm","id":2,"clk":"ALa8AQC7fgC37AE=","pt":1780316450854,"mc":[{"id":"1.258742455","rc":[{"atl":[[7.6,2.15]],"id":99072898},{"tv":2596.62,"batb":[[0,11,24.28]],"trd":[[11,184.47]],"ltp":11,"atb":[[11,24.28],[9.6,26.7]],"atl":[[13,19.27]],"batl":[],"id":97736949}],"tv":40417.39}],"rt":639159132508622315,"dt":639159132508622772}
{"op":"mcm","id":2,"clk":"ALq8AQDBfgC77AE=","pt":1780316450948,"mc":[{"id":"1.258742455","rc":[{"tv":1360.65,"batb":[[0,21,5.62]],"trd":[[21,199.22]],"ltp":21,"atb":[[21,5.62]],"id":99072900},{"batb":[[0,11,24.45]],"atb":[[11,24.45]],"id":97736949}],"tv":40451.11}],"rt":639159132509562336,"dt":639159132509562807}
{"op":"mcm","id":2,"clk":"AL\u002B8AQDEfgDC7AE=","pt":1780316451054,"mc":[{"id":"1.258742455","rc":[{"atl":[[22,2.53]],"batl":[[2,24,9.69],[1,23,10.34],[0,22,2.53]],"id":99072900},{"atl":[[85,5.51]],"batl":[],"id":98464183},{"atl":[[3.6,90.72]],"batl":[[1,3.6,90.72]],"id":88302242}]}],"rt":639159132510620373,"dt":639159132510620878}
{"op":"mcm","id":2,"clk":"AMK8AQDKfgDK7AE=","pt":1780316451152,"mc":[{"id":"1.258742455","rc":[{"batb":[[1,20,25.07]],"atb":[[20,25.07],[1.01,119120.23]],"atl":[[23,12.91],[22,5.22]],"batl":[[1,23,12.91],[0,22,5.22]],"id":99072900},{"atl":[[200,1.58]],"batl":[[2,200,1.58]],"id":99072897}]}],"rt":639159132511603843,"dt":639159132511604414}
{"op":"mcm","id":2,"clk":"AMe8AQDSfgDW7AE=","pt":1780316451254,"mc":[{"id":"1.258742455","rc":[{"atl":[[5,6.43]],"batl":[[0,5,6.43]],"id":99072898},{"tv":1367.93,"batb":[[0,21,9.66]],"trd":[[21,206.5]],"atb":[[21,9.66],[18.5,18.78]],"id":99072900}],"tv":40458.39}],"rt":639159132512618942,"dt":639159132512619412}
{"op":"mcm","id":2,"clk":"ANC8AQDWfgDf7AE=","pt":1780316451359,"mc":[{"id":"1.258742455","rc":[{"tv":1384.45,"batb":[[0,21,1.12]],"trd":[[21,223.02]],"atb":[[21,1.12]],"id":99072900},{"batb":[[0,11,24.58]],"atb":[[11,24.58]],"id":97736949}],"tv":40474.91}],"rt":639159132513670668,"dt":639159132513671184}
{"op":"mcm","id":2,"clk":"ANG8AQDZfgDo7AE=","pt":1780316451459,"mc":[{"id":"1.258742455","rc":[{"atl":[[5,6.98]],"batl":[[0,5,6.98]],"id":99072898},{"batb":[],"atb":[[19,11.81]],"atl":[[23,11.47],[22,7.44]],"batl":[[1,23,11.47],[0,22,7.44]],"id":99072900},{"tv":14151.05,"batb":[[0,3.5,10.75]],"trd":[[3.5,673.48]],"atb":[[3.5,10.75]],"id":88302242}],"tv":40476.63}],"rt":639159132514676995,"dt":639159132514677519}
{"op":"mcm","id":2,"clk":"ANW8AQDdfgDx7AE=","pt":1780316451519,"mc":[{"id":"1.258742455","rc":[{"tv":8762.31,"batb":[[2,4.8,50.38],[1,4.9,55.77],[0,5,10.89]],"trd":[[5,239.55]],"atb":[[5,10.89]],"atl":[[7.6,2.32],[5,0]],"batl":[[2,5.3,21.15],[1,5.2,27.03],[0,5.1,43.1]],"id":99072898},{"tv":1386.69,"batb":[[2,19,11.81],[1,19.5,33.52],[0,20,25.07]],"trd":[[21,225.26]],"atb":[[21,0]],"atl":[[21,3.03]],"batl":[[2,23,11.47],[1,22,7.44],[0,21,3.03]],"id":99072900}],"tv":40492.83}],"rt":639159132515275265,"dt":639159132515275738}
{"op":"mcm","id":2,"clk":"APi8AQCCfwCY7QE=","pt":1780316451668,"mc":[{"id":"1.258742455","rc":[{"batb":[[1,4.9,58.45],[0,5,12.25]],"atb":[[4.9,58.45],[5,12.25]],"atl":[[5.4,43.88],[5.5,32.6]],"batl":[],"id":99072898},{"batb":[[0,48,7.8]],"atb":[[48,7.8]],"id":97008932},{"tv":1387.69,"batb":[[1,19.5,35.25],[0,20,20.61]],"trd":[[21,226.26]],"atb":[[20,20.61],[19.5,35.25]],"atl":[[22,9.19],[21,3.01]],"batl":[[1,22,9.19],[0,21,3.01]],"id":99072900},{"batb":[[0,95,4.33]],"atb":[[95,4.33]],"id":99072901},{"batb":[[0,3.5,7.77]],"atb":[[3.5,7.77]],"id":88302242},{"batb":[[0,11,25.74]],"atb":[[11,25.74]],"id":97736949}],"tv":40493.83}],"rt":639159132516763369,"dt":639159132516763955}
{"op":"mcm","id":2,"clk":"AIG9AQCIfwCg7QE=","pt":1780316451720,"mc":[{"id":"1.258742455","rc":[{"batb":[],"atb":[[4.7,98.28]],"atl":[[5.4,37.88]],"batl":[],"id":99072898},{"atl":[[27,13.05]],"batl":[],"id":99072900}]}],"rt":639159132517292727,"dt":639159132517293310}
{"op":"mcm","id":2,"clk":"AIa9AQCOfwCq7QE=","pt":1780316451826,"mc":[{"id":"1.258742455","rc":[{"batb":[],"atb":[[15.5,5.73],[18.5,8.45]],"id":99072900},{"tv":14167.81,"trd":[[3.55,989.13]],"ltp":3.55,"atl":[[3.55,48.13]],"batl":[[0,3.55,48.13]],"id":88302242}],"tv":40510.59}],"rt":639159132518337387,"dt":639159132518337754}
{"op":"mcm","id":2,"clk":"AIi9AQCVfwCv7QE=","pt":1780316451930,"mc":[{"id":"1.258742455","rc":[{"atl":[[5.5,38.6]],"batl":[],"id":99072898},{"tv":924.71,"trd":[[60,131.71],[55,121.15]],"ltp":60,"atl":[[60,3.21],[55,0]],"batl":[[0,60,3.21]],"id":98464183},{"atb":[[2,27.56]],"id":99072897}],"tv":40516.71}],"rt":639159132519382983,"dt":639159132519383456}
{"op":"mcm","id":2,"clk":"AI29AQCbfwC47QE=","pt":1780316452032,"mc":[{"id":"1.258742455","rc":[{"batb":[],"atb":[[4.5,44.22]],"id":99072898},{"atl":[[21,3.41]],"batl":[[0,21,3.41]],"id":99072900},{"batb":[[2,48,11.84],[1,50,22.65],[0,55,1.35]],"atb":[[55,1.35]],"id":98464183},{"batb":[[0,3.5,8.42]],"atb":[[3.5,8.42]],"id":88302242},{"atl":[[14,17.38]],"batl":[],"id":97736949}]}],"rt":639159132520400794,"dt":639159132520401642}
{"op":"mcm","id":2,"clk":"AJO9AQChfwDH7QE=","pt":1780316452131,"mc":[{"id":"1.258742455","rc":[{"batb":[[0,55,6.77]],"atb":[[55,6.77]],"atl":[[60,1.34],[70,10.17]],"batl":[[2,70,10.17],[0,60,1.34]],"id":98464183}]}],"rt":639159132521397432,"dt":639159132521397879}
{"op":"mcm","id":2,"clk":"AJy9AQCofwDP7QE=","pt":1780316452236,"mc":[{"id":"1.258742455","rc":[{"batb":[[1,4.9,56.45]],"atb":[[4.9,56.45],[4.6,78.32],[4.5,41.5]],"id":99072898},{"batb":[[1,50,22.23]],"atb":[[50,22.23]],"id":98464183},{"batb":[[1,8.2,20.99]],"atb":[[8.2,20.99]],"id":98117699},{"batb":[],"atb":[[3.3,65.99]],"id":88302242},{"batb":[[0,11,25.53]],"atb":[[11,25.53]],"id":97736949}]}],"rt":639159132522444958,"dt":639159132522445377}
{"op":"mcm","id":2,"clk":"AKS9AQCtfwDY7QE=","pt":1780316452340,"mc":[{"id":"1.258742455","rc":[{"batb":[[1,50,21.87],[0,55,8.25]],"atb":[[55,8.25],[50,21.87]],"atl":[[60,0.43]],"batl":[[2,75,5.65],[1,70,10.17],[0,65,26.02]],"id":98464183}]}],"rt":639159132523486216,"dt":639159132523486640}
{"op":"mcm","id":2,"clk":"AKq9AQCzfwDf7QE=","pt":1780316452436,"mc":[{"id":"1.258742455","rc":[{"batb":[[0,5,14.21]],"atb":[[5,14.21]],"id":99072898},{"batb":[[0,20,19.93]],"atb":[[20,19.93],[17.5,30.54]],"atl":[[24,16.48]],"batl":[],"id":99072900}]}],"rt":639159132524442761,"dt":639159132524443200}
{"op":"mcm","id":2,"clk":"AK29AQC5fwDn7QE=","pt":1780316452541,"mc":[{"id":"1.258742455","rc":[{"batb":[[0,3.5,7.77]],"atb":[[3.5,7.77]],"id":88302242}]}],"rt":639159132525486977,"dt":639159132525487400}
{"op":"mcm","id":2,"clk":"AMq9AQDdfwD57QE=","pt":1780316452639,"mc":[{"id":"1.258742455","rc":[{"batb":[[0,55,8.99]],"atb":[[55,8.99]],"atl":[[60,0]],"batl":[[0,65,25.59]],"id":98464183},{"batb":[[0,11,25.23]],"atb":[[11,25.23]],"id":97736949}]}],"rt":639159132526470707,"dt":639159132526471159}
{"op":"mcm","id":2,"clk":"ANO9AQDrfwCR7gE=","pt":1780316452744,"mc":[{"id":"1.258742455","rc":[{"atl":[[5.6,32.8]],"batl":[],"id":99072898}]}],"rt":639159132527523681,"dt":639159132527524048}
{"op":"mcm","id":2,"clk":"AN\u002B9AQD3fwCi7gE=","pt":1780316452951,"mc":[{"id":"1.258742455","rc":[{"atl":[[80,15.56]],"batl":[],"id":98464183},{"batb":[[0,11,25.44]],"atb":[[11,25.44]],"id":97736949}]}],"rt":639159132529593440,"dt":639159132529593843}
{"op":"mcm","id":2,"clk":"AO29AQD8fwCx7gE=","pt":1780316453060,"mc":[{"id":"1.258742455","rc":[{"tv":14184.57,"trd":[[3.55,1005.89]],"atl":[[3.55,39.75]],"batl":[[0,3.55,39.75]],"id":88302242},{"batb":[[0,11,27.18]],"atb":[[11,27.18]],"id":97736949}],"tv":40533.47}],"rt":639159132530686738,"dt":639159132530687256}
{"op":"mcm","id":2,"clk":"APG9AQCAgAEAu\u002B4B","pt":1780316453156,"mc":[{"id":"1.258742455","rc":[{"atl":[[3.55,43.85]],"batl":[[0,3.55,43.85]],"id":88302242}]}],"rt":639159132531650750,"dt":639159132531651065}
{"op":"mcm","id":2,"clk":"APq9AQCHgAEAxO4B","pt":1780316453257,"mc":[{"id":"1.258742455","rc":[{"atl":[[50,9.8]],"batl":[[0,50,9.8]],"id":97008932}]}],"rt":639159132532649220,"dt":639159132532649558}
{"op":"mcm","id":2,"clk":"AIC\u002BAQCOgAEAzu4B","pt":1780316453311,"mc":[{"id":"1.258742455","rc":[{"batb":[[0,8.4,17.74]],"atb":[[8.4,17.74]],"id":98117699},{"atl":[[3.55,39.75]],"batl":[[0,3.55,39.75]],"id":88302242}]}],"rt":639159132533192421,"dt":639159132533192821}
{"op":"mcm","id":2,"clk":"AIO\u002BAQCUgAEA1e4B","pt":1780316453417,"mc":[{"id":"1.258742455","rc":[{"atl":[[65,4.16]],"batl":[],"id":97008932},{"batb":[[0,8.4,18.84]],"atb":[[8.4,18.84],[7.2,11.06]],"atl":[[1000,6.48]],"id":98117699},{"batb":[[0,3.5,8.25]],"atb":[[3.5,8.25]],"id":88302242}]}],"rt":639159132534266493,"dt":639159132534266958}
{"op":"mcm","id":2,"clk":"AIm\u002BAQCZgAEA3e4B","pt":1780316453510,"mc":[{"id":"1.258742455","rc":[{"atb":[[3.3,2.17]],"atl":[[50,9.91]],"batl":[[0,50,9.91]],"id":97008932},{"atl":[[1000,6.25]],"id":98117699},{"atl":[[180,1.5]],"batl":[[0,180,1.5]],"id":99072897}]}],"rt":639159132535186166,"dt":639159132535186573}
{"op":"mcm","id":2,"clk":"ALG\u002BAQCcgAEA4u4B","pt":1780316453612,"mc":[{"id":"1.258742455","rc":[{"atl":[[24,15.44]],"batl":[],"id":99072900},{"atl":[[8.8,10.05],[9.2,26.23]],"batl":[[1,8.8,10.05]],"id":98117699},{"batb":[[0,11,26.97]],"atb":[[11,26.97]],"id":97736949}]}],"rt":639159132536204730,"dt":639159132536205082}
{"op":"mcm","id":2,"clk":"AMy\u002BAQCigAEA6u4B","pt":1780316453723,"mc":[{"id":"1.258742455","rc":[{"batb":[[0,3.5,8.74]],"atb":[[3.5,8.74]],"atl":[[3.55,41.19]],"batl":[[0,3.55,41.19]],"id":88302242}]}],"rt":639159132537313025,"dt":639159132537313453}
{"op":"mcm","id":2,"clk":"ANq\u002BAQCrgAEAhO8B","pt":1780316454030,"mc":[{"id":"1.258742455","rc":[{"batb":[[0,11,27.09]],"atb":[[11,27.09]],"id":97736949}]}],"rt":639159132540375139,"dt":639159132540375464}
{"op":"mcm","id":2,"clk":"AN\u002B\u002BAQCxgAEAjO8B","pt":1780316454128,"mc":[{"id":"1.258742455","rc":[{"tv":1389.69,"batb":[[0,20,18.93]],"trd":[[20,95.53]],"ltp":20,"atb":[[20,18.93]],"id":99072900},{"atl":[[4.9,10.77]],"batl":[[0,4.9,10.77]],"id":10398159},{"tv":14201.23,"trd":[[3.55,1022.55]],"atl":[[3.55,33.91]],"batl":[[0,3.55,33.91]],"id":88302242}],"tv":40552.13}],"rt":639159132541367582,"dt":639159132541368011}
{"op":"mcm","id":2,"clk":"AOS\u002BAQC4gAEAle8B","pt":1780316454235,"mc":[{"id":"1.258742455","rc":[{"atl":[[4.9,30.69]],"batl":[[0,4.9,30.69]],"id":10398159},{"atl":[[8.6,2.01]],"batl":[[0,8.6,2.01]],"id":98117699}]}],"rt":639159132542427884,"dt":639159132542428235}
{"op":"mcm","id":2,"clk":"APC\u002BAQDBgAEApO8B","pt":1780316454436,"mc":[{"id":"1.258742455","rc":[{"atl":[[8.6,2.25]],"batl":[[0,8.6,2.25]],"id":98117699},{"batb":[[0,3.5,9.36]],"atb":[[3.5,9.36]],"id":88302242}]}],"rt":639159132544445429,"dt":639159132544445819}
{"op":"mcm","id":2,"clk":"APK\u002BAQDLgAEAqu8B","pt":1780316454542,"mc":[{"id":"1.258742455","rc":[{"atl":[[3.55,43.91]],"batl":[[0,3.55,43.91]],"id":88302242}]}],"rt":639159132545505917,"dt":639159132545506272}
{"op":"mcm","id":2,"clk":"AIC/AQDegAEAuu8B","pt":1780316454751,"mc":[{"id":"1.258742455","rc":[{"atl":[[8.6,2.47]],"batl":[[0,8.6,2.47]],"id":98117699}]}],"rt":639159132547591039,"dt":639159132547591451}
{"op":"mcm","id":2,"clk":"AIS/AQDhgAEAwu8B","pt":1780316454851,"mc":[{"id":"1.258742455","rc":[{"batb":[[0,3.5,24.36]],"atb":[[3.5,24.36]],"id":88302242}]}],"rt":639159132548593078,"dt":639159132548593432}
{"op":"mcm","id":2,"clk":"AIy/AQDvgAEA0e8B","pt":1780316455060,"mc":[{"id":"1.258742455","rc":[{"tv":1414.89,"batb":[[2,19.5,35.25],[1,20,18.93],[0,22,4.4]],"trd":[[22,144.44],[21,233.08]],"ltp":22,"atb":[[22,4.4]],"atl":[[22,0],[21,0]],"batl":[[2,25,8.88],[1,24,15.44],[0,23,11.47]],"id":99072900},{"atl":[[4.9,31.64]],"batl":[[0,4.9,31.64]],"id":10398159}],"tv":40577.33}],"rt":639159132550679482,"dt":639159132550679939}
{"op":"mcm","id":2,"clk":"AJC/AQDygAEA1u8B","pt":1780316455115,"mc":[{"id":"1.258742455","rc":[{"batb":[[0,5,3.32]],"atb":[[5,3.32]],"id":99072898},{"tv":1426.01,"batb":[[1,20,23.63],[0,21,1.67]],"trd":[[22,153.24],[21,235.4]],"ltp":21,"atb":[[22,0],[21,1.67],[20,23.63]],"atl":[[26,8.48],[22,7.17]],"batl":[[2,24,15.44],[1,23,11.47],[0,22,7.17]],"id":99072900}],"tv":40588.45}],"rt":639159132551232104,"dt":639159132551232635}
{"op":"mcm","id":2,"clk":"AJe/AQD2gAEA3\u002B8B","pt":1780316455220,"mc":[{"id":"1.258742455","rc":[{"tv":8762.39,"batb":[[0,5,3.28]],"trd":[[5,239.63]],"atb":[[5,3.28]],"id":99072898},{"batb":[[1,20,21.9],[0,21,4.32]],"atb":[[21,4.32],[20,21.9]],"atl":[[22,5.53]],"batl":[[0,22,5.53]],"id":99072900},{"batb":[[0,4.8,153.93]],"atb":[[4.8,153.93]],"id":10398159},{"tv":14203.69,"batb":[[1,3.45,86.45]],"trd":[[3.55,1025.01]],"atb":[[3.45,86.45]],"atl":[[3.55,42.68]],"batl":[[0,3.55,42.68]],"id":88302242},{"batb":[[0,11,26.97]],"atb":[[9.8,14.03],[11,26.97]],"id":97736949}],"tv":40590.99}],"rt":639159132552291170,"dt":639159132552291708}
{"op":"mcm","id":2,"clk":"AJy/AQD8gAEA5u8B","pt":1780316455324,"mc":[{"id":"1.258742455","rc":[{"tv":8768.95,"batb":[[2,4.7,98.28],[1,4.8,50.38],[0,4.9,56.45]],"trd":[[5,246.19]],"atb":[[5,0]],"atl":[[5,11.82]],"batl":[[2,5.2,27.03],[1,5.1,43.1],[0,5,11.82]],"id":99072898},{"atl":[[27,6.92],[24,8.65]],"batl":[[2,24,8.65]],"id":99072900},{"batb":[[0,4.8,154.91]],"atb":[[4.8,154.91]],"id":10398159}],"tv":40597.55}],"rt":639159132553322766,"dt":639159132553323292}
{"op":"mcm","id":2,"clk":"AKS/AQCAgQEA6\u002B8B","pt":1780316455425,"mc":[{"id":"1.258742455","rc":[{"atl":[[5.5,40.99],[5,13.25]],"batl":[[0,5,13.25]],"id":99072898},{"batb":[[2,19.5,36.11],[1,20,23.63]],"atb":[[20,23.63],[19.5,36.11]],"atl":[[22,6.02]],"batl":[[0,22,6.02]],"id":99072900},{"batb":[[0,3.5,34.06]],"atb":[[3.5,34.06]],"id":88302242}]}],"rt":639159132554332746,"dt":639159132554333129}
{"op":"mcm","id":2,"clk":"AKa/AQCEgQEA8O8B","pt":1780316455525,"mc":[{"id":"1.258742455","rc":[{"atl":[[22,3.52]],"batl":[[0,22,3.52]],"id":99072900},{"tv":414.46,"batb":[[2,90,6.58],[1,95,4.33],[0,100,2.9]],"trd":[[100,32.67]],"atb":[[100,2.9]],"atl":[[100,0]],"batl":[[0,110,6.21]],"id":99072901}],"tv":40597.75}],"rt":639159132555335944,"dt":639159132555336362}
{"op":"mcm","id":2,"clk":"AKy/AQCFgQEA\u002BO8B","pt":1780316455636,"mc":[{"id":"1.258742455","rc":[{"batb":[[0,4.9,55.29]],"atb":[[4.9,55.29]],"id":99072898},{"batb":[[1,95,4.73],[0,100,4.72]],"atb":[[100,4.72],[95,4.73],[85,9.21],[80,4.02]],"id":99072901},{"batb":[[0,3.5,35.02]],"atb":[[3.5,35.02]],"id":88302242}]}],"rt":639159132556436289,"dt":639159132556436718}
{"op":"mcm","id":2,"clk":"ALC/AQCGgQEA/O8B","pt":1780316455733,"mc":[{"id":"1.258742455","rc":[{"atl":[[5,14.47]],"batl":[[0,5,14.47]],"id":99072898},{"batb":[[0,21,4.97]],"atb":[[21,4.97]],"id":99072900},{"batb":[[0,100,5.74]],"atb":[[100,5.74],[75,6.73]],"id":99072901},{"atl":[[4.9,32.48]],"batl":[[0,4.9,32.48]],"id":10398159},{"batb":[[0,8.4,19.84]],"atb":[[8.4,19.84]],"atl":[[8.6,2.01]],"batl":[[0,8.6,2.01]],"id":98117699},{"tv":14247.21,"batb":[[0,3.5,13.26]],"trd":[[3.5,717]],"ltp":3.5,"atb":[[3.5,13.26]],"id":88302242}],"tv":40641.27}],"rt":639159132557411125,"dt":639159132557411622}
{"op":"mcm","id":2,"clk":"ALe/AQCNgQEAgvAB","pt":1780316455841,"mc":[{"id":"1.258742455","rc":[{"batb":[],"atb":[[4.6,72.32]],"atl":[[5.5,34.99]],"batl":[],"id":99072898},{"batb":[[0,21,9.79]],"atb":[[21,9.79]],"atl":[[22,3.03]],"batl":[[0,22,3.03]],"id":99072900},{"batb":[],"atb":[[75,5.71]],"atl":[[130,1.62]],"batl":[[2,130,1.62]],"id":99072901},{"tv":8756.77,"batb":[[2,4.7,79.54],[1,4.8,154.91],[0,4.9,107.52]],"trd":[[4.9,418.26]],"ltp":4.9,"atb":[[4.9,107.52]],"atl":[[4.9,0]],"batl":[[2,5.2,41.82],[1,5.1,33.65],[0,5,110.2]],"id":10398159},{"batb":[],"atb":[[46,8.98]],"id":98464183},{"batb":[],"atb":[[7.8,26.44]],"atl":[[8.6,1.93]],"batl":[[0,8.6,1.93]],"id":98117699},{"batb":[[0,3.5,12.3]],"atb":[[3.5,12.3]],"atl":[[3.55,48.66]],"batl":[[0,3.55,48.66]],"id":88302242}],"tv":40706.22}],"rt":639159132558491167,"dt":639159132558491731}
{"op":"mcm","id":2,"clk":"ALm/AQCOgQEAhfAB","pt":1780316455939,"mc":[{"id":"1.258742455","rc":[{"tv":8797.89,"batb":[[2,4.8,50.38],[1,4.9,55.29],[0,5,27.53]],"trd":[[5,275.13]],"atb":[[5,27.53]],"atl":[[5,0]],"batl":[[2,5.3,21.15],[1,5.2,27.03],[0,5.1,43.1]],"id":99072898},{"batb":[[1,20,21.9]],"atb":[[20,21.9]],"atl":[[26,10.63],[22,0]],"batl":[[2,25,8.88],[1,24,8.65],[0,23,11.47]],"id":99072900},{"batb":[[0,100,5.86]],"atb":[[100,5.86]],"id":99072901},{"tv":8765.79,"batb":[[0,4.9,103.01]],"trd":[[4.9,427.28]],"atb":[[4.9,103.01],[4.3,146.57]],"id":10398159},{"batb":[[0,3.5,3.88]],"atb":[[3.5,3.88]],"atl":[[3.6,84.1]],"batl":[[1,3.6,84.1]],"id":88302242}],"tv":40744.18}],"rt":639159132559469642,"dt":639159132559470200}
{"op":"mcm","id":2,"clk":"AMK/AQCUgQEAi/AB","pt":1780316456052,"mc":[{"id":"1.258742455","rc":[{"batb":[],"atb":[[4.5,47.5]],"atl":[[5.4,43.88]],"batl":[],"id":99072898},{"batb":[[2,19.5,34.38],[0,21,4.97]],"atb":[[21,4.97],[19.5,34.38]],"id":99072900},{"batb":[[0,100,4.04]],"atb":[[100,4.04]],"id":99072901},{"batb":[[1,4.8,176.09],[0,4.9,123.84]],"atb":[[4.4,174.8],[4.9,123.84],[4.3,138.51],[4.8,176.09]],"atl":[[5,112.49]],"batl":[[0,5,112.49]],"id":10398159},{"batb":[[0,55,6.17]],"atb":[[55,6.17]],"id":98464183},{"batb":[[0,8.4,10.04]],"atb":[[8.4,10.04],[7.8,22.37],[7.6,135.42]],"id":98117699},{"tv":14254.97,"batb":[[2,3.35,164.82],[1,3.4,94.79],[0,3.45,86.45]],"trd":[[3.5,724.76]],"atb":[[3.5,0]],"atl":[[3.5,15.11]],"batl":[[2,3.6,84.1],[1,3.55,48.66],[0,3.5,15.11]],"id":88302242},{"batb":[[0,11,20.14]],"atb":[[11,20.14]],"id":97736949},{"batb":[[0,160,2.93]],"atb":[[160,2.93],[130,1.77]],"id":99072897}],"tv":40751.94}],"rt":639159132560600398,"dt":639159132560601339}
{"op":"mcm","id":2,"clk":"AMy/AQCZgQEAkfAB","pt":1780316456154,"mc":[{"id":"1.258742455","rc":[{"batb":[[1,46,11.63]],"atb":[[46,11.63]],"atl":[[50,10.06]],"batl":[[0,50,10.06]],"id":97008932},{"batb":[[1,8.2,24.78]],"atb":[[8.2,24.78]],"atl":[[8.6,3.14]],"batl":[[0,8.6,3.14]],"id":98117699},{"atl":[[3.55,52.08]],"batl":[[1,3.55,52.08]],"id":88302242},{"batb":[[0,11,23.24]],"atb":[[11,23.24]],"atl":[[11.5,22.36]],"batl":[[0,11.5,22.36]],"id":97736949},{"batb":[[1,150,3.98]],"atb":[[150,3.98]],"id":99072897}]}],"rt":639159132561620915,"dt":639159132561621416}
{"op":"mcm","id":2,"clk":"ANO/AQCegQEAmvAB","pt":1780316456263,"mc":[{"id":"1.258742455","rc":[{"tv":8852.95,"batb":[[2,4.7,98.28],[1,4.8,50.38],[0,4.9,55.29]],"trd":[[5,330.19]],"atb":[[5,0]],"atl":[[5,4.23]],"batl":[[2,5.2,27.03],[1,5.1,43.1],[0,5,4.23]],"id":99072898},{"batb":[[2,19.5,23.22],[0,21,5.86]],"atb":[[21,5.86],[19,24.99],[19.5,23.22]],"id":99072900},{"batb":[[0,100,3.92]],"atb":[[100,3.92]],"id":99072901},{"atl":[[5,54.68],[5.1,118.59]],"batl":[[1,5.1,118.59],[0,5,54.68]],"id":10398159},{"batb":[],"atb":[[44,21.06],[40,8.86]],"atl":[[60,0.09]],"batl":[[0,65,25.68]],"id":98464183},{"tv":2568.19,"batb":[[2,7.8,22.37],[1,8,58.67],[0,8.2,24.78]],"trd":[[8.4,18.32]],"ltp":8.4,"atb":[[8.4,0]],"atl":[[8.4,3.95]],"batl":[[2,8.8,10.05],[1,8.6,3.14],[0,8.4,3.95]],"id":98117699},{"tv":14263.53,"batb":[[0,3.45,78.05]],"trd":[[3.5,733.32]],"atb":[[3.05,377.99],[3.1,2.94],[3.45,78.05]],"atl":[[3.5,10.83],[3.55,59.09],[3.8,16.19],[3.7,298.14]],"batl":[[1,3.55,59.09],[0,3.5,10.83]],"id":88302242},{"batb":[],"atb":[[700,1.29],[630,2]],"id":10445502}],"tv":40827.5}],"rt":639159132562716297,"dt":639159132562717112}
{"op":"mcm","id":2,"clk":"ANm/AQCigQEAnfAB","pt":1780316456355,"mc":[{"id":"1.258742455","rc":[{"batb":[[0,4.9,57.77]],"atb":[[4.9,57.77]],"id":99072898},{"batb":[[0,21,10.68]],"atb":[[21,10.68]],"id":99072900},{"batb":[[0,4.9,127.52]],"atb":[[4.4,168.8],[4.9,127.52]],"atl":[[5.4,50.44],[5.3,43.59]],"batl":[],"id":10398159},{"batb":[[0,55,8.99]],"atb":[[55,8.99]],"id":98464183},{"atl":[[8.6,6.25]],"batl":[[1,8.6,6.25]],"id":98117699},{"batb":[[0,3.45,58.73]],"atb":[[3.3,59.99],[3.45,58.73]],"id":88302242}]}],"rt":639159132563632354,"dt":639159132563632897}
{"op":"mcm","id":2,"clk":"AOW/AQCmgQEApvAB","pt":1780316456459,"mc":[{"id":"1.258742455","rc":[{"atl":[[5,14]],"batl":[[0,5,14]],"id":99072898},{"batb":[[1,46,13.36]],"atb":[[46,13.36]],"id":97008932},{"batb":[[1,20,23.63]],"atb":[[20,23.63]],"id":99072900},{"batb":[[0,100,3.97]],"atb":[[100,3.97]],"id":99072901},{"batb":[[0,4.9,136.27]],"atb":[[4.4,78.3],[4.9,136.27]],"atl":[[5.2,22.44],[5.1,137.98]],"batl":[[2,5.2,22.44],[1,5.1,137.98]],"id":10398159},{"batb":[[0,8.2,23.78]],"atb":[[7.6,142.56],[8.2,23.78]],"atl":[[8.6,8.86]],"batl":[[1,8.6,8.86]],"id":98117699},{"tv":14269.57,"batb":[[2,3.4,94.79],[1,3.45,58.73],[0,3.5,10.51]],"trd":[[3.55,1031.05]],"ltp":3.55,"atb":[[3.5,10.51]],"atl":[[3.5,0],[3.55,52.65]],"batl":[[2,3.65,49.01],[1,3.6,84.1],[0,3.55,52.65]],"id":88302242}],"tv":40833.54}],"rt":639159132564676736,"dt":639159132564677366}
{"op":"mcm","id":2,"clk":"APO/AQCrgQEAq/AB","pt":1780316456565,"mc":[{"id":"1.258742455","rc":[{"atl":[[5.4,46.28]],"batl":[],"id":99072898},{"batb":[[2,19.5,24.95],[1,20,21.9],[0,21,11.54]],"atb":[[21,11.54],[20,21.9],[19.5,24.95]],"id":99072900},{"batb":[[0,100,5.79]],"atb":[[100,5.79]],"id":99072901},{"batb":[[0,4.9,152.27]],"atb":[[4.4,67.3],[4.9,152.27]],"atl":[[5.4,56.44]],"batl":[],"id":10398159},{"atl":[[60,0.35]],"batl":[[0,65,25.94]],"id":98464183},{"batb":[],"atb":[[7.6,142.27],[7.4,66.9]],"id":98117699},{"tv":14278.81,"batb":[[1,3.45,56.87],[0,3.5,8.91]],"trd":[[3.5,736.52],[3.55,1037.09]],"atb":[[3.5,8.91],[3.25,21.35],[3.45,56.87]],"atl":[[3.75,59.84],[3.55,49.63]],"batl":[[0,3.55,49.63]],"id":88302242},{"batb":[[0,11,31.06]],"atb":[[11,31.06]],"id":97736949},{"batb":[[0,160,4.75]],"atb":[[160,4.75]],"id":99072897}],"tv":40842.78}],"rt":639159132565727891,"dt":639159132565728544}
{"op":"mcm","id":2,"clk":"APa/AQCugQEAs/AB","pt":1780316456616,"mc":[{"id":"1.258742455","rc":[{"batb":[],"atb":[[4.5,151.98]],"atl":[[5,56.83]],"batl":[[0,5,56.83]],"id":10398159},{"batb":[[1,150,5.71]],"atb":[[150,5.71]],"atl":[[180,1.73]],"batl":[[0,180,1.73]],"id":99072897}]}],"rt":639159132566240058,"dt":639159132566240466}
{"op":"mcm","id":2,"clk":"AP\u002B/AQCygQEAuPAB","pt":1780316456716,"mc":[{"id":"1.258742455","rc":[{"atl":[[5,14.49]],"batl":[[0,5,14.49]],"id":99072898},{"batb":[[0,100,5.82]],"atb":[[100,5.82]],"id":99072901},{"atl":[[5,47.63]],"batl":[[0,5,47.63]],"id":10398159},{"atl":[[60,0.56]],"batl":[[0,65,26.15]],"id":98464183},{"atl":[[9.4,26.32]],"batl":[],"id":98117699},{"atl":[[3.55,66.19]],"batl":[[0,3.55,66.19]],"id":88302242}]}],"rt":639159132567245019,"dt":639159132567245462}
{"op":"mcm","id":2,"clk":"AITAAQC2gQEAvfAB","pt":1780316456820,"mc":[{"id":"1.258742455","rc":[{"batb":[[0,4.9,153.2]],"atb":[[4.9,153.2]],"atl":[[5,48.09]],"batl":[[0,5,48.09]],"id":10398159},{"batb":[[0,8.2,22.23]],"atb":[[7.4,72.9],[8.2,22.23]],"id":98117699},{"atl":[[3.7,304.14]],"batl":[],"id":88302242}]}],"rt":639159132568280200,"dt":639159132568280620}
{"op":"mcm","id":2,"clk":"AIzAAQC7gQEAxvAB","pt":1780316456927,"mc":[{"id":"1.258742455","rc":[{"atl":[[5,45.94]],"batl":[[0,5,45.94]],"id":10398159},{"atl":[[9.4,25.32],[9.2,32.23]],"batl":[],"id":98117699},{"tv":14279.39,"batb":[[0,3.5,8.62]],"trd":[[3.5,737.1]],"ltp":3.5,"atb":[[3.5,8.62]],"id":88302242}],"tv":40843.36}],"rt":639159132569356470,"dt":639159132569356956}
{"op":"mcm","id":2,"clk":"AJLAAQDAgQEA0PAB","pt":1780316457028,"mc":[{"id":"1.258742455","rc":[{"batb":[],"atb":[[75,4.82]],"id":99072901},{"atl":[[3.55,71.19]],"batl":[[0,3.55,71.19]],"id":88302242},{"batb":[[0,11,31.69]],"atb":[[11,31.69]],"id":97736949},{"atl":[[190,7.34]],"batl":[[1,190,7.34]],"id":99072897}]}],"rt":639159132570363767,"dt":639159132570364218}
{"op":"mcm","id":2,"clk":"AJrAAQDHgQEA2PAB","pt":1780316457142,"mc":[{"id":"1.258742455","rc":[{"tv":564.17,"batb":[[0,48,6.8]],"trd":[[48,57.82]],"ltp":48,"atb":[[48,6.8]],"id":97008932},{"tv":8766.13,"batb":[[0,4.9,153.03]],"trd":[[4.9,427.62]],"atb":[[4.9,153.03]],"atl":[[5,46.87]],"batl":[[0,5,46.87]],"id":10398159},{"batb":[],"atb":[[3.25,15.35]],"id":88302242}],"tv":40845.7}],"rt":639159132571502485,"dt":639159132571503002}
{"op":"mcm","id":2,"clk":"AJzAAQDNgQEA4fAB","pt":1780316457234,"mc":[{"id":"1.258742455","rc":[{"atl":[[50,10.27]],"batl":[[0,50,10.27]],"id":97008932},{"batb":[[1,95,4.62]],"atb":[[95,4.62]],"id":99072901},{"batb":[[1,4.8,173.98]],"atb":[[4.8,173.98]],"atl":[[5,46.45]],"batl":[[0,5,46.45]],"id":10398159},{"atl":[[1000,6.55],[8.8,9.82],[8.6,8.69]],"batl":[[2,8.8,9.82],[1,8.6,8.69]],"id":98117699},{"atl":[[3.55,71.04],[3.6,83.9]],"batl":[[1,3.6,83.9],[0,3.55,71.04]],"id":88302242},{"batb":[[0,11,29.64]],"atb":[[11,29.64]],"id":97736949}]}],"rt":639159132572425472,"dt":639159132572425976}
{"op":"mcm","id":2,"clk":"AKXAAQDTgQEA6/AB","pt":1780316457341,"mc":[{"id":"1.258742455","rc":[{"batb":[],"atb":[[75,5.54]],"id":99072901},{"batb":[[0,55,9.02]],"atb":[[55,9.02],[44,18.52]],"id":98464183},{"atl":[[1000,6.25],[8.4,0]],"batl":[[2,9,12.82],[1,8.8,9.82],[0,8.6,8.69]],"id":98117699},{"batb":[],"atb":[[3.3,65.99]],"atl":[[3.7,298.14]],"batl":[],"id":88302242}]}],"rt":639159132573493254,"dt":639159132573493692}
{"op":"mcm","id":2,"clk":"AKnAAQDYgQEA9vAB","pt":1780316457442,"mc":[{"id":"1.258742455","rc":[{"atl":[[5,47.42]],"batl":[[0,5,47.42]],"id":10398159},{"batb":[],"atb":[[7.6,146.43]],"atl":[[8.4,0.13],[8.6,8.86]],"batl":[[0,8.6,8.99]],"id":98117699}]}],"rt":639159132574503540,"dt":639159132574503935}
{"op":"mcm","id":2,"clk":"ALHAAQDggQEAiPEB","pt":1780316457648,"mc":[{"id":"1.258742455","rc":[{"atl":[[3.75,65.84]],"batl":[],"id":88302242}]}],"rt":639159132576559234,"dt":639159132576559627}
{"op":"mcm","id":2,"clk":"ALTAAQDlgQEAj/EB","pt":1780316457745,"mc":[{"id":"1.258742455","rc":[{"atl":[[5,14.83]],"batl":[[0,5,14.83]],"id":99072898},{"batb":[[0,4.9,152.1]],"atb":[[4.9,152.1]],"id":10398159},{"atl":[[9.2,26.23]],"batl":[],"id":98117699}]}],"rt":639159132577536035,"dt":639159132577536384}
{"op":"mcm","id":2,"clk":"ALnAAQDqgQEAmvEB","pt":1780316457849,"mc":[{"id":"1.258742455","rc":[{"atb":[[3.3,2.17]],"id":97736949}]}],"rt":639159132578575207,"dt":639159132578575521}
{"op":"mcm","id":2,"clk":"AL/AAQDvgQEApfEB","pt":1780316457953,"mc":[{"id":"1.258742455","rc":[{"atl":[[9.4,31.32]],"batl":[],"id":98117699}]}],"rt":639159132579610322,"dt":639159132579610630}
{"op":"mcm","id":2,"clk":"AMHAAQDygQEArvEB","pt":1780316458051,"mc":[{"id":"1.258742455","rc":[{"batb":[[0,4.9,151.71]],"atb":[[4.9,151.71]],"atl":[[5,49.1]],"batl":[[0,5,49.1]],"id":10398159}]}],"rt":639159132580596861,"dt":639159132580597224}
{"op":"mcm","id":2,"clk":"AMXAAQD6gQEAuPEB","pt":1780316458162,"mc":[{"id":"1.258742455","rc":[{"batb":[[0,4.9,56.79]],"atb":[[4.9,56.79]],"id":99072898}]}],"rt":639159132581705631,"dt":639159132581706079}
{"op":"mcm","id":2,"clk":"ANLAAQCBggEAzfEB","pt":1780316458363,"mc":[{"id":"1.258742455","rc":[{"atl":[[5,57.1]],"batl":[[0,5,57.1]],"id":10398159}]}],"rt":639159132583714710,"dt":639159132583715070}
{"op":"mcm","id":2,"clk":"ANzAAQCOggEA4PEB","pt":1780316458517,"mc":[{"id":"1.258742455","rc":[{"atl":[[24,9.93]],"batl":[[1,24,9.93]],"id":99072900},{"atl":[[5,69.32]],"batl":[[0,5,69.32]],"id":10398159},{"atb":[[2,27.01]],"id":99072897}]}],"rt":639159132585251841,"dt":639159132585252206}
{"op":"mcm","id":2,"clk":"AOHAAQCRggEA5fEB","pt":1780316458617,"mc":[{"id":"1.258742455","rc":[{"batb":[[0,160,5.3]],"atb":[[170,0.55]],"id":99072897}]}],"rt":639159132586251438,"dt":639159132586251794}
{"op":"mcm","id":2,"clk":"AOXAAQCXggEA6/EB","pt":1780316458721,"mc":[{"id":"1.258742455","rc":[{"tv":262.79,"batb":[[0,160,4.88]],"trd":[[170,30.08]],"atb":[[170,0.13]],"id":99072897}],"tv":40846.54}],"rt":639159132587289533,"dt":639159132587289978}
{"op":"mcm","id":2,"clk":"AO/AAQCbggEA9PEB","pt":1780316458825,"mc":[{"id":"1.258742455","rc":[{"tv":8878.89,"trd":[[5,356.13]],"atl":[[5,1.86]],"batl":[[0,5,1.86]],"id":99072898},{"batb":[],"atb":[[44,17.3]],"id":98464183},{"tv":263.03,"batb":[[0,160,4.76]],"trd":[[170,30.32]],"atb":[[170,0.01]],"id":99072897}],"tv":40872.72}],"rt":639159132588329487,"dt":639159132588329921}
{"op":"mcm","id":2,"clk":"APTAAQCgggEA/vEB","pt":1780316458925,"mc":[{"id":"1.258742455","rc":[{"atl":[[5,0.83]],"batl":[[2,5.3,21.15],[1,5.2,27.03],[0,5.1,43.93]],"id":99072898},{"atl":[[5,71.97]],"batl":[[0,5,71.97]],"id":10398159},{"batb":[[2,3.35,164.82],[1,3.4,94.79],[0,3.45,56.87]],"atb":[[3.5,0]],"id":88302242},{"tv":263.05,"batb":[[0,160,4.66]],"trd":[[170,30.34]],"atb":[[170,0],[160,4.66]],"id":99072897}],"tv":40872.74}],"rt":639159132589330612,"dt":639159132589331117}
{"op":"mcm","id":2,"clk":"APjAAQCjggEAg/IB","pt":1780316459026,"mc":[{"id":"1.258742455","rc":[{"batb":[[0,4.9,58.76]],"atb":[[4.9,58.76]],"atl":[[5.4,43.88],[5,0]],"batl":[[0,5.1,43.1]],"id":99072898},{"batb":[[0,4.9,153.69]],"atb":[[4.9,153.69]],"id":10398159},{"batb":[[0,8.2,23.41]],"atb":[[8.2,23.41]],"id":98117699},{"batb":[[2,3.4,94.79],[1,3.45,56.87],[0,3.5,1.48]],"atb":[[3.5,1.48]],"id":88302242},{"batb":[[0,1000,92.09]],"atb":[[1000,92.09]],"id":10445502}]}],"rt":639159132590343678,"dt":639159132590344176}
{"op":"mcm","id":2,"clk":"APzAAQCpggEAkPIB","pt":1780316459131,"mc":[{"id":"1.258742455","rc":[{"batb":[[1,46,11.63]],"atb":[[46,11.63]],"id":97008932}]}],"rt":639159132591391774,"dt":639159132591392148}
{"op":"mcm","id":2,"clk":"AIPBAQCxggEAmPIB","pt":1780316459235,"mc":[{"id":"1.258742455","rc":[{"atl":[[5.4,37.88]],"batl":[],"id":99072898},{"batb":[[0,4.9,170.18]],"atb":[[4.9,170.18]],"id":10398159}]}],"rt":639159132592430015,"dt":639159132592430389}
{"op":"mcm","id":2,"clk":"AJDBAQC9ggEAqPIB","pt":1780316459438,"mc":[{"id":"1.258742455","rc":[{"batb":[[0,4.9,170.76]],"atb":[[4.9,170.76]],"id":10398159}]}],"rt":639159132594460479,"dt":639159132594460898}
{"op":"mcm","id":2,"clk":"AJbBAQDFggEAtfIB","pt":1780316459542,"mc":[{"id":"1.258742455","rc":[{"atl":[[5.5,40.99]],"batl":[],"id":99072898},{"batb":[],"atb":[[16,5.86]],"id":99072900}]}],"rt":639159132595506224,"dt":639159132595506554}
{"op":"mcm","id":2,"clk":"AKPBAQDWggEAwfIB","pt":1780316459746,"mc":[{"id":"1.258742455","rc":[{"tv":2568.45,"batb":[[0,8.2,24.28]],"trd":[[8.4,18.58]],"atb":[[8.4,0.87]],"atl":[[8.4,0]],"batl":[[0,8.6,8.86]],"id":98117699}],"tv":40873}],"rt":639159132597540334,"dt":639159132597540800}
{"op":"mcm","id":2,"clk":"AKbBAQDfggEAyfIB","pt":1780316459850,"mc":[{"id":"1.258742455","rc":[{"batb":[[1,20,23.6]],"atb":[[20,23.6]],"id":99072900}]}],"rt":639159132598579159,"dt":639159132598579524}
{"op":"mcm","id":2,"clk":"ALbBAQD5ggEA6/IB","pt":1780316460161,"mc":[{"id":"1.258742455","rc":[{"batb":[[2,140,2.74]],"atb":[[140,2.74]],"id":99072897}]}],"rt":639159132601695445,"dt":639159132601695771}
{"op":"mcm","id":2,"clk":"AL3BAQCCgwEA8fIB","pt":1780316460267,"mc":[{"id":"1.258742455","rc":[{"atl":[[5,5.07]],"batl":[[2,5.2,27.03],[1,5.1,43.1],[0,5,5.07]],"id":99072898},{"batb":[],"atb":[[19,26.05]],"id":99072900},{"atl":[[60,0.76]],"batl":[[0,65,26.35]],"id":98464183},{"atb":[[1.17,2.84]],"id":98117699},{"atb":[[1.17,196.7]],"id":88302242},{"batb":[[1,150,6.71]],"atb":[[150,6.71]],"id":99072897}]}],"rt":639159132602749856,"dt":639159132602750346}
{"op":"mcm","id":2,"clk":"AMfBAQCEgwEA\u002B/IB","pt":1780316460324,"mc":[{"id":"1.258742455","rc":[{"atb":[[1.17,2]],"id":98117699},{"batb":[[0,3.5,1.69]],"atb":[[3.5,1.69]],"id":88302242}]}],"rt":639159132603324976,"dt":639159132603325343}
{"op":"mcm","id":2,"clk":"AMzBAQCLgwEAhfMB","pt":1780316460416,"mc":[{"id":"1.258742455","rc":[{"batb":[[0,4.9,58.9]],"atb":[[4.9,58.9]],"atl":[[5.4,40.26]],"batl":[],"id":99072898},{"batb":[[0,8.2,25.12]],"atb":[[8.2,24.25]],"id":98117699},{"atb":[[1.17,196.12]],"id":88302242}]}],"rt":639159132604247815,"dt":639159132604248269}
{"op":"mcm","id":2,"clk":"ANPBAQCVgwEAjPMB","pt":1780316460525,"mc":[{"id":"1.258742455","rc":[{"atl":[[5,5.35]],"batl":[[0,5,5.35]],"id":99072898},{"tv":14283.93,"batb":[[2,3.35,164.82],[1,3.4,94.79],[0,3.45,56.87]],"trd":[[3.5,741.64]],"atb":[[3.5,0]],"atl":[[3.5,2.73]],"batl":[[2,3.6,83.9],[1,3.55,71.04],[0,3.5,2.73]],"id":88302242},{"tv":193.12,"batb":[[0,1000,91.09]],"trd":[[1000,148.64]],"atb":[[1000,91.09]],"id":10445502}],"tv":40879.54}],"rt":639159132605335182,"dt":639159132605335678}
{"op":"mcm","id":2,"clk":"ANrBAQCZgwEAlfMB","pt":1780316460621,"mc":[{"id":"1.258742455","rc":[{"atl":[[5.5,34.99]],"batl":[],"id":99072898},{"batb":[[1,20,25.33]],"atb":[[20,25.33]],"id":99072900},{"batb":[[0,4.9,171.37]],"atb":[[4.9,171.37]],"id":10398159},{"tv":14285.93,"trd":[[3.5,743.64]],"atl":[[3.5,1.73],[3.55,74.42]],"batl":[[1,3.55,74.42],[0,3.5,1.73]],"id":88302242}],"tv":40881.54}],"rt":639159132606299408,"dt":639159132606300087}
{"op":"mcm","id":2,"clk":"AOTBAQClgwEAo/MB","pt":1780316460828,"mc":[{"id":"1.258742455","rc":[{"atl":[[8.8,11.48]],"batl":[[1,8.8,11.48]],"id":98117699},{"tv":14289.39,"trd":[[3.5,747.1]],"atl":[[3.5,0]],"batl":[[2,3.65,49.01],[1,3.6,83.9],[0,3.55,74.42]],"id":88302242}],"tv":40885}],"rt":639159132608363365,"dt":639159132608363858}
{"op":"mcm","id":2,"clk":"AOfBAQCqgwEAqvMB","pt":1780316460932,"mc":[{"id":"1.258742455","rc":[{"atl":[[5.4,46.26],[5,5.07]],"batl":[[0,5,5.07]],"id":99072898},{"batb":[[1,20,23.6]],"atb":[[20,23.6]],"id":99072900},{"tv":14292.85,"batb":[[0,3.45,79.69]],"trd":[[3.55,1040.55]],"ltp":3.55,"atb":[[3.3,59.99],[3.45,79.69]],"atl":[[3.75,59.84],[3.55,69.31]],"batl":[[0,3.55,69.31]],"id":88302242}],"tv":40888.46}],"rt":639159132609397494,"dt":639159132609398060}
{"op":"mcm","id":2,"clk":"AOvBAQCugwEAr/MB","pt":1780316461030,"mc":[{"id":"1.258742455","rc":[{"atb":[[3.75,14.54]],"id":10398159},{"atl":[[65,26.79]],"batl":[[0,65,27.55]],"id":98464183},{"batb":[[2,3.4,94.79],[1,3.45,79.69],[0,3.5,16.17]],"atb":[[3.5,16.17]],"id":88302242}]}],"rt":639159132610378365,"dt":639159132610378771}
{"op":"mcm","id":2,"clk":"APTBAQC5gwEAt/MB","pt":1780316461145,"mc":[{"id":"1.258742455","rc":[{"atl":[[5,5.44]],"batl":[[0,5,5.44]],"id":99072898},{"batb":[[0,4.9,170.18]],"atb":[[4.9,170.18]],"id":10398159},{"batb":[],"atb":[[3.25,21.35]],"atl":[[3.7,304.14]],"batl":[],"id":88302242}]}],"rt":639159132611535832,"dt":639159132611536329}
{"op":"mcm","id":2,"clk":"APfBAQC9gwEAv/MB","pt":1780316461236,"mc":[{"id":"1.258742455","rc":[{"batb":[],"atb":[[4.6,77.07]],"id":99072898},{"batb":[],"atb":[[44,5.67]],"id":98464183},{"batb":[],"atb":[[670,2],[630,0]],"id":10445502}]}],"rt":639159132612441780,"dt":639159132612442262}
{"op":"mcm","id":2,"clk":"APrBAQDBgwEAxfMB","pt":1780316461342,"mc":[{"id":"1.258742455","rc":[{"atl":[[5,5.79]],"batl":[[0,5,5.79]],"id":99072898},{"batb":[],"atb":[[42,18.96]],"id":98464183},{"atl":[[3.55,70.14]],"batl":[[0,3.55,70.14]],"id":88302242}]}],"rt":639159132613503927,"dt":639159132613504379}
{"op":"mcm","id":2,"clk":"AILCAQDJgwEAzPMB","pt":1780316461442,"mc":[{"id":"1.258742455","rc":[{"atl":[[5.3,70.33]],"batl":[],"id":10398159}]}],"rt":639159132614501214,"dt":639159132614501544}
{"op":"mcm","id":2,"clk":"AIrCAQDPgwEA0/MB","pt":1780316461545,"mc":[{"id":"1.258742455","rc":[{"batb":[],"atb":[[19,34.09]],"id":99072900},{"atl":[[5,72.42]],"batl":[[0,5,72.42]],"id":10398159},{"tv":14293.43,"batb":[[0,3.5,15.88]],"trd":[[3.5,747.68]],"ltp":3.5,"atb":[[3.5,15.88]],"id":88302242}],"tv":40889.04}],"rt":639159132615529419,"dt":639159132615529982}
{"op":"mcm","id":2,"clk":"AJTCAQDYgwEA2fMB","pt":1780316461649,"mc":[{"id":"1.258742455","rc":[{"tv":8766.49,"batb":[[0,4.9,170]],"trd":[[4.9,427.98]],"atb":[[4.9,170]],"id":10398159},{"batb":[],"atb":[[3.25,15.35]],"atl":[[3.55,70.35],[3.7,298.14]],"batl":[[0,3.55,70.35]],"id":88302242}],"tv":40889.4}],"rt":639159132616568985,"dt":639159132616569524}
{"op":"mcm","id":2,"clk":"AJjCAQDcgwEA4/MB","pt":1780316461745,"mc":[{"id":"1.258742455","rc":[{"atl":[[25,9.91]],"batl":[[2,25,9.91]],"id":99072900},{"batb":[[1,3.45,84.37]],"atb":[[3.45,84.37]],"id":88302242}]}],"rt":639159132617533354,"dt":639159132617533783}
{"op":"mcm","id":2,"clk":"AJvCAQDfgwEA6/MB","pt":1780316461850,"mc":[{"id":"1.258742455","rc":[{"batb":[[0,55,9.04]],"atb":[[55,9.04]],"id":98464183},{"batb":[],"atb":[[3.3,65.99]],"atl":[[3.75,65.84]],"batl":[],"id":88302242}]}],"rt":639159132618576681,"dt":639159132618577129}
{"op":"mcm","id":2,"clk":"AKPCAQDkgwEA8PMB","pt":1780316461952,"mc":[{"id":"1.258742455","rc":[{"atl":[[5.2,27.03]],"batl":[[2,5.2,27.03]],"id":10398159}]}],"rt":639159132619600799,"dt":639159132619601511}
{"op":"mcm","id":2,"clk":"AKfCAQDqgwEA\u002BfMB","pt":1780316462056,"mc":[{"id":"1.258742455","rc":[{"atl":[[26,11.55]],"batl":[],"id":99072900}]}],"rt":639159132620643511,"dt":639159132620643954}
{"op":"mcm","id":2,"clk":"AKrCAQDrgwEAgfQB","pt":1780316462156,"mc":[{"id":"1.258742455","rc":[{"batb":[[1,4.8,175.98]],"atb":[[4.8,175.98]],"id":10398159}]}],"rt":639159132621643422,"dt":639159132621643819}
{"op":"mcm","id":2,"clk":"ALjCAQD2gwEAkvQB","pt":1780316462312,"mc":[{"id":"1.258742455","rc":[{"atl":[[5.7,9.63]],"batl":[],"id":99072898},{"batb":[[2,4.7,75.26]],"atb":[[4.7,75.26]],"id":10398159}]}],"rt":639159132623204396,"dt":639159132623204883}
{"op":"mcm","id":2,"clk":"ANDCAQCLhAEApPQB","pt":1780316462626,"mc":[{"id":"1.258742455","rc":[{"batb":[[2,4.7,68.26]],"atb":[[4.7,68.26]],"id":10398159},{"batb":[[0,55,9.24]],"atb":[[55,9.24]],"id":98464183},{"batb":[[0,160,4.73]],"atb":[[160,4.73]],"id":99072897}]}],"rt":639159132626339197,"dt":639159132626339591}
{"op":"mcm","id":2,"clk":"ANTCAQCPhAEAqfQB","pt":1780316462724,"mc":[{"id":"1.258742455","rc":[{"batb":[[0,48,6]],"atb":[[48,6]],"atl":[[55,23.06]],"batl":[[1,55,23.06]],"id":97008932},{"batb":[[0,8.2,24.28]],"atb":[[1.17,2.3],[8.2,23.41]],"id":98117699},{"atl":[[1000,3.86]],"id":88302242}]}],"rt":639159132627319348,"dt":639159132627320360}
{"op":"mcm","id":2,"clk":"ANbCAQCVhAEArvQB","pt":1780316462826,"mc":[{"id":"1.258742455","rc":[{"atl":[[5,2.75]],"batl":[[0,5,2.75]],"id":99072898},{"atl":[[38,3.7]],"id":99072900},{"tv":418.46,"batb":[[0,100,3.82]],"trd":[[100,36.67]],"atb":[[100,3.82]],"id":99072901},{"atl":[[1000,6.87],[8.6,8.69]],"batl":[[0,8.6,8.69]],"id":98117699}],"tv":40893.4}],"rt":639159132628345438,"dt":639159132628346053}
{"op":"mcm","id":2,"clk":"ANzCAQCahAEAt/QB","pt":1780316462930,"mc":[{"id":"1.258742455","rc":[{"atb":[[1.17,2]],"id":98117699},{"atl":[[1000,3]],"id":88302242}]}],"rt":639159132629380356,"dt":639159132629380759}
{"op":"mcm","id":2,"clk":"AODCAQCchAEAwPQB","pt":1780316463033,"mc":[{"id":"1.258742455","rc":[{"batb":[],"atb":[[4.6,72.32]],"atl":[[5,2.03]],"batl":[[0,5,2.03]],"id":99072898},{"batb":[[0,100,3.74]],"atb":[[100,3.74]],"id":99072901},{"batb":[[2,8,58.67],[1,8.2,23.41],[0,8.4,1.17]],"atb":[[8.4,1.17]],"atl":[[1000,6.25]],"id":98117699},{"atl":[[3.55,71.21]],"batl":[[0,3.55,71.21]],"id":88302242},{"tv":195.12,"batb":[[0,1000,90.09]],"trd":[[1000,150.64]],"atb":[[1000,90.09]],"id":10445502}],"tv":40895.4}],"rt":639159132630413083,"dt":639159132630413726}
{"op":"mcm","id":2,"clk":"AOnCAQCghAEAxPQB","pt":1780316463136,"mc":[{"id":"1.258742455","rc":[{"atl":[[8.8,12.1]],"batl":[[1,8.8,12.1]],"id":98117699}]}],"rt":639159132631442500,"dt":639159132631442950}
{"op":"mcm","id":2,"clk":"AO3CAQCihAEAy/QB","pt":1780316463237,"mc":[{"id":"1.258742455","rc":[{"tv":421.1,"batb":[[0,100,2.42]],"trd":[[100,39.31]],"atb":[[100,2.42]],"id":99072901}],"tv":40898.04}],"rt":639159132632449500,"dt":639159132632449913}
{"op":"mcm","id":2,"clk":"APXCAQClhAEA1/QB","pt":1780316463341,"mc":[{"id":"1.258742455","rc":[{"tv":424.36,"batb":[[2,85,9.21],[1,90,6.58],[0,95,5.41]],"trd":[[100,42.57]],"atb":[[100,0.79]],"id":99072901},{"atl":[[14,6.64],[13,7.84]],"batl":[],"id":97736949},{"atb":[[1.05,101]],"id":10445502}],"tv":40901.3}],"rt":639159132633494934,"dt":639159132633495462}
{"op":"mcm","id":2,"clk":"APnCAQCrhAEA4fQB","pt":1780316463446,"mc":[{"id":"1.258742455","rc":[{"batb":[[0,95,4.53]],"atb":[[100,0],[95,4.53]],"id":99072901},{"batb":[],"atb":[[7.4,66.9]],"id":98117699},{"batb":[[2,3.35,164.82],[1,3.4,94.79],[0,3.45,84.37]],"atb":[[3.5,0]],"id":88302242},{"atb":[[1.05,100.17]],"id":10445502}]}],"rt":639159132634544307,"dt":639159132634544842}
{"op":"mcm","id":2,"clk":"APzCAQCwhAEA6fQB","pt":1780316463548,"mc":[{"id":"1.258742455","rc":[{"atl":[[110,6.33]],"batl":[[0,110,6.33]],"id":99072901},{"atl":[[5,60.2]],"batl":[[0,5,60.2]],"id":10398159},{"batb":[[0,8.4,12]],"atb":[[8.4,12]],"id":98117699},{"atb":[[1.05,100]],"id":10445502}]}],"rt":639159132635564103,"dt":639159132635564522}
{"op":"mcm","id":2,"clk":"AP7CAQC1hAEA8PQB","pt":1780316463653,"mc":[{"id":"1.258742455","rc":[{"batb":[[0,95,4.13]],"atb":[[95,4.13]],"id":99072901},{"batb":[[0,4.9,170.57]],"atb":[[4.9,170.57]],"id":10398159},{"tv":2572.45,"batb":[[0,8.4,10]],"trd":[[8.4,22.58]],"atb":[[8.4,10],[7.6,152.43]],"id":98117699},{"tv":2600.62,"trd":[[11.5,65.19]],"ltp":11.5,"atl":[[11.5,20.36]],"batl":[[0,11.5,20.36]],"id":97736949},{"batb":[[0,1000,90.26]],"atb":[[1000,90.26]],"id":10445502}],"tv":40909.3}],"rt":639159132636616695,"dt":639159132636617204}
{"op":"mcm","id":2,"clk":"AITDAQC3hAEA9fQB","pt":1780316463754,"mc":[{"id":"1.258742455","rc":[{"atl":[[5,2.81]],"batl":[[0,5,2.81]],"id":99072898},{"batb":[[1,8.2,25.15]],"atb":[[8.2,25.15]],"id":98117699},{"batb":[[0,11,34.17]],"atb":[[11,34.17]],"id":97736949}]}],"rt":639159132637622659,"dt":639159132637623102}
{"op":"mcm","id":2,"clk":"AInDAQC9hAEA/fQB","pt":1780316463856,"mc":[{"id":"1.258742455","rc":[{"batb":[[0,95,4.2]],"atb":[[95,4.2]],"id":99072901},{"atl":[[3.55,81.21]],"batl":[[0,3.55,81.21]],"id":88302242}]}],"rt":639159132638642447,"dt":639159132638642812}
{"op":"mcm","id":2,"clk":"AIvDAQDBhAEAhfUB","pt":1780316463958,"mc":[{"id":"1.258742455","rc":[{"batb":[],"atb":[[3.3,59.99]],"id":88302242},{"tv":2609.22,"trd":[[11.5,73.79]],"atl":[[11.5,16.06]],"batl":[[0,11.5,16.06]],"id":97736949},{"atb":[[2,26.01]],"id":99072897}],"tv":40917.9}],"rt":639159132639659848,"dt":639159132639660248}
{"op":"mcm","id":2,"clk":"AJHDAQDKhAEAivUB","pt":1780316464062,"mc":[{"id":"1.258742455","rc":[{"batb":[[0,4.9,170]],"atb":[[4.9,170]],"atl":[[5.3,43.59]],"batl":[],"id":10398159}]}],"rt":639159132640703779,"dt":639159132640704165}
{"op":"mcm","id":2,"clk":"AJXDAQDOhAEAjfUB","pt":1780316464111,"mc":[{"id":"1.258742455","rc":[{"batb":[],"atb":[[3.25,21.35]],"id":88302242},{"atl":[[11.5,14.28]],"batl":[[0,11.5,14.28]],"id":97736949}]}],"rt":639159132641194526,"dt":639159132641195045}
{"op":"mcm","id":2,"clk":"AJvDAQDXhAEAl/UB","pt":1780316464217,"mc":[{"id":"1.258742455","rc":[{"batb":[[0,4.9,170.57]],"atb":[[4.9,170.57]],"id":10398159},{"batb":[[2,7.8,22.37],[1,8,58.67],[0,8.2,25.15]],"atb":[[8.4,0]],"id":98117699}]}],"rt":639159132642250470,"dt":639159132642250889}
{"op":"mcm","id":2,"clk":"AKTDAQDihAEAo/UB","pt":1780316464420,"mc":[{"id":"1.258742455","rc":[{"batb":[[0,11,35.72]],"atb":[[11,35.72]],"id":97736949}]}],"rt":639159132644292624,"dt":639159132644293029}
{"op":"mcm","id":2,"clk":"ALbDAQD1hAEAuPUB","pt":1780316464730,"mc":[{"id":"1.258742455","rc":[{"batb":[],"atb":[[7.6,146.43]],"id":98117699}]}],"rt":639159132647384242,"dt":639159132647384599}
{"op":"mcm","id":2,"clk":"AMLDAQCIhQEAy/UB","pt":1780316464940,"mc":[{"id":"1.258742455","rc":[{"atl":[[36,3.84]],"id":99072900},{"batb":[],"atb":[[7.4,72.9],[7.2,15.04]],"id":98117699}]}],"rt":639159132649480077,"dt":639159132649480492}
{"op":"mcm","id":2,"clk":"AM3DAQCUhQEA2/UB","pt":1780316465141,"mc":[{"id":"1.258742455","rc":[{"batb":[[0,95,4.33]],"atb":[[95,4.33]],"id":99072901}]}],"rt":639159132651490497,"dt":639159132651490915}
{"op":"mcm","id":2,"clk":"ANLDAQCZhQEA4/UB","pt":1780316465242,"mc":[{"id":"1.258742455","rc":[{"batb":[[0,4.9,171.14]],"atb":[[4.9,171.14]],"id":10398159},{"tv":14301.43,"batb":[[0,3.45,80.37]],"trd":[[3.45,88.48]],"ltp":3.45,"atb":[[3.45,80.37]],"id":88302242},{"tv":197.12,"batb":[[0,1000,89.26]],"trd":[[1000,152.64]],"atb":[[1000,89.26]],"id":10445502}],"tv":40927.9}],"rt":639159132652501486,"dt":639159132652501880}
{"op":"mcm","id":2,"clk":"ANfDAQCehQEA8/UB","pt":1780316465345,"mc":[{"id":"1.258742455","rc":[{"atl":[[5,3.31]],"batl":[[0,5,3.31]],"id":99072898},{"batb":[[0,4.9,171.28]],"atb":[[4.9,171.28]],"id":10398159},{"atl":[[3.5,17.61]],"batl":[[2,3.6,83.9],[1,3.55,81.21],[0,3.5,17.61]],"id":88302242}]}],"rt":639159132653531879,"dt":639159132653532272}
{"op":"mcm","id":2,"clk":"AN3DAQChhQEA//UB","pt":1780316465451,"mc":[{"id":"1.258742455","rc":[{"tv":8885.51,"batb":[[2,4.8,50.38],[1,4.9,58.9],[0,5,4.69]],"trd":[[5,362.75]],"atb":[[5,4.69]],"atl":[[5,0]],"batl":[[2,5.3,21.15],[1,5.2,27.03],[0,5.1,43.1]],"id":99072898},{"batb":[[1,20,25.33]],"atb":[[20,25.33]],"id":99072900},{"atl":[[3.55,84.56]],"batl":[[1,3.55,84.56]],"id":88302242}],"tv":40934.52}],"rt":639159132654591185,"dt":639159132654591675}
{"op":"mcm","id":2,"clk":"AOjDAQCnhQEAjfYB","pt":1780316465555,"mc":[{"id":"1.258742455","rc":[{"batb":[],"atb":[[4.7,102.28]],"atl":[[5.4,43.88]],"batl":[],"id":99072898},{"batb":[[1,20,23.6]],"atb":[[20,23.6]],"id":99072900},{"batb":[[0,4.9,172.33]],"atb":[[4.9,172.33]],"id":10398159},{"tv":14305.61,"batb":[[0,3.45,52.87]],"trd":[[3.5,751.86]],"ltp":3.5,"atb":[[3.45,52.87]],"atl":[[3.5,19.27]],"batl":[[0,3.5,19.27]],"id":88302242}],"tv":40938.7}],"rt":639159132655636604,"dt":639159132655637082}
{"op":"mcm","id":2,"clk":"AO3DAQCphQEAlvYB","pt":1780316465654,"mc":[{"id":"1.258742455","rc":[{"tv":14309.79,"batb":[[0,3.45,45.16]],"trd":[[3.5,756.04]],"atb":[[3.45,45.16]],"atl":[[3.5,29.18]],"batl":[[0,3.5,29.18]],"id":88302242}],"tv":40942.88}],"rt":639159132656620749,"dt":639159132656621189}
{"op":"mcm","id":2,"clk":"APjDAQCshQEAnfYB","pt":1780316465755,"mc":[{"id":"1.258742455","rc":[{"atl":[[5.4,37.88]],"batl":[],"id":99072898},{"atb":[[1.17,2.12]],"id":98464183},{"tv":14313.97,"trd":[[3.5,760.22]],"atl":[[3.75,59.84],[3.5,27.09]],"batl":[[0,3.5,27.09]],"id":88302242},{"batb":[[0,11,39.3]],"atb":[[11,39.3]],"id":97736949}],"tv":40947.06}],"rt":639159132657627433,"dt":639159132657627890}
{"op":"mcm","id":2,"clk":"AP/DAQCthQEAo/YB","pt":1780316465857,"mc":[{"id":"1.258742455","rc":[{"batb":[[0,4.9,184.83]],"atb":[[4.9,184.83]],"atl":[[5.1,140.58]],"batl":[[1,5.1,140.58]],"id":10398159},{"atb":[[1.17,2]],"id":98464183},{"atl":[[9,10.82]],"batl":[[2,9,10.82]],"id":98117699},{"tv":14329.27,"batb":[[0,3.45,39.51]],"trd":[[3.5,775.52]],"atb":[[3.45,39.51]],"atl":[[3.5,19.44],[3.55,82.95],[3.6,85.06]],"batl":[[2,3.6,85.06],[1,3.55,82.95],[0,3.5,19.44]],"id":88302242}],"tv":40962.36}],"rt":639159132658659297,"dt":639159132658659851}
{"op":"mcm","id":2,"clk":"AITEAQC2hQEAqPYB","pt":1780316465960,"mc":[{"id":"1.258742455","rc":[{"batb":[],"atb":[[4.5,41.5]],"atl":[[5.5,40.99]],"batl":[],"id":99072898},{"batb":[[1,4.8,176.98]],"atb":[[4.8,176.98]],"id":10398159},{"batb":[[1,50,21.99]],"atb":[[50,21.99]],"id":98464183},{"tv":2576.45,"batb":[[0,8.2,24.15]],"trd":[[8.2,10]],"ltp":8.2,"atb":[[8.2,24.15],[7.2,16.04]],"atl":[[9,12.49]],"batl":[[2,9,12.49]],"id":98117699},{"tv":14333.49,"trd":[[3.5,779.74]],"atl":[[3.5,17.33],[3.7,304.14]],"batl":[[0,3.5,17.33]],"id":88302242}],"tv":40970.58}],"rt":639159132659683623,"dt":639159132659684206}
{"op":"mcm","id":2,"clk":"AJDEAQC7hQEAs/YB","pt":1780316466063,"mc":[{"id":"1.258742455","rc":[{"batb":[[1,8,62.74]],"atb":[[8,62.74]],"id":98117699}]}],"rt":639159132660709620,"dt":639159132660709959}
{"op":"mcm","id":2,"clk":"AJrEAQDBhQEAt/YB","pt":1780316466114,"mc":[{"id":"1.258742455","rc":[{"batb":[],"atb":[[4.6,78.32]],"id":99072898},{"atl":[[3.5,13.58]],"batl":[[0,3.5,13.58]],"id":88302242}]}],"rt":639159132661225113,"dt":639159132661225537}
{"op":"mcm","id":2,"clk":"AJ/EAQDFhQEAwfYB","pt":1780316466223,"mc":[{"id":"1.258742455","rc":[{"batb":[[0,48,6.21]],"atb":[[48,6.21]],"id":97008932},{"tv":1442.59,"batb":[[0,21,3.74]],"trd":[[21,251.98]],"atb":[[21,3.74]],"id":99072900},{"batb":[[0,95,4.44]],"atb":[[95,4.44]],"id":99072901},{"atl":[[3.5,13.77],[3.6,75.06]],"batl":[[2,3.6,75.06],[0,3.5,13.77]],"id":88302242},{"batb":[[0,11,40.25]],"atb":[[11,40.25]],"id":97736949}],"tv":40987.16}],"rt":639159132662314388,"dt":639159132662314867}
{"op":"mcm","id":2,"clk":"AKrEAQDIhQEAyPYB","pt":1780316466329,"mc":[{"id":"1.258742455","rc":[{"atl":[[5.9,40.73],[5.8,12.64]],"batl":[],"id":99072898},{"atl":[[22,5.57]],"batl":[[2,24,9.93],[1,23,11.47],[0,22,5.57]],"id":99072900},{"batb":[[0,4.9,186.08]],"atb":[[4.9,186.08]],"id":10398159}]}],"rt":639159132663373778,"dt":639159132663374244}
{"op":"mcm","id":2,"clk":"ALTEAQDLhQEA0PYB","pt":1780316466423,"mc":[{"id":"1.258742455","rc":[{"batb":[[2,19,34.09],[1,19.5,24.95],[0,20,24.09]],"atb":[[21,0.49],[1.01,136420.23]],"id":99072900},{"atl":[[5,58.3]],"batl":[[0,5,58.3]],"id":10398159},{"tv":14343.35,"batb":[[0,3.45,34.58]],"trd":[[3.45,98.34]],"ltp":3.45,"atb":[[3.45,34.58]],"atl":[[3.55,77.95]],"batl":[[1,3.55,77.95]],"id":88302242}],"tv":40997.02}],"rt":639159132664311655,"dt":639159132664312281}
{"op":"mcm","id":2,"clk":"AL7EAQDRhQEA1fYB","pt":1780316466529,"mc":[{"id":"1.258742455","rc":[{"batb":[[2,19,27.78],[1,19.5,23.22]],"atb":[[19,27.78],[19.5,23.22]],"id":99072900},{"batb":[[0,3.45,44.45]],"atb":[[3.45,44.45]],"atl":[[3.5,15.3]],"batl":[[0,3.5,15.3]],"id":88302242}]}],"rt":639159132665371179,"dt":639159132665371607}
{"op":"mcm","id":2,"clk":"AMTEAQDahQEA4PYB","pt":1780316466627,"mc":[{"id":"1.258742455","rc":[{"tv":8901.07,"batb":[[2,4.7,102.28],[1,4.8,50.38],[0,4.9,55.81]],"trd":[[4.9,830.87],[5,372.13]],"ltp":4.9,"atb":[[4.9,55.81],[5,0]],"id":99072898},{"tv":1443.57,"batb":[[0,20,23.6]],"trd":[[21,252.96]],"atb":[[21,0]],"atl":[[22,10.53],[21,2.58]],"batl":[[2,23,11.47],[1,22,10.53],[0,21,2.58]],"id":99072900},{"atl":[[5,55.65]],"batl":[[0,5,55.65]],"id":10398159}],"tv":41013.56}],"rt":639159132666355565,"dt":639159132666356079}
{"op":"mcm","id":2,"clk":"AMzEAQDghQEA8vYB","pt":1780316466737,"mc":[{"id":"1.258742455","rc":[{"atl":[[5,22.25]],"batl":[[0,5,22.25]],"id":10398159},{"batb":[[1,8,64.98]],"atb":[[8,64.98]],"id":98117699},{"tv":14373.95,"batb":[[2,3.4,94.79],[1,3.45,44.45],[0,3.5,16.11]],"trd":[[3.5,810.34]],"ltp":3.5,"atb":[[3.5,16.11]],"atl":[[3.5,0],[3.55,74.6]],"batl":[[2,3.65,49.01],[1,3.6,75.06],[0,3.55,74.6]],"id":88302242}],"tv":41044.16}],"rt":639159132667453489,"dt":639159132667453957}
{"op":"mcm","id":2,"clk":"AM/EAQDphQEA9/YB","pt":1780316466839,"mc":[{"id":"1.258742455","rc":[{"atl":[[5,10.79]],"batl":[[2,5.2,27.03],[1,5.1,43.1],[0,5,10.79]],"id":99072898},{"tv":1453.57,"batb":[[2,19,26.05]],"trd":[[22,158.08],[21,258.12]],"ltp":22,"atb":[[19,26.05]],"atl":[[22,6.2],[21,1.25]],"batl":[[1,22,6.2],[0,21,1.25]],"id":99072900},{"batb":[[1,3.45,50.33]],"atb":[[3.45,50.33]],"id":88302242}],"tv":41054.16}],"rt":639159132668471874,"dt":639159132668472421}
{"op":"mcm","id":2,"clk":"ANnEAQDyhQEAgvcB","pt":1780316466945,"mc":[{"id":"1.258742455","rc":[{"atl":[[5.4,40.23],[5.5,49.47],[5,12.54]],"batl":[[0,5,12.54]],"id":99072898},{"tv":1456.59,"batb":[[2,19.5,24.47],[1,20,23.6],[0,21,2.8]],"trd":[[21,261.14]],"ltp":21,"atb":[[21,2.8],[19.5,24.47]],"atl":[[22,8.13],[21,0]],"batl":[[2,24,9.93],[1,23,11.47],[0,22,8.13]],"id":99072900},{"batb":[[0,4.9,188.16]],"atb":[[4.9,188.16]],"atl":[[5,20.26]],"batl":[[0,5,20.26]],"id":10398159}],"tv":41057.18}],"rt":639159132669530015,"dt":639159132669530481}
{"op":"mcm","id":2,"clk":"AN7EAQD9hQEAiPcB","pt":1780316467047,"mc":[{"id":"1.258742455","rc":[{"batb":[],"atb":[[4.6,72.32]],"id":99072898},{"atl":[[3.7,298.14]],"batl":[],"id":88302242}]}],"rt":639159132670550025,"dt":639159132670550422}
{"op":"mcm","id":2,"clk":"AOLEAQCFhgEAjvcB","pt":1780316467146,"mc":[{"id":"1.258742455","rc":[{"atl":[[5.5,43.47]],"batl":[],"id":99072898},{"batb":[],"atb":[[3.25,15.35]],"id":88302242}]}],"rt":639159132671545053,"dt":639159132671545408}
{"op":"mcm","id":2,"clk":"AObEAQCKhgEAlvcB","pt":1780316467248,"mc":[{"id":"1.258742455","rc":[{"batb":[],"atb":[[4.5,47.5]],"id":99072898},{"atl":[[3.75,65.84],[3.55,75.4]],"batl":[[0,3.55,75.4]],"id":88302242}]}],"rt":639159132672561337,"dt":639159132672561769}
{"op":"mcm","id":2,"clk":"AO3EAQCThgEAnPcB","pt":1780316467352,"mc":[{"id":"1.258742455","rc":[{"atl":[[5.4,46.23],[5.5,34.99]],"batl":[],"id":99072898},{"atl":[[5,20.74]],"batl":[[0,5,20.74]],"id":10398159},{"batb":[],"atb":[[3.3,65.99]],"id":88302242}]}],"rt":639159132673598692,"dt":639159132673599073}
{"op":"mcm","id":2,"clk":"APDEAQCYhgEAovcB","pt":1780316467453,"mc":[{"id":"1.258742455","rc":[{"batb":[[2,3.35,164.82],[1,3.4,94.79],[0,3.45,50.33]],"atb":[[3.5,0]],"id":88302242},{"tv":2612.52,"batb":[[0,11,38.6]],"trd":[[11,187.77]],"ltp":11,"atb":[[11,38.6]],"id":97736949}],"tv":41060.48}],"rt":639159132674613820,"dt":639159132674614212}
{"op":"mcm","id":2,"clk":"APLEAQCchgEApvcB","pt":1780316467556,"mc":[{"id":"1.258742455","rc":[{"tv":8766.82,"batb":[[0,4.9,187.99]],"trd":[[4.9,428.31]],"atb":[[4.9,187.99]],"id":10398159}],"tv":41060.81}],"rt":639159132675637521,"dt":639159132675637945}
{"op":"mcm","id":2,"clk":"APvEAQClhgEAr/cB","pt":1780316467661,"mc":[{"id":"1.258742455","rc":[{"atl":[[5,19.06]],"batl":[[0,5,19.06]],"id":10398159},{"batb":[[0,3.45,73.16]],"atb":[[3.45,73.16]],"id":88302242},{"batb":[[0,11,41.78]],"atb":[[11,41.78]],"id":97736949}]}],"rt":639159132676697718,"dt":639159132676698096}
{"op":"mcm","id":2,"clk":"AILFAQCthgEAs/cB","pt":1780316467762,"mc":[{"id":"1.258742455","rc":[{"batb":[[0,55,9.27]],"atb":[[55,9.27]],"id":98464183}]}],"rt":639159132677699145,"dt":639159132677699530}
{"op":"mcm","id":2,"clk":"AIrFAQCvhgEAuvcB","pt":1780316467869,"mc":[{"id":"1.258742455","rc":[{"batb":[],"atb":[[3.3,59.99]],"atl":[[3.5,22]],"batl":[[2,3.6,75.06],[1,3.55,75.4],[0,3.5,22]],"id":88302242}]}],"rt":639159132678770193,"dt":639159132678770590}
{"op":"mcm","id":2,"clk":"AI/FAQC4hgEAwfcB","pt":1780316467972,"mc":[{"id":"1.258742455","rc":[{"batb":[[2,19.5,26.2]],"atb":[[19.5,26.2]],"id":99072900},{"atl":[[5,19.48]],"batl":[[0,5,19.48]],"id":10398159}]}],"rt":639159132679796712,"dt":639159132679797134}
{"op":"mcm","id":2,"clk":"AJPFAQC8hgEAx/cB","pt":1780316468072,"mc":[{"id":"1.258742455","rc":[{"atl":[[5.4,43.88]],"batl":[],"id":99072898},{"atl":[[5,19.06]],"batl":[[0,5,19.06]],"id":10398159},{"tv":14417.95,"batb":[[2,3.4,94.79],[1,3.45,50.33],[0,3.5,1.7]],"trd":[[3.5,854.34]],"atb":[[3.5,1.7],[3.25,21.35],[3.45,50.33]],"atl":[[3.5,0]],"batl":[[2,3.65,49.01],[1,3.6,75.06],[0,3.55,75.4]],"id":88302242}],"tv":41104.81}],"rt":639159132680803009,"dt":639159132680803483}
{"op":"mcm","id":2,"clk":"AJzFAQDDhgEA0vcB","pt":1780316468128,"mc":[{"id":"1.258742455","rc":[{"tv":14421.35,"batb":[[2,3.35,164.82],[1,3.4,94.79],[0,3.45,50.33]],"trd":[[3.5,857.74]],"atb":[[3.5,0]],"atl":[[3.5,5.28]],"batl":[[2,3.6,75.06],[1,3.55,75.4],[0,3.5,5.28]],"id":88302242}],"tv":41108.21}],"rt":639159132681357566,"dt":639159132681358099}
{"op":"mcm","id":2,"clk":"AKTFAQDJhgEA2fcB","pt":1780316468230,"mc":[{"id":"1.258742455","rc":[{"atl":[[5.4,46.23]],"batl":[],"id":99072898},{"batb":[[2,19.5,24.47]],"atb":[[19.5,24.47]],"id":99072900},{"atl":[[5,19.48]],"batl":[[0,5,19.48]],"id":10398159},{"tv":14425.29,"trd":[[3.5,861.68]],"atl":[[3.5,3.31]],"batl":[[0,3.5,3.31]],"id":88302242}],"tv":41112.15}],"rt":639159132682375321,"dt":639159132682375756}
{"op":"mcm","id":2,"clk":"AKnFAQDMhgEA3vcB","pt":1780316468326,"mc":[{"id":"1.258742455","rc":[{"tv":14431.91,"batb":[[2,3.4,94.79],[1,3.45,50.33],[0,3.5,1.61]],"trd":[[3.5,868.3]],"atb":[[3.5,1.61]],"atl":[[3.5,0]],"batl":[[2,3.65,49.01],[1,3.6,75.06],[0,3.55,75.4]],"id":88302242}],"tv":41118.77}],"rt":639159132683339734,"dt":639159132683340133}
{"op":"mcm","id":2,"clk":"ALPFAQDRhgEA5fcB","pt":1780316468437,"mc":[{"id":"1.258742455","rc":[{"atl":[[5.4,43.88]],"batl":[],"id":99072898},{"atl":[[5,19.06]],"batl":[[0,5,19.06]],"id":10398159},{"tv":14435.13,"batb":[[2,3.35,164.82],[1,3.4,94.79],[0,3.45,50.33]],"trd":[[3.5,871.52]],"atb":[[3.5,0]],"atl":[[3.75,59.84]],"batl":[],"id":88302242}],"tv":41121.99}],"rt":639159132684455102,"dt":639159132684455788}
{"op":"mcm","id":2,"clk":"ALnFAQDXhgEA7PcB","pt":1780316468537,"mc":[{"id":"1.258742455","rc":[{"batb":[[0,3.45,73.16]],"atb":[[3.45,73.16]],"id":88302242}]}],"rt":639159132685445167,"dt":639159132685445534}
{"op":"mcm","id":2,"clk":"AL/FAQDchgEA9PcB","pt":1780316468638,"mc":[{"id":"1.258742455","rc":[{"atl":[[5.4,46.23]],"batl":[],"id":99072898},{"batb":[],"atb":[[3.25,15.35]],"atl":[[3.7,304.14]],"batl":[],"id":88302242}]}],"rt":639159132686464368,"dt":639159132686464762}
{"op":"mcm","id":2,"clk":"AMPFAQDfhgEA/fcB","pt":1780316468741,"mc":[{"id":"1.258742455","rc":[{"atl":[[5.1,145.78]],"batl":[[1,5.1,145.78]],"id":10398159}]}],"rt":639159132687492839,"dt":639159132687493158}
{"op":"mcm","id":2,"clk":"AMjFAQDhhgEAhPgB","pt":1780316468840,"mc":[{"id":"1.258742455","rc":[{"batb":[[0,4.9,54.76]],"atb":[[4.9,54.76]],"id":99072898},{"batb":[[0,4.9,177.67]],"atb":[[4.9,177.67]],"atl":[[5.1,143.62]],"batl":[[1,5.1,143.62]],"id":10398159},{"batb":[[1,50,21.87]],"atb":[[50,21.87]],"id":98464183},{"batb":[],"atb":[[3.3,65.99]],"atl":[[3.55,74.54],[3.6,73.9]],"batl":[[1,3.6,73.9],[0,3.55,74.54]],"id":88302242},{"batb":[[0,11,40.28]],"atb":[[11,40.28]],"id":97736949}]}],"rt":639159132688482466,"dt":639159132688482946}
{"op":"mcm","id":2,"clk":"AMzFAQDlhgEAivgB","pt":1780316468944,"mc":[{"id":"1.258742455","rc":[{"atl":[[5,44.4]],"batl":[[0,5,44.4]],"id":10398159}]}],"rt":639159132689525263,"dt":639159132689525610}
{"op":"mcm","id":2,"clk":"ANLFAQDthgEAkfgB","pt":1780316469050,"mc":[{"id":"1.258742455","rc":[{"atl":[[5,14.54]],"batl":[[0,5,14.54]],"id":99072898},{"batb":[[0,4.9,176.62]],"atb":[[4.9,176.62]],"id":10398159}]}],"rt":639159132690590477,"dt":639159132690590837}
{"op":"mcm","id":2,"clk":"ANrFAQDxhgEAmfgB","pt":1780316469154,"mc":[{"id":"1.258742455","rc":[{"batb":[[0,4.9,172.15]],"atb":[[4.9,172.15]],"id":10398159},{"atl":[[10.5,29.47]],"batl":[],"id":98117699},{"atl":[[3.7,298.14]],"batl":[],"id":88302242}]}],"rt":639159132691621845,"dt":639159132691622215}
{"op":"mcm","id":2,"clk":"AN7FAQD2hgEAoPgB","pt":1780316469251,"mc":[{"id":"1.258742455","rc":[{"batb":[[0,21,2.9]],"atb":[[21,2.9]],"id":99072900},{"atl":[[5,46.57]],"batl":[[0,5,46.57]],"id":10398159}]}],"rt":639159132692588225,"dt":639159132692588616}
{"op":"mcm","id":2,"clk":"AOnFAQD5hgEAp/gB","pt":1780316469357,"mc":[{"id":"1.258742455","rc":[{"atl":[[3.75,65.84]],"batl":[],"id":88302242}]}],"rt":639159132693654198,"dt":639159132693654545}
{"op":"mcm","id":2,"clk":"AO7FAQD8hgEAsPgB","pt":1780316469460,"mc":[{"id":"1.258742455","rc":[{"batb":[],"atb":[[3.3,59.99]],"id":88302242}]}],"rt":639159132694677857,"dt":639159132694678218}
{"op":"mcm","id":2,"clk":"APTFAQCChwEAuPgB","pt":1780316469560,"mc":[{"id":"1.258742455","rc":[{"batb":[[0,21,3.14]],"atb":[[21,3.14]],"id":99072900}]}],"rt":639159132695676527,"dt":639159132695676945}
{"op":"mcm","id":2,"clk":"APvFAQCFhwEAwvgB","pt":1780316469662,"mc":[{"id":"1.258742455","rc":[{"batb":[],"atb":[[3.25,21.35]],"id":88302242}]}],"rt":639159132696700227,"dt":639159132696700577}
{"op":"mcm","id":2,"clk":"AILGAQCLhwEAyfgB","pt":1780316469770,"mc":[{"id":"1.258742455","rc":[{"tv":2578.45,"batb":[[0,8.2,23.15]],"trd":[[8.2,12]],"atb":[[8.2,23.15]],"id":98117699}],"tv":41123.99}],"rt":639159132697780368,"dt":639159132697780720}
{"op":"mcm","id":2,"clk":"AIXGAQCRhwEA0/gB","pt":1780316469820,"mc":[{"id":"1.258742455","rc":[{"batb":[[0,4.9,55.89]],"atb":[[4.9,55.89],[1.02,100.84]],"id":99072898},{"atb":[[1.02,69.84]],"id":97008932},{"atb":[[1.02,366.36]],"id":99072900},{"atb":[[1.02,181.12]],"id":99072901},{"batb":[[0,4.9,173.27]],"atb":[[4.9,173.27],[1.02,442.01]],"id":10398159},{"atb":[[1.02,204.63]],"id":98464183},{"atb":[[1.02,100.84]],"id":98117699},{"batb":[[0,3.45,74.76]],"atb":[[1.02,100.84],[3.45,74.76]],"id":88302242},{"atb":[[1.02,100.84]],"id":97736949},{"atb":[[1.02,168.44]],"id":10445502},{"atb":[[1.02,234.78]],"id":99072897}]}],"rt":639159132698280784,"dt":639159132698281700}
{"op":"mcm","id":2,"clk":"AIvGAQCXhwEA1/gB","pt":1780316469921,"mc":[{"id":"1.258742455","rc":[{"batb":[[0,8.2,25.75]],"atb":[[8.2,25.75]],"atl":[[8.6,10.5]],"batl":[[0,8.6,10.5]],"id":98117699}]}],"rt":639159132699295685,"dt":639159132699296126}
{"op":"mcm","id":2,"clk":"AKLGAQCmhwEA9/gB","pt":1780316470337,"mc":[{"id":"1.258742455","rc":[{"batb":[[0,21,3.44]],"atb":[[21,3.44]],"id":99072900}]}],"rt":639159132703453792,"dt":639159132703454145}
{"op":"mcm","id":2,"clk":"AKnGAQCrhwEAgPkB","pt":1780316470442,"mc":[{"id":"1.258742455","rc":[{"atl":[[22,7.55]],"batl":[[0,22,7.55]],"id":99072900}]}],"rt":639159132704498197,"dt":639159132704498519}
{"op":"mcm","id":2,"clk":"ALHGAQCvhwEAhvkB","pt":1780316470541,"mc":[{"id":"1.258742455","rc":[{"tv":1458.19,"batb":[[0,21,4.24]],"trd":[[22,159.68]],"ltp":22,"atb":[[21,4.24]],"atl":[[22,6.75]],"batl":[[0,22,6.75]],"id":99072900},{"tv":2581.19,"batb":[[0,8.2,27.12]],"trd":[[8.6,46.56]],"ltp":8.6,"atb":[[7,11.85],[8.2,27.12]],"atl":[[10,5.72],[8.6,9.13]],"batl":[[0,8.6,9.13]],"id":98117699},{"batb":[[0,11,40.18]],"atb":[[11,40.18]],"atl":[[1000,1.1]],"id":97736949}],"tv":41128.33}],"rt":639159132705493610,"dt":639159132705494136}
{"op":"mcm","id":2,"clk":"ALjGAQC1hwEAj/kB","pt":1780316470646,"mc":[{"id":"1.258742455","rc":[{"atl":[[1000,1]],"id":97736949}]}],"rt":639159132706537121,"dt":639159132706537513}
{"op":"mcm","id":2,"clk":"AL3GAQC5hwEAlfkB","pt":1780316470752,"mc":[{"id":"1.258742455","rc":[{"batb":[[0,21,4.66]],"atb":[[21,4.66]],"atl":[[22,9.7]],"batl":[[0,22,9.7]],"id":99072900},{"atl":[[11.5,14.38]],"batl":[[0,11.5,14.38]],"id":97736949}]}],"rt":639159132707600054,"dt":639159132707600438}
{"op":"mcm","id":2,"clk":"AM/GAQDGhwEAs/kB","pt":1780316471156,"mc":[{"id":"1.258742455","rc":[{"atl":[[5,12.54]],"batl":[[0,5,12.54]],"id":99072898},{"tv":576.59,"batb":[[2,42,13.49],[1,44,9.39],[0,46,11.63]],"trd":[[48,70.24]],"atb":[[48,0]],"atl":[[48,8.64]],"batl":[[2,55,23.06],[1,50,10.27],[0,48,8.64]],"id":97008932}],"tv":41140.75}],"rt":639159132711642046,"dt":639159132711642455}
{"op":"mcm","id":2,"clk":"ANjGAQDMhwEAufkB","pt":1780316471266,"mc":[{"id":"1.258742455","rc":[{"atl":[[48,10.86]],"batl":[[0,48,10.86]],"id":97008932},{"atl":[[8.4,3]],"batl":[[2,8.8,12.1],[1,8.6,9.13],[0,8.4,3]],"id":98117699}]}],"rt":639159132712742565,"dt":639159132712742970}
{"op":"mcm","id":2,"clk":"ANzGAQDOhwEAwfkB","pt":1780316471366,"mc":[{"id":"1.258742455","rc":[{"atl":[[5.4,43.88]],"batl":[],"id":99072898},{"batb":[[0,46,7.17]],"atb":[[46,7.17]],"atl":[[50,13.27],[48,11.63]],"batl":[[1,50,13.27],[0,48,11.63]],"id":97008932},{"atl":[[8.4,6]],"batl":[[0,8.4,6]],"id":98117699}]}],"rt":639159132713742097,"dt":639159132713742620}
{"op":"mcm","id":2,"clk":"AN/GAQDPhwEAzfkB","pt":1780316471470,"mc":[{"id":"1.258742455","rc":[{"batb":[[2,42,15.22]],"atb":[[42,15.22]],"id":97008932},{"batb":[[2,19.5,26.2]],"atb":[[19.5,26.2]],"id":99072900},{"batb":[[0,4.9,173.66]],"atb":[[4.9,173.66]],"id":10398159},{"atl":[[8.4,7.23],[8.6,10.3]],"batl":[[1,8.6,10.3],[0,8.4,7.23]],"id":98117699},{"batb":[],"atb":[[690,2],[670,0]],"id":10445502}]}],"rt":639159132714779420,"dt":639159132714779880}
{"op":"mcm","id":2,"clk":"AOLGAQDRhwEA2vkB","pt":1780316471571,"mc":[{"id":"1.258742455","rc":[{"atl":[[5,1.75]],"batl":[[0,5,1.75]],"id":99072898},{"atl":[[50,13.21]],"batl":[[1,50,13.21]],"id":97008932},{"tv":2587.25,"batb":[[0,8.2,24.09]],"trd":[[8.2,18.06]],"ltp":8.2,"atb":[[8.2,24.09]],"atl":[[9.4,24.32]],"batl":[],"id":98117699}],"tv":41146.81}],"rt":639159132715790069,"dt":639159132715790500}
{"op":"mcm","id":2,"clk":"AOnGAQDWhwEA3/kB","pt":1780316471620,"mc":[{"id":"1.258742455","rc":[{"batb":[],"atb":[[38,23.31]],"atl":[[48,12.43]],"batl":[[0,48,12.43]],"id":97008932},{"batb":[[0,4.9,174.28]],"atb":[[4.9,174.28]],"id":10398159},{"batb":[[0,8.2,23.78]],"atb":[[8.2,23.78]],"id":98117699}]}],"rt":639159132716284063,"dt":639159132716284576}
{"op":"mcm","id":2,"clk":"APHGAQDdhwEA6PkB","pt":1780316471731,"mc":[{"id":"1.258742455","rc":[{"atl":[[5,0]],"batl":[[2,5.3,21.15],[1,5.2,27.03],[0,5.1,43.1]],"id":99072898},{"batb":[[0,8.2,19.98]],"atb":[[8.2,19.98]],"atl":[[8.4,10.48],[9.2,32.23],[9.6,5.83]],"batl":[[0,8.4,10.48]],"id":98117699}]}],"rt":639159132717407070,"dt":639159132717407506}
{"op":"mcm","id":2,"clk":"APTGAQDghwEA7vkB","pt":1780316471830,"mc":[{"id":"1.258742455","rc":[{"atl":[[5,4.39]],"batl":[[2,5.2,27.03],[1,5.1,43.1],[0,5,4.39]],"id":99072898},{"tv":578.99,"trd":[[48,72.64]],"atl":[[55,23.31],[48,11.22]],"batl":[[2,55,23.31],[0,48,11.22]],"id":97008932},{"batb":[[0,21,5.64]],"atb":[[21,5.64]],"atl":[[1000,6.64]],"id":99072900},{"batb":[[0,8.2,18.98]],"atb":[[1.17,2.95],[8.2,18.98],[7.2,15.35]],"atl":[[8.4,13.48]],"batl":[[0,8.4,13.48]],"id":98117699},{"batb":[[2,3.4,94.79],[1,3.45,74.76],[0,3.5,18.8]],"atb":[[3.5,18.8]],"id":88302242},{"batb":[],"atb":[[9.8,13.52]],"id":97736949}],"tv":41149.21}],"rt":639159132718377150,"dt":639159132718377744}
{"op":"mcm","id":2,"clk":"APrGAQDihwEA9PkB","pt":1780316471932,"mc":[{"id":"1.258742455","rc":[{"atl":[[5.4,46.21]],"batl":[],"id":99072898},{"batb":[[0,3.5,25.3]],"atb":[[3.5,25.3]],"id":88302242}]}],"rt":639159132719406196,"dt":639159132719406614}
{"op":"mcm","id":2,"clk":"AIDHAQDnhwEA\u002BfkB","pt":1780316472038,"mc":[{"id":"1.258742455","rc":[{"batb":[],"atb":[[4.2,116.79]],"id":99072898},{"atl":[[1000,6.25]],"id":99072900},{"batb":[],"atb":[[4.1,107.73]],"id":10398159},{"batb":[[0,8.2,16.38]],"atb":[[1.17,2],[8.2,16.38]],"atl":[[8.4,14.12]],"batl":[[0,8.4,14.12]],"id":98117699},{"batb":[[1,3.45,80.14]],"atb":[[3.45,80.14]],"atl":[[3.55,73.49]],"batl":[[0,3.55,73.49]],"id":88302242}]}],"rt":639159132720463007,"dt":639159132720463492}
{"op":"mcm","id":2,"clk":"AITHAQDuhwEAgPoB","pt":1780316472138,"mc":[{"id":"1.258742455","rc":[{"atl":[[23,11.86]],"batl":[[1,23,11.86]],"id":99072900},{"batb":[[0,8.2,17.33]],"atb":[[7,12.56],[8.2,17.33]],"atl":[[8.4,17.12]],"batl":[[0,8.4,17.12]],"id":98117699},{"atl":[[3.55,72.05]],"batl":[[0,3.55,72.05]],"id":88302242},{"batb":[],"atb":[[9.4,6.29]],"id":97736949}]}],"rt":639159132721460189,"dt":639159132721460580}
{"op":"mcm","id":2,"clk":"AIXHAQDyhwEAhPoB","pt":1780316472240,"mc":[{"id":"1.258742455","rc":[{"batb":[],"atb":[[4.2,117.98]],"id":99072898},{"batb":[[2,4.7,68.16]],"atb":[[4.7,68.16],[4.2,30.96]],"id":10398159},{"atl":[[8.4,17.75]],"batl":[[0,8.4,17.75]],"id":98117699},{"tv":14437.13,"batb":[[0,3.5,24.3]],"trd":[[3.5,873.52]],"atb":[[3.5,24.3],[3.25,15.35],[3.35,159.77]],"id":88302242}],"tv":41151.21}],"rt":639159132722476821,"dt":639159132722477360}
{"op":"mcm","id":2,"clk":"AIvHAQD2hwEAifoB","pt":1780316472337,"mc":[{"id":"1.258742455","rc":[{"batb":[[2,42,15.1]],"atb":[[42,15.1]],"id":97008932},{"batb":[],"atb":[[18.5,8.18]],"id":99072900},{"atb":[[3,6.8]],"id":88302242}]}],"rt":639159132723459962,"dt":639159132723460375}
{"op":"mcm","id":2,"clk":"AJHHAQD5hwEAkvoB","pt":1780316472441,"mc":[{"id":"1.258742455","rc":[{"batb":[[0,8.2,13.54]],"atb":[[8.2,13.54]],"id":98117699},{"tv":14458.44,"batb":[[0,3.5,13.65]],"trd":[[3.5,894.83]],"atb":[[3.5,13.65]],"id":88302242}],"tv":41172.52}],"rt":639159132724490993,"dt":639159132724491452}
{"op":"mcm","id":2,"clk":"AJnHAQCCiAEAn/oB","pt":1780316472553,"mc":[{"id":"1.258742455","rc":[{"batb":[[2,42,15.22]],"atb":[[42,15.22]],"id":97008932},{"batb":[],"atb":[[19,26.31]],"id":99072900},{"batb":[],"atb":[[3.3,65.99],[3,8.47]],"id":88302242},{"batb":[[0,11,41.39]],"atb":[[11,41.39]],"id":97736949}]}],"rt":639159132725609230,"dt":639159132725609653}
{"op":"mcm","id":2,"clk":"AJ/HAQCFiAEApPoB","pt":1780316472645,"mc":[{"id":"1.258742455","rc":[{"tv":2589.25,"batb":[[0,8.2,12.54]],"trd":[[8.2,20.06]],"atb":[[8.2,12.54]],"id":98117699}],"tv":41174.52}],"rt":639159132726536096,"dt":639159132726536456}
{"op":"mcm","id":2,"clk":"AKbHAQCJiAEAq/oB","pt":1780316472747,"mc":[{"id":"1.258742455","rc":[{"batb":[[0,46,7.22]],"atb":[[46,7.22]],"id":97008932}]}],"rt":639159132727552862,"dt":639159132727553235}
{"op":"mcm","id":2,"clk":"AKrHAQCLiAEAs/oB","pt":1780316472851,"mc":[{"id":"1.258742455","rc":[{"atl":[[8.4,18.58]],"batl":[[0,8.4,18.58]],"id":98117699},{"atl":[[3.55,72.84]],"batl":[[0,3.55,72.84]],"id":88302242}]}],"rt":639159132728596583,"dt":639159132728597059}
{"op":"mcm","id":2,"clk":"AK3HAQCQiAEAuvoB","pt":1780316472956,"mc":[{"id":"1.258742455","rc":[{"tv":579.03,"trd":[[48,72.68]],"atl":[[48,11.21]],"batl":[[0,48,11.21]],"id":97008932}],"tv":41174.56}],"rt":639159132729647193,"dt":639159132729647537}
{"op":"mcm","id":2,"clk":"ALDHAQCRiAEAwPoB","pt":1780316473057,"mc":[{"id":"1.258742455","rc":[{"atl":[[5,47.05]],"batl":[[0,5,47.05]],"id":10398159}]}],"rt":639159132730654469,"dt":639159132730654893}
{"op":"mcm","id":2,"clk":"ALbHAQCViAEAyPoB","pt":1780316473158,"mc":[{"id":"1.258742455","rc":[{"tv":14459.08,"batb":[[0,3.5,13.33]],"trd":[[3.5,895.47]],"atb":[[3.5,13.33]],"id":88302242}],"tv":41175.2}],"rt":639159132731655118,"dt":639159132731655522}
{"op":"mcm","id":2,"clk":"ALzHAQCZiAEAzPoB","pt":1780316473260,"mc":[{"id":"1.258742455","rc":[{"tv":8767.16,"batb":[[0,4.9,174.11]],"trd":[[4.9,428.65]],"atb":[[4.9,174.11]],"id":10398159}],"tv":41175.54}],"rt":639159132732684933,"dt":639159132732685412}
{"op":"mcm","id":2,"clk":"AMvHAQCgiAEA3PoB","pt":1780316473472,"mc":[{"id":"1.258742455","rc":[{"tv":579.74,"batb":[[0,46,7.76]],"trd":[[48,73.39]],"atb":[[46,7.76]],"atl":[[48,10.85]],"batl":[[0,48,10.85]],"id":97008932},{"atl":[[23,9.67]],"batl":[[1,23,9.67]],"id":99072900}],"tv":41176.25}],"rt":639159132734805063,"dt":639159132734805546}
{"op":"mcm","id":2,"clk":"AM3HAQChiAEA4voB","pt":1780316473569,"mc":[{"id":"1.258742455","rc":[{"batb":[[2,19.5,24.47]],"atb":[[19.5,24.47]],"id":99072900}]}],"rt":639159132735771673,"dt":639159132735772083}
{"op":"mcm","id":2,"clk":"ANDHAQCjiAEA6/oB","pt":1780316473624,"mc":[{"id":"1.258742455","rc":[{"batb":[[0,55,9.3]],"atb":[[55,9.3]],"id":98464183}]}],"rt":639159132736324032,"dt":639159132736324613}
{"op":"mcm","id":2,"clk":"AP7HAQC/iAEAo/sB","pt":1780316474449,"mc":[{"id":"1.258742455","rc":[{"batb":[[2,140,3.17]],"atb":[[140,3.17]],"id":99072897}]}],"rt":639159132744569971,"dt":639159132744570300}
{"op":"mcm","id":2,"clk":"AIbIAQDFiAEArvsB","pt":1780316474653,"mc":[{"id":"1.258742455","rc":[{"atl":[[5,1.54]],"batl":[[0,5,1.54]],"id":99072898},{"atl":[[1000,0.41],[55,23.06],[50,13.56]],"batl":[[2,55,23.06],[1,50,13.56]],"id":97008932},{"batb":[[0,4.9,171.93]],"atb":[[4.9,171.93]],"atl":[[5.1,143.18]],"batl":[[1,5.1,143.18]],"id":10398159},{"atl":[[1000,6.59],[8.8,11.48]],"batl":[[2,8.8,11.48]],"id":98117699},{"batb":[[0,11,39.88]],"atb":[[11,39.88]],"id":97736949}]}],"rt":639159132746615462,"dt":639159132746616141}
{"op":"mcm","id":2,"clk":"AI7IAQDHiAEAtvsB","pt":1780316474753,"mc":[{"id":"1.258742455","rc":[{"atl":[[1000,0.22]],"id":97008932},{"batb":[[0,95,4.59]],"atb":[[95,4.59]],"id":99072901},{"atl":[[1000,6.25]],"id":98117699}]}],"rt":639159132747611337,"dt":639159132747611736}
{"op":"mcm","id":2,"clk":"AJXIAQDLiAEAvPsB","pt":1780316474854,"mc":[{"id":"1.258742455","rc":[{"atl":[[48,11.04]],"batl":[[0,48,11.04]],"id":97008932},{"batb":[[2,19.5,26.2]],"atb":[[19.5,26.2]],"id":99072900},{"tv":8769.16,"batb":[[0,4.9,170.93]],"trd":[[4.9,430.65]],"atb":[[4.9,170.93]],"id":10398159},{"atl":[[8.4,18.72],[8.6,10.5]],"batl":[[1,8.6,10.5],[0,8.4,18.72]],"id":98117699}],"tv":41178.25}],"rt":639159132748622016,"dt":639159132748622630}
{"op":"mcm","id":2,"clk":"AKLIAQDWiAEAzPsB","pt":1780316475064,"mc":[{"id":"1.258742455","rc":[{"atl":[[8.4,22.9]],"batl":[[0,8.4,22.9]],"id":98117699},{"tv":14464.08,"trd":[[3.55,1045.55]],"ltp":3.55,"atl":[[3.55,70.34]],"batl":[[0,3.55,70.34]],"id":88302242},{"batb":[[0,160,5.2]],"atb":[[160,5.2]],"id":99072897}],"tv":41183.25}],"rt":639159132750722623,"dt":639159132750723082}
{"op":"mcm","id":2,"clk":"AK3IAQDdiAEA2fsB","pt":1780316475265,"mc":[{"id":"1.258742455","rc":[{"tv":8904.15,"batb":[[0,4.9,56.35]],"trd":[[5,375.21]],"ltp":5,"atb":[[5,0.46]],"atl":[[5,0]],"batl":[[2,5.3,21.15],[1,5.2,27.03],[0,5.1,43.1]],"id":99072898},{"batb":[[0,160,5.42]],"atb":[[160,5.42]],"id":99072897}],"tv":41186.33}],"rt":639159132752732388,"dt":639159132752733015}
{"op":"mcm","id":2,"clk":"ALTIAQDiiAEA4PsB","pt":1780316475368,"mc":[{"id":"1.258742455","rc":[{"atl":[[5.4,43.88]],"batl":[],"id":99072898},{"batb":[[2,19.5,24.47]],"atb":[[19.5,24.47]],"id":99072900},{"batb":[[0,3.5,6.83]],"atb":[[3.5,6.83]],"id":88302242}]}],"rt":639159132753757582,"dt":639159132753757998}
{"op":"mcm","id":2,"clk":"AL7IAQDliAEA6fsB","pt":1780316475471,"mc":[{"id":"1.258742455","rc":[{"batb":[[0,46,7.8]],"atb":[[46,7.8]],"id":97008932},{"batb":[[2,3.35,159.77],[1,3.4,94.79],[0,3.45,80.14]],"atb":[[3.5,0]],"atl":[[3.55,77.76]],"batl":[[0,3.55,77.76]],"id":88302242},{"batb":[[0,160,4.95]],"atb":[[160,4.95]],"id":99072897}]}],"rt":639159132754789777,"dt":639159132754790350}
{"op":"mcm","id":2,"clk":"AMnIAQDpiAEA7/sB","pt":1780316475574,"mc":[{"id":"1.258742455","rc":[{"batb":[[2,19.5,26.2]],"atb":[[19.5,26.2]],"id":99072900}]}],"rt":639159132755816308,"dt":639159132755816691}
{"op":"mcm","id":2,"clk":"AMzIAQDtiAEA9vsB","pt":1780316475627,"mc":[{"id":"1.258742455","rc":[{"batb":[[0,4.9,172.11]],"atb":[[4.9,172.11]],"id":10398159},{"batb":[[0,11,38.67]],"atb":[[11,38.67]],"id":97736949}]}],"rt":639159132756348648,"dt":639159132756349061}
{"op":"mcm","id":2,"clk":"AM/IAQDxiAEA\u002BvsB","pt":1780316475727,"mc":[{"id":"1.258742455","rc":[{"atl":[[5.4,37.88]],"batl":[],"id":99072898},{"batb":[],"atb":[[3.3,59.99]],"id":88302242}]}],"rt":639159132757359614,"dt":639159132757360202}
{"op":"mcm","id":2,"clk":"ANXIAQDziAEAgfwB","pt":1780316475829,"mc":[{"id":"1.258742455","rc":[{"batb":[[0,4.9,57.35]],"atb":[[4.9,56.89]],"id":99072898}]}],"rt":639159132758368269,"dt":639159132758368674}
{"op":"mcm","id":2,"clk":"AN3IAQD3iAEAifwB","pt":1780316475930,"mc":[{"id":"1.258742455","rc":[{"atl":[[5.5,40.99]],"batl":[],"id":99072898},{"batb":[],"atb":[[3.25,21.35]],"id":88302242}]}],"rt":639159132759375246,"dt":639159132759375586}
{"op":"mcm","id":2,"clk":"AOHIAQCBiQEAl/wB","pt":1780316476035,"mc":[{"id":"1.258742455","rc":[{"tv":2601.79,"batb":[[0,8.2,6.27]],"trd":[[8.2,32.6]],"atb":[[8.2,6.27]],"id":98117699}],"tv":41198.87}],"rt":639159132760431141,"dt":639159132760431541}
{"op":"mcm","id":2,"clk":"AOrIAQCGiQEAovwB","pt":1780316476137,"mc":[{"id":"1.258742455","rc":[{"batb":[[0,4.9,173.47]],"atb":[[4.9,173.47]],"atl":[[5,42.91]],"batl":[[0,5,42.91]],"id":10398159},{"atl":[[8.4,24.28]],"batl":[[0,8.4,24.28]],"id":98117699},{"batb":[[1,3.4,105.61]],"atb":[[3.4,105.61]],"id":88302242}]}],"rt":639159132761455490,"dt":639159132761456028}
{"op":"mcm","id":2,"clk":"AO/IAQCOiQEAqfwB","pt":1780316476239,"mc":[{"id":"1.258742455","rc":[{"tv":8905.07,"batb":[[0,4.9,56.89]],"trd":[[5,376.13]],"atb":[[5,0]],"atl":[[5,9.54]],"batl":[[2,5.2,27.03],[1,5.1,43.1],[0,5,9.54]],"id":99072898}],"tv":41199.79}],"rt":639159132762476219,"dt":639159132762476732}
{"op":"mcm","id":2,"clk":"AILJAQCfiQEAw/wB","pt":1780316476452,"mc":[{"id":"1.258742455","rc":[{"atl":[[5,43.79]],"batl":[[0,5,43.79]],"id":10398159}]}],"rt":639159132764605614,"dt":639159132764605998}
{"op":"mcm","id":2,"clk":"AIfJAQCgiQEAzPwB","pt":1780316476551,"mc":[{"id":"1.258742455","rc":[{"batb":[[0,46,7.76]],"atb":[[46,7.76]],"id":97008932},{"batb":[],"atb":[[670,2]],"id":10445502}]}],"rt":639159132765594100,"dt":639159132765594616}
{"op":"mcm","id":2,"clk":"AJDJAQCmiQEA0/wB","pt":1780316476655,"mc":[{"id":"1.258742455","rc":[{"batb":[],"atb":[[690,0]],"id":10445502}]}],"rt":639159132766635718,"dt":639159132766636152}
{"op":"mcm","id":2,"clk":"AJXJAQCqiQEA2/wB","pt":1780316476755,"mc":[{"id":"1.258742455","rc":[{"atl":[[5.5,34.99]],"batl":[],"id":99072898},{"batb":[[0,46,7.81]],"atb":[[46,7.81]],"id":97008932},{"atl":[[5,44.85]],"batl":[[0,5,44.85]],"id":10398159}]}],"rt":639159132767630736,"dt":639159132767631188}
{"op":"mcm","id":2,"clk":"AJvJAQCviQEA5vwB","pt":1780316476860,"mc":[{"id":"1.258742455","rc":[{"atl":[[3.55,78.55]],"batl":[[0,3.55,78.55]],"id":88302242},{"tv":2615.83,"batb":[[0,11,37.02]],"trd":[[11,191.08]],"atb":[[11,37.02]],"id":97736949}],"tv":41203.1}],"rt":639159132768694808,"dt":639159132768695409}
{"op":"mcm","id":2,"clk":"AJ7JAQC0iQEA7fwB","pt":1780316476958,"mc":[{"id":"1.258742455","rc":[{"atl":[[5.4,43.88]],"batl":[],"id":99072898},{"tv":579.77,"trd":[[48,73.42]],"atl":[[48,11.03]],"batl":[[0,48,11.03]],"id":97008932},{"atl":[[5,50.31]],"batl":[[0,5,50.31]],"id":10398159}],"tv":41203.13}],"rt":639159132769667150,"dt":639159132769667697}
{"op":"mcm","id":2,"clk":"ALrJAQDKiQEAkf0B","pt":1780316477372,"mc":[{"id":"1.258742455","rc":[{"batb":[[0,46,7.85]],"atb":[[46,7.85]],"id":97008932},{"batb":[[1,4.8,78.28]],"atb":[[4.8,78.28]],"id":10398159}]}],"rt":639159132773803202,"dt":639159132773803605}
{"op":"mcm","id":2,"clk":"AMLJAQDOiQEAnf0B","pt":1780316477473,"mc":[{"id":"1.258742455","rc":[{"tv":8869.78,"batb":[[2,4.8,78.28],[1,4.9,173.47],[0,5,48.39]],"trd":[[5,262.74]],"ltp":5,"atb":[[5,48.39]],"atl":[[5,0]],"batl":[[2,5.3,43.59],[1,5.2,27.03],[0,5.1,143.18]],"id":10398159}],"tv":41303.75}],"rt":639159132774813685,"dt":639159132774814101}
{"op":"mcm","id":2,"clk":"AMfJAQDUiQEApf0B","pt":1780316477579,"mc":[{"id":"1.258742455","rc":[{"atl":[[5.4,46.19]],"batl":[],"id":99072898},{"batb":[[2,19.5,24.47],[0,21,6.21]],"atb":[[21,6.21],[19.5,24.47]],"id":99072900},{"tv":8875.38,"batb":[[1,4.9,169.92],[0,5,70.65]],"trd":[[5,268.34]],"atb":[[4.7,75.04],[4.9,169.92],[5,70.65],[4.5,158.95]],"atl":[[5.1,145.46]],"batl":[[0,5.1,145.46]],"id":10398159},{"tv":14498.66,"batb":[[0,3.45,62.85]],"trd":[[3.45,132.92]],"ltp":3.45,"atb":[[3.45,62.85]],"atl":[[3.55,81.84]],"batl":[[0,3.55,81.84]],"id":88302242}],"tv":41343.93}],"rt":639159132775868366,"dt":639159132775869110}
{"op":"mcm","id":2,"clk":"AM/JAQDaiQEAq/0B","pt":1780316477679,"mc":[{"id":"1.258742455","rc":[{"atl":[[5,9.68]],"batl":[[0,5,9.68]],"id":99072898},{"batb":[[0,46,9.07]],"atb":[[46,9.07]],"id":97008932},{"batb":[[1,4.9,175.02]],"atb":[[4.9,175.02],[4.5,124.3]],"atl":[[5.1,162.08]],"batl":[[0,5.1,162.08]],"id":10398159},{"batb":[[0,55,9.32]],"atb":[[55,9.32]],"id":98464183},{"batb":[[0,8.2,5]],"atb":[[7.6,142.27],[8.2,5]],"atl":[[9.8,5.48]],"batl":[],"id":98117699},{"batb":[[0,3.45,82.06]],"atb":[[3.45,82.06]],"atl":[[3.5,19.33]],"batl":[[2,3.6,73.9],[1,3.55,81.84],[0,3.5,19.33]],"id":88302242}]}],"rt":639159132776880261,"dt":639159132776881306}
{"op":"mcm","id":2,"clk":"ANPJAQDciQEAs/0B","pt":1780316477732,"mc":[{"id":"1.258742455","rc":[{"batb":[[1,4.9,191.29]],"atb":[[4.4,47.44],[4.9,191.29]],"atl":[[5.1,157.89]],"batl":[[0,5.1,157.89]],"id":10398159},{"batb":[[2,7.8,23.75]],"atb":[[7.8,23.75]],"atl":[[9.4,25.7]],"batl":[],"id":98117699}]}],"rt":639159132777402673,"dt":639159132777403243}
{"op":"mcm","id":2,"clk":"ANnJAQDjiQEAvv0B","pt":1780316477841,"mc":[{"id":"1.258742455","rc":[{"batb":[[0,46,9.16]],"atb":[[46,9.16]],"id":97008932},{"batb":[],"atb":[[4.5,118.3]],"id":10398159},{"batb":[[0,3.45,76.68]],"atb":[[1.17,196.63],[3.45,76.68]],"atl":[[3.5,21.84]],"batl":[[0,3.5,21.84]],"id":88302242}]}],"rt":639159132778510056,"dt":639159132778510552}
{"op":"mcm","id":2,"clk":"AOHJAQDpiQEAyP0B","pt":1780316477940,"mc":[{"id":"1.258742455","rc":[{"atl":[[5,9.83]],"batl":[[0,5,9.83]],"id":99072898},{"batb":[[0,95,4.52]],"atb":[[95,4.52]],"id":99072901},{"batb":[[0,5,86.65]],"atb":[[5,86.65]],"atl":[[5.1,158.43]],"batl":[[0,5.1,158.43]],"id":10398159},{"batb":[[0,8.2,12.5]],"atb":[[8.2,12.5]],"id":98117699},{"atb":[[1.17,196.12]],"id":88302242}]}],"rt":639159132779483162,"dt":639159132779483605}
{"op":"mcm","id":2,"clk":"AOfJAQDtiQEAzP0B","pt":1780316478038,"mc":[{"id":"1.258742455","rc":[{"tv":579.8,"trd":[[48,73.45]],"atl":[[48,11.01]],"batl":[[0,48,11.01]],"id":97008932},{"tv":8881.96,"batb":[[0,5,83.36]],"trd":[[5,274.92]],"atb":[[4.6,107.97],[5,83.36],[4.5,107.3]],"atl":[[5.4,50.44]],"batl":[],"id":10398159},{"tv":14499.68,"trd":[[3.5,896.49]],"ltp":3.5,"atl":[[3.5,21.33],[3.55,79.45]],"batl":[[1,3.55,79.45],[0,3.5,21.33]],"id":88302242}],"tv":41351.56}],"rt":639159132780461868,"dt":639159132780462413}
{"op":"mcm","id":2,"clk":"APPJAQD0iQEA1f0B","pt":1780316478143,"mc":[{"id":"1.258742455","rc":[{"tv":8922.37,"batb":[[0,4.9,48.24]],"trd":[[4.9,848.17]],"ltp":4.9,"atb":[[4.9,48.24]],"atl":[[5,10.19]],"batl":[[0,5,10.19]],"id":99072898},{"atl":[[3.75,59.84],[3.5,18.82]],"batl":[[0,3.5,18.82]],"id":88302242}],"tv":41368.86}],"rt":639159132781508767,"dt":639159132781509205}
{"op":"mcm","id":2,"clk":"AP3JAQD/iQEA4/0B","pt":1780316478255,"mc":[{"id":"1.258742455","rc":[{"atl":[[5,20.12]],"batl":[[0,5,20.12]],"id":99072898},{"tv":8882.36,"batb":[[0,5,83.16]],"trd":[[5,275.32]],"atb":[[5,83.16]],"atl":[[5.5,14.5]],"batl":[],"id":10398159},{"atl":[[3.5,19.54]],"batl":[[0,3.5,19.54]],"id":88302242},{"tv":2633.11,"batb":[[0,11,28.39]],"trd":[[11,208.36]],"atb":[[11,28.39]],"id":97736949}],"tv":41386.54}],"rt":639159132782632447,"dt":639159132782632879}
{"op":"mcm","id":2,"clk":"AP7JAQCEigEA7P0B","pt":1780316478352,"mc":[{"id":"1.258742455","rc":[{"batb":[[0,4.9,44.76]],"atb":[[4.9,44.76]],"id":99072898},{"batb":[[0,8.2,16.59]],"atb":[[8.2,16.59]],"id":98117699},{"atl":[[3.7,304.14]],"batl":[],"id":88302242},{"batb":[[0,11,23.86]],"atb":[[11,23.86]],"id":97736949}]}],"rt":639159132783597263,"dt":639159132783597682}
{"op":"mcm","id":2,"clk":"AIPKAQCGigEA7/0B","pt":1780316478449,"mc":[{"id":"1.258742455","rc":[{"atl":[[5,21.34]],"batl":[[0,5,21.34]],"id":99072898},{"batb":[[0,46,9.21]],"atb":[[46,9.21]],"id":97008932},{"batb":[[0,5,83.58]],"atb":[[5,83.58]],"id":10398159},{"batb":[[0,11,22.31]],"atb":[[11,22.31]],"id":97736949},{"batb":[[0,160,5.44]],"atb":[[160,5.44]],"id":99072897}]}],"rt":639159132784567858,"dt":639159132784568362}
{"op":"mcm","id":2,"clk":"AI7KAQCPigEA/P0B","pt":1780316478561,"mc":[{"id":"1.258742455","rc":[{"tv":14500.24,"batb":[[0,3.45,76.4]],"trd":[[3.45,133.48]],"ltp":3.45,"atb":[[3.45,76.4]],"id":88302242},{"batb":[[0,11,22.61]],"atb":[[11,22.61]],"id":97736949}],"tv":41387.1}],"rt":639159132785692297,"dt":639159132785692745}
{"op":"mcm","id":2,"clk":"AJvKAQCWigEAjf4B","pt":1780316478767,"mc":[{"id":"1.258742455","rc":[{"tv":14511.28,"batb":[[1,3.4,94.79]],"trd":[[3.5,907.53]],"ltp":3.5,"atb":[[3.4,94.79]],"atl":[[3.5,14.02]],"batl":[[0,3.5,14.02]],"id":88302242}],"tv":41398.14}],"rt":639159132787751739,"dt":639159132787752219}
{"op":"mcm","id":2,"clk":"AJ7KAQCaigEAlP4B","pt":1780316478870,"mc":[{"id":"1.258742455","rc":[{"atl":[[3.5,0.72]],"batl":[[2,3.65,49.01],[1,3.6,73.9],[0,3.55,80.17]],"id":88302242},{"batb":[[0,11,22.85]],"atb":[[11,22.85]],"id":97736949}]}],"rt":639159132788779960,"dt":639159132788780359}
{"op":"mcm","id":2,"clk":"AKjKAQCeigEAm/4B","pt":1780316478973,"mc":[{"id":"1.258742455","rc":[{"tv":8910.36,"batb":[[0,5,69.58]],"trd":[[5,303.32]],"atb":[[5,69.58]],"id":10398159}],"tv":41426.14}],"rt":639159132789806662,"dt":639159132789807064}
{"op":"mcm","id":2,"clk":"AKvKAQCgigEAo/4B","pt":1780316479075,"mc":[{"id":"1.258742455","rc":[{"batb":[[0,5,44.52]],"atb":[[5,44.52]],"id":10398159},{"tv":2635.11,"batb":[[0,11,21.85]],"trd":[[11,210.36]],"atb":[[11,21.85]],"id":97736949}],"tv":41428.14}],"rt":639159132790836299,"dt":639159132790836754}
{"op":"mcm","id":2,"clk":"ALTKAQCnigEAqP4B","pt":1780316479173,"mc":[{"id":"1.258742455","rc":[{"batb":[[0,5,44.1]],"atb":[[5,44.1]],"id":10398159},{"atl":[[3.5,13.72]],"batl":[[2,3.6,73.9],[1,3.55,79.45],[0,3.5,13.72]],"id":88302242}]}],"rt":639159132791816196,"dt":639159132791816677}
{"op":"mcm","id":2,"clk":"ALfKAQCoigEAr/4B","pt":1780316479274,"mc":[{"id":"1.258742455","rc":[{"tv":2616.43,"batb":[[0,8.2,9.27]],"trd":[[8.2,47.24]],"atb":[[8.2,9.27]],"id":98117699},{"atl":[[3.7,298.14]],"batl":[],"id":88302242}],"tv":41442.78}],"rt":639159132792826969,"dt":639159132792827357}
{"op":"mcm","id":2,"clk":"AMLKAQC1igEAu/4B","pt":1780316479433,"mc":[{"id":"1.258742455","rc":[{"batb":[],"atb":[[7.4,76.33]],"id":98117699},{"atl":[[3.75,65.84]],"batl":[],"id":88302242}]}],"rt":639159132794412400,"dt":639159132794412784}
{"op":"mcm","id":2,"clk":"AMXKAQC4igEAxv4B","pt":1780316479533,"mc":[{"id":"1.258742455","rc":[{"batb":[],"atb":[[4.7,111.24]],"id":10398159}]}],"rt":639159132795409856,"dt":639159132795410196}
{"op":"mcm","id":2,"clk":"AMnKAQC9igEAz/4B","pt":1780316479638,"mc":[{"id":"1.258742455","rc":[{"atl":[[5.5,24.48]],"batl":[],"id":10398159}]}],"rt":639159132796462840,"dt":639159132796463194}
{"op":"mcm","id":2,"clk":"AM3KAQDGigEA2f4B","pt":1780316479742,"mc":[{"id":"1.258742455","rc":[{"batb":[[0,46,9.27]],"atb":[[46,9.27]],"id":97008932},{"tv":8914.36,"batb":[[0,5,42.1]],"trd":[[5,307.32]],"atb":[[5,42.1]],"id":10398159}],"tv":41446.78}],"rt":639159132797502940,"dt":639159132797503356}
{"op":"mcm","id":2,"clk":"ANHKAQDIigEA5f4B","pt":1780316479845,"mc":[{"id":"1.258742455","rc":[{"atl":[[3.6,84.9]],"batl":[[2,3.6,84.9]],"id":88302242}]}],"rt":639159132798532680,"dt":639159132798533018}
{"op":"mcm","id":2,"clk":"ANbKAQDKigEA7f4B","pt":1780316479943,"mc":[{"id":"1.258742455","rc":[{"batb":[[0,11,22.16]],"atb":[[11,22.16]],"id":97736949}]}],"rt":639159132799520112,"dt":639159132799520464}
{"op":"mcm","id":2,"clk":"ANnKAQDRigEA\u002Bv4B","pt":1780316480047,"mc":[{"id":"1.258742455","rc":[{"atl":[[3.75,59.84]],"batl":[],"id":88302242}]}],"rt":639159132800555782,"dt":639159132800556107}
{"op":"mcm","id":2,"clk":"AOPKAQDbigEAi/8B","pt":1780316480254,"mc":[{"id":"1.258742455","rc":[{"atl":[[3.7,304.14]],"batl":[],"id":88302242}]}],"rt":639159132802625405,"dt":639159132802625841}
{"op":"mcm","id":2,"clk":"AOrKAQDligEAk/8B","pt":1780316480360,"mc":[{"id":"1.258742455","rc":[{"batb":[[0,4.9,46.08]],"atb":[[4.9,46.08]],"id":99072898},{"batb":[[0,5,43.4]],"atb":[[5,43.4]],"id":10398159},{"batb":[[0,55,9.52]],"atb":[[55,9.52]],"atl":[[65,28.25]],"batl":[[0,65,29.01]],"id":98464183},{"batb":[[0,8.2,10.74]],"atb":[[8.2,10.74]],"id":98117699},{"batb":[[0,3.45,78.28]],"atb":[[3.45,78.28]],"id":88302242},{"batb":[[0,1000,89.27]],"atb":[[1000,89.27]],"id":10445502},{"batb":[[0,160,5.51]],"atb":[[160,5.51]],"id":99072897}]}],"rt":639159132803685557,"dt":639159132803686265}
{"op":"mcm","id":2,"clk":"AO7KAQDnigEAnf8B","pt":1780316480458,"mc":[{"id":"1.258742455","rc":[{"tv":1470.61,"batb":[[2,19,26.31],[1,19.5,24.47],[0,20,23.6]],"trd":[[21,273.56]],"ltp":21,"atb":[[21,0]],"atl":[[21,1.79]],"batl":[[2,23,9.67],[1,22,9.7],[0,21,1.79]],"id":99072900}],"tv":41459.2}],"rt":639159132804659722,"dt":639159132804660218}
{"op":"mcm","id":2,"clk":"APvKAQDwigEArv8B","pt":1780316480664,"mc":[{"id":"1.258742455","rc":[{"batb":[],"atb":[[18.5,9.4]],"id":99072900}]}],"rt":639159132806724980,"dt":639159132806725327}
{"op":"mcm","id":2,"clk":"AInLAQD3igEAv/8B","pt":1780316480774,"mc":[{"id":"1.258742455","rc":[{"tv":1474.19,"batb":[[2,19.5,24.47],[1,20,23.6],[0,21,1.02]],"trd":[[21,277.14]],"atb":[[21,1.02]],"atl":[[21,0]],"batl":[[2,24,9.93],[1,23,9.67],[0,22,9.7]],"id":99072900}],"tv":41462.78}],"rt":639159132807824899,"dt":639159132807825340}
{"op":"mcm","id":2,"clk":"AI3LAQD6igEAxf8B","pt":1780316480870,"mc":[{"id":"1.258742455","rc":[{"batb":[[2,4.8,94.76]],"atb":[[4.7,75.04],[4.8,94.76]],"id":10398159}]}],"rt":639159132808786282,"dt":639159132808786689}
{"op":"mcm","id":2,"clk":"AJbLAQD/igEAzf8B","pt":1780316480972,"mc":[{"id":"1.258742455","rc":[{"tv":1475.73,"batb":[[2,19,26.31],[1,19.5,24.47],[0,20,23.99]],"trd":[[21,278.68]],"atb":[[21,0.39]],"id":99072900}],"tv":41464.32}],"rt":639159132809801564,"dt":639159132809801953}
{"op":"mcm","id":2,"clk":"AKPLAQCGiwEA3/8B","pt":1780316481124,"mc":[{"id":"1.258742455","rc":[{"atb":[[1.17,2.45]],"id":99072898},{"atl":[[48,10.82]],"batl":[[0,48,10.82]],"id":97008932},{"batb":[[2,19.5,24.47],[1,20,23.6],[0,21,1]],"atb":[[21,1],[1.01,137960.23]],"id":99072900},{"atl":[[60,0.56]],"batl":[[0,65,28.81]],"id":98464183},{"batb":[[0,11,21.59]],"atb":[[11,21.59]],"id":97736949}]}],"rt":639159132811320587,"dt":639159132811321450}
{"op":"mcm","id":2,"clk":"AKzLAQCKiwEA5/8B","pt":1780316481229,"mc":[{"id":"1.258742455","rc":[{"atb":[[1.17,2]],"atl":[[5,31.34]],"batl":[[0,5,31.34]],"id":99072898},{"atl":[[48,3.79]],"batl":[[0,48,3.79]],"id":97008932}]}],"rt":639159132812371232,"dt":639159132812371568}
{"op":"mcm","id":2,"clk":"ALXLAQCSiwEA8/8B","pt":1780316481344,"mc":[{"id":"1.258742455","rc":[{"tv":8930.37,"batb":[[0,4.9,46.53]],"trd":[[5,384.13]],"ltp":5,"atb":[[4.9,46.53]],"atl":[[5,27.34]],"batl":[[0,5,27.34]],"id":99072898},{"tv":593.87,"batb":[[0,46,2.61]],"trd":[[46,84.76]],"ltp":46,"atb":[[46,2.61]],"id":97008932},{"batb":[],"atb":[[4.1,48.33],[4.3,214.69]],"atl":[[5.2,103.21],[5.1,73.49]],"batl":[[1,5.2,103.21],[0,5.1,73.49]],"id":10398159},{"atl":[[3.6,73.9]],"batl":[[2,3.6,73.9]],"id":88302242}],"tv":41486.39}],"rt":639159132813529120,"dt":639159132813529664}
{"op":"mcm","id":2,"clk":"AL3LAQCUiwEA\u002BP8B","pt":1780316481439,"mc":[{"id":"1.258742455","rc":[{"atl":[[48,2.22]],"batl":[[0,48,2.22]],"id":97008932},{"batb":[[0,5,70]],"atb":[[5,70]],"id":10398159}]}],"rt":639159132814468373,"dt":639159132814468731}
{"op":"mcm","id":2,"clk":"AMbLAQCbiwEAgYAC","pt":1780316481543,"mc":[{"id":"1.258742455","rc":[{"batb":[[0,46,4.52]],"atb":[[46,4.52]],"id":97008932},{"batb":[[0,5,71.46]],"atb":[[5,71.46]],"id":10398159}]}],"rt":639159132815510275,"dt":639159132815510648}
{"op":"mcm","id":2,"clk":"AMzLAQCeiwEAjoAC","pt":1780316481645,"mc":[{"id":"1.258742455","rc":[{"atl":[[5,17.41]],"batl":[[0,5,17.41]],"id":99072898},{"atl":[[48,3.56]],"batl":[[0,48,3.56]],"id":97008932},{"batb":[[0,5,82.57]],"atb":[[5,82.57]],"id":10398159}]}],"rt":639159132816533940,"dt":639159132816534370}
{"op":"mcm","id":2,"clk":"ANDLAQCkiwEAl4AC","pt":1780316481750,"mc":[{"id":"1.258742455","rc":[{"tv":14515.28,"batb":[[0,3.45,76.28]],"trd":[[3.45,137.48]],"ltp":3.45,"atb":[[3.45,76.28]],"id":88302242}],"tv":41490.39}],"rt":639159132817581287,"dt":639159132817581666}
{"op":"mcm","id":2,"clk":"ANnLAQCuiwEAp4AC","pt":1780316481860,"mc":[{"id":"1.258742455","rc":[{"batb":[[1,44,10.53]],"atb":[[44,10.53]],"id":97008932},{"batb":[[0,5,108.65]],"atb":[[5,108.65]],"id":10398159}]}],"rt":639159132818683721,"dt":639159132818684253}
{"op":"mcm","id":2,"clk":"AN/LAQCziwEAs4AC","pt":1780316482053,"mc":[{"id":"1.258742455","rc":[{"tv":8920.36,"batb":[[0,5,105.65]],"trd":[[5,313.32]],"atb":[[5,105.65]],"id":10398159}],"tv":41496.39}],"rt":639159132820618579,"dt":639159132820619087}
{"op":"mcm","id":2,"clk":"AObLAQC3iwEAuoAC","pt":1780316482159,"mc":[{"id":"1.258742455","rc":[{"batb":[[0,5,108.51]],"atb":[[5,108.51]],"atl":[[5.8,4.75],[5.1,60.6]],"batl":[[0,5.1,60.6]],"id":10398159}]}],"rt":639159132821672138,"dt":639159132821672540}
{"op":"mcm","id":2,"clk":"AO7LAQC6iwEAxoAC","pt":1780316482256,"mc":[{"id":"1.258742455","rc":[{"batb":[[0,46,4.64]],"atb":[[46,4.64]],"id":97008932},{"batb":[],"atb":[[4.2,24.16],[4.3,207.69]],"id":10398159}]}],"rt":639159132822645891,"dt":639159132822646306}
{"op":"mcm","id":2,"clk":"APPLAQC/iwEAzoAC","pt":1780316482359,"mc":[{"id":"1.258742455","rc":[{"atl":[[5.1,65.8]],"batl":[[0,5.1,65.8]],"id":10398159},{"batb":[],"atb":[[690,2],[670,0]],"id":10445502}]}],"rt":639159132823668878,"dt":639159132823669250}
{"op":"mcm","id":2,"clk":"AIPMAQDNiwEA8IAC","pt":1780316482572,"mc":[{"id":"1.258742455","rc":[{"batb":[],"atb":[[120,4.4]],"id":99072897}]}],"rt":639159132825799196,"dt":639159132825799602}
{"op":"mcm","id":2,"clk":"AI/MAQDZiwEAhYEC","pt":1780316482781,"mc":[{"id":"1.258742455","rc":[{"tv":8949.42,"batb":[[0,5,93.98]],"trd":[[5,342.38]],"atb":[[5,93.98]],"id":10398159}],"tv":41525.45}],"rt":639159132827888670,"dt":639159132827889150}
{"op":"mcm","id":2,"clk":"AJLMAQDgiwEAioEC","pt":1780316482879,"mc":[{"id":"1.258742455","rc":[{"tv":8944.37,"batb":[[0,4.9,39.53]],"trd":[[4.9,862.17]],"ltp":4.9,"atb":[[4.9,39.53]],"id":99072898},{"atl":[[3.55,64.45]],"batl":[[1,3.55,64.45]],"id":88302242}],"tv":41539.45}],"rt":639159132828867943,"dt":639159132828868444}
{"op":"mcm","id":2,"clk":"AJXMAQDkiwEAl4EC","pt":1780316482976,"mc":[{"id":"1.258742455","rc":[{"atl":[[5,27.99]],"batl":[[0,5,27.99]],"id":99072898},{"batb":[[0,46,4.74]],"atb":[[46,4.74]],"id":97008932},{"batb":[[0,5,91.12]],"atb":[[5,91.12]],"atl":[[5.1,68.79]],"batl":[[0,5.1,68.79]],"id":10398159},{"atl":[[3.5,28.72]],"batl":[[0,3.5,28.72]],"id":88302242}]}],"rt":639159132829841380,"dt":639159132829841927}
{"op":"mcm","id":2,"clk":"AJjMAQDsiwEApIEC","pt":1780316483078,"mc":[{"id":"1.258742455","rc":[{"batb":[[0,4.9,50.39]],"atb":[[4.9,50.39]],"id":99072898}]}],"rt":639159132830875121,"dt":639159132830875525}
{"op":"mcm","id":2,"clk":"ALDMAQCNjAEA1YEC","pt":1780316483444,"mc":[{"id":"1.258742455","rc":[{"atl":[[5,37.99]],"batl":[[0,5,37.99]],"id":99072898}]}],"rt":639159132834523385,"dt":639159132834523780}
{"op":"mcm","id":2,"clk":"ALbMAQCRjAEA3YEC","pt":1780316483543,"mc":[{"id":"1.258742455","rc":[{"batb":[[0,21,1.19]],"atb":[[21,1.19]],"id":99072900}]}],"rt":639159132835509921,"dt":639159132835510255}
{"op":"mcm","id":2,"clk":"ALrMAQCajAEA54EC","pt":1780316483645,"mc":[{"id":"1.258742455","rc":[{"atl":[[5,44.68]],"batl":[[0,5,44.68]],"id":99072898}]}],"rt":639159132836534938,"dt":639159132836535278}
{"op":"mcm","id":2,"clk":"AMLMAQCfjAEA74EC","pt":1780316483752,"mc":[{"id":"1.258742455","rc":[{"tv":9033.72,"batb":[[2,4.8,50.38],[1,4.9,50.39],[0,5,20.2]],"trd":[[5,473.48]],"ltp":5,"atb":[[5,20.2]],"atl":[[5,0]],"batl":[[2,5.3,21.15],[1,5.2,27.03],[0,5.1,43.1]],"id":99072898}],"tv":41628.8}],"rt":639159132837601919,"dt":639159132837602393}
{"op":"mcm","id":2,"clk":"AMvMAQCjjAEA94EC","pt":1780316483852,"mc":[{"id":"1.258742455","rc":[{"batb":[[0,5,30.43]],"atb":[[5,30.43]],"atl":[[5.4,43.88]],"batl":[],"id":99072898},{"batb":[],"atb":[[18.5,7.61]],"id":99072900},{"batb":[[0,5,64.52]],"atb":[[5,64.52]],"id":10398159},{"batb":[],"atb":[[7.6,146.46]],"id":98117699},{"batb":[[0,3.45,43.58]],"atb":[[3.45,43.58]],"atl":[[3.5,50.14]],"batl":[[0,3.5,50.14]],"id":88302242}]}],"rt":639159132838602361,"dt":639159132838603028}
{"op":"mcm","id":2,"clk":"ANDMAQCojAEAgIIC","pt":1780316483954,"mc":[{"id":"1.258742455","rc":[{"batb":[[1,4.9,52.63]],"atb":[[4.9,52.63]],"atl":[[1000,6.7],[5.4,46.14]],"batl":[],"id":99072898},{"batb":[[0,21,1]],"atb":[[21,1]],"id":99072900},{"batb":[],"atb":[[4.7,68.16],[4.6,114.85]],"id":10398159},{"batb":[[1,8,69.17]],"atb":[[8,69.17]],"id":98117699},{"tv":14602.44,"batb":[[2,3.3,59.99],[1,3.35,159.77],[0,3.4,94.79]],"trd":[[3.45,224.64]],"atb":[[3.45,0]],"atl":[[3.45,6.42]],"batl":[[2,3.55,64.45],[1,3.5,50.14],[0,3.45,6.42]],"id":88302242}],"tv":41715.96}],"rt":639159132839626402,"dt":639159132839627264}
{"op":"mcm","id":2,"clk":"ANXMAQCtjAEAiIIC","pt":1780316484058,"mc":[{"id":"1.258742455","rc":[{"batb":[[0,5,37.28]],"atb":[[5,37.28]],"atl":[[1000,6.25],[5.4,43.88]],"batl":[],"id":99072898},{"batb":[[0,46,5.03]],"atb":[[46,5.03]],"id":97008932},{"batb":[[0,21,1.63]],"atb":[[21,1.63]],"id":99072900},{"batb":[[0,95,4.66]],"atb":[[95,4.66]],"id":99072901},{"batb":[[0,5,76.33]],"atb":[[4.7,75.02],[5,76.33]],"id":10398159},{"batb":[[0,8.2,14.45]],"atb":[[8.2,14.45]],"id":98117699},{"tv":14607.14,"batb":[[0,3.4,113.74]],"trd":[[3.45,229.34]],"atb":[[3.4,113.74]],"atl":[[3.5,52.35],[3.45,4.07]],"batl":[[1,3.5,52.35],[0,3.45,4.07]],"id":88302242},{"batb":[[0,11,22.79]],"atb":[[11,22.79]],"id":97736949},{"atb":[[140,0]],"id":10445502}],"tv":41720.66}],"rt":639159132840661501,"dt":639159132840662384}
{"op":"mcm","id":2,"clk":"ANrMAQC1jAEAj4IC","pt":1780316484161,"mc":[{"id":"1.258742455","rc":[{"tv":9040.68,"batb":[[0,5,35.28]],"trd":[[5,480.44]],"atb":[[5,35.28]],"atl":[[5.5,39.3],[5.1,35.74]],"batl":[[0,5.1,35.74]],"id":99072898},{"batb":[[0,46,5.24]],"atb":[[46,5.24]],"id":97008932},{"batb":[[0,21,2.01]],"atb":[[1.17,2.36],[21,2.01]],"id":99072900},{"batb":[[0,8.2,14.87]],"atb":[[1.17,2.82],[8.2,14.87]],"id":98117699},{"tv":14615.28,"batb":[[2,3.35,159.77],[1,3.4,97.69],[0,3.45,3.04]],"trd":[[3.45,237.48]],"atb":[[1.17,196.3],[3.4,97.69],[3.45,3.04]],"atl":[[3.5,64.37],[3.45,0]],"batl":[[2,3.6,73.9],[1,3.55,64.45],[0,3.5,64.37]],"id":88302242},{"batb":[[0,11,23.29]],"atb":[[11,23.29]],"id":97736949},{"atb":[[150,1]],"id":10445502}],"tv":41735.76}],"rt":639159132841693399,"dt":639159132841694018}
{"op":"mcm","id":2,"clk":"AN7MAQC6jAEAloIC","pt":1780316484265,"mc":[{"id":"1.258742455","rc":[{"batb":[[0,5,28.42]],"atb":[[5,28.42]],"atl":[[5.4,40.14]],"batl":[],"id":99072898},{"tv":1481.73,"trd":[[22,165.68]],"ltp":22,"atb":[[1.17,2]],"atl":[[22,6.7]],"batl":[[0,22,6.7]],"id":99072900},{"batb":[[0,5,78.57]],"atb":[[4.7,68.16],[5,78.57]],"id":10398159},{"batb":[[0,8.2,11.16]],"atb":[[1.17,2],[8.2,11.16]],"id":98117699},{"tv":14617.86,"batb":[],"trd":[[3.5,910.11]],"ltp":3.5,"atb":[[1.17,196.12],[3.25,41.48]],"atl":[[3.5,74.11]],"batl":[[0,3.5,74.11]],"id":88302242},{"atb":[[100,10]],"id":10445502}],"tv":41744.34}],"rt":639159132842730675,"dt":639159132842731551}
{"op":"mcm","id":2,"clk":"AOfMAQC\u002BjAEAm4IC","pt":1780316484364,"mc":[{"id":"1.258742455","rc":[{"batb":[[0,5,26.95]],"atb":[[5,26.95],[4.5,41.5]],"id":99072898},{"batb":[[0,21,2.37]],"atb":[[21,2.37]],"id":99072900},{"batb":[[2,4.8,78.28]],"atb":[[4.8,78.28]],"atl":[[5.5,14.5]],"batl":[],"id":10398159},{"batb":[[0,8.2,11.98]],"atb":[[8.2,11.98]],"id":98117699},{"batb":[[0,3.45,3.22]],"atb":[[3.45,3.22]],"id":88302242}]}],"rt":639159132843718909,"dt":639159132843719397}
{"op":"mcm","id":2,"clk":"AO7MAQDBjAEAo4IC","pt":1780316484464,"mc":[{"id":"1.258742455","rc":[{"atl":[[5.1,37.85]],"batl":[[0,5.1,37.85]],"id":99072898},{"batb":[[0,21,3.92]],"atb":[[21,3.92]],"id":99072900},{"batb":[[0,8.2,11.56]],"atb":[[8.2,11.56]],"id":98117699}]}],"rt":639159132844727006,"dt":639159132844727391}
{"op":"mcm","id":2,"clk":"APjMAQDHjAEArYIC","pt":1780316484567,"mc":[{"id":"1.258742455","rc":[{"batb":[],"atb":[[4.6,78.32]],"atl":[[5.5,45.3]],"batl":[],"id":99072898},{"atl":[[22,8.91]],"batl":[[0,22,8.91]],"id":99072900},{"batb":[[1,3.4,114.09]],"atb":[[3.4,114.09]],"id":88302242}]}],"rt":639159132845753403,"dt":639159132845753839}
{"op":"mcm","id":2,"clk":"AP3MAQDIjAEAtIIC","pt":1780316484669,"mc":[{"id":"1.258742455","rc":[{"batb":[[0,95,3.7]],"atb":[[95,3.7]],"id":99072901}]}],"rt":639159132846771874,"dt":639159132846772330}
{"op":"mcm","id":2,"clk":"AIzNAQDVjAEAx4IC","pt":1780316484877,"mc":[{"id":"1.258742455","rc":[{"batb":[[0,8.2,11.73]],"atb":[[8.2,11.73]],"id":98117699},{"batb":[[0,11,22.08]],"atb":[[11,22.08]],"id":97736949}]}],"rt":639159132848857848,"dt":639159132848858426}
{"op":"mcm","id":2,"clk":"AJPNAQDhjAEA2YIC","pt":1780316485081,"mc":[{"id":"1.258742455","rc":[{"batb":[],"atb":[[4.7,123.86]],"id":99072898}]}],"rt":639159132850893523,"dt":639159132850893854}
{"op":"mcm","id":2,"clk":"AKHNAQDqjAEA64IC","pt":1780316485243,"mc":[{"id":"1.258742455","rc":[{"atl":[[20,0]],"id":99072898},{"atl":[[300,0]],"id":99072900},{"atl":[[19,0.55]],"id":10398159},{"atl":[[80,0]],"id":98117699},{"atl":[[11,24.13]],"id":88302242},{"batb":[[0,11,22.71]],"atb":[[11,22.71]],"atl":[[11.5,14.13],[130,0]],"batl":[[0,11.5,14.13]],"id":97736949}]}],"rt":639159132852507700,"dt":639159132852508530}
{"op":"mcm","id":2,"clk":"AMHNAQD8jAEAiIMC","pt":1780316485543,"mc":[{"id":"1.258742455","rc":[{"batb":[[0,8.2,11.56]],"atb":[[8.2,11.56]],"id":98117699},{"tv":14619.86,"batb":[[0,3.45,2.22]],"trd":[[3.45,239.48]],"ltp":3.45,"atb":[[3.45,2.22]],"id":88302242}],"tv":41746.34}],"rt":639159132855514258,"dt":639159132855514959}
{"op":"mcm","id":2,"clk":"AMjNAQCAjQEAkoMC","pt":1780316485647,"mc":[{"id":"1.258742455","rc":[{"batb":[[0,5,89.51]],"atb":[[5,89.51]],"id":10398159},{"batb":[[0,11,24.07]],"atb":[[11,24.07]],"atl":[[11.5,13.46]],"batl":[[0,11.5,13.46]],"id":97736949}]}],"rt":639159132856552902,"dt":639159132856553393}
{"op":"mcm","id":2,"clk":"ANPNAQCIjQEAoYMC","pt":1780316485850,"mc":[{"id":"1.258742455","rc":[{"batb":[[1,4.9,53.63]],"atb":[[4.9,53.63]],"atl":[[19.5,1.86]],"id":99072898},{"tv":8960.7,"batb":[[1,4.9,192.29],[0,5,83.87]],"trd":[[5,353.66]],"atb":[[4.9,192.29],[5,83.87]],"id":10398159}],"tv":41757.62}],"rt":639159132858586607,"dt":639159132858587030}
{"op":"mcm","id":2,"clk":"ANrNAQCNjQEAqoMC","pt":1780316485957,"mc":[{"id":"1.258742455","rc":[{"atl":[[32,2.18]],"id":99072898},{"atl":[[200,1.76]],"batl":[[2,200,1.76]],"id":99072897}]}],"rt":639159132859650237,"dt":639159132859650865}
{"op":"mcm","id":2,"clk":"AN7NAQCQjQEAtYMC","pt":1780316486057,"mc":[{"id":"1.258742455","rc":[{"batb":[[0,5,81.63]],"atb":[[5,81.63]],"id":10398159}]}],"rt":639159132860650734,"dt":639159132860651055}
{"op":"mcm","id":2,"clk":"AOLNAQCWjQEAvIMC","pt":1780316486157,"mc":[{"id":"1.258742455","rc":[{"batb":[[0,21,2.37]],"atb":[[21,2.37]],"id":99072900}]}],"rt":639159132861649828,"dt":639159132861650184}
{"op":"mcm","id":2,"clk":"AOTNAQCbjQEAyYMC","pt":1780316486260,"mc":[{"id":"1.258742455","rc":[{"batb":[[0,5,82.04]],"atb":[[5,82.04]],"id":10398159}]}],"rt":639159132862681360,"dt":639159132862681841}
{"op":"mcm","id":2,"clk":"AO7NAQCjjQEA24MC","pt":1780316486464,"mc":[{"id":"1.258742455","rc":[{"atl":[[28,3.88],[26,24.71]],"batl":[],"id":99072900},{"batb":[],"atb":[[690,0],[660,2]],"id":10445502}]}],"rt":639159132864727998,"dt":639159132864728553}
{"op":"mcm","id":2,"clk":"APLNAQCmjQEA44MC","pt":1780316486566,"mc":[{"id":"1.258742455","rc":[{"batb":[[0,21,2.6]],"atb":[[21,2.6]],"id":99072900},{"batb":[[0,5,82.68]],"atb":[[5,82.68]],"id":10398159}]}],"rt":639159132865746496,"dt":639159132865746906}
{"op":"mcm","id":2,"clk":"AP/NAQCyjQEA\u002BIMC","pt":1780316486774,"mc":[{"id":"1.258742455","rc":[{"batb":[[1,4.9,53.18]],"atb":[[4.9,53.18]],"id":99072898}]}],"rt":639159132867818819,"dt":639159132867819251}
{"op":"mcm","id":2,"clk":"AITOAQCzjQEAgYQC","pt":1780316486874,"mc":[{"id":"1.258742455","rc":[{"batb":[[2,4.8,48.91]],"atb":[[1.17,3.42],[4.8,48.91]],"id":99072898},{"atl":[[3.6,57.24]],"batl":[[2,3.6,57.24]],"id":88302242}]}],"rt":639159132868819976,"dt":639159132868820463}
{"op":"mcm","id":2,"clk":"AIvOAQC\u002BjQEAhoQC","pt":1780316486980,"mc":[{"id":"1.258742455","rc":[{"batb":[[0,5,27.12]],"atb":[[1.17,2],[5,27.12]],"id":99072898},{"atl":[[3.5,90.77]],"batl":[[0,3.5,90.77]],"id":88302242}]}],"rt":639159132869884418,"dt":639159132869884884}
{"op":"mcm","id":2,"clk":"AJHOAQDCjQEAjIQC","pt":1780316487082,"mc":[{"id":"1.258742455","rc":[{"batb":[[1,4.9,54.01],[0,5,27.71]],"atb":[[4.9,54.01],[5,27.71]],"id":99072898}]}],"rt":639159132870901173,"dt":639159132870901525}
{"op":"mcm","id":2,"clk":"AJzOAQDJjQEApoQC","pt":1780316487244,"mc":[{"id":"1.258742455","rc":[{"batb":[[0,5,83.5]],"atb":[[5,83.5]],"id":10398159}]}],"rt":639159132872520201,"dt":639159132872520687}
{"op":"mcm","id":2,"clk":"AKvOAQDQjQEAtoQC","pt":1780316487442,"mc":[{"id":"1.258742455","rc":[{"batb":[[0,3.45,2.04]],"atb":[[3.45,2.04]],"id":88302242}]}],"rt":639159132874501143,"dt":639159132874501549}
{"op":"mcm","id":2,"clk":"ALLOAQDUjQEAwYQC","pt":1780316487548,"mc":[{"id":"1.258742455","rc":[{"batb":[[0,21,2.94]],"atb":[[21,2.94]],"id":99072900}]}],"rt":639159132875566668,"dt":639159132875567067}
{"op":"mcm","id":2,"clk":"ALrOAQDYjQEAy4QC","pt":1780316487652,"mc":[{"id":"1.258742455","rc":[{"tv":9060.7,"batb":[[0,5,33.5]],"trd":[[5,453.66]],"atb":[[5,33.5]],"id":10398159}],"tv":41857.62}],"rt":639159132876604002,"dt":639159132876604498}
{"op":"mcm","id":2,"clk":"AMbOAQDbjQEA0oQC","pt":1780316487752,"mc":[{"id":"1.258742455","rc":[{"tv":9064.44,"batb":[[2,4.7,68.16],[1,4.8,78.28],[0,4.9,192.29]],"trd":[[5,457.4]],"atb":[[5,0]],"atl":[[5,8.13]],"batl":[[2,5.2,103.21],[1,5.1,68.79],[0,5,8.13]],"id":10398159}],"tv":41861.36}],"rt":639159132877600458,"dt":639159132877601733}
{"op":"mcm","id":2,"clk":"AMzOAQDhjQEA2oQC","pt":1780316487857,"mc":[{"id":"1.258742455","rc":[{"batb":[[0,5,51.37]],"atb":[[5,51.37]],"id":99072898},{"tv":9066.92,"trd":[[5,459.88]],"atl":[[5,6.89],[5.1,77.39]],"batl":[[1,5.1,77.39],[0,5,6.89]],"id":10398159},{"batb":[[0,8.2,15.92]],"atb":[[8.2,15.92]],"id":98117699},{"batb":[[0,3.45,2.48]],"atb":[[3.45,2.48]],"id":88302242},{"batb":[[0,1000,89.28]],"atb":[[1000,89.28]],"id":10445502}],"tv":41863.84}],"rt":639159132878654493,"dt":639159132878655086}
{"op":"mcm","id":2,"clk":"ANHOAQDkjQEA44QC","pt":1780316487959,"mc":[{"id":"1.258742455","rc":[{"batb":[],"atb":[[4.5,30.5]],"atl":[[5.1,35.74]],"batl":[[0,5.1,35.74]],"id":99072898},{"batb":[[0,4.9,176.02]],"atb":[[4.9,176.02]],"id":10398159},{"atl":[[3.5,79.74]],"batl":[[0,3.5,79.74]],"id":88302242}]}],"rt":639159132879670611,"dt":639159132879671032}
{"op":"mcm","id":2,"clk":"ANjOAQDrjQEA7IQC","pt":1780316488063,"mc":[{"id":"1.258742455","rc":[{"batb":[[0,5,59.83]],"atb":[[4.7,102.28],[5,59.83]],"id":99072898},{"batb":[],"atb":[[4.6,108.85]],"atl":[[5,11.41]],"batl":[[0,5,11.41]],"id":10398159},{"batb":[[0,8.2,16.66]],"atb":[[8.2,16.66]],"atl":[[8.4,24.03]],"batl":[[0,8.4,24.03]],"id":98117699}]}],"rt":639159132880708707,"dt":639159132880709132}
{"op":"mcm","id":2,"clk":"AN7OAQDtjQEA9IQC","pt":1780316488160,"mc":[{"id":"1.258742455","rc":[{"atb":[[3.7,52.3]],"id":10398159},{"atl":[[3.5,83.68]],"batl":[[0,3.5,83.68]],"id":88302242}]}],"rt":639159132881685359,"dt":639159132881685777}
{"op":"mcm","id":2,"clk":"AOfOAQDzjQEA\u002B4QC","pt":1780316488264,"mc":[{"id":"1.258742455","rc":[{"atl":[[5.1,26.43]],"batl":[[0,5.1,26.43]],"id":99072898},{"batb":[],"atb":[[4.5,113.3]],"atl":[[5.5,8.5]],"batl":[],"id":10398159}]}],"rt":639159132882724817,"dt":639159132882725159}
{"op":"mcm","id":2,"clk":"AOnOAQD5jQEAhoUC","pt":1780316488366,"mc":[{"id":"1.258742455","rc":[{"atl":[[5.1,17.81]],"batl":[[0,5.1,17.81]],"id":99072898},{"batb":[[0,4.9,179.62]],"atb":[[4.9,179.62]],"id":10398159},{"batb":[[0,3.45,2.04]],"atb":[[3.45,2.04]],"id":88302242}]}],"rt":639159132883742710,"dt":639159132883743264}
{"op":"mcm","id":2,"clk":"APPOAQD\u002BjQEAlYUC","pt":1780316488472,"mc":[{"id":"1.258742455","rc":[{"atl":[[5.4,56.44]],"batl":[],"id":10398159}]}],"rt":639159132884804281,"dt":639159132884804612}
{"op":"mcm","id":2,"clk":"APfOAQCBjgEAm4UC","pt":1780316488571,"mc":[{"id":"1.258742455","rc":[{"batb":[[0,5,61.3]],"atb":[[5,61.3]],"id":99072898}]}],"rt":639159132885799141,"dt":639159132885799548}
{"op":"mcm","id":2,"clk":"APzOAQCIjgEApIUC","pt":1780316488676,"mc":[{"id":"1.258742455","rc":[{"batb":[[0,5,65.3]],"atb":[[5,65.3]],"id":99072898},{"tv":9082.49,"trd":[[5,475.45]],"atl":[[5,3.63]],"batl":[[0,5,3.63]],"id":10398159}],"tv":41879.41}],"rt":639159132886841497,"dt":639159132886841899}
{"op":"mcm","id":2,"clk":"AIXPAQCNjgEAroUC","pt":1780316488780,"mc":[{"id":"1.258742455","rc":[{"atl":[[5.4,37.88]],"batl":[],"id":99072898},{"tv":9089.75,"batb":[[2,4.8,78.28],[1,4.9,179.62],[0,5,26.52]],"trd":[[5,482.71]],"atb":[[5,26.52]],"atl":[[5,0]],"batl":[[2,5.3,43.59],[1,5.2,103.21],[0,5.1,77.39]],"id":10398159}],"tv":41886.67}],"rt":639159132887878506,"dt":639159132887878911}
{"op":"mcm","id":2,"clk":"AInPAQCRjgEAtYUC","pt":1780316488880,"mc":[{"id":"1.258742455","rc":[{"atl":[[5.4,40.12]],"batl":[],"id":99072898},{"batb":[[1,4.9,182.26]],"atb":[[4.9,182.26]],"id":10398159},{"batb":[[0,8.2,12.66]],"atb":[[8.2,12.66]],"id":98117699},{"tv":14792.85,"batb":[[2,3.3,59.99],[1,3.35,159.77],[0,3.4,29.63]],"trd":[[3.4,171.91],[3.45,243.56]],"ltp":3.4,"atb":[[3.4,29.63],[3.45,0]],"id":88302242}],"tv":42059.66}],"rt":639159132888884041,"dt":639159132888884490}
{"op":"mcm","id":2,"clk":"AIzPAQCVjgEAu4UC","pt":1780316488979,"mc":[{"id":"1.258742455","rc":[{"atl":[[5.4,37.88],[5.5,42.91]],"batl":[],"id":99072898},{"batb":[[2,19.5,26.2]],"atb":[[19.5,26.2]],"id":99072900},{"batb":[],"atb":[[4.7,72.89]],"id":10398159},{"batb":[[0,8.2,11.56]],"atb":[[8.2,11.56]],"id":98117699},{"batb":[[1,3.35,185.03]],"atb":[[3.25,47.25],[3.35,185.03]],"atl":[[3.5,86.8],[3.7,293.41],[3.45,18.25]],"batl":[[2,3.55,64.45],[1,3.5,86.8],[0,3.45,18.25]],"id":88302242}]}],"rt":639159132889874191,"dt":639159132889874932}
{"op":"mcm","id":2,"clk":"AJTPAQCVjgEAwYUC","pt":1780316489082,"mc":[{"id":"1.258742455","rc":[{"tv":9076.31,"batb":[[2,4.9,54.01],[1,5,65.3],[0,5.1,9.81]],"trd":[[5.1,35.63]],"ltp":5.1,"atb":[[4.6,71.83],[5.1,9.81]],"atl":[[5.1,0]],"batl":[[2,5.4,37.88],[1,5.3,21.15],[0,5.2,27.03]],"id":99072898},{"atl":[[48,2.22]],"batl":[[0,48,2.22]],"id":97008932},{"batb":[[0,21,3.5]],"atb":[[21,3.5]],"id":99072900},{"batb":[[2,4.8,83.04]],"atb":[[4.8,83.04]],"atl":[[5.1,74.4]],"batl":[[0,5.1,74.4]],"id":10398159},{"atl":[[60,0.47]],"batl":[[0,65,28.72]],"id":98464183},{"batb":[[0,8.2,15.38]],"atb":[[8.2,15.38]],"atl":[[8.4,23.2]],"batl":[[0,8.4,23.2]],"id":98117699},{"batb":[[1,3.35,179.27],[0,3.4,35.25]],"atb":[[3.25,69.1],[3.4,35.25],[3.35,179.27]],"atl":[[3.75,44.35],[3.45,20.3]],"batl":[[0,3.45,20.3]],"id":88302242}],"tv":42095.29}],"rt":639159132890901786,"dt":639159132890902419}
{"op":"mcm","id":2,"clk":"AJ7PAQCcjgEAxoUC","pt":1780316489188,"mc":[{"id":"1.258742455","rc":[{"atl":[[5.7,11.83],[5.6,30.37]],"batl":[],"id":99072898},{"batb":[[2,4.8,78.28],[1,4.9,189.22]],"atb":[[4.9,189.22],[4.5,107.3],[4.8,78.28]],"id":10398159},{"batb":[[0,8.2,12.1]],"atb":[[8.2,12.1]],"id":98117699},{"tv":14795.23,"trd":[[3.45,245.94]],"ltp":3.45,"atl":[[3.45,19.11]],"batl":[[0,3.45,19.11]],"id":88302242}],"tv":42097.67}],"rt":639159132891968057,"dt":639159132891968559}
{"op":"mcm","id":2,"clk":"AKPPAQCgjgEA0oUC","pt":1780316489293,"mc":[{"id":"1.258742455","rc":[{"batb":[[1,5,68.62],[0,5.1,10.81]],"atb":[[5,68.62],[5.1,10.81],[4.5,21.83]],"atl":[[5.2,20.72]],"batl":[[0,5.2,20.72]],"id":99072898},{"atl":[[48,2.86]],"batl":[[0,48,2.86]],"id":97008932},{"tv":14827.31,"batb":[[0,3.4,11.4]],"trd":[[3.45,278.02]],"atb":[[3.25,63.1],[3.4,11.4],[3.2,37.8]],"atl":[[3.5,94.21],[3.7,287.41],[3.45,10.64]],"batl":[[1,3.5,94.21],[0,3.45,10.64]],"id":88302242}],"tv":42129.75}],"rt":639159132893008869,"dt":639159132893009372}
{"op":"mcm","id":2,"clk":"AKbPAQCpjgEA2oUC","pt":1780316489389,"mc":[{"id":"1.258742455","rc":[{"batb":[],"atb":[[4.6,65.83]],"atl":[[5.4,17.26],[5.5,36.91]],"batl":[[2,5.4,17.26]],"id":99072898},{"batb":[],"atb":[[4.6,114.85]],"atl":[[5.4,50.44]],"batl":[],"id":10398159},{"batb":[[0,8.2,11.56]],"atb":[[8.2,11.56]],"id":98117699},{"tv":14829.69,"trd":[[3.45,280.4]],"atl":[[3.45,9.45]],"batl":[[0,3.45,9.45]],"id":88302242}],"tv":42132.13}],"rt":639159132893976473,"dt":639159132893977024}
{"op":"mcm","id":2,"clk":"AKvPAQCrjgEA64UC","pt":1780316489447,"mc":[{"id":"1.258742455","rc":[{"batb":[[0,5.1,9.81]],"atb":[[4.6,61.83],[5.1,9.81]],"id":99072898},{"batb":[],"atb":[[3.2,43.8]],"atl":[[3.65,69.25]],"batl":[],"id":88302242}]}],"rt":639159132894550336,"dt":639159132894550782}
{"op":"mcm","id":2,"clk":"ALHPAQCxjgEA\u002BIUC","pt":1780316489549,"mc":[{"id":"1.258742455","rc":[{"batb":[[0,5.1,10.45]],"atb":[[4.7,108.28],[5.1,10.45]],"atl":[[5.2,18.86],[5.6,36.37]],"batl":[[0,5.2,18.86]],"id":99072898},{"tv":9189.76,"trd":[[5.1,247.07]],"ltp":5.1,"atl":[[5.5,14.5],[5.1,24.38]],"batl":[[0,5.1,24.38]],"id":10398159},{"tv":14831.7,"trd":[[3.45,282.41]],"atl":[[3.45,26.99]],"batl":[[0,3.45,26.99]],"id":88302242},{"batb":[[0,11,24.35]],"atb":[[11,24.35]],"id":97736949}],"tv":42234.15}],"rt":639159132895571352,"dt":639159132895571878}
{"op":"mcm","id":2,"clk":"ALjPAQC3jgEAgYYC","pt":1780316489650,"mc":[{"id":"1.258742455","rc":[{"atl":[[5.6,38.57]],"batl":[],"id":99072898},{"batb":[[2,19.5,24.47]],"atb":[[19.5,24.47]],"id":99072900},{"batb":[[2,4.8,88.72]],"atb":[[4.8,88.72]],"atl":[[5.2,127.81],[5.5,23.68]],"batl":[[1,5.2,127.81]],"id":10398159}]}],"rt":639159132896577322,"dt":639159132896577728}
{"op":"mcm","id":2,"clk":"AMDPAQC8jgEAjIYC","pt":1780316489758,"mc":[{"id":"1.258742455","rc":[{"batb":[[1,4.9,194.78],[0,5,42.34]],"atb":[[4.9,194.78],[5,42.34],[4.3,204.94]],"atl":[[5.5,34.72],[5.8,13.97],[5.1,12.82]],"batl":[[0,5.1,12.82]],"id":10398159},{"tv":14836,"batb":[[2,3.25,63.1],[1,3.3,59.99],[0,3.35,179.27]],"trd":[[3.45,286.71]],"atb":[[3.4,0],[3.1,15.32]],"atl":[[1000,3.29],[3.45,36.04]],"batl":[[0,3.45,36.04]],"id":88302242},{"atl":[[11.5,13.21]],"batl":[[0,11.5,13.21]],"id":97736949}],"tv":42238.45}],"rt":639159132897663246,"dt":639159132897663793}
{"op":"mcm","id":2,"clk":"AMTPAQC9jgEAkoYC","pt":1780316489853,"mc":[{"id":"1.258742455","rc":[{"tv":9084.21,"batb":[[0,5.1,10.8]],"trd":[[5.1,43.53]],"atb":[[5.1,10.8]],"atl":[[5.2,19.67]],"batl":[[0,5.2,19.67]],"id":99072898},{"batb":[[0,5,58.64]],"atb":[[5,58.64]],"atl":[[1000,1.28],[5.3,22.74]],"batl":[[2,5.3,22.74]],"id":10398159},{"batb":[[0,8.2,7.47]],"atb":[[8.2,7.47]],"id":98117699},{"batb":[],"atb":[[3.2,72.29]],"atl":[[1000,3]],"id":88302242},{"batb":[[0,11,26.33]],"atb":[[11,26.33]],"id":97736949}],"tv":42246.35}],"rt":639159132898616063,"dt":639159132898616632}
{"op":"mcm","id":2,"clk":"AMrPAQDDjgEAnYYC","pt":1780316489958,"mc":[{"id":"1.258742455","rc":[{"batb":[[0,3.35,159]],"atb":[[3.35,159]],"atl":[[3.5,94.5],[3.45,47.29]],"batl":[[1,3.5,94.5],[0,3.45,47.29]],"id":88302242}]}],"rt":639159132899660339,"dt":639159132899660971}
{"op":"mcm","id":2,"clk":"ANDPAQDGjgEApYYC","pt":1780316490066,"mc":[{"id":"1.258742455","rc":[{"batb":[[0,5.1,9.48]],"atb":[[5.1,9.48]],"id":99072898},{"batb":[[0,46,5.14]],"atb":[[46,5.14]],"id":97008932},{"atl":[[1000,1.01],[5.1,14.67]],"batl":[[0,5.1,14.67]],"id":10398159},{"atl":[[8.4,24.65]],"batl":[[0,8.4,24.65]],"id":98117699},{"batb":[],"atb":[[3.2,66.29]],"id":88302242}]}],"rt":639159132900738404,"dt":639159132900738835}
{"op":"mcm","id":2,"clk":"ANTPAQDKjgEAqoYC","pt":1780316490163,"mc":[{"id":"1.258742455","rc":[{"atl":[[5.2,20.69]],"batl":[[0,5.2,20.69]],"id":99072898},{"atl":[[5.2,128.08],[5.1,40.38]],"batl":[[1,5.2,128.08],[0,5.1,40.38]],"id":10398159},{"batb":[[0,3.35,155.16]],"atb":[[3.35,155.16]],"id":88302242},{"atb":[[1.17,2.3]],"id":97736949}]}],"rt":639159132901716084,"dt":639159132901716498}
{"op":"mcm","id":2,"clk":"ANrPAQDOjgEAsYYC","pt":1780316490263,"mc":[{"id":"1.258742455","rc":[{"batb":[[2,3.3,59.99],[1,3.35,155.16],[0,3.4,15]],"atb":[[3.15,28.21],[3.4,15]],"id":88302242},{"atb":[[1.17,2]],"id":97736949}]}],"rt":639159132902716172,"dt":639159132902716565}
{"op":"mcm","id":2,"clk":"AODPAQDRjgEAuIYC","pt":1780316490366,"mc":[{"id":"1.258742455","rc":[{"batb":[[0,5.1,5.86]],"atb":[[5.1,5.86]],"id":99072898},{"batb":[[0,5,53.53]],"atb":[[5,53.53]],"atl":[[5.1,42.76]],"batl":[[0,5.1,42.76]],"id":10398159},{"tv":14838,"trd":[[3.45,288.71]],"atl":[[3.45,46.29]],"batl":[[0,3.45,46.29]],"id":88302242},{"batb":[[0,11,26.63]],"atb":[[11,26.63]],"id":97736949}],"tv":42248.35}],"rt":639159132903744098,"dt":639159132903744636}
{"op":"mcm","id":2,"clk":"AOXPAQDUjgEAvoYC","pt":1780316490472,"mc":[{"id":"1.258742455","rc":[{"batb":[[0,5.1,7.05]],"atb":[[5.1,7.05]],"id":99072898},{"batb":[[0,3.4,29.68]],"atb":[[3.4,29.68]],"id":88302242}]}],"rt":639159132904805925,"dt":639159132904806316}
{"op":"mcm","id":2,"clk":"AOrPAQDVjgEAxoYC","pt":1780316490572,"mc":[{"id":"1.258742455","rc":[{"batb":[[0,5.1,1.19]],"atb":[[5.1,1.19]],"id":99072898},{"batb":[[0,5,54.86]],"atb":[[5,54.86]],"id":10398159},{"batb":[[1,3.35,161.37]],"atb":[[3.35,161.37]],"id":88302242}]}],"rt":639159132905805108,"dt":639159132905805551}
{"op":"mcm","id":2,"clk":"APHPAQDYjgEAzIYC","pt":1780316490673,"mc":[{"id":"1.258742455","rc":[{"tv":2626.21,"batb":[[0,8.2,2.58]],"trd":[[8.2,57.02]],"atb":[[8.2,2.58]],"id":98117699},{"tv":14930.9,"batb":[[0,3.4,18.22]],"trd":[[3.4,194.83],[3.45,358.69]],"ltp":3.4,"atb":[[3.4,18.22]],"atl":[[3.45,11.3]],"batl":[[0,3.45,11.3]],"id":88302242},{"tv":2642.39,"batb":[[0,11,22.99]],"trd":[[11,217.64]],"atb":[[11,22.99]],"id":97736949}],"tv":42358.31}],"rt":639159132906810006,"dt":639159132906810493}
{"op":"mcm","id":2,"clk":"APTPAQDbjgEA1IYC","pt":1780316490777,"mc":[{"id":"1.258742455","rc":[{"batb":[[2,4.8,48.91],[1,4.9,54.01],[0,5,68.62]],"atb":[[5.1,0]],"atl":[[5.2,21.83]],"batl":[[0,5.2,21.83]],"id":99072898},{"batb":[[0,3.4,29.17]],"atb":[[3.15,22.21],[3.4,29.17]],"atl":[[3.45,3.37]],"batl":[[0,3.45,3.37]],"id":88302242}]}],"rt":639159132907856569,"dt":639159132907857022}
{"op":"mcm","id":2,"clk":"APnPAQDfjgEA3oYC","pt":1780316490879,"mc":[{"id":"1.258742455","rc":[{"batb":[[0,3.4,35.49]],"atb":[[3.4,35.49]],"atl":[[3.45,22.14]],"batl":[[0,3.45,22.14]],"id":88302242},{"batb":[[0,11,22.49]],"atb":[[11,22.49]],"id":97736949}]}],"rt":639159132908872822,"dt":639159132908873264}
{"op":"mcm","id":2,"clk":"AP3PAQDhjgEA6IYC","pt":1780316490984,"mc":[{"id":"1.258742455","rc":[{"batb":[[0,46,4.81]],"atb":[[46,4.81]],"id":97008932},{"batb":[[0,21,3.27]],"atb":[[21,3.27]],"id":99072900},{"atl":[[5.1,44.88]],"batl":[[0,5.1,44.88]],"id":10398159},{"atl":[[60,0.71]],"batl":[[0,65,28.96]],"id":98464183},{"batb":[],"atb":[[3.2,72.29]],"id":88302242},{"batb":[[0,11,21.64]],"atb":[[11,21.64]],"id":97736949}]}],"rt":639159132909923394,"dt":639159132909923807}
{"op":"mcm","id":2,"clk":"AP/PAQDkjgEA84YC","pt":1780316491085,"mc":[{"id":"1.258742455","rc":[{"tv":9088.34,"batb":[[0,5,66.55]],"trd":[[5,484.57]],"ltp":5,"atb":[[5,66.55]],"atl":[[5.2,23.31]],"batl":[[0,5.2,23.31]],"id":99072898}],"tv":42362.44}],"rt":639159132910933238,"dt":639159132910933650}
{"op":"mcm","id":2,"clk":"AILQAQDpjgEA/IYC","pt":1780316491140,"mc":[{"id":"1.258742455","rc":[{"atl":[[48,3.17]],"batl":[[0,48,3.17]],"id":97008932},{"batb":[[0,11,21.85]],"atb":[[11,21.85]],"id":97736949}]}],"rt":639159132911483940,"dt":639159132911484368}
{"op":"mcm","id":2,"clk":"AIjQAQDxjgEAiIcC","pt":1780316491242,"mc":[{"id":"1.258742455","rc":[{"batb":[[0,95,4.6]],"atb":[[95,4.6]],"id":99072901}]}],"rt":639159132912498485,"dt":639159132912498816}
{"op":"mcm","id":2,"clk":"AIvQAQD6jgEAlIcC","pt":1780316491346,"mc":[{"id":"1.258742455","rc":[{"batb":[],"atb":[[4.7,102.28]],"id":99072898}]}],"rt":639159132913542469,"dt":639159132913542875}
{"op":"mcm","id":2,"clk":"AJDQAQCBjwEAoIcC","pt":1780316491448,"mc":[{"id":"1.258742455","rc":[{"batb":[[0,46,4.88]],"atb":[[46,4.88]],"id":97008932},{"atl":[[3.45,22.83]],"batl":[[0,3.45,22.83]],"id":88302242}]}],"rt":639159132914564692,"dt":639159132914565091}
{"op":"mcm","id":2,"clk":"AJnQAQCMjwEAqYcC","pt":1780316491551,"mc":[{"id":"1.258742455","rc":[{"batb":[[2,4.8,87.44]],"atb":[[4.6,39.68],[4.8,87.44]],"id":99072898},{"atl":[[27,20.23],[26,11.55]],"batl":[],"id":99072900},{"batb":[],"atb":[[3.05,297.07],[3,81.46]],"atl":[[3.7,206.49],[3.6,130.23]],"batl":[],"id":88302242}]}],"rt":639159132915592786,"dt":639159132915593256}
{"op":"mcm","id":2,"clk":"AJ/QAQCQjwEAsIcC","pt":1780316491650,"mc":[{"id":"1.258742455","rc":[{"atl":[[5.6,47.29]],"batl":[],"id":99072898},{"tv":597.87,"trd":[[48,77.45]],"ltp":48,"atl":[[48,1.17]],"batl":[[0,48,1.17]],"id":97008932}],"tv":42366.44}],"rt":639159132916582085,"dt":639159132916582466}
{"op":"mcm","id":2,"clk":"AKTQAQCXjwEAtocC","pt":1780316491750,"mc":[{"id":"1.258742455","rc":[{"atl":[[3.45,23.73]],"batl":[[0,3.45,23.73]],"id":88302242}]}],"rt":639159132917578538,"dt":639159132917578900}
{"op":"mcm","id":2,"clk":"AKzQAQCbjwEAwIcC","pt":1780316491857,"mc":[{"id":"1.258742455","rc":[{"batb":[[0,5,68.87]],"atb":[[5,68.87]],"id":99072898},{"batb":[[0,46,5.49]],"atb":[[46,5.49]],"id":97008932},{"batb":[[0,21,3.95]],"atb":[[21,3.95]],"id":99072900},{"batb":[[0,95,4.75]],"atb":[[95,4.75]],"id":99072901},{"batb":[[0,5,57.19]],"atb":[[5,57.19]],"id":10398159},{"batb":[[0,55,9.84]],"atb":[[55,9.84]],"id":98464183},{"batb":[[0,8.2,4.75]],"atb":[[8.2,4.75]],"id":98117699},{"batb":[[0,3.4,33.34]],"atb":[[3.4,33.34]],"id":88302242},{"batb":[[0,11,23.14]],"atb":[[11,23.14]],"id":97736949},{"batb":[[0,1000,89.29]],"atb":[[1000,89.29]],"id":10445502},{"batb":[[0,160,5.62]],"atb":[[160,5.62]],"id":99072897}]}],"rt":639159132918649822,"dt":639159132918650368}
{"op":"mcm","id":2,"clk":"ALfQAQCljwEA0ocC","pt":1780316492063,"mc":[{"id":"1.258742455","rc":[{"atl":[[22,21]],"id":99072898},{"atl":[[21,20]],"id":10398159},{"atl":[[60,20]],"id":98117699},{"batb":[[0,3.4,36.29]],"atb":[[3.4,36.29]],"atl":[[3.5,79.5],[9.8,21.99]],"batl":[[1,3.5,79.5]],"id":88302242},{"atl":[[130,20]],"id":97736949}]}],"rt":639159132920715318,"dt":639159132920715925}
{"op":"mcm","id":2,"clk":"ALvQAQCojwEA2YcC","pt":1780316492167,"mc":[{"id":"1.258742455","rc":[{"batb":[[0,5,55.86]],"atb":[[5,55.86]],"id":10398159},{"atl":[[3.45,38.73]],"batl":[[0,3.45,38.73]],"id":88302242},{"batb":[],"atb":[[680,2.18],[660,0]],"id":10445502}]}],"rt":639159132921772037,"dt":639159132921772447}
{"op":"mcm","id":2,"clk":"AMDQAQCqjwEA3ocC","pt":1780316492263,"mc":[{"id":"1.258742455","rc":[{"batb":[],"atb":[[4.7,98.25]],"id":99072898},{"batb":[],"atb":[[4.4,40.43],[4.6,107.97],[4.5,100.33]],"id":10398159},{"atl":[[3.65,65.82],[3.6,126.85]],"batl":[],"id":88302242}]}],"rt":639159132922707046,"dt":639159132922707496}
{"op":"mcm","id":2,"clk":"AM3QAQCwjwEA6YcC","pt":1780316492369,"mc":[{"id":"1.258742455","rc":[{"batb":[[0,5,56.74]],"atb":[[5,56.74]],"atl":[[5.1,34.83]],"batl":[[0,5.1,34.83]],"id":10398159},{"atl":[[3.45,41.11]],"batl":[[0,3.45,41.11]],"id":88302242}]}],"rt":639159132923774456,"dt":639159132923774955}
{"op":"mcm","id":2,"clk":"AOnQAQDGjwEAjIgC","pt":1780316492776,"mc":[{"id":"1.258742455","rc":[{"batb":[[0,21,4.97]],"atb":[[21,4.97]],"id":99072900},{"atl":[[3.5,79.21]],"batl":[[1,3.5,79.21]],"id":88302242}]}],"rt":639159132927845952,"dt":639159132927846423}
{"op":"mcm","id":2,"clk":"AO7QAQDKjwEAlogC","pt":1780316492879,"mc":[{"id":"1.258742455","rc":[{"batb":[[0,5,68.28]],"atb":[[5,68.28]],"id":99072898}]}],"rt":639159132928874258,"dt":639159132928874672}
{"op":"mcm","id":2,"clk":"AP3QAQDcjwEAqogC","pt":1780316493185,"mc":[{"id":"1.258742455","rc":[{"tv":9090.76,"batb":[[0,5,67.07]],"trd":[[5,486.99]],"atb":[[5,67.07]],"atl":[[5.6,38.57]],"batl":[],"id":99072898},{"batb":[[0,5,57.47]],"atb":[[5,57.47]],"id":10398159}],"tv":42368.86}],"rt":639159132931930035,"dt":639159132931930490}
{"op":"mcm","id":2,"clk":"AJLRAQDsjwEAxIgC","pt":1780316493449,"mc":[{"id":"1.258742455","rc":[{"batb":[[0,11,23.3]],"atb":[[11,23.3]],"id":97736949}]}],"rt":639159132934575139,"dt":639159132934575512}
{"op":"mcm","id":2,"clk":"ALLRAQD5jwEA4IgC","pt":1780316493762,"mc":[{"id":"1.258742455","rc":[{"tv":625.32,"trd":[[50,108.34],[48,79.8]],"ltp":50,"atl":[[50,1.01],[48,0]],"batl":[[2,60,8.87],[1,55,23.06],[0,50,1.01]],"id":97008932},{"atl":[[3.65,51.58]],"batl":[],"id":88302242}],"tv":42396.31}],"rt":639159132937705452,"dt":639159132937705886}
{"op":"mcm","id":2,"clk":"ALjRAQD7jwEA54gC","pt":1780316493863,"mc":[{"id":"1.258742455","rc":[{"atl":[[5.5,38.78]],"batl":[],"id":99072898},{"tv":627.34,"batb":[[2,46,13.67],[1,48,3.04],[0,50,2.01]],"trd":[[50,110.36]],"atb":[[50,2.01],[48,3.04],[46,13.67]],"atl":[[50,0]],"batl":[[2,65,4.16],[1,60,8.87],[0,55,23.06]],"id":97008932},{"batb":[[0,8.2,13.46]],"atb":[[8.2,13.46]],"id":98117699}],"tv":42398.33}],"rt":639159132938708968,"dt":639159132938709450}
{"op":"mcm","id":2,"clk":"AL7RAQD/jwEA7ogC","pt":1780316493961,"mc":[{"id":"1.258742455","rc":[{"batb":[[2,46,15.5],[1,48,4.95],[0,50,2.71]],"atb":[[50,2.71],[48,4.95],[46,15.5],[38,20.3]],"atl":[[55,21.25],[70,8.74],[65,6.47]],"batl":[[2,65,6.47],[0,55,21.25]],"id":97008932},{"batb":[],"atb":[[9.6,37.07]],"id":97736949}]}],"rt":639159132939697942,"dt":639159132939698457}
{"op":"mcm","id":2,"clk":"AMLRAQCEkAEA9ogC","pt":1780316494065,"mc":[{"id":"1.258742455","rc":[{"batb":[[2,46,15.37],[0,50,4.18]],"atb":[[50,4.18],[46,15.37]],"atl":[[75,15.99]],"batl":[],"id":97008932},{"batb":[[0,5,55.86]],"atb":[[5,55.86]],"id":10398159},{"atl":[[3.45,51.67]],"batl":[[0,3.45,51.67]],"id":88302242}]}],"rt":639159132940733655,"dt":639159132940734156}
{"op":"mcm","id":2,"clk":"AMbRAQCKkAEA/4gC","pt":1780316494168,"mc":[{"id":"1.258742455","rc":[{"batb":[[2,46,15.22]],"atb":[[46,15.22]],"atl":[[60,5.83]],"batl":[[1,60,5.83]],"id":97008932}]}],"rt":639159132941761840,"dt":639159132941762271}
{"op":"mcm","id":2,"clk":"ANDRAQCOkAEAh4kC","pt":1780316494272,"mc":[{"id":"1.258742455","rc":[{"batb":[[1,48,6.98],[0,50,5.28]],"atb":[[50,5.28],[48,6.98]],"atl":[[55,21.37]],"batl":[[0,55,21.37]],"id":97008932},{"batb":[[0,3.4,22.39]],"atb":[[3.4,22.39]],"atl":[[3.45,53.79]],"batl":[[0,3.45,53.79]],"id":88302242},{"batb":[[0,11,22.93]],"atb":[[9.4,8.28],[11,22.93]],"id":97736949}]}],"rt":639159132942802150,"dt":639159132942802792}
{"op":"mcm","id":2,"clk":"ANzRAQCXkAEAn4kC","pt":1780316494481,"mc":[{"id":"1.258742455","rc":[{"atl":[[55,21.25],[75,17.54]],"batl":[[0,55,21.25]],"id":97008932},{"batb":[[0,11,23.05]],"atb":[[11,23.05]],"id":97736949}]}],"rt":639159132944893629,"dt":639159132944894108}
{"op":"mcm","id":2,"clk":"AOLRAQCZkAEAqIkC","pt":1780316494578,"mc":[{"id":"1.258742455","rc":[{"batb":[[0,5,56.38]],"atb":[[5,56.38]],"id":10398159}]}],"rt":639159132945863036,"dt":639159132945863402}
{"op":"mcm","id":2,"clk":"AOXRAQCckAEAr4kC","pt":1780316494673,"mc":[{"id":"1.258742455","rc":[{"atl":[[95,3.04]],"batl":[],"id":97008932}]}],"rt":639159132946816250,"dt":639159132946816618}
{"op":"mcm","id":2,"clk":"AOvRAQCekAEAuIkC","pt":1780316494778,"mc":[{"id":"1.258742455","rc":[{"atl":[[55,21.69]],"batl":[[0,55,21.69]],"id":97008932},{"tv":14936.21,"batb":[[0,3.4,19.73]],"trd":[[3.4,200.14]],"atb":[[3.4,19.73]],"id":88302242}],"tv":42403.64}],"rt":639159132947857125,"dt":639159132947857526}
{"op":"mcm","id":2,"clk":"APzRAQCmkAEAzokC","pt":1780316494983,"mc":[{"id":"1.258742455","rc":[{"batb":[[0,5,56.9]],"atb":[[5,56.9]],"id":10398159}]}],"rt":639159132949914858,"dt":639159132949915278}
{"op":"mcm","id":2,"clk":"AILSAQCskAEA2IkC","pt":1780316495093,"mc":[{"id":"1.258742455","rc":[{"atl":[[55,22.02]],"batl":[[0,55,22.02]],"id":97008932}]}],"rt":639159132951016175,"dt":639159132951016517}
{"op":"mcm","id":2,"clk":"AI3SAQC0kAEA74kC","pt":1780316495250,"mc":[{"id":"1.258742455","rc":[{"batb":[],"atb":[[7.2,32.72]],"atl":[[8.8,20.28]],"batl":[[2,8.8,20.28]],"id":98117699}]}],"rt":639159132952583833,"dt":639159132952584241}
{"op":"mcm","id":2,"clk":"AJPSAQC5kAEA\u002BYkC","pt":1780316495355,"mc":[{"id":"1.258742455","rc":[{"atl":[[5.1,39.83]],"batl":[[0,5.1,39.83]],"id":10398159}]}],"rt":639159132953630010,"dt":639159132953630444}
{"op":"mcm","id":2,"clk":"AJfSAQC8kAEAgYoC","pt":1780316495454,"mc":[{"id":"1.258742455","rc":[{"batb":[],"atb":[[4.2,22.97]],"id":10398159},{"batb":[],"atb":[[9.4,7.75]],"id":97736949}]}],"rt":639159132954626014,"dt":639159132954626370}
{"op":"mcm","id":2,"clk":"AKbSAQDEkAEAj4oC","pt":1780316495655,"mc":[{"id":"1.258742455","rc":[{"batb":[],"atb":[[4.2,116.79]],"id":99072898},{"batb":[],"atb":[[7,11.85]],"id":98117699}]}],"rt":639159132956631013,"dt":639159132956631449}
{"op":"mcm","id":2,"clk":"AKzSAQDGkAEAlIoC","pt":1780316495757,"mc":[{"id":"1.258742455","rc":[{"atl":[[5.2,25.43]],"batl":[[0,5.2,25.43]],"id":99072898},{"batb":[],"atb":[[4.3,206.1]],"id":10398159},{"atb":[[1.17,196.31]],"id":88302242},{"batb":[],"atb":[[9.4,8.28]],"id":97736949}]}],"rt":639159132957647726,"dt":639159132957648148}
{"op":"mcm","id":2,"clk":"ALTSAQDJkAEAl4oC","pt":1780316495858,"mc":[{"id":"1.258742455","rc":[{"batb":[],"atb":[[42,15.1]],"id":97008932},{"atb":[[1.17,196.12]],"id":88302242}]}],"rt":639159132958667023,"dt":639159132958667443}
{"op":"mcm","id":2,"clk":"AL3SAQDQkAEAoYoC","pt":1780316495960,"mc":[{"id":"1.258742455","rc":[{"batb":[],"atb":[[19,26.05]],"id":99072900},{"atl":[[5.5,55.11]],"batl":[],"id":10398159},{"batb":[[0,3.4,20.38]],"atb":[[3.4,20.38],[3,79.79]],"atl":[[3.65,78.14]],"batl":[],"id":88302242},{"atl":[[13.5,18.37]],"batl":[],"id":97736949},{"batb":[[1,150,7.08]],"atb":[[150,7.08]],"id":99072897}]}],"rt":639159132959683642,"dt":639159132959684172}
{"op":"mcm","id":2,"clk":"AMPSAQDTkAEAq4oC","pt":1780316496066,"mc":[{"id":"1.258742455","rc":[{"batb":[],"atb":[[4.3,12.58]],"id":99072898},{"batb":[],"atb":[[42,15.22]],"id":97008932},{"batb":[],"atb":[[7,12.56]],"id":98117699},{"atb":[[2.9,3.71]],"id":88302242}]}],"rt":639159132960743091,"dt":639159132960743493}
{"op":"mcm","id":2,"clk":"AMzSAQDakAEAsYoC","pt":1780316496168,"mc":[{"id":"1.258742455","rc":[{"atl":[[5.3,222.74]],"batl":[[2,5.3,222.74]],"id":10398159}]}],"rt":639159132961759384,"dt":639159132961759776}
{"op":"mcm","id":2,"clk":"ANHSAQDekAEAvooC","pt":1780316496273,"mc":[{"id":"1.258742455","rc":[{"batb":[],"atb":[[18.5,7.88]],"id":99072900},{"batb":[[0,11,23.16]],"atb":[[11,23.16]],"id":97736949}]}],"rt":639159132962815155,"dt":639159132962815523}
{"op":"mcm","id":2,"clk":"ANXSAQDjkAEAzIoC","pt":1780316496379,"mc":[{"id":"1.258742455","rc":[{"atl":[[55,22.66]],"batl":[[0,55,22.66]],"id":97008932},{"batb":[[0,5,55.86]],"atb":[[5,55.86]],"atl":[[5.1,47.02]],"batl":[[0,5.1,47.02]],"id":10398159},{"atl":[[4.6,4.57]],"id":88302242},{"atl":[[11.5,19.01]],"batl":[[0,11.5,19.01]],"id":97736949}]}],"rt":639159132963871614,"dt":639159132963872135}
{"op":"mcm","id":2,"clk":"AN/SAQDqkAEA04oC","pt":1780316496484,"mc":[{"id":"1.258742455","rc":[{"tv":9205.76,"batb":[[0,5,47.86]],"trd":[[5,498.71]],"ltp":5,"atb":[[5,47.86]],"id":10398159},{"batb":[[0,8.2,17.83]],"atb":[[8.2,17.83]],"id":98117699},{"tv":14960.21,"batb":[[0,3.4,8.38]],"trd":[[3.4,224.14]],"atb":[[3.4,8.38]],"id":88302242}],"tv":42443.64}],"rt":639159132964918419,"dt":639159132964918925}
{"op":"mcm","id":2,"clk":"AOPSAQDrkAEA3ooC","pt":1780316496579,"mc":[{"id":"1.258742455","rc":[{"batb":[[1,48,10.84]],"atb":[[48,10.84],[40,8.34]],"id":97008932},{"batb":[[0,5,32.86]],"atb":[[5,32.86]],"id":10398159}]}],"rt":639159132965871200,"dt":639159132965871610}
{"op":"mcm","id":2,"clk":"AOnSAQDukAEA6IoC","pt":1780316496681,"mc":[{"id":"1.258742455","rc":[{"batb":[],"atb":[[42,25.63],[38,11.07]],"id":97008932},{"batb":[[0,3.4,7.92]],"atb":[[2.98,74.95],[3.4,7.92],[3,6.8]],"atl":[[3.45,57.33]],"batl":[[0,3.45,57.33]],"id":88302242},{"batb":[],"atb":[[680,0.18],[660,2]],"id":10445502}]}],"rt":639159132966887748,"dt":639159132966888143}
{"op":"mcm","id":2,"clk":"APLSAQD4kAEA7ooC","pt":1780316496785,"mc":[{"id":"1.258742455","rc":[{"atl":[[5.7,31.77]],"batl":[],"id":99072898},{"atl":[[27,26.36]],"batl":[],"id":99072900},{"tv":9214.36,"batb":[[0,5,28.56]],"trd":[[5,507.31]],"atb":[[5,28.56]],"id":10398159},{"tv":2645.69,"batb":[[0,11,21.51]],"trd":[[11,220.94]],"atb":[[11,21.51]],"id":97736949}],"tv":42455.54}],"rt":639159132967930693,"dt":639159132967931152}
{"op":"mcm","id":2,"clk":"APzSAQD9kAEA\u002BooC","pt":1780316496889,"mc":[{"id":"1.258742455","rc":[{"batb":[[0,50,9.14]],"atb":[[50,9.14]],"id":97008932}]}],"rt":639159132968971736,"dt":639159132968972059}
{"op":"mcm","id":2,"clk":"AITTAQD/kAEAgosC","pt":1780316496989,"mc":[{"id":"1.258742455","rc":[{"batb":[[1,48,12.57]],"atb":[[48,12.57]],"id":97008932},{"batb":[[0,11,21.28]],"atb":[[11,21.28]],"id":97736949}]}],"rt":639159132969971505,"dt":639159132969971938}
{"op":"mcm","id":2,"clk":"AI3TAQCEkQEAjIsC","pt":1780316497093,"mc":[{"id":"1.258742455","rc":[{"atl":[[55,22.02]],"batl":[[0,55,22.02]],"id":97008932}]}],"rt":639159132971012095,"dt":639159132971012444}
{"op":"mcm","id":2,"clk":"AJXTAQCIkQEAj4sC","pt":1780316497193,"mc":[{"id":"1.258742455","rc":[{"atl":[[5.1,56.82],[5.6,29.01]],"batl":[[0,5.1,56.82]],"id":10398159},{"atl":[[14,14.42]],"batl":[],"id":97736949}]}],"rt":639159132972010687,"dt":639159132972011074}
{"op":"mcm","id":2,"clk":"AJjTAQCNkQEAl4sC","pt":1780316497252,"mc":[{"id":"1.258742455","rc":[{"atl":[[80,7.99]],"batl":[],"id":97008932},{"atb":[[2.02,66.71]],"atl":[[7.4,3.99]],"id":10398159}]}],"rt":639159132972600311,"dt":639159132972600650}
{"op":"mcm","id":2,"clk":"AKDTAQCOkQEAnosC","pt":1780316497346,"mc":[{"id":"1.258742455","rc":[{"tv":9120.76,"trd":[[5.2,30]],"ltp":5.2,"atl":[[5.2,10.43]],"batl":[[0,5.2,10.43]],"id":99072898},{"tv":9224.36,"batb":[[0,5,23.56]],"trd":[[5,517.31]],"atb":[[5,23.56]],"id":10398159},{"atl":[[90,5.36]],"batl":[],"id":98464183}],"tv":42495.54}],"rt":639159132973550410,"dt":639159132973550914}
{"op":"mcm","id":2,"clk":"AK3TAQCXkQEAposC","pt":1780316497450,"mc":[{"id":"1.258742455","rc":[{"batb":[[2,4.9,54.01],[1,5,67.07],[0,5.1,11.61]],"atb":[[5.1,11.61]],"id":99072898},{"atl":[[55,21.25]],"batl":[[0,55,21.25]],"id":97008932},{"batb":[[0,5,14.34]],"atb":[[5,14.34]],"id":10398159},{"atl":[[11.5,22.53]],"batl":[[0,11.5,22.53]],"id":97736949}]}],"rt":639159132974577340,"dt":639159132974577779}
{"op":"mcm","id":2,"clk":"ALjTAQCckQEAsIsC","pt":1780316497555,"mc":[{"id":"1.258742455","rc":[{"batb":[[0,5.1,12.73]],"atb":[[5.1,12.73],[4,30.49]],"atl":[[5.2,16.6]],"batl":[[0,5.2,16.6]],"id":99072898}]}],"rt":639159132975626817,"dt":639159132975627225}
{"op":"mcm","id":2,"clk":"AMDTAQCgkQEAvosC","pt":1780316497660,"mc":[{"id":"1.258742455","rc":[{"atl":[[5.2,12.15]],"batl":[[0,5.2,12.15]],"id":99072898},{"atl":[[55,22.19]],"batl":[[0,55,22.19]],"id":97008932}]}],"rt":639159132976679887,"dt":639159132976680298}
{"op":"mcm","id":2,"clk":"AMbTAQClkQEAx4sC","pt":1780316497760,"mc":[{"id":"1.258742455","rc":[{"batb":[[0,5,3.63]],"atb":[[5,3.63]],"id":10398159},{"tv":2627.93,"batb":[[0,8.2,16.97]],"trd":[[8.2,58.74]],"atb":[[8.2,16.97]],"id":98117699}],"tv":42497.26}],"rt":639159132977683740,"dt":639159132977684217}
{"op":"mcm","id":2,"clk":"AM7TAQCpkQEAz4sC","pt":1780316497862,"mc":[{"id":"1.258742455","rc":[{"batb":[[0,5.1,15.05]],"atb":[[4.6,33.68],[5.1,15.05]],"atl":[[5.3,30.49],[5.6,44.16],[32,0]],"batl":[[1,5.3,30.49]],"id":99072898},{"atl":[[55,21.25]],"batl":[[0,55,21.25]],"id":97008932}]}],"rt":639159132978702977,"dt":639159132978703396}
{"op":"mcm","id":2,"clk":"ANHTAQCqkQEA04sC","pt":1780316497962,"mc":[{"id":"1.258742455","rc":[{"atl":[[5.2,2.12],[21,2.18]],"batl":[[0,5.2,2.12]],"id":99072898}]}],"rt":639159132979700291,"dt":639159132979700703}
{"op":"mcm","id":2,"clk":"ANfTAQCzkQEA24sC","pt":1780316498069,"mc":[{"id":"1.258742455","rc":[{"batb":[[0,5.1,23.31]],"atb":[[5.1,23.31]],"id":99072898},{"atl":[[55,21.9]],"batl":[[0,55,21.9]],"id":97008932},{"atl":[[24,11.26]],"batl":[[2,24,11.26]],"id":99072900}]}],"rt":639159132980777078,"dt":639159132980777503}
{"op":"mcm","id":2,"clk":"AN7TAQC2kQEA4YsC","pt":1780316498169,"mc":[{"id":"1.258742455","rc":[{"batb":[[2,4.9,56.69]],"atb":[[4.7,104.25],[4.9,56.69]],"atl":[[5.2,2.73],[5.6,41.96]],"batl":[[0,5.2,2.73]],"id":99072898},{"batb":[[0,8.2,12.6]],"atb":[[8.2,12.6]],"id":98117699}]}],"rt":639159132981771821,"dt":639159132981772245}
{"op":"mcm","id":2,"clk":"AOvTAQC\u002BkQEA8YsC","pt":1780316498380,"mc":[{"id":"1.258742455","rc":[{"atl":[[55,22.24]],"batl":[[0,55,22.24]],"id":97008932},{"tv":14980.61,"batb":[[2,3.25,63.1],[1,3.3,59.99],[0,3.35,159.09]],"trd":[[3.4,239.98],[3.35,27.52]],"ltp":3.35,"atb":[[3.4,0],[3.35,159.09]],"id":88302242}],"tv":42517.66}],"rt":639159132983879038,"dt":639159132983879567}
{"op":"mcm","id":2,"clk":"AOzTAQC/kQEA\u002BYsC","pt":1780316498476,"mc":[{"id":"1.258742455","rc":[{"batb":[[0,5.1,38.17]],"atb":[[5.1,38.17]],"id":99072898}]}],"rt":639159132984844483,"dt":639159132984844807}
{"op":"mcm","id":2,"clk":"AO/TAQDCkQEAgIwC","pt":1780316498579,"mc":[{"id":"1.258742455","rc":[{"batb":[],"atb":[[4.6,22.15]],"id":99072898}]}],"rt":639159132985868369,"dt":639159132985868736}
{"op":"mcm","id":2,"clk":"AP3TAQDHkQEAiowC","pt":1780316498690,"mc":[{"id":"1.258742455","rc":[{"atl":[[5.2,2.12]],"batl":[[0,5.2,2.12]],"id":99072898}]}],"rt":639159132986982237,"dt":639159132986982559}
{"op":"mcm","id":2,"clk":"AIDUAQDHkQEAk4wC","pt":1780316498790,"mc":[{"id":"1.258742455","rc":[{"atl":[[55,22.33]],"batl":[[0,55,22.33]],"id":97008932},{"batb":[],"atb":[[3.2,66.29]],"id":88302242}]}],"rt":639159132987987635,"dt":639159132987988071}
{"op":"mcm","id":2,"clk":"AI3UAQDOkQEApYwC","pt":1780316498991,"mc":[{"id":"1.258742455","rc":[{"batb":[[2,4.9,55.86]],"atb":[[1.17,3.35],[4.9,55.86]],"atl":[[5.2,0.74]],"batl":[[2,5.5,38.78],[1,5.4,17.26],[0,5.3,31.23]],"id":99072898},{"batb":[[2,46,13.96]],"atb":[[46,13.96]],"id":97008932},{"batb":[],"atb":[[3.15,28.21]],"id":88302242}]}],"rt":639159132989993249,"dt":639159132989993715}
{"op":"mcm","id":2,"clk":"AJTUAQDSkQEArIwC","pt":1780316499096,"mc":[{"id":"1.258742455","rc":[{"batb":[[0,5.1,44.25]],"atb":[[1.17,2],[5.1,44.25]],"id":99072898},{"batb":[[2,3.3,59.99],[1,3.35,159.09],[0,3.4,6]],"atb":[[3.4,6]],"id":88302242}]}],"rt":639159132991043739,"dt":639159132991044243}
{"op":"mcm","id":2,"clk":"AJfUAQDUkQEAtYwC","pt":1780316499144,"mc":[{"id":"1.258742455","rc":[{"batb":[[1,5,67.85],[0,5.1,44.82]],"atb":[[5,67.85],[5.1,44.82]],"atl":[[5.5,21.24]],"batl":[[2,5.5,21.24]],"id":99072898},{"tv":9234.28,"batb":[[2,4.7,72.89],[1,4.8,88.72],[0,4.9,193.45]],"trd":[[4.9,433.31],[5,524.57]],"ltp":4.9,"atb":[[4.9,193.45],[5,0]],"id":10398159}],"tv":42527.58}],"rt":639159132991519954,"dt":639159132991520392}
{"op":"mcm","id":2,"clk":"AJ7UAQDdkQEAwIwC","pt":1780316499252,"mc":[{"id":"1.258742455","rc":[{"batb":[[0,4.9,187.89]],"atb":[[4.9,187.89]],"atl":[[5,7.11]],"batl":[[2,5.2,128.08],[1,5.1,56.82],[0,5,7.11]],"id":10398159},{"batb":[[1,3.35,160.16]],"atb":[[3.35,160.16]],"id":88302242},{"batb":[[0,11,13.46]],"atb":[[11,13.46]],"id":97736949},{"atb":[[10,11.89]],"id":99072897}]}],"rt":639159132992607599,"dt":639159132992608075}
{"op":"mcm","id":2,"clk":"AKHUAQDfkQEAxowC","pt":1780316499351,"mc":[{"id":"1.258742455","rc":[{"tv":9239.3,"trd":[[5,529.59]],"ltp":5,"atl":[[5,7.84]],"batl":[[0,5,7.84]],"id":10398159}],"tv":42532.6}],"rt":639159132993591946,"dt":639159132993592366}
{"op":"mcm","id":2,"clk":"AKfUAQDlkQEAz4wC","pt":1780316499457,"mc":[{"id":"1.258742455","rc":[{"batb":[[0,5.1,46.61]],"atb":[[5.1,46.61]],"id":99072898},{"batb":[[0,11,10.28]],"atb":[[11,10.28]],"id":97736949}]}],"rt":639159132994653850,"dt":639159132994654238}
{"op":"mcm","id":2,"clk":"AK3UAQDpkQEA1owC","pt":1780316499558,"mc":[{"id":"1.258742455","rc":[{"atl":[[5.6,35.96]],"batl":[],"id":99072898},{"atl":[[55,22.76]],"batl":[[0,55,22.76]],"id":97008932},{"batb":[[2,4.7,82.89]],"atb":[[4.7,82.89],[4.6,101.97]],"atl":[[5,6.03]],"batl":[[0,5,6.03]],"id":10398159},{"batb":[],"atb":[[3.15,22.21]],"id":88302242}]}],"rt":639159132995663102,"dt":639159132995663530}
{"op":"mcm","id":2,"clk":"ALjUAQDwkQEA6IwC","pt":1780316499760,"mc":[{"id":"1.258742455","rc":[{"atl":[[5.7,37.77]],"batl":[],"id":99072898},{"batb":[],"atb":[[4.5,106.33]],"atl":[[5.5,49.11]],"batl":[],"id":10398159},{"batb":[],"atb":[[3.2,72.29]],"id":88302242}]}],"rt":639159132997680153,"dt":639159132997680562}
{"op":"mcm","id":2,"clk":"AMHUAQCDkgEA94wC","pt":1780316499970,"mc":[{"id":"1.258742455","rc":[{"atl":[[5.4,56.44]],"batl":[],"id":10398159}]}],"rt":639159132999783308,"dt":639159132999783691}
{"op":"mcm","id":2,"clk":"AOLUAQCYkgEApo0C","pt":1780316500481,"mc":[{"id":"1.258742455","rc":[{"tv":629.06,"batb":[[0,50,8.28]],"trd":[[50,112.08]],"atb":[[50,8.28]],"id":97008932}],"tv":42534.32}],"rt":639159133004893925,"dt":639159133004894333}
{"op":"mcm","id":2,"clk":"APHUAQCkkgEAvo0C","pt":1780316500687,"mc":[{"id":"1.258742455","rc":[{"batb":[[0,50,8.69]],"atb":[[50,8.69]],"atl":[[55,23.3]],"batl":[[0,55,23.3]],"id":97008932},{"tv":2661.69,"batb":[[0,11,2.28]],"trd":[[11,236.94]],"atb":[[11,2.28]],"id":97736949}],"tv":42550.32}],"rt":639159133006951876,"dt":639159133006952319}
{"op":"mcm","id":2,"clk":"APTUAQCpkgEAxY0C","pt":1780316500788,"mc":[{"id":"1.258742455","rc":[{"atl":[[5.7,35.57],[5.8,14.78]],"batl":[],"id":99072898},{"batb":[[0,8.2,16.91]],"atb":[[8.2,16.91]],"id":98117699},{"batb":[[2,3.3,67.18]],"atb":[[3.3,67.18]],"id":88302242},{"batb":[[2,10,39.61],[1,10.5,22.05]],"atb":[[10.5,22.05],[10,39.61],[9.6,40.19]],"id":97736949}]}],"rt":639159133007961508,"dt":639159133007961958}
{"op":"mcm","id":2,"clk":"APvUAQCtkgEA0Y0C","pt":1780316500888,"mc":[{"id":"1.258742455","rc":[{"tv":2666.25,"batb":[[2,9.8,13.52],[1,10,39.61],[0,10.5,22.05]],"trd":[[11,241.5]],"atb":[[11,0],[9.6,41.31]],"atl":[[11.5,24.59],[11,0.64]],"batl":[[0,11.5,25.23]],"id":97736949}],"tv":42554.88}],"rt":639159133008967640,"dt":639159133008968025}
{"op":"mcm","id":2,"clk":"AILVAQCxkgEA240C","pt":1780316500950,"mc":[{"id":"1.258742455","rc":[{"batb":[[0,4.9,194.06]],"atb":[[4.9,194.06]],"id":10398159}]}],"rt":639159133009584190,"dt":639159133009584521}
{"op":"mcm","id":2,"clk":"AIXVAQC3kgEA4Y0C","pt":1780316501051,"mc":[{"id":"1.258742455","rc":[{"batb":[],"atb":[[9.6,26.56]],"atl":[[11,1.39]],"batl":[[2,12,10.01],[1,11.5,24.59],[0,11,1.39]],"id":97736949}]}],"rt":639159133010595422,"dt":639159133010595807}
{"op":"mcm","id":2,"clk":"AI3VAQC9kgEA6o0C","pt":1780316501153,"mc":[{"id":"1.258742455","rc":[{"tv":9251.36,"batb":[[2,4.8,88.72],[1,4.9,194.06],[0,5,22.88]],"trd":[[5,541.65]],"atb":[[5,22.88]],"atl":[[5,0]],"batl":[[2,5.3,222.74],[1,5.2,128.08],[0,5.1,56.82]],"id":10398159},{"batb":[[0,8.2,21.08]],"atb":[[8.2,21.08]],"id":98117699},{"batb":[],"atb":[[9.4,11.5],[1.17,2.46],[9.6,23.45]],"id":97736949}],"tv":42566.94}],"rt":639159133011621448,"dt":639159133011621917}
{"op":"mcm","id":2,"clk":"AJXVAQDEkgEA9I0C","pt":1780316501257,"mc":[{"id":"1.258742455","rc":[{"batb":[[0,3.4,14.02]],"atb":[[3.4,14.02]],"id":88302242}]}],"rt":639159133012652007,"dt":639159133012652435}
{"op":"mcm","id":2,"clk":"AJ7VAQDMkgEAgo4C","pt":1780316501360,"mc":[{"id":"1.258742455","rc":[{"batb":[[0,5,32.96]],"atb":[[5,32.96]],"id":10398159},{"batb":[[0,8.2,16.91]],"atb":[[8.2,16.91]],"id":98117699},{"atb":[[1.17,2]],"atl":[[11,2]],"batl":[[0,11,2]],"id":97736949}]}],"rt":639159133013687232,"dt":639159133013687682}
{"op":"mcm","id":2,"clk":"AKPVAQDRkgEAjI4C","pt":1780316501458,"mc":[{"id":"1.258742455","rc":[{"batb":[],"atb":[[4.6,12.65]],"id":99072898},{"tv":9259.31,"batb":[[0,5,28.98]],"trd":[[5,549.6]],"atb":[[5,28.98],[4.5,100.33]],"atl":[[5.4,50.44]],"batl":[],"id":10398159},{"batb":[[0,10.5,15.85]],"atb":[[10.5,15.85],[9.6,17.45]],"atl":[[13.5,12.37]],"batl":[],"id":97736949}],"tv":42574.89}],"rt":639159133014664872,"dt":639159133014665446}
{"op":"mcm","id":2,"clk":"AKnVAQDSkgEAlY4C","pt":1780316501563,"mc":[{"id":"1.258742455","rc":[{"atl":[[5.9,6.52],[6,55.3]],"batl":[],"id":99072898},{"batb":[],"atb":[[9,24.1]],"atl":[[11.5,42.19]],"batl":[[1,11.5,42.19]],"id":97736949},{"batb":[],"atb":[[680,2.18],[660,0]],"id":10445502}]}],"rt":639159133015707925,"dt":639159133015708355}
{"op":"mcm","id":2,"clk":"ALTVAQDckgEAno4C","pt":1780316501665,"mc":[{"id":"1.258742455","rc":[{"tv":9164.02,"batb":[[0,5.1,24.98]],"trd":[[5.1,86.79]],"ltp":5.1,"atb":[[5.1,24.98]],"id":99072898},{"batb":[],"atb":[[4.6,107.97]],"atl":[[5.5,55.11]],"batl":[],"id":10398159},{"batb":[[0,10.5,15.17]],"atb":[[9.4,17.5],[10.5,15.17],[9.2,21.56]],"atl":[[13,13.84],[12.5,8.13]],"batl":[],"id":97736949}],"tv":42618.15}],"rt":639159133016735058,"dt":639159133016735499}
{"op":"mcm","id":2,"clk":"ALzVAQDikgEAqY4C","pt":1780316501770,"mc":[{"id":"1.258742455","rc":[{"atl":[[5.2,10.73]],"batl":[[2,5.4,17.26],[1,5.3,30.49],[0,5.2,10.73]],"id":99072898},{"tv":9263.45,"batb":[[0,5,26.91]],"trd":[[5,553.74]],"atb":[[5,26.91]],"id":10398159},{"tv":2682.09,"batb":[[0,10.5,5.69]],"trd":[[10.5,229.99]],"ltp":10.5,"atb":[[10.5,5.69]],"atl":[[11,3.2]],"batl":[[0,11,3.2]],"id":97736949}],"tv":42638.13}],"rt":639159133017783706,"dt":639159133017784232}
{"op":"mcm","id":2,"clk":"AMLVAQDkkgEAso4C","pt":1780316501871,"mc":[{"id":"1.258742455","rc":[{"batb":[[0,5.1,38.97]],"atb":[[5.1,38.97]],"atl":[[5.7,37.72],[5.2,13.89]],"batl":[[0,5.2,13.89]],"id":99072898},{"batb":[[0,3.4,15.23]],"atb":[[3.4,15.23]],"id":88302242},{"batb":[[0,10.5,9.6]],"atb":[[10.5,9.6]],"id":97736949}]}],"rt":639159133018789197,"dt":639159133018789616}
{"op":"mcm","id":2,"clk":"AMnVAQDpkgEAu44C","pt":1780316501974,"mc":[{"id":"1.258742455","rc":[{"atl":[[5.1,57.34]],"batl":[[0,5.1,57.34]],"id":10398159},{"batb":[[0,55,10.31]],"atb":[[55,10.31]],"atl":[[1000,0.1]],"id":98464183},{"atl":[[1000,3.17]],"id":88302242},{"batb":[[0,10.5,7.05]],"atb":[[9.4,20.86],[10.5,7.05]],"id":97736949}]}],"rt":639159133019816824,"dt":639159133019817306}
{"op":"mcm","id":2,"clk":"AMzVAQDukgEAwY4C","pt":1780316502076,"mc":[{"id":"1.258742455","rc":[{"batb":[[0,5.1,41.09]],"atb":[[5.1,41.09]],"atl":[[5.7,31.72]],"batl":[],"id":99072898},{"atl":[[1000,0]],"id":98464183},{"atl":[[1000,3]],"id":88302242}]}],"rt":639159133020840621,"dt":639159133020841482}
{"op":"mcm","id":2,"clk":"ANLVAQDxkgEAy44C","pt":1780316502177,"mc":[{"id":"1.258742455","rc":[{"atl":[[5.2,10.73]],"batl":[[0,5.2,10.73]],"id":99072898},{"tv":9263.91,"batb":[[0,5,26.68]],"trd":[[5,554.2]],"atb":[[5,26.68]],"id":10398159},{"atl":[[65,28.35]],"batl":[[0,65,29.06]],"id":98464183},{"atl":[[3.45,57.5]],"batl":[[0,3.45,57.5]],"id":88302242}],"tv":42638.59}],"rt":639159133021858499,"dt":639159133021859081}
{"op":"mcm","id":2,"clk":"ANfVAQD1kgEA044C","pt":1780316502280,"mc":[{"id":"1.258742455","rc":[{"batb":[],"atb":[[4.8,84.28]],"atl":[[5.6,41.96]],"batl":[],"id":99072898},{"batb":[],"atb":[[42,23.9]],"id":97008932},{"batb":[[0,10.5,7.86]],"atb":[[10.5,7.86]],"id":97736949}]}],"rt":639159133022888141,"dt":639159133022888692}
{"op":"mcm","id":2,"clk":"AOLVAQD7kgEA3Y4C","pt":1780316502382,"mc":[{"id":"1.258742455","rc":[{"batb":[[0,5.1,42.31]],"atb":[[5.1,42.31]],"atl":[[5.2,11]],"batl":[[0,5.2,11]],"id":99072898},{"atl":[[55,23.39]],"batl":[[0,55,23.39]],"id":97008932},{"atl":[[3.45,58.14]],"batl":[[0,3.45,58.14]],"id":88302242}]}],"rt":639159133023901889,"dt":639159133023902460}
{"op":"mcm","id":2,"clk":"AOrVAQD9kgEA544C","pt":1780316502486,"mc":[{"id":"1.258742455","rc":[{"batb":[[0,50,8.72]],"atb":[[50,8.72]],"id":97008932},{"batb":[[0,5,30.42]],"atb":[[5,30.42]],"id":10398159}]}],"rt":639159133024943353,"dt":639159133024943804}
{"op":"mcm","id":2,"clk":"APLVAQD/kgEA7Y4C","pt":1780316502586,"mc":[{"id":"1.258742455","rc":[{"tv":14981.17,"batb":[[0,3.4,14.95]],"trd":[[3.4,240.54]],"ltp":3.4,"atb":[[3.4,14.95]],"id":88302242}],"tv":42639.15}],"rt":639159133025946950,"dt":639159133025947416}
{"op":"mcm","id":2,"clk":"APrVAQCBkwEA\u002BY4C","pt":1780316502691,"mc":[{"id":"1.258742455","rc":[{"atl":[[5.2,11.45]],"batl":[[0,5.2,11.45]],"id":99072898}]}],"rt":639159133026988122,"dt":639159133026988565}
{"op":"mcm","id":2,"clk":"AIfWAQCNkwEAio8C","pt":1780316502894,"mc":[{"id":"1.258742455","rc":[{"batb":[[0,3.4,13.74]],"atb":[[3.4,13.74]],"id":88302242}]}],"rt":639159133029025163,"dt":639159133029025653}
{"op":"mcm","id":2,"clk":"AI7WAQCQkwEAko8C","pt":1780316502950,"mc":[{"id":"1.258742455","rc":[{"batb":[[0,5.1,43.49]],"atb":[[5.1,43.49]],"atl":[[5.2,11.96]],"batl":[[0,5.2,11.96]],"id":99072898},{"batb":[[0,5,31.62]],"atb":[[5,31.62]],"id":10398159},{"batb":[[0,10.5,8.28]],"atb":[[10.5,8.28]],"id":97736949}]}],"rt":639159133029580673,"dt":639159133029581124}
{"op":"mcm","id":2,"clk":"AKjWAQCjkwEAuY8C","pt":1780316503361,"mc":[{"id":"1.258742455","rc":[{"atl":[[50,1.99]],"id":97736949}]}],"rt":639159133033691504,"dt":639159133033691926}
{"op":"mcm","id":2,"clk":"ANnWAQC/kwEA748C","pt":1780316504078,"mc":[{"id":"1.258742455","rc":[{"batb":[[1,4.9,199.96],[0,5,32.06]],"atb":[[4.9,199.96],[5,32.06]],"id":10398159}]}],"rt":639159133040871244,"dt":639159133040871668}
{"op":"mcm","id":2,"clk":"AOPWAQDFkwEAgJAC","pt":1780316504280,"mc":[{"id":"1.258742455","rc":[{"batb":[[0,5,31.62]],"atb":[[5,31.62]],"id":10398159}]}],"rt":639159133042880125,"dt":639159133042880528}
{"op":"mcm","id":2,"clk":"APvWAQDdkwEAoZAC","pt":1780316504688,"mc":[{"id":"1.258742455","rc":[{"atl":[[75,15.99]],"batl":[],"id":97008932}]}],"rt":639159133046966239,"dt":639159133046966695}
{"op":"mcm","id":2,"clk":"AIDXAQDkkwEAppAC","pt":1780316504746,"mc":[{"id":"1.258742455","rc":[{"atl":[[5.3,227.61]],"batl":[[2,5.3,227.61]],"id":10398159}]}],"rt":639159133047542243,"dt":639159133047542682}
{"op":"mcm","id":2,"clk":"AI3XAQDtkwEAtZAC","pt":1780316504950,"mc":[{"id":"1.258742455","rc":[{"tv":1491.67,"batb":[[2,19,26.05],[1,19.5,24.47],[0,20,23.6]],"trd":[[21,288.62]],"ltp":21,"atb":[[21,0]],"atl":[[21,5.03]],"batl":[[2,23,9.67],[1,22,8.91],[0,21,5.03]],"id":99072900},{"batb":[[0,55,9.84]],"atb":[[55,9.84]],"atl":[[65,28.25]],"batl":[[0,65,28.96]],"id":98464183},{"atl":[[3.45,57.97]],"batl":[[0,3.45,57.97]],"id":88302242},{"atl":[[1000,1.77],[12,9.56],[11.5,41.92]],"batl":[[2,12,9.56],[1,11.5,41.92]],"id":97736949}],"tv":42649.09}],"rt":639159133049583081,"dt":639159133049583643}
{"op":"mcm","id":2,"clk":"AJfXAQD0kwEAvZAC","pt":1780316505059,"mc":[{"id":"1.258742455","rc":[{"atl":[[5.2,1.97]],"batl":[[0,5.2,1.97]],"id":99072898},{"batb":[[0,8.2,21.08]],"atb":[[8.2,21.08]],"id":98117699}]}],"rt":639159133050675593,"dt":639159133050676018}
{"op":"mcm","id":2,"clk":"AJzXAQD3kwEAwpAC","pt":1780316505156,"mc":[{"id":"1.258742455","rc":[{"tv":2647.93,"batb":[[0,8.2,11.08]],"trd":[[8.2,78.74]],"atb":[[8.2,11.08]],"id":98117699},{"batb":[[0,3.4,14.19]],"atb":[[3.4,14.19]],"id":88302242},{"atl":[[1000,1]],"id":97736949}],"tv":42669.09}],"rt":639159133051643774,"dt":639159133051644207}
{"op":"mcm","id":2,"clk":"AKPXAQD/kwEAy5AC","pt":1780316505260,"mc":[{"id":"1.258742455","rc":[{"batb":[[0,5.1,45.09]],"atb":[[5.1,45.09]],"atl":[[5.2,0.74]],"batl":[[2,5.5,21.24],[1,5.4,17.26],[0,5.3,31.23]],"id":99072898},{"atl":[[11.5,42.32],[11,3.57]],"batl":[[1,11.5,42.32],[0,11,3.57]],"id":97736949}]}],"rt":639159133052685313,"dt":639159133052685746}
{"op":"mcm","id":2,"clk":"AKfXAQCAlAEA1JAC","pt":1780316505365,"mc":[{"id":"1.258742455","rc":[{"atl":[[5.7,29.57]],"batl":[],"id":99072898},{"batb":[[0,8.2,6.91]],"atb":[[8.2,6.91]],"id":98117699}]}],"rt":639159133053727110,"dt":639159133053727459}
{"op":"mcm","id":2,"clk":"ALjXAQCMlAEA6JAC","pt":1780316505569,"mc":[{"id":"1.258742455","rc":[{"atl":[[9.4,10.78]],"batl":[],"id":98117699}]}],"rt":639159133055769965,"dt":639159133055770371}
{"op":"mcm","id":2,"clk":"AMjXAQCYlAEA\u002B5AC","pt":1780316505775,"mc":[{"id":"1.258742455","rc":[{"tv":9188.02,"batb":[[0,5.1,33.09]],"trd":[[5.1,110.79]],"atb":[[5.1,33.09]],"atl":[[5.6,35.96]],"batl":[],"id":99072898},{"tv":9287.91,"batb":[[0,5,19.62]],"trd":[[5,578.2]],"atb":[[5,19.62]],"id":10398159},{"tv":927.37,"batb":[[0,55,8.51]],"trd":[[55,123.81]],"ltp":55,"atb":[[55,8.51]],"id":98464183},{"tv":2659.93,"batb":[[2,7.6,146.46],[1,7.8,23.75],[0,8,70.08]],"trd":[[8.2,90.74]],"atb":[[8.2,0.91]],"id":98117699}],"tv":42731.75}],"rt":639159133057826984,"dt":639159133057827534}
{"op":"mcm","id":2,"clk":"AM7XAQCdlAEAiJEC","pt":1780316505876,"mc":[{"id":"1.258742455","rc":[{"batb":[[1,5,68.85]],"atb":[[5,68.85]],"atl":[[5.2,10.9]],"batl":[[2,5.4,17.26],[1,5.3,30.49],[0,5.2,10.9]],"id":99072898},{"batb":[[0,55,8.85]],"atb":[[55,8.85]],"id":98464183},{"batb":[[0,8,69.17]],"atb":[[8.2,0]],"id":98117699}]}],"rt":639159133058837698,"dt":639159133058838113}
{"op":"mcm","id":2,"clk":"ANXXAQChlAEAkpEC","pt":1780316505983,"mc":[{"id":"1.258742455","rc":[{"batb":[[0,5.1,42.55]],"atb":[[5.1,42.55]],"atl":[[5.7,31.7],[5.2,11.92]],"batl":[[0,5.2,11.92]],"id":99072898},{"batb":[],"atb":[[7.4,86.2]],"id":98117699},{"batb":[[0,3.4,15.57]],"atb":[[3.4,15.57]],"id":88302242},{"batb":[[0,10.5,13.56]],"atb":[[10.5,13.56]],"id":97736949}]}],"rt":639159133059915554,"dt":639159133059916052}
{"op":"mcm","id":2,"clk":"ANrXAQCnlAEAnZEC","pt":1780316506090,"mc":[{"id":"1.258742455","rc":[{"atl":[[5.7,37.7]],"batl":[],"id":99072898},{"batb":[],"atb":[[46,8.64]],"atl":[[60,1.38]],"batl":[[2,70,10.17],[1,65,28.25],[0,60,1.38]],"id":98464183},{"batb":[],"atb":[[7.4,90.93]],"id":98117699}]}],"rt":639159133060980684,"dt":639159133060981193}
{"op":"mcm","id":2,"clk":"AOTXAQCulAEAqZEC","pt":1780316506195,"mc":[{"id":"1.258742455","rc":[{"atl":[[60,5.11]],"batl":[[0,60,5.11]],"id":98464183},{"batb":[[0,10.5,20.59]],"atb":[[10.5,20.59]],"id":97736949}]}],"rt":639159133062034167,"dt":639159133062034607}
{"op":"mcm","id":2,"clk":"APDXAQC6lAEAuZEC","pt":1780316506348,"mc":[{"id":"1.258742455","rc":[{"batb":[],"atb":[[7.4,84.93]],"id":98117699}]}],"rt":639159133063558670,"dt":639159133063559146}
{"op":"mcm","id":2,"clk":"APrXAQC/lAEAxZEC","pt":1780316506454,"mc":[{"id":"1.258742455","rc":[{"batb":[[0,5,20.07]],"atb":[[5,20.07]],"id":10398159}]}],"rt":639159133064617217,"dt":639159133064617597}
{"op":"mcm","id":2,"clk":"AP7XAQDFlAEA1JEC","pt":1780316506562,"mc":[{"id":"1.258742455","rc":[{"batb":[],"atb":[[18,31.54]],"id":99072900},{"batb":[[0,3.4,16.83]],"atb":[[3.4,16.83]],"atl":[[3.65,152.23]],"batl":[],"id":88302242},{"atl":[[12,28.16],[11.5,24.72]],"batl":[[2,12,28.16],[1,11.5,24.72]],"id":97736949},{"batb":[],"atb":[[680,0.18],[700,3.29]],"id":10445502}]}],"rt":639159133065696672,"dt":639159133065697122}
{"op":"mcm","id":2,"clk":"AIvYAQDMlAEA5JEC","pt":1780316506668,"mc":[{"id":"1.258742455","rc":[{"atl":[[5.7,31.7]],"batl":[],"id":99072898},{"tv":1493.67,"batb":[[2,19,12.87]],"trd":[[21,290.62]],"atb":[[19,12.87]],"atl":[[21,4.03]],"batl":[[0,21,4.03]],"id":99072900},{"batb":[[0,5,19.62]],"atb":[[5,19.62]],"id":10398159},{"batb":[],"atb":[[7.2,38.72]],"id":98117699},{"atl":[[3.6,53.86]],"batl":[],"id":88302242}],"tv":42733.75}],"rt":639159133066759514,"dt":639159133066760022}
{"op":"mcm","id":2,"clk":"AI7YAQDQlAEA75EC","pt":1780316506764,"mc":[{"id":"1.258742455","rc":[{"atl":[[11,2.96]],"batl":[[0,11,2.96]],"id":97736949}]}],"rt":639159133067720605,"dt":639159133067720935}
{"op":"mcm","id":2,"clk":"AJTYAQDYlAEA/pEC","pt":1780316506871,"mc":[{"id":"1.258742455","rc":[{"atl":[[5.6,41.96]],"batl":[],"id":99072898}]}],"rt":639159133068788389,"dt":639159133068788749}
{"op":"mcm","id":2,"clk":"ALTYAQDqlAEAspIC","pt":1780316507382,"mc":[{"id":"1.258742455","rc":[{"batb":[],"atb":[[40,5.38]],"id":97008932},{"batb":[],"atb":[[7.2,46.7]],"id":98117699}]}],"rt":639159133073903030,"dt":639159133073903406}
{"op":"mcm","id":2,"clk":"AL3YAQDxlAEAvJIC","pt":1780316507497,"mc":[{"id":"1.258742455","rc":[{"atl":[[3.45,57.28]],"batl":[[0,3.45,57.28]],"id":88302242}]}],"rt":639159133075046744,"dt":639159133075047200}
{"op":"mcm","id":2,"clk":"AM/YAQCBlQEA2JIC","pt":1780316507793,"mc":[{"id":"1.258742455","rc":[{"batb":[[0,5,9.54]],"atb":[[5,9.54]],"id":10398159}]}],"rt":639159133078010388,"dt":639159133078010794}
{"op":"mcm","id":2,"clk":"AN3YAQCOlQEA6ZIC","pt":1780316507995,"mc":[{"id":"1.258742455","rc":[{"atl":[[5.2,1.76]],"batl":[[0,5.2,1.76]],"id":99072898},{"batb":[[0,5,11.54]],"atb":[[5,11.54]],"id":10398159},{"atb":[[1.17,196.46]],"id":88302242},{"batb":[[0,10.5,22.57]],"atb":[[10.5,22.57]],"id":97736949}]}],"rt":639159133080032166,"dt":639159133080032628}
{"op":"mcm","id":2,"clk":"AOTYAQCTlQEA9ZIC","pt":1780316508052,"mc":[{"id":"1.258742455","rc":[{"atb":[[1.17,196.12]],"id":88302242}]}],"rt":639159133080599094,"dt":639159133080599459}
{"op":"mcm","id":2,"clk":"AO7YAQCalQEA/pIC","pt":1780316508153,"mc":[{"id":"1.258742455","rc":[{"atl":[[5.2,0.74]],"batl":[[2,5.5,21.24],[1,5.4,17.26],[0,5.3,31.23]],"id":99072898},{"batb":[[0,3.4,17.17]],"atb":[[3.4,17.17]],"id":88302242}]}],"rt":639159133081613897,"dt":639159133081614324}
{"op":"mcm","id":2,"clk":"APnYAQCglQEAhpMC","pt":1780316508255,"mc":[{"id":"1.258742455","rc":[{"atl":[[5.7,29.57]],"batl":[],"id":99072898},{"batb":[[2,46,13.42]],"atb":[[46,13.42]],"id":97008932},{"tv":931.37,"trd":[[60,135.71]],"ltp":60,"atl":[[60,3.11]],"batl":[[0,60,3.11]],"id":98464183}],"tv":42737.75}],"rt":639159133082636015,"dt":639159133082636444}
{"op":"mcm","id":2,"clk":"AP7YAQCjlQEAipMC","pt":1780316508356,"mc":[{"id":"1.258742455","rc":[{"batb":[],"atb":[[4.7,89.74]],"id":10398159},{"atl":[[60,0]],"batl":[[2,75,5.65],[1,70,10.17],[0,65,28.25]],"id":98464183}]}],"rt":639159133083640078,"dt":639159133083640516}
{"op":"mcm","id":2,"clk":"AIXZAQColQEAkpMC","pt":1780316508460,"mc":[{"id":"1.258742455","rc":[{"atl":[[60,0.63]],"batl":[[0,65,28.88]],"id":98464183}]}],"rt":639159133084679962,"dt":639159133084680320}
{"op":"mcm","id":2,"clk":"AJTZAQCwlQEAn5MC","pt":1780316508661,"mc":[{"id":"1.258742455","rc":[{"atl":[[5.6,35.96]],"batl":[],"id":99072898}]}],"rt":639159133086693872,"dt":639159133086694304}
{"op":"mcm","id":2,"clk":"AJ7ZAQC3lQEAq5MC","pt":1780316508868,"mc":[{"id":"1.258742455","rc":[{"atl":[[5.7,35.57]],"batl":[],"id":99072898}]}],"rt":639159133088759602,"dt":639159133088759979}
{"op":"mcm","id":2,"clk":"AKjZAQC\u002BlQEAspMC","pt":1780316508967,"mc":[{"id":"1.258742455","rc":[{"atl":[[50,4.01]],"id":97736949}]}],"rt":639159133089756446,"dt":639159133089756766}
{"op":"mcm","id":2,"clk":"AK3ZAQDAlQEAvZMC","pt":1780316509069,"mc":[{"id":"1.258742455","rc":[{"atl":[[5.1,76.34]],"batl":[[0,5.1,76.34]],"id":10398159}]}],"rt":639159133090773053,"dt":639159133090773452}
{"op":"mcm","id":2,"clk":"ALTZAQDFlQEAxpMC","pt":1780316509173,"mc":[{"id":"1.258742455","rc":[{"batb":[[0,95,3.85]],"atb":[[95,3.85]],"id":99072901},{"batb":[[0,5,6.94]],"atb":[[5,6.94]],"id":10398159}]}],"rt":639159133091810483,"dt":639159133091810973}
{"op":"mcm","id":2,"clk":"ALrZAQDKlQEAzZMC","pt":1780316509276,"mc":[{"id":"1.258742455","rc":[{"tv":2727.22,"batb":[[2,9.6,17.45],[1,9.8,13.52],[0,10,39.61]],"trd":[[10.5,275.12]],"atb":[[10.5,0]],"atl":[[10.5,63.92]],"batl":[[2,11.5,24.72],[1,11,2.96],[0,10.5,63.92]],"id":97736949}],"tv":42782.88}],"rt":639159133092837812,"dt":639159133092838381}
{"op":"mcm","id":2,"clk":"AMHZAQDNlQEA1ZMC","pt":1780316509380,"mc":[{"id":"1.258742455","rc":[{"tv":9189.5,"trd":[[5.2,31.48]],"ltp":5.2,"atl":[[5.2,0]],"batl":[[0,5.3,30.49]],"id":99072898},{"tv":1499.55,"trd":[[21,296.5]],"atl":[[21,1.09]],"batl":[[0,21,1.09]],"id":99072900},{"batb":[[0,5,29.42]],"atb":[[5,29.42]],"id":10398159},{"batb":[[1,3.35,157.42],[0,3.4,41.04]],"atb":[[3.4,41.04],[3.35,157.42]],"atl":[[3.75,39.02]],"batl":[],"id":88302242},{"batb":[],"atb":[[9.4,17.64],[9,27.46]],"atl":[[11,9.28],[10.5,70.88]],"batl":[[1,11,9.28],[0,10.5,70.88]],"id":97736949}],"tv":42790.24}],"rt":639159133093886566,"dt":639159133093887319}
{"op":"mcm","id":2,"clk":"AMzZAQDQlQEA3pMC","pt":1780316509485,"mc":[{"id":"1.258742455","rc":[{"batb":[[0,5.1,45]],"atb":[[5.1,45]],"id":99072898},{"batb":[[2,19,14.6]],"atb":[[19,14.6]],"id":99072900},{"batb":[[0,5,40.83]],"atb":[[5,40.83]],"id":10398159},{"batb":[[0,3.4,43.71]],"atb":[[3.25,65.72],[3.4,43.71]],"atl":[[3.65,157.47],[3.45,29.52]],"batl":[[0,3.45,29.52]],"id":88302242},{"batb":[[0,10,32.33]],"atb":[[9.2,24.93],[10,32.33]],"atl":[[13,12.08],[11.5,16.83],[11,12.6],[10.5,77.21]],"batl":[[2,11.5,16.83],[1,11,12.6],[0,10.5,77.21]],"id":97736949}]}],"rt":639159133094934619,"dt":639159133094935121}
{"op":"mcm","id":2,"clk":"ANfZAQDXlQEA55MC","pt":1780316509588,"mc":[{"id":"1.258742455","rc":[{"atb":[[4,25.51]],"id":99072898},{"tv":1500.85,"batb":[[0,20,24.25]],"trd":[[21,297.8]],"atb":[[20,24.25]],"atl":[[21,0.44]],"batl":[[2,24,11.26],[1,23,9.67],[0,22,9.35]],"id":99072900},{"batb":[[0,5,56.83]],"atb":[[5,56.83]],"id":10398159},{"batb":[[0,3.4,53.43]],"atb":[[3.4,53.43]],"atl":[[3.45,18.96]],"batl":[[0,3.45,18.96]],"id":88302242},{"batb":[[1,9.8,10.69]],"atb":[[9.8,10.69],[9.2,9.83]],"atl":[[11.5,14.76]],"batl":[[2,11.5,14.76]],"id":97736949}],"tv":42791.54}],"rt":639159133095966350,"dt":639159133095966896}
{"op":"mcm","id":2,"clk":"AN7ZAQDblQEA8pMC","pt":1780316509689,"mc":[{"id":"1.258742455","rc":[{"batb":[[0,10,24.63]],"atb":[[10,24.63]],"id":97736949}]}],"rt":639159133096974930,"dt":639159133096975244}
{"op":"mcm","id":2,"clk":"AOXZAQDllQEA/ZMC","pt":1780316509794,"mc":[{"id":"1.258742455","rc":[{"batb":[[0,5,58.15]],"atb":[[5,58.15]],"id":10398159},{"batb":[[0,3.4,58.68]],"atb":[[3.4,58.68]],"id":88302242},{"batb":[[1,9.8,11.01]],"atb":[[9.4,11.64],[9.8,11.01],[9.2,13.09]],"atl":[[13,6.08],[11.5,14.66],[11,16.05],[10.5,79.26]],"batl":[[2,11.5,14.66],[1,11,16.05],[0,10.5,79.26]],"id":97736949}]}],"rt":639159133098025274,"dt":639159133098025744}
{"op":"mcm","id":2,"clk":"AOzZAQDslQEAjJQC","pt":1780316509998,"mc":[{"id":"1.258742455","rc":[{"batb":[[1,9.8,10.69]],"atb":[[9.8,10.69],[9.2,19.09]],"atl":[[12.5,14.13]],"batl":[],"id":97736949}]}],"rt":639159133100063933,"dt":639159133100064410}
{"op":"mcm","id":2,"clk":"APDZAQDylQEAkpQC","pt":1780316510100,"mc":[{"id":"1.258742455","rc":[{"batb":[],"atb":[[9,30.94]],"id":97736949}]}],"rt":639159133101084753,"dt":639159133101085211}
{"op":"mcm","id":2,"clk":"APbZAQD4lQEAnZQC","pt":1780316510155,"mc":[{"id":"1.258742455","rc":[{"batb":[[0,8,70.3]],"atb":[[8,70.3]],"id":98117699},{"batb":[[0,1000,89.3]],"atb":[[1000,89.3]],"id":10445502}]}],"rt":639159133101626994,"dt":639159133101627368}
{"op":"mcm","id":2,"clk":"APrZAQD8lQEAq5QC","pt":1780316510265,"mc":[{"id":"1.258742455","rc":[{"batb":[[1,9.8,10.88]],"atb":[[9.8,10.88]],"id":97736949}]}],"rt":639159133102732000,"dt":639159133102732510}
