{"op":"mcm","id":2,"clk":"APMrAO0XALM7","pt":1780316176730,"mc":[{"id":"1.258742455","rc":[{"batb":[[0,60,40]],"atb":[[60,40]],"id":98464183}]}],"rt":639159129767383639,"dt":639159129767384049}
{"op":"mcm","id":2,"clk":"APYrAPQXAL07","pt":1780316176863,"mc":[{"id":"1.258742455","rc":[{"batb":[[0,60,45.77]],"atb":[[60,45.77]],"id":98464183}]}],"rt":639159129768714625,"dt":639159129768715003}
{"op":"mcm","id":2,"clk":"APsrAIQYANM7","pt":1780316176942,"mc":[{"id":"1.258742455","rc":[{"batb":[[0,3.55,64.06]],"atb":[[3.55,64.06]],"id":88302242}]}],"rt":639159129769505682,"dt":639159129769506252}
{"op":"mcm","id":2,"clk":"AJwsAJcYAPU7","pt":1780316177039,"mc":[{"id":"1.258742455","rc":[{"atl":[[5.4,26.52]],"batl":[],"id":99072898},{"batb":[[2,3.45,22.23]],"atb":[[3.45,22.23]],"id":88302242}]}],"rt":639159129770478283,"dt":639159129770478944}
{"op":"mcm","id":2,"clk":"AJ4sAJkYAP47","pt":1780316177139,"mc":[{"id":"1.258742455","rc":[{"tv":2102.09,"batb":[[0,10,21.55]],"trd":[[10,479.06]],"ltp":10,"atb":[[10,21.55]],"id":98117699}],"tv":33183}],"rt":639159129771472489,"dt":639159129771472957}
{"op":"mcm","id":2,"clk":"AKQsAKQYAJA8","pt":1780316177299,"mc":[{"id":"1.258742455","rc":[{"batb":[[0,10,20.55]],"atb":[[10,20.55]],"id":98117699}]}],"rt":639159129773069958,"dt":639159129773070345}
{"op":"mcm","id":2,"clk":"ALUsALUYALA8","pt":1780316177608,"mc":[{"id":"1.258742455","rc":[{"batb":[[1,9.8,12.49]],"atb":[[9.8,12.49]],"id":98117699}]}],"rt":639159129776163862,"dt":639159129776164413}
{"op":"mcm","id":2,"clk":"ANYsAMgYAN48","pt":1780316178026,"mc":[{"id":"1.258742455","rc":[{"atl":[[4.9,43.66]],"batl":[[0,4.9,43.66]],"id":99072898},{"tv":895.89,"batb":[[0,24,15.63]],"trd":[[24,90.29]],"atb":[[24,15.63]],"id":99072900},{"batb":[[0,80,3.84]],"atb":[[80,3.84]],"id":99072901},{"batb":[[0,4.5,117.14]],"atb":[[4.5,117.14]],"id":10398159},{"batb":[[0,160,4.63]],"atb":[[160,4.63]],"id":99072897}],"tv":33184.73}],"rt":639159129780343067,"dt":639159129780343901}
{"op":"mcm","id":2,"clk":"AN8sANIYAOk8","pt":1780316178131,"mc":[{"id":"1.258742455","rc":[{"batb":[[0,10,13.01]],"atb":[[10,13.01]],"id":98117699},{"tv":11485.17,"batb":[[0,3.55,54.06]],"trd":[[3.55,278.65]],"atb":[[3.55,54.06]],"id":88302242}],"tv":33204.73}],"rt":639159129781393558,"dt":639159129781394181}
{"op":"mcm","id":2,"clk":"AO4sAN4YAPg8","pt":1780316178335,"mc":[{"id":"1.258742455","rc":[{"batb":[[0,10,10.65]],"atb":[[10,10.65]],"id":98117699}]}],"rt":639159129783439001,"dt":639159129783439413}
{"op":"mcm","id":2,"clk":"APIsAOMYAIE9","pt":1780316178435,"mc":[{"id":"1.258742455","rc":[{"batb":[[2,4.5,42.51]],"atb":[[4.5,42.51]],"id":99072898},{"batb":[[0,3.55,58.22]],"atb":[[3.55,58.22]],"id":88302242}]}],"rt":639159129784428491,"dt":639159129784428917}
{"op":"mcm","id":2,"clk":"AI0tAPYYAK89","pt":1780316178845,"mc":[{"id":"1.258742455","rc":[{"batb":[[0,4.7,41.78]],"atb":[[4.7,41.78]],"id":99072898},{"batb":[[0,4.5,118.8]],"atb":[[4.5,118.8]],"id":10398159},{"batb":[[0,60,28.26]],"atb":[[60,28.26]],"id":98464183},{"batb":[[0,3.55,60.32]],"atb":[[3.55,60.32]],"id":88302242},{"batb":[[0,1000,103.94]],"atb":[[1000,103.94]],"id":10445502}]}],"rt":639159129788535890,"dt":639159129788536483}
{"op":"mcm","id":2,"clk":"AJ8tAIYZAMo9","pt":1780316179155,"mc":[{"id":"1.258742455","rc":[{"atl":[[32,0.22]],"id":98117699},{"atl":[[50,1.99]],"id":97736949}]}],"rt":639159129791627769,"dt":639159129791628322}
{"op":"mcm","id":2,"clk":"ALUtAJQZAO49","pt":1780316179509,"mc":[{"id":"1.258742455","rc":[{"atl":[[4.7,99.96],[4.9,29.98]],"batl":[[1,4.7,99.96]],"id":10398159}]}],"rt":639159129795171068,"dt":639159129795171434}
{"op":"mcm","id":2,"clk":"AMAtAJkZAP89","pt":1780316179712,"mc":[{"id":"1.258742455","rc":[{"atl":[[5.7,9.63]],"batl":[],"id":99072898},{"atl":[[90,3.05]],"id":97008932},{"batb":[],"atb":[[4,15.82]],"id":10398159}]}],"rt":639159129797207463,"dt":639159129797207898}
{"op":"mcm","id":2,"clk":"ANotAKcZAKY\u002B","pt":1780316180126,"mc":[{"id":"1.258742455","rc":[{"atl":[[4.7,10.82],[3.65,12.95]],"batl":[[1,3.65,12.95]],"id":88302242}]}],"rt":639159129801343365,"dt":639159129801343990}
{"op":"mcm","id":2,"clk":"AOAtAKkZALE\u002B","pt":1780316180227,"mc":[{"id":"1.258742455","rc":[{"batb":[[1,3.5,32.85]],"atb":[[3.5,32.85]],"atl":[[3.6,9.23]],"batl":[[0,3.6,9.23]],"id":88302242}]}],"rt":639159129802357385,"dt":639159129802357837}
{"op":"mcm","id":2,"clk":"AOctAK0ZAL8\u002B","pt":1780316180331,"mc":[{"id":"1.258742455","rc":[{"tv":645.12,"batb":[[0,60,22.26]],"trd":[[60,93.91]],"atb":[[60,22.26]],"id":98464183},{"tv":11548.1,"trd":[[3.65,95.29],[3.7,162.78],[3.6,189.15]],"ltp":3.7,"atl":[[3.65,0],[3.7,6.68],[3.6,0]],"batl":[[2,3.8,31.82],[1,3.75,35.3],[0,3.7,6.68]],"id":88302242},{"tv":220.82,"batb":[[0,160,3.63]],"trd":[[160,48.84]],"ltp":160,"atb":[[160,3.63]],"id":99072897}],"tv":33270.64}],"rt":639159129803390828,"dt":639159129803391675}
{"op":"mcm","id":2,"clk":"AOstALAZAMU\u002B","pt":1780316180432,"mc":[{"id":"1.258742455","rc":[{"batb":[[2,38,12.16]],"atb":[[38,12.16]],"id":97008932},{"batb":[[1,4.4,149.74]],"atb":[[4.4,149.74]],"atl":[[4.8,22.67]],"batl":[[2,4.8,22.67]],"id":10398159},{"batb":[[2,9.6,10.24]],"atb":[[9.6,10.24]],"id":98117699},{"batb":[[2,3.5,42.51],[1,3.55,60.32],[0,3.6,9.94]],"atb":[[3.5,42.51],[3.6,9.94],[3.45,29.92]],"id":88302242},{"batb":[],"atb":[[9.4,20.25]],"id":97736949}]}],"rt":639159129804398433,"dt":639159129804399129}
{"op":"mcm","id":2,"clk":"APEtALkZAM4\u002B","pt":1780316180536,"mc":[{"id":"1.258742455","rc":[{"tv":678.1,"batb":[[2,48,6.38],[1,50,17.72],[0,55,30.4]],"trd":[[60,126.89]],"atb":[[60,0]],"atl":[[60,5.8]],"batl":[[2,70,10.57],[1,65,27.95],[0,60,5.8]],"id":98464183},{"batb":[[0,3.6,14.11]],"atb":[[3.6,14.11]],"atl":[[3.75,14.05],[3.7,5.2]],"batl":[[1,3.75,14.05],[0,3.7,5.2]],"id":88302242},{"batb":[[1,150,3.29]],"atb":[[150,3.29]],"id":99072897}],"tv":33303.62}],"rt":639159129805445052,"dt":639159129805445818}
{"op":"mcm","id":2,"clk":"APctAMEZANo\u002B","pt":1780316180642,"mc":[{"id":"1.258742455","rc":[{"atl":[[4.8,19.44]],"batl":[[2,4.8,19.44]],"id":10398159},{"batb":[[0,55,28.5]],"atb":[[55,28.5]],"atl":[[65,29.88]],"batl":[[1,65,29.88]],"id":98464183},{"batb":[[0,3.6,29.66]],"atb":[[3.6,29.66]],"id":88302242}]}],"rt":639159129806501627,"dt":639159129806502195}
{"op":"mcm","id":2,"clk":"AIMuAMgZAOU\u002B","pt":1780316180746,"mc":[{"id":"1.258742455","rc":[{"batb":[[0,4.7,34.56]],"atb":[[4.7,34.56]],"id":99072898},{"atl":[[46,5.01]],"batl":[[0,46,5.01]],"id":97008932},{"atl":[[4.8,22.67]],"batl":[[2,4.8,22.67]],"id":10398159},{"atl":[[65,26.51]],"batl":[[1,65,26.51]],"id":98464183},{"batb":[[1,3.55,69.9]],"atb":[[3.55,69.9]],"id":88302242}]}],"rt":639159129807535246,"dt":639159129807535832}
{"op":"mcm","id":2,"clk":"AIouAM0ZAO4\u002B","pt":1780316180845,"mc":[{"id":"1.258742455","rc":[{"atl":[[4.8,11.52]],"batl":[[2,5,12.08],[1,4.9,43.66],[0,4.8,11.52]],"id":99072898},{"batb":[],"atb":[[34,9.51]],"id":98464183},{"atl":[[4,7.82]],"batl":[],"id":88302242}]}],"rt":639159129808530507,"dt":639159129808530961}
{"op":"mcm","id":2,"clk":"AJMuANAZAPQ\u002B","pt":1780316180948,"mc":[{"id":"1.258742455","rc":[{"atl":[[4.8,19.44]],"batl":[[2,4.8,19.44]],"id":10398159},{"batb":[],"atb":[[9.4,18.57],[9.2,17.73]],"id":98117699},{"batb":[[1,150,5.02]],"atb":[[150,5.02]],"id":99072897}]}],"rt":639159129809563758,"dt":639159129809564475}
{"op":"mcm","id":2,"clk":"AJkuANUZAP0\u002B","pt":1780316181049,"mc":[{"id":"1.258742455","rc":[{"batb":[[0,4.7,24.02]],"atb":[[4.7,24.02]],"atl":[[5.1,12.68]],"batl":[],"id":99072898},{"atl":[[3.7,5.84]],"batl":[[0,3.7,5.84]],"id":88302242}]}],"rt":639159129810572921,"dt":639159129810573308}
{"op":"mcm","id":2,"clk":"AKUuANwZAJI/","pt":1780316181209,"mc":[{"id":"1.258742455","rc":[{"batb":[[0,4.7,19.26]],"atb":[[4.7,19.26]],"id":99072898},{"tv":11548.25,"batb":[[0,3.6,29.59]],"trd":[[3.6,189.3]],"ltp":3.6,"atb":[[3.6,29.59]],"id":88302242}],"tv":33303.77}],"rt":639159129812171807,"dt":639159129812172268}
{"op":"mcm","id":2,"clk":"AKwuAOAZAJ8/","pt":1780316181311,"mc":[{"id":"1.258742455","rc":[{"batb":[[0,4.7,16.47]],"atb":[[4.7,16.47]],"id":99072898},{"batb":[[0,4.5,117.22]],"atb":[[4.5,117.22]],"atl":[[4.6,52.75]],"batl":[[0,4.6,52.75]],"id":10398159},{"atl":[[3.65,5.2]],"batl":[[2,3.75,14.05],[1,3.7,5.84],[0,3.65,5.2]],"id":88302242},{"atl":[[11,0]],"batl":[[0,11.5,9.12]],"id":97736949}]}],"rt":639159129813190120,"dt":639159129813190573}
{"op":"mcm","id":2,"clk":"AK4uAOMZAKg/","pt":1780316181410,"mc":[{"id":"1.258742455","rc":[{"batb":[[1,4.6,40.38],[0,4.7,18.36]],"atb":[[4.7,18.36],[4.6,40.38]],"atl":[[4.9,32.34],[4.8,15.55]],"batl":[[1,4.9,32.34],[0,4.8,15.55]],"id":99072898},{"batb":[[0,55,28.09]],"atb":[[1.17,2.19],[55,28.09]],"atl":[[60,6.72],[65,24.28]],"batl":[[1,65,24.28],[0,60,6.72]],"id":98464183},{"batb":[],"atb":[[9.4,22]],"id":98117699},{"atl":[[11.5,8.89]],"batl":[[0,11.5,8.89]],"id":97736949}]}],"rt":639159129814184427,"dt":639159129814185033}
{"op":"mcm","id":2,"clk":"ALUuAO4ZALI/","pt":1780316181516,"mc":[{"id":"1.258742455","rc":[{"atl":[[4.8,22.66]],"batl":[[2,4.8,22.66]],"id":10398159},{"atb":[[1.17,2]],"id":98464183},{"batb":[[1,3.55,71.9]],"atb":[[3.55,71.9]],"id":88302242}]}],"rt":639159129815241366,"dt":639159129815241764}
{"op":"mcm","id":2,"clk":"ALsuAPQZAL0/","pt":1780316181617,"mc":[{"id":"1.258742455","rc":[{"batb":[[1,50,17.91]],"atb":[[50,17.91]],"id":98464183}]}],"rt":639159129816250907,"dt":639159129816251468}
{"op":"mcm","id":2,"clk":"AMEuAPwZAMc/","pt":1780316181721,"mc":[{"id":"1.258742455","rc":[{"batb":[[0,3.6,30.59]],"atb":[[3.6,30.59]],"id":88302242}]}],"rt":639159129817292184,"dt":639159129817293006}
{"op":"mcm","id":2,"clk":"AMsuAIQaANc/","pt":1780316181832,"mc":[{"id":"1.258742455","rc":[{"atl":[[60,6.75]],"batl":[[0,60,6.75]],"id":98464183},{"atl":[[15.5,3.73]],"batl":[],"id":97736949}]}],"rt":639159129818403610,"dt":639159129818403997}
{"op":"mcm","id":2,"clk":"ANUuAI0aAOg/","pt":1780316182031,"mc":[{"id":"1.258742455","rc":[{"tv":682.1,"batb":[[0,55,26.09]],"trd":[[55,37.43]],"ltp":55,"atb":[[55,26.09]],"id":98464183}],"tv":33307.77}],"rt":639159129820390261,"dt":639159129820390906}
{"op":"mcm","id":2,"clk":"ANouAI4aAPQ/","pt":1780316182132,"mc":[{"id":"1.258742455","rc":[{"atl":[[46,5.05]],"batl":[[0,46,5.05]],"id":97008932},{"tv":2110.09,"batb":[[0,10,6.65]],"trd":[[10,487.06]],"atb":[[10,6.65]],"id":98117699},{"atl":[[3.65,5.76]],"batl":[[0,3.65,5.76]],"id":88302242}],"tv":33315.77}],"rt":639159129821404539,"dt":639159129821405033}
{"op":"mcm","id":2,"clk":"AOEuAJYaAIBA","pt":1780316182236,"mc":[{"id":"1.258742455","rc":[{"atl":[[5.1,32.79]],"batl":[],"id":10398159},{"batb":[[0,55,32.23]],"atb":[[55,32.23]],"id":98464183},{"tv":2122.87,"batb":[[2,9.4,22],[1,9.6,10.24],[0,9.8,12.75]],"trd":[[10,499.84]],"atb":[[10,0.26]],"id":98117699},{"batb":[],"atb":[[3.4,20.39]],"id":88302242}],"tv":33328.55}],"rt":639159129822446515,"dt":639159129822447011}
{"op":"mcm","id":2,"clk":"AOsuAJsaAIdA","pt":1780316182352,"mc":[{"id":"1.258742455","rc":[{"atl":[[4.8,19.44]],"batl":[[2,4.8,19.44]],"id":10398159},{"tv":2123.91,"batb":[[2,9.6,10.24],[1,9.8,12.49],[0,10,2.91]],"trd":[[10,500.88]],"atb":[[9.4,18.57],[10,2.91]],"id":98117699},{"tv":11548.39,"batb":[[0,3.6,30.52]],"trd":[[3.6,189.44]],"atb":[[3.6,30.52]],"id":88302242}],"tv":33329.73}],"rt":639159129823601345,"dt":639159129823601823}
{"op":"mcm","id":2,"clk":"AO8uAJ4aAI9A","pt":1780316182441,"mc":[{"id":"1.258742455","rc":[{"tv":2129.73,"batb":[[2,9.4,18.57],[1,9.6,10.24],[0,9.8,10.87]],"trd":[[10,506.7]],"atb":[[9.8,10.87],[10,0],[8,54.4]],"atl":[[12,16.74],[10,1.81]],"batl":[[2,11,12.6],[1,10.5,12.82],[0,10,1.81]],"id":98117699}],"tv":33335.55}],"rt":639159129824487718,"dt":639159129824488164}
{"op":"mcm","id":2,"clk":"APYuAKQaAJpA","pt":1780316182545,"mc":[{"id":"1.258742455","rc":[{"tv":7381.11,"batb":[[0,4.7,21.21]],"trd":[[4.7,40.38]],"ltp":4.7,"atb":[[4.7,21.21]],"id":99072898},{"atl":[[10,5.01]],"batl":[[0,10,5.01]],"id":98117699},{"tv":11561.39,"batb":[[0,3.6,24.02]],"trd":[[3.6,202.44]],"atb":[[3.6,24.02]],"id":88302242},{"batb":[[1,150,3.29]],"atb":[[150,3.29]],"id":99072897}],"tv":33355.55}],"rt":639159129825533799,"dt":639159129825534402}
{"op":"mcm","id":2,"clk":"AP8uAKoaAKhA","pt":1780316182654,"mc":[{"id":"1.258742455","rc":[{"batb":[[0,9.8,2.34]],"atb":[[9.8,2.34]],"atl":[[12,14.62]],"batl":[],"id":98117699},{"batb":[[2,9.8,15.66]],"atb":[[9.8,15.66]],"id":97736949}]}],"rt":639159129826627288,"dt":639159129826627904}
{"op":"mcm","id":2,"clk":"AIQvAK8aALBA","pt":1780316182745,"mc":[{"id":"1.258742455","rc":[{"batb":[[2,9.2,14.28],[1,9.4,18.57],[0,9.6,10.24]],"atb":[[9.8,0],[9.2,14.28],[9,23.57]],"id":98117699}]}],"rt":639159129827530481,"dt":639159129827530889}
{"op":"mcm","id":2,"clk":"AIovALYaALxA","pt":1780316182859,"mc":[{"id":"1.258742455","rc":[{"batb":[[1,150,5.02]],"atb":[[150,5.02]],"id":99072897}]}],"rt":639159129828673225,"dt":639159129828673575}
{"op":"mcm","id":2,"clk":"AKYvANIaAPlA","pt":1780316183319,"mc":[{"id":"1.258742455","rc":[{"atb":[[1.17,2.3]],"id":10398159},{"atl":[[1000,7.02],[10,6.14]],"batl":[[0,10,6.14]],"id":98117699}]}],"rt":639159129833273313,"dt":639159129833273794}
{"op":"mcm","id":2,"clk":"ALAvANsaAItB","pt":1780316183532,"mc":[{"id":"1.258742455","rc":[{"atb":[[1.17,2]],"id":10398159},{"atl":[[1000,6.25]],"id":98117699}]}],"rt":639159129835401311,"dt":639159129835401915}
{"op":"mcm","id":2,"clk":"ALQvAOIaAJZB","pt":1780316183627,"mc":[{"id":"1.258742455","rc":[{"tv":7575.32,"batb":[[0,4.5,117.37]],"trd":[[4.6,797.61]],"atb":[[4.5,117.37]],"atl":[[4.6,52.6]],"batl":[[0,4.6,52.6]],"id":10398159},{"tv":2131.27,"batb":[[0,9.6,9.47]],"trd":[[9.6,214.7]],"ltp":9.6,"atb":[[9.6,9.47]],"id":98117699},{"atl":[[12,29.74]],"batl":[[1,12,29.74]],"id":97736949}],"tv":33357.39}],"rt":639159129836356484,"dt":639159129836357619}
{"op":"mcm","id":2,"clk":"ALgvAOQaAKFB","pt":1780316183721,"mc":[{"id":"1.258742455","rc":[{"atl":[[12,10.93]],"batl":[],"id":98117699},{"atl":[[11.5,9.89]],"batl":[[0,11.5,9.89]],"id":97736949}]}],"rt":639159129837294856,"dt":639159129837295299}
{"op":"mcm","id":2,"clk":"AMEvAOsaAKtB","pt":1780316183833,"mc":[{"id":"1.258742455","rc":[{"batb":[[0,9.6,10.51]],"atb":[[9.6,10.51]],"id":98117699}]}],"rt":639159129838415166,"dt":639159129838415557}
{"op":"mcm","id":2,"clk":"AMovAPQaALJB","pt":1780316183932,"mc":[{"id":"1.258742455","rc":[{"atl":[[5,24.21]],"batl":[[2,5,24.21]],"id":99072898},{"tv":7579.46,"batb":[[0,4.5,115.3]],"trd":[[4.5,1665.15]],"ltp":4.5,"atb":[[4.5,115.3]],"id":10398159},{"batb":[[2,9.8,10.18]],"atb":[[9.8,10.18]],"id":97736949}],"tv":33361.53}],"rt":639159129839400631,"dt":639159129839401750}
{"op":"mcm","id":2,"clk":"ANAvAPgaALpB","pt":1780316184036,"mc":[{"id":"1.258742455","rc":[{"batb":[],"atb":[[8.4,23.76]],"atl":[[16,4.07]],"batl":[],"id":97736949}]}],"rt":639159129840441774,"dt":639159129840442158}
{"op":"mcm","id":2,"clk":"AOMvAIAbANVB","pt":1780316184342,"mc":[{"id":"1.258742455","rc":[{"atl":[[1000,6.35]],"batl":[],"id":99072901}]}],"rt":639159129843506748,"dt":639159129843507107}
{"op":"mcm","id":2,"clk":"AOwvAIIbAN1B","pt":1780316184446,"mc":[{"id":"1.258742455","rc":[{"atl":[[1000,6.25]],"batl":[],"id":99072901},{"batb":[],"atb":[[4,19.82]],"id":10398159},{"atl":[[1000,3.11]],"id":88302242}]}],"rt":639159129844542928,"dt":639159129844543336}
{"op":"mcm","id":2,"clk":"APIvAIUbAOxB","pt":1780316184549,"mc":[{"id":"1.258742455","rc":[{"atl":[[95,4.04]],"batl":[[0,95,4.63]],"id":99072901}]}],"rt":639159129845575689,"dt":639159129845576033}
{"op":"mcm","id":2,"clk":"APwvAIcbAPZB","pt":1780316184654,"mc":[{"id":"1.258742455","rc":[{"atl":[[32,1.85]],"id":10398159},{"atl":[[1000,3]],"id":88302242},{"atl":[[50,4.11]],"id":97736949}]}],"rt":639159129846626249,"dt":639159129846626640}
{"op":"mcm","id":2,"clk":"AIEwAIobAIFC","pt":1780316184753,"mc":[{"id":"1.258742455","rc":[{"tv":11561.43,"trd":[[3.65,95.33]],"ltp":3.65,"atl":[[3.65,5.74],[3.7,5.95]],"batl":[[1,3.7,5.95],[0,3.65,5.74]],"id":88302242},{"batb":[[0,10.5,38.23]],"atb":[[10.5,38.23]],"id":97736949}],"tv":33361.57}],"rt":639159129847608812,"dt":639159129847609426}
{"op":"mcm","id":2,"clk":"AIcwAI8bAIpC","pt":1780316184809,"mc":[{"id":"1.258742455","rc":[{"batb":[[0,10.5,39.81]],"atb":[[10.5,39.81]],"atl":[[11.5,11.34]],"batl":[[0,11.5,11.34]],"id":97736949}]}],"rt":639159129848169394,"dt":639159129848169784}
{"op":"mcm","id":2,"clk":"AJEwAJIbAJFC","pt":1780316184908,"mc":[{"id":"1.258742455","rc":[{"batb":[[2,4.3,111.66]],"atb":[[4.3,111.66]],"id":10398159}]}],"rt":639159129849166104,"dt":639159129849166452}
{"op":"mcm","id":2,"clk":"AJ8wAJobAKRC","pt":1780316185118,"mc":[{"id":"1.258742455","rc":[{"batb":[[1,10,45.8]],"atb":[[10,45.8]],"atl":[[12,31.12]],"batl":[[1,12,31.12]],"id":97736949}]}],"rt":639159129851260802,"dt":639159129851261150}
{"op":"mcm","id":2,"clk":"ALUwAKgbAMZC","pt":1780316185528,"mc":[{"id":"1.258742455","rc":[{"atl":[[4.8,15]],"batl":[[0,4.8,15]],"id":99072898},{"atl":[[10,5.01]],"batl":[[0,10,5.01]],"id":98117699},{"atl":[[3.65,25.74]],"batl":[[0,3.65,25.74]],"id":88302242}]}],"rt":639159129855362790,"dt":639159129855363195}
{"op":"mcm","id":2,"clk":"AMEwAKsbANRC","pt":1780316185641,"mc":[{"id":"1.258742455","rc":[{"batb":[],"atb":[[4.3,18.38]],"id":99072898},{"batb":[[0,55,33.78]],"atb":[[55,33.78]],"id":98464183},{"batb":[[0,3.6,8.47]],"atb":[[3.6,8.47]],"id":88302242}]}],"rt":639159129856490776,"dt":639159129856491620}
{"op":"mcm","id":2,"clk":"AMQwALAbAN1C","pt":1780316185737,"mc":[{"id":"1.258742455","rc":[{"batb":[[2,4.5,44.51],[1,4.6,41.93]],"atb":[[4.6,41.93],[4.5,44.51]],"id":99072898},{"batb":[[1,4.4,147.64]],"atb":[[4.4,147.64]],"id":10398159},{"batb":[[0,9.6,11.51]],"atb":[[9.6,11.51]],"id":98117699},{"atl":[[16.5,4.76]],"id":97736949},{"batb":[[1,150,3.29]],"atb":[[150,3.29]],"id":99072897}]}],"rt":639159129857453045,"dt":639159129857453452}
{"op":"mcm","id":2,"clk":"AM0wALIbAOhC","pt":1780316185836,"mc":[{"id":"1.258742455","rc":[{"atl":[[4.6,4]],"batl":[[0,4.6,4]],"id":10398159},{"batb":[[0,3.6,4.3]],"atb":[[3.6,4.3]],"atl":[[3.65,34.1]],"batl":[[0,3.65,34.1]],"id":88302242},{"batb":[[0,10.5,40.83]],"atb":[[10.5,40.83]],"id":97736949}]}],"rt":639159129858442694,"dt":639159129858443139}
{"op":"mcm","id":2,"clk":"ANQwALYbAPFC","pt":1780316185937,"mc":[{"id":"1.258742455","rc":[{"batb":[[0,4.7,22.13]],"atb":[[4.7,22.13]],"id":99072898},{"batb":[[0,24,19.39]],"atb":[[24,19.39]],"id":99072900},{"batb":[[1,75,9.03]],"atb":[[75,9.03]],"id":99072901},{"batb":[[1,3.55,62.32],[0,3.6,1]],"atb":[[3.55,62.32],[3.6,1]],"id":88302242},{"batb":[[1,150,5.02]],"atb":[[150,5.02]],"id":99072897}]}],"rt":639159129859451781,"dt":639159129859452541}
{"op":"mcm","id":2,"clk":"ANcwALwbAP1C","pt":1780316186039,"mc":[{"id":"1.258742455","rc":[{"batb":[],"atb":[[160,5]],"id":10445502}]}],"rt":639159129860467292,"dt":639159129860467928}
{"op":"mcm","id":2,"clk":"AN8wAMIbAI9D","pt":1780316186240,"mc":[{"id":"1.258742455","rc":[{"atl":[[22,1]],"id":99072898},{"atl":[[22,1]],"id":10398159},{"atl":[[22,5.99]],"id":98117699},{"atl":[[22,1]],"id":88302242},{"batb":[[2,9.8,11.98]],"atb":[[9.8,11.98]],"atl":[[12.5,20.46]],"batl":[[2,12.5,20.46]],"id":97736949}]}],"rt":639159129862484049,"dt":639159129862484476}
{"op":"mcm","id":2,"clk":"AOswAMQbAJpD","pt":1780316186345,"mc":[{"id":"1.258742455","rc":[{"tv":2141.29,"batb":[[2,9.4,18.57],[1,9.6,11.51],[0,10,9.15]],"trd":[[10,516.72]],"ltp":10,"atb":[[10,9.15]],"atl":[[10,0]],"batl":[[2,11.5,6.38],[1,11,12.6],[0,10.5,12.82]],"id":98117699}],"tv":33371.59}],"rt":639159129863536577,"dt":639159129863537281}
{"op":"mcm","id":2,"clk":"APEwAMYbAKlD","pt":1780316186453,"mc":[{"id":"1.258742455","rc":[{"tv":2159.59,"batb":[[2,9.6,11.51],[1,9.8,3.09],[0,10,3]],"trd":[[10,535.02]],"atb":[[9.4,21.99],[9.8,3.09],[10,3]],"id":98117699}],"tv":33389.89}],"rt":639159129864608630,"dt":639159129864609141}
{"op":"mcm","id":2,"clk":"APUwAMsbAK5D","pt":1780316186554,"mc":[{"id":"1.258742455","rc":[{"batb":[[0,4.7,15.79]],"atb":[[4.7,15.79]],"id":99072898},{"tv":705.66,"batb":[[2,46,4.3],[1,48,6.38],[0,50,17.91]],"trd":[[55,60.99]],"atb":[[55,0]],"atl":[[55,10.22]],"batl":[[2,65,24.28],[1,60,6.75],[0,55,10.22]],"id":98464183},{"tv":2165.59,"batb":[[2,9.4,21.99],[1,9.6,11.51],[0,9.8,5.8]],"trd":[[10,541.02]],"atb":[[9.8,5.8],[9.2,17.73],[10,0]],"atl":[[10,3]],"batl":[[2,11,12.6],[1,10.5,12.82],[0,10,3]],"id":98117699}],"tv":33419.45}],"rt":639159129865621067,"dt":639159129865621741}
{"op":"mcm","id":2,"clk":"AP0wANEbALtD","pt":1780316186663,"mc":[{"id":"1.258742455","rc":[{"batb":[[0,4.7,21.24]],"atb":[[4.7,21.24]],"id":99072898},{"tv":711.14,"batb":[[0,50,15.17]],"trd":[[50,34.77]],"ltp":50,"atb":[[50,15.17]],"id":98464183},{"atl":[[10,5.1]],"batl":[[0,10,5.1]],"id":98117699},{"batb":[],"atb":[[9.4,23.4]],"id":97736949}],"tv":33424.93}],"rt":639159129866711424,"dt":639159129866711927}
{"op":"mcm","id":2,"clk":"AIYxANUbAMZD","pt":1780316186763,"mc":[{"id":"1.258742455","rc":[{"atl":[[36,2.91]],"batl":[],"id":99072900},{"batb":[[0,50,13.45]],"atb":[[50,13.45],[32,6.43]],"atl":[[60,8.67],[55,18.52]],"batl":[[1,60,8.67],[0,55,18.52]],"id":98464183},{"batb":[[2,9.4,18.57],[0,9.8,3.09]],"atb":[[9.4,18.57],[9.8,3.09]],"atl":[[10.5,10.72],[10,2.1]],"batl":[[1,10.5,10.72],[0,10,2.1]],"id":98117699},{"atb":[[8.2,10]],"id":97736949}]}],"rt":639159129867713654,"dt":639159129867714363}
{"op":"mcm","id":2,"clk":"AIgxANcbAMtD","pt":1780316186811,"mc":[{"id":"1.258742455","rc":[{"atl":[[60,8.89]],"batl":[[1,60,8.89]],"id":98464183}]}],"rt":639159129868189033,"dt":639159129868189447}
{"op":"mcm","id":2,"clk":"AI8xAN8bANRD","pt":1780316186920,"mc":[{"id":"1.258742455","rc":[{"tv":7587.46,"batb":[[2,4.4,147.64],[1,4.5,115.3],[0,4.6,32.62]],"trd":[[4.6,805.61]],"ltp":4.6,"atb":[[4.6,32.62]],"atl":[[4.6,0]],"batl":[[2,4.9,29.98],[1,4.8,19.44],[0,4.7,99.96]],"id":10398159},{"tv":738.04,"batb":[[2,44,4.4],[1,46,4.3],[0,48,6.38]],"trd":[[50,61.67]],"atb":[[50,0]],"atl":[[55,20.56],[50,5.21]],"batl":[[2,60,8.89],[1,55,20.56],[0,50,5.21]],"id":98464183},{"atl":[[10,4.89]],"batl":[[0,10,4.89]],"id":98117699}],"tv":33459.83}],"rt":639159129869285728,"dt":639159129869286650}
{"op":"mcm","id":2,"clk":"AJYxAOEbAN1D","pt":1780316187027,"mc":[{"id":"1.258742455","rc":[{"batb":[[0,4.6,40.09]],"atb":[[4.6,40.09]],"id":10398159},{"batb":[[1,46,10.86],[0,48,2.6]],"atb":[[48,2.6],[46,10.86]],"id":98464183}]}],"rt":639159129870356567,"dt":639159129870357202}
{"op":"mcm","id":2,"clk":"AJwxAOQbAOhD","pt":1780316187123,"mc":[{"id":"1.258742455","rc":[{"batb":[[0,4.6,51.65]],"atb":[[4.6,51.65]],"id":10398159},{"atl":[[60,8.67]],"batl":[[2,60,8.67]],"id":98464183},{"atl":[[1000,3.36]],"id":88302242}]}],"rt":639159129871306665,"dt":639159129871307063}
{"op":"mcm","id":2,"clk":"AKkxAOkbAPFD","pt":1780316187224,"mc":[{"id":"1.258742455","rc":[{"atl":[[4.9,26.32]],"batl":[[2,4.9,26.32]],"id":10398159},{"atl":[[1000,3]],"id":88302242}]}],"rt":639159129872320837,"dt":639159129872321668}
{"op":"mcm","id":2,"clk":"AK4xAOobAPhD","pt":1780316187321,"mc":[{"id":"1.258742455","rc":[{"atl":[[3.65,34.46]],"batl":[[0,3.65,34.46]],"id":88302242},{"batb":[],"atb":[[9.6,6.69]],"atl":[[13,11.23]],"batl":[],"id":97736949}]}],"rt":639159129873295500,"dt":639159129873296073}
{"op":"mcm","id":2,"clk":"AMcxAPgbAJBE","pt":1780316187632,"mc":[{"id":"1.258742455","rc":[{"atl":[[95,3.94]],"batl":[[0,95,4.53]],"id":99072901},{"atl":[[11,11.88]],"batl":[[2,11,11.88]],"id":98117699},{"atl":[[1000,3.56]],"id":88302242}]}],"rt":639159129876404717,"dt":639159129876405423}
{"op":"mcm","id":2,"clk":"AMwxAPsbAJlE","pt":1780316187733,"mc":[{"id":"1.258742455","rc":[{"atl":[[4.8,16.22]],"batl":[[0,4.8,16.22]],"id":99072898},{"atb":[[1.17,2.11]],"id":99072900},{"batb":[[1,4.5,110.73]],"atb":[[4.5,110.73]],"atl":[[4.7,98.68],[1000,1.33]],"batl":[[0,4.7,98.68]],"id":10398159},{"atl":[[60,7.75],[55,10.34]],"batl":[[2,60,7.75],[1,55,10.34]],"id":98464183},{"atl":[[1000,7.14]],"id":98117699},{"atl":[[3.7,5.84]],"batl":[[1,3.7,5.84]],"id":88302242}]}],"rt":639159129877415850,"dt":639159129877416572}
{"op":"mcm","id":2,"clk":"ANYxAP0bAKJE","pt":1780316187836,"mc":[{"id":"1.258742455","rc":[{"batb":[[0,48,8.95]],"atb":[[48,8.95]],"atl":[[50,5.52]],"batl":[[0,50,5.52]],"id":98464183},{"atl":[[1000,3]],"id":88302242},{"batb":[],"atb":[[9.2,25.13]],"atl":[[13.5,4.62]],"batl":[],"id":97736949}]}],"rt":639159129878437639,"dt":639159129878438126}
{"op":"mcm","id":2,"clk":"AOExAIAcAKtE","pt":1780316187940,"mc":[{"id":"1.258742455","rc":[{"atb":[[1.17,2]],"id":99072900},{"atl":[[1000,1.01]],"id":10398159},{"tv":743.24,"batb":[[2,42,4.92],[1,44,4.4],[0,46,10.86]],"trd":[[48,60.16]],"ltp":48,"atb":[[48,0]],"atl":[[48,1.48]],"batl":[[2,55,10.34],[1,50,5.52],[0,48,1.48]],"id":98464183},{"atl":[[1000,6.25]],"id":98117699},{"atl":[[3.65,35.02]],"batl":[[0,3.65,35.02]],"id":88302242}],"tv":33465.03}],"rt":639159129879481845,"dt":639159129879482388}
{"op":"mcm","id":2,"clk":"AOkxAIUcAL1E","pt":1780316188042,"mc":[{"id":"1.258742455","rc":[{"batb":[[0,24,19.5]],"atb":[[24,19.5]],"id":99072900},{"atl":[[4.8,19.76]],"batl":[[1,4.8,19.76]],"id":10398159},{"batb":[[1,44,10.9]],"atb":[[44,10.9]],"atl":[[70,8.1]],"batl":[],"id":98464183},{"batb":[],"atb":[[9.2,14.28]],"atl":[[10.5,11.24],[10,5.26]],"batl":[[1,10.5,11.24],[0,10,5.26]],"id":98117699},{"batb":[],"atb":[[9.4,20.25]],"id":97736949}]}],"rt":639159129880503290,"dt":639159129880503975}
{"op":"mcm","id":2,"clk":"APAxAIccAMVE","pt":1780316188142,"mc":[{"id":"1.258742455","rc":[{"tv":743.74,"trd":[[48,60.66]],"atl":[[48,1.23]],"batl":[[0,48,1.23]],"id":98464183}],"tv":33465.53}],"rt":639159129881503915,"dt":639159129881504338}
{"op":"mcm","id":2,"clk":"AP4xAJMcANlE","pt":1780316188367,"mc":[{"id":"1.258742455","rc":[{"tv":745.52,"trd":[[48,62.44]],"atl":[[48,0.34]],"batl":[[2,60,7.75],[1,55,10.34],[0,50,5.86]],"id":98464183},{"batb":[],"atb":[[9.4,22.38]],"atl":[[14,4.64]],"batl":[],"id":97736949}],"tv":33467.31}],"rt":639159129883755965,"dt":639159129883756399}
{"op":"mcm","id":2,"clk":"AIgyAJscAOlE","pt":1780316188555,"mc":[{"id":"1.258742455","rc":[{"batb":[],"atb":[[9.2,17.8]],"id":98117699},{"tv":1885.58,"batb":[[0,10.5,41.53]],"trd":[[11.5,29.2]],"ltp":11.5,"atb":[[10.5,41.53]],"atl":[[11.5,11.26]],"batl":[[0,11.5,11.26]],"id":97736949}],"tv":33467.47}],"rt":639159129885635932,"dt":639159129885636341}
{"op":"mcm","id":2,"clk":"AI8yAKEcAPhE","pt":1780316188712,"mc":[{"id":"1.258742455","rc":[{"batb":[],"atb":[[3.95,4.39]],"id":99072898},{"tv":746.2,"trd":[[48,63.12]],"atl":[[48,0]],"batl":[[0,50,5.52]],"id":98464183},{"batb":[[0,10.5,43.52]],"atb":[[9.4,21.85],[10.5,43.52]],"id":97736949}],"tv":33468.15}],"rt":639159129887232840,"dt":639159129887233294}
{"op":"mcm","id":2,"clk":"AJUyAKIcAIJF","pt":1780316188813,"mc":[{"id":"1.258742455","rc":[{"batb":[[0,46,11.61]],"atb":[[48,0.75]],"id":98464183},{"batb":[],"atb":[[9.4,25.01],[9,8.41]],"atl":[[14.5,4.55]],"batl":[],"id":97736949}]}],"rt":639159129888207018,"dt":639159129888207616}
{"op":"mcm","id":2,"clk":"AJsyAKMcAI5F","pt":1780316188915,"mc":[{"id":"1.258742455","rc":[{"batb":[],"atb":[[21,12.44]],"id":99072900},{"batb":[],"atb":[[3.95,39.18]],"id":10398159},{"batb":[[0,46,11.72]],"atb":[[48,0.86]],"id":98464183}]}],"rt":639159129889232251,"dt":639159129889232617}
{"op":"mcm","id":2,"clk":"AKIyAKgcAJdF","pt":1780316189021,"mc":[{"id":"1.258742455","rc":[{"atb":[[1.17,2.17]],"id":97008932},{"atl":[[1000,6.3]],"batl":[],"id":99072901},{"atl":[[4.7,103.22]],"batl":[[0,4.7,103.22]],"id":10398159},{"atb":[[1.17,2.05]],"id":98464183},{"atl":[[10,6.3]],"batl":[[0,10,6.3]],"id":98117699},{"batb":[[0,3.6,4.03]],"atb":[[1.17,195.56],[3.6,4.03]],"atl":[[3.65,34.1]],"batl":[[0,3.65,34.1]],"id":88302242},{"atl":[[1000,8.8]],"batl":[],"id":99072897}]}],"rt":639159129890292859,"dt":639159129890293615}
{"op":"mcm","id":2,"clk":"AKcyAKocAJ9F","pt":1780316189123,"mc":[{"id":"1.258742455","rc":[{"batb":[],"atb":[[4,35.74]],"id":99072898},{"batb":[[2,38,12.03]],"atb":[[38,12.03]],"id":97008932},{"batb":[],"atb":[[20,4.22]],"id":99072900},{"tv":7607.46,"batb":[[0,4.6,41.65]],"trd":[[4.6,825.61]],"atb":[[3.9,4.27],[4.6,41.65]],"id":10398159},{"batb":[[2,9.2,14.28],[1,9.4,18.57],[0,9.6,11.51]],"atb":[[9.8,0],[9.2,14.28],[8.6,5.29]],"id":98117699},{"atb":[[3.05,297.07]],"id":88302242},{"batb":[[2,9.8,12.49]],"atb":[[9.4,21.85],[9.8,12.49]],"id":97736949}],"tv":33488.15}],"rt":639159129891309235,"dt":639159129891309905}
{"op":"mcm","id":2,"clk":"AKwyALAcAKpF","pt":1780316189226,"mc":[{"id":"1.258742455","rc":[{"atb":[[1.17,2]],"id":97008932},{"atl":[[1000,6.25]],"batl":[],"id":99072901},{"batb":[[0,4.6,19.03]],"atb":[[4.6,19.03]],"id":10398159},{"tv":746.23,"trd":[[50,61.7]],"ltp":50,"atb":[[1.17,2]],"atl":[[50,5.5]],"batl":[[0,50,5.5]],"id":98464183},{"atb":[[1.17,195.12]],"id":88302242},{"atl":[[1000,8.75]],"batl":[],"id":99072897}],"tv":33488.18}],"rt":639159129892343154,"dt":639159129892344046}
{"op":"mcm","id":2,"clk":"ALUyALgcALVF","pt":1780316189331,"mc":[{"id":"1.258742455","rc":[{"batb":[[0,4.7,26.51]],"atb":[[4.7,26.51]],"id":99072898},{"batb":[[0,42,12.23]],"atb":[[42,12.23],[36,3.15]],"id":97008932},{"atl":[[90,0.64]],"batl":[[0,95,4.58]],"id":99072901},{"batb":[[0,4.6,11.56]],"atb":[[4.6,11.56]],"atl":[[4.9,29.87]],"batl":[[2,4.9,29.87]],"id":10398159},{"batb":[[0,46,11.77]],"atb":[[30,11.48],[46,10.91]],"id":98464183},{"batb":[],"atb":[[8.4,6.04]],"id":98117699},{"tv":11570.37,"batb":[[2,3.45,29.92],[1,3.5,42.51],[0,3.55,62.32]],"trd":[[3.65,96.21],[3.6,210.5]],"ltp":3.6,"atb":[[3.1,4.55],[3.6,0]],"atl":[[3.65,33.66],[3.6,15.97]],"batl":[[2,3.7,5.84],[1,3.65,33.66],[0,3.6,15.97]],"id":88302242},{"batb":[],"atb":[[8.8,6.38]],"atl":[[15,4.56]],"batl":[],"id":97736949},{"atl":[[180,1.48]],"batl":[[0,180,1.48]],"id":99072897}],"tv":33497.12}],"rt":639159129893397580,"dt":639159129893398610}
{"op":"mcm","id":2,"clk":"ALsyALocAMNF","pt":1780316189430,"mc":[{"id":"1.258742455","rc":[{"batb":[[2,4.3,111.66],[1,4.4,147.64],[0,4.5,110.73]],"atb":[[4.6,0]],"atl":[[5.1,36.26]],"batl":[],"id":10398159},{"atl":[[3.6,18.59]],"batl":[[0,3.6,18.59]],"id":88302242},{"batb":[],"atb":[[9.4,25]],"id":97736949}]}],"rt":639159129894386901,"dt":639159129894387489}
{"op":"mcm","id":2,"clk":"AMAyAL4cAM1F","pt":1780316189539,"mc":[{"id":"1.258742455","rc":[{"atl":[[5.1,9.16]],"batl":[],"id":99072898},{"batb":[[2,9.2,17.79]],"atb":[[9.2,17.79]],"id":98117699}]}],"rt":639159129895474055,"dt":639159129895474501}
{"op":"mcm","id":2,"clk":"AMEyAMEcANxF","pt":1780316189636,"mc":[{"id":"1.258742455","rc":[{"atl":[[3.7,5.2]],"batl":[[2,3.7,5.2]],"id":88302242}]}],"rt":639159129896445624,"dt":639159129896446022}
{"op":"mcm","id":2,"clk":"AMUyAMQcAOJF","pt":1780316189738,"mc":[{"id":"1.258742455","rc":[{"atl":[[4.7,40.01],[4.8,80.84]],"batl":[[1,4.8,80.84],[0,4.7,40.01]],"id":10398159},{"batb":[[1,3.5,47.89]],"atb":[[3.5,47.89]],"id":88302242}]}],"rt":639159129897469207,"dt":639159129897470161}
{"op":"mcm","id":2,"clk":"AMsyAMYcAOpF","pt":1780316189843,"mc":[{"id":"1.258742455","rc":[{"atl":[[3.65,33.1]],"batl":[[1,3.65,33.1]],"id":88302242}]}],"rt":639159129898510067,"dt":639159129898510431}
{"op":"mcm","id":2,"clk":"AM8yAMkcAPJF","pt":1780316189948,"mc":[{"id":"1.258742455","rc":[{"batb":[],"atb":[[8.6,6.48]],"atl":[[17.5,4.2]],"id":97736949}]}],"rt":639159129899567023,"dt":639159129899567740}
{"op":"mcm","id":2,"clk":"AN4yANAcAIxG","pt":1780316190155,"mc":[{"id":"1.258742455","rc":[{"atl":[[3.65,13.1]],"batl":[[1,3.65,13.1]],"id":88302242}]}],"rt":639159129901632342,"dt":639159129901632719}
{"op":"mcm","id":2,"clk":"AN8yANUcAJNG","pt":1780316190254,"mc":[{"id":"1.258742455","rc":[{"atl":[[11.5,10.26]],"batl":[[0,11.5,10.26]],"id":97736949}]}],"rt":639159129902618496,"dt":639159129902618831}
{"op":"mcm","id":2,"clk":"AOIyANkcAJtG","pt":1780316190309,"mc":[{"id":"1.258742455","rc":[{"batb":[[2,9.2,14.28]],"atb":[[9.2,14.28]],"id":98117699},{"batb":[],"atb":[[9.4,21.85]],"atl":[[12,32.12]],"batl":[[1,12,32.12]],"id":97736949}]}],"rt":639159129903168797,"dt":639159129903169376}
{"op":"mcm","id":2,"clk":"AOcyAOMcAKdG","pt":1780316190417,"mc":[{"id":"1.258742455","rc":[{"atb":[[8,7]],"atl":[[17,5.65]],"id":97736949}]}],"rt":639159129904250991,"dt":639159129904251513}
{"op":"mcm","id":2,"clk":"AO4yAOscALdG","pt":1780316190635,"mc":[{"id":"1.258742455","rc":[{"atl":[[1000,1.65]],"id":97736949}]}],"rt":639159129906434243,"dt":639159129906434618}
{"op":"mcm","id":2,"clk":"APMyAO0cAMJG","pt":1780316190725,"mc":[{"id":"1.258742455","rc":[{"atl":[[5.1,32.79]],"batl":[],"id":10398159},{"batb":[[2,9.4,18.57],[1,9.6,11.51],[0,9.8,1.08]],"atb":[[9.8,1.08]],"id":98117699},{"atb":[[1.17,195.24]],"atl":[[3.7,9.17]],"batl":[[2,3.7,9.17]],"id":88302242}]}],"rt":639159129907333268,"dt":639159129907333661}
{"op":"mcm","id":2,"clk":"APcyAO8cAMtG","pt":1780316190826,"mc":[{"id":"1.258742455","rc":[{"atb":[[1.17,195.12]],"id":88302242},{"atl":[[1000,1]],"id":97736949}]}],"rt":639159129908342797,"dt":639159129908343390}
{"op":"mcm","id":2,"clk":"AIMzAPEcANVG","pt":1780316190934,"mc":[{"id":"1.258742455","rc":[{"batb":[[0,3.55,62.44]],"atb":[[3.55,62.44]],"id":88302242},{"atl":[[12,32.77]],"batl":[[1,12,32.77]],"id":97736949}]}],"rt":639159129909423438,"dt":639159129909423869}
{"op":"mcm","id":2,"clk":"AIMzAPMcANdG","pt":1780316191033,"mc":[{"id":"1.258742455","rc":[{"atl":[[50,1.99]],"id":97736949}]}],"rt":639159129910415846,"dt":639159129910416212}
{"op":"mcm","id":2,"clk":"AJozAP4cAOlG","pt":1780316191237,"mc":[{"id":"1.258742455","rc":[{"atl":[[75,15.44]],"batl":[],"id":97008932},{"atl":[[17,12.99]],"id":98117699},{"tv":189.1,"batb":[[0,1000,92.94]],"trd":[[1000,144.62]],"atb":[[1000,92.94]],"id":10445502},{"atl":[[280,11]],"batl":[],"id":99072897}],"tv":33519.12}],"rt":639159129912450957,"dt":639159129912451438}
{"op":"mcm","id":2,"clk":"AOAzAKYdAMFH","pt":1780316192214,"mc":[{"id":"1.258742455","rc":[{"batb":[],"atb":[[4.4,36.28]],"id":99072898}]}],"rt":639159129922228085,"dt":639159129922228512}
{"op":"mcm","id":2,"clk":"AOozAKwdANNH","pt":1780316192417,"mc":[{"id":"1.258742455","rc":[{"tv":7401.11,"trd":[[4.8,86.8]],"ltp":4.8,"atl":[[4.8,6.22]],"batl":[[0,4.8,6.22]],"id":99072898},{"atl":[[5.4,10.96]],"batl":[],"id":10398159},{"atl":[[18,5.35]],"id":97736949}],"tv":33539.12}],"rt":639159129924247871,"dt":639159129924248528}
{"op":"mcm","id":2,"clk":"APAzALAdANxH","pt":1780316192519,"mc":[{"id":"1.258742455","rc":[{"atl":[[4.8,4.7]],"batl":[[0,4.8,4.7]],"id":99072898}]}],"rt":639159129925268316,"dt":639159129925268664}
{"op":"mcm","id":2,"clk":"APYzALQdAOZH","pt":1780316192622,"mc":[{"id":"1.258742455","rc":[{"tv":7405.11,"trd":[[4.8,90.8]],"atl":[[4.8,2.7]],"batl":[[0,4.8,2.7]],"id":99072898}],"tv":33543.12}],"rt":639159129926308028,"dt":639159129926308786}
{"op":"mcm","id":2,"clk":"AP0zALodAP1H","pt":1780316192824,"mc":[{"id":"1.258742455","rc":[{"batb":[[0,46,9.46]],"atb":[[46,8.6]],"id":98464183},{"atl":[[3.9,5.47]],"batl":[],"id":88302242}]}],"rt":639159129928322877,"dt":639159129928323211}
{"op":"mcm","id":2,"clk":"AIc0AMMdAJNI","pt":1780316193035,"mc":[{"id":"1.258742455","rc":[{"atl":[[50,7.24]],"batl":[[0,50,7.24]],"id":98464183}]}],"rt":639159129930427749,"dt":639159129930428383}
{"op":"mcm","id":2,"clk":"AKo0AN4dAMtI","pt":1780316193650,"mc":[{"id":"1.258742455","rc":[{"tv":7609.46,"batb":[[0,4.5,109.73]],"trd":[[4.5,1667.15]],"ltp":4.5,"atb":[[4.5,109.73]],"id":10398159}],"tv":33545.12}],"rt":639159129936584180,"dt":639159129936584835}
{"op":"mcm","id":2,"clk":"ALU0AOUdANNI","pt":1780316193755,"mc":[{"id":"1.258742455","rc":[{"tv":2165.99,"trd":[[10,541.42]],"atl":[[10,6.1]],"batl":[[0,10,6.1]],"id":98117699}],"tv":33545.52}],"rt":639159129937630754,"dt":639159129937631206}
{"op":"mcm","id":2,"clk":"ALs0AO0dAN5I","pt":1780316193858,"mc":[{"id":"1.258742455","rc":[{"atl":[[4.8,0]],"batl":[[2,5.1,9.16],[1,5,24.21],[0,4.9,32.34]],"id":99072898},{"batb":[[1,23,12.09],[0,24,19.39]],"atb":[[24,19.39],[23,12.09]],"id":99072900},{"batb":[[0,3.55,62.32]],"atb":[[3.55,62.32]],"id":88302242},{"atl":[[18.5,4.32]],"id":97736949}]}],"rt":639159129938664260,"dt":639159129938665034}
{"op":"mcm","id":2,"clk":"AMg0APQdAPFI","pt":1780316194010,"mc":[{"id":"1.258742455","rc":[{"batb":[[0,4.7,37.07]],"atb":[[4.7,37.07]],"id":99072898}]}],"rt":639159129940193475,"dt":639159129940194160}
{"op":"mcm","id":2,"clk":"ANE0APkdAPZI","pt":1780316194114,"mc":[{"id":"1.258742455","rc":[{"batb":[],"atb":[[3.4,24.39]],"id":88302242}]}],"rt":639159129941223074,"dt":639159129941223491}
{"op":"mcm","id":2,"clk":"APc0AIseAJxJ","pt":1780316194526,"mc":[{"id":"1.258742455","rc":[{"atl":[[900,1]],"batl":[],"id":99072901}]}],"rt":639159129945343850,"dt":639159129945344181}
{"op":"mcm","id":2,"clk":"AM81ALEeAOxJ","pt":1780316195455,"mc":[{"id":"1.258742455","rc":[{"tv":2169.99,"trd":[[10,545.42]],"atl":[[10,4.1]],"batl":[[0,10,4.1]],"id":98117699}],"tv":33549.52}],"rt":639159129954627280,"dt":639159129954627679}
{"op":"mcm","id":2,"clk":"AN81ALceAP9J","pt":1780316195613,"mc":[{"id":"1.258742455","rc":[{"atl":[[5.5,8.5]],"batl":[],"id":10398159},{"atb":[[7.8,7.62]],"id":97736949}]}],"rt":639159129956211752,"dt":639159129956212118}
{"op":"mcm","id":2,"clk":"AP81AMkeAKpK","pt":1780316196022,"mc":[{"id":"1.258742455","rc":[{"tv":507.53,"batb":[[0,42,14.37]],"trd":[[46,47.22]],"ltp":46,"atb":[[42,14.37]],"atl":[[46,3.2]],"batl":[[0,46,3.2]],"id":97008932}],"tv":33553.22}],"rt":639159129960299178,"dt":639159129960299807}
{"op":"mcm","id":2,"clk":"AIQ2AM0eALFK","pt":1780316196125,"mc":[{"id":"1.258742455","rc":[{"batb":[[2,40,6.32],[1,42,14.37],[0,44,1.79]],"atb":[[44,1.79]],"atl":[[46,4.85]],"batl":[[0,46,4.85]],"id":97008932}]}],"rt":639159129961331998,"dt":639159129961332572}
{"op":"mcm","id":2,"clk":"AIs2ANQeALVK","pt":1780316196225,"mc":[{"id":"1.258742455","rc":[{"atl":[[25,5.62]],"batl":[[0,25,5.62]],"id":99072900}]}],"rt":639159129962346742,"dt":639159129962347092}
{"op":"mcm","id":2,"clk":"AJA2ANgeALxK","pt":1780316196326,"mc":[{"id":"1.258742455","rc":[{"batb":[[1,42,12.23],[0,44,3.69]],"atb":[[44,3.69],[42,12.23]],"id":97008932},{"atl":[[10,1.41]],"batl":[[0,10,1.41]],"id":98117699}]}],"rt":639159129963340071,"dt":639159129963340489}
{"op":"mcm","id":2,"clk":"AJk2ANweAMNK","pt":1780316196433,"mc":[{"id":"1.258742455","rc":[{"batb":[],"atb":[[9.2,17.78]],"id":98117699}]}],"rt":639159129964415251,"dt":639159129964415984}
{"op":"mcm","id":2,"clk":"AK02AOgeANJK","pt":1780316196653,"mc":[{"id":"1.258742455","rc":[{"atl":[[5.3,32.05]],"batl":[],"id":99072898}]}],"rt":639159129966614978,"dt":639159129966615513}
{"op":"mcm","id":2,"clk":"ALQ2APIeAN1K","pt":1780316196749,"mc":[{"id":"1.258742455","rc":[{"atl":[[25,2.26]],"batl":[[0,25,2.26]],"id":99072900},{"atl":[[1000,6.35]],"id":99072901},{"batb":[[0,4.5,111.97]],"atb":[[4.5,111.97]],"id":10398159}]}],"rt":639159129967578175,"dt":639159129967578577}
{"op":"mcm","id":2,"clk":"ALg2APceAOdK","pt":1780316196853,"mc":[{"id":"1.258742455","rc":[{"atl":[[1000,6.25]],"id":99072901},{"batb":[],"atb":[[3.95,48.48]],"id":10398159},{"atl":[[19,4.34]],"id":97736949}]}],"rt":639159129968612736,"dt":639159129968613240}
{"op":"mcm","id":2,"clk":"ALk2APweAO5K","pt":1780316196955,"mc":[{"id":"1.258742455","rc":[{"atl":[[95,4.04]],"batl":[[0,95,4.68]],"id":99072901}]}],"rt":639159129969630357,"dt":639159129969630710}
{"op":"mcm","id":2,"clk":"AMY2AI0fAPpK","pt":1780316197158,"mc":[{"id":"1.258742455","rc":[{"batb":[],"atb":[[3.95,26.19],[3.85,11.32]],"id":99072898},{"batb":[[0,3.55,37.1]],"atb":[[3.55,37.1],[3.4,51.19]],"id":88302242},{"batb":[],"atb":[[9.6,8.69]],"id":97736949}]}],"rt":639159129971664150,"dt":639159129971664517}
{"op":"mcm","id":2,"clk":"AMs2AJQfAIJL","pt":1780316197261,"mc":[{"id":"1.258742455","rc":[{"atl":[[4.9,17.16]],"batl":[[0,4.9,17.16]],"id":99072898}]}],"rt":639159129972693448,"dt":639159129972693770}
{"op":"mcm","id":2,"clk":"ANg2AJ0fAJZL","pt":1780316197417,"mc":[{"id":"1.258742455","rc":[{"batb":[],"atb":[[9.2,14.28]],"id":98117699},{"atl":[[3.95,3.41]],"batl":[],"id":88302242}]}],"rt":639159129974253919,"dt":639159129974254276}
{"op":"mcm","id":2,"clk":"AOI2AKkfAK5L","pt":1780316197622,"mc":[{"id":"1.258742455","rc":[{"batb":[[2,4.6,41.93],[1,4.7,37.07],[0,4.8,10]],"atb":[[4.8,10]],"id":99072898}]}],"rt":639159129976297560,"dt":639159129976298128}
{"op":"mcm","id":2,"clk":"AOs2AK4fALhL","pt":1780316197719,"mc":[{"id":"1.258742455","rc":[{"tv":7410.03,"batb":[[0,4.8,11]],"trd":[[4.8,95.72]],"atb":[[4.8,11]],"atl":[[5.2,27.06]],"batl":[],"id":99072898}],"tv":33558.14}],"rt":639159129977276226,"dt":639159129977276611}
{"op":"mcm","id":2,"clk":"API2ALUfAMVL","pt":1780316197829,"mc":[{"id":"1.258742455","rc":[{"batb":[[0,4.8,19.77]],"atb":[[4.8,19.77]],"atl":[[5,12.08]],"batl":[[1,5,12.08]],"id":99072898},{"atl":[[50,7.56]],"batl":[[0,50,7.56]],"id":98464183},{"batb":[],"atb":[[9.2,17.81]],"id":98117699}]}],"rt":639159129978376574,"dt":639159129978377017}
{"op":"mcm","id":2,"clk":"APY2ALkfANBL","pt":1780316197931,"mc":[{"id":"1.258742455","rc":[{"atl":[[5.2,30.43]],"batl":[],"id":99072898},{"atl":[[50,2.37]],"batl":[[0,50,2.37]],"id":98464183}]}],"rt":639159129979397039,"dt":639159129979397418}
{"op":"mcm","id":2,"clk":"AP02AL4fAN1L","pt":1780316198037,"mc":[{"id":"1.258742455","rc":[{"atl":[[3.6,21.25]],"batl":[[0,3.6,21.25]],"id":88302242},{"batb":[[2,9.8,27.79]],"atb":[[9.8,27.79]],"id":97736949}]}],"rt":639159129980453911,"dt":639159129980454275}
{"op":"mcm","id":2,"clk":"AIE3AMQfAORL","pt":1780316198135,"mc":[{"id":"1.258742455","rc":[{"batb":[[0,3.55,20.56]],"atb":[[3.55,20.56]],"atl":[[3.6,23.92]],"batl":[[0,3.6,23.92]],"id":88302242}]}],"rt":639159129981433401,"dt":639159129981433778}
{"op":"mcm","id":2,"clk":"AIc3AMgfAPBL","pt":1780316198242,"mc":[{"id":"1.258742455","rc":[{"batb":[[0,3.55,10.08]],"atb":[[3.55,10.08]],"id":88302242}]}],"rt":639159129982501076,"dt":639159129982501456}
{"op":"mcm","id":2,"clk":"AI43AM0fAPlL","pt":1780316198342,"mc":[{"id":"1.258742455","rc":[{"tv":746.43,"batb":[[0,46,9.36]],"trd":[[48,63.32]],"ltp":48,"atb":[[48,0.76]],"id":98464183},{"batb":[[0,10.5,44.26]],"atb":[[10.5,44.26]],"id":97736949}],"tv":33558.34}],"rt":639159129983498936,"dt":639159129983499775}
{"op":"mcm","id":2,"clk":"AJQ3ANIfAIVM","pt":1780316198446,"mc":[{"id":"1.258742455","rc":[{"atl":[[3.6,30.6]],"batl":[[0,3.6,30.6]],"id":88302242}]}],"rt":639159129984545616,"dt":639159129984545976}
{"op":"mcm","id":2,"clk":"AJs3ANgfAI9M","pt":1780316198549,"mc":[{"id":"1.258742455","rc":[{"atl":[[50,2.61]],"batl":[[0,50,2.61]],"id":98464183}]}],"rt":639159129985573410,"dt":639159129985573767}
{"op":"mcm","id":2,"clk":"AKE3ANofAJtM","pt":1780316198652,"mc":[{"id":"1.258742455","rc":[{"batb":[[0,46,9.48]],"atb":[[48,0.88]],"id":98464183},{"batb":[[0,3.55,5.92]],"atb":[[3.55,5.92]],"id":88302242}]}],"rt":639159129986602707,"dt":639159129986603047}
{"op":"mcm","id":2,"clk":"AKU3AOIfAKVM","pt":1780316198754,"mc":[{"id":"1.258742455","rc":[{"atl":[[5,14.86]],"batl":[[1,5,14.86]],"id":99072898},{"batb":[[1,3.5,46.28]],"atb":[[3.5,46.28]],"id":88302242}]}],"rt":639159129987618201,"dt":639159129987618796}
{"op":"mcm","id":2,"clk":"AKo3AOofALBM","pt":1780316198855,"mc":[{"id":"1.258742455","rc":[{"atb":[[6,6.8]],"id":98117699}]}],"rt":639159129988634428,"dt":639159129988634760}
{"op":"mcm","id":2,"clk":"ALE3APUfALpM","pt":1780316198959,"mc":[{"id":"1.258742455","rc":[{"atl":[[5.6,8.85]],"batl":[],"id":10398159},{"atl":[[50,2.59]],"batl":[[0,50,2.59]],"id":98464183}]}],"rt":639159129989675577,"dt":639159129989676000}
{"op":"mcm","id":2,"clk":"ALQ3AP0fAMZM","pt":1780316199016,"mc":[{"id":"1.258742455","rc":[{"atl":[[100,1.53]],"batl":[[1,100,1.53]],"id":99072901},{"atl":[[4.7,44.6]],"batl":[[0,4.7,44.6]],"id":10398159}]}],"rt":639159129990243010,"dt":639159129990243407}
{"op":"mcm","id":2,"clk":"ALc3AIQgAM9M","pt":1780316199116,"mc":[{"id":"1.258742455","rc":[{"tv":7610.83,"batb":[[0,4.5,111.28]],"trd":[[4.5,1668.52]],"atb":[[4.5,111.28]],"id":10398159}],"tv":33559.71}],"rt":639159129991244047,"dt":639159129991244708}
{"op":"mcm","id":2,"clk":"AOo3ALkgAIZN","pt":1780316199836,"mc":[{"id":"1.258742455","rc":[{"atl":[[3.7,5.2]],"batl":[[2,3.7,5.2]],"id":88302242}]}],"rt":639159129998442482,"dt":639159129998442824}
{"op":"mcm","id":2,"clk":"APY3AMMgAI5N","pt":1780316199941,"mc":[{"id":"1.258742455","rc":[{"batb":[[2,4.6,43.82],[1,4.7,37.68],[0,4.8,21.56]],"atb":[[4.7,37.68],[4.6,43.82],[4.8,21.56]],"id":99072898},{"batb":[[1,42,11.1],[0,44,4.46]],"atb":[[44,4.46],[42,11.1]],"id":97008932},{"atl":[[25,1.96]],"batl":[[0,25,1.96]],"id":99072900},{"atl":[[900,1.8],[95,3.94]],"batl":[[0,95,4.58]],"id":99072901},{"batb":[[0,4.5,121.96]],"atb":[[4.5,121.96]],"atl":[[4.8,83.11]],"batl":[[1,4.8,83.11]],"id":10398159},{"batb":[[0,10.5,45.74]],"atb":[[10.5,45.74]],"id":97736949}]}],"rt":639159129999488184,"dt":639159129999488801}
{"op":"mcm","id":2,"clk":"AP03AMYgAJRN","pt":1780316200043,"mc":[{"id":"1.258742455","rc":[{"batb":[[2,4.6,39.35]],"atb":[[4.6,39.35]],"id":99072898},{"batb":[],"atb":[[3.9,14.33]],"id":10398159},{"tv":11572.37,"trd":[[3.6,212.5]],"atl":[[3.6,29.6]],"batl":[[0,3.6,29.6]],"id":88302242},{"atl":[[19.5,5.11]],"id":97736949}],"tv":33561.71}],"rt":639159130000514599,"dt":639159130000515167}
{"op":"mcm","id":2,"clk":"AIM4AM4gAJxN","pt":1780316200145,"mc":[{"id":"1.258742455","rc":[{"atl":[[5.7,32.93],[5.6,6.03]],"batl":[],"id":99072898},{"batb":[[0,80,4.18]],"atb":[[80,4.18]],"id":99072901}]}],"rt":639159130001528619,"dt":639159130001529054}
{"op":"mcm","id":2,"clk":"AKI4ANwgAMdN","pt":1780316200659,"mc":[{"id":"1.258742455","rc":[{"tv":11627.92,"trd":[[3.6,268.05]],"atl":[[3.6,1.82]],"batl":[[0,3.6,1.82]],"id":88302242}],"tv":33617.26}],"rt":639159130006673397,"dt":639159130006673832}
{"op":"mcm","id":2,"clk":"AKs4AN8gAM9N","pt":1780316200759,"mc":[{"id":"1.258742455","rc":[{"batb":[],"atb":[[9.2,14.28]],"atl":[[10,3.79]],"batl":[[0,10,3.79]],"id":98117699},{"batb":[[0,3.55,16]],"atb":[[3.55,16]],"id":88302242}]}],"rt":639159130007674358,"dt":639159130007674752}
{"op":"mcm","id":2,"clk":"ALE4AOAgAN1N","pt":1780316200861,"mc":[{"id":"1.258742455","rc":[{"batb":[[0,4.8,12.79]],"atb":[[4.8,12.79]],"id":99072898},{"batb":[[1,75,9.39]],"atb":[[75,9.39]],"id":99072901},{"atl":[[10,5.65]],"batl":[[0,10,5.65]],"id":98117699},{"batb":[[0,3.55,25.64]],"atb":[[3.55,25.64]],"id":88302242}]}],"rt":639159130008694082,"dt":639159130008694620}
{"op":"mcm","id":2,"clk":"ALU4AOIgAORN","pt":1780316200915,"mc":[{"id":"1.258742455","rc":[{"batb":[[0,3.55,42.21]],"atb":[[3.55,42.21]],"id":88302242}]}],"rt":639159130009236113,"dt":639159130009236420}
{"op":"mcm","id":2,"clk":"ALo4AOggAOxN","pt":1780316201016,"mc":[{"id":"1.258742455","rc":[{"tv":11631.56,"batb":[[2,3.5,46.28],[1,3.55,42.21],[0,3.6,9.98]],"trd":[[3.6,271.69]],"atb":[[3.6,9.98]],"atl":[[3.6,0]],"batl":[[2,3.75,14.05],[1,3.7,5.2],[0,3.65,13.1]],"id":88302242}],"tv":33620.9}],"rt":639159130010243005,"dt":639159130010243749}
{"op":"mcm","id":2,"clk":"AL44AOsgAPhN","pt":1780316201133,"mc":[{"id":"1.258742455","rc":[{"batb":[[0,4.8,9.33]],"atb":[[4.8,9.33]],"id":99072898},{"batb":[[2,3.5,42.51]],"atb":[[3.5,42.51]],"id":88302242},{"batb":[],"atb":[[9.2,21.95],[9,11.6]],"id":97736949}]}],"rt":639159130011409152,"dt":639159130011409774}
{"op":"mcm","id":2,"clk":"ANQ4APYgAKJO","pt":1780316201536,"mc":[{"id":"1.258742455","rc":[{"tv":1904.74,"trd":[[11.5,48.36]],"atl":[[11.5,0.68]],"batl":[[2,13,11.23],[1,12.5,20.46],[0,12,33.45]],"id":97736949}],"tv":33640.06}],"rt":639159130015440684,"dt":639159130015441382}
{"op":"mcm","id":2,"clk":"ANg4APcgAK1O","pt":1780316201640,"mc":[{"id":"1.258742455","rc":[{"batb":[[2,10,45.8],[1,10.5,45.74],[0,11,12.1]],"atb":[[11,12.1],[9.2,25.13]],"atl":[[20,6.94]],"id":97736949}]}],"rt":639159130016479979,"dt":639159130016480394}
{"op":"mcm","id":2,"clk":"AOI4APsgALlO","pt":1780316201745,"mc":[{"id":"1.258742455","rc":[{"batb":[[2,70,5.77]],"atb":[[70,5.77]],"id":99072901},{"batb":[],"atb":[[8.8,8.77]],"id":98117699},{"batb":[],"atb":[[9.4,24.95]],"atl":[[11.5,0]],"batl":[[0,12,32.77]],"id":97736949}]}],"rt":639159130017534201,"dt":639159130017534838}
{"op":"mcm","id":2,"clk":"APE4AIkhAM5O","pt":1780316201952,"mc":[{"id":"1.258742455","rc":[{"tv":511.65,"trd":[[46,51.34]],"atl":[[46,2.79]],"batl":[[0,46,2.79]],"id":97008932},{"batb":[[1,10.5,42.19]],"atb":[[10.5,42.19]],"id":97736949}],"tv":33644.18}],"rt":639159130019596977,"dt":639159130019597492}
{"op":"mcm","id":2,"clk":"AIA5AJAhAORO","pt":1780316202154,"mc":[{"id":"1.258742455","rc":[{"batb":[],"atb":[[4.2,126],[3.95,4.39]],"atl":[[4.9,32.69]],"batl":[[0,4.9,32.69]],"id":99072898},{"batb":[],"atb":[[3.4,24.39],[3.35,122.26]],"id":88302242},{"batb":[],"atb":[[9.4,26.95],[9.6,6.69]],"id":97736949}]}],"rt":639159130021627217,"dt":639159130021628031}
{"op":"mcm","id":2,"clk":"AIo5AJEhAO9O","pt":1780316202254,"mc":[{"id":"1.258742455","rc":[{"batb":[[2,3.5,45.17]],"atb":[[3.5,45.17]],"id":88302242},{"atl":[[11.5,8.23]],"batl":[[2,12.5,20.46],[1,12,32.77],[0,11.5,8.23]],"id":97736949}]}],"rt":639159130022628189,"dt":639159130022628666}
{"op":"mcm","id":2,"clk":"AJI5AJghAPdO","pt":1780316202359,"mc":[{"id":"1.258742455","rc":[{"atl":[[5.7,9.09]],"id":10398159},{"batb":[[2,44,10.9],[1,46,8.6],[0,48,22.88]],"atb":[[48,22.88]],"id":98464183},{"atl":[[11.5,15.18]],"batl":[[0,11.5,15.18]],"id":97736949}]}],"rt":639159130023672714,"dt":639159130023673449}
{"op":"mcm","id":2,"clk":"AJ05AJshAIVP","pt":1780316202464,"mc":[{"id":"1.258742455","rc":[{"batb":[[0,48,26.77]],"atb":[[48,26.77]],"id":98464183},{"batb":[],"atb":[[9.4,23.85]],"id":97736949},{"batb":[[1,150,3.29]],"atb":[[150,3.29]],"id":99072897}]}],"rt":639159130024717853,"dt":639159130024718873}
{"op":"mcm","id":2,"clk":"AKU5AKAhAJFP","pt":1780316202517,"mc":[{"id":"1.258742455","rc":[{"batb":[[1,46,10.3]],"atb":[[46,10.3]],"atl":[[50,0.85]],"batl":[[2,65,24.28],[1,60,7.75],[0,55,11.19]],"id":98464183},{"batb":[[1,150,5.02]],"atb":[[150,5.02]],"id":99072897}]}],"rt":639159130025249710,"dt":639159130025250134}
{"op":"mcm","id":2,"clk":"ALc5AKchAJpP","pt":1780316202623,"mc":[{"id":"1.258742455","rc":[{"tv":748.13,"batb":[[2,46,10.3],[1,48,26.77],[0,50,2.96]],"trd":[[50,63.4]],"ltp":50,"atb":[[50,2.96]],"atl":[[55,6.18],[50,0]],"batl":[[0,55,6.18]],"id":98464183},{"batb":[],"atb":[[9,20.04]],"id":98117699}],"tv":33645.88}],"rt":639159130026312122,"dt":639159130026312623}
{"op":"mcm","id":2,"clk":"ALs5AKohAKBP","pt":1780316202723,"mc":[{"id":"1.258742455","rc":[{"tv":7419.03,"batb":[[0,4.8,4.83]],"trd":[[4.8,104.72]],"atb":[[4.8,4.83]],"id":99072898},{"batb":[[0,24,14.85]],"atb":[[24,14.85]],"id":99072900},{"batb":[[0,50,3.71]],"atb":[[50,3.71]],"id":98464183}],"tv":33654.88}],"rt":639159130027309707,"dt":639159130027310205}
{"op":"mcm","id":2,"clk":"AMU5ALEhAKZP","pt":1780316202824,"mc":[{"id":"1.258742455","rc":[{"tv":7428.69,"batb":[[2,4.5,44.51],[1,4.6,39.35],[0,4.7,37.68]],"trd":[[4.8,114.38]],"atb":[[4.8,0]],"atl":[[4.8,2.59]],"batl":[[2,5,14.86],[1,4.9,32.69],[0,4.8,2.59]],"id":99072898},{"batb":[[1,48,26.54]],"atb":[[48,26.54]],"id":98464183}],"tv":33664.54}],"rt":639159130028323522,"dt":639159130028324291}
{"op":"mcm","id":2,"clk":"AMo5ALohAK5P","pt":1780316202930,"mc":[{"id":"1.258742455","rc":[{"atl":[[4.9,38.7],[5,17.26],[4.8,5.86]],"batl":[[2,5,17.26],[1,4.9,38.7],[0,4.8,5.86]],"id":99072898},{"batb":[[1,48,26.85]],"atb":[[48,26.85]],"atl":[[55,6.6]],"batl":[[0,55,6.6]],"id":98464183},{"batb":[],"atb":[[9,23.6]],"id":98117699}]}],"rt":639159130029380226,"dt":639159130029380995}
{"op":"mcm","id":2,"clk":"ANI5AMEhALVP","pt":1780316203034,"mc":[{"id":"1.258742455","rc":[{"batb":[[0,4.7,27.12]],"atb":[[4.7,27.12]],"id":99072898},{"batb":[[0,24,19.42]],"atb":[[24,19.42]],"id":99072900},{"batb":[[1,48,28.51]],"atb":[[48,28.51]],"id":98464183},{"batb":[[1,3.55,44.28]],"atb":[[3.55,44.28]],"atl":[[3.65,14.4]],"batl":[[0,3.65,14.4]],"id":88302242}]}],"rt":639159130030423492,"dt":639159130030424233}
{"op":"mcm","id":2,"clk":"AOk5ANUhANVP","pt":1780316203345,"mc":[{"id":"1.258742455","rc":[{"tv":750.13,"batb":[[0,50,2.71]],"trd":[[50,65.4]],"atb":[[50,2.71]],"id":98464183}],"tv":33666.54}],"rt":639159130033533138,"dt":639159130033533559}
{"op":"mcm","id":2,"clk":"AO85ANwhAN1P","pt":1780316203452,"mc":[{"id":"1.258742455","rc":[{"batb":[[0,50,3.46]],"atb":[[50,3.46]],"id":98464183},{"batb":[[1,3.55,49.28]],"atb":[[3.55,49.28]],"atl":[[3.65,14.98]],"batl":[[0,3.65,14.98]],"id":88302242}]}],"rt":639159130034610625,"dt":639159130034611030}
{"op":"mcm","id":2,"clk":"APc5AOAhAOhP","pt":1780316203550,"mc":[{"id":"1.258742455","rc":[{"batb":[],"atb":[[65,2.84]],"id":99072901}]}],"rt":639159130035582654,"dt":639159130035583037}
{"op":"mcm","id":2,"clk":"APw5AOMhAPVP","pt":1780316203648,"mc":[{"id":"1.258742455","rc":[{"batb":[[0,4.5,131.96]],"atb":[[4.5,131.96]],"id":10398159}]}],"rt":639159130036568403,"dt":639159130036568740}
{"op":"mcm","id":2,"clk":"AIQ6AOchAP1P","pt":1780316203750,"mc":[{"id":"1.258742455","rc":[{"atl":[[5.3,26.83]],"batl":[],"id":99072898},{"tv":11679.52,"batb":[[2,3.45,29.92],[1,3.5,45.17],[0,3.55,49.28]],"trd":[[3.6,319.65]],"atb":[[3.6,0]],"atl":[[3.6,12.74]],"batl":[[2,3.7,5.2],[1,3.65,14.98],[0,3.6,12.74]],"id":88302242}],"tv":33714.5}],"rt":639159130037586099,"dt":639159130037586586}
{"op":"mcm","id":2,"clk":"AIc6AOwhAIhQ","pt":1780316203853,"mc":[{"id":"1.258742455","rc":[{"atl":[[5.1,12.58]],"batl":[],"id":99072898},{"atl":[[3.65,21.58],[3.6,19.35]],"batl":[[1,3.65,21.58],[0,3.6,19.35]],"id":88302242},{"batb":[],"atb":[[9.4,26.95]],"id":97736949}]}],"rt":639159130038613614,"dt":639159130038614277}
{"op":"mcm","id":2,"clk":"AJM6AP0hAKxQ","pt":1780316204159,"mc":[{"id":"1.258742455","rc":[{"batb":[],"atb":[[3.4,27.05]],"id":88302242}]}],"rt":639159130041673893,"dt":639159130041674664}
{"op":"mcm","id":2,"clk":"AKw6AJYiAM9Q","pt":1780316204531,"mc":[{"id":"1.258742455","rc":[{"batb":[[2,46,32.3]],"atb":[[46,32.3]],"id":98464183},{"batb":[[1,3.5,50.17]],"atb":[[3.5,50.17]],"id":88302242}]}],"rt":639159130045393698,"dt":639159130045394107}
{"op":"mcm","id":2,"clk":"ALs6AKQiAONQ","pt":1780316204727,"mc":[{"id":"1.258742455","rc":[{"batb":[],"atb":[[3.85,53.69]],"id":10398159},{"atl":[[3.65,21]],"batl":[[1,3.65,21]],"id":88302242}]}],"rt":639159130047354022,"dt":639159130047354473}
{"op":"mcm","id":2,"clk":"ANM6ALIiAPxQ","pt":1780316205032,"mc":[{"id":"1.258742455","rc":[{"batb":[[1,3.5,55.17]],"atb":[[3.5,55.17]],"id":88302242}]}],"rt":639159130050405411,"dt":639159130050405771}
{"op":"mcm","id":2,"clk":"AOA6ALoiAIdR","pt":1780316205237,"mc":[{"id":"1.258742455","rc":[{"atl":[[900,0]],"batl":[],"id":99072901}]}],"rt":639159130052448543,"dt":639159130052448882}
{"op":"mcm","id":2,"clk":"AOc6AMAiAI9R","pt":1780316205340,"mc":[{"id":"1.258742455","rc":[{"atl":[[90,1.44]],"batl":[[2,100,1.53],[1,95,3.94],[0,90,1.44]],"id":99072901}]}],"rt":639159130053482699,"dt":639159130053483270}
{"op":"mcm","id":2,"clk":"AO86AMQiAJhR","pt":1780316205444,"mc":[{"id":"1.258742455","rc":[{"tv":11683.52,"batb":[[0,3.55,47.28]],"trd":[[3.55,282.65]],"ltp":3.55,"atb":[[3.55,47.28]],"id":88302242}],"tv":33718.5}],"rt":639159130054519795,"dt":639159130054520168}
{"op":"mcm","id":2,"clk":"AP86ANAiAKxR","pt":1780316205651,"mc":[{"id":"1.258742455","rc":[{"batb":[],"atb":[[3.3,8.99]],"id":88302242}]}],"rt":639159130056593273,"dt":639159130056593633}
{"op":"mcm","id":2,"clk":"AIQ7ANMiALFR","pt":1780316205748,"mc":[{"id":"1.258742455","rc":[{"batb":[[1,10.5,43.19]],"atb":[[10.5,43.19]],"id":97736949}]}],"rt":639159130057564954,"dt":639159130057565284}
{"op":"mcm","id":2,"clk":"AIw7ANYiALlR","pt":1780316205853,"mc":[{"id":"1.258742455","rc":[{"batb":[],"atb":[[60,16.05]],"id":99072901},{"batb":[[1,10.5,36.83]],"atb":[[10.5,36.83]],"id":97736949},{"atl":[[180,0.52]],"batl":[[2,220,1.13],[1,210,1.77],[0,190,3.17]],"id":99072897}]}],"rt":639159130058609789,"dt":639159130058610356}
{"op":"mcm","id":2,"clk":"AJc7AN0iAMBR","pt":1780316205953,"mc":[{"id":"1.258742455","rc":[{"batb":[[1,150,3.29]],"atb":[[150,3.29]],"id":99072897}]}],"rt":639159130059620290,"dt":639159130059620672}
{"op":"mcm","id":2,"clk":"AK87AO0iANtR","pt":1780316206216,"mc":[{"id":"1.258742455","rc":[{"tv":757.05,"batb":[[2,44,10.9],[1,46,32.3],[0,48,28.51]],"trd":[[50,72.32]],"atb":[[50,0]],"atl":[[50,2.54]],"batl":[[2,60,7.75],[1,55,6.6],[0,50,2.54]],"id":98464183}],"tv":33725.42}],"rt":639159130062242954,"dt":639159130062243366}
{"op":"mcm","id":2,"clk":"ALg7APciAONR","pt":1780316206367,"mc":[{"id":"1.258742455","rc":[{"batb":[[1,4.6,41.54],[0,4.7,24.62]],"atb":[[4.7,24.62],[4.6,41.54]],"atl":[[4.9,32.69],[5,14.86],[4.8,7.91]],"batl":[[2,5,14.86],[1,4.9,32.69],[0,4.8,7.91]],"id":99072898},{"atl":[[1000,0.39]],"id":97008932},{"batb":[[0,4.5,120.29]],"atb":[[4.5,120.29]],"atl":[[4.6,25],[4.8,83.05]],"batl":[[2,4.8,83.05],[1,4.7,44.6],[0,4.6,25]],"id":10398159},{"batb":[[0,48,26.54]],"atb":[[48,26.54]],"atl":[[55,6.18]],"batl":[[1,55,6.18]],"id":98464183},{"batb":[[0,3.55,45.21]],"atb":[[3.55,45.21]],"atl":[[3.65,19.7]],"batl":[[1,3.65,19.7]],"id":88302242},{"batb":[[1,10.5,31.5],[0,11,15.49]],"atb":[[11,15.49],[10.5,31.5]],"atl":[[1000,1.51]],"id":97736949}]}],"rt":639159130063758749,"dt":639159130063759866}
{"op":"mcm","id":2,"clk":"AL87APoiAO1R","pt":1780316206430,"mc":[{"id":"1.258742455","rc":[{"batb":[[0,4.7,26.21]],"atb":[[4.7,26.21]],"id":99072898},{"atl":[[1000,0.22]],"id":97008932},{"atl":[[4.8,80.78]],"batl":[[2,4.8,80.78]],"id":10398159},{"atl":[[1000,1]],"id":97736949}]}],"rt":639159130064386063,"dt":639159130064386463}
{"op":"mcm","id":2,"clk":"AMU7AIIjAPRR","pt":1780316206531,"mc":[{"id":"1.258742455","rc":[{"batb":[[0,4.7,36.78]],"atb":[[4.7,36.78]],"id":99072898},{"atl":[[46,2.96]],"batl":[[0,46,2.96]],"id":97008932},{"atl":[[11.5,15.69]],"batl":[[0,11.5,15.69]],"id":97736949}]}],"rt":639159130065394913,"dt":639159130065395775}
{"op":"mcm","id":2,"clk":"ANc7AJAjAIlS","pt":1780316206748,"mc":[{"id":"1.258742455","rc":[{"tv":7463.29,"batb":[[0,4.7,19.49]],"trd":[[4.7,74.98]],"ltp":4.7,"atb":[[4.7,19.49]],"id":99072898}],"tv":33760.02}],"rt":639159130067563525,"dt":639159130067563913}
{"op":"mcm","id":2,"clk":"AOE7AJMjAJJS","pt":1780316206843,"mc":[{"id":"1.258742455","rc":[{"atl":[[4.9,36.09],[5,17.26]],"batl":[[2,5,17.26],[1,4.9,36.09]],"id":99072898},{"batb":[],"atb":[[9.2,17.81]],"id":98117699}]}],"rt":639159130068518875,"dt":639159130068519509}
{"op":"mcm","id":2,"clk":"AOo7AJ4jAKFS","pt":1780316206957,"mc":[{"id":"1.258742455","rc":[{"batb":[[0,4.7,26.73]],"atb":[[4.7,26.73]],"id":99072898}]}],"rt":639159130069653262,"dt":639159130069653672}
{"op":"mcm","id":2,"clk":"API7AKMjAKtS","pt":1780316207050,"mc":[{"id":"1.258742455","rc":[{"tv":2171.99,"batb":[[2,9.2,17.81],[1,9.4,18.57],[0,9.6,11.59]],"trd":[[9.8,209]],"ltp":9.8,"atb":[[9.8,0.08]],"id":98117699},{"atl":[[3.6,19.87]],"batl":[[0,3.6,19.87]],"id":88302242}],"tv":33762.02}],"rt":639159130070587528,"dt":639159130070588084}
{"op":"mcm","id":2,"clk":"AP47AKgjALlS","pt":1780316207154,"mc":[{"id":"1.258742455","rc":[{"batb":[[0,4.7,28.24]],"atb":[[4.7,28.24]],"id":99072898},{"batb":[[0,44,4.79]],"atb":[[44,4.79]],"id":97008932},{"batb":[[0,24,20.03]],"atb":[[24,20.03]],"id":99072900},{"batb":[[0,80,4.36]],"atb":[[80,4.36]],"id":99072901},{"batb":[[0,4.5,121.86]],"atb":[[4.5,121.86]],"id":10398159},{"batb":[[0,48,26.84]],"atb":[[48,26.84]],"id":98464183},{"batb":[[2,9.4,18.57],[1,9.6,9.47],[0,9.8,1.57]],"atb":[[9.8,1.57],[9.6,9.47]],"id":98117699},{"batb":[[0,3.55,47.21]],"atb":[[3.55,47.21]],"atl":[[3.6,13.26]],"batl":[[0,3.6,13.26]],"id":88302242},{"batb":[[0,11,16.81]],"atb":[[11,16.81]],"id":97736949},{"batb":[[0,160,3.72]],"atb":[[160,3.72]],"id":99072897}]}],"rt":639159130071624847,"dt":639159130071625471}
{"op":"mcm","id":2,"clk":"AK48AMYjAPpS","pt":1780316207771,"mc":[{"id":"1.258742455","rc":[{"tv":2173.99,"batb":[[2,9.2,17.81],[1,9.4,18.57],[0,9.6,10.04]],"trd":[[9.8,211]],"atb":[[9.8,0.57]],"id":98117699}],"tv":33764.02}],"rt":639159130077796507,"dt":639159130077796915}
{"op":"mcm","id":2,"clk":"AL08AM0jAJBT","pt":1780316207929,"mc":[{"id":"1.258742455","rc":[{"atl":[[25,1.4]],"batl":[[0,25,1.4]],"id":99072900}]}],"rt":639159130079370524,"dt":639159130079370876}
{"op":"mcm","id":2,"clk":"AM08ANkjAKRT","pt":1780316208127,"mc":[{"id":"1.258742455","rc":[{"atl":[[50,0]],"batl":[[2,65,24.28],[1,60,7.75],[0,55,6.18]],"id":98464183}]}],"rt":639159130081355862,"dt":639159130081356410}
{"op":"mcm","id":2,"clk":"ANo8ANsjALBT","pt":1780316208244,"mc":[{"id":"1.258742455","rc":[{"batb":[[2,46,32.3],[1,48,26.84],[0,50,3.63]],"atb":[[50,3.63]],"id":98464183},{"batb":[[2,9.2,14.28]],"atb":[[9.2,14.28]],"id":98117699}]}],"rt":639159130082518144,"dt":639159130082518749}
{"op":"mcm","id":2,"clk":"AN48AN4jALpT","pt":1780316208331,"mc":[{"id":"1.258742455","rc":[{"batb":[[1,48,28.49]],"atb":[[48,28.49]],"id":98464183}]}],"rt":639159130083389873,"dt":639159130083390232}
{"op":"mcm","id":2,"clk":"AOc8AOgjAMFT","pt":1780316208445,"mc":[{"id":"1.258742455","rc":[{"batb":[[2,9.2,17.82]],"atb":[[9.2,17.82]],"id":98117699}]}],"rt":639159130084529355,"dt":639159130084529696}
{"op":"mcm","id":2,"clk":"AJ89AJUkAINU","pt":1780316209151,"mc":[{"id":"1.258742455","rc":[{"atl":[[12,31.77]],"batl":[[1,12,31.77]],"id":97736949}]}],"rt":639159130091595531,"dt":639159130091596095}
{"op":"mcm","id":2,"clk":"AKk9AKAkAJ1U","pt":1780316209361,"mc":[{"id":"1.258742455","rc":[{"atb":[[1.17,2.13]],"atl":[[25,2.03]],"batl":[[0,25,2.03]],"id":99072900},{"atl":[[1000,6.35]],"id":99072901}]}],"rt":639159130093688581,"dt":639159130093689334}
{"op":"mcm","id":2,"clk":"ALI9AKUkAKhU","pt":1780316209461,"mc":[{"id":"1.258742455","rc":[{"atb":[[1.17,2]],"id":99072900},{"atl":[[1000,6.25]],"id":99072901}]}],"rt":639159130094691710,"dt":639159130094692065}
{"op":"mcm","id":2,"clk":"ALg9AKkkALRU","pt":1780316209565,"mc":[{"id":"1.258742455","rc":[{"batb":[[1,23,12.22]],"atb":[[23,12.22]],"id":99072900},{"atl":[[95,4.04]],"batl":[[1,95,4.04]],"id":99072901}]}],"rt":639159130095730706,"dt":639159130095731054}
{"op":"mcm","id":2,"clk":"AMg9ALEkAMZU","pt":1780316209722,"mc":[{"id":"1.258742455","rc":[{"batb":[[2,3.45,34.92]],"atb":[[3.45,34.92]],"id":88302242}]}],"rt":639159130097308074,"dt":639159130097308695}
{"op":"mcm","id":2,"clk":"AM49ALMkANBU","pt":1780316209823,"mc":[{"id":"1.258742455","rc":[{"batb":[],"atb":[[55,4.13]],"id":99072901}]}],"rt":639159130098312108,"dt":639159130098312706}
{"op":"mcm","id":2,"clk":"API9AMgkAP9U","pt":1780316210232,"mc":[{"id":"1.258742455","rc":[{"atb":[[1.17,2.15]],"id":97008932},{"atb":[[1.17,2.05]],"id":10398159},{"atb":[[1.17,2.17]],"id":98464183},{"atl":[[10,4.96]],"batl":[[0,10,4.96]],"id":98117699},{"tv":11692.5,"trd":[[3.6,328.63]],"ltp":3.6,"atl":[[3.6,8.77]],"batl":[[0,3.6,8.77]],"id":88302242}],"tv":33773}],"rt":639159130102403589,"dt":639159130102404031}
{"op":"mcm","id":2,"clk":"APs9AMskAIlV","pt":1780316210337,"mc":[{"id":"1.258742455","rc":[{"atb":[[1.17,2]],"id":97008932},{"tv":896.77,"batb":[[0,24,19.59]],"trd":[[24,91.17]],"atb":[[24,19.59]],"atl":[[1000,6.63],[25,4.47]],"batl":[[0,25,4.47]],"id":99072900},{"batb":[[0,80,4.57]],"atb":[[80,4.57]],"id":99072901},{"atb":[[1.17,2]],"id":10398159},{"atb":[[1.17,2]],"id":98464183},{"atl":[[4.1,7]],"batl":[],"id":88302242},{"batb":[],"atb":[[9.6,9.77]],"id":97736949}],"tv":33773.88}],"rt":639159130103453110,"dt":639159130103453538}
{"op":"mcm","id":2,"clk":"AII\u002BAM4kAJJV","pt":1780316210440,"mc":[{"id":"1.258742455","rc":[{"batb":[[0,44,4.94]],"atb":[[44,4.94]],"id":97008932},{"atl":[[1000,6.25]],"id":99072900},{"batb":[],"atb":[[50,21.68]],"id":99072901},{"tv":7610.93,"trd":[[4.6,825.71]],"ltp":4.6,"atl":[[4.6,24.95]],"batl":[[0,4.6,24.95]],"id":10398159},{"batb":[[0,50,3.8]],"atb":[[50,3.8]],"id":98464183},{"tv":11729.94,"trd":[[3.6,366.07]],"atl":[[3.6,35.42]],"batl":[[0,3.6,35.42]],"id":88302242}],"tv":33811.42}],"rt":639159130104489359,"dt":639159130104489866}
{"op":"mcm","id":2,"clk":"AIo\u002BANIkAJ1V","pt":1780316210543,"mc":[{"id":"1.258742455","rc":[{"atl":[[25,4.85]],"batl":[[0,25,4.85]],"id":99072900},{"tv":11768.24,"trd":[[3.6,404.37]],"atl":[[3.6,16.27]],"batl":[[0,3.6,16.27]],"id":88302242}],"tv":33849.72}],"rt":639159130105516261,"dt":639159130105516661}
{"op":"mcm","id":2,"clk":"AJA\u002BANckAKVV","pt":1780316210653,"mc":[{"id":"1.258742455","rc":[{"atl":[[3.6,26.08]],"batl":[[0,3.6,26.08]],"id":88302242}]}],"rt":639159130106616138,"dt":639159130106616495}
{"op":"mcm","id":2,"clk":"AKE\u002BAOkkAMVV","pt":1780316210954,"mc":[{"id":"1.258742455","rc":[{"atl":[[3.6,16.27]],"batl":[[0,3.6,16.27]],"id":88302242}]}],"rt":639159130109626799,"dt":639159130109627295}
{"op":"mcm","id":2,"clk":"ANg\u002BAJQlAJhW","pt":1780316211727,"mc":[{"id":"1.258742455","rc":[{"tv":7616.93,"trd":[[4.6,831.71]],"atl":[[4.6,21.95]],"batl":[[0,4.6,21.95]],"id":10398159}],"tv":33855.72}],"rt":639159130117354436,"dt":639159130117354886}
{"op":"mcm","id":2,"clk":"AOk\u002BAKUlAKtW","pt":1780316211935,"mc":[{"id":"1.258742455","rc":[{"tv":765.05,"batb":[[2,44,10.9],[1,46,32.3],[0,48,28.29]],"trd":[[50,79.92],[48,63.72]],"ltp":48,"atb":[[50,0],[48,28.29]],"id":98464183}],"tv":33863.72}],"rt":639159130119434849,"dt":639159130119435270}
{"op":"mcm","id":2,"clk":"AO0\u002BALAlALJW","pt":1780316212035,"mc":[{"id":"1.258742455","rc":[{"batb":[[2,46,32.3],[1,48,29.73],[0,50,3.55]],"atb":[[50,3.55],[48,29.73]],"id":98464183}]}],"rt":639159130120431285,"dt":639159130120431697}
{"op":"mcm","id":2,"clk":"AP0\u002BAMAlAMNW","pt":1780316212247,"mc":[{"id":"1.258742455","rc":[{"atl":[[5.2,27.06],[5.3,23.35]],"batl":[],"id":99072898},{"batb":[[1,23,12.09]],"atb":[[23,12.09]],"id":99072900},{"batb":[[0,80,4.1]],"atb":[[80,4.1]],"atl":[[95,3.94]],"batl":[[1,95,3.94]],"id":99072901},{"batb":[[0,4.5,120.61]],"atb":[[4.5,120.61]],"atl":[[4.8,80.52]],"batl":[[2,4.8,80.52]],"id":10398159},{"batb":[],"atb":[[9,8.41]],"id":97736949}]}],"rt":639159130122556852,"dt":639159130122557272}
{"op":"mcm","id":2,"clk":"AIo/ANIlANZW","pt":1780316212449,"mc":[{"id":"1.258742455","rc":[{"batb":[],"atb":[[4,34.49]],"id":99072898},{"batb":[],"atb":[[44,3.3]],"id":99072901},{"tv":11772.32,"batb":[[0,3.55,45.17]],"trd":[[3.55,286.73]],"ltp":3.55,"atb":[[3.55,45.17]],"id":88302242},{"batb":[],"atb":[[9.8,27.28]],"id":97736949}],"tv":33867.8}],"rt":639159130124572341,"dt":639159130124573041}
{"op":"mcm","id":2,"clk":"AI4/ANglAN5W","pt":1780316212550,"mc":[{"id":"1.258742455","rc":[{"batb":[],"atb":[[20,3.97]],"id":99072900},{"batb":[],"atb":[[3.9,13.05]],"id":10398159},{"atl":[[3.6,26.04]],"batl":[[0,3.6,26.04]],"id":88302242}]}],"rt":639159130125577939,"dt":639159130125578475}
{"op":"mcm","id":2,"clk":"AJQ/AN8lAOlW","pt":1780316212658,"mc":[{"id":"1.258742455","rc":[{"batb":[],"atb":[[4,35.74]],"id":99072898},{"batb":[],"atb":[[36,3.01]],"id":97008932},{"batb":[],"atb":[[3.85,54.99]],"id":10398159},{"batb":[],"atb":[[8.4,5.44]],"id":98117699},{"batb":[],"atb":[[3.1,2.94]],"id":88302242},{"batb":[],"atb":[[9.8,27.79]],"id":97736949}]}],"rt":639159130126660568,"dt":639159130126661122}
{"op":"mcm","id":2,"clk":"AJo/AOolAPJW","pt":1780316212762,"mc":[{"id":"1.258742455","rc":[{"batb":[],"atb":[[21,12.68]],"id":99072900}]}],"rt":639159130127703579,"dt":639159130127703925}
{"op":"mcm","id":2,"clk":"AJ4/AOwlAP5W","pt":1780316212863,"mc":[{"id":"1.258742455","rc":[{"batb":[[2,40,6.44]],"atb":[[40,6.44]],"id":97008932},{"batb":[],"atb":[[8.4,6.04]],"id":98117699},{"atb":[[3.05,298.71]],"id":88302242}]}],"rt":639159130128709193,"dt":639159130128709570}
{"op":"mcm","id":2,"clk":"APg/ALImAPlX","pt":1780316214152,"mc":[{"id":"1.258742455","rc":[{"tv":11792.04,"trd":[[3.6,424.09]],"ltp":3.6,"atl":[[3.6,16.18]],"batl":[[0,3.6,16.18]],"id":88302242}],"tv":33887.52}],"rt":639159130141598538,"dt":639159130141599085}
{"op":"mcm","id":2,"clk":"AP4/ALgmAP9X","pt":1780316214251,"mc":[{"id":"1.258742455","rc":[{"batb":[[0,4.7,29.69]],"atb":[[4.7,29.69]],"id":99072898},{"batb":[],"atb":[[48,3.2]],"id":99072901},{"batb":[[0,4.5,122.13]],"atb":[[4.5,122.13]],"id":10398159},{"batb":[[0,3.55,47.09]],"atb":[[3.55,47.09]],"atl":[[3.6,6.41]],"batl":[[0,3.6,6.41]],"id":88302242},{"batb":[[0,1000,92.95]],"atb":[[1000,92.95]],"id":10445502}]}],"rt":639159130142598549,"dt":639159130142598980}
{"op":"mcm","id":2,"clk":"AKFAAM8mAKFY","pt":1780316214661,"mc":[{"id":"1.258742455","rc":[{"tv":773.05,"batb":[[2,44,10.9],[1,46,32.3],[0,48,29.28]],"trd":[[50,87.02],[48,64.62]],"atb":[[50,0],[48,29.28]],"id":98464183}],"tv":33895.52}],"rt":639159130146692962,"dt":639159130146693410}
{"op":"mcm","id":2,"clk":"AKZAANImAKxY","pt":1780316214760,"mc":[{"id":"1.258742455","rc":[{"batb":[],"atb":[[55,3.02],[50,19.13]],"id":99072901},{"atl":[[55,7.56]],"batl":[[0,55,7.56]],"id":98464183}]}],"rt":639159130147683736,"dt":639159130147684343}
{"op":"mcm","id":2,"clk":"AKtAANsmALVY","pt":1780316214866,"mc":[{"id":"1.258742455","rc":[{"batb":[],"atb":[[46,3.26]],"id":99072901}]}],"rt":639159130148747071,"dt":639159130148747454}
{"op":"mcm","id":2,"clk":"AMVAAOsmANRY","pt":1780316215226,"mc":[{"id":"1.258742455","rc":[{"atb":[[1.17,2.2]],"id":98117699},{"atb":[[1.17,195.27]],"id":88302242}]}],"rt":639159130152340537,"dt":639159130152340958}
{"op":"mcm","id":2,"clk":"ANJAAPQmAOZY","pt":1780316215436,"mc":[{"id":"1.258742455","rc":[{"atb":[[1.17,2]],"id":98117699},{"atb":[[1.17,195.12]],"id":88302242}]}],"rt":639159130154439831,"dt":639159130154440244}
{"op":"mcm","id":2,"clk":"ANlAAPsmAO5Y","pt":1780316215535,"mc":[{"id":"1.258742455","rc":[{"batb":[[0,9.6,10.24]],"atb":[[9.8,0.77]],"id":98117699},{"batb":[[0,3.55,47.24]],"atb":[[3.55,47.24]],"id":88302242}]}],"rt":639159130155437599,"dt":639159130155438021}
{"op":"mcm","id":2,"clk":"AOdAAIonAIRZ","pt":1780316215746,"mc":[{"id":"1.258742455","rc":[{"tv":7475.29,"trd":[[4.8,126.38]],"ltp":4.8,"atl":[[4.8,1.91]],"batl":[[0,4.8,1.91]],"id":99072898},{"batb":[[2,46,32.3],[1,48,29.28],[0,50,3.32]],"atb":[[50,3.32]],"id":98464183}],"tv":33907.52}],"rt":639159130157538698,"dt":639159130157539555}
{"op":"mcm","id":2,"clk":"APBAAJUnAJlZ","pt":1780316215943,"mc":[{"id":"1.258742455","rc":[{"tv":11806.3,"batb":[[0,3.55,40.11]],"trd":[[3.55,300.99]],"ltp":3.55,"atb":[[3.55,40.11]],"id":88302242}],"tv":33921.78}],"rt":639159130159515067,"dt":639159130159515435}
{"op":"mcm","id":2,"clk":"APlAAJwnAKJZ","pt":1780316216047,"mc":[{"id":"1.258742455","rc":[{"atl":[[3.6,16.44]],"batl":[[0,3.6,16.44]],"id":88302242}]}],"rt":639159130160551958,"dt":639159130160552293}
{"op":"mcm","id":2,"clk":"AP5AAKcnAKtZ","pt":1780316216149,"mc":[{"id":"1.258742455","rc":[{"tv":1906.74,"batb":[[0,11,15.81]],"trd":[[11,50.6]],"ltp":11,"atb":[[11,15.81]],"id":97736949}],"tv":33923.78}],"rt":639159130161578311,"dt":639159130161578922}
{"op":"mcm","id":2,"clk":"AL9BAMcnAPlZ","pt":1780316216972,"mc":[{"id":"1.258742455","rc":[{"atl":[[80,0]],"id":98117699},{"atl":[[160,2]],"id":97736949}]}],"rt":639159130169808534,"dt":639159130169808921}
{"op":"mcm","id":2,"clk":"AMVBAM8nAIRa","pt":1780316217077,"mc":[{"id":"1.258742455","rc":[{"atl":[[18,0]],"id":99072898},{"batb":[[1,4.4,157.64]],"atb":[[4.4,157.64]],"atl":[[18,0]],"id":10398159},{"tv":779.69,"batb":[[2,44,10.9],[1,46,32.3],[0,48,28.6]],"trd":[[50,93.66]],"ltp":50,"atb":[[50,0],[48,28.6]],"id":98464183},{"atl":[[13.5,2.09]],"id":88302242},{"atl":[[12,32.77]],"batl":[[1,12,32.77]],"id":97736949}],"tv":33930.42}],"rt":639159130170860984,"dt":639159130170861471}
{"op":"mcm","id":2,"clk":"ANBBANonAJJa","pt":1780316217236,"mc":[{"id":"1.258742455","rc":[{"batb":[[2,46,32.3],[1,48,28.6],[0,50,4.03]],"atb":[[50,4.03]],"id":98464183}]}],"rt":639159130172443323,"dt":639159130172443927}
{"op":"mcm","id":2,"clk":"APNBAPAnALta","pt":1780316217647,"mc":[{"id":"1.258742455","rc":[{"tv":11810.3,"trd":[[3.6,428.09]],"ltp":3.6,"atl":[[3.6,14.44]],"batl":[[0,3.6,14.44]],"id":88302242}],"tv":33934.42}],"rt":639159130176554442,"dt":639159130176554850}
{"op":"mcm","id":2,"clk":"APlBAPMnAMNa","pt":1780316217746,"mc":[{"id":"1.258742455","rc":[{"atl":[[3.6,4.41]],"batl":[[0,3.6,4.41]],"id":88302242}]}],"rt":639159130177538798,"dt":639159130177539269}
{"op":"mcm","id":2,"clk":"AP5BAPcnAM5a","pt":1780316217850,"mc":[{"id":"1.258742455","rc":[{"atl":[[4.8,0.53]],"batl":[[2,5.1,12.58],[1,5,17.26],[0,4.9,36.62]],"id":99072898},{"atl":[[25,4.22]],"batl":[[0,25,4.22]],"id":99072900}]}],"rt":639159130178578851,"dt":639159130178579262}
{"op":"mcm","id":2,"clk":"AJtCAIsoAO5a","pt":1780316218257,"mc":[{"id":"1.258742455","rc":[{"atl":[[5,22.17]],"batl":[[1,5,22.17]],"id":99072898}]}],"rt":639159130182650927,"dt":639159130182651507}
{"op":"mcm","id":2,"clk":"APRCAMYoAMtb","pt":1780316219444,"mc":[{"id":"1.258742455","rc":[{"tv":787.75,"batb":[[2,44,10.9],[1,46,32.3],[0,48,27.63]],"trd":[[50,101.72]],"atb":[[50,0],[48,27.63]],"id":98464183}],"tv":33942.48}],"rt":639159130194523640,"dt":639159130194524078}
{"op":"mcm","id":2,"clk":"APhCAMkoANhb","pt":1780316219545,"mc":[{"id":"1.258742455","rc":[{"batb":[[2,46,32.3],[1,48,27.63],[0,50,1.44]],"atb":[[50,1.44]],"id":98464183}]}],"rt":639159130195535886,"dt":639159130195536508}
{"op":"mcm","id":2,"clk":"AINDAMwoAONb","pt":1780316219649,"mc":[{"id":"1.258742455","rc":[{"batb":[[1,48,26.19],[0,50,4.89]],"atb":[[50,4.89],[48,26.19]],"id":98464183}]}],"rt":639159130196573379,"dt":639159130196574290}
{"op":"mcm","id":2,"clk":"AIlDAM8oAO9b","pt":1780316219749,"mc":[{"id":"1.258742455","rc":[{"atl":[[70,10.69]],"batl":[],"id":98464183}]}],"rt":639159130197571868,"dt":639159130197572238}
{"op":"mcm","id":2,"clk":"AKtDAN0oAJtc","pt":1780316220165,"mc":[{"id":"1.258742455","rc":[{"batb":[],"atb":[[8.6,20.98]],"atl":[[11,14.3]],"batl":[[2,11,14.3]],"id":98117699}]}],"rt":639159130201729210,"dt":639159130201729577}
{"op":"mcm","id":2,"clk":"ALRDAOYoAKZc","pt":1780316220269,"mc":[{"id":"1.258742455","rc":[{"atl":[[95,3.14]],"batl":[],"id":98464183}]}],"rt":639159130202773463,"dt":639159130202774021}
{"op":"mcm","id":2,"clk":"ALxDAOkoALFc","pt":1780316220371,"mc":[{"id":"1.258742455","rc":[{"tv":1912.97,"trd":[[11.5,54.59]],"ltp":11.5,"atl":[[11.5,12.58]],"batl":[[0,11.5,12.58]],"id":97736949}],"tv":33948.71}],"rt":639159130203793096,"dt":639159130203793725}
{"op":"mcm","id":2,"clk":"ANdDAP8oANxc","pt":1780316220738,"mc":[{"id":"1.258742455","rc":[{"batb":[[0,80,4.6]],"atb":[[80,4.6]],"atl":[[1000,6.35]],"id":99072901},{"batb":[[0,4.5,124.54]],"atb":[[4.5,124.54]],"atl":[[1000,1.5]],"id":10398159}]}],"rt":639159130207462766,"dt":639159130207463180}
{"op":"mcm","id":2,"clk":"AN1DAIMpAOVc","pt":1780316220848,"mc":[{"id":"1.258742455","rc":[{"atl":[[1000,6.25]],"id":99072901},{"atl":[[1000,1.01]],"id":10398159}]}],"rt":639159130208558876,"dt":639159130208559386}
{"op":"mcm","id":2,"clk":"AOdDAIgpAO9c","pt":1780316220946,"mc":[{"id":"1.258742455","rc":[{"atl":[[30,8.25]],"batl":[],"id":99072900},{"atl":[[95,4.04]],"batl":[[1,95,4.04]],"id":99072901},{"atl":[[4.7,45.09]],"batl":[[1,4.7,45.09]],"id":10398159}]}],"rt":639159130209539732,"dt":639159130209540107}
{"op":"mcm","id":2,"clk":"AO9DAJQpAIVd","pt":1780316221149,"mc":[{"id":"1.258742455","rc":[{"tv":516.97,"trd":[[46,56.66]],"atl":[[46,0.3]],"batl":[[2,55,19.43],[1,50,12.27],[0,48,5.42]],"id":97008932},{"tv":356.02,"batb":[[2,75,9.39],[1,80,4.6],[0,90,1.23]],"trd":[[90,31.45]],"ltp":90,"atb":[[90,1.23]],"atl":[[90,0]],"batl":[[2,110,2.08],[1,100,1.53],[0,95,4.04]],"id":99072901},{"tv":221.84,"batb":[[2,150,3.29],[1,160,3.72],[0,180,2.16]],"trd":[[180,45.4]],"ltp":180,"atb":[[180,2.16]],"atl":[[180,0]],"batl":[[0,190,2.65]],"id":99072897}],"tv":33957.93}],"rt":639159130211575386,"dt":639159130211576119}
{"op":"mcm","id":2,"clk":"APhDAJwpAI5d","pt":1780316221250,"mc":[{"id":"1.258742455","rc":[{"atl":[[4.8,5.36]],"batl":[[2,5,22.17],[1,4.9,36.09],[0,4.8,5.36]],"id":99072898},{"atl":[[46,0.17]],"batl":[[0,48,5.29]],"id":97008932},{"atl":[[90,3.17]],"batl":[],"id":98464183},{"tv":221.98,"batb":[[0,180,2.09]],"trd":[[180,45.54]],"atb":[[180,2.09]],"id":99072897}],"tv":33958.07}],"rt":639159130212582805,"dt":639159130212583590}
{"op":"mcm","id":2,"clk":"AP1DAKApAJhd","pt":1780316221356,"mc":[{"id":"1.258742455","rc":[{"batb":[[1,4.6,39.99]],"atb":[[4.6,39.99]],"atl":[[5.1,7.48]],"batl":[],"id":99072898},{"atl":[[32,3.26]],"batl":[],"id":99072900},{"atl":[[110,0.37],[95,3.74]],"batl":[[2,120,1.48],[0,95,3.74]],"id":99072901},{"atl":[[6.8,0]],"id":10398159},{"atl":[[24,2.19]],"id":98117699},{"tv":222.1,"batb":[[0,180,2.03]],"trd":[[180,45.66]],"atb":[[180,2.03]],"id":99072897}],"tv":33958.19}],"rt":639159130213646965,"dt":639159130213647597}
{"op":"mcm","id":2,"clk":"AIVEAKkpAJ5d","pt":1780316221457,"mc":[{"id":"1.258742455","rc":[{"atl":[[70,6.35]],"batl":[],"id":97008932},{"batb":[[0,4.5,127.08]],"atb":[[4.5,127.08]],"atl":[[4.9,33.96]],"batl":[],"id":10398159},{"atl":[[75,5.77]],"batl":[],"id":98464183},{"batb":[[1,10.5,30.48]],"atb":[[10.5,30.48]],"id":97736949},{"tv":222.22,"batb":[[0,180,1.97]],"trd":[[180,45.78]],"atb":[[180,1.97],[80,4.6]],"atl":[[190,1.62]],"batl":[[0,190,1.62]],"id":99072897}],"tv":33958.31}],"rt":639159130214664931,"dt":639159130214665540}
{"op":"mcm","id":2,"clk":"AI5EALIpAKld","pt":1780316221564,"mc":[{"id":"1.258742455","rc":[{"batb":[[0,44,4.84]],"atb":[[44,4.84]],"id":97008932},{"batb":[[2,80,5.6],[1,85,2.67]],"atb":[[85,2.67],[80,5.6]],"atl":[[120,2.7]],"batl":[[2,120,3.07]],"id":99072901},{"tv":222.34,"batb":[[2,160,3.72],[1,170,2.67],[0,180,1.91]],"trd":[[180,45.9]],"atb":[[180,1.91],[170,2.67],[150,5.02]],"id":99072897}],"tv":33958.43}],"rt":639159130215721435,"dt":639159130215722420}
{"op":"mcm","id":2,"clk":"AJREALcpALBd","pt":1780316221666,"mc":[{"id":"1.258742455","rc":[{"atl":[[1000,0.32]],"id":97008932},{"tv":797.53,"batb":[[2,44,10.9],[1,46,32.3],[0,48,26.08]],"trd":[[50,111.5]],"atb":[[50,0],[48,26.08]],"id":98464183},{"atl":[[10,4.61]],"batl":[[0,10,4.61]],"id":98117699},{"batb":[[0,11,15.19]],"atb":[[11,15.19]],"id":97736949}],"tv":33968.21}],"rt":639159130216741358,"dt":639159130216741818}
{"op":"mcm","id":2,"clk":"AJxEALwpALpd","pt":1780316221773,"mc":[{"id":"1.258742455","rc":[{"atl":[[1000,0.22]],"id":97008932},{"atl":[[3.6,14.16]],"batl":[[0,3.6,14.16]],"id":88302242},{"batb":[[0,11,8]],"atb":[[11,8]],"id":97736949},{"tv":222.46,"batb":[[0,180,1.85]],"trd":[[180,46.02]],"atb":[[180,1.85]],"id":99072897}],"tv":33968.33}],"rt":639159130217813467,"dt":639159130217814185}
{"op":"mcm","id":2,"clk":"AKBEAL8pAMJd","pt":1780316221873,"mc":[{"id":"1.258742455","rc":[{"atl":[[46,0.27]],"batl":[[0,48,5.39]],"id":97008932}]}],"rt":639159130218808510,"dt":639159130218808863}
{"op":"mcm","id":2,"clk":"AKdEAMQpANFd","pt":1780316221975,"mc":[{"id":"1.258742455","rc":[{"tv":1926.27,"batb":[[0,11,1.35]],"trd":[[11,63.9]],"ltp":11,"atb":[[11,1.35]],"atl":[[11.5,16.45]],"batl":[[0,11.5,16.45]],"id":97736949},{"tv":222.64,"batb":[[0,180,1.76]],"trd":[[180,46.2]],"atb":[[180,1.76]],"id":99072897}],"tv":33981.81}],"rt":639159130219828803,"dt":639159130219829395}
{"op":"mcm","id":2,"clk":"ALBEAMgpAORd","pt":1780316222083,"mc":[{"id":"1.258742455","rc":[{"tv":1928.97,"batb":[[2,9.8,27.79],[1,10,45.8],[0,10.5,30.48]],"trd":[[11,66.6]],"atb":[[11,0]],"atl":[[11,7.95]],"batl":[[2,12,32.77],[1,11.5,16.45],[0,11,7.95]],"id":97736949}],"tv":33984.51}],"rt":639159130220910672,"dt":639159130220911328}
{"op":"mcm","id":2,"clk":"ALJEAMspAOtd","pt":1780316222139,"mc":[{"id":"1.258742455","rc":[{"atl":[[10,2.23]],"batl":[[0,10,2.23]],"id":98117699},{"atl":[[11,12.01]],"batl":[[0,11,12.01]],"id":97736949}]}],"rt":639159130221472654,"dt":639159130221473072}
{"op":"mcm","id":2,"clk":"ALlEAM8pAPZd","pt":1780316222239,"mc":[{"id":"1.258742455","rc":[{"atl":[[4.9,20.56]],"batl":[[1,4.9,20.56]],"id":99072898},{"batb":[[0,44,6.43]],"atb":[[44,6.43]],"id":97008932},{"atl":[[3.6,4.41]],"batl":[[0,3.6,4.41]],"id":88302242},{"batb":[[0,10.5,29.48]],"atb":[[9.4,23.85],[10.5,29.48],[9.6,6.69]],"id":97736949},{"batb":[[1,170,4.26]],"atb":[[170,4.26]],"id":99072897}]}],"rt":639159130222471098,"dt":639159130222472033}
{"op":"mcm","id":2,"clk":"AMNEANQpAINe","pt":1780316222349,"mc":[{"id":"1.258742455","rc":[{"atl":[[4.8,0.53]],"batl":[[2,5.1,7.48],[1,5,22.17],[0,4.9,21.09]],"id":99072898}]}],"rt":639159130223569502,"dt":639159130223569922}
{"op":"mcm","id":2,"clk":"AMtEANgpAJFe","pt":1780316222448,"mc":[{"id":"1.258742455","rc":[{"atl":[[5,17.26]],"batl":[[1,5,17.26]],"id":99072898},{"batb":[[2,75,9.39],[1,80,5.6],[0,85,2.67]],"atb":[[90,0]],"id":99072901},{"batb":[[2,150,5.02],[1,160,3.72],[0,170,4.26]],"atb":[[180,0]],"id":99072897}]}],"rt":639159130224562041,"dt":639159130224562574}
{"op":"mcm","id":2,"clk":"ANlEAN8pAKJe","pt":1780316222652,"mc":[{"id":"1.258742455","rc":[{"atl":[[5,19.06]],"batl":[[1,5,19.06]],"id":99072898},{"batb":[[1,80,4.47],[0,85,3.72]],"atb":[[85,3.72],[80,4.47]],"id":99072901},{"atl":[[190,2.65]],"batl":[[0,190,2.65]],"id":99072897}]}],"rt":639159130226603092,"dt":639159130226603594}
{"op":"mcm","id":2,"clk":"APdEAO4pAL5e","pt":1780316222964,"mc":[{"id":"1.258742455","rc":[{"tv":227.94,"batb":[[0,170,4.28]],"trd":[[190,34.76]],"ltp":190,"atb":[[190,0.02]],"atl":[[190,0]],"batl":[[2,230,1.09],[1,220,1.13],[0,210,1.77]],"id":99072897}],"tv":33989.81}],"rt":639159130229724981,"dt":639159130229725605}
{"op":"mcm","id":2,"clk":"AIBFAPspAMxe","pt":1780316223067,"mc":[{"id":"1.258742455","rc":[{"batb":[[1,160,5.45]],"atb":[[160,5.45]],"id":99072897}]}],"rt":639159130230750667,"dt":639159130230751071}
{"op":"mcm","id":2,"clk":"AIpFAP8pANZe","pt":1780316223166,"mc":[{"id":"1.258742455","rc":[{"batb":[[0,170,4.92]],"atb":[[180,0.64]],"atl":[[200,0.09]],"batl":[[0,210,1.86]],"id":99072897}]}],"rt":639159130231744897,"dt":639159130231745934}
{"op":"mcm","id":2,"clk":"AJBFAIMqAOFe","pt":1780316223268,"mc":[{"id":"1.258742455","rc":[{"atl":[[12.5,10.23],[12,23.98]],"batl":[[2,12,23.98]],"id":97736949},{"tv":228.06,"batb":[[0,170,4.86]],"trd":[[190,34.8],[180,46.28]],"ltp":180,"atb":[[190,0],[180,0.6]],"id":99072897}],"tv":33989.93}],"rt":639159130232759080,"dt":639159130232759912}
{"op":"mcm","id":2,"clk":"AJ9FAIoqAPRe","pt":1780316223424,"mc":[{"id":"1.258742455","rc":[{"atl":[[190,0.6]],"batl":[[0,210,2.46]],"id":99072897}]}],"rt":639159130234324213,"dt":639159130234324644}
{"op":"mcm","id":2,"clk":"AK5FAJIqAIZf","pt":1780316223632,"mc":[{"id":"1.258742455","rc":[{"tv":517.52,"batb":[[2,42,11.1],[1,44,6.43],[0,46,2.39]],"trd":[[46,57.21]],"atb":[[46,2.39]],"atl":[[46,0]],"batl":[[0,48,5.12]],"id":97008932},{"tv":361.34,"trd":[[95,29.48]],"ltp":95,"atl":[[95,1.08]],"batl":[[0,95,1.08]],"id":99072901},{"tv":229.26,"batb":[[2,160,5.45],[1,170,4.86],[0,190,2.06]],"trd":[[190,36]],"ltp":190,"atb":[[190,2.06]],"atl":[[190,0]],"batl":[[0,210,1.86]],"id":99072897}],"tv":33997}],"rt":639159130236403446,"dt":639159130236404361}
{"op":"mcm","id":2,"clk":"ALZFAJYqAJBf","pt":1780316223735,"mc":[{"id":"1.258742455","rc":[{"batb":[[1,44,7.56],[0,46,3.75]],"atb":[[46,3.75],[44,7.56]],"id":97008932},{"batb":[[2,80,4.47],[1,85,3.72],[0,90,2.41]],"atb":[[90,2.41]],"atl":[[100,1.67],[95,0.4]],"batl":[[2,130,1],[1,120,3.07],[0,100,2.07]],"id":99072901},{"tv":229.76,"batb":[[0,190,1.81]],"trd":[[190,36.5]],"atb":[[190,1.81]],"id":99072897}],"tv":33997.5}],"rt":639159130237438338,"dt":639159130237439192}
{"op":"mcm","id":2,"clk":"ALxFAJgqAJZf","pt":1780316223834,"mc":[{"id":"1.258742455","rc":[{"batb":[[1,44,5.66],[0,46,5.58]],"atb":[[46,5.58],[44,5.66]],"atl":[[95,2.51]],"id":97008932},{"atl":[[160,1.88]],"batl":[],"id":99072901},{"batb":[[2,46,32.3],[1,48,26.08],[0,50,3.47]],"atb":[[50,3.47]],"id":98464183},{"batb":[[1,170,5.14]],"atb":[[180,0.88]],"atl":[[210,0.74]],"batl":[[2,280,11.62],[1,230,1.09],[0,220,1.96]],"id":99072897}]}],"rt":639159130238425045,"dt":639159130238425874}
{"op":"mcm","id":2,"clk":"AMVFAJsqAJ9f","pt":1780316223942,"mc":[{"id":"1.258742455","rc":[{"batb":[[1,85,4.46]],"atb":[[85,4.46]],"atl":[[100,1]],"batl":[[0,100,1.4]],"id":99072901}]}],"rt":639159130239500320,"dt":639159130239501077}
{"op":"mcm","id":2,"clk":"ANJFAKQqAK9f","pt":1780316224140,"mc":[{"id":"1.258742455","rc":[{"atl":[[290,0]],"id":98464183}]}],"rt":639159130241482165,"dt":639159130241482556}
{"op":"mcm","id":2,"clk":"AOFFAKwqAMNf","pt":1780316224348,"mc":[{"id":"1.258742455","rc":[{"atl":[[19.5,21.86]],"id":99072898},{"atb":[[1.17,2.17]],"atl":[[48,4.95]],"batl":[[0,48,4.95]],"id":97008932},{"atl":[[25,4.12]],"batl":[[0,25,4.12]],"id":99072900},{"batb":[[0,4.5,126.93]],"atb":[[4.5,126.93]],"atl":[[18,20]],"id":10398159},{"atl":[[55,11.88]],"batl":[[0,55,11.88]],"id":98464183},{"atl":[[100,20]],"id":98117699},{"atb":[[1.17,196.86]],"atl":[[11,44.13]],"id":88302242},{"atl":[[120,20],[12,22.98]],"batl":[[2,12,22.98]],"id":97736949}]}],"rt":639159130243563978,"dt":639159130243564918}
{"op":"mcm","id":2,"clk":"AOhFAK8qAMxf","pt":1780316224450,"mc":[{"id":"1.258742455","rc":[{"atl":[[4.8,6.27]],"batl":[[2,5,19.06],[1,4.9,20.56],[0,4.8,6.27]],"id":99072898},{"atb":[[1.17,2]],"id":97008932},{"atb":[[1.17,195.12]],"id":88302242},{"atl":[[11,13.01]],"batl":[[0,11,13.01]],"id":97736949},{"batb":[[2,170,4.26],[1,180,2.47]],"atb":[[180,2.47],[150,3.04]],"id":99072897}]}],"rt":639159130244577020,"dt":639159130244577796}
{"op":"mcm","id":2,"clk":"AOxFALUqANNf","pt":1780316224555,"mc":[{"id":"1.258742455","rc":[{"atl":[[5,26.56],[4.8,5.74]],"batl":[[2,5,26.56],[0,4.8,5.74]],"id":99072898},{"batb":[[1,44,4.99],[0,46,6.14]],"atb":[[46,6.14],[44,4.99]],"atl":[[48,4.89]],"batl":[[0,48,4.89]],"id":97008932},{"atb":[[1.17,2.14]],"id":99072900},{"batb":[[2,80,3.97],[0,90,5.32]],"atb":[[90,5.32],[80,3.97]],"atl":[[95,0.3]],"batl":[[0,100,1.3]],"id":99072901},{"tv":11812.04,"batb":[[0,3.55,40.83]],"trd":[[3.6,429.83]],"atb":[[3.55,40.83]],"atl":[[3.6,3.54]],"batl":[[0,3.6,3.54]],"id":88302242},{"batb":[],"atb":[[9.4,27.06]],"atl":[[1000,2.08],[12,22.33],[11.5,15.94]],"batl":[[2,12,22.33],[1,11.5,15.94]],"id":97736949},{"batb":[[1,180,5.14],[0,190,1.98]],"atb":[[190,1.98],[180,5.14],[160,5.13]],"id":99072897}],"tv":33999.24}],"rt":639159130245629255,"dt":639159130245630622}
{"op":"mcm","id":2,"clk":"APFFALYqANxf","pt":1780316224654,"mc":[{"id":"1.258742455","rc":[{"atb":[[1.17,2]],"id":99072900},{"atl":[[1000,1]],"id":97736949},{"batb":[[0,190,3.57]],"atb":[[190,3.57]],"id":99072897}]}],"rt":639159130246621300,"dt":639159130246622020}
{"op":"mcm","id":2,"clk":"APVFALgqAOZf","pt":1780316224758,"mc":[{"id":"1.258742455","rc":[{"batb":[[0,24,19.73]],"atb":[[24,19.73]],"id":99072900},{"batb":[],"atb":[[9.4,23.85]],"atl":[[11.5,16.57],[11,13.46]],"batl":[[1,11.5,16.57],[0,11,13.46]],"id":97736949},{"batb":[[2,170,5.99]],"atb":[[170,5.99]],"id":99072897}]}],"rt":639159130247666986,"dt":639159130247667652}
{"op":"mcm","id":2,"clk":"APpFALkqAPJf","pt":1780316224861,"mc":[{"id":"1.258742455","rc":[{"batb":[[2,46,10.3],[1,48,5.84]],"atb":[[48,5.84],[46,10.3]],"id":98464183}]}],"rt":639159130248688867,"dt":639159130248689238}
{"op":"mcm","id":2,"clk":"AINGALwqAP1f","pt":1780316224965,"mc":[{"id":"1.258742455","rc":[{"atl":[[48,4.17]],"batl":[[0,48,4.17]],"id":97008932},{"batb":[[2,44,10.9],[1,46,10.3],[0,48,1.95]],"atb":[[50,0],[48,1.95]],"id":98464183},{"tv":11819.12,"batb":[[2,3.5,55.17],[1,3.55,40.83],[0,3.6,9.84]],"trd":[[3.6,436.91]],"atb":[[3.6,9.84]],"atl":[[3.6,0]],"batl":[[2,3.75,14.05],[1,3.7,5.2],[0,3.65,19.7]],"id":88302242}],"tv":34006.32}],"rt":639159130249732273,"dt":639159130249732716}
{"op":"mcm","id":2,"clk":"AIxGAMAqAIhg","pt":1780316225069,"mc":[{"id":"1.258742455","rc":[{"atl":[[50,3.46]],"batl":[[2,60,7.75],[1,55,11.88],[0,50,3.46]],"id":98464183},{"atl":[[3.65,15.45]],"batl":[[0,3.65,15.45]],"id":88302242}]}],"rt":639159130250772898,"dt":639159130250773447}
{"op":"mcm","id":2,"clk":"AJNGAMEqAJJg","pt":1780316225169,"mc":[{"id":"1.258742455","rc":[{"batb":[[2,42,4.92],[1,44,10.9],[0,46,10.6]],"atb":[[48,0.3]],"id":98464183}]}],"rt":639159130251768737,"dt":639159130251769103}
{"op":"mcm","id":2,"clk":"AJpGAMQqAJ5g","pt":1780316225271,"mc":[{"id":"1.258742455","rc":[{"tv":11833.26,"trd":[[3.65,110.35]],"ltp":3.65,"atl":[[3.65,8.38],[3.9,30.86]],"batl":[[0,3.65,8.38]],"id":88302242}],"tv":34020.46}],"rt":639159130252793152,"dt":639159130252793676}
{"op":"mcm","id":2,"clk":"AKFGAMgqAKxg","pt":1780316225379,"mc":[{"id":"1.258742455","rc":[{"batb":[[0,46,8.9]],"atb":[[46,8.6]],"id":98464183},{"atl":[[10,4.24]],"batl":[[0,10,4.24]],"id":98117699}]}],"rt":639159130253874070,"dt":639159130253874454}
{"op":"mcm","id":2,"clk":"AKhGAMkqALpg","pt":1780316225477,"mc":[{"id":"1.258742455","rc":[{"atl":[[50,5.01]],"batl":[[0,50,5.01]],"id":98464183},{"batb":[[0,3.6,29.54]],"atb":[[3.6,29.54]],"id":88302242},{"tv":1946.84,"trd":[[11,84.47]],"atl":[[11,4.52]],"batl":[[0,11,4.52]],"id":97736949}],"tv":34038.33}],"rt":639159130254850067,"dt":639159130254850702}
{"op":"mcm","id":2,"clk":"AK5GAM4qAMZg","pt":1780316225584,"mc":[{"id":"1.258742455","rc":[{"atl":[[48,4.22]],"batl":[[0,48,4.22]],"id":97008932},{"batb":[[0,46,2.34]],"atb":[[46,2.04]],"id":98464183},{"batb":[[0,3.6,39.11]],"atb":[[3.6,39.11]],"id":88302242}]}],"rt":639159130255923650,"dt":639159130255924223}
{"op":"mcm","id":2,"clk":"ALdGANAqANRg","pt":1780316225639,"mc":[{"id":"1.258742455","rc":[{"tv":802.21,"batb":[[2,40,4.94],[1,42,4.92],[0,44,10.9]],"trd":[[48,65.22],[46,58.29]],"ltp":46,"atb":[[48,0],[46,0]],"atl":[[48,3.12],[46,3.87],[65,22.89]],"batl":[[2,50,5.01],[1,48,3.12],[0,46,3.87]],"id":98464183},{"atl":[[3.65,6.6]],"batl":[[0,3.65,6.6]],"id":88302242}],"tv":34043.01}],"rt":639159130256476413,"dt":639159130256476858}
{"op":"mcm","id":2,"clk":"AMBGANMqAORg","pt":1780316225747,"mc":[{"id":"1.258742455","rc":[{"tv":517.53,"batb":[[0,46,6.13]],"trd":[[46,57.22]],"atb":[[46,6.13]],"id":97008932},{"tv":806.09,"trd":[[46,62.17]],"atl":[[46,2.27]],"batl":[[0,46,2.27]],"id":98464183},{"batb":[[2,9.2,14.28]],"atb":[[9.2,14.28]],"id":98117699},{"atb":[[1.17,2.69]],"id":97736949}],"tv":34046.9}],"rt":639159130257554370,"dt":639159130257554809}
{"op":"mcm","id":2,"clk":"AMdGANYqAPRg","pt":1780316225849,"mc":[{"id":"1.258742455","rc":[{"batb":[[0,44,8.49]],"atb":[[44,8.49]],"atl":[[60,9.52]],"batl":[],"id":98464183},{"atl":[[3.7,14.08]],"batl":[[1,3.7,14.08]],"id":88302242},{"atb":[[1.17,2]],"id":97736949}]}],"rt":639159130258573940,"dt":639159130258574552}
{"op":"mcm","id":2,"clk":"AMxGANgqAIBh","pt":1780316225945,"mc":[{"id":"1.258742455","rc":[{"batb":[[1,42,8.75]],"atb":[[42,8.75]],"id":98464183},{"batb":[[2,9.2,17.83]],"atb":[[9.2,17.83]],"id":98117699},{"batb":[[0,10.5,30.17]],"atb":[[10.5,30.17]],"id":97736949}]}],"rt":639159130259534266,"dt":639159130259534608}
{"op":"mcm","id":2,"clk":"ANVGANsqAIth","pt":1780316226062,"mc":[{"id":"1.258742455","rc":[{"tv":7486.77,"batb":[[2,4.6,39.99],[1,4.7,29.69],[0,4.8,29.26]],"trd":[[4.8,137.86]],"atb":[[4.8,29.26]],"atl":[[4.8,0],[32,0]],"batl":[[2,5.1,7.48],[1,5,26.56],[0,4.9,20.56]],"id":99072898},{"atl":[[48,4.68]],"batl":[[1,48,4.68]],"id":98464183},{"atl":[[3.65,7.21],[32,0]],"batl":[[0,3.65,7.21]],"id":88302242},{"atl":[[50,4.17]],"id":97736949}],"tv":34058.38}],"rt":639159130260703052,"dt":639159130260703678}
{"op":"mcm","id":2,"clk":"ANxGAN4qAJRh","pt":1780316226157,"mc":[{"id":"1.258742455","rc":[{"atl":[[19,2.1]],"id":99072898},{"atl":[[4.6,67]],"batl":[[0,4.6,67]],"id":10398159},{"batb":[[2,9.2,14.28]],"atb":[[9.2,14.28]],"id":98117699},{"atl":[[3.8,3.46],[10.5,4.08],[3.85,57.33]],"batl":[],"id":88302242}]}],"rt":639159130261655084,"dt":639159130261655559}
{"op":"mcm","id":2,"clk":"AN9GAOAqAKFh","pt":1780316226258,"mc":[{"id":"1.258742455","rc":[{"batb":[[0,4.8,35.89]],"atb":[[4.8,35.89]],"atl":[[1000,6.39],[4.9,7.96],[5,17.26]],"batl":[[1,5,17.26],[0,4.9,7.96]],"id":99072898},{"batb":[[0,44,1.99]],"atb":[[44,1.99]],"id":98464183}]}],"rt":639159130262662975,"dt":639159130262663773}
{"op":"mcm","id":2,"clk":"AOZGAOUqALBh","pt":1780316226360,"mc":[{"id":"1.258742455","rc":[{"batb":[[0,4.8,43.04]],"atb":[[4.8,43.04]],"atl":[[1000,6.25],[4.9,3.4]],"batl":[[0,4.9,3.4]],"id":99072898},{"batb":[[0,46,3.74]],"atb":[[46,3.74]],"id":97008932},{"batb":[[2,75,9.39],[1,80,4.71],[0,90,6.37]],"atb":[[90,6.37],[85,0.74]],"id":99072901},{"batb":[],"atb":[[29,35.54]],"atl":[[85,3.21]],"batl":[],"id":98464183},{"tv":11833.46,"batb":[[0,3.6,39.01]],"trd":[[3.6,437.11]],"ltp":3.6,"atb":[[3.6,39.01]],"id":88302242},{"batb":[[2,170,3.32],[0,190,1.76]],"atb":[[190,1.76],[170,3.32]],"id":99072897}],"tv":34058.58}],"rt":639159130263686200,"dt":639159130263687084}
{"op":"mcm","id":2,"clk":"APJGAOgqALph","pt":1780316226472,"mc":[{"id":"1.258742455","rc":[{"tv":7487.05,"batb":[[0,4.8,57.77]],"trd":[[4.8,138.14]],"atb":[[4.8,57.77]],"id":99072898},{"atl":[[4.7,35.96]],"batl":[[1,4.7,35.96]],"id":10398159},{"batb":[[2,170,1.59]],"atb":[[170,1.59]],"id":99072897}],"tv":34058.86}],"rt":639159130264796723,"dt":639159130264797404}
{"op":"mcm","id":2,"clk":"AIBHAOsqAMNh","pt":1780316226565,"mc":[{"id":"1.258742455","rc":[{"batb":[],"atb":[[4.3,6.39]],"id":99072898},{"atl":[[20,1]],"id":10398159}]}],"rt":639159130265735166,"dt":639159130265735732}
{"op":"mcm","id":2,"clk":"AKZHAPoqAPFh","pt":1780316227077,"mc":[{"id":"1.258742455","rc":[{"atl":[[4.1,2]],"batl":[],"id":88302242},{"atl":[[11,11.71]],"batl":[[0,11,11.71]],"id":97736949}]}],"rt":639159130270855185,"dt":639159130270855615}
{"op":"mcm","id":2,"clk":"AK1HAP0qAPxh","pt":1780316227181,"mc":[{"id":"1.258742455","rc":[{"tv":2186.97,"batb":[[0,9.6,3.75]],"trd":[[9.8,212.54],[9.6,226.14]],"ltp":9.6,"atb":[[9.8,0],[9.6,3.75]],"id":98117699}],"tv":34071.84}],"rt":639159130271900314,"dt":639159130271900774}
{"op":"mcm","id":2,"clk":"ALNHAP8qAIdi","pt":1780316227236,"mc":[{"id":"1.258742455","rc":[{"batb":[[0,44,2.14]],"atb":[[44,2.14]],"atl":[[50,8.47]],"batl":[[2,50,8.47]],"id":98464183},{"batb":[[0,10.5,30.87]],"atb":[[10.5,30.87]],"id":97736949},{"batb":[[2,160,5.13],[1,170,1.59],[0,180,5.31]],"atb":[[190,0.17]],"id":99072897}]}],"rt":639159130272444495,"dt":639159130272444979}
{"op":"mcm","id":2,"clk":"ALlHAIMrAIti","pt":1780316227341,"mc":[{"id":"1.258742455","rc":[{"tv":810.03,"batb":[[2,38,5.89],[1,40,4.94],[0,42,8.92]],"trd":[[44,88.51]],"ltp":44,"atb":[[44,0.17]],"id":98464183},{"batb":[[0,9.6,7.12]],"atb":[[9.6,7.12]],"atl":[[9.8,2.06]],"batl":[[2,10.5,11.24],[1,10,4.24],[0,9.8,2.06]],"id":98117699},{"batb":[[1,170,3.32]],"atb":[[170,3.32]],"id":99072897}],"tv":34075.78}],"rt":639159130273494980,"dt":639159130273495540}
{"op":"mcm","id":2,"clk":"AL9HAIQrAJRi","pt":1780316227445,"mc":[{"id":"1.258742455","rc":[{"tv":810.38,"batb":[[1,40,8.86],[0,42,6.15]],"trd":[[44,88.86]],"atb":[[44,0],[42,6.15],[40,8.86]],"atl":[[60,3.72],[46,3.79],[44,3.39]],"batl":[[2,48,4.68],[1,46,3.79],[0,44,3.39]],"id":98464183}],"tv":34076.13}],"rt":639159130274538766,"dt":639159130274539558}
{"op":"mcm","id":2,"clk":"AMdHAIgrAJti","pt":1780316227555,"mc":[{"id":"1.258742455","rc":[{"atb":[[1.17,2.19]],"atl":[[25,5.03]],"batl":[[0,25,5.03]],"id":99072900},{"atl":[[4.6,71.36]],"batl":[[0,4.6,71.36]],"id":10398159},{"atl":[[75,3.33]],"batl":[],"id":98464183},{"batb":[[0,10.5,33.9]],"atb":[[10.5,33.9]],"id":97736949}]}],"rt":639159130275627935,"dt":639159130275628630}
{"op":"mcm","id":2,"clk":"AM5HAIwrAKJi","pt":1780316227656,"mc":[{"id":"1.258742455","rc":[{"batb":[[0,42,2.32]],"atb":[[42,2.32]],"atl":[[46,3.45]],"batl":[[1,46,3.45]],"id":98464183}]}],"rt":639159130276641761,"dt":639159130276642173}
{"op":"mcm","id":2,"clk":"ANdHAJcrAKpi","pt":1780316227758,"mc":[{"id":"1.258742455","rc":[{"atb":[[1.17,2]],"id":99072900}]}],"rt":639159130277665143,"dt":639159130277665544}
{"op":"mcm","id":2,"clk":"AN9HAJorALVi","pt":1780316227862,"mc":[{"id":"1.258742455","rc":[{"batb":[[1,23,12.28]],"atb":[[23,12.28]],"id":99072900},{"tv":7618.41,"batb":[[0,4.5,126.19]],"trd":[[4.5,1670]],"ltp":4.5,"atb":[[4.5,126.19]],"id":10398159},{"tv":1947.08,"trd":[[11,84.71]],"atl":[[11,11.59]],"batl":[[0,11,11.59]],"id":97736949}],"tv":34077.85}],"rt":639159130278701132,"dt":639159130278701548}
{"op":"mcm","id":2,"clk":"AOdHAKArAL9i","pt":1780316227964,"mc":[{"id":"1.258742455","rc":[{"tv":815.7,"trd":[[44,94.18]],"atl":[[44,0.73]],"batl":[[2,50,8.47],[1,48,4.68],[0,46,4.18]],"id":98464183}],"tv":34083.17}],"rt":639159130279722552,"dt":639159130279723076}
{"op":"mcm","id":2,"clk":"AOhHAKgrAMli","pt":1780316228066,"mc":[{"id":"1.258742455","rc":[{"tv":815.74,"trd":[[44,94.22]],"atl":[[44,0.71]],"batl":[[0,46,4.16]],"id":98464183}],"tv":34083.21}],"rt":639159130280739659,"dt":639159130280740009}
{"op":"mcm","id":2,"clk":"APdHALMrANxi","pt":1780316228270,"mc":[{"id":"1.258742455","rc":[{"batb":[[1,3.55,44.63]],"atb":[[3.55,44.63]],"id":88302242}]}],"rt":639159130282790445,"dt":639159130282791096}
{"op":"mcm","id":2,"clk":"AJ1IANgrAJZj","pt":1780316228879,"mc":[{"id":"1.258742455","rc":[{"batb":[],"atb":[[8.8,12.74]],"id":98117699}]}],"rt":639159130288870427,"dt":639159130288870834}
{"op":"mcm","id":2,"clk":"ALNIAOgrAKFj","pt":1780316229083,"mc":[{"id":"1.258742455","rc":[{"atl":[[11,11.88]],"batl":[],"id":98117699},{"batb":[[1,3.55,40.83]],"atb":[[3.55,40.83]],"id":88302242}]}],"rt":639159130290916524,"dt":639159130290917010}
{"op":"mcm","id":2,"clk":"ALdIAOsrAKlj","pt":1780316229142,"mc":[{"id":"1.258742455","rc":[{"atb":[[1.1,50.86]],"id":88302242}]}],"rt":639159130291504868,"dt":639159130291505245}
{"op":"mcm","id":2,"clk":"AL9IAPMrALJj","pt":1780316229247,"mc":[{"id":"1.258742455","rc":[{"batb":[[0,4.5,136.19]],"atb":[[4.5,136.19]],"id":10398159}]}],"rt":639159130292546838,"dt":639159130292547436}
{"op":"mcm","id":2,"clk":"AMRIAPkrALlj","pt":1780316229349,"mc":[{"id":"1.258742455","rc":[{"atb":[[1.1,50.18]],"atl":[[10.5,4.05]],"id":88302242}]}],"rt":639159130293569515,"dt":639159130293570423}
{"op":"mcm","id":2,"clk":"ANJIAIAsAMVj","pt":1780316229551,"mc":[{"id":"1.258742455","rc":[{"atb":[[1.1,50]],"id":88302242}]}],"rt":639159130295596171,"dt":639159130295596573}
{"op":"mcm","id":2,"clk":"ANpIAIUsAMxj","pt":1780316229649,"mc":[{"id":"1.258742455","rc":[{"tv":11833.82,"trd":[[3.65,110.71]],"ltp":3.65,"atl":[[3.65,7.03]],"batl":[[0,3.65,7.03]],"id":88302242}],"tv":34083.57}],"rt":639159130296575786,"dt":639159130296576215}
{"op":"mcm","id":2,"clk":"AO9IAJQsAOlj","pt":1780316229967,"mc":[{"id":"1.258742455","rc":[{"batb":[[0,90,3.7]],"atb":[[90,3.7]],"id":99072901},{"batb":[[0,180,2.64]],"atb":[[180,2.47]],"id":99072897}]}],"rt":639159130299747993,"dt":639159130299748752}
{"op":"mcm","id":2,"clk":"APJIAJYsAOxj","pt":1780316230061,"mc":[{"id":"1.258742455","rc":[{"batb":[],"atb":[[8.8,20.51]],"id":98117699},{"batb":[[1,170,1.59]],"atb":[[170,1.59]],"id":99072897}]}],"rt":639159130300690032,"dt":639159130300690706}
{"op":"mcm","id":2,"clk":"AIpJAKksAINk","pt":1780316230275,"mc":[{"id":"1.258742455","rc":[{"tv":2004.22,"batb":[[0,10.5,5.33]],"trd":[[10.5,67.98]],"ltp":10.5,"atb":[[10.5,5.33]],"id":97736949}],"tv":34140.71}],"rt":639159130302835410,"dt":639159130302835850}
{"op":"mcm","id":2,"clk":"AJZJAK8sAI9k","pt":1780316230380,"mc":[{"id":"1.258742455","rc":[{"tv":7493.84,"batb":[[2,4.7,29.69],[1,4.8,57.77],[0,4.9,6.71]],"trd":[[4.9,30.33]],"ltp":4.9,"atb":[[4.9,6.71]],"atl":[[4.9,0]],"batl":[[2,5.2,27.06],[1,5.1,7.48],[0,5,17.26]],"id":99072898},{"batb":[[0,4.5,138.3]],"atb":[[4.5,138.3]],"atl":[[4.6,26.31]],"batl":[[0,4.6,26.31]],"id":10398159},{"atl":[[3.65,0.61]],"batl":[[2,3.8,3.46],[1,3.75,14.05],[0,3.7,14.69]],"id":88302242},{"atl":[[11,15.35]],"batl":[[0,11,15.35]],"id":97736949},{"batb":[[0,180,2.47]],"atb":[[190,0]],"id":99072897}],"tv":34147.5}],"rt":639159130303879931,"dt":639159130303880741}
{"op":"mcm","id":2,"clk":"AJ1JALMsAJdk","pt":1780316230473,"mc":[{"id":"1.258742455","rc":[{"tv":7507.25,"batb":[[2,4.6,37.8],[1,4.7,31.27],[0,4.8,60.05]],"trd":[[4.9,43.74]],"atb":[[4.7,31.27],[4.4,25.84],[4.9,0.01],[4.6,37.8],[4.8,60.04]],"atl":[[5,14.86]],"batl":[[0,5,14.86]],"id":99072898},{"batb":[[0,24,19.59]],"atb":[[24,19.59]],"id":99072900},{"batb":[[0,9.6,13.07]],"atb":[[9.6,13.07]],"atl":[[1000,7.23],[10.5,10.72],[10,3.87]],"batl":[[2,10.5,10.72],[1,10,3.87]],"id":98117699},{"batb":[],"atb":[[9.2,21.95],[9,11.7]],"atl":[[12,23.33]],"batl":[[2,12,23.33]],"id":97736949}],"tv":34160.91}],"rt":639159130304814425,"dt":639159130304815261}
{"op":"mcm","id":2,"clk":"AKZJALwsAJ5k","pt":1780316230581,"mc":[{"id":"1.258742455","rc":[{"atl":[[1000,6.25],[12.5,21.74]],"batl":[],"id":98117699},{"tv":11835.04,"batb":[[2,3.55,40.83],[1,3.6,39.01],[0,3.65,9.47]],"trd":[[3.65,111.93]],"atb":[[3.65,9.47]],"atl":[[3.65,0]],"batl":[[0,3.7,14.08]],"id":88302242},{"tv":2014.88,"batb":[[2,9.6,6.69],[1,9.8,27.79],[0,10,45.8]],"trd":[[10.5,78.64]],"atb":[[10.5,0]],"atl":[[13,2.73],[10.5,7.52]],"batl":[[2,11.5,16.57],[1,11,15.35],[0,10.5,7.52]],"id":97736949},{"batb":[[2,150,3.04],[1,160,5.13],[0,170,2.47]],"atb":[[180,0.88]],"id":99072897}],"tv":34172.79}],"rt":639159130305893596,"dt":639159130305894323}
{"op":"mcm","id":2,"clk":"AKtJAMQsAKdk","pt":1780316230680,"mc":[{"id":"1.258742455","rc":[{"batb":[[0,4.8,60.04]],"atb":[[4.9,0]],"id":99072898},{"atl":[[9.8,2.53],[10,4.38]],"batl":[[1,10,4.38],[0,9.8,2.53]],"id":98117699},{"batb":[],"atb":[[8.8,9.76],[9,8.41]],"id":97736949}]}],"rt":639159130306878744,"dt":639159130306879390}
{"op":"mcm","id":2,"clk":"ALBJAMwsAK5k","pt":1780316230779,"mc":[{"id":"1.258742455","rc":[{"tv":2016.86,"batb":[],"trd":[[10.5,80.62]],"atb":[[9.4,8.93]],"atl":[[12,22.33],[10.5,10.29]],"batl":[[0,10.5,10.29]],"id":97736949}],"tv":34174.77}],"rt":639159130307874521,"dt":639159130307874892}
{"op":"mcm","id":2,"clk":"AMJJAOUsAMpk","pt":1780316231043,"mc":[{"id":"1.258742455","rc":[{"batb":[],"atb":[[8.8,12.74]],"id":98117699}]}],"rt":639159130310512724,"dt":639159130310513049}
{"op":"mcm","id":2,"clk":"ANZJAO4sAN9k","pt":1780316231252,"mc":[{"id":"1.258742455","rc":[{"atl":[[5.8,31.74]],"batl":[],"id":99072898},{"atl":[[12,10.75],[11,35.77]],"batl":[[1,11,35.77]],"id":97736949}]}],"rt":639159130312599974,"dt":639159130312600312}
{"op":"mcm","id":2,"clk":"AONJAPYsAOlk","pt":1780316231355,"mc":[{"id":"1.258742455","rc":[{"atl":[[5.7,9.63]],"batl":[],"id":99072898},{"atl":[[20,1.5]],"id":10398159},{"batb":[[0,42,2.38]],"atb":[[42,2.38]],"id":98464183},{"tv":11932,"batb":[[2,3.45,34.92],[1,3.5,55.17],[0,3.55,40.83]],"trd":[[3.65,130.87],[3.6,515.13]],"ltp":3.6,"atb":[[3.65,0],[3.6,0]],"atl":[[3.6,1.52]],"batl":[[2,3.75,14.05],[1,3.7,14.08],[0,3.6,1.52]],"id":88302242}],"tv":34271.73}],"rt":639159130313631979,"dt":639159130313632493}
{"op":"mcm","id":2,"clk":"AOZJAPosAPBk","pt":1780316231453,"mc":[{"id":"1.258742455","rc":[{"atl":[[5.2,30.25],[5.3,26.54],[5.1,4.06]],"batl":[[2,5.2,30.25],[1,5.1,4.06]],"id":99072898},{"tv":7671.03,"batb":[[2,4.4,157.64],[1,4.5,138.3],[0,4.6,47.29]],"trd":[[4.6,884.33]],"ltp":4.6,"atb":[[4.6,47.29]],"atl":[[4.9,30.41],[4.6,0]],"batl":[[2,4.9,30.41],[1,4.8,80.52],[0,4.7,35.96]],"id":10398159},{"atl":[[44,0]],"batl":[[0,46,3.45]],"id":98464183},{"batb":[[2,9.2,17.83]],"atb":[[9.2,17.83]],"atl":[[9.8,0.47]],"batl":[[2,11,11.88],[1,10.5,10.72],[0,10,4.85]],"id":98117699},{"tv":11935.04,"batb":[[2,3.5,55.17],[1,3.55,35.29],[0,3.6,7.39]],"trd":[[3.6,518.17]],"atb":[[3.55,35.29],[3.6,7.39]],"atl":[[3.65,18.77],[3.6,0]],"batl":[[0,3.65,18.77]],"id":88302242},{"batb":[[2,9.6,12.29]],"atb":[[9,11.77],[9.6,12.29]],"atl":[[10.5,10.25]],"batl":[[0,10.5,10.25]],"id":97736949}],"tv":34327.39}],"rt":639159130314615617,"dt":639159130314616342}
{"op":"mcm","id":2,"clk":"AOtJAIUtAPlk","pt":1780316231565,"mc":[{"id":"1.258742455","rc":[{"batb":[[2,4.7,31.27],[1,4.8,60.04],[0,4.9,19.89]],"atb":[[4.9,19.89],[3.8,9.19]],"atl":[[5.2,27.06]],"batl":[[2,5.2,27.06]],"id":99072898},{"batb":[[2,42,12.83],[0,46,5.47]],"atb":[[46,5.47],[42,12.83]],"id":97008932},{"batb":[[0,24,25.64]],"atb":[[24,25.64]],"id":99072900},{"tv":361.93,"batb":[[0,90,4.27]],"trd":[[95,30.07]],"atb":[[95,0.57]],"atl":[[95,0]],"batl":[[0,100,1]],"id":99072901},{"tv":7676.33,"batb":[[1,4.5,171.17],[0,4.6,52.1]],"trd":[[4.6,889.63]],"atb":[[4.6,52.1],[4.5,171.17]],"atl":[[5,9.57],[5.1,36.18]],"batl":[],"id":10398159},{"batb":[[0,42,5.84]],"atb":[[42,5.84]],"id":98464183},{"batb":[[1,9.4,22.11],[0,9.6,21.72]],"atb":[[9.4,22.11],[9.6,21.72]],"id":98117699},{"tv":11943.1,"batb":[[2,3.5,45.51],[1,3.55,66.43],[0,3.6,3.36]],"trd":[[3.6,526.23]],"atb":[[1.17,195.72],[3.5,45.51],[3.55,66.43],[3.4,36.65],[3.6,3.36],[3.45,27.23]],"id":88302242},{"batb":[[0,10,56.39]],"atb":[[10,56.39]],"atl":[[1000,1.22]],"id":97736949}],"tv":34341.34}],"rt":639159130315735753,"dt":639159130315736628}
{"op":"mcm","id":2,"clk":"APBJAIstAP1k","pt":1780316231663,"mc":[{"id":"1.258742455","rc":[{"atl":[[48,4.27]],"batl":[[0,48,4.27]],"id":97008932},{"batb":[[0,4.6,65.7]],"atb":[[4.6,65.7]],"atl":[[4.9,26.32]],"batl":[[2,4.9,26.32]],"id":10398159},{"batb":[[0,42,8.99]],"atb":[[42,8.99]],"id":98464183},{"atb":[[1.17,195.12]],"id":88302242},{"atl":[[1000,1]],"id":97736949},{"batb":[[1,160,3.4]],"atb":[[160,3.4]],"id":99072897}]}],"rt":639159130316707015,"dt":639159130316707648}
{"op":"mcm","id":2,"clk":"APhJAI8tAIhl","pt":1780316231766,"mc":[{"id":"1.258742455","rc":[{"batb":[[2,4.6,37.8],[1,4.7,31.27],[0,4.8,60.04]],"atb":[[4.9,0]],"id":99072898},{"batb":[[0,46,3.74]],"atb":[[46,3.74]],"id":97008932},{"batb":[[0,24,19.59]],"atb":[[24,19.59]],"id":99072900},{"batb":[[0,90,4.38]],"atb":[[90,3.81]],"atl":[[120,1.11]],"batl":[[1,120,1.48]],"id":99072901},{"batb":[[2,40,8.86],[1,42,5.53],[0,44,2.66]],"atb":[[44,2.66],[42,5.53]],"atl":[[46,1.52]],"batl":[[0,46,1.52]],"id":98464183},{"batb":[[0,9.6,13.07]],"atb":[[9.6,13.07]],"atl":[[9.8,2.32]],"batl":[[2,10.5,10.72],[1,10,4.38],[0,9.8,2.32]],"id":98117699},{"tv":11951.02,"batb":[[2,3.45,27.23],[1,3.5,45.51],[0,3.55,66.43]],"trd":[[3.6,534.15]],"atb":[[3.6,0]],"atl":[[3.6,10.29]],"batl":[[2,3.7,14.08],[1,3.65,18.77],[0,3.6,10.29]],"id":88302242},{"batb":[[0,10,41.36]],"atb":[[10,41.36]],"atl":[[11,35.99]],"batl":[[1,11,35.99]],"id":97736949}],"tv":34349.26}],"rt":639159130317739323,"dt":639159130317740164}
{"op":"mcm","id":2,"clk":"AP5JAJQtAI5l","pt":1780316231866,"mc":[{"id":"1.258742455","rc":[{"batb":[],"atb":[[9.2,25.32]],"atl":[[10.5,17.83]],"batl":[[0,10.5,17.83]],"id":97736949}]}],"rt":639159130318742681,"dt":639159130318743110}
{"op":"mcm","id":2,"clk":"AIVKAJgtAJdl","pt":1780316231969,"mc":[{"id":"1.258742455","rc":[{"batb":[[1,42,6.89]],"atb":[[42,6.89]],"id":98464183}]}],"rt":639159130319773480,"dt":639159130319773855}
{"op":"mcm","id":2,"clk":"AIxKAJwtAJ9l","pt":1780316232075,"mc":[{"id":"1.258742455","rc":[{"atl":[[10.5,21.11]],"batl":[[0,10.5,21.11]],"id":97736949}]}],"rt":639159130320831250,"dt":639159130320831784}
{"op":"mcm","id":2,"clk":"AJZKAKAtAKNl","pt":1780316232173,"mc":[{"id":"1.258742455","rc":[{"tv":517.54,"batb":[[0,46,3.73]],"trd":[[46,57.23]],"atb":[[46,3.73]],"id":97008932},{"atl":[[3.6,0]],"batl":[[2,3.75,14.05],[1,3.7,14.08],[0,3.65,18.77]],"id":88302242}],"tv":34349.27}],"rt":639159130321813097,"dt":639159130321813577}
{"op":"mcm","id":2,"clk":"AJlKAKUtAK9l","pt":1780316232273,"mc":[{"id":"1.258742455","rc":[{"batb":[],"atb":[[4.5,37.76]],"id":99072898},{"batb":[],"atb":[[4.3,103.97]],"id":10398159},{"batb":[],"atb":[[8.8,9.17]],"id":98117699}]}],"rt":639159130322814785,"dt":639159130322815576}
{"op":"mcm","id":2,"clk":"AKFKAKotALpl","pt":1780316232377,"mc":[{"id":"1.258742455","rc":[{"tv":518.12,"batb":[[0,46,3.44]],"trd":[[46,57.81]],"atb":[[46,3.44]],"id":97008932},{"batb":[[1,9.4,18.57]],"atb":[[9.4,18.57]],"atl":[[32,2.34]],"id":98117699},{"atl":[[3.7,14.75]],"batl":[[1,3.7,14.75]],"id":88302242},{"batb":[[0,10,40.36]],"atb":[[10,40.36]],"id":97736949}],"tv":34349.85}],"rt":639159130323853328,"dt":639159130323853836}
{"op":"mcm","id":2,"clk":"AKdKAK8tAMJl","pt":1780316232483,"mc":[{"id":"1.258742455","rc":[{"batb":[[0,3.55,35.29]],"atb":[[3.55,35.29]],"id":88302242},{"atl":[[50,1.99]],"id":97736949},{"batb":[[0,170,2.98]],"atb":[[170,2.1]],"id":99072897}]}],"rt":639159130324910917,"dt":639159130324911380}
{"op":"mcm","id":2,"clk":"AK9KALQtAMpl","pt":1780316232583,"mc":[{"id":"1.258742455","rc":[{"batb":[[1,42,6.83]],"atb":[[42,6.83]],"id":98464183},{"batb":[[1,9.4,22.13]],"atb":[[9.4,22.13]],"id":98117699}]}],"rt":639159130325908230,"dt":639159130325908869}
{"op":"mcm","id":2,"clk":"ALtKAMItAONl","pt":1780316232749,"mc":[{"id":"1.258742455","rc":[{"batb":[],"atb":[[9.2,29.3]],"id":97736949}]}],"rt":639159130327573268,"dt":639159130327573819}
{"op":"mcm","id":2,"clk":"AMJKAMUtAO5l","pt":1780316232848,"mc":[{"id":"1.258742455","rc":[{"batb":[[2,4.4,173.36]],"atb":[[4.4,173.36]],"id":10398159},{"atl":[[11.5,21.07]],"batl":[[2,11.5,21.07]],"id":97736949}]}],"rt":639159130328575321,"dt":639159130328575679}
{"op":"mcm","id":2,"clk":"AM5KAM4tAIBm","pt":1780316233049,"mc":[{"id":"1.258742455","rc":[{"tv":363.93,"batb":[[2,80,4.71],[1,90,4.38],[0,100,1.66]],"trd":[[100,22.47]],"ltp":100,"atb":[[100,1.66]],"atl":[[100,0]],"batl":[[2,160,2.18],[1,130,1],[0,120,1.48]],"id":99072901},{"atl":[[11.5,15.95]],"batl":[[2,11.5,15.95]],"id":97736949}],"tv":34351.85}],"rt":639159130330576227,"dt":639159130330576822}
{"op":"mcm","id":2,"clk":"ANdKANItAItm","pt":1780316233203,"mc":[{"id":"1.258742455","rc":[{"tv":365.01,"batb":[[1,90,5.08],[0,100,1.12]],"trd":[[100,23.55]],"atb":[[100,1.12],[90,4.51]],"id":99072901},{"batb":[[1,9.4,18.57]],"atb":[[9.4,18.57]],"id":98117699},{"batb":[],"atb":[[9.2,25.93]],"id":97736949}],"tv":34352.93}],"rt":639159130332117065,"dt":639159130332117701}
{"op":"mcm","id":2,"clk":"ANpKANYtAJJm","pt":1780316233257,"mc":[{"id":"1.258742455","rc":[{"batb":[[0,4.8,61.51]],"atb":[[4.8,61.51]],"id":99072898},{"batb":[[0,46,3.74]],"atb":[[46,3.74]],"id":97008932},{"batb":[[0,24,20.17]],"atb":[[24,20.17]],"id":99072900},{"batb":[[1,90,5.24]],"atb":[[90,4.67]],"id":99072901},{"batb":[[0,4.6,67.24]],"atb":[[4.6,67.24]],"id":10398159},{"batb":[[0,44,2.98]],"atb":[[44,2.98]],"id":98464183},{"batb":[[0,9.6,14.51]],"atb":[[9.6,14.51]],"id":98117699},{"batb":[[0,3.55,37.29]],"atb":[[3.55,37.29]],"id":88302242},{"batb":[[0,10,42.53]],"atb":[[10,42.53]],"id":97736949},{"batb":[[0,1000,92.96]],"atb":[[1000,92.96]],"id":10445502},{"batb":[[0,170,3.06]],"atb":[[170,2.18]],"id":99072897}]}],"rt":639159130332648814,"dt":639159130332649481}
{"op":"mcm","id":2,"clk":"AOBKAN0tAJpm","pt":1780316233358,"mc":[{"id":"1.258742455","rc":[{"tv":2017.14,"trd":[[10.5,80.9]],"atl":[[10.5,20.97]],"batl":[[0,10.5,20.97]],"id":97736949}],"tv":34353.21}],"rt":639159130333668638,"dt":639159130333669013}
{"op":"mcm","id":2,"clk":"AOlKAOAtAKNm","pt":1780316233463,"mc":[{"id":"1.258742455","rc":[{"atl":[[4.9,1.19]],"batl":[[2,5.1,4.06],[1,5,14.86],[0,4.9,1.19]],"id":99072898},{"atl":[[1000,0.36]],"id":97008932},{"batb":[[1,42,7.64],[0,44,3.14]],"atb":[[44,3.14],[42,7.64]],"atl":[[46,1.77]],"batl":[[0,46,1.77]],"id":98464183},{"batb":[[0,9.6,17]],"atb":[[9.6,17]],"id":98117699},{"atl":[[3.7,14.08]],"batl":[[1,3.7,14.08]],"id":88302242}]}],"rt":639159130334713507,"dt":639159130334713980}
{"op":"mcm","id":2,"clk":"AO9KAOQtAKtm","pt":1780316233564,"mc":[{"id":"1.258742455","rc":[{"atl":[[5.2,30.3]],"batl":[],"id":99072898},{"atl":[[1000,0.22],[48,4.32]],"batl":[[0,48,4.32]],"id":97008932},{"batb":[[1,9.4,22.13]],"atb":[[9.4,22.13]],"id":98117699},{"batb":[],"atb":[[9.2,29.3]],"id":97736949}]}],"rt":639159130335722321,"dt":639159130335722737}
{"op":"mcm","id":2,"clk":"APdKAOotALdm","pt":1780316233668,"mc":[{"id":"1.258742455","rc":[{"atl":[[50,12.41]],"batl":[[1,50,12.41]],"id":97008932},{"atl":[[110,4.69]],"batl":[[2,130,1],[1,120,1.11],[0,110,4.69]],"id":99072901},{"batb":[[2,4.4,157.64]],"atb":[[4.4,157.64]],"id":10398159},{"batb":[[0,10,44.83]],"atb":[[10,44.83]],"id":97736949}]}],"rt":639159130336763917,"dt":639159130336764625}
{"op":"mcm","id":2,"clk":"AINLAPQtAMVm","pt":1780316233871,"mc":[{"id":"1.258742455","rc":[{"batb":[[0,46,3.59]],"atb":[[46,3.59]],"id":97008932},{"atb":[[1.17,2.19]],"id":98464183},{"atl":[[1000,6.93]],"id":98117699},{"batb":[[2,3.5,45.51],[1,3.55,37.29],[0,3.6,7.44]],"atb":[[3.6,7.44]],"id":88302242}]}],"rt":639159130338794491,"dt":639159130338794918}
{"op":"mcm","id":2,"clk":"AIhLAP0tAM5m","pt":1780316233975,"mc":[{"id":"1.258742455","rc":[{"atl":[[5.2,27.06]],"batl":[],"id":99072898},{"batb":[[1,44,6.72]],"atb":[[44,6.72]],"id":97008932},{"atl":[[25,4.97]],"batl":[[0,25,4.97]],"id":99072900},{"atl":[[110,5.06]],"batl":[[0,110,5.06]],"id":99072901},{"tv":7678.77,"batb":[[0,4.6,66.02]],"trd":[[4.6,892.07]],"atb":[[4.6,66.02]],"atl":[[5,12.95]],"batl":[],"id":10398159},{"tv":815.78,"batb":[[0,44,3.19]],"trd":[[46,62.21]],"ltp":46,"atb":[[1.17,2],[44,3.19]],"atl":[[46,1.75]],"batl":[[0,46,1.75]],"id":98464183},{"atl":[[1000,6.25]],"id":98117699},{"atl":[[200,0.21]],"batl":[[0,220,2.08]],"id":99072897}],"tv":34355.69}],"rt":639159130339833631,"dt":639159130339834517}
{"op":"mcm","id":2,"clk":"AJFLAIEuANRm","pt":1780316234079,"mc":[{"id":"1.258742455","rc":[{"batb":[[0,44,3.38]],"atb":[[44,3.38]],"id":98464183},{"atl":[[9.8,3]],"batl":[[0,9.8,3]],"id":98117699},{"tv":2017.86,"trd":[[10.5,81.62]],"atl":[[10.5,20.61]],"batl":[[0,10.5,20.61]],"id":97736949}],"tv":34356.41}],"rt":639159130340871932,"dt":639159130340872634}
{"op":"mcm","id":2,"clk":"AJpLAIMuAOBm","pt":1780316234179,"mc":[{"id":"1.258742455","rc":[{"tv":518.14,"batb":[[0,46,3.58]],"trd":[[46,57.83]],"atb":[[46,3.58]],"id":97008932},{"atl":[[160,0.67]],"batl":[],"id":99072901},{"tv":7680.44,"batb":[[0,4.6,65.18]],"trd":[[4.6,893.74]],"atb":[[4.6,65.18]],"id":10398159},{"tv":818.66,"batb":[[0,44,4.82]],"trd":[[44,97.1]],"ltp":44,"atb":[[44,4.82]],"id":98464183},{"batb":[],"atb":[[8.8,5.2]],"id":98117699},{"batb":[],"atb":[[9.2,25.32]],"atl":[[11.5,11.45]],"batl":[[2,11.5,11.45]],"id":97736949}],"tv":34360.98}],"rt":639159130341871550,"dt":639159130341872248}
{"op":"mcm","id":2,"clk":"AKRLAIcuAO5m","pt":1780316234279,"mc":[{"id":"1.258742455","rc":[{"atl":[[4.7,40.62]],"batl":[[0,4.7,40.62]],"id":10398159}]}],"rt":639159130342873467,"dt":639159130342873838}
{"op":"mcm","id":2,"clk":"AKtLAIouAPpm","pt":1780316234384,"mc":[{"id":"1.258742455","rc":[{"batb":[[2,75,9.39],[1,80,4.71],[0,90,5.24]],"atb":[[100,0]],"id":99072901},{"batb":[[0,44,3.59]],"atb":[[44,3.59]],"id":98464183}]}],"rt":639159130343923449,"dt":639159130343924095}
{"op":"mcm","id":2,"clk":"ALJLAI0uAIln","pt":1780316234442,"mc":[{"id":"1.258742455","rc":[{"batb":[[0,90,4.19]],"atb":[[90,3.62]],"id":99072901},{"tv":818.67,"batb":[[2,38,5.89],[1,40,8.86],[0,42,8.35]],"trd":[[46,62.22]],"ltp":46,"atb":[[44,0.71]],"atl":[[46,1.74]],"batl":[[0,46,1.74]],"id":98464183}],"tv":34360.99}],"rt":639159130344508125,"dt":639159130344508660}
{"op":"mcm","id":2,"clk":"AL1LAJEuAJdn","pt":1780316234543,"mc":[{"id":"1.258742455","rc":[{"batb":[[0,90,1.78]],"atb":[[90,1.21]],"atl":[[100,0.19]],"batl":[[0,110,5.25]],"id":99072901}]}],"rt":639159130345517325,"dt":639159130345517724}
{"op":"mcm","id":2,"clk":"AMRLAJYuAKJn","pt":1780316234645,"mc":[{"id":"1.258742455","rc":[{"atl":[[48,4.37]],"batl":[[0,48,4.37]],"id":97008932}]}],"rt":639159130346532036,"dt":639159130346532365}
{"op":"mcm","id":2,"clk":"AMpLAJouAK5n","pt":1780316234746,"mc":[{"id":"1.258742455","rc":[{"batb":[[0,90,2.61]],"atb":[[90,2.04]],"id":99072901},{"batb":[[0,42,6.99]],"atb":[[42,6.28]],"id":98464183},{"atl":[[3.65,19.37]],"batl":[[0,3.65,19.37]],"id":88302242}]}],"rt":639159130347546756,"dt":639159130347547491}
{"op":"mcm","id":2,"clk":"AO1LALwuANBn","pt":1780316235161,"mc":[{"id":"1.258742455","rc":[{"batb":[[0,3.6,17.53]],"atb":[[3.6,17.53]],"id":88302242}]}],"rt":639159130351692182,"dt":639159130351692586}
{"op":"mcm","id":2,"clk":"APdLAMIuANdn","pt":1780316235262,"mc":[{"id":"1.258742455","rc":[{"tv":518.15,"batb":[[0,46,3.57]],"trd":[[46,57.84]],"atb":[[46,3.57]],"id":97008932},{"batb":[[0,42,7.05]],"atb":[[44,0.77]],"id":98464183},{"batb":[],"atb":[[3.45,36.81]],"id":88302242}],"tv":34361}],"rt":639159130352703859,"dt":639159130352704297}
{"op":"mcm","id":2,"clk":"AP9LAMwuAOFn","pt":1780316235369,"mc":[{"id":"1.258742455","rc":[{"batb":[[0,90,1.78]],"atb":[[90,1.21]],"id":99072901}]}],"rt":639159130353767940,"dt":639159130353768494}
{"op":"mcm","id":2,"clk":"AIxMANMuAOpn","pt":1780316235471,"mc":[{"id":"1.258742455","rc":[{"tv":818.69,"trd":[[46,62.24]],"atl":[[46,1.73]],"batl":[[0,46,1.73]],"id":98464183}],"tv":34361.02}],"rt":639159130354795914,"dt":639159130354796290}
{"op":"mcm","id":2,"clk":"AJBMANcuAPJn","pt":1780316235574,"mc":[{"id":"1.258742455","rc":[{"atl":[[11,10.82]],"batl":[],"id":98117699}]}],"rt":639159130355818634,"dt":639159130355819138}
{"op":"mcm","id":2,"clk":"AJtMAN4uAP5n","pt":1780316235677,"mc":[{"id":"1.258742455","rc":[{"atl":[[11,9.75]],"batl":[],"id":98117699}]}],"rt":639159130356852847,"dt":639159130356853166}
{"op":"mcm","id":2,"clk":"AKRMAOAuAIVo","pt":1780316235778,"mc":[{"id":"1.258742455","rc":[{"batb":[[1,4.7,32.27]],"atb":[[4.7,32.27]],"id":99072898},{"tv":822.15,"batb":[[2,40,8.86],[1,42,6.28],[0,44,1.7]],"trd":[[46,65.7]],"atb":[[46,0.93]],"atl":[[46,0]],"batl":[[2,55,11.88],[1,50,8.47],[0,48,4.68]],"id":98464183},{"atl":[[3.65,19.96]],"batl":[[0,3.65,19.96]],"id":88302242},{"batb":[],"atb":[[9,12.77]],"id":97736949}],"tv":34364.48}],"rt":639159130357859752,"dt":639159130357860443}
{"op":"mcm","id":2,"clk":"AKtMAOcuAJBo","pt":1780316235879,"mc":[{"id":"1.258742455","rc":[{"batb":[],"atb":[[3.85,53.69]],"id":10398159},{"batb":[[0,44,4.42]],"atb":[[44,3.49]],"id":98464183},{"batb":[[1,9.8,27.28]],"atb":[[9.8,27.28]],"id":97736949}]}],"rt":639159130358868689,"dt":639159130358869089}
{"op":"mcm","id":2,"clk":"ALJMAOouAJdo","pt":1780316235984,"mc":[{"id":"1.258742455","rc":[{"batb":[],"atb":[[4,34.49]],"id":99072898},{"tv":824.01,"batb":[[1,42,7.57],[0,44,3.49]],"trd":[[46,67.56]],"atb":[[46,0],[42,7.57]],"id":98464183},{"tv":11951.21,"batb":[[0,3.6,17.43]],"trd":[[3.6,534.34]],"atb":[[3.6,17.43]],"id":88302242}],"tv":34366.53}],"rt":639159130359924397,"dt":639159130359925168}
{"op":"mcm","id":2,"clk":"ALpMAOsuAKFo","pt":1780316236041,"mc":[{"id":"1.258742455","rc":[{"atl":[[48,1.56]],"batl":[[0,48,1.56]],"id":98464183},{"tv":11959.21,"trd":[[3.65,138.87]],"ltp":3.65,"atl":[[3.65,15.96]],"batl":[[0,3.65,15.96]],"id":88302242}],"tv":34374.53}],"rt":639159130360487803,"dt":639159130360488195}
{"op":"mcm","id":2,"clk":"AL5MAPIuAKpo","pt":1780316236139,"mc":[{"id":"1.258742455","rc":[{"atl":[[5.2,30.29]],"batl":[],"id":99072898},{"batb":[[2,42,11.1],[1,44,4.99]],"atb":[[44,4.99],[42,11.1]],"atl":[[1000,0.36]],"id":97008932},{"batb":[[1,23,12.09]],"atb":[[23,12.09],[21,12.44]],"id":99072900},{"batb":[[0,90,1.74]],"atb":[[95,0.77],[90,0.97]],"id":99072901},{"batb":[[1,4.5,166.65],[0,4.6,69.46]],"atb":[[4.6,69.46],[4.5,166.65]],"atl":[[4.7,40.13],[1000,1.9]],"batl":[[0,4.7,40.13]],"id":10398159},{"batb":[[1,42,6.76],[0,44,3.82]],"atb":[[46,0.33],[42,6.76]],"atl":[[50,5.01]],"batl":[[1,50,5.01]],"id":98464183},{"batb":[[1,9.4,18.57]],"atb":[[9.4,18.57],[8.4,5.44]],"id":98117699},{"batb":[[2,3.5,55.1],[0,3.6,7.34]],"atb":[[3.5,55.1],[3.6,7.34]],"atl":[[1000,3.23]],"id":88302242},{"batb":[],"atb":[[9.2,21.95]],"atl":[[1000,2.28],[11.5,10.82],[11,35.54]],"batl":[[2,11.5,10.82],[1,11,35.54]],"id":97736949}]}],"rt":639159130361473191,"dt":639159130361474291}
{"op":"mcm","id":2,"clk":"AM1MAP0uALto","pt":1780316236346,"mc":[{"id":"1.258742455","rc":[{"batb":[],"atb":[[40,6.32]],"atl":[[1000,0.22]],"id":97008932},{"atl":[[1000,1.01]],"id":10398159},{"batb":[[0,3.6,17.38]],"atb":[[3.6,17.38]],"atl":[[1000,3]],"id":88302242},{"batb":[],"atb":[[9,13.33]],"atl":[[1000,1]],"id":97736949}]}],"rt":639159130363537939,"dt":639159130363538684}
{"op":"mcm","id":2,"clk":"ANNMAP8uAMVo","pt":1780316236446,"mc":[{"id":"1.258742455","rc":[{"batb":[],"atb":[[4.1,57.4]],"id":99072898},{"atl":[[48,4.51]],"batl":[[0,48,4.51]],"id":97008932},{"batb":[],"atb":[[20,4.22]],"id":99072900},{"batb":[],"atb":[[3.9,14.33]],"atl":[[4.8,81.41]],"batl":[[1,4.8,81.41]],"id":10398159},{"batb":[],"atb":[[8.2,6.4]],"id":98117699},{"atb":[[3.05,297.07]],"atl":[[3.65,16.19]],"batl":[[0,3.65,16.19]],"id":88302242},{"atl":[[11,36.27],[10.5,21.16]],"batl":[[1,11,36.27],[0,10.5,21.16]],"id":97736949}]}],"rt":639159130364542636,"dt":639159130364543821}
{"op":"mcm","id":2,"clk":"ANpMAIcvAMpo","pt":1780316236553,"mc":[{"id":"1.258742455","rc":[{"batb":[],"atb":[[38,12.16]],"id":97008932}]}],"rt":639159130365614234,"dt":639159130365614593}
{"op":"mcm","id":2,"clk":"AOBMAJAvANNo","pt":1780316236656,"mc":[{"id":"1.258742455","rc":[{"atb":[[3.1,4.55]],"id":88302242}]}],"rt":639159130366642046,"dt":639159130366642404}
{"op":"mcm","id":2,"clk":"AJtNAMEvAIdp","pt":1780316237480,"mc":[{"id":"1.258742455","rc":[{"atl":[[55,15]],"id":97736949}]}],"rt":639159130374884676,"dt":639159130374885055}
{"op":"mcm","id":2,"clk":"AKRNAM4vAJJp","pt":1780316237685,"mc":[{"id":"1.258742455","rc":[{"atl":[[20,0.5]],"id":10398159}]}],"rt":639159130376931723,"dt":639159130376932247}
{"op":"mcm","id":2,"clk":"ALJNANkvAJtp","pt":1780316237841,"mc":[{"id":"1.258742455","rc":[{"tv":7514.05,"batb":[[0,4.8,58.11]],"trd":[[4.8,144.94]],"ltp":4.8,"atb":[[4.8,58.11]],"id":99072898}],"tv":34381.33}],"rt":639159130378492478,"dt":639159130378492896}
{"op":"mcm","id":2,"clk":"AL1NAOAvAKNp","pt":1780316237949,"mc":[{"id":"1.258742455","rc":[{"atl":[[4.9,9.46]],"batl":[[0,4.9,9.46]],"id":99072898}]}],"rt":639159130379573984,"dt":639159130379574523}
{"op":"mcm","id":2,"clk":"AO9NAIEwANNp","pt":1780316238563,"mc":[{"id":"1.258742455","rc":[{"batb":[],"atb":[[3.45,34.81]],"id":88302242}]}],"rt":639159130385709904,"dt":639159130385710483}
{"op":"mcm","id":2,"clk":"APhNAIgwANtp","pt":1780316238673,"mc":[{"id":"1.258742455","rc":[{"batb":[[1,3.55,39.29]],"atb":[[3.55,39.29]],"id":88302242}]}],"rt":639159130386814223,"dt":639159130386814678}
{"op":"mcm","id":2,"clk":"AKVOAKQwAIZq","pt":1780316239178,"mc":[{"id":"1.258742455","rc":[{"atl":[[1000,0.17]],"id":98464183},{"batb":[[0,3.6,18.9]],"atb":[[3.6,18.9]],"atl":[[1000,3.31]],"id":88302242},{"batb":[[0,10,48.08]],"atb":[[10,48.08]],"id":97736949},{"batb":[[2,160,3.4],[1,170,2.18],[0,180,1.04]],"atb":[[180,1.04]],"id":99072897}]}],"rt":639159130391863026,"dt":639159130391863663}
{"op":"mcm","id":2,"clk":"AKhOAKgwAI1q","pt":1780316239276,"mc":[{"id":"1.258742455","rc":[{"atl":[[1000,0]],"id":98464183}]}],"rt":639159130392846481,"dt":639159130392846835}
{"op":"mcm","id":2,"clk":"ALFOALIwAJZq","pt":1780316239388,"mc":[{"id":"1.258742455","rc":[{"atl":[[50,5.18]],"batl":[[1,50,5.18]],"id":98464183},{"atl":[[1000,3]],"id":88302242}]}],"rt":639159130393957173,"dt":639159130393957604}
{"op":"mcm","id":2,"clk":"ALpOALMwAKNq","pt":1780316239483,"mc":[{"id":"1.258742455","rc":[{"atl":[[3.7,14.39]],"batl":[[1,3.7,14.39]],"id":88302242}]}],"rt":639159130394909841,"dt":639159130394910259}
{"op":"mcm","id":2,"clk":"ANNOAMAwALpq","pt":1780316239743,"mc":[{"id":"1.258742455","rc":[{"batb":[[0,180,1.21]],"atb":[[190,0.17]],"id":99072897}]}],"rt":639159130397509689,"dt":639159130397510040}
{"op":"mcm","id":2,"clk":"ANpOAMkwAM5q","pt":1780316239950,"mc":[{"id":"1.258742455","rc":[{"tv":520.15,"batb":[[0,46,2.57]],"trd":[[46,59.84]],"atb":[[46,2.57]],"id":97008932},{"tv":2020.74,"batb":[[0,10,46.64]],"trd":[[10,2.88]],"ltp":10,"atb":[[10,46.64]],"id":97736949}],"tv":34386.21}],"rt":639159130399578141,"dt":639159130399578685}
{"op":"mcm","id":2,"clk":"AJNPAO8wAI1r","pt":1780316240670,"mc":[{"id":"1.258742455","rc":[{"atl":[[4.1,7]],"batl":[],"id":88302242}]}],"rt":639159130406784023,"dt":639159130406784401}
{"op":"mcm","id":2,"clk":"AMhPAIsxALRr","pt":1780316241193,"mc":[{"id":"1.258742455","rc":[{"batb":[[2,3.5,53.1]],"atb":[[3.5,53.1]],"atl":[[4.8,9.7]],"id":88302242}]}],"rt":639159130412009670,"dt":639159130412010091}
{"op":"mcm","id":2,"clk":"ANBPAI0xALhr","pt":1780316241289,"mc":[{"id":"1.258742455","rc":[{"batb":[[0,3.6,53.9]],"atb":[[3.6,53.9]],"id":88302242}]}],"rt":639159130412969782,"dt":639159130412970178}
{"op":"mcm","id":2,"clk":"AN9PAJ0xAMhr","pt":1780316241490,"mc":[{"id":"1.258742455","rc":[{"batb":[[0,46,2.53]],"atb":[[46,2.53]],"id":97008932},{"batb":[[0,3.6,73.93]],"atb":[[3.6,73.93]],"atl":[[3.65,12.03]],"batl":[[0,3.65,12.03]],"id":88302242}]}],"rt":639159130414976596,"dt":639159130414977090}
{"op":"mcm","id":2,"clk":"AOhPAKExAMtr","pt":1780316241597,"mc":[{"id":"1.258742455","rc":[{"atl":[[3.65,1.79]],"batl":[[0,3.65,1.79]],"id":88302242},{"atl":[[11,35.27]],"batl":[[1,11,35.27]],"id":97736949}]}],"rt":639159130416055978,"dt":639159130416056399}
{"op":"mcm","id":2,"clk":"APNPAKUxANFr","pt":1780316241654,"mc":[{"id":"1.258742455","rc":[{"batb":[[0,4.8,63.3]],"atb":[[4.8,63.3]],"id":99072898},{"atl":[[10.5,22.16]],"batl":[[0,10.5,22.16]],"id":97736949}]}],"rt":639159130416621425,"dt":639159130416621889}
{"op":"mcm","id":2,"clk":"APlPALAxANdr","pt":1780316241755,"mc":[{"id":"1.258742455","rc":[{"atl":[[20,0]],"id":10398159},{"atl":[[10.5,23.43]],"batl":[[0,10.5,23.43]],"id":97736949}]}],"rt":639159130417627719,"dt":639159130417628344}
{"op":"mcm","id":2,"clk":"AIBQALQxAOBr","pt":1780316241855,"mc":[{"id":"1.258742455","rc":[{"tv":7681.44,"batb":[[0,4.6,68.96]],"trd":[[4.6,894.74]],"atb":[[4.6,68.96]],"id":10398159}],"tv":34387.21}],"rt":639159130418630443,"dt":639159130418630847}
{"op":"mcm","id":2,"clk":"AKJQANIxAP1r","pt":1780316242370,"mc":[{"id":"1.258742455","rc":[{"tv":826.01,"batb":[[0,44,2.81]],"trd":[[46,68.22],[44,98.44]],"ltp":44,"atb":[[46,0],[44,2.81]],"id":98464183}],"tv":34389.21}],"rt":639159130423783831,"dt":639159130423784576}
{"op":"mcm","id":2,"clk":"AKtQANMxAIRs","pt":1780316242471,"mc":[{"id":"1.258742455","rc":[{"tv":2024.74,"batb":[[0,10,44.64]],"trd":[[10,6.88]],"atb":[[10,44.64]],"id":97736949}],"tv":34393.21}],"rt":639159130424793989,"dt":639159130424794363}
{"op":"mcm","id":2,"clk":"ALBQANoxAI5s","pt":1780316242573,"mc":[{"id":"1.258742455","rc":[{"atl":[[4.9,11.58]],"batl":[[0,4.9,11.58]],"id":99072898},{"atl":[[48,4.37]],"batl":[[0,48,4.37]],"id":97008932},{"batb":[[0,4.6,65.59]],"atb":[[4.6,65.59]],"id":10398159},{"atl":[[50,5.01]],"batl":[[1,50,5.01]],"id":98464183},{"batb":[[0,3.6,72.41]],"atb":[[1.17,195.26],[3.6,72.41]],"atl":[[1000,3.63],[3.65,1.56],[3.7,14.08]],"batl":[[1,3.7,14.08],[0,3.65,1.56]],"id":88302242},{"batb":[[0,180,1.05]],"atb":[[180,0.88]],"id":99072897}]}],"rt":639159130425816819,"dt":639159130425817632}
{"op":"mcm","id":2,"clk":"ALdQAOAxAJds","pt":1780316242680,"mc":[{"id":"1.258742455","rc":[{"tv":899.57,"trd":[[25,125.58]],"ltp":25,"atl":[[25,3.57]],"batl":[[0,25,3.57]],"id":99072900},{"atb":[[1.17,195.12]],"atl":[[1000,3]],"id":88302242}],"tv":34396.01}],"rt":639159130426884595,"dt":639159130426885231}
{"op":"mcm","id":2,"clk":"AMFQAOYxAJps","pt":1780316242781,"mc":[{"id":"1.258742455","rc":[{"batb":[[1,3.55,39.43]],"atb":[[3.55,39.43]],"atl":[[3.65,2.19]],"batl":[[0,3.65,2.19]],"id":88302242}]}],"rt":639159130427893569,"dt":639159130427893982}
{"op":"mcm","id":2,"clk":"AMhQAOoxAKNs","pt":1780316242888,"mc":[{"id":"1.258742455","rc":[{"atl":[[25,1.29]],"batl":[[0,25,1.29]],"id":99072900},{"batb":[],"atb":[[3.45,37.48]],"id":88302242}]}],"rt":639159130428963249,"dt":639159130428963898}
{"op":"mcm","id":2,"clk":"AJJRAJAyAOhs","pt":1780316243656,"mc":[{"id":"1.258742455","rc":[{"batb":[[0,10,43.56]],"atb":[[10,43.56]],"atl":[[11,35.05]],"batl":[[1,11,35.05]],"id":97736949}]}],"rt":639159130436639181,"dt":639159130436640011}
{"op":"mcm","id":2,"clk":"AM1RALgyAJxt","pt":1780316244182,"mc":[{"id":"1.258742455","rc":[{"tv":2038.58,"batb":[[0,10,36.64]],"trd":[[10,20.72]],"atb":[[10,36.64]],"id":97736949}],"tv":34409.85}],"rt":639159130441901094,"dt":639159130441901781}
{"op":"mcm","id":2,"clk":"ANRRAL8yAKJt","pt":1780316244284,"mc":[{"id":"1.258742455","rc":[{"tv":902.15,"batb":[[2,23,12.09],[1,24,20.17],[0,25,2.56]],"trd":[[25,128.16]],"atb":[[25,2.56]],"atl":[[25,0]],"batl":[[2,28,4.36],[1,27,13.15],[0,26,4.04]],"id":99072900}],"tv":34412.43}],"rt":639159130442919864,"dt":639159130442920361}
{"op":"mcm","id":2,"clk":"AN1RAMsyAK5t","pt":1780316244385,"mc":[{"id":"1.258742455","rc":[{"tv":907.25,"batb":[[2,22,21.61],[1,23,12.09],[0,24,20.18]],"trd":[[25,133.26]],"atb":[[25,0.01]],"id":99072900},{"atl":[[10.5,27.1]],"batl":[[0,10.5,27.1]],"id":97736949}],"tv":34417.53}],"rt":639159130443935810,"dt":639159130443936339}
{"op":"mcm","id":2,"clk":"AORRANAyALRt","pt":1780316244485,"mc":[{"id":"1.258742455","rc":[{"tv":907.27,"batb":[[0,24,20.17]],"trd":[[25,133.28]],"atb":[[25,0]],"atl":[[30,2.9],[25,1.11]],"batl":[[2,27,13.15],[1,26,4.04],[0,25,1.11]],"id":99072900},{"batb":[[0,9.6,10]],"atb":[[9.6,10]],"id":98117699}],"tv":34417.55}],"rt":639159130444932519,"dt":639159130444933033}
{"op":"mcm","id":2,"clk":"AO1RANUyAL1t","pt":1780316244588,"mc":[{"id":"1.258742455","rc":[{"atl":[[25,3.61]],"batl":[[0,25,3.61]],"id":99072900},{"atl":[[10.5,22.45]],"batl":[[0,10.5,22.45]],"id":97736949}]}],"rt":639159130445967771,"dt":639159130445968223}
{"op":"mcm","id":2,"clk":"AJJSAPYyANtt","pt":1780316244958,"mc":[{"id":"1.258742455","rc":[{"tv":7520.67,"batb":[[2,4.7,32.27],[1,4.8,63.3],[0,4.9,8.48]],"trd":[[4.9,50.36]],"ltp":4.9,"atb":[[4.9,8.48]],"atl":[[4.9,0]],"batl":[[2,5.2,30.29],[1,5.1,4.06],[0,5,14.86]],"id":99072898},{"atl":[[25,6.25]],"batl":[[0,25,6.25]],"id":99072900},{"atl":[[4.8,5.99]],"id":88302242},{"atl":[[10.5,21.45]],"batl":[[0,10.5,21.45]],"id":97736949}],"tv":34424.17}],"rt":639159130449661581,"dt":639159130449662346}
{"op":"mcm","id":2,"clk":"AJtSAPsyAOFt","pt":1780316245065,"mc":[{"id":"1.258742455","rc":[{"atl":[[5.2,27.06]],"batl":[[2,5.2,27.06]],"id":99072898},{"atl":[[3.65,11.36]],"batl":[[0,3.65,11.36]],"id":88302242},{"tv":2040.58,"batb":[[0,10,35.64]],"trd":[[10,22.72]],"atb":[[10,35.64]],"id":97736949}],"tv":34426.17}],"rt":639159130450734851,"dt":639159130450735533}
{"op":"mcm","id":2,"clk":"AKJSAIIzAOlt","pt":1780316245165,"mc":[{"id":"1.258742455","rc":[{"batb":[[0,3.6,56.8]],"atb":[[3.6,56.8]],"id":88302242}]}],"rt":639159130451732019,"dt":639159130451732417}
{"op":"mcm","id":2,"clk":"AKhSAIczAPBt","pt":1780316245268,"mc":[{"id":"1.258742455","rc":[{"batb":[],"atb":[[3.3,6.33]],"id":88302242}]}],"rt":639159130452758344,"dt":639159130452758688}
{"op":"mcm","id":2,"clk":"ALBSAIwzAPht","pt":1780316245369,"mc":[{"id":"1.258742455","rc":[{"batb":[[2,4.6,37.8],[1,4.7,32.27],[0,4.8,63.3]],"atb":[[4.9,0]],"id":99072898},{"batb":[[0,46,3.68]],"atb":[[46,3.68]],"id":97008932},{"tv":2059.8,"batb":[[0,10,26.03]],"trd":[[10,41.94]],"atb":[[10,26.03]],"id":97736949}],"tv":34445.39}],"rt":639159130453776500,"dt":639159130453777233}
{"op":"mcm","id":2,"clk":"ALdSAJAzAP1t","pt":1780316245472,"mc":[{"id":"1.258742455","rc":[{"atl":[[5.2,30.25]],"batl":[[2,5.2,30.25]],"id":99072898},{"batb":[[1,170,1.67],[0,180,1.57]],"atb":[[180,1.4],[170,1.67]],"id":99072897}]}],"rt":639159130454801600,"dt":639159130454802034}
{"op":"mcm","id":2,"clk":"ALxSAJQzAIJu","pt":1780316245573,"mc":[{"id":"1.258742455","rc":[{"atb":[[1.17,2.1]],"id":99072900},{"atb":[[1.17,2.12]],"id":98464183},{"batb":[[0,10,22.78]],"atb":[[10,22.78]],"id":97736949}]}],"rt":639159130455815051,"dt":639159130455815490}
{"op":"mcm","id":2,"clk":"AMFSAJgzAIhu","pt":1780316245677,"mc":[{"id":"1.258742455","rc":[{"atb":[[1.17,2]],"id":99072900},{"atb":[[1.17,2]],"id":98464183},{"batb":[[1,9.8,35.12]],"atb":[[9.8,35.12]],"id":97736949}]}],"rt":639159130456847267,"dt":639159130456848294}
{"op":"mcm","id":2,"clk":"AMdSAKEzAI9u","pt":1780316245785,"mc":[{"id":"1.258742455","rc":[{"batb":[[1,23,12.19]],"atb":[[23,12.19]],"id":99072900},{"batb":[[0,44,2.93]],"atb":[[46,0.12]],"id":98464183},{"batb":[[0,10,23.6]],"atb":[[10,23.6]],"id":97736949}]}],"rt":639159130457937245,"dt":639159130457937947}
{"op":"mcm","id":2,"clk":"APxSAMYzALlu","pt":1780316246551,"mc":[{"id":"1.258742455","rc":[{"atl":[[110,1.99]],"id":98464183},{"atl":[[3.8,5.46]],"batl":[],"id":88302242}]}],"rt":639159130465590318,"dt":639159130465590702}
{"op":"mcm","id":2,"clk":"AIJTAM0zAL5u","pt":1780316246655,"mc":[{"id":"1.258742455","rc":[{"atl":[[4.7,44.88]],"batl":[[0,4.7,44.88]],"id":10398159},{"batb":[[0,44,3.08]],"atb":[[44,2.96]],"id":98464183},{"tv":2060.81,"batb":[[0,10,25.85]],"trd":[[10.5,82.63]],"ltp":10.5,"atb":[[10,25.85]],"atl":[[10.5,20.94]],"batl":[[0,10.5,20.94]],"id":97736949}],"tv":34446.4}],"rt":639159130466636131,"dt":639159130466636958}
{"op":"mcm","id":2,"clk":"AIlTANIzAMZu","pt":1780316246756,"mc":[{"id":"1.258742455","rc":[{"atl":[[25,5.14]],"batl":[[0,25,5.14]],"id":99072900},{"tv":826.05,"trd":[[48,65.26]],"ltp":48,"atl":[[48,1.54]],"batl":[[0,48,1.54]],"id":98464183}],"tv":34446.44}],"rt":639159130467644826,"dt":639159130467645316}
{"op":"mcm","id":2,"clk":"AJNTANYzAM9u","pt":1780316246857,"mc":[{"id":"1.258742455","rc":[{"batb":[[0,10,26.91]],"atb":[[10,26.91]],"id":97736949}]}],"rt":639159130468649887,"dt":639159130468650243}
{"op":"mcm","id":2,"clk":"AJ5TAOMzAOFu","pt":1780316247072,"mc":[{"id":"1.258742455","rc":[{"batb":[[0,10,30.71]],"atb":[[10,30.71]],"id":97736949}]}],"rt":639159130470798965,"dt":639159130470799375}
{"op":"mcm","id":2,"clk":"AKVTAOszAOtu","pt":1780316247173,"mc":[{"id":"1.258742455","rc":[{"atl":[[5.4,32.24]],"batl":[],"id":99072898},{"tv":7683.22,"batb":[[0,4.6,64.7]],"trd":[[4.6,896.52]],"atb":[[4.6,64.7]],"id":10398159}],"tv":34448.22}],"rt":639159130471812610,"dt":639159130471813266}
{"op":"mcm","id":2,"clk":"ALVTAII0AIJv","pt":1780316247475,"mc":[{"id":"1.258742455","rc":[{"tv":7812.63,"batb":[[2,4.3,103.97],[1,4.4,157.64],[0,4.5,166.65]],"trd":[[4.6,1025.93]],"atb":[[4.6,0]],"atl":[[4.6,10.3]],"batl":[[2,4.8,81.41],[1,4.7,44.88],[0,4.6,10.3]],"id":10398159}],"tv":34577.63}],"rt":639159130474831275,"dt":639159130474831788}
{"op":"mcm","id":2,"clk":"AL1TAIg0AIlv","pt":1780316247578,"mc":[{"id":"1.258742455","rc":[{"batb":[[2,4.7,32.27],[1,4.8,63.3],[0,4.9,8.98]],"atb":[[4.9,8.98]],"atl":[[5.2,27.06]],"batl":[[2,5.2,27.06]],"id":99072898},{"batb":[[2,42,12.83],[1,44,6.72]],"atb":[[44,6.72],[42,12.83]],"id":97008932},{"atl":[[4.6,48.27],[4.8,84.74]],"batl":[[2,4.8,84.74],[0,4.6,48.27]],"id":10398159},{"batb":[[1,9.4,22.13]],"atb":[[9.4,22.13]],"id":98117699},{"batb":[[1,3.55,49],[0,3.6,72.42]],"atb":[[3.55,49],[3.6,72.42]],"id":88302242},{"batb":[],"atb":[[9.2,25.34]],"id":97736949},{"batb":[[0,180,3.19]],"atb":[[180,3.02]],"id":99072897}]}],"rt":639159130475865560,"dt":639159130475866461}
{"op":"mcm","id":2,"clk":"AMRTAIs0AI5v","pt":1780316247684,"mc":[{"id":"1.258742455","rc":[{"atl":[[5.4,35.37],[5.3,23.35]],"batl":[],"id":99072898},{"tv":7821.93,"batb":[[0,4.5,159.1]],"trd":[[4.6,1035.23]],"atb":[[4.5,159.1]],"atl":[[4.6,47.01]],"batl":[[0,4.6,47.01]],"id":10398159},{"atl":[[3.65,2.19]],"batl":[[0,3.65,2.19]],"id":88302242},{"batb":[[2,160,5.13]],"atb":[[160,5.13]],"id":99072897}],"tv":34586.93}],"rt":639159130476918507,"dt":639159130476919153}
{"op":"mcm","id":2,"clk":"AMpTAI00AJNv","pt":1780316247781,"mc":[{"id":"1.258742455","rc":[{"batb":[[0,4.5,126.23]],"atb":[[4.5,126.23]],"id":10398159}]}],"rt":639159130477895195,"dt":639159130477895526}
{"op":"mcm","id":2,"clk":"ANJTAJI0AJtv","pt":1780316247891,"mc":[{"id":"1.258742455","rc":[{"atl":[[48,4.42]],"batl":[[0,48,4.42]],"id":97008932},{"batb":[[2,3.5,86.1]],"atb":[[3.5,86.1]],"id":88302242}]}],"rt":639159130478991262,"dt":639159130478991657}
{"op":"mcm","id":2,"clk":"ANdTAJY0AKJv","pt":1780316247989,"mc":[{"id":"1.258742455","rc":[{"atl":[[11,38.25]],"batl":[[1,11,38.25]],"id":97736949}]}],"rt":639159130479972601,"dt":639159130479972924}
{"op":"mcm","id":2,"clk":"AOlTAKE0AK9v","pt":1780316248191,"mc":[{"id":"1.258742455","rc":[{"tv":7522.67,"trd":[[5,15.9]],"ltp":5,"atl":[[5,13.86]],"batl":[[0,5,13.86]],"id":99072898},{"atb":[[6,1]],"id":97008932},{"atb":[[6,1]],"id":99072900},{"atb":[[6,1]],"id":99072901},{"tv":7832.57,"batb":[[1,4.4,148.17]],"trd":[[4.6,1045.87]],"atb":[[4.4,148.17]],"atl":[[4.6,41.69]],"batl":[[0,4.6,41.69]],"id":10398159},{"atb":[[6,1]],"id":98464183},{"atb":[[6,7.8]],"id":98117699},{"tv":11961.21,"trd":[[3.65,140.87]],"atl":[[3.65,1.18]],"batl":[[0,3.65,1.18]],"id":88302242},{"atb":[[6,1]],"id":97736949},{"atb":[[6,1]],"id":10445502},{"atb":[[6,1]],"id":99072897}],"tv":34601.57}],"rt":639159130481990705,"dt":639159130481991248}
{"op":"mcm","id":2,"clk":"APZTAK00AL1v","pt":1780316248345,"mc":[{"id":"1.258742455","rc":[{"tv":7561.91,"batb":[[2,4.6,37.8],[1,4.7,32.27],[0,4.8,52.66]],"trd":[[4.9,68.32],[4.8,166.22]],"ltp":4.8,"atb":[[4.9,0],[4.8,52.66]],"id":99072898},{"atl":[[4.6,3.72]],"batl":[[0,4.6,3.72]],"id":10398159},{"batb":[[0,44,3.12]],"atb":[[46,0.16]],"id":98464183},{"tv":11963.52,"trd":[[3.65,143.18]],"atl":[[3.65,0.03]],"batl":[[2,3.8,5.46],[1,3.75,14.05],[0,3.7,14.11]],"id":88302242}],"tv":34643.12}],"rt":639159130483535065,"dt":639159130483535551}
{"op":"mcm","id":2,"clk":"AP1TALA0AMZv","pt":1780316248450,"mc":[{"id":"1.258742455","rc":[{"atl":[[5.3,26.52]],"batl":[],"id":99072898},{"batb":[[0,3.6,81.93]],"atb":[[3.6,81.93]],"id":88302242}]}],"rt":639159130484579970,"dt":639159130484580324}
{"op":"mcm","id":2,"clk":"AIFUALI0AMtv","pt":1780316248551,"mc":[{"id":"1.258742455","rc":[{"tv":11963.58,"batb":[[2,3.55,49],[1,3.6,81.93],[0,3.65,9.75]],"trd":[[3.65,143.24]],"atb":[[3.65,9.75]],"atl":[[3.65,0]],"batl":[[0,3.7,14.08]],"id":88302242}],"tv":34643.18}],"rt":639159130485590827,"dt":639159130485591208}
{"op":"mcm","id":2,"clk":"AIZUALw0ANJv","pt":1780316248654,"mc":[{"id":"1.258742455","rc":[{"batb":[[2,4.3,113.97]],"atb":[[4.3,113.97]],"id":10398159},{"tv":11964.78,"batb":[[0,3.65,9.15]],"trd":[[3.65,144.44]],"atb":[[3.65,9.15]],"id":88302242}],"tv":34644.38}],"rt":639159130486618414,"dt":639159130486618853}
{"op":"mcm","id":2,"clk":"AI1UAMM0ANdv","pt":1780316248756,"mc":[{"id":"1.258742455","rc":[{"atl":[[1000,0.32]],"id":97008932},{"atl":[[1000,2.67],[4.8,83.85]],"batl":[[2,4.8,83.85]],"id":10398159},{"batb":[[0,44,3]],"atb":[[46,0.04]],"id":98464183},{"tv":11964.98,"batb":[[2,3.55,48.86],[0,3.65,9.05]],"trd":[[3.65,144.64]],"atb":[[3.65,9.05],[3.55,48.86]],"id":88302242}],"tv":34644.58}],"rt":639159130487641534,"dt":639159130487642302}
{"op":"mcm","id":2,"clk":"AJNUAMc0AN5v","pt":1780316248862,"mc":[{"id":"1.258742455","rc":[{"atl":[[1000,0.22]],"id":97008932},{"atl":[[1000,1.01]],"id":10398159},{"atl":[[3.9,36.86],[3.7,14.74]],"batl":[[0,3.7,14.74]],"id":88302242}]}],"rt":639159130488697252,"dt":639159130488697894}
{"op":"mcm","id":2,"clk":"AJNUAMw0AOZv","pt":1780316248961,"mc":[{"id":"1.258742455","rc":[{"atl":[[48,4.52]],"batl":[[0,48,4.52]],"id":97008932},{"atl":[[4.7,45.87],[4.6,4.39],[4.8,88.57]],"batl":[[2,4.8,88.57],[1,4.7,45.87],[0,4.6,4.39]],"id":10398159},{"batb":[],"atb":[[3.45,43.48]],"id":88302242}]}],"rt":639159130489691107,"dt":639159130489691564}
{"op":"mcm","id":2,"clk":"AKxUANo0APtv","pt":1780316249270,"mc":[{"id":"1.258742455","rc":[{"atb":[[1.17,2.59]],"atl":[[1000,1.12]],"id":97736949}]}],"rt":639159130492787547,"dt":639159130492787963}
{"op":"mcm","id":2,"clk":"ALBUAN80AIFw","pt":1780316249376,"mc":[{"id":"1.258742455","rc":[{"batb":[[0,44,3.03]],"atb":[[46,0.07]],"id":98464183},{"atb":[[1.17,2]],"id":97736949}]}],"rt":639159130493845737,"dt":639159130493846336}
{"op":"mcm","id":2,"clk":"ALlUAOE0AIZw","pt":1780316249476,"mc":[{"id":"1.258742455","rc":[{"batb":[],"atb":[[4.1,45.34]],"atl":[[5,18.95]],"batl":[],"id":10398159},{"tv":11965.21,"batb":[[0,3.65,8.93]],"trd":[[3.65,144.87]],"atb":[[3.65,8.93]],"id":88302242},{"batb":[[0,10,31.3]],"atb":[[10,31.3]],"atl":[[1000,1]],"id":97736949}],"tv":34644.81}],"rt":639159130494844737,"dt":639159130494845620}
{"op":"mcm","id":2,"clk":"AMBUAOM0AIhw","pt":1780316249578,"mc":[{"id":"1.258742455","rc":[{"batb":[[2,3.5,86.1],[1,3.55,48.86],[0,3.6,81.93]],"atb":[[3.65,0]],"id":88302242},{"atl":[[11,38.37]],"batl":[[1,11,38.37]],"id":97736949}]}],"rt":639159130495864853,"dt":639159130495865327}
{"op":"mcm","id":2,"clk":"ANNUAPA0AKJw","pt":1780316249993,"mc":[{"id":"1.258742455","rc":[{"atl":[[4.8,83.85]],"batl":[[2,4.8,83.85]],"id":10398159},{"atl":[[3.9,41.33]],"batl":[],"id":88302242}]}],"rt":639159130500012372,"dt":639159130500012795}
{"op":"mcm","id":2,"clk":"ANpUAPQ0AKpw","pt":1780316250089,"mc":[{"id":"1.258742455","rc":[{"atl":[[5.3,23.35]],"batl":[],"id":99072898},{"batb":[],"atb":[[3.45,37.48]],"atl":[[3.9,36.86]],"batl":[],"id":88302242}]}],"rt":639159130500970989,"dt":639159130500971432}
{"op":"mcm","id":2,"clk":"AN5UAPY0ALBw","pt":1780316250192,"mc":[{"id":"1.258742455","rc":[{"batb":[],"atb":[[4.4,31.84]],"atl":[[5.4,41.37]],"batl":[],"id":99072898}]}],"rt":639159130502002160,"dt":639159130502002534}
{"op":"mcm","id":2,"clk":"AOlUAIU1AL9w","pt":1780316250366,"mc":[{"id":"1.258742455","rc":[{"batb":[],"atb":[[3.4,42.65]],"id":88302242}]}],"rt":639159130503737628,"dt":639159130503737979}
{"op":"mcm","id":2,"clk":"APFUAIw1AMhw","pt":1780316250458,"mc":[{"id":"1.258742455","rc":[{"atl":[[5.4,35.65]],"batl":[],"id":99072898}]}],"rt":639159130504655208,"dt":639159130504655535}
{"op":"mcm","id":2,"clk":"AP9UAJY1ANZw","pt":1780316250661,"mc":[{"id":"1.258742455","rc":[{"tv":7841.35,"batb":[[2,4.4,148.17],[1,4.5,126.23],[0,4.6,38.86]],"trd":[[4.6,1054.65]],"atb":[[4.6,38.86]],"atl":[[4.9,8.51],[4.6,0]],"batl":[[2,4.9,8.51],[1,4.8,83.85],[0,4.7,45.87]],"id":10398159}],"tv":34653.59}],"rt":639159130506690078,"dt":639159130506690570}
{"op":"mcm","id":2,"clk":"AIlVAJ41AOFw","pt":1780316250775,"mc":[{"id":"1.258742455","rc":[{"atl":[[5.2,30.23],[5.3,26.52]],"batl":[[2,5.2,30.23]],"id":99072898},{"batb":[[2,42,11.1],[1,44,4.99]],"atb":[[44,4.99],[42,11.1]],"id":97008932},{"tv":7845.65,"batb":[[1,4.5,133.71],[0,4.6,36.71]],"trd":[[4.6,1058.95]],"atb":[[4.6,36.71],[4.5,133.71]],"atl":[[4.8,80.52]],"batl":[[1,4.8,80.52]],"id":10398159},{"batb":[[2,9.2,14.28],[1,9.4,18.57]],"atb":[[9.4,18.57],[9.2,14.28]],"id":98117699},{"batb":[[1,3.55,39.29],[0,3.6,72.42]],"atb":[[3.55,39.29],[3.6,72.42]],"id":88302242},{"batb":[],"atb":[[9.2,21.95],[9,9.97]],"id":97736949}],"tv":34657.89}],"rt":639159130507831396,"dt":639159130507831952}
{"op":"mcm","id":2,"clk":"AIxVAKE1AOhw","pt":1780316250866,"mc":[{"id":"1.258742455","rc":[{"atl":[[5,15.57]],"batl":[],"id":10398159}]}],"rt":639159130508741965,"dt":639159130508742252}
{"op":"mcm","id":2,"clk":"AJhVAKk1AO9w","pt":1780316250978,"mc":[{"id":"1.258742455","rc":[{"batb":[[0,4.6,42.58]],"atb":[[4.6,42.58]],"id":10398159},{"tv":2123.42,"batb":[[2,9.4,8.93],[1,9.6,12.29],[0,9.8,35.12]],"trd":[[10,104.55]],"ltp":10,"atb":[[10,0]],"atl":[[10,8.69]],"batl":[[2,11,38.37],[1,10.5,20.94],[0,10,8.69]],"id":97736949}],"tv":34720.5}],"rt":639159130509861406,"dt":639159130509861941}
{"op":"mcm","id":2,"clk":"AJ1VAKw1APVw","pt":1780316251072,"mc":[{"id":"1.258742455","rc":[{"batb":[[0,4.6,61.66]],"atb":[[4.6,61.66]],"id":10398159},{"batb":[[0,9.8,29.6]],"atb":[[8.8,6.38],[9.8,29.6],[8.6,9.96]],"id":97736949}]}],"rt":639159130510798342,"dt":639159130510798883}
{"op":"mcm","id":2,"clk":"AKhVALQ1AINx","pt":1780316251182,"mc":[{"id":"1.258742455","rc":[{"atl":[[5,9.57]],"batl":[],"id":10398159},{"tv":2127.06,"batb":[[1,9.6,19.37]],"trd":[[10,108.19]],"atb":[[9.2,6.85],[9.6,19.37]],"atl":[[12.5,2.72],[10,13.67]],"batl":[[0,10,13.67]],"id":97736949}],"tv":34724.14}],"rt":639159130511904804,"dt":639159130511905240}
{"op":"mcm","id":2,"clk":"ALFVALo1AIpx","pt":1780316251287,"mc":[{"id":"1.258742455","rc":[{"atl":[[5.8,36.04]],"batl":[],"id":99072898},{"batb":[],"atb":[[4.1,39.34]],"id":10398159},{"batb":[[0,9.8,26.13]],"atb":[[9.8,26.13]],"id":97736949}]}],"rt":639159130512955879,"dt":639159130512956184}
{"op":"mcm","id":2,"clk":"ALlVAL41AJZx","pt":1780316251390,"mc":[{"id":"1.258742455","rc":[{"tv":385.02,"batb":[[2,65,2.84],[1,70,5.77],[0,75,5.84]],"trd":[[95,31.62],[90,33.39],[85,36.32],[80,73.02],[75,19.29]],"ltp":75,"atb":[[95,0],[90,0],[85,0],[80,0],[75,5.84]],"id":99072901},{"atl":[[5.1,42.18]],"batl":[],"id":10398159},{"atl":[[4.1,11.54]],"batl":[],"id":88302242},{"batb":[[0,9.8,25.13]],"atb":[[9.8,25.13]],"id":97736949}],"tv":34744.15}],"rt":639159130513982716,"dt":639159130513983206}
{"op":"mcm","id":2,"clk":"AMBVAMM1AJtx","pt":1780316251491,"mc":[{"id":"1.258742455","rc":[{"tv":7849.29,"batb":[[0,4.6,59.84]],"trd":[[4.6,1062.59]],"atb":[[4.2,25.29],[4.6,59.84]],"id":10398159}],"tv":34747.79}],"rt":639159130514996169,"dt":639159130514996772}
{"op":"mcm","id":2,"clk":"AMhVAMk1AKZx","pt":1780316251593,"mc":[{"id":"1.258742455","rc":[{"batb":[[2,70,5.77],[1,75,6.98],[0,80,1]],"atb":[[80,1],[75,6.98]],"atl":[[100,0.64],[95,2.93]],"batl":[[2,120,1.11],[1,110,5.7],[0,95,2.93]],"id":99072901}]}],"rt":639159130516011839,"dt":639159130516012222}
{"op":"mcm","id":2,"clk":"ANJVAM41ALBx","pt":1780316251700,"mc":[{"id":"1.258742455","rc":[{"batb":[[0,80,1.57]],"atb":[[80,1.57]],"id":99072901}]}],"rt":639159130517083228,"dt":639159130517083604}
{"op":"mcm","id":2,"clk":"ANZVANA1ALdx","pt":1780316251799,"mc":[{"id":"1.258742455","rc":[{"atl":[[5,18.71]],"batl":[[0,5,18.71]],"id":99072898},{"atl":[[25,5.74]],"batl":[[0,25,5.74]],"id":99072900},{"batb":[[1,75,5.84],[0,80,2.64]],"atb":[[80,2.64],[75,5.84]],"id":99072901},{"batb":[[1,4.5,138.17]],"atb":[[4.5,138.17]],"id":10398159},{"batb":[[0,9.8,26]],"atb":[[9.8,26]],"id":97736949}]}],"rt":639159130518069335,"dt":639159130518069960}
{"op":"mcm","id":2,"clk":"ANpVANY1AL5x","pt":1780316251895,"mc":[{"id":"1.258742455","rc":[{"batb":[[0,80,2.07]],"atb":[[80,2.07]],"id":99072901}]}],"rt":639159130519039508,"dt":639159130519040062}
{"op":"mcm","id":2,"clk":"AOVVANw1AMdx","pt":1780316252000,"mc":[{"id":"1.258742455","rc":[{"batb":[[0,44,3.16]],"atb":[[46,0.2]],"id":98464183},{"atl":[[3.7,25.54]],"batl":[[0,3.7,25.54]],"id":88302242},{"batb":[[0,9.8,28.04]],"atb":[[9.8,28.04]],"id":97736949},{"atl":[[200,0.41]],"batl":[[2,230,1.09],[1,220,1.13],[0,210,1.15]],"id":99072897}]}],"rt":639159130520078394,"dt":639159130520078821}
{"op":"mcm","id":2,"clk":"AOlVAN41AMxx","pt":1780316252096,"mc":[{"id":"1.258742455","rc":[{"atl":[[95,3.39]],"batl":[[0,95,3.39]],"id":99072901},{"batb":[[1,170,3.4]],"atb":[[170,3.4]],"id":99072897}]}],"rt":639159130521046993,"dt":639159130521047352}
{"op":"mcm","id":2,"clk":"AOtVAOQ1ANNx","pt":1780316252199,"mc":[{"id":"1.258742455","rc":[{"batb":[],"atb":[[8.8,11.2]],"atl":[[11.5,12.38]],"batl":[],"id":98117699},{"tv":2127.39,"trd":[[10,108.52]],"atl":[[10,13.5]],"batl":[[0,10,13.5]],"id":97736949}],"tv":34748.12}],"rt":639159130522072394,"dt":639159130522072967}
{"op":"mcm","id":2,"clk":"AO1VAOc1ANpx","pt":1780316252253,"mc":[{"id":"1.258742455","rc":[{"batb":[[2,4.4,140.52]],"atb":[[4.4,140.52]],"id":10398159},{"batb":[[0,44,3.3]],"atb":[[46,0.34]],"id":98464183},{"atl":[[10,6.7]],"batl":[[0,10,6.7]],"id":97736949}]}],"rt":639159130522623982,"dt":639159130522624387}
{"op":"mcm","id":2,"clk":"APJVAOs1AN9x","pt":1780316252358,"mc":[{"id":"1.258742455","rc":[{"tv":524.16,"batb":[[0,46,1.68]],"trd":[[46,63.85]],"atb":[[46,1.68]],"id":97008932},{"batb":[[0,9.8,30.42]],"atb":[[9.8,30.42]],"id":97736949}],"tv":34752.13}],"rt":639159130523661570,"dt":639159130523662103}
{"op":"mcm","id":2,"clk":"APlVAPU1AOdx","pt":1780316252462,"mc":[{"id":"1.258742455","rc":[{"batb":[[2,40,6.32],[1,42,11.1],[0,44,5.52]],"atb":[[46,0.53]],"id":97008932},{"tv":2128.27,"trd":[[10,109.4]],"atl":[[10,6.26]],"batl":[[0,10,6.26]],"id":97736949}],"tv":34753.01}],"rt":639159130524698416,"dt":639159130524698817}
{"op":"mcm","id":2,"clk":"AP5VAPs1AOxx","pt":1780316252564,"mc":[{"id":"1.258742455","rc":[{"tv":826.09,"trd":[[48,65.3]],"atl":[[48,1.52]],"batl":[[0,48,1.52]],"id":98464183}],"tv":34753.05}],"rt":639159130525717722,"dt":639159130525718108}
{"op":"mcm","id":2,"clk":"AIRWAII2APRx","pt":1780316252670,"mc":[{"id":"1.258742455","rc":[{"batb":[[0,44,7.33]],"atb":[[44,6.8]],"id":97008932},{"tv":7851.04,"batb":[[0,4.6,58.97]],"trd":[[4.6,1064.34]],"atb":[[4.6,58.97]],"id":10398159}],"tv":34754.8}],"rt":639159130526780429,"dt":639159130526780963}
{"op":"mcm","id":2,"clk":"ALJWAJ42AKFy","pt":1780316253385,"mc":[{"id":"1.258742455","rc":[{"tv":2141.25,"batb":[[0,9.8,23.93]],"trd":[[9.8,12.98]],"ltp":9.8,"atb":[[9.8,23.93]],"id":97736949}],"tv":34767.78}],"rt":639159130533938691,"dt":639159130533939123}
{"op":"mcm","id":2,"clk":"ALZWAKI2AKhy","pt":1780316253490,"mc":[{"id":"1.258742455","rc":[{"atl":[[5.9,6.52]],"batl":[],"id":99072898},{"atl":[[4.7,50.42]],"batl":[[0,4.7,50.42]],"id":10398159}]}],"rt":639159130534978474,"dt":639159130534978836}
{"op":"mcm","id":2,"clk":"ANRWALs2AMZy","pt":1780316254001,"mc":[{"id":"1.258742455","rc":[{"batb":[],"atb":[[9,15.97]],"atl":[[12,16.75]],"batl":[],"id":97736949}]}],"rt":639159130540087642,"dt":639159130540087995}
{"op":"mcm","id":2,"clk":"AOBWAL82AMxy","pt":1780316254103,"mc":[{"id":"1.258742455","rc":[{"batb":[[0,4.8,55.55]],"atb":[[4.8,55.55]],"id":99072898},{"batb":[[0,44,7.64]],"atb":[[44,7.11]],"id":97008932},{"batb":[[0,24,20.74]],"atb":[[24,20.74]],"id":99072900},{"batb":[[0,80,2.24]],"atb":[[80,2.24]],"id":99072901},{"batb":[[0,4.6,61.97]],"atb":[[4.6,61.97]],"id":10398159},{"batb":[[0,44,3.61]],"atb":[[44,3.27]],"id":98464183},{"batb":[[0,9.6,11.44]],"atb":[[9.6,11.44]],"id":98117699},{"tv":12035.47,"batb":[[0,3.6,76.26]],"trd":[[3.75,247.58],[3.7,213.86]],"ltp":3.75,"atb":[[3.6,76.26]],"atl":[[3.75,4.46],[3.7,0]],"batl":[[2,3.85,57.33],[1,3.8,5.46],[0,3.75,4.46]],"id":88302242},{"batb":[[0,9.8,25.34]],"atb":[[9.8,25.34]],"id":97736949},{"batb":[[0,1000,92.97]],"atb":[[1000,92.97]],"id":10445502},{"batb":[[0,180,3.27]],"atb":[[180,3.1]],"id":99072897}],"tv":34838.04}],"rt":639159130541116592,"dt":639159130541117456}
{"op":"mcm","id":2,"clk":"AOZWAMY2ANNy","pt":1780316254202,"mc":[{"id":"1.258742455","rc":[{"batb":[[2,3.55,48.8],[1,3.6,76.26],[0,3.65,11.05]],"atb":[[3.65,11.05],[3.55,48.8]],"id":88302242},{"atl":[[10,13.17]],"batl":[[0,10,13.17]],"id":97736949}]}],"rt":639159130542102356,"dt":639159130542102744}
{"op":"mcm","id":2,"clk":"APJWAMo2AN1y","pt":1780316254256,"mc":[{"id":"1.258742455","rc":[{"batb":[[0,3.65,16.71]],"atb":[[3.65,16.71]],"id":88302242},{"batb":[[0,9.8,17.5]],"atb":[[9.8,17.5]],"id":97736949}]}],"rt":639159130542642285,"dt":639159130542642700}
{"op":"mcm","id":2,"clk":"AP1WANE2AORy","pt":1780316254361,"mc":[{"id":"1.258742455","rc":[{"tv":525.22,"batb":[[0,44,7.11]],"trd":[[46,64.91]],"atb":[[46,0]],"atl":[[46,0.65]],"batl":[[0,48,5.17]],"id":97008932},{"batb":[[0,3.65,32.33]],"atb":[[3.65,32.33],[3.4,28.12]],"atl":[[3.85,31.71]],"batl":[[2,3.85,31.71]],"id":88302242},{"batb":[],"atb":[[8.4,27.26],[8.6,6.48]],"atl":[[10,16.39]],"batl":[[0,10,16.39]],"id":97736949}],"tv":34839.1}],"rt":639159130543692204,"dt":639159130543692673}
{"op":"mcm","id":2,"clk":"AIhXANY2AO1y","pt":1780316254467,"mc":[{"id":"1.258742455","rc":[{"atl":[[180,0.2]],"id":97008932},{"batb":[[2,3.6,85.69],[1,3.65,32.33],[0,3.7,10.41]],"atb":[[3.7,10.41],[3.6,85.69]],"atl":[[3.75,1.04]],"batl":[[0,3.75,1.04]],"id":88302242},{"tv":2176.25,"batb":[[2,9.2,6.85],[1,9.4,8.93],[0,9.6,19.37]],"trd":[[9.8,47.98]],"atb":[[9.8,0]],"atl":[[9.8,6.62],[12,9.57]],"batl":[[2,10.5,20.94],[1,10,16.39],[0,9.8,6.62]],"id":97736949}],"tv":34874.1}],"rt":639159130544749362,"dt":639159130544750125}
{"op":"mcm","id":2,"clk":"AJBXANo2APFy","pt":1780316254567,"mc":[{"id":"1.258742455","rc":[{"batb":[],"atb":[[3.55,47.93],[3.4,22.12]],"atl":[[3.75,1.8],[3.9,30.86],[3.8,15.27]],"batl":[[1,3.8,15.27],[0,3.75,1.8]],"id":88302242},{"batb":[[1,9.4,15.59],[0,9.6,12.77]],"atb":[[9.4,15.59],[9.6,12.77]],"id":97736949}]}],"rt":639159130545750131,"dt":639159130545750739}
{"op":"mcm","id":2,"clk":"AJZXAOA2APhy","pt":1780316254671,"mc":[{"id":"1.258742455","rc":[{"batb":[[0,9.6,1.99]],"atb":[[9.6,1.99]],"id":97736949}]}],"rt":639159130546789117,"dt":639159130546789447}
{"op":"mcm","id":2,"clk":"AJxXAOY2AIJz","pt":1780316254774,"mc":[{"id":"1.258742455","rc":[{"batb":[],"atb":[[1.17,195.99],[3.45,43.48]],"atl":[[4.2,32.82],[3.95,9.41]],"batl":[],"id":88302242},{"batb":[],"atb":[[8.4,23.76],[8.2,13.62],[9,9.97]],"atl":[[12,3.57]],"batl":[],"id":97736949}]}],"rt":639159130547821019,"dt":639159130547821699}
{"op":"mcm","id":2,"clk":"AKBXAOc2AIlz","pt":1780316254874,"mc":[{"id":"1.258742455","rc":[{"tv":12035.73,"batb":[[0,3.7,15.85]],"trd":[[3.7,214.12]],"ltp":3.7,"atb":[[1.17,195.12],[3.7,15.85]],"id":88302242},{"atl":[[9.8,9.73]],"batl":[[0,9.8,9.73]],"id":97736949}],"tv":34874.36}],"rt":639159130548817804,"dt":639159130548818177}
{"op":"mcm","id":2,"clk":"AKdXAPI2AJVz","pt":1780316254979,"mc":[{"id":"1.258742455","rc":[{"batb":[[0,3.7,16.72]],"atb":[[3.7,16.72]],"id":88302242},{"batb":[],"atb":[[8.8,12.38]],"atl":[[11.5,16.82],[11,38.25]],"batl":[],"id":97736949}]}],"rt":639159130549874396,"dt":639159130549874787}
{"op":"mcm","id":2,"clk":"ALBXAPc2AKBz","pt":1780316255080,"mc":[{"id":"1.258742455","rc":[{"batb":[[0,44,3.64]],"atb":[[46,0.37]],"id":98464183},{"batb":[[2,9,9.97],[1,9.2,6.85],[0,9.4,15.59]],"atb":[[9.6,0]],"id":97736949}]}],"rt":639159130550879109,"dt":639159130550879672}
{"op":"mcm","id":2,"clk":"ALxXAIM3ALRz","pt":1780316255284,"mc":[{"id":"1.258742455","rc":[{"atl":[[5,20.41]],"batl":[[0,5,20.41]],"id":99072898},{"atl":[[1000,0.42],[50,12.27],[48,4.66]],"batl":[[1,50,12.27],[0,48,5.31]],"id":97008932},{"batb":[[1,23,12.09]],"atb":[[23,12.09]],"atl":[[25,5.14]],"batl":[[0,25,5.14]],"id":99072900},{"batb":[[1,4.5,133.71]],"atb":[[1.17,2.77],[4.5,133.71]],"atl":[[4.7,49.43],[1000,1.17]],"batl":[[0,4.7,49.43]],"id":10398159},{"atl":[[1000,1.49],[11,37.52],[10.5,20.39]],"batl":[[2,10.5,20.39]],"id":97736949}]}],"rt":639159130552921909,"dt":639159130552922408}
{"op":"mcm","id":2,"clk":"AMhXAIo3AMVz","pt":1780316255401,"mc":[{"id":"1.258742455","rc":[{"atl":[[1000,0.22]],"id":97008932},{"atb":[[1.17,2]],"atl":[[1000,1.01]],"id":10398159},{"batb":[],"atb":[[3.45,37.48]],"id":88302242},{"batb":[[0,9.4,15.77]],"atb":[[9.6,0.18]],"atl":[[1000,1]],"id":97736949}]}],"rt":639159130554087394,"dt":639159130554087803}
{"op":"mcm","id":2,"clk":"AMtXAI83AMpz","pt":1780316255491,"mc":[{"id":"1.258742455","rc":[{"atl":[[46,0.85]],"batl":[[0,48,5.51]],"id":97008932},{"batb":[[0,4.6,62.74]],"atb":[[4.6,62.74]],"atl":[[4.8,80.68]],"batl":[[1,4.8,80.68]],"id":10398159},{"tv":2176.61,"batb":[[0,9.4,15.59]],"trd":[[9.6,0.36]],"ltp":9.6,"atb":[[8.4,26.76],[8.8,6.38],[9.6,0]],"atl":[[10,16.88]],"batl":[[1,10,16.88]],"id":97736949}],"tv":34874.72}],"rt":639159130554988609,"dt":639159130554989319}
{"op":"mcm","id":2,"clk":"ANFXAJM3ANZz","pt":1780316255595,"mc":[{"id":"1.258742455","rc":[{"batb":[],"atb":[[3.5,92.1]],"id":88302242},{"tv":2178.65,"trd":[[9.8,50.02]],"ltp":9.8,"atl":[[9.8,8.71]],"batl":[[0,9.8,8.71]],"id":97736949}],"tv":34876.76}],"rt":639159130556030041,"dt":639159130556030577}
{"op":"mcm","id":2,"clk":"ANZXAJU3ANxz","pt":1780316255694,"mc":[{"id":"1.258742455","rc":[{"batb":[],"atb":[[8.6,12.48]],"id":97736949}]}],"rt":639159130557024838,"dt":639159130557025126}
{"op":"mcm","id":2,"clk":"ANtXAJw3AONz","pt":1780316255796,"mc":[{"id":"1.258742455","rc":[{"atl":[[48,5.95]],"batl":[[0,48,6.8]],"id":97008932},{"batb":[],"atb":[[8.4,27.76],[8.8,7.38],[8.6,13.48]],"id":97736949}]}],"rt":639159130558045234,"dt":639159130558045730}
{"op":"mcm","id":2,"clk":"AIRYAMg3AJV0","pt":1780316256568,"mc":[{"id":"1.258742455","rc":[{"tv":12039.73,"batb":[[0,3.7,14.72]],"trd":[[3.7,218.12]],"atb":[[3.7,14.72]],"id":88302242}],"tv":34880.76}],"rt":639159130565770234,"dt":639159130565770701}
{"op":"mcm","id":2,"clk":"AIlYAMs3AJx0","pt":1780316256673,"mc":[{"id":"1.258742455","rc":[{"atl":[[3.75,9.3]],"batl":[[0,3.75,9.3]],"id":88302242}]}],"rt":639159130566813477,"dt":639159130566814044}
{"op":"mcm","id":2,"clk":"AJBYANM3AKN0","pt":1780316256775,"mc":[{"id":"1.258742455","rc":[{"atl":[[6,16.83]],"id":99072898}]}],"rt":639159130567836081,"dt":639159130567837041}
{"op":"mcm","id":2,"clk":"AJpYANU3AKh0","pt":1780316256874,"mc":[{"id":"1.258742455","rc":[{"batb":[[0,3.7,9.15]],"atb":[[3.7,9.15]],"atl":[[3.75,14.66],[3.9,57.64],[3.85,3.4]],"batl":[[2,3.85,3.4],[0,3.75,14.66]],"id":88302242}]}],"rt":639159130568818272,"dt":639159130568818717}
{"op":"mcm","id":2,"clk":"AJ5YANk3ALF0","pt":1780316256978,"mc":[{"id":"1.258742455","rc":[{"batb":[[2,3.55,47.93],[1,3.6,85.69],[0,3.65,33.2]],"atb":[[3.7,0.87]],"id":88302242}]}],"rt":639159130569867409,"dt":639159130569867809}
{"op":"mcm","id":2,"clk":"AKtYAOY3AMF0","pt":1780316257286,"mc":[{"id":"1.258742455","rc":[{"batb":[[2,3.6,85.69],[1,3.65,32.33],[0,3.7,8.37]],"atb":[[3.7,8.37]],"id":88302242}]}],"rt":639159130572940842,"dt":639159130572941239}
{"op":"mcm","id":2,"clk":"ALJYAOk3AMh0","pt":1780316257385,"mc":[{"id":"1.258742455","rc":[{"batb":[],"atb":[[3.5,86.1]],"id":88302242}]}],"rt":639159130573929392,"dt":639159130573929979}
{"op":"mcm","id":2,"clk":"ALtYAO83ANJ0","pt":1780316257493,"mc":[{"id":"1.258742455","rc":[{"tv":909.27,"batb":[[0,24,19.74]],"trd":[[24,93.17]],"ltp":24,"atb":[[24,19.74]],"id":99072900}],"tv":34882.76}],"rt":639159130575008714,"dt":639159130575009162}
{"op":"mcm","id":2,"clk":"AMNYAPY3AOJ0","pt":1780316257691,"mc":[{"id":"1.258742455","rc":[{"batb":[[0,4.8,56.61]],"atb":[[4.8,56.61]],"id":99072898},{"batb":[[0,4.6,63.85]],"atb":[[4.6,63.85]],"id":10398159},{"batb":[[0,3.7,9.74]],"atb":[[3.7,9.74],[3.45,43.48]],"id":88302242},{"batb":[[0,1000,92.98]],"atb":[[1000,92.98]],"id":10445502}]}],"rt":639159130576997708,"dt":639159130576998092}
{"op":"mcm","id":2,"clk":"AMhYAPs3AOl0","pt":1780316257796,"mc":[{"id":"1.258742455","rc":[{"atb":[[1.17,2.3]],"id":98464183},{"tv":12049.77,"batb":[[0,3.7,3.85]],"trd":[[3.7,228.16]],"atb":[[3.7,3.85]],"atl":[[3.75,18.81]],"batl":[[0,3.75,18.81]],"id":88302242},{"tv":2186.87,"batb":[[0,9.4,20.81]],"trd":[[9.8,58.24]],"atb":[[9.4,20.81]],"atl":[[9.8,4.6]],"batl":[[0,9.8,4.6]],"id":97736949}],"tv":34901.02}],"rt":639159130578042458,"dt":639159130578043404}
{"op":"mcm","id":2,"clk":"AMtYAIA4APF0","pt":1780316257899,"mc":[{"id":"1.258742455","rc":[{"tv":12057.47,"batb":[[2,3.55,47.93],[1,3.6,85.69],[0,3.65,32.33]],"trd":[[3.7,235.86]],"atb":[[3.7,0]],"atl":[[3.7,10.55]],"batl":[[2,3.8,15.27],[1,3.75,18.81],[0,3.7,10.55]],"id":88302242},{"batb":[[2,9.2,6.85],[1,9.4,20.81],[0,9.6,6.5]],"atb":[[9.6,6.5]],"id":97736949}],"tv":34908.72}],"rt":639159130579071785,"dt":639159130579072549}
{"op":"mcm","id":2,"clk":"AM1YAIs4APd0","pt":1780316258001,"mc":[{"id":"1.258742455","rc":[{"atb":[[1.17,2]],"id":98464183},{"batb":[],"atb":[[8.4,31.33]],"atl":[[9.8,1.49]],"batl":[[0,9.8,1.49]],"id":97736949}]}],"rt":639159130580092782,"dt":639159130580093159}
{"op":"mcm","id":2,"clk":"ANRYAJI4AIB1","pt":1780316258105,"mc":[{"id":"1.258742455","rc":[{"tv":826.33,"batb":[[0,44,3.82]],"trd":[[48,65.54]],"atb":[[46,0.55]],"atl":[[48,1.4]],"batl":[[0,48,1.4]],"id":98464183},{"atb":[[1.17,2.95]],"id":97736949}],"tv":34908.96}],"rt":639159130581130883,"dt":639159130581131587}
{"op":"mcm","id":2,"clk":"ANZYAJU4AId1","pt":1780316258203,"mc":[{"id":"1.258742455","rc":[{"atb":[[1.17,2]],"id":97736949}]}],"rt":639159130582113673,"dt":639159130582113986}
{"op":"mcm","id":2,"clk":"ANxYAJs4AJV1","pt":1780316258308,"mc":[{"id":"1.258742455","rc":[{"batb":[[0,44,8.27]],"atb":[[44,8.27]],"id":97008932},{"batb":[[1,9.4,23.2],[0,9.6,7.45]],"atb":[[9.4,23.2],[9.6,7.45]],"id":97736949}]}],"rt":639159130583161653,"dt":639159130583162197}
{"op":"mcm","id":2,"clk":"AOZYAJ84AJx1","pt":1780316258410,"mc":[{"id":"1.258742455","rc":[{"atl":[[3.95,3.41]],"batl":[],"id":88302242},{"batb":[],"atb":[[8.6,7.48]],"id":97736949}]}],"rt":639159130584186654,"dt":639159130584187001}
{"op":"mcm","id":2,"clk":"AO9YAKQ4AKp1","pt":1780316258571,"mc":[{"id":"1.258742455","rc":[{"atl":[[3.9,63.64]],"batl":[],"id":88302242},{"batb":[],"atb":[[8.8,13.38]],"id":97736949}]}],"rt":639159130585796273,"dt":639159130585797079}
{"op":"mcm","id":2,"clk":"AIlZALE4AMN1","pt":1780316258973,"mc":[{"id":"1.258742455","rc":[{"batb":[],"atb":[[8.4,23.22],[8.2,11.07]],"id":97736949}]}],"rt":639159130589814594,"dt":639159130589815021}
{"op":"mcm","id":2,"clk":"ALVZAMc4APJ1","pt":1780316259697,"mc":[{"id":"1.258742455","rc":[{"tv":525.28,"batb":[[0,44,8.24]],"trd":[[44,23.89]],"ltp":44,"atb":[[44,8.24]],"id":97008932},{"tv":909.37,"batb":[[0,24,19.69]],"trd":[[24,93.27]],"atb":[[24,19.69]],"id":99072900},{"tv":385.06,"batb":[[0,80,2.22]],"trd":[[80,73.06]],"ltp":80,"atb":[[80,2.22]],"id":99072901},{"tv":7851.58,"batb":[[0,4.6,63.58]],"trd":[[4.6,1064.88]],"atb":[[4.6,63.58]],"id":10398159},{"tv":826.39,"batb":[[0,44,3.79]],"trd":[[46,68.28]],"ltp":46,"atb":[[46,0.52]],"id":98464183},{"tv":2187.23,"batb":[[0,9.6,11.31]],"trd":[[9.6,226.4]],"atb":[[9.6,11.31]],"id":98117699},{"tv":12058.15,"batb":[[0,3.65,31.99]],"trd":[[3.65,145.55]],"ltp":3.65,"atb":[[3.65,31.99]],"id":88302242},{"tv":2190.11,"batb":[[2,9.4,23.2],[1,9.6,7.45],[0,9.8,1.04]],"trd":[[9.8,61.48]],"atb":[[9.8,1.04]],"atl":[[9.8,0]],"batl":[[2,11,37.52],[1,10.5,20.39],[0,10,16.88]],"id":97736949},{"tv":229.78,"batb":[[0,180,3.26]],"trd":[[190,36.52]],"atb":[[190,0.16]],"id":99072897}],"tv":34913.96}],"rt":639159130597057588,"dt":639159130597058916}
{"op":"mcm","id":2,"clk":"ALhZAMk4APh1","pt":1780316259797,"mc":[{"id":"1.258742455","rc":[{"batb":[[1,3.6,76.26]],"atb":[[3.6,76.26]],"id":88302242},{"tv":2192.2,"batb":[[2,9.2,6.85],[1,9.4,23.2],[0,9.6,7.45]],"trd":[[9.8,63.57]],"atb":[[9.8,0]],"atl":[[9.8,4.51]],"batl":[[2,10.5,20.39],[1,10,16.88],[0,9.8,4.51]],"id":97736949}],"tv":34916.05}],"rt":639159130598056996,"dt":639159130598057777}
{"op":"mcm","id":2,"clk":"ALxZAM44AP91","pt":1780316259897,"mc":[{"id":"1.258742455","rc":[{"batb":[[1,3.6,85.68]],"atb":[[3.6,85.68]],"id":88302242},{"atl":[[9.8,9.12]],"batl":[[0,9.8,9.12]],"id":97736949},{"tv":230.1,"batb":[[0,180,3.1]],"trd":[[190,36.84]],"atb":[[190,0]],"atl":[[190,0.43]],"batl":[[0,210,1.58]],"id":99072897}],"tv":34916.37}],"rt":639159130599057865,"dt":639159130599058691}
{"op":"mcm","id":2,"clk":"AMRZANA4AIh2","pt":1780316260000,"mc":[{"id":"1.258742455","rc":[{"atl":[[5,16.37]],"batl":[[0,5,16.37]],"id":99072898},{"batb":[],"atb":[[8.2,5.79]],"id":98117699},{"atb":[[3.1,2.94]],"id":88302242},{"batb":[],"atb":[[8.8,7.38],[8.6,11.07]],"id":97736949}]}],"rt":639159130600080766,"dt":639159130600081843}
{"op":"mcm","id":2,"clk":"AMhZANU4AI52","pt":1780316260106,"mc":[{"id":"1.258742455","rc":[{"batb":[],"atb":[[4.1,56.18]],"id":99072898},{"batb":[],"atb":[[3.9,13.05]],"id":10398159},{"batb":[[1,3.6,76.26]],"atb":[[3.6,76.26]],"id":88302242},{"batb":[[1,9.4,17.98]],"atb":[[9.4,17.98]],"atl":[[11.5,10.82]],"batl":[],"id":97736949},{"batb":[[1,170,1.67]],"atb":[[170,1.67]],"atl":[[200,0.32]],"batl":[[0,210,1.49]],"id":99072897}]}],"rt":639159130601147778,"dt":639159130601148675}
{"op":"mcm","id":2,"clk":"AM1ZANs4AJZ2","pt":1780316260209,"mc":[{"id":"1.258742455","rc":[{"batb":[],"atb":[[9,15.97]],"id":97736949}]}],"rt":639159130602175335,"dt":639159130602175700}
{"op":"mcm","id":2,"clk":"ANFZAN04AKB2","pt":1780316260306,"mc":[{"id":"1.258742455","rc":[{"batb":[],"atb":[[20,3.97]],"id":99072900},{"batb":[],"atb":[[9,15.41]],"atl":[[12,9.57]],"batl":[],"id":97736949}]}],"rt":639159130603139826,"dt":639159130603140462}
{"op":"mcm","id":2,"clk":"ANhZAOI4AK52","pt":1780316260369,"mc":[{"id":"1.258742455","rc":[{"batb":[],"atb":[[38,12.03]],"id":97008932},{"batb":[],"atb":[[8.2,6.4]],"id":98117699},{"atb":[[3.15,5.58]],"id":88302242}]}],"rt":639159130603772233,"dt":639159130603772601}
{"op":"mcm","id":2,"clk":"AOJZAOU4ALp2","pt":1780316260469,"mc":[{"id":"1.258742455","rc":[{"batb":[],"atb":[[4.1,57.4]],"id":99072898},{"batb":[],"atb":[[21,12.68]],"id":99072900},{"tv":7866.96,"batb":[[0,4.6,55.89]],"trd":[[4.6,1080.26]],"atb":[[3.95,49.75],[4.6,55.89]],"id":10398159},{"batb":[],"atb":[[8.4,23.82]],"id":97736949}],"tv":34931.75}],"rt":639159130604766374,"dt":639159130604766933}
{"op":"mcm","id":2,"clk":"AOpZAOg4AMN2","pt":1780316260574,"mc":[{"id":"1.258742455","rc":[{"batb":[],"atb":[[38,12.16]],"id":97008932}]}],"rt":639159130605817237,"dt":639159130605817551}
{"op":"mcm","id":2,"clk":"APlZAPQ4ANJ2","pt":1780316260778,"mc":[{"id":"1.258742455","rc":[{"batb":[],"atb":[[9,9.41]],"id":97736949}]}],"rt":639159130607863286,"dt":639159130607864204}
{"op":"mcm","id":2,"clk":"AIFaAPc4ANl2","pt":1780316260880,"mc":[{"id":"1.258742455","rc":[{"atl":[[12,3.57]],"batl":[],"id":97736949}]}],"rt":639159130608883598,"dt":639159130608883936}
{"op":"mcm","id":2,"clk":"AIRaAP84AN92","pt":1780316260982,"mc":[{"id":"1.258742455","rc":[{"atb":[[42,3.06]],"id":99072901},{"batb":[],"atb":[[8.8,13.38]],"atl":[[11,34.32]],"batl":[],"id":97736949}]}],"rt":639159130609903425,"dt":639159130609904086}
{"op":"mcm","id":2,"clk":"AIxaAIY5AOd2","pt":1780316261086,"mc":[{"id":"1.258742455","rc":[{"atl":[[11,39.23]],"batl":[],"id":97736949}]}],"rt":639159130610945816,"dt":639159130610946172}
{"op":"mcm","id":2,"clk":"AJRaAI85AO52","pt":1780316261194,"mc":[{"id":"1.258742455","rc":[{"atb":[[6,5.81]],"atl":[[11.5,16.82]],"batl":[],"id":97736949}]}],"rt":639159130612017453,"dt":639159130612017847}
{"op":"mcm","id":2,"clk":"AJtaAJY5APt2","pt":1780316261303,"mc":[{"id":"1.258742455","rc":[{"tv":919.65,"batb":[[2,23,12.09],[1,24,19.69],[0,25,10.84]],"trd":[[25,143.56]],"ltp":25,"atb":[[25,10.84]],"atl":[[25,0]],"batl":[[2,28,4.36],[1,27,13.15],[0,26,4.04]],"id":99072900},{"batb":[],"atb":[[4.2,35.29]],"id":10398159}],"tv":34942.03}],"rt":639159130613116103,"dt":639159130613116796}
{"op":"mcm","id":2,"clk":"AJxaAJo5AIR3","pt":1780316261397,"mc":[{"id":"1.258742455","rc":[{"batb":[[0,25,13.33]],"atb":[[25,13.33]],"id":99072900},{"batb":[[1,9.4,15.59],[0,9.6,9.84]],"atb":[[9.4,15.59],[9.6,9.84]],"id":97736949}]}],"rt":639159130614048880,"dt":639159130614049605}
{"op":"mcm","id":2,"clk":"AKRaAKI5AIx3","pt":1780316261499,"mc":[{"id":"1.258742455","rc":[{"atl":[[6.2,7.11]],"id":99072898},{"tv":921.55,"batb":[[0,25,17.01]],"trd":[[25,145.46]],"atb":[[25,17.01]],"atl":[[26,3.05]],"batl":[[0,26,3.05]],"id":99072900},{"batb":[[0,4.6,57.89]],"atb":[[4.6,57.89]],"id":10398159}],"tv":34943.93}],"rt":639159130615070842,"dt":639159130615071519}
{"op":"mcm","id":2,"clk":"AK9aAKk5AJx3","pt":1780316261603,"mc":[{"id":"1.258742455","rc":[{"tv":955.57,"batb":[[2,22,21.61],[1,23,12.09],[0,24,19.69]],"trd":[[25,179.48]],"atb":[[25,0]],"id":99072900}],"tv":34977.95}],"rt":639159130616113955,"dt":639159130616114409}
{"op":"mcm","id":2,"clk":"ALJaAK45AKF3","pt":1780316261704,"mc":[{"id":"1.258742455","rc":[{"batb":[[2,23,12.09],[1,24,19.69],[0,25,1.5]],"atb":[[25,1.5]],"id":99072900}]}],"rt":639159130617123275,"dt":639159130617123736}
{"op":"mcm","id":2,"clk":"ALdaALQ5AKd3","pt":1780316261805,"mc":[{"id":"1.258742455","rc":[{"tv":958.57,"batb":[[2,22,21.61],[1,23,12.09],[0,24,19.69]],"trd":[[25,182.48]],"atb":[[25,0]],"atl":[[26,4.5],[25,2.5]],"batl":[[2,27,13.15],[1,26,4.5],[0,25,2.5]],"id":99072900}],"tv":34980.95}],"rt":639159130618127896,"dt":639159130618128619}
{"op":"mcm","id":2,"clk":"AMRaAL85ALR3","pt":1780316262009,"mc":[{"id":"1.258742455","rc":[{"tv":526.98,"batb":[[2,42,11.1],[1,44,8.24],[0,46,1.81]],"trd":[[46,66.61]],"ltp":46,"atb":[[46,1.81]],"atl":[[46,0]],"batl":[[0,48,5.95]],"id":97008932},{"tv":2197.52,"trd":[[9.8,68.89]],"atl":[[9.8,6.46]],"batl":[[0,9.8,6.46]],"id":97736949}],"tv":34987.97}],"rt":639159130620175720,"dt":639159130620176369}
{"op":"mcm","id":2,"clk":"AM9aAMg5AMZ3","pt":1780316262170,"mc":[{"id":"1.258742455","rc":[{"batb":[[1,44,6.43],[0,46,3.46]],"atb":[[46,3.46],[44,6.43]],"id":97008932}]}],"rt":639159130621787983,"dt":639159130621788339}
{"op":"mcm","id":2,"clk":"ANZaANA5ANB3","pt":1780316262274,"mc":[{"id":"1.258742455","rc":[{"batb":[],"atb":[[3.4,12.52]],"atl":[[3.7,12.55]],"batl":[[0,3.7,12.55]],"id":88302242}]}],"rt":639159130622818591,"dt":639159130622819033}
{"op":"mcm","id":2,"clk":"ANxaANU5ANp3","pt":1780316262371,"mc":[{"id":"1.258742455","rc":[{"atl":[[9.8,0.81]],"batl":[[2,11,39.23],[1,10.5,20.39],[0,10,17.69]],"id":97736949}]}],"rt":639159130623794138,"dt":639159130623794505}
{"op":"mcm","id":2,"clk":"AONaANk5AOB3","pt":1780316262473,"mc":[{"id":"1.258742455","rc":[{"atl":[[3.7,14.45]],"batl":[[0,3.7,14.45]],"id":88302242}]}],"rt":639159130624816823,"dt":639159130624817558}
{"op":"mcm","id":2,"clk":"AOpaAOI5AOt3","pt":1780316262576,"mc":[{"id":"1.258742455","rc":[{"atl":[[11.5,10.82]],"batl":[],"id":97736949}]}],"rt":639159130625838363,"dt":639159130625838668}
{"op":"mcm","id":2,"clk":"APhaAOw5AP53","pt":1780316262786,"mc":[{"id":"1.258742455","rc":[{"batb":[[0,46,4.71]],"atb":[[46,4.71]],"id":97008932},{"atl":[[12,9.57]],"batl":[],"id":97736949}]}],"rt":639159130627942020,"dt":639159130627942578}
{"op":"mcm","id":2,"clk":"AIBbAPA5AIZ4","pt":1780316262889,"mc":[{"id":"1.258742455","rc":[{"tv":7920.96,"trd":[[4.7,700.96]],"ltp":4.7,"atl":[[4.7,22.43]],"batl":[[0,4.7,22.43]],"id":10398159},{"atl":[[9.8,6.38]],"batl":[[2,10.5,20.39],[1,10,16.88],[0,9.8,6.38]],"id":97736949}],"tv":35041.97}],"rt":639159130628969884,"dt":639159130628970279}
{"op":"mcm","id":2,"clk":"AIRbAPY5AJB4","pt":1780316262997,"mc":[{"id":"1.258742455","rc":[{"tv":2204.84,"batb":[[0,9.6,3.34]],"trd":[[9.6,7.68]],"ltp":9.6,"atb":[[9.6,3.34]],"atl":[[13,4.72],[12.5,4.71],[12,11.56]],"batl":[],"id":97736949}],"tv":35049.29}],"rt":639159130630057836,"dt":639159130630058353}
{"op":"mcm","id":2,"clk":"AItbAPw5AJd4","pt":1780316263091,"mc":[{"id":"1.258742455","rc":[{"batb":[[0,4.6,65.5]],"atb":[[4.6,65.5]],"atl":[[4.7,16.85]],"batl":[[0,4.7,16.85]],"id":10398159},{"tv":2208.08,"batb":[[2,9.2,12.46],[0,9.6,1.72]],"trd":[[9.6,10.92]],"atb":[[9.2,12.46],[9.6,1.72]],"atl":[[9.8,8.91]],"batl":[[0,9.8,8.91]],"id":97736949}],"tv":35052.53}],"rt":639159130630989360,"dt":639159130630989844}
{"op":"mcm","id":2,"clk":"AJBbAIE6AKF4","pt":1780316263198,"mc":[{"id":"1.258742455","rc":[{"atl":[[48,4.66]],"batl":[[0,48,4.66]],"id":97008932},{"atl":[[11.5,3.87]],"batl":[],"id":97736949}]}],"rt":639159130632062128,"dt":639159130632062627}
{"op":"mcm","id":2,"clk":"AJlbAIY6AKd4","pt":1780316263298,"mc":[{"id":"1.258742455","rc":[{"batb":[[0,4.8,58.38]],"atb":[[4.8,58.38]],"id":99072898},{"tv":2210.74,"batb":[[2,9,9.41],[1,9.2,12.46],[0,9.4,15.98]],"trd":[[9.6,13.58]],"atb":[[9.6,0.39]],"id":97736949}],"tv":35055.19}],"rt":639159130633068259,"dt":639159130633068870}
{"op":"mcm","id":2,"clk":"AKFbAIw6AK94","pt":1780316263404,"mc":[{"id":"1.258742455","rc":[{"batb":[[1,4.5,131.17]],"atb":[[4.5,131.17]],"id":10398159},{"batb":[[1,3.6,77.47]],"atb":[[3.6,77.47]],"id":88302242},{"tv":2213.52,"batb":[[0,9.4,14.59]],"trd":[[9.4,2],[9.6,14.36]],"ltp":9.4,"atb":[[9.4,14.59],[9.6,0]],"atl":[[12,5.56],[9.6,4.79]],"batl":[[2,10,16.88],[1,9.8,8.91],[0,9.6,4.79]],"id":97736949}],"tv":35057.97}],"rt":639159130634127259,"dt":639159130634127891}
{"op":"mcm","id":2,"clk":"AKxbAI86ALh4","pt":1780316263503,"mc":[{"id":"1.258742455","rc":[{"tv":2215.96,"trd":[[9.6,16.8]],"ltp":9.6,"atl":[[9.6,3.57]],"batl":[[0,9.6,3.57]],"id":97736949}],"tv":35060.41}],"rt":639159130635113004,"dt":639159130635113404}
{"op":"mcm","id":2,"clk":"ALRbAJM6AL94","pt":1780316263606,"mc":[{"id":"1.258742455","rc":[{"batb":[[0,46,2.9]],"atb":[[46,2.9]],"id":97008932},{"batb":[[0,9.4,6.93]],"atb":[[9.4,6.93]],"atl":[[11.5,9.87]],"batl":[],"id":97736949}]}],"rt":639159130636147821,"dt":639159130636148203}
{"op":"mcm","id":2,"clk":"ALhbAJg6AMp4","pt":1780316263711,"mc":[{"id":"1.258742455","rc":[{"batb":[[2,3.55,45.93],[1,3.6,86.87]],"atb":[[3.55,45.93],[3.6,86.87]],"id":88302242},{"batb":[],"atb":[[8.8,7.38]],"id":97736949}]}],"rt":639159130637193901,"dt":639159130637260330}
{"op":"mcm","id":2,"clk":"AMNbAJ06ANR4","pt":1780316263814,"mc":[{"id":"1.258742455","rc":[{"batb":[[0,3.65,33.99]],"atb":[[3.65,33.99]],"id":88302242},{"batb":[[0,9.4,2.99]],"atb":[[9.4,2.99]],"id":97736949}]}],"rt":639159130638221438,"dt":639159130638221827}
{"op":"mcm","id":2,"clk":"AMdbAKA6ANx4","pt":1780316263871,"mc":[{"id":"1.258742455","rc":[{"batb":[],"atb":[[8.6,17.07]],"id":97736949}]}],"rt":639159130638793113,"dt":639159130638793437}
{"op":"mcm","id":2,"clk":"AM9bAKE6AOd4","pt":1780316263971,"mc":[{"id":"1.258742455","rc":[{"batb":[],"atb":[[8.6,13.48]],"atl":[[9.6,6.05]],"batl":[[0,9.6,6.05]],"id":97736949}]}],"rt":639159130639795629,"dt":639159130639795983}
{"op":"mcm","id":2,"clk":"ANhbAKQ6AO54","pt":1780316264078,"mc":[{"id":"1.258742455","rc":[{"atl":[[11.5,3.87]],"batl":[],"id":97736949}]}],"rt":639159130640867666,"dt":639159130640868044}
{"op":"mcm","id":2,"clk":"AOVbAK86APx4","pt":1780316264276,"mc":[{"id":"1.258742455","rc":[{"atl":[[11,45.23]],"batl":[],"id":97736949}]}],"rt":639159130642844680,"dt":639159130642845059}
{"op":"mcm","id":2,"clk":"AOlbALM6AIh5","pt":1780316264381,"mc":[{"id":"1.258742455","rc":[{"atb":[[1.17,2.1]],"atl":[[25,2.96]],"batl":[[0,25,2.96]],"id":99072900},{"atb":[[1.17,1.11]],"id":99072901},{"batb":[[0,180,3.4]],"atb":[[180,3.4]],"id":99072897}]}],"rt":639159130643897040,"dt":639159130643897446}
{"op":"mcm","id":2,"clk":"AO5bALk6AI55","pt":1780316264483,"mc":[{"id":"1.258742455","rc":[{"batb":[[1,170,3.4]],"atb":[[170,3.4]],"id":99072897}]}],"rt":639159130644913825,"dt":639159130644914161}
{"op":"mcm","id":2,"clk":"APBbAL46AJN5","pt":1780316264586,"mc":[{"id":"1.258742455","rc":[{"atb":[[1.17,2]],"id":99072900},{"atb":[[1.17,1]],"id":99072901}]}],"rt":639159130645945560,"dt":639159130645946013}
{"op":"mcm","id":2,"clk":"APlbAMI6AJl5","pt":1780316264699,"mc":[{"id":"1.258742455","rc":[{"batb":[[1,23,12.19]],"atb":[[23,12.19]],"id":99072900},{"batb":[[0,80,2.33]],"atb":[[80,2.33]],"id":99072901}]}],"rt":639159130647070517,"dt":639159130647070973}
{"op":"mcm","id":2,"clk":"AIlcAMw6AKl5","pt":1780316264896,"mc":[{"id":"1.258742455","rc":[{"batb":[[1,3.6,90.5]],"atb":[[3.6,90.5]],"id":88302242}]}],"rt":639159130649042671,"dt":639159130649043019}
{"op":"mcm","id":2,"clk":"AJFcAM46ALN5","pt":1780316264999,"mc":[{"id":"1.258742455","rc":[{"tv":2221.28,"trd":[[9.6,22.12]],"atl":[[9.6,3.39]],"batl":[[0,9.6,3.39]],"id":97736949}],"tv":35065.73}],"rt":639159130650075581,"dt":639159130650076044}
{"op":"mcm","id":2,"clk":"AJ9cANw6AMR5","pt":1780316265208,"mc":[{"id":"1.258742455","rc":[{"tv":2225.28,"batb":[[2,8.8,7.38],[1,9,9.41],[0,9.2,13.45]],"trd":[[9.4,6]],"ltp":9.4,"atb":[[9.4,0.99]],"id":97736949}],"tv":35069.73}],"rt":639159130652157190,"dt":639159130652157704}
{"op":"mcm","id":2,"clk":"AKtcAOY6ANh5","pt":1780316265406,"mc":[{"id":"1.258742455","rc":[{"atl":[[25,2.86]],"batl":[[0,25,2.86]],"id":99072900},{"atb":[[1.17,2.2]],"id":98464183},{"batb":[[0,9.6,11.15]],"atb":[[9.6,11.15]],"atl":[[1000,6.41]],"id":98117699},{"batb":[[1,9,15.04]],"atb":[[9,15.04]],"id":97736949},{"batb":[[1,170,1.67]],"atb":[[170,1.67]],"id":99072897}]}],"rt":639159130654141641,"dt":639159130654142141}
{"op":"mcm","id":2,"clk":"ALBcAOk6AON5","pt":1780316265510,"mc":[{"id":"1.258742455","rc":[{"tv":536.3,"batb":[[0,46,3.57]],"trd":[[48,41]],"ltp":48,"atb":[[48,0.67]],"atl":[[48,0]],"batl":[[2,60,2.6],[1,55,19.43],[0,50,12.27]],"id":97008932},{"atb":[[1.17,2]],"id":98464183},{"atl":[[1000,6.25]],"id":98117699}],"tv":35079.05}],"rt":639159130655184736,"dt":639159130655185182}
{"op":"mcm","id":2,"clk":"ALZcAOw6AOx5","pt":1780316265565,"mc":[{"id":"1.258742455","rc":[{"tv":826.59,"batb":[[0,44,3.89]],"trd":[[48,65.74]],"ltp":48,"atb":[[46,0.62]],"atl":[[48,1.3]],"batl":[[0,48,1.3]],"id":98464183},{"atl":[[9.8,3.16]],"batl":[[0,9.8,3.16]],"id":98117699},{"batb":[],"atb":[[8.6,7.48]],"id":97736949}],"tv":35079.25}],"rt":639159130655734399,"dt":639159130655734855}
{"op":"mcm","id":2,"clk":"ALxcAPE6APN5","pt":1780316265670,"mc":[{"id":"1.258742455","rc":[{"atl":[[100,2.61]],"id":97008932}]}],"rt":639159130656784667,"dt":639159130656784980}
{"op":"mcm","id":2,"clk":"AMJcAPU6APl5","pt":1780316265771,"mc":[{"id":"1.258742455","rc":[{"atl":[[3.7,29.45]],"batl":[[0,3.7,29.45]],"id":88302242},{"batb":[],"atb":[[8.4,29.82]],"id":97736949}]}],"rt":639159130657791923,"dt":639159130657792331}
{"op":"mcm","id":2,"clk":"AMlcAPg6AIB6","pt":1780316265874,"mc":[{"id":"1.258742455","rc":[{"batb":[[1,3.6,81.1]],"atb":[[3.6,81.1]],"atl":[[3.75,18.05]],"batl":[[1,3.75,18.05]],"id":88302242}]}],"rt":639159130658830765,"dt":639159130658831197}
{"op":"mcm","id":2,"clk":"AIJdAJg7AL16","pt":1780316266596,"mc":[{"id":"1.258742455","rc":[{"batb":[[1,44,5.27],[0,46,3.8]],"atb":[[48,0.9],[44,5.27]],"id":97008932},{"batb":[[0,80,2.22]],"atb":[[80,2.22]],"id":99072901},{"atl":[[1000,1.7],[10,16.39]],"batl":[[2,10,16.39]],"id":97736949}]}],"rt":639159130666041535,"dt":639159130666042107}
{"op":"mcm","id":2,"clk":"AItdAJs7AMJ6","pt":1780316266698,"mc":[{"id":"1.258742455","rc":[{"atl":[[1000,1]],"id":97736949},{"batb":[[1,170,3.4]],"atb":[[170,3.4]],"id":99072897}]}],"rt":639159130667065306,"dt":639159130667065776}
{"op":"mcm","id":2,"clk":"AJNdAKE7AMV6","pt":1780316266800,"mc":[{"id":"1.258742455","rc":[{"atl":[[9.8,9.31],[9.6,3.69]],"batl":[[1,9.8,9.31],[0,9.6,3.69]],"id":97736949}]}],"rt":639159130668080549,"dt":639159130668080940}
{"op":"mcm","id":2,"clk":"AJddAKU7AMl6","pt":1780316266902,"mc":[{"id":"1.258742455","rc":[{"tv":2247.28,"batb":[[0,9.2,2.45]],"trd":[[9.4,7.98],[9.2,20.02]],"ltp":9.2,"atb":[[9.4,0],[9.2,2.45]],"id":97736949}],"tv":35101.25}],"rt":639159130669102635,"dt":639159130669103019}
{"op":"mcm","id":2,"clk":"AJ5dAKo7ANB6","pt":1780316267005,"mc":[{"id":"1.258742455","rc":[{"atl":[[25,0.36]],"batl":[[2,28,4.36],[1,27,13.15],[0,26,4.86]],"id":99072900},{"batb":[[0,9.6,18.78]],"atb":[[9.6,18.78]],"id":98117699},{"batb":[],"atb":[[3.5,88.89]],"id":88302242}]}],"rt":639159130670136878,"dt":639159130670137408}
{"op":"mcm","id":2,"clk":"AKxdALw7AOJ6","pt":1780316267210,"mc":[{"id":"1.258742455","rc":[{"atl":[[4.9,58.25]],"batl":[[2,4.9,58.25]],"id":10398159}]}],"rt":639159130672185455,"dt":639159130672185852}
{"op":"mcm","id":2,"clk":"ALVdAME7AOl6","pt":1780316267318,"mc":[{"id":"1.258742455","rc":[{"atl":[[4.8,19.6]],"batl":[[1,4.8,19.6]],"id":10398159}]}],"rt":639159130673264473,"dt":639159130673264895}
{"op":"mcm","id":2,"clk":"AMRdAM07APV6","pt":1780316267474,"mc":[{"id":"1.258742455","rc":[{"atl":[[4.7,13.96]],"batl":[[0,4.7,13.96]],"id":10398159},{"atb":[[1.17,2.86]],"atl":[[1000,1.2]],"id":97736949}]}],"rt":639159130674818787,"dt":639159130674819176}
{"op":"mcm","id":2,"clk":"AMhdANA7APt6","pt":1780316267575,"mc":[{"id":"1.258742455","rc":[{"tv":7941.72,"batb":[[0,4.6,55.12]],"trd":[[4.6,1101.02]],"ltp":4.6,"atb":[[4.6,55.12]],"id":10398159},{"atb":[[1.17,2]],"atl":[[1000,1]],"id":97736949}],"tv":35122.01}],"rt":639159130675832383,"dt":639159130675832810}
{"op":"mcm","id":2,"clk":"AMtdANM7AIB7","pt":1780316267674,"mc":[{"id":"1.258742455","rc":[{"batb":[[0,9.2,3.31]],"atb":[[9.2,3.31]],"atl":[[9.8,9.51]],"batl":[[1,9.8,9.51]],"id":97736949}]}],"rt":639159130676818539,"dt":639159130676818857}
{"op":"mcm","id":2,"clk":"AONdAOQ7AJJ7","pt":1780316267981,"mc":[{"id":"1.258742455","rc":[{"batb":[],"atb":[[8.4,26.82]],"id":97736949}]}],"rt":639159130679891184,"dt":639159130679891560}
{"op":"mcm","id":2,"clk":"AOxdAOg7AJd7","pt":1780316268089,"mc":[{"id":"1.258742455","rc":[{"batb":[],"atb":[[8,10]],"id":97736949}]}],"rt":639159130680969239,"dt":639159130680969634}
{"op":"mcm","id":2,"clk":"AINeAO87AKN7","pt":1780316268294,"mc":[{"id":"1.258742455","rc":[{"batb":[[0,4.8,59.38]],"atb":[[4.8,59.38]],"id":99072898},{"batb":[[0,46,4.02]],"atb":[[46,3.12]],"id":97008932},{"batb":[[0,4.6,56.17]],"atb":[[4.6,56.17]],"id":10398159},{"batb":[[0,44,4.12]],"atb":[[44,3.5]],"id":98464183},{"batb":[[0,9.6,19.82]],"atb":[[9.6,19.82]],"id":98117699},{"batb":[[0,3.65,35.31]],"atb":[[3.65,35.31]],"id":88302242},{"batb":[[0,9.2,4.39]],"atb":[[9.2,4.39]],"id":97736949}]}],"rt":639159130683020654,"dt":639159130683021374}
{"op":"mcm","id":2,"clk":"AIheAPM7AKZ7","pt":1780316268394,"mc":[{"id":"1.258742455","rc":[{"tv":2257.28,"batb":[[2,8.6,7.48],[1,8.8,7.38],[0,9,14.43]],"trd":[[9.2,28.8],[9,1.22]],"ltp":9,"atb":[[9.2,0],[9,14.43]],"id":97736949}],"tv":35132.01}],"rt":639159130684024376,"dt":639159130684024891}
{"op":"mcm","id":2,"clk":"AJ5eAPo7AL17","pt":1780316268699,"mc":[{"id":"1.258742455","rc":[{"batb":[],"atb":[[8.4,20.82]],"id":97736949}]}],"rt":639159130687073553,"dt":639159130687073974}
{"op":"mcm","id":2,"clk":"AKleAP87AMV7","pt":1780316268807,"mc":[{"id":"1.258742455","rc":[{"batb":[[2,8.8,7.38],[1,9,14.43],[0,9.2,4.95]],"atb":[[9.2,4.95]],"id":97736949}]}],"rt":639159130688152097,"dt":639159130688152503}
{"op":"mcm","id":2,"clk":"AK9eAII8AMp7","pt":1780316268910,"mc":[{"id":"1.258742455","rc":[{"batb":[],"atb":[[8.2,17.07]],"id":97736949}]}],"rt":639159130689187139,"dt":639159130689187520}
{"op":"mcm","id":2,"clk":"AM5eAKA8AO57","pt":1780316269370,"mc":[{"id":"1.258742455","rc":[{"batb":[],"atb":[[8.2,11.07]],"id":97736949}]}],"rt":639159130693786989,"dt":639159130693787445}
{"op":"mcm","id":2,"clk":"ANReAKc8APZ7","pt":1780316269476,"mc":[{"id":"1.258742455","rc":[{"atl":[[10,10.13]],"batl":[[2,10,10.13]],"id":97736949}]}],"rt":639159130694841933,"dt":639159130694842279}
{"op":"mcm","id":2,"clk":"ANxeAKs8AP57","pt":1780316269582,"mc":[{"id":"1.258742455","rc":[{"atl":[[1000,3.25]],"id":88302242},{"batb":[],"atb":[[1.17,2.35],[8.4,26.82]],"id":97736949}]}],"rt":639159130695902296,"dt":639159130695902699}
{"op":"mcm","id":2,"clk":"AOJeAK88AIJ8","pt":1780316269683,"mc":[{"id":"1.258742455","rc":[{"atl":[[60,5.72]],"batl":[],"id":98464183},{"atl":[[10,6.38]],"batl":[[1,10,6.38]],"id":98117699},{"tv":12072.15,"batb":[[0,3.65,28.31]],"trd":[[3.65,159.55]],"atb":[[3.65,28.31]],"id":88302242},{"batb":[[0,9.2,7.34]],"atb":[[9.2,7.34]],"atl":[[10.5,23.39]],"batl":[],"id":97736949}],"tv":35146.01}],"rt":639159130696918330,"dt":639159130696918833}
{"op":"mcm","id":2,"clk":"AOZeALU8AId8","pt":1780316269792,"mc":[{"id":"1.258742455","rc":[{"batb":[],"atb":[[38,10.24]],"id":97008932},{"atl":[[11,18.06]],"batl":[],"id":98117699},{"atl":[[1000,3]],"id":88302242},{"atb":[[1.17,2]],"id":97736949}]}],"rt":639159130697999948,"dt":639159130698000335}
{"op":"mcm","id":2,"clk":"AOteALs8AJV8","pt":1780316269894,"mc":[{"id":"1.258742455","rc":[{"atl":[[3.7,29.7]],"batl":[[0,3.7,29.7]],"id":88302242},{"batb":[[0,9.2,7.69]],"atb":[[9.4,0.35]],"id":97736949}]}],"rt":639159130699023453,"dt":639159130699023831}
{"op":"mcm","id":2,"clk":"AIlfANA8ALJ8","pt":1780316270309,"mc":[{"id":"1.258742455","rc":[{"tv":7579.21,"batb":[[0,4.8,50.73]],"trd":[[4.8,183.52]],"atb":[[4.8,50.73]],"id":99072898}],"tv":35163.31}],"rt":639159130703174703,"dt":639159130703175102}
{"op":"mcm","id":2,"clk":"AJFfANY8AL58","pt":1780316270410,"mc":[{"id":"1.258742455","rc":[{"batb":[],"atb":[[8.2,27.18]],"id":97736949}]}],"rt":639159130704177917,"dt":639159130704178275}
{"op":"mcm","id":2,"clk":"AJhfANc8AMN8","pt":1780316270511,"mc":[{"id":"1.258742455","rc":[{"tv":7580.85,"trd":[[5,17.54]],"ltp":5,"atl":[[5,15.55]],"batl":[[0,5,15.55]],"id":99072898},{"tv":963.37,"batb":[[0,24,17.29]],"trd":[[24,98.07]],"ltp":24,"atb":[[24,17.29]],"id":99072900}],"tv":35169.75}],"rt":639159130705193932,"dt":639159130705194369}
{"op":"mcm","id":2,"clk":"AKFfAOg8ANJ8","pt":1780316270712,"mc":[{"id":"1.258742455","rc":[{"batb":[[2,4.7,32.27],[1,4.8,50.73],[0,4.9,2.3]],"atb":[[4.9,2.3]],"id":99072898}]}],"rt":639159130707200047,"dt":639159130707200410}
{"op":"mcm","id":2,"clk":"ALtfAPM8AO58","pt":1780316270973,"mc":[{"id":"1.258742455","rc":[{"batb":[],"atb":[[4.4,25.84]],"id":99072898},{"tv":7943.72,"batb":[[0,4.6,55.17]],"trd":[[4.6,1103.02]],"atb":[[4.6,55.17]],"id":10398159}],"tv":35171.75}],"rt":639159130709808858,"dt":639159130709809283}
{"op":"mcm","id":2,"clk":"AM1fAP08AP58","pt":1780316271174,"mc":[{"id":"1.258742455","rc":[{"batb":[],"atb":[[4.5,43.76]],"id":99072898}]}],"rt":639159130711817792,"dt":639159130711818166}
{"op":"mcm","id":2,"clk":"AOJfAJQ9AJN9","pt":1780316271487,"mc":[{"id":"1.258742455","rc":[{"atl":[[5.2,26.03]],"batl":[],"id":10398159}]}],"rt":639159130714953652,"dt":639159130714954032}
{"op":"mcm","id":2,"clk":"APVfAKk9AKh9","pt":1780316271794,"mc":[{"id":"1.258742455","rc":[{"atl":[[3.7,44.7]],"batl":[[0,3.7,44.7]],"id":88302242}]}],"rt":639159130718025258,"dt":639159130718025598}
{"op":"mcm","id":2,"clk":"AIJgALU9AMN9","pt":1780316272102,"mc":[{"id":"1.258742455","rc":[{"batb":[[0,24,17.75]],"atb":[[24,17.75]],"id":99072900},{"batb":[[0,80,2.35]],"atb":[[80,2.35]],"id":99072901},{"atl":[[55,12.75]],"batl":[[2,55,12.75]],"id":98464183},{"atl":[[3.95,21.15]],"batl":[],"id":88302242},{"batb":[[0,180,3.46]],"atb":[[180,3.46]],"id":99072897}]}],"rt":639159130721099613,"dt":639159130721100094}
{"op":"mcm","id":2,"clk":"AItgALs9AM19","pt":1780316272211,"mc":[{"id":"1.258742455","rc":[{"atl":[[5.5,25.63]],"batl":[],"id":99072898},{"atl":[[27,15.28]],"batl":[[1,27,15.28]],"id":99072900}]}],"rt":639159130722193979,"dt":639159130722194373}
{"op":"mcm","id":2,"clk":"AJVgAL49ANh9","pt":1780316272312,"mc":[{"id":"1.258742455","rc":[{"tv":998.87,"batb":[[2,21,12.68],[1,22,21.61],[0,23,12.19]],"trd":[[24,133.57]],"atb":[[24,0]],"id":99072900}],"tv":35207.25}],"rt":639159130723202263,"dt":639159130723202705}
{"op":"mcm","id":2,"clk":"AJpgAMY9AOB9","pt":1780316272415,"mc":[{"id":"1.258742455","rc":[{"batb":[[0,4.9,4.03]],"atb":[[4.9,4.03]],"id":99072898},{"atl":[[25,2.8]],"batl":[[2,27,15.28],[1,26,4.5],[0,25,2.8]],"id":99072900}]}],"rt":639159130724235426,"dt":639159130724235882}
{"op":"mcm","id":2,"clk":"AJ5gAMo9AOx9","pt":1780316272512,"mc":[{"id":"1.258742455","rc":[{"atl":[[25,4.27]],"batl":[[0,25,4.27]],"id":99072900}]}],"rt":639159130725203613,"dt":639159130725203973}
{"op":"mcm","id":2,"clk":"AKFgAM09APZ9","pt":1780316272625,"mc":[{"id":"1.258742455","rc":[{"batb":[[2,21,11.16]],"atb":[[21,11.16]],"atl":[[24,2.56]],"batl":[[2,26,4.5],[1,25,4.27],[0,24,2.56]],"id":99072900}]}],"rt":639159130726329809,"dt":639159130726330234}
{"op":"mcm","id":2,"clk":"AKhgANE9APl9","pt":1780316272716,"mc":[{"id":"1.258742455","rc":[{"batb":[[2,4.7,29.1],[1,4.8,49.87],[0,4.9,5.44]],"atb":[[4.7,29.1],[4.9,5.44],[4.8,49.87]],"atl":[[5.2,27.06],[5,14.44]],"batl":[[2,5.2,27.06],[0,5,14.44]],"id":99072898},{"batb":[[0,23,12.09]],"atb":[[23,12.09]],"id":99072900},{"atl":[[3.7,44.45]],"batl":[[0,3.7,44.45]],"id":88302242}]}],"rt":639159130727239300,"dt":639159130727239830}
{"op":"mcm","id":2,"clk":"AKxgANM9AIF\u002B","pt":1780316272773,"mc":[{"id":"1.258742455","rc":[{"batb":[[0,4.9,24.89]],"atb":[[4.4,14.84],[4.9,24.89]],"id":99072898},{"atl":[[24,3.6]],"batl":[[0,24,3.6]],"id":99072900}]}],"rt":639159130727807091,"dt":639159130727807511}
{"op":"mcm","id":2,"clk":"ALBgANg9AIh\u002B","pt":1780316272921,"mc":[{"id":"1.258742455","rc":[{"batb":[[2,4.7,34.07],[0,4.9,31.63]],"atb":[[4.7,34.07],[4.9,31.63]],"id":99072898},{"batb":[[2,21,7.55]],"atb":[[21,7.55]],"id":99072900}]}],"rt":639159130729304914,"dt":639159130729305303}
{"op":"mcm","id":2,"clk":"AL1gAOE9AJZ\u002B","pt":1780316273082,"mc":[{"id":"1.258742455","rc":[{"atl":[[32,3.99]],"id":10398159},{"tv":2197.23,"batb":[[0,9.6,14.82]],"trd":[[9.6,236.4]],"atb":[[9.6,14.82]],"id":98117699}],"tv":35217.25}],"rt":639159130730903312,"dt":639159130730903759}
{"op":"mcm","id":2,"clk":"AMhgAO49AKt\u002B","pt":1780316273283,"mc":[{"id":"1.258742455","rc":[{"atl":[[24,1.04]],"batl":[[0,24,1.04]],"id":99072900},{"atl":[[3.75,10.55],[3.95,26.55]],"batl":[[1,3.75,10.55]],"id":88302242}]}],"rt":639159130732910286,"dt":639159130732910691}
{"op":"mcm","id":2,"clk":"ANFgAPY9ALV\u002B","pt":1780316273387,"mc":[{"id":"1.258742455","rc":[{"batb":[[0,9.6,16.15]],"atb":[[9.6,16.15]],"id":98117699},{"atl":[[3.7,51.95]],"batl":[[0,3.7,51.95]],"id":88302242}]}],"rt":639159130733952334,"dt":639159130733952723}
{"op":"mcm","id":2,"clk":"ANtgAPs9AL1\u002B","pt":1780316273491,"mc":[{"id":"1.258742455","rc":[{"batb":[[2,4.7,29.1]],"atb":[[4.7,29.1]],"id":99072898},{"tv":539,"trd":[[50,78.97]],"ltp":50,"atl":[[50,10.92]],"batl":[[0,50,10.92]],"id":97008932},{"atl":[[60,6.95]],"batl":[],"id":98464183},{"atl":[[12,15.39]],"batl":[],"id":98117699}],"tv":35219.95}],"rt":639159130734994240,"dt":639159130734994674}
{"op":"mcm","id":2,"clk":"AOVgAP49AMV\u002B","pt":1780316273594,"mc":[{"id":"1.258742455","rc":[{"tv":7953.72,"batb":[[0,4.6,50.17]],"trd":[[4.6,1113.02]],"atb":[[4.6,50.17]],"id":10398159},{"atb":[[1.17,2.12]],"id":97736949}],"tv":35229.95}],"rt":639159130736025773,"dt":639159130736026160}
{"op":"mcm","id":2,"clk":"APJgAIQ\u002BANd\u002B","pt":1780316273801,"mc":[{"id":"1.258742455","rc":[{"batb":[],"atb":[[19,13.42]],"atl":[[29,10.21]],"batl":[],"id":99072900},{"atb":[[1.17,2]],"id":97736949}]}],"rt":639159130738091511,"dt":639159130738091842}
{"op":"mcm","id":2,"clk":"AP5gAIo\u002BAOB\u002B","pt":1780316273904,"mc":[{"id":"1.258742455","rc":[{"batb":[[0,9.2,7.81]],"atb":[[9.4,0.47]],"id":97736949}]}],"rt":639159130739116664,"dt":639159130739116993}
{"op":"mcm","id":2,"clk":"AINhAJA\u002BAO1\u002B","pt":1780316274005,"mc":[{"id":"1.258742455","rc":[{"atl":[[5.2,27.75]],"batl":[],"id":10398159}]}],"rt":639159130740136082,"dt":639159130740136439}
{"op":"mcm","id":2,"clk":"AIthAJU\u002BAPR\u002B","pt":1780316274107,"mc":[{"id":"1.258742455","rc":[{"atl":[[9.6,2.78]],"batl":[[0,9.6,2.78]],"id":97736949}]}],"rt":639159130741153671,"dt":639159130741154029}
{"op":"mcm","id":2,"clk":"AK1hAKM\u002BAI9/","pt":1780316274413,"mc":[{"id":"1.258742455","rc":[{"atl":[[5.5,28.48]],"batl":[],"id":99072898}]}],"rt":639159130744217046,"dt":639159130744217357}
{"op":"mcm","id":2,"clk":"AMxhAK0\u002BAKR/","pt":1780316274687,"mc":[{"id":"1.258742455","rc":[{"tv":7959.72,"batb":[[0,4.6,47.17]],"trd":[[4.6,1119.02]],"atb":[[4.6,47.17]],"id":10398159}],"tv":35235.95}],"rt":639159130746953140,"dt":639159130746953525}
{"op":"mcm","id":2,"clk":"AOFhAL4\u002BALp/","pt":1780316274985,"mc":[{"id":"1.258742455","rc":[{"tv":12082.15,"batb":[[0,3.65,23.31]],"trd":[[3.65,169.55]],"atb":[[3.65,23.31]],"id":88302242}],"tv":35245.95}],"rt":639159130749934132,"dt":639159130749934489}
{"op":"mcm","id":2,"clk":"AO1hAMI\u002BAMd/","pt":1780316275089,"mc":[{"id":"1.258742455","rc":[{"atl":[[11.5,5.86]],"batl":[],"id":97736949}]}],"rt":639159130750967155,"dt":639159130750967510}
{"op":"mcm","id":2,"clk":"AJNiAOE\u002BAIyAAQ==","pt":1780316275700,"mc":[{"id":"1.258742455","rc":[{"atl":[[1000,0.35]],"id":97008932},{"batb":[[0,80,2.56]],"atb":[[80,2.56]],"id":99072901},{"batb":[[0,44,4.34]],"atb":[[46,0.84]],"id":98464183},{"atl":[[13,5.68]],"batl":[],"id":98117699}]}],"rt":639159130757085575,"dt":639159130757085955}
{"op":"mcm","id":2,"clk":"AJtiAOg\u002BAJeAAQ==","pt":1780316275814,"mc":[{"id":"1.258742455","rc":[{"batb":[[1,4.8,50.87]],"atb":[[4.8,50.87]],"id":99072898},{"atl":[[1000,0.22]],"id":97008932},{"tv":2219.23,"batb":[[0,9.6,5.15]],"trd":[[9.6,258.4]],"atb":[[9.6,5.15]],"id":98117699},{"batb":[[0,9.2,8.81]],"atb":[[9.2,8.34]],"id":97736949}],"tv":35267.95}],"rt":639159130758227255,"dt":639159130758227703}
{"op":"mcm","id":2,"clk":"AJ9iAOo\u002BAKGAAQ==","pt":1780316275907,"mc":[{"id":"1.258742455","rc":[{"atl":[[55,19.56]],"batl":[[1,55,19.56]],"id":97008932},{"tv":851.93,"trd":[[55,73.71],[50,121.52],[48,68.34]],"ltp":55,"atl":[[55,6.39],[50,0],[48,0]],"batl":[[2,65,22.89],[1,60,6.95],[0,55,6.39]],"id":98464183},{"atl":[[9.8,4.5]],"batl":[[0,9.8,4.5]],"id":98117699}],"tv":35293.29}],"rt":639159130759151704,"dt":639159130759152039}
{"op":"mcm","id":2,"clk":"AKViAO8\u002BAK2AAQ==","pt":1780316276011,"mc":[{"id":"1.258742455","rc":[{"batb":[[2,44,3.5],[1,46,1.23],[0,50,4.56]],"atb":[[50,4.56],[48,0.39]],"id":98464183},{"tv":2226.87,"batb":[[2,9,23.6],[1,9.2,14.28],[0,9.4,18.57]],"trd":[[9.6,266.04]],"atb":[[9.6,0]],"atl":[[9.6,3.39]],"batl":[[2,10,6.38],[1,9.8,4.5],[0,9.6,3.39]],"id":98117699}],"tv":35300.93}],"rt":639159130760192214,"dt":639159130760192720}
{"op":"mcm","id":2,"clk":"AKxiAPQ\u002BALWAAQ==","pt":1780316276116,"mc":[{"id":"1.258742455","rc":[{"atl":[[4.7,39.19]],"batl":[[0,4.7,39.19]],"id":10398159},{"tv":853.59,"batb":[[2,44,5.28],[1,48,5],[0,50,3.73]],"trd":[[50,123.18]],"ltp":50,"atb":[[50,3.73],[48,5],[44,4.44]],"atl":[[60,9.72],[55,9.93]],"batl":[[1,60,9.72],[0,55,9.93]],"id":98464183},{"batb":[[2,9,20.04]],"atb":[[8.8,14.83],[9,20.04]],"id":98117699}],"tv":35302.59}],"rt":639159130761246347,"dt":639159130761246871}
{"op":"mcm","id":2,"clk":"ALRiAPk\u002BAMCAAQ==","pt":1780316276215,"mc":[{"id":"1.258742455","rc":[{"tv":854.77,"batb":[[0,50,3.14]],"trd":[[50,124.36]],"atb":[[50,3.14]],"atl":[[60,6.72],[55,8.73]],"batl":[[1,60,6.72],[0,55,8.73]],"id":98464183},{"batb":[],"atb":[[8.4,21.34]],"id":98117699},{"atl":[[4.6,22.58]],"id":88302242}],"tv":35303.77}],"rt":639159130762230870,"dt":639159130762231308}
{"op":"mcm","id":2,"clk":"ALpiAP0\u002BAMiAAQ==","pt":1780316276318,"mc":[{"id":"1.258742455","rc":[{"batb":[[2,44,4.87],[1,48,3.3]],"atb":[[48,3.3],[46,0.63],[44,4.24]],"atl":[[60,3.95],[55,9]],"batl":[[1,60,3.95],[0,55,9]],"id":98464183},{"batb":[],"atb":[[8.8,8.83]],"atl":[[11.5,6.38]],"batl":[],"id":98117699},{"batb":[[1,3.6,90.5]],"atb":[[3.6,90.5]],"id":88302242}]}],"rt":639159130763257503,"dt":639159130763257993}
{"op":"mcm","id":2,"clk":"AMBiAIA/ANSAAQ==","pt":1780316276379,"mc":[{"id":"1.258742455","rc":[{"batb":[[2,46,1.56]],"atb":[[46,1.56]],"id":98464183}]}],"rt":639159130763877498,"dt":639159130763877850}
{"op":"mcm","id":2,"clk":"AMdiAIQ/ANmAAQ==","pt":1780316276523,"mc":[{"id":"1.258742455","rc":[{"batb":[[1,48,4.19]],"atb":[[48,4.19]],"atl":[[55,9.77],[70,8.1]],"batl":[[0,55,9.77]],"id":98464183},{"batb":[],"atb":[[8.6,26.98]],"atl":[[11,24.06]],"batl":[],"id":98117699},{"batb":[[0,3.65,33.65]],"atb":[[3.65,33.65]],"id":88302242}]}],"rt":639159130765307827,"dt":639159130765308312}
{"op":"mcm","id":2,"clk":"ANhiAI0/AOyAAQ==","pt":1780316276683,"mc":[{"id":"1.258742455","rc":[{"batb":[[1,3.6,81.1]],"atb":[[3.6,81.1]],"id":88302242}]}],"rt":639159130766911429,"dt":639159130766911803}
{"op":"mcm","id":2,"clk":"APViAJ0/AImBAQ==","pt":1780316277090,"mc":[{"id":"1.258742455","rc":[{"tv":7588.85,"trd":[[5,25.54]],"atl":[[5,10.44]],"batl":[[0,5,10.44]],"id":99072898}],"tv":35311.77}],"rt":639159130770978363,"dt":639159130770978832}
{"op":"mcm","id":2,"clk":"AP9iAKM/AJOBAQ==","pt":1780316277191,"mc":[{"id":"1.258742455","rc":[{"atl":[[5.1,12.64]],"batl":[[1,5.1,12.64]],"id":99072898}]}],"rt":639159130771993097,"dt":639159130771993521}
{"op":"mcm","id":2,"clk":"AIhjAKg/AJ\u002BBAQ==","pt":1780316277297,"mc":[{"id":"1.258742455","rc":[{"batb":[[0,9.4,17.57]],"atb":[[9.4,17.57]],"id":98117699}]}],"rt":639159130773050633,"dt":639159130773051008}
{"op":"mcm","id":2,"clk":"AI5jAKk/AKaBAQ==","pt":1780316277397,"mc":[{"id":"1.258742455","rc":[{"atl":[[5.2,30.07]],"batl":[[2,5.2,30.07]],"id":99072898},{"atl":[[29,18.72]],"batl":[],"id":99072900},{"atl":[[5,12.77]],"batl":[],"id":10398159},{"batb":[],"atb":[[8.8,5.2],[8.6,30.61]],"id":98117699},{"batb":[[0,9.2,11.85]],"atb":[[9.2,11.38]],"id":97736949}]}],"rt":639159130774050430,"dt":639159130774050960}
{"op":"mcm","id":2,"clk":"AJZjALM/AK\u002BBAQ==","pt":1780316277501,"mc":[{"id":"1.258742455","rc":[{"batb":[[2,9,14.43],[1,9.2,11.38],[0,9.4,3.84]],"atb":[[9.4,3.84]],"id":97736949}]}],"rt":639159130775091276,"dt":639159130775091755}
{"op":"mcm","id":2,"clk":"AJ5jALU/ALaBAQ==","pt":1780316277598,"mc":[{"id":"1.258742455","rc":[{"atl":[[3.7,54.95]],"batl":[[0,3.7,54.95]],"id":88302242}]}],"rt":639159130776065595,"dt":639159130776065977}
{"op":"mcm","id":2,"clk":"AMNjAMg/ANaBAQ==","pt":1780316278011,"mc":[{"id":"1.258742455","rc":[{"batb":[],"atb":[[8.4,20.82]],"id":97736949}]}],"rt":639159130780195985,"dt":639159130780196347}
{"op":"mcm","id":2,"clk":"ANNjAM0/AOWBAQ==","pt":1780316278212,"mc":[{"id":"1.258742455","rc":[{"batb":[],"atb":[[8.6,13.48]],"id":97736949}]}],"rt":639159130782203577,"dt":639159130782203908}
{"op":"mcm","id":2,"clk":"AOhjANc/APWBAQ==","pt":1780316278418,"mc":[{"id":"1.258742455","rc":[{"atl":[[9.6,2.88]],"batl":[[0,9.6,2.88]],"id":97736949}]}],"rt":639159130784264074,"dt":639159130784264436}
{"op":"mcm","id":2,"clk":"AIZkAOc/AJGCAQ==","pt":1780316278680,"mc":[{"id":"1.258742455","rc":[{"batb":[[1,4.8,52.32]],"atb":[[4.8,52.32]],"atl":[[5,7.54]],"batl":[[0,5,7.54]],"id":99072898},{"atl":[[25,3.91]],"batl":[[1,25,3.91]],"id":99072900},{"batb":[[2,46,1.34]],"atb":[[46,1.34]],"id":98464183},{"atl":[[1000,7.03],[9.8,4.03]],"batl":[[1,9.8,4.03]],"id":98117699}]}],"rt":639159130786883497,"dt":639159130786883896}
{"op":"mcm","id":2,"clk":"AJJkAOk/AJqCAQ==","pt":1780316278783,"mc":[{"id":"1.258742455","rc":[{"batb":[[2,9,25.69]],"atb":[[9,25.69]],"atl":[[10,5.87]],"batl":[[2,10,5.87]],"id":98117699}]}],"rt":639159130787908912,"dt":639159130787909309}
{"op":"mcm","id":2,"clk":"AJZkAO4/AKOCAQ==","pt":1780316278880,"mc":[{"id":"1.258742455","rc":[{"atl":[[1000,6.25]],"id":98117699}]}],"rt":639159130788898925,"dt":639159130788899232}
{"op":"mcm","id":2,"clk":"AJlkAPY/AKqCAQ==","pt":1780316278989,"mc":[{"id":"1.258742455","rc":[{"atl":[[9.8,4.48],[9.6,3.72]],"batl":[[1,9.8,4.48],[0,9.6,3.72]],"id":98117699}]}],"rt":639159130789972509,"dt":639159130789972906}
{"op":"mcm","id":2,"clk":"AL5kAJhAAOSCAQ==","pt":1780316279604,"mc":[{"id":"1.258742455","rc":[{"batb":[[0,3.65,34.69]],"atb":[[3.65,34.69]],"id":88302242},{"batb":[[0,1000,92.99]],"atb":[[1000,92.99]],"id":10445502}]}],"rt":639159130796124608,"dt":639159130796124988}
{"op":"mcm","id":2,"clk":"AMlkAKZAAPiCAQ==","pt":1780316279814,"mc":[{"id":"1.258742455","rc":[{"atl":[[9.6,6.72]],"batl":[[0,9.6,6.72]],"id":98117699},{"atl":[[9.8,9.31]],"batl":[[1,9.8,9.31]],"id":97736949}]}],"rt":639159130798222157,"dt":639159130798222584}
{"op":"mcm","id":2,"clk":"ANtkALpAAKyDAQ==","pt":1780316280280,"mc":[{"id":"1.258742455","rc":[{"atl":[[11,40.32]],"batl":[],"id":97736949}]}],"rt":639159130802886281,"dt":639159130802886757}
{"op":"mcm","id":2,"clk":"AONkAL9AALaDAQ==","pt":1780316280390,"mc":[{"id":"1.258742455","rc":[{"atl":[[9.6,7.79]],"batl":[[0,9.6,7.79]],"id":97736949}]}],"rt":639159130803979861,"dt":639159130803980235}
{"op":"mcm","id":2,"clk":"ALJlAIJBAJSEAQ==","pt":1780316281718,"mc":[{"id":"1.258742455","rc":[{"batb":[[0,9.4,19.74]],"atb":[[9.4,19.74]],"id":98117699}]}],"rt":639159130817263993,"dt":639159130817264362}
{"op":"mcm","id":2,"clk":"AL1lAI5BAKaEAQ==","pt":1780316281921,"mc":[{"id":"1.258742455","rc":[{"batb":[[1,4.5,121.17]],"atb":[[4.5,121.17]],"id":10398159}]}],"rt":639159130819289529,"dt":639159130819289908}
{"op":"mcm","id":2,"clk":"AN5lAKNBAMWEAQ==","pt":1780316282289,"mc":[{"id":"1.258742455","rc":[{"batb":[],"atb":[[4.6,30.34]],"id":99072898}]}],"rt":639159130822977906,"dt":639159130822978229}
{"op":"mcm","id":2,"clk":"APtlALlBAO\u002BEAQ==","pt":1780316282796,"mc":[{"id":"1.258742455","rc":[{"tv":12102.15,"batb":[[0,3.65,24.69]],"trd":[[3.65,189.55]],"atb":[[3.65,24.69]],"id":88302242}],"tv":35331.77}],"rt":639159130828039647,"dt":639159130828040047}
{"op":"mcm","id":2,"clk":"AIRmAMBBAPmEAQ==","pt":1780316282902,"mc":[{"id":"1.258742455","rc":[{"batb":[[0,3.65,14.35]],"atb":[[3.65,14.35]],"id":88302242}]}],"rt":639159130829097221,"dt":639159130829097535}
{"op":"mcm","id":2,"clk":"AIdmAMJBAP6EAQ==","pt":1780316282994,"mc":[{"id":"1.258742455","rc":[{"atl":[[3.7,60.03]],"batl":[[0,3.7,60.03]],"id":88302242}]}],"rt":639159130830023972,"dt":639159130830024294}
{"op":"mcm","id":2,"clk":"AJJmANBBAIyFAQ==","pt":1780316283204,"mc":[{"id":"1.258742455","rc":[{"batb":[[2,4.4,150.04]],"atb":[[4.4,150.04]],"id":10398159}]}],"rt":639159130832118788,"dt":639159130832119182}
{"op":"mcm","id":2,"clk":"AJpmANRBAJSFAQ==","pt":1780316283308,"mc":[{"id":"1.258742455","rc":[{"batb":[[0,3.65,25.46]],"atb":[[3.65,25.46]],"atl":[[3.9,38.25],[3.7,49.48]],"batl":[[0,3.7,49.48]],"id":88302242}]}],"rt":639159130833162502,"dt":639159130833162904}
{"op":"mcm","id":2,"clk":"AJ9mANdBAJqFAQ==","pt":1780316283407,"mc":[{"id":"1.258742455","rc":[{"atl":[[24,3.44]],"batl":[[0,24,3.44]],"id":99072900},{"batb":[[0,9.4,17.01]],"atb":[[9.4,17.01]],"id":98117699},{"tv":12189.25,"trd":[[3.7,322.96]],"ltp":3.7,"atl":[[3.7,5.93]],"batl":[[0,3.7,5.93]],"id":88302242},{"batb":[[2,8.8,7.38],[1,9,14.43],[0,9.2,11.85]],"atb":[[9.4,0.47]],"id":97736949}],"tv":35418.87}],"rt":639159130834152377,"dt":639159130834152883}
