{"op":"mcm","id":2,"clk":"AKVmANpBAKSFAQ==","pt":1780316283510,"mc":[{"id":"1.258742455","rc":[{"tv":1023.05,"batb":[[2,20,3.97],[1,21,7.55],[0,22,21.61]],"trd":[[23,46]],"ltp":23,"atb":[[23,0]],"id":99072900},{"tv":12201.11,"batb":[[2,3.6,90.5],[1,3.65,25.46],[0,3.7,37.62]],"trd":[[3.7,334.82]],"atb":[[3.15,3.99],[3.7,37.62],[3.6,90.5]],"atl":[[3.7,0]],"batl":[[2,3.85,3.4],[1,3.8,15.27],[0,3.75,10.55]],"id":88302242}],"tv":35454.91}],"rt":639159130835182981,"dt":639159130835183457}
{"op":"mcm","id":2,"clk":"AK1mAOFBAKyFAQ==","pt":1780316283618,"mc":[{"id":"1.258742455","rc":[{"batb":[],"atb":[[4.1,56.18]],"id":99072898},{"batb":[[0,22,19.93]],"atb":[[22,19.93]],"atl":[[24,4.69],[23,2.68]],"batl":[[2,25,3.91],[1,24,4.69],[0,23,2.68]],"id":99072900},{"batb":[[0,9.4,18.7]],"atb":[[9.4,18.7],[8.2,5.79]],"id":98117699},{"tv":12210.39,"batb":[[1,3.65,39.45]],"trd":[[3.75,256.86]],"ltp":3.75,"atb":[[3.65,39.45]],"atl":[[3.75,5.91]],"batl":[[0,3.75,5.91]],"id":88302242},{"tv":2258.22,"batb":[[0,9.2,8.99]],"trd":[[9.4,8.92]],"ltp":9.4,"atb":[[9.4,0],[8.4,20.22],[9.2,8.99]],"id":97736949}],"tv":35465.13}],"rt":639159130836263181,"dt":639159130836263930}
{"op":"mcm","id":2,"clk":"ALRmAOZBALGFAQ==","pt":1780316283720,"mc":[{"id":"1.258742455","rc":[{"batb":[],"atb":[[38,10.11]],"id":97008932},{"batb":[[2,20,6.62],[1,21,9.98]],"atb":[[21,9.98],[20,6.62]],"atl":[[28,2.93]],"batl":[],"id":99072900},{"batb":[],"atb":[[3.95,48.48]],"id":10398159},{"batb":[[2,3.6,86.87],[0,3.7,53.27]],"atb":[[3.7,53.27],[3.2,4.36],[3.6,86.87],[3.45,28.96]],"atl":[[3.75,4.15]],"batl":[[0,3.75,4.15]],"id":88302242}]}],"rt":639159130837283596,"dt":639159130837284118}
{"op":"mcm","id":2,"clk":"ALlmAOhBALiFAQ==","pt":1780316283822,"mc":[{"id":"1.258742455","rc":[{"batb":[],"atb":[[4.2,127.19]],"id":99072898},{"batb":[[1,21,8.6]],"atb":[[21,8.6],[19,5.59],[19.5,3.42]],"id":99072900},{"batb":[],"atb":[[8.2,6.4]],"id":98117699},{"batb":[[0,3.7,54.42]],"atb":[[3.7,54.42]],"id":88302242},{"batb":[],"atb":[[8,10.62]],"id":97736949}]}],"rt":639159130838302442,"dt":639159130838302912}
{"op":"mcm","id":2,"clk":"AMFmAO5BAL\u002BFAQ==","pt":1780316283923,"mc":[{"id":"1.258742455","rc":[{"tv":1044.45,"batb":[[0,22,9.23]],"trd":[[22,69.22]],"ltp":22,"atb":[[22,9.23]],"atl":[[27,14]],"batl":[],"id":99072900},{"batb":[],"atb":[[3.45,22.96]],"atl":[[3.9,32.25]],"batl":[],"id":88302242},{"batb":[],"atb":[[8.6,7.48]],"id":97736949}],"tv":35486.53}],"rt":639159130839314685,"dt":639159130839315254}
{"op":"mcm","id":2,"clk":"AMZmAPNBAMeFAQ==","pt":1780316284024,"mc":[{"id":"1.258742455","rc":[{"batb":[[2,42,11.22]],"atb":[[42,11.22]],"id":97008932},{"tv":1046.07,"batb":[],"trd":[[23,47.62]],"ltp":23,"atb":[[19.5,3.68],[18.5,3.59]],"atl":[[23,1.87]],"batl":[[0,23,1.87]],"id":99072900},{"batb":[],"atb":[[3.9,14.33]],"id":10398159},{"batb":[[0,3.7,59.54]],"atb":[[3.7,59.54]],"id":88302242},{"tv":2319.6,"trd":[[9.8,87.51],[10.5,89.55],[10,129.66],[9.6,37.7]],"ltp":10.5,"atl":[[9.8,0],[10.5,19.93],[10,0],[9.6,0]],"batl":[[2,11.5,5.86],[1,11,40.32],[0,10.5,19.93]],"id":97736949}],"tv":35549.53}],"rt":639159130840319852,"dt":639159130840320532}
{"op":"mcm","id":2,"clk":"AMpmAPZBANCFAQ==","pt":1780316284127,"mc":[{"id":"1.258742455","rc":[{"batb":[[0,22,8.03]],"atb":[[22,8.03]],"atl":[[23,3.12]],"batl":[[0,23,3.12]],"id":99072900},{"batb":[],"atb":[[3.5,94.89]],"atl":[[3.95,32.55]],"batl":[],"id":88302242},{"batb":[[2,9.2,8.99],[1,9.4,2.93],[0,10,2.88]],"atb":[[9.4,2.93],[8.4,26.22],[10,2.88]],"id":97736949}]}],"rt":639159130841350406,"dt":639159130841350956}
{"op":"mcm","id":2,"clk":"ANFmAPpBANaFAQ==","pt":1780316284185,"mc":[{"id":"1.258742455","rc":[{"tv":2322.82,"batb":[[2,9.2,14.64],[1,9.4,6],[0,10,1.27]],"trd":[[10,132.88]],"ltp":10,"atb":[[9.4,6],[8.8,13.03],[10,1.27],[9.2,14.64]],"atl":[[10.5,22.22]],"batl":[[0,10.5,22.22]],"id":97736949}],"tv":35552.75}],"rt":639159130841926975,"dt":639159130841927361}
{"op":"mcm","id":2,"clk":"ANZmAINCAN\u002BFAQ==","pt":1780316284332,"mc":[{"id":"1.258742455","rc":[{"batb":[[0,4.9,29.9]],"atb":[[4.9,29.9]],"atl":[[5.1,14.51]],"batl":[[1,5.1,14.51]],"id":99072898},{"batb":[[0,4.6,37.98]],"atb":[[4.6,37.98]],"atl":[[4.7,46.15]],"batl":[[0,4.7,46.15]],"id":10398159},{"batb":[[0,9.4,17.01]],"atb":[[9.4,17.01]],"atl":[[9.6,8.11]],"batl":[[0,9.6,8.11]],"id":98117699},{"tv":2325.36,"batb":[[2,9.4,6],[1,9.6,6.39],[0,9.8,3.48]],"trd":[[10,135.42]],"atb":[[9.8,3.48],[10,0],[9.6,6.39]],"atl":[[10.5,23.76],[10,11.16]],"batl":[[2,11,40.32],[1,10.5,23.76],[0,10,11.16]],"id":97736949},{"batb":[[1,170,1.67]],"atb":[[170,1.67]],"id":99072897}],"tv":35555.29}],"rt":639159130843405662,"dt":639159130843406428}
{"op":"mcm","id":2,"clk":"AN1mAIZCAOaFAQ==","pt":1780316284388,"mc":[{"id":"1.258742455","rc":[{"tv":540.79,"batb":[[0,46,3.12]],"trd":[[48,42.79]],"ltp":48,"atb":[[48,0]],"atl":[[48,0.64]],"batl":[[0,50,11.56]],"id":97008932},{"atl":[[3.75,14.83]],"batl":[[0,3.75,14.83]],"id":88302242},{"tv":2330.76,"trd":[[10,140.82]],"atl":[[10.5,24.97],[10,8.46]],"batl":[[1,10.5,24.97],[0,10,8.46]],"id":97736949}],"tv":35562.48}],"rt":639159130843960161,"dt":639159130843960624}
{"op":"mcm","id":2,"clk":"AONmAIhCAO2FAQ==","pt":1780316284488,"mc":[{"id":"1.258742455","rc":[{"batb":[[0,4.9,10.45]],"atb":[[4.9,10.45]],"atl":[[5.1,12.64]],"batl":[[1,5.1,12.64]],"id":99072898},{"batb":[[0,22,5.4]],"atb":[[22,5.4],[18,5.36]],"id":99072900},{"tv":7965.9,"batb":[[0,4.6,27.28]],"trd":[[4.6,1125.2]],"atb":[[4.6,27.28]],"id":10398159},{"batb":[[0,9.4,9.49]],"atb":[[9.4,9.49]],"id":98117699},{"tv":2350.5,"batb":[[0,9.8,2.77]],"trd":[[10,160.56]],"atb":[[8.8,7.38],[9.8,2.77],[9.2,16.37]],"atl":[[11,34.32],[10.5,18.1],[10,0]],"batl":[[2,11.5,5.86],[1,11,34.32],[0,10.5,18.1]],"id":97736949}],"tv":35588.4}],"rt":639159130844960790,"dt":639159130844961751}
{"op":"mcm","id":2,"clk":"AOtmAI1CAPKFAQ==","pt":1780316284597,"mc":[{"id":"1.258742455","rc":[{"atl":[[5.1,14.51]],"batl":[[1,5.1,14.51]],"id":99072898},{"batb":[[0,4.6,25.42]],"atb":[[4.6,25.42]],"id":10398159},{"tv":2245.49,"batb":[[2,8.8,5.2],[1,9,25.69],[0,9.2,14.46]],"trd":[[9.4,136.87]],"ltp":9.4,"atb":[[9.4,0.18],[8.4,25],[8.6,26.98]],"id":98117699},{"atl":[[3.75,17.02]],"batl":[[0,3.75,17.02]],"id":88302242},{"tv":2354.92,"batb":[[2,9.6,8.05],[1,9.8,2.29],[0,10,2.6]],"trd":[[9.8,91.93]],"ltp":9.8,"atb":[[8.4,20.22],[9.8,2.29],[10,2.6],[9.6,8.05]],"id":97736949}],"tv":35611.44}],"rt":639159130846050272,"dt":639159130846050854}
{"op":"mcm","id":2,"clk":"AO5mAI9CAPeFAQ==","pt":1780316284695,"mc":[{"id":"1.258742455","rc":[{"batb":[[0,4.9,3.71]],"atb":[[4.9,3.71]],"id":99072898},{"tv":8016.74,"batb":[[2,4.3,113.97],[1,4.4,150.04],[0,4.5,121.17]],"trd":[[4.6,1176.04]],"atb":[[4.6,0]],"atl":[[4.6,23.21]],"batl":[[2,4.8,19.6],[1,4.7,46.15],[0,4.6,23.21]],"id":10398159},{"tv":2245.85,"batb":[[1,9,28.2],[0,9.2,14.28]],"trd":[[9.4,137.23]],"atb":[[9.4,0],[9,28.2],[8.6,11.29]],"atl":[[9.4,15.99],[11,21.26]],"batl":[[2,9.8,4.48],[1,9.6,8.11],[0,9.4,15.99]],"id":98117699},{"tv":12218.69,"batb":[],"trd":[[3.75,265.16]],"atb":[[3.5,84.11]],"atl":[[3.75,2.19]],"batl":[[0,3.75,2.19]],"id":88302242},{"tv":2360.12,"batb":[[2,9.4,6],[1,9.6,8.05],[0,9.8,2.29]],"trd":[[10,165.76]],"ltp":10,"atb":[[10,0]],"atl":[[12.5,10.71]],"batl":[],"id":97736949}],"tv":35676.14}],"rt":639159130847037723,"dt":639159130847038431}
{"op":"mcm","id":2,"clk":"APNmAJJCAP2FAQ==","pt":1780316284794,"mc":[{"id":"1.258742455","rc":[{"batb":[[0,4.9,16.09]],"atb":[[4.9,16.09]],"atl":[[5.1,12.64]],"batl":[[1,5.1,12.64]],"id":99072898},{"atl":[[4.9,61.49]],"batl":[],"id":10398159},{"tv":2257.39,"batb":[[2,8.8,10.85],[0,9.2,4.72]],"trd":[[9.2,162.81]],"ltp":9.2,"atb":[[8.8,10.85],[9.2,4.72]],"atl":[[9.4,18.85]],"batl":[[0,9.4,18.85]],"id":98117699},{"tv":12223.07,"batb":[[2,3.65,39.45],[1,3.7,59.54],[0,3.75,9.07]],"trd":[[3.75,269.54]],"atb":[[3.75,9.07]],"atl":[[3.75,0]],"batl":[[2,3.9,32.25],[1,3.85,3.4],[0,3.8,15.27]],"id":88302242},{"batb":[[2,9.6,8.05],[1,9.8,2.29],[0,10,2.84]],"atb":[[10,2.84]],"id":97736949},{"batb":[[1,170,3.4]],"atb":[[170,3.4]],"id":99072897}],"tv":35692.06}],"rt":639159130848027173,"dt":639159130848027833}
{"op":"mcm","id":2,"clk":"APhmAJdCAIuGAQ==","pt":1780316284901,"mc":[{"id":"1.258742455","rc":[{"batb":[[0,4.9,23.84]],"atb":[[4.9,23.84]],"atl":[[5.1,14.51]],"batl":[[1,5.1,14.51]],"id":99072898},{"tv":8036.38,"trd":[[4.6,1195.68]],"atl":[[4.6,13.39]],"batl":[[0,4.6,13.39]],"id":10398159},{"tv":2264.83,"batb":[[2,8.6,5.29],[1,8.8,10.85],[0,9,28.2]],"trd":[[9.2,170.25]],"atb":[[8.4,21.34],[8.2,10.14],[9.2,0],[8.6,5.29]],"atl":[[10.5,8.54],[9.2,5.84]],"batl":[[2,9.6,8.11],[1,9.4,18.85],[0,9.2,5.84]],"id":98117699},{"batb":[[1,3.7,68.76]],"atb":[[3.7,68.76]],"atl":[[3.8,17.53]],"batl":[[0,3.8,17.53]],"id":88302242},{"tv":2360.74,"batb":[[0,10,4.26]],"trd":[[10,166.38]],"atb":[[10,4.26],[9,20.43]],"id":97736949}],"tv":35719.76}],"rt":639159130849091181,"dt":639159130849091719}
{"op":"mcm","id":2,"clk":"APpmAJpCAI\u002BGAQ==","pt":1780316285003,"mc":[{"id":"1.258742455","rc":[{"batb":[[0,4.9,30.85]],"atb":[[4.9,30.85]],"id":99072898},{"atl":[[4.6,0]],"batl":[[2,4.9,61.49],[1,4.8,19.6],[0,4.7,46.15]],"id":10398159},{"batb":[[2,8.6,10.94]],"atb":[[8.4,5.44],[8.6,10.94]],"atl":[[9.4,20.26]],"batl":[[1,9.4,20.26]],"id":98117699},{"batb":[[0,3.75,23.72]],"atb":[[3.75,23.72]],"id":88302242},{"tv":2361.82,"batb":[[0,10,3.72]],"trd":[[10,167.46]],"atb":[[10,3.72]],"id":97736949}],"tv":35720.84}],"rt":639159130850112036,"dt":639159130850112653}
{"op":"mcm","id":2,"clk":"AIBnAJ5CAJuGAQ==","pt":1780316285104,"mc":[{"id":"1.258742455","rc":[{"batb":[[0,4.9,29.73]],"atb":[[4.9,29.73]],"atl":[[5,5]],"batl":[[0,5,5]],"id":99072898},{"atl":[[1000,0.33],[55,19.43]],"batl":[[1,55,19.43]],"id":97008932},{"batb":[],"atb":[[17.5,18.2]],"id":99072900},{"batb":[],"atb":[[4.2,29.29]],"atl":[[1000,1.78],[5.1,36.18],[4.8,19.44]],"batl":[[1,4.8,19.44]],"id":10398159},{"batb":[[0,9,27.2]],"atb":[[8.4,11.44],[9,27.2]],"atl":[[9.4,16.88],[1000,6.8],[9.8,3.87],[9.6,7.78]],"batl":[[2,9.6,7.78],[1,9.4,16.88]],"id":98117699},{"batb":[],"atb":[[3.5,69.59]],"id":88302242},{"batb":[],"atb":[[9,14.8]],"id":97736949}]}],"rt":639159130851120523,"dt":639159130851121328}
{"op":"mcm","id":2,"clk":"AIVnAJ9CAKSGAQ==","pt":1780316285206,"mc":[{"id":"1.258742455","rc":[{"atl":[[1000,0.22]],"id":97008932},{"atl":[[1000,1.01]],"id":10398159},{"atl":[[1000,6.25],[11,15.26]],"batl":[],"id":98117699},{"atl":[[3.85,13.41]],"batl":[[1,3.85,13.41]],"id":88302242}]}],"rt":639159130852145175,"dt":639159130852145624}
{"op":"mcm","id":2,"clk":"AIxnAKFCALKGAQ==","pt":1780316285312,"mc":[{"id":"1.258742455","rc":[{"atl":[[50,11.03]],"batl":[[0,50,11.67]],"id":97008932},{"batb":[],"atb":[[4.1,45.34]],"atl":[[4.7,46.59],[4.6,0.33],[5,18.77]],"batl":[[0,4.7,46.92]],"id":10398159},{"batb":[[0,9,21.55]],"atb":[[9,21.55]],"atl":[[9.4,17.43]],"batl":[[1,9.4,17.43]],"id":98117699},{"batb":[],"atb":[[3.5,63.59]],"id":88302242}]}],"rt":639159130853202375,"dt":639159130853202827}
{"op":"mcm","id":2,"clk":"AI5nAKJCALmGAQ==","pt":1780316285411,"mc":[{"id":"1.258742455","rc":[{"atb":[[12,2.85]],"id":99072900},{"atl":[[10,11.87]],"batl":[],"id":98117699},{"batb":[[1,9.8,4.02]],"atb":[[9.8,4.02],[9,8.8]],"id":97736949}]}],"rt":639159130854194166,"dt":639159130854194520}
{"op":"mcm","id":2,"clk":"AJRnAKZCAMCGAQ==","pt":1780316285515,"mc":[{"id":"1.258742455","rc":[{"atb":[[12,2.3]],"id":99072900},{"tv":12235.07,"batb":[[0,3.75,17.72]],"trd":[[3.75,281.54]],"atb":[[3.75,17.72],[3.55,51.93]],"id":88302242}],"tv":35732.84}],"rt":639159130855229232,"dt":639159130855229673}
{"op":"mcm","id":2,"clk":"AJpnAKtCAMmGAQ==","pt":1780316285621,"mc":[{"id":"1.258742455","rc":[{"batb":[[0,4.9,36.74]],"atb":[[4.9,36.74]],"id":99072898},{"atb":[[12,1.99]],"id":99072900},{"batb":[],"atb":[[8.4,5.44]],"id":98117699},{"tv":2363.82,"batb":[[0,10,2.72]],"trd":[[10,169.46]],"atb":[[10,2.72],[9.2,22.37],[8,7.62]],"id":97736949}],"tv":35734.84}],"rt":639159130856302464,"dt":639159130856302903}
{"op":"mcm","id":2,"clk":"AKFnAK5CANCGAQ==","pt":1780316285719,"mc":[{"id":"1.258742455","rc":[{"tv":1046.69,"trd":[[23,48.24]],"atl":[[23,2.81]],"batl":[[0,23,2.81]],"id":99072900},{"batb":[[0,3.75,3.07]],"atb":[[3.75,3.07]],"id":88302242},{"batb":[],"atb":[[1.17,2.71],[8.4,23.22]],"atl":[[1000,1.15]],"id":97736949}],"tv":35735.46}],"rt":639159130857271208,"dt":639159130857271695}
{"op":"mcm","id":2,"clk":"AKRnALFCANiGAQ==","pt":1780316285823,"mc":[{"id":"1.258742455","rc":[{"atl":[[5,12.77]],"batl":[],"id":10398159},{"batb":[[1,8.8,13.56]],"atb":[[8.8,13.56],[8.2,16.14]],"id":98117699},{"batb":[[2,9.6,9.05],[1,9.8,5.02]],"atb":[[9.4,7],[1.17,2],[9.8,5.02],[9.6,9.05]],"atl":[[1000,1]],"id":97736949}]}],"rt":639159130858312600,"dt":639159130858313152}
{"op":"mcm","id":2,"clk":"AKpnALNCAOWGAQ==","pt":1780316285923,"mc":[{"id":"1.258742455","rc":[{"tv":864.36,"trd":[[55,83.3]],"ltp":55,"atl":[[55,4.98]],"batl":[[0,55,4.98]],"id":98464183},{"batb":[[0,10,3.43]],"atb":[[10,3.43]],"atl":[[11,34.47]],"batl":[[1,11,34.47]],"id":97736949}],"tv":35745.05}],"rt":639159130859308271,"dt":639159130859308701}
{"op":"mcm","id":2,"clk":"AKxnALdCAO2GAQ==","pt":1780316286027,"mc":[{"id":"1.258742455","rc":[{"atl":[[5.1,42.18],[4.8,24.41]],"batl":[[1,4.8,24.41]],"id":10398159},{"tv":12236.21,"batb":[[0,3.75,2.5]],"trd":[[3.75,282.68]],"atb":[[3.75,2.5]],"id":88302242}],"tv":35746.19}],"rt":639159130860356541,"dt":639159130860357017}
{"op":"mcm","id":2,"clk":"AK5nALtCAPWGAQ==","pt":1780316286129,"mc":[{"id":"1.258742455","rc":[{"batb":[[2,46,1.68]],"atb":[[46,1.68]],"atl":[[55,5.84]],"batl":[[0,55,5.84]],"id":98464183},{"batb":[[2,3.6,86.87],[1,3.65,39.45],[0,3.7,68.76]],"atb":[[3.75,0]],"id":88302242}]}],"rt":639159130861367901,"dt":639159130861368393}
{"op":"mcm","id":2,"clk":"ALRnAMRCAISHAQ==","pt":1780316286285,"mc":[{"id":"1.258742455","rc":[{"batb":[[0,50,7.9]],"atb":[[50,7.9]],"id":98464183},{"batb":[],"atb":[[8.4,9.52]],"id":98117699}]}],"rt":639159130862926558,"dt":639159130862926945}
{"op":"mcm","id":2,"clk":"ALdnAMdCAIqHAQ==","pt":1780316286382,"mc":[{"id":"1.258742455","rc":[{"batb":[[0,50,8.76]],"atb":[[50,8.76]],"atl":[[55,5.07]],"batl":[[0,55,5.07]],"id":98464183}]}],"rt":639159130863900120,"dt":639159130863900551}
{"op":"mcm","id":2,"clk":"AMdnANVCAJuHAQ==","pt":1780316286693,"mc":[{"id":"1.258742455","rc":[{"batb":[],"atb":[[3.55,45.93]],"id":88302242}]}],"rt":639159130867010345,"dt":639159130867010689}
{"op":"mcm","id":2,"clk":"AM9nANtCAKOHAQ==","pt":1780316286838,"mc":[{"id":"1.258742455","rc":[{"batb":[[0,4.9,39.29]],"atb":[[4.9,39.29]],"id":99072898},{"batb":[[0,46,3.39]],"atb":[[46,3.39]],"id":97008932},{"batb":[[0,22,5.92]],"atb":[[22,5.92]],"id":99072900},{"batb":[[0,80,2.71]],"atb":[[80,2.71]],"id":99072901},{"batb":[[0,4.5,123.94]],"atb":[[4.5,123.94]],"id":10398159},{"batb":[[0,50,9.01]],"atb":[[50,9.01]],"id":98464183},{"batb":[[0,9,22.93]],"atb":[[9,22.93]],"id":98117699},{"batb":[[2,3.6,87.37],[0,3.7,71.11]],"atb":[[3.7,71.11],[3.6,87.37]],"id":88302242},{"batb":[[0,10,4.68]],"atb":[[10,4.68]],"id":97736949},{"batb":[[0,180,3.52]],"atb":[[180,3.52]],"id":99072897}]}],"rt":639159130868460946,"dt":639159130868461528}
{"op":"mcm","id":2,"clk":"ANdnAN1CAKmHAQ==","pt":1780316286899,"mc":[{"id":"1.258742455","rc":[{"batb":[],"atb":[[4.1,54.81]],"id":10398159},{"batb":[],"atb":[[3.5,69.59]],"id":88302242}]}],"rt":639159130869074772,"dt":639159130869075167}
{"op":"mcm","id":2,"clk":"AIBoAPFCAMmHAQ==","pt":1780316287312,"mc":[{"id":"1.258742455","rc":[{"atl":[[9.8,5.86]],"batl":[],"id":98117699},{"batb":[[2,3.6,87.87]],"atb":[[3.6,87.87]],"id":88302242}]}],"rt":639159130873201999,"dt":639159130873202362}
{"op":"mcm","id":2,"clk":"AIdoAPdCANaHAQ==","pt":1780316287418,"mc":[{"id":"1.258742455","rc":[{"batb":[[2,46,3.67]],"atb":[[46,3.67]],"id":98464183},{"batb":[],"atb":[[8.2,19.61]],"id":98117699}]}],"rt":639159130874258820,"dt":639159130874259263}
{"op":"mcm","id":2,"clk":"AJ9oAIZDAO\u002BHAQ==","pt":1780316287723,"mc":[{"id":"1.258742455","rc":[{"batb":[[0,22,8.28]],"atb":[[22,8.28]],"id":99072900},{"atl":[[4.7,106.77],[4.9,11.75]],"batl":[[2,4.9,11.75],[0,4.7,107.1]],"id":10398159},{"atl":[[11.5,17.46]],"batl":[],"id":98117699},{"atl":[[3.9,5.47],[3.95,71.69]],"batl":[[2,3.9,5.47]],"id":88302242}]}],"rt":639159130877310261,"dt":639159130877310872}
{"op":"mcm","id":2,"clk":"AKNoAIlDAPWHAQ==","pt":1780316287824,"mc":[{"id":"1.258742455","rc":[{"atl":[[4.8,23.12]],"batl":[[1,4.8,23.12]],"id":10398159},{"atl":[[12.5,10.74]],"batl":[],"id":98117699},{"batb":[[2,3.65,39.45],[1,3.7,71.11],[0,3.75,10.35]],"atb":[[3.75,10.35]],"id":88302242}]}],"rt":639159130878320834,"dt":639159130878321638}
{"op":"mcm","id":2,"clk":"AK5oAJJDAIKIAQ==","pt":1780316288032,"mc":[{"id":"1.258742455","rc":[{"batb":[[0,10,2.95]],"atb":[[10,2.95]],"id":97736949}]}],"rt":639159130880400838,"dt":639159130880401389}
{"op":"mcm","id":2,"clk":"ALJoAJVDAImIAQ==","pt":1780316288082,"mc":[{"id":"1.258742455","rc":[{"batb":[[0,46,3.91]],"atb":[[46,3.91]],"id":97008932},{"batb":[[0,4.5,126.15]],"atb":[[4.5,126.15]],"id":10398159},{"batb":[[0,9,25.15]],"atb":[[9,25.15]],"id":98117699},{"batb":[[2,3.65,39.95]],"atb":[[3.65,39.95],[1.17,195.27]],"id":88302242},{"batb":[[0,10,4.44]],"atb":[[10,4.44]],"atl":[[1000,1.42]],"id":97736949}]}],"rt":639159130880905142,"dt":639159130880905550}
{"op":"mcm","id":2,"clk":"ALtoAJpDAJCIAQ==","pt":1780316288187,"mc":[{"id":"1.258742455","rc":[{"batb":[[2,3.65,37.95]],"atb":[[3.65,37.95],[3.6,85.87]],"id":88302242}]}],"rt":639159130881946724,"dt":639159130881947120}
{"op":"mcm","id":2,"clk":"AL9oAJ5DAJiIAQ==","pt":1780316288287,"mc":[{"id":"1.258742455","rc":[{"atb":[[1.17,195.12]],"id":88302242},{"atl":[[1000,1]],"id":97736949}]}],"rt":639159130882947385,"dt":639159130882947795}
{"op":"mcm","id":2,"clk":"AMpoAKNDAJ6IAQ==","pt":1780316288390,"mc":[{"id":"1.258742455","rc":[{"tv":12247.57,"batb":[[0,3.75,4.82]],"trd":[[3.75,294.04]],"atb":[[3.75,4.82],[3.5,63.59]],"id":88302242},{"atl":[[11,34.89]],"batl":[[1,11,34.89]],"id":97736949}],"tv":35757.55}],"rt":639159130883985846,"dt":639159130883986259}
{"op":"mcm","id":2,"clk":"AM1oAKdDAKaIAQ==","pt":1780316288491,"mc":[{"id":"1.258742455","rc":[{"tv":12263.25,"batb":[[2,3.6,85.87],[1,3.65,37.95],[0,3.7,68.09]],"trd":[[3.75,303.68],[3.7,340.86]],"ltp":3.7,"atb":[[3.75,0],[3.7,68.09]],"atl":[[3.75,15]],"batl":[[2,3.85,13.41],[1,3.8,17.53],[0,3.75,15]],"id":88302242}],"tv":35773.23}],"rt":639159130884990701,"dt":639159130884991200}
{"op":"mcm","id":2,"clk":"ANJoAK1DALOIAQ==","pt":1780316288605,"mc":[{"id":"1.258742455","rc":[{"batb":[[0,22,10.94]],"atb":[[22,10.94]],"id":99072900},{"batb":[],"atb":[[3.55,51.93]],"atl":[[3.75,28.48]],"batl":[[0,3.75,28.48]],"id":88302242},{"batb":[[0,10,6.17]],"atb":[[10,6.17]],"id":97736949}]}],"rt":639159130886128337,"dt":639159130886128756}
{"op":"mcm","id":2,"clk":"AOFoALNDAMWIAQ==","pt":1780316288802,"mc":[{"id":"1.258742455","rc":[{"batb":[[0,22,12.09]],"atb":[[22,12.09]],"id":99072900}]}],"rt":639159130888101487,"dt":639159130888101879}
{"op":"mcm","id":2,"clk":"AONoALdDAM2IAQ==","pt":1780316288906,"mc":[{"id":"1.258742455","rc":[{"tv":2284.83,"trd":[[9.4,145.55],[9.2,181.93]],"ltp":9.4,"atl":[[9.4,13.27],[9.2,0]],"batl":[[2,9.8,5.86],[1,9.6,7.78],[0,9.4,13.27]],"id":98117699},{"batb":[[1,3.65,38.45]],"atb":[[3.65,38.45]],"id":88302242}],"tv":35793.23}],"rt":639159130889162553,"dt":639159130889163016}
{"op":"mcm","id":2,"clk":"AOhoALtDANGIAQ==","pt":1780316289006,"mc":[{"id":"1.258742455","rc":[{"batb":[[0,9,32.81]],"atb":[[9,32.81]],"id":98117699}]}],"rt":639159130890140265,"dt":639159130890140603}
{"op":"mcm","id":2,"clk":"AO9oAMRDAOSIAQ==","pt":1780316289216,"mc":[{"id":"1.258742455","rc":[{"batb":[],"atb":[[3.55,45.93]],"id":88302242}]}],"rt":639159130892240470,"dt":639159130892240832}
{"op":"mcm","id":2,"clk":"APNoAMdDAOiIAQ==","pt":1780316289313,"mc":[{"id":"1.258742455","rc":[{"tv":2294.83,"batb":[[0,9,27.81]],"trd":[[9,16]],"ltp":9,"atb":[[8.4,5.44],[9,27.81]],"atl":[[10,5.87]],"batl":[],"id":98117699}],"tv":35803.23}],"rt":639159130893209954,"dt":639159130893210396}
{"op":"mcm","id":2,"clk":"APxoAMpDAO\u002BIAQ==","pt":1780316289415,"mc":[{"id":"1.258742455","rc":[{"atl":[[9.2,2.96]],"batl":[[2,9.6,7.78],[1,9.4,13.27],[0,9.2,2.96]],"id":98117699},{"batb":[],"atb":[[3.5,69.59]],"id":88302242}]}],"rt":639159130894236151,"dt":639159130894236523}
{"op":"mcm","id":2,"clk":"AP1oAMpDAPSIAQ==","pt":1780316289515,"mc":[{"id":"1.258742455","rc":[{"atl":[[10.5,14.54]],"batl":[],"id":98117699},{"tv":12273.25,"batb":[[0,3.7,63.09]],"trd":[[3.7,350.86]],"atb":[[3.7,63.09]],"id":88302242}],"tv":35813.23}],"rt":639159130895234169,"dt":639159130895234607}
{"op":"mcm","id":2,"clk":"AIlpAM1DAPuIAQ==","pt":1780316289631,"mc":[{"id":"1.258742455","rc":[{"tv":12287.05,"batb":[[0,3.7,56.19]],"trd":[[3.7,364.66]],"atb":[[3.7,56.19]],"id":88302242}],"tv":35827.03}],"rt":639159130896394250,"dt":639159130896394616}
{"op":"mcm","id":2,"clk":"AJppANtDAKCJAQ==","pt":1780316290027,"mc":[{"id":"1.258742455","rc":[{"atl":[[3.75,53.48]],"batl":[[0,3.75,53.48]],"id":88302242}]}],"rt":639159130900356582,"dt":639159130900357044}
{"op":"mcm","id":2,"clk":"AKFpAOBDAKiJAQ==","pt":1780316290140,"mc":[{"id":"1.258742455","rc":[{"batb":[[0,4.9,40.34]],"atb":[[4.9,40.34]],"id":99072898},{"atl":[[1000,0.34]],"id":97008932},{"batb":[[0,4.5,137.52]],"atb":[[4.5,137.52]],"id":10398159},{"atl":[[10.5,8.54]],"batl":[],"id":98117699},{"atl":[[1000,3.63]],"id":88302242},{"atb":[[6,1]],"id":97736949},{"batb":[[0,180,3.22]],"atb":[[180,3.22]],"id":99072897}]}],"rt":639159130901482155,"dt":639159130901482735}
{"op":"mcm","id":2,"clk":"AKZpAOJDAK2JAQ==","pt":1780316290189,"mc":[{"id":"1.258742455","rc":[{"atl":[[1000,0.22]],"id":97008932},{"batb":[[0,3.7,51.07]],"atb":[[3.7,51.07]],"atl":[[1000,3],[3.75,58.6]],"batl":[[0,3.75,58.6]],"id":88302242}]}],"rt":639159130901968325,"dt":639159130901968789}
{"op":"mcm","id":2,"clk":"AKppAORDALOJAQ==","pt":1780316290287,"mc":[{"id":"1.258742455","rc":[{"atl":[[48,0.76]],"batl":[[0,50,11.79]],"id":97008932},{"atl":[[10,11.87]],"batl":[],"id":98117699},{"batb":[[0,3.7,12.72]],"atb":[[3.7,12.72]],"atl":[[3.75,59.23]],"batl":[[0,3.75,59.23]],"id":88302242},{"batb":[[1,170,1.67]],"atb":[[170,1.67]],"id":99072897}]}],"rt":639159130902954508,"dt":639159130902955008}
{"op":"mcm","id":2,"clk":"ALNpAOhDALqJAQ==","pt":1780316290392,"mc":[{"id":"1.258742455","rc":[{"tv":12312.49,"batb":[[2,3.55,45.93],[1,3.6,85.87],[0,3.65,38.45]],"trd":[[3.7,390.1]],"atb":[[3.7,0]],"atl":[[3.7,10.73]],"batl":[[2,3.8,17.53],[1,3.75,59.23],[0,3.7,10.73]],"id":88302242},{"batb":[[0,1000,93]],"atb":[[1000,93]],"id":10445502}],"tv":35852.47}],"rt":639159130904004461,"dt":639159130904004985}
{"op":"mcm","id":2,"clk":"ALhpAO5DAMCJAQ==","pt":1780316290491,"mc":[{"id":"1.258742455","rc":[{"atl":[[5.1,12.64]],"batl":[[1,5.1,12.64]],"id":99072898},{"atl":[[4.9,8.51]],"batl":[[2,4.9,8.51]],"id":10398159},{"batb":[],"atb":[[8.4,9.22]],"id":98117699},{"batb":[[1,3.6,76.47],[0,3.65,29.65]],"atb":[[3.65,29.65],[3.6,76.47]],"id":88302242}]}],"rt":639159130904992337,"dt":639159130904992874}
{"op":"mcm","id":2,"clk":"ALxpAPJDAMmJAQ==","pt":1780316290595,"mc":[{"id":"1.258742455","rc":[{"atl":[[5.2,27.06]],"batl":[[2,5.2,27.06]],"id":99072898},{"batb":[[2,8.6,14.72]],"atb":[[8.6,14.72]],"atl":[[9.2,0]],"batl":[[2,9.8,5.86],[1,9.6,7.78],[0,9.4,13.27]],"id":98117699},{"batb":[[2,3.55,36.42]],"atb":[[3.5,60.01],[3.55,36.42]],"id":88302242}]}],"rt":639159130906026137,"dt":639159130906026535}
{"op":"mcm","id":2,"clk":"AMJpAPZDANGJAQ==","pt":1780316290700,"mc":[{"id":"1.258742455","rc":[{"atl":[[3.95,65.69]],"batl":[],"id":88302242}]}],"rt":639159130907077460,"dt":639159130907077813}
{"op":"mcm","id":2,"clk":"AM1pAP1DAN\u002BJAQ==","pt":1780316290909,"mc":[{"id":"1.258742455","rc":[{"atl":[[1000,2]],"id":98464183},{"atl":[[10,5.87]],"batl":[],"id":98117699},{"batb":[],"atb":[[3.5,54.01]],"atl":[[3.9,11.47]],"batl":[],"id":88302242}]}],"rt":639159130909167535,"dt":639159130909167965}
{"op":"mcm","id":2,"clk":"AN5pAIZEAOyJAQ==","pt":1780316291115,"mc":[{"id":"1.258742455","rc":[{"atl":[[1000,0.14]],"id":98464183},{"atl":[[10.5,14.54]],"batl":[],"id":98117699},{"batb":[],"atb":[[3.45,28.96]],"id":88302242}]}],"rt":639159130911230487,"dt":639159130911230931}
{"op":"mcm","id":2,"clk":"AORpAIpEAPWJAQ==","pt":1780316291213,"mc":[{"id":"1.258742455","rc":[{"atl":[[1000,0]],"id":98464183},{"batb":[],"atb":[[9,6.5]],"id":97736949}]}],"rt":639159130912212072,"dt":639159130912212415}
{"op":"mcm","id":2,"clk":"AOxpAI5EAPyJAQ==","pt":1780316291315,"mc":[{"id":"1.258742455","rc":[{"tv":1052.31,"batb":[[0,22,12.88]],"trd":[[23,53.86]],"atb":[[23,0.79]],"atl":[[23,0]],"batl":[[2,26,4.5],[1,25,3.91],[0,24,4.69]],"id":99072900},{"tv":864.64,"batb":[[0,50,8.87]],"trd":[[50,124.64]],"ltp":50,"atb":[[50,8.87]],"id":98464183},{"tv":2368.1,"trd":[[10.5,93.83]],"ltp":10.5,"atl":[[10.5,15.96]],"batl":[[0,10.5,15.96]],"id":97736949}],"tv":35862.65}],"rt":639159130913242471,"dt":639159130913242990}
{"op":"mcm","id":2,"clk":"APdpAJJEAIOKAQ==","pt":1780316291419,"mc":[{"id":"1.258742455","rc":[{"atl":[[32,1.85]],"id":10398159},{"batb":[[0,50,9.87]],"atb":[[50,9.87]],"id":98464183},{"batb":[[0,10,8.42]],"atb":[[10,8.42]],"id":97736949},{"batb":[[1,170,3.4]],"atb":[[170,3.4]],"id":99072897}]}],"rt":639159130914269163,"dt":639159130914269559}
{"op":"mcm","id":2,"clk":"AIhqAJxEAJaKAQ==","pt":1780316291625,"mc":[{"id":"1.258742455","rc":[{"atl":[[3.8,22.03]],"batl":[[2,3.8,22.03]],"id":88302242},{"atl":[[11,34.74]],"batl":[[1,11,34.74]],"id":97736949}]}],"rt":639159130916334251,"dt":639159130916334629}
{"op":"mcm","id":2,"clk":"AKpqALJEALqKAQ==","pt":1780316291988,"mc":[{"id":"1.258742455","rc":[{"atl":[[11,36.34]],"batl":[[1,11,36.34]],"id":97736949}]}],"rt":639159130919967974,"dt":639159130919968329}
{"op":"mcm","id":2,"clk":"ALFqALZEAMCKAQ==","pt":1780316292094,"mc":[{"id":"1.258742455","rc":[{"batb":[[2,8.8,13.56],[1,9,27.81],[0,9.2,1]],"atb":[[9.2,1]],"id":98117699},{"atb":[[1.17,195.58]],"atl":[[3.8,17.53]],"batl":[[2,3.8,17.53]],"id":88302242},{"atl":[[11,36.87]],"batl":[[1,11,36.87]],"id":97736949}]}],"rt":639159130921019769,"dt":639159130921020205}
{"op":"mcm","id":2,"clk":"ALtqALxEAMmKAQ==","pt":1780316292197,"mc":[{"id":"1.258742455","rc":[{"batb":[[2,46,3.49]],"atb":[[46,3.49]],"id":98464183},{"batb":[],"atb":[[8.2,16.14]],"id":98117699},{"atb":[[1.17,195.12]],"atl":[[3.7,183.71]],"batl":[[0,3.7,183.71]],"id":88302242},{"batb":[],"atb":[[8.4,19.65],[8.2,23.56],[9.2,19.33]],"id":97736949}]}],"rt":639159130922051316,"dt":639159130922051734}
{"op":"mcm","id":2,"clk":"AMNqAL9EANeKAQ==","pt":1780316292302,"mc":[{"id":"1.258742455","rc":[{"tv":12350.49,"batb":[[2,3.5,54.01],[1,3.55,36.42],[0,3.6,76.47]],"trd":[[3.65,227.55]],"ltp":3.65,"atb":[[3.65,0]],"atl":[[3.65,6.88],[3.7,187.71]],"batl":[[2,3.75,59.23],[1,3.7,187.71],[0,3.65,6.88]],"id":88302242},{"tv":2388.1,"trd":[[10.5,113.83]],"atl":[[10.5,5.96]],"batl":[[0,10.5,5.96]],"id":97736949}],"tv":35920.65}],"rt":639159130923104593,"dt":639159130923105119}
{"op":"mcm","id":2,"clk":"AM5qAMNEANuKAQ==","pt":1780316292400,"mc":[{"id":"1.258742455","rc":[{"atl":[[5,9.57]],"batl":[],"id":10398159},{"batb":[],"atb":[[8.2,10.14]],"id":98117699},{"batb":[],"atb":[[3.4,22.05],[3.45,19.37]],"atl":[[3.65,8.01],[3.7,192.78]],"batl":[[1,3.7,192.78],[0,3.65,8.01]],"id":88302242},{"batb":[[0,10,12.88]],"atb":[[10,12.88]],"id":97736949}]}],"rt":639159130924081772,"dt":639159130924082205}
{"op":"mcm","id":2,"clk":"ANhqAMlEAOOKAQ==","pt":1780316292508,"mc":[{"id":"1.258742455","rc":[{"tv":8037.04,"batb":[[2,4.4,150.04],[1,4.5,137.52],[0,4.6,10.33]],"trd":[[4.6,1196.34]],"atb":[[4.6,10.33]],"atl":[[4.6,0]],"batl":[[0,4.7,106.77]],"id":10398159},{"tv":12364.07,"trd":[[3.65,241.13]],"atl":[[3.65,1.22]],"batl":[[0,3.65,1.22]],"id":88302242},{"batb":[[0,10,14.73]],"atb":[[10,14.73]],"id":97736949}],"tv":35934.89}],"rt":639159130925165417,"dt":639159130925165983}
{"op":"mcm","id":2,"clk":"AOJqAM1EAOWKAQ==","pt":1780316292605,"mc":[{"id":"1.258742455","rc":[{"batb":[[0,4.6,27.07]],"atb":[[4.6,27.07]],"id":10398159},{"batb":[],"atb":[[8.4,15.22]],"id":98117699},{"batb":[[0,3.6,60.85]],"atb":[[3.6,60.85]],"id":88302242}]}],"rt":639159130926132360,"dt":639159130926132815}
{"op":"mcm","id":2,"clk":"AOlqANVEAO2KAQ==","pt":1780316292711,"mc":[{"id":"1.258742455","rc":[{"batb":[[0,4.6,59.59]],"atb":[[4.1,44.33],[4.6,59.59]],"atl":[[4.7,46.59],[4.8,65.97]],"batl":[[1,4.8,65.97],[0,4.7,46.59]],"id":10398159},{"atl":[[10,3.87]],"batl":[],"id":98117699},{"tv":12366.51,"trd":[[3.65,243.57]],"atl":[[3.65,0],[3.9,5.47],[3.95,26.55],[3.85,83.43]],"batl":[[2,3.8,17.53],[1,3.75,59.23],[0,3.7,192.78]],"id":88302242},{"atl":[[11.5,15.37],[11,16.45],[10.5,5.04]],"batl":[[2,11.5,15.37],[1,11,16.45],[0,10.5,5.04]],"id":97736949}],"tv":35937.33}],"rt":639159130927194296,"dt":639159130927194810}
{"op":"mcm","id":2,"clk":"AO5qANlEAPWKAQ==","pt":1780316292813,"mc":[{"id":"1.258742455","rc":[{"batb":[],"atb":[[4.1,38.33]],"id":10398159},{"atl":[[9.6,9.78]],"batl":[[1,9.6,9.78]],"id":98117699},{"batb":[],"atb":[[3.45,13.37]],"id":88302242},{"tv":2389.94,"batb":[[2,9.6,14.71],[1,9.8,10.68],[0,10,19.47]],"trd":[[10,171.3]],"ltp":10,"atb":[[9.8,10.68],[10,19.47],[9.6,14.71]],"id":97736949}],"tv":35939.17}],"rt":639159130928209308,"dt":639159130928209789}
{"op":"mcm","id":2,"clk":"APVqAOFEAPiKAQ==","pt":1780316292911,"mc":[{"id":"1.258742455","rc":[{"atl":[[3.65,11.2],[3.85,89.43]],"batl":[[2,3.75,59.23],[1,3.7,192.78],[0,3.65,11.2]],"id":88302242},{"tv":2398.38,"batb":[[0,10,20.65]],"trd":[[10.5,122.27]],"ltp":10.5,"atb":[[10,20.65]],"atl":[[10.5,0.82]],"batl":[[2,12,5.56],[1,11.5,15.37],[0,11,17.27]],"id":97736949}],"tv":35947.61}],"rt":639159130929194056,"dt":639159130929194491}
{"op":"mcm","id":2,"clk":"APhqAOREAIKLAQ==","pt":1780316293017,"mc":[{"id":"1.258742455","rc":[{"batb":[],"atb":[[4.2,35.29]],"id":10398159},{"batb":[],"atb":[[3.4,28.05]],"id":88302242},{"batb":[[0,10,25.08]],"atb":[[10,25.08]],"id":97736949},{"batb":[[1,170,1.67]],"atb":[[170,1.67]],"id":99072897}]}],"rt":639159130930250482,"dt":639159130930250842}
{"op":"mcm","id":2,"clk":"APxqAOhEAIeLAQ==","pt":1780316293117,"mc":[{"id":"1.258742455","rc":[{"atl":[[5,6.75]],"batl":[[0,5,6.75]],"id":99072898},{"atl":[[24,3.65]],"batl":[[0,24,3.65]],"id":99072900},{"tv":12374.93,"trd":[[3.65,251.99]],"atl":[[1000,3.88],[3.65,6.99]],"batl":[[0,3.65,6.99]],"id":88302242},{"tv":2400.02,"batb":[[2,9.8,10.68],[1,10,25.08],[0,10.5,2.75]],"trd":[[10.5,123.91]],"atb":[[10.5,2.75],[9.2,14.38]],"atl":[[11,9.26],[10.5,0]],"batl":[[0,11,9.26]],"id":97736949},{"atl":[[190,0.58]],"batl":[[0,210,1.64]],"id":99072897}],"tv":35957.67}],"rt":639159130931253140,"dt":639159130931253643}
{"op":"mcm","id":2,"clk":"AIBrAO5EAJCLAQ==","pt":1780316293226,"mc":[{"id":"1.258742455","rc":[{"tv":7593.99,"batb":[[0,4.9,37.77]],"trd":[[4.9,73.46]],"ltp":4.9,"atb":[[4.9,37.77]],"id":99072898},{"tv":1053.89,"batb":[[0,22,12.09]],"trd":[[23,55.44]],"atb":[[23,0]],"id":99072900},{"atl":[[1000,3]],"id":88302242}],"tv":35964.39}],"rt":639159130932345168,"dt":639159130932345664}
{"op":"mcm","id":2,"clk":"AIZrAPNEAJiLAQ==","pt":1780316293328,"mc":[{"id":"1.258742455","rc":[{"tv":8039.04,"batb":[[0,4.6,58.59]],"trd":[[4.6,1198.34]],"atb":[[1.17,2.06],[4.6,58.59]],"id":10398159},{"atl":[[3.8,18.41]],"batl":[],"id":88302242}],"tv":35966.39}],"rt":639159130933361492,"dt":639159130933362006}
{"op":"mcm","id":2,"clk":"AItrAPdEAKCLAQ==","pt":1780316293435,"mc":[{"id":"1.258742455","rc":[{"atb":[[1.05,300.6]],"id":99072898},{"atb":[[1.11,39.14]],"id":97008932},{"atb":[[1.05,2604.4]],"atl":[[1000,6.66]],"id":99072900},{"batb":[[0,80,2.92]],"atb":[[80,2.92]],"id":99072901},{"atb":[[1.17,2]],"id":10398159},{"atb":[[1.17,2.17]],"id":98464183},{"tv":12379.81,"trd":[[3.65,256.87]],"atl":[[3.65,4.55]],"batl":[[0,3.65,4.55]],"id":88302242},{"batb":[],"atb":[[9.2,8.38]],"atl":[[12.5,4.71]],"batl":[],"id":97736949},{"atl":[[1000,8.8]],"batl":[],"id":99072897}],"tv":35971.27}],"rt":639159130934427932,"dt":639159130934428396}
{"op":"mcm","id":2,"clk":"AJNrAPlEAKmLAQ==","pt":1780316293536,"mc":[{"id":"1.258742455","rc":[{"tv":542.53,"trd":[[50,79.18],[48,44.32]],"ltp":50,"atl":[[50,10.93],[48,0]],"batl":[[0,50,10.93]],"id":97008932},{"atl":[[1000,6.25]],"id":99072900},{"batb":[[0,4.6,58.65]],"atb":[[4.6,58.65]],"id":10398159},{"atb":[[1.17,2]],"id":98464183}],"tv":35973.01}],"rt":639159130935441354,"dt":639159130935441828}
{"op":"mcm","id":2,"clk":"AJlrAP9EAK\u002BLAQ==","pt":1780316293632,"mc":[{"id":"1.258742455","rc":[{"atb":[[1.11,39.06]],"id":97008932},{"atl":[[23,0.41]],"batl":[[0,24,4.06]],"id":99072900},{"atb":[[1.17,3.14]],"atl":[[4.7,46.15]],"batl":[[0,4.7,46.15]],"id":10398159},{"batb":[[0,50,10.04]],"atb":[[50,10.04]],"id":98464183},{"atl":[[9.4,12.72]],"batl":[[0,9.4,12.72]],"id":98117699},{"batb":[[0,3.6,59.93]],"atb":[[3.6,59.93]],"id":88302242},{"batb":[],"atb":[[9.4,13]],"atl":[[13,10.72]],"batl":[],"id":97736949},{"atl":[[1000,8.75]],"batl":[],"id":99072897}]}],"rt":639159130936403621,"dt":639159130936404072}
{"op":"mcm","id":2,"clk":"AJtrAIBFALKLAQ==","pt":1780316293732,"mc":[{"id":"1.258742455","rc":[{"batb":[[0,4.9,28.29]],"atb":[[4.9,28.29]],"id":99072898},{"batb":[[0,46,3.99]],"atb":[[46,3.99]],"id":97008932},{"tv":12382.37,"trd":[[3.65,259.43]],"atl":[[3.65,3.27]],"batl":[[0,3.65,3.27]],"id":88302242},{"atl":[[190,0.63]],"batl":[[0,210,1.69]],"id":99072897}],"tv":35975.57}],"rt":639159130937405978,"dt":639159130937406475}
{"op":"mcm","id":2,"clk":"AKJrAIFFALyLAQ==","pt":1780316293833,"mc":[{"id":"1.258742455","rc":[{"atb":[[1.17,2]],"id":10398159},{"batb":[[0,9.2,3.9]],"atb":[[9.2,3.9]],"id":98117699}]}],"rt":639159130938410928,"dt":639159130938411294}
{"op":"mcm","id":2,"clk":"AKZrAIVFAMiLAQ==","pt":1780316293936,"mc":[{"id":"1.258742455","rc":[{"tv":8039.42,"batb":[[0,4.6,59.6]],"trd":[[4.7,701.34]],"ltp":4.7,"atb":[[4.6,59.6]],"atl":[[4.7,45.95]],"batl":[[0,4.7,45.95]],"id":10398159},{"batb":[[2,8.8,17.31]],"atb":[[8.8,17.31]],"id":98117699}],"tv":35975.95}],"rt":639159130939444986,"dt":639159130939445421}
{"op":"mcm","id":2,"clk":"ALBrAI5FANGLAQ==","pt":1780316294093,"mc":[{"id":"1.258742455","rc":[{"tv":7607.49,"batb":[[2,4.8,52.32],[1,4.9,28.29],[0,5,3.25]],"trd":[[5,39.04]],"ltp":5,"atb":[[5,3.25]],"atl":[[5,0]],"batl":[[2,5.3,26.52],[1,5.2,27.06],[0,5.1,12.64]],"id":99072898},{"batb":[[0,10.5,3.47]],"atb":[[10.5,3.47]],"id":97736949}],"tv":35989.45}],"rt":639159130941010577,"dt":639159130941011075}
{"op":"mcm","id":2,"clk":"ALhrAJNFANmLAQ==","pt":1780316294194,"mc":[{"id":"1.258742455","rc":[{"tv":7614,"batb":[[2,4.7,29.1],[1,4.8,52.32],[0,4.9,38.44]],"trd":[[5,45.55]],"atb":[[4.9,38.44],[5,0]],"atl":[[5,3.25]],"batl":[[2,5.2,27.06],[1,5.1,12.64],[0,5,3.25]],"id":99072898},{"batb":[[2,8.8,13.56]],"atb":[[8.8,13.56]],"id":98117699},{"atl":[[3.75,79.23]],"batl":[[2,3.75,79.23]],"id":88302242},{"tv":2400.3,"trd":[[11,84.99]],"ltp":11,"atl":[[11,9.12]],"batl":[[0,11,9.12]],"id":97736949}],"tv":35996.24}],"rt":639159130942029364,"dt":639159130942029877}
{"op":"mcm","id":2,"clk":"AMBrAJhFAOGLAQ==","pt":1780316294297,"mc":[{"id":"1.258742455","rc":[{"batb":[],"atb":[[4.1,6.18]],"atl":[[5,18.42]],"batl":[[0,5,18.42]],"id":99072898},{"batb":[[2,8.8,17.31]],"atb":[[8.8,17.31]],"id":98117699},{"tv":12385.35,"trd":[[3.65,262.41]],"atl":[[3.65,1.78]],"batl":[[0,3.65,1.78]],"id":88302242}],"tv":35999.22}],"rt":639159130943050795,"dt":639159130943051288}
{"op":"mcm","id":2,"clk":"AMZrAJtFAOuLAQ==","pt":1780316294398,"mc":[{"id":"1.258742455","rc":[{"batb":[],"atb":[[4.5,37.76]],"id":99072898}]}],"rt":639159130944061426,"dt":639159130944061774}
{"op":"mcm","id":2,"clk":"AMxrAJxFAPKLAQ==","pt":1780316294501,"mc":[{"id":"1.258742455","rc":[{"batb":[[0,50,10.14]],"atb":[[50,10.14]],"id":98464183},{"tv":12388.91,"trd":[[3.65,265.97]],"atl":[[3.65,0]],"batl":[[2,3.8,18.41],[1,3.75,79.23],[0,3.7,192.78]],"id":88302242},{"batb":[[0,10.5,5.53]],"atb":[[10.5,5.53]],"id":97736949}],"tv":36002.78}],"rt":639159130945094173,"dt":639159130945094570}
{"op":"mcm","id":2,"clk":"ANRrAJ9FAPuLAQ==","pt":1780316294605,"mc":[{"id":"1.258742455","rc":[{"batb":[],"atb":[[4.6,36.34]],"id":99072898}]}],"rt":639159130946140979,"dt":639159130946141341}
{"op":"mcm","id":2,"clk":"ANxrAKRFAISMAQ==","pt":1780316294713,"mc":[{"id":"1.258742455","rc":[{"tv":7631.24,"batb":[[2,4.8,52.32],[1,4.9,38.44],[0,5,9.58]],"trd":[[5,62.79]],"atb":[[5,9.58]],"atl":[[5.2,5.95],[5.3,9.17],[5,0]],"batl":[[2,5.3,9.17],[1,5.2,5.95],[0,5.1,12.64]],"id":99072898},{"atl":[[4.7,50.89]],"batl":[[0,4.7,50.89]],"id":10398159},{"atl":[[3.65,12.93]],"batl":[[2,3.75,79.23],[1,3.7,192.78],[0,3.65,12.93]],"id":88302242}],"tv":36020.02}],"rt":639159130947217341,"dt":639159130947217996}
{"op":"mcm","id":2,"clk":"AOFrAKdFAIqMAQ==","pt":1780316294812,"mc":[{"id":"1.258742455","rc":[{"batb":[],"atb":[[4.5,27.56]],"id":99072898},{"batb":[[2,8.8,13.56]],"atb":[[8.8,13.56]],"id":98117699},{"tv":12397.45,"batb":[[0,3.6,55.66]],"trd":[[3.6,542.88]],"ltp":3.6,"atb":[[3.6,55.66]],"atl":[[3.65,14.82]],"batl":[[0,3.65,14.82]],"id":88302242},{"batb":[],"atb":[[9.2,2.73]],"id":97736949}],"tv":36028.56}],"rt":639159130948204277,"dt":639159130948204764}
{"op":"mcm","id":2,"clk":"AOVrAKpFAJGMAQ==","pt":1780316294915,"mc":[{"id":"1.258742455","rc":[{"atl":[[5.1,8.58]],"batl":[[0,5.1,8.58]],"id":99072898},{"batb":[[0,9.2,1]],"atb":[[9.2,1]],"id":98117699},{"batb":[[0,3.6,45.62]],"atb":[[3.6,45.62]],"atl":[[3.75,64.23],[3.85,83.43]],"batl":[[2,3.75,64.23]],"id":88302242}]}],"rt":639159130949236723,"dt":639159130949237200}
{"op":"mcm","id":2,"clk":"AO9rAK1FAJiMAQ==","pt":1780316295019,"mc":[{"id":"1.258742455","rc":[{"batb":[[0,5,14.67]],"atb":[[5,14.67]],"id":99072898}]}],"rt":639159130950275937,"dt":639159130950276340}
{"op":"mcm","id":2,"clk":"APdrALBFAKGMAQ==","pt":1780316295115,"mc":[{"id":"1.258742455","rc":[{"atl":[[5.2,14.68]],"batl":[[1,5.2,14.68]],"id":99072898},{"tv":1059.89,"batb":[[0,22,9.09]],"trd":[[22,75.22]],"ltp":22,"atb":[[22,9.09]],"id":99072900},{"atl":[[3.9,11.47]],"batl":[],"id":88302242},{"tv":2401.09,"trd":[[11,85.78]],"atl":[[11,8.73]],"batl":[[0,11,8.73]],"id":97736949}],"tv":36035.35}],"rt":639159130951238239,"dt":639159130951238729}
{"op":"mcm","id":2,"clk":"AP9rALNFAKuMAQ==","pt":1780316295221,"mc":[{"id":"1.258742455","rc":[{"atl":[[5.4,29.65]],"batl":[],"id":99072898},{"atl":[[23,2.38]],"batl":[[2,25,3.91],[1,24,3.65],[0,23,2.38]],"id":99072900}]}],"rt":639159130952292997,"dt":639159130952293371}
{"op":"mcm","id":2,"clk":"AIZsALpFALCMAQ==","pt":1780316295320,"mc":[{"id":"1.258742455","rc":[{"atl":[[5.3,6]],"batl":[[2,5.3,6]],"id":99072898}]}],"rt":639159130953285419,"dt":639159130953285812}
{"op":"mcm","id":2,"clk":"AJRsAMNFAMCMAQ==","pt":1780316295430,"mc":[{"id":"1.258742455","rc":[{"atl":[[5.5,34.48]],"batl":[],"id":99072898},{"batb":[[0,22,6.43]],"atb":[[22,6.43]],"atl":[[23,3.35]],"batl":[[0,23,3.35]],"id":99072900}]}],"rt":639159130954382185,"dt":639159130954382578}
{"op":"mcm","id":2,"clk":"AKVsAMhFAM2MAQ==","pt":1780316295628,"mc":[{"id":"1.258742455","rc":[{"batb":[[0,22,5.28]],"atb":[[22,5.28]],"id":99072900}]}],"rt":639159130956366410,"dt":639159130956366759}
{"op":"mcm","id":2,"clk":"AKxsANJFANWMAQ==","pt":1780316295734,"mc":[{"id":"1.258742455","rc":[{"batb":[[2,4.8,47.13]],"atb":[[4.8,47.13]],"id":99072898},{"tv":8041.44,"batb":[[0,4.6,58.59]],"trd":[[4.6,1200.36]],"ltp":4.6,"atb":[[4.6,58.59]],"id":10398159},{"atl":[[3.9,5.47],[3.7,209.44]],"batl":[[1,3.7,209.44]],"id":88302242}],"tv":36037.37}],"rt":639159130957420292,"dt":639159130957420834}
{"op":"mcm","id":2,"clk":"ALVsANZFANuMAQ==","pt":1780316295833,"mc":[{"id":"1.258742455","rc":[{"batb":[[1,4.9,39.44]],"atb":[[4.9,39.44]],"id":99072898},{"batb":[[0,22,2.92]],"atb":[[22,2.92]],"id":99072900},{"batb":[[1,9,28.81]],"atb":[[9,28.81]],"id":98117699},{"batb":[[1,10,26.08]],"atb":[[10,26.08]],"id":97736949}]}],"rt":639159130958407661,"dt":639159130958408049}
{"op":"mcm","id":2,"clk":"AL1sANhFAN6MAQ==","pt":1780316295935,"mc":[{"id":"1.258742455","rc":[{"batb":[[2,4.8,44.27],[1,4.9,40.41],[0,5,16.69]],"atb":[[4.9,40.41],[5,16.69],[4.8,44.27]],"id":99072898},{"atl":[[55,19.64],[50,10.82]],"batl":[[1,55,19.64],[0,50,10.82]],"id":97008932},{"batb":[[1,4.5,123.94],[0,4.6,63.22]],"atb":[[4.6,63.22],[4.5,123.94]],"id":10398159},{"batb":[[1,9,26.59]],"atb":[[1.17,2.35],[9,26.59]],"atl":[[1000,6.52]],"id":98117699},{"atb":[[1.17,196.12]],"atl":[[3.65,15.92],[3.75,63.6],[3.8,17.53],[3.85,89.43]],"batl":[[2,3.75,63.6],[0,3.65,15.92]],"id":88302242},{"batb":[[1,10,24.59],[0,10.5,7.25]],"atb":[[10.5,7.25],[10,24.59]],"atl":[[1000,1.61],[11,8.31]],"batl":[[0,11,8.31]],"id":97736949},{"atl":[[190,0.48]],"batl":[[0,210,1.54]],"id":99072897}]}],"rt":639159130959438179,"dt":639159130959438776}
{"op":"mcm","id":2,"clk":"AMNsANxFAOWMAQ==","pt":1780316295994,"mc":[{"id":"1.258742455","rc":[{"atl":[[1000,6.25]],"id":98117699},{"atb":[[1.17,196.29]],"id":88302242},{"atl":[[1000,1.26]],"id":97736949}]}],"rt":639159130960023936,"dt":639159130960024317}
{"op":"mcm","id":2,"clk":"AMlsAN9FAOiMAQ==","pt":1780316296092,"mc":[{"id":"1.258742455","rc":[{"atb":[[1.17,2]],"atl":[[9.4,12.99]],"batl":[[0,9.4,12.99]],"id":98117699},{"atb":[[1.17,196.12]],"atl":[[3.65,17.92]],"batl":[[0,3.65,17.92]],"id":88302242},{"atl":[[1000,1],[11.5,15.72]],"batl":[[1,11.5,15.72]],"id":97736949}]}],"rt":639159130961002239,"dt":639159130961002717}
{"op":"mcm","id":2,"clk":"AM9sAONFAOyMAQ==","pt":1780316296193,"mc":[{"id":"1.258742455","rc":[{"batb":[[0,9.2,1.35]],"atb":[[9.2,1.35]],"id":98117699},{"batb":[[0,3.6,45.79]],"atb":[[3.6,45.79]],"id":88302242},{"batb":[[0,10.5,8]],"atb":[[10.5,8]],"atl":[[11,8.57]],"batl":[[0,11,8.57]],"id":97736949}]}],"rt":639159130962012077,"dt":639159130962012537}
{"op":"mcm","id":2,"clk":"ANhsAOZFAPSMAQ==","pt":1780316296297,"mc":[{"id":"1.258742455","rc":[{"atl":[[5.5,37.7]],"batl":[],"id":99072898}]}],"rt":639159130963058070,"dt":639159130963058433}
{"op":"mcm","id":2,"clk":"AORsAOpFAIONAQ==","pt":1780316296502,"mc":[{"id":"1.258742455","rc":[{"batb":[[2,46,3.36]],"atb":[[46,3.36]],"id":98464183},{"atl":[[200,0.12]],"batl":[[0,210,1.34]],"id":99072897}]}],"rt":639159130965100797,"dt":639159130965101205}
{"op":"mcm","id":2,"clk":"AOpsAO9FAIuNAQ==","pt":1780316296604,"mc":[{"id":"1.258742455","rc":[{"tv":2401.37,"trd":[[11,86.06]],"atl":[[11,8.43]],"batl":[[0,11,8.43]],"id":97736949}],"tv":36037.65}],"rt":639159130966121805,"dt":639159130966122209}
{"op":"mcm","id":2,"clk":"AP1sAPlFAKONAQ==","pt":1780316296917,"mc":[{"id":"1.258742455","rc":[{"batb":[[0,22,4.96]],"atb":[[22,4.96]],"id":99072900},{"batb":[[2,3.5,61.5],[1,3.55,43.91]],"atb":[[3.5,61.5],[3.55,43.91],[3.45,20.86]],"id":88302242}]}],"rt":639159130969252123,"dt":639159130969252535}
{"op":"mcm","id":2,"clk":"AINtAP1FAKeNAQ==","pt":1780316297016,"mc":[{"id":"1.258742455","rc":[{"atl":[[32,3.99]],"id":10398159},{"batb":[[0,50,10.23]],"atb":[[50,10.23]],"id":98464183},{"batb":[],"atb":[[3.4,35.54]],"atl":[[10.5,1.99]],"id":88302242},{"batb":[[0,10.5,9.9]],"atb":[[10.5,9.9]],"atl":[[50,4.13]],"id":97736949}]}],"rt":639159130970246055,"dt":639159130970246511}
{"op":"mcm","id":2,"clk":"AJFtAIRGALGNAQ==","pt":1780316297216,"mc":[{"id":"1.258742455","rc":[{"batb":[[0,10.5,11.84]],"atb":[[10.5,11.84]],"id":97736949}]}],"rt":639159130972278101,"dt":639159130972278431}
{"op":"mcm","id":2,"clk":"AJVtAI1GALuNAQ==","pt":1780316297319,"mc":[{"id":"1.258742455","rc":[{"tv":2402.19,"trd":[[11,86.88]],"atl":[[11,8.02]],"batl":[[0,11,8.02]],"id":97736949}],"tv":36038.47}],"rt":639159130973267639,"dt":639159130973268014}
{"op":"mcm","id":2,"clk":"AKNtAI9GAL6NAQ==","pt":1780316297423,"mc":[{"id":"1.258742455","rc":[{"atl":[[4.7,55.89]],"batl":[[0,4.7,55.89]],"id":10398159}]}],"rt":639159130974308420,"dt":639159130974308763}
{"op":"mcm","id":2,"clk":"AKhtAJRGAMaNAQ==","pt":1780316297520,"mc":[{"id":"1.258742455","rc":[{"batb":[[1,10,23.88]],"atb":[[10,23.88]],"id":97736949}]}],"rt":639159130975287380,"dt":639159130975287781}
{"op":"mcm","id":2,"clk":"AK5tAJhGAMyNAQ==","pt":1780316297627,"mc":[{"id":"1.258742455","rc":[{"batb":[[0,3.6,59.48]],"atb":[[3.6,59.48]],"id":88302242},{"atl":[[11,9.07]],"batl":[[0,11,9.07]],"id":97736949}]}],"rt":639159130976353887,"dt":639159130976354349}
{"op":"mcm","id":2,"clk":"AMZtAKNGAOGNAQ==","pt":1780316297934,"mc":[{"id":"1.258742455","rc":[{"atl":[[5.9,28.29],[5.8,6.29]],"batl":[],"id":99072898},{"atl":[[29,10.21],[27,19.18]],"batl":[],"id":99072900}]}],"rt":639159130979422978,"dt":639159130979423418}
{"op":"mcm","id":2,"clk":"AIBuANNGAJmOAQ==","pt":1780316298907,"mc":[{"id":"1.258742455","rc":[{"atl":[[5.1,11.58]],"batl":[[0,5.1,11.58]],"id":99072898},{"atl":[[1000,1.95]],"id":10398159},{"atl":[[1000,6.62]],"id":98117699},{"atb":[[1.17,196.34]],"id":88302242},{"batb":[[0,180,3.52]],"atb":[[180,3.52]],"id":99072897}]}],"rt":639159130989154921,"dt":639159130989155318}
{"op":"mcm","id":2,"clk":"AIVuANlGAKOOAQ==","pt":1780316299011,"mc":[{"id":"1.258742455","rc":[{"batb":[[0,4.6,59.65]],"atb":[[4.6,59.65]],"id":10398159},{"atl":[[1000,6.25]],"id":98117699},{"atb":[[1.17,196.12]],"id":88302242}]}],"rt":639159130990192945,"dt":639159130990193362}
{"op":"mcm","id":2,"clk":"AI9uAN5GALCOAQ==","pt":1780316299115,"mc":[{"id":"1.258742455","rc":[{"atl":[[1000,1.01]],"id":10398159},{"atl":[[9.6,10.15]],"batl":[[1,9.6,10.15]],"id":98117699},{"batb":[[1,3.55,44.13]],"atb":[[3.55,44.13]],"id":88302242}]}],"rt":639159130991227602,"dt":639159130991228032}
{"op":"mcm","id":2,"clk":"AJVuAOJGALSOAQ==","pt":1780316299215,"mc":[{"id":"1.258742455","rc":[{"atl":[[4.8,66.91]],"batl":[[1,4.8,66.91]],"id":10398159}]}],"rt":639159130992238422,"dt":639159130992238848}
{"op":"mcm","id":2,"clk":"AKpuAOpGAMiOAQ==","pt":1780316299520,"mc":[{"id":"1.258742455","rc":[{"atl":[[10,5.86]],"batl":[],"id":98117699}]}],"rt":639159130995288913,"dt":639159130995289305}
{"op":"mcm","id":2,"clk":"AKxuAOpGAM\u002BOAQ==","pt":1780316299624,"mc":[{"id":"1.258742455","rc":[{"batb":[],"atb":[[3.4,41.76]],"id":88302242}]}],"rt":639159130996322405,"dt":639159130996322862}
{"op":"mcm","id":2,"clk":"ALpuAPdGAOaOAQ==","pt":1780316299928,"mc":[{"id":"1.258742455","rc":[{"atl":[[3.75,43.6]],"batl":[[2,3.75,43.6]],"id":88302242}]}],"rt":639159130999358464,"dt":639159130999358791}
{"op":"mcm","id":2,"clk":"APtuAJpHAKuPAQ==","pt":1780316300806,"mc":[{"id":"1.258742455","rc":[{"tv":8045.68,"batb":[[1,4.5,128.89]],"trd":[[4.7,705.58]],"ltp":4.7,"atb":[[4.5,128.89]],"atl":[[4.7,53.77]],"batl":[[0,4.7,53.77]],"id":10398159}],"tv":36042.71}],"rt":639159131008138153,"dt":639159131008138619}
{"op":"mcm","id":2,"clk":"AIFvAJ9HALSPAQ==","pt":1780316300908,"mc":[{"id":"1.258742455","rc":[{"tv":8102.77,"batb":[[2,4.5,128.89],[1,4.6,59.65],[0,4.7,5.09]],"trd":[[4.7,762.67]],"atb":[[4.7,5.09],[4.2,29.98]],"atl":[[4.7,0],[5.4,14.1],[5.1,38.79]],"batl":[[2,5,9.57],[1,4.9,8.51],[0,4.8,66.91]],"id":10398159},{"batb":[],"atb":[[8.6,10.94]],"id":98117699},{"batb":[[0,3.6,45.79]],"atb":[[3.4,32.23],[3.35,131.84],[3.6,45.79]],"id":88302242}],"tv":36099.8}],"rt":639159131009156155,"dt":639159131009156576}
{"op":"mcm","id":2,"clk":"AIVvAKJHAL6PAQ==","pt":1780316301013,"mc":[{"id":"1.258742455","rc":[{"atl":[[5.2,16.81]],"batl":[[1,5.2,16.81]],"id":99072898},{"tv":8110.13,"batb":[[1,4.6,67.04],[0,4.7,1.41]],"trd":[[4.7,770.03]],"atb":[[4.7,1.41],[4.6,67.04]],"atl":[[5.4,10.96],[5.5,11.6]],"batl":[],"id":10398159},{"batb":[[1,3.55,27.56]],"atb":[[3.55,27.56]],"id":88302242}],"tv":36107.16}],"rt":639159131010211084,"dt":639159131010211675}
{"op":"mcm","id":2,"clk":"AItvAKVHAMWPAQ==","pt":1780316301117,"mc":[{"id":"1.258742455","rc":[{"atl":[[5.2,14.68]],"batl":[[1,5.2,14.68]],"id":99072898},{"tv":8112.95,"batb":[[2,4.4,150.04],[1,4.5,128.89],[0,4.6,79.2]],"trd":[[4.7,772.85]],"atb":[[4.7,0],[4.6,79.2]],"atl":[[4.7,4.38]],"batl":[[2,4.9,8.51],[1,4.8,66.91],[0,4.7,4.38]],"id":10398159},{"batb":[[0,3.6,41.37]],"atb":[[3.6,41.37]],"atl":[[3.65,23.59]],"batl":[[0,3.65,23.59]],"id":88302242}],"tv":36109.98}],"rt":639159131011252352,"dt":639159131011252845}
{"op":"mcm","id":2,"clk":"AJFvAKZHAMmPAQ==","pt":1780316301216,"mc":[{"id":"1.258742455","rc":[{"tv":12474.99,"batb":[[0,3.6,2.6]],"trd":[[3.6,620.42]],"atb":[[3.6,2.6]],"id":88302242}],"tv":36187.52}],"rt":639159131012241691,"dt":639159131012242081}
{"op":"mcm","id":2,"clk":"AJlvAKxHANGPAQ==","pt":1780316301319,"mc":[{"id":"1.258742455","rc":[{"tv":8121.71,"batb":[[2,4.5,128.89],[1,4.6,79.2],[0,4.7,28.08]],"trd":[[4.7,781.61]],"atb":[[4.7,28.08]],"atl":[[4.7,0]],"batl":[[2,5,9.57],[1,4.9,8.51],[0,4.8,66.91]],"id":10398159},{"tv":12480.19,"batb":[[2,3.45,20.86],[1,3.5,61.5],[0,3.55,27.56]],"trd":[[3.6,625.62]],"atb":[[3.3,15.98],[1.1,50.86],[3.35,122.26],[3.6,0]],"atl":[[3.85,79.42],[3.6,26.86]],"batl":[[2,3.7,209.44],[1,3.65,23.59],[0,3.6,26.86]],"id":88302242},{"batb":[[0,10.5,15.08]],"atb":[[10.5,15.08]],"id":97736949}],"tv":36201.48}],"rt":639159131013269736,"dt":639159131013270695}
{"op":"mcm","id":2,"clk":"AJ9vALFHANiPAQ==","pt":1780316301420,"mc":[{"id":"1.258742455","rc":[{"atb":[[1.06,5846.74]],"id":97008932},{"batb":[[0,80,3.24]],"atb":[[85,0.32]],"id":99072901},{"atl":[[5.5,8.5],[5.6,11.93]],"batl":[],"id":10398159},{"atb":[[1.1,50.86]],"id":98117699},{"batb":[[1,3.5,74.4]],"atb":[[3.5,74.4]],"atl":[[3.6,43.29]],"batl":[[0,3.6,43.29]],"id":88302242},{"atl":[[11,5.31]],"batl":[[0,11,5.31]],"id":97736949}]}],"rt":639159131014294172,"dt":639159131014294656}
{"op":"mcm","id":2,"clk":"AKZvALVHAOCPAQ==","pt":1780316301524,"mc":[{"id":"1.258742455","rc":[{"atl":[[5.1,3]],"batl":[[0,5.1,3]],"id":99072898},{"batb":[[0,3.55,18.63]],"atb":[[1.1,50.19],[3.55,18.63],[3.4,26.01]],"id":88302242}]}],"rt":639159131015321683,"dt":639159131015322044}
{"op":"mcm","id":2,"clk":"ALFvALhHAOmPAQ==","pt":1780316301633,"mc":[{"id":"1.258742455","rc":[{"tv":7635.24,"batb":[[0,5,14.69]],"trd":[[5,66.79]],"atb":[[5,14.69]],"atl":[[5.1,4.05]],"batl":[[0,5.1,4.05]],"id":99072898},{"atb":[[1.06,5846.18]],"id":97008932},{"tv":8125.71,"batb":[[1,4.6,74.57],[0,4.7,30.71]],"trd":[[4.7,785.61]],"atb":[[4.7,30.71],[4.6,74.57]],"atl":[[4.9,9.55],[4.8,65.97]],"batl":[[1,4.9,9.55],[0,4.8,65.97]],"id":10398159},{"atb":[[1.1,50.17]],"id":98117699},{"batb":[[0,3.55,18.41]],"atb":[[1.17,196.44],[3.55,18.41]],"atl":[[3.65,22.49],[3.7,212.44],[3.85,73.42],[3.6,50.12]],"batl":[[2,3.7,212.44],[1,3.65,22.49],[0,3.6,50.12]],"id":88302242},{"batb":[[0,10.5,15.82]],"atb":[[10.5,15.82]],"id":97736949}],"tv":36209.48}],"rt":639159131016414810,"dt":639159131016415617}
{"op":"mcm","id":2,"clk":"ALRvALpHAO\u002BPAQ==","pt":1780316301730,"mc":[{"id":"1.258742455","rc":[{"atl":[[5.1,12.67]],"batl":[[0,5.1,12.67]],"id":99072898},{"batb":[],"atb":[[4.2,23.98]],"atl":[[5.2,26.03],[5.1,32.79]],"batl":[],"id":10398159},{"atb":[[1.1,50]],"id":98117699},{"batb":[],"atb":[[1.17,196.12],[1.1,50],[3.4,20.01]],"id":88302242}]}],"rt":639159131017376848,"dt":639159131017377485}
{"op":"mcm","id":2,"clk":"ALtvAMNHAPmPAQ==","pt":1780316301836,"mc":[{"id":"1.258742455","rc":[{"atb":[[1.06,5845.87]],"id":97008932},{"batb":[[0,9.2,1.52]],"atb":[[9.2,1.52]],"id":98117699},{"tv":12480.57,"batb":[[1,3.5,74.72]],"trd":[[3.6,626]],"atb":[[3.5,74.72]],"atl":[[3.8,23.53],[3.6,49.93]],"batl":[[0,3.6,49.93]],"id":88302242},{"tv":2402.49,"trd":[[11,87.18]],"atl":[[11,5.16]],"batl":[[0,11,5.16]],"id":97736949}],"tv":36210.16}],"rt":639159131018446333,"dt":639159131018446970}
{"op":"mcm","id":2,"clk":"AMRvAMZHAISQAQ==","pt":1780316301938,"mc":[{"id":"1.258742455","rc":[{"batb":[[0,46,4.29]],"atb":[[46,4.29]],"id":97008932},{"batb":[],"atb":[[4.3,119.97]],"atl":[[5.2,32.03]],"batl":[],"id":10398159},{"batb":[],"atb":[[3.35,128.26]],"atl":[[3.65,37.49]],"batl":[[1,3.65,37.49]],"id":88302242}]}],"rt":639159131019461008,"dt":639159131019461568}
{"op":"mcm","id":2,"clk":"ANFvANVHAJiQAQ==","pt":1780316302096,"mc":[{"id":"1.258742455","rc":[{"atl":[[5.8,8.29]],"batl":[],"id":99072898},{"atl":[[4.8,70.58]],"batl":[[0,4.8,70.58]],"id":10398159}]}],"rt":639159131021040918,"dt":639159131021041575}
{"op":"mcm","id":2,"clk":"ANhvANhHAKSQAQ==","pt":1780316302198,"mc":[{"id":"1.258742455","rc":[{"batb":[[0,50,10.33]],"atb":[[50,10.33]],"id":98464183},{"atl":[[3.75,41.39],[3.8,21.27]],"batl":[],"id":88302242},{"batb":[],"atb":[[9.6,11.2]],"id":97736949}]}],"rt":639159131022060355,"dt":639159131022060813}
{"op":"mcm","id":2,"clk":"APBvAPRHANOQAQ==","pt":1780316302708,"mc":[{"id":"1.258742455","rc":[{"tv":1066.59,"batb":[[2,21,8.6],[1,22,4.96],[0,23,1.65]],"trd":[[23,62.14]],"ltp":23,"atb":[[23,1.65]],"atl":[[23,0]],"batl":[[2,26,4.5],[1,25,3.91],[0,24,3.65]],"id":99072900}],"tv":36216.86}],"rt":639159131027165781,"dt":639159131027166201}
{"op":"mcm","id":2,"clk":"APdvAPxHAOCQAQ==","pt":1780316302819,"mc":[{"id":"1.258742455","rc":[{"atl":[[5.2,16.81]],"batl":[[1,5.2,16.81]],"id":99072898},{"tv":1069.89,"batb":[[0,23,1.58]],"trd":[[23,65.44]],"atb":[[23,1.58]],"id":99072900},{"tv":8130.79,"batb":[[0,4.7,28.17]],"trd":[[4.7,790.69]],"atb":[[4.7,28.17]],"id":10398159},{"tv":2403.29,"batb":[[0,10.5,18.59]],"trd":[[11,87.98]],"atb":[[10.5,18.59]],"atl":[[11,4.76]],"batl":[[0,11,4.76]],"id":97736949},{"batb":[[0,180,1.9]],"atb":[[180,1.9]],"id":99072897}],"tv":36226.04}],"rt":639159131028267711,"dt":639159131028268417}
{"op":"mcm","id":2,"clk":"AP5vAIBIAOeQAQ==","pt":1780316302917,"mc":[{"id":"1.258742455","rc":[{"batb":[[2,4.8,42.5]],"atb":[[4.8,42.5]],"atl":[[5.2,14.68]],"batl":[[1,5.2,14.68]],"id":99072898},{"batb":[[1,22,5.86]],"atb":[[22,5.86]],"id":99072900},{"batb":[[0,4.7,4.63]],"atb":[[4.7,4.63]],"id":10398159},{"tv":2403.59,"trd":[[11,88.28]],"atl":[[11,4.61]],"batl":[[0,11,4.61]],"id":97736949}],"tv":36226.34}],"rt":639159131029248941,"dt":639159131029249435}
{"op":"mcm","id":2,"clk":"AINwAIVIAO2QAQ==","pt":1780316303016,"mc":[{"id":"1.258742455","rc":[{"batb":[[2,4.5,132.48]],"atb":[[4.5,132.48]],"atl":[[5.5,11.59]],"batl":[],"id":10398159},{"atl":[[3.6,52.93]],"batl":[[0,3.6,52.93]],"id":88302242}]}],"rt":639159131030242464,"dt":639159131030242876}
{"op":"mcm","id":2,"clk":"AI5wAIhIAPSQAQ==","pt":1780316303127,"mc":[{"id":"1.258742455","rc":[{"batb":[[2,20,6.62],[1,21,8.6],[0,22,5.86]],"atb":[[23,0]],"atl":[[28,7.61],[27,14]],"batl":[],"id":99072900},{"atl":[[4.9,51.2],[4.8,24.05]],"batl":[[1,4.9,51.2],[0,4.8,24.05]],"id":10398159},{"batb":[[1,9,27.89]],"atb":[[9,27.89]],"id":98117699},{"atl":[[3.75,110.87],[3.85,3.4]],"batl":[],"id":88302242},{"atb":[[1.17,2.35]],"id":97736949}]}],"rt":639159131031356117,"dt":639159131031356546}
{"op":"mcm","id":2,"clk":"AJNwAJJIAIGRAQ==","pt":1780316303230,"mc":[{"id":"1.258742455","rc":[{"batb":[[0,50,10.44]],"atb":[[50,10.44]],"id":98464183},{"atb":[[1.17,2]],"id":97736949}]}],"rt":639159131032383007,"dt":639159131032383472}
{"op":"mcm","id":2,"clk":"AJtwAJVIAIeRAQ==","pt":1780316303340,"mc":[{"id":"1.258742455","rc":[{"atl":[[23,1.21]],"batl":[[2,25,3.91],[1,24,3.65],[0,23,1.21]],"id":99072900},{"atl":[[4.8,28.96]],"batl":[[0,4.8,28.96]],"id":10398159},{"batb":[[0,10.5,18.94]],"atb":[[10.5,18.94]],"id":97736949}]}],"rt":639159131033483912,"dt":639159131033484572}
{"op":"mcm","id":2,"clk":"ALBwAJ9IAJ2RAQ==","pt":1780316303734,"mc":[{"id":"1.258742455","rc":[{"batb":[],"atb":[[8.4,16.65]],"id":97736949}]}],"rt":639159131037419839,"dt":639159131037420218}
{"op":"mcm","id":2,"clk":"ALtwAKRIAKaRAQ==","pt":1780316303942,"mc":[{"id":"1.258742455","rc":[{"atl":[[6.2,9.11]],"id":99072898},{"tv":8133.13,"batb":[[0,4.7,3.46]],"trd":[[4.7,793.03]],"atb":[[4.7,3.46]],"id":10398159},{"tv":2404.38,"batb":[[0,10.5,20.87]],"trd":[[11,89.07]],"atb":[[10.5,20.87]],"atl":[[11,4.22]],"batl":[[0,11,4.22]],"id":97736949}],"tv":36229.47}],"rt":639159131039501739,"dt":639159131039502462}
{"op":"mcm","id":2,"clk":"AORwAMNIAOeRAQ==","pt":1780316304816,"mc":[{"id":"1.258742455","rc":[{"batb":[[2,46,3.26]],"atb":[[46,3.26]],"id":98464183}]}],"rt":639159131048244798,"dt":639159131048245265}
{"op":"mcm","id":2,"clk":"AOtwAMZIAO\u002BRAQ==","pt":1780316304920,"mc":[{"id":"1.258742455","rc":[{"tv":7675.24,"batb":[[2,4.7,29.1],[1,4.8,42.5],[0,4.9,35.1]],"trd":[[4.9,84.08],[5,96.17]],"ltp":4.9,"atb":[[4.9,35.1],[5,0]],"atl":[[5.5,34.48]],"batl":[],"id":99072898},{"tv":1071.83,"batb":[[0,22,4.89]],"trd":[[22,77.16]],"ltp":22,"atb":[[22,4.89]],"id":99072900}],"tv":36271.41}],"rt":639159131049286924,"dt":639159131049287420}
{"op":"mcm","id":2,"clk":"APBwAMhIAPeRAQ==","pt":1780316305020,"mc":[{"id":"1.258742455","rc":[{"atl":[[5.2,16.8]],"batl":[[1,5.2,16.8]],"id":99072898},{"atl":[[23,2.72]],"batl":[[0,23,2.72]],"id":99072900},{"batb":[[0,4.7,15.13]],"atb":[[4.7,15.13]],"atl":[[5.5,8.5]],"batl":[],"id":10398159},{"tv":12497.39,"trd":[[3.6,642.82]],"atl":[[3.6,44.52]],"batl":[[0,3.6,44.52]],"id":88302242},{"batb":[[0,180,3.57]],"atb":[[180,3.57]],"id":99072897}],"tv":36288.23}],"rt":639159131050286264,"dt":639159131050286785}
{"op":"mcm","id":2,"clk":"APlwAM9IAIKSAQ==","pt":1780316305133,"mc":[{"id":"1.258742455","rc":[{"atl":[[5,2.83],[5.1,17.3]],"batl":[[2,5.2,16.8],[1,5.1,17.3],[0,5,2.83]],"id":99072898},{"batb":[],"atb":[[4.2,16.63]],"id":10398159},{"batb":[[0,3.55,31.18]],"atb":[[3.55,31.18]],"id":88302242}]}],"rt":639159131051413958,"dt":639159131051414345}
{"op":"mcm","id":2,"clk":"APtwANFIAI6SAQ==","pt":1780316305224,"mc":[{"id":"1.258742455","rc":[{"atl":[[50,11.11]],"batl":[[0,50,11.11]],"id":97008932},{"atb":[[1.17,2.4]],"atl":[[23,3.57]],"batl":[[0,23,3.57]],"id":99072900},{"atl":[[95,3.54]],"batl":[[0,95,3.54]],"id":99072901},{"batb":[[0,4.7,12.09]],"atb":[[4.7,12.09]],"id":10398159},{"batb":[[0,50,10.27]],"atb":[[50,10.27]],"atl":[[55,5.31]],"batl":[[0,55,5.31]],"id":98464183},{"tv":12504.09,"batb":[[0,3.55,39.95]],"trd":[[3.6,649.52]],"atb":[[3.55,39.95]],"atl":[[3.6,40.07]],"batl":[[0,3.6,40.07]],"id":88302242},{"atl":[[190,0.55]],"batl":[[0,210,1.41]],"id":99072897}],"tv":36294.93}],"rt":639159131052325660,"dt":639159131052326282}
{"op":"mcm","id":2,"clk":"AIBxANVIAJiSAQ==","pt":1780316305325,"mc":[{"id":"1.258742455","rc":[{"batb":[[0,4.9,38.76]],"atb":[[4.9,38.76]],"atl":[[5,10.84],[5.1,34.6]],"batl":[[1,5.1,34.6],[0,5,10.84]],"id":99072898},{"atb":[[1.17,2]],"id":99072900},{"batb":[[0,4.7,37.36]],"atb":[[4.7,37.36]],"id":10398159},{"atl":[[3.6,34.34]],"batl":[[0,3.6,34.34]],"id":88302242},{"batb":[[0,10.5,26.54]],"atb":[[10.5,26.54],[9.2,17.83]],"id":97736949}]}],"rt":639159131053337504,"dt":639159131053337938}
{"op":"mcm","id":2,"clk":"AIdxANtIAKGSAQ==","pt":1780316305431,"mc":[{"id":"1.258742455","rc":[{"batb":[],"atb":[[4.6,30.34]],"id":99072898},{"tv":1072.63,"trd":[[23,66.24]],"ltp":23,"atl":[[23,3.17]],"batl":[[0,23,3.17]],"id":99072900}],"tv":36295.73}],"rt":639159131054388279,"dt":639159131054388857}
{"op":"mcm","id":2,"clk":"AJNxAORIALWSAQ==","pt":1780316305638,"mc":[{"id":"1.258742455","rc":[{"batb":[],"atb":[[4.5,33.56]],"atl":[[5.5,28.48]],"batl":[],"id":99072898}]}],"rt":639159131056458936,"dt":639159131056459288}
{"op":"mcm","id":2,"clk":"AJNxAOVIALuSAQ==","pt":1780316305735,"mc":[{"id":"1.258742455","rc":[{"atl":[[3.7,209.44]],"batl":[[2,3.7,209.44]],"id":88302242}]}],"rt":639159131057437496,"dt":639159131057437842}
{"op":"mcm","id":2,"clk":"AJdxAOlIAMSSAQ==","pt":1780316305839,"mc":[{"id":"1.258742455","rc":[{"atl":[[5.4,35.65]],"batl":[],"id":99072898},{"batb":[[1,4.6,75.57]],"atb":[[4.6,75.57]],"id":10398159}]}],"rt":639159131058469325,"dt":639159131058469765}
{"op":"mcm","id":2,"clk":"AJ5xAPFIAM2SAQ==","pt":1780316305940,"mc":[{"id":"1.258742455","rc":[{"atl":[[10,19.51]],"batl":[],"id":98117699}]}],"rt":639159131059487733,"dt":639159131059488079}
{"op":"mcm","id":2,"clk":"ALRxAIBJAOiSAQ==","pt":1780316306199,"mc":[{"id":"1.258742455","rc":[{"batb":[],"atb":[[18.5,13.63]],"id":99072900},{"atl":[[12,3.51]],"batl":[],"id":98117699}]}],"rt":639159131062069649,"dt":639159131062070083}
{"op":"mcm","id":2,"clk":"ALpxAIZJAPeSAQ==","pt":1780316306307,"mc":[{"id":"1.258742455","rc":[{"atb":[[1.17,2.1]],"atl":[[50,11.01]],"batl":[[0,50,11.01]],"id":97008932},{"tv":1074.17,"batb":[[0,22,5.66]],"trd":[[23,67.78]],"atb":[[22,5.66]],"atl":[[23,2.4]],"batl":[[0,23,2.4]],"id":99072900},{"atb":[[1.17,196.84]],"id":88302242},{"batb":[[0,10.5,24.47]],"atb":[[10.5,24.47]],"id":97736949},{"batb":[[0,180,3.47]],"atb":[[180,3.47]],"atl":[[190,0.65]],"batl":[[0,210,1.51]],"id":99072897}],"tv":36297.27}],"rt":639159131063149967,"dt":639159131063150555}
{"op":"mcm","id":2,"clk":"AMFxAIlJAP\u002BSAQ==","pt":1780316306414,"mc":[{"id":"1.258742455","rc":[{"atb":[[1.17,2]],"id":97008932},{"atl":[[23,0.89]],"batl":[[2,26,4.5],[1,25,3.91],[0,24,4.54]],"id":99072900},{"atb":[[1.17,196.12]],"id":88302242}]}],"rt":639159131064218010,"dt":639159131064218404}
{"op":"mcm","id":2,"clk":"AMlxAIxJAIaTAQ==","pt":1780316306512,"mc":[{"id":"1.258742455","rc":[{"tv":7678.7,"batb":[[0,4.9,37.03]],"trd":[[4.9,87.54]],"atb":[[4.9,37.03]],"id":99072898},{"batb":[[0,46,4.39]],"atb":[[46,4.39]],"id":97008932},{"batb":[[0,22,9.33]],"atb":[[22,9.33]],"atl":[[23,0.04]],"batl":[[0,24,3.69]],"id":99072900},{"tv":12504.81,"batb":[[0,3.55,40.31]],"trd":[[3.6,650.24]],"atb":[[3.55,40.31]],"atl":[[3.6,33.98]],"batl":[[0,3.6,33.98]],"id":88302242}],"tv":36301.45}],"rt":639159131065203552,"dt":639159131065204060}
{"op":"mcm","id":2,"clk":"AORxAJlJAKSTAQ==","pt":1780316307022,"mc":[{"id":"1.258742455","rc":[{"batb":[],"atb":[[4.2,126]],"id":99072898},{"batb":[],"atb":[[8.2,9.53]],"id":98117699},{"batb":[],"atb":[[3.2,2.8]],"id":88302242},{"atb":[[8,7]],"id":97736949}]}],"rt":639159131070301798,"dt":639159131070302232}
{"op":"mcm","id":2,"clk":"AOtxAJ9JAKyTAQ==","pt":1780316307130,"mc":[{"id":"1.258742455","rc":[{"batb":[[2,42,11.1]],"atb":[[42,11.1]],"id":97008932},{"batb":[],"atb":[[19.5,3.42]],"id":99072900},{"batb":[],"atb":[[3.9,13.05]],"id":10398159},{"atl":[[11.5,21.26]],"batl":[[1,11.5,21.26]],"id":97736949}]}],"rt":639159131071384375,"dt":639159131071384805}
{"op":"mcm","id":2,"clk":"APhxAKVJALaTAQ==","pt":1780316307236,"mc":[{"id":"1.258742455","rc":[{"batb":[],"atb":[[4.5,40.04]],"id":99072898},{"atl":[[3.85,29.02]],"batl":[],"id":88302242}]}],"rt":639159131072443936,"dt":639159131072444323}
{"op":"mcm","id":2,"clk":"APxxAKdJAL\u002BTAQ==","pt":1780316307334,"mc":[{"id":"1.258742455","rc":[{"batb":[],"atb":[[4.1,7.4]],"id":99072898},{"batb":[[2,42,11.22]],"atb":[[42,11.22]],"id":97008932},{"batb":[],"atb":[[19.5,3.68]],"id":99072900},{"batb":[],"atb":[[3.95,49.75]],"id":10398159},{"batb":[],"atb":[[7.8,2.63]],"id":98117699},{"atb":[[3.05,298.71]],"id":88302242},{"batb":[],"atb":[[9.2,18.37]],"id":97736949}]}],"rt":639159131073420019,"dt":639159131073420483}
{"op":"mcm","id":2,"clk":"AIByAKtJAMeTAQ==","pt":1780316307435,"mc":[{"id":"1.258742455","rc":[{"atl":[[5.3,27.45]],"batl":[],"id":10398159}]}],"rt":639159131074433561,"dt":639159131074433935}
{"op":"mcm","id":2,"clk":"AIlyALlJANeTAQ==","pt":1780316307640,"mc":[{"id":"1.258742455","rc":[{"tv":2297.87,"batb":[[2,8.6,10.94],[1,8.8,13.56],[0,9,27.89]],"trd":[[9.2,184.97]],"ltp":9.2,"atb":[[9.2,0]],"atl":[[9.2,2.48]],"batl":[[2,9.6,10.15],[1,9.4,12.99],[0,9.2,2.48]],"id":98117699}],"tv":36304.49}],"rt":639159131076482746,"dt":639159131076483198}
{"op":"mcm","id":2,"clk":"AI1yALpJAN2TAQ==","pt":1780316307740,"mc":[{"id":"1.258742455","rc":[{"batb":[[0,4.7,44.67]],"atb":[[4.7,44.67]],"id":10398159}]}],"rt":639159131077482699,"dt":639159131077483055}
{"op":"mcm","id":2,"clk":"AJNyAL9JAOSTAQ==","pt":1780316307800,"mc":[{"id":"1.258742455","rc":[{"tv":2299.99,"trd":[[9.2,187.09]],"atl":[[9.2,1.42]],"batl":[[0,9.2,1.42]],"id":98117699}],"tv":36306.61}],"rt":639159131078084813,"dt":639159131078085166}
{"op":"mcm","id":2,"clk":"AJlyAMVJAOyTAQ==","pt":1780316307902,"mc":[{"id":"1.258742455","rc":[{"tv":8136.59,"trd":[[4.8,438.31]],"ltp":4.8,"atl":[[4.8,27.23]],"batl":[[0,4.8,27.23]],"id":10398159},{"batb":[],"atb":[[8.4,9.22]],"atl":[[10.5,8.54]],"batl":[],"id":98117699}],"tv":36310.07}],"rt":639159131079096609,"dt":639159131079097038}
{"op":"mcm","id":2,"clk":"AJ9yAMxJAPGTAQ==","pt":1780316308000,"mc":[{"id":"1.258742455","rc":[{"batb":[[1,4.8,45.21],[0,4.9,35.81]],"atb":[[4.9,35.81],[4.8,45.21]],"atl":[[5,14.63],[5.1,30.55]],"batl":[[1,5.1,30.55],[0,5,14.63]],"id":99072898},{"batb":[[0,80,3.03]],"atb":[[1.17,1.11],[80,2.71]],"id":99072901},{"batb":[[0,4.7,51.27]],"atb":[[4.7,51.27]],"id":10398159},{"atl":[[9.4,12.72],[1000,7.09],[9.6,9.78]],"batl":[[2,9.6,9.78],[1,9.4,12.72]],"id":98117699},{"batb":[[1,3.5,74.4]],"atb":[[3.5,74.4]],"id":88302242}]}],"rt":639159131080082721,"dt":639159131080083242}
{"op":"mcm","id":2,"clk":"AKZyANVJAPmTAQ==","pt":1780316308104,"mc":[{"id":"1.258742455","rc":[{"atb":[[1.17,1]],"id":99072901},{"tv":8191.05,"trd":[[4.8,492.77]],"atl":[[4.9,53.33],[4.8,0]],"batl":[[2,5.1,32.79],[1,5,9.57],[0,4.9,53.33]],"id":10398159},{"batb":[],"atb":[[8.2,15.53]],"atl":[[1000,6.25],[10,25.51],[9.6,7.78]],"batl":[[2,9.6,7.78]],"id":98117699}],"tv":36364.53}],"rt":639159131081120834,"dt":639159131081121680}
{"op":"mcm","id":2,"clk":"AK1yANlJAIiUAQ==","pt":1780316308210,"mc":[{"id":"1.258742455","rc":[{"tv":7680.7,"batb":[[0,4.9,27.8]],"trd":[[4.9,89.54]],"atb":[[4.9,27.8]],"id":99072898},{"batb":[[0,80,3.14]],"atb":[[85,0.43]],"id":99072901},{"atl":[[4.9,77.24]],"batl":[[0,4.9,77.24]],"id":10398159},{"tv":2303.99,"batb":[[0,9,25.89]],"trd":[[9,20]],"ltp":9,"atb":[[9,25.89]],"atl":[[9.4,13.19],[9.2,1.79]],"batl":[[1,9.4,13.19],[0,9.2,1.79]],"id":98117699},{"atl":[[3.6,39.75]],"batl":[[0,3.6,39.75]],"id":88302242}],"tv":36370.53}],"rt":639159131082184796,"dt":639159131082185411}
{"op":"mcm","id":2,"clk":"ALdyANtJAI6UAQ==","pt":1780316308312,"mc":[{"id":"1.258742455","rc":[{"atl":[[80,15.01]],"batl":[],"id":98464183}]}],"rt":639159131083197711,"dt":639159131083198041}
{"op":"mcm","id":2,"clk":"AL5yAOBJAJeUAQ==","pt":1780316308415,"mc":[{"id":"1.258742455","rc":[{"batb":[[0,4.7,56.38]],"atb":[[4.7,56.38]],"id":10398159}]}],"rt":639159131084232609,"dt":639159131084232930}
{"op":"mcm","id":2,"clk":"AMRyAOFJAJ6UAQ==","pt":1780316308516,"mc":[{"id":"1.258742455","rc":[{"batb":[[0,4.9,17.65]],"atb":[[4.9,17.65]],"id":99072898},{"atl":[[23,0]],"batl":[[0,24,3.65]],"id":99072900},{"atl":[[5.2,26.03]],"batl":[],"id":10398159},{"batb":[[0,3.55,34.53]],"atb":[[3.55,34.53]],"id":88302242}]}],"rt":639159131085247195,"dt":639159131085247584}
{"op":"mcm","id":2,"clk":"AMxyAOdJAKeUAQ==","pt":1780316308619,"mc":[{"id":"1.258742455","rc":[{"batb":[[0,4.9,10.38]],"atb":[[4.9,10.38]],"atl":[[5.2,14.68]],"batl":[[2,5.2,14.68]],"id":99072898},{"atl":[[75,17.88]],"batl":[],"id":97008932}]}],"rt":639159131086268165,"dt":639159131086268550}
{"op":"mcm","id":2,"clk":"ANJyAOtJALOUAQ==","pt":1780316308726,"mc":[{"id":"1.258742455","rc":[{"tv":7689.68,"batb":[[2,4.6,30.34],[1,4.7,29.1],[0,4.8,45.21]],"trd":[[4.9,98.52]],"atb":[[4.9,0]],"atl":[[5.3,8.92],[5,19.4]],"batl":[[0,5,19.4]],"id":99072898},{"atb":[[1.05,3119.2]],"id":99072900},{"atl":[[5.3,33.45]],"batl":[],"id":10398159},{"atl":[[3.65,35.49]],"batl":[[1,3.65,35.49]],"id":88302242}],"tv":36379.51}],"rt":639159131087341942,"dt":639159131087342433}
{"op":"mcm","id":2,"clk":"ANlyAPJJAMCUAQ==","pt":1780316308926,"mc":[{"id":"1.258742455","rc":[{"batb":[],"atb":[[4.5,33.56]],"id":99072898},{"atl":[[32,1.85]],"id":10398159}]}],"rt":639159131089345148,"dt":639159131089345509}
{"op":"mcm","id":2,"clk":"AOpyAPxJAN6UAQ==","pt":1780316309233,"mc":[{"id":"1.258742455","rc":[{"batb":[],"atb":[[4.5,27.56]],"id":99072898}]}],"rt":639159131092411688,"dt":639159131092412073}
{"op":"mcm","id":2,"clk":"APZyAINKAO\u002BUAQ==","pt":1780316309435,"mc":[{"id":"1.258742455","rc":[{"batb":[],"atb":[[4.4,20.84]],"id":99072898}]}],"rt":639159131094430479,"dt":639159131094430866}
{"op":"mcm","id":2,"clk":"AIBzAIhKAPaUAQ==","pt":1780316309539,"mc":[{"id":"1.258742455","rc":[{"atl":[[19.5,1.86]],"id":99072898},{"atl":[[18,0]],"id":10398159},{"atl":[[100,0]],"id":98117699},{"atl":[[11,24.13]],"id":88302242},{"atl":[[120,0]],"id":97736949}]}],"rt":639159131095469368,"dt":639159131095469777}
{"op":"mcm","id":2,"clk":"AIdzAIhKAPyUAQ==","pt":1780316309642,"mc":[{"id":"1.258742455","rc":[{"atb":[[1.17,2.57]],"id":97736949}]}],"rt":639159131096496967,"dt":639159131096497287}
{"op":"mcm","id":2,"clk":"AI9zAIxKAIGVAQ==","pt":1780316309746,"mc":[{"id":"1.258742455","rc":[{"atl":[[4.9,3.08],[20,20]],"batl":[[2,5.1,30.55],[1,5,19.4],[0,4.9,3.08]],"id":99072898},{"atl":[[19,20.55]],"id":10398159},{"atl":[[85,20]],"id":98117699},{"atl":[[11,44.13],[3.6,36.75]],"batl":[[0,3.6,36.75]],"id":88302242},{"atb":[[1.17,2]],"atl":[[120,20]],"id":97736949}]}],"rt":639159131097542555,"dt":639159131097543012}
{"op":"mcm","id":2,"clk":"AJNzAI1KAIyVAQ==","pt":1780316309797,"mc":[{"id":"1.258742455","rc":[{"atl":[[5.5,31.44]],"batl":[],"id":99072898},{"atl":[[5.5,11.51]],"batl":[],"id":10398159},{"tv":12510.81,"batb":[[0,3.55,31.53]],"trd":[[3.55,306.99]],"ltp":3.55,"atb":[[3.55,31.53],[3.25,11.96]],"id":88302242},{"batb":[[0,10.5,25.04]],"atb":[[10.5,25.04]],"id":97736949}],"tv":36385.51}],"rt":639159131098057928,"dt":639159131098058382}
{"op":"mcm","id":2,"clk":"AJZzAJBKAJWVAQ==","pt":1780316309900,"mc":[{"id":"1.258742455","rc":[{"tv":7691.68,"trd":[[4.9,100.52]],"atl":[[5.4,32.52],[4.9,10.03],[5.3,6]],"batl":[[0,4.9,10.03]],"id":99072898},{"batb":[],"atb":[[8.4,5.44]],"id":98117699},{"batb":[[0,3.55,18.76]],"atb":[[3.3,6.33],[3.55,18.76]],"id":88302242}],"tv":36387.51}],"rt":639159131099082379,"dt":639159131099082831}
{"op":"mcm","id":2,"clk":"AJ5zAJRKAJuVAQ==","pt":1780316310001,"mc":[{"id":"1.258742455","rc":[{"atl":[[5.4,26.52]],"batl":[],"id":99072898},{"tv":12550.81,"batb":[[2,3.4,20.01],[1,3.45,20.86],[0,3.5,75.16]],"trd":[[3.55,346.99]],"atb":[[3.55,0.76]],"id":88302242},{"batb":[[1,170,3.4]],"atb":[[170,3.4]],"id":99072897}],"tv":36427.51}],"rt":639159131100095081,"dt":639159131100095540}
{"op":"mcm","id":2,"clk":"AKpzAJVKAKOVAQ==","pt":1780316310110,"mc":[{"id":"1.258742455","rc":[{"tv":7694.58,"trd":[[4.9,103.42]],"atl":[[4.9,8.58],[5.5,28.48],[5.6,8.99]],"batl":[[0,4.9,8.58]],"id":99072898},{"atl":[[5.5,8.5]],"batl":[],"id":10398159},{"batb":[[2,3.45,37.54],[1,3.5,91.08],[0,3.55,12.33]],"atb":[[3.5,91.08],[3.55,12.33],[3.25,2.26],[3.4,34.69],[3.35,142.94],[3.2,12.54],[3.45,37.54]],"id":88302242}],"tv":36430.41}],"rt":639159131101177909,"dt":639159131101178391}
{"op":"mcm","id":2,"clk":"AK9zAJdKAKuVAQ==","pt":1780316310213,"mc":[{"id":"1.258742455","rc":[{"tv":7695.84,"batb":[[2,4.7,29.1],[1,4.8,45.21],[0,4.9,8.07]],"trd":[[4.9,104.68]],"atb":[[4.9,8.07]],"atl":[[4.9,0],[5.3,12]],"batl":[[2,5.2,14.68],[1,5.1,30.55],[0,5,19.4]],"id":99072898}],"tv":36431.67}],"rt":639159131102212671,"dt":639159131102213180}
{"op":"mcm","id":2,"clk":"ALVzAJtKALCVAQ==","pt":1780316310312,"mc":[{"id":"1.258742455","rc":[{"atl":[[5.7,12.55],[5.6,6.03]],"batl":[],"id":99072898},{"batb":[],"atb":[[8,58.19]],"id":98117699},{"batb":[],"atb":[[3.35,136.94]],"id":88302242}]}],"rt":639159131103204206,"dt":639159131103204644}
{"op":"mcm","id":2,"clk":"ALtzAJ5KALiVAQ==","pt":1780316310415,"mc":[{"id":"1.258742455","rc":[{"batb":[[2,3.4,34.69],[1,3.45,37.54],[0,3.5,91.84]],"atb":[[3.55,0.76]],"id":88302242}]}],"rt":639159131104228115,"dt":639159131104228571}
{"op":"mcm","id":2,"clk":"AMFzAJ9KAMGVAQ==","pt":1780316310516,"mc":[{"id":"1.258742455","rc":[{"batb":[],"atb":[[4.4,14.84]],"id":99072898},{"tv":12552.33,"batb":[[0,3.5,91.08]],"trd":[[3.55,348.51]],"atb":[[3.3,12.33],[3.55,0]],"atl":[[3.55,7.58],[3.8,11.46]],"batl":[[2,3.65,35.49],[1,3.6,36.75],[0,3.55,7.58]],"id":88302242}],"tv":36433.19}],"rt":639159131105251745,"dt":639159131105252327}
{"op":"mcm","id":2,"clk":"AMxzAKRKAMaVAQ==","pt":1780316310624,"mc":[{"id":"1.258742455","rc":[{"batb":[[2,4.6,30.34],[1,4.7,29.1],[0,4.8,45.21]],"atb":[[4.9,0]],"id":99072898},{"batb":[[1,170,1.67]],"atb":[[170,1.67]],"id":99072897}]}],"rt":639159131106321783,"dt":639159131106322297}
{"op":"mcm","id":2,"clk":"ANBzAKVKAMuVAQ==","pt":1780316310724,"mc":[{"id":"1.258742455","rc":[{"batb":[[1,170,3.4]],"atb":[[170,3.4]],"id":99072897}]}],"rt":639159131107322183,"dt":639159131107322589}
{"op":"mcm","id":2,"clk":"ANhzAKhKANKVAQ==","pt":1780316310826,"mc":[{"id":"1.258742455","rc":[{"batb":[[2,4.7,29.1],[1,4.8,45.21],[0,4.9,2.8]],"atb":[[4.9,2.8],[4.5,33.56]],"atl":[[5.3,6]],"batl":[],"id":99072898},{"batb":[[0,46,4.69]],"atb":[[46,4.69]],"id":97008932},{"batb":[[0,22,9.95]],"atb":[[22,9.95]],"id":99072900},{"batb":[[0,80,3.31]],"atb":[[80,2.88]],"id":99072901},{"batb":[[0,4.7,59.31]],"atb":[[4.7,59.31]],"id":10398159},{"batb":[[0,50,10.54]],"atb":[[50,10.54]],"id":98464183},{"batb":[[0,9,27.42]],"atb":[[9,27.42]],"id":98117699},{"batb":[[0,3.5,95.01]],"atb":[[3.5,95.01]],"atl":[[3.8,5.46]],"batl":[],"id":88302242},{"batb":[[0,10.5,26.35]],"atb":[[10.5,26.35]],"id":97736949},{"batb":[[0,1000,93.01]],"atb":[[1000,93.01]],"id":10445502},{"batb":[[0,180,3.55]],"atb":[[180,3.55]],"id":99072897}]}],"rt":639159131108345305,"dt":639159131108346330}
{"op":"mcm","id":2,"clk":"AN5zAKtKANqVAQ==","pt":1780316310933,"mc":[{"id":"1.258742455","rc":[{"atl":[[9.2,3.54]],"batl":[[0,9.2,3.54]],"id":98117699}]}],"rt":639159131109411275,"dt":639159131109411626}
{"op":"mcm","id":2,"clk":"AORzAK5KAN\u002BVAQ==","pt":1780316311035,"mc":[{"id":"1.258742455","rc":[{"atl":[[5.4,32.52]],"batl":[],"id":99072898},{"atb":[[1.17,2.43]],"id":99072900},{"batb":[[0,9,28.56]],"atb":[[9,28.56]],"id":98117699},{"atl":[[3.75,116.87]],"batl":[],"id":88302242},{"batb":[[0,10.5,28.12]],"atb":[[10.5,28.12]],"id":97736949}]}],"rt":639159131110431318,"dt":639159131110431724}
{"op":"mcm","id":2,"clk":"AOpzALFKAOaVAQ==","pt":1780316311139,"mc":[{"id":"1.258742455","rc":[{"atb":[[1.17,2]],"id":99072900}]}],"rt":639159131111476331,"dt":639159131111476738}
{"op":"mcm","id":2,"clk":"AO1zALVKAOqVAQ==","pt":1780316311235,"mc":[{"id":"1.258742455","rc":[{"batb":[[0,22,10.38]],"atb":[[22,10.38]],"id":99072900}]}],"rt":639159131112430034,"dt":639159131112430405}
{"op":"mcm","id":2,"clk":"APlzALpKAPuVAQ==","pt":1780316311447,"mc":[{"id":"1.258742455","rc":[{"tv":8198.53,"batb":[[0,4.7,55.57]],"trd":[[4.7,800.51]],"ltp":4.7,"atb":[[4.7,55.57]],"id":10398159}],"tv":36440.67}],"rt":639159131114547832,"dt":639159131114548243}
{"op":"mcm","id":2,"clk":"AIN0AMNKAIeWAQ==","pt":1780316311546,"mc":[{"id":"1.258742455","rc":[{"batb":[[0,4.9,10.64]],"atb":[[4.9,10.64]],"id":99072898}]}],"rt":639159131115544247,"dt":639159131115544603}
{"op":"mcm","id":2,"clk":"AIp0AMVKAJCWAQ==","pt":1780316311653,"mc":[{"id":"1.258742455","rc":[{"batb":[[0,4.7,78.02]],"atb":[[4.7,78.02]],"id":10398159}]}],"rt":639159131116611742,"dt":639159131116612132}
{"op":"mcm","id":2,"clk":"AJl0ANFKAJyWAQ==","pt":1780316311804,"mc":[{"id":"1.258742455","rc":[{"batb":[[0,3.5,78.33]],"atb":[[3.5,78.33]],"id":88302242}]}],"rt":639159131118118917,"dt":639159131118119369}
{"op":"mcm","id":2,"clk":"AKB0ANZKAKSWAQ==","pt":1780316311911,"mc":[{"id":"1.258742455","rc":[{"tv":1084.55,"batb":[[0,22,5.19]],"trd":[[22,87.54]],"ltp":22,"atb":[[22,5.19]],"id":99072900},{"tv":12604.33,"batb":[[0,3.5,52.32]],"trd":[[3.5,52.58]],"ltp":3.5,"atb":[[3.5,52.32]],"id":88302242}],"tv":36503.05}],"rt":639159131119195060,"dt":639159131119195474}
{"op":"mcm","id":2,"clk":"AKh0AN1KAKuWAQ==","pt":1780316312013,"mc":[{"id":"1.258742455","rc":[{"batb":[[0,4.9,14.32]],"atb":[[4.9,14.32]],"id":99072898},{"batb":[[0,22,7.93]],"atb":[[22,7.93]],"id":99072900},{"batb":[[1,3.45,50.34]],"atb":[[3.45,50.34]],"id":88302242}]}],"rt":639159131120206373,"dt":639159131120206812}
{"op":"mcm","id":2,"clk":"ALF0AORKALKWAQ==","pt":1780316312117,"mc":[{"id":"1.258742455","rc":[{"batb":[[0,22,9.4]],"atb":[[22,9.4]],"id":99072900},{"batb":[],"atb":[[4.1,48.33]],"id":10398159},{"batb":[],"atb":[[3.25,8.66]],"id":88302242}]}],"rt":639159131121246407,"dt":639159131121246854}
{"op":"mcm","id":2,"clk":"ALZ0AOVKALuWAQ==","pt":1780316312214,"mc":[{"id":"1.258742455","rc":[{"batb":[[0,22,10.35]],"atb":[[22,10.35]],"id":99072900},{"batb":[[0,3.5,58.27]],"atb":[[3.5,58.27]],"id":88302242}]}],"rt":639159131122220595,"dt":639159131122220987}
{"op":"mcm","id":2,"clk":"ANh0AIhLAPOWAQ==","pt":1780316312835,"mc":[{"id":"1.258742455","rc":[{"atl":[[3.65,20.49]],"batl":[[2,3.65,20.49]],"id":88302242}]}],"rt":639159131128435573,"dt":639159131128435937}
{"op":"mcm","id":2,"clk":"AOJ0AI1LAPyWAQ==","pt":1780316312944,"mc":[{"id":"1.258742455","rc":[{"atl":[[5.2,214.68]],"batl":[[2,5.2,214.68]],"id":99072898}]}],"rt":639159131129520426,"dt":639159131129520759}
{"op":"mcm","id":2,"clk":"AOd0AJFLAIOXAQ==","pt":1780316313037,"mc":[{"id":"1.258742455","rc":[{"tv":7712.86,"batb":[[0,4.9,10.67]],"trd":[[4.9,121.7]],"atb":[[4.9,10.67]],"atl":[[5.1,30.97]],"batl":[[1,5.1,30.97]],"id":99072898},{"atl":[[75,17.91]],"batl":[],"id":97008932},{"atl":[[40,3.09]],"id":99072900},{"atl":[[95,3.56]],"batl":[[0,95,3.56]],"id":99072901},{"atl":[[4.8,0.44]],"batl":[[0,4.9,77.68]],"id":10398159},{"atl":[[55,5.35]],"batl":[[0,55,5.35]],"id":98464183},{"atl":[[10.5,8.74]],"batl":[],"id":98117699},{"atl":[[3.75,117.44]],"batl":[],"id":88302242},{"tv":2404.8,"batb":[[0,10.5,27.91]],"trd":[[10.5,124.33]],"ltp":10.5,"atb":[[10.5,27.91]],"id":97736949},{"tv":189.12,"batb":[[0,1000,93]],"trd":[[1000,144.64]],"atb":[[1000,93]],"id":10445502},{"atl":[[210,0.75]],"batl":[[0,210,1.52]],"id":99072897}],"tv":36520.51}],"rt":639159131130455549,"dt":639159131130456125}
{"op":"mcm","id":2,"clk":"AOx0AJhLAI6XAQ==","pt":1780316313137,"mc":[{"id":"1.258742455","rc":[{"tv":7734.19,"batb":[[2,4.6,30.34],[1,4.7,29.1],[0,4.8,45.21]],"trd":[[4.9,143.03]],"atb":[[4.9,0]],"atl":[[5,14.63]],"batl":[[0,5,14.63]],"id":99072898}],"tv":36541.84}],"rt":639159131131462542,"dt":639159131131462979}
{"op":"mcm","id":2,"clk":"APN0AJxLAJaXAQ==","pt":1780316313237,"mc":[{"id":"1.258742455","rc":[{"atl":[[5.5,31.4]],"batl":[],"id":99072898},{"atl":[[5.7,12.07],[5,11.3]],"batl":[[1,5,11.3]],"id":10398159},{"atl":[[9.2,1.79]],"batl":[[0,9.2,1.79]],"id":98117699}]}],"rt":639159131132453424,"dt":639159131132453831}
{"op":"mcm","id":2,"clk":"APp0AKJLAJyXAQ==","pt":1780316313341,"mc":[{"id":"1.258742455","rc":[{"atl":[[5.4,35.44],[5,19.4]],"batl":[[0,5,19.4]],"id":99072898},{"atl":[[5.6,8.85]],"batl":[],"id":10398159},{"batb":[[0,3.5,74.95]],"atb":[[3.5,74.95]],"id":88302242}]}],"rt":639159131133491202,"dt":639159131133491662}
{"op":"mcm","id":2,"clk":"AIp1AKVLAKuXAQ==","pt":1780316313544,"mc":[{"id":"1.258742455","rc":[{"batb":[],"atb":[[4.5,27.56]],"id":99072898}]}],"rt":639159131135522642,"dt":639159131135523040}
{"op":"mcm","id":2,"clk":"AJF1AKxLALKXAQ==","pt":1780316313650,"mc":[{"id":"1.258742455","rc":[{"batb":[[1,4.7,31.61],[0,4.8,44.36]],"atb":[[4.7,31.61],[4.8,44.36]],"atl":[[5,22.4]],"batl":[[0,5,22.4]],"id":99072898},{"batb":[[0,22,9.92]],"atb":[[22,9.92]],"id":99072900},{"atl":[[4.9,76.2]],"batl":[[0,4.9,76.64]],"id":10398159},{"tv":232.68,"batb":[[0,180,2.26]],"trd":[[180,48.86]],"ltp":180,"atb":[[180,2.26]],"id":99072897}],"tv":36544.42}],"rt":639159131136582848,"dt":639159131136583693}
{"op":"mcm","id":2,"clk":"AJh1AK1LALeXAQ==","pt":1780316313700,"mc":[{"id":"1.258742455","rc":[{"batb":[],"atb":[[4.4,20.84]],"id":99072898},{"batb":[],"atb":[[3.25,18.47]],"id":88302242}]}],"rt":639159131137083283,"dt":639159131137083616}
{"op":"mcm","id":2,"clk":"AKF1ALFLALyXAQ==","pt":1780316313807,"mc":[{"id":"1.258742455","rc":[{"tv":233.96,"batb":[[1,170,1.67],[0,180,1.62]],"trd":[[180,50.14]],"atb":[[180,1.62],[170,1.67]],"atl":[[190,0.88]],"batl":[[1,220,1.88],[0,200,1]],"id":99072897}],"tv":36545.7}],"rt":639159131138153904,"dt":639159131138154292}
{"op":"mcm","id":2,"clk":"AKx1ALVLAMWXAQ==","pt":1780316313916,"mc":[{"id":"1.258742455","rc":[{"tv":2307.57,"batb":[[2,8.8,13.56],[1,9,28.56],[0,9.2,2.43]],"trd":[[9.2,190.67]],"ltp":9.2,"atb":[[9.2,2.43]],"atl":[[9.2,0]],"batl":[[2,9.8,5.86],[1,9.6,7.78],[0,9.4,13.19]],"id":98117699},{"tv":2417.98,"batb":[[0,10.5,18.78]],"trd":[[10.5,137.51]],"atb":[[10.5,18.78]],"id":97736949},{"batb":[[2,150,3.04],[1,160,5.13],[0,170,1.75]],"atb":[[180,0.08]],"id":99072897}],"tv":36562.46}],"rt":639159131139245743,"dt":639159131139246326}
{"op":"mcm","id":2,"clk":"ALB1ALxLAMyXAQ==","pt":1780316314017,"mc":[{"id":"1.258742455","rc":[{"batb":[],"atb":[[8.4,9.19]],"id":98117699},{"tv":2423.08,"batb":[[0,10.5,17.64]],"trd":[[10.5,142.61]],"atb":[[10.5,17.64]],"id":97736949},{"batb":[[1,160,3.4],[0,170,2.18]],"atb":[[170,2.1],[160,3.4]],"id":99072897}],"tv":36567.56}],"rt":639159131140249497,"dt":639159131140250004}
{"op":"mcm","id":2,"clk":"ALR1AMFLANSXAQ==","pt":1780316314118,"mc":[{"id":"1.258742455","rc":[{"batb":[],"atb":[[3.25,8.66]],"id":88302242},{"batb":[[0,10.5,16.17]],"atb":[[10.5,16.17]],"id":97736949}]}],"rt":639159131141265344,"dt":639159131141265715}
{"op":"mcm","id":2,"clk":"ALh1AMRLAN\u002BXAQ==","pt":1780316314220,"mc":[{"id":"1.258742455","rc":[{"atb":[[7,13]],"id":99072900},{"batb":[],"atb":[[3.25,18.48]],"id":88302242},{"batb":[[1,10,22.15]],"atb":[[10,22.15]],"id":97736949}]}],"rt":639159131142289004,"dt":639159131142289403}
{"op":"mcm","id":2,"clk":"ALt1AMhLAOeXAQ==","pt":1780316314322,"mc":[{"id":"1.258742455","rc":[{"atl":[[24,7.65]],"batl":[[0,24,7.65]],"id":99072900}]}],"rt":639159131143305530,"dt":639159131143305909}
{"op":"mcm","id":2,"clk":"AMF1AM9LAO\u002BXAQ==","pt":1780316314429,"mc":[{"id":"1.258742455","rc":[{"batb":[],"atb":[[8.2,9.53]],"atl":[[10,19.51]],"batl":[],"id":98117699}]}],"rt":639159131144376254,"dt":639159131144376670}
{"op":"mcm","id":2,"clk":"AMl1ANFLAPSXAQ==","pt":1780316314527,"mc":[{"id":"1.258742455","rc":[{"atl":[[19,0]],"id":99072898}]}],"rt":639159131145353520,"dt":639159131145353896}
{"op":"mcm","id":2,"clk":"ANJ1ANVLAP6XAQ==","pt":1780316314630,"mc":[{"id":"1.258742455","rc":[{"batb":[],"atb":[[8.4,15.19]],"atl":[[10.5,14.74]],"batl":[],"id":98117699}]}],"rt":639159131146383009,"dt":639159131146383434}
{"op":"mcm","id":2,"clk":"APR1AOhLAKaYAQ==","pt":1780316315142,"mc":[{"id":"1.258742455","rc":[{"atl":[[10.5,18.22]],"batl":[],"id":98117699}]}],"rt":639159131151505597,"dt":639159131151505952}
{"op":"mcm","id":2,"clk":"AIJ2APNLALiYAQ==","pt":1780316315344,"mc":[{"id":"1.258742455","rc":[{"batb":[],"atb":[[17,56.3]],"id":99072900},{"tv":12610.33,"batb":[[0,3.5,71.95]],"trd":[[3.5,58.58]],"atb":[[3.5,71.95]],"id":88302242}],"tv":36573.56}],"rt":639159131153520119,"dt":639159131153520706}
{"op":"mcm","id":2,"clk":"AJx2AIRMAN6YAQ==","pt":1780316315713,"mc":[{"id":"1.258742455","rc":[{"batb":[[1,9,29.56]],"atb":[[9,29.56]],"id":98117699}]}],"rt":639159131157210574,"dt":639159131157210978}
{"op":"mcm","id":2,"clk":"ANF2AKpMAKOZAQ==","pt":1780316316533,"mc":[{"id":"1.258742455","rc":[{"tv":12618.17,"trd":[[3.55,356.35]],"ltp":3.55,"atl":[[3.55,3.66]],"batl":[[0,3.55,3.66]],"id":88302242}],"tv":36581.4}],"rt":639159131165408871,"dt":639159131165409225}
{"op":"mcm","id":2,"clk":"AOR2ALJMALWZAQ==","pt":1780316316736,"mc":[{"id":"1.258742455","rc":[{"atb":[[1.17,2.41]],"id":10398159},{"atl":[[3.55,0]],"batl":[[2,3.7,209.44],[1,3.65,20.49],[0,3.6,36.75]],"id":88302242}]}],"rt":639159131167440889,"dt":639159131167441639}
{"op":"mcm","id":2,"clk":"AO52ALlMAL6ZAQ==","pt":1780316316839,"mc":[{"id":"1.258742455","rc":[{"atb":[[1.17,2]],"id":10398159}]}],"rt":639159131168474920,"dt":639159131168475289}
{"op":"mcm","id":2,"clk":"APZ2AL1MAMOZAQ==","pt":1780316316941,"mc":[{"id":"1.258742455","rc":[{"batb":[[0,4.7,78.43]],"atb":[[4.7,78.43]],"id":10398159}]}],"rt":639159131169488192,"dt":639159131169488544}
{"op":"mcm","id":2,"clk":"AP52AMFMAMuZAQ==","pt":1780316317043,"mc":[{"id":"1.258742455","rc":[{"atl":[[3.75,111.44]],"batl":[],"id":88302242}]}],"rt":639159131170515865,"dt":639159131170516257}
{"op":"mcm","id":2,"clk":"AIZ3AMhMANGZAQ==","pt":1780316317149,"mc":[{"id":"1.258742455","rc":[{"atl":[[5.2,14.68]],"batl":[[2,5.2,14.68]],"id":99072898}]}],"rt":639159131171570595,"dt":639159131171570937}
{"op":"mcm","id":2,"clk":"AIx3AM1MANqZAQ==","pt":1780316317202,"mc":[{"id":"1.258742455","rc":[{"atl":[[5.1,230.97]],"batl":[[1,5.1,230.97]],"id":99072898},{"atl":[[3.8,11.46]],"batl":[],"id":88302242}]}],"rt":639159131172097158,"dt":639159131172097479}
{"op":"mcm","id":2,"clk":"AJF3ANZMAOCZAQ==","pt":1780316317305,"mc":[{"id":"1.258742455","rc":[{"tv":7778.99,"batb":[[2,4.7,31.61],[1,4.8,44.36],[0,5,22.18]],"trd":[[5,140.97]],"ltp":5,"atb":[[5,22.18]],"atl":[[5,0]],"batl":[[2,5.3,6],[1,5.2,14.68],[0,5.1,230.97]],"id":99072898}],"tv":36626.2}],"rt":639159131173132305,"dt":639159131173132697}
{"op":"mcm","id":2,"clk":"AJZ3ANxMAOeZAQ==","pt":1780316317408,"mc":[{"id":"1.258742455","rc":[{"tv":7823.34,"batb":[[0,4.9,20.1]],"trd":[[5,185.32]],"atb":[[4.9,20.1],[5,0]],"atl":[[5.4,32.52],[5.2,18.2],[5.5,28.48],[5,18.03],[5.6,8.87]],"batl":[[2,5.2,18.2],[1,5.1,230.97],[0,5,18.03]],"id":99072898},{"batb":[[0,10.5,10.5]],"atb":[[10.5,10.5]],"id":97736949}],"tv":36670.55}],"rt":639159131174161308,"dt":639159131174161898}
{"op":"mcm","id":2,"clk":"AJx3AN9MAO6ZAQ==","pt":1780316317509,"mc":[{"id":"1.258742455","rc":[{"batb":[[0,4.9,13.2]],"atb":[[4.9,13.2]],"atl":[[5.5,31.36],[5,25.78]],"batl":[[0,5,25.78]],"id":99072898}]}],"rt":639159131175171114,"dt":639159131175171474}
{"op":"mcm","id":2,"clk":"AKB3AOZMAPiZAQ==","pt":1780316317619,"mc":[{"id":"1.258742455","rc":[{"batb":[],"atb":[[4.4,14.84]],"atl":[[5.4,26.52],[5.2,14.68],[5,13.18]],"batl":[[2,5.2,14.68],[0,5,13.18]],"id":99072898},{"batb":[[0,10.5,16.18]],"atb":[[10.5,16.18]],"id":97736949}]}],"rt":639159131176269383,"dt":639159131176269774}
{"op":"mcm","id":2,"clk":"AKh3AOlMAIaaAQ==","pt":1780316317719,"mc":[{"id":"1.258742455","rc":[{"batb":[[0,4.9,7.67]],"atb":[[4.9,7.67]],"id":99072898}]}],"rt":639159131177266539,"dt":639159131177266943}
{"op":"mcm","id":2,"clk":"AK53APBMAJCaAQ==","pt":1780316317826,"mc":[{"id":"1.258742455","rc":[{"batb":[[2,4.6,36.34],[1,4.7,31.61],[0,4.8,44.36]],"atb":[[4.9,0],[4.6,36.34]],"atl":[[5.5,37.36]],"batl":[],"id":99072898}]}],"rt":639159131178339058,"dt":639159131178339403}
{"op":"mcm","id":2,"clk":"ALJ3APRMAJSaAQ==","pt":1780316317927,"mc":[{"id":"1.258742455","rc":[{"atl":[[5.4,29.43]],"batl":[],"id":99072898}]}],"rt":639159131179350164,"dt":639159131179350537}
{"op":"mcm","id":2,"clk":"ALt3APhMAJ\u002BaAQ==","pt":1780316318030,"mc":[{"id":"1.258742455","rc":[{"batb":[[0,4.8,33.77]],"atb":[[4.8,33.77]],"id":99072898}]}],"rt":639159131180378157,"dt":639159131180378587}
{"op":"mcm","id":2,"clk":"AL13AP1MAKeaAQ==","pt":1780316318131,"mc":[{"id":"1.258742455","rc":[{"atl":[[4.9,7.47]],"batl":[[2,5.1,230.97],[1,5,13.18],[0,4.9,7.47]],"id":99072898}]}],"rt":639159131181391636,"dt":639159131181392067}
{"op":"mcm","id":2,"clk":"AM93AIZNALqaAQ==","pt":1780316318338,"mc":[{"id":"1.258742455","rc":[{"atl":[[5.5,31.36]],"batl":[],"id":99072898}]}],"rt":639159131183464996,"dt":639159131183465353}
{"op":"mcm","id":2,"clk":"ANN3AIxNAMKaAQ==","pt":1780316318438,"mc":[{"id":"1.258742455","rc":[{"batb":[[2,4.6,30.34]],"atb":[[4.6,30.34]],"id":99072898}]}],"rt":639159131184464978,"dt":639159131184465333}
{"op":"mcm","id":2,"clk":"ANt3AJFNAMmaAQ==","pt":1780316318543,"mc":[{"id":"1.258742455","rc":[{"atl":[[5.3,12]],"batl":[],"id":99072898}]}],"rt":639159131185508542,"dt":639159131185508901}
{"op":"mcm","id":2,"clk":"AOF3AJhNANCaAQ==","pt":1780316318644,"mc":[{"id":"1.258742455","rc":[{"batb":[],"atb":[[4.4,20.84]],"id":99072898},{"batb":[[0,3.5,100.62]],"atb":[[3.5,100.62]],"id":88302242}]}],"rt":639159131186525069,"dt":639159131186525430}
{"op":"mcm","id":2,"clk":"AOR3AJlNANeaAQ==","pt":1780316318744,"mc":[{"id":"1.258742455","rc":[{"batb":[[2,3.45,50.34],[1,3.5,100.62],[0,3.55,15.27]],"atb":[[3.55,15.27]],"id":88302242},{"batb":[[0,170,1.75]],"atb":[[170,1.67]],"id":99072897}]}],"rt":639159131187521496,"dt":639159131187522048}
{"op":"mcm","id":2,"clk":"AOp3AJxNAOCaAQ==","pt":1780316318848,"mc":[{"id":"1.258742455","rc":[{"atl":[[5.2,18.35]],"batl":[],"id":99072898}]}],"rt":639159131188560719,"dt":639159131188561310}
{"op":"mcm","id":2,"clk":"AO93AKJNAOuaAQ==","pt":1780316318950,"mc":[{"id":"1.258742455","rc":[{"tv":12648.71,"batb":[[2,3.4,34.69],[1,3.45,50.34],[0,3.5,100.62]],"trd":[[3.55,386.89]],"atb":[[3.55,0]],"atl":[[3.55,18.37]],"batl":[[2,3.65,20.49],[1,3.6,36.75],[0,3.55,18.37]],"id":88302242}],"tv":36701.09}],"rt":639159131189580624,"dt":639159131189581084}
{"op":"mcm","id":2,"clk":"APF3AKRNAPSaAQ==","pt":1780316319052,"mc":[{"id":"1.258742455","rc":[{"tv":12690.68,"batb":[[2,3.45,50.34],[1,3.5,100.62],[0,3.55,11.81]],"trd":[[3.55,428.86]],"atb":[[3.3,6.33],[3.55,11.81]],"atl":[[3.55,0]],"batl":[[2,3.7,209.44],[1,3.65,20.49],[0,3.6,36.75]],"id":88302242}],"tv":36743.06}],"rt":639159131190601249,"dt":639159131190601856}
{"op":"mcm","id":2,"clk":"APp3AKhNAPmaAQ==","pt":1780316319153,"mc":[{"id":"1.258742455","rc":[{"atl":[[5.3,14.93]],"batl":[],"id":99072898},{"atl":[[50,11.07]],"batl":[[0,50,11.07]],"id":97008932},{"tv":8242.53,"batb":[[0,4.7,56.43]],"trd":[[4.7,844.51]],"atb":[[4.7,56.43]],"id":10398159},{"batb":[],"atb":[[3.3,16.04]],"id":88302242}],"tv":36787.06}],"rt":639159131191615409,"dt":639159131191615832}
{"op":"mcm","id":2,"clk":"AP93AKxNAICbAQ==","pt":1780316319207,"mc":[{"id":"1.258742455","rc":[{"batb":[],"atb":[[8.4,11.44]],"id":98117699}]}],"rt":639159131192150925,"dt":639159131192151269}
{"op":"mcm","id":2,"clk":"AIR4ALBNAIybAQ==","pt":1780316319313,"mc":[{"id":"1.258742455","rc":[{"tv":542.55,"trd":[[46,66.63]],"ltp":46,"id":97008932},{"batb":[[0,4.7,67.43]],"atb":[[4.7,67.43]],"atl":[[4.8,23.44]],"batl":[[2,5,11.3],[1,4.9,76.2],[0,4.8,23.44]],"id":10398159},{"batb":[],"atb":[[3.35,142.94]],"atl":[[3.8,5.46]],"batl":[],"id":88302242}],"tv":36787.08}],"rt":639159131193215708,"dt":639159131193216186}
{"op":"mcm","id":2,"clk":"AJB4ALJNAJabAQ==","pt":1780316319419,"mc":[{"id":"1.258742455","rc":[{"atl":[[170,0.14]],"batl":[],"id":99072901},{"atl":[[5.6,11.83]],"batl":[],"id":10398159}]}],"rt":639159131194275553,"dt":639159131194276018}
{"op":"mcm","id":2,"clk":"AJx4AL1NAKCbAQ==","pt":1780316319530,"mc":[{"id":"1.258742455","rc":[{"atl":[[90,0.19]],"batl":[[0,95,3.75]],"id":99072901},{"atl":[[3.75,117.44]],"batl":[],"id":88302242}]}],"rt":639159131195379688,"dt":639159131195380153}
{"op":"mcm","id":2,"clk":"AKZ4AMFNAKybAQ==","pt":1780316319622,"mc":[{"id":"1.258742455","rc":[{"atl":[[5.3,27.45]],"batl":[],"id":10398159}]}],"rt":639159131196299062,"dt":639159131196299421}
{"op":"mcm","id":2,"clk":"AKt4AMJNALebAQ==","pt":1780316319727,"mc":[{"id":"1.258742455","rc":[{"atl":[[5,19.27]],"batl":[[2,5,19.27]],"id":10398159}]}],"rt":639159131197355917,"dt":639159131197356297}
{"op":"mcm","id":2,"clk":"ALt4AM5NAMibAQ==","pt":1780316319931,"mc":[{"id":"1.258742455","rc":[{"atl":[[55,19.43]],"batl":[[1,55,19.43]],"id":97008932},{"batb":[],"atb":[[16.5,3.6]],"id":99072900},{"batb":[[0,4.7,76.07]],"atb":[[4.7,76.07]],"atl":[[5.2,32.03]],"batl":[],"id":10398159},{"batb":[[1,9,27.42]],"atb":[[1.17,2.85],[9,27.42]],"atl":[[9.4,12.72],[1000,7.6]],"batl":[[0,9.4,12.72]],"id":98117699},{"atl":[[1000,3.63]],"id":88302242},{"batb":[[0,10.5,17.56]],"atb":[[10.5,17.56]],"id":97736949}]}],"rt":639159131199392833,"dt":639159131199393339}
{"op":"mcm","id":2,"clk":"AMZ4ANRNANKbAQ==","pt":1780316320038,"mc":[{"id":"1.258742455","rc":[{"atb":[[1.17,2]],"atl":[[1000,6.25]],"id":98117699},{"atl":[[1000,3],[3.75,111.44]],"batl":[],"id":88302242}]}],"rt":639159131200467812,"dt":639159131200468158}
{"op":"mcm","id":2,"clk":"ANB4ANdNAN\u002BbAQ==","pt":1780316320141,"mc":[{"id":"1.258742455","rc":[{"batb":[[0,9.2,3.28]],"atb":[[9.2,3.28]],"atl":[[9.4,13.29],[9.6,8.56]],"batl":[[1,9.6,8.56],[0,9.4,13.29]],"id":98117699},{"atl":[[3.6,37.38]],"batl":[[0,3.6,37.38]],"id":88302242}]}],"rt":639159131201496807,"dt":639159131201497193}
{"op":"mcm","id":2,"clk":"AOB4ANtNAOqbAQ==","pt":1780316320344,"mc":[{"id":"1.258742455","rc":[{"tv":12754.68,"batb":[[2,3.4,34.69],[1,3.45,50.34],[0,3.5,80.43]],"trd":[[3.5,98.96],[3.55,452.48]],"ltp":3.5,"atb":[[3.5,80.43],[3.55,0]],"atl":[[3.8,11.46]],"batl":[],"id":88302242}],"tv":36851.08}],"rt":639159131203518093,"dt":639159131203518563}
{"op":"mcm","id":2,"clk":"AOZ4AN5NAPObAQ==","pt":1780316320441,"mc":[{"id":"1.258742455","rc":[{"batb":[],"atb":[[8.4,15.19]],"id":98117699}]}],"rt":639159131204492701,"dt":639159131204493090}
{"op":"mcm","id":2,"clk":"APN4AOZNAPubAQ==","pt":1780316320547,"mc":[{"id":"1.258742455","rc":[{"atl":[[95,0.92]],"batl":[[0,95,1.11]],"id":99072901},{"batb":[],"atb":[[4.3,131.47]],"atl":[[4.8,0.44]],"batl":[[2,5.1,32.79],[1,5,19.27],[0,4.9,76.64]],"id":10398159},{"atl":[[3.55,5.32]],"batl":[[2,3.65,20.49],[1,3.6,37.38],[0,3.55,5.32]],"id":88302242}]}],"rt":639159131205554080,"dt":639159131205554501}
{"op":"mcm","id":2,"clk":"APl4AOlNAICcAQ==","pt":1780316320654,"mc":[{"id":"1.258742455","rc":[{"atl":[[5.6,8.85]],"batl":[],"id":10398159}]}],"rt":639159131206624280,"dt":639159131206624590}
{"op":"mcm","id":2,"clk":"AIJ5AO5NAIacAQ==","pt":1780316320753,"mc":[{"id":"1.258742455","rc":[{"atb":[[1.17,196.89]],"id":88302242}]}],"rt":639159131207610815,"dt":639159131207611202}
{"op":"mcm","id":2,"clk":"AId5AO5NAI6cAQ==","pt":1780316320807,"mc":[{"id":"1.258742455","rc":[{"batb":[],"atb":[[1.17,196.12],[3.35,136.94]],"id":88302242}]}],"rt":639159131208154206,"dt":639159131208154463}
{"op":"mcm","id":2,"clk":"AIt5APJNAJecAQ==","pt":1780316320910,"mc":[{"id":"1.258742455","rc":[{"tv":12756.22,"trd":[[3.55,454.02]],"ltp":3.55,"atl":[[3.55,4.55],[3.8,5.46]],"batl":[[0,3.55,4.55]],"id":88302242}],"tv":36852.62}],"rt":639159131209182130,"dt":639159131209182538}
{"op":"mcm","id":2,"clk":"AJJ5APVNAJ2cAQ==","pt":1780316321009,"mc":[{"id":"1.258742455","rc":[{"atl":[[5.2,26.03]],"batl":[],"id":10398159},{"atl":[[60,1.95]],"batl":[[1,60,1.95]],"id":98464183},{"batb":[],"atb":[[3.3,22.04]],"id":88302242}]}],"rt":639159131210170932,"dt":639159131210171401}
{"op":"mcm","id":2,"clk":"AJh5APpNAKWcAQ==","pt":1780316321122,"mc":[{"id":"1.258742455","rc":[{"atb":[[7,3]],"id":97008932},{"atl":[[95,0.63]],"batl":[[1,110,5.06],[0,100,1.46]],"id":99072901},{"tv":868.64,"batb":[[0,50,8.54]],"trd":[[50,128.64]],"atb":[[50,8.54]],"id":98464183},{"atl":[[3.75,117.44]],"batl":[],"id":88302242}],"tv":36856.62}],"rt":639159131211299472,"dt":639159131211299997}
{"op":"mcm","id":2,"clk":"AJ55AP9NAK2cAQ==","pt":1780316321218,"mc":[{"id":"1.258742455","rc":[{"atl":[[5.3,33.45]],"batl":[],"id":10398159}]}],"rt":639159131212272098,"dt":639159131212272570}
{"op":"mcm","id":2,"clk":"AKd5AIROALucAQ==","pt":1780316321330,"mc":[{"id":"1.258742455","rc":[{"atl":[[4.9,0]],"batl":[[2,5.2,18.35],[1,5.1,230.97],[0,5,13.18]],"id":99072898},{"tv":12783.9,"batb":[[0,3.5,66.59]],"trd":[[3.5,126.64]],"ltp":3.5,"atb":[[3.5,66.59]],"id":88302242}],"tv":36884.3}],"rt":639159131213379447,"dt":639159131213379999}
{"op":"mcm","id":2,"clk":"AK55AIpOAMScAQ==","pt":1780316321436,"mc":[{"id":"1.258742455","rc":[{"atl":[[5.3,12]],"batl":[],"id":99072898}]}],"rt":639159131214438427,"dt":639159131214438758}
{"op":"mcm","id":2,"clk":"AMR5AJlOAN\u002BcAQ==","pt":1780316321735,"mc":[{"id":"1.258742455","rc":[{"atl":[[4.9,2]],"batl":[[2,5.1,230.97],[1,5,13.18],[0,4.9,2]],"id":99072898}]}],"rt":639159131217430687,"dt":639159131217431055}
{"op":"mcm","id":2,"clk":"AMd5AJlOAOScAQ==","pt":1780316321832,"mc":[{"id":"1.258742455","rc":[{"atl":[[5.3,8.91]],"batl":[],"id":99072898}]}],"rt":639159131218405097,"dt":639159131218405452}
{"op":"mcm","id":2,"clk":"ANR5AKZOAPmcAQ==","pt":1780316322037,"mc":[{"id":"1.258742455","rc":[{"atl":[[5.4,35.43]],"batl":[],"id":99072898}]}],"rt":639159131220458959,"dt":639159131220459325}
{"op":"mcm","id":2,"clk":"AOF5ALROAI2dAQ==","pt":1780316322243,"mc":[{"id":"1.258742455","rc":[{"atl":[[5.7,9.63],[5.6,6.03]],"batl":[],"id":99072898}]}],"rt":639159131222512204,"dt":639159131222512602}
{"op":"mcm","id":2,"clk":"APZ5AMxOALCdAQ==","pt":1780316322605,"mc":[{"id":"1.258742455","rc":[{"atl":[[5.4,29.43]],"batl":[],"id":99072898}]}],"rt":639159131226131036,"dt":639159131226131478}
{"op":"mcm","id":2,"clk":"AP15ANFOALydAQ==","pt":1780316322711,"mc":[{"id":"1.258742455","rc":[{"atl":[[5,15.18]],"batl":[[1,5,15.18]],"id":99072898}]}],"rt":639159131227189238,"dt":639159131227189563}
{"op":"mcm","id":2,"clk":"AIJ6ANtOAMWdAQ==","pt":1780316322811,"mc":[{"id":"1.258742455","rc":[{"atl":[[5.3,14.91]],"batl":[],"id":99072898}]}],"rt":639159131228190413,"dt":639159131228190764}
{"op":"mcm","id":2,"clk":"AIp6AN1OAMqdAQ==","pt":1780316322913,"mc":[{"id":"1.258742455","rc":[{"atl":[[4.9,4.61]],"batl":[[0,4.9,4.61]],"id":99072898},{"atl":[[4.9,78.08]],"batl":[[0,4.9,78.52]],"id":10398159},{"tv":12792.16,"trd":[[3.55,462.28]],"ltp":3.55,"atl":[[1000,3.86],[3.55,0.42]],"batl":[[2,3.7,209.44],[1,3.65,20.49],[0,3.6,37.8]],"id":88302242}],"tv":36892.56}],"rt":639159131229207558,"dt":639159131229208049}
{"op":"mcm","id":2,"clk":"AJJ6AONOAMydAQ==","pt":1780316323014,"mc":[{"id":"1.258742455","rc":[{"batb":[],"atb":[[8.4,11.44]],"id":98117699},{"atl":[[1000,3]],"id":88302242}]}],"rt":639159131230222171,"dt":639159131230222588}
{"op":"mcm","id":2,"clk":"AJl6AOxOANOdAQ==","pt":1780316323120,"mc":[{"id":"1.258742455","rc":[{"atl":[[3.65,21.35]],"batl":[[1,3.65,21.35]],"id":88302242}]}],"rt":639159131231288083,"dt":639159131231288422}
{"op":"mcm","id":2,"clk":"AJ56AO9OANydAQ==","pt":1780316323221,"mc":[{"id":"1.258742455","rc":[{"atl":[[3.75,111.44]],"batl":[],"id":88302242}]}],"rt":639159131232297486,"dt":639159131232297831}
{"op":"mcm","id":2,"clk":"AKZ6APFOAOKdAQ==","pt":1780316323323,"mc":[{"id":"1.258742455","rc":[{"tv":7832.56,"batb":[[2,4.7,31.61],[1,4.8,33.77],[0,4.9,46.67]],"trd":[[4.9,152.25]],"ltp":4.9,"atb":[[4.9,46.67]],"atl":[[4.9,0],[5,17.18]],"batl":[[2,5.2,18.35],[1,5.1,230.97],[0,5,17.18]],"id":99072898},{"atl":[[38,2.76]],"id":99072900}],"tv":36901.78}],"rt":639159131233310848,"dt":639159131233311331}
{"op":"mcm","id":2,"clk":"AKt6APNOAOqdAQ==","pt":1780316323425,"mc":[{"id":"1.258742455","rc":[{"batb":[[0,4.9,61.31]],"atb":[[4.9,61.31]],"atl":[[5.4,26.52],[5.3,12]],"batl":[],"id":99072898},{"atl":[[5.6,11.82]],"batl":[],"id":10398159},{"atl":[[3.8,11.46]],"batl":[],"id":88302242},{"batb":[],"atb":[[9.6,14.43]],"id":97736949}]}],"rt":639159131234331489,"dt":639159131234331916}
{"op":"mcm","id":2,"clk":"ALF6APZOAPCdAQ==","pt":1780316323528,"mc":[{"id":"1.258742455","rc":[{"atl":[[5.2,14.68]],"batl":[[2,5.2,14.68]],"id":99072898}]}],"rt":639159131235359075,"dt":639159131235359479}
{"op":"mcm","id":2,"clk":"ALp6APtOAPedAQ==","pt":1780316323632,"mc":[{"id":"1.258742455","rc":[{"atl":[[5.2,16.75],[5.3,6]],"batl":[[2,5.2,16.75]],"id":99072898},{"atl":[[48,1.98]],"batl":[[2,55,19.43],[1,50,11.07],[0,48,1.98]],"id":97008932},{"atl":[[5.4,13.93]],"batl":[],"id":10398159},{"batb":[],"atb":[[7.8,6.4],[8.2,5.79],[8,54.4]],"id":98117699},{"tv":12842.68,"batb":[[2,3.5,76.4],[1,3.55,16.02],[0,3.6,12.1]],"trd":[[3.55,463.12],[3.6,699.92]],"ltp":3.6,"atb":[[3.5,76.4],[3.55,16.02],[3.6,12.1]],"atl":[[3.65,19.46],[3.55,0],[3.6,0]],"batl":[[2,3.75,111.44],[1,3.7,209.44],[0,3.65,19.46]],"id":88302242},{"batb":[[2,9.8,8.95]],"atb":[[9.8,8.95],[9,9.73],[9.6,11.2]],"id":97736949}],"tv":36952.3}],"rt":639159131236406937,"dt":639159131236407550}
{"op":"mcm","id":2,"clk":"AL96APtOAP2dAQ==","pt":1780316323732,"mc":[{"id":"1.258742455","rc":[{"batb":[],"atb":[[4.4,14.84]],"atl":[[5.1,233.83]],"batl":[[1,5.1,233.83]],"id":99072898},{"atl":[[5.3,36.42],[4.8,23.5]],"batl":[[2,5,19.27],[1,4.9,78.08],[0,4.8,23.5]],"id":10398159},{"batb":[],"atb":[[7.8,2.63],[7.6,124.18]],"id":98117699},{"tv":12863.24,"batb":[[1,3.55,21.56],[0,3.6,1.82]],"trd":[[3.6,720.48]],"atb":[[3.55,21.56],[3.6,1.82]],"atl":[[3.65,6.53],[3.7,205.44],[3.85,32.95]],"batl":[[1,3.7,205.44],[0,3.65,6.53]],"id":88302242},{"batb":[],"atb":[[8.8,10.65],[9,6.5]],"id":97736949}],"tv":36972.86}],"rt":639159131237399675,"dt":639159131237400261}
{"op":"mcm","id":2,"clk":"AMJ6AP9OAIWeAQ==","pt":1780316323836,"mc":[{"id":"1.258742455","rc":[{"atl":[[48,2.04]],"batl":[[0,48,2.04]],"id":97008932},{"batb":[[1,75,7.53],[0,80,5]],"atb":[[80,4.57],[75,7.53]],"id":99072901},{"tv":12866.88,"batb":[[2,3.45,50.34],[1,3.5,76.4],[0,3.55,21.56]],"trd":[[3.6,724.12]],"atb":[[3.6,0]],"atl":[[3.65,22.12],[3.8,15.41],[3.6,3.05]],"batl":[[2,3.7,205.44],[1,3.65,22.12],[0,3.6,3.05]],"id":88302242},{"batb":[[0,10.5,11.88]],"atb":[[10.5,11.88]],"id":97736949}],"tv":36976.5}],"rt":639159131238445673,"dt":639159131238446231}
{"op":"mcm","id":2,"clk":"AMd6AIBPAIueAQ==","pt":1780316323944,"mc":[{"id":"1.258742455","rc":[{"atl":[[5.4,32.52]],"batl":[],"id":99072898},{"atl":[[5.3,30.42]],"batl":[],"id":10398159},{"batb":[[0,3.55,22.56]],"atb":[[3.3,16.04],[3.55,22.56]],"id":88302242}]}],"rt":639159131239522523,"dt":639159131239522907}
{"op":"mcm","id":2,"clk":"AM96AIZPAJKeAQ==","pt":1780316324049,"mc":[{"id":"1.258742455","rc":[{"batb":[],"atb":[[4.5,33.56]],"id":99072898},{"batb":[[1,75,5.84],[0,80,3.31]],"atb":[[80,2.88],[75,5.84]],"id":99072901},{"atl":[[3.8,9.41]],"batl":[],"id":88302242}]}],"rt":639159131240568923,"dt":639159131240569254}
{"op":"mcm","id":2,"clk":"ANN6AIxPAJieAQ==","pt":1780316324145,"mc":[{"id":"1.258742455","rc":[{"tv":542.57,"batb":[[0,46,4.68]],"trd":[[46,66.65]],"atb":[[46,4.68]],"id":97008932},{"atl":[[5.2,32.03]],"batl":[],"id":10398159},{"batb":[],"atb":[[3.4,40.69]],"id":88302242}],"tv":36976.52}],"rt":639159131241535346,"dt":639159131241535774}
{"op":"mcm","id":2,"clk":"ANx6AJFPAKSeAQ==","pt":1780316324248,"mc":[{"id":"1.258742455","rc":[{"atl":[[3.85,38.95]],"batl":[],"id":88302242}]}],"rt":639159131242563553,"dt":639159131242563873}
{"op":"mcm","id":2,"clk":"AOR6AJZPAKyeAQ==","pt":1780316324347,"mc":[{"id":"1.258742455","rc":[{"atl":[[3.65,22.74]],"batl":[[1,3.65,22.74]],"id":88302242}]}],"rt":639159131243553727,"dt":639159131243554150}
{"op":"mcm","id":2,"clk":"AOt6AJxPALOeAQ==","pt":1780316324452,"mc":[{"id":"1.258742455","rc":[{"tv":8247.85,"batb":[[0,4.7,73.41]],"trd":[[4.7,849.83]],"atb":[[4.7,73.41]],"id":10398159},{"tv":873.96,"trd":[[55,88.62]],"ltp":55,"atl":[[55,2.69]],"batl":[[0,55,2.69]],"id":98464183},{"atl":[[3.65,24.74]],"batl":[[1,3.65,24.74]],"id":88302242}],"tv":36987.16}],"rt":639159131244603231,"dt":639159131244603668}
{"op":"mcm","id":2,"clk":"APB6AJ9PAL\u002BeAQ==","pt":1780316324551,"mc":[{"id":"1.258742455","rc":[{"tv":8249.57,"batb":[[0,4.7,72.55]],"trd":[[4.7,851.55]],"atb":[[4.7,72.55]],"id":10398159},{"batb":[[0,50,10.57]],"atb":[[50,10.57]],"atl":[[55,3.04]],"batl":[[0,55,3.04]],"id":98464183}],"tv":36988.88}],"rt":639159131245594202,"dt":639159131245594637}
{"op":"mcm","id":2,"clk":"APp6AKVPAMKeAQ==","pt":1780316324607,"mc":[{"id":"1.258742455","rc":[{"batb":[],"atb":[[4,29.82]],"id":10398159},{"atl":[[55,6.4]],"batl":[[0,55,6.4]],"id":98464183},{"batb":[],"atb":[[3.4,34.69]],"id":88302242}]}],"rt":639159131246154247,"dt":639159131246154643}
{"op":"mcm","id":2,"clk":"AIJ7AKZPAMmeAQ==","pt":1780316324718,"mc":[{"id":"1.258742455","rc":[{"atl":[[55,6.75]],"batl":[[0,55,6.75]],"id":98464183}]}],"rt":639159131247265421,"dt":639159131247265866}
{"op":"mcm","id":2,"clk":"AId7AKpPANCeAQ==","pt":1780316324810,"mc":[{"id":"1.258742455","rc":[{"batb":[],"atb":[[3.35,142.94]],"atl":[[3.85,32.95]],"batl":[],"id":88302242}]}],"rt":639159131248180584,"dt":639159131248181033}
{"op":"mcm","id":2,"clk":"AJF7AK5PANeeAQ==","pt":1780316324920,"mc":[{"id":"1.258742455","rc":[{"atl":[[4.9,36.43],[5,77.08]],"batl":[[2,5,77.08],[1,4.9,36.43]],"id":10398159},{"batb":[],"atb":[[8.6,15.94]],"id":98117699}]}],"rt":639159131249283605,"dt":639159131249284037}
{"op":"mcm","id":2,"clk":"AJd7ALRPAOCeAQ==","pt":1780316325019,"mc":[{"id":"1.258742455","rc":[{"atl":[[4.8,0.44]],"batl":[[2,5.1,32.79],[1,5,77.08],[0,4.9,36.87]],"id":10398159},{"atl":[[3.8,15.41]],"batl":[],"id":88302242}]}],"rt":639159131250274118,"dt":639159131250274544}
{"op":"mcm","id":2,"clk":"AKh7AL9PAPCeAQ==","pt":1780316325224,"mc":[{"id":"1.258742455","rc":[{"atl":[[5,69.11]],"batl":[[1,5,69.11]],"id":10398159}]}],"rt":639159131252325576,"dt":639159131252325931}
{"op":"mcm","id":2,"clk":"ALF7AMVPAPqeAQ==","pt":1780316325428,"mc":[{"id":"1.258742455","rc":[{"atb":[[16,3.9]],"id":99072900}]}],"rt":639159131254359388,"dt":639159131254359709}
{"op":"mcm","id":2,"clk":"AL17AMpPAIKfAQ==","pt":1780316325532,"mc":[{"id":"1.258742455","rc":[{"atl":[[5.1,33.83]],"batl":[[1,5.1,33.83]],"id":99072898},{"atl":[[5.2,26.03]],"batl":[],"id":10398159}]}],"rt":639159131255407504,"dt":639159131255407866}
{"op":"mcm","id":2,"clk":"AMF7ANRPAISfAQ==","pt":1780316325632,"mc":[{"id":"1.258742455","rc":[{"batb":[[2,4.7,29.1],[1,4.8,34.25],[0,4.9,63.02]],"atb":[[4.7,29.1],[4.9,63.02],[4.8,34.25]],"id":99072898},{"batb":[[0,46,5.7]],"atb":[[46,5.7]],"atl":[[48,2.27]],"batl":[[0,48,2.27]],"id":97008932},{"batb":[[0,4.7,66.1]],"atb":[[4.7,66.1]],"atl":[[4.9,34.7]],"batl":[[0,4.9,35.14]],"id":10398159},{"atl":[[1000,3.46],[3.65,23.88]],"batl":[[1,3.65,23.88]],"id":88302242},{"batb":[[0,10.5,10.54]],"atb":[[10.5,10.54]],"id":97736949}]}],"rt":639159131256403616,"dt":639159131256404081}
{"op":"mcm","id":2,"clk":"AMR7ANVPAI2fAQ==","pt":1780316325733,"mc":[{"id":"1.258742455","rc":[{"batb":[[0,4.9,67.87]],"atb":[[4.9,67.87]],"atl":[[5,11.75]],"batl":[[0,5,11.75]],"id":99072898},{"atl":[[5.3,36.42]],"batl":[],"id":10398159},{"atl":[[1000,3]],"id":88302242},{"tv":2425.73,"batb":[[0,10.5,9.22]],"trd":[[10.5,145.26]],"atb":[[10.5,9.22]],"id":97736949}],"tv":36991.53}],"rt":639159131257416839,"dt":639159131257417332}
{"op":"mcm","id":2,"clk":"AMp7ANtPAJSfAQ==","pt":1780316325835,"mc":[{"id":"1.258742455","rc":[{"batb":[[1,4.8,45.94]],"atb":[[4.8,45.94]],"atl":[[5,4]],"batl":[[0,5,4]],"id":99072898},{"batb":[[1,75,7.53],[0,80,5]],"atb":[[80,4.57],[75,7.53]],"id":99072901},{"atl":[[3.6,3.51]],"batl":[[0,3.6,3.51]],"id":88302242}]}],"rt":639159131258430133,"dt":639159131258430507}
{"op":"mcm","id":2,"clk":"AM97AN9PAJ6fAQ==","pt":1780316325940,"mc":[{"id":"1.258742455","rc":[{"tv":7840.56,"batb":[[2,4.8,45.94],[1,4.9,67.87],[0,5,2.14]],"trd":[[5,193.32]],"ltp":5,"atb":[[5,2.14]],"atl":[[5,0]],"batl":[[2,5.3,6],[1,5.2,16.75],[0,5.1,33.83]],"id":99072898}],"tv":36999.53}],"rt":639159131259478422,"dt":639159131259478753}
{"op":"mcm","id":2,"clk":"ANV7AOBPAKOfAQ==","pt":1780316326040,"mc":[{"id":"1.258742455","rc":[{"atl":[[3.6,9.93]],"batl":[[0,3.6,9.93]],"id":88302242}]}],"rt":639159131260482724,"dt":639159131260483222}
{"op":"mcm","id":2,"clk":"ANt7AOhPAKmfAQ==","pt":1780316326144,"mc":[{"id":"1.258742455","rc":[{"tv":7842.88,"batb":[[2,4.7,29.1],[1,4.8,45.94],[0,4.9,68.85]],"trd":[[5,195.64]],"atb":[[5,0.98]],"id":99072898},{"batb":[[0,22,6.25]],"atb":[[22,6.25]],"id":99072900},{"batb":[],"atb":[[9.2,3.27]],"id":97736949},{"batb":[[2,120,4.6],[1,150,3.04],[0,160,3.56]],"atb":[[170,0.08]],"id":99072897}],"tv":37001.85}],"rt":639159131261517087,"dt":639159131261517560}
{"op":"mcm","id":2,"clk":"AOB7AOlPALKfAQ==","pt":1780316326244,"mc":[{"id":"1.258742455","rc":[{"batb":[[0,4.9,80.54]],"atb":[[4.9,79.56]],"atl":[[5.4,26.52],[5.1,35.83]],"batl":[[0,5.1,35.83]],"id":99072898},{"atl":[[5.3,30.42]],"batl":[],"id":10398159},{"batb":[[0,3.55,16.02]],"atb":[[3.55,16.02]],"id":88302242}]}],"rt":639159131262522620,"dt":639159131262523019}
{"op":"mcm","id":2,"clk":"AOd7AOxPALufAQ==","pt":1780316326348,"mc":[{"id":"1.258742455","rc":[{"tv":7844.84,"batb":[[0,4.9,79.56]],"trd":[[5,197.6]],"atb":[[5,0],[4.5,27.56]],"atl":[[5.9,6.52],[5.7,38.19],[5,6.86]],"batl":[[2,5.2,16.75],[1,5.1,35.83],[0,5,6.86]],"id":99072898},{"batb":[[0,22,5.3]],"atb":[[22,5.3]],"id":99072900}],"tv":37003.81}],"rt":639159131263563554,"dt":639159131263564043}
{"op":"mcm","id":2,"clk":"AOt7APJPAMOfAQ==","pt":1780316326449,"mc":[{"id":"1.258742455","rc":[{"atl":[[23,1.43]],"batl":[[2,25,3.91],[1,24,7.65],[0,23,1.43]],"id":99072900},{"atl":[[5.2,32.03]],"batl":[],"id":10398159}]}],"rt":639159131264576523,"dt":639159131264577049}
{"op":"mcm","id":2,"clk":"APF7APdPAMufAQ==","pt":1780316326553,"mc":[{"id":"1.258742455","rc":[{"batb":[],"atb":[[4.6,36.34]],"atl":[[5.5,37.36],[19.5,4.04]],"batl":[],"id":99072898},{"batb":[[0,22,8.99]],"atb":[[22,8.99]],"id":99072900},{"atl":[[18.5,2.06]],"id":10398159},{"batb":[[1,150,4.73]],"atb":[[150,4.73]],"id":99072897}]}],"rt":639159131265607227,"dt":639159131265607691}
{"op":"mcm","id":2,"clk":"APd7APlPANWfAQ==","pt":1780316326657,"mc":[{"id":"1.258742455","rc":[{"atl":[[24,3.65],[23,4.92]],"batl":[[1,24,3.65],[0,23,4.92]],"id":99072900}]}],"rt":639159131266647280,"dt":639159131266647677}
{"op":"mcm","id":2,"clk":"AIF8AIJQAOWfAQ==","pt":1780316326813,"mc":[{"id":"1.258742455","rc":[{"batb":[[0,22,5.3]],"atb":[[22,5.3]],"id":99072900}]}],"rt":639159131268215819,"dt":639159131268216157}
{"op":"mcm","id":2,"clk":"AIZ8AItQAO2fAQ==","pt":1780316326916,"mc":[{"id":"1.258742455","rc":[{"batb":[[0,10.5,8.65]],"atb":[[10.5,8.65]],"id":97736949},{"batb":[[0,160,3.73]],"atb":[[180,0.25]],"id":99072897}]}],"rt":639159131269243648,"dt":639159131269244023}
{"op":"mcm","id":2,"clk":"AIx8AJBQAPSfAQ==","pt":1780316327023,"mc":[{"id":"1.258742455","rc":[{"atl":[[48,2.32]],"batl":[[0,48,2.32]],"id":97008932},{"atl":[[5.2,26.03]],"batl":[],"id":10398159}]}],"rt":639159131270315297,"dt":639159131270315713}
{"op":"mcm","id":2,"clk":"AJB8AJZQAPufAQ==","pt":1780316327121,"mc":[{"id":"1.258742455","rc":[{"batb":[],"atb":[[4.6,30.34]],"atl":[[5.5,31.36]],"batl":[],"id":99072898}]}],"rt":639159131271292436,"dt":639159131271292756}
{"op":"mcm","id":2,"clk":"AJd8AJtQAIWgAQ==","pt":1780316327233,"mc":[{"id":"1.258742455","rc":[{"atl":[[5.3,36.42]],"batl":[],"id":10398159},{"atb":[[7,12]],"id":98464183}]}],"rt":639159131272418270,"dt":639159131272418687}
{"op":"mcm","id":2,"clk":"AKF8AKBQAJOgAQ==","pt":1780316327325,"mc":[{"id":"1.258742455","rc":[{"batb":[],"atb":[[4.5,33.56]],"atl":[[5.4,32.52]],"batl":[],"id":99072898},{"tv":542.59,"batb":[[0,46,5.69]],"trd":[[46,66.67]],"atb":[[46,5.69]],"id":97008932}],"tv":37003.83}],"rt":639159131273335892,"dt":639159131273336334}
{"op":"mcm","id":2,"clk":"ALB8AKpQAKSgAQ==","pt":1780316327532,"mc":[{"id":"1.258742455","rc":[{"atl":[[3.6,24.93]],"batl":[[0,3.6,24.93]],"id":88302242}]}],"rt":639159131275400267,"dt":639159131275400679}
{"op":"mcm","id":2,"clk":"ALx8AK1QAKygAQ==","pt":1780316327641,"mc":[{"id":"1.258742455","rc":[{"atl":[[3.6,25.47]],"batl":[[0,3.6,25.47]],"id":88302242}]}],"rt":639159131276496821,"dt":639159131276497150}
{"op":"mcm","id":2,"clk":"ANh8AL5QAMSgAQ==","pt":1780316328047,"mc":[{"id":"1.258742455","rc":[{"atl":[[3.6,39.13]],"batl":[[0,3.6,39.13]],"id":88302242}]}],"rt":639159131280550137,"dt":639159131280550540}
{"op":"mcm","id":2,"clk":"AN98AMFQAMugAQ==","pt":1780316328145,"mc":[{"id":"1.258742455","rc":[{"tv":7859.78,"batb":[[0,4.9,72.09]],"trd":[[4.9,167.19]],"ltp":4.9,"atb":[[4.9,72.09]],"atl":[[5,13.86]],"batl":[[0,5,13.86]],"id":99072898},{"tv":8261.57,"batb":[[0,4.7,60.1]],"trd":[[4.7,863.55]],"atb":[[4.7,60.1]],"id":10398159},{"tv":2313.57,"batb":[[2,8.6,15.94],[1,8.8,13.56],[0,9,27.7]],"trd":[[9.2,196.67]],"atb":[[9.2,0.28]],"id":98117699},{"tv":12888.88,"batb":[[0,3.55,26.64]],"trd":[[3.55,485.12]],"ltp":3.55,"atb":[[3.55,26.64]],"id":88302242}],"tv":37058.77}],"rt":639159131281536647,"dt":639159131281537144}
{"op":"mcm","id":2,"clk":"AOl8AM1QANWgAQ==","pt":1780316328252,"mc":[{"id":"1.258742455","rc":[{"atl":[[5,22.03]],"batl":[[0,5,22.03]],"id":99072898}]}],"rt":639159131282605234,"dt":639159131282605619}
{"op":"mcm","id":2,"clk":"AOx8AM5QANygAQ==","pt":1780316328350,"mc":[{"id":"1.258742455","rc":[{"batb":[[0,3.55,28.04]],"atb":[[3.55,28.04]],"id":88302242}]}],"rt":639159131283582247,"dt":639159131283582675}
{"op":"mcm","id":2,"clk":"APZ8ANRQAOqgAQ==","pt":1780316328555,"mc":[{"id":"1.258742455","rc":[{"batb":[],"atb":[[8.4,5.44]],"id":98117699}]}],"rt":639159131285635685,"dt":639159131285636045}
{"op":"mcm","id":2,"clk":"APt8ANpQAPGgAQ==","pt":1780316328662,"mc":[{"id":"1.258742455","rc":[{"atl":[[5,28.04]],"batl":[[0,5,28.04]],"id":99072898},{"atl":[[50,11.38]],"batl":[[1,50,11.38]],"id":97008932}]}],"rt":639159131286697187,"dt":639159131286697586}
{"op":"mcm","id":2,"clk":"AIF9AN5QAPWgAQ==","pt":1780316328711,"mc":[{"id":"1.258742455","rc":[{"tv":8271.58,"batb":[[0,4.7,55.1]],"trd":[[4.7,873.56]],"atb":[[4.7,55.1]],"id":10398159},{"batb":[],"atb":[[8.2,11.79]],"id":98117699}],"tv":37068.78}],"rt":639159131287192974,"dt":639159131287193510}
{"op":"mcm","id":2,"clk":"AId9AORQAPugAQ==","pt":1780316328822,"mc":[{"id":"1.258742455","rc":[{"atl":[[5.1,32.97]],"batl":[[1,5.1,32.97]],"id":99072898},{"atl":[[5.2,28.99]],"batl":[],"id":10398159},{"batb":[[1,48,5.88]],"atb":[[48,5.88]],"id":98464183},{"tv":12892.34,"batb":[[0,3.55,26.31]],"trd":[[3.55,488.58]],"atb":[[3.55,26.31]],"id":88302242}],"tv":37072.24}],"rt":639159131288306245,"dt":639159131288306862}
{"op":"mcm","id":2,"clk":"AIx9AOhQAIChAQ==","pt":1780316328917,"mc":[{"id":"1.258742455","rc":[{"batb":[[0,4.7,77.85]],"atb":[[4.7,77.85]],"atl":[[5.1,35.75]],"batl":[[2,5.1,35.75]],"id":10398159},{"atl":[[3.8,11.46]],"batl":[],"id":88302242},{"batb":[],"atb":[[9,9.76]],"id":97736949}]}],"rt":639159131289254365,"dt":639159131289254805}
{"op":"mcm","id":2,"clk":"AKR9AINRAKmhAQ==","pt":1780316329436,"mc":[{"id":"1.258742455","rc":[{"atl":[[5,30.04]],"batl":[[0,5,30.04]],"id":99072898}]}],"rt":639159131294436512,"dt":639159131294436855}
{"op":"mcm","id":2,"clk":"AKd9AIVRAK6hAQ==","pt":1780316329538,"mc":[{"id":"1.258742455","rc":[{"batb":[[1,4.6,74.62]],"atb":[[4.6,74.62]],"id":10398159}]}],"rt":639159131295467334,"dt":639159131295467698}
{"op":"mcm","id":2,"clk":"ALl9AJJRAMehAQ==","pt":1780316329843,"mc":[{"id":"1.258742455","rc":[{"atl":[[4.8,25.44]],"batl":[[2,5,69.11],[1,4.9,34.7],[0,4.8,25.44]],"id":10398159},{"tv":12935.58,"batb":[[0,3.55,4.69]],"trd":[[3.55,531.82]],"atb":[[3.55,4.69]],"id":88302242}],"tv":37115.48}],"rt":639159131298516851,"dt":639159131298517298}
{"op":"mcm","id":2,"clk":"AL19AJVRAMqhAQ==","pt":1780316329946,"mc":[{"id":"1.258742455","rc":[{"atl":[[4.8,47.38]],"batl":[[0,4.8,47.38]],"id":10398159},{"batb":[],"atb":[[7.8,6.4]],"id":98117699},{"atl":[[3.8,15.41]],"batl":[],"id":88302242}]}],"rt":639159131299546020,"dt":639159131299546436}
{"op":"mcm","id":2,"clk":"AMF9AJhRAM6hAQ==","pt":1780316330048,"mc":[{"id":"1.258742455","rc":[{"batb":[[0,3.55,18.52]],"atb":[[3.55,18.52]],"id":88302242}]}],"rt":639159131300569255,"dt":639159131300569575}
{"op":"mcm","id":2,"clk":"AMp9AJxRANahAQ==","pt":1780316330156,"mc":[{"id":"1.258742455","rc":[{"atl":[[5.3,30.42]],"batl":[],"id":10398159},{"atl":[[3.8,11.46]],"batl":[],"id":88302242}]}],"rt":639159131301643164,"dt":639159131301643534}
{"op":"mcm","id":2,"clk":"AOB9ALBRAPOhAQ==","pt":1780316330455,"mc":[{"id":"1.258742455","rc":[{"atl":[[5.2,34.99]],"batl":[],"id":10398159}]}],"rt":639159131304632829,"dt":639159131304633206}
{"op":"mcm","id":2,"clk":"AOZ9ALRRAPuhAQ==","pt":1780316330557,"mc":[{"id":"1.258742455","rc":[{"batb":[[1,3.5,47.74],[0,3.55,42.4]],"atb":[[3.5,47.74],[3.55,42.4]],"id":88302242}]}],"rt":639159131305647315,"dt":639159131305647686}
{"op":"mcm","id":2,"clk":"APd9AMFRAIeiAQ==","pt":1780316330761,"mc":[{"id":"1.258742455","rc":[{"batb":[],"atb":[[4.1,6.18]],"id":99072898},{"batb":[],"atb":[[3.95,48.48]],"id":10398159},{"batb":[],"atb":[[7.8,2.63]],"id":98117699}]}],"rt":639159131307690932,"dt":639159131307691395}
{"op":"mcm","id":2,"clk":"AP59AMlRAI2iAQ==","pt":1780316330820,"mc":[{"id":"1.258742455","rc":[{"batb":[[0,4.9,74.09]],"atb":[[4.9,74.09]],"id":99072898},{"atb":[[3.05,297.07]],"id":88302242}]}],"rt":639159131308283470,"dt":639159131308283933}
{"op":"mcm","id":2,"clk":"AIV\u002BAMtRAJGiAQ==","pt":1780316330917,"mc":[{"id":"1.258742455","rc":[{"batb":[],"atb":[[7.8,1.99]],"id":98117699},{"batb":[],"atb":[[9,6.5]],"id":97736949}]}],"rt":639159131309246942,"dt":639159131309247285}
{"op":"mcm","id":2,"clk":"AIt\u002BANRRAJ2iAQ==","pt":1780316331028,"mc":[{"id":"1.258742455","rc":[{"batb":[],"atb":[[4.2,127.19]],"id":99072898},{"batb":[],"atb":[[19.5,3.42]],"id":99072900},{"batb":[],"atb":[[4,31.07]],"id":10398159},{"atb":[[3.05,298.71]],"id":88302242},{"batb":[],"atb":[[9.2,2.73]],"id":97736949}]}],"rt":639159131310361908,"dt":639159131310362474}
{"op":"mcm","id":2,"clk":"AJx\u002BAN1RAKqiAQ==","pt":1780316331239,"mc":[{"id":"1.258742455","rc":[{"batb":[[2,42,11.1]],"atb":[[42,11.1]],"id":97008932},{"batb":[],"atb":[[7.8,2.63]],"id":98117699}]}],"rt":639159131312473813,"dt":639159131312474194}
{"op":"mcm","id":2,"clk":"AKR\u002BAOBRALaiAQ==","pt":1780316331336,"mc":[{"id":"1.258742455","rc":[{"atl":[[5,23.04]],"batl":[[0,5,23.04]],"id":99072898},{"batb":[],"atb":[[19,5.85]],"id":99072900},{"batb":[],"atb":[[9,7.06]],"id":97736949}]}],"rt":639159131313443616,"dt":639159131313443992}
{"op":"mcm","id":2,"clk":"AKZ\u002BAOFRAL\u002BiAQ==","pt":1780316331433,"mc":[{"id":"1.258742455","rc":[{"batb":[],"atb":[[40,6.44]],"id":97008932}]}],"rt":639159131314410412,"dt":639159131314410765}
{"op":"mcm","id":2,"clk":"AMh\u002BAPVRAOGiAQ==","pt":1780316331842,"mc":[{"id":"1.258742455","rc":[{"atl":[[5,25.04]],"batl":[[0,5,25.04]],"id":99072898}]}],"rt":639159131318502895,"dt":639159131318503248}
{"op":"mcm","id":2,"clk":"AM5\u002BAP1RAOaiAQ==","pt":1780316331957,"mc":[{"id":"1.258742455","rc":[{"atl":[[5,27.09]],"batl":[[0,5,27.09]],"id":99072898},{"atl":[[48,2.09]],"batl":[[0,48,2.09]],"id":97008932},{"batb":[[0,4.7,75.25]],"atb":[[4.7,75.25]],"atl":[[4.9,34.55]],"batl":[[1,4.9,34.55]],"id":10398159},{"batb":[[0,10.5,7.19]],"atb":[[10.5,7.19]],"id":97736949}]}],"rt":639159131319651533,"dt":639159131319652086}
{"op":"mcm","id":2,"clk":"ANN\u002BAP5RAPCiAQ==","pt":1780316332057,"mc":[{"id":"1.258742455","rc":[{"tv":7861.78,"batb":[[0,4.9,73.09]],"trd":[[4.9,169.19]],"atb":[[4.9,73.09]],"id":99072898},{"tv":12981.52,"batb":[[0,3.55,19.43]],"trd":[[3.55,577.76]],"atb":[[3.55,19.43]],"id":88302242},{"tv":2428.51,"batb":[[0,10.5,5.8]],"trd":[[10.5,148.04]],"atb":[[10.5,5.8],[9,10.33]],"id":97736949}],"tv":37166.2}],"rt":639159131320650860,"dt":639159131320651343}
{"op":"mcm","id":2,"clk":"ANt\u002BAIVSAPqiAQ==","pt":1780316332162,"mc":[{"id":"1.258742455","rc":[{"atl":[[4.8,25.44]],"batl":[[0,4.8,25.44]],"id":10398159},{"batb":[[0,3.55,32.02]],"atb":[[3.55,32.02]],"id":88302242},{"batb":[],"atb":[[9,7.06]],"id":97736949}]}],"rt":639159131321701918,"dt":639159131321702452}
{"op":"mcm","id":2,"clk":"AOJ\u002BAIdSAIKjAQ==","pt":1780316332254,"mc":[{"id":"1.258742455","rc":[{"batb":[[0,4.9,34.89]],"atb":[[4.9,34.89]],"id":99072898},{"atl":[[5.4,10.96],[5.7,9.09],[5.6,8.85]],"batl":[],"id":10398159},{"batb":[],"atb":[[3.2,2.8]],"id":88302242}]}],"rt":639159131322625115,"dt":639159131322625551}
{"op":"mcm","id":2,"clk":"AOx\u002BAI5SAImjAQ==","pt":1780316332361,"mc":[{"id":"1.258742455","rc":[{"atl":[[12,15.3],[11.5,11.75]],"batl":[[2,12,15.3],[1,11.5,11.75]],"id":97736949},{"tv":235.96,"batb":[[0,160,2.73]],"trd":[[180,50.64],[170,20.16],[160,50.18]],"ltp":160,"atb":[[180,0],[170,0],[160,2.73]],"id":99072897}],"tv":37168.2}],"rt":639159131323693236,"dt":639159131323693706}
{"op":"mcm","id":2,"clk":"APF\u002BAJNSAI6jAQ==","pt":1780316332459,"mc":[{"id":"1.258742455","rc":[{"batb":[],"atb":[[9,10.33]],"id":97736949}]}],"rt":639159131324670950,"dt":639159131324671291}
{"op":"mcm","id":2,"clk":"APl\u002BAJtSAJSjAQ==","pt":1780316332561,"mc":[{"id":"1.258742455","rc":[{"tv":7885.94,"batb":[[0,4.9,22.81]],"trd":[[4.9,193.35]],"atb":[[4.9,22.81]],"id":99072898},{"atb":[[1.17,2.17]],"id":97736949},{"batb":[[0,160,3.31]],"atb":[[160,3.31]],"atl":[[180,0.06]],"batl":[[0,200,1.06]],"id":99072897}],"tv":37192.36}],"rt":639159131325687456,"dt":639159131325687853}
{"op":"mcm","id":2,"clk":"AIF/AJ9SAJujAQ==","pt":1780316332664,"mc":[{"id":"1.258742455","rc":[{"batb":[[2,4.7,27.04],[1,4.8,38.79]],"atb":[[4.7,27.04],[4.6,37.36],[4.8,38.79]],"atl":[[5,29.92]],"batl":[[0,5,29.92]],"id":99072898},{"atl":[[5.1,32.79]],"batl":[],"id":10398159},{"batb":[],"atb":[[7.8,6.41],[8,58.18]],"id":98117699},{"atl":[[3.9,9.39],[3.85,29.02]],"batl":[],"id":88302242},{"batb":[],"atb":[[1.17,2],[9.2,6]],"id":97736949}]}],"rt":639159131326723985,"dt":639159131326724600}
{"op":"mcm","id":2,"clk":"AId/AKZSAKWjAQ==","pt":1780316332722,"mc":[{"id":"1.258742455","rc":[{"batb":[[0,4.9,6.27]],"atb":[[4.9,6.27]],"atl":[[5,34.65]],"batl":[[0,5,34.65]],"id":99072898},{"batb":[],"atb":[[3.4,38.44]],"id":88302242},{"batb":[[0,10.5,5.97]],"atb":[[10.5,5.97]],"id":97736949},{"atl":[[190,0.22]],"batl":[[1,220,1.13],[0,210,1.15]],"id":99072897}]}],"rt":639159131327306564,"dt":639159131327306996}
{"op":"mcm","id":2,"clk":"AI1/AKtSAKmjAQ==","pt":1780316332817,"mc":[{"id":"1.258742455","rc":[{"tv":7893.36,"batb":[[2,4.6,37.36],[1,4.7,27.04],[0,4.8,38.79]],"trd":[[4.9,200.77]],"atb":[[4.9,0]],"atl":[[4.9,7.27]],"batl":[[2,5.1,32.97],[1,5,34.65],[0,4.9,7.27]],"id":99072898},{"batb":[[0,160,5.04]],"atb":[[160,5.04]],"id":99072897}],"tv":37199.78}],"rt":639159131328250714,"dt":639159131328251203}
{"op":"mcm","id":2,"clk":"AJR/AK9SALKjAQ==","pt":1780316332923,"mc":[{"id":"1.258742455","rc":[{"batb":[[0,4.8,37.79]],"atb":[[4.8,37.79]],"id":99072898},{"batb":[[0,22,9]],"atb":[[22,9]],"id":99072900},{"tv":8291.57,"batb":[[0,4.7,65.25]],"trd":[[4.7,893.55]],"atb":[[4.7,65.25]],"id":10398159},{"batb":[[0,3.55,41.7]],"atb":[[3.55,41.7]],"id":88302242},{"batb":[[0,10.5,11.67]],"atb":[[10.5,11.67]],"id":97736949}],"tv":37219.77}],"rt":639159131329310545,"dt":639159131329311059}
{"op":"mcm","id":2,"clk":"AJp/ALBSALmjAQ==","pt":1780316333028,"mc":[{"id":"1.258742455","rc":[{"atl":[[5.1,35.74]],"batl":[],"id":10398159},{"atl":[[3.95,30.46],[3.6,27.47]],"batl":[[0,3.6,27.47]],"id":88302242},{"batb":[],"atb":[[9.4,16.24]],"id":97736949}]}],"rt":639159131330364323,"dt":639159131330364767}
{"op":"mcm","id":2,"clk":"AKN/ALZSAMKjAQ==","pt":1780316333129,"mc":[{"id":"1.258742455","rc":[{"batb":[[0,4.7,72.52]],"atb":[[4.7,72.52]],"atl":[[5,72.04]],"batl":[[2,5,72.04]],"id":10398159},{"batb":[],"atb":[[8.2,15.55]],"id":98117699},{"atl":[[3.9,5.47]],"batl":[],"id":88302242}]}],"rt":639159131331368911,"dt":639159131331369304}
{"op":"mcm","id":2,"clk":"AK1/AL9SAMyjAQ==","pt":1780316333232,"mc":[{"id":"1.258742455","rc":[{"atl":[[48,2.15]],"batl":[[0,48,2.15]],"id":97008932},{"batb":[[0,4.7,81.01]],"atb":[[4.7,81.01]],"atl":[[4.9,39.14]],"batl":[[1,4.9,39.14]],"id":10398159}]}],"rt":639159131332402063,"dt":639159131332402441}
{"op":"mcm","id":2,"clk":"ALN/AMVSANSjAQ==","pt":1780316333332,"mc":[{"id":"1.258742455","rc":[{"batb":[],"atb":[[4.5,27.56]],"atl":[[5.4,26.52],[5.7,9.63],[5.8,37.8]],"batl":[],"id":99072898},{"tv":12996.34,"trd":[[3.6,738.94]],"ltp":3.6,"atl":[[3.6,20.06]],"batl":[[0,3.6,20.06]],"id":88302242}],"tv":37234.59}],"rt":639159131333405242,"dt":639159131333405953}
{"op":"mcm","id":2,"clk":"AL5/AMVSAOCjAQ==","pt":1780316333437,"mc":[{"id":"1.258742455","rc":[{"tv":542.61,"batb":[[0,46,5.68]],"trd":[[46,66.69]],"atb":[[46,5.68]],"id":97008932},{"batb":[],"atb":[[3.4,34.69]],"id":88302242}],"tv":37234.61}],"rt":639159131334453157,"dt":639159131334453640}
{"op":"mcm","id":2,"clk":"AMN/AMdSAOmjAQ==","pt":1780316333544,"mc":[{"id":"1.258742455","rc":[{"batb":[],"atb":[[4.4,20.84]],"atl":[[5.3,12]],"batl":[],"id":99072898},{"batb":[[0,3.55,48.21]],"atb":[[3.55,48.21]],"id":88302242}]}],"rt":639159131335522764,"dt":639159131335523192}
{"op":"mcm","id":2,"clk":"AMV/AMtSAOujAQ==","pt":1780316333636,"mc":[{"id":"1.258742455","rc":[{"tv":8326.16,"batb":[[2,4.5,137.49],[0,4.7,63.72]],"trd":[[4.7,928.14]],"atb":[[4.7,63.72],[4.5,137.49]],"id":10398159},{"atl":[[3.6,18.05]],"batl":[[0,3.6,18.05]],"id":88302242}],"tv":37269.2}],"rt":639159131336445044,"dt":639159131336445466}
{"op":"mcm","id":2,"clk":"AMx/AM5SAPCjAQ==","pt":1780316333740,"mc":[{"id":"1.258742455","rc":[{"atl":[[4.8,46.17]],"batl":[[0,4.8,46.17]],"id":10398159},{"batb":[],"atb":[[8.2,11.79]],"id":98117699}]}],"rt":639159131337484054,"dt":639159131337484438}
{"op":"mcm","id":2,"clk":"ANJ/ANBSAPmjAQ==","pt":1780316333842,"mc":[{"id":"1.258742455","rc":[{"batb":[],"atb":[[4.4,159.65],[4.3,129.07]],"id":10398159},{"batb":[[2,46,4.96],[0,50,12.27]],"atb":[[50,12.27],[46,4.96]],"id":98464183}]}],"rt":639159131338504866,"dt":639159131338505351}
{"op":"mcm","id":2,"clk":"ANh/ANJSAIOkAQ==","pt":1780316333943,"mc":[{"id":"1.258742455","rc":[{"batb":[],"atb":[[8.2,15.55]],"id":98117699},{"atl":[[3.75,41.96],[3.8,77.07]],"batl":[],"id":88302242}]}],"rt":639159131339514639,"dt":639159131339515106}
{"op":"mcm","id":2,"clk":"AOl/ANtSAJKkAQ==","pt":1780316334151,"mc":[{"id":"1.258742455","rc":[{"atl":[[4.9,9.27],[5.1,37.22]],"batl":[[2,5.1,37.22],[0,4.9,9.27]],"id":99072898},{"tv":1087.47,"batb":[[0,22,6.07]],"trd":[[22,90.46]],"atb":[[22,6.07],[19,3.79],[18.5,3.59]],"id":99072900},{"tv":13032.46,"batb":[[2,3.5,47.74],[1,3.55,48.21],[0,3.6,12.55]],"trd":[[3.6,775.06]],"atb":[[3.6,12.55]],"atl":[[3.6,0]],"batl":[[2,3.75,41.96],[1,3.7,205.44],[0,3.65,23.88]],"id":88302242}],"tv":37308.24}],"rt":639159131341595220,"dt":639159131341595957}
{"op":"mcm","id":2,"clk":"AO5/AOJSAJikAQ==","pt":1780316334253,"mc":[{"id":"1.258742455","rc":[{"batb":[],"atb":[[4.3,119.97]],"id":10398159},{"batb":[],"atb":[[8.2,11.79]],"id":98117699},{"atl":[[3.95,26.55],[4,11.69]],"batl":[],"id":88302242}]}],"rt":639159131342609331,"dt":639159131342609812}
{"op":"mcm","id":2,"clk":"APd/AOdSAJ\u002BkAQ==","pt":1780316334353,"mc":[{"id":"1.258742455","rc":[{"atl":[[48,2.2]],"batl":[[0,48,2.2]],"id":97008932},{"atl":[[23,6.05]],"batl":[[0,23,6.05]],"id":99072900},{"tv":13035.34,"batb":[[1,3.55,50.24],[0,3.6,11.11]],"trd":[[3.6,777.94]],"atb":[[3.55,50.24],[3.6,11.11]],"id":88302242}],"tv":37311.12}],"rt":639159131343611521,"dt":639159131343612056}
{"op":"mcm","id":2,"clk":"AICAAQDrUgCnpAE=","pt":1780316334457,"mc":[{"id":"1.258742455","rc":[{"batb":[],"atb":[[3.35,136.94]],"atl":[[3.8,71.07]],"batl":[],"id":88302242}]}],"rt":639159131344657594,"dt":639159131344658025}
{"op":"mcm","id":2,"clk":"AImAAQDuUgCvpAE=","pt":1780316334515,"mc":[{"id":"1.258742455","rc":[{"batb":[[0,22,2.37]],"atb":[[22,2.37]],"id":99072900}]}],"rt":639159131345232809,"dt":639159131345233240}
{"op":"mcm","id":2,"clk":"AJKAAQD0UgC3pAE=","pt":1780316334618,"mc":[{"id":"1.258742455","rc":[{"tv":1092.21,"batb":[[2,19.5,3.42],[1,20,6.62],[0,21,8.6]],"trd":[[22,95.2]],"atb":[[22,0]],"atl":[[22,1.35]],"batl":[[2,24,3.65],[1,23,6.05],[0,22,1.35]],"id":99072900},{"batb":[],"atb":[[3.4,40.69]],"atl":[[3.85,35.02]],"batl":[],"id":88302242}],"tv":37315.86}],"rt":639159131346265256,"dt":639159131346265798}
{"op":"mcm","id":2,"clk":"AJyAAQD3UgC/pAE=","pt":1780316334719,"mc":[{"id":"1.258742455","rc":[{"atl":[[22,5.4]],"batl":[[0,22,5.4]],"id":99072900},{"atl":[[3.65,24.46]],"batl":[[0,3.65,24.46]],"id":88302242}]}],"rt":639159131347275136,"dt":639159131347275579}
{"op":"mcm","id":2,"clk":"AKOAAQD8UgDCpAE=","pt":1780316334820,"mc":[{"id":"1.258742455","rc":[{"batb":[[0,4.8,40.67]],"atb":[[4.8,40.67]],"id":99072898},{"batb":[[0,46,5.98]],"atb":[[46,5.98]],"id":97008932},{"tv":1093.47,"trd":[[22,96.46]],"atl":[[23,2.56],[22,4.77]],"batl":[[1,23,2.56],[0,22,4.77]],"id":99072900},{"batb":[[0,80,5.17]],"atb":[[80,4.74]],"id":99072901},{"batb":[[0,4.7,66.65]],"atb":[[4.7,66.65]],"id":10398159},{"batb":[[0,50,12.55]],"atb":[[50,12.55]],"id":98464183},{"batb":[[0,9,29.23]],"atb":[[9,28.95]],"id":98117699},{"batb":[[0,3.6,14.94]],"atb":[[3.6,14.94]],"id":88302242},{"batb":[[0,10.5,12.98]],"atb":[[10.5,12.98]],"id":97736949},{"batb":[[0,1000,93.01]],"atb":[[1000,93.01]],"id":10445502},{"batb":[[0,160,5.12]],"atb":[[160,5.12]],"id":99072897}],"tv":37317.12}],"rt":639159131348284529,"dt":639159131348285076}
{"op":"mcm","id":2,"clk":"AK\u002BAAQCCUwDJpAE=","pt":1780316334928,"mc":[{"id":"1.258742455","rc":[{"tv":1095.47,"batb":[[0,21,7.3]],"trd":[[22,98.46]],"atb":[[21,7.3]],"atl":[[1000,6.45],[22,3.77]],"batl":[[0,22,3.77]],"id":99072900},{"atb":[[1.17,196.29]],"id":88302242}],"tv":37319.12}],"rt":639159131349358458,"dt":639159131349359000}
{"op":"mcm","id":2,"clk":"ALqAAQCLUwDQpAE=","pt":1780316335032,"mc":[{"id":"1.258742455","rc":[{"atl":[[1000,6.25]],"id":99072900},{"tv":13035.62,"batb":[[0,3.6,14.8]],"trd":[[3.6,778.22]],"atb":[[1.17,196.12],[3.6,14.8]],"id":88302242}],"tv":37319.4}],"rt":639159131350396608,"dt":639159131350397092}
{"op":"mcm","id":2,"clk":"AL\u002BAAQCPUwDWpAE=","pt":1780316335133,"mc":[{"id":"1.258742455","rc":[{"atl":[[4.9,11.27]],"batl":[[0,4.9,11.27]],"id":99072898},{"batb":[[2,19.5,1.43],[1,20,4.63],[0,21,5.31]],"atb":[[21,5.31],[20,4.63],[19,1.8],[19.5,1.43],[18.5,1.6]],"atl":[[24,3.85],[22,5.21]],"batl":[[2,24,3.85],[0,22,5.21]],"id":99072900},{"batb":[[2,3.5,47.91]],"atb":[[3.5,47.91]],"id":88302242}]}],"rt":639159131351407777,"dt":639159131351408244}
{"op":"mcm","id":2,"clk":"AMmAAQCTUwDhpAE=","pt":1780316335237,"mc":[{"id":"1.258742455","rc":[{"atl":[[4.9,12.27]],"batl":[[0,4.9,12.27]],"id":99072898},{"tv":1104.95,"batb":[[2,19,1.8],[1,19.5,1.43],[0,20,5.2]],"trd":[[21,101.6]],"ltp":21,"atb":[[21,0.57]],"atl":[[22,6.35]],"batl":[[0,22,6.35]],"id":99072900},{"atb":[[2,17]],"id":10398159}],"tv":37328.88}],"rt":639159131352451627,"dt":639159131352452109}
{"op":"mcm","id":2,"clk":"ANKAAQCYUwDmpAE=","pt":1780316335337,"mc":[{"id":"1.258742455","rc":[{"batb":[[0,20,6.14]],"atb":[[21,0],[20,6.14]],"id":99072900},{"batb":[],"atb":[[8.2,15.55]],"id":98117699},{"batb":[],"atb":[[9.6,14.43]],"id":97736949}]}],"rt":639159131353460568,"dt":639159131353461036}
{"op":"mcm","id":2,"clk":"AOWAAQCdUwD2pAE=","pt":1780316335543,"mc":[{"id":"1.258742455","rc":[{"atl":[[21,1.45]],"batl":[[2,23,2.56],[1,22,6.35],[0,21,1.45]],"id":99072900}]}],"rt":639159131355513224,"dt":639159131355513581}
{"op":"mcm","id":2,"clk":"AO6AAQClUwCBpQE=","pt":1780316335650,"mc":[{"id":"1.258742455","rc":[{"atl":[[26,2.15],[21,2.18]],"batl":[[0,21,2.18]],"id":99072900},{"tv":387.06,"batb":[[0,80,4.17]],"trd":[[85,37.18],[80,74.2]],"atb":[[85,0],[80,4.17]],"id":99072901}],"tv":37330.88}],"rt":639159131356584965,"dt":639159131356585402}
{"op":"mcm","id":2,"clk":"APKAAQCnUwCLpQE=","pt":1780316335747,"mc":[{"id":"1.258742455","rc":[{"batb":[[2,75,7.53],[1,80,4.17],[0,85,2.55]],"atb":[[85,2.55]],"atl":[[100,0.45]],"batl":[[0,100,1.27]],"id":99072901},{"tv":13065.22,"batb":[[2,3.45,50.34],[1,3.5,47.91],[0,3.55,50.24]],"trd":[[3.6,807.82]],"atb":[[3.6,0]],"atl":[[3.6,0.2]],"batl":[[0,3.65,24.66]],"id":88302242}],"tv":37360.48}],"rt":639159131357550186,"dt":639159131357550645}
{"op":"mcm","id":2,"clk":"APyAAQCtUwCWpQE=","pt":1780316335858,"mc":[{"id":"1.258742455","rc":[{"atl":[[3.7,212.77]],"batl":[[1,3.7,212.77]],"id":88302242}]}],"rt":639159131358667366,"dt":639159131358667768}
{"op":"mcm","id":2,"clk":"AP\u002BAAQCxUwCjpQE=","pt":1780316335953,"mc":[{"id":"1.258742455","rc":[{"batb":[[2,19,5.5],[1,19.5,5.13]],"atb":[[19,5.5],[19.5,5.13]],"id":99072900},{"batb":[[1,80,3.1],[0,85,5.23]],"atb":[[85,5.23],[80,3.1]],"id":99072901},{"batb":[[0,4.7,72.9]],"atb":[[4.7,72.9]],"atl":[[4.8,25.44]],"batl":[[0,4.8,25.44]],"id":10398159},{"batb":[[0,3.55,67.94]],"atb":[[3.55,67.94]],"atl":[[3.85,49.74]],"batl":[],"id":88302242}]}],"rt":639159131359614654,"dt":639159131359615027}
{"op":"mcm","id":2,"clk":"AImBAQC0UwCppQE=","pt":1780316336056,"mc":[{"id":"1.258742455","rc":[{"batb":[],"atb":[[4.1,8.17]],"id":99072898},{"atl":[[21,0.73]],"batl":[[2,24,3.85],[1,23,2.56],[0,22,7.08]],"id":99072900},{"batb":[[1,80,3.62]],"atb":[[80,3.62]],"id":99072901},{"batb":[],"atb":[[3.4,34.69]],"id":88302242}]}],"rt":639159131360641704,"dt":639159131360642108}
{"op":"mcm","id":2,"clk":"AJ2BAQC\u002BUwC7pQE=","pt":1780316336262,"mc":[{"id":"1.258742455","rc":[{"batb":[],"atb":[[3.35,142.94]],"atl":[[3.85,35.02]],"batl":[],"id":88302242}]}],"rt":639159131362703149,"dt":639159131362703551}
{"op":"mcm","id":2,"clk":"AL2BAQDHUwDSpQE=","pt":1780316336522,"mc":[{"id":"1.258742455","rc":[{"tv":1106.95,"trd":[[22,99],[21,103.06]],"ltp":22,"atl":[[22,6.08],[21,0]],"batl":[[0,22,6.08]],"id":99072900}],"tv":37362.48}],"rt":639159131365304883,"dt":639159131365305295}
{"op":"mcm","id":2,"clk":"AMWBAQDMUwDbpQE=","pt":1780316336638,"mc":[{"id":"1.258742455","rc":[{"batb":[[2,19.5,5.13],[1,20,6.14],[0,21,1.11]],"atb":[[21,1.11]],"atl":[[22,6.85]],"batl":[[0,22,6.85]],"id":99072900}]}],"rt":639159131366458007,"dt":639159131366458411}
{"op":"mcm","id":2,"clk":"AMyBAQDRUwDhpQE=","pt":1780316336726,"mc":[{"id":"1.258742455","rc":[{"batb":[[1,20,6.9]],"atb":[[20,6.9]],"id":99072900}]}],"rt":639159131367340707,"dt":639159131367341081}
{"op":"mcm","id":2,"clk":"AIGCAQD8UwCfpgE=","pt":1780316337644,"mc":[{"id":"1.258742455","rc":[{"tv":13069.22,"batb":[[0,3.55,65.94]],"trd":[[3.55,581.76]],"ltp":3.55,"atb":[[3.55,65.94]],"id":88302242}],"tv":37366.48}],"rt":639159131376523340,"dt":639159131376523716}
{"op":"mcm","id":2,"clk":"AJiCAQCVVACxpgE=","pt":1780316337956,"mc":[{"id":"1.258742455","rc":[{"batb":[[0,4.8,38.33]],"atb":[[4.8,38.33]],"atl":[[5,26.59]],"batl":[[1,5,26.59]],"id":99072898},{"atl":[[1000,6.62],[24,3.65],[23,3.07]],"batl":[[2,24,3.65],[1,23,3.07]],"id":99072900},{"batb":[[1,3.5,47.74],[0,3.55,73.76]],"atb":[[3.5,47.74],[3.55,73.76]],"id":88302242},{"batb":[[0,10.5,14.32]],"atb":[[10.5,14.32]],"id":97736949}]}],"rt":639159131379641815,"dt":639159131379642279}
{"op":"mcm","id":2,"clk":"AKCCAQCWVAC7pgE=","pt":1780316338062,"mc":[{"id":"1.258742455","rc":[{"tv":7910.66,"batb":[[0,4.8,29.68]],"trd":[[4.8,200.82]],"ltp":4.8,"atb":[[4.8,29.68]],"id":99072898},{"atl":[[1000,6.25]],"id":99072900}],"tv":37383.78}],"rt":639159131380703308,"dt":639159131380703769}
{"op":"mcm","id":2,"clk":"AKOCAQCaVADDpgE=","pt":1780316338161,"mc":[{"id":"1.258742455","rc":[{"atl":[[22,7.22]],"batl":[[0,22,7.22]],"id":99072900},{"batb":[[0,3.55,56.34]],"atb":[[3.55,56.34]],"id":88302242}]}],"rt":639159131381696802,"dt":639159131381697212}
{"op":"mcm","id":2,"clk":"ALGCAQCeVADRpgE=","pt":1780316338314,"mc":[{"id":"1.258742455","rc":[{"tv":1108.95,"trd":[[22,101]],"atl":[[22,6.22]],"batl":[[0,22,6.22]],"id":99072900}],"tv":37385.78}],"rt":639159131383226605,"dt":639159131383227008}
{"op":"mcm","id":2,"clk":"ALmCAQCjVADapgE=","pt":1780316338421,"mc":[{"id":"1.258742455","rc":[{"batb":[[0,4.8,30.76]],"atb":[[4.8,30.76]],"id":99072898},{"batb":[[0,21,2.47]],"atb":[[21,2.47]],"id":99072900},{"batb":[[0,4.7,74.01]],"atb":[[4.7,74.01]],"atl":[[18.5,0]],"id":10398159},{"tv":875.96,"batb":[[0,50,11.55]],"trd":[[50,130.64]],"ltp":50,"atb":[[50,11.55]],"id":98464183},{"batb":[[0,3.55,57.81]],"atb":[[3.55,57.81]],"id":88302242},{"batb":[[0,1000,93.02]],"atb":[[1000,93.02]],"id":10445502}],"tv":37387.78}],"rt":639159131384296266,"dt":639159131384296792}
{"op":"mcm","id":2,"clk":"AMqCAQCvVADopgE=","pt":1780316338626,"mc":[{"id":"1.258742455","rc":[{"tv":7925.66,"batb":[[0,4.8,23.26]],"trd":[[4.8,215.82]],"atb":[[4.8,23.26]],"id":99072898}],"tv":37402.78}],"rt":639159131386340511,"dt":639159131386341116}
{"op":"mcm","id":2,"clk":"ANWCAQCxVADwpgE=","pt":1780316338726,"mc":[{"id":"1.258742455","rc":[{"batb":[[0,10.5,15.42]],"atb":[[10.5,15.42]],"id":97736949}]}],"rt":639159131387342939,"dt":639159131387343297}
{"op":"mcm","id":2,"clk":"ANuCAQC0VAD4pgE=","pt":1780316338830,"mc":[{"id":"1.258742455","rc":[{"batb":[[0,4.8,31.82]],"atb":[[4.8,31.82]],"id":99072898},{"batb":[[2,3.45,42.85]],"atb":[[3.4,27.2],[3.45,42.85]],"id":88302242}]}],"rt":639159131388385923,"dt":639159131388386312}
{"op":"mcm","id":2,"clk":"AOCCAQC3VAD8pgE=","pt":1780316338926,"mc":[{"id":"1.258742455","rc":[{"batb":[[0,4.8,35.4]],"atb":[[4.8,35.4]],"id":99072898}]}],"rt":639159131389345605,"dt":639159131389345967}
{"op":"mcm","id":2,"clk":"AOeCAQC\u002BVACMpwE=","pt":1780316339035,"mc":[{"id":"1.258742455","rc":[{"atb":[[2,28.73]],"id":88302242}]}],"rt":639159131390432457,"dt":639159131390432829}
{"op":"mcm","id":2,"clk":"AJmDAQDMVAC1pwE=","pt":1780316339544,"mc":[{"id":"1.258742455","rc":[{"atl":[[5.1,32.97]],"batl":[[2,5.1,32.97]],"id":99072898}]}],"rt":639159131395520077,"dt":639159131395520498}
{"op":"mcm","id":2,"clk":"ALGDAQDVVADRpwE=","pt":1780316339853,"mc":[{"id":"1.258742455","rc":[{"tv":7931.12,"trd":[[4.9,206.23]],"ltp":4.9,"atl":[[4.9,9.54]],"batl":[[0,4.9,9.54]],"id":99072898},{"atb":[[2.98,2.99]],"id":88302242}],"tv":37408.24}],"rt":639159131398613864,"dt":639159131398614288}
{"op":"mcm","id":2,"clk":"ALqDAQDYVADZpwE=","pt":1780316339955,"mc":[{"id":"1.258742455","rc":[{"batb":[],"atb":[[4.4,27.82]],"id":99072898},{"batb":[[2,4.5,133.9]],"atb":[[4.5,133.9]],"id":10398159},{"batb":[[0,3.55,59.19]],"atb":[[3.55,59.19]],"id":88302242}]}],"rt":639159131399632921,"dt":639159131399633376}
{"op":"mcm","id":2,"clk":"AMyDAQDgVADtpwE=","pt":1780316340161,"mc":[{"id":"1.258742455","rc":[{"tv":1113.89,"batb":[[2,19,5.5],[1,19.5,5.13],[0,20,6.9]],"trd":[[21,108]],"ltp":21,"atb":[[21,0]],"id":99072900}],"tv":37413.18}],"rt":639159131401691955,"dt":639159131401692337}
{"op":"mcm","id":2,"clk":"ANWDAQDnVAD3pwE=","pt":1780316340267,"mc":[{"id":"1.258742455","rc":[{"batb":[[2,4.6,72.06],[1,4.7,33.2],[0,4.8,36.49]],"atb":[[4.7,33.2],[4.6,72.06],[4.8,36.49]],"atl":[[4.9,12.44],[5,32.02],[5.1,38.1]],"batl":[[2,5.1,38.1],[1,5,32.02],[0,4.9,12.44]],"id":99072898},{"batb":[[2,42,13.83],[1,44,7.66],[0,46,6.3]],"atb":[[46,6.3],[44,7.66],[42,13.83],[40,7.85]],"atl":[[55,22.4],[50,13.22],[48,3.33]],"batl":[[2,55,22.4],[1,50,13.22],[0,48,3.33]],"id":97008932},{"batb":[[2,19.5,6.7],[1,20,12.13],[0,21,1.53]],"atb":[[21,1.53],[20,12.13],[19.5,6.7]],"atl":[[24,5.14],[23,7.02],[22,8.39]],"batl":[[2,24,5.14],[1,23,7.02],[0,22,8.39]],"id":99072900},{"batb":[[2,75,8.57],[1,80,7.74],[0,85,5.7]],"atb":[[85,5.7],[80,7.74],[75,8.57]],"atl":[[110,5.53],[100,1.17],[95,1.47],[90,0.45]],"batl":[[2,110,5.53],[1,100,1.17],[0,95,1.92]],"id":99072901},{"tv":8400.18,"batb":[[2,4.5,152.34],[1,4.6,91.82],[0,4.7,41.82]],"trd":[[4.7,1002.16]],"atb":[[4.7,41.82],[4.6,91.82],[4.5,152.34]],"atl":[[4.9,54.29],[5,86.36],[4.8,32.24]],"batl":[[2,5,86.36],[1,4.9,54.29],[0,4.8,32.24]],"id":10398159},{"batb":[[2,46,6.36],[1,48,8.85],[0,50,14.28]],"atb":[[50,14.28],[48,8.85],[46,6.36]],"atl":[[60,5.62],[55,9.41]],"batl":[[1,60,5.62],[0,55,9.41]],"id":98464183},{"batb":[[2,8.6,18.22],[1,8.8,17.1],[0,9,33.09]],"atb":[[8.8,17.1],[9.2,0.84],[9,32.25],[8.6,18.22]],"atl":[[9.4,14.8],[9.8,8.6],[10,21.35],[9.6,11.48]],"batl":[[2,9.8,8.6],[1,9.6,11.48],[0,9.4,14.8]],"id":98117699},{"batb":[[2,3.45,61.56],[1,3.5,65.66],[0,3.55,60.42]],"atb":[[3.5,65.66],[3.55,60.42],[3.4,43.25],[3.45,61.56]],"atl":[[3.65,40.85],[3.75,51.05],[3.7,228.59],[3.6,10.31]],"batl":[[2,3.7,228.59],[1,3.65,40.85],[0,3.6,10.31]],"id":88302242},{"batb":[[2,9.8,10.21],[1,10,26.37],[0,10.5,16.99]],"atb":[[9.8,10.21],[10.5,16.99],[10,26.37]],"atl":[[12,17.18],[11.5,14.93],[11,5.57]],"batl":[[2,12,17.18],[1,11.5,14.93],[0,11,5.57]],"id":97736949},{"batb":[[1,150,5.6],[0,160,5.77]],"atb":[[160,5.77],[150,5.6]],"atl":[[200,0.55],[190,0.73],[180,0.57]],"batl":[[2,220,1.13],[1,210,1.3],[0,190,1.3]],"id":99072897}],"tv":37487.2}],"rt":639159131402756158,"dt":639159131402757270}
{"op":"mcm","id":2,"clk":"ANuDAQDrVAD/pwE=","pt":1780316340329,"mc":[{"id":"1.258742455","rc":[{"atb":[[1.01,43889.08]],"id":99072898},{"batb":[],"atb":[[38,19.34]],"id":97008932},{"batb":[],"atb":[[19,10.07]],"id":99072900},{"batb":[],"atb":[[4.1,107.73]],"id":10398159},{"batb":[],"atb":[[40,17.86]],"id":98464183},{"batb":[],"atb":[[3.15,68.53]],"id":88302242},{"batb":[],"atb":[[9,21.67]],"id":97736949},{"batb":[],"atb":[[710,2]],"id":10445502},{"atl":[[1000,10.75]],"batl":[],"id":99072897}]}],"rt":639159131403375113,"dt":639159131403375621}
{"op":"mcm","id":2,"clk":"AN\u002BDAQDuVACHqAE=","pt":1780316340425,"mc":[{"id":"1.258742455","rc":[{"batb":[[0,4.8,37.34]],"atb":[[4.8,37.34]],"id":99072898},{"atl":[[48,1.35]],"batl":[[0,48,1.35]],"id":97008932},{"batb":[[2,19,11.59],[1,19.5,7.39],[0,20,12.13]],"atb":[[1.05,4107.4],[21,0],[19,11.59],[19.5,7.39]],"atl":[[24,6.04]],"batl":[[2,24,6.04]],"id":99072900},{"atl":[[110,6.21],[90,0.19]],"batl":[[2,110,6.21],[0,95,1.66]],"id":99072901},{"batb":[[0,4.7,48]],"atb":[[4.7,48],[4.4,171.13]],"atl":[[5.1,43.43],[4.8,60.47]],"batl":[[0,4.8,60.47]],"id":10398159},{"atl":[[55,10.74]],"batl":[[0,55,10.74]],"id":98464183},{"tv":13089.84,"batb":[[2,3.5,65.66],[1,3.55,61.76],[0,3.6,13.7]],"trd":[[3.6,828.44]],"ltp":3.6,"atb":[[3.55,61.76],[3.6,13.7]],"atl":[[3.6,0]],"batl":[[2,3.75,51.05],[1,3.7,228.59],[0,3.65,40.85]],"id":88302242},{"batb":[[2,9.8,10.84]],"atb":[[9.8,10.84],[9.6,15.03]],"atl":[[12.5,5.74],[12,18.1]],"batl":[[2,12,18.1]],"id":97736949},{"batb":[[2,120,5.31],[0,160,5.79]],"atb":[[170,0.02],[140,0.71]],"id":99072897}],"tv":37507.82}],"rt":639159131404338453,"dt":639159131404339203}
{"op":"mcm","id":2,"clk":"AOKDAQDzVACQqAE=","pt":1780316340528,"mc":[{"id":"1.258742455","rc":[{"tv":13090.82,"batb":[[0,3.6,13.21]],"trd":[[3.6,829.42]],"atb":[[3.6,13.21]],"id":88302242}],"tv":37508.8}],"rt":639159131405362573,"dt":639159131405363091}
{"op":"mcm","id":2,"clk":"AOmDAQD6VACZqAE=","pt":1780316340637,"mc":[{"id":"1.258742455","rc":[{"batb":[[0,4.7,39.51]],"atb":[[4.7,39.51]],"id":10398159},{"batb":[[0,9,32.53]],"atb":[[9.2,0.28]],"atl":[[10,22.17]],"batl":[],"id":98117699},{"atl":[[3.65,41.43],[3.85,29.02]],"batl":[[0,3.65,41.43]],"id":88302242},{"atl":[[1000,9.75],[180,0.06]],"batl":[[2,230,1.09],[1,220,1.88],[0,200,1.34]],"id":99072897}]}],"rt":639159131406448959,"dt":639159131406449467}
{"op":"mcm","id":2,"clk":"AO\u002BDAQD9VACjqAE=","pt":1780316340737,"mc":[{"id":"1.258742455","rc":[{"batb":[[2,19,12.27]],"atb":[[19,12.27]],"id":99072900},{"batb":[],"atb":[[70,6.33]],"atl":[[120,1.48]],"batl":[],"id":99072901},{"batb":[[1,3.55,71.53]],"atb":[[3.55,71.53],[3.35,136.94]],"atl":[[3.75,57.45],[3.8,85.75]],"batl":[[2,3.75,57.45]],"id":88302242},{"batb":[[0,160,6.08]],"atb":[[170,0.31]],"atl":[[1000,8.75]],"batl":[],"id":99072897}]}],"rt":639159131407455168,"dt":639159131407455685}
{"op":"mcm","id":2,"clk":"APSDAQD\u002BVACnqAE=","pt":1780316340836,"mc":[{"id":"1.258742455","rc":[{"atl":[[4.8,63.6]],"batl":[[0,4.8,63.6]],"id":10398159},{"batb":[[2,8.6,19.99]],"atb":[[8.6,19.99]],"id":98117699},{"tv":13091.11,"batb":[[0,3.6,13.07]],"trd":[[3.6,829.71]],"atb":[[3.6,13.07]],"atl":[[3.8,91.75]],"batl":[],"id":88302242},{"atl":[[270,1]],"batl":[],"id":99072897}],"tv":37509.09}],"rt":639159131408444446,"dt":639159131408445022}
{"op":"mcm","id":2,"clk":"APqDAQCAVQCwqAE=","pt":1780316340939,"mc":[{"id":"1.258742455","rc":[{"batb":[],"atb":[[4.5,30.22]],"atl":[[5.2,18.61]],"batl":[],"id":99072898},{"batb":[[0,46,5.98]],"atb":[[46,5.98]],"id":97008932},{"atb":[[1.17,2.39]],"id":99072900},{"batb":[[0,85,6.38]],"atb":[[85,6.38]],"id":99072901},{"batb":[[0,4.7,43.25]],"atb":[[4.7,43.25]],"atl":[[1000,1.79]],"id":10398159},{"batb":[],"atb":[[3.4,49.25]],"id":88302242},{"batb":[],"atb":[[9.6,15.86]],"id":97736949},{"batb":[[0,160,6.51]],"atb":[[160,6.2]],"id":99072897}]}],"rt":639159131409473212,"dt":639159131409473747}
{"op":"mcm","id":2,"clk":"AP2DAQCDVQC3qAE=","pt":1780316341040,"mc":[{"id":"1.258742455","rc":[{"tv":7937.12,"trd":[[4.9,212.23]],"atl":[[4.9,9.44]],"batl":[[0,4.9,9.44]],"id":99072898},{"batb":[[0,46,6.02]],"atb":[[46,6.02]],"id":97008932},{"batb":[],"atb":[[1.17,2],[18.5,2.47]],"id":99072900},{"atl":[[1000,1.01]],"id":10398159},{"batb":[[2,46,8.03]],"atb":[[46,8.03]],"id":98464183},{"batb":[[2,8.6,14.99]],"atb":[[8.6,14.99]],"id":98117699},{"atl":[[3.65,25.04]],"batl":[[0,3.65,25.04]],"id":88302242},{"atl":[[180,0.2]],"batl":[[0,200,1.48]],"id":99072897}],"tv":37515.09}],"rt":639159131410479954,"dt":639159131410480528}
{"op":"mcm","id":2,"clk":"AIKEAQCIVQC/qAE=","pt":1780316341142,"mc":[{"id":"1.258742455","rc":[{"atl":[[5.2,22.46],[4.9,7.9]],"batl":[[0,4.9,7.9]],"id":99072898},{"batb":[[0,20,12.52]],"atb":[[21,0.39]],"id":99072900},{"atl":[[120,1.83]],"batl":[],"id":99072901},{"atl":[[4.9,55.07]],"batl":[[1,4.9,55.07]],"id":10398159},{"batb":[],"atb":[[8.4,6.99]],"id":98117699},{"atl":[[3.65,31.24]],"batl":[[0,3.65,31.24]],"id":88302242}]}],"rt":639159131411503586,"dt":639159131411504078}
{"op":"mcm","id":2,"clk":"AI\u002BEAQCSVQDNqAE=","pt":1780316341352,"mc":[{"id":"1.258742455","rc":[{"batb":[],"atb":[[40,9.4]],"id":97008932},{"batb":[],"atb":[[9.6,16.53]],"id":97736949}]}],"rt":639159131413597547,"dt":639159131413598209}
{"op":"mcm","id":2,"clk":"AJSEAQCVVQDVqAE=","pt":1780316341451,"mc":[{"id":"1.258742455","rc":[{"batb":[[0,85,6.6]],"atb":[[85,6.6],[70,6.9]],"id":99072901},{"tv":8443.43,"batb":[[0,4.7,21.95]],"trd":[[4.7,1045.41]],"atb":[[4.7,21.95]],"id":10398159},{"atl":[[3.8,85.75]],"batl":[],"id":88302242}],"tv":37558.34}],"rt":639159131414593283,"dt":639159131414593760}
{"op":"mcm","id":2,"clk":"AJeEAQCYVQDeqAE=","pt":1780316341553,"mc":[{"id":"1.258742455","rc":[{"batb":[[1,4.7,40.33]],"atb":[[4.7,40.33],[4.4,20.84]],"id":99072898},{"batb":[[0,46,5.98]],"atb":[[46,5.98]],"id":97008932},{"batb":[[2,4.5,144.86],[1,4.6,84.43]],"atb":[[4.4,178.44],[4.6,84.43],[4.5,144.86]],"atl":[[4.8,66.51]],"batl":[[0,4.8,66.51]],"id":10398159},{"batb":[],"atb":[[8.4,10.75]],"id":98117699},{"atl":[[4.1,15.36],[4,7.82]],"batl":[],"id":88302242},{"batb":[[1,10,29.59]],"atb":[[10,29.59]],"id":97736949}]}],"rt":639159131415617513,"dt":639159131415618016}
{"op":"mcm","id":2,"clk":"AJ2EAQCbVQDoqAE=","pt":1780316341658,"mc":[{"id":"1.258742455","rc":[{"batb":[[0,4.7,21.63]],"atb":[[4.7,21.63]],"id":10398159},{"batb":[[0,3.6,14.48]],"atb":[[3.6,14.48]],"atl":[[3.85,35.02]],"batl":[],"id":88302242}]}],"rt":639159131416664962,"dt":639159131416665518}
{"op":"mcm","id":2,"clk":"AKKEAQCeVQDtqAE=","pt":1780316341759,"mc":[{"id":"1.258742455","rc":[{"batb":[[0,46,6.02]],"atb":[[46,6.02]],"id":97008932},{"batb":[],"atb":[[4.4,186.82],[4.3,128.03]],"id":10398159},{"atl":[[180,0.06]],"batl":[[0,200,1.34]],"id":99072897}]}],"rt":639159131417674916,"dt":639159131417675318}
{"op":"mcm","id":2,"clk":"AKmEAQChVQD1qAE=","pt":1780316341864,"mc":[{"id":"1.258742455","rc":[{"batb":[[0,3.6,13.07]],"atb":[[3.6,13.07]],"id":88302242},{"batb":[[0,10.5,17.54]],"atb":[[10.5,17.54]],"id":97736949}]}],"rt":639159131418723673,"dt":639159131418724098}
{"op":"mcm","id":2,"clk":"AK2EAQCjVQD9qAE=","pt":1780316341916,"mc":[{"id":"1.258742455","rc":[{"atl":[[9.4,15.5]],"batl":[[0,9.4,15.5]],"id":98117699},{"atl":[[180,0.07]],"batl":[[0,200,1.35]],"id":99072897}]}],"rt":639159131419246676,"dt":639159131419247043}
{"op":"mcm","id":2,"clk":"AL6EAQCyVQCZqQE=","pt":1780316342226,"mc":[{"id":"1.258742455","rc":[{"atl":[[5.2,32.03],[5.3,27.45]],"batl":[],"id":10398159},{"batb":[],"atb":[[7.8,2.63],[7.6,120.41]],"id":98117699},{"batb":[],"atb":[[3.25,8.66]],"id":88302242},{"batb":[],"atb":[[8.8,7.38],[9.2,2.73],[9,18.4]],"id":97736949}]}],"rt":639159131422338559,"dt":639159131422339142}
{"op":"mcm","id":2,"clk":"AMWEAQC3VQChqQE=","pt":1780316342328,"mc":[{"id":"1.258742455","rc":[{"tv":546.61,"batb":[[0,46,4.02]],"trd":[[46,70.69]],"atb":[[46,4.02]],"id":97008932}],"tv":37562.34}],"rt":639159131423361592,"dt":639159131423362012}
{"op":"mcm","id":2,"clk":"AMiEAQC8VQCqqQE=","pt":1780316342431,"mc":[{"id":"1.258742455","rc":[{"batb":[],"atb":[[4.5,33.3]],"id":99072898},{"batb":[[0,46,4.46]],"atb":[[46,4.46],[38,21.49]],"atl":[[48,2.07]],"batl":[[0,48,2.07]],"id":97008932},{"batb":[[0,4.7,40.53]],"atb":[[4.7,40.53]],"id":10398159}]}],"rt":639159131424388948,"dt":639159131424389462}
{"op":"mcm","id":2,"clk":"AM\u002BEAQC/VQCyqQE=","pt":1780316342536,"mc":[{"id":"1.258742455","rc":[{"batb":[[0,46,6.42]],"atb":[[46,6.42]],"id":97008932},{"tv":8457.04,"batb":[[0,4.7,33.72]],"trd":[[4.7,1059.02]],"atb":[[4.7,33.72]],"id":10398159},{"atl":[[180,0.1]],"batl":[[0,200,1.38]],"id":99072897}],"tv":37575.95}],"rt":639159131425442186,"dt":639159131425442638}
{"op":"mcm","id":2,"clk":"ANOEAQDEVQC/qQE=","pt":1780316342644,"mc":[{"id":"1.258742455","rc":[{"tv":7952.92,"batb":[[2,4.7,40.33],[1,4.8,37.34],[0,4.9,8.66]],"trd":[[4.9,228.03]],"atb":[[4.9,8.66]],"atl":[[4.9,0]],"batl":[[2,5.2,22.46],[1,5.1,38.1],[0,5,32.02]],"id":99072898},{"atl":[[25,4.61]],"batl":[],"id":99072900},{"atl":[[5.1,47.62]],"batl":[],"id":10398159}],"tv":37591.75}],"rt":639159131426519691,"dt":639159131426520205}
{"op":"mcm","id":2,"clk":"ANuEAQDIVQDDqQE=","pt":1780316342745,"mc":[{"id":"1.258742455","rc":[{"tv":7956.56,"batb":[[1,4.8,44.4],[0,4.9,6.84]],"trd":[[4.9,231.67]],"atb":[[4.9,6.84],[4.8,44.4]],"id":99072898},{"batb":[[2,9.8,14.07],[1,10,26.37]],"atb":[[9.8,14.07],[10,26.37]],"id":97736949}],"tv":37595.39}],"rt":639159131427526998,"dt":639159131427527437}
{"op":"mcm","id":2,"clk":"AOSEAQDRVQDNqQE=","pt":1780316342849,"mc":[{"id":"1.258742455","rc":[{"tv":7969.36,"batb":[[2,4.6,72.06],[1,4.7,40.33],[0,4.8,44.84]],"trd":[[4.9,244.47]],"atb":[[4.9,0.44]],"id":99072898}],"tv":37608.19}],"rt":639159131428574069,"dt":639159131428574443}
{"op":"mcm","id":2,"clk":"AOiEAQDRVQDQqQE=","pt":1780316342942,"mc":[{"id":"1.258742455","rc":[{"tv":7970.24,"batb":[[0,4.8,37.34]],"trd":[[4.9,245.35]],"atb":[[4.9,0],[4.8,37.34]],"atl":[[4.9,0.67]],"batl":[[0,5,32.69]],"id":99072898}],"tv":37609.07}],"rt":639159131429505517,"dt":639159131429506069}
{"op":"mcm","id":2,"clk":"AOyEAQDTVQDXqQE=","pt":1780316343042,"mc":[{"id":"1.258742455","rc":[{"batb":[[2,4.6,75.01],[1,4.7,43.08],[0,4.8,41.74]],"atb":[[4.7,43.08],[4.6,75.01],[4.8,41.74]],"atl":[[5.3,18.64],[5.1,40.33]],"batl":[[1,5.1,40.33]],"id":99072898}]}],"rt":639159131430504125,"dt":639159131430504526}
{"op":"mcm","id":2,"clk":"APeEAQDZVQDhqQE=","pt":1780316343151,"mc":[{"id":"1.258742455","rc":[{"atl":[[5.3,12.64]],"batl":[],"id":99072898},{"batb":[],"atb":[[8.4,12.43]],"id":98117699},{"batb":[[0,10.5,18.25]],"atb":[[10.5,18.25]],"id":97736949}]}],"rt":639159131431593391,"dt":639159131431593881}
{"op":"mcm","id":2,"clk":"APiEAQDaVQDkqQE=","pt":1780316343250,"mc":[{"id":"1.258742455","rc":[{"tv":2428.86,"trd":[[11,89.42]],"ltp":11,"atl":[[11,5.39]],"batl":[[0,11,5.39]],"id":97736949}],"tv":37609.42}],"rt":639159131432580768,"dt":639159131432581246}
{"op":"mcm","id":2,"clk":"AIGFAQDgVQDqqQE=","pt":1780316343352,"mc":[{"id":"1.258742455","rc":[{"batb":[[0,50,14.38]],"atb":[[50,14.38]],"id":98464183}]}],"rt":639159131433600104,"dt":639159131433600523}
{"op":"mcm","id":2,"clk":"AIeFAQDkVQDyqQE=","pt":1780316343455,"mc":[{"id":"1.258742455","rc":[{"atl":[[5.4,32.52]],"batl":[],"id":99072898}]}],"rt":639159131434629816,"dt":639159131434630356}
{"op":"mcm","id":2,"clk":"AJeFAQDwVQCAqgE=","pt":1780316343664,"mc":[{"id":"1.258742455","rc":[{"batb":[[0,4.8,43.42]],"atb":[[4.8,43.42]],"id":99072898},{"atl":[[1000,0.36]],"id":97008932},{"atl":[[22,8.02]],"batl":[[0,22,8.02]],"id":99072900},{"batb":[[0,4.7,30.94]],"atb":[[4.7,30.94],[4.4,192.07]],"atl":[[5,90.98]],"batl":[[2,5,90.98]],"id":10398159},{"batb":[[1,3.55,63.71]],"atb":[[3.55,63.71]],"id":88302242},{"batb":[[0,160,6.19]],"atb":[[170,0.42],[160,5.77]],"id":99072897}]}],"rt":639159131436719135,"dt":639159131436719784}
{"op":"mcm","id":2,"clk":"AKGFAQD1VQCEqgE=","pt":1780316343711,"mc":[{"id":"1.258742455","rc":[{"atl":[[1000,0.22]],"id":97008932}]}],"rt":639159131437193940,"dt":639159131437194280}
{"op":"mcm","id":2,"clk":"AK2FAQD9VQCLqgE=","pt":1780316343819,"mc":[{"id":"1.258742455","rc":[{"atl":[[48,2.21]],"batl":[[0,48,2.21]],"id":97008932},{"batb":[[0,20,12.58]],"atb":[[21,0.45]],"id":99072900},{"batb":[[0,10.5,20.16]],"atb":[[10.5,20.16]],"id":97736949}]}],"rt":639159131438269570,"dt":639159131438269972}
{"op":"mcm","id":2,"clk":"ALmFAQCDVgCRqgE=","pt":1780316343923,"mc":[{"id":"1.258742455","rc":[{"tv":2429.79,"trd":[[11,90.35]],"atl":[[11,4.93]],"batl":[[0,11,4.93]],"id":97736949}],"tv":37610.35}],"rt":639159131439310666,"dt":639159131439311069}
{"op":"mcm","id":2,"clk":"AL\u002BFAQCHVgCVqgE=","pt":1780316344022,"mc":[{"id":"1.258742455","rc":[{"atl":[[12.5,7.1]],"batl":[],"id":97736949}]}],"rt":639159131440303923,"dt":639159131440304274}
{"op":"mcm","id":2,"clk":"AMeFAQCLVgCdqgE=","pt":1780316344127,"mc":[{"id":"1.258742455","rc":[{"atl":[[11,3.58]],"batl":[[0,11,3.58]],"id":97736949}]}],"rt":639159131441354443,"dt":639159131441354806}
{"op":"mcm","id":2,"clk":"AM2FAQCQVgCnqgE=","pt":1780316344247,"mc":[{"id":"1.258742455","rc":[{"batb":[[0,4.7,12.04]],"atb":[[4.7,12.04]],"id":10398159},{"batb":[[0,10.5,27.34]],"atb":[[10.5,27.34]],"id":97736949}]}],"rt":639159131442551017,"dt":639159131442551492}
{"op":"mcm","id":2,"clk":"ANeFAQCTVgCsqgE=","pt":1780316344335,"mc":[{"id":"1.258742455","rc":[{"batb":[[0,20,12.52]],"atb":[[21,0.39]],"id":99072900},{"atl":[[11,4.23]],"batl":[[0,11,4.23]],"id":97736949}]}],"rt":639159131443435000,"dt":639159131443435488}
{"op":"mcm","id":2,"clk":"ANyFAQCWVgCyqgE=","pt":1780316344437,"mc":[{"id":"1.258742455","rc":[{"atl":[[5,28.02],[5.1,38.33]],"batl":[[1,5.1,38.33],[0,5,28.69]],"id":99072898},{"batb":[[0,20,12.61]],"atb":[[21,0.48]],"id":99072900}]}],"rt":639159131444451233,"dt":639159131444451592}
{"op":"mcm","id":2,"clk":"AOuFAQCiVgDEqgE=","pt":1780316344653,"mc":[{"id":"1.258742455","rc":[{"tv":7971.58,"batb":[[2,4.7,43.08],[1,4.8,43.42],[0,4.9,7.41]],"trd":[[4.9,246.69]],"atb":[[4.9,7.41]],"atl":[[4.9,0]],"batl":[[0,5,28.02]],"id":99072898},{"batb":[[0,20,12.52]],"atb":[[21,0.39]],"id":99072900}],"tv":37611.69}],"rt":639159131446610576,"dt":639159131446611175}
{"op":"mcm","id":2,"clk":"APCFAQCoVgDLqgE=","pt":1780316344750,"mc":[{"id":"1.258742455","rc":[{"batb":[[1,4.8,50.46]],"atb":[[4.8,50.46]],"id":99072898}]}],"rt":639159131447580855,"dt":639159131447581331}
{"op":"mcm","id":2,"clk":"APaFAQCtVgDdqgE=","pt":1780316344952,"mc":[{"id":"1.258742455","rc":[{"batb":[[0,4.9,7.87]],"atb":[[4.4,14.84],[4.9,7.87]],"id":99072898}]}],"rt":639159131449607768,"dt":639159131449608198}
{"op":"mcm","id":2,"clk":"AIOGAQC1VgD0qgE=","pt":1780316345261,"mc":[{"id":"1.258742455","rc":[{"batb":[[0,4.9,8.3]],"atb":[[4.9,8.3],[4.5,39.3]],"id":99072898},{"tv":8459.04,"batb":[[0,4.7,11.04]],"trd":[[4.7,1061.02]],"atb":[[4.7,11.04]],"id":10398159}],"tv":37613.69}],"rt":639159131452691593,"dt":639159131452692291}
{"op":"mcm","id":2,"clk":"AIuGAQDEVgCAqwE=","pt":1780316345468,"mc":[{"id":"1.258742455","rc":[{"atl":[[60,3.48]],"batl":[],"id":97008932},{"tv":1114.67,"batb":[[0,20,12.13]],"trd":[[21,108.78]],"atb":[[21,0]],"atl":[[21,0.61]],"batl":[[0,22,8.63]],"id":99072900},{"batb":[[0,10.5,28.04]],"atb":[[10.5,28.04]],"id":97736949},{"batb":[],"atb":[[710,0],[680,2.18]],"id":10445502}],"tv":37614.47}],"rt":639159131454759903,"dt":639159131454760474}
{"op":"mcm","id":2,"clk":"AI6GAQDGVgCJqwE=","pt":1780316345519,"mc":[{"id":"1.258742455","rc":[{"tv":1115.89,"trd":[[21,110]],"atl":[[21,0]],"batl":[[0,22,8.02]],"id":99072900},{"batb":[[0,85,6.72]],"atb":[[85,6.72]],"id":99072901},{"batb":[[0,9,33.62]],"atb":[[9,33.34]],"id":98117699},{"batb":[[0,3.6,14.35]],"atb":[[3.6,14.35]],"id":88302242}],"tv":37615.69}],"rt":639159131455276637,"dt":639159131455277249}
{"op":"mcm","id":2,"clk":"AJWGAQDLVgCQqwE=","pt":1780316345630,"mc":[{"id":"1.258742455","rc":[{"atl":[[50,13.92]],"batl":[[1,50,13.92]],"id":97008932},{"batb":[[0,20,6.9]],"atb":[[20,6.9],[18.5,4.1]],"atl":[[22,8.4],[21,0.35]],"batl":[[0,22,8.75]],"id":99072900},{"tv":8461.04,"batb":[[0,4.7,10.04]],"trd":[[4.7,1063.02]],"atb":[[4.7,10.04]],"id":10398159},{"tv":2432.14,"trd":[[11,92.7]],"atl":[[11,3.06]],"batl":[[0,11,3.06]],"id":97736949}],"tv":37620.04}],"rt":639159131456377302,"dt":639159131456377919}
{"op":"mcm","id":2,"clk":"AJqGAQDPVgCVqwE=","pt":1780316345722,"mc":[{"id":"1.258742455","rc":[{"batb":[[1,4.8,51.46]],"atb":[[4.8,51.46]],"id":99072898},{"batb":[[2,4.4,192.07],[1,4.5,148.86],[0,4.6,85.39]],"atb":[[4.7,0.96],[4.5,148.86]],"id":10398159},{"batb":[[0,10.5,29.93]],"atb":[[10.5,29.93]],"atl":[[13,11.86],[11,2.41]],"batl":[[0,11,2.41]],"id":97736949}]}],"rt":639159131457308223,"dt":639159131457308716}
{"op":"mcm","id":2,"clk":"AJ\u002BGAQDTVgCcqwE=","pt":1780316345831,"mc":[{"id":"1.258742455","rc":[{"batb":[],"atb":[[44,5.46]],"atl":[[65,23.99]],"batl":[[2,65,23.99]],"id":98464183},{"batb":[[1,10,29.59]],"atb":[[10,29.59]],"id":97736949}]}],"rt":639159131458390830,"dt":639159131458391259}
{"op":"mcm","id":2,"clk":"AKOGAQDWVgCjqwE=","pt":1780316345935,"mc":[{"id":"1.258742455","rc":[{"batb":[[2,42,14.67]],"atb":[[42,14.67]],"id":97008932},{"batb":[[0,20,8.76]],"atb":[[20,8.76]],"id":99072900},{"batb":[[0,85,7.73]],"atb":[[85,7.73]],"id":99072901}]}],"rt":639159131459435530,"dt":639159131459436080}
{"op":"mcm","id":2,"clk":"AKaGAQDbVgCsqwE=","pt":1780316346035,"mc":[{"id":"1.258742455","rc":[{"tv":13112.63,"batb":[[0,3.6,3.59]],"trd":[[3.6,851.23]],"atb":[[3.6,3.59]],"id":88302242},{"tv":2433.09,"batb":[[1,10,26.37]],"trd":[[11,93.65]],"atb":[[10,26.37]],"atl":[[11,1.93]],"batl":[[0,11,1.93]],"id":97736949}],"tv":37642.51}],"rt":639159131460435540,"dt":639159131460435988}
{"op":"mcm","id":2,"clk":"AKuGAQDdVgCzqwE=","pt":1780316346142,"mc":[{"id":"1.258742455","rc":[{"tv":7988.32,"batb":[[0,4.9,2.76]],"trd":[[4.9,259.15],[5,201.88]],"ltp":5,"atb":[[4.9,2.76]],"atl":[[5,25.88]],"batl":[[0,5,25.88]],"id":99072898},{"tv":387.24,"trd":[[90,33.57]],"ltp":90,"atl":[[95,0.63],[90,0.1]],"batl":[[2,120,1.83],[1,110,6.21],[0,100,1.9]],"id":99072901},{"batb":[[0,3.6,1.28]],"atb":[[3.6,1.28]],"atl":[[3.65,36.46]],"batl":[[0,3.65,36.46]],"id":88302242},{"batb":[[0,10.5,30.98]],"atb":[[10.5,30.98]],"atl":[[13,12.57]],"batl":[],"id":97736949},{"atl":[[180,0.07]],"batl":[[0,200,1.35]],"id":99072897}],"tv":37659.43}],"rt":639159131461503753,"dt":639159131461504286}
{"op":"mcm","id":2,"clk":"ALKGAQDhVgDAqwE=","pt":1780316346241,"mc":[{"id":"1.258742455","rc":[{"atl":[[5,31.88]],"batl":[[0,5,31.88]],"id":99072898},{"atl":[[21,0]],"batl":[[0,22,8.4]],"id":99072900},{"tv":387.43,"batb":[[0,85,7.83]],"trd":[[90,33.76]],"atb":[[90,0.1]],"atl":[[90,0],[130,1.62]],"batl":[[0,100,1.8]],"id":99072901},{"batb":[],"atb":[[4.3,122.03]],"id":10398159},{"tv":13115.19,"batb":[[2,3.45,61.56],[1,3.5,65.66],[0,3.55,63.71]],"trd":[[3.6,853.79]],"atb":[[1.01,54778.82],[3.6,0]],"atl":[[3.65,42.46],[3.6,2.31]],"batl":[[2,3.7,228.59],[1,3.65,42.46],[0,3.6,2.31]],"id":88302242},{"batb":[[1,10,29.59]],"atb":[[10,29.59]],"id":97736949},{"atl":[[180,0.06]],"batl":[[0,200,1.34]],"id":99072897}],"tv":37662.18}],"rt":639159131462493146,"dt":639159131462493761}
{"op":"mcm","id":2,"clk":"ALiGAQDkVgDGqwE=","pt":1780316346346,"mc":[{"id":"1.258742455","rc":[{"atl":[[22,5.9]],"batl":[[0,22,5.9]],"id":99072900},{"batb":[[0,85,7.73]],"atb":[[90,0]],"id":99072901}]}],"rt":639159131463540365,"dt":639159131463540727}
{"op":"mcm","id":2,"clk":"AL6GAQDmVgDOqwE=","pt":1780316346444,"mc":[{"id":"1.258742455","rc":[{"batb":[[0,4.9,2.33]],"atb":[[4.9,2.33],[1.01,46319.08]],"id":99072898},{"batb":[],"atb":[[40,10.28]],"id":97008932},{"batb":[[0,20,9.82]],"atb":[[20,9.82]],"id":99072900},{"atl":[[95,0.17]],"batl":[[0,100,1.34]],"id":99072901},{"batb":[],"atb":[[4.2,22.63]],"id":10398159},{"batb":[[0,3.55,46.01]],"atb":[[3.55,46.01]],"id":88302242}]}],"rt":639159131464525909,"dt":639159131464526522}
{"op":"mcm","id":2,"clk":"AMiGAQDqVgDXqwE=","pt":1780316346551,"mc":[{"id":"1.258742455","rc":[{"atl":[[95,0.57]],"batl":[[0,100,1.74]],"id":99072901},{"batb":[[0,10.5,31.54]],"atb":[[10.5,31.54]],"id":97736949}]}],"rt":639159131465598763,"dt":639159131465599303}
{"op":"mcm","id":2,"clk":"AMuGAQDqVgDiqwE=","pt":1780316346651,"mc":[{"id":"1.258742455","rc":[{"batb":[[2,4.7,45.33]],"atb":[[4.7,45.33]],"atl":[[1000,6.48]],"id":99072898},{"atl":[[95,0.17]],"batl":[[0,100,1.34]],"id":99072901},{"batb":[],"atb":[[3.4,43.25]],"atl":[[3.6,0]],"batl":[[2,3.75,57.45],[1,3.7,228.59],[0,3.65,42.46]],"id":88302242}]}],"rt":639159131466594180,"dt":639159131466594776}
{"op":"mcm","id":2,"clk":"ANCGAQDtVgDoqwE=","pt":1780316346750,"mc":[{"id":"1.258742455","rc":[{"atl":[[1000,6.25]],"id":99072898},{"atl":[[3.85,29.02]],"batl":[],"id":88302242}]}],"rt":639159131467582276,"dt":639159131467582681}
{"op":"mcm","id":2,"clk":"ANaGAQDwVgDwqwE=","pt":1780316346859,"mc":[{"id":"1.258742455","rc":[{"tv":7988.78,"batb":[[2,4.6,75.01],[1,4.7,45.33],[0,4.8,52.41]],"trd":[[4.9,259.61]],"ltp":4.9,"atb":[[4.9,0.95]],"id":99072898},{"atl":[[95,0.4]],"batl":[[0,100,1.57]],"id":99072901},{"batb":[],"atb":[[3.35,142.94]],"id":88302242}],"tv":37662.64}],"rt":639159131468672865,"dt":639159131468673415}
{"op":"mcm","id":2,"clk":"ANuGAQD1VgD5qwE=","pt":1780316346962,"mc":[{"id":"1.258742455","rc":[{"atl":[[3.8,91.75]],"batl":[],"id":88302242}]}],"rt":639159131469702675,"dt":639159131469703134}
{"op":"mcm","id":2,"clk":"AOiGAQD7VgCMrAE=","pt":1780316347163,"mc":[{"id":"1.258742455","rc":[{"atl":[[3.6,1]],"batl":[[2,3.7,228.59],[1,3.65,42.46],[0,3.6,1]],"id":88302242}]}],"rt":639159131471709951,"dt":639159131471710369}
{"op":"mcm","id":2,"clk":"APOGAQCEVwCarAE=","pt":1780316347315,"mc":[{"id":"1.258742455","rc":[{"batb":[],"atb":[[4.5,33.3]],"id":99072898},{"batb":[[0,85,7.75]],"atb":[[90,0.02]],"id":99072901}]}],"rt":639159131473234372,"dt":639159131473234768}
{"op":"mcm","id":2,"clk":"APWGAQCGVwCkrAE=","pt":1780316347425,"mc":[{"id":"1.258742455","rc":[{"tv":1119.39,"batb":[[0,20,11.57]],"trd":[[22,104.5]],"ltp":22,"atb":[[20,11.57]],"atl":[[22,4.15]],"batl":[[0,22,4.15]],"id":99072900},{"atl":[[95,0.17]],"batl":[[0,100,1.34]],"id":99072901},{"atl":[[9.4,17.5]],"batl":[[0,9.4,17.5]],"id":98117699},{"atl":[[190,0.63]],"batl":[[0,200,1.24]],"id":99072897}],"tv":37666.14}],"rt":639159131474326078,"dt":639159131474326539}
{"op":"mcm","id":2,"clk":"AP6GAQCJVwCrrAE=","pt":1780316347523,"mc":[{"id":"1.258742455","rc":[{"batb":[],"atb":[[4.4,20.84]],"id":99072898},{"batb":[[0,20,11.9]],"atb":[[21,0.33]],"atl":[[25,5.9]],"batl":[],"id":99072900},{"batb":[[0,85,8.02]],"atb":[[90,0.29]],"atl":[[95,0.23]],"batl":[[0,100,1.4]],"id":99072901},{"atl":[[3.6,1.47]],"batl":[[0,3.6,1.47]],"id":88302242},{"batb":[[1,10,30.17]],"atb":[[10,30.17]],"id":97736949}]}],"rt":639159131475312801,"dt":639159131475313334}
{"op":"mcm","id":2,"clk":"AIWHAQCNVwCxrAE=","pt":1780316347629,"mc":[{"id":"1.258742455","rc":[{"batb":[],"atb":[[15.5,1.59]],"atl":[[22,2.37]],"batl":[[0,22,2.37]],"id":99072900}]}],"rt":639159131476375117,"dt":639159131476375487}
{"op":"mcm","id":2,"clk":"AIuHAQCRVwC4rAE=","pt":1780316347733,"mc":[{"id":"1.258742455","rc":[{"atl":[[3.6,1]],"batl":[[0,3.6,1]],"id":88302242}]}],"rt":639159131477417566,"dt":639159131477417963}
{"op":"mcm","id":2,"clk":"AJGHAQCYVwDErAE=","pt":1780316347837,"mc":[{"id":"1.258742455","rc":[{"batb":[[0,20,12.12]],"atb":[[21,0.55]],"atl":[[22,3.59]],"batl":[[0,22,3.59]],"id":99072900},{"atl":[[95,0.27]],"batl":[[0,100,1.44]],"id":99072901}]}],"rt":639159131478452854,"dt":639159131478453324}
{"op":"mcm","id":2,"clk":"AJ2HAQCgVwDKrAE=","pt":1780316347941,"mc":[{"id":"1.258742455","rc":[{"batb":[[2,19.5,7.39],[1,20,11.57],[0,21,2.06]],"atb":[[21,2.06]],"id":99072900}]}],"rt":639159131479489273,"dt":639159131479489705}
{"op":"mcm","id":2,"clk":"AKCHAQCiVwDSrAE=","pt":1780316348044,"mc":[{"id":"1.258742455","rc":[{"batb":[[0,4.8,45.37]],"atb":[[4.8,44.42]],"id":99072898},{"tv":884.61,"batb":[[0,50,10.05]],"trd":[[50,139.29]],"atb":[[50,10.05]],"id":98464183}],"tv":37674.79}],"rt":639159131480519769,"dt":639159131480520320}
{"op":"mcm","id":2,"clk":"AKmHAQCqVwDdrAE=","pt":1780316348147,"mc":[{"id":"1.258742455","rc":[{"batb":[[2,3.45,65.38]],"atb":[[3.45,65.38]],"id":88302242}]}],"rt":639159131481557725,"dt":639159131481558177}
{"op":"mcm","id":2,"clk":"AK2HAQCxVwDorAE=","pt":1780316348249,"mc":[{"id":"1.258742455","rc":[{"batb":[[0,4.8,52.43]],"atb":[[4.8,51.48]],"id":99072898},{"batb":[],"atb":[[44,8]],"atl":[[65,25.59]],"batl":[[2,65,25.59]],"id":98464183},{"batb":[],"atb":[[9.2,4.72]],"id":97736949}]}],"rt":639159131482573407,"dt":639159131482574012}
{"op":"mcm","id":2,"clk":"AMuHAQDJVwCLrQE=","pt":1780316348656,"mc":[{"id":"1.258742455","rc":[{"batb":[[2,3.45,76.63],[1,3.5,76.91]],"atb":[[3.5,76.91],[3.4,54.5],[3.35,154.19],[3.45,76.63]],"id":88302242}]}],"rt":639159131486644914,"dt":639159131486645361}
{"op":"mcm","id":2,"clk":"ANWHAQDNVwCRrQE=","pt":1780316348758,"mc":[{"id":"1.258742455","rc":[{"tv":7990.68,"batb":[[0,4.8,51.48]],"trd":[[4.9,261.51]],"atb":[[4.9,0]],"atl":[[4.9,0.78]],"batl":[[0,5,32.66]],"id":99072898}],"tv":37676.69}],"rt":639159131487663911,"dt":639159131487664383}
{"op":"mcm","id":2,"clk":"AN\u002BHAQDXVwCdrQE=","pt":1780316348965,"mc":[{"id":"1.258742455","rc":[{"atl":[[95,0.32]],"batl":[[0,100,1.49]],"id":99072901}]}],"rt":639159131489735531,"dt":639159131489735919}
{"op":"mcm","id":2,"clk":"AO2HAQDhVwC0rQE=","pt":1780316349270,"mc":[{"id":"1.258742455","rc":[{"atb":[[1.17,2.15]],"atl":[[50,13.82]],"batl":[[1,50,13.82]],"id":97008932},{"batb":[[0,85,7.34]],"atb":[[1.17,1.1],[85,7.05]],"id":99072901},{"batb":[[0,4.6,84.43]],"atb":[[4.7,0]],"atl":[[4.9,54.29]],"batl":[[1,4.9,54.29]],"id":10398159},{"batb":[[2,8.8,17.1],[1,9,33.34],[0,9.2,2.16]],"atb":[[9.2,2.16]],"atl":[[9.4,12.35]],"batl":[[0,9.4,12.35]],"id":98117699}]}],"rt":639159131492780368,"dt":639159131492780906}
{"op":"mcm","id":2,"clk":"APSHAQDnVwDCrQE=","pt":1780316349427,"mc":[{"id":"1.258742455","rc":[{"batb":[[0,4.8,52.7]],"atb":[[4.8,52.7]],"id":99072898},{"batb":[[0,46,6.66]],"atb":[[1.17,2],[46,6.66],[38,22.45]],"atl":[[55,23.06]],"batl":[[2,55,23.06]],"id":97008932},{"batb":[[0,21,2.59]],"atb":[[21,2.59]],"id":99072900},{"atb":[[1.17,1]],"id":99072901},{"batb":[[0,4.6,85.7]],"atb":[[4.6,85.7]],"atl":[[5,290.98]],"batl":[[2,5,290.98]],"id":10398159},{"batb":[[0,50,10.27]],"atb":[[50,10.27]],"id":98464183},{"batb":[],"atb":[[3.35,158.14]],"atl":[[3.8,95.22]],"batl":[],"id":88302242},{"tv":2437.09,"batb":[[0,10.5,30.6]],"trd":[[10.5,152.04]],"ltp":10.5,"atb":[[10.5,30.6]],"id":97736949},{"batb":[[0,160,6.26]],"atb":[[160,5.84]],"id":99072897}],"tv":37680.69}],"rt":639159131494365561,"dt":639159131494366427}
{"op":"mcm","id":2,"clk":"APuHAQDpVwDHrQE=","pt":1780316349531,"mc":[{"id":"1.258742455","rc":[{"tv":546.91,"trd":[[48,44.62]],"ltp":48,"atl":[[48,2.05]],"batl":[[0,48,2.05]],"id":97008932},{"batb":[[0,21,6.31]],"atb":[[21,6.31]],"id":99072900},{"batb":[[0,85,7.44]],"atb":[[90,0.39]],"id":99072901},{"batb":[[2,4.4,184.06],[0,4.6,68.5]],"atb":[[4.4,184.06],[4.6,68.5]],"atl":[[4.7,1.62],[4.8,71.97]],"batl":[[2,4.9,54.29],[1,4.8,71.97],[0,4.7,1.62]],"id":10398159},{"batb":[],"atb":[[8.2,9.55]],"id":98117699},{"batb":[[0,10.5,23.42]],"atb":[[10.5,23.42]],"id":97736949}],"tv":37680.99}],"rt":639159131495394688,"dt":639159131495395432}
{"op":"mcm","id":2,"clk":"AIGIAQDxVwDPrQE=","pt":1780316349634,"mc":[{"id":"1.258742455","rc":[{"tv":549.13,"trd":[[48,46.84]],"atl":[[48,0.94]],"batl":[[2,60,3.48],[1,55,23.06],[0,50,14.76]],"id":97008932},{"batb":[[0,21,6.69]],"atb":[[21,6.69]],"id":99072900},{"atl":[[11,2]],"batl":[[0,11,2]],"id":97736949}],"tv":37683.21}],"rt":639159131496422970,"dt":639159131496423444}
{"op":"mcm","id":2,"clk":"AIiIAQD2VwDXrQE=","pt":1780316349737,"mc":[{"id":"1.258742455","rc":[{"batb":[[0,46,9.57]],"atb":[[46,9.57]],"atl":[[60,5.2],[50,13.69]],"batl":[[2,60,5.2],[0,50,14.63]],"id":97008932},{"tv":8475.04,"trd":[[4.7,1066.26],[4.8,503.53]],"ltp":4.8,"atl":[[4.7,0],[4.8,66.59]],"batl":[[2,5,290.98],[1,4.9,54.29],[0,4.8,66.59]],"id":10398159},{"batb":[[0,3.55,63.73]],"atb":[[3.55,63.73]],"id":88302242}],"tv":37697.21}],"rt":639159131497450943,"dt":639159131497451556}
{"op":"mcm","id":2,"clk":"AIuIAQD6VwDkrQE=","pt":1780316349840,"mc":[{"id":"1.258742455","rc":[{"tv":8478.6,"batb":[[0,4.6,72.59]],"trd":[[4.7,1069.82]],"ltp":4.7,"atb":[[4.6,72.59]],"atl":[[4.7,25.87]],"batl":[[2,4.9,54.29],[1,4.8,66.59],[0,4.7,25.87]],"id":10398159},{"batb":[],"atb":[[8.4,18.43]],"id":98117699}],"tv":37700.77}],"rt":639159131498476325,"dt":639159131498476923}
{"op":"mcm","id":2,"clk":"AJGIAQCAWADwrQE=","pt":1780316349944,"mc":[{"id":"1.258742455","rc":[{"atl":[[48,0.14]],"batl":[[0,50,13.83]],"id":97008932},{"tv":8519.65,"batb":[[2,4.4,182.28]],"trd":[[4.7,1110.87]],"atb":[[4.4,182.28]],"atl":[[4.7,8.28]],"batl":[[0,4.7,8.28]],"id":10398159},{"batb":[],"atb":[[3.4,58.52]],"atl":[[3.85,32.59]],"batl":[],"id":88302242},{"atl":[[11,2.29]],"batl":[[0,11,2.29]],"id":97736949}],"tv":37741.82}],"rt":639159131499523568,"dt":639159131499524127}
{"op":"mcm","id":2,"clk":"AJaIAQCCWAD8rQE=","pt":1780316350050,"mc":[{"id":"1.258742455","rc":[{"batb":[[0,46,10.31]],"atb":[[46,10.31]],"id":97008932},{"tv":8536.2,"batb":[[2,4.5,148.86],[1,4.6,72.59],[0,4.7,6.52]],"trd":[[4.7,1127.42]],"atb":[[4.7,6.52],[4.3,128.22]],"atl":[[4.7,0],[5.1,52.83]],"batl":[[2,5,290.98],[1,4.9,54.29],[0,4.8,66.59]],"id":10398159}],"tv":37758.37}],"rt":639159131500582291,"dt":639159131500582741}
{"op":"mcm","id":2,"clk":"AJyIAQCHWACArgE=","pt":1780316350153,"mc":[{"id":"1.258742455","rc":[{"batb":[[0,4.8,45.64]],"atb":[[4.8,45.64]],"id":99072898},{"batb":[[1,4.6,84.85],[0,4.7,33.59]],"atb":[[4.7,33.59],[4.6,84.85]],"id":10398159},{"atl":[[4,11.64]],"batl":[],"id":88302242},{"batb":[[1,10,26.96]],"atb":[[10,26.96]],"id":97736949}]}],"rt":639159131501614037,"dt":639159131501614513}
{"op":"mcm","id":2,"clk":"AKOIAQCKWACFrgE=","pt":1780316350249,"mc":[{"id":"1.258742455","rc":[{"atl":[[1000,6.35]],"id":99072898},{"atl":[[95,0.4]],"batl":[[0,100,1.57]],"id":99072901},{"tv":8538.68,"batb":[[0,4.7,32.35]],"trd":[[4.7,1129.9]],"atb":[[4.7,32.35]],"id":10398159},{"batb":[],"atb":[[8.4,14.67]],"id":98117699},{"tv":2452.93,"batb":[[0,10.5,15.49]],"trd":[[10.5,167.88]],"atb":[[10.5,15.49]],"id":97736949}],"tv":37776.69}],"rt":639159131502569977,"dt":639159131502570450}
{"op":"mcm","id":2,"clk":"AKqIAQCOWACRrgE=","pt":1780316350354,"mc":[{"id":"1.258742455","rc":[{"atl":[[4.9,1.04]],"batl":[[2,5.1,38.33],[1,5,31.88],[0,4.9,1.04]],"id":99072898},{"atl":[[48,0.72]],"batl":[[0,50,14.41]],"id":97008932},{"batb":[[0,85,7.17]],"atb":[[90,0.12]],"id":99072901},{"batb":[],"atb":[[4.2,16.63]],"id":10398159},{"atb":[[20,22.99]],"id":98464183},{"atl":[[11,2.77]],"batl":[[0,11,2.77]],"id":97736949}]}],"rt":639159131503619896,"dt":639159131503620452}
{"op":"mcm","id":2,"clk":"ALKIAQCRWACergE=","pt":1780316350454,"mc":[{"id":"1.258742455","rc":[{"atl":[[4.9,0.78]],"batl":[[2,5.2,22.46],[1,5.1,38.33],[0,5,32.66]],"id":99072898},{"batb":[[1,4.6,89.55]],"atb":[[4.6,89.55]],"id":10398159},{"batb":[],"atb":[[8.4,18.42]],"id":98117699},{"batb":[[1,10,33.37],[0,10.5,15.6]],"atb":[[10.5,15.6],[10,33.37]],"id":97736949}]}],"rt":639159131504626117,"dt":639159131504626566}
{"op":"mcm","id":2,"clk":"ALuIAQCVWACorgE=","pt":1780316350562,"mc":[{"id":"1.258742455","rc":[{"tv":8007.97,"batb":[[0,4.8,37]],"trd":[[4.8,233.11]],"ltp":4.8,"atb":[[4.8,37]],"id":99072898},{"batb":[[0,85,7.26]],"atb":[[90,0.21]],"id":99072901},{"batb":[],"atb":[[4.2,22.97],[4.3,134.22]],"atl":[[5.2,37.15]],"batl":[],"id":10398159},{"batb":[],"atb":[[8.4,14.67]],"id":98117699},{"batb":[[0,10.5,16.15]],"atb":[[10.5,16.15]],"atl":[[11,3.49]],"batl":[[0,11,3.49]],"id":97736949},{"batb":[],"atb":[[680,0.18],[670,2]],"id":10445502}],"tv":37793.98}],"rt":639159131505704884,"dt":639159131505705506}
{"op":"mcm","id":2,"clk":"AMGIAQCaWACwrgE=","pt":1780316350664,"mc":[{"id":"1.258742455","rc":[{"atl":[[5.4,26.52]],"batl":[],"id":99072898},{"batb":[[0,4.7,27.07]],"atb":[[4.7,27.07]],"id":10398159}]}],"rt":639159131506719233,"dt":639159131506719654}
{"op":"mcm","id":2,"clk":"AMeIAQCgWAC4rgE=","pt":1780316350764,"mc":[{"id":"1.258742455","rc":[{"batb":[[0,4.8,36.15]],"atb":[[4.8,36.15]],"atl":[[1000,6.25],[4.9,11.36]],"batl":[[2,5.1,38.33],[1,5,31.88],[0,4.9,11.36]],"id":99072898}]}],"rt":639159131507719445,"dt":639159131507719797}
{"op":"mcm","id":2,"clk":"AMyIAQCjWADFrgE=","pt":1780316350868,"mc":[{"id":"1.258742455","rc":[{"atl":[[5.3,18.64],[5.1,38.42]],"batl":[[2,5.1,38.42]],"id":99072898},{"batb":[],"atb":[[8.4,18.42]],"id":98117699},{"batb":[[0,10.5,16.71]],"atb":[[10.5,16.71]],"id":97736949}]}],"rt":639159131508759110,"dt":639159131508759505}
{"op":"mcm","id":2,"clk":"AM\u002BIAQCmWADOrgE=","pt":1780316350966,"mc":[{"id":"1.258742455","rc":[{"batb":[[0,4.8,30.75]],"atb":[[4.8,30.75]],"id":99072898}]}],"rt":639159131509744796,"dt":639159131509745320}
{"op":"mcm","id":2,"clk":"ANSIAQCpWADTrgE=","pt":1780316351021,"mc":[{"id":"1.258742455","rc":[{"batb":[],"atb":[[36,4.06]],"atl":[[60,5.83]],"batl":[[2,60,5.83]],"id":97008932},{"batb":[],"atb":[[3.95,58.48]],"atl":[[1000,1.11],[5.3,32.25]],"batl":[],"id":10398159},{"atl":[[9.4,10.35],[1000,6.35]],"batl":[[0,9.4,10.35]],"id":98117699},{"batb":[],"atb":[[3.3,20.21]],"atl":[[1000,3.1],[3.9,9]],"batl":[],"id":88302242},{"atl":[[1000,1.1]],"id":97736949}]}],"rt":639159131510293823,"dt":639159131510294616}
{"op":"mcm","id":2,"clk":"ANmIAQCuWADZrgE=","pt":1780316351124,"mc":[{"id":"1.258742455","rc":[{"batb":[[0,4.8,31.64]],"atb":[[4.8,31.64]],"id":99072898}]}],"rt":639159131511316890,"dt":639159131511317229}
{"op":"mcm","id":2,"clk":"APCIAQDDWAD8rgE=","pt":1780316351547,"mc":[{"id":"1.258742455","rc":[{"tv":550.57,"batb":[[2,44,7.66],[1,46,10.31],[0,48,1.94]],"trd":[[48,48.28]],"atb":[[48,1.94]],"atl":[[48,0]],"batl":[[0,50,13.69]],"id":97008932},{"batb":[[0,4.7,27.39]],"atb":[[4.7,27.39]],"atl":[[1000,1.01]],"id":10398159},{"atl":[[1000,6.25]],"id":98117699},{"atl":[[1000,3]],"id":88302242},{"atl":[[1000,1]],"id":97736949}],"tv":37795.42}],"rt":639159131515548169,"dt":639159131515548696}
{"op":"mcm","id":2,"clk":"APOIAQDFWAD/rgE=","pt":1780316351640,"mc":[{"id":"1.258742455","rc":[{"tv":551.83,"batb":[[0,48,1.32]],"trd":[[48,49.54]],"atb":[[48,1.32]],"id":97008932},{"atl":[[4.9,54.39]],"batl":[[1,4.9,54.39]],"id":10398159},{"atl":[[9.8,8.7]],"batl":[[2,9.8,8.7]],"id":98117699},{"atl":[[3.75,57.55]],"batl":[],"id":88302242},{"tv":2453.27,"batb":[[0,10.5,17.42]],"trd":[[11,93.99]],"ltp":11,"atb":[[10.5,17.42]],"atl":[[11.5,15.03],[11,2.7]],"batl":[[1,11.5,15.03],[0,11,2.7]],"id":97736949}],"tv":37797.02}],"rt":639159131516487059,"dt":639159131516487645}
{"op":"mcm","id":2,"clk":"APiIAQDJWACHrwE=","pt":1780316351741,"mc":[{"id":"1.258742455","rc":[{"tv":552.65,"batb":[[1,46,8.35],[0,48,2.83]],"trd":[[48,50.36]],"atb":[[48,2.83],[46,8.35],[34,5.72]],"atl":[[65,6.79]],"batl":[],"id":97008932},{"batb":[[0,4.7,29.41]],"atb":[[4.7,29.41]],"id":10398159},{"tv":13132.49,"batb":[[0,3.55,55.08]],"trd":[[3.55,599.06]],"ltp":3.55,"atb":[[3.55,55.08]],"id":88302242},{"batb":[[0,10.5,19.33]],"atb":[[10.5,19.33]],"atl":[[11,2.63]],"batl":[[0,11,2.63]],"id":97736949}],"tv":37815.14}],"rt":639159131517490586,"dt":639159131517491071}
{"op":"mcm","id":2,"clk":"AP6IAQDOWACSrwE=","pt":1780316351850,"mc":[{"id":"1.258742455","rc":[{"atb":[[28,14.48]],"id":97008932},{"atl":[[5.1,68.83]],"batl":[],"id":10398159},{"atl":[[3.6,14.41]],"batl":[[0,3.6,14.41]],"id":88302242}]}],"rt":639159131518587010,"dt":639159131518587365}
{"op":"mcm","id":2,"clk":"AIOJAQDSWACYrwE=","pt":1780316351951,"mc":[{"id":"1.258742455","rc":[{"atl":[[75,15.47],[65,5.35]],"batl":[],"id":97008932},{"atl":[[3.6,16.76]],"batl":[[0,3.6,16.76]],"id":88302242}]}],"rt":639159131519602035,"dt":639159131519602439}
{"op":"mcm","id":2,"clk":"AImJAQDXWACjrwE=","pt":1780316352053,"mc":[{"id":"1.258742455","rc":[{"atl":[[50,11.85]],"batl":[[0,50,11.85]],"id":97008932},{"tv":2454.27,"batb":[[0,10.5,19.91]],"trd":[[11,94.99]],"atb":[[10.5,19.91]],"atl":[[11,1.84]],"batl":[[0,11,1.84]],"id":97736949}],"tv":37816.14}],"rt":639159131520611281,"dt":639159131520611759}
{"op":"mcm","id":2,"clk":"AJKJAQDZWACorwE=","pt":1780316352157,"mc":[{"id":"1.258742455","rc":[{"tv":13138.49,"batb":[[0,3.55,52.08]],"trd":[[3.55,605.06]],"atb":[[3.55,52.08]],"id":88302242}],"tv":37822.14}],"rt":639159131521656204,"dt":639159131521656557}
{"op":"mcm","id":2,"clk":"AJaJAQDaWACwrwE=","pt":1780316352254,"mc":[{"id":"1.258742455","rc":[{"atl":[[1000,6.52]],"id":99072898},{"atl":[[50,12.65],[70,6.9]],"batl":[[0,50,12.65]],"id":97008932},{"batb":[[0,21,7.41]],"atb":[[21,7.41]],"id":99072900},{"atb":[[1.17,196.26]],"atl":[[1000,3.35]],"id":88302242},{"atl":[[11,0.64]],"batl":[[2,12.5,7.1],[1,12,18.1],[0,11.5,15.67]],"id":97736949}]}],"rt":639159131522622462,"dt":639159131522623052}
{"op":"mcm","id":2,"clk":"AJ2JAQDcWADBrwE=","pt":1780316352364,"mc":[{"id":"1.258742455","rc":[{"atl":[[1000,6.25]],"id":99072898},{"batb":[[0,21,7.85]],"atb":[[21,7.85]],"atl":[[22,2.37]],"batl":[[0,22,2.37]],"id":99072900},{"batb":[[0,4.7,27.39]],"atb":[[4.7,27.39]],"id":10398159},{"batb":[[0,3.55,42.31]],"atb":[[1.17,196.12],[3.55,42.31]],"atl":[[3.6,19.45]],"batl":[[0,3.6,19.45]],"id":88302242},{"batb":[[1,10,36.52]],"atb":[[10,36.52]],"id":97736949}]}],"rt":639159131523720502,"dt":639159131523721499}
{"op":"mcm","id":2,"clk":"AKGJAQDfWADDrwE=","pt":1780316352459,"mc":[{"id":"1.258742455","rc":[{"atl":[[4.9,11.63]],"batl":[[0,4.9,11.63]],"id":99072898},{"tv":2330.88,"batb":[[2,8.6,14.99],[1,8.8,17.1],[0,9,26.84]],"trd":[[9.2,200.99],[9,32.99]],"ltp":9,"atb":[[9.2,0],[9,26.84]],"id":98117699},{"batb":[[1,3.5,77.05]],"atb":[[3.5,77.05]],"atl":[[1000,3]],"id":88302242}],"tv":37839.45}],"rt":639159131524674016,"dt":639159131524674644}
{"op":"mcm","id":2,"clk":"AKyJAQDlWADKrwE=","pt":1780316352575,"mc":[{"id":"1.258742455","rc":[{"batb":[[1,46,8.86]],"atb":[[46,8.86]],"id":97008932},{"atl":[[22,0]],"batl":[[2,25,5.9],[1,24,6.04],[0,23,7.02]],"id":99072900},{"batb":[[0,4.7,27.85]],"atb":[[4.7,27.85]],"id":10398159},{"batb":[[0,3.55,24.59]],"atb":[[3.55,24.59]],"atl":[[3.6,19.8]],"batl":[[0,3.6,19.8]],"id":88302242},{"batb":[[0,10.5,24.17]],"atb":[[10.5,24.17]],"id":97736949}]}],"rt":639159131525830717,"dt":639159131525831344}
{"op":"mcm","id":2,"clk":"ALCJAQDoWADRrwE=","pt":1780316352665,"mc":[{"id":"1.258742455","rc":[{"batb":[[0,48,1.93]],"atb":[[48,1.93]],"id":97008932},{"batb":[[0,21,9.02]],"atb":[[21,9.02]],"atl":[[22,0.35]],"batl":[[0,23,7.37]],"id":99072900},{"atl":[[5.1,52.83]],"batl":[],"id":10398159},{"batb":[[0,9,23.54]],"atb":[[8.4,14.67],[9,23.54]],"atl":[[9.4,11.32],[9.2,0.38]],"batl":[[0,9.4,11.7]],"id":98117699},{"batb":[[0,3.55,27.82]],"atb":[[3.55,27.82]],"atl":[[3.65,41.85]],"batl":[[1,3.65,41.85]],"id":88302242},{"batb":[[0,10.5,30.62]],"atb":[[10.5,30.62]],"atl":[[13,6.57]],"batl":[],"id":97736949}]}],"rt":639159131526730781,"dt":639159131526731471}
{"op":"mcm","id":2,"clk":"ALaJAQDrWADXrwE=","pt":1780316352769,"mc":[{"id":"1.258742455","rc":[{"atl":[[4.9,2.4]],"batl":[[0,4.9,2.4]],"id":99072898},{"atl":[[22,0]],"batl":[[0,23,7.02]],"id":99072900},{"atl":[[9.4,12.32],[9.2,0]],"batl":[[0,9.4,12.32]],"id":98117699},{"atl":[[3.65,40.68]],"batl":[[1,3.65,40.68]],"id":88302242}]}],"rt":639159131527768478,"dt":639159131527768981}
{"op":"mcm","id":2,"clk":"AL2JAQDuWADcrwE=","pt":1780316352873,"mc":[{"id":"1.258742455","rc":[{"atl":[[26,3.43]],"batl":[],"id":99072900},{"batb":[[0,9,24.47]],"atb":[[8.4,8.67],[9,24.47]],"id":98117699},{"batb":[[0,10.5,31.72]],"atb":[[10.5,31.72]],"atl":[[13.5,10.62]],"batl":[],"id":97736949}]}],"rt":639159131528812035,"dt":639159131528812449}
{"op":"mcm","id":2,"clk":"AMWJAQD0WADlrwE=","pt":1780316352924,"mc":[{"id":"1.258742455","rc":[{"batb":[[1,80,8.83]],"atb":[[80,8.83]],"id":99072901},{"atl":[[10.5,18.72]],"batl":[],"id":98117699},{"atl":[[3.65,45.6]],"batl":[[1,3.65,45.6]],"id":88302242}]}],"rt":639159131529320522,"dt":639159131529320918}
{"op":"mcm","id":2,"clk":"AM2JAQD7WADyrwE=","pt":1780316353029,"mc":[{"id":"1.258742455","rc":[{"batb":[[0,4.7,27.07]],"atb":[[4.7,27.07]],"id":10398159},{"batb":[],"atb":[[8.2,15.55]],"id":98117699}]}],"rt":639159131530380024,"dt":639159131530380423}
{"op":"mcm","id":2,"clk":"ANOJAQCAWQD6rwE=","pt":1780316353131,"mc":[{"id":"1.258742455","rc":[{"tv":13173.09,"batb":[[0,3.55,10.52]],"trd":[[3.55,639.66]],"atb":[[3.55,10.52]],"id":88302242}],"tv":37874.05}],"rt":639159131531387122,"dt":639159131531387580}
{"op":"mcm","id":2,"clk":"ANiJAQCEWQCEsAE=","pt":1780316353234,"mc":[{"id":"1.258742455","rc":[{"atl":[[23,3.07]],"batl":[[0,23,3.07]],"id":99072900},{"batb":[[0,4.7,27.7]],"atb":[[4.7,27.7]],"id":10398159},{"batb":[[0,9,25.04]],"atb":[[8.4,12.43],[9,25.04]],"id":98117699},{"tv":13185.15,"batb":[[0,3.55,1.16]],"trd":[[3.55,651.72]],"atb":[[3.55,1.16],[3.35,178.41]],"atl":[[3.9,12.81],[3.6,25.66]],"batl":[[0,3.6,25.66]],"id":88302242},{"batb":[[0,1000,93.03]],"atb":[[1000,93.03]],"id":10445502}],"tv":37886.11}],"rt":639159131532421341,"dt":639159131532421858}
{"op":"mcm","id":2,"clk":"AOGJAQCKWQCQsAE=","pt":1780316353344,"mc":[{"id":"1.258742455","rc":[{"batb":[[0,4.8,39.84]],"atb":[[4.2,107.09],[4.8,39.84]],"atl":[[4.9,1.05]],"batl":[[0,4.9,1.05]],"id":99072898},{"batb":[],"atb":[[32,10.44]],"atl":[[75,15.99]],"batl":[],"id":97008932},{"atl":[[23,4.86]],"batl":[[0,23,4.86]],"id":99072900},{"batb":[[0,4.7,35]],"atb":[[4.7,35]],"atl":[[4.9,57.26],[4.8,63.68]],"batl":[[1,4.9,57.26],[0,4.8,63.68]],"id":10398159},{"batb":[[2,8.6,18.75]],"atb":[[8.6,18.75],[7.2,20.05]],"id":98117699},{"batb":[[0,3.55,3.06]],"atb":[[3.55,3.06],[3.35,151.04]],"atl":[[3.75,61.36],[3.6,36.82]],"batl":[[0,3.6,36.82]],"id":88302242},{"batb":[[0,10.5,34.87]],"atb":[[10.5,34.87]],"id":97736949}]}],"rt":639159131533517471,"dt":639159131533518123}
{"op":"mcm","id":2,"clk":"AO2JAQCVWQCgsAE=","pt":1780316353547,"mc":[{"id":"1.258742455","rc":[{"batb":[[0,4.7,35.64]],"atb":[[4.7,35.64]],"id":10398159},{"batb":[[1,10,37.01]],"atb":[[10,37.01]],"id":97736949}]}],"rt":639159131535549354,"dt":639159131535549721}
{"op":"mcm","id":2,"clk":"AICKAQCjWQC1sAE=","pt":1780316353948,"mc":[{"id":"1.258742455","rc":[{"atl":[[4.9,1.19]],"batl":[[0,4.9,1.19]],"id":99072898}]}],"rt":639159131539558178,"dt":639159131539558558}
{"op":"mcm","id":2,"clk":"AIOKAQCkWQC\u002BsAE=","pt":1780316354053,"mc":[{"id":"1.258742455","rc":[{"batb":[[0,4.7,36.45]],"atb":[[4.7,36.45]],"id":10398159}]}],"rt":639159131540609259,"dt":639159131540609577}
{"op":"mcm","id":2,"clk":"AImKAQCqWQDHsAE=","pt":1780316354160,"mc":[{"id":"1.258742455","rc":[{"batb":[],"atb":[[30,6.93]],"id":97008932}]}],"rt":639159131541682955,"dt":639159131541683288}
{"op":"mcm","id":2,"clk":"AJCKAQCvWQDTsAE=","pt":1780316354357,"mc":[{"id":"1.258742455","rc":[{"batb":[],"atb":[[4.2,105.9]],"id":99072898},{"batb":[],"atb":[[4,29.82]],"id":10398159},{"atb":[[3.05,297.07]],"id":88302242},{"batb":[],"atb":[[700,3.29],[670,0]],"id":10445502}]}],"rt":639159131543648823,"dt":639159131543649233}
{"op":"mcm","id":2,"clk":"AJqKAQC8WQDrsAE=","pt":1780316354570,"mc":[{"id":"1.258742455","rc":[{"batb":[],"atb":[[19,12.01]],"id":99072900},{"batb":[],"atb":[[7.8,1.99]],"id":98117699},{"batb":[],"atb":[[9,17.84]],"id":97736949}]}],"rt":639159131545778576,"dt":639159131545779028}
{"op":"mcm","id":2,"clk":"AKKKAQC\u002BWQD4sAE=","pt":1780316354679,"mc":[{"id":"1.258742455","rc":[{"batb":[[0,4.7,35.64]],"atb":[[4.7,35.64]],"id":10398159},{"atl":[[500,0.53]],"id":98464183}]}],"rt":639159131546871283,"dt":639159131546871697}
{"op":"mcm","id":2,"clk":"AKiKAQDFWQCAsQE=","pt":1780316354770,"mc":[{"id":"1.258742455","rc":[{"batb":[],"atb":[[4.1,9.39]],"atl":[[4.9,1.41]],"batl":[[0,4.9,1.41]],"id":99072898},{"batb":[],"atb":[[40,10.16]],"id":97008932},{"batb":[],"atb":[[4,31.07]],"id":10398159},{"atb":[[3.05,298.71]],"id":88302242}]}],"rt":639159131547779425,"dt":639159131547779871}
{"op":"mcm","id":2,"clk":"AKqKAQDGWQCHsQE=","pt":1780316354832,"mc":[{"id":"1.258742455","rc":[{"batb":[[1,4.7,47.06]],"atb":[[4.7,47.06]],"id":99072898},{"batb":[],"atb":[[19,12.27]],"id":99072900},{"batb":[],"atb":[[7.8,2.63]],"id":98117699},{"batb":[],"atb":[[9.4,16.77]],"id":97736949}]}],"rt":639159131548402047,"dt":639159131548402471}
{"op":"mcm","id":2,"clk":"ALKKAQDNWQCPsQE=","pt":1780316354975,"mc":[{"id":"1.258742455","rc":[{"batb":[],"atb":[[42,14.79]],"id":97008932},{"tv":1121.39,"batb":[[0,21,8.02]],"trd":[[21,112]],"ltp":21,"atb":[[21,8.02]],"id":99072900}],"tv":37888.11}],"rt":639159131549832372,"dt":639159131549832771}
{"op":"mcm","id":2,"clk":"AL\u002BKAQDYWQCdsQE=","pt":1780316355130,"mc":[{"id":"1.258742455","rc":[{"batb":[[1,46,7.32]],"atb":[[46,7.32]],"atl":[[50,12.34]],"batl":[[0,50,12.34]],"id":97008932},{"batb":[[0,21,8.84]],"atb":[[21,8.84]],"atl":[[23,4.35],[22,0.04]],"batl":[[0,23,4.39]],"id":99072900},{"batb":[[0,85,7.16]],"atb":[[90,0.11]],"id":99072901},{"batb":[[1,3.5,76.91],[0,3.55,4.13]],"atb":[[3.5,76.91],[3.55,4.13]],"atl":[[1000,3.82],[3.6,36.47]],"batl":[[0,3.6,36.47]],"id":88302242},{"batb":[[0,10.5,36.43]],"atb":[[10.5,36.43]],"atl":[[1000,1.22]],"id":97736949}]}],"rt":639159131551379175,"dt":639159131551379701}
{"op":"mcm","id":2,"clk":"AMaKAQDdWQCjsQE=","pt":1780316355228,"mc":[{"id":"1.258742455","rc":[{"atl":[[1000,3]],"id":88302242},{"atl":[[1000,1]],"id":97736949}]}],"rt":639159131552363917,"dt":639159131552364224}
{"op":"mcm","id":2,"clk":"AM2KAQDmWQCssQE=","pt":1780316355338,"mc":[{"id":"1.258742455","rc":[{"atl":[[22,0]],"batl":[[0,23,4.35]],"id":99072900},{"batb":[[0,85,7.24]],"atb":[[90,0.19]],"atl":[[95,0.28]],"batl":[[0,100,1.45]],"id":99072901},{"atl":[[3.65,46.42]],"batl":[[1,3.65,46.42]],"id":88302242},{"atl":[[11,0.86]],"batl":[[0,11.5,15.89]],"id":97736949}]}],"rt":639159131553456346,"dt":639159131553456804}
{"op":"mcm","id":2,"clk":"ANmKAQDyWQC8sQE=","pt":1780316355546,"mc":[{"id":"1.258742455","rc":[{"atl":[[3.6,35.47]],"batl":[[0,3.6,35.47]],"id":88302242}]}],"rt":639159131555547679,"dt":639159131555548029}
{"op":"mcm","id":2,"clk":"AN\u002BKAQDzWQDDsQE=","pt":1780316355645,"mc":[{"id":"1.258742455","rc":[{"atl":[[95,0.34]],"batl":[[0,100,1.51]],"id":99072901}]}],"rt":639159131556536041,"dt":639159131556536412}
{"op":"mcm","id":2,"clk":"AOaKAQD\u002BWQDLsQE=","pt":1780316355750,"mc":[{"id":"1.258742455","rc":[{"atl":[[4.9,1.77]],"batl":[[0,4.9,1.77]],"id":99072898}]}],"rt":639159131557579356,"dt":639159131557579697}
{"op":"mcm","id":2,"clk":"AO2KAQCDWgDRsQE=","pt":1780316355851,"mc":[{"id":"1.258742455","rc":[{"batb":[[0,4.7,34.37]],"atb":[[4.7,34.37]],"id":10398159}]}],"rt":639159131558592405,"dt":639159131558592759}
{"op":"mcm","id":2,"clk":"APeKAQCQWgDgsQE=","pt":1780316356056,"mc":[{"id":"1.258742455","rc":[{"batb":[[0,4.7,36.16]],"atb":[[4.7,36.16]],"id":10398159}]}],"rt":639159131560652157,"dt":639159131560652510}
{"op":"mcm","id":2,"clk":"AISLAQCbWgDwsQE=","pt":1780316356258,"mc":[{"id":"1.258742455","rc":[{"batb":[[0,4.7,34.37]],"atb":[[4.7,34.37]],"id":10398159},{"atl":[[3.6,32.14]],"batl":[[0,3.6,32.14]],"id":88302242}]}],"rt":639159131562658915,"dt":639159131562659358}
{"op":"mcm","id":2,"clk":"AImLAQChWgD6sQE=","pt":1780316356359,"mc":[{"id":"1.258742455","rc":[{"tv":13191.81,"batb":[[2,3.4,58.52],[1,3.45,76.63],[0,3.5,77.71]],"trd":[[3.55,658.38]],"atb":[[3.55,0.8]],"id":88302242}],"tv":37894.77}],"rt":639159131563669512,"dt":639159131563669978}
{"op":"mcm","id":2,"clk":"AJCLAQCmWgCEsgE=","pt":1780316356464,"mc":[{"id":"1.258742455","rc":[{"batb":[[0,4.7,35.51]],"atb":[[4.7,35.51]],"id":10398159},{"tv":2334.88,"batb":[[0,9,23.04]],"trd":[[9,36.99]],"atb":[[9,23.04]],"id":98117699}],"tv":37898.77}],"rt":639159131564719985,"dt":639159131564720621}
{"op":"mcm","id":2,"clk":"AKGLAQCtWgCfsgE=","pt":1780316356765,"mc":[{"id":"1.258742455","rc":[{"batb":[[2,8.6,21.99]],"atb":[[8.6,21.99]],"id":98117699},{"batb":[],"atb":[[3.35,145.04]],"id":88302242}]}],"rt":639159131567746158,"dt":639159131567746533}
{"op":"mcm","id":2,"clk":"AKqLAQCyWgCtsgE=","pt":1780316356925,"mc":[{"id":"1.258742455","rc":[{"batb":[],"atb":[[3.3,26.21]],"id":88302242}]}],"rt":639159131569332967,"dt":639159131569333306}
{"op":"mcm","id":2,"clk":"ALGLAQC3WgCysgE=","pt":1780316357021,"mc":[{"id":"1.258742455","rc":[{"atl":[[4.9,1.55]],"batl":[[0,4.9,1.55]],"id":99072898},{"batb":[[0,4.7,34.37]],"atb":[[4.7,34.37]],"id":10398159}]}],"rt":639159131570292355,"dt":639159131570292711}
{"op":"mcm","id":2,"clk":"ALiLAQC8WgC5sgE=","pt":1780316357129,"mc":[{"id":"1.258742455","rc":[{"batb":[[0,4.7,35.53]],"atb":[[4.7,35.53]],"id":10398159}]}],"rt":639159131571370457,"dt":639159131571370816}
{"op":"mcm","id":2,"clk":"AL6LAQDDWgC/sgE=","pt":1780316357228,"mc":[{"id":"1.258742455","rc":[{"atl":[[23,8.03]],"batl":[[0,23,8.03]],"id":99072900}]}],"rt":639159131572364797,"dt":639159131572365182}
{"op":"mcm","id":2,"clk":"AM6LAQDNWgDcsgE=","pt":1780316357442,"mc":[{"id":"1.258742455","rc":[{"batb":[],"atb":[[4.2,111.23]],"atl":[[4.9,1.19]],"batl":[[0,4.9,1.19]],"id":99072898},{"atl":[[500,0.91]],"id":98464183}]}],"rt":639159131574499416,"dt":639159131574499856}
{"op":"mcm","id":2,"clk":"ANOLAQDTWgDmsgE=","pt":1780316357544,"mc":[{"id":"1.258742455","rc":[{"atl":[[4.9,12.19]],"batl":[[0,4.9,12.19]],"id":99072898},{"atl":[[22,0.06]],"batl":[[0,23,8.09]],"id":99072900},{"tv":8562.68,"batb":[[0,4.7,23.53]],"trd":[[4.7,1153.9]],"atb":[[4.7,23.53]],"id":10398159},{"tv":13193.41,"batb":[[0,3.5,76.91]],"trd":[[3.55,659.98]],"atb":[[3.55,0]],"atl":[[3.55,12.2]],"batl":[[2,3.65,46.42],[1,3.6,32.14],[0,3.55,12.2]],"id":88302242}],"tv":37924.37}],"rt":639159131575521848,"dt":639159131575522444}
{"op":"mcm","id":2,"clk":"ANqLAQDVWgDzsgE=","pt":1780316357647,"mc":[{"id":"1.258742455","rc":[{"batb":[[0,48,3.56]],"atb":[[48,3.56]],"id":97008932},{"tv":1121.51,"trd":[[22,104.62]],"ltp":22,"atl":[[22,0]],"batl":[[0,23,8.03]],"id":99072900},{"tv":13207.59,"trd":[[3.55,674.16]],"atl":[[3.55,5.11],[3.7,232.42]],"batl":[[0,3.55,5.11]],"id":88302242}],"tv":37938.67}],"rt":639159131576552883,"dt":639159131576553423}
{"op":"mcm","id":2,"clk":"AN2LAQDaWgD5sgE=","pt":1780316357745,"mc":[{"id":"1.258742455","rc":[{"atl":[[4.9,12.76]],"batl":[[0,4.9,12.76]],"id":99072898},{"batb":[[0,4.7,22.37]],"atb":[[4.7,22.37]],"id":10398159},{"tv":13217.81,"trd":[[3.55,684.38]],"atl":[[3.55,0]],"batl":[[2,3.7,232.42],[1,3.65,46.42],[0,3.6,32.14]],"id":88302242}],"tv":37948.89}],"rt":639159131577535025,"dt":639159131577535478}
{"op":"mcm","id":2,"clk":"AOCLAQDbWgCAswE=","pt":1780316357841,"mc":[{"id":"1.258742455","rc":[{"batb":[[1,46,9.03]],"atb":[[46,9.03]],"id":97008932},{"batb":[[2,3.45,76.63],[1,3.5,76.91],[0,3.55,8.94]],"atb":[[3.55,8.94]],"atl":[[3.7,228.59]],"batl":[[2,3.7,228.59]],"id":88302242}]}],"rt":639159131578495462,"dt":639159131578495928}
{"op":"mcm","id":2,"clk":"AOWLAQDeWgCFswE=","pt":1780316357947,"mc":[{"id":"1.258742455","rc":[{"atl":[[4.9,13.55]],"batl":[[0,4.9,13.55]],"id":99072898},{"atl":[[50,13.58]],"batl":[[0,50,13.58]],"id":97008932}]}],"rt":639159131579553920,"dt":639159131579554299}
{"op":"mcm","id":2,"clk":"AOuLAQDjWgCOswE=","pt":1780316358046,"mc":[{"id":"1.258742455","rc":[{"atl":[[50,11.39]],"batl":[[0,50,11.39]],"id":97008932},{"batb":[[0,3.55,10.7]],"atb":[[3.55,10.7]],"id":88302242}]}],"rt":639159131580538895,"dt":639159131580539398}
{"op":"mcm","id":2,"clk":"APGLAQDnWgCUswE=","pt":1780316358155,"mc":[{"id":"1.258742455","rc":[{"batb":[[0,4.7,32.46]],"atb":[[4.7,32.46]],"atl":[[4.9,59.37]],"batl":[[1,4.9,59.37]],"id":10398159},{"batb":[[0,9,26.82]],"atb":[[9,26.82]],"atl":[[9.4,13.32]],"batl":[[0,9.4,13.32]],"id":98117699}]}],"rt":639159131581632965,"dt":639159131581633414}
{"op":"mcm","id":2,"clk":"APeLAQDtWgCdswE=","pt":1780316358263,"mc":[{"id":"1.258742455","rc":[{"atl":[[50,11.7]],"batl":[[0,50,11.7]],"id":97008932}]}],"rt":639159131582710546,"dt":639159131582710886}
{"op":"mcm","id":2,"clk":"APuLAQDyWgCjswE=","pt":1780316358365,"mc":[{"id":"1.258742455","rc":[{"batb":[[0,4.7,32.79]],"atb":[[4.7,32.79]],"id":10398159},{"batb":[[0,3.55,12.14]],"atb":[[3.3,20.21],[3.55,12.14]],"id":88302242}]}],"rt":639159131583729838,"dt":639159131583730232}
{"op":"mcm","id":2,"clk":"AIGMAQDzWgCrswE=","pt":1780316358462,"mc":[{"id":"1.258742455","rc":[{"atl":[[4.9,21.77]],"batl":[[0,4.9,21.77]],"id":99072898}]}],"rt":639159131584695614,"dt":639159131584696012}
{"op":"mcm","id":2,"clk":"AImMAQD6WgCzswE=","pt":1780316358571,"mc":[{"id":"1.258742455","rc":[{"atl":[[22,0.03]],"batl":[[0,23,8.06]],"id":99072900},{"batb":[[0,4.7,32.46]],"atb":[[4.7,32.46]],"id":10398159}]}],"rt":639159131585795369,"dt":639159131585795741}
{"op":"mcm","id":2,"clk":"AI2MAQD6WgC7swE=","pt":1780316358667,"mc":[{"id":"1.258742455","rc":[{"atl":[[4.9,22.54]],"batl":[[0,4.9,22.54]],"id":99072898},{"atl":[[80,5.57]],"batl":[],"id":97008932},{"atl":[[22,0]],"batl":[[0,23,8.03]],"id":99072900},{"batb":[],"atb":[[7.8,5.67]],"id":98117699},{"batb":[],"atb":[[3.35,151.04]],"id":88302242},{"tv":2472.14,"batb":[[0,10.5,21.05]],"trd":[[10.5,185.75]],"ltp":10.5,"atb":[[10.5,21.05]],"id":97736949}],"tv":37966.76}],"rt":639159131586748567,"dt":639159131586749101}
{"op":"mcm","id":2,"clk":"AJaMAQD/WgDHswE=","pt":1780316358771,"mc":[{"id":"1.258742455","rc":[{"atl":[[22,0.04]],"batl":[[0,23,8.07]],"id":99072900},{"batb":[[0,4.7,33.12]],"atb":[[4.7,33.12]],"id":10398159},{"tv":2477.73,"batb":[[0,10.5,18.25]],"trd":[[10.5,191.34]],"atb":[[10.5,18.25]],"id":97736949}],"tv":37972.35}],"rt":639159131587786817,"dt":639159131587787262}
{"op":"mcm","id":2,"clk":"AJ2MAQCAWwDOswE=","pt":1780316358871,"mc":[{"id":"1.258742455","rc":[{"atl":[[11,1.36]],"batl":[[2,12,18.1],[1,11.5,15.03],[0,11,1.36]],"id":97736949}]}],"rt":639159131588790156,"dt":639159131588790520}
{"op":"mcm","id":2,"clk":"AKOMAQCBWwDUswE=","pt":1780316358972,"mc":[{"id":"1.258742455","rc":[{"atl":[[22,0]],"batl":[[0,23,8.03]],"id":99072900},{"atl":[[95,0.28]],"batl":[[0,100,1.45]],"id":99072901},{"batb":[[0,3.55,18]],"atb":[[3.55,18]],"atl":[[3.6,29.45]],"batl":[[0,3.6,29.45]],"id":88302242},{"batb":[[0,10.5,15.11]],"atb":[[10.5,15.11]],"id":97736949}]}],"rt":639159131589805501,"dt":639159131589805982}
{"op":"mcm","id":2,"clk":"AKqMAQCFWwDfswE=","pt":1780316359031,"mc":[{"id":"1.258742455","rc":[{"atl":[[11,1.66]],"batl":[[0,11,1.66]],"id":97736949}]}],"rt":639159131590385803,"dt":639159131590386138}
{"op":"mcm","id":2,"clk":"AK\u002BMAQCJWwDoswE=","pt":1780316359132,"mc":[{"id":"1.258742455","rc":[{"atl":[[3.6,23.59]],"batl":[[0,3.6,23.59]],"id":88302242},{"tv":2482.29,"batb":[[0,10.5,12.83]],"trd":[[10.5,195.9]],"atb":[[10.5,12.83]],"id":97736949}],"tv":37976.91}],"rt":639159131591400533,"dt":639159131591400950}
{"op":"mcm","id":2,"clk":"ALSMAQCKWwDwswE=","pt":1780316359234,"mc":[{"id":"1.258742455","rc":[{"atl":[[95,0.17]],"batl":[[0,100,1.34]],"id":99072901},{"batb":[[0,4.7,33.63]],"atb":[[4.7,33.63]],"id":10398159}]}],"rt":639159131592420080,"dt":639159131592420454}
{"op":"mcm","id":2,"clk":"ALuMAQCNWwD5swE=","pt":1780316359342,"mc":[{"id":"1.258742455","rc":[{"atl":[[3.6,24.87]],"batl":[[0,3.6,24.87]],"id":88302242},{"tv":2486.85,"batb":[[0,10.5,10.55]],"trd":[[10.5,200.46]],"atb":[[10.5,10.55]],"atl":[[11,2.41]],"batl":[[0,11,2.41]],"id":97736949}],"tv":37981.47}],"rt":639159131593506162,"dt":639159131593506747}
{"op":"mcm","id":2,"clk":"AMCMAQCPWwD\u002BswE=","pt":1780316359441,"mc":[{"id":"1.258742455","rc":[{"batb":[[0,48,3.61]],"atb":[[48,3.61]],"id":97008932},{"batb":[[0,4.7,46.63]],"atb":[[4.7,46.63]],"id":10398159},{"atl":[[13.5,4.62]],"batl":[],"id":97736949}]}],"rt":639159131594490880,"dt":639159131594491293}
{"op":"mcm","id":2,"clk":"AMWMAQCSWwCDtAE=","pt":1780316359538,"mc":[{"id":"1.258742455","rc":[{"batb":[[0,4.7,48.11]],"atb":[[4.7,48.11]],"id":10398159},{"tv":2491.08,"batb":[[0,10.5,7.85]],"trd":[[10.5,204.69]],"atb":[[10.5,7.85]],"id":97736949}],"tv":37985.7}],"rt":639159131595469201,"dt":639159131595469642}
{"op":"mcm","id":2,"clk":"AMyMAQCVWwCLtAE=","pt":1780316359641,"mc":[{"id":"1.258742455","rc":[{"atl":[[500,0.53]],"id":98464183},{"batb":[[1,10,38.85],[0,10.5,10.79]],"atb":[[10.5,10.79],[10,38.85]],"atl":[[13,12.57],[11,3.16]],"batl":[[0,11,3.16]],"id":97736949}]}],"rt":639159131596498204,"dt":639159131596498625}
{"op":"mcm","id":2,"clk":"ANKMAQCYWwCTtAE=","pt":1780316359744,"mc":[{"id":"1.258742455","rc":[{"tv":885.36,"batb":[[0,50,9.9]],"trd":[[50,140.04]],"atb":[[50,9.9]],"id":98464183},{"tv":2493.82,"batb":[[0,10.5,8.32]],"trd":[[10.5,207.43]],"atb":[[10.5,8.32]],"id":97736949}],"tv":37989.19}],"rt":639159131597518879,"dt":639159131597519343}
{"op":"mcm","id":2,"clk":"ANuMAQCZWwCZtAE=","pt":1780316359845,"mc":[{"id":"1.258742455","rc":[{"atl":[[3.75,87.44]],"batl":[],"id":88302242},{"batb":[[0,160,6.89]],"atb":[[160,6.47]],"id":99072897}]}],"rt":639159131598535540,"dt":639159131598535910}
{"op":"mcm","id":2,"clk":"AN6MAQCdWwCjtAE=","pt":1780316359950,"mc":[{"id":"1.258742455","rc":[{"batb":[[0,85,7.33]],"atb":[[90,0.28]],"id":99072901},{"tv":2496.56,"batb":[[0,10.5,7.02]],"trd":[[10.5,210.17]],"atb":[[10.5,7.02]],"id":97736949},{"batb":[[2,150,5.6],[1,160,6.47],[0,170,1.43]],"atb":[[170,1.43]],"id":99072897}],"tv":37991.93}],"rt":639159131599585474,"dt":639159131599585930}
{"op":"mcm","id":2,"clk":"AOaMAQCfWwCotAE=","pt":1780316360053,"mc":[{"id":"1.258742455","rc":[{"tv":236.08,"batb":[[2,160,4.74],[1,170,3.16],[0,180,1.67]],"trd":[[180,50.76]],"ltp":180,"atb":[[180,1.67],[170,3.16],[160,4.74]],"atl":[[180,0]],"batl":[[0,200,1.18]],"id":99072897}],"tv":37992.05}],"rt":639159131600609955,"dt":639159131600610464}
{"op":"mcm","id":2,"clk":"AO6MAQCiWwCxtAE=","pt":1780316360155,"mc":[{"id":"1.258742455","rc":[{"atl":[[5,25.88]],"batl":[[1,5,25.88]],"id":99072898},{"tv":2500.54,"batb":[[0,10.5,4.96]],"trd":[[10.5,214.15]],"atb":[[9.4,18.86],[10.5,4.96]],"id":97736949},{"batb":[[1,170,3.32]],"atb":[[170,3.32]],"atl":[[190,0.12]],"batl":[[1,220,1.13],[0,210,1.42]],"id":99072897}],"tv":37996.03}],"rt":639159131601627314,"dt":639159131601627799}
{"op":"mcm","id":2,"clk":"APKMAQCmWwC6tAE=","pt":1780316360260,"mc":[{"id":"1.258742455","rc":[{"atl":[[95,0.24]],"batl":[[0,100,1.41]],"id":99072901},{"atl":[[3.65,40.42]],"batl":[[1,3.65,40.42]],"id":88302242}]}],"rt":639159131602684464,"dt":639159131602684857}
{"op":"mcm","id":2,"clk":"APaMAQCpWwDAtAE=","pt":1780316360358,"mc":[{"id":"1.258742455","rc":[{"atl":[[4.9,21.77]],"batl":[[0,4.9,21.77]],"id":99072898}]}],"rt":639159131603668083,"dt":639159131603668483}
{"op":"mcm","id":2,"clk":"AICNAQCtWwDLtAE=","pt":1780316360472,"mc":[{"id":"1.258742455","rc":[{"batb":[[0,48,3.56]],"atb":[[48,3.56]],"id":97008932},{"batb":[],"atb":[[9.2,19.82]],"id":97736949},{"batb":[[0,180,1.99]],"atb":[[180,1.99]],"id":99072897}]}],"rt":639159131604804184,"dt":639159131604804551}
{"op":"mcm","id":2,"clk":"AIyNAQCyWwDdtAE=","pt":1780316360676,"mc":[{"id":"1.258742455","rc":[{"batb":[[1,4.7,45.33]],"atb":[[4.7,45.33]],"id":99072898}]}],"rt":639159131606846155,"dt":639159131606846611}
{"op":"mcm","id":2,"clk":"AJKNAQC0WwDmtAE=","pt":1780316360769,"mc":[{"id":"1.258742455","rc":[{"atl":[[95,0.28]],"batl":[[0,100,1.45]],"id":99072901},{"batb":[[0,10.5,5.07]],"atb":[[10.5,5.07]],"id":97736949}]}],"rt":639159131607774839,"dt":639159131607775284}
{"op":"mcm","id":2,"clk":"AJqNAQC4WwDwtAE=","pt":1780316360869,"mc":[{"id":"1.258742455","rc":[{"atl":[[4.9,29.12]],"batl":[[0,4.9,29.12]],"id":99072898},{"atl":[[1000,0.34]],"id":97008932},{"batb":[[0,4.7,40.51]],"atb":[[4.7,40.51]],"atl":[[4.9,57.77]],"batl":[[1,4.9,57.77]],"id":10398159},{"batb":[[0,9,25.51]],"atb":[[9,25.51]],"id":98117699},{"tv":13223.71,"batb":[[0,3.55,15.05]],"trd":[[3.55,690.28]],"atb":[[3.55,15.05]],"id":88302242},{"batb":[[0,10.5,3.91]],"atb":[[10.5,3.91]],"id":97736949},{"batb":[[1,170,3.21],[0,180,2.28]],"atb":[[180,2.28],[170,3.21]],"id":99072897}],"tv":38001.93}],"rt":639159131608776906,"dt":639159131608777485}
{"op":"mcm","id":2,"clk":"AJ6NAQC7WwD3tAE=","pt":1780316360973,"mc":[{"id":"1.258742455","rc":[{"atl":[[1000,0.22]],"id":97008932},{"tv":8564.84,"batb":[[0,4.7,36.94]],"trd":[[4.7,1156.06]],"atb":[[4.7,36.94]],"atl":[[4.8,66.52]],"batl":[[0,4.8,66.52]],"id":10398159},{"batb":[[1,48,10.94]],"atb":[[48,10.94]],"id":98464183},{"batb":[[1,8.8,20.86],[0,9,23.04]],"atb":[[8.8,20.86],[9,23.04]],"id":98117699},{"atl":[[3.7,232.36]],"batl":[[2,3.7,232.36]],"id":88302242},{"batb":[[0,10.5,5.64]],"atb":[[10.5,5.64]],"id":97736949},{"batb":[[2,160,6.47]],"atb":[[160,6.47]],"id":99072897}],"tv":38004.09}],"rt":639159131609816514,"dt":639159131609817060}
{"op":"mcm","id":2,"clk":"AKKNAQC/WwD8tAE=","pt":1780316361074,"mc":[{"id":"1.258742455","rc":[{"batb":[[0,48,3.63]],"atb":[[48,3.63]],"atl":[[50,11.82]],"batl":[[0,50,11.82]],"id":97008932},{"atl":[[95,1.28]],"batl":[[2,110,6.21],[1,100,1.17],[0,95,1.28]],"id":99072901},{"atl":[[3.6,27.48]],"batl":[[0,3.6,27.48]],"id":88302242},{"batb":[[0,10.5,6.02]],"atb":[[10.5,6.02]],"id":97736949}]}],"rt":639159131610826160,"dt":639159131610826823}
