{"op":"mcm","id":2,"initialClk":"KrzToekJK8yq8eIJK/uHytgJ","clk":"AAAAAAAA","conflateMs":0,"heartbeatMs":5000,"pt":1780316095909,"ct":"SUB_IMAGE","mc":[{"id":"1.258742455","marketDefinition":{"bspMarket":true,"turnInPlayEnabled":true,"persistenceEnabled":true,"marketBaseRate":5,"bettingType":"ODDS","status":"OPEN","venue":"Gowran Park","timezone":"Europe/London","regulators":["MR_INT"],"marketType":"WIN","numberOfWinners":1,"countryCode":"IE","inPlay":false,"betDelay":0,"numberOfActiveRunners":11,"eventId":"35666846","crossMatching":true,"runnersVoidable":false,"suspendTime":"2026-06-01T12:29:00Z","discountAllowed":true,"runners":[{"status":"ACTIVE","sortPriority":1,"id":99072898,"adjustmentFactor":27.778},{"status":"ACTIVE","sortPriority":2,"id":88302242,"adjustmentFactor":24.852},{"status":"ACTIVE","sortPriority":3,"id":10398159,"adjustmentFactor":21.07},{"status":"ACTIVE","sortPriority":4,"id":98117699,"adjustmentFactor":9.231},{"status":"ACTIVE","sortPriority":5,"id":97736949,"adjustmentFactor":6.462},{"status":"ACTIVE","sortPriority":6,"id":99072900,"adjustmentFactor":4.214},{"status":"ACTIVE","sortPriority":7,"id":97008932,"adjustmentFactor":2.551},{"status":"ACTIVE","sortPriority":8,"id":98464183,"adjustmentFactor":2.308},{"status":"ACTIVE","sortPriority":9,"id":99072901,"adjustmentFactor":0.746},{"status":"ACTIVE","sortPriority":10,"id":99072897,"adjustmentFactor":0.692},{"status":"ACTIVE","sortPriority":11,"id":10445502,"adjustmentFactor":0.097}],"version":7431362689,"eventTypeId":"7","complete":true,"openDate":"2026-06-01T12:29:00Z","marketTime":"2026-06-01T12:29:00Z","bspReconciled":false},"rc":[{"tv":6866.27,"batb":[[0,4.1,70.21],[2,3.95,38.21],[1,4,58.1]],"trd":[[4.1,419.67],[4.2,281.05],[4,85.1],[4.3,11.42],[3.95,40.51],[3.9,64.81],[3.85,126.3],[3.8,182.65],[3.75,483.24],[3.7,429.97],[3.65,581.87],[3.6,921.92],[3.55,705.96],[3.4,123.05],[2.9,36.52],[2.92,23.66],[3.3,47.11],[2.84,23.84],[2.98,43.88],[2.72,48.24],[2.68,38.05],[2.96,42.05],[2.78,228.29],[2.66,83.08],[2.88,51.8],[3.45,505.74],[3.5,694.97],[3.35,58.23],[3.15,53.29],[2.8,7.93],[3.25,35.87],[3,36.29],[3.1,58.92],[2.86,58.77],[4.7,2],[4.6,2],[2.36,20.25],[2.32,16.05],[2.7,40.27],[3.2,41.63],[3.05,18],[2.74,21.78],[2.76,23.51],[2.38,2],[4.9,2.6],[2.24,9.08],[2.26,19.36],[2.28,3.88],[2.82,8.1],[2.94,1.71]],"ltp":4.1,"atb":[[3.5,6.46],[4.1,70.21],[2.82,319.15],[3.95,38.21],[4,58.1],[3.9,30.33],[3.6,43.68],[1.44,8136.14],[2.32,2812.92],[3.85,39.16],[3.55,4.88],[3.4,1.99],[3.8,40.33],[3.75,4.64],[1.17,2],[2,25.01],[3.65,11.3],[3.35,9.85],[3,4.35],[3.7,10.77],[2.6,8.86],[3.1,1.99],[3.15,1.99],[3.25,2.95],[3.45,1.99],[3.3,47.99],[1.03,2211.6],[1.21,25],[1.06,6301.68],[1.02,99.97],[1.01,43888.08],[2.88,72.29],[2.92,19.33],[3.05,1.99],[2.94,3.42],[3.2,4.09],[1.55,11.3],[2.74,3.13],[1.07,5],[1.15,2.5],[2.7,8.32],[2.64,1.99],[1.09,1],[2.72,1.99],[2.76,1.99],[2.78,1.99],[2.8,1.99],[1.11,1],[2.5,5],[2.66,1.99],[2.86,1.99],[2.9,1.99],[2.98,65.12],[2.36,93.9],[1.66,2.55],[1.42,157.14],[1.5,132],[1.46,215.22],[1.36,91.67],[1.4,82.5],[1.56,3.55],[1.05,100],[1.08,100],[2.84,1.99],[2.96,1.99],[2.54,1.99],[2.48,1.99],[2.4,1.99],[2.42,1.99],[2.56,1.99],[2.34,1.99],[2.3,1.99],[2.58,1.99],[2.46,1.99],[2.52,1.99],[2.2,1.99],[2.18,1.99],[2.28,1.99],[2.38,1.99],[2.24,1.99],[2.26,1.99],[2.44,1.99],[2.22,1.99],[1.51,45.1],[2.04,32.69],[1.1,50]],"atl":[[4.2,20.1],[1000,6.25],[7,3.99],[6.2,1.99],[4.5,30.11],[16,20],[5.5,3.99],[5,14.99],[4.3,20.73],[4.6,2.57],[4.4,7.84],[4.9,28.47],[4.8,24.17],[4.7,25.71],[6.4,1.99],[330,0.26],[6,11.99],[8.4,1.99],[7.8,2.99],[32,2.1],[8.6,1.99],[5.1,5.1],[5.9,1.99],[5.3,1.99],[5.2,39.81],[8.2,1.99],[5.7,4.9],[7.6,1.99],[7.4,1.99],[7.2,1.99],[970,0.23],[6.8,1.99],[60,0.01],[5.8,1.99],[8,10],[6.6,1.99],[5.6,1.99],[5.4,1.99],[19.5,1.86],[390,0.01],[990,1.71],[690,0.01],[40,1.88],[25,1.85],[160,2],[55,15],[34,13],[17,13],[250,10],[600,10],[480,0.02]],"batl":[[0,4.2,20.1],[1,4.3,20.73],[2,4.4,7.84]],"id":99072898},{"tv":487.73,"batb":[[1,40,7.31],[0,42,11.93],[2,38,12.53]],"trd":[[46,35.19],[42,57.84],[44,20.45],[48,31.68],[50,76.27],[40,62.98],[55,90.56],[60,21.14],[38,8.29],[36,16.29],[75,11.92],[70,16.13],[65,10.79],[80,5.25],[19,11.6],[85,1.64],[18.5,1.71],[23,0.46],[21,0.84],[20,0.52],[19.5,0.18],[2.36,2],[18,4]],"ltp":46,"atb":[[40,7.31],[42,11.93],[1.17,2],[38,12.53],[1.44,7960.56],[5.1,2576.54],[32,8.03],[18,5.77],[28,13.48],[27,1.99],[36,1.99],[1.11,39.06],[1.09,1],[1.07,5],[1.9,12.97],[1.06,5845.87],[1.1,50],[34,3.53],[26,36.61],[1.05,100],[1.02,68.97],[21,2.85],[1.03,2104.69],[1.01,44647.46],[29,9.7],[30,4.36],[14.5,1.99],[1.08,100],[8,7],[1.55,7.3],[19,3.55],[24,1.99],[1.15,2.5],[1.57,32.8],[2.4,16.3],[23,1.99],[17.5,1.99],[16,6.67],[20,1.99],[15,8.94],[5,0.01],[4,0.01],[2,26.01],[14,7.62],[16.5,1.99],[22,1.99],[25,1.99],[19.5,1.99],[18.5,1.99],[17,1.99],[12,6],[11,6.7],[9.6,3.84],[10,1.89],[15.5,2.07],[11.5,2.86],[1.51,45.1],[2.04,32.69],[6.2,6.54],[3.1,16.19]],"atl":[[46,3.9],[48,1.41],[1000,0.22],[65,5.64],[55,18.78],[60,1.99],[70,3.22],[50,11.58],[75,3.93],[80,3.58],[100,1.99],[95,1.99],[90,2.58],[85,1.99],[110,1],[180,0.23],[900,0.86],[330,0.26],[600,11.85],[680,1.86],[390,0.01],[480,0.02],[980,1.42],[690,0.01]],"batl":[[0,46,3.9],[1,48,1.41],[2,50,11.58]],"id":97008932},{"tv":876.34,"batb":[[0,24,16.16],[2,22,20.41],[1,23,11.47]],"trd":[[24,74.28],[25,119.24],[26,41.39],[27,9.64],[28,0.54],[23,21.82],[22,47.82],[20,53.73],[16,8.65],[14.5,21.8],[13,34.33],[21,92.12],[19.5,17.71],[19,31.87],[17,32.07],[18.5,8.18],[18,24.01],[17.5,10.22],[15.5,10.25],[15,15.6],[12,15.88],[11.5,45.61],[10.5,46.73],[10,11.1],[14,6],[16.5,2.72],[13.5,5.36],[12.5,8.76],[11,20.58],[9.4,13.58],[9.6,20.75],[8.4,1.32],[8.6,2.68]],"ltp":24,"atb":[[20,2.86],[24,16.16],[13.5,1.99],[13,10.42],[12.5,1.99],[22,20.41],[1.44,8079.05],[4.9,2611.23],[18,3.78],[9.8,1.99],[23,11.47],[1.17,2],[21,11.14],[12,1.99],[1.08,100],[18.5,1.99],[17,54.93],[1.06,6433.14],[19,10.86],[1.02,365.5],[1.03,2209.55],[1.01,43714.23],[17.5,16.59],[19.5,10.14],[16,1.99],[16.5,1.99],[1.05,2256.6],[1.07,5],[8.4,1.99],[10.5,1.99],[1.1,50],[1.55,7.3],[9.6,9],[1.15,2.5],[9.2,1.99],[8,1.99],[10,20.79],[9,1.99],[8.6,1.99],[2.1,21],[8.8,1.99],[9.4,2.99],[11.5,1.99],[11,2.99],[6.2,6.54],[3.65,12.45],[3.75,24],[3.95,33.56],[3.45,13.47],[5.9,2.55],[4.3,20],[6.8,1.99],[7.8,1.99],[7.6,1.99],[7.4,1.99],[8.2,1.99],[2,26],[7,10],[7.2,8],[1.51,45.1],[2.04,32.69],[3.1,16.19]],"atl":[[25,8.45],[1000,6.25],[48,1.85],[60,1.99],[26,3.05],[36,1.99],[75,1.99],[34,11.99],[32,7.49],[27,12.2],[29,8.24],[30,1.99],[28,3.42],[900,0.86],[330,0.26],[200,1],[210,1.86],[160,2],[40,3.04],[85,1.99],[80,3.87],[390,0.01],[70,1.99],[50,1.99],[46,1.99],[44,1.99],[65,1.99],[42,1.99],[38,1.99],[980,0.99],[690,0.01],[55,15],[250,10],[600,10],[480,0.02]],"batl":[[0,25,8.45],[1,26,3.05],[2,27,12.2]],"id":99072900},{"tv":330.49,"batb":[[2,80,1.73],[1,90,2.14],[0,95,5.62]],"trd":[[100,19.65],[85,30.1],[110,15.86],[90,23.27],[80,63.71],[75,12.19],[95,13.74],[120,27.15],[130,20],[150,14.62],[140,35.09],[160,25.72],[170,6.08],[180,3.91],[330,0.16],[44,0.58],[42,4.32],[40,1.1],[29,0.22],[28,1.78],[24,0.72],[23,3.88],[22,0.46],[21,2.22],[20,1.9],[19.5,2.06]],"ltp":100,"atb":[[85,0.68],[95,5.21],[90,2.14],[100,0.41],[1.44,8577.24],[5.1,2786.72],[18,7.66],[75,8.4],[80,1.05],[70,5],[60,15.12],[1.02,180.26],[50,20.55],[1.11,1],[1.01,44069.71],[1.06,6322.44],[1.03,2115.06],[1.17,1],[21,3.69],[1.1,50],[1.09,1],[22,1.99],[23,1.99],[27,1.99],[26,1.99],[25,1.99],[29,1.99],[28,1.99],[55,3.1],[48,1.99],[46,1.99],[44,1.99],[42,1.99],[38,1.99],[36,1.99],[34,1.99],[65,1.99],[32,1.99],[20,8.21],[1.55,7.3],[1.07,5],[1.15,2.5],[40,4],[15,2.37],[5,0.01],[4,0.01],[2,26.01],[30,3.55],[14,6.92],[1.05,9333.8],[18.5,7.14],[1.08,100],[17,2.06],[24,2.87],[16,2.27],[15.5,2.07],[10,1.89],[11,3.4],[11.5,2.86],[1.51,45.1],[2.04,32.69],[6.2,6.54],[3.1,16.19]],"atl":[[120,1.11],[1000,6.25],[140,2.66],[150,1.52],[180,3.87],[170,1.36],[130,1],[160,0.67],[280,0.05],[230,0.11],[220,0.05],[210,0.05],[200,0.05],[190,0.2],[590,0.34],[330,0.26],[380,0.14],[360,0.07],[680,1.85],[390,0.01],[480,0.02],[890,0.2],[690,0.01]],"batl":[[0,120,1.11],[2,140,2.66],[1,130,1]],"id":99072901},{"tv":6917.58,"batb":[[0,4.4,59.21],[2,4.2,84.92],[1,4.3,96.27]],"trd":[[4.4,590.32],[4.5,1417.62],[4.3,559.05],[4.2,339.64],[4.6,492.73],[4.7,552.94],[4.8,434.85],[4.9,353.31],[3.65,7.73],[4.1,83.33],[5.1,147.06],[3.05,84.78],[3.55,147.44],[2.98,81.71],[2.96,101.29],[5,162.12],[3.45,36.98],[3.75,65.07],[2.94,87.23],[3.5,129.64],[3.25,44.42],[3,96.58],[3.1,110.28],[3.6,129.91],[5.2,229.1],[5.3,55.72],[3.15,55.28],[3.8,23.17],[3.2,36.1],[4,91.33],[3.7,18.9],[3.95,19.68],[3.85,10.2],[3.9,16.68],[3.3,15.82],[5.4,22.18],[5.5,31.73],[5.6,7.18],[5.7,1.44],[3.35,21.06],[2.92,5.98]],"ltp":4.4,"atb":[[3.75,5.87],[4.4,59.21],[4.1,56.64],[3.85,37.26],[4.2,84.92],[4.3,96.27],[1.17,2],[3.5,72.32],[3.45,2],[4,8.9],[1.01,60025.51],[1.44,8193.22],[2.38,2685.52],[3.95,39.18],[3.4,4],[3.55,8.41],[3.65,3.99],[3.9,2.99],[3.25,2.88],[3.8,1.99],[2.76,3.99],[3.1,16.99],[3.35,281.65],[1.03,1856.46],[1.06,5936.69],[1.02,441.15],[3.7,42.3],[2.7,4],[1.55,7.3],[1.07,5],[1.15,2.5],[2,57],[1.05,798.6],[3.6,1.99],[3.3,10.88],[3,11],[3.15,1.99],[1.11,1],[3.2,1.99],[1.09,1],[1.95,34.74],[2.1,90],[2.18,55.93],[2.3,3.55],[2.5,8.05],[2.02,64.71],[1.99,33.33],[1.08,100],[3.05,1.99],[2.78,1.99],[2.96,1.99],[2.86,1.99],[2.9,1.99],[2.74,1.99],[2.92,1.99],[2.94,1.99],[2.84,1.99],[2.98,1.99],[2.8,1.99],[2.82,1.99],[2.04,32.69],[2.88,23],[2.72,11],[1.51,45.1],[1.1,50]],"atl":[[4.5,23.09],[4.7,270.6],[4.6,28.71],[1000,1.01],[5,23.19],[4.8,14.82],[8.2,1.99],[16.5,2.08],[32,1.85],[6.2,4.99],[5.8,2.76],[17,33],[6,27.5],[7,3.99],[5.1,6.8],[4.9,23.89],[5.2,2.11],[19,0.55],[5.7,1.99],[5.4,4.74],[330,0.26],[5.3,1.99],[5.5,1.99],[5.6,1.99],[6.6,4.5],[6.4,39.99],[7.8,1.99],[8,10],[11,1.99],[7.6,1.99],[5.9,1.99],[7.4,1.99],[7.2,1.99],[10.5,1.99],[980,1.12],[9.8,1.99],[10,1.99],[9.6,1.99],[6.8,5.1],[9.4,1.99],[9.2,1.99],[9,1.99],[8.4,1.99],[8.8,1.99],[8.6,1.99],[26,1.86],[390,0.01],[690,0.01],[46,1.88],[160,2],[34,13],[55,15],[48,1],[250,10],[600,10],[480,0.02]],"batl":[[0,4.5,23.09],[2,4.7,270.6],[1,4.6,28.71]],"id":10398159},{"tv":544.45,"batb":[[1,60,21.01],[2,55,15.68],[0,65,17.37]],"trd":[[70,3.67],[65,25.52],[60,19.43],[55,33.43],[50,29.29],[48,54.96],[46,54.21],[44,84.57],[42,29.53],[40,45.71],[38,52.27],[110,6.21],[90,5.36],[80,10.29],[32,12.78],[36,23.03],[34,29.96],[95,2.69],[120,4],[100,1.06],[85,0.5],[21,4.25],[26,1.04],[25,0.96],[19,2],[20,2.94],[19.5,2.43],[18,1.9],[22,0.46]],"ltp":70,"atb":[[60,21.01],[50,15.6],[7.2,0.85],[55,15.68],[46,1.99],[65,17.37],[48,4.22],[11,3.4],[44,1.99],[1.17,2],[1.44,8556.48],[5.1,2592.98],[18,3.78],[36,2.37],[26,5.55],[42,2.32],[40,2.2],[38,2.93],[34,5.86],[1.09,1],[1.1,50],[1.22,96],[5,9.52],[29,33.02],[1.07,5],[1.06,6389.03],[1.02,203.76],[21,2.86],[1.03,2396.2],[1.01,44428.64],[28,1.99],[27,1.99],[32,2.78],[30,8.43],[9,1],[24,1.99],[23,1.99],[22,1.99],[20,1.99],[19,1.99],[19.5,1.99],[18.5,1.99],[17,1.99],[17.5,1.99],[16,1.99],[16.5,1.99],[25,7.56],[1.55,7.3],[7,9],[1.15,2.5],[14,8.91],[15.5,4.06],[1.08,100],[15,8.93],[4,0.01],[2,26.01],[13.5,1.99],[1.51,45.1],[2.04,32.69],[6.2,6.54],[3.1,16.19],[5.9,13.47],[6.6,17.68],[5.7,7.02],[5.3,7.67],[11.5,2.55],[7.4,10.31],[8.6,3.55],[14.5,1.99],[1.05,100],[10,1.89]],"atl":[[70,9.17],[80,11.37],[90,1.99],[75,1.99],[120,2.99],[110,2.02],[100,1.99],[95,1.99],[85,1.99],[730,0.27],[900,0.86],[330,0.26],[970,0.23],[600,10],[540,1.86],[390,0.01],[840,1.88],[530,1.85],[340,0.2],[290,9],[960,1.38],[690,0.01],[480,0.02]],"batl":[[0,70,9.17],[2,80,11.37],[1,75,1.99]],"id":98464183},{"tv":1923.16,"batb":[[0,9.6,18.04],[1,9.4,17.72],[2,9.2,11.85]],"trd":[[9.8,194.5],[9.6,169.98],[9.2,77.72],[9.4,91.89],[10,463.74],[10.5,430.53],[11,191.6],[11.5,85.42],[15.5,37.99],[15,66.01],[14.5,37.37],[9,3.98],[13,25.07],[12,13.29],[8.4,2.38],[8.2,6],[8,0.36],[14,9.47],[16,4.66],[17,3.5],[17.5,1.14],[12.5,4.56],[36,1],[34,1]],"ltp":9.8,"atb":[[9.6,18.04],[8.4,19.49],[4,1],[8.2,19.1],[9,26.77],[1.44,8559.07],[3.15,2542.81],[7.6,120.41],[9.4,17.72],[8.8,6.78],[9.2,11.85],[8.6,2.99],[1.1,50],[1.01,62387.23],[1.6,5.5],[1.17,2],[7,6.52],[8,34.64],[6,6.8],[1.06,5704.9],[1.04,245.63],[1.02,99.97],[1.03,1999.17],[1.11,1],[1.05,100],[3,12],[7.4,41.05],[1.55,7.3],[7.8,1.99],[1.07,5],[1.15,2.5],[1.09,1],[1.08,100],[7.2,9.68],[6.8,1.99],[6.6,1.99],[6.4,1.99],[4.6,1.99],[4.5,1.99],[4.7,1.99],[5.4,1.99],[5.2,1.99],[4.9,5.54],[5.3,1.99],[5.5,1.99],[5,1.99],[5.1,1.99],[4.8,1.99],[5.9,4.54],[5.6,1.99],[5.7,1.99],[5.8,1.99],[6.2,1.99],[3.95,33.56],[4.3,20],[3.65,12.45],[3.75,24],[3.45,13.47],[2,26],[1.51,45.1],[2.04,32.69],[3.1,16.19]],"atl":[[9.8,9.89],[12,13.1],[1000,6.25],[11.5,4.9],[11,5.41],[95,20],[10,6.52],[10.5,10.82],[13,7.67],[12.5,21.71],[13.5,1.99],[32,2.24],[21,4.26],[330,0.26],[55,15],[14,1.99],[28,1.99],[14.5,1.99],[20,13.99],[22,4.99],[27,1.99],[26,1.99],[25,1.99],[24,2.22],[23,2.99],[19.5,1.99],[19,1.99],[18.5,1.99],[18,1.99],[17.5,1.99],[17,1.99],[16.5,1.99],[16,1.99],[15.5,1.99],[15,1.99],[34,13],[150,1.86],[390,0.01],[990,1.8],[690,0.01],[420,1.88],[260,1.85],[160,2],[250,10],[600,10],[480,0.02]],"batl":[[0,9.8,9.89],[1,10,6.52],[2,10.5,10.82]],"id":98117699},{"tv":10307.07,"batb":[[0,3.9,74.89],[2,3.8,126.79],[1,3.85,36.24]],"trd":[[3.95,1124.74],[3.9,1584.82],[4,1253.36],[3.85,1229.67],[3.8,454.87],[4.1,503.83],[4.6,250.05],[3.05,19.53],[8.4,30.05],[4.2,386.2],[5.7,66.46],[6.2,174.12],[9.8,16.88],[8.6,61.76],[4.5,324.23],[3.45,20.63],[6.4,37.06],[4.3,272.87],[4.7,417.29],[8.8,39.99],[2.9,10.34],[11.5,4.49],[5.3,37.72],[4.8,180.35],[3.7,33.64],[3.75,184.82],[4.4,126.21],[4.9,124.37],[3,84.58],[5,354.53],[8,6.11],[3.65,12.34],[3.25,6.62],[3.15,49.13],[3.2,50.63],[3.6,20.08],[3.5,0.58],[3.55,125.68],[3.4,3],[3.35,22.96],[3.1,65.73],[3.3,8],[2.96,4.2],[2.92,85.04],[2.84,10],[2.82,10.06],[2.78,2],[2.8,6.22],[2.58,1.96],[2.56,0.04],[2.94,0.01],[2.98,13.89],[7.8,17.6],[5.8,46.74],[6,44.59],[8.2,9.85],[5.1,62.64],[5.2,48.98],[5.9,75.04],[5.6,4.34],[6.6,23.21],[7,10.78],[7.2,12.98],[9.4,2.72],[7.4,10.02],[9,1.94],[10,4],[11,8.75],[10.5,4],[12.5,1.26],[12,3.89]],"ltp":3.95,"atb":[[3.35,90.74],[3.3,2.23],[3.9,74.89],[1.17,195.12],[3.7,23.47],[3.65,4.51],[3.85,36.24],[1.44,8079.92],[2.26,2563.57],[3.55,30.54],[3.1,2.94],[1.01,51980.82],[3.8,126.79],[3.75,34.73],[3,6.8],[3.15,3.99],[3.5,2.99],[3.05,297.07],[1.06,5275.04],[1.02,99.97],[1.03,2057.12],[1.09,1],[1.2,4.41],[1.11,1],[3.2,2.8],[3.45,1.99],[3.6,7],[1.85,4],[1.55,7.3],[1.07,5],[1.15,2.5],[2,27],[2.78,1.99],[2.92,22.11],[2.88,1.99],[2.82,1.99],[2.86,1.99],[2.94,1.99],[2.84,1.99],[2.9,1.99],[2.96,1.99],[3.4,1.99],[2.98,1.99],[3.25,2.26],[2.64,78.21],[2.06,117.92],[1.47,2.55],[1.31,212.9],[1.23,286.96],[1.21,157.14],[1.37,3.55],[1.27,366.67],[2.7,1.99],[2.56,1.99],[2.54,1.99],[2.68,1.99],[2.66,1.99],[2.46,1.99],[2.38,1.99],[2.52,1.99],[2.42,1.99],[2.74,1.99],[2.36,1.99],[2.4,1.99],[2.76,1.99],[2.48,1.99],[2.62,1.99],[2.58,1.99],[2.44,1.99],[2.6,1.99],[2.5,4.99],[2.72,1.99],[2.8,1.99],[1.05,100],[1.08,100],[1.6,20],[1.51,45.1],[2.04,32.69],[1.1,50]],"atl":[[3.95,13.47],[4,24.78],[1000,3],[4.1,65.61],[4.2,60.79],[4.7,15.81],[50,1.85],[15,20],[5,12.52],[4.3,15.89],[32,2.02],[4.8,5.99],[14.5,1.99],[4.4,34.04],[4.5,54.5],[4.6,24.22],[5.7,1.99],[9,16.35],[10,24.62],[6.4,10.79],[6,46.97],[330,0.26],[14,1.99],[13.5,2.09],[11,24.13],[7.6,4.06],[6.6,2.52],[5.5,6.52],[10.5,2.02],[9.4,1.99],[9.8,1.99],[11.5,1.99],[7,5.69],[8,19.5],[12.5,1.99],[13,1.99],[4.9,2.52],[5.3,1.99],[5.1,1.99],[5.2,4.86],[8.2,1.99],[970,1.12],[12,2.68],[7.4,7.52],[7.8,3.02],[9.6,1.99],[8.4,1.99],[5.9,1.99],[6.2,2.99],[7.2,1.99],[5.6,1.99],[5.4,40.6],[44,1.73],[5.8,1.99],[17,13],[29,1.86],[390,0.01],[6.8,1.99],[8.8,1.99],[8.6,1.99],[9.2,1.99],[690,0.01],[34,13],[80,1.88],[160,2],[55,15],[250,10],[600,10],[480,0.02]],"batl":[[1,4,24.78],[0,3.95,13.47],[2,4.1,65.61]],"id":88302242},{"tv":1721.17,"batb":[[0,12,30.65],[2,11,5.91],[1,11.5,21.48]],"trd":[[12.5,30.38],[12,5.79],[13,16.61],[13.5,163.26],[14,89.6],[14.5,195.67],[15,140.76],[15.5,140.18],[16,177.77],[16.5,175.87],[17,69.35],[17.5,111.1],[18,128.26],[18.5,120.92],[19,41.07],[19.5,8.08],[21,51.02],[22,13.96],[20,27.33],[23,10],[24,4.19]],"ltp":12.5,"atb":[[10.5,14.36],[12,30.65],[9.8,17.56],[1.44,7722.71],[3.45,2809.2],[11,5.91],[10,40.1],[11.5,21.48],[9.2,1.99],[1.17,2],[9,4.29],[1.09,1],[1.11,1],[1.03,2379.93],[1.02,99.97],[1.04,155.68],[1.06,6233.35],[1.01,45332.47],[1.1,50],[1.07,5],[8.4,20.1],[1.05,1090],[1.55,7.3],[1.08,100],[1.15,2.5],[8.2,5.85],[6.6,1.99],[7.8,1.99],[7,1.99],[7.6,1.99],[6.8,1.99],[7.4,1.99],[6.4,1.99],[7.2,1.99],[8,1.99],[8.8,1.99],[8.6,1.99],[9.4,1.99],[9.6,1.99],[2,26],[4.7,17.84],[4.1,10.65],[4.5,9.43],[5.5,14.67],[6.2,18.09],[5.1,24.15],[1.51,45.1],[2.04,32.69],[3.1,16.19]],"atl":[[13,24.5],[15.5,1.99],[13.5,5.75],[14,15.15],[14.5,4.86],[15,9.4],[38,2.53],[16,2.15],[180,20],[50,4.07],[16.5,2.79],[27,0.53],[17,3.29],[200,1.86],[18,3],[19,1.99],[17.5,1.99],[20,4.49],[18.5,1.99],[19.5,2.71],[26,1.99],[25,1.99],[24,3.19],[23,1.99],[22,1.99],[21,2.99],[900,0.86],[28,1],[330,2.11],[250,10],[160,2],[30,1.99],[48,1.99],[46,1.99],[42,1.99],[40,2.99],[36,1.99],[34,1.99],[32,7],[970,0.23],[75,1.99],[70,1.99],[60,1.99],[55,15.03],[990,2.22],[390,0.01],[690,0.01],[440,1.88],[480,1.02],[600,10]],"batl":[[0,13,24.5],[2,14,15.15],[1,13.5,5.75]],"id":97736949},{"tv":160.67,"batb":[[0,1000,107.04],[1,900,1],[2,730,1.85]],"trd":[[1000,116.19],[500,0.22],[480,0.26],[750,3.7],[740,0.08],[690,0.02],[520,0.2],[210,4],[220,4],[100,20.4],[65,5.72],[70,0.28],[55,1.62],[50,2.16],[120,1.6],[19.5,0.16],[19,0.06]],"ltp":1000,"atb":[[1.44,7649.2],[5.1,2569.62],[1000,107.04],[2,26.01],[310,1],[700,1.29],[1.06,6511.85],[1.02,167.57],[21,2.56],[1.03,1985.33],[1.01,44202.04],[110,7],[300,1],[180,2],[100,5],[290,9.08],[1.55,7.3],[1.07,5],[1.15,2.5],[15,0.01],[5,0.01],[4,0.01],[38,0.74],[22,5.95],[680,0.18],[1.05,100],[1.08,100],[16.5,2.13],[23,4.5],[19.5,3.57],[18.5,1.89],[27,2.54],[36,3.55],[65,2.55],[900,1],[730,1.85],[60,2],[95,9.07],[10,1.89],[16,2.27],[15.5,2.07],[11,3.4],[11.5,2.86],[1.51,45.1],[2.04,32.69],[6.2,6.54],[3.1,16.19],[1.1,50]],"id":10445502},{"tv":218.77,"batb":[[0,160,2.3],[2,140,1.73],[1,150,1.31]],"trd":[[170,19.95],[160,46.84],[190,29.46],[180,44.38],[220,1.47],[200,21.44],[210,4.6],[250,8.03],[260,0.77],[240,0.24],[230,0.1],[290,0.18],[280,0.48],[150,12.67],[140,7.74],[95,2.54],[110,0.38],[100,3.58],[120,0.88],[400,0.06],[390,0.02],[380,0.28],[360,0.3],[340,0.1],[350,0.19],[330,1.17],[320,0.1],[310,0.17],[300,0.2],[270,0.1],[50,2.37],[48,3.64],[36,0.34],[22,2.06],[21,0.3],[20,1.18],[23,0.46]],"ltp":160,"atb":[[95,2.19],[1.44,8427.61],[5.1,2688.12],[160,2.3],[18,3.78],[14.5,2.44],[130,0.2],[140,1.73],[150,1.31],[70,3.59],[2,26.01],[110,11.01],[1.03,2101.23],[1.06,5278.5],[1.02,233.92],[1.01,44211.55],[120,4.4],[32,1.99],[90,11.14],[30,3],[1.55,7.3],[1.17,1],[1.07,5],[1.15,2.5],[48,2.55],[60,1.99],[34,1.99],[85,1.99],[80,3.04],[75,2.8],[55,3.32],[46,1.99],[44,3.32],[42,1.99],[40,1.99],[38,1.99],[36,1.99],[50,7],[15,0.01],[100,2.07],[5,0.01],[4,0.01],[14,6.92],[19.5,12.11],[1.05,100],[1.08,100],[17.5,4],[16.5,2.13],[29,3.55],[23,3],[21,1.7],[65,5],[16,2.27],[10,1.89],[15.5,2.07],[27,0.32],[11.5,2.86],[11,3.4],[1.51,45.1],[2.04,32.69],[3.1,16.19],[6.2,6.54],[1.1,50]],"atl":[[180,0.32],[1000,8.75],[190,2.65],[210,1.77],[390,0.05],[370,0.11],[220,1.13],[230,1.09],[260,0.62],[380,0.06],[300,0.14],[330,0.41],[340,0.05],[690,0.01],[360,0.1],[320,0.09],[290,0.05],[310,0.05],[350,0.05],[400,2.62],[500,1],[480,0.02],[890,0.2]],"batl":[[0,190,2.97],[1,210,1.77],[2,220,1.13]],"id":99072897}],"img":true,"tv":30353.7}],"rt":639159128959306730,"dt":639159128959315155}
{"op":"mcm","id":2,"clk":"AA0ABAAO","pt":1780316096075,"mc":[{"id":"1.258742455","rc":[{"atl":[[4,21.66]],"batl":[[1,4,21.66]],"id":88302242}]}],"rt":639159128960828063,"dt":639159128960828427}
{"op":"mcm","id":2,"clk":"ABMACQAU","pt":1780316096176,"mc":[{"id":"1.258742455","rc":[{"atl":[[3.95,16.59]],"batl":[[0,3.95,16.59]],"id":88302242}]}],"rt":639159128961841978,"dt":639159128961842303}
{"op":"mcm","id":2,"clk":"ACEADQAf","pt":1780316096280,"mc":[{"id":"1.258742455","rc":[{"atl":[[80,4.58]],"batl":[],"id":97008932},{"batb":[[2,11.5,21.48],[1,12,30.65],[0,12.5,2]],"atb":[[12.5,2]],"id":97736949}]}],"rt":639159128962882872,"dt":639159128962883333}
{"op":"mcm","id":2,"clk":"ACUADgAl","pt":1780316096386,"mc":[{"id":"1.258742455","rc":[{"tv":1725.17,"batb":[[2,11,5.91],[1,11.5,21.48],[0,12,30.65]],"trd":[[12.5,34.38]],"atb":[[12.5,0]],"atl":[[12.5,5]],"batl":[[2,13.5,5.75],[1,13,24.5],[0,12.5,5]],"id":97736949}],"tv":30357.7}],"rt":639159128963940275,"dt":639159128963940793}
{"op":"mcm","id":2,"clk":"ACwADwAq","pt":1780316096484,"mc":[{"id":"1.258742455","rc":[{"batb":[[0,4.4,49.21]],"atb":[[4.4,49.21]],"id":10398159},{"batb":[[0,3.9,60.95]],"atb":[[3.9,60.95]],"id":88302242},{"batb":[[0,12,27.84]],"atb":[[12,27.84],[10.5,15.96]],"id":97736949}]}],"rt":639159128964928513,"dt":639159128964928990}
{"op":"mcm","id":2,"clk":"ADIAEQA4","pt":1780316096587,"mc":[{"id":"1.258742455","rc":[{"tv":6876.01,"trd":[[4.2,290.79]],"ltp":4.2,"atl":[[4.2,15.23]],"batl":[[0,4.2,15.23]],"id":99072898},{"tv":6926.7,"trd":[[4.5,1426.74]],"ltp":4.5,"atl":[[4.5,18.53],[16.5,0]],"batl":[[0,4.5,18.53]],"id":10398159},{"atl":[[4,19.69]],"batl":[[1,4,19.69]],"id":88302242}],"tv":30376.56}],"rt":639159128965956030,"dt":639159128965956599}
{"op":"mcm","id":2,"clk":"ADkAEQA8","pt":1780316096688,"mc":[{"id":"1.258742455","rc":[{"atl":[[4.2,17.98]],"batl":[[0,4.2,17.98]],"id":99072898},{"tv":878.12,"trd":[[25,121.02]],"ltp":25,"atl":[[25,7.56]],"batl":[[0,25,7.56]],"id":99072900},{"atl":[[4.5,21.87]],"batl":[[0,4.5,21.87]],"id":10398159},{"atl":[[4,23.24]],"batl":[[1,4,23.24]],"id":88302242},{"batb":[],"atb":[[10.5,14.77]],"id":97736949}],"tv":30378.34}],"rt":639159128966967482,"dt":639159128966968070}
{"op":"mcm","id":2,"clk":"AD8AGABI","pt":1780316096746,"mc":[{"id":"1.258742455","rc":[{"atl":[[4.5,6.44]],"batl":[[0,4.5,6.44]],"id":10398159}]}],"rt":639159128967548508,"dt":639159128967548907}
{"op":"mcm","id":2,"clk":"AEQAGwBO","pt":1780316096843,"mc":[{"id":"1.258742455","rc":[{"batb":[[0,4.4,59.21]],"atb":[[4.4,59.21]],"id":10398159}]}],"rt":639159128968508869,"dt":639159128968509290}
{"op":"mcm","id":2,"clk":"AEYAIQBa","pt":1780316096946,"mc":[{"id":"1.258742455","rc":[{"atl":[[1000,0.61]],"id":97736949}]}],"rt":639159128969541472,"dt":639159128969541893}
{"op":"mcm","id":2,"clk":"AE0AJwBm","pt":1780316097052,"mc":[{"id":"1.258742455","rc":[{"atl":[[1000,0]],"id":97736949}]}],"rt":639159128970605529,"dt":639159128970605958}
{"op":"mcm","id":2,"clk":"AFAALQBw","pt":1780316097153,"mc":[{"id":"1.258742455","rc":[{"atl":[[12.5,5.61]],"batl":[[0,12.5,5.61]],"id":97736949}]}],"rt":639159128971617701,"dt":639159128971618093}
{"op":"mcm","id":2,"clk":"AFkANQCHAQ==","pt":1780316097358,"mc":[{"id":"1.258742455","rc":[{"batb":[],"atb":[[10.5,14.35]],"id":97736949}]}],"rt":639159128973664112,"dt":639159128973664565}
{"op":"mcm","id":2,"clk":"AMEBAHMAiQI=","pt":1780316099056,"mc":[{"id":"1.258742455","rc":[{"atl":[[25,3.93]],"batl":[[0,25,3.93]],"id":99072900},{"tv":10308.97,"batb":[[0,3.9,60]],"trd":[[3.9,1586.72]],"ltp":3.9,"atb":[[3.9,60]],"id":88302242}],"tv":30380.24}],"rt":639159128990641422,"dt":639159128990641944}
{"op":"mcm","id":2,"clk":"AOMBAIYBALwC","pt":1780316099674,"mc":[{"id":"1.258742455","rc":[{"tv":553.09,"batb":[[0,65,13.05]],"trd":[[65,34.16]],"ltp":65,"atb":[[65,13.05]],"id":98464183}],"tv":30388.88}],"rt":639159128996826526,"dt":639159128996826954}
{"op":"mcm","id":2,"clk":"AOgBAIgBAMcC","pt":1780316099775,"mc":[{"id":"1.258742455","rc":[{"batb":[[0,65,10.32]],"atb":[[65,10.32]],"id":98464183},{"atl":[[9.8,11.66]],"batl":[[0,9.8,11.66]],"id":98117699}]}],"rt":639159128997835818,"dt":639159128997836322}
{"op":"mcm","id":2,"clk":"AJ8CAKsBAKcD","pt":1780316100756,"mc":[{"id":"1.258742455","rc":[{"batb":[],"atb":[[3.7,32.44]],"id":88302242}]}],"rt":639159129007663493,"dt":639159129007663833}
{"op":"mcm","id":2,"clk":"AKUCAK0BALED","pt":1780316100867,"mc":[{"id":"1.258742455","rc":[{"atl":[[44,0.41]],"batl":[[0,46,4.31]],"id":97008932},{"tv":879.79,"batb":[[0,24,15.33]],"trd":[[24,75.95]],"ltp":24,"atb":[[24,15.33]],"id":99072900},{"atl":[[110,0.09]],"batl":[[0,120,1.2]],"id":99072901},{"tv":6931.54,"trd":[[4.5,1431.58]],"atl":[[4.5,4.02]],"batl":[[0,4.5,4.02]],"id":10398159},{"tv":554.01,"batb":[[0,65,9.86]],"trd":[[65,35.08]],"atb":[[65,9.86]],"id":98464183},{"tv":1927.34,"batb":[[0,9.6,15.95]],"trd":[[9.6,174.16]],"ltp":9.6,"atb":[[9.6,15.95]],"id":98117699},{"tv":10323.27,"batb":[[0,3.9,52.85]],"trd":[[3.9,1601.02]],"atb":[[3.9,52.85]],"atl":[[4,13.25]],"batl":[[1,4,13.25]],"id":88302242},{"tv":1726.77,"batb":[[0,12,27.04]],"trd":[[12,7.39]],"ltp":12,"atb":[[12,27.04]],"id":97736949}],"tv":30416.39}],"rt":639159129008760162,"dt":639159129008760949}
{"op":"mcm","id":2,"clk":"ALICALABAMMD","pt":1780316101067,"mc":[{"id":"1.258742455","rc":[{"atl":[[46,3.43]],"batl":[[0,46,3.84]],"id":97008932},{"batb":[[0,24,14.93]],"atb":[[24,14.93]],"id":99072900},{"atl":[[4.5,0.68]],"batl":[[2,4.8,14.82],[1,4.7,270.6],[0,4.6,29.39]],"id":10398159},{"batb":[[0,9.6,14.95]],"atb":[[9.6,14.95]],"atl":[[9.8,9.89]],"batl":[[0,9.8,9.89]],"id":98117699}]}],"rt":639159129010757158,"dt":639159129010757737}
{"op":"mcm","id":2,"clk":"AL0CALQBANoD","pt":1780316101281,"mc":[{"id":"1.258742455","rc":[{"tv":6898.35,"trd":[[4.2,313.13]],"atl":[[4.2,6.81]],"batl":[[0,4.2,6.81]],"id":99072898},{"atl":[[25,3.71]],"batl":[[0,25,3.71]],"id":99072900},{"tv":6944.25,"batb":[[0,4.4,52.85]],"trd":[[4.4,603.03]],"ltp":4.4,"atb":[[4.4,52.85]],"id":10398159},{"tv":10346.73,"trd":[[3.95,1148.2]],"ltp":3.95,"atb":[[1.17,196.08]],"atl":[[3.95,4.86]],"batl":[[0,3.95,4.86]],"id":88302242},{"tv":1732.09,"trd":[[12.5,39.7]],"ltp":12.5,"atb":[[1.17,2.2]],"atl":[[12.5,2.95]],"batl":[[0,12.5,2.95]],"id":97736949}],"tv":30480.22}],"rt":639159129012897925,"dt":639159129012898486}
{"op":"mcm","id":2,"clk":"AMMCALgBAOMD","pt":1780316101377,"mc":[{"id":"1.258742455","rc":[{"atl":[[4.5,15.91]],"batl":[[2,4.7,270.6],[1,4.6,28.71],[0,4.5,15.91]],"id":10398159},{"atb":[[1.17,195.12]],"id":88302242},{"atb":[[1.17,2]],"id":97736949}]}],"rt":639159129013855061,"dt":639159129013855742}
{"op":"mcm","id":2,"clk":"AMkCALwBAO4D","pt":1780316101485,"mc":[{"id":"1.258742455","rc":[{"tv":490.53,"trd":[[46,37.17],[44,21.27]],"atl":[[46,2.44],[44,0]],"batl":[[0,46,2.44]],"id":97008932},{"batb":[],"atb":[[4.1,32.07]],"id":10398159},{"tv":10347.69,"batb":[[0,3.9,68.29]],"trd":[[3.95,1149.16]],"atb":[[3.9,68.29]],"atl":[[3.95,4.38]],"batl":[[0,3.95,4.38]],"id":88302242},{"tv":1732.29,"batb":[[0,12,27.14]],"trd":[[12.5,39.9]],"atb":[[12,27.14]],"atl":[[12.5,2.85]],"batl":[[0,12.5,2.85]],"id":97736949}],"tv":30484.18}],"rt":639159129014927609,"dt":639159129014928353}
{"op":"mcm","id":2,"clk":"AN0CAMgBAJEE","pt":1780316101797,"mc":[{"id":"1.258742455","rc":[{"tv":10347.71,"trd":[[3.95,1149.18]],"atl":[[3.95,4.37]],"batl":[[0,3.95,4.37]],"id":88302242}],"tv":30484.2}],"rt":639159129018051236,"dt":639159129018051609}
{"op":"mcm","id":2,"clk":"AOgCANMBAKEE","pt":1780316101992,"mc":[{"id":"1.258742455","rc":[{"tv":6911.97,"batb":[[2,4,58.1],[1,4.1,70.21],[0,4.2,20.19]],"trd":[[4.2,326.75]],"atb":[[4.2,20.19]],"atl":[[4.2,0]],"batl":[[2,4.5,30.11],[1,4.4,7.84],[0,4.3,20.73]],"id":99072898}],"tv":30497.82}],"rt":639159129020006083,"dt":639159129020006580}
{"op":"mcm","id":2,"clk":"AO4CANcBAKsE","pt":1780316102050,"mc":[{"id":"1.258742455","rc":[{"batb":[[1,4.1,78.45],[0,4.2,33.77]],"atb":[[4.2,33.77],[4.1,78.45]],"id":99072898},{"atl":[[4.5,18.76]],"batl":[[0,4.5,18.76]],"id":10398159},{"atl":[[9.8,11.66]],"batl":[[0,9.8,11.66]],"id":98117699},{"batb":[[2,120,4.6]],"atb":[[140,0]],"id":99072897}]}],"rt":639159129020583747,"dt":639159129020584266}
{"op":"mcm","id":2,"clk":"APMCANwBALQE","pt":1780316102152,"mc":[{"id":"1.258742455","rc":[{"tv":6922.97,"batb":[[0,4.2,28.27]],"trd":[[4.2,337.75]],"atb":[[4.2,28.27]],"id":99072898},{"batb":[[0,42,10.2]],"atb":[[42,10.2]],"id":97008932},{"atb":[[11,5.49]],"id":99072900},{"batb":[[0,4.4,42.85]],"atb":[[4.4,42.85]],"id":10398159},{"batb":[[0,9.6,12.02]],"atb":[[9.6,12.02]],"id":98117699},{"batb":[[0,3.9,45.76]],"atb":[[3.9,45.76]],"id":88302242},{"batb":[[0,12,22.19]],"atb":[[12,22.19]],"id":97736949}],"tv":30508.82}],"rt":639159129021604713,"dt":639159129021605370}
{"op":"mcm","id":2,"clk":"APsCAOUBAL4E","pt":1780316102256,"mc":[{"id":"1.258742455","rc":[{"batb":[],"atb":[[3.9,21.91]],"atl":[[4.5,24.22]],"batl":[[2,4.5,24.22]],"id":99072898},{"tv":491.73,"batb":[[0,42,9.6]],"trd":[[42,59.04]],"ltp":42,"atb":[[42,9.6]],"id":97008932},{"batb":[[0,4.4,35.08]],"atb":[[4.4,35.08]],"id":10398159},{"atl":[[70,9.52]],"batl":[[0,70,9.52]],"id":98464183}],"tv":30510.02}],"rt":639159129022647242,"dt":639159129022647815}
{"op":"mcm","id":2,"clk":"AIMDAOgBAMgE","pt":1780316102357,"mc":[{"id":"1.258742455","rc":[{"batb":[[0,4.2,39.27]],"atb":[[4.2,39.27]],"id":99072898}]}],"rt":639159129023662309,"dt":639159129023662817}
{"op":"mcm","id":2,"clk":"AI4DAOwBAM8E","pt":1780316102462,"mc":[{"id":"1.258742455","rc":[{"batb":[],"atb":[[3.85,28.34]],"id":99072898},{"tv":554.11,"batb":[[0,65,9.81]],"trd":[[65,35.18]],"atb":[[65,9.81]],"id":98464183},{"tv":1951.38,"batb":[[2,9,26.77],[1,9.2,11.85],[0,9.4,17.72]],"trd":[[9.6,198.2]],"atb":[[9.6,0]],"atl":[[9.6,3.91]],"batl":[[2,10,6.52],[1,9.8,11.66],[0,9.6,3.91]],"id":98117699}],"tv":30534.16}],"rt":639159129024697198,"dt":639159129024697675}
{"op":"mcm","id":2,"clk":"AJQDAO4BANYE","pt":1780316102562,"mc":[{"id":"1.258742455","rc":[{"batb":[[0,4.2,47.46]],"atb":[[4.2,47.46]],"id":99072898},{"batb":[[0,4.4,42.89]],"atb":[[4.4,42.89]],"id":10398159},{"batb":[[0,9.4,7.37]],"atb":[[9.4,7.37]],"id":98117699}]}],"rt":639159129025704859,"dt":639159129025705365}
{"op":"mcm","id":2,"clk":"AJkDAPMBAN8E","pt":1780316102666,"mc":[{"id":"1.258742455","rc":[{"atl":[[4.5,22.81]],"batl":[[0,4.5,22.81]],"id":10398159},{"atb":[[1.17,2.31]],"atl":[[9.8,7.62],[9.6,13.28]],"batl":[[1,9.8,7.62],[0,9.6,13.28]],"id":98117699}]}],"rt":639159129026745592,"dt":639159129026745992}
{"op":"mcm","id":2,"clk":"AKADAPcBAOcE","pt":1780316102768,"mc":[{"id":"1.258742455","rc":[{"batb":[[2,8.8,6.78],[1,9,26.77],[0,9.2,16.16]],"atb":[[9.4,0],[1.17,2],[9.2,16.16]],"id":98117699},{"batb":[[0,12,22.63]],"atb":[[12,22.63]],"id":97736949}]}],"rt":639159129027760890,"dt":639159129027761667}
{"op":"mcm","id":2,"clk":"AKgDAPwBAPIE","pt":1780316102873,"mc":[{"id":"1.258742455","rc":[{"batb":[[2,4,56.13],[1,4.1,78.53]],"atb":[[1.17,2.98],[4.1,78.53],[4,56.13]],"id":99072898},{"batb":[[0,42,11.33]],"atb":[[42,11.33]],"id":97008932},{"batb":[[1,23,10.97],[0,24,14.54]],"atb":[[24,14.54],[23,10.97]],"atl":[[25,1.64]],"batl":[[0,25,1.64]],"id":99072900},{"batb":[[0,4.4,41.32]],"atb":[[4.4,41.32]],"atl":[[4.6,28.38],[4.8,34.79]],"batl":[[1,4.6,28.38]],"id":10398159},{"batb":[[0,65,10.22]],"atb":[[65,10.22]],"id":98464183},{"tv":1952,"batb":[[1,9,30.48],[0,9.2,13.25]],"trd":[[9.6,198.82]],"atb":[[9.2,13.25],[9,30.48]],"atl":[[9.4,4.13],[1000,7.7],[9.8,6.91],[10,5.48],[9.6,14.89]],"batl":[[2,9.8,6.91],[1,9.6,14.89],[0,9.4,4.13]],"id":98117699},{"atl":[[3.95,4.23]],"batl":[[0,3.95,4.23]],"id":88302242},{"batb":[[0,12,23.82]],"atb":[[12,23.82]],"id":97736949}],"tv":30534.78}],"rt":639159129028809323,"dt":639159129028810134}
{"op":"mcm","id":2,"clk":"AKwDAIACAPwE","pt":1780316102973,"mc":[{"id":"1.258742455","rc":[{"atb":[[1.17,2]],"id":99072898},{"tv":1954,"batb":[[0,9.2,12.25]],"trd":[[9.4,93.89]],"ltp":9.4,"atb":[[9.2,12.25]],"atl":[[9.4,3.13],[1000,6.25]],"batl":[[0,9.4,3.13]],"id":98117699},{"batb":[[0,3.9,54.58]],"atb":[[3.9,54.58]],"id":88302242},{"tv":1732.38,"trd":[[12.5,39.99]],"atl":[[12.5,2.8]],"batl":[[0,12.5,2.8]],"id":97736949}],"tv":30536.87}],"rt":639159129029810639,"dt":639159129029811256}
{"op":"mcm","id":2,"clk":"ALMDAIICAIMF","pt":1780316103074,"mc":[{"id":"1.258742455","rc":[{"batb":[[0,4.2,48.44]],"atb":[[4.2,48.44]],"id":99072898},{"atl":[[9.4,12.7],[9.8,7.74],[9.6,15.51]],"batl":[[2,9.8,7.74],[1,9.6,15.51],[0,9.4,12.7]],"id":98117699}]}],"rt":639159129030828005,"dt":639159129030828516}
{"op":"mcm","id":2,"clk":"ALwDAIUCAIsF","pt":1780316103181,"mc":[{"id":"1.258742455","rc":[{"batb":[[0,9.2,7.25]],"atb":[[8.4,3.59],[9.2,7.25]],"atl":[[9.6,6.14]],"batl":[[1,9.6,6.14]],"id":98117699},{"batb":[[0,3.9,69.54]],"atb":[[3.9,69.54]],"atl":[[3.95,3.12]],"batl":[[0,3.95,3.12]],"id":88302242}]}],"rt":639159129031891039,"dt":639159129031891489}
{"op":"mcm","id":2,"clk":"AMMDAIgCAJMF","pt":1780316103281,"mc":[{"id":"1.258742455","rc":[{"tv":6945.1,"batb":[[0,4.4,40.9]],"trd":[[4.4,603.88]],"atb":[[4.4,40.9]],"id":10398159},{"atl":[[9.4,14.64]],"batl":[[0,9.4,14.64]],"id":98117699}],"tv":30537.72}],"rt":639159129032897520,"dt":639159129032897922}
{"op":"mcm","id":2,"clk":"AMsDAIsCAJgF","pt":1780316103384,"mc":[{"id":"1.258742455","rc":[{"batb":[[2,4,62.35]],"atb":[[4,62.35]],"id":99072898}]}],"rt":639159129033928087,"dt":639159129033928445}
{"op":"mcm","id":2,"clk":"AN4DAJMCAKwF","pt":1780316103591,"mc":[{"id":"1.258742455","rc":[{"batb":[[0,4.2,148.44]],"atb":[[4.2,148.44]],"id":99072898}]}],"rt":639159129035988063,"dt":639159129035988477}
{"op":"mcm","id":2,"clk":"AOwDAJgCAMMF","pt":1780316103793,"mc":[{"id":"1.258742455","rc":[{"atl":[[4.3,15.19],[4.5,6.99]],"batl":[[2,4.5,6.99],[0,4.3,15.19]],"id":99072898},{"batb":[[0,9.2,2.94]],"atb":[[9.2,2.94]],"id":98117699},{"tv":1732.61,"trd":[[12.5,40.22]],"atl":[[12.5,2.69]],"batl":[[0,12.5,2.69]],"id":97736949}],"tv":30537.95}],"rt":639159129038009845,"dt":639159129038010335}
{"op":"mcm","id":2,"clk":"AIsEAKoCAPcF","pt":1780316104255,"mc":[{"id":"1.258742455","rc":[{"atl":[[13,1.99]],"batl":[],"id":98117699}]}],"rt":639159129042629011,"dt":639159129042629380}
{"op":"mcm","id":2,"clk":"AI8EALECAP4F","pt":1780316104361,"mc":[{"id":"1.258742455","rc":[{"atl":[[12.5,28.97]],"batl":[],"id":98117699}]}],"rt":639159129043692186,"dt":639159129043692593}
{"op":"mcm","id":2,"clk":"AJwEALICAI0G","pt":1780316104463,"mc":[{"id":"1.258742455","rc":[{"batb":[[2,4.2,22.42]],"atb":[[4.2,22.42]],"id":10398159}]}],"rt":639159129044713505,"dt":639159129044713922}
{"op":"mcm","id":2,"clk":"AKwEALoCAKcG","pt":1780316104666,"mc":[{"id":"1.258742455","rc":[{"tv":1958,"batb":[[2,8.6,2.99],[1,8.8,6.78],[0,9,31.42]],"trd":[[9.2,81.72]],"ltp":9.2,"atb":[[9.2,0.94]],"id":98117699}],"tv":30541.95}],"rt":639159129046743899,"dt":639159129046744316}
{"op":"mcm","id":2,"clk":"ALUEALwCALgG","pt":1780316104772,"mc":[{"id":"1.258742455","rc":[{"batb":[[2,4,56.13]],"atb":[[4,56.13]],"id":99072898},{"tv":1959.88,"batb":[[0,9,30.48]],"trd":[[9.2,83.6]],"atb":[[9.2,0]],"atl":[[10.5,7.44],[9.2,3.21]],"batl":[[2,9.6,6.14],[1,9.4,14.64],[0,9.2,3.21]],"id":98117699}],"tv":30543.83}],"rt":639159129047804739,"dt":639159129047805231}
{"op":"mcm","id":2,"clk":"ALgEAL0CAMUG","pt":1780316104871,"mc":[{"id":"1.258742455","rc":[{"batb":[[2,8.6,8.95],[1,8.8,17.08],[0,9,26.77]],"atb":[[8.8,17.08],[9,26.77],[8.6,8.95]],"atl":[[9.2,4.33]],"batl":[[0,9.2,4.33]],"id":98117699},{"batb":[[0,12,28.78]],"atb":[[12,28.78]],"id":97736949}]}],"rt":639159129048792257,"dt":639159129048792801}
{"op":"mcm","id":2,"clk":"AMAEAL8CANAG","pt":1780316104979,"mc":[{"id":"1.258742455","rc":[{"atl":[[9.4,5.08],[9.2,12.79]],"batl":[[1,9.4,5.08],[0,9.2,12.79]],"id":98117699}]}],"rt":639159129049873707,"dt":639159129049874073}
{"op":"mcm","id":2,"clk":"AMcEAMACAOEG","pt":1780316105081,"mc":[{"id":"1.258742455","rc":[{"atl":[[9.2,14.75]],"batl":[[0,9.2,14.75]],"id":98117699}]}],"rt":639159129050895925,"dt":639159129050896317}
{"op":"mcm","id":2,"clk":"AM8EAMUCAO8G","pt":1780316105188,"mc":[{"id":"1.258742455","rc":[{"batb":[[0,9,25.77]],"atb":[[8.2,2.99],[9,25.77]],"id":98117699}]}],"rt":639159129051961556,"dt":639159129051961933}
{"op":"mcm","id":2,"clk":"AN8EAM8CAI0H","pt":1780316105388,"mc":[{"id":"1.258742455","rc":[{"atl":[[4.8,24.79]],"batl":[],"id":10398159}]}],"rt":639159129053959340,"dt":639159129053959727}
{"op":"mcm","id":2,"clk":"AOQEANICAJYH","pt":1780316105489,"mc":[{"id":"1.258742455","rc":[{"batb":[[1,4.1,79.53]],"atb":[[4.1,79.53]],"id":99072898}]}],"rt":639159129054975137,"dt":639159129054975496}
{"op":"mcm","id":2,"clk":"AP0EANkCALcH","pt":1780316105804,"mc":[{"id":"1.258742455","rc":[{"tv":10349.71,"batb":[[0,3.9,68.54]],"trd":[[3.9,1603.02]],"ltp":3.9,"atb":[[3.9,68.54]],"id":88302242}],"tv":30545.83}],"rt":639159129058118250,"dt":639159129058118646}
{"op":"mcm","id":2,"clk":"AIEFANoCAMQH","pt":1780316105901,"mc":[{"id":"1.258742455","rc":[{"atl":[[4.3,21.7]],"batl":[[0,4.3,21.7]],"id":99072898},{"tv":1965.04,"trd":[[9.2,88.76]],"atl":[[9.2,12.17]],"batl":[[0,9.2,12.17]],"id":98117699}],"tv":30550.99}],"rt":639159129059094299,"dt":639159129059094707}
{"op":"mcm","id":2,"clk":"AJEFAN4CANkH","pt":1780316106058,"mc":[{"id":"1.258742455","rc":[{"batb":[[1,8.8,21.84]],"atb":[[8.8,21.84]],"id":98117699}]}],"rt":639159129060674981,"dt":639159129060675443}
{"op":"mcm","id":2,"clk":"ALUFAO4CAJQI","pt":1780316106576,"mc":[{"id":"1.258742455","rc":[{"batb":[[1,8.8,17.08]],"atb":[[8.8,17.08]],"id":98117699}]}],"rt":639159129065838716,"dt":639159129065839182}
{"op":"mcm","id":2,"clk":"ANIFAPYCAL0I","pt":1780316106992,"mc":[{"id":"1.258742455","rc":[{"atl":[[25,5.41]],"batl":[[0,25,5.41]],"id":99072900}]}],"rt":639159129070000224,"dt":639159129070000597}
{"op":"mcm","id":2,"clk":"AOoFAP8CANoI","pt":1780316107299,"mc":[{"id":"1.258742455","rc":[{"atl":[[4.9,1.99],[5,68.43]],"batl":[],"id":99072898},{"atl":[[12.5,9.25],[11.5,15.43]],"batl":[],"id":98117699}]}],"rt":639159129073076784,"dt":639159129073077212}
{"op":"mcm","id":2,"clk":"AI8GAI4DAIUJ","pt":1780316107762,"mc":[{"id":"1.258742455","rc":[{"tv":6927.72,"trd":[[4.3,16.17]],"ltp":4.3,"atl":[[4.3,19.32]],"batl":[[0,4.3,19.32]],"id":99072898},{"batb":[[0,4.4,43.24]],"atb":[[4.4,43.24]],"id":10398159}],"tv":30555.74}],"rt":639159129077699783,"dt":639159129077700187}
{"op":"mcm","id":2,"clk":"AJoGAJEDAIoJ","pt":1780316107863,"mc":[{"id":"1.258742455","rc":[{"tv":6930.15,"trd":[[4.3,18.6]],"atl":[[4.3,18.11]],"batl":[[0,4.3,18.11]],"id":99072898},{"atb":[[1.04,0.86]],"id":99072900},{"tv":556.11,"batb":[[0,65,9.22]],"trd":[[65,37.18]],"atb":[[65,9.22]],"id":98464183}],"tv":30560.17}],"rt":639159129078708809,"dt":639159129078709354}
{"op":"mcm","id":2,"clk":"AKsGAJkDAKMJ","pt":1780316108170,"mc":[{"id":"1.258742455","rc":[{"batb":[],"atb":[[3.95,33.21]],"id":99072898},{"atb":[[1.04,0.44]],"id":99072900},{"tv":1969.04,"trd":[[9.2,92.76]],"atl":[[9.2,10.17]],"batl":[[0,9.2,10.17]],"id":98117699}],"tv":30564.17}],"rt":639159129081781873,"dt":639159129081782389}
{"op":"mcm","id":2,"clk":"ALEGAJ4DAKwJ","pt":1780316108276,"mc":[{"id":"1.258742455","rc":[{"batb":[[0,4.2,153.44]],"atb":[[4.2,153.44]],"id":99072898}]}],"rt":639159129082849801,"dt":639159129082850161}
{"op":"mcm","id":2,"clk":"ALIGAKIDALMJ","pt":1780316108376,"mc":[{"id":"1.258742455","rc":[{"atb":[[1.04,0]],"id":99072900}]}],"rt":639159129083840608,"dt":639159129083841243}
{"op":"mcm","id":2,"clk":"ALQGAKYDAL4J","pt":1780316108478,"mc":[{"id":"1.258742455","rc":[{"tv":880.67,"trd":[[25,121.9]],"ltp":25,"atl":[[25,4.97]],"batl":[[0,25,4.97]],"id":99072900}],"tv":30565.05}],"rt":639159129084865362,"dt":639159129084865831}
{"op":"mcm","id":2,"clk":"AMkGAKoDAM8J","pt":1780316108687,"mc":[{"id":"1.258742455","rc":[{"tv":10351.67,"trd":[[3.95,1151.14]],"ltp":3.95,"atl":[[3.95,2.14]],"batl":[[0,3.95,2.14]],"id":88302242}],"tv":30567.01}],"rt":639159129086955566,"dt":639159129086956009}
{"op":"mcm","id":2,"clk":"ANwGAK8DAOQJ","pt":1780316108888,"mc":[{"id":"1.258742455","rc":[{"atb":[[3,10]],"id":10445502}]}],"rt":639159129088959672,"dt":639159129088960002}
{"op":"mcm","id":2,"clk":"AOUGALYDAPUJ","pt":1780316109094,"mc":[{"id":"1.258742455","rc":[{"atb":[[1.17,2.28]],"id":99072900},{"atl":[[1000,7.01],[9.8,6.91],[9.6,5.52]],"batl":[[2,9.6,5.52]],"id":98117699},{"atl":[[1000,3.21]],"id":88302242}]}],"rt":639159129091024960,"dt":639159129091025383}
{"op":"mcm","id":2,"clk":"AOkGALoDAIAK","pt":1780316109198,"mc":[{"id":"1.258742455","rc":[{"atb":[[1.17,2]],"id":99072900},{"atl":[[1000,3]],"id":88302242}]}],"rt":639159129092059790,"dt":639159129092060136}
{"op":"mcm","id":2,"clk":"AP0GAL0DAIgK","pt":1780316109299,"mc":[{"id":"1.258742455","rc":[{"batb":[[0,24,14.82]],"atb":[[24,14.82]],"id":99072900},{"atl":[[1000,6.25]],"id":98117699},{"atl":[[3.95,2.35]],"batl":[[0,3.95,2.35]],"id":88302242}]}],"rt":639159129093070716,"dt":639159129093071157}
{"op":"mcm","id":2,"clk":"AIUHAL8DAJAK","pt":1780316109355,"mc":[{"id":"1.258742455","rc":[{"atl":[[9.4,5.84]],"batl":[[1,9.4,5.84]],"id":98117699}]}],"rt":639159129093631044,"dt":639159129093631426}
{"op":"mcm","id":2,"clk":"AL0HANkDANoK","pt":1780316110186,"mc":[{"id":"1.258742455","rc":[{"batb":[[2,4,51.13]],"atb":[[4,51.13]],"id":99072898}]}],"rt":639159129101942195,"dt":639159129101942630}
{"op":"mcm","id":2,"clk":"AMIHANoDAOQK","pt":1780316110281,"mc":[{"id":"1.258742455","rc":[{"batb":[[0,4.2,158.44]],"atb":[[4.2,158.44]],"id":99072898}]}],"rt":639159129102897585,"dt":639159129102897978}
{"op":"mcm","id":2,"clk":"ANcHAOMDAP4K","pt":1780316110490,"mc":[{"id":"1.258742455","rc":[{"tv":10372.44,"batb":[[0,3.9,58.16]],"trd":[[3.9,1623.79]],"ltp":3.9,"atb":[[3.9,58.16]],"id":88302242}],"tv":30587.78}],"rt":639159129104982546,"dt":639159129104982959}
{"op":"mcm","id":2,"clk":"AOAHAOcDAIoL","pt":1780316110590,"mc":[{"id":"1.258742455","rc":[{"atl":[[3.95,12.85]],"batl":[[0,3.95,12.85]],"id":88302242}]}],"rt":639159129105978173,"dt":639159129105978601}
{"op":"mcm","id":2,"clk":"AOgHAOoDAJYL","pt":1780316110693,"mc":[{"id":"1.258742455","rc":[{"tv":884.67,"batb":[[0,24,12.82]],"trd":[[24,79.95]],"ltp":24,"atb":[[24,12.82]],"id":99072900}],"tv":30591.78}],"rt":639159129107007655,"dt":639159129107008109}
{"op":"mcm","id":2,"clk":"AKwIAIcEAOgL","pt":1780316111565,"mc":[{"id":"1.258742455","rc":[{"batb":[[0,4.2,143.75]],"atb":[[4.2,143.75]],"id":99072898},{"batb":[[0,4.4,102.06]],"atb":[[4.4,102.06]],"id":10398159}]}],"rt":639159129115727314,"dt":639159129115727683}
{"op":"mcm","id":2,"clk":"ALkIAIgEAPAL","pt":1780316111668,"mc":[{"id":"1.258742455","rc":[{"tv":6959.53,"trd":[[4.3,47.98]],"atl":[[4.3,3.42]],"batl":[[0,4.3,3.42]],"id":99072898},{"batb":[[0,4.4,113.06]],"atb":[[4.4,113.06]],"atl":[[4.5,7.58]],"batl":[[0,4.5,7.58]],"id":10398159},{"batb":[[0,3.9,49.34]],"atb":[[3.9,49.34]],"atl":[[3.95,15.13]],"batl":[[0,3.95,15.13]],"id":88302242}],"tv":30621.16}],"rt":639159129116764435,"dt":639159129116764974}
{"op":"mcm","id":2,"clk":"AL4IAIoEAPoL","pt":1780316111777,"mc":[{"id":"1.258742455","rc":[{"tv":6966.37,"batb":[[2,4.1,79.53],[1,4.2,143.75],[0,4.3,24.04]],"trd":[[4.3,54.82]],"atb":[[4.3,24.04]],"atl":[[4.3,0]],"batl":[[2,4.6,2.57],[1,4.5,6.99],[0,4.4,7.84]],"id":99072898},{"atl":[[9.2,14.38]],"batl":[[0,9.2,14.38]],"id":98117699}],"tv":30628}],"rt":639159129117854859,"dt":639159129117855291}
{"op":"mcm","id":2,"clk":"AMUIAI0EAIAM","pt":1780316111883,"mc":[{"id":"1.258742455","rc":[{"tv":7014.46,"batb":[[1,4.2,143.74],[0,4.3,11]],"trd":[[4.2,337.77],[4.3,102.89]],"ltp":4.2,"atb":[[4.2,143.74],[3.9,1],[3.7,7.41],[4.3,11]],"atl":[[4.4,5.85],[4.5,5]],"batl":[[1,4.5,5],[0,4.4,5.85]],"id":99072898},{"batb":[[0,4.4,94.24]],"atb":[[4.4,94.24]],"id":10398159},{"batb":[[0,9,20.11]],"atb":[[9,20.11]],"id":98117699},{"batb":[[0,3.9,20.18]],"atb":[[3.9,20.18]],"id":88302242}],"tv":30676.09}],"rt":639159129118911825,"dt":639159129118912500}
{"op":"mcm","id":2,"clk":"AM0IAI4EAIkM","pt":1780316111982,"mc":[{"id":"1.258742455","rc":[{"tv":7021.84,"batb":[[0,4.3,7.31]],"trd":[[4.3,110.27]],"ltp":4.3,"atb":[[4.3,7.31]],"id":99072898},{"tv":10412.78,"batb":[[2,3.75,34.73],[1,3.8,126.79],[0,3.85,36.24]],"trd":[[3.9,1664.13]],"atb":[[3.9,0]],"atl":[[3.9,23.78]],"batl":[[2,4,13.25],[1,3.95,15.13],[0,3.9,23.78]],"id":88302242}],"tv":30723.81}],"rt":639159129119898028,"dt":639159129119898582}
{"op":"mcm","id":2,"clk":"ANUIAJAEAJIM","pt":1780316112095,"mc":[{"id":"1.258742455","rc":[{"batb":[[0,4.3,22.35]],"atb":[[4.3,22.35]],"id":99072898},{"atb":[[1.17,2.38]],"atl":[[25,6.71]],"batl":[[0,25,6.71]],"id":99072900},{"batb":[[0,4.4,116.19]],"atb":[[4.4,116.19]],"atl":[[1000,1.66],[4.5,8.08]],"batl":[[0,4.5,8.08]],"id":10398159},{"batb":[[0,9,23.77]],"atb":[[9,23.77]],"id":98117699},{"batb":[[1,3.8,135.73],[0,3.85,33.07]],"atb":[[3.8,135.73],[3.7,36.44],[3.85,33.07]],"atl":[[3.9,28.01]],"batl":[[0,3.9,28.01]],"id":88302242}]}],"rt":639159129121038053,"dt":639159129121038620}
{"op":"mcm","id":2,"clk":"ANkIAJEEAKAM","pt":1780316112195,"mc":[{"id":"1.258742455","rc":[{"atb":[[1.17,2]],"id":99072900},{"atl":[[1000,1.01]],"id":10398159}]}],"rt":639159129122034378,"dt":639159129122034731}
{"op":"mcm","id":2,"clk":"AOgIAJUEAKgM","pt":1780316112302,"mc":[{"id":"1.258742455","rc":[{"batb":[],"atb":[[3.95,24.8]],"atl":[[5,14.99]],"batl":[],"id":99072898},{"batb":[[1,23,11.35]],"atb":[[23,11.35]],"id":99072900},{"atl":[[4.6,29.03]],"batl":[[1,4.6,29.03]],"id":10398159},{"atl":[[9.8,5.14],[11,2.99],[10.5,5.68]],"batl":[],"id":98117699},{"atl":[[4.2,30.11],[4.1,60.45],[4,55.74]],"batl":[[2,4,55.74]],"id":88302242}]}],"rt":639159129123101435,"dt":639159129123101985}
{"op":"mcm","id":2,"clk":"AOsIAJcEALYM","pt":1780316112402,"mc":[{"id":"1.258742455","rc":[{"atl":[[5.1,48.27]],"batl":[],"id":99072898}]}],"rt":639159129124102126,"dt":639159129124102541}
{"op":"mcm","id":2,"clk":"APYIAJsEAL8M","pt":1780316112505,"mc":[{"id":"1.258742455","rc":[{"batb":[[0,3.85,23.9]],"atb":[[3.85,23.9]],"id":88302242}]}],"rt":639159129125137627,"dt":639159129125137957}
{"op":"mcm","id":2,"clk":"AP0IAJwEAMwM","pt":1780316112562,"mc":[{"id":"1.258742455","rc":[{"batb":[[0,4.3,30.08]],"atb":[[4.3,30.08]],"id":99072898},{"atl":[[25,2.94]],"batl":[[0,25,2.94]],"id":99072900}]}],"rt":639159129125707555,"dt":639159129125707988}
{"op":"mcm","id":2,"clk":"AIMJAJ4EANQM","pt":1780316112662,"mc":[{"id":"1.258742455","rc":[{"batb":[[0,3.85,12.16]],"atb":[[3.85,12.16]],"id":88302242}]}],"rt":639159129126698655,"dt":639159129126699077}
{"op":"mcm","id":2,"clk":"AIwJAKEEAN0M","pt":1780316112764,"mc":[{"id":"1.258742455","rc":[{"atl":[[70,9.89]],"batl":[[0,70,9.89]],"id":98464183}]}],"rt":639159129127723654,"dt":639159129127724044}
{"op":"mcm","id":2,"clk":"AJkJAKkEAO0M","pt":1780316112973,"mc":[{"id":"1.258742455","rc":[{"atl":[[4.8,27.89]],"batl":[],"id":99072898}]}],"rt":639159129129812334,"dt":639159129129812666}
{"op":"mcm","id":2,"clk":"AKAJAKwEAPMM","pt":1780316113075,"mc":[{"id":"1.258742455","rc":[{"tv":556.21,"batb":[[0,65,9.17]],"trd":[[65,37.28]],"atb":[[65,9.17]],"id":98464183},{"tv":10422.78,"batb":[[0,3.85,7.16]],"trd":[[3.85,1239.67]],"ltp":3.85,"atb":[[3.85,7.16]],"id":88302242}],"tv":30733.91}],"rt":639159129130833050,"dt":639159129130833483}
{"op":"mcm","id":2,"clk":"AKYJAK8EAPoM","pt":1780316113178,"mc":[{"id":"1.258742455","rc":[{"batb":[[0,12,29.24]],"atb":[[12,29.24]],"id":97736949}]}],"rt":639159129131863159,"dt":639159129131863511}
{"op":"mcm","id":2,"clk":"ALIJALgEAIkN","pt":1780316113380,"mc":[{"id":"1.258742455","rc":[{"atl":[[4.5,19.44]],"batl":[[1,4.5,19.44]],"id":99072898}]}],"rt":639159129133883536,"dt":639159129133883883}
{"op":"mcm","id":2,"clk":"ALcJAL0EAJUN","pt":1780316113485,"mc":[{"id":"1.258742455","rc":[{"batb":[],"atb":[[4,55.94]],"id":99072898},{"atl":[[4.5,12.19]],"batl":[[0,4.5,12.19]],"id":10398159}]}],"rt":639159129134930591,"dt":639159129134930980}
{"op":"mcm","id":2,"clk":"ALoJAMAEAJkN","pt":1780316113584,"mc":[{"id":"1.258742455","rc":[{"tv":1732.69,"batb":[[0,12,30.39]],"trd":[[12.5,40.3]],"atb":[[12,30.39]],"atl":[[12.5,2.65]],"batl":[[0,12.5,2.65]],"id":97736949}],"tv":30733.99}],"rt":639159129135926433,"dt":639159129135926983}
{"op":"mcm","id":2,"clk":"AL8JAMQEAKMN","pt":1780316113686,"mc":[{"id":"1.258742455","rc":[{"atl":[[4.5,22.89]],"batl":[[1,4.5,22.89]],"id":99072898},{"tv":6946,"batb":[[0,4.4,115.74]],"trd":[[4.4,604.78]],"atb":[[1.17,2.25],[4.4,115.74]],"id":10398159},{"atl":[[9.2,10.17]],"batl":[[0,9.2,10.17]],"id":98117699}],"tv":30734.89}],"rt":639159129136938319,"dt":639159129136938715}
{"op":"mcm","id":2,"clk":"AMMJAMYEAKwN","pt":1780316113792,"mc":[{"id":"1.258742455","rc":[{"atl":[[4.8,24.17]],"batl":[],"id":99072898},{"atb":[[1.17,2]],"atl":[[4.8,14.82]],"batl":[],"id":10398159},{"atl":[[9.2,8.21]],"batl":[[0,9.2,8.21]],"id":98117699},{"tv":10437.1,"batb":[[2,3.7,36.44],[1,3.75,34.73],[0,3.8,135.73]],"trd":[[3.85,1253.99]],"atb":[[3.85,0]],"atl":[[3.85,11.26]],"batl":[[2,3.95,15.13],[1,3.9,28.01],[0,3.85,11.26]],"id":88302242},{"tv":1735.55,"batb":[],"trd":[[12.5,43.16]],"atb":[[10.5,10.38]],"atl":[[12.5,1.22]],"batl":[[0,12.5,1.22]],"id":97736949}],"tv":30752.07}],"rt":639159129137999043,"dt":639159129137999551}
{"op":"mcm","id":2,"clk":"AMkJAMkEALUN","pt":1780316113892,"mc":[{"id":"1.258742455","rc":[{"tv":6946.2,"batb":[[0,4.4,115.89]],"trd":[[4.5,1431.78]],"ltp":4.5,"atb":[[4.4,115.89]],"atl":[[4.5,12.09]],"batl":[[0,4.5,12.09]],"id":10398159},{"batb":[[0,9,35.53]],"atb":[[9,35.53]],"id":98117699},{"batb":[[1,3.75,43.75],[0,3.8,126.79]],"atb":[[3.65,18.48],[3.75,43.75],[3.8,126.79]],"atl":[[3.85,13.26]],"batl":[[0,3.85,13.26]],"id":88302242}],"tv":30752.27}],"rt":639159129139003340,"dt":639159129139003824}
{"op":"mcm","id":2,"clk":"ANAJAM0EAMUN","pt":1780316114000,"mc":[{"id":"1.258742455","rc":[{"tv":1985.45,"batb":[[2,8.8,17.08],[1,9,35.53],[0,9.2,4.06]],"trd":[[9.2,109.17]],"atb":[[9.2,4.06]],"atl":[[9.2,0]],"batl":[[2,9.8,5.14],[1,9.6,5.52],[0,9.4,5.84]],"id":98117699},{"batb":[[0,3.8,135.81]],"atb":[[3.8,135.81]],"id":88302242},{"batb":[[2,11,6.94]],"atb":[[11,6.94]],"id":97736949}],"tv":30768.68}],"rt":639159129140084296,"dt":639159129140084796}
{"op":"mcm","id":2,"clk":"ANYJANEEAMsN","pt":1780316114099,"mc":[{"id":"1.258742455","rc":[{"batb":[[0,4.4,108.11]],"atb":[[4.4,108.11]],"id":10398159},{"tv":1993.59,"batb":[[2,8.6,8.95],[1,8.8,17.08],[0,9,35.52]],"trd":[[9.2,117.29],[9,4]],"ltp":9,"atb":[[9.2,0],[9,35.52]],"atl":[[9.4,3.89]],"batl":[[0,9.4,3.89]],"id":98117699},{"batb":[[2,11,9.34]],"atb":[[11,9.34]],"id":97736949}],"tv":30776.82}],"rt":639159129141067888,"dt":639159129141068390}
{"op":"mcm","id":2,"clk":"AN4JANcEANQN","pt":1780316114203,"mc":[{"id":"1.258742455","rc":[{"batb":[[2,8.8,17.08],[1,9,35.52],[0,9.2,7.97]],"atb":[[9.2,7.97]],"atl":[[10,3.49]],"batl":[],"id":98117699},{"tv":1735.81,"trd":[[12.5,43.42]],"atl":[[12.5,1.09]],"batl":[[0,12.5,1.09]],"id":97736949}],"tv":30777.08}],"rt":639159129142109153,"dt":639159129142109640}
{"op":"mcm","id":2,"clk":"AOkJANwEANwN","pt":1780316114302,"mc":[{"id":"1.258742455","rc":[{"batb":[[0,9.2,12.08]],"atb":[[9.2,12.08]],"atl":[[9.4,11.8]],"batl":[[0,9.4,11.8]],"id":98117699}]}],"rt":639159129143100666,"dt":639159129143101041}
{"op":"mcm","id":2,"clk":"AOwJAN8EAOYN","pt":1780316114407,"mc":[{"id":"1.258742455","rc":[{"atl":[[6.4,3.94]],"id":99072898}]}],"rt":639159129144148734,"dt":639159129144149051}
{"op":"mcm","id":2,"clk":"AIIKAPcEAIgO","pt":1780316114771,"mc":[{"id":"1.258742455","rc":[{"tv":494.71,"batb":[[0,42,9.84]],"trd":[[42,62.02]],"atb":[[42,9.84]],"id":97008932}],"tv":30780.06}],"rt":639159129147791412,"dt":639159129147791873}
{"op":"mcm","id":2,"clk":"AJYKAIUFAJcO","pt":1780316114977,"mc":[{"id":"1.258742455","rc":[{"batb":[[0,4.3,34.08]],"atb":[[4.3,34.08]],"id":99072898}]}],"rt":639159129149853283,"dt":639159129149853627}
{"op":"mcm","id":2,"clk":"AKIKAIoFAKEO","pt":1780316115084,"mc":[{"id":"1.258742455","rc":[{"tv":7030.7,"batb":[[0,4.3,29.65]],"trd":[[4.3,119.13]],"atb":[[4.3,29.65]],"id":99072898}],"tv":30788.92}],"rt":639159129150923266,"dt":639159129150923667}
{"op":"mcm","id":2,"clk":"ALIKAJIFAKoO","pt":1780316115286,"mc":[{"id":"1.258742455","rc":[{"atl":[[3.95,18.36]],"batl":[[2,3.95,18.36]],"id":88302242}]}],"rt":639159129152941116,"dt":639159129152941435}
{"op":"mcm","id":2,"clk":"AL4KAJUFALIO","pt":1780316115389,"mc":[{"id":"1.258742455","rc":[{"batb":[[2,4.1,78.2],[1,4.2,144.44]],"atb":[[4.2,144.44],[4.1,78.2]],"id":99072898},{"batb":[[0,4.4,118.87]],"atb":[[4.4,118.87]],"atl":[[4.6,31.17]],"batl":[[1,4.6,31.17]],"id":10398159},{"batb":[[1,9,31.86],[0,9.2,16.31]],"atb":[[9.2,16.31],[9,31.86]],"atl":[[9.4,11.04],[9.6,6.59]],"batl":[[1,9.6,6.59],[0,9.4,11.04]],"id":98117699},{"atl":[[3.9,29.09],[3.95,18.15],[4,55.54]],"batl":[[2,3.95,18.15],[1,3.9,29.09]],"id":88302242},{"batb":[[0,12,31.97]],"atb":[[12,31.97]],"id":97736949}]}],"rt":639159129153974698,"dt":639159129153975254}
{"op":"mcm","id":2,"clk":"AMMKAJkFALoO","pt":1780316115490,"mc":[{"id":"1.258742455","rc":[{"batb":[[1,4.2,145.44]],"atb":[[4.2,145.44]],"id":99072898},{"batb":[[0,4.4,119.87]],"atb":[[4.4,119.87]],"id":10398159},{"batb":[[1,9,32.86]],"atb":[[9,32.86]],"id":98117699}]}],"rt":639159129154986283,"dt":639159129154986738}
{"op":"mcm","id":2,"clk":"AOUKAKUFAOEO","pt":1780316115901,"mc":[{"id":"1.258742455","rc":[{"atb":[[1.17,2.23]],"id":97008932},{"tv":885.51,"batb":[[0,24,12.4]],"trd":[[24,80.79]],"atb":[[24,12.4]],"atl":[[25,3.34]],"batl":[[0,25,3.34]],"id":99072900},{"atb":[[1.17,2.28]],"id":10398159},{"atl":[[70,10.05]],"batl":[[0,70,10.05]],"id":98464183},{"tv":10439.78,"trd":[[3.85,1256.67]],"atl":[[3.85,11.92]],"batl":[[0,3.85,11.92]],"id":88302242},{"atb":[[1.17,2.23]],"id":97736949}],"tv":30792.44}],"rt":639159129159093167,"dt":639159129159093715}
{"op":"mcm","id":2,"clk":"AOoKAKcFAOgO","pt":1780316116007,"mc":[{"id":"1.258742455","rc":[{"atb":[[1.17,2]],"id":97008932},{"atb":[[1.17,2]],"atl":[[4.9,25.89],[4.6,31.67]],"batl":[[1,4.6,31.67]],"id":10398159},{"atl":[[3.95,14.92]],"batl":[[2,3.95,14.92]],"id":88302242},{"atb":[[1.17,2]],"id":97736949}]}],"rt":639159129160150584,"dt":639159129160151122}
{"op":"mcm","id":2,"clk":"APAKAKsFAPMO","pt":1780316116107,"mc":[{"id":"1.258742455","rc":[{"batb":[[0,42,10.07]],"atb":[[42,10.07]],"id":97008932},{"batb":[[0,24,14.59]],"atb":[[24,14.59]],"id":99072900},{"tv":6946.76,"trd":[[4.5,1432.34]],"atl":[[4.5,11.81]],"batl":[[0,4.5,11.81]],"id":10398159},{"tv":1736.27,"trd":[[12.5,43.88]],"atl":[[12.5,0.86]],"batl":[[2,14,15.15],[1,13.5,5.75],[0,13,25.36]],"id":97736949}],"tv":30793.46}],"rt":639159129161150599,"dt":639159129161151287}
{"op":"mcm","id":2,"clk":"APgKALIFAPoO","pt":1780316116209,"mc":[{"id":"1.258742455","rc":[{"atb":[[1.17,2.17]],"id":97008932},{"atl":[[110,0.46]],"batl":[[0,120,1.57]],"id":99072901},{"batb":[[0,4.4,119.72]],"atb":[[4.4,119.72]],"id":10398159},{"atl":[[70,11.06]],"batl":[[0,70,11.06]],"id":98464183},{"tv":10443.3,"trd":[[3.85,1260.19]],"atl":[[3.85,10.16]],"batl":[[0,3.85,10.16]],"id":88302242},{"tv":1737.99,"batb":[[0,12,32.03]],"trd":[[12.5,45.6]],"atb":[[12.5,0.06]],"atl":[[12.5,0]],"batl":[[0,13,24.5]],"id":97736949},{"atl":[[1000,8.8]],"batl":[],"id":99072897}],"tv":30798.7}],"rt":639159129162175539,"dt":639159129162176207}
{"op":"mcm","id":2,"clk":"AP0KALcFAIQP","pt":1780316116264,"mc":[{"id":"1.258742455","rc":[{"atb":[[1.17,2]],"id":97008932},{"atl":[[3.85,2]],"batl":[[0,3.85,2]],"id":88302242},{"atl":[[1000,8.75]],"batl":[],"id":99072897}]}],"rt":639159129162727286,"dt":639159129162727719}
{"op":"mcm","id":2,"clk":"AIcLALkFAJIP","pt":1780316116366,"mc":[{"id":"1.258742455","rc":[{"batb":[[0,42,10.24]],"atb":[[42,10.24]],"id":97008932},{"atl":[[180,0.37]],"batl":[[0,190,3.02]],"id":99072897}]}],"rt":639159129163743740,"dt":639159129163744236}
{"op":"mcm","id":2,"clk":"ALMLAMsFAL4P","pt":1780316116878,"mc":[{"id":"1.258742455","rc":[{"batb":[],"atb":[[3.9,2.99]],"id":99072898},{"atl":[[10,5.48]],"batl":[],"id":98117699}]}],"rt":639159129168861268,"dt":639159129168861816}
{"op":"mcm","id":2,"clk":"AMMLANQFANMP","pt":1780316117088,"mc":[{"id":"1.258742455","rc":[{"tv":333.9,"batb":[[0,95,3.91]],"trd":[[100,20.47],[95,16.33]],"ltp":95,"atb":[[100,0],[95,3.91]],"id":99072901}],"tv":30802.11}],"rt":639159129170964117,"dt":639159129170964618}
{"op":"mcm","id":2,"clk":"AM4LANUFAN4P","pt":1780316117189,"mc":[{"id":"1.258742455","rc":[{"batb":[],"atb":[[3.35,89.25]],"id":88302242}]}],"rt":639159129171973467,"dt":639159129171973876}
{"op":"mcm","id":2,"clk":"AN0LAN4FAPcP","pt":1780316117395,"mc":[{"id":"1.258742455","rc":[{"atl":[[5.2,0]],"batl":[],"id":99072898},{"batb":[],"atb":[[20,2.61]],"id":99072900},{"batb":[],"atb":[[8.4,2.99]],"id":98117699},{"atl":[[13.5,19.74],[13,9.52]],"batl":[[1,13.5,19.74],[0,13,9.52]],"id":97736949}]}],"rt":639159129174034633,"dt":639159129174035174}
{"op":"mcm","id":2,"clk":"AOQLAOEFAIIQ","pt":1780316117495,"mc":[{"id":"1.258742455","rc":[{"batb":[[0,4.3,37.77]],"atb":[[3.5,5.03],[4.3,37.77]],"id":99072898}]}],"rt":639159129175034927,"dt":639159129175035298}
{"op":"mcm","id":2,"clk":"AO8LAOgFAI8Q","pt":1780316117597,"mc":[{"id":"1.258742455","rc":[{"tv":341.65,"batb":[[2,80,1.05],[1,85,1.74],[0,90,2.18]],"trd":[[95,24.08]],"atb":[[95,0.04],[85,1.74]],"id":99072901},{"batb":[],"atb":[[3.75,4.54]],"id":10398159},{"batb":[[0,9.2,8.34]],"atb":[[9.2,8.34]],"id":98117699},{"atb":[[3.25,3.8]],"id":88302242}],"tv":30809.86}],"rt":639159129176048310,"dt":639159129176048797}
{"op":"mcm","id":2,"clk":"APcLAOoFAJkQ","pt":1780316117702,"mc":[{"id":"1.258742455","rc":[{"tv":7129.29,"batb":[[2,4,55.94],[1,4.1,78.2],[0,4.2,133.92]],"trd":[[4.2,360.81],[4.3,194.68]],"ltp":4.2,"atb":[[4.2,133.92],[4.3,0]],"id":99072898},{"batb":[[1,40,7.19]],"atb":[[40,7.19]],"id":97008932},{"batb":[],"atb":[[20,2.86]],"id":99072900},{"tv":346.01,"batb":[[2,75,8.4],[1,80,1.05],[0,85,1.74]],"trd":[[95,24.16],[90,27.55]],"ltp":90,"atb":[[95,0],[90,0]],"atl":[[95,3.34],[90,1.02]],"batl":[[2,120,1.57],[1,95,3.34],[0,90,1.02]],"id":99072901},{"batb":[[1,60,20.93]],"atb":[[60,20.93]],"id":98464183},{"batb":[],"atb":[[8,35.26]],"id":98117699},{"batb":[],"atb":[[10.5,9.9]],"id":97736949},{"batb":[[1,150,3.29],[0,160,4.28]],"atb":[[160,4.28],[150,3.29]],"id":99072897}],"tv":30912.81}],"rt":639159129177106798,"dt":639159129177107415}
{"op":"mcm","id":2,"clk":"AIAMAOsFAKAQ","pt":1780316117806,"mc":[{"id":"1.258742455","rc":[{"batb":[[0,4.2,125.73]],"atb":[[3.65,12.67],[4.2,125.73]],"id":99072898},{"atl":[[100,1.34]],"batl":[[2,100,1.34]],"id":99072901},{"batb":[[0,4.4,127.5]],"atb":[[4.4,127.5],[3.85,38.56]],"atl":[[4.5,8.96]],"batl":[[0,4.5,8.96]],"id":10398159},{"atl":[[9.6,4.67]],"batl":[[1,9.6,4.67]],"id":98117699},{"batb":[[2,3.75,43.75],[1,3.8,135.81],[0,3.85,13.65]],"atb":[[3.85,13.65]],"atl":[[3.9,24.86],[3.85,0]],"batl":[[2,4,55.54],[1,3.95,14.92],[0,3.9,24.86]],"id":88302242},{"batb":[[0,12,34.79]],"atb":[[12,34.73]],"id":97736949}]}],"rt":639159129178138452,"dt":639159129178138972}
{"op":"mcm","id":2,"clk":"AIYMAPAFAKoQ","pt":1780316117904,"mc":[{"id":"1.258742455","rc":[{"tv":7131.63,"trd":[[4.4,2.34]],"ltp":4.4,"atl":[[4.4,4.68]],"batl":[[0,4.4,4.68]],"id":99072898},{"batb":[],"atb":[[36,2.13]],"id":97008932},{"tv":347.03,"batb":[[0,85,2.73]],"trd":[[90,28.57]],"atb":[[85,2.73]],"atl":[[90,0.51]],"batl":[[2,120,1.57],[1,100,1.34],[0,95,3.85]],"id":99072901},{"tv":6964.68,"batb":[[2,4.3,96.27],[1,4.4,127.5],[0,4.5,19.73]],"trd":[[4.5,1450.26]],"atb":[[4.5,19.73]],"atl":[[4.5,0]],"batl":[[2,4.8,14.82],[1,4.7,270.6],[0,4.6,31.67]],"id":10398159},{"batb":[[2,55,15.77]],"atb":[[55,15.77]],"id":98464183},{"batb":[],"atb":[[10.5,10.38]],"id":97736949}],"tv":30934.09}],"rt":639159129179125654,"dt":639159129179126518}
{"op":"mcm","id":2,"clk":"AIwMAPQFALAQ","pt":1780316118010,"mc":[{"id":"1.258742455","rc":[{"atl":[[100,2.34],[90,0],[170,0.33],[150,0.3]],"batl":[[1,100,2.34],[0,95,3.34]],"id":99072901},{"tv":7004.14,"batb":[[2,4.2,22.42],[1,4.3,96.27],[0,4.4,127.5]],"trd":[[4.5,1489.72]],"atb":[[4.5,0]],"id":10398159},{"atl":[[5.4,1.99]],"id":88302242}],"tv":30973.55}],"rt":639159129180185897,"dt":639159129180186459}
{"op":"mcm","id":2,"clk":"AJMMAPkFAL4Q","pt":1780316118114,"mc":[{"id":"1.258742455","rc":[{"atl":[[100,1]],"batl":[[1,100,1]],"id":99072901},{"atl":[[10,7.38]],"batl":[],"id":98117699}]}],"rt":639159129181228237,"dt":639159129181228712}
{"op":"mcm","id":2,"clk":"AJwMAPwFAMEQ","pt":1780316118214,"mc":[{"id":"1.258742455","rc":[{"atl":[[25,6.49]],"batl":[[0,25,6.49]],"id":99072900},{"batb":[[0,85,1.74]],"atb":[[85,1.74]],"id":99072901}]}],"rt":639159129182221783,"dt":639159129182222239}
{"op":"mcm","id":2,"clk":"AKYMAIAGAMcQ","pt":1780316118279,"mc":[{"id":"1.258742455","rc":[{"tv":10555.4,"batb":[[2,3.7,36.44],[1,3.75,43.75],[0,3.8,93.41]],"trd":[[3.8,539.67],[3.85,1287.49]],"ltp":3.8,"atb":[[3.8,93.41],[3.85,0]],"id":88302242}],"tv":31085.65}],"rt":639159129182874281,"dt":639159129182874764}
{"op":"mcm","id":2,"clk":"AK0MAIQGAM8Q","pt":1780316118377,"mc":[{"id":"1.258742455","rc":[{"atl":[[4.4,6.73]],"batl":[[0,4.4,6.73]],"id":99072898},{"atl":[[1000,0.41]],"id":97008932},{"batb":[[0,65,11.45]],"atb":[[65,11.45]],"id":98464183},{"batb":[[0,3.8,98.71]],"atb":[[3.8,98.71]],"atl":[[3.85,12.89]],"batl":[[2,3.95,14.92],[1,3.9,24.86],[0,3.85,12.89]],"id":88302242}]}],"rt":639159129183854864,"dt":639159129183855362}
{"op":"mcm","id":2,"clk":"ALIMAIcGANcQ","pt":1780316118472,"mc":[{"id":"1.258742455","rc":[{"atl":[[1000,0.22]],"id":97008932}]}],"rt":639159129184803574,"dt":639159129184803977}
{"op":"mcm","id":2,"clk":"ALgMAIkGAN4Q","pt":1780316118577,"mc":[{"id":"1.258742455","rc":[{"atl":[[48,1.6]],"batl":[[1,48,1.6]],"id":97008932}]}],"rt":639159129185851046,"dt":639159129185851385}
{"op":"mcm","id":2,"clk":"ANsMAJ8GAIkR","pt":1780316118989,"mc":[{"id":"1.258742455","rc":[{"batb":[[2,4.3,96.27],[1,4.4,127.5],[0,4.5,1]],"atb":[[4.5,1]],"id":10398159}]}],"rt":639159129189971580,"dt":639159129189971990}
{"op":"mcm","id":2,"clk":"AOYMAKMGAJsR","pt":1780316119189,"mc":[{"id":"1.258742455","rc":[{"batb":[[0,3.8,87.96]],"atb":[[3.8,87.96]],"id":88302242}]}],"rt":639159129191972107,"dt":639159129191972450}
{"op":"mcm","id":2,"clk":"AO4MAKUGAKcR","pt":1780316119294,"mc":[{"id":"1.258742455","rc":[{"tv":10607.3,"batb":[[0,3.8,62.01]],"trd":[[3.8,591.57]],"atb":[[3.8,62.01]],"id":88302242}],"tv":31137.55}],"rt":639159129193021822,"dt":639159129193022200}
{"op":"mcm","id":2,"clk":"AIUNAK4GALgR","pt":1780316119499,"mc":[{"id":"1.258742455","rc":[{"batb":[[0,3.8,53.98]],"atb":[[3.8,53.98]],"id":88302242}]}],"rt":639159129195070711,"dt":639159129195071071}
{"op":"mcm","id":2,"clk":"AI0NALAGAMQR","pt":1780316119602,"mc":[{"id":"1.258742455","rc":[{"tv":351.03,"batb":[[2,65,1.99],[1,70,5],[0,75,9.19]],"trd":[[85,33.58],[80,64.23]],"ltp":80,"atb":[[85,0],[80,0.79]],"id":99072901},{"tv":10610.76,"trd":[[3.85,1290.95]],"ltp":3.85,"atl":[[3.85,11.16]],"batl":[[0,3.85,11.16]],"id":88302242}],"tv":31145.01}],"rt":639159129196097086,"dt":639159129196097533}
{"op":"mcm","id":2,"clk":"AJENALIGAM8R","pt":1780316119704,"mc":[{"id":"1.258742455","rc":[{"atl":[[70,11.42]],"batl":[[0,70,11.42]],"id":98464183},{"batb":[[0,3.8,66.56]],"atb":[[3.8,66.56]],"atl":[[3.9,29.25]],"batl":[[1,3.9,29.25]],"id":88302242}]}],"rt":639159129197126802,"dt":639159129197127193}
{"op":"mcm","id":2,"clk":"AJ4NALUGANYR","pt":1780316119804,"mc":[{"id":"1.258742455","rc":[{"atl":[[95,3.6]],"batl":[[0,95,3.6]],"id":99072901}]}],"rt":639159129198122682,"dt":639159129198123050}
{"op":"mcm","id":2,"clk":"AK0NAL0GAOkR","pt":1780316120019,"mc":[{"id":"1.258742455","rc":[{"tv":556.3,"batb":[[0,65,11.4]],"trd":[[65,37.37]],"atb":[[65,11.4]],"id":98464183}],"tv":31145.1}],"rt":639159129200279437,"dt":639159129200279842}
{"op":"mcm","id":2,"clk":"ALYNAL8GAPAR","pt":1780316120067,"mc":[{"id":"1.258742455","rc":[{"atb":[[3,10]],"id":99072897}]}],"rt":639159129200753793,"dt":639159129200754121}
{"op":"mcm","id":2,"clk":"ALoNAMQGAPkR","pt":1780316120168,"mc":[{"id":"1.258742455","rc":[{"atl":[[4.6,36.11]],"batl":[[0,4.6,36.11]],"id":10398159},{"batb":[[0,12,35.17]],"atb":[[12.5,0.44]],"id":97736949}]}],"rt":639159129201762517,"dt":639159129201762936}
{"op":"mcm","id":2,"clk":"AP8NAOcGAM8S","pt":1780316121094,"mc":[{"id":"1.258742455","rc":[{"batb":[[0,4.2,124.05]],"atb":[[1.17,2.96],[4.2,124.05]],"id":99072898},{"batb":[[1,4.4,113.57]],"atb":[[4.4,113.57]],"atl":[[1000,1.72],[4.6,33.32]],"batl":[[0,4.6,33.32]],"id":10398159},{"batb":[[0,9.2,7.03]],"atb":[[9.2,7.03]],"atl":[[1000,6.83]],"id":98117699},{"tv":10625.28,"batb":[[0,3.8,63.26]],"trd":[[3.85,1305.47]],"atb":[[3.8,63.26]],"atl":[[3.85,0]],"batl":[[2,4,55.54],[1,3.95,14.92],[0,3.9,29.25]],"id":88302242},{"batb":[[0,12,29.55]],"atb":[[12,29.11]],"atl":[[13.5,20.66],[13,8.59]],"batl":[[1,13.5,20.66],[0,13,8.59]],"id":97736949}],"tv":31159.62}],"rt":639159129211024171,"dt":639159129211024920}
{"op":"mcm","id":2,"clk":"AIUOAOsGANUS","pt":1780316121194,"mc":[{"id":"1.258742455","rc":[{"atb":[[1.17,2]],"id":99072898},{"atb":[[1.17,2.35]],"atl":[[1000,1.01]],"id":10398159},{"atl":[[1000,6.25]],"id":98117699},{"batb":[[2,3.75,43.75],[1,3.8,78.24],[0,3.85,12.81]],"atb":[[3.8,78.24],[3.85,12.81]],"atl":[[1000,3.3],[3.9,24.86],[4.1,65.04],[3.95,12.64],[4,51.99]],"batl":[[2,4,51.99],[1,3.95,12.64],[0,3.9,24.86]],"id":88302242},{"tv":1738.06,"batb":[[0,12,26.79]],"trd":[[13,16.68]],"ltp":13,"atb":[[1.17,2.15],[12,26.35]],"atl":[[13,8.55]],"batl":[[0,13,8.55]],"id":97736949}],"tv":31159.69}],"rt":639159129212020789,"dt":639159129212021491}
{"op":"mcm","id":2,"clk":"AIwOAO8GAN4S","pt":1780316121297,"mc":[{"id":"1.258742455","rc":[{"batb":[[1,4.1,79.16]],"atb":[[4.1,79.16]],"id":99072898},{"tv":7005.09,"batb":[[2,4.2,22.42],[1,4.3,96.27],[0,4.4,114.1]],"trd":[[4.5,1490.67]],"atb":[[1.17,2],[4.5,0.53]],"atl":[[4.7,271.31]],"batl":[[1,4.7,271.31]],"id":10398159},{"atl":[[9.4,11.62]],"batl":[[0,9.4,11.62]],"id":98117699},{"tv":10655.98,"batb":[[2,3.7,36.44],[1,3.75,43.75],[0,3.8,78.24]],"trd":[[3.9,1669.21],[3.85,1331.09]],"ltp":3.9,"atb":[[3.85,0]],"atl":[[1000,3],[3.9,22.32]],"batl":[[0,3.9,22.32]],"id":88302242},{"batb":[[2,11.5,21.48],[1,12,26.35],[0,12.5,1.51]],"atb":[[1.17,2],[12.5,1.51]],"id":97736949}],"tv":31191.34}],"rt":639159129213048193,"dt":639159129213048759}
{"op":"mcm","id":2,"clk":"AJYOAPQGAOMS","pt":1780316121402,"mc":[{"id":"1.258742455","rc":[{"batb":[[0,4.4,114.45]],"atb":[[4.5,0.88]],"id":10398159},{"tv":10656.58,"batb":[[0,3.8,78.94]],"trd":[[3.85,1331.69]],"ltp":3.85,"atb":[[3.85,0.7]],"id":88302242},{"batb":[[0,12.5,1.66]],"atb":[[12.5,1.66]],"id":97736949}],"tv":31191.94}],"rt":639159129214105395,"dt":639159129214105855}
{"op":"mcm","id":2,"clk":"AKAOAPkGAOkS","pt":1780316121506,"mc":[{"id":"1.258742455","rc":[{"atl":[[4.3,14.85]],"batl":[[2,4.5,22.89],[1,4.4,6.73],[0,4.3,14.85]],"id":99072898},{"batb":[[0,75,8.4]],"atb":[[80,0]],"id":99072901},{"tv":7006.85,"batb":[[0,4.4,113.57]],"trd":[[4.5,1492.43]],"atb":[[4.5,0]],"atl":[[4.5,17.28]],"batl":[[2,4.7,271.31],[1,4.6,33.32],[0,4.5,17.28]],"id":10398159},{"batb":[[0,65,9.12]],"atb":[[65,9.12]],"id":98464183},{"tv":1998.23,"batb":[[2,8.6,8.95],[1,8.8,17.08],[0,9,33.46]],"trd":[[9.2,121.93]],"ltp":9.2,"atb":[[9.2,0.6]],"id":98117699},{"tv":10690.82,"batb":[[2,3.8,78.24],[1,3.85,13.12],[0,3.95,12.09]],"trd":[[3.9,1699.17],[3.95,1155.42]],"ltp":3.95,"atb":[[3.95,12.09],[3.85,13.12]],"atl":[[4.2,34.69],[3.9,0],[4.1,60.45],[3.95,0],[4,42.55]],"batl":[[2,4.2,34.69],[1,4.1,60.45],[0,4,42.55]],"id":88302242},{"tv":1741.39,"batb":[[2,11,9.34],[1,11.5,21.48],[0,12,26.35]],"trd":[[12.5,48.93]],"ltp":12.5,"atb":[[12.5,0]],"atl":[[12.5,5.79]],"batl":[[2,13.5,20.66],[1,13,8.55],[0,12.5,5.79]],"id":97736949}],"tv":31235.91}],"rt":639159129215145022,"dt":639159129215146069}
{"op":"mcm","id":2,"clk":"AKkOAPwGAPMS","pt":1780316121608,"mc":[{"id":"1.258742455","rc":[{"batb":[[1,4.1,70.92]],"atb":[[4.1,70.92]],"atl":[[4.3,17.46]],"batl":[[0,4.3,17.46]],"id":99072898},{"batb":[[0,4.4,105.79]],"atb":[[4.4,105.79]],"atl":[[4.5,20.32]],"batl":[[0,4.5,20.32]],"id":10398159},{"atl":[[9.4,13.54]],"batl":[[0,9.4,13.54]],"id":98117699},{"tv":10715,"batb":[[0,3.9,22.16]],"trd":[[3.95,1179.6]],"atb":[[3.9,22.16],[3.95,0]],"atl":[[4.2,30.11],[4.4,38.49],[3.95,12.09]],"batl":[[2,4.1,60.45],[1,4,42.55],[0,3.95,12.09]],"id":88302242},{"batb":[[1,11.5,18.68]],"atb":[[11.5,18.68]],"id":97736949}],"tv":31260.09}],"rt":639159129216159538,"dt":639159129216160170}
{"op":"mcm","id":2,"clk":"ALEOAP4GAPsS","pt":1780316121710,"mc":[{"id":"1.258742455","rc":[{"tv":10718.56,"trd":[[3.95,1183.16]],"atl":[[4.2,10],[3.95,10.31]],"batl":[[0,3.95,10.31]],"id":88302242}],"tv":31263.65}],"rt":639159129217177667,"dt":639159129217178097}
{"op":"mcm","id":2,"clk":"ALkOAIMHAIYT","pt":1780316121811,"mc":[{"id":"1.258742455","rc":[{"atl":[[3.95,23.1]],"batl":[[0,3.95,23.1]],"id":88302242}]}],"rt":639159129218190829,"dt":639159129218191227}
{"op":"mcm","id":2,"clk":"AL4OAIYHAI8T","pt":1780316121912,"mc":[{"id":"1.258742455","rc":[{"atl":[[4.3,2.61]],"batl":[[0,4.3,2.61]],"id":99072898},{"batb":[[1,3.85,17.65]],"atb":[[3.85,17.65]],"id":88302242},{"atl":[[12.5,0]],"batl":[[2,14,15.15],[1,13.5,20.66],[0,13,8.55]],"id":97736949}]}],"rt":639159129219203252,"dt":639159129219203919}
{"op":"mcm","id":2,"clk":"AMkOAIkHAJUT","pt":1780316122018,"mc":[{"id":"1.258742455","rc":[{"atl":[[4.5,3.04]],"batl":[[0,4.5,3.04]],"id":10398159},{"atl":[[3.95,12.79]],"batl":[[0,3.95,12.79]],"id":88302242}]}],"rt":639159129220267812,"dt":639159129220268608}
{"op":"mcm","id":2,"clk":"ANcOAJEHAKQT","pt":1780316122186,"mc":[{"id":"1.258742455","rc":[{"atl":[[4,54.97]],"batl":[[1,4,54.97]],"id":88302242}]}],"rt":639159129221945967,"dt":639159129221946347}
{"op":"mcm","id":2,"clk":"AN4OAJMHALAT","pt":1780316122273,"mc":[{"id":"1.258742455","rc":[{"batb":[],"atb":[[3.75,34.73]],"id":88302242}]}],"rt":639159129222815825,"dt":639159129222816196}
{"op":"mcm","id":2,"clk":"AOYOAJUHALkT","pt":1780316122379,"mc":[{"id":"1.258742455","rc":[{"atl":[[70,11.49]],"batl":[[0,70,11.49]],"id":98464183}]}],"rt":639159129223872022,"dt":639159129223872419}
{"op":"mcm","id":2,"clk":"APMOAJ0HAM0T","pt":1780316122591,"mc":[{"id":"1.258742455","rc":[{"batb":[],"atb":[[21,14.16]],"id":99072900},{"atl":[[4.1,94.41],[4,12.48]],"batl":[[2,4.1,94.41],[1,4,12.48]],"id":88302242}]}],"rt":639159129225995403,"dt":639159129225996005}
{"op":"mcm","id":2,"clk":"APsOAKMHANYT","pt":1780316122694,"mc":[{"id":"1.258742455","rc":[{"tv":556.32,"batb":[[0,65,9.11]],"trd":[[65,37.39]],"atb":[[65,9.11]],"id":98464183},{"atl":[[3.95,0]],"batl":[[2,4.2,10],[1,4.1,94.41],[0,4,12.48]],"id":88302242}],"tv":31263.67}],"rt":639159129227017009,"dt":639159129227017522}
{"op":"mcm","id":2,"clk":"AIIPAKcHAOIT","pt":1780316122793,"mc":[{"id":"1.258742455","rc":[{"batb":[],"atb":[[3.85,33.89]],"id":99072898},{"atb":[[3.85,5.55]],"id":97008932},{"atb":[[3.85,5.55]],"id":99072900},{"batb":[[0,75,9.51]],"atb":[[3.85,5.55],[75,9.51]],"id":99072901},{"batb":[],"atb":[[3.85,44.11]],"id":10398159},{"atb":[[3.85,5.55]],"id":98464183},{"atb":[[3.85,5.55]],"id":98117699},{"batb":[[1,3.85,23.2]],"atb":[[3.85,23.2]],"atl":[[3.95,0.96]],"batl":[[0,4,13.44]],"id":88302242},{"atb":[[3.85,5.55]],"id":97736949},{"atb":[[3.85,5.55]],"id":10445502},{"atb":[[3.85,5.55]],"id":99072897}]}],"rt":639159129228015275,"dt":639159129228016234}
{"op":"mcm","id":2,"clk":"AIcPAKgHAOsT","pt":1780316122893,"mc":[{"id":"1.258742455","rc":[{"atl":[[140,0]],"batl":[],"id":99072901}]}],"rt":639159129229014320,"dt":639159129229014906}
{"op":"mcm","id":2,"clk":"AIsPAK0HAPAT","pt":1780316122995,"mc":[{"id":"1.258742455","rc":[{"atl":[[13,8.76]],"batl":[[0,13,8.76]],"id":97736949}]}],"rt":639159129230027813,"dt":639159129230028242}
{"op":"mcm","id":2,"clk":"ALcPAMQHAK0U","pt":1780316123710,"mc":[{"id":"1.258742455","rc":[{"batb":[],"atb":[[8,51.61]],"id":98117699}]}],"rt":639159129237178501,"dt":639159129237178832}
{"op":"mcm","id":2,"clk":"ALsPAMYHALYU","pt":1780316123810,"mc":[{"id":"1.258742455","rc":[{"atl":[[85,4.11]],"batl":[],"id":98464183},{"tv":10722.56,"batb":[[0,3.9,20.16]],"trd":[[3.9,1703.17]],"ltp":3.9,"atb":[[3.9,20.16]],"id":88302242}],"tv":31267.67}],"rt":639159129238179247,"dt":639159129238180082}
{"op":"mcm","id":2,"clk":"AMIPAM8HAL0U","pt":1780316123916,"mc":[{"id":"1.258742455","rc":[{"atl":[[46,2.47]],"batl":[[0,46,2.47]],"id":97008932},{"tv":10722.78,"batb":[[0,3.9,20.05]],"trd":[[3.9,1703.39]],"atb":[[3.9,20.05]],"id":88302242}],"tv":31267.89}],"rt":639159129239240443,"dt":639159129239241492}
{"op":"mcm","id":2,"clk":"AM4PANUHANAU","pt":1780316124071,"mc":[{"id":"1.258742455","rc":[{"tv":1741.42,"batb":[[0,12,26.33]],"trd":[[12,7.42]],"ltp":12,"atb":[[12,26.33]],"id":97736949}],"tv":31267.92}],"rt":639159129240791581,"dt":639159129240792053}
{"op":"mcm","id":2,"clk":"ANUPANcHANoU","pt":1780316124175,"mc":[{"id":"1.258742455","rc":[{"batb":[[0,4.4,106.2]],"atb":[[4.4,106.2]],"id":10398159},{"batb":[[1,11.5,19.86]],"atb":[[11.5,19.86]],"id":97736949}]}],"rt":639159129241829887,"dt":639159129241830315}
{"op":"mcm","id":2,"clk":"AOMPAOIHAO8U","pt":1780316124382,"mc":[{"id":"1.258742455","rc":[{"atl":[[16,0]],"id":99072898},{"atl":[[17,13]],"id":10398159},{"atl":[[95,0]],"id":98117699},{"tv":10740.78,"batb":[[0,3.9,11.05]],"trd":[[3.9,1721.39]],"atb":[[3.9,11.05]],"atl":[[15,0]],"id":88302242},{"atl":[[180,0]],"id":97736949}],"tv":31285.92}],"rt":639159129243898041,"dt":639159129243898798}
{"op":"mcm","id":2,"clk":"AOYPAOMHAPsU","pt":1780316124482,"mc":[{"id":"1.258742455","rc":[{"atl":[[3.95,13.99]],"batl":[[2,4.1,94.41],[1,4,12.48],[0,3.95,13.99]],"id":88302242}]}],"rt":639159129244901741,"dt":639159129244902168}
{"op":"mcm","id":2,"clk":"AOsPAOcHAIMV","pt":1780316124584,"mc":[{"id":"1.258742455","rc":[{"tv":7135.63,"batb":[[0,4.2,122.05]],"trd":[[4.2,364.81]],"ltp":4.2,"atb":[[4.2,122.05]],"id":99072898},{"batb":[[0,3.9,2.31]],"atb":[[3.9,2.31]],"id":88302242}],"tv":31289.92}],"rt":639159129245923265,"dt":639159129245923670}
{"op":"mcm","id":2,"clk":"APQPAOoHAIsV","pt":1780316124696,"mc":[{"id":"1.258742455","rc":[{"batb":[[0,65,11.56]],"atb":[[65,11.56]],"id":98464183},{"batb":[[1,11.5,22.63]],"atb":[[11.5,22.63]],"id":97736949}]}],"rt":639159129247037245,"dt":639159129247037593}
{"op":"mcm","id":2,"clk":"AKwQAIkIAOEV","pt":1780316125606,"mc":[{"id":"1.258742455","rc":[{"atl":[[4.5,5.04]],"batl":[[0,4.5,5.04]],"id":10398159},{"atl":[[90,3.74]],"batl":[],"id":98464183}]}],"rt":639159129256140559,"dt":639159129256141079}
{"op":"mcm","id":2,"clk":"ALEQAI0IAOoV","pt":1780316125713,"mc":[{"id":"1.258742455","rc":[{"atl":[[32,0]],"id":88302242}]}],"rt":639159129257208661,"dt":639159129257208992}
{"op":"mcm","id":2,"clk":"AMUQAJsIAIUW","pt":1780316126020,"mc":[{"id":"1.258742455","rc":[{"tv":7154.31,"trd":[[4.4,15.8],[4.3,199.9]],"ltp":4.4,"atl":[[4.4,0],[4.3,0]],"batl":[[2,4.7,25.71],[1,4.6,2.57],[0,4.5,22.89]],"id":99072898},{"batb":[[2,3.75,34.73],[1,3.8,78.24],[0,3.85,23.2]],"atb":[[3.9,0]],"id":88302242}],"tv":31308.6}],"rt":639159129260284356,"dt":639159129260285189}
{"op":"mcm","id":2,"clk":"AMwQAJ4IAI0W","pt":1780316126125,"mc":[{"id":"1.258742455","rc":[{"tv":7169.21,"batb":[[2,4.1,78.98],[1,4.2,122.05],[0,4.3,15.26]],"trd":[[4.5,14.9]],"ltp":4.5,"atb":[[4.1,78.98],[3.95,17.05],[4.3,15.26]],"atl":[[4.7,3.23],[4.6,16.44],[4.5,1]],"batl":[[2,4.7,3.23],[1,4.6,16.44],[0,4.5,1]],"id":99072898},{"atl":[[4.5,23.46]],"batl":[[0,4.5,23.46]],"id":10398159},{"batb":[[0,65,9.11]],"atb":[[65,9.11]],"id":98464183},{"tv":1999.43,"batb":[[0,9,29.07]],"trd":[[9.2,123.13]],"atb":[[9.2,0],[9,29.07]],"atl":[[9.2,2.92]],"batl":[[2,9.6,4.67],[1,9.4,13.54],[0,9.2,2.92]],"id":98117699},{"batb":[[0,3.85,10.78]],"atb":[[3.85,10.78]],"atl":[[3.9,12.72],[4.3,20.4]],"batl":[[2,4,12.48],[1,3.95,13.99],[0,3.9,12.72]],"id":88302242},{"batb":[[1,11.5,19.86]],"atb":[[11.5,19.86]],"id":97736949}],"tv":31324.7}],"rt":639159129261340861,"dt":639159129261342014}
{"op":"mcm","id":2,"clk":"AM4QAKAIAJQW","pt":1780316126174,"mc":[{"id":"1.258742455","rc":[{"batb":[[1,4.2,130.11]],"atb":[[4.2,130.11]],"atl":[[4.4,1.91]],"batl":[[2,4.6,16.44],[1,4.5,1],[0,4.4,1.91]],"id":99072898},{"batb":[[1,4.3,88.47],[0,4.4,95.2]],"atb":[[4.4,95.2],[4.3,88.47]],"id":10398159}]}],"rt":639159129261824003,"dt":639159129261824513}
{"op":"mcm","id":2,"clk":"ANgQAKYIAKAW","pt":1780316126280,"mc":[{"id":"1.258742455","rc":[{"tv":7173.03,"batb":[[2,4.2,130.11],[1,4.3,20.54],[0,4.4,17.04]],"trd":[[4.4,19.62]],"ltp":4.4,"atb":[[4.4,17.04],[4.3,20.54]],"atl":[[4.4,0],[4.6,19.32],[4.5,0]],"batl":[[2,4.8,24.17],[1,4.7,3.23],[0,4.6,19.32]],"id":99072898},{"batb":[[2,38,14.26],[0,42,8.51]],"atb":[[42,8.51],[38,14.26]],"id":97008932},{"atl":[[25,3.34]],"batl":[[0,25,3.34]],"id":99072900},{"atl":[[4.5,25.46]],"batl":[[0,4.5,25.46]],"id":10398159},{"batb":[[2,8.6,12.05],[1,8.8,14.74]],"atb":[[1.17,2.57],[8.8,14.74],[8.6,12.05]],"id":98117699},{"batb":[[0,3.85,18.15]],"atb":[[3.85,18.15]],"atl":[[4.2,14.54]],"batl":[],"id":88302242},{"batb":[[2,11,6.94]],"atb":[[11,6.94],[10.5,13.16]],"id":97736949}],"tv":31328.52}],"rt":639159129262882418,"dt":639159129262883331}
{"op":"mcm","id":2,"clk":"AN0QAKgIAKkW","pt":1780316126382,"mc":[{"id":"1.258742455","rc":[{"batb":[[1,4.3,32.53],[0,4.4,28.04]],"atb":[[4.4,28.04],[3.95,4.39],[4.3,32.53]],"atl":[[4.5,14.43]],"batl":[[2,4.7,3.23],[1,4.6,19.32],[0,4.5,14.43]],"id":99072898},{"batb":[[1,40,5.46]],"atb":[[40,5.46]],"id":97008932},{"batb":[[2,8.6,8.95],[0,9,21.1]],"atb":[[1.17,2],[8.4,6.8],[9,21.1],[8.6,8.95]],"atl":[[9.4,5.62],[9.2,12.42]],"batl":[[1,9.4,5.62],[0,9.2,12.42]],"id":98117699}]}],"rt":639159129263899770,"dt":639159129263900362}
{"op":"mcm","id":2,"clk":"AOYQAKwIALAW","pt":1780316126488,"mc":[{"id":"1.258742455","rc":[{"tv":7201.89,"trd":[[4.5,43.76]],"ltp":4.5,"atl":[[4.5,0]],"batl":[[2,4.8,24.17],[1,4.7,3.23],[0,4.6,19.32]],"id":99072898},{"tv":2000.57,"batb":[[0,9,20.1]],"trd":[[9.2,124.27]],"atb":[[9,20.1]],"atl":[[9.2,13.78]],"batl":[[0,9.2,13.78]],"id":98117699}],"tv":31358.52}],"rt":639159129264965344,"dt":639159129264965841}
{"op":"mcm","id":2,"clk":"AOwQAK8IALgW","pt":1780316126589,"mc":[{"id":"1.258742455","rc":[{"batb":[],"atb":[[21,11.14]],"id":99072900},{"atl":[[5,26.61]],"batl":[],"id":10398159},{"atl":[[4.2,32.45],[3.95,15.72]],"batl":[[1,3.95,15.72]],"id":88302242}]}],"rt":639159129265973649,"dt":639159129265974358}
{"op":"mcm","id":2,"clk":"AJIRALsIANsW","pt":1780316127002,"mc":[{"id":"1.258742455","rc":[{"atl":[[95,3.91]],"batl":[],"id":98464183}]}],"rt":639159129270100327,"dt":639159129270100683}
{"op":"mcm","id":2,"clk":"AJsRAL0IAOUW","pt":1780316127110,"mc":[{"id":"1.258742455","rc":[{"batb":[[2,38,12.82]],"atb":[[38,12.82]],"id":97008932},{"tv":2002.21,"trd":[[9.2,125.91]],"atl":[[9.2,12.96]],"batl":[[0,9.2,12.96]],"id":98117699}],"tv":31360.16}],"rt":639159129271181851,"dt":639159129271182544}
{"op":"mcm","id":2,"clk":"AJ8RAMEIAPEW","pt":1780316127213,"mc":[{"id":"1.258742455","rc":[{"batb":[[0,42,9.8]],"atb":[[42,9.8]],"id":97008932},{"atl":[[4.5,27.46]],"batl":[[0,4.5,27.46]],"id":10398159},{"atl":[[70,11.84]],"batl":[[0,70,11.84]],"id":98464183}]}],"rt":639159129272214183,"dt":639159129272214566}
{"op":"mcm","id":2,"clk":"AKwRAMcIAPcW","pt":1780316127315,"mc":[{"id":"1.258742455","rc":[{"atl":[[4.9,23.89]],"batl":[],"id":99072898}]}],"rt":639159129273233682,"dt":639159129273234073}
{"op":"mcm","id":2,"clk":"ALQRAMoIAIIX","pt":1780316127419,"mc":[{"id":"1.258742455","rc":[{"atl":[[3.95,25.72]],"batl":[[1,3.95,25.72]],"id":88302242}]}],"rt":639159129274270748,"dt":639159129274271192}
{"op":"mcm","id":2,"clk":"ALcRAMwIAIsX","pt":1780316127469,"mc":[{"id":"1.258742455","rc":[{"batb":[[1,4.3,34.31]],"atb":[[4.3,34.31]],"id":99072898},{"atl":[[25,1.89]],"batl":[[0,25,1.89]],"id":99072900},{"atl":[[4.7,270.6]],"batl":[[2,4.7,270.6]],"id":10398159},{"tv":556.42,"batb":[[0,65,9.06]],"trd":[[65,37.49]],"atb":[[65,9.06]],"id":98464183},{"batb":[[1,3.8,76.24]],"atb":[[3.8,76.24]],"id":88302242}],"tv":31360.26}],"rt":639159129274772991,"dt":639159129274773447}
{"op":"mcm","id":2,"clk":"AMARANEIAJUX","pt":1780316127574,"mc":[{"id":"1.258742455","rc":[{"batb":[[0,4.4,29.36]],"atb":[[4.4,29.36],[4.1,78.02]],"atl":[[5.2,39.57],[5.1,5.1]],"batl":[],"id":99072898},{"batb":[[1,23,10.97],[0,24,14.31]],"atb":[[24,14.31],[23,10.97]],"id":99072900},{"atl":[[4.6,34.9]],"batl":[[1,4.6,34.9]],"id":10398159},{"atl":[[9.4,5.04],[1000,7.58],[9.6,3.6]],"batl":[[2,9.6,3.6],[1,9.4,5.04]],"id":98117699},{"atl":[[1000,3.4]],"id":88302242}]}],"rt":639159129275824305,"dt":639159129275824864}
{"op":"mcm","id":2,"clk":"AMIRANMIAKEX","pt":1780316127681,"mc":[{"id":"1.258742455","rc":[{"atl":[[4.5,31.64]],"batl":[[0,4.5,31.64]],"id":10398159},{"atl":[[1000,6.25]],"id":98117699},{"atl":[[1000,3]],"id":88302242},{"batb":[[0,12,26.8]],"atb":[[12,26.8]],"id":97736949}]}],"rt":639159129276888122,"dt":639159129276888549}
{"op":"mcm","id":2,"clk":"AMcRANgIAKoX","pt":1780316127782,"mc":[{"id":"1.258742455","rc":[{"atl":[[4.6,21.32]],"batl":[[0,4.6,21.32]],"id":99072898},{"atl":[[9.4,5.81],[9.2,13.52]],"batl":[[1,9.4,5.81],[0,9.2,13.52]],"id":98117699},{"tv":10800.78,"batb":[[2,3.7,36.44],[1,3.75,34.73],[0,3.8,64.39]],"trd":[[3.8,615.27],[3.85,1367.99]],"ltp":3.8,"atb":[[3.8,64.39],[3.85,0]],"atl":[[3.9,13.12]],"batl":[[0,3.9,13.12]],"id":88302242}],"tv":31420.26}],"rt":639159129277908072,"dt":639159129277908761}
{"op":"mcm","id":2,"clk":"ANMRANsIALcX","pt":1780316127889,"mc":[{"id":"1.258742455","rc":[{"batb":[[0,4.4,37.18]],"atb":[[4.4,37.18]],"atl":[[4.6,18.44]],"batl":[[0,4.6,18.44]],"id":99072898}]}],"rt":639159129278969429,"dt":639159129278970033}
{"op":"mcm","id":2,"clk":"ANkRAN4IAL0X","pt":1780316127988,"mc":[{"id":"1.258742455","rc":[{"tv":7007.84,"batb":[[0,4.4,94.7]],"trd":[[4.4,605.77]],"ltp":4.4,"atb":[[4.4,94.7]],"id":10398159},{"tv":1741.52,"batb":[[0,12,27.98]],"trd":[[13,16.78]],"ltp":13,"atb":[[12,27.98]],"atl":[[13,8.71]],"batl":[[0,13,8.71]],"id":97736949}],"tv":31421.35}],"rt":639159129279966277,"dt":639159129279966993}
{"op":"mcm","id":2,"clk":"AO8RAOoIAOMX","pt":1780316128398,"mc":[{"id":"1.258742455","rc":[{"atb":[[1.03,2212.47]],"id":99072898},{"atb":[[1.17,2.23]],"id":97008932},{"tv":886.35,"batb":[[0,24,13.89]],"trd":[[24,81.63]],"atb":[[24,13.89]],"atl":[[25,2.29]],"batl":[[0,25,2.29]],"id":99072900},{"batb":[[0,75,9.79]],"atb":[[75,9.79]],"id":99072901},{"atb":[[1.17,2.28]],"id":10398159},{"atl":[[70,12]],"batl":[[0,70,12]],"id":98464183},{"tv":10803.12,"batb":[[2,3.75,34.73],[1,3.8,64.39],[0,3.85,1.11]],"trd":[[3.9,1723.73]],"ltp":3.9,"atb":[[3.85,1.11]],"atl":[[3.9,11.95]],"batl":[[0,3.9,11.95]],"id":88302242}],"tv":31424.53}],"rt":639159129284066528,"dt":639159129284067246}
{"op":"mcm","id":2,"clk":"APURAO0IAOkX","pt":1780316128501,"mc":[{"id":"1.258742455","rc":[{"atb":[[1.17,2]],"id":97008932},{"atb":[[1.17,2]],"atl":[[4.7,70.6]],"batl":[[2,4.7,70.6]],"id":10398159}]}],"rt":639159129285093294,"dt":639159129285093662}
{"op":"mcm","id":2,"clk":"APwRAO8IAO4X","pt":1780316128603,"mc":[{"id":"1.258742455","rc":[{"atb":[[1.03,2212.2]],"id":99072898},{"batb":[[0,42,10.03]],"atb":[[42,10.03]],"id":97008932},{"tv":7008.4,"trd":[[4.5,1492.99]],"ltp":4.5,"atl":[[4.5,31.36]],"batl":[[0,4.5,31.36]],"id":10398159},{"tv":10805.34,"batb":[[2,3.7,36.44],[1,3.75,34.73],[0,3.8,64.39]],"trd":[[3.85,1370.21]],"ltp":3.85,"atb":[[3.85,0]],"id":88302242}],"tv":31427.31}],"rt":639159129286112221,"dt":639159129286112695}
{"op":"mcm","id":2,"clk":"AIQSAPEIAPYX","pt":1780316128705,"mc":[{"id":"1.258742455","rc":[{"tv":7071.11,"batb":[[2,4.3,88.47],[1,4.4,94.7],[0,4.5,18.64]],"trd":[[4.5,1555.7]],"atb":[[4.5,18.64]],"atl":[[4.5,0]],"batl":[[2,4.8,14.82],[1,4.7,70.6],[0,4.6,34.9]],"id":10398159}],"tv":31490.02}],"rt":639159129287129066,"dt":639159129287129484}
{"op":"mcm","id":2,"clk":"AI0SAPQIAP8X","pt":1780316128807,"mc":[{"id":"1.258742455","rc":[{"batb":[[0,4.4,29.36]],"atb":[[4.4,29.36],[1.03,2211.6]],"atl":[[4.6,21.67]],"batl":[[0,4.6,21.67]],"id":99072898},{"batb":[[2,4.3,96.16]],"atb":[[4.3,96.16]],"id":10398159},{"atl":[[4.1,98.99]],"batl":[],"id":88302242}]}],"rt":639159129288153568,"dt":639159129288154006}
{"op":"mcm","id":2,"clk":"AJESAPcIAIoY","pt":1780316128915,"mc":[{"id":"1.258742455","rc":[{"batb":[[1,4.3,34.9]],"atb":[[4.3,34.9]],"id":99072898},{"batb":[[0,42,8.09]],"atb":[[42,8.09]],"id":97008932},{"batb":[[0,24,9.95]],"atb":[[24,9.95]],"id":99072900},{"batb":[[0,4.5,37.26]],"atb":[[4.5,37.26]],"atl":[[5,4.99]],"batl":[],"id":10398159},{"batb":[[0,65,7.11]],"atb":[[65,7.11]],"id":98464183},{"batb":[[0,3.8,49.41]],"atb":[[3.8,49.41]],"id":88302242},{"tv":162.67,"batb":[[0,1000,106.04]],"trd":[[1000,118.19]],"atb":[[1000,106.04]],"id":10445502}],"tv":31492.02}],"rt":639159129289233276,"dt":639159129289233958}
{"op":"mcm","id":2,"clk":"AJcSAPwIAJEY","pt":1780316129014,"mc":[{"id":"1.258742455","rc":[{"atl":[[5,36.61]],"batl":[],"id":99072898},{"batb":[[2,38,11.09]],"atb":[[38,11.09]],"id":97008932},{"atl":[[5.1,28.15]],"batl":[],"id":10398159},{"tv":559.34,"batb":[[0,65,5.65]],"trd":[[65,40.41]],"atb":[[65,5.65]],"id":98464183},{"batb":[[1,3.75,43.81],[0,3.8,40.39]],"atb":[[3.75,43.81],[3.8,40.39]],"id":88302242}],"tv":31494.94}],"rt":639159129290227803,"dt":639159129290228628}
{"op":"mcm","id":2,"clk":"AJoSAP0IAJwY","pt":1780316129117,"mc":[{"id":"1.258742455","rc":[{"batb":[[1,4.4,93.86]],"atb":[[4.4,93.86]],"id":10398159},{"atl":[[9.6,5.59]],"batl":[[2,9.6,5.59]],"id":98117699}]}],"rt":639159129291252998,"dt":639159129291253768}
{"op":"mcm","id":2,"clk":"AJ8SAP8IAKYY","pt":1780316129215,"mc":[{"id":"1.258742455","rc":[{"tv":7073.11,"batb":[[0,4.5,36.26]],"trd":[[4.5,1557.7]],"atb":[[4.5,36.26]],"id":10398159}],"tv":31496.94}],"rt":639159129292237345,"dt":639159129292237796}
{"op":"mcm","id":2,"clk":"ALgSAI0JAMMY","pt":1780316129576,"mc":[{"id":"1.258742455","rc":[{"atl":[[13.5,35.48]],"batl":[[1,13.5,35.48]],"id":97736949}]}],"rt":639159129295844627,"dt":639159129295844957}
{"op":"mcm","id":2,"clk":"AMISAJAJANYY","pt":1780316129783,"mc":[{"id":"1.258742455","rc":[{"atl":[[70,12.34]],"batl":[[0,70,12.34]],"id":98464183}]}],"rt":639159129297912630,"dt":639159129297912977}
{"op":"mcm","id":2,"clk":"AMoSAJQJAN0Y","pt":1780316129890,"mc":[{"id":"1.258742455","rc":[{"tv":2004.21,"batb":[[0,9,19.1]],"trd":[[9,6]],"ltp":9,"atb":[[9,19.1]],"id":98117699}],"tv":31498.94}],"rt":639159129298977382,"dt":639159129298977751}
{"op":"mcm","id":2,"clk":"APASAKMJAJIZ","pt":1780316130505,"mc":[{"id":"1.258742455","rc":[{"batb":[[2,4.3,106.38]],"atb":[[4.3,106.38]],"id":10398159},{"tv":1745.26,"batb":[[0,12,30.63]],"trd":[[12,11.16]],"ltp":12,"atb":[[12,30.63]],"id":97736949}],"tv":31502.68}],"rt":639159129305130025,"dt":639159129305130625}
{"op":"mcm","id":2,"clk":"APgSAKUJAJ4Z","pt":1780316130613,"mc":[{"id":"1.258742455","rc":[{"atl":[[4.6,28.43]],"batl":[[0,4.6,28.43]],"id":99072898},{"tv":7074.11,"batb":[[1,4.4,101.67],[0,4.5,35.76]],"trd":[[4.5,1558.7]],"atb":[[4.4,101.67],[4.5,35.76]],"atl":[[4.6,39.36]],"batl":[[0,4.6,39.36]],"id":10398159},{"batb":[[0,9,22.85]],"atb":[[9,22.85]],"id":98117699},{"atl":[[1000,3.56]],"id":88302242},{"batb":[[0,12,31.07]],"atb":[[12,31.07],[10.5,10.38],[10,42.92]],"id":97736949}],"tv":31503.68}],"rt":639159129306216124,"dt":639159129306216661}
{"op":"mcm","id":2,"clk":"AP4SAKgJAKUZ","pt":1780316130712,"mc":[{"id":"1.258742455","rc":[{"batb":[],"atb":[[4.1,56.63]],"id":10398159},{"batb":[[0,9,19.21]],"atb":[[9,19.21]],"id":98117699},{"atl":[[1000,3]],"id":88302242}]}],"rt":639159129307202978,"dt":639159129307203366}
{"op":"mcm","id":2,"clk":"AIETAKoJAK0Z","pt":1780316130813,"mc":[{"id":"1.258742455","rc":[{"atl":[[3.95,26.28]],"batl":[[1,3.95,26.28]],"id":88302242}]}],"rt":639159129308214764,"dt":639159129308215095}
{"op":"mcm","id":2,"clk":"AIgTAKwJALMZ","pt":1780316130915,"mc":[{"id":"1.258742455","rc":[{"atl":[[3.85,15]],"batl":[[2,3.95,26.28],[1,3.9,11.95],[0,3.85,15]],"id":88302242}]}],"rt":639159129309231941,"dt":639159129309232242}
{"op":"mcm","id":2,"clk":"AI8TAK8JALwZ","pt":1780316131018,"mc":[{"id":"1.258742455","rc":[{"batb":[[0,4.5,85.76]],"atb":[[4.5,85.76]],"id":10398159},{"batb":[],"atb":[[10.5,13.2]],"id":97736949}]}],"rt":639159129310266764,"dt":639159129310267312}
{"op":"mcm","id":2,"clk":"AJgTALIJAMUZ","pt":1780316131123,"mc":[{"id":"1.258742455","rc":[{"batb":[[2,70,5],[1,75,9.79],[0,80,1.01]],"atb":[[80,1.01]],"id":99072901},{"tv":7086.65,"trd":[[4.6,505.27]],"ltp":4.6,"atl":[[4.6,33.09]],"batl":[[0,4.6,33.09]],"id":10398159},{"batb":[[0,9,22.96]],"atb":[[9,22.96]],"id":98117699},{"tv":10809.16,"batb":[[0,3.8,37.81]],"trd":[[3.85,1374.03]],"atb":[[3.8,37.81]],"atl":[[3.85,24.77]],"batl":[[0,3.85,24.77]],"id":88302242}],"tv":31520.04}],"rt":639159129311316346,"dt":639159129311316848}
{"op":"mcm","id":2,"clk":"AJoTALUJAMsZ","pt":1780316131174,"mc":[{"id":"1.258742455","rc":[{"batb":[[1,4.3,36.9]],"atb":[[4.3,36.9]],"id":99072898},{"batb":[[1,4.4,112.67]],"atb":[[4.4,112.67]],"id":10398159},{"batb":[],"atb":[[10.5,10.38]],"id":97736949}]}],"rt":639159129311823935,"dt":639159129311824327}
{"op":"mcm","id":2,"clk":"AKATALcJANMZ","pt":1780316131277,"mc":[{"id":"1.258742455","rc":[{"atl":[[9.2,4.03]],"batl":[[0,9.2,4.03]],"id":98117699},{"atl":[[3.95,25.32]],"batl":[[2,3.95,25.32]],"id":88302242}]}],"rt":639159129312850234,"dt":639159129312850866}
{"op":"mcm","id":2,"clk":"AKgTALkJANwZ","pt":1780316131382,"mc":[{"id":"1.258742455","rc":[{"batb":[[1,75,8.68],[0,80,2.08]],"atb":[[80,2.08],[75,8.68]],"id":99072901}]}],"rt":639159129313904133,"dt":639159129313904477}
{"op":"mcm","id":2,"clk":"ALATALwJAOcZ","pt":1780316131483,"mc":[{"id":"1.258742455","rc":[{"batb":[[0,4.5,88.98]],"atb":[[4.5,88.98]],"id":10398159},{"atl":[[10,5.39],[9.6,3.6]],"batl":[[2,9.6,3.6]],"id":98117699}]}],"rt":639159129314917628,"dt":639159129314918328}
{"op":"mcm","id":2,"clk":"ALYTAL0JAPEZ","pt":1780316131584,"mc":[{"id":"1.258742455","rc":[{"tv":7098.65,"batb":[[0,4.5,82.98]],"trd":[[4.5,1570.7]],"ltp":4.5,"atb":[[4.5,82.98]],"id":10398159},{"tv":10824.84,"batb":[[0,3.8,29.97]],"trd":[[3.8,630.95]],"ltp":3.8,"atb":[[3.8,29.97]],"id":88302242}],"tv":31547.72}],"rt":639159129315923893,"dt":639159129315924434}
{"op":"mcm","id":2,"clk":"AL0TAL4JAPgZ","pt":1780316131687,"mc":[{"id":"1.258742455","rc":[{"batb":[[2,4.3,96.16],[1,4.4,180.33]],"atb":[[4.4,180.33],[4.3,96.16]],"id":10398159}]}],"rt":639159129316957317,"dt":639159129316957770}
{"op":"mcm","id":2,"clk":"AMETAMAJAIQa","pt":1780316131801,"mc":[{"id":"1.258742455","rc":[{"atl":[[18,20]],"id":99072898},{"atl":[[18,20]],"id":10398159},{"atl":[[80,20]],"id":98117699},{"atl":[[13.5,22.09]],"id":88302242},{"atl":[[160,22]],"id":97736949}]}],"rt":639159129318096339,"dt":639159129318096792}
{"op":"mcm","id":2,"clk":"ANUTAMUJAJwa","pt":1780316131999,"mc":[{"id":"1.258742455","rc":[{"atl":[[32,3.95]],"id":10398159},{"atl":[[50,1.99]],"id":97736949}]}],"rt":639159129320074235,"dt":639159129320074893}
{"op":"mcm","id":2,"clk":"APITAMwJALga","pt":1780316132308,"mc":[{"id":"1.258742455","rc":[{"batb":[],"atb":[[4,47.52]],"id":99072898},{"atl":[[4.4,34.04]],"batl":[],"id":88302242}]}],"rt":639159129323166252,"dt":639159129323166872}
{"op":"mcm","id":2,"clk":"APgTAM0JALsa","pt":1780316132406,"mc":[{"id":"1.258742455","rc":[{"atl":[[9.2,12.68]],"batl":[[0,9.2,12.68]],"id":98117699}]}],"rt":639159129324146531,"dt":639159129324147054}
{"op":"mcm","id":2,"clk":"AIoUANYJANka","pt":1780316132713,"mc":[{"id":"1.258742455","rc":[{"atl":[[5.6,19.77]],"id":88302242}]}],"rt":639159129327216647,"dt":639159129327216971}
{"op":"mcm","id":2,"clk":"AKgUAOQJAPwa","pt":1780316133183,"mc":[{"id":"1.258742455","rc":[{"atl":[[4.8,67.45]],"batl":[[2,4.8,67.45]],"id":10398159}]}],"rt":639159129331919497,"dt":639159129331919850}
{"op":"mcm","id":2,"clk":"ALcUAOkJAIgb","pt":1780316133386,"mc":[{"id":"1.258742455","rc":[{"tv":563.34,"batb":[[0,65,3.65]],"trd":[[65,44.41]],"atb":[[65,3.65]],"id":98464183}],"tv":31551.72}],"rt":639159129333941082,"dt":639159129333941665}
{"op":"mcm","id":2,"clk":"ALwUAOsJAI8b","pt":1780316133488,"mc":[{"id":"1.258742455","rc":[{"atl":[[4.6,30.21]],"batl":[[0,4.6,30.21]],"id":99072898},{"atb":[[1.17,2.19]],"id":99072900},{"batb":[[1,4.4,172.52],[0,4.5,86.69]],"atb":[[4.4,172.52],[4.5,86.69]],"atl":[[1000,1.78],[4.6,31.51]],"batl":[[0,4.6,31.51]],"id":10398159},{"tv":567.36,"batb":[[0,65,1.64]],"trd":[[65,48.43]],"atb":[[65,1.64]],"id":98464183},{"atl":[[1000,3.27],[3.9,11.55],[3.95,24.76]],"batl":[[2,3.95,24.76],[1,3.9,11.55]],"id":88302242}],"tv":31555.74}],"rt":639159129334962849,"dt":639159129334963740}
{"op":"mcm","id":2,"clk":"AMIUAOwJAJQb","pt":1780316133590,"mc":[{"id":"1.258742455","rc":[{"atb":[[1.17,2]],"id":99072900},{"atl":[[1000,1.01]],"id":10398159},{"tv":568.76,"batb":[[2,50,15.6],[1,55,15.77],[0,60,21.87]],"trd":[[65,49.83]],"atb":[[1.05,2660],[65,0.94]],"id":98464183},{"atl":[[1000,3]],"id":88302242}],"tv":31557.14}],"rt":639159129335983617,"dt":639159129335984073}
{"op":"mcm","id":2,"clk":"AMwUAO0JAJkb","pt":1780316133691,"mc":[{"id":"1.258742455","rc":[{"batb":[[0,24,10.14]],"atb":[[24,10.14]],"id":99072900},{"atl":[[4.7,71.37]],"batl":[[1,4.7,71.37]],"id":10398159},{"tv":570.64,"batb":[[0,60,20.93]],"trd":[[65,51.71]],"atb":[[65,0]],"atl":[[65,1.39]],"batl":[[2,75,1.99],[1,70,12.34],[0,65,1.39]],"id":98464183},{"atl":[[3.9,11.71],[3.85,24.88]],"batl":[[1,3.9,11.71],[0,3.85,24.88]],"id":88302242}],"tv":31559.02}],"rt":639159129336990284,"dt":639159129336990981}
{"op":"mcm","id":2,"clk":"ANQUAO0JAKAb","pt":1780316133794,"mc":[{"id":"1.258742455","rc":[{"batb":[[0,12,25.84]],"atb":[[12,25.84]],"id":97736949}]}],"rt":639159129338025709,"dt":639159129338026287}
{"op":"mcm","id":2,"clk":"ANoUAO8JAKYb","pt":1780316133900,"mc":[{"id":"1.258742455","rc":[{"atb":[[1.17,2.17]],"id":97008932},{"atl":[[95,3.75]],"batl":[[0,95,3.75]],"id":99072901},{"atl":[[4.6,17.32]],"batl":[[0,4.6,17.32]],"id":10398159},{"batb":[[0,60,22.16]],"atb":[[60,22.16]],"atl":[[70,13.35]],"batl":[[1,70,13.35]],"id":98464183},{"tv":10828.36,"batb":[[0,3.8,43.38]],"trd":[[3.85,1377.55]],"ltp":3.85,"atb":[[3.8,43.38]],"atl":[[3.85,23.12]],"batl":[[0,3.85,23.12]],"id":88302242},{"tv":1809.04,"batb":[[2,10.5,3.47],[1,11,15.44],[0,11.5,4.35]],"trd":[[12,62.84],[11.5,12.1]],"ltp":11.5,"atb":[[12,0],[11.5,4.35],[11,15.44],[10.5,3.47]],"atl":[[13,21.19]],"batl":[[0,13,21.19]],"id":97736949},{"atl":[[1000,8.8]],"batl":[],"id":99072897}],"tv":31626.32}],"rt":639159129339086788,"dt":639159129339087568}
{"op":"mcm","id":2,"clk":"AOUUAPMJAKob","pt":1780316134000,"mc":[{"id":"1.258742455","rc":[{"batb":[[0,4.4,37.16]],"atb":[[4.4,37.16]],"id":99072898},{"atb":[[1.17,2]],"id":97008932},{"batb":[[0,24,14.13]],"atb":[[24,14.13]],"id":99072900},{"batb":[[0,4.5,97.69]],"atb":[[4.5,97.69]],"id":10398159},{"batb":[[0,3.8,52.44]],"atb":[[3.8,52.44]],"atl":[[4.1,94.41],[3.85,11.44]],"batl":[[0,3.85,11.44]],"id":88302242},{"tv":1817.74,"batb":[[2,10,46.09],[1,10.5,18.41],[0,11,15.44]],"trd":[[11.5,20.8]],"atb":[[9.8,20.54],[11.5,0],[10.5,18.41],[10,46.09]],"atl":[[12.5,7.51],[11.5,7.91]],"batl":[[2,13,21.19],[1,12.5,7.51],[0,11.5,7.91]],"id":97736949},{"atl":[[1000,8.75]],"batl":[],"id":99072897}],"tv":31635.02}],"rt":639159129340082774,"dt":639159129340083566}
{"op":"mcm","id":2,"clk":"AOkUAPYJALAb","pt":1780316134105,"mc":[{"id":"1.258742455","rc":[{"atl":[[4.6,26.98]],"batl":[[0,4.6,26.98]],"id":99072898},{"batb":[[0,42,6.06]],"atb":[[42,6.06]],"id":97008932},{"atl":[[25,5.23]],"batl":[[0,25,5.23]],"id":99072900},{"batb":[[0,80,1.01]],"atb":[[80,1.01]],"id":99072901},{"batb":[[1,4.4,180.12]],"atb":[[4.4,180.12]],"id":10398159},{"atl":[[70,13.29]],"batl":[[1,70,13.29]],"id":98464183},{"tv":10851.24,"batb":[[2,3.75,43.81],[1,3.8,52.44],[0,3.85,11.31]],"trd":[[3.85,1400.43]],"atb":[[3.85,11.31]],"atl":[[3.85,0]],"batl":[[2,4,12.48],[1,3.95,24.76],[0,3.9,11.71]],"id":88302242},{"tv":1824.98,"batb":[[2,10,31.67]],"trd":[[11.5,28.04]],"atb":[[9.8,17.56],[10,31.67],[9.6,5.06]],"atl":[[15,0],[14.5,0],[11.5,4.29]],"batl":[[0,11.5,4.29]],"id":97736949},{"atl":[[180,0.42]],"batl":[[0,190,3.07]],"id":99072897}],"tv":31665.14}],"rt":639159129341131049,"dt":639159129341132279}
{"op":"mcm","id":2,"clk":"APAUAPkJALgb","pt":1780316134208,"mc":[{"id":"1.258742455","rc":[{"batb":[[1,4.4,172.52]],"atb":[[4.4,172.52]],"id":10398159},{"tv":10873.86,"batb":[[2,3.7,36.44],[1,3.75,43.81],[0,3.8,52.44]],"trd":[[3.85,1423.05]],"atb":[[3.85,0]],"id":88302242},{"batb":[[0,11,5.94]],"atb":[[11,5.94]],"atl":[[13.5,20.66]],"batl":[],"id":97736949}],"tv":31687.76}],"rt":639159129342168129,"dt":639159129342168848}
{"op":"mcm","id":2,"clk":"AP4UAPwJAMAb","pt":1780316134313,"mc":[{"id":"1.258742455","rc":[{"atl":[[3.9,44.13]],"batl":[[0,3.9,44.13]],"id":88302242},{"batb":[[2,10,25.68],[1,10.5,12.42],[0,11,1.03]],"atb":[[11,1.03],[10.5,12.42],[10,25.68]],"atl":[[13,20.98]],"batl":[[2,13,20.98]],"id":97736949}]}],"rt":639159129343211016,"dt":639159129343211493}
{"op":"mcm","id":2,"clk":"AIsVAIMKAM8b","pt":1780316134512,"mc":[{"id":"1.258742455","rc":[{"batb":[[0,3.8,67.43]],"atb":[[3.8,67.43]],"id":88302242}]}],"rt":639159129345199620,"dt":639159129345199988}
{"op":"mcm","id":2,"clk":"AJcVAIcKAN4b","pt":1780316134716,"mc":[{"id":"1.258742455","rc":[{"batb":[[0,4.4,40.24]],"atb":[[4.4,40.24]],"id":99072898},{"batb":[[0,42,6.38]],"atb":[[42,6.38]],"id":97008932},{"batb":[[0,24,14.69]],"atb":[[24,14.69]],"id":99072900},{"batb":[[0,80,1.18]],"atb":[[80,1.18]],"id":99072901},{"batb":[[0,4.5,100.71]],"atb":[[4.5,100.71]],"id":10398159},{"batb":[[0,60,22.38]],"atb":[[60,22.38]],"id":98464183},{"batb":[[0,9,24.47]],"atb":[[9,24.47]],"id":98117699},{"batb":[[0,3.8,71]],"atb":[[3.8,71]],"id":88302242},{"batb":[[0,11,2.26]],"atb":[[11,2.26]],"id":97736949},{"batb":[[0,1000,106.05]],"atb":[[1000,106.05]],"id":10445502},{"batb":[[0,160,4.36]],"atb":[[160,4.36]],"id":99072897}]}],"rt":639159129347248211,"dt":639159129347248948}
{"op":"mcm","id":2,"clk":"AJsVAIcKAOQb","pt":1780316134817,"mc":[{"id":"1.258742455","rc":[{"tv":574.64,"batb":[[0,60,6.38]],"trd":[[60,23.43]],"ltp":60,"atb":[[60,6.38]],"id":98464183}],"tv":31691.76}],"rt":639159129348249032,"dt":639159129348249675}
{"op":"mcm","id":2,"clk":"AKgVAIoKAPAb","pt":1780316134974,"mc":[{"id":"1.258742455","rc":[{"batb":[[0,42,8.37]],"atb":[[42,8.37]],"id":97008932},{"atl":[[65,2.83]],"batl":[[0,65,2.83]],"id":98464183}]}],"rt":639159129349818761,"dt":639159129349819195}
{"op":"mcm","id":2,"clk":"AK4VAIwKAPUb","pt":1780316135082,"mc":[{"id":"1.258742455","rc":[{"batb":[[0,60,4.28]],"atb":[[60,4.28]],"id":98464183},{"batb":[[0,11,2.88]],"atb":[[11,2.88]],"id":97736949}]}],"rt":639159129350907058,"dt":639159129350907573}
{"op":"mcm","id":2,"clk":"ALYVAI4KAPsb","pt":1780316135188,"mc":[{"id":"1.258742455","rc":[{"atl":[[70,11.51]],"batl":[[1,70,11.51]],"id":98464183}]}],"rt":639159129351958012,"dt":639159129351958372}
{"op":"mcm","id":2,"clk":"AMYVAJQKAIwc","pt":1780316135487,"mc":[{"id":"1.258742455","rc":[{"tv":165.09,"batb":[[0,1000,104.84]],"trd":[[1000,120.61]],"atb":[[1000,104.84]],"id":10445502}],"tv":31694.18}],"rt":639159129354952994,"dt":639159129354953520}
{"op":"mcm","id":2,"clk":"AM4VAJcKAJMc","pt":1780316135593,"mc":[{"id":"1.258742455","rc":[{"tv":1825.11,"trd":[[11.5,28.17]],"atl":[[11.5,4.23]],"batl":[[0,11.5,4.23]],"id":97736949}],"tv":31694.31}],"rt":639159129356012088,"dt":639159129356012440}
{"op":"mcm","id":2,"clk":"AOAVAJsKAJ4c","pt":1780316135798,"mc":[{"id":"1.258742455","rc":[{"batb":[[1,4.3,37.9]],"atb":[[4.3,37.9]],"id":99072898},{"batb":[[0,4.5,101.71]],"atb":[[4.5,101.71]],"id":10398159},{"batb":[],"atb":[[9.4,2.99],[9.6,6.06]],"id":97736949}]}],"rt":639159129358065688,"dt":639159129358066313}
{"op":"mcm","id":2,"clk":"APUVAKIKALsc","pt":1780316136207,"mc":[{"id":"1.258742455","rc":[{"atl":[[11.5,0]],"batl":[[2,13.5,20.66],[1,13,20.98],[0,12.5,7.51]],"id":97736949}]}],"rt":639159129362150378,"dt":639159129362150733}
{"op":"mcm","id":2,"clk":"AIIWAKQKAMEc","pt":1780316136310,"mc":[{"id":"1.258742455","rc":[{"batb":[[1,4.4,180.1]],"atb":[[4.4,180.1]],"id":10398159}]}],"rt":639159129363181373,"dt":639159129363181958}
{"op":"mcm","id":2,"clk":"AIsWAKYKAMoc","pt":1780316136413,"mc":[{"id":"1.258742455","rc":[{"tv":2041.19,"batb":[[2,8.8,14.74],[1,9,24.47],[0,9.4,1.92]],"trd":[[9.4,105.51],[9.2,151.27]],"ltp":9.4,"atb":[[9.4,1.92]],"atl":[[9.4,0],[9.2,0]],"batl":[[2,10,5.39],[1,9.8,5.14],[0,9.6,3.6]],"id":98117699},{"atl":[[12,13.04]],"batl":[[2,13,20.98],[1,12.5,7.51],[0,12,13.04]],"id":97736949}],"tv":31731.29}],"rt":639159129364212692,"dt":639159129364213145}
{"op":"mcm","id":2,"clk":"AJIWAKcKANQc","pt":1780316136514,"mc":[{"id":"1.258742455","rc":[{"atl":[[4.6,30.88]],"batl":[[0,4.6,30.88]],"id":99072898},{"atb":[[1.17,2.26]],"id":99072900},{"batb":[[1,4.4,172.52]],"atb":[[4.4,172.52]],"id":10398159},{"tv":2045.03,"batb":[[2,8.8,18.53],[0,9.2,7.47]],"trd":[[9.4,109.35]],"atb":[[9.4,0],[8.8,18.53],[9.2,7.47]],"atl":[[10.5,7.52],[10,3.49],[9.6,0]],"batl":[[2,10.5,7.52],[1,10,3.49],[0,9.8,5.14]],"id":98117699},{"atb":[[1.17,195.88]],"atl":[[4.1,98.94]],"batl":[],"id":88302242},{"batb":[],"atb":[[9.4,6.08],[9.6,2.99]],"atl":[[11.5,7.95]],"batl":[[2,12.5,7.51],[1,12,13.04],[0,11.5,7.95]],"id":97736949}],"tv":31735.13}],"rt":639159129365226984,"dt":639159129365227982}
{"op":"mcm","id":2,"clk":"AJsWAKkKANwc","pt":1780316136618,"mc":[{"id":"1.258742455","rc":[{"atb":[[1.17,2]],"id":99072900},{"batb":[[2,9,24.47],[1,9.2,7.47],[0,9.4,3.8]],"atb":[[9.4,3.8]],"atl":[[9.8,0]],"batl":[[2,11,2.99],[1,10.5,7.52],[0,10,3.49]],"id":98117699},{"batb":[[0,3.8,56.01]],"atb":[[1.17,195.12],[3.8,56.01]],"atl":[[3.85,11.56]],"batl":[[2,3.95,24.76],[1,3.9,44.13],[0,3.85,11.56]],"id":88302242}]}],"rt":639159129366267753,"dt":639159129366268199}
{"op":"mcm","id":2,"clk":"AKIWAKoKAOgc","pt":1780316136719,"mc":[{"id":"1.258742455","rc":[{"batb":[[1,23,11.23]],"atb":[[23,11.23]],"id":99072900},{"atl":[[9.8,8.56]],"batl":[[2,10.5,7.52],[1,10,3.49],[0,9.8,8.56]],"id":98117699},{"batb":[[0,3.8,56.77]],"atb":[[3.8,56.77]],"id":88302242},{"batb":[],"atb":[[9.4,2.99],[9.8,2.99],[9.2,5.14]],"atl":[[14,5.45]],"batl":[],"id":97736949}]}],"rt":639159129367279734,"dt":639159129367280200}
{"op":"mcm","id":2,"clk":"AKYWAKwKAO8c","pt":1780316136821,"mc":[{"id":"1.258742455","rc":[{"batb":[[2,9,29.98],[1,9.2,14.98],[0,9.4,11.31]],"atb":[[9.4,11.31],[9.2,14.98],[9,29.98]],"atl":[[9.8,12.16]],"batl":[[0,9.8,12.16]],"id":98117699},{"batb":[],"atb":[[9.4,6.11]],"id":97736949}]}],"rt":639159129368292141,"dt":639159129368292734}
{"op":"mcm","id":2,"clk":"ALAWAK4KAPgc","pt":1780316136923,"mc":[{"id":"1.258742455","rc":[{"tv":7100.65,"batb":[[0,4.5,100.71]],"trd":[[4.5,1572.7]],"atb":[[4.5,100.71]],"id":10398159},{"batb":[[0,9.4,14.94]],"atb":[[9.4,14.94]],"id":98117699}],"tv":31737.13}],"rt":639159129369314951,"dt":639159129369315367}
{"op":"mcm","id":2,"clk":"ALIWAK8KAIId","pt":1780316136978,"mc":[{"id":"1.258742455","rc":[{"atl":[[4.6,41.49]],"batl":[[0,4.6,41.49]],"id":10398159}]}],"rt":639159129369859295,"dt":639159129369859624}
{"op":"mcm","id":2,"clk":"ALgWALQKAIwd","pt":1780316137082,"mc":[{"id":"1.258742455","rc":[{"batb":[[0,60,26.28]],"atb":[[60,26.28]],"id":98464183},{"tv":2049.03,"batb":[[2,9.2,14.98],[1,9.4,12.94],[0,9.6,3.58]],"trd":[[9.4,113.35]],"atb":[[9.4,12.94],[9.6,3.58]],"id":98117699}],"tv":31741.13}],"rt":639159129370904655,"dt":639159129370905083}
{"op":"mcm","id":2,"clk":"ALwWALYKAJQd","pt":1780316137184,"mc":[{"id":"1.258742455","rc":[{"atl":[[4.6,41.99]],"batl":[[0,4.6,41.99]],"id":10398159},{"batb":[[0,60,28.89]],"atb":[[60,28.89]],"id":98464183},{"atl":[[9.8,3.6]],"batl":[[0,9.8,3.6]],"id":98117699},{"batb":[[0,3.8,47.71]],"atb":[[3.8,47.71]],"id":88302242}]}],"rt":639159129371920802,"dt":639159129371921480}
{"op":"mcm","id":2,"clk":"AMMWALkKAJsd","pt":1780316137287,"mc":[{"id":"1.258742455","rc":[{"atl":[[65,2.88]],"batl":[[0,65,2.88]],"id":98464183},{"tv":2056.19,"batb":[[2,9,29.98],[1,9.2,14.98],[0,9.4,12.94]],"trd":[[9.6,205.98]],"ltp":9.6,"atb":[[9.6,0]],"atl":[[9.6,1.8]],"batl":[[2,10,3.49],[1,9.8,3.6],[0,9.6,1.8]],"id":98117699}],"tv":31748.29}],"rt":639159129372957506,"dt":639159129372958090}
{"op":"mcm","id":2,"clk":"AM4WALwKAKQd","pt":1780316137388,"mc":[{"id":"1.258742455","rc":[{"atl":[[65,3.28]],"batl":[[0,65,3.28]],"id":98464183},{"batb":[[0,9.4,9.31]],"atb":[[9.4,9.31]],"id":98117699}]}],"rt":639159129373967893,"dt":639159129373968257}
{"op":"mcm","id":2,"clk":"AN8WAMcKAL8d","pt":1780316137700,"mc":[{"id":"1.258742455","rc":[{"atl":[[50,4.11]],"id":97736949}]}],"rt":639159129377085692,"dt":639159129377086015}
{"op":"mcm","id":2,"clk":"AOIWAMwKAMgd","pt":1780316137806,"mc":[{"id":"1.258742455","rc":[{"atl":[[5.2,0],[5.3,46.41]],"batl":[],"id":99072898},{"tv":7102.38,"batb":[[0,4.5,99.85]],"trd":[[4.5,1574.43]],"atb":[[4.5,99.85]],"id":10398159},{"tv":574.76,"batb":[[0,60,28.83]],"trd":[[60,23.55]],"atb":[[60,28.83]],"id":98464183},{"atl":[[12,21.63],[11.5,4.9],[9.6,5.43]],"batl":[[0,9.6,5.43]],"id":98117699},{"tv":10874.06,"batb":[[0,3.8,47.61]],"trd":[[3.8,631.15]],"ltp":3.8,"atb":[[3.8,47.61]],"atl":[[3.85,12.41]],"batl":[[0,3.85,12.41]],"id":88302242},{"batb":[[0,11,4.55]],"atb":[[11,4.55]],"atl":[[13.5,6.67],[12,24.62]],"batl":[[1,12,24.62]],"id":97736949}],"tv":31750.34}],"rt":639159129378145762,"dt":639159129378146492}
{"op":"mcm","id":2,"clk":"AOsWANEKANwd","pt":1780316138013,"mc":[{"id":"1.258742455","rc":[{"batb":[[0,80,2.16]],"atb":[[80,2.16]],"id":99072901},{"batb":[[0,9.4,1.8]],"atb":[[9.4,1.8]],"id":98117699}]}],"rt":639159129380216964,"dt":639159129380217339}
{"op":"mcm","id":2,"clk":"APEWANMKAOMd","pt":1780316138116,"mc":[{"id":"1.258742455","rc":[{"atl":[[4.6,46.26]],"batl":[[0,4.6,46.26]],"id":10398159}]}],"rt":639159129381243708,"dt":639159129381244061}
{"op":"mcm","id":2,"clk":"AP0WANcKAO8d","pt":1780316138220,"mc":[{"id":"1.258742455","rc":[{"atl":[[46,2.52]],"batl":[[0,46,2.52]],"id":97008932},{"tv":574.77,"batb":[[0,60,28.82]],"trd":[[60,23.56]],"atb":[[60,28.82]],"id":98464183}],"tv":31750.35}],"rt":639159129382285684,"dt":639159129382286088}
{"op":"mcm","id":2,"clk":"AJEXAN8KAI0e","pt":1780316138483,"mc":[{"id":"1.258742455","rc":[{"batb":[],"atb":[[8.8,22.25]],"id":98117699}]}],"rt":639159129384908592,"dt":639159129384909007}
{"op":"mcm","id":2,"clk":"AJcXAOQKAJge","pt":1780316138584,"mc":[{"id":"1.258742455","rc":[{"tv":1825.47,"trd":[[11.5,28.53]],"atl":[[11.5,7.77]],"batl":[[0,11.5,7.77]],"id":97736949}],"tv":31750.71}],"rt":639159129385918200,"dt":639159129385918642}
{"op":"mcm","id":2,"clk":"AJ8XAOkKAKIe","pt":1780316138690,"mc":[{"id":"1.258742455","rc":[{"tv":7103.46,"batb":[[0,4.5,99.31]],"trd":[[4.5,1575.51]],"atb":[[4.5,99.31]],"id":10398159},{"tv":583.19,"batb":[[0,60,22.82]],"trd":[[60,31.98]],"atb":[[60,22.82]],"id":98464183}],"tv":31760.21}],"rt":639159129386978122,"dt":639159129386978524}
{"op":"mcm","id":2,"clk":"AKQXAO0KAKoe","pt":1780316138791,"mc":[{"id":"1.258742455","rc":[{"batb":[[0,3.8,56.67]],"atb":[[3.8,56.67]],"id":88302242}]}],"rt":639159129387995590,"dt":639159129387995973}
{"op":"mcm","id":2,"clk":"AK0XAPQKALUe","pt":1780316138896,"mc":[{"id":"1.258742455","rc":[{"tv":7203.61,"batb":[[0,4.4,39.38]],"trd":[[4.4,21.34]],"ltp":4.4,"atb":[[4.4,39.38]],"id":99072898},{"tv":888.07,"batb":[[0,24,13.83]],"trd":[[24,83.35]],"atb":[[24,13.83]],"id":99072900},{"batb":[[0,60,24.33]],"atb":[[60,24.33]],"id":98464183},{"tv":10879.25,"trd":[[3.85,1428.24]],"ltp":3.85,"atl":[[3.85,9.82]],"batl":[[0,3.85,9.82]],"id":88302242},{"atl":[[12,25.49]],"batl":[[1,12,25.49]],"id":97736949}],"tv":31768.84}],"rt":639159129389043214,"dt":639159129389043695}
{"op":"mcm","id":2,"clk":"ALIXAPgKAMIe","pt":1780316138997,"mc":[{"id":"1.258742455","rc":[{"batb":[[0,60,26]],"atb":[[60,26]],"id":98464183},{"batb":[],"atb":[[3.5,32.99]],"id":88302242}]}],"rt":639159129390050543,"dt":639159129390051151}
{"op":"mcm","id":2,"clk":"AM0XAIgLAO4e","pt":1780316139417,"mc":[{"id":"1.258742455","rc":[{"atl":[[70,9.13],[65,4.43]],"batl":[[1,70,9.13],[0,65,4.43]],"id":98464183},{"batb":[[2,9,26.23]],"atb":[[1.17,2.63],[9,26.23]],"id":98117699},{"atl":[[1000,3.21]],"id":88302242},{"atl":[[1000,0.82],[13.5,5.75]],"batl":[],"id":97736949}]}],"rt":639159129394251337,"dt":639159129394251792}
{"op":"mcm","id":2,"clk":"ANQXAIoLAPge","pt":1780316139517,"mc":[{"id":"1.258742455","rc":[{"atb":[[1.17,2]],"id":98117699},{"atl":[[1000,3]],"id":88302242},{"atl":[[1000,0]],"id":97736949}]}],"rt":639159129395252128,"dt":639159129395252490}
{"op":"mcm","id":2,"clk":"ANsXAI8LAIQf","pt":1780316139621,"mc":[{"id":"1.258742455","rc":[{"batb":[[0,9.4,2.43]],"atb":[[9.4,2.43]],"id":98117699},{"atl":[[3.85,10.03]],"batl":[[0,3.85,10.03]],"id":88302242},{"atl":[[12,26.31]],"batl":[[1,12,26.31]],"id":97736949}]}],"rt":639159129396292095,"dt":639159129396292731}
{"op":"mcm","id":2,"clk":"AN4XAJMLAIwf","pt":1780316139675,"mc":[{"id":"1.258742455","rc":[{"atl":[[10.5,13.06]],"batl":[],"id":98117699}]}],"rt":639159129396829419,"dt":639159129396829891}
{"op":"mcm","id":2,"clk":"APkXAKALAKof","pt":1780316139992,"mc":[{"id":"1.258742455","rc":[{"atl":[[9.8,5.6]],"batl":[[1,9.8,5.6]],"id":98117699},{"atl":[[3.95,34.76]],"batl":[[2,3.95,34.76]],"id":88302242}]}],"rt":639159129400002067,"dt":639159129400002482}
{"op":"mcm","id":2,"clk":"AJcYAKsLANUf","pt":1780316140404,"mc":[{"id":"1.258742455","rc":[{"atl":[[1000,1]],"id":97736949}]}],"rt":639159129404122641,"dt":639159129404122984}
{"op":"mcm","id":2,"clk":"AKIYALALAPMf","pt":1780316140706,"mc":[{"id":"1.258742455","rc":[{"atb":[[3.25,2.26]],"id":88302242}]}],"rt":639159129407144416,"dt":639159129407145226}
{"op":"mcm","id":2,"clk":"ALwYALYLAJkg","pt":1780316141114,"mc":[{"id":"1.258742455","rc":[{"batb":[],"atb":[[8.8,18.53]],"id":98117699}]}],"rt":639159129411219790,"dt":639159129411220361}
{"op":"mcm","id":2,"clk":"AMUYALgLAKEg","pt":1780316141221,"mc":[{"id":"1.258742455","rc":[{"atl":[[5.2,1.99]],"batl":[],"id":99072898},{"batb":[[0,60,48]],"atb":[[60,48]],"id":98464183},{"atl":[[15,1.99],[14.5,1.99]],"batl":[],"id":97736949},{"tv":167.09,"batb":[[0,1000,103.84]],"trd":[[1000,122.61]],"atb":[[1000,103.84]],"id":10445502}],"tv":31770.84}],"rt":639159129412293354,"dt":639159129412293827}
{"op":"mcm","id":2,"clk":"AOAYAMULAL4g","pt":1780316141478,"mc":[{"id":"1.258742455","rc":[{"atb":[[3.65,11.3]],"id":99072898},{"batb":[],"atb":[[3.85,42.81]],"id":10398159}]}],"rt":639159129414863325,"dt":639159129414863854}
{"op":"mcm","id":2,"clk":"AOsYAM0LANYg","pt":1780316141685,"mc":[{"id":"1.258742455","rc":[{"batb":[],"atb":[[36,1.99]],"id":97008932},{"batb":[],"atb":[[8,50.99]],"atl":[[10.5,7.52]],"batl":[],"id":98117699}]}],"rt":639159129416929303,"dt":639159129416929684}
{"op":"mcm","id":2,"clk":"APMYANELAOAg","pt":1780316141790,"mc":[{"id":"1.258742455","rc":[{"batb":[],"atb":[[20,2.61]],"id":99072900},{"atl":[[65,24.43]],"batl":[[0,65,24.43]],"id":98464183},{"tv":1834.57,"batb":[[2,9.8,2.99],[1,10,34.53],[0,10.5,11.94]],"trd":[[11,9.1]],"ltp":11,"atb":[[11,0],[10.5,11.94],[10,34.53]],"atl":[[14,0],[12,20.44],[11,0.22]],"batl":[[1,12,20.44],[0,11.5,7.99]],"id":97736949}],"tv":31779.94}],"rt":639159129417984440,"dt":639159129417985137}
{"op":"mcm","id":2,"clk":"APcYANgLAO8g","pt":1780316141892,"mc":[{"id":"1.258742455","rc":[{"batb":[],"atb":[[3.75,5.97]],"atl":[[4.6,26.98]],"batl":[[0,4.6,26.98]],"id":99072898},{"batb":[],"atb":[[36,2.13]],"id":97008932},{"batb":[],"atb":[[3.85,44.11]],"atl":[[4.6,22.09]],"batl":[[0,4.6,22.09]],"id":10398159},{"batb":[[1,55,15.68]],"atb":[[55,15.68]],"id":98464183},{"batb":[],"atb":[[8.2,3.6]],"id":98117699},{"atb":[[3.3,3.75]],"atl":[[3.85,1.06]],"batl":[[0,3.85,1.06]],"id":88302242},{"batb":[],"atb":[[9.4,2.99]],"atl":[[13.5,0]],"batl":[],"id":97736949}]}],"rt":639159129419001640,"dt":639159129419002317}
{"op":"mcm","id":2,"clk":"AP0YANkLAPgg","pt":1780316141997,"mc":[{"id":"1.258742455","rc":[{"batb":[],"atb":[[21,11.38]],"id":99072900},{"tv":10920.51,"batb":[[0,3.8,36.04]],"trd":[[3.8,672.41]],"ltp":3.8,"atb":[[3.8,36.04]],"id":88302242},{"batb":[],"atb":[[9.4,3.52]],"id":97736949}],"tv":31821.2}],"rt":639159129420049191,"dt":639159129420049571}
{"op":"mcm","id":2,"clk":"AIIZAN4LAIMh","pt":1780316142095,"mc":[{"id":"1.258742455","rc":[{"atl":[[4.5,2]],"batl":[[2,4.7,3.23],[1,4.6,26.98],[0,4.5,2]],"id":99072898},{"batb":[[2,50,15.7]],"atb":[[50,15.7]],"id":98464183},{"atl":[[3.85,11.62]],"batl":[[0,3.85,11.62]],"id":88302242}]}],"rt":639159129421036299,"dt":639159129421036677}
{"op":"mcm","id":2,"clk":"AIsZAOMLAIsh","pt":1780316142199,"mc":[{"id":"1.258742455","rc":[{"tv":7207.21,"trd":[[4.5,47.36]],"ltp":4.5,"atl":[[4.6,30.85],[4.5,0.2]],"batl":[[2,4.8,24.17],[1,4.7,3.23],[0,4.6,31.05]],"id":99072898},{"batb":[[0,42,8.24]],"atb":[[42,8.24]],"id":97008932},{"batb":[[0,9.4,2.14]],"atb":[[9.4,2.14]],"atl":[[1000,6.54]],"id":98117699},{"batb":[[0,3.8,34.37]],"atb":[[3.8,34.37]],"id":88302242}],"tv":31824.8}],"rt":639159129422071926,"dt":639159129422072545}
{"op":"mcm","id":2,"clk":"AI8ZAOwLAJkh","pt":1780316142304,"mc":[{"id":"1.258742455","rc":[{"batb":[[0,4.4,42.45]],"atb":[[4.4,42.45],[4.1,69.96]],"atl":[[4.6,26.98]],"batl":[[0,4.6,27.18]],"id":99072898},{"batb":[[0,42,8.56]],"atb":[[42,8.56]],"id":97008932},{"batb":[[0,24,14.4]],"atb":[[24,14.4]],"id":99072900},{"batb":[[0,80,2.33]],"atb":[[80,2.33]],"id":99072901},{"batb":[[0,4.5,102.31]],"atb":[[4.5,102.31]],"id":10398159},{"batb":[[0,60,48.23]],"atb":[[60,48.23]],"id":98464183},{"batb":[[0,9.4,3.58]],"atb":[[9.4,3.58]],"id":98117699},{"batb":[[2,3.7,43.94],[0,3.8,37.93]],"atb":[[3.8,37.93],[3.7,43.94]],"id":88302242},{"batb":[[0,10.5,4.28]],"atb":[[10.5,4.28]],"id":97736949},{"batb":[[0,1000,103.86]],"atb":[[1000,103.86]],"id":10445502},{"batb":[[0,160,4.45]],"atb":[[160,4.45]],"id":99072897}]}],"rt":639159129423117709,"dt":639159129423118416}
{"op":"mcm","id":2,"clk":"AJgZAPMLAKUh","pt":1780316142409,"mc":[{"id":"1.258742455","rc":[{"batb":[[1,55,16.09]],"atb":[[55,16.09]],"id":98464183},{"atl":[[1000,6.9]],"id":98117699},{"tv":1835.01,"batb":[[2,10,34.53],[1,10.5,4.28],[0,11,1.37]],"trd":[[11,9.54]],"atb":[[11,1.37]],"atl":[[11,0]],"batl":[[0,11.5,7.77]],"id":97736949}],"tv":31825.24}],"rt":639159129424173757,"dt":639159129424174161}
{"op":"mcm","id":2,"clk":"AKEZAP0LALMh","pt":1780316142514,"mc":[{"id":"1.258742455","rc":[{"atl":[[1000,6.25],[9.6,5.72]],"batl":[[0,9.6,5.72]],"id":98117699},{"batb":[[0,3.8,28.87]],"atb":[[3.8,28.87]],"id":88302242},{"batb":[],"atb":[[9.4,6.62]],"id":97736949}]}],"rt":639159129425225527,"dt":639159129425226163}
{"op":"mcm","id":2,"clk":"AKgZAIQMAMAh","pt":1780316142614,"mc":[{"id":"1.258742455","rc":[{"atl":[[9.8,6.25]],"batl":[[1,9.8,6.25]],"id":98117699},{"batb":[[0,3.8,17.13]],"atb":[[3.8,17.13]],"id":88302242},{"tv":1837.75,"batb":[[2,9.8,2.99],[1,10,34.53],[0,10.5,4.28]],"trd":[[11,12.28]],"atb":[[11,0]],"atl":[[11.5,21.12],[11,7.91]],"batl":[[2,12,20.44],[1,11.5,21.12],[0,11,7.91]],"id":97736949}],"tv":31827.98}],"rt":639159129426220548,"dt":639159129426221041}
{"op":"mcm","id":2,"clk":"ALQZAIsMAMwh","pt":1780316142721,"mc":[{"id":"1.258742455","rc":[{"batb":[[0,3.8,23.05]],"atb":[[3.8,23.05]],"id":88302242},{"batb":[],"atb":[[9.4,3.52],[9.2,1.99],[9,7.52]],"id":97736949}]}],"rt":639159129427294148,"dt":639159129427294511}
{"op":"mcm","id":2,"clk":"ALwZAJMMANgh","pt":1780316142823,"mc":[{"id":"1.258742455","rc":[{"batb":[[0,10.5,3.28]],"atb":[[10.5,3.28]],"id":97736949}]}],"rt":639159129428311237,"dt":639159129428311554}
{"op":"mcm","id":2,"clk":"AMkZAJ4MAOoh","pt":1780316142987,"mc":[{"id":"1.258742455","rc":[{"atl":[[65,24.48]],"batl":[[0,65,24.48]],"id":98464183}]}],"rt":639159129429949107,"dt":639159129429949551}
{"op":"mcm","id":2,"clk":"ANAZAKIMAPUh","pt":1780316143089,"mc":[{"id":"1.258742455","rc":[{"tv":10928.51,"batb":[[0,3.8,19.05]],"trd":[[3.8,680.41]],"atb":[[3.8,19.05]],"id":88302242}],"tv":31835.98}],"rt":639159129430976047,"dt":639159129430976427}
{"op":"mcm","id":2,"clk":"ANkZAKkMAIQi","pt":1780316143202,"mc":[{"id":"1.258742455","rc":[{"atl":[[4.8,14.82]],"batl":[[2,4.8,14.82]],"id":10398159},{"atl":[[3.85,12.43]],"batl":[[0,3.85,12.43]],"id":88302242}]}],"rt":639159129432105281,"dt":639159129432105660}
{"op":"mcm","id":2,"clk":"AOUZALEMAKMi","pt":1780316143404,"mc":[{"id":"1.258742455","rc":[{"batb":[[0,60,28.02]],"atb":[[60,28.02]],"id":98464183}]}],"rt":639159129434119698,"dt":639159129434120047}
{"op":"mcm","id":2,"clk":"AOwZALkMAK8i","pt":1780316143510,"mc":[{"id":"1.258742455","rc":[{"tv":10928.71,"batb":[[0,3.8,18.95]],"trd":[[3.8,680.61]],"atb":[[3.8,18.95]],"id":88302242},{"batb":[[1,150,5.02]],"atb":[[150,5.02]],"id":99072897}],"tv":31836.18}],"rt":639159129435180603,"dt":639159129435181032}
{"op":"mcm","id":2,"clk":"APwZAMUMAMUi","pt":1780316143714,"mc":[{"id":"1.258742455","rc":[{"atl":[[4.8,214.82]],"batl":[[2,4.8,214.82]],"id":10398159},{"atl":[[5.6,1.99]],"id":88302242}]}],"rt":639159129437220677,"dt":639159129437221051}
{"op":"mcm","id":2,"clk":"AIMaAMgMANAi","pt":1780316143814,"mc":[{"id":"1.258742455","rc":[{"tv":583.21,"batb":[[0,60,28.01]],"trd":[[60,32]],"atb":[[60,28.01]],"id":98464183},{"batb":[],"atb":[[3.6,11.72]],"atl":[[4.1,100.94]],"batl":[],"id":88302242}],"tv":31836.2}],"rt":639159129438223275,"dt":639159129438223958}
{"op":"mcm","id":2,"clk":"AIoaAMkMAN4i","pt":1780316143919,"mc":[{"id":"1.258742455","rc":[{"batb":[[0,3.8,29.39]],"atb":[[3.8,29.39]],"id":88302242}]}],"rt":639159129439269523,"dt":639159129439269874}
{"op":"mcm","id":2,"clk":"AJcaAM0MAOoi","pt":1780316144024,"mc":[{"id":"1.258742455","rc":[{"atl":[[32,1.85]],"id":10398159}]}],"rt":639159129440324707,"dt":639159129440325076}
{"op":"mcm","id":2,"clk":"AJwaANIMAPUi","pt":1780316144125,"mc":[{"id":"1.258742455","rc":[{"batb":[[1,4.3,37.31]],"atb":[[4.3,37.31]],"id":99072898},{"batb":[[1,4.4,170.18]],"atb":[[4.4,170.18]],"id":10398159},{"atl":[[11,8.86]],"batl":[[0,11,8.86]],"id":97736949}]}],"rt":639159129441330341,"dt":639159129441330703}
{"op":"mcm","id":2,"clk":"AMYaANsMAKUj","pt":1780316144589,"mc":[{"id":"1.258742455","rc":[{"tv":499.74,"batb":[[0,42,9.05]],"trd":[[46,42.2]],"ltp":46,"atb":[[46,0.49]],"atl":[[46,0]],"batl":[[2,55,18.78],[1,50,11.58],[0,48,1.6]],"id":97008932}],"tv":31841.23}],"rt":639159129445971747,"dt":639159129445972136}
{"op":"mcm","id":2,"clk":"AM4aAN4MAK8j","pt":1780316144693,"mc":[{"id":"1.258742455","rc":[{"batb":[[2,40,5.46],[1,42,8.56],[0,44,1.97]],"atb":[[44,1.48]],"atl":[[50,11.92],[48,4.36]],"batl":[[1,50,11.92],[0,48,4.36]],"id":97008932},{"atl":[[3.85,14.16]],"batl":[[0,3.85,14.16]],"id":88302242}]}],"rt":639159129447046404,"dt":639159129447047033}
{"op":"mcm","id":2,"clk":"ANIaAOIMALoj","pt":1780316144798,"mc":[{"id":"1.258742455","rc":[{"tv":594.76,"batb":[[0,60,22.01]],"trd":[[60,43.55]],"atb":[[60,22.01]],"id":98464183},{"batb":[[1,150,3.29]],"atb":[[150,3.29]],"id":99072897}],"tv":31852.78}],"rt":639159129448067609,"dt":639159129448068247}
{"op":"mcm","id":2,"clk":"ANUaAOcMAMIj","pt":1780316144898,"mc":[{"id":"1.258742455","rc":[{"batb":[],"atb":[[4.1,68.7]],"id":99072898}]}],"rt":639159129449067747,"dt":639159129449068067}
{"op":"mcm","id":2,"clk":"AOEaAOkMAM4j","pt":1780316145006,"mc":[{"id":"1.258742455","rc":[{"atl":[[50,11.58]],"batl":[[1,50,11.58]],"id":97008932},{"batb":[[1,75,9.71]],"atb":[[75,9.71]],"id":99072901}]}],"rt":639159129450138283,"dt":639159129450138896}
{"op":"mcm","id":2,"clk":"AOQaAOsMANcj","pt":1780316145102,"mc":[{"id":"1.258742455","rc":[{"batb":[[0,60,23.55]],"atb":[[60,23.55]],"id":98464183}]}],"rt":639159129451097641,"dt":639159129451097987}
{"op":"mcm","id":2,"clk":"AOcaAO8MAN8j","pt":1780316145205,"mc":[{"id":"1.258742455","rc":[{"atl":[[4.6,18.44]],"batl":[[0,4.6,18.64]],"id":99072898},{"atb":[[1.17,2.17]],"id":97008932},{"batb":[[1,23,10.97],[0,24,14.21]],"atb":[[24,14.21],[23,10.97]],"atl":[[25,4.94]],"batl":[[0,25,4.94]],"id":99072900},{"atl":[[4.7,74.2]],"batl":[[1,4.7,74.2]],"id":10398159},{"atl":[[65,25.56]],"batl":[[0,65,25.56]],"id":98464183},{"batb":[[0,3.8,37.2]],"atb":[[3.8,37.2]],"atl":[[3.9,45.69]],"batl":[[1,3.9,45.69]],"id":88302242},{"atl":[[13,8.5],[12,19.62],[11.5,22.48]],"batl":[[2,12,19.62],[1,11.5,22.48]],"id":97736949}]}],"rt":639159129452132472,"dt":639159129452133202}
{"op":"mcm","id":2,"clk":"APAaAPIMAOcj","pt":1780316145310,"mc":[{"id":"1.258742455","rc":[{"tv":7218.69,"batb":[[0,4.4,36.71]],"trd":[[4.4,32.82]],"ltp":4.4,"atb":[[4.4,36.71]],"id":99072898},{"batb":[[1,42,8.39]],"atb":[[1.17,2],[42,8.39]],"atl":[[1000,0.32],[48,4.17]],"batl":[[0,48,4.17]],"id":97008932},{"batb":[[0,4.5,116.25]],"atb":[[4.5,116.25]],"id":10398159},{"atl":[[3.85,15.24]],"batl":[[0,3.85,15.24]],"id":88302242}],"tv":31864.26}],"rt":639159129453181375,"dt":639159129453182080}
{"op":"mcm","id":2,"clk":"AIQbAPwMAPIj","pt":1780316145416,"mc":[{"id":"1.258742455","rc":[{"batb":[[0,44,2.14]],"atb":[[46,0.66]],"atl":[[1000,0.22]],"id":97008932}]}],"rt":639159129454240872,"dt":639159129454241581}
{"op":"mcm","id":2,"clk":"AJUbAIENAPgj","pt":1780316145516,"mc":[{"id":"1.258742455","rc":[{"atl":[[50,11.68]],"batl":[[1,50,11.68]],"id":97008932}]}],"rt":639159129455243266,"dt":639159129455243617}
{"op":"mcm","id":2,"clk":"AJ8bAIUNAIAk","pt":1780316145620,"mc":[{"id":"1.258742455","rc":[{"atl":[[3.9,13.27]],"batl":[[1,3.9,13.27]],"id":88302242}]}],"rt":639159129456286251,"dt":639159129456286853}
{"op":"mcm","id":2,"clk":"AKQbAIgNAIkk","pt":1780316145722,"mc":[{"id":"1.258742455","rc":[{"batb":[[2,9,27.23],[1,9.2,15.98]],"atb":[[9.2,15.98],[9,27.23]],"id":98117699},{"atl":[[3.85,47.66]],"batl":[[0,3.85,47.66]],"id":88302242},{"batb":[],"atb":[[9.2,2.99]],"id":97736949}]}],"rt":639159129457305760,"dt":639159129457306185}
{"op":"mcm","id":2,"clk":"ALQbAI8NAJok","pt":1780316145927,"mc":[{"id":"1.258742455","rc":[{"batb":[[0,3.8,26.76]],"atb":[[3.8,26.76]],"id":88302242}]}],"rt":639159129459355833,"dt":639159129459356175}
{"op":"mcm","id":2,"clk":"ANkbAKENAMYk","pt":1780316146396,"mc":[{"id":"1.258742455","rc":[{"batb":[[0,60,21.55]],"atb":[[60,21.55]],"id":98464183}]}],"rt":639159129464045127,"dt":639159129464045857}
{"op":"mcm","id":2,"clk":"AOkbAKsNANwk","pt":1780316146599,"mc":[{"id":"1.258742455","rc":[{"tv":503.62,"batb":[[2,38,11.09],[1,40,5.46],[0,42,8.59]],"trd":[[46,43.52],[44,23.83]],"ltp":44,"atb":[[46,0],[44,0.2]],"id":97008932}],"tv":31868.14}],"rt":639159129466077694,"dt":639159129466078328}
{"op":"mcm","id":2,"clk":"APIbALANAOok","pt":1780316146702,"mc":[{"id":"1.258742455","rc":[{"atl":[[46,4.86]],"batl":[[2,50,11.68],[1,48,4.17],[0,46,4.86]],"id":97008932}]}],"rt":639159129467105779,"dt":639159129467106156}
{"op":"mcm","id":2,"clk":"AP8bAL8NAIcl","pt":1780316146908,"mc":[{"id":"1.258742455","rc":[{"batb":[[0,80,1.35]],"atb":[[80,1.35]],"id":99072901}]}],"rt":639159129469165812,"dt":639159129469166154}
{"op":"mcm","id":2,"clk":"AI8cAMwNAJ0l","pt":1780316147117,"mc":[{"id":"1.258742455","rc":[{"batb":[[0,42,8.39]],"atb":[[44,0]],"id":97008932},{"tv":1839.65,"batb":[[2,10,34.53],[1,10.5,11.79],[0,11,7.89]],"trd":[[11,14.18]],"atb":[[11,7.89],[10.5,11.79]],"atl":[[11,0]],"batl":[[2,12.5,7.51],[1,12,19.62],[0,11.5,22.48]],"id":97736949}],"tv":31870.04}],"rt":639159129471251504,"dt":639159129471252199}
{"op":"mcm","id":2,"clk":"AJUcAM8NAKol","pt":1780316147218,"mc":[{"id":"1.258742455","rc":[{"batb":[],"atb":[[4,53.27]],"atl":[[4.6,21.64]],"batl":[[0,4.6,21.84]],"id":99072898},{"batb":[[0,3.8,20.84]],"atb":[[3.8,20.84]],"id":88302242},{"batb":[],"atb":[[9.4,6.62]],"atl":[[11.5,9.13]],"batl":[[0,11.5,9.13]],"id":97736949}]}],"rt":639159129472267493,"dt":639159129472268209}
{"op":"mcm","id":2,"clk":"AJocANMNALQl","pt":1780316147327,"mc":[{"id":"1.258742455","rc":[{"tv":10970.39,"batb":[[2,3.65,18.48],[1,3.7,43.94],[0,3.75,43.81]],"trd":[[3.8,722.29]],"atb":[[3.8,0]],"atl":[[3.8,16.22],[4.1,90.86]],"batl":[[2,3.9,13.27],[1,3.85,47.66],[0,3.8,16.22]],"id":88302242}],"tv":31911.72}],"rt":639159129473353247,"dt":639159129473353729}
{"op":"mcm","id":2,"clk":"AKscANwNAMQl","pt":1780316147433,"mc":[{"id":"1.258742455","rc":[{"atl":[[4.6,18.44]],"batl":[[0,4.6,18.64]],"id":99072898}]}],"rt":639159129474486776,"dt":639159129474487169}
{"op":"mcm","id":2,"clk":"ALIcAN4NANMl","pt":1780316147534,"mc":[{"id":"1.258742455","rc":[{"batb":[[2,4.2,120.11]],"atb":[[4.2,120.11]],"id":99072898},{"batb":[[1,3.7,54.54],[0,3.75,32.08]],"atb":[[3.75,32.08],[3.7,54.54],[3.6,7]],"id":88302242}]}],"rt":639159129475423410,"dt":639159129475423806}
{"op":"mcm","id":2,"clk":"ALwcAOQNAN8l","pt":1780316147587,"mc":[{"id":"1.258742455","rc":[{"batb":[[0,4.4,46.71]],"atb":[[4.4,46.71]],"id":99072898}]}],"rt":639159129475951482,"dt":639159129475952029}
{"op":"mcm","id":2,"clk":"AMMcAOsNAOsl","pt":1780316147692,"mc":[{"id":"1.258742455","rc":[{"atl":[[3.95,33.03],[3.85,45.93]],"batl":[[1,3.85,45.93]],"id":88302242}]}],"rt":639159129477004647,"dt":639159129477005083}
{"op":"mcm","id":2,"clk":"AMkcAO0NAPcl","pt":1780316147792,"mc":[{"id":"1.258742455","rc":[{"atl":[[4.9,40.38]],"batl":[],"id":10398159},{"atl":[[4.1,56.9],[3.95,62.57]],"batl":[],"id":88302242}]}],"rt":639159129477998170,"dt":639159129477998759}
{"op":"mcm","id":2,"clk":"AOAcAPINAIcm","pt":1780316148000,"mc":[{"id":"1.258742455","rc":[{"tv":2058.09,"batb":[[0,9.4,2.63]],"trd":[[9.4,115.25]],"ltp":9.4,"atb":[[9.4,2.63]],"id":98117699}],"tv":31913.62}],"rt":639159129480092008,"dt":639159129480092399}
{"op":"mcm","id":2,"clk":"AOwcAPwNAJwm","pt":1780316148206,"mc":[{"id":"1.258742455","rc":[{"batb":[[1,10.5,12.94]],"atb":[[10.5,12.94]],"id":97736949}]}],"rt":639159129482141785,"dt":639159129482142546}
{"op":"mcm","id":2,"clk":"APUcAP8NAKkm","pt":1780316148312,"mc":[{"id":"1.258742455","rc":[{"atb":[[1.17,2.11]],"id":97736949}]}],"rt":639159129483205403,"dt":639159129483205737}
{"op":"mcm","id":2,"clk":"APwcAIAOALkm","pt":1780316148422,"mc":[{"id":"1.258742455","rc":[{"atb":[[1.17,2]],"id":97736949}]}],"rt":639159129484304729,"dt":639159129484305068}
{"op":"mcm","id":2,"clk":"AIQdAIEOAMUm","pt":1780316148517,"mc":[{"id":"1.258742455","rc":[{"batb":[[0,11,8]],"atb":[[11,8]],"id":97736949}]}],"rt":639159129485254045,"dt":639159129485254371}
{"op":"mcm","id":2,"clk":"AJodAIsOAOAm","pt":1780316148725,"mc":[{"id":"1.258742455","rc":[{"tv":7178.04,"batb":[[0,4.5,78.96]],"trd":[[4.5,1650.09]],"atb":[[4.5,78.96]],"id":10398159}],"tv":31988.2}],"rt":639159129487328510,"dt":639159129487329111}
{"op":"mcm","id":2,"clk":"AJ8dAI8OAOMm","pt":1780316148828,"mc":[{"id":"1.258742455","rc":[{"batb":[[0,4.5,113.61]],"atb":[[4.5,113.61]],"atl":[[4.6,55.99]],"batl":[[0,4.6,55.99]],"id":10398159}]}],"rt":639159129488367071,"dt":639159129488367585}
{"op":"mcm","id":2,"clk":"AKodAJMOAOom","pt":1780316148932,"mc":[{"id":"1.258742455","rc":[{"tv":1843.65,"batb":[[0,11,6]],"trd":[[11,18.18]],"atb":[[11,6]],"id":97736949}],"tv":31992.2}],"rt":639159129489398703,"dt":639159129489399111}
{"op":"mcm","id":2,"clk":"AK8dAJUOAPMm","pt":1780316149030,"mc":[{"id":"1.258742455","rc":[{"tv":2061.09,"batb":[[0,9.4,1.13]],"trd":[[9.4,118.25]],"atb":[[9.4,1.13]],"id":98117699}],"tv":31995.2}],"rt":639159129490384129,"dt":639159129490384522}
{"op":"mcm","id":2,"clk":"ALwdAJoOAIAn","pt":1780316149141,"mc":[{"id":"1.258742455","rc":[{"tv":7188.96,"batb":[[0,4.5,108.15]],"trd":[[4.5,1661.01]],"atb":[[4.5,108.15]],"id":10398159}],"tv":32006.12}],"rt":639159129491492979,"dt":639159129491493356}
{"op":"mcm","id":2,"clk":"AMAdAJ0OAI4n","pt":1780316149201,"mc":[{"id":"1.258742455","rc":[{"batb":[[0,9.4,3.86]],"atb":[[9.4,3.86]],"id":98117699}]}],"rt":639159129492093766,"dt":639159129492094334}
{"op":"mcm","id":2,"clk":"AN8dAKkOAK4n","pt":1780316149507,"mc":[{"id":"1.258742455","rc":[{"tv":7219.09,"batb":[[0,4.4,50.74]],"trd":[[4.5,47.76]],"ltp":4.5,"atb":[[4.4,49.81],[4.5,0.93]],"atl":[[4.5,0]],"batl":[[0,4.6,18.44]],"id":99072898},{"batb":[[0,42,8.72]],"atb":[[42,8.72]],"id":97008932},{"batb":[[0,24,14.77]],"atb":[[24,14.77]],"id":99072900},{"batb":[[0,80,1.52]],"atb":[[80,1.52]],"id":99072901},{"tv":7394.96,"batb":[[0,4.5,111.19]],"trd":[[4.7,646.96],[4.6,617.25]],"ltp":4.7,"atb":[[4.5,111.19]],"atl":[[4.7,27.19],[4.6,0]],"batl":[[2,4.9,40.38],[1,4.8,214.82],[0,4.7,27.19]],"id":10398159},{"batb":[[0,60,21.77]],"atb":[[60,21.77]],"id":98464183},{"batb":[[0,9.4,5.31]],"atb":[[9.4,5.31]],"id":98117699},{"batb":[[0,3.75,35.72]],"atb":[[3.75,35.72]],"id":88302242},{"batb":[[0,11,7.24]],"atb":[[11,7.24]],"id":97736949},{"batb":[[0,1000,103.87]],"atb":[[1000,103.87]],"id":10445502},{"batb":[[0,160,4.53]],"atb":[[160,4.53]],"id":99072897}],"tv":32212.52}],"rt":639159129495155119,"dt":639159129495155894}
{"op":"mcm","id":2,"clk":"AOMdALAOALUn","pt":1780316149601,"mc":[{"id":"1.258742455","rc":[{"atl":[[4.6,21.6]],"batl":[[0,4.6,21.6]],"id":99072898},{"atb":[[1.04,0.86]],"id":99072900},{"batb":[[2,4.4,174.52],[1,4.5,118.74],[0,4.6,40.45]],"atb":[[4.4,174.52],[4.6,40.45],[4.5,118.74]],"atl":[[4.7,30.93],[4.9,25.89]],"batl":[[2,4.9,25.89],[0,4.7,30.93]],"id":10398159},{"batb":[[1,3.7,63.73],[0,3.75,26.64]],"atb":[[3.75,26.64],[3.7,63.73]],"atl":[[32,2.06],[4,17.03]],"batl":[],"id":88302242},{"batb":[],"atb":[[9.4,3.52],[9.2,6.08]],"id":97736949}]}],"rt":639159129496096694,"dt":639159129496097327}
{"op":"mcm","id":2,"clk":"AOsdALQOAL8n","pt":1780316149706,"mc":[{"id":"1.258742455","rc":[{"tv":892.07,"batb":[[0,24,12.77]],"trd":[[24,87.35]],"atb":[[24,12.77]],"id":99072900},{"batb":[[0,80,1.87]],"atb":[[85,0.35]],"id":99072901},{"tv":7399.49,"batb":[[0,4.6,36.33]],"trd":[[4.6,621.78]],"ltp":4.6,"atb":[[4.1,44.05],[4.6,36.33]],"atl":[[4.7,62.38],[4.8,218.52]],"batl":[[1,4.8,218.52],[0,4.7,62.38]],"id":10398159},{"batb":[[0,3.75,21.79]],"atb":[[3.75,21.79]],"atl":[[3.95,67.14]],"batl":[],"id":88302242}],"tv":32221.05}],"rt":639159129497142965,"dt":639159129497143468}
{"op":"mcm","id":2,"clk":"APMdALoOAMQn","pt":1780316149809,"mc":[{"id":"1.258742455","rc":[{"atb":[[1.04,0.44]],"id":99072900},{"atl":[[4.7,58.64]],"batl":[[0,4.7,58.64]],"id":10398159}]}],"rt":639159129498175786,"dt":639159129498176131}
{"op":"mcm","id":2,"clk":"APgdALwOAM4n","pt":1780316149907,"mc":[{"id":"1.258742455","rc":[{"batb":[[1,4.5,120.63],[0,4.6,41.44]],"atb":[[4.6,41.44],[4.5,120.63]],"id":10398159}]}],"rt":639159129499159605,"dt":639159129499160240}
{"op":"mcm","id":2,"clk":"AP0dAL8OANkn","pt":1780316150018,"mc":[{"id":"1.258742455","rc":[{"atb":[[1.04,0]],"id":99072900},{"atl":[[65,25.96]],"batl":[[0,65,25.96]],"id":98464183}]}],"rt":639159129500265011,"dt":639159129500265727}
{"op":"mcm","id":2,"clk":"AIceAMYOAN8n","pt":1780316150118,"mc":[{"id":"1.258742455","rc":[{"tv":892.95,"trd":[[25,122.78]],"ltp":25,"atl":[[25,4.5]],"batl":[[0,25,4.5]],"id":99072900}],"tv":32221.93}],"rt":639159129501267306,"dt":639159129501267754}
{"op":"mcm","id":2,"clk":"AIseAMkOAOYn","pt":1780316150217,"mc":[{"id":"1.258742455","rc":[{"batb":[],"atb":[[4,47.52]],"id":99072898},{"tv":594.87,"batb":[[0,60,21.72]],"trd":[[60,43.66]],"atb":[[60,21.72]],"id":98464183}],"tv":32222.04}],"rt":639159129502256962,"dt":639159129502257455}
{"op":"mcm","id":2,"clk":"AJIeAM0OAPEn","pt":1780316150321,"mc":[{"id":"1.258742455","rc":[{"batb":[],"atb":[[4.2,19.42]],"id":10398159},{"atl":[[3.85,13.51]],"batl":[[1,3.85,13.51]],"id":88302242}]}],"rt":639159129503291925,"dt":639159129503292348}
{"op":"mcm","id":2,"clk":"AJceANAOAPcn","pt":1780316150423,"mc":[{"id":"1.258742455","rc":[{"batb":[[0,4.6,44.44]],"atb":[[4.6,44.44]],"id":10398159},{"batb":[[0,3.75,32.19]],"atb":[[3.75,32.19]],"atl":[[3.8,48.64]],"batl":[[0,3.8,48.64]],"id":88302242}]}],"rt":639159129504308677,"dt":639159129504309435}
{"op":"mcm","id":2,"clk":"AKMeANcOAIEo","pt":1780316150528,"mc":[{"id":"1.258742455","rc":[{"batb":[[0,4.6,10.31]],"atb":[[4.6,10.31]],"atl":[[4.8,18.52]],"batl":[[1,4.8,18.52]],"id":10398159},{"batb":[[0,11,7.84]],"atb":[[11,7.84]],"id":97736949}]}],"rt":639159129505377452,"dt":639159129505378123}
{"op":"mcm","id":2,"clk":"AKweAN0OAIso","pt":1780316150629,"mc":[{"id":"1.258742455","rc":[{"batb":[[1,55,38.09]],"atb":[[55,38.09]],"id":98464183},{"batb":[[0,3.75,21.79]],"atb":[[3.75,21.79]],"atl":[[3.85,11.85],[4,4.61]],"batl":[[1,3.85,11.85]],"id":88302242}]}],"rt":639159129506373004,"dt":639159129506373494}
{"op":"mcm","id":2,"clk":"ALMeAOIOAJIo","pt":1780316150732,"mc":[{"id":"1.258742455","rc":[{"batb":[[0,42,6.73]],"atb":[[42,6.73]],"id":97008932},{"batb":[[0,4.6,57.07]],"atb":[[4.1,33.38],[4.6,57.07]],"id":10398159},{"tv":11013.97,"batb":[[2,3.6,7],[1,3.65,18.48],[0,3.7,63.73]],"trd":[[3.75,228.4]],"ltp":3.75,"atb":[[3.75,0]],"atl":[[3.75,11.03]],"batl":[[2,3.85,11.85],[1,3.8,48.64],[0,3.75,11.03]],"id":88302242}],"tv":32265.62}],"rt":639159129507398670,"dt":639159129507399553}
{"op":"mcm","id":2,"clk":"ALweAOoOAJoo","pt":1780316150840,"mc":[{"id":"1.258742455","rc":[{"batb":[[0,4.6,64.52]],"atb":[[4.6,64.52]],"atl":[[4.9,29.57]],"batl":[[2,4.9,29.57]],"id":10398159},{"tv":1843.79,"trd":[[11.5,28.67]],"ltp":11.5,"atl":[[11.5,9.06]],"batl":[[0,11.5,9.06]],"id":97736949}],"tv":32265.76}],"rt":639159129508477979,"dt":639159129508478713}
{"op":"mcm","id":2,"clk":"AMYeAO8OAKIo","pt":1780316150892,"mc":[{"id":"1.258742455","rc":[{"atl":[[4.7,63.03]],"batl":[[0,4.7,63.03]],"id":10398159},{"batb":[[0,3.7,50.76]],"atb":[[3.7,50.76]],"id":88302242}]}],"rt":639159129509001983,"dt":639159129509002396}
{"op":"mcm","id":2,"clk":"AMweAPUOAKso","pt":1780316150997,"mc":[{"id":"1.258742455","rc":[{"batb":[[0,11,9.53]],"atb":[[11,9.53]],"id":97736949}]}],"rt":639159129510047703,"dt":639159129510048044}
{"op":"mcm","id":2,"clk":"AIAfAJMPAN4o","pt":1780316151614,"mc":[{"id":"1.258742455","rc":[{"batb":[],"atb":[[4,51.52]],"id":99072898},{"tv":7474.07,"batb":[[0,4.6,27.24]],"trd":[[4.6,696.36]],"atb":[[4.6,27.24]],"id":10398159},{"batb":[],"atb":[[3.5,31.99]],"id":88302242}],"tv":32340.34}],"rt":639159129516227299,"dt":639159129516227808}
{"op":"mcm","id":2,"clk":"AIsfAJcPAOko","pt":1780316151718,"mc":[{"id":"1.258742455","rc":[{"batb":[[1,4.3,35.53],[0,4.4,49.42]],"atb":[[1.17,2.66],[4.4,48.49],[4.3,35.53]],"id":99072898},{"atl":[[1000,0.39],[50,11.58],[48,4.4]],"batl":[[2,50,11.58],[1,48,4.4]],"id":97008932},{"tv":7475.25,"batb":[[1,4.5,102.98],[0,4.6,29.89]],"trd":[[4.6,697.54]],"atb":[[4.6,29.89],[4.5,102.98]],"atl":[[4.7,59.43],[1000,1.68]],"batl":[[0,4.7,59.43]],"id":10398159},{"batb":[[0,60,25.78]],"atb":[[60,25.78]],"id":98464183},{"atl":[[1000,6.76]],"id":98117699},{"atl":[[1000,3.16],[3.9,11.55],[3.85,10.56]],"batl":[[2,3.85,10.56]],"id":88302242},{"tv":1844.16,"batb":[[1,10.5,11.79],[0,11,12.87]],"trd":[[11.5,29.04]],"atb":[[11,12.87],[10.5,11.79]],"atl":[[1000,1.83],[11.5,7.51]],"batl":[[0,11.5,7.51]],"id":97736949}],"tv":32341.89}],"rt":639159129517273694,"dt":639159129517274761}
{"op":"mcm","id":2,"clk":"AJUfAKEPAP0o","pt":1780316151924,"mc":[{"id":"1.258742455","rc":[{"atb":[[1.17,2]],"id":99072898},{"atl":[[1000,0.22]],"id":97008932},{"atl":[[1000,1.01]],"id":10398159},{"atl":[[1000,6.25]],"id":98117699},{"batb":[[1,3.65,24.87]],"atb":[[3.65,24.87]],"atl":[[1000,3],[3.9,16.15]],"batl":[],"id":88302242},{"atl":[[1000,1]],"id":97736949}]}],"rt":639159129519321221,"dt":639159129519321997}
{"op":"mcm","id":2,"clk":"AJgfAKYPAIYp","pt":1780316152024,"mc":[{"id":"1.258742455","rc":[{"batb":[[2,4.3,35.53],[1,4.4,48.82],[0,4.5,1.26]],"atb":[[4.4,48.82],[4.5,1.26]],"id":99072898},{"atl":[[46,5.03]],"batl":[[0,46,5.03]],"id":97008932},{"batb":[[2,4.4,115.7]],"atb":[[4.4,115.7]],"atl":[[4.8,19.19]],"batl":[[1,4.8,19.19]],"id":10398159},{"atl":[[9.6,6.23]],"batl":[[0,9.6,6.23]],"id":98117699},{"atl":[[3.8,48.8]],"batl":[[1,3.8,48.8]],"id":88302242},{"atl":[[12,20.45]],"batl":[[1,12,20.45]],"id":97736949}]}],"rt":639159129520325011,"dt":639159129520325647}
{"op":"mcm","id":2,"clk":"AKEfAKsPAJAp","pt":1780316152127,"mc":[{"id":"1.258742455","rc":[{"tv":7477.15,"batb":[[0,4.6,28.94]],"trd":[[4.6,699.44]],"atb":[[4.6,28.94]],"id":10398159}],"tv":32343.79}],"rt":639159129521353563,"dt":639159129521354015}
{"op":"mcm","id":2,"clk":"AKUfAK8PAJop","pt":1780316152227,"mc":[{"id":"1.258742455","rc":[{"batb":[],"atb":[[4.2,13.66]],"id":10398159},{"atl":[[4.2,27.91],[4.1,52.37],[4.3,15.89]],"batl":[],"id":88302242}]}],"rt":639159129522357618,"dt":639159129522358046}
{"op":"mcm","id":2,"clk":"AN4fANEPAPAp","pt":1780316153006,"mc":[{"id":"1.258742455","rc":[{"batb":[[0,4.5,9.31]],"atb":[[4.5,9.31]],"id":99072898},{"batb":[[0,42,7.05]],"atb":[[42,7.05]],"id":97008932},{"batb":[[0,24,13.35]],"atb":[[24,13.35]],"id":99072900},{"batb":[[0,80,2.05]],"atb":[[80,1.7]],"id":99072901},{"batb":[[0,4.6,31.92]],"atb":[[4.6,31.92]],"id":10398159},{"batb":[[0,60,26.01]],"atb":[[60,26.01]],"id":98464183},{"batb":[[0,9.4,6.77]],"atb":[[9.4,6.77]],"id":98117699},{"batb":[[0,3.7,54.46]],"atb":[[3.7,54.46]],"id":88302242},{"tv":1850.16,"batb":[[0,11,11.12]],"trd":[[11,24.18]],"ltp":11,"atb":[[11,11.12]],"id":97736949},{"batb":[[0,1000,103.88]],"atb":[[1000,103.88]],"id":10445502},{"batb":[[0,160,4.62]],"atb":[[160,4.62]],"id":99072897}],"tv":32349.79}],"rt":639159129530168913,"dt":639159129530169915}
{"op":"mcm","id":2,"clk":"AOMfANMPAPQp","pt":1780316153102,"mc":[{"id":"1.258742455","rc":[{"batb":[[0,4.5,19.51]],"atb":[[4.5,19.51]],"id":99072898},{"batb":[],"atb":[[9.2,2.99]],"id":97736949}]}],"rt":639159129531105419,"dt":639159129531105900}
{"op":"mcm","id":2,"clk":"APIfANwPAIoq","pt":1780316153313,"mc":[{"id":"1.258742455","rc":[{"batb":[],"atb":[[4,44.49]],"id":99072898},{"atl":[[4.7,35.84],[4.8,63.06]],"batl":[[1,4.8,63.06],[0,4.7,35.84]],"id":10398159}]}],"rt":639159129533213532,"dt":639159129533214005}
{"op":"mcm","id":2,"clk":"AP0fAOMPAJQq","pt":1780316153421,"mc":[{"id":"1.258742455","rc":[{"atl":[[4,6.6]],"batl":[],"id":88302242},{"atl":[[14,1.99],[13.5,1.99]],"batl":[],"id":97736949}]}],"rt":639159129534292444,"dt":639159129534293134}
{"op":"mcm","id":2,"clk":"AIkgAOcPAJ8q","pt":1780316153522,"mc":[{"id":"1.258742455","rc":[{"tv":7478.01,"batb":[[0,4.6,31.49]],"trd":[[4.6,700.3]],"atb":[[4.6,31.49]],"id":10398159},{"tv":1852.16,"batb":[[0,11,10.12]],"trd":[[11,26.18]],"atb":[[11,10.12]],"id":97736949}],"tv":32352.65}],"rt":639159129535313369,"dt":639159129535313773}
{"op":"mcm","id":2,"clk":"AJ4gAPkPANIq","pt":1780316153989,"mc":[{"id":"1.258742455","rc":[{"tv":1872.41,"batb":[[2,9.8,2.99],[1,10,34.53],[0,10.5,11.79]],"trd":[[11,46.43]],"atb":[[11,0]],"atl":[[11,1]],"batl":[[2,12,20.45],[1,11.5,7.51],[0,11,1]],"id":97736949}],"tv":32372.9}],"rt":639159129539973682,"dt":639159129539974122}
{"op":"mcm","id":2,"clk":"AKUgAP8PAN4q","pt":1780316154088,"mc":[{"id":"1.258742455","rc":[{"batb":[[0,4.5,37.26]],"atb":[[4.5,37.26]],"id":99072898},{"atl":[[4.8,59.36]],"batl":[[1,4.8,59.36]],"id":10398159},{"batb":[[0,60,27.53]],"atb":[[60,27.53]],"id":98464183},{"atl":[[3.75,0]],"batl":[[2,3.9,16.15],[1,3.85,10.56],[0,3.8,48.8]],"id":88302242},{"batb":[[2,9.8,8.51],[1,10,40.05],[0,10.5,17.31]],"atb":[[8.8,5.21],[9.8,8.51],[10.5,17.31],[10,40.05],[9,4.29]],"id":97736949}]}],"rt":639159129540968940,"dt":639159129540969702}
{"op":"mcm","id":2,"clk":"AK0gAIkQAOcq","pt":1780316154192,"mc":[{"id":"1.258742455","rc":[{"batb":[],"atb":[[4,34.49]],"atl":[[4.7,13.63]],"batl":[[1,4.7,13.63]],"id":99072898},{"atl":[[4.8,63.04]],"batl":[[1,4.8,63.04]],"id":10398159},{"atl":[[3.9,11.55]],"batl":[[2,3.9,11.55]],"id":88302242}]}],"rt":639159129542003800,"dt":639159129542004461}
{"op":"mcm","id":2,"clk":"ALUgAI0QAO4q","pt":1780316154295,"mc":[{"id":"1.258742455","rc":[{"batb":[[2,3.6,21.52],[0,3.7,70.98]],"atb":[[3.55,45.06],[3.7,70.98],[3.6,21.52]],"id":88302242}]}],"rt":639159129543038257,"dt":639159129543038730}
{"op":"mcm","id":2,"clk":"ALsgAJEQAPwq","pt":1780316154400,"mc":[{"id":"1.258742455","rc":[{"tv":596.59,"batb":[[0,60,26.67]],"trd":[[60,45.38]],"atb":[[60,26.67]],"id":98464183}],"tv":32374.62}],"rt":639159129544085548,"dt":639159129544085931}
{"op":"mcm","id":2,"clk":"AMEgAJkQAI4r","pt":1780316154598,"mc":[{"id":"1.258742455","rc":[{"atb":[[1.17,2.52]],"id":97736949}]}],"rt":639159129546065567,"dt":639159129546065936}
{"op":"mcm","id":2,"clk":"AMcgAKMQAJUr","pt":1780316154706,"mc":[{"id":"1.258742455","rc":[{"atl":[[4.6,27.63]],"batl":[[0,4.6,27.63]],"id":99072898},{"batb":[[0,42,8.18]],"atb":[[42,8.18]],"id":97008932},{"atb":[[1.17,1.11]],"id":99072901},{"batb":[[0,9.4,8.63]],"atb":[[9.4,8.63]],"id":98117699},{"tv":11017.43,"batb":[[0,3.7,69.25]],"trd":[[3.7,37.1]],"ltp":3.7,"atb":[[1.17,195.93],[3.7,69.25]],"id":88302242},{"atb":[[1.17,2]],"id":97736949}],"tv":32378.08}],"rt":639159129547138458,"dt":639159129547139126}
{"op":"mcm","id":2,"clk":"ANEgAKkQAJ8r","pt":1780316154810,"mc":[{"id":"1.258742455","rc":[{"atb":[[1.17,1]],"id":99072901},{"atb":[[1.17,195.12]],"atl":[[3.75,10.63]],"batl":[[2,3.85,10.56],[1,3.8,48.8],[0,3.75,10.63]],"id":88302242},{"batb":[[0,10.5,17.83]],"atb":[[10.5,17.83]],"id":97736949}]}],"rt":639159129548186972,"dt":639159129548187668}
{"op":"mcm","id":2,"clk":"ANogALIQAKkr","pt":1780316154913,"mc":[{"id":"1.258742455","rc":[{"batb":[[0,42,9.7]],"atb":[[42,9.7]],"id":97008932},{"batb":[[0,80,2.16]],"atb":[[85,0.46]],"id":99072901},{"tv":7483.01,"batb":[[0,4.6,28.99]],"trd":[[4.6,705.3]],"atb":[[4.6,28.99]],"atl":[[4.8,59.36]],"batl":[[1,4.8,59.36]],"id":10398159},{"batb":[[0,9.4,16.15]],"atb":[[9.4,16.15]],"id":98117699},{"batb":[[0,3.7,70.06]],"atb":[[3.7,70.06]],"atl":[[3.9,16.13]],"batl":[],"id":88302242}],"tv":32383.08}],"rt":639159129549212228,"dt":639159129549212697}
{"op":"mcm","id":2,"clk":"AN4gALsQALAr","pt":1780316155011,"mc":[{"id":"1.258742455","rc":[{"tv":11223.43,"batb":[[2,3.45,1.99],[1,3.5,31.99],[0,3.55,41.99]],"trd":[[3.65,62.08],[3.55,131.82],[3.7,144.18],[3.6,63.12]],"ltp":3.55,"atb":[[3.65,0],[3.55,41.99],[3.7,0],[3.6,0]],"id":88302242}],"tv":32589.08}],"rt":639159129550194626,"dt":639159129550195043}
{"op":"mcm","id":2,"clk":"AOggAMIQALsr","pt":1780316155116,"mc":[{"id":"1.258742455","rc":[{"atl":[[4.7,15.94],[4.6,10.6]],"batl":[[1,4.7,15.94],[0,4.6,10.6]],"id":99072898},{"atl":[[4.9,25.89],[5,8.65]],"batl":[[2,4.9,25.89]],"id":10398159},{"batb":[[0,9.4,19.77]],"atb":[[9.4,19.77]],"atl":[[9.6,2.6]],"batl":[[0,9.6,2.6]],"id":98117699},{"batb":[[2,3.5,31.99],[1,3.55,51.43],[0,3.6,11.62]],"atb":[[3.55,51.43],[3.6,11.62]],"atl":[[3.75,12.44],[3.85,12.36]],"batl":[[2,3.85,12.36],[0,3.75,12.44]],"id":88302242},{"batb":[],"atb":[[9.2,6.17]],"id":97736949},{"batb":[[1,150,5.02]],"atb":[[150,5.02]],"id":99072897}]}],"rt":639159129551248748,"dt":639159129551249290}
{"op":"mcm","id":2,"clk":"AO8gAMUQAMEr","pt":1780316155216,"mc":[{"id":"1.258742455","rc":[{"atl":[[4.7,13.63],[4.8,27.9]],"batl":[[2,4.8,27.9],[1,4.7,13.63]],"id":99072898},{"batb":[[2,38,12.82]],"atb":[[38,12.82]],"id":97008932},{"atl":[[4.9,3.99],[32,3.97]],"batl":[[2,4.9,3.99]],"id":10398159},{"atl":[[11,4.77],[10.5,5.68]],"batl":[],"id":98117699},{"batb":[[2,3.5,41.37],[1,3.55,41.99],[0,3.6,13.61]],"atb":[[3.5,41.37],[3.55,41.99],[3.6,13.61]],"atl":[[3.7,10.78]],"batl":[[2,3.8,48.8],[1,3.75,12.44],[0,3.7,10.78]],"id":88302242},{"batb":[],"atb":[[9.4,6.73]],"id":97736949}]}],"rt":639159129552245848,"dt":639159129552246600}
{"op":"mcm","id":2,"clk":"APUgAMsQAMkr","pt":1780316155319,"mc":[{"id":"1.258742455","rc":[{"atl":[[5,41.33],[4.8,28.9]],"batl":[[2,4.8,28.9]],"id":99072898},{"batb":[[2,3.5,55.89],[0,3.6,30.13]],"atb":[[3.5,55.89],[3.6,30.13],[3.45,16.51]],"atl":[[3.7,12.61],[3.95,54.11]],"batl":[[0,3.7,12.61]],"id":88302242}]}],"rt":639159129553271792,"dt":639159129553272303}
{"op":"mcm","id":2,"clk":"AIMhANEQANIr","pt":1780316155422,"mc":[{"id":"1.258742455","rc":[{"batb":[[1,150,3.29]],"atb":[[150,3.29]],"id":99072897}]}],"rt":639159129554307480,"dt":639159129554308027}
{"op":"mcm","id":2,"clk":"AJEhANgQAN0r","pt":1780316155625,"mc":[{"id":"1.258742455","rc":[{"atl":[[65,26.31]],"batl":[[0,65,26.31]],"id":98464183}]}],"rt":639159129556331268,"dt":639159129556331943}
{"op":"mcm","id":2,"clk":"AJkhAN0QAOYr","pt":1780316155729,"mc":[{"id":"1.258742455","rc":[{"atl":[[4.7,4.39]],"batl":[[0,4.7,4.39]],"id":10398159},{"tv":2066.29,"batb":[[2,9.2,15.98],[1,9.4,19.77],[0,9.6,1]],"trd":[[9.6,211.18]],"ltp":9.6,"atb":[[9.6,1]],"atl":[[9.6,0]],"batl":[[2,10.5,5.68],[1,10,3.49],[0,9.8,6.25]],"id":98117699}],"tv":32594.28}],"rt":639159129557371793,"dt":639159129557372291}
{"op":"mcm","id":2,"clk":"AJ4hAN8QAO0r","pt":1780316155830,"mc":[{"id":"1.258742455","rc":[{"batb":[[1,4.4,49.82]],"atb":[[4.4,49.82]],"id":99072898},{"atl":[[5.1,31.8]],"batl":[],"id":10398159},{"tv":2068.27,"batb":[[2,9,27.23],[1,9.2,15.98],[0,9.4,20.78]],"trd":[[9.6,213.16]],"atb":[[9.4,20.77],[9.6,0.01]],"id":98117699},{"batb":[[1,150,5.02]],"atb":[[150,5.02]],"id":99072897}],"tv":32596.26}],"rt":639159129558387206,"dt":639159129558387674}
{"op":"mcm","id":2,"clk":"AKQhAOEQAPMr","pt":1780316155930,"mc":[{"id":"1.258742455","rc":[{"atl":[[5,4.99]],"batl":[],"id":10398159},{"tv":596.71,"batb":[[0,60,26.61]],"trd":[[60,45.5]],"atb":[[60,26.61]],"id":98464183}],"tv":32596.38}],"rt":639159129559390117,"dt":639159129559390674}
{"op":"mcm","id":2,"clk":"AKchAOQQAPsr","pt":1780316155986,"mc":[{"id":"1.258742455","rc":[{"batb":[[0,10.5,18.53]],"atb":[[10.5,18.53]],"id":97736949},{"batb":[[1,150,3.29]],"atb":[[150,3.29]],"id":99072897}]}],"rt":639159129559938948,"dt":639159129559939312}
{"op":"mcm","id":2,"clk":"ALQhAOoQAIos","pt":1780316156196,"mc":[{"id":"1.258742455","rc":[{"tv":7485.61,"batb":[[0,4.6,27.69]],"trd":[[4.6,707.9]],"atb":[[4.6,27.69]],"id":10398159}],"tv":32598.98}],"rt":639159129562045750,"dt":639159129562046119}
{"op":"mcm","id":2,"clk":"AMEhAO4QAI4s","pt":1780316156297,"mc":[{"id":"1.258742455","rc":[{"atl":[[4.7,34.28]],"batl":[[0,4.7,34.28]],"id":10398159}]}],"rt":639159129563048598,"dt":639159129563049162}
{"op":"mcm","id":2,"clk":"AMghAO8QAJYs","pt":1780316156397,"mc":[{"id":"1.258742455","rc":[{"atl":[[5,8.65]],"batl":[],"id":10398159},{"atl":[[3.8,16.38]],"batl":[[2,3.8,16.38]],"id":88302242},{"tv":1872.58,"trd":[[11,46.6]],"atl":[[11,0.92]],"batl":[[2,12.5,7.51],[1,12,20.45],[0,11.5,8.43]],"id":97736949},{"batb":[[1,150,5.02]],"atb":[[150,5.02]],"id":99072897}],"tv":32599.15}],"rt":639159129564055684,"dt":639159129564056328}
{"op":"mcm","id":2,"clk":"ANohAPEQAJ4s","pt":1780316156505,"mc":[{"id":"1.258742455","rc":[{"batb":[[0,4.5,40.33]],"atb":[[4.5,40.33]],"id":99072898},{"batb":[[0,42,10.03]],"atb":[[42,10.03]],"id":97008932},{"batb":[[0,24,13.92]],"atb":[[24,13.92]],"id":99072900},{"batb":[[0,80,2.33]],"atb":[[80,1.87]],"id":99072901},{"batb":[[0,4.6,30.69]],"atb":[[4.6,30.69]],"atl":[[5,4.99]],"batl":[],"id":10398159},{"batb":[[0,60,26.84]],"atb":[[60,26.84]],"id":98464183},{"batb":[[0,9.4,22.25]],"atb":[[9.4,22.24]],"id":98117699},{"tv":11239.43,"batb":[[0,3.6,25.98]],"trd":[[3.6,79.12]],"ltp":3.6,"atb":[[3.6,25.98]],"atl":[[3.75,44.86]],"batl":[[1,3.75,44.86]],"id":88302242},{"batb":[[0,10.5,19.85]],"atb":[[10.5,19.85],[9.6,6.13]],"id":97736949},{"batb":[[0,1000,103.9]],"atb":[[1000,103.9]],"id":10445502},{"batb":[[0,160,4.71]],"atb":[[160,4.71]],"id":99072897}],"tv":32615.15}],"rt":639159129565135951,"dt":639159129565136822}
{"op":"mcm","id":2,"clk":"AOQhAPQQAKgs","pt":1780316156610,"mc":[{"id":"1.258742455","rc":[{"tv":2080.77,"batb":[[2,9.2,15.98],[1,9.4,22.25],[0,9.8,14.16]],"trd":[[9.8,207]],"ltp":9.8,"atb":[[9.8,14.16]],"atl":[[9.8,0]],"batl":[[2,11,4.77],[1,10.5,5.68],[0,10,3.49]],"id":98117699},{"atl":[[3.65,10.15]],"batl":[[2,3.75,44.86],[1,3.7,12.61],[0,3.65,10.15]],"id":88302242}],"tv":32627.65}],"rt":639159129566185041,"dt":639159129566185721}
{"op":"mcm","id":2,"clk":"AO0hAPkQALMs","pt":1780316156717,"mc":[{"id":"1.258742455","rc":[{"atl":[[5,8.65]],"batl":[],"id":10398159},{"batb":[[2,9.4,22.24],[1,9.6,11.03],[0,9.8,24.03]],"atb":[[8.8,10.57],[9.8,24.03],[8.6,2.99],[9.6,11.03]],"atl":[[11,2.99],[10.5,7.86],[10,7.7]],"batl":[[2,11,2.99],[1,10.5,7.86],[0,10,7.7]],"id":98117699},{"batb":[[2,3.5,46.51],[1,3.55,52.4],[0,3.6,9.46]],"atb":[[3.5,46.51],[3.55,52.4],[3.6,9.46],[3.45,26.05]],"atl":[[3.9,4.58]],"batl":[],"id":88302242},{"batb":[[1,150,3.29]],"atb":[[150,3.29]],"id":99072897}]}],"rt":639159129567254699,"dt":639159129567255420}
{"op":"mcm","id":2,"clk":"APUhAP8QALss","pt":1780316156817,"mc":[{"id":"1.258742455","rc":[{"atl":[[4.7,38.65]],"batl":[[0,4.7,38.65]],"id":10398159},{"atl":[[65,26.35]],"batl":[[0,65,26.35]],"id":98464183},{"batb":[],"atb":[[8.8,6.78]],"atl":[[11,1]],"batl":[[2,11,1]],"id":98117699},{"batb":[[0,10.5,21.74]],"atb":[[10.5,21.74]],"id":97736949}]}],"rt":639159129568257372,"dt":639159129568257752}
{"op":"mcm","id":2,"clk":"AIAiAIcRAM8s","pt":1780316157018,"mc":[{"id":"1.258742455","rc":[{"tv":596.73,"batb":[[0,60,26.83]],"trd":[[60,45.52]],"atb":[[60,26.83]],"id":98464183},{"tv":2089.69,"trd":[[10,472.66]],"ltp":10,"atl":[[10,3.23]],"batl":[[0,10,3.23]],"id":98117699}],"tv":32636.59}],"rt":639159129570264568,"dt":639159129570265063}
{"op":"mcm","id":2,"clk":"AIMiAI0RANcs","pt":1780316157120,"mc":[{"id":"1.258742455","rc":[{"tv":7486.83,"batb":[[0,4.6,30.08]],"trd":[[4.6,709.12]],"atb":[[4.6,30.08]],"id":10398159},{"batb":[[2,9.6,11.03],[1,9.8,24.03],[0,10,1.06]],"atb":[[10,1.06],[9,23.48]],"atl":[[10,0]],"batl":[[2,11.5,4.9],[1,11,1],[0,10.5,7.86]],"id":98117699},{"tv":1873.07,"trd":[[11,47.09]],"atl":[[11,0.67]],"batl":[[0,11.5,8.18]],"id":97736949}],"tv":32638.3}],"rt":639159129571285801,"dt":639159129571286506}
{"op":"mcm","id":2,"clk":"AIoiAJIRAOAs","pt":1780316157233,"mc":[{"id":"1.258742455","rc":[{"atl":[[46,5.07]],"batl":[[0,46,5.07]],"id":97008932},{"tv":2091.21,"batb":[[1,9.8,27.45],[0,10,11.4]],"trd":[[10,474.18]],"atb":[[9.8,27.45],[10,11.4]],"id":98117699},{"batb":[[0,3.6,5.84]],"atb":[[3.6,5.84]],"id":88302242}],"tv":32639.82}],"rt":639159129572411982,"dt":639159129572412665}
{"op":"mcm","id":2,"clk":"AI0iAJURAOss","pt":1780316157322,"mc":[{"id":"1.258742455","rc":[{"batb":[[1,40,7.19]],"atb":[[40,7.19]],"id":97008932},{"atl":[[5,4.99]],"batl":[],"id":10398159},{"batb":[],"atb":[[9,17.97]],"id":98117699}]}],"rt":639159129573302697,"dt":639159129573303309}
{"op":"mcm","id":2,"clk":"AJAiAJoRAPEs","pt":1780316157427,"mc":[{"id":"1.258742455","rc":[{"batb":[[1,4.4,50.87]],"atb":[[4.4,50.87]],"atl":[[4.6,8.28]],"batl":[[0,4.6,8.28]],"id":99072898},{"batb":[[0,60,48.83]],"atb":[[60,48.83]],"id":98464183},{"batb":[[0,10,14.95]],"atb":[[9.4,20.38],[10,14.95]],"id":98117699},{"tv":11251.11,"batb":[[2,3.45,26.05],[1,3.5,46.51],[0,3.55,52.4]],"trd":[[3.6,90.8]],"atb":[[3.6,0]],"atl":[[1000,3.26],[3.65,10.75],[3.8,16.22],[3.85,1.8],[3.6,10.07]],"batl":[[2,3.7,12.61],[1,3.65,10.75],[0,3.6,10.07]],"id":88302242},{"atl":[[1000,1.46],[12,19.62]],"batl":[[1,12,19.62]],"id":97736949}],"tv":32651.5}],"rt":639159129574349883,"dt":639159129574350865}
{"op":"mcm","id":2,"clk":"AJgiAJ4RAPgs","pt":1780316157531,"mc":[{"id":"1.258742455","rc":[{"atl":[[4.9,27.62],[4.8,25.17]],"batl":[[2,4.8,25.17]],"id":99072898},{"tv":11262.21,"trd":[[3.6,101.9]],"atl":[[1000,3],[3.6,4.52]],"batl":[[0,3.6,4.52]],"id":88302242},{"batb":[[2,9.8,11.45]],"atb":[[9.8,11.45]],"atl":[[1000,1]],"id":97736949},{"batb":[[1,150,5.02]],"atb":[[150,5.02]],"id":99072897}],"tv":32662.6}],"rt":639159129575395248,"dt":639159129575395859}
{"op":"mcm","id":2,"clk":"AKAiAKIRAIEt","pt":1780316157630,"mc":[{"id":"1.258742455","rc":[{"atl":[[4.6,6.29]],"batl":[[0,4.6,6.29]],"id":99072898},{"tv":11271.25,"batb":[[2,3.5,57.29],[1,3.55,52.4],[0,3.6,2.88]],"trd":[[3.6,110.94]],"atb":[[3.5,57.29],[3.6,2.88]],"atl":[[3.7,12.87],[3.6,0]],"batl":[[2,3.75,44.86],[1,3.7,12.87],[0,3.65,10.75]],"id":88302242},{"atl":[[11.5,7.74],[11,0.9]],"batl":[[0,11.5,8.64]],"id":97736949}],"tv":32671.64}],"rt":639159129576383238,"dt":639159129576384198}
{"op":"mcm","id":2,"clk":"AKYiAKURAIkt","pt":1780316157735,"mc":[{"id":"1.258742455","rc":[{"atl":[[4.8,28.92]],"batl":[[2,4.8,28.92]],"id":99072898},{"tv":11277.01,"batb":[[2,3.45,26.05],[1,3.5,57.29],[0,3.55,52.4]],"trd":[[3.6,116.7]],"atb":[[3.6,0]],"atl":[[3.65,12.58],[3.6,10.85]],"batl":[[2,3.7,12.87],[1,3.65,12.58],[0,3.6,10.85]],"id":88302242},{"batb":[[2,9.8,8.51]],"atb":[[9.8,8.51]],"id":97736949},{"batb":[[1,150,3.29]],"atb":[[150,3.29]],"id":99072897}],"tv":32677.4}],"rt":639159129577431134,"dt":639159129577431782}
{"op":"mcm","id":2,"clk":"AK8iAKgRAJUt","pt":1780316157837,"mc":[{"id":"1.258742455","rc":[{"atl":[[3.6,12.69]],"batl":[[0,3.6,12.69]],"id":88302242},{"batb":[[2,9.8,11.45]],"atb":[[9.8,11.45]],"id":97736949},{"batb":[[1,150,5.02]],"atb":[[150,5.02]],"id":99072897}]}],"rt":639159129578453907,"dt":639159129578454596}
{"op":"mcm","id":2,"clk":"ALMiAKwRAJst","pt":1780316157890,"mc":[{"id":"1.258742455","rc":[{"atl":[[4.8,25.17]],"batl":[[2,4.8,25.17]],"id":99072898},{"atl":[[3.6,12.79]],"batl":[[0,3.6,12.79]],"id":88302242}]}],"rt":639159129578983260,"dt":639159129578983876}
{"op":"mcm","id":2,"clk":"ANUiAMURAMot","pt":1780316158407,"mc":[{"id":"1.258742455","rc":[{"atl":[[65,27.22]],"batl":[[0,65,27.22]],"id":98464183},{"tv":11284.63,"trd":[[3.6,124.32]],"atl":[[3.6,8.98]],"batl":[[0,3.6,8.98]],"id":88302242}],"tv":32685.02}],"rt":639159129584147780,"dt":639159129584148342}
{"op":"mcm","id":2,"clk":"AN0iAMgRANEt","pt":1780316158510,"mc":[{"id":"1.258742455","rc":[{"atb":[[1.17,2.17]],"id":97008932},{"atl":[[95,3.9]],"batl":[[0,95,3.9]],"id":99072901},{"batb":[[0,10,13.74]],"atb":[[10,13.74]],"id":98117699},{"tv":1875.07,"batb":[[0,10.5,20.74]],"trd":[[10.5,2]],"ltp":10.5,"atb":[[10.5,20.74]],"id":97736949},{"atl":[[1000,8.8]],"batl":[],"id":99072897}],"tv":32687.02}],"rt":639159129585185491,"dt":639159129585186312}
{"op":"mcm","id":2,"clk":"AOEiANERANgt","pt":1780316158612,"mc":[{"id":"1.258742455","rc":[{"atb":[[1.17,2]],"id":97008932},{"atl":[[1000,8.75]],"batl":[],"id":99072897}]}],"rt":639159129586198271,"dt":639159129586198946}
{"op":"mcm","id":2,"clk":"AOciANMRAOMt","pt":1780316158712,"mc":[{"id":"1.258742455","rc":[{"atl":[[5.4,30.63]],"batl":[],"id":99072898},{"batb":[[0,42,10.2]],"atb":[[42,10.2]],"id":97008932},{"atl":[[4.9,43.14],[4.8,15.49]],"batl":[[2,4.9,43.14],[1,4.8,15.49]],"id":10398159},{"atl":[[12.5,20.25]],"batl":[],"id":98117699},{"atl":[[3.8,44.58],[3.95,24.57]],"batl":[],"id":88302242},{"atl":[[180,0.47]],"batl":[[0,190,3.12]],"id":99072897}]}],"rt":639159129587198214,"dt":639159129587198830}
{"op":"mcm","id":2,"clk":"AOsiANYRAOst","pt":1780316158816,"mc":[{"id":"1.258742455","rc":[{"atl":[[5.3,1.99]],"batl":[],"id":99072898},{"atl":[[12,13.1]],"batl":[],"id":98117699}]}],"rt":639159129588238009,"dt":639159129588238411}
{"op":"mcm","id":2,"clk":"APQiANwRAPYt","pt":1780316158921,"mc":[{"id":"1.258742455","rc":[{"atb":[[1.17,2.23]],"id":97008932},{"tv":893.79,"batb":[[0,24,13.5]],"trd":[[24,88.19]],"ltp":24,"atb":[[24,13.5]],"atl":[[25,4.9]],"batl":[[0,25,4.9]],"id":99072900},{"batb":[[0,80,2.5]],"atb":[[85,0.63]],"id":99072901},{"atl":[[1000,0.09]],"id":98464183},{"tv":11289.23,"trd":[[3.6,128.92]],"atl":[[3.6,6.68]],"batl":[[0,3.6,6.68]],"id":88302242}],"tv":32692.46}],"rt":639159129589295014,"dt":639159129589295620}
{"op":"mcm","id":2,"clk":"APoiAN8RAP4t","pt":1780316159018,"mc":[{"id":"1.258742455","rc":[{"atb":[[1.17,2]],"id":97008932},{"batb":[[0,3.55,78.71]],"atb":[[3.55,78.71]],"id":88302242}]}],"rt":639159129590266608,"dt":639159129590267503}
{"op":"mcm","id":2,"clk":"AP0iAOARAIcu","pt":1780316159122,"mc":[{"id":"1.258742455","rc":[{"batb":[[0,42,10.43]],"atb":[[42,10.43]],"id":97008932},{"batb":[[1,55,28.56],[0,60,30.03]],"atb":[[60,30.03],[55,28.56]],"atl":[[1000,0]],"id":98464183},{"atl":[[3.6,1.94]],"batl":[[0,3.6,1.94]],"id":88302242}]}],"rt":639159129591306665,"dt":639159129591307174}
{"op":"mcm","id":2,"clk":"AIUjAOgRAJAu","pt":1780316159226,"mc":[{"id":"1.258742455","rc":[{"tv":7498.83,"batb":[[0,4.6,24.08]],"trd":[[4.6,721.12]],"atb":[[4.6,24.08]],"id":10398159},{"atl":[[65,27.31]],"batl":[[0,65,27.31]],"id":98464183},{"batb":[],"atb":[[3.4,16.52]],"id":88302242},{"batb":[[1,150,3.29]],"atb":[[150,3.29]],"id":99072897}],"tv":32704.46}],"rt":639159129592341339,"dt":639159129592341914}
{"op":"mcm","id":2,"clk":"AIsjAO4RAJsu","pt":1780316159334,"mc":[{"id":"1.258742455","rc":[{"atl":[[4.6,16.82]],"batl":[[0,4.6,16.82]],"id":99072898},{"atl":[[11,10.2]],"batl":[[1,11,10.2]],"id":98117699}]}],"rt":639159129593418114,"dt":639159129593418816}
{"op":"mcm","id":2,"clk":"AJMjAPARAKku","pt":1780316159434,"mc":[{"id":"1.258742455","rc":[{"batb":[[0,4.6,52.32]],"atb":[[4.6,52.32]],"id":10398159}]}],"rt":639159129594421517,"dt":639159129594421918}
{"op":"mcm","id":2,"clk":"AJsjAPQRALIu","pt":1780316159540,"mc":[{"id":"1.258742455","rc":[{"tv":11293.23,"batb":[[0,3.55,76.71]],"trd":[[3.55,135.82]],"ltp":3.55,"atb":[[3.55,76.71]],"id":88302242}],"tv":32708.46}],"rt":639159129595478469,"dt":639159129595478894}
{"op":"mcm","id":2,"clk":"ALUjAP8RAM4u","pt":1780316159798,"mc":[{"id":"1.258742455","rc":[{"tv":11296.43,"trd":[[3.6,132.12]],"ltp":3.6,"atl":[[3.6,0.34]],"batl":[[2,3.75,44.86],[1,3.7,12.87],[0,3.65,12.92]],"id":88302242}],"tv":32711.66}],"rt":639159129598066643,"dt":639159129598067107}
{"op":"mcm","id":2,"clk":"ALojAIESANwu","pt":1780316159903,"mc":[{"id":"1.258742455","rc":[{"atl":[[4.8,28.9]],"batl":[[2,4.8,28.9]],"id":99072898},{"tv":11304.43,"batb":[[2,3.5,57.29],[1,3.55,76.71],[0,3.6,5.27]],"trd":[[3.65,69.4],[3.6,132.8]],"ltp":3.65,"atb":[[3.6,5.27]],"atl":[[3.65,8.92],[3.6,0]],"batl":[[0,3.65,8.92]],"id":88302242},{"batb":[[2,9.8,8.51]],"atb":[[9.8,8.51]],"id":97736949}],"tv":32719.66}],"rt":639159129599121578,"dt":639159129599122125}
{"op":"mcm","id":2,"clk":"AL4jAIYSAOYu","pt":1780316160003,"mc":[{"id":"1.258742455","rc":[{"atl":[[5,8.65]],"batl":[],"id":10398159},{"atl":[[65,27.36]],"batl":[[0,65,27.36]],"id":98464183},{"batb":[[2,3.5,66.86]],"atb":[[3.5,66.86]],"id":88302242}]}],"rt":639159129600111884,"dt":639159129600112562}
{"op":"mcm","id":2,"clk":"AMQjAIoSAOsu","pt":1780316160105,"mc":[{"id":"1.258742455","rc":[{"atb":[[6,1.99]],"id":98117699},{"batb":[[0,3.6,7.27]],"atb":[[3.6,7.27]],"id":88302242}]}],"rt":639159129601134679,"dt":639159129601135201}
{"op":"mcm","id":2,"clk":"AM0jAI8SAPIu","pt":1780316160221,"mc":[{"id":"1.258742455","rc":[{"batb":[[0,4.5,43.41]],"atb":[[4.5,43.41]],"id":99072898},{"batb":[[0,42,10.76]],"atb":[[42,10.76]],"id":97008932},{"batb":[[0,24,14.08]],"atb":[[24,14.08]],"id":99072900},{"batb":[[0,80,2.67]],"atb":[[80,2.04]],"id":99072901},{"batb":[[0,4.6,55.34]],"atb":[[4.6,55.34]],"id":10398159},{"batb":[[0,60,30.26]],"atb":[[60,30.26]],"id":98464183},{"batb":[[0,10,15.13]],"atb":[[10,15.13]],"id":98117699},{"tv":11307.89,"batb":[[0,3.6,9.39]],"trd":[[3.6,136.26]],"ltp":3.6,"atb":[[3.6,9.39]],"id":88302242},{"batb":[[0,10.5,22.06]],"atb":[[10.5,22.06]],"id":97736949},{"batb":[[0,1000,103.91]],"atb":[[1000,103.91]],"id":10445502},{"batb":[[0,160,4.79]],"atb":[[160,4.79]],"id":99072897}],"tv":32723.12}],"rt":639159129602288768,"dt":639159129602289591}
{"op":"mcm","id":2,"clk":"ANIjAJESAPku","pt":1780316160314,"mc":[{"id":"1.258742455","rc":[{"tv":596.74,"batb":[[0,60,30.25]],"trd":[[60,45.53]],"atb":[[60,30.25]],"id":98464183}],"tv":32723.13}],"rt":639159129603227877,"dt":639159129603228252}
{"op":"mcm","id":2,"clk":"ANwjAJISAIQv","pt":1780316160413,"mc":[{"id":"1.258742455","rc":[{"batb":[[0,3.6,10.39]],"atb":[[3.6,10.39]],"id":88302242}]}],"rt":639159129604212202,"dt":639159129604212689}
{"op":"mcm","id":2,"clk":"AN4jAJQSAI8v","pt":1780316160515,"mc":[{"id":"1.258742455","rc":[{"tv":7241.09,"trd":[[4.6,24]],"ltp":4.6,"atl":[[4.6,5.82]],"batl":[[0,4.6,5.82]],"id":99072898},{"atl":[[46,5.1]],"batl":[[0,46,5.1]],"id":97008932},{"atl":[[1000,6.55]],"id":99072900},{"tv":608.74,"batb":[[0,60,24.25]],"trd":[[60,57.53]],"atb":[[60,24.25]],"id":98464183},{"atl":[[1000,6.97]],"id":98117699},{"atb":[[1.17,196.09]],"id":88302242},{"batb":[[0,10.5,25.91]],"atb":[[10.5,25.91]],"id":97736949}],"tv":32757.13}],"rt":639159129605231400,"dt":639159129605232316}
{"op":"mcm","id":2,"clk":"AOcjAJgSAJUv","pt":1780316160618,"mc":[{"id":"1.258742455","rc":[{"atl":[[4.6,0]],"batl":[[2,4.9,27.62],[1,4.8,28.9],[0,4.7,13.63]],"id":99072898},{"atl":[[1000,6.25]],"id":99072900},{"atl":[[1000,6.25]],"id":98117699},{"tv":11328.67,"batb":[[2,3.45,26.05],[1,3.5,66.86],[0,3.55,76.71]],"trd":[[3.6,157.04]],"atb":[[3.6,0]],"atl":[[3.6,10.8]],"batl":[[2,3.7,12.87],[1,3.65,8.92],[0,3.6,10.8]],"id":88302242},{"batb":[[1,10,42.3]],"atb":[[10,42.3]],"id":97736949}],"tv":32777.91}],"rt":639159129606264538,"dt":639159129606265168}
{"op":"mcm","id":2,"clk":"AOwjAJsSAJ8v","pt":1780316160721,"mc":[{"id":"1.258742455","rc":[{"atl":[[4.8,25.17]],"batl":[[1,4.8,25.17]],"id":99072898},{"atl":[[25,5.2]],"batl":[[0,25,5.2]],"id":99072900},{"atl":[[5,4.99]],"batl":[],"id":10398159},{"batb":[[0,60,30.39]],"atb":[[60,30.39]],"id":98464183},{"atl":[[11,10.92]],"batl":[[1,11,10.92]],"id":98117699},{"batb":[[1,3.5,57.29]],"atb":[[1.17,195.12],[3.5,57.29]],"atl":[[3.65,9.52],[3.6,12.62]],"batl":[[1,3.65,9.52],[0,3.6,12.62]],"id":88302242},{"batb":[[0,10.5,32.27]],"atb":[[10.5,32.27]],"id":97736949},{"atl":[[180,1.43]],"batl":[[2,210,1.77],[1,190,2.65],[0,180,1.43]],"id":99072897}]}],"rt":639159129607294540,"dt":639159129607295363}
{"op":"mcm","id":2,"clk":"APYjAJ8SAKgv","pt":1780316160824,"mc":[{"id":"1.258742455","rc":[{"atl":[[5,36.61]],"batl":[],"id":99072898},{"tv":11330.61,"trd":[[3.6,158.98]],"atl":[[3.6,11.65]],"batl":[[0,3.6,11.65]],"id":88302242},{"batb":[[1,150,5.02]],"atb":[[150,5.02]],"id":99072897}],"tv":32779.85}],"rt":639159129608322049,"dt":639159129608322465}
{"op":"mcm","id":2,"clk":"APwjAKUSALIv","pt":1780316160926,"mc":[{"id":"1.258742455","rc":[{"atl":[[90,0.11]],"batl":[[0,95,4.01]],"id":99072901}]}],"rt":639159129609343441,"dt":639159129609343729}
{"op":"mcm","id":2,"clk":"AIYkAKgSAMAv","pt":1780316161028,"mc":[{"id":"1.258742455","rc":[{"atl":[[110,0.37]],"batl":[[2,120,1.48]],"id":99072901},{"batb":[[0,160,4.84]],"atb":[[170,0.05]],"id":99072897}]}],"rt":639159129610357618,"dt":639159129610358323}
{"op":"mcm","id":2,"clk":"AIwkAK0SAMkv","pt":1780316161133,"mc":[{"id":"1.258742455","rc":[{"atl":[[4.7,14.16]],"batl":[[0,4.7,14.16]],"id":99072898},{"atb":[[27,0]],"id":99072897}]}],"rt":639159129611410129,"dt":639159129611410506}
{"op":"mcm","id":2,"clk":"AJIkALASANAv","pt":1780316161236,"mc":[{"id":"1.258742455","rc":[{"atl":[[65,27.66]],"batl":[[0,65,27.66]],"id":98464183}]}],"rt":639159129612441155,"dt":639159129612441544}
{"op":"mcm","id":2,"clk":"AJ8kALkSAN8v","pt":1780316161441,"mc":[{"id":"1.258742455","rc":[{"atl":[[10.5,17]],"batl":[[0,10.5,17]],"id":98117699}]}],"rt":639159129614493756,"dt":639159129614494102}
{"op":"mcm","id":2,"clk":"AKMkALsSAOQv","pt":1780316161491,"mc":[{"id":"1.258742455","rc":[{"tv":1877.07,"batb":[[0,10.5,31.27]],"trd":[[10.5,4]],"atb":[[10.5,31.27]],"id":97736949}],"tv":32781.85}],"rt":639159129614995419,"dt":639159129614995899}
{"op":"mcm","id":2,"clk":"AKgkAL0SAOsv","pt":1780316161593,"mc":[{"id":"1.258742455","rc":[{"atl":[[4.8,2.99]],"batl":[[1,4.8,2.99]],"id":99072898},{"atl":[[95,3.64]],"batl":[[0,95,3.75]],"id":99072901},{"tv":608.86,"batb":[[0,60,30.33]],"trd":[[60,57.65]],"atb":[[60,30.33]],"id":98464183}],"tv":32781.97}],"rt":639159129616016450,"dt":639159129616017072}
{"op":"mcm","id":2,"clk":"AL0kAMYSAIYw","pt":1780316161902,"mc":[{"id":"1.258742455","rc":[{"atl":[[3.65,10.14],[3.75,45.48],[3.7,13.49],[4,8.6]],"batl":[[2,3.7,13.49],[1,3.65,10.14]],"id":88302242}]}],"rt":639159129619106202,"dt":639159129619106645}
{"op":"mcm","id":2,"clk":"AMAkAMkSAI4w","pt":1780316162004,"mc":[{"id":"1.258742455","rc":[{"batb":[[0,60,35.31]],"atb":[[60,35.31]],"id":98464183},{"atl":[[3.8,45.2]],"batl":[],"id":88302242},{"batb":[[0,10.5,33.23]],"atb":[[10.5,33.23]],"id":97736949}]}],"rt":639159129620123179,"dt":639159129620123572}
{"op":"mcm","id":2,"clk":"ANEkANISAJgw","pt":1780316162213,"mc":[{"id":"1.258742455","rc":[{"batb":[],"atb":[[4.2,112.05]],"id":99072898},{"batb":[],"atb":[[8.4,2.99],[8.8,2.99],[9.2,12.3]],"id":98117699},{"atl":[[3.75,43.67],[3.9,0],[3.95,20],[3.85,0],[4,4.05]],"batl":[],"id":88302242},{"batb":[],"atb":[[8.8,1.99]],"atl":[[13.5,2.99]],"batl":[],"id":97736949}]}],"rt":639159129622209587,"dt":639159129622210184}
{"op":"mcm","id":2,"clk":"ANUkANcSAKIw","pt":1780316162314,"mc":[{"id":"1.258742455","rc":[{"atl":[[4.7,43.45]],"batl":[[0,4.7,43.45]],"id":10398159}]}],"rt":639159129623216765,"dt":639159129623217158}
{"op":"mcm","id":2,"clk":"ANokANoSAKsw","pt":1780316162414,"mc":[{"id":"1.258742455","rc":[{"tv":612.78,"batb":[[0,60,32.31]],"trd":[[60,61.57]],"atb":[[60,32.31]],"id":98464183}],"tv":32785.89}],"rt":639159129624223800,"dt":639159129624224253}
{"op":"mcm","id":2,"clk":"AOYkAOESALow","pt":1780316162621,"mc":[{"id":"1.258742455","rc":[{"batb":[[2,4.4,50.87],[1,4.5,43.41],[0,4.6,55.55]],"atb":[[4.6,55.55]],"id":99072898}]}],"rt":639159129626296901,"dt":639159129626297479}
{"op":"mcm","id":2,"clk":"AOokAOcSAMAw","pt":1780316162724,"mc":[{"id":"1.258742455","rc":[{"batb":[[0,4.6,85.03]],"atb":[[4.1,62.94],[4.6,85.03]],"id":99072898},{"atl":[[5,8.64]],"batl":[],"id":10398159},{"tv":1877.53,"trd":[[11,47.55]],"ltp":11,"atl":[[11,0.67]],"batl":[[0,11.5,8.41]],"id":97736949}],"tv":32786.35}],"rt":639159129627327940,"dt":639159129627328632}
{"op":"mcm","id":2,"clk":"AO4kAO4SAMkw","pt":1780316162827,"mc":[{"id":"1.258742455","rc":[{"batb":[],"atb":[[4.1,51]],"atl":[[4.8,13.22]],"batl":[[1,4.8,13.22]],"id":99072898},{"tv":7502.03,"batb":[[0,4.6,53.74]],"trd":[[4.6,724.32]],"atb":[[4.6,53.74]],"id":10398159}],"tv":32789.55}],"rt":639159129628354999,"dt":639159129628355699}
{"op":"mcm","id":2,"clk":"APMkAPQSANAw","pt":1780316162929,"mc":[{"id":"1.258742455","rc":[{"atl":[[4.7,12.17]],"batl":[[0,4.7,12.17]],"id":99072898}]}],"rt":639159129629374251,"dt":639159129629374647}
{"op":"mcm","id":2,"clk":"APokAPgSANUw","pt":1780316163032,"mc":[{"id":"1.258742455","rc":[{"atl":[[4.7,1.77]],"batl":[[0,4.7,1.77]],"id":99072898}]}],"rt":639159129630403640,"dt":639159129630404200}
{"op":"mcm","id":2,"clk":"AIElAIMTAOIw","pt":1780316163233,"mc":[{"id":"1.258742455","rc":[{"atl":[[500,1]],"id":10398159}]}],"rt":639159129632407410,"dt":639159129632407802}
{"op":"mcm","id":2,"clk":"AIYlAIkTAOow","pt":1780316163335,"mc":[{"id":"1.258742455","rc":[{"batb":[[2,4.4,49.49],[1,4.5,44.87],[0,4.6,86.37]],"atb":[[4.4,49.49],[4.6,86.37],[4.5,44.87]],"id":99072898},{"atl":[[46,4.93]],"batl":[[0,46,4.93]],"id":97008932},{"batb":[[0,4.6,56.9]],"atb":[[4.6,56.9]],"id":10398159},{"batb":[[0,60,32.55]],"atb":[[60,32.55]],"id":98464183},{"tv":11340.61,"batb":[],"trd":[[3.6,168.98]],"atb":[[3.35,90.98]],"atl":[[3.7,13.23],[3.6,6.65]],"batl":[[2,3.7,13.23],[0,3.6,6.65]],"id":88302242},{"batb":[[0,160,4.62]],"atb":[[160,4.57]],"id":99072897}],"tv":32799.55}],"rt":639159129633436120,"dt":639159129633436948}
{"op":"mcm","id":2,"clk":"AJAlAJETAPQw","pt":1780316163492,"mc":[{"id":"1.258742455","rc":[{"atl":[[65,27.9]],"batl":[[0,65,27.9]],"id":98464183}]}],"rt":639159129635000155,"dt":639159129635000592}
{"op":"mcm","id":2,"clk":"AKUlAJwTAI8x","pt":1780316163903,"mc":[{"id":"1.258742455","rc":[{"tv":7506.03,"batb":[[0,4.6,54.9]],"trd":[[4.6,728.32]],"atb":[[4.6,54.9]],"id":10398159}],"tv":32803.55}],"rt":639159129639116415,"dt":639159129639116839}
{"op":"mcm","id":2,"clk":"AK0lAKITAJYx","pt":1780316164008,"mc":[{"id":"1.258742455","rc":[{"batb":[[0,10.5,33.94]],"atb":[[10.5,33.94]],"id":97736949}]}],"rt":639159129640167166,"dt":639159129640167524}
{"op":"mcm","id":2,"clk":"ALIlAKkTAKQx","pt":1780316164209,"mc":[{"id":"1.258742455","rc":[{"atl":[[5.5,41.21]],"batl":[],"id":99072898},{"atl":[[10.5,19]],"batl":[[0,10.5,19]],"id":98117699}]}],"rt":639159129642172062,"dt":639159129642172975}
{"op":"mcm","id":2,"clk":"ALglAK0TAK0x","pt":1780316164315,"mc":[{"id":"1.258742455","rc":[{"batb":[[0,4.6,89.4]],"atb":[[4.6,89.4]],"atl":[[5.4,1.99]],"batl":[],"id":99072898},{"batb":[[0,42,11.1]],"atb":[[42,11.1]],"id":97008932},{"batb":[[0,24,14.66]],"atb":[[24,14.66]],"id":99072900},{"batb":[[0,80,2.85]],"atb":[[80,2.22]],"id":99072901},{"batb":[[0,4.6,57.93]],"atb":[[4.6,57.93]],"id":10398159},{"batb":[[0,60,32.79]],"atb":[[60,32.79]],"id":98464183},{"batb":[[0,10,16.52]],"atb":[[10,16.52]],"atl":[[10.5,19.98]],"batl":[[0,10.5,19.98]],"id":98117699},{"tv":11342.51,"batb":[[0,3.55,79.68]],"trd":[[3.55,137.72]],"ltp":3.55,"atb":[[3.55,79.68]],"id":88302242},{"tv":1877.71,"batb":[[0,10.5,37.14]],"trd":[[11,47.73]],"atb":[[10.5,37.14]],"atl":[[11,0.58]],"batl":[[0,11.5,8.32]],"id":97736949},{"batb":[[0,1000,103.93]],"atb":[[1000,103.93]],"id":10445502},{"batb":[[0,160,4.71]],"atb":[[160,4.66]],"id":99072897}],"tv":32805.63}],"rt":639159129643227479,"dt":639159129643228597}
{"op":"mcm","id":2,"clk":"ANAlALsTAMgx","pt":1780316164723,"mc":[{"id":"1.258742455","rc":[{"batb":[[0,60,54.79]],"atb":[[60,54.79]],"id":98464183}]}],"rt":639159129647312030,"dt":639159129647312445}
{"op":"mcm","id":2,"clk":"ANUlAL4TANIx","pt":1780316164826,"mc":[{"id":"1.258742455","rc":[{"batb":[[0,4.6,66.13]],"atb":[[4.6,66.13]],"atl":[[4.7,47.6]],"batl":[[0,4.7,47.6]],"id":10398159},{"batb":[[0,10,8.99]],"atb":[[10,8.99]],"id":98117699},{"batb":[[1,150,3.29]],"atb":[[150,3.29]],"id":99072897}]}],"rt":639159129648344691,"dt":639159129648345328}
{"op":"mcm","id":2,"clk":"APYlANYTAP0x","pt":1780316165338,"mc":[{"id":"1.258742455","rc":[{"atb":[[3.75,4.64]],"id":99072898},{"batb":[],"atb":[[21,11.14]],"id":99072900},{"batb":[],"atb":[[3.85,42.81]],"id":10398159},{"batb":[],"atb":[[8.2,2.99]],"id":98117699},{"batb":[],"atb":[[9.4,6.2]],"id":97736949}]}],"rt":639159129653468891,"dt":639159129653469413}
{"op":"mcm","id":2,"clk":"APklANcTAIUy","pt":1780316165396,"mc":[{"id":"1.258742455","rc":[{"batb":[],"atb":[[36,1.99]],"id":97008932},{"tv":7508.03,"batb":[[0,4.6,65.13]],"trd":[[4.6,730.32]],"atb":[[4.6,65.13]],"id":10398159},{"batb":[[2,50,15.6]],"atb":[[50,15.6]],"id":98464183},{"batb":[],"atb":[[3.3,2.23]],"id":88302242}],"tv":32807.63}],"rt":639159129654044482,"dt":639159129654044920}
{"op":"mcm","id":2,"clk":"AIMmANgTAI0y","pt":1780316165495,"mc":[{"id":"1.258742455","rc":[{"tv":7241.49,"batb":[],"trd":[[4.7,2.4]],"ltp":4.7,"atb":[[3.95,5.66]],"atl":[[4.7,1.57]],"batl":[[0,4.7,1.57]],"id":99072898},{"batb":[],"atb":[[21,11.38]],"id":99072900},{"tv":7509.32,"batb":[[0,4.6,64.49]],"trd":[[4.6,731.61]],"atb":[[3.95,40.45],[4.6,64.49]],"id":10398159},{"tv":617.3,"batb":[[0,60,52.53]],"trd":[[60,66.09]],"atb":[[60,52.53]],"id":98464183},{"batb":[],"atb":[[8.6,3.57]],"id":98117699},{"tv":1878.16,"batb":[],"trd":[[11,48.18]],"atb":[[9.4,6.73]],"atl":[[11,0.36]],"batl":[[0,11.5,8.1]],"id":97736949}],"tv":32814.29}],"rt":639159129655033539,"dt":639159129655034166}
{"op":"mcm","id":2,"clk":"AIkmANwTAJcy","pt":1780316165609,"mc":[{"id":"1.258742455","rc":[{"tv":11350.51,"batb":[[0,3.55,75.68]],"trd":[[3.55,145.72]],"atb":[[3.55,75.68]],"id":88302242},{"batb":[[1,150,5.02]],"atb":[[150,5.02]],"id":99072897}],"tv":32822.29}],"rt":639159129656169132,"dt":639159129656169633}
{"op":"mcm","id":2,"clk":"AJImAOETAKIy","pt":1780316165710,"mc":[{"id":"1.258742455","rc":[{"batb":[[1,4.5,45.87]],"atb":[[4.5,45.87]],"id":99072898},{"batb":[[2,38,12.95]],"atb":[[38,12.95]],"id":97008932},{"batb":[[2,50,15.7]],"atb":[[50,15.7]],"id":98464183},{"batb":[[2,9.6,12.03],[1,9.8,28.45]],"atb":[[9.8,28.45],[9.6,12.03]],"id":98117699},{"tv":11380.95,"batb":[[0,3.55,50.05]],"trd":[[3.55,176.16]],"atb":[[3.05,298.71],[3.55,50.05]],"atl":[[3.8,28.36]],"batl":[],"id":88302242}],"tv":32852.73}],"rt":639159129657180001,"dt":639159129657180651}
{"op":"mcm","id":2,"clk":"AJcmAOUTAK0y","pt":1780316165811,"mc":[{"id":"1.258742455","rc":[{"atl":[[3.6,7.27]],"batl":[[0,3.6,7.27]],"id":88302242}]}],"rt":639159129658187179,"dt":639159129658187832}
{"op":"mcm","id":2,"clk":"AJ0mAOYTALQy","pt":1780316165913,"mc":[{"id":"1.258742455","rc":[{"batb":[[0,3.55,35.53]],"atb":[[3.55,35.53]],"id":88302242}]}],"rt":639159129659209990,"dt":639159129659210278}
{"op":"mcm","id":2,"clk":"AK8mAPUTANwy","pt":1780316166316,"mc":[{"id":"1.258742455","rc":[{"atl":[[1000,6.87]],"id":99072898}]}],"rt":639159129663241866,"dt":639159129663242351}
{"op":"mcm","id":2,"clk":"ALYmAPkTAOUy","pt":1780316166422,"mc":[{"id":"1.258742455","rc":[{"atl":[[1000,6.25]],"id":99072898}]}],"rt":639159129664298343,"dt":639159129664299057}
{"op":"mcm","id":2,"clk":"AL0mAP4TAO8y","pt":1780316166522,"mc":[{"id":"1.258742455","rc":[{"atl":[[4.7,2.19]],"batl":[[0,4.7,2.19]],"id":99072898}]}],"rt":639159129665299749,"dt":639159129665300140}
{"op":"mcm","id":2,"clk":"AMkmAIMUAPgy","pt":1780316166638,"mc":[{"id":"1.258742455","rc":[{"atl":[[12,28.41]],"batl":[[1,12,28.41]],"id":97736949}]}],"rt":639159129666461511,"dt":639159129666461910}
{"op":"mcm","id":2,"clk":"ANMmAIsUAIcz","pt":1780316166834,"mc":[{"id":"1.258742455","rc":[{"batb":[[0,60,33.83]],"atb":[[60,33.83]],"id":98464183},{"batb":[[0,3.55,55.45]],"atb":[[3.55,55.45]],"id":88302242}]}],"rt":639159129668424210,"dt":639159129668424601}
{"op":"mcm","id":2,"clk":"AN4mAI8UAI8z","pt":1780316166933,"mc":[{"id":"1.258742455","rc":[{"batb":[[1,9.8,25.03]],"atb":[[9.8,25.03]],"id":98117699}]}],"rt":639159129669414999,"dt":639159129669415349}
{"op":"mcm","id":2,"clk":"AOcmAJcUAKEz","pt":1780316167140,"mc":[{"id":"1.258742455","rc":[{"atl":[[13.5,1.99]],"batl":[],"id":97736949}]}],"rt":639159129671485627,"dt":639159129671486165}
{"op":"mcm","id":2,"clk":"AO0mAJsUAK4z","pt":1780316167194,"mc":[{"id":"1.258742455","rc":[{"tv":11382.68,"trd":[[3.6,170.71]],"ltp":3.6,"atl":[[3.6,6.41]],"batl":[[0,3.6,6.41]],"id":88302242},{"atl":[[13,9.5]],"batl":[],"id":97736949}],"tv":32854.46}],"rt":639159129672019791,"dt":639159129672020166}
{"op":"mcm","id":2,"clk":"APMmAJ0UALYz","pt":1780316167296,"mc":[{"id":"1.258742455","rc":[{"batb":[[0,3.55,66.02]],"atb":[[3.55,66.02]],"id":88302242}]}],"rt":639159129673042508,"dt":639159129673042852}
{"op":"mcm","id":2,"clk":"APomAKEUALwz","pt":1780316167395,"mc":[{"id":"1.258742455","rc":[{"batb":[[0,4.6,93.69]],"atb":[[4.6,93.69]],"atl":[[4.8,17.33]],"batl":[[1,4.8,17.33]],"id":99072898},{"batb":[[0,42,11.92]],"atb":[[42,11.92]],"atl":[[48,5.12]],"batl":[[1,48,5.12]],"id":97008932},{"batb":[[0,24,15.73]],"atb":[[24,15.73]],"atl":[[26,4.04]],"batl":[[1,26,4.04]],"id":99072900},{"batb":[[0,80,3.18]],"atb":[[80,2.55]],"atl":[[100,1.26]],"batl":[[1,100,1.26]],"id":99072901},{"batb":[[0,4.6,69.31]],"atb":[[4.6,69.31]],"atl":[[4.8,20.11]],"batl":[[1,4.8,20.11]],"id":10398159},{"batb":[[1,55,30.4]],"atb":[[55,30.4]],"atl":[[70,10.57]],"batl":[[1,70,10.57]],"id":98464183},{"batb":[[1,9.8,26.65]],"atb":[[9.8,26.65]],"atl":[[10.5,21.49]],"batl":[[0,10.5,21.49]],"id":98117699},{"batb":[[0,3.55,69.54]],"atb":[[3.55,69.54]],"atl":[[3.65,13.57]],"batl":[[1,3.65,13.57]],"id":88302242},{"tv":1882.16,"batb":[[0,10.5,36.66]],"trd":[[10.5,8]],"ltp":10.5,"atb":[[10.5,36.66]],"atl":[[11.5,9.12]],"batl":[[0,11.5,9.48]],"id":97736949},{"batb":[],"atb":[[95,3.03]],"id":99072897}],"tv":32858.46}],"rt":639159129674032038,"dt":639159129674032997}
{"op":"mcm","id":2,"clk":"AIYnAKoUANIz","pt":1780316167603,"mc":[{"id":"1.258742455","rc":[{"atl":[[3.75,43.05]],"batl":[],"id":88302242}]}],"rt":639159129676116214,"dt":639159129676116764}
{"op":"mcm","id":2,"clk":"AJEnAKwUAOAz","pt":1780316167712,"mc":[{"id":"1.258742455","rc":[{"batb":[[1,4.5,50.23]],"atb":[[4.5,50.23]],"atl":[[4.9,31.62]],"batl":[[2,4.9,31.62]],"id":99072898},{"batb":[[1,40,8.05]],"atb":[[40,8.05]],"atl":[[50,12.27]],"batl":[[2,50,12.27]],"id":97008932},{"batb":[[1,23,12.09]],"atb":[[23,12.09]],"atl":[[27,13.15]],"batl":[[2,27,13.15]],"id":99072900},{"batb":[[1,75,10.06]],"atb":[[75,10.06]],"id":99072901},{"batb":[[1,4.5,107.9]],"atb":[[4.5,107.9]],"atl":[[4.9,47.66]],"batl":[[2,4.9,47.66]],"id":10398159},{"batb":[[2,50,17.72]],"atb":[[50,17.72]],"atl":[[75,3.33]],"batl":[[2,75,3.33]],"id":98464183},{"batb":[[2,9.6,13.73]],"atb":[[9.6,13.73]],"atl":[[11,12.4]],"batl":[[1,11,12.4]],"id":98117699},{"batb":[[1,3.5,60.85]],"atb":[[3.5,60.85]],"atl":[[3.65,14.19],[3.7,16.6]],"batl":[[2,3.7,16.6],[1,3.65,14.19]],"id":88302242},{"batb":[[1,10,43.89]],"atb":[[10,43.89]],"atl":[[12,29.74]],"batl":[[1,12,29.74]],"id":97736949},{"batb":[],"atb":[[90,12.03]],"id":99072897}]}],"rt":639159129677200044,"dt":639159129677201454}
{"op":"mcm","id":2,"clk":"ALwnAMAUAKk0","pt":1780316168328,"mc":[{"id":"1.258742455","rc":[{"tv":640.97,"batb":[[0,60,21.84]],"trd":[[60,89.76]],"atb":[[60,21.84]],"id":98464183}],"tv":32882.13}],"rt":639159129683363423,"dt":639159129683363841}
{"op":"mcm","id":2,"clk":"AMEnAMMUALE0","pt":1780316168432,"mc":[{"id":"1.258742455","rc":[{"batb":[[2,38,13.89]],"atb":[[38,13.89]],"atl":[[55,19.43]],"batl":[],"id":97008932},{"batb":[[2,22,21.61]],"atb":[[22,21.61]],"atl":[[28,4.36]],"batl":[],"id":99072900},{"batb":[[2,70,5.38]],"atb":[[70,5.38]],"id":99072901},{"batb":[],"atb":[[48,6.38]],"atl":[[85,5.33]],"batl":[],"id":98464183}]}],"rt":639159129684401811,"dt":639159129684402310}
{"op":"mcm","id":2,"clk":"AMgnAMoUALw0","pt":1780316168532,"mc":[{"id":"1.258742455","rc":[{"batb":[[2,4.4,54.08]],"atb":[[4.4,54.08]],"atl":[[5,40.65]],"batl":[],"id":99072898},{"batb":[[2,4.4,120.91]],"atb":[[4.4,120.91]],"atl":[[5,13.22]],"batl":[],"id":10398159},{"batb":[[0,60,23.21]],"atb":[[60,23.21]],"id":98464183},{"batb":[],"atb":[[9.4,22.19]],"atl":[[11.5,6.38]],"batl":[[2,11.5,6.38]],"id":98117699},{"batb":[[2,3.45,29.77]],"atb":[[3.45,29.77]],"atl":[[3.75,46.47]],"batl":[],"id":88302242},{"batb":[[2,9.8,10.18]],"atb":[[9.8,10.18]],"atl":[[12.5,8.82]],"batl":[[2,12.5,8.82]],"id":97736949},{"batb":[],"atb":[[85,2.95]],"id":99072897}]}],"rt":639159129685406613,"dt":639159129685407248}
{"op":"mcm","id":2,"clk":"ANEnAMsUAMg0","pt":1780316168634,"mc":[{"id":"1.258742455","rc":[{"atl":[[12.5,19.05]],"batl":[[2,12.5,19.05]],"id":97736949}]}],"rt":639159129686417166,"dt":639159129686417496}
{"op":"mcm","id":2,"clk":"AOknANEUAO00","pt":1780316168896,"mc":[{"id":"1.258742455","rc":[{"batb":[[0,4.6,77.71]],"atb":[[4.6,77.71]],"atl":[[4.8,22.5]],"batl":[[1,4.8,22.5]],"id":10398159},{"batb":[[0,60,23.5]],"atb":[[60,23.5]],"id":98464183}]}],"rt":639159129689041235,"dt":639159129689041849}
{"op":"mcm","id":2,"clk":"APMnANUUAPg0","pt":1780316169001,"mc":[{"id":"1.258742455","rc":[{"batb":[],"atb":[[9.6,7.9]],"atl":[[13,10.81]],"batl":[],"id":97736949},{"batb":[],"atb":[[75,3.91]],"id":99072897}]}],"rt":639159129690093416,"dt":639159129690094025}
{"op":"mcm","id":2,"clk":"APonANgUAIM1","pt":1780316169098,"mc":[{"id":"1.258742455","rc":[{"batb":[],"atb":[[4.3,40.34]],"atl":[[5.1,9.16]],"batl":[],"id":99072898},{"batb":[],"atb":[[36,3.01]],"atl":[[60,2.6]],"batl":[],"id":97008932},{"batb":[],"atb":[[21,12.68]],"atl":[[29,9.18]],"batl":[],"id":99072900},{"batb":[],"atb":[[65,2.41]],"id":99072901},{"batb":[],"atb":[[4.3,101.66]],"atl":[[5.1,36.44]],"batl":[],"id":10398159},{"batb":[],"atb":[[46,4.3]],"atl":[[80,12.7]],"batl":[],"id":98464183},{"batb":[],"atb":[[9.2,14.28]],"atl":[[12,14.62]],"batl":[],"id":98117699},{"batb":[],"atb":[[3.4,20.39]],"atl":[[3.8,31.82]],"batl":[],"id":88302242}]}],"rt":639159129691061611,"dt":639159129691062348}
{"op":"mcm","id":2,"clk":"ALMoAI4VAN81","pt":1780316169926,"mc":[{"id":"1.258742455","rc":[{"batb":[[1,4.5,49.3]],"atb":[[4.5,49.3]],"id":99072898},{"atl":[[3.7,15.98]],"batl":[[2,3.7,15.98]],"id":88302242}]}],"rt":639159129699341871,"dt":639159129699342316}
{"op":"mcm","id":2,"clk":"ALYoAKMVAOs1","pt":1780316170030,"mc":[{"id":"1.258742455","rc":[{"atl":[[3.6,7.03]],"batl":[[0,3.6,7.03]],"id":88302242}]}],"rt":639159129700383928,"dt":639159129700384330}
{"op":"mcm","id":2,"clk":"AL4oAKYVAPU1","pt":1780316170135,"mc":[{"id":"1.258742455","rc":[{"batb":[],"atb":[[4.2,116.95]],"atl":[[5.2,5.95]],"batl":[],"id":99072898},{"batb":[],"atb":[[34,4.61]],"atl":[[65,6.21]],"batl":[],"id":97008932},{"batb":[],"atb":[[20,3.97]],"atl":[[30,2.9]],"batl":[],"id":99072900},{"batb":[],"atb":[[60,15.58]],"id":99072901},{"batb":[],"atb":[[4.2,19.29]],"atl":[[5.2,6.65]],"batl":[],"id":10398159},{"batb":[],"atb":[[44,4.4]],"atl":[[90,4.92]],"batl":[],"id":98464183},{"batb":[],"atb":[[9,20.04]],"atl":[[12.5,21.74]],"batl":[],"id":98117699},{"batb":[],"atb":[[3.35,94.89]],"atl":[[3.85,3.4]],"batl":[],"id":88302242},{"batb":[],"atb":[[9.4,8.54]],"atl":[[13.5,3.25]],"batl":[],"id":97736949},{"atb":[[70,4.78]],"id":99072897}]}],"rt":639159129701433405,"dt":639159129701434427}
{"op":"mcm","id":2,"clk":"ANcoALIVAKE2","pt":1780316170593,"mc":[{"id":"1.258742455","rc":[{"atl":[[13,15.06]],"batl":[],"id":97736949}]}],"rt":639159129706006743,"dt":639159129706007096}
{"op":"mcm","id":2,"clk":"ANwoALUVAKw2","pt":1780316170710,"mc":[{"id":"1.258742455","rc":[{"batb":[],"atb":[[4.1,56.18]],"atl":[[5.3,6]],"batl":[],"id":99072898},{"batb":[],"atb":[[4.1,39.34]],"atl":[[5.3,6.6]],"batl":[],"id":10398159},{"batb":[],"atb":[[42,4.92]],"atl":[[100,3.08]],"batl":[],"id":98464183},{"batb":[],"atb":[[3.3,6.33]],"atl":[[3.9,3.47]],"batl":[],"id":88302242},{"batb":[],"atb":[[9.2,8.09]],"atl":[[14,3.25]],"batl":[],"id":97736949},{"atb":[[65,6.3]],"id":99072897}]}],"rt":639159129707178908,"dt":639159129707179665}
{"op":"mcm","id":2,"clk":"AOAoALcVALU2","pt":1780316170800,"mc":[{"id":"1.258742455","rc":[{"batb":[],"atb":[[32,9.22]],"atl":[[70,3.76]],"batl":[],"id":97008932},{"batb":[],"atb":[[19.5,11.57]],"atl":[[32,8.36]],"batl":[],"id":99072900},{"batb":[],"atb":[[55,3.61]],"id":99072901},{"batb":[[0,60,45.5]],"atb":[[60,45.5]],"id":98464183},{"batb":[],"atb":[[8.8,5.2]],"atl":[[13,3.48]],"batl":[],"id":98117699}]}],"rt":639159129708083973,"dt":639159129708084399}
{"op":"mcm","id":2,"clk":"AOcoALgVAL82","pt":1780316170903,"mc":[{"id":"1.258742455","rc":[{"batb":[[0,60,51]],"atb":[[60,51]],"id":98464183},{"batb":[[1,9.8,30.05]],"atb":[[9.8,30.05]],"id":98117699}]}],"rt":639159129709113178,"dt":639159129709113551}
{"op":"mcm","id":2,"clk":"APUoAMMVANo2","pt":1780316171216,"mc":[{"id":"1.258742455","rc":[{"atl":[[11,16.87]],"batl":[[1,11,16.87]],"id":98117699}]}],"rt":639159129712239730,"dt":639159129712240082}
{"op":"mcm","id":2,"clk":"AIEpAMYVAOU2","pt":1780316171317,"mc":[{"id":"1.258742455","rc":[{"tv":11462.68,"batb":[[0,3.55,29.54]],"trd":[[3.55,256.16]],"ltp":3.55,"atb":[[3.55,29.54]],"id":88302242}],"tv":32962.13}],"rt":639159129713248924,"dt":639159129713249315}
{"op":"mcm","id":2,"clk":"AIQpAMoVAO42","pt":1780316171419,"mc":[{"id":"1.258742455","rc":[{"atl":[[5.4,5.9]],"batl":[],"id":99072898},{"batb":[],"atb":[[30,5.63]],"atl":[[75,4.44]],"batl":[],"id":97008932},{"atl":[[34,12.81]],"batl":[],"id":99072900},{"batb":[],"atb":[[50,21.11]],"id":99072901},{"batb":[],"atb":[[40,4.94]],"atl":[[95,5.06]],"batl":[],"id":98464183},{"batb":[],"atb":[[8.6,5.87]],"id":98117699},{"batb":[[0,3.55,18.97]],"atb":[[3.55,18.97]],"atl":[[3.95,23.41]],"batl":[],"id":88302242},{"batb":[],"atb":[[9,6.26]],"atl":[[14.5,3.21]],"batl":[],"id":97736949},{"atb":[[60,3.4]],"id":99072897}]}],"rt":639159129714275517,"dt":639159129714276183}
{"op":"mcm","id":2,"clk":"AIwpAMsVAPc2","pt":1780316171519,"mc":[{"id":"1.258742455","rc":[{"atl":[[3.6,10.88]],"batl":[[0,3.6,10.88]],"id":88302242}]}],"rt":639159129715274980,"dt":639159129715275650}
{"op":"mcm","id":2,"clk":"AJEpAM0VAP42","pt":1780316171623,"mc":[{"id":"1.258742455","rc":[{"batb":[[0,3.55,15.45]],"atb":[[3.55,15.45]],"id":88302242}]}],"rt":639159129716310627,"dt":639159129716311033}
{"op":"mcm","id":2,"clk":"AKopANYVAJc3","pt":1780316171933,"mc":[{"id":"1.258742455","rc":[{"atb":[[1.17,2.11]],"id":99072900},{"batb":[],"atb":[[4.3,115.64]],"id":10398159},{"batb":[[0,3.55,26.84]],"atb":[[3.55,26.84]],"atl":[[1000,3.34]],"id":88302242}]}],"rt":639159129719415160,"dt":639159129719415555}
{"op":"mcm","id":2,"clk":"ALApANsVAKQ3","pt":1780316172038,"mc":[{"id":"1.258742455","rc":[{"atb":[[1.17,2]],"id":99072900},{"tv":353.03,"batb":[[0,80,2.18]],"trd":[[85,34.84],[80,64.97]],"atb":[[85,0],[80,2.18]],"id":99072901},{"atl":[[1000,3]],"id":88302242},{"batb":[],"atb":[[9.6,16.19]],"id":97736949}],"tv":32964.13}],"rt":639159129720465304,"dt":639159129720465968}
{"op":"mcm","id":2,"clk":"ALIpAOEVAKw3","pt":1780316172137,"mc":[{"id":"1.258742455","rc":[{"atl":[[80,5.07]],"batl":[],"id":97008932},{"batb":[[1,23,12.2]],"atb":[[23,12.2]],"id":99072900},{"batb":[],"atb":[[48,2.59]],"id":99072901},{"batb":[[2,4.4,142.09]],"atb":[[4.4,142.09]],"id":10398159},{"batb":[],"atb":[[38,5.89]],"id":98464183},{"batb":[],"atb":[[8.4,5.44]],"id":98117699},{"batb":[[0,3.55,30.74]],"atb":[[3.55,30.74]],"atl":[[3.65,14.53]],"batl":[[1,3.65,14.53]],"id":88302242},{"batb":[],"atb":[[8.8,4.08]],"atl":[[15,3.22]],"batl":[],"id":97736949}]}],"rt":639159129721454462,"dt":639159129721455215}
{"op":"mcm","id":2,"clk":"ALkpAOcVALc3","pt":1780316172241,"mc":[{"id":"1.258742455","rc":[{"atl":[[90,0.59]],"batl":[[0,95,4.23]],"id":99072901}]}],"rt":639159129722494057,"dt":639159129722494427}
{"op":"mcm","id":2,"clk":"AL8pAPIVAME3","pt":1780316172298,"mc":[{"id":"1.258742455","rc":[{"batb":[],"atb":[[4.3,35.06]],"id":99072898}]}],"rt":639159129723060926,"dt":639159129723061441}
{"op":"mcm","id":2,"clk":"AMgpAPoVAMo3","pt":1780316172402,"mc":[{"id":"1.258742455","rc":[{"atl":[[95,3.94]],"batl":[[0,95,4.53]],"id":99072901}]}],"rt":639159129724101294,"dt":639159129724101885}
{"op":"mcm","id":2,"clk":"ANApAIIWANQ3","pt":1780316172504,"mc":[{"id":"1.258742455","rc":[{"atl":[[10.5,12.35]],"batl":[[0,10.5,12.35]],"id":98117699},{"atl":[[3.75,14.05],[3.6,7.03]],"batl":[[0,3.6,7.03]],"id":88302242}]}],"rt":639159129725122149,"dt":639159129725122590}
{"op":"mcm","id":2,"clk":"ANcpAIsWAN83","pt":1780316172610,"mc":[{"id":"1.258742455","rc":[{"batb":[[2,4.4,44.08]],"atb":[[4.4,44.08]],"id":99072898},{"atl":[[85,2.46]],"batl":[],"id":97008932},{"batb":[[0,10,16.53]],"atb":[[10,16.53]],"id":98117699}]}],"rt":639159129726177671,"dt":639159129726178108}
{"op":"mcm","id":2,"clk":"AOApAJEWAOc3","pt":1780316172713,"mc":[{"id":"1.258742455","rc":[{"tv":7245.87,"batb":[[2,4.5,49.3],[1,4.6,93.69],[0,4.7,7.81]],"trd":[[4.7,6.78]],"atb":[[4.7,7.81]],"atl":[[4.7,0]],"batl":[[2,5,40.65],[1,4.9,31.62],[0,4.8,17.33]],"id":99072898},{"batb":[],"atb":[[46,2.62]],"id":99072901},{"batb":[],"atb":[[36,5.57]],"id":98464183},{"batb":[],"atb":[[8.6,4.23]],"id":97736949}],"tv":32968.51}],"rt":639159129727211801,"dt":639159129727212657}
{"op":"mcm","id":2,"clk":"AOYpAJQWAPA3","pt":1780316172816,"mc":[{"id":"1.258742455","rc":[{"tv":7261.47,"batb":[[2,4.4,44.08],[1,4.5,49.3],[0,4.6,93.7]],"trd":[[4.7,22.38]],"atb":[[4.7,0.01]],"atl":[[4.9,27.89],[5,44.21]],"batl":[[2,5,44.21],[1,4.9,27.89]],"id":99072898},{"tv":7511.8,"batb":[[0,4.6,69.01]],"trd":[[4.6,734.09]],"atb":[[4.6,69.01]],"id":10398159},{"batb":[[0,10,18.71]],"atb":[[10,18.71]],"id":98117699},{"batb":[[1,150,3.29]],"atb":[[150,3.29]],"id":99072897}],"tv":32986.59}],"rt":639159129728242786,"dt":639159129728243661}
{"op":"mcm","id":2,"clk":"AO4pAJ0WAPo3","pt":1780316172919,"mc":[{"id":"1.258742455","rc":[{"tv":7261.49,"batb":[[0,4.6,93.69]],"trd":[[4.7,22.4]],"atb":[[4.7,0]],"atl":[[4.7,5.49],[4.9,9.57]],"batl":[[2,4.9,9.57],[1,4.8,17.33],[0,4.7,5.49]],"id":99072898},{"batb":[[0,24,11.74]],"atb":[[24,11.74]],"id":99072900},{"batb":[[0,10,11.17]],"atb":[[10,11.17]],"atl":[[11,7.67]],"batl":[[1,11,7.67]],"id":98117699},{"batb":[[0,3.55,32.74]],"atb":[[3.55,32.74]],"id":88302242},{"batb":[[1,150,5.02]],"atb":[[150,5.02]],"id":99072897}],"tv":32986.61}],"rt":639159129729274633,"dt":639159129729275512}
{"op":"mcm","id":2,"clk":"APkpAKEWAIU4","pt":1780316173022,"mc":[{"id":"1.258742455","rc":[{"batb":[[0,4.6,76.47]],"atb":[[4.6,76.47]],"id":10398159},{"batb":[[0,60,29.16]],"atb":[[60,29.16]],"id":98464183}]}],"rt":639159129730305191,"dt":639159129730305787}
{"op":"mcm","id":2,"clk":"APopAKYWAIo4","pt":1780316173127,"mc":[{"id":"1.258742455","rc":[{"batb":[[1,9.8,26.65]],"atb":[[9.8,26.65]],"id":98117699}]}],"rt":639159129731347410,"dt":639159129731347841}
{"op":"mcm","id":2,"clk":"AP4pALAWAI84","pt":1780316173235,"mc":[{"id":"1.258742455","rc":[{"batb":[],"atb":[[19,12.4]],"id":99072900},{"batb":[],"atb":[[44,2.64]],"id":99072901},{"batb":[],"atb":[[4.3,101.66]],"id":10398159}]}],"rt":639159129732428080,"dt":639159129732428546}
{"op":"mcm","id":2,"clk":"AIAqALMWAJk4","pt":1780316173331,"mc":[{"id":"1.258742455","rc":[{"batb":[],"atb":[[4.3,35.64]],"id":99072898},{"tv":1884.16,"batb":[[0,10.5,35.66]],"trd":[[10.5,10]],"atb":[[10.5,35.66]],"id":97736949}],"tv":32988.61}],"rt":639159129733388764,"dt":639159129733389524}
{"op":"mcm","id":2,"clk":"AIoqALwWAK04","pt":1780316173536,"mc":[{"id":"1.258742455","rc":[{"batb":[[0,3.55,34.74]],"atb":[[3.55,34.74]],"atl":[[3.75,35.3]],"batl":[],"id":88302242},{"batb":[],"atb":[[9.4,23.46]],"id":97736949}]}],"rt":639159129735440451,"dt":639159129735441603}
{"op":"mcm","id":2,"clk":"AJQqAMwWAMc4","pt":1780316173746,"mc":[{"id":"1.258742455","rc":[{"tv":7341.97,"trd":[[4.7,33.38],[4.9,23.54],[5,13.9],[4.8,34.66]],"ltp":5,"atl":[[4.7,0],[4.9,0],[5,37.26],[4.8,0]],"batl":[[2,5.2,5.95],[1,5.1,9.16],[0,5,37.26]],"id":99072898},{"tv":503.83,"batb":[[0,42,11.71]],"trd":[[42,62.23]],"ltp":42,"atb":[[42,11.71]],"id":97008932},{"tv":894.16,"batb":[[0,24,11.37]],"trd":[[24,88.56]],"atb":[[24,11.37]],"id":99072900},{"tv":353.14,"batb":[[0,80,2.07]],"trd":[[80,65.08]],"atb":[[80,2.07]],"id":99072901},{"tv":7513.72,"batb":[[0,4.6,74.55]],"trd":[[4.6,736.01]],"atb":[[4.6,74.55]],"id":10398159},{"tv":641.12,"batb":[[0,60,29.01]],"trd":[[60,89.91]],"atb":[[60,29.01]],"id":98464183},{"tv":2092.09,"batb":[[0,10,17.83]],"trd":[[10,475.06]],"atb":[[10,17.83]],"id":98117699},{"tv":11465.17,"batb":[[0,3.55,32.25]],"trd":[[3.55,258.65]],"atb":[[3.55,32.25]],"id":88302242},{"tv":1885,"batb":[[0,10.5,34.82]],"trd":[[10.5,10.84]],"atb":[[10.5,34.82]],"id":97736949},{"tv":167.1,"batb":[[0,1000,103.92]],"trd":[[1000,122.62]],"atb":[[1000,103.92]],"id":10445502},{"tv":218.82,"batb":[[0,160,4.66]],"trd":[[170,20]],"ltp":170,"atb":[[170,0]],"id":99072897}],"tv":33076.12}],"rt":639159129737538606,"dt":639159129737539883}
{"op":"mcm","id":2,"clk":"AJgqANEWANQ4","pt":1780316173802,"mc":[{"id":"1.258742455","rc":[{"batb":[[2,4.5,49.3],[1,4.6,93.69],[0,4.7,12.89]],"atb":[[4.7,12.89]],"id":99072898},{"batb":[[1,40,6.32]],"atb":[[40,6.32]],"id":97008932},{"atl":[[4.9,65.47]],"batl":[[2,4.9,65.47]],"id":10398159},{"batb":[],"atb":[[9.6,13.05]],"id":97736949}]}],"rt":639159129738101182,"dt":639159129738102008}
{"op":"mcm","id":2,"clk":"AJ4qANUWAN04","pt":1780316173902,"mc":[{"id":"1.258742455","rc":[{"batb":[[0,4.7,30.18]],"atb":[[4.7,30.18],[4.2,105.9]],"atl":[[4.9,17.16],[5,49.79]],"batl":[[2,5.1,9.16],[1,5,49.79],[0,4.9,17.16]],"id":99072898},{"batb":[[2,38,12.16],[0,42,10.19]],"atb":[[42,10.19],[38,12.16]],"id":97008932},{"batb":[[0,4.6,66.35]],"atb":[[4.6,66.35]],"atl":[[4.7,53.18]],"batl":[[0,4.7,53.18]],"id":10398159},{"batb":[[0,60,23.51]],"atb":[[60,23.51]],"id":98464183},{"batb":[[0,10,10.29]],"atb":[[10,10.29]],"id":98117699},{"batb":[[2,3.45,20.23]],"atb":[[3.4,30.13],[3.45,20.23]],"atl":[[3.6,11]],"batl":[[0,3.6,11]],"id":88302242},{"batb":[],"atb":[[9.4,20.25]],"id":97736949}]}],"rt":639159129739100354,"dt":639159129739101065}
{"op":"mcm","id":2,"clk":"AKQqAN4WAOc4","pt":1780316174006,"mc":[{"id":"1.258742455","rc":[{"atl":[[5.2,9.5],[5,28.17]],"batl":[[1,5,28.17]],"id":99072898},{"batb":[[2,38,13.89]],"atb":[[38,13.89]],"id":97008932},{"tv":2098.09,"batb":[[2,9.6,10.24]],"trd":[[10.5,436.53]],"ltp":10.5,"atb":[[9.6,10.24]],"atl":[[10.5,9.35]],"batl":[[0,10.5,9.35]],"id":98117699},{"atl":[[13,9.81]],"batl":[],"id":97736949}],"tv":33082.12}],"rt":639159129740140962,"dt":639159129740141472}
{"op":"mcm","id":2,"clk":"AKgqAOMWAPM4","pt":1780316174111,"mc":[{"id":"1.258742455","rc":[{"batb":[[2,4.6,93.69],[1,4.7,30.18],[0,4.8,13.72]],"atb":[[4.3,20.38],[4.8,13.72]],"id":99072898},{"batb":[[0,10,11.26]],"atb":[[10,11.26]],"atl":[[10.5,11.45]],"batl":[[0,10.5,11.45]],"id":98117699},{"batb":[[1,3.5,62.85]],"atb":[[3.5,62.85]],"id":88302242},{"atl":[[12,30.74]],"batl":[[1,12,30.74]],"id":97736949}]}],"rt":639159129741188200,"dt":639159129741188651}
{"op":"mcm","id":2,"clk":"AK4qAOkWAII5","pt":1780316174213,"mc":[{"id":"1.258742455","rc":[{"batb":[[1,4.7,37.4]],"atb":[[4.7,37.4]],"atl":[[5.2,30.61]],"batl":[],"id":99072898},{"batb":[[2,38,12.16]],"atb":[[38,12.16]],"id":97008932},{"atl":[[25,2.26]],"batl":[[0,25,2.26]],"id":99072900},{"tv":7517.52,"batb":[[0,4.6,56.99]],"trd":[[4.6,739.81]],"atb":[[4.6,56.99]],"id":10398159},{"atl":[[10.5,14.82]],"batl":[[0,10.5,14.82]],"id":98117699}],"tv":33085.92}],"rt":639159129742215339,"dt":639159129742215804}
{"op":"mcm","id":2,"clk":"ALIqAPMWAI85","pt":1780316174319,"mc":[{"id":"1.258742455","rc":[{"atl":[[5.5,45.31]],"batl":[],"id":99072898},{"batb":[],"atb":[[29,11.09]],"id":97008932},{"tv":7565.96,"batb":[[0,4.6,4.53]],"trd":[[4.6,788.25]],"atb":[[4.6,4.53]],"id":10398159},{"batb":[],"atb":[[8.2,5.79]],"id":98117699},{"batb":[[0,10.5,29.3]],"atb":[[10.5,29.3],[9.6,4.76]],"atl":[[11,5.31]],"batl":[[2,12,30.74],[1,11.5,9.12],[0,11,5.31]],"id":97736949},{"batb":[[0,160,2.68]],"atb":[[160,2.68]],"id":99072897}],"tv":33134.36}],"rt":639159129743275348,"dt":639159129743275953}
{"op":"mcm","id":2,"clk":"ALcqAPsWAJ45","pt":1780316174419,"mc":[{"id":"1.258742455","rc":[{"atl":[[5.2,27.06],[5.3,9.48],[5.5,8.09],[5.6,35.21]],"batl":[],"id":99072898},{"batb":[[2,38,13.89]],"atb":[[38,13.89]],"id":97008932},{"tv":7575.02,"batb":[[2,4.3,101.66],[1,4.4,142.09],[0,4.5,107.9]],"trd":[[4.6,797.31]],"atb":[[4.6,0]],"atl":[[4.9,69.13],[4.6,50.3]],"batl":[[2,4.8,22.5],[1,4.7,53.18],[0,4.6,50.3]],"id":10398159},{"batb":[[1,150,3.29]],"atb":[[150,3.29]],"id":99072897}],"tv":33143.42}],"rt":639159129744269004,"dt":639159129744270056}
{"op":"mcm","id":2,"clk":"ALgqAP8WAKQ5","pt":1780316174519,"mc":[{"id":"1.258742455","rc":[{"atl":[[4.7,39.86],[4.6,48.75]],"batl":[[1,4.7,39.86],[0,4.6,48.75]],"id":10398159},{"tv":644.14,"batb":[[0,60,17.51]],"trd":[[60,92.93]],"atb":[[60,17.51]],"id":98464183},{"batb":[[2,9.6,13.64]],"atb":[[9.6,13.64]],"atl":[[12.5,32.85]],"batl":[],"id":98117699},{"atl":[[3.6,7.03]],"batl":[[0,3.6,7.03]],"id":88302242}],"tv":33146.44}],"rt":639159129745277149,"dt":639159129745277753}
{"op":"mcm","id":2,"clk":"AL8qAIgXAK45","pt":1780316174626,"mc":[{"id":"1.258742455","rc":[{"atl":[[4.7,35.47]],"batl":[[1,4.7,35.47]],"id":10398159},{"batb":[[0,10.5,31.18]],"atb":[[10.5,31.18]],"id":97736949},{"batb":[[0,160,4.22]],"atb":[[160,4.22]],"id":99072897}]}],"rt":639159129746341958,"dt":639159129746342610}
{"op":"mcm","id":2,"clk":"AMIqAIwXALw5","pt":1780316174728,"mc":[{"id":"1.258742455","rc":[{"atl":[[4.9,32.34],[5,12.08]],"batl":[[1,5,12.08],[0,4.9,32.34]],"id":99072898},{"batb":[[0,10.5,31.88]],"atb":[[10.5,31.88]],"id":97736949},{"batb":[[1,150,5.02]],"atb":[[150,5.02]],"id":99072897}]}],"rt":639159129747364004,"dt":639159129747364698}
{"op":"mcm","id":2,"clk":"AMgqAJMXAMY5","pt":1780316174833,"mc":[{"id":"1.258742455","rc":[{"atl":[[5.6,39.25]],"batl":[],"id":99072898},{"batb":[],"atb":[[9.2,23.19]],"id":97736949}]}],"rt":639159129748407503,"dt":639159129748408168}
{"op":"mcm","id":2,"clk":"AM8qAKgXAOU5","pt":1780316174939,"mc":[{"id":"1.258742455","rc":[{"batb":[[2,4.5,49.3],[1,4.6,93.69],[0,4.7,37.4]],"atb":[[4.8,0]],"id":99072898}]}],"rt":639159129749475489,"dt":639159129749475854}
{"op":"mcm","id":2,"clk":"AOYqAKwXAOs5","pt":1780316175037,"mc":[{"id":"1.258742455","rc":[{"batb":[[2,4.6,92.35],[1,4.7,40.19],[0,4.8,2.9]],"atb":[[4.7,40.19],[4.6,92.35],[4.5,47.51],[4.8,2.9]],"atl":[[5.2,30.56]],"batl":[],"id":99072898},{"batb":[[0,42,10.52]],"atb":[[42,10.52]],"id":97008932},{"batb":[[0,24,11.95]],"atb":[[24,11.95]],"id":99072900},{"batb":[[0,80,2.24]],"atb":[[80,2.24]],"id":99072901},{"batb":[[0,4.5,110.99]],"atb":[[4.5,110.99]],"atl":[[4.7,36.75],[1000,1.93],[4.8,19.44]],"batl":[[2,4.8,19.44],[1,4.7,36.75]],"id":10398159},{"batb":[[0,60,18]],"atb":[[60,18]],"id":98464183},{"batb":[[0,10,12.65]],"atb":[[10,12.65]],"atl":[[10.5,12.82]],"batl":[[0,10.5,12.82]],"id":98117699},{"batb":[[2,3.45,27.23],[0,3.55,34.55]],"atb":[[3.55,34.55],[3.45,27.23]],"atl":[[1000,3.44],[3.65,14.19],[3.85,29.02]],"batl":[[1,3.65,14.19]],"id":88302242},{"batb":[[0,10.5,33.21]],"atb":[[10.5,33.21]],"id":97736949},{"batb":[[0,1000,103.93]],"atb":[[1000,103.93]],"id":10445502},{"batb":[[0,160,4.31]],"atb":[[160,4.31]],"id":99072897}]}],"rt":639159129750453585,"dt":639159129750454358}
{"op":"mcm","id":2,"clk":"AOoqAK8XAPY5","pt":1780316175140,"mc":[{"id":"1.258742455","rc":[{"batb":[[0,42,12.06]],"atb":[[42,12.06]],"id":97008932},{"batb":[[0,24,16.49]],"atb":[[24,16.49]],"id":99072900},{"atl":[[4.7,41.54],[1000,1.01]],"batl":[[1,4.7,41.54]],"id":10398159},{"batb":[[0,10,20.19]],"atb":[[10,20.19]],"atl":[[11,9.27]],"batl":[[1,11,9.27]],"id":98117699},{"batb":[[2,3.45,20.23]],"atb":[[3.45,20.23]],"atl":[[1000,3]],"id":88302242},{"tv":1885.19,"batb":[[0,10.5,38.75]],"trd":[[11,48.37]],"ltp":11,"atb":[[10.5,38.75]],"atl":[[11,5.21]],"batl":[[0,11,5.21]],"id":97736949}],"tv":33146.63}],"rt":639159129751482776,"dt":639159129751483570}
{"op":"mcm","id":2,"clk":"APMqALIXAIY6","pt":1780316175242,"mc":[{"id":"1.258742455","rc":[{"atl":[[4.6,49.67]],"batl":[[0,4.6,49.67]],"id":10398159},{"atl":[[11,12.6]],"batl":[[1,11,12.6]],"id":98117699},{"batb":[[2,3.45,22.23]],"atb":[[3.45,22.23]],"atl":[[3.6,7.47]],"batl":[[0,3.6,7.47]],"id":88302242}]}],"rt":639159129752497565,"dt":639159129752498213}
{"op":"mcm","id":2,"clk":"APYqALUXAI46","pt":1780316175345,"mc":[{"id":"1.258742455","rc":[{"atl":[[65,27.95]],"batl":[[0,65,27.95]],"id":98464183},{"batb":[[0,10,22.55]],"atb":[[10,22.55]],"atl":[[13.5,3.74]],"batl":[],"id":98117699},{"tv":1885.42,"trd":[[11,48.6]],"atl":[[11,5.1]],"batl":[[0,11,5.1]],"id":97736949}],"tv":33146.86}],"rt":639159129753535459,"dt":639159129753536119}
{"op":"mcm","id":2,"clk":"AP8qALcXAJc6","pt":1780316175404,"mc":[{"id":"1.258742455","rc":[{"tv":7347.77,"batb":[[2,4.5,47.51],[1,4.6,36.8],[0,4.7,40.19]],"trd":[[4.8,40.46]],"ltp":4.8,"atb":[[4.6,36.8],[4.8,0]],"atl":[[4.8,13.17]],"batl":[[2,5,12.08],[1,4.9,32.34],[0,4.8,13.17]],"id":99072898},{"atl":[[110,2.08]],"batl":[[2,110,2.08]],"id":99072901}],"tv":33152.66}],"rt":639159129754122892,"dt":639159129754123712}
{"op":"mcm","id":2,"clk":"AIgrALkXAKM6","pt":1780316175506,"mc":[{"id":"1.258742455","rc":[{"tv":7374.11,"trd":[[4.8,66.8]],"atl":[[4.8,0]],"batl":[[2,5.1,9.16],[1,5,12.08],[0,4.9,32.34]],"id":99072898},{"batb":[[2,3.45,29.92],[0,3.55,51.09]],"atb":[[3.55,51.09],[3.45,29.92]],"id":88302242},{"atl":[[11,0.15]],"batl":[[2,12.5,19.05],[1,12,30.74],[0,11.5,9.27]],"id":97736949}],"tv":33179}],"rt":639159129755143894,"dt":639159129755144488}
{"op":"mcm","id":2,"clk":"AI8rALsXAK46","pt":1780316175608,"mc":[{"id":"1.258742455","rc":[{"atl":[[4.6,53.67]],"batl":[[0,4.6,53.67]],"id":10398159},{"batb":[[0,3.55,61.57]],"atb":[[3.55,61.57]],"id":88302242},{"batb":[],"atb":[[9.4,23.45]],"id":97736949}]}],"rt":639159129756160449,"dt":639159129756160865}
{"op":"mcm","id":2,"clk":"AJorAL4XALk6","pt":1780316175709,"mc":[{"id":"1.258742455","rc":[{"batb":[[1,4.6,37.8]],"atb":[[4.6,37.8]],"atl":[[5.3,26.83]],"batl":[],"id":99072898},{"batb":[[0,10,23.55]],"atb":[[10,23.55]],"id":98117699}]}],"rt":639159129757172769,"dt":639159129757173165}
{"op":"mcm","id":2,"clk":"AKcrAMEXAMY6","pt":1780316175810,"mc":[{"id":"1.258742455","rc":[{"atl":[[46,4.98]],"batl":[[0,46,4.98]],"id":97008932}]}],"rt":639159129758189013,"dt":639159129758189600}
{"op":"mcm","id":2,"clk":"AMErANYXAO86","pt":1780316176014,"mc":[{"id":"1.258742455","rc":[{"batb":[[1,10,44.14]],"atb":[[10,44.14]],"id":97736949}]}],"rt":639159129760228334,"dt":639159129760228724}
{"op":"mcm","id":2,"clk":"AMgrANsXAPY6","pt":1780316176119,"mc":[{"id":"1.258742455","rc":[{"atl":[[3.6,7.99]],"batl":[[0,3.6,7.99]],"id":88302242}]}],"rt":639159129761273382,"dt":639159129761273703}
{"op":"mcm","id":2,"clk":"ANArAOAXAIE7","pt":1780316176233,"mc":[{"id":"1.258742455","rc":[{"atl":[[4.7,36.75]],"batl":[[1,4.7,36.75]],"id":10398159}]}],"rt":639159129762419597,"dt":639159129762419968}
{"op":"mcm","id":2,"clk":"ANcrAOIXAI07","pt":1780316176321,"mc":[{"id":"1.258742455","rc":[{"batb":[[0,80,3.37]],"atb":[[80,3.37]],"id":99072901}]}],"rt":639159129763297977,"dt":639159129763298639}
