{"op":"mcm","id":2,"clk":"AK\u002BNAQDIWwCOtQE=","pt":1780316361237,"mc":[{"id":"1.258742455","rc":[{"batb":[[0,85,7.31]],"atb":[[90,0.26]],"atl":[[95,1.34]],"batl":[[0,95,1.34]],"id":99072901},{"atl":[[200,4.13]],"batl":[[1,220,1.88],[0,200,4.25]],"id":99072897}]}],"rt":639159131612449735,"dt":639159131612450201}
{"op":"mcm","id":2,"clk":"ALSNAQDNWwCWtQE=","pt":1780316361335,"mc":[{"id":"1.258742455","rc":[{"atb":[[1.01,67425.51]],"id":10398159},{"atb":[[1.01,78395.23]],"id":98117699},{"atb":[[1.01,58220.82]],"id":88302242},{"batb":[[2,160,4.74]],"atb":[[160,4.74]],"atl":[[190,0.21],[270,0]],"batl":[[0,200,4.34]],"id":99072897}]}],"rt":639159131613434963,"dt":639159131613435453}
{"op":"mcm","id":2,"clk":"ALiNAQDRWwCctQE=","pt":1780316361438,"mc":[{"id":"1.258742455","rc":[{"atl":[[5.2,31.45]],"batl":[],"id":99072898},{"batb":[[0,180,1.96]],"atb":[[180,1.96]],"id":99072897}]}],"rt":639159131614462587,"dt":639159131614463383}
{"op":"mcm","id":2,"clk":"AL6NAQDVWwCktQE=","pt":1780316361544,"mc":[{"id":"1.258742455","rc":[{"batb":[],"atb":[[150,3.87]],"id":99072897}]}],"rt":639159131615519570,"dt":639159131615519912}
{"op":"mcm","id":2,"clk":"AMGNAQDZWwCstQE=","pt":1780316361642,"mc":[{"id":"1.258742455","rc":[{"atl":[[190,0.39]],"batl":[[0,200,4.52]],"id":99072897}]}],"rt":639159131616499222,"dt":639159131616499547}
{"op":"mcm","id":2,"clk":"AM6NAQDjWwC9tQE=","pt":1780316361853,"mc":[{"id":"1.258742455","rc":[{"batb":[[0,10.5,6.34]],"atb":[[10.5,6.34]],"id":97736949}]}],"rt":639159131618612841,"dt":639159131618613192}
{"op":"mcm","id":2,"clk":"ANWNAQDoWwDFtQE=","pt":1780316361963,"mc":[{"id":"1.258742455","rc":[{"atb":[[3,10.35]],"id":99072898},{"atl":[[9.8,10.07]],"batl":[[2,9.8,10.07]],"id":98117699},{"batb":[[0,10.5,11.88]],"atb":[[10.5,11.88]],"id":97736949},{"batb":[[2,150,3.87],[1,160,4.74],[0,170,3.5]],"atb":[[180,0.29]],"id":99072897}]}],"rt":639159131619717353,"dt":639159131619717898}
{"op":"mcm","id":2,"clk":"AOGNAQDvWwDZtQE=","pt":1780316362172,"mc":[{"id":"1.258742455","rc":[{"tv":8018.77,"trd":[[4.9,272.31]],"ltp":4.9,"atl":[[4.9,23.72]],"batl":[[0,4.9,23.72]],"id":99072898},{"atl":[[190,0.53]],"batl":[[0,200,4.66]],"id":99072897}],"tv":38014.89}],"rt":639159131621804815,"dt":639159131621805348}
{"op":"mcm","id":2,"clk":"AOiNAQDwWwDftQE=","pt":1780316362271,"mc":[{"id":"1.258742455","rc":[{"atl":[[4.9,15.5]],"batl":[[0,4.9,15.5]],"id":99072898},{"atl":[[5.1,49.88]],"batl":[],"id":10398159},{"atl":[[500,0]],"id":98464183},{"batb":[],"atb":[[8.2,11.79],[8,54.4]],"id":98117699},{"atl":[[4.1,11.54],[4,7.82]],"batl":[],"id":88302242},{"batb":[[0,10.5,18.99]],"atb":[[9.4,15.62],[10.5,18.99],[9.6,13.3]],"id":97736949}]}],"rt":639159131622791531,"dt":639159131622792106}
{"op":"mcm","id":2,"clk":"AO2NAQD1WwDntQE=","pt":1780316362368,"mc":[{"id":"1.258742455","rc":[{"batb":[[1,46,9.64]],"atb":[[46,9.64]],"id":97008932}]}],"rt":639159131623759827,"dt":639159131623760248}
{"op":"mcm","id":2,"clk":"APeNAQD7WwDxtQE=","pt":1780316362474,"mc":[{"id":"1.258742455","rc":[{"atl":[[4.9,14.14]],"batl":[[0,4.9,14.14]],"id":99072898},{"batb":[[0,48,3.56]],"atb":[[48,3.56]],"id":97008932},{"atl":[[11,2.86]],"batl":[[0,11,2.86]],"id":97736949}]}],"rt":639159131624824493,"dt":639159131624824997}
{"op":"mcm","id":2,"clk":"APyNAQD\u002BWwD6tQE=","pt":1780316362581,"mc":[{"id":"1.258742455","rc":[{"batb":[[0,4.8,41.25]],"atb":[[4.8,41.25]],"id":99072898},{"atl":[[9.6,12.92]],"batl":[[1,9.6,12.92]],"id":98117699},{"batb":[[0,10.5,19.67]],"atb":[[10.5,19.67]],"atl":[[11,2.36]],"batl":[[0,11,2.36]],"id":97736949}]}],"rt":639159131625894233,"dt":639159131625894653}
{"op":"mcm","id":2,"clk":"AIOOAQCCXACFtgE=","pt":1780316362681,"mc":[{"id":"1.258742455","rc":[{"batb":[[0,48,3.63]],"atb":[[48,3.63]],"id":97008932},{"atl":[[9.4,14.83]],"batl":[[0,9.4,14.83]],"id":98117699}]}],"rt":639159131626892234,"dt":639159131626892723}
{"op":"mcm","id":2,"clk":"AJGOAQCGXACRtgE=","pt":1780316362878,"mc":[{"id":"1.258742455","rc":[{"atl":[[60,6.74]],"batl":[[1,60,6.74]],"id":98464183},{"tv":13233.71,"batb":[[0,3.55,10.05]],"trd":[[3.55,700.28]],"atb":[[3.55,10.05]],"id":88302242}],"tv":38024.89}],"rt":639159131628860542,"dt":639159131628860962}
{"op":"mcm","id":2,"clk":"AJiOAQCHXACdtgE=","pt":1780316362977,"mc":[{"id":"1.258742455","rc":[{"atl":[[4.9,14.3]],"batl":[[0,4.9,14.3]],"id":99072898}]}],"rt":639159131629855404,"dt":639159131629855774}
{"op":"mcm","id":2,"clk":"AKKOAQCMXACktgE=","pt":1780316363083,"mc":[{"id":"1.258742455","rc":[{"atl":[[4.9,14.14]],"batl":[[0,4.9,14.14]],"id":99072898},{"batb":[[0,48,3.71]],"atb":[[48,3.71]],"atl":[[75,18.48]],"batl":[],"id":97008932},{"batb":[[0,3.55,5.18]],"atb":[[3.55,5.18]],"id":88302242}]}],"rt":639159131630912559,"dt":639159131630913008}
{"op":"mcm","id":2,"clk":"AKyOAQCTXAC2tgE=","pt":1780316363285,"mc":[{"id":"1.258742455","rc":[{"batb":[[0,3.55,5.91]],"atb":[[3.55,5.91]],"id":88302242}]}],"rt":639159131632935213,"dt":639159131632935604}
{"op":"mcm","id":2,"clk":"ALOOAQCTXADCtgE=","pt":1780316363344,"mc":[{"id":"1.258742455","rc":[{"batb":[],"atb":[[4,27.07]],"id":10398159},{"atb":[[1.17,2.6]],"id":97736949}]}],"rt":639159131633519874,"dt":639159131633520230}
{"op":"mcm","id":2,"clk":"ALiOAQCZXADHtgE=","pt":1780316363445,"mc":[{"id":"1.258742455","rc":[{"tv":8021.89,"trd":[[4.9,275.43]],"atl":[[4.9,12.58]],"batl":[[0,4.9,12.58]],"id":99072898},{"batb":[[0,3.55,7.46]],"atb":[[3.55,7.46]],"id":88302242},{"atb":[[1.17,2]],"id":97736949}],"tv":38028.01}],"rt":639159131634533431,"dt":639159131634533877}
{"op":"mcm","id":2,"clk":"AL2OAQCcXADOtgE=","pt":1780316363544,"mc":[{"id":"1.258742455","rc":[{"atl":[[120,3.45]],"batl":[],"id":99072901},{"tv":896.02,"trd":[[55,99.28]],"ltp":55,"atl":[[55,5.41]],"batl":[[0,55,5.41]],"id":98464183},{"batb":[[0,10.5,20.27]],"atb":[[10.5,20.27]],"id":97736949}],"tv":38038.67}],"rt":639159131635522388,"dt":639159131635522883}
{"op":"mcm","id":2,"clk":"ANGOAQCmXADbtgE=","pt":1780316363749,"mc":[{"id":"1.258742455","rc":[{"batb":[[0,4.7,36.43]],"atb":[[4.7,36.43]],"id":10398159},{"atl":[[55,2.75],[70,10.17]],"batl":[[0,55,2.75]],"id":98464183}]}],"rt":639159131637571552,"dt":639159131637571916}
{"op":"mcm","id":2,"clk":"ANiOAQCqXADjtgE=","pt":1780316363849,"mc":[{"id":"1.258742455","rc":[{"batb":[[0,48,4.52]],"atb":[[48,4.52]],"atl":[[1000,0.39]],"id":97008932},{"atb":[[1.17,2.1]],"id":99072900},{"atb":[[1.17,1.1]],"id":99072901},{"batb":[[0,50,11.99]],"atb":[[50,11.99]],"atl":[[55,2.94]],"batl":[[0,55,2.94]],"id":98464183},{"atb":[[1.17,196.61]],"id":88302242}]}],"rt":639159131638570560,"dt":639159131638570995}
{"op":"mcm","id":2,"clk":"AN6OAQCxXADstgE=","pt":1780316363958,"mc":[{"id":"1.258742455","rc":[{"atl":[[1000,0.22]],"id":97008932},{"atb":[[1.17,2]],"id":99072900},{"atb":[[1.17,196.12]],"id":88302242}]}],"rt":639159131639660460,"dt":639159131639660835}
{"op":"mcm","id":2,"clk":"AOOOAQC1XAD0tgE=","pt":1780316364064,"mc":[{"id":"1.258742455","rc":[{"atl":[[55,23.23]],"batl":[[1,55,23.23]],"id":97008932},{"batb":[[0,21,8.94]],"atb":[[21,8.94]],"id":99072900},{"atb":[[1.17,1]],"id":99072901},{"atl":[[55,4.27]],"batl":[[0,55,4.27]],"id":98464183},{"batb":[[0,3.55,7.95]],"atb":[[3.55,7.95]],"id":88302242}]}],"rt":639159131640718318,"dt":639159131640718841}
{"op":"mcm","id":2,"clk":"AOqOAQC4XAD5tgE=","pt":1780316364155,"mc":[{"id":"1.258742455","rc":[{"batb":[[0,85,7.41]],"atb":[[90,0.36]],"id":99072901}]}],"rt":639159131641628956,"dt":639159131641629333}
{"op":"mcm","id":2,"clk":"AO2OAQC9XACBtwE=","pt":1780316364269,"mc":[{"id":"1.258742455","rc":[{"atb":[[15,11.19]],"id":97008932},{"atb":[[15,2.25]],"id":99072900}]}],"rt":639159131642767731,"dt":639159131642768069}
{"op":"mcm","id":2,"clk":"APOOAQC\u002BXACKtwE=","pt":1780316364372,"mc":[{"id":"1.258742455","rc":[{"tv":13242.36,"batb":[[0,3.55,3.63]],"trd":[[3.55,708.93]],"atb":[[3.55,3.63]],"id":88302242}],"tv":38047.32}],"rt":639159131643798194,"dt":639159131643798575}
{"op":"mcm","id":2,"clk":"APuOAQDDXACVtwE=","pt":1780316364467,"mc":[{"id":"1.258742455","rc":[{"atl":[[5,23.05],[5.1,41.18]],"batl":[[2,5.1,41.18],[1,5,23.05]],"id":99072898},{"atl":[[4.8,63.68]],"batl":[[0,4.8,63.68]],"id":10398159},{"batb":[[0,9,26.79]],"atb":[[9,26.79]],"id":98117699},{"atl":[[3.65,44.17]],"batl":[[1,3.65,44.17]],"id":88302242}]}],"rt":639159131644747863,"dt":639159131644748371}
{"op":"mcm","id":2,"clk":"AIaPAQDHXACatwE=","pt":1780316364572,"mc":[{"id":"1.258742455","rc":[{"atl":[[70,12.81]],"batl":[],"id":98464183},{"batb":[[0,3.55,1.35]],"atb":[[3.55,1.35]],"id":88302242}]}],"rt":639159131645801443,"dt":639159131645801901}
{"op":"mcm","id":2,"clk":"AJuPAQDTXAC0twE=","pt":1780316364879,"mc":[{"id":"1.258742455","rc":[{"batb":[[0,3.55,1.72]],"atb":[[3.55,1.72]],"id":88302242}]}],"rt":639159131648873901,"dt":639159131648874273}
{"op":"mcm","id":2,"clk":"AKWPAQDaXAC8twE=","pt":1780316364988,"mc":[{"id":"1.258742455","rc":[{"batb":[[0,48,4.7]],"atb":[[48,4.7]],"atl":[[50,11.51]],"batl":[[0,50,11.51]],"id":97008932},{"atl":[[4.8,65.68]],"batl":[[0,4.8,65.68]],"id":10398159}]}],"rt":639159131649957399,"dt":639159131649957832}
{"op":"mcm","id":2,"clk":"ALGPAQDfXADKtwE=","pt":1780316365187,"mc":[{"id":"1.258742455","rc":[{"atl":[[50,11.55],[85,2.94]],"batl":[[0,50,11.55]],"id":97008932}]}],"rt":639159131651947693,"dt":639159131651948072}
{"op":"mcm","id":2,"clk":"ALWPAQDmXADTtwE=","pt":1780316365249,"mc":[{"id":"1.258742455","rc":[{"batb":[[0,3.55,1.35]],"atb":[[3.55,1.35]],"id":88302242}]}],"rt":639159131652575722,"dt":639159131652576089}
{"op":"mcm","id":2,"clk":"ALqPAQDqXADctwE=","pt":1780316365346,"mc":[{"id":"1.258742455","rc":[{"atb":[[15,3.25]],"id":99072900}]}],"rt":639159131653544813,"dt":639159131653545145}
{"op":"mcm","id":2,"clk":"AMSPAQDyXADitwE=","pt":1780316365496,"mc":[{"id":"1.258742455","rc":[{"batb":[[0,3.55,1.7]],"atb":[[3.55,1.7]],"id":88302242}]}],"rt":639159131655045051,"dt":639159131655045464}
{"op":"mcm","id":2,"clk":"AMmPAQD\u002BXADwtwE=","pt":1780316365655,"mc":[{"id":"1.258742455","rc":[{"atb":[[15,5.77]],"id":99072900},{"batb":[[0,85,7.33]],"atb":[[90,0.28]],"id":99072901},{"batb":[],"atb":[[7.6,124.31]],"id":98117699}]}],"rt":639159131656634595,"dt":639159131656634955}
{"op":"mcm","id":2,"clk":"AM2PAQCEXQD4twE=","pt":1780316365763,"mc":[{"id":"1.258742455","rc":[{"tv":13244.36,"batb":[[2,3.4,58.52],[1,3.45,76.63],[0,3.5,77.61]],"trd":[[3.55,710.93]],"atb":[[3.55,0.7]],"id":88302242}],"tv":38049.32}],"rt":639159131657707978,"dt":639159131657708368}
{"op":"mcm","id":2,"clk":"ANaPAQCIXQD\u002BtwE=","pt":1780316365866,"mc":[{"id":"1.258742455","rc":[{"batb":[[2,44,9.39]],"atb":[[44,9.39]],"id":97008932},{"atl":[[3.6,31.16]],"batl":[[0,3.6,31.16]],"id":88302242}]}],"rt":639159131658739142,"dt":639159131658739532}
{"op":"mcm","id":2,"clk":"AN6PAQCKXQCDuAE=","pt":1780316365962,"mc":[{"id":"1.258742455","rc":[{"batb":[[0,3.5,77.26]],"atb":[[3.55,0.35]],"atl":[[3.6,34.17]],"batl":[[0,3.6,34.17]],"id":88302242}]}],"rt":639159131659698643,"dt":639159131659699077}
{"op":"mcm","id":2,"clk":"AOSPAQCPXQCIuAE=","pt":1780316366066,"mc":[{"id":"1.258742455","rc":[{"batb":[[1,4.7,47.06]],"atb":[[4.7,47.06]],"id":99072898},{"batb":[[2,3.4,80.52]],"atb":[[3.4,80.52]],"id":88302242}]}],"rt":639159131660742765,"dt":639159131660743420}
{"op":"mcm","id":2,"clk":"AOiPAQCTXQCNuAE=","pt":1780316366165,"mc":[{"id":"1.258742455","rc":[{"tv":1124.51,"batb":[[0,21,7.44]],"trd":[[21,115]],"ltp":21,"atb":[[21,7.44]],"id":99072900},{"batb":[],"atb":[[3.35,145.04]],"id":88302242},{"batb":[],"atb":[[9.4,17.31]],"id":97736949}],"tv":38052.32}],"rt":639159131661731390,"dt":639159131661731914}
{"op":"mcm","id":2,"clk":"AOyPAQCZXQCYuAE=","pt":1780316366271,"mc":[{"id":"1.258742455","rc":[{"batb":[[0,4.8,48.75]],"atb":[[4.8,48.75]],"id":99072898},{"atl":[[95,1.42]],"batl":[[0,95,1.42]],"id":99072901}]}],"rt":639159131662792777,"dt":639159131662793159}
{"op":"mcm","id":2,"clk":"AO\u002BPAQCeXQCguAE=","pt":1780316366372,"mc":[{"id":"1.258742455","rc":[{"batb":[[0,21,9.06]],"atb":[[21,9.06]],"atl":[[22,0.23]],"batl":[[0,23,8.26]],"id":99072900},{"tv":390.27,"batb":[[2,80,8.83],[1,85,7.33],[0,95,1.24]],"trd":[[95,34.46]],"ltp":95,"atb":[[95,1.24]],"atl":[[95,0]],"batl":[[2,120,3.45],[1,110,6.21],[0,100,1.17]],"id":99072901},{"batb":[],"atb":[[3.3,26.21]],"id":88302242}],"tv":38055.16}],"rt":639159131663796790,"dt":639159131663797254}
{"op":"mcm","id":2,"clk":"APuPAQCnXQCvuAE=","pt":1780316366576,"mc":[{"id":"1.258742455","rc":[{"batb":[[0,48,4.86]],"atb":[[48,4.86]],"id":97008932},{"batb":[[2,80,9.18],[1,85,7.57]],"atb":[[90,0.52],[80,9.18],[75,6.88]],"atl":[[120,1.83],[100,0.45]],"batl":[[2,130,1.62],[1,120,1.83],[0,110,6.66]],"id":99072901}]}],"rt":639159131665836548,"dt":639159131665837054}
{"op":"mcm","id":2,"clk":"AP6PAQCpXQC1uAE=","pt":1780316366677,"mc":[{"id":"1.258742455","rc":[{"atl":[[130,2.65]],"batl":[[2,130,2.65]],"id":99072901},{"batb":[[0,4.7,34.95]],"atb":[[4.7,34.95]],"id":10398159}]}],"rt":639159131666848939,"dt":639159131666849413}
{"op":"mcm","id":2,"clk":"AIaQAQCuXQC9uAE=","pt":1780316366777,"mc":[{"id":"1.258742455","rc":[{"batb":[[2,85,7.98],[1,90,2.49],[0,95,2.97]],"atb":[[95,2.97],[90,2.49],[85,7.98]],"atl":[[100,0.26]],"batl":[[0,110,6.47]],"id":99072901}]}],"rt":639159131667856152,"dt":639159131667856620}
{"op":"mcm","id":2,"clk":"AI2QAQCzXQDEuAE=","pt":1780316366884,"mc":[{"id":"1.258742455","rc":[{"batb":[],"atb":[[140,1]],"id":10445502}]}],"rt":639159131668923350,"dt":639159131668923753}
{"op":"mcm","id":2,"clk":"AI\u002BQAQC6XQDPuAE=","pt":1780316366985,"mc":[{"id":"1.258742455","rc":[{"batb":[[2,85,7],[0,95,3.89]],"atb":[[95,3.89],[85,7]],"atl":[[100,0]],"batl":[[0,110,6.21]],"id":99072901}]}],"rt":639159131669926472,"dt":639159131669926846}
{"op":"mcm","id":2,"clk":"AJqQAQC9XQDYuAE=","pt":1780316367088,"mc":[{"id":"1.258742455","rc":[{"batb":[[0,95,4.1]],"atb":[[95,4.1]],"id":99072901}]}],"rt":639159131670968649,"dt":639159131670969079}
{"op":"mcm","id":2,"clk":"AKKQAQDCXQDluAE=","pt":1780316367189,"mc":[{"id":"1.258742455","rc":[{"batb":[],"atb":[[70,5.77]],"atl":[[130,1.62]],"batl":[[2,130,1.62]],"id":99072901}]}],"rt":639159131671974692,"dt":639159131671975143}
{"op":"mcm","id":2,"clk":"AKiQAQDGXQDquAE=","pt":1780316367244,"mc":[{"id":"1.258742455","rc":[{"atl":[[4.9,9.36]],"batl":[[0,4.9,9.36]],"id":99072898},{"batb":[[0,21,10.56]],"atb":[[21,10.56]],"id":99072900},{"batb":[[1,90,2.39],[0,95,4.3]],"atb":[[95,4.3],[90,2.39]],"id":99072901},{"batb":[[0,4.7,35.46]],"atb":[[4.7,35.46]],"atl":[[4.9,57.26]],"batl":[[1,4.9,57.26]],"id":10398159},{"atl":[[1000,3.21]],"id":88302242}]}],"rt":639159131672524080,"dt":639159131672524677}
{"op":"mcm","id":2,"clk":"ALSQAQDJXQD2uAE=","pt":1780316367350,"mc":[{"id":"1.258742455","rc":[{"tv":8040.61,"batb":[[2,4.7,47.06],[1,4.8,48.75],[0,4.9,8.33]],"trd":[[4.9,294.15]],"atb":[[4.9,8.33]],"atl":[[4.9,0]],"batl":[[2,5.2,31.45],[1,5.1,41.18],[0,5,23.05]],"id":99072898},{"batb":[[0,95,4.78]],"atb":[[100,0.11],[95,4.67]],"id":99072901}],"tv":38073.88}],"rt":639159131673593076,"dt":639159131673593680}
{"op":"mcm","id":2,"clk":"ALyQAQDNXQCEuQE=","pt":1780316367453,"mc":[{"id":"1.258742455","rc":[{"batb":[[0,4.9,24.94]],"atb":[[4.9,24.94]],"atl":[[5.1,38.42]],"batl":[[1,5.1,38.42]],"id":99072898},{"atl":[[1000,3]],"id":88302242}]}],"rt":639159131674614285,"dt":639159131674614730}
{"op":"mcm","id":2,"clk":"AMGQAQDTXQCQuQE=","pt":1780316367561,"mc":[{"id":"1.258742455","rc":[{"batb":[[1,4.8,51.76],[0,4.9,25.1]],"atb":[[4.9,25.1],[4.8,51.76]],"atl":[[5.2,22.46],[5.1,41.13]],"batl":[[2,5.2,22.46],[1,5.1,41.13]],"id":99072898},{"atl":[[50,11.59]],"batl":[[0,50,11.59]],"id":97008932},{"atl":[[22,1.81]],"batl":[[2,24,6.04],[1,23,8.03],[0,22,1.81]],"id":99072900},{"batb":[[0,95,4.67]],"atb":[[100,0]],"id":99072901},{"atl":[[9.2,0.08]],"batl":[[0,9.4,14.91]],"id":98117699},{"atl":[[3.6,34.38]],"batl":[[0,3.6,34.38]],"id":88302242}]}],"rt":639159131675697321,"dt":639159131675697833}
{"op":"mcm","id":2,"clk":"AMiQAQDYXQCZuQE=","pt":1780316367658,"mc":[{"id":"1.258742455","rc":[{"atl":[[5,17.62]],"batl":[[0,5,17.62]],"id":99072898},{"atl":[[140,0.28]],"batl":[],"id":99072901},{"batb":[[0,4.7,34.29]],"atb":[[4.7,34.29]],"id":10398159},{"atl":[[55,4.9]],"batl":[[0,55,4.9]],"id":98464183}]}],"rt":639159131676670585,"dt":639159131676671009}
{"op":"mcm","id":2,"clk":"ANOQAQDiXQCjuQE=","pt":1780316367766,"mc":[{"id":"1.258742455","rc":[{"batb":[[0,4.9,28.75]],"atb":[[4.4,14.84],[4.9,28.75]],"atl":[[5.3,12.64]],"batl":[],"id":99072898},{"atl":[[23,4.35],[22,5.79]],"batl":[[1,23,4.35],[0,22,5.79]],"id":99072900},{"batb":[[0,4.7,35.99]],"atb":[[4.7,35.99]],"id":10398159},{"batb":[[0,9,26.32]],"atb":[[9,26.32]],"atl":[[9.2,0.72]],"batl":[[0,9.4,15.55]],"id":98117699},{"batb":[[0,3.5,78.71]],"atb":[[3.5,78.36]],"id":88302242}]}],"rt":639159131677741912,"dt":639159131677742407}
{"op":"mcm","id":2,"clk":"ANmQAQDoXQCtuQE=","pt":1780316367866,"mc":[{"id":"1.258742455","rc":[{"batb":[],"atb":[[80,9.74]],"id":99072901}]}],"rt":639159131678742984,"dt":639159131678743410}
{"op":"mcm","id":2,"clk":"AN\u002BQAQDsXQC2uQE=","pt":1780316367969,"mc":[{"id":"1.258742455","rc":[{"batb":[[0,4.9,34.09]],"atb":[[4.9,34.09],[4.5,39.3]],"atl":[[5.4,32.52]],"batl":[],"id":99072898},{"batb":[[1,46,11.73]],"atb":[[46,11.73]],"id":97008932},{"atl":[[160,1.88]],"batl":[],"id":99072901},{"batb":[[0,4.7,36.65]],"atb":[[4.7,36.65]],"id":10398159},{"atl":[[10.5,14.74]],"batl":[],"id":98117699}]}],"rt":639159131679771176,"dt":639159131679771763}
{"op":"mcm","id":2,"clk":"AOKQAQDwXQDDuQE=","pt":1780316368069,"mc":[{"id":"1.258742455","rc":[{"atl":[[5,19.07]],"batl":[[0,5,19.07]],"id":99072898},{"atl":[[22,6.1]],"batl":[[0,22,6.1]],"id":99072900},{"batb":[[0,95,4.68]],"atb":[[100,0.01]],"id":99072901},{"batb":[[0,9,26.63]],"atb":[[9,26.63]],"id":98117699},{"tv":2503.16,"trd":[[11,97.61]],"ltp":11,"atl":[[11,1.05]],"batl":[[0,11,1.05]],"id":97736949}],"tv":38076.5}],"rt":639159131680771894,"dt":639159131680772418}
{"op":"mcm","id":2,"clk":"AOqQAQD0XQDOuQE=","pt":1780316368179,"mc":[{"id":"1.258742455","rc":[{"batb":[[0,21,10.18]],"atb":[[21,10.18]],"id":99072900}]}],"rt":639159131681878105,"dt":639159131681878568}
{"op":"mcm","id":2,"clk":"APCQAQD4XQDVuQE=","pt":1780316368274,"mc":[{"id":"1.258742455","rc":[{"batb":[[0,95,3.44]],"atb":[[95,3.43]],"id":99072901},{"batb":[[0,4.7,35.99]],"atb":[[4.7,35.99]],"id":10398159},{"atl":[[11,7.12]],"batl":[[0,11,7.12]],"id":97736949}]}],"rt":639159131682824569,"dt":639159131682825070}
{"op":"mcm","id":2,"clk":"APSQAQD8XQDbuQE=","pt":1780316368376,"mc":[{"id":"1.258742455","rc":[{"batb":[[0,95,3.48]],"atb":[[100,0.05]],"id":99072901},{"batb":[],"atb":[[9.6,14.97]],"id":97736949}]}],"rt":639159131683838105,"dt":639159131683838554}
{"op":"mcm","id":2,"clk":"APuQAQCGXgDkuQE=","pt":1780316368475,"mc":[{"id":"1.258742455","rc":[{"batb":[[0,4.9,50.58]],"atb":[[4.9,50.58]],"id":99072898},{"batb":[[0,10.5,20.98]],"atb":[[10.5,20.98]],"id":97736949}]}],"rt":639159131684832285,"dt":639159131684832771}
{"op":"mcm","id":2,"clk":"AIORAQCMXgDsuQE=","pt":1780316368580,"mc":[{"id":"1.258742455","rc":[{"batb":[[0,95,3.43]],"atb":[[100,0]],"id":99072901},{"atl":[[4.9,56.19]],"batl":[[1,4.9,56.19]],"id":10398159},{"tv":2503.54,"trd":[[11,97.99]],"atl":[[11,6.93]],"batl":[[0,11,6.93]],"id":97736949}],"tv":38076.88}],"rt":639159131685877686,"dt":639159131685878159}
{"op":"mcm","id":2,"clk":"AIqRAQCNXgD4uQE=","pt":1780316368683,"mc":[{"id":"1.258742455","rc":[{"batb":[[0,4.9,52.06]],"atb":[[4.9,52.06]],"atl":[[5.4,36.41],[5,12.89]],"batl":[[0,5,12.89]],"id":99072898},{"atl":[[4.9,55.13]],"batl":[[1,4.9,55.13]],"id":10398159}]}],"rt":639159131686913866,"dt":639159131686914337}
{"op":"mcm","id":2,"clk":"AI\u002BRAQCSXgD/uQE=","pt":1780316368785,"mc":[{"id":"1.258742455","rc":[{"atl":[[4.8,69.14]],"batl":[[0,4.8,69.14]],"id":10398159},{"atl":[[3.6,39.57]],"batl":[[0,3.6,39.57]],"id":88302242}]}],"rt":639159131687935796,"dt":639159131687936231}
{"op":"mcm","id":2,"clk":"AJSRAQCWXgCJugE=","pt":1780316368887,"mc":[{"id":"1.258742455","rc":[{"atl":[[5.1,38.42]],"batl":[[1,5.1,38.42]],"id":99072898},{"batb":[],"atb":[[9.2,21.56]],"id":97736949}]}],"rt":639159131688955431,"dt":639159131688955886}
{"op":"mcm","id":2,"clk":"AJ\u002BRAQCeXgCYugE=","pt":1780316369050,"mc":[{"id":"1.258742455","rc":[{"batb":[[0,10.5,23]],"atb":[[10.5,23]],"id":97736949}]}],"rt":639159131690583861,"dt":639159131690584328}
{"op":"mcm","id":2,"clk":"AKWRAQCiXgCjugE=","pt":1780316369151,"mc":[{"id":"1.258742455","rc":[{"tv":556.11,"batb":[[0,48,3.13]],"trd":[[48,53.82]],"atb":[[48,3.13]],"id":97008932}],"tv":38080.34}],"rt":639159131691591662,"dt":639159131691592143}
{"op":"mcm","id":2,"clk":"AKmRAQCkXgCsugE=","pt":1780316369265,"mc":[{"id":"1.258742455","rc":[{"atl":[[5,13.03]],"batl":[[0,5,13.03]],"id":99072898},{"tv":2504.32,"trd":[[11,98.77]],"atl":[[11,6.54]],"batl":[[0,11,6.54]],"id":97736949}],"tv":38081.12}],"rt":639159131692736296,"dt":639159131692736802}
{"op":"mcm","id":2,"clk":"AK\u002BRAQCqXgC1ugE=","pt":1780316369357,"mc":[{"id":"1.258742455","rc":[{"batb":[[0,48,2.64]],"atb":[[48,2.64]],"atl":[[50,12.03]],"batl":[[0,50,12.03]],"id":97008932}]}],"rt":639159131693650009,"dt":639159131693650441}
{"op":"mcm","id":2,"clk":"ALmRAQCvXgDBugE=","pt":1780316369459,"mc":[{"id":"1.258742455","rc":[{"batb":[[0,48,1.01]],"atb":[[48,1.01]],"id":97008932},{"atl":[[11,6.91]],"batl":[[0,11,6.91]],"id":97736949}]}],"rt":639159131694667231,"dt":639159131694667716}
{"op":"mcm","id":2,"clk":"AMORAQCyXgDHugE=","pt":1780316369560,"mc":[{"id":"1.258742455","rc":[{"batb":[[2,44,7.66]],"atb":[[44,7.66]],"id":97008932},{"batb":[[1,90,6.14]],"atb":[[90,6.14],[80,6.8]],"id":99072901},{"batb":[],"atb":[[680,2.18],[700,1.29]],"id":10445502}]}],"rt":639159131695681801,"dt":639159131695682361}
{"op":"mcm","id":2,"clk":"AMiRAQC6XgDLugE=","pt":1780316369660,"mc":[{"id":"1.258742455","rc":[{"batb":[[0,4.7,36.48]],"atb":[[4.7,36.48]],"id":10398159}]}],"rt":639159131696682744,"dt":639159131696683108}
{"op":"mcm","id":2,"clk":"ANeRAQC/XgDXugE=","pt":1780316369861,"mc":[{"id":"1.258742455","rc":[{"batb":[[0,4.7,35.99]],"atb":[[4.7,35.99]],"id":10398159}]}],"rt":639159131698691086,"dt":639159131698691431}
{"op":"mcm","id":2,"clk":"AOuRAQDVXgD6ugE=","pt":1780316370281,"mc":[{"id":"1.258742455","rc":[{"tv":8050.55,"trd":[[5,211.82]],"ltp":5,"atl":[[5,8.06]],"batl":[[0,5,8.06]],"id":99072898},{"batb":[[0,4.7,37.02]],"atb":[[4.7,37.02]],"id":10398159},{"batb":[[0,9,29.1]],"atb":[[9,29.1]],"id":98117699}],"tv":38091.06}],"rt":639159131702892208,"dt":639159131702892694}
{"op":"mcm","id":2,"clk":"APORAQDXXgCAuwE=","pt":1780316370381,"mc":[{"id":"1.258742455","rc":[{"atl":[[5,0.14]],"batl":[[2,5.3,12.64],[1,5.2,22.46],[0,5.1,38.56]],"id":99072898}]}],"rt":639159131703893632,"dt":639159131703894054}
{"op":"mcm","id":2,"clk":"APiRAQDiXgCIuwE=","pt":1780316370482,"mc":[{"id":"1.258742455","rc":[{"atl":[[5,0]],"batl":[[0,5.1,38.42]],"id":99072898},{"batb":[],"atb":[[4.4,191.79]],"id":10398159},{"tv":13245.06,"batb":[[0,3.5,78.36]],"trd":[[3.55,711.63]],"atb":[[3.55,0]],"atl":[[3.55,14.34]],"batl":[[2,3.65,44.17],[1,3.6,39.57],[0,3.55,14.34]],"id":88302242}],"tv":38091.76}],"rt":639159131704903367,"dt":639159131704903857}
{"op":"mcm","id":2,"clk":"AIGSAQDmXgCRuwE=","pt":1780316370588,"mc":[{"id":"1.258742455","rc":[{"batb":[[0,4.7,24.02]],"atb":[[4.7,24.02]],"id":10398159}]}],"rt":639159131705958120,"dt":639159131705958562}
{"op":"mcm","id":2,"clk":"AIeSAQDwXgCXuwE=","pt":1780316370686,"mc":[{"id":"1.258742455","rc":[{"batb":[[0,4.9,54.66]],"atb":[[4.9,54.66]],"atl":[[5.4,30.41]],"batl":[],"id":99072898},{"batb":[[0,4.7,24.34]],"atb":[[4.7,24.34]],"id":10398159},{"batb":[[0,3.5,60.44]],"atb":[[3.5,60.44]],"atl":[[3.55,16],[3.6,45.05]],"batl":[[1,3.6,45.05],[0,3.55,16]],"id":88302242}]}],"rt":639159131706940469,"dt":639159131706940963}
{"op":"mcm","id":2,"clk":"AI6SAQDzXgCeuwE=","pt":1780316370788,"mc":[{"id":"1.258742455","rc":[{"batb":[[0,4.7,10.35]],"atb":[[4.7,10.35]],"id":10398159}]}],"rt":639159131707963546,"dt":639159131707963966}
{"op":"mcm","id":2,"clk":"AJWSAQD5XgCluwE=","pt":1780316370849,"mc":[{"id":"1.258742455","rc":[{"atl":[[5.5,37.36]],"batl":[],"id":99072898},{"batb":[[0,4.7,10.03]],"atb":[[4.7,10.03]],"id":10398159},{"atl":[[3.8,89.22]],"batl":[],"id":88302242}]}],"rt":639159131708576260,"dt":639159131708576667}
{"op":"mcm","id":2,"clk":"AJqSAQCAXwCruwE=","pt":1780316370946,"mc":[{"id":"1.258742455","rc":[{"batb":[[0,9,29.27]],"atb":[[9,29.27]],"id":98117699},{"batb":[[0,3.5,67.57]],"atb":[[3.5,67.57]],"id":88302242}]}],"rt":639159131709543769,"dt":639159131709544103}
{"op":"mcm","id":2,"clk":"AJ6SAQCEXwCxuwE=","pt":1780316371050,"mc":[{"id":"1.258742455","rc":[{"atl":[[3.75,93.44]],"batl":[],"id":88302242}]}],"rt":639159131710583977,"dt":639159131710584325}
{"op":"mcm","id":2,"clk":"AKiSAQCLXwC6uwE=","pt":1780316371252,"mc":[{"id":"1.258742455","rc":[{"tv":1126.51,"batb":[[0,21,9.18]],"trd":[[21,117]],"atb":[[21,9.18]],"id":99072900}],"tv":38093.76}],"rt":639159131712603965,"dt":639159131712604402}
{"op":"mcm","id":2,"clk":"ALGSAQCSXwDIuwE=","pt":1780316371456,"mc":[{"id":"1.258742455","rc":[{"atl":[[3.55,14.34]],"batl":[[0,3.55,14.34]],"id":88302242}]}],"rt":639159131714640341,"dt":639159131714640760}
{"op":"mcm","id":2,"clk":"ALySAQCbXwDVuwE=","pt":1780316371663,"mc":[{"id":"1.258742455","rc":[{"atl":[[3.55,14.81]],"batl":[[0,3.55,14.81]],"id":88302242}]}],"rt":639159131716712863,"dt":639159131716713241}
{"op":"mcm","id":2,"clk":"AMiSAQCkXwDiuwE=","pt":1780316371870,"mc":[{"id":"1.258742455","rc":[{"tv":13248.9,"trd":[[3.55,715.47]],"atl":[[3.55,12.89]],"batl":[[0,3.55,12.89]],"id":88302242}],"tv":38097.6}],"rt":639159131718785555,"dt":639159131718786083}
{"op":"mcm","id":2,"clk":"ANaSAQCtXwDvuwE=","pt":1780316372078,"mc":[{"id":"1.258742455","rc":[{"atl":[[3.55,12.42]],"batl":[[0,3.55,12.42]],"id":88302242}]}],"rt":639159131720865925,"dt":639159131720866376}
{"op":"mcm","id":2,"clk":"ANmSAQCyXwD3uwE=","pt":1780316372182,"mc":[{"id":"1.258742455","rc":[{"batb":[],"atb":[[4.6,78.01]],"atl":[[5.5,43.58]],"batl":[],"id":99072898}]}],"rt":639159131721898560,"dt":639159131721898890}
{"op":"mcm","id":2,"clk":"AN6SAQC2XwCAvAE=","pt":1780316372283,"mc":[{"id":"1.258742455","rc":[{"batb":[],"atb":[[4.6,70.99]],"id":99072898},{"atl":[[22,6.49]],"batl":[[0,22,6.49]],"id":99072900},{"batb":[],"atb":[[8.4,8.67]],"id":98117699},{"atl":[[3.75,89.62],[3.9,9]],"batl":[],"id":88302242}]}],"rt":639159131722908119,"dt":639159131722908534}
{"op":"mcm","id":2,"clk":"AOiSAQC9XwCUvAE=","pt":1780316372488,"mc":[{"id":"1.258742455","rc":[{"atl":[[13,10.72]],"batl":[],"id":97736949}]}],"rt":639159131724962917,"dt":639159131724963371}
{"op":"mcm","id":2,"clk":"AP2SAQDSXwCvvAE=","pt":1780316372746,"mc":[{"id":"1.258742455","rc":[{"atl":[[11,7.43]],"batl":[[0,11,7.43]],"id":97736949}]}],"rt":639159131727545582,"dt":639159131727546023}
{"op":"mcm","id":2,"clk":"AI2TAQDfXwDEvAE=","pt":1780316372960,"mc":[{"id":"1.258742455","rc":[{"batb":[[0,4.9,58.98]],"atb":[[4.9,58.98]],"id":99072898}]}],"rt":639159131729681234,"dt":639159131729681588}
{"op":"mcm","id":2,"clk":"AJCTAQDkXwDLvAE=","pt":1780316373059,"mc":[{"id":"1.258742455","rc":[{"batb":[[2,4.7,44.81],[1,4.8,52.24],[0,4.9,60.52]],"atb":[[4.7,44.81],[4.9,60.52],[4.8,52.24]],"id":99072898},{"tv":1128.51,"batb":[[0,21,8.18]],"trd":[[21,119]],"atb":[[21,8.18]],"atl":[[23,5.12]],"batl":[[1,23,5.12]],"id":99072900},{"batb":[[0,95,3.23]],"atb":[[95,3.23]],"id":99072901},{"batb":[[0,4.7,11.56]],"atb":[[4.7,11.56]],"id":10398159},{"atl":[[9.4,14.26],[1000,6.75],[9.6,12.14]],"batl":[[1,9.6,12.14],[0,9.4,14.98]],"id":98117699},{"atl":[[1000,3.27],[3.65,43.35],[3.6,44.84]],"batl":[[2,3.65,43.35],[1,3.6,44.84]],"id":88302242},{"atl":[[1000,1.31]],"id":97736949}],"tv":38099.6}],"rt":639159131730666220,"dt":639159131730666762}
{"op":"mcm","id":2,"clk":"AJSTAQDnXwDUvAE=","pt":1780316373159,"mc":[{"id":"1.258742455","rc":[{"batb":[[0,95,4.23]],"atb":[[95,4.23]],"id":99072901},{"atl":[[1000,6.25]],"id":98117699},{"atl":[[1000,3],[3.55,13.34]],"batl":[[0,3.55,13.34]],"id":88302242},{"atl":[[1000,1]],"id":97736949}]}],"rt":639159131731674963,"dt":639159131731675457}
{"op":"mcm","id":2,"clk":"AJyTAQDwXwDevAE=","pt":1780316373261,"mc":[{"id":"1.258742455","rc":[{"batb":[[0,21,7.01]],"atb":[[21,7.01]],"id":99072900},{"atl":[[9.4,14.51],[9.2,0.97]],"batl":[[0,9.4,15.48]],"id":98117699},{"atl":[[3.55,13.45],[3.6,45]],"batl":[[1,3.6,45],[0,3.55,13.45]],"id":88302242},{"atl":[[11,7.74]],"batl":[[0,11,7.74]],"id":97736949}]}],"rt":639159131732693817,"dt":639159131732694316}
{"op":"mcm","id":2,"clk":"AKWTAQD4XwDvvAE=","pt":1780316373464,"mc":[{"id":"1.258742455","rc":[{"batb":[[0,21,6.48]],"atb":[[21,6.48]],"id":99072900}]}],"rt":639159131734721565,"dt":639159131734722023}
{"op":"mcm","id":2,"clk":"AKqTAQD9XwD2vAE=","pt":1780316373567,"mc":[{"id":"1.258742455","rc":[{"batb":[[0,21,6.04]],"atb":[[21,6.04]],"id":99072900}]}],"rt":639159131735754140,"dt":639159131735754574}
{"op":"mcm","id":2,"clk":"ALCTAQCFYACEvQE=","pt":1780316373771,"mc":[{"id":"1.258742455","rc":[{"batb":[[0,21,6.36]],"atb":[[21,6.36]],"id":99072900}]}],"rt":639159131737791196,"dt":639159131737791621}
{"op":"mcm","id":2,"clk":"AL6TAQCTYACmvQE=","pt":1780316374180,"mc":[{"id":"1.258742455","rc":[{"batb":[[1,4.6,145.1]],"atb":[[4.6,145.1]],"id":10398159}]}],"rt":639159131741879359,"dt":639159131741879778}
{"op":"mcm","id":2,"clk":"AMmTAQCdYAC0vQE=","pt":1780316374385,"mc":[{"id":"1.258742455","rc":[{"tv":8584.84,"batb":[[0,4.7,2.89]],"trd":[[4.7,1176.06]],"atb":[[4.7,2.89]],"id":10398159}],"tv":38119.6}],"rt":639159131743930844,"dt":639159131743931266}
{"op":"mcm","id":2,"clk":"AM\u002BTAQClYAC4vQE=","pt":1780316374490,"mc":[{"id":"1.258742455","rc":[{"atl":[[5.2,20.39]],"batl":[[1,5.2,20.39]],"id":99072898},{"batb":[[0,48,2.96]],"atb":[[48,2.96]],"id":97008932},{"batb":[[1,4.6,137.79]],"atb":[[4.6,137.79]],"atl":[[4.8,71.93]],"batl":[[0,4.8,71.93]],"id":10398159},{"atl":[[3.6,41.32]],"batl":[[1,3.6,41.32]],"id":88302242}]}],"rt":639159131744982306,"dt":639159131744982715}
{"op":"mcm","id":2,"clk":"ANKTAQCuYADCvQE=","pt":1780316374591,"mc":[{"id":"1.258742455","rc":[{"batb":[[2,44,9.39]],"atb":[[44,9.39]],"id":97008932},{"batb":[[0,4.7,1.56]],"atb":[[4.7,1.56]],"id":10398159},{"batb":[],"atb":[[3.15,3.99],[3.1,57.36]],"id":88302242}]}],"rt":639159131745996269,"dt":639159131745996701}
{"op":"mcm","id":2,"clk":"ANmTAQCxYADKvQE=","pt":1780316374695,"mc":[{"id":"1.258742455","rc":[{"batb":[[0,48,3.06]],"atb":[[48,3.06]],"id":97008932},{"batb":[],"atb":[[75,5.84]],"id":99072901}]}],"rt":639159131747032563,"dt":639159131747032902}
{"op":"mcm","id":2,"clk":"AOGTAQC8YADRvQE=","pt":1780316374754,"mc":[{"id":"1.258742455","rc":[{"atl":[[50,11.55]],"batl":[[0,50,11.55]],"id":97008932}]}],"rt":639159131747617771,"dt":639159131747618093}
{"op":"mcm","id":2,"clk":"AO\u002BTAQDEYADfvQE=","pt":1780316374955,"mc":[{"id":"1.258742455","rc":[{"atl":[[50,11.73]],"batl":[[0,50,11.73]],"id":97008932}]}],"rt":639159131749629153,"dt":639159131749629508}
{"op":"mcm","id":2,"clk":"AP2TAQDPYADvvQE=","pt":1780316375164,"mc":[{"id":"1.258742455","rc":[{"atl":[[22,2.8]],"batl":[[0,22,2.8]],"id":99072900}]}],"rt":639159131751720060,"dt":639159131751720402}
{"op":"mcm","id":2,"clk":"AIeUAQDSYAD2vQE=","pt":1780316375266,"mc":[{"id":"1.258742455","rc":[{"batb":[[0,48,3.15]],"atb":[[48,3.15]],"id":97008932}]}],"rt":639159131752745349,"dt":639159131752745824}
{"op":"mcm","id":2,"clk":"AI6UAQDZYACBvgE=","pt":1780316375372,"mc":[{"id":"1.258742455","rc":[{"batb":[[0,21,6.9]],"atb":[[21,6.9]],"id":99072900}]}],"rt":639159131753805251,"dt":639159131753805685}
{"op":"mcm","id":2,"clk":"AKKUAQDrYACivgE=","pt":1780316375777,"mc":[{"id":"1.258742455","rc":[{"batb":[[1,4.8,53.24]],"atb":[[4.8,53.24]],"id":99072898}]}],"rt":639159131757851225,"dt":639159131757851584}
{"op":"mcm","id":2,"clk":"AK\u002BUAQDyYACuvgE=","pt":1780316375978,"mc":[{"id":"1.258742455","rc":[{"batb":[[1,4.8,57.11]],"atb":[[4.8,57.11]],"id":99072898},{"tv":1135.67,"batb":[[0,21,1.72]],"trd":[[21,126.16]],"atb":[[21,1.72]],"id":99072900},{"batb":[[0,10.5,22.4]],"atb":[[10.5,22.4]],"id":97736949},{"batb":[[0,170,3.28]],"atb":[[180,0.07]],"id":99072897}],"tv":38126.76}],"rt":639159131759866420,"dt":639159131759866847}
{"op":"mcm","id":2,"clk":"ALWUAQD6YACyvgE=","pt":1780316376080,"mc":[{"id":"1.258742455","rc":[{"tv":8072.07,"batb":[[0,4.9,49.76]],"trd":[[4.9,315.67]],"ltp":4.9,"atb":[[4.9,49.76]],"atl":[[5.1,48.71]],"batl":[[0,5.1,48.71]],"id":99072898},{"atl":[[1000,6.64],[22,7.98]],"batl":[[0,22,7.98]],"id":99072900},{"batb":[[2,4.5,156.15]],"atb":[[4.5,156.15]],"atl":[[1000,1.54]],"id":10398159},{"tv":2348.92,"batb":[[0,9,19.78]],"trd":[[9,51.03]],"atb":[[9,19.78]],"id":98117699},{"batb":[[1,3.45,85.56],[0,3.5,57.76]],"atb":[[1.17,196.87],[3.5,57.76],[3.45,85.56]],"atl":[[3.55,15.22]],"batl":[[0,3.55,15.22]],"id":88302242},{"atl":[[190,0.75]],"batl":[[0,200,4.88]],"id":99072897}],"tv":38162.32}],"rt":639159131760880138,"dt":639159131760880815}
{"op":"mcm","id":2,"clk":"ALqUAQD/YAC6vgE=","pt":1780316376186,"mc":[{"id":"1.258742455","rc":[{"atl":[[5.2,23.04],[5,9.11]],"batl":[[2,5.2,23.04],[1,5.1,48.71],[0,5,9.11]],"id":99072898},{"batb":[[2,19,12.27],[1,19.5,7.39],[0,20,11.89]],"atb":[[21,0.32]],"atl":[[1000,6.25],[22,10]],"batl":[[0,22,10]],"id":99072900},{"batb":[[0,4.7,17.16]],"atb":[[4.7,17.16]],"atl":[[1000,1.01]],"id":10398159},{"batb":[[2,8.6,18.75]],"atb":[[8.6,18.75]],"atl":[[9.2,6.97]],"batl":[[2,9.6,12.14],[1,9.4,14.51],[0,9.2,6.97]],"id":98117699},{"batb":[[0,3.5,66.69]],"atb":[[1.17,196.12],[3.5,66.69],[1.01,63155.82]],"atl":[[3.55,13.45],[3.6,45.06]],"batl":[[1,3.6,45.06],[0,3.55,13.45]],"id":88302242},{"atb":[[1.01,48149.55]],"id":99072897}]}],"rt":639159131761943383,"dt":639159131761944017}
{"op":"mcm","id":2,"clk":"AL\u002BUAQCBYQDHvgE=","pt":1780316376287,"mc":[{"id":"1.258742455","rc":[{"batb":[[0,4.9,59.28]],"atb":[[4.9,59.28],[1.01,54119.08]],"atl":[[5.1,51.37]],"batl":[[1,5.1,51.37]],"id":99072898},{"batb":[[0,48,3.35]],"atb":[[48,3.35]],"id":97008932},{"batb":[[0,20,11.57]],"atb":[[21,0],[1.01,54074.23]],"atl":[[23,5.51]],"batl":[[1,23,5.51]],"id":99072900},{"batb":[[0,95,4.26]],"atb":[[100,0.03]],"id":99072901},{"batb":[[0,4.7,17.69]],"atb":[[4.7,17.69]],"atl":[[4.9,55.66]],"batl":[[1,4.9,55.66]],"id":10398159},{"batb":[[0,9,23.04]],"atb":[[1.01,94397.23],[9,23.04]],"atl":[[9.2,11.97]],"batl":[[0,9.2,11.97]],"id":98117699},{"batb":[[0,3.5,67.44]],"atb":[[3.5,67.44]],"atl":[[3.55,12.53]],"batl":[[0,3.55,12.53]],"id":88302242}]}],"rt":639159131762952473,"dt":639159131762953058}
{"op":"mcm","id":2,"clk":"AMmUAQCJYQDNvgE=","pt":1780316376388,"mc":[{"id":"1.258742455","rc":[{"batb":[],"atb":[[4.6,67.99]],"atl":[[5.5,37.36],[5,9.71]],"batl":[[0,5,9.71]],"id":99072898},{"batb":[[0,4.7,31.43]],"atb":[[4.7,31.43]],"id":10398159},{"batb":[],"atb":[[690,2]],"id":10445502}]}],"rt":639159131763969000,"dt":639159131763969430}
{"op":"mcm","id":2,"clk":"ANCUAQCLYQDXvgE=","pt":1780316376491,"mc":[{"id":"1.258742455","rc":[{"batb":[[0,4.9,54.96]],"atb":[[4.9,54.96]],"id":99072898},{"atl":[[26,2.15],[22,11.31]],"batl":[[0,22,11.31]],"id":99072900},{"batb":[[0,4.7,33.52]],"atb":[[4.7,33.52]],"id":10398159},{"atl":[[9.2,14.8]],"batl":[[0,9.2,14.8]],"id":98117699},{"batb":[],"atb":[[680,0.18]],"id":10445502}]}],"rt":639159131764992599,"dt":639159131764993042}
{"op":"mcm","id":2,"clk":"ANqUAQCTYQDgvgE=","pt":1780316376594,"mc":[{"id":"1.258742455","rc":[{"tv":8080.72,"trd":[[5,220.47]],"ltp":5,"atl":[[5.5,31.36],[5,5.39]],"batl":[[0,5,5.39]],"id":99072898},{"batb":[[0,95,4.29]],"atb":[[100,0.06]],"id":99072901},{"atl":[[10.5,8.74]],"batl":[],"id":98117699}],"tv":38170.97}],"rt":639159131766026072,"dt":639159131766026518}
{"op":"mcm","id":2,"clk":"AOaUAQChYQDuvgE=","pt":1780316376797,"mc":[{"id":"1.258742455","rc":[{"atl":[[5,0]],"batl":[[2,5.3,12.64],[1,5.2,23.04],[0,5.1,51.37]],"id":99072898},{"atl":[[21,1.56]],"batl":[[2,23,5.51],[1,22,11.31],[0,21,1.56]],"id":99072900},{"batb":[[1,4.6,143.75]],"atb":[[4.6,143.75]],"id":10398159}]}],"rt":639159131768057900,"dt":639159131768058325}
{"op":"mcm","id":2,"clk":"AO\u002BUAQCpYQD2vgE=","pt":1780316376854,"mc":[{"id":"1.258742455","rc":[{"atl":[[5.4,36.41]],"batl":[],"id":99072898},{"atl":[[10,28.17]],"batl":[],"id":98117699}]}],"rt":639159131768624374,"dt":639159131768624754}
{"op":"mcm","id":2,"clk":"APaUAQCvYQCBvwE=","pt":1780316376963,"mc":[{"id":"1.258742455","rc":[{"atl":[[5.1,48.71]],"batl":[[0,5.1,48.71]],"id":99072898},{"atl":[[21,3.37]],"batl":[[0,21,3.37]],"id":99072900},{"batb":[[0,4.7,34.95]],"atb":[[4.7,34.95]],"id":10398159}]}],"rt":639159131769712530,"dt":639159131769713022}
{"op":"mcm","id":2,"clk":"AP2UAQCzYQCIvwE=","pt":1780316377060,"mc":[{"id":"1.258742455","rc":[{"atl":[[21,3.89]],"batl":[[0,21,3.89]],"id":99072900}]}],"rt":639159131770682338,"dt":639159131770682687}
{"op":"mcm","id":2,"clk":"AIOVAQC4YQCNvwE=","pt":1780316377167,"mc":[{"id":"1.258742455","rc":[{"batb":[[1,90,7.15]],"atb":[[90,7.15]],"id":99072901}]}],"rt":639159131771748775,"dt":639159131771749139}
{"op":"mcm","id":2,"clk":"AI\u002BVAQDDYQCdvwE=","pt":1780316377377,"mc":[{"id":"1.258742455","rc":[{"atl":[[5.4,30.41]],"batl":[],"id":99072898}]}],"rt":639159131773853283,"dt":639159131773853628}
{"op":"mcm","id":2,"clk":"AJmVAQDKYQCyvwE=","pt":1780316377582,"mc":[{"id":"1.258742455","rc":[{"atl":[[5.5,37.36]],"batl":[],"id":99072898}]}],"rt":639159131775905808,"dt":639159131775906142}
{"op":"mcm","id":2,"clk":"AKGVAQDQYQC2vwE=","pt":1780316377680,"mc":[{"id":"1.258742455","rc":[{"batb":[],"atb":[[140,1.71]],"id":99072897}]}],"rt":639159131776886857,"dt":639159131776887232}
{"op":"mcm","id":2,"clk":"AKqVAQDUYQDAvwE=","pt":1780316377779,"mc":[{"id":"1.258742455","rc":[{"batb":[[0,4.7,39.23]],"atb":[[4.7,39.23]],"id":10398159}]}],"rt":639159131777873196,"dt":639159131777873536}
{"op":"mcm","id":2,"clk":"AK6VAQDWYQDEvwE=","pt":1780316377882,"mc":[{"id":"1.258742455","rc":[{"batb":[],"atb":[[4.1,8.17]],"id":99072898},{"batb":[],"atb":[[3.05,297.07]],"id":88302242}]}],"rt":639159131778905215,"dt":639159131778905551}
{"op":"mcm","id":2,"clk":"ALaVAQDZYQDPvwE=","pt":1780316377986,"mc":[{"id":"1.258742455","rc":[{"batb":[],"atb":[[4,25.82]],"id":10398159},{"atl":[[9.2,23.26]],"batl":[[0,9.2,23.26]],"id":98117699},{"atb":[[2.98,1.99]],"id":88302242}]}],"rt":639159131779938804,"dt":639159131779939164}
{"op":"mcm","id":2,"clk":"ALyVAQDdYQDSvwE=","pt":1780316378083,"mc":[{"id":"1.258742455","rc":[{"batb":[[2,19,12.01]],"atb":[[19,12.01]],"id":99072900},{"batb":[[0,9,18.3]],"atb":[[7.8,5.03],[9,18.3]],"id":98117699},{"batb":[],"atb":[[9.4,16.78]],"id":97736949}]}],"rt":639159131780911447,"dt":639159131780911904}
{"op":"mcm","id":2,"clk":"AMeVAQDiYQDdvwE=","pt":1780316378190,"mc":[{"id":"1.258742455","rc":[{"batb":[[0,9,10.64]],"atb":[[9,10.64]],"atl":[[9.2,24.06]],"batl":[[0,9.2,24.06]],"id":98117699}]}],"rt":639159131781985095,"dt":639159131781985447}
{"op":"mcm","id":2,"clk":"AMqVAQDoYQDlvwE=","pt":1780316378290,"mc":[{"id":"1.258742455","rc":[{"batb":[],"atb":[[4.2,112.42]],"id":99072898},{"batb":[[0,48,3.56]],"atb":[[48,3.56],[42,14.67]],"id":97008932},{"batb":[[0,95,4.4]],"atb":[[95,4.34]],"id":99072901},{"batb":[],"atb":[[4,27.07]],"id":10398159},{"batb":[[0,50,12.19]],"atb":[[50,12.19]],"id":98464183},{"batb":[],"atb":[[3.05,298.71]],"id":88302242},{"batb":[[0,170,3.34]],"atb":[[170,3.27]],"id":99072897}]}],"rt":639159131782979579,"dt":639159131782980105}
{"op":"mcm","id":2,"clk":"ANGVAQDvYQDrvwE=","pt":1780316378397,"mc":[{"id":"1.258742455","rc":[{"batb":[],"atb":[[18,5.64]],"id":99072900},{"batb":[],"atb":[[7.6,124.97],[8.2,13.34]],"id":98117699},{"batb":[[0,3.5,70.88]],"atb":[[3.5,70.88]],"id":88302242},{"batb":[],"atb":[[9.4,17.31]],"id":97736949}]}],"rt":639159131784047833,"dt":639159131784048353}
{"op":"mcm","id":2,"clk":"ANeVAQD2YQDtvwE=","pt":1780316378492,"mc":[{"id":"1.258742455","rc":[{"batb":[],"atb":[[40,10.28]],"id":97008932},{"batb":[[0,95,3.48]],"atb":[[95,3.42]],"id":99072901},{"batb":[[1,8.8,17.32]],"atb":[[8.8,17.32]],"id":98117699}]}],"rt":639159131784996892,"dt":639159131784997391}
{"op":"mcm","id":2,"clk":"AOqVAQCHYgD/vwE=","pt":1780316378703,"mc":[{"id":"1.258742455","rc":[{"batb":[[0,95,4.54]],"atb":[[95,4.48]],"id":99072901},{"batb":[[1,8.8,18.84]],"atb":[[8.8,18.84]],"id":98117699}]}],"rt":639159131787106233,"dt":639159131787106713}
{"op":"mcm","id":2,"clk":"APaVAQCMYgCGwAE=","pt":1780316378806,"mc":[{"id":"1.258742455","rc":[{"atl":[[5.1,49.77]],"batl":[[0,5.1,49.77]],"id":99072898},{"atl":[[1000,6.59],[23,5.12],[22,11.8]],"batl":[[2,23,5.12],[1,22,11.8]],"id":99072900},{"batb":[[0,4.7,37.67]],"atb":[[4.7,37.67]],"id":10398159},{"batb":[[0,3.5,70.13]],"atb":[[3.5,70.13]],"atl":[[3.55,12.42],[3.6,44.9]],"batl":[[1,3.6,44.9],[0,3.55,12.42]],"id":88302242},{"batb":[[0,10.5,22]],"atb":[[10.5,22]],"id":97736949},{"batb":[[0,170,3.27]],"atb":[[180,0]],"id":99072897}]}],"rt":639159131788140540,"dt":639159131788141062}
{"op":"mcm","id":2,"clk":"AISWAQCSYgCPwAE=","pt":1780316378913,"mc":[{"id":"1.258742455","rc":[{"atl":[[1000,6.25]],"id":99072900},{"atb":[[2.98,3.75]],"id":88302242}]}],"rt":639159131789216397,"dt":639159131789216756}
{"op":"mcm","id":2,"clk":"AIeWAQCZYgCTwAE=","pt":1780316378962,"mc":[{"id":"1.258742455","rc":[{"atl":[[21,4.23]],"batl":[[0,21,4.23]],"id":99072900},{"atl":[[200,0.55],[180,0.02]],"batl":[[0,200,1.32]],"id":99072897}]}],"rt":639159131789704787,"dt":639159131789705223}
{"op":"mcm","id":2,"clk":"AJCWAQCfYgCcwAE=","pt":1780316379066,"mc":[{"id":"1.258742455","rc":[{"batb":[[0,9,6.89]],"atb":[[9,6.89]],"id":98117699},{"batb":[[1,160,6.47]],"atb":[[160,6.47]],"atl":[[1000,10.75]],"batl":[],"id":99072897}]}],"rt":639159131790740531,"dt":639159131790740969}
{"op":"mcm","id":2,"clk":"AJiWAQClYgCjwAE=","pt":1780316379168,"mc":[{"id":"1.258742455","rc":[{"atl":[[180,0]],"batl":[[0,200,1.3]],"id":99072897}]}],"rt":639159131791766860,"dt":639159131791767205}
{"op":"mcm","id":2,"clk":"AJ2WAQCqYgCnwAE=","pt":1780316379268,"mc":[{"id":"1.258742455","rc":[{"batb":[[0,95,4.61]],"atb":[[100,0.13]],"id":99072901},{"atl":[[1000,9.75]],"batl":[],"id":99072897}]}],"rt":639159131792761958,"dt":639159131792762330}
{"op":"mcm","id":2,"clk":"AKSWAQCvYgCywAE=","pt":1780316379372,"mc":[{"id":"1.258742455","rc":[{"batb":[[0,170,3.29]],"atb":[[180,0.02]],"atl":[[1000,8.75]],"batl":[],"id":99072897}]}],"rt":639159131793799942,"dt":639159131793800298}
{"op":"mcm","id":2,"clk":"AKuWAQCzYgC1wAE=","pt":1780316379476,"mc":[{"id":"1.258742455","rc":[{"atl":[[270,1]],"batl":[],"id":99072897}]}],"rt":639159131794839328,"dt":639159131794839658}
{"op":"mcm","id":2,"clk":"ALCWAQC2YgC8wAE=","pt":1780316379575,"mc":[{"id":"1.258742455","rc":[{"batb":[[2,19,7.44]],"atb":[[19,7.44],[18,13.56]],"atl":[[28,2.93],[26,10.07]],"batl":[],"id":99072900},{"batb":[],"atb":[[690,0],[700,3.29]],"id":10445502},{"atl":[[190,0.61]],"batl":[[0,200,1.16]],"id":99072897}]}],"rt":639159131795829787,"dt":639159131795830208}
{"op":"mcm","id":2,"clk":"ALaWAQC6YgDGwAE=","pt":1780316379677,"mc":[{"id":"1.258742455","rc":[{"batb":[],"atb":[[4.6,72.32]],"id":99072898},{"batb":[[0,170,3.42]],"atb":[[180,0.15]],"id":99072897}]}],"rt":639159131796853541,"dt":639159131796853888}
{"op":"mcm","id":2,"clk":"AL6WAQC7YgDLwAE=","pt":1780316379781,"mc":[{"id":"1.258742455","rc":[{"tv":2351.92,"batb":[[0,9,5.39]],"trd":[[9,54.03]],"atb":[[9,5.39]],"id":98117699}],"tv":38173.97}],"rt":639159131797894995,"dt":639159131797895431}
{"op":"mcm","id":2,"clk":"AM2WAQDMYgDcwAE=","pt":1780316379984,"mc":[{"id":"1.258742455","rc":[{"atl":[[9.2,25.18]],"batl":[[0,9.2,25.18]],"id":98117699}]}],"rt":639159131799924282,"dt":639159131799924636}
{"op":"mcm","id":2,"clk":"ANSWAQDTYgDiwAE=","pt":1780316380087,"mc":[{"id":"1.258742455","rc":[{"atl":[[3.55,0]],"batl":[[2,3.7,232.36],[1,3.65,43.35],[0,3.6,44.9]],"id":88302242}]}],"rt":639159131800950232,"dt":639159131800950623}
{"op":"mcm","id":2,"clk":"AN6WAQDZYgDrwAE=","pt":1780316380189,"mc":[{"id":"1.258742455","rc":[{"batb":[],"atb":[[4.5,43.83]],"id":99072898}]}],"rt":639159131801975351,"dt":639159131801975765}
{"op":"mcm","id":2,"clk":"APCWAQDnYgD7wAE=","pt":1780316380494,"mc":[{"id":"1.258742455","rc":[{"atl":[[3.75,83.62]],"batl":[],"id":88302242}]}],"rt":639159131805025583,"dt":639159131805025921}
{"op":"mcm","id":2,"clk":"APyWAQDvYgCKwQE=","pt":1780316380699,"mc":[{"id":"1.258742455","rc":[{"batb":[],"atb":[[4.4,19.57]],"id":99072898},{"atl":[[3.8,95.22]],"batl":[],"id":88302242}]}],"rt":639159131807077721,"dt":639159131807078113}
{"op":"mcm","id":2,"clk":"AIOXAQD1YgCOwQE=","pt":1780316380751,"mc":[{"id":"1.258742455","rc":[{"tv":8084.72,"batb":[[0,4.9,52.96]],"trd":[[4.9,319.67]],"ltp":4.9,"atb":[[4.9,52.96]],"id":99072898}],"tv":38177.97}],"rt":639159131807592823,"dt":639159131807593218}
{"op":"mcm","id":2,"clk":"AMiXAQCkYwDYwQE=","pt":1780316381783,"mc":[{"id":"1.258742455","rc":[{"batb":[[0,20,13.84]],"atb":[[20,13.84]],"id":99072900},{"batb":[[0,9,7.02]],"atb":[[9,7.02]],"id":98117699}]}],"rt":639159131817913055,"dt":639159131817913436}
{"op":"mcm","id":2,"clk":"AM\u002BXAQCmYwDewQE=","pt":1780316381884,"mc":[{"id":"1.258742455","rc":[{"batb":[[0,4.9,59.88]],"atb":[[4.9,59.88],[4.3,11.42]],"atl":[[5.2,27.22],[5.1,52.39]],"batl":[[1,5.2,27.22],[0,5.1,52.39]],"id":99072898},{"batb":[[0,20,14.34]],"atb":[[20,14.34]],"atl":[[21,22.23]],"batl":[[0,21,22.23]],"id":99072900},{"batb":[[1,8.8,19.56]],"atb":[[8.8,19.56]],"id":98117699}]}],"rt":639159131818919827,"dt":639159131818920339}
{"op":"mcm","id":2,"clk":"ANSXAQCpYwDjwQE=","pt":1780316381985,"mc":[{"id":"1.258742455","rc":[{"batb":[[1,19.5,9.1]],"atb":[[19.5,9.1]],"atl":[[21,29.28]],"batl":[[0,21,29.28]],"id":99072900},{"atl":[[3.7,237.65]],"batl":[[2,3.7,237.65]],"id":88302242},{"atb":[[1.17,2.41]],"id":97736949}]}],"rt":639159131819933195,"dt":639159131819933553}
{"op":"mcm","id":2,"clk":"AN2XAQCsYwDmwQE=","pt":1780316382088,"mc":[{"id":"1.258742455","rc":[{"batb":[[0,20,7.41]],"atb":[[20,7.41],[18,15.54]],"atl":[[21,30.4]],"batl":[[0,21,30.4]],"id":99072900},{"tv":13254.08,"batb":[[0,3.5,67.54]],"trd":[[3.5,131.82]],"ltp":3.5,"atb":[[3.5,67.54]],"id":88302242},{"atb":[[1.17,2]],"id":97736949}],"tv":38183.15}],"rt":639159131820963524,"dt":639159131820964016}
{"op":"mcm","id":2,"clk":"AOGXAQCyYwDqwQE=","pt":1780316382192,"mc":[{"id":"1.258742455","rc":[{"batb":[[0,20,5.9]],"atb":[[20,5.9]],"id":99072900},{"batb":[[0,10.5,22.41]],"atb":[[10.5,22.41]],"id":97736949}]}],"rt":639159131821997101,"dt":639159131821997496}
{"op":"mcm","id":2,"clk":"AO\u002BXAQC/YwD4wQE=","pt":1780316382396,"mc":[{"id":"1.258742455","rc":[{"batb":[[1,19.5,6.84]],"atb":[[19.5,6.84]],"atl":[[21,31.36]],"batl":[[0,21,31.36]],"id":99072900}]}],"rt":639159131824044405,"dt":639159131824044780}
{"op":"mcm","id":2,"clk":"AP2XAQDGYwCJwgE=","pt":1780316382553,"mc":[{"id":"1.258742455","rc":[{"atl":[[5.3,16.68]],"batl":[[2,5.3,16.68]],"id":99072898},{"atl":[[50,11.55]],"batl":[[0,50,11.55]],"id":97008932},{"atl":[[3.75,88.78]],"batl":[],"id":88302242}]}],"rt":639159131825609146,"dt":639159131825609591}
{"op":"mcm","id":2,"clk":"AIaYAQDMYwCPwgE=","pt":1780316382702,"mc":[{"id":"1.258742455","rc":[{"batb":[[1,19.5,7.77]],"atb":[[19.5,7.77]],"id":99072900}]}],"rt":639159131827101774,"dt":639159131827102184}
{"op":"mcm","id":2,"clk":"AJOYAQDTYwCZwgE=","pt":1780316382860,"mc":[{"id":"1.258742455","rc":[{"atl":[[50,11.62]],"batl":[[0,50,11.62]],"id":97008932}]}],"rt":639159131828683988,"dt":639159131828684341}
{"op":"mcm","id":2,"clk":"AJyYAQDYYwCewgE=","pt":1780316382964,"mc":[{"id":"1.258742455","rc":[{"batb":[[0,50,12.24]],"atb":[[50,12.24]],"id":98464183}]}],"rt":639159131829723480,"dt":639159131829723853}
{"op":"mcm","id":2,"clk":"AKOYAQDeYwClwgE=","pt":1780316383068,"mc":[{"id":"1.258742455","rc":[{"batb":[[0,95,4.67]],"atb":[[100,0.19]],"id":99072901}]}],"rt":639159131830761891,"dt":639159131830762221}
{"op":"mcm","id":2,"clk":"AK\u002BYAQDkYwCswgE=","pt":1780316383169,"mc":[{"id":"1.258742455","rc":[{"batb":[],"atb":[[4.2,117.98]],"atl":[[5.4,34.63]],"batl":[],"id":99072898},{"atl":[[3.6,45.77]],"batl":[[0,3.6,45.77]],"id":88302242}]}],"rt":639159131831773261,"dt":639159131831773662}
{"op":"mcm","id":2,"clk":"ALyYAQDwYwC0wgE=","pt":1780316383280,"mc":[{"id":"1.258742455","rc":[{"batb":[[0,48,3.6]],"atb":[[48,3.6]],"id":97008932}]}],"rt":639159131832876027,"dt":639159131832876366}
{"op":"mcm","id":2,"clk":"AMGYAQDyYwC9wgE=","pt":1780316383377,"mc":[{"id":"1.258742455","rc":[{"batb":[[1,19.5,8.23]],"atb":[[19.5,8.23]],"id":99072900}]}],"rt":639159131833847876,"dt":639159131833848223}
{"op":"mcm","id":2,"clk":"AM6YAQD4YwDJwgE=","pt":1780316383484,"mc":[{"id":"1.258742455","rc":[{"tv":13254.52,"batb":[[0,3.5,67.32]],"trd":[[3.5,132.26]],"atb":[[3.5,67.32]],"id":88302242}],"tv":38183.59}],"rt":639159131834922649,"dt":639159131834923321}
{"op":"mcm","id":2,"clk":"ANaYAQD8YwDVwgE=","pt":1780316383586,"mc":[{"id":"1.258742455","rc":[{"tv":896.04,"trd":[[55,99.3]],"atl":[[55,4.89]],"batl":[[0,55,4.89]],"id":98464183}],"tv":38183.61}],"rt":639159131835948457,"dt":639159131835948895}
{"op":"mcm","id":2,"clk":"ANyYAQCBZADgwgE=","pt":1780316383691,"mc":[{"id":"1.258742455","rc":[{"tv":556.13,"trd":[[50,79.2]],"ltp":50,"atl":[[50,11.61]],"batl":[[0,50,11.61]],"id":97008932},{"atl":[[55,5.53]],"batl":[[0,55,5.53]],"id":98464183},{"atl":[[3.95,33.45]],"batl":[],"id":88302242}],"tv":38183.63}],"rt":639159131836993762,"dt":639159131836994210}
{"op":"mcm","id":2,"clk":"ALCZAQCsZACxwwE=","pt":1780316384871,"mc":[{"id":"1.258742455","rc":[{"atl":[[4.9,55.13]],"batl":[[1,4.9,55.13]],"id":10398159}]}],"rt":639159131848789312,"dt":639159131848789710}
{"op":"mcm","id":2,"clk":"AL\u002BZAQC0ZADCwwE=","pt":1780316385072,"mc":[{"id":"1.258742455","rc":[{"batb":[],"atb":[[3.25,15.35]],"atl":[[3.65,49.33]],"batl":[[1,3.65,49.33]],"id":88302242}]}],"rt":639159131850797916,"dt":639159131850798343}
{"op":"mcm","id":2,"clk":"AMaZAQC5ZADFwwE=","pt":1780316385176,"mc":[{"id":"1.258742455","rc":[{"atl":[[60,5.62]],"batl":[[1,60,5.62]],"id":98464183},{"batb":[[0,3.5,73.58]],"atb":[[3.5,73.58]],"id":88302242},{"batb":[],"atb":[[690,2],[700,1.29]],"id":10445502}]}],"rt":639159131851837339,"dt":639159131851837800}
{"op":"mcm","id":2,"clk":"AM\u002BZAQC/ZADSwwE=","pt":1780316385376,"mc":[{"id":"1.258742455","rc":[{"batb":[[0,170,3.5]],"atb":[[180,0.23]],"atl":[[190,0.43]],"batl":[[1,220,1.13],[0,210,1.73]],"id":99072897}]}],"rt":639159131853840654,"dt":639159131853841435}
{"op":"mcm","id":2,"clk":"ANWZAQDDZADYwwE=","pt":1780316385480,"mc":[{"id":"1.258742455","rc":[{"atl":[[3.75,63.78]],"batl":[],"id":88302242},{"batb":[[0,10.5,23.37]],"atb":[[10.5,23.37]],"id":97736949}]}],"rt":639159131854883858,"dt":639159131854884236}
{"op":"mcm","id":2,"clk":"ANmZAQDEZADewwE=","pt":1780316385582,"mc":[{"id":"1.258742455","rc":[{"atl":[[5.5,41.48]],"batl":[],"id":99072898}]}],"rt":639159131855899535,"dt":639159131855899856}
{"op":"mcm","id":2,"clk":"AIaaAQDlZACYxAE=","pt":1780316386399,"mc":[{"id":"1.258742455","rc":[{"batb":[[1,8.8,20.57]],"atb":[[8.8,20.57]],"id":98117699}]}],"rt":639159131864069049,"dt":639159131864069398}
{"op":"mcm","id":2,"clk":"AJKaAQDsZACmxAE=","pt":1780316386601,"mc":[{"id":"1.258742455","rc":[{"atl":[[5.6,10.21]],"batl":[],"id":99072898},{"atl":[[25,4.61]],"batl":[],"id":99072900},{"batb":[],"atb":[[1.01,64685.82],[3.2,16.7]],"id":88302242},{"tv":2506.92,"batb":[[2,9.8,15.81]],"trd":[[11,101.37]],"atb":[[9.8,15.81]],"atl":[[11,6.44]],"batl":[[0,11,6.44]],"id":97736949}],"tv":38186.23}],"rt":639159131866098091,"dt":639159131866098683}
{"op":"mcm","id":2,"clk":"AJ2aAQDwZAC2xAE=","pt":1780316386759,"mc":[{"id":"1.258742455","rc":[{"atl":[[5,90.98]],"batl":[[2,5,90.98]],"id":10398159}]}],"rt":639159131867673715,"dt":639159131867674052}
{"op":"mcm","id":2,"clk":"AKSaAQDyZAC6xAE=","pt":1780316386858,"mc":[{"id":"1.258742455","rc":[{"batb":[[0,4.7,41.13]],"atb":[[4.7,41.13]],"id":10398159},{"atl":[[190,0.47]],"batl":[[1,220,1.88],[0,200,1.02]],"id":99072897}]}],"rt":639159131868665629,"dt":639159131868666023}
{"op":"mcm","id":2,"clk":"AKqaAQD3ZAC\u002BxAE=","pt":1780316386961,"mc":[{"id":"1.258742455","rc":[{"atl":[[5.1,50.42],[4.8,66.47]],"batl":[[0,4.8,66.47]],"id":10398159}]}],"rt":639159131869692997,"dt":639159131869693469}
{"op":"mcm","id":2,"clk":"ALaaAQCCZQDCxAE=","pt":1780316387070,"mc":[{"id":"1.258742455","rc":[{"atl":[[4.8,56.54]],"batl":[[0,4.8,56.54]],"id":10398159}]}],"rt":639159131870784307,"dt":639159131870784696}
{"op":"mcm","id":2,"clk":"AL2aAQCFZQDLxAE=","pt":1780316387170,"mc":[{"id":"1.258742455","rc":[{"atl":[[4.8,59.13]],"batl":[[0,4.8,59.13]],"id":10398159}]}],"rt":639159131871784469,"dt":639159131871784808}
{"op":"mcm","id":2,"clk":"AMWaAQCMZQDQxAE=","pt":1780316387272,"mc":[{"id":"1.258742455","rc":[{"batb":[[0,4.7,53.61]],"atb":[[4.7,53.61]],"id":10398159}]}],"rt":639159131872797002,"dt":639159131872797353}
{"op":"mcm","id":2,"clk":"ANOaAQCWZQDgxAE=","pt":1780316387477,"mc":[{"id":"1.258742455","rc":[{"tv":392.27,"trd":[[110,17.86]],"ltp":110,"atl":[[110,5.21]],"batl":[[0,110,5.21]],"id":99072901}],"tv":38188.23}],"rt":639159131874848825,"dt":639159131874849183}
{"op":"mcm","id":2,"clk":"AN6aAQCaZQDtxAE=","pt":1780316387594,"mc":[{"id":"1.258742455","rc":[{"batb":[[1,90,8.61]],"atb":[[90,8.61]],"atl":[[110,6.21]],"batl":[[0,110,6.21]],"id":99072901}]}],"rt":639159131876019779,"dt":639159131876020113}
{"op":"mcm","id":2,"clk":"AOKaAQCbZQD1xAE=","pt":1780316387681,"mc":[{"id":"1.258742455","rc":[{"batb":[[0,95,4.87]],"atb":[[100,0.39]],"id":99072901},{"atl":[[4.8,60.98]],"batl":[[0,4.8,60.98]],"id":10398159},{"atl":[[4,15.61]],"batl":[],"id":88302242}]}],"rt":639159131876893516,"dt":639159131876893889}
{"op":"mcm","id":2,"clk":"AOyaAQChZQD8xAE=","pt":1780316387784,"mc":[{"id":"1.258742455","rc":[{"atl":[[5.1,57.07]],"batl":[[0,5.1,57.07]],"id":99072898}]}],"rt":639159131877923487,"dt":639159131877923905}
{"op":"mcm","id":2,"clk":"APSaAQCoZQCExQE=","pt":1780316387887,"mc":[{"id":"1.258742455","rc":[{"atb":[[1.17,2.18]],"id":10398159},{"batb":[[0,10.5,25.21]],"atb":[[10.5,25.21]],"id":97736949}]}],"rt":639159131878954745,"dt":639159131878955153}
{"op":"mcm","id":2,"clk":"APiaAQCtZQCLxQE=","pt":1780316387990,"mc":[{"id":"1.258742455","rc":[{"atb":[[1.17,2]],"id":10398159}]}],"rt":639159131879976849,"dt":639159131879977210}
{"op":"mcm","id":2,"clk":"AP6aAQCvZQCWxQE=","pt":1780316388092,"mc":[{"id":"1.258742455","rc":[{"batb":[[0,4.7,53.79]],"atb":[[4.7,53.79]],"id":10398159}]}],"rt":639159131880999874,"dt":639159131881000198}
{"op":"mcm","id":2,"clk":"AIybAQC6ZQCjxQE=","pt":1780316388297,"mc":[{"id":"1.258742455","rc":[{"batb":[[1,46,11.63]],"atb":[[46,11.63]],"id":97008932},{"batb":[[0,20,4.15]],"atb":[[20,4.15]],"id":99072900}]}],"rt":639159131883050708,"dt":639159131883051095}
{"op":"mcm","id":2,"clk":"AJGbAQDDZQCsxQE=","pt":1780316388398,"mc":[{"id":"1.258742455","rc":[{"tv":1143.97,"batb":[[2,18.5,4.1],[1,19,7.44],[0,19.5,8.23]],"trd":[[20,62.03]],"ltp":20,"atb":[[20,0]],"atl":[[20,2.46]],"batl":[[2,22,11.8],[1,21,31.36],[0,20,2.46]],"id":99072900}],"tv":38196.53}],"rt":639159131884063752,"dt":639159131884064234}
{"op":"mcm","id":2,"clk":"AJabAQDIZQC0xQE=","pt":1780316388456,"mc":[{"id":"1.258742455","rc":[{"batb":[],"atb":[[17,58.04]],"atl":[[25,2.17],[21,32.09]],"batl":[[1,21,32.09]],"id":99072900}]}],"rt":639159131884641773,"dt":639159131884642129}
{"op":"mcm","id":2,"clk":"AKCbAQDMZQC7xQE=","pt":1780316388557,"mc":[{"id":"1.258742455","rc":[{"batb":[[0,19.5,3.1]],"atb":[[19.5,3.1]],"atl":[[20,2.58]],"batl":[[0,20,2.58]],"id":99072900},{"batb":[[1,90,7.83]],"atb":[[90,7.83]],"id":99072901}]}],"rt":639159131885653917,"dt":639159131885654280}
{"op":"mcm","id":2,"clk":"AKebAQDTZQDExQE=","pt":1780316388658,"mc":[{"id":"1.258742455","rc":[{"batb":[[0,19.5,1.71]],"atb":[[19.5,1.71]],"id":99072900}]}],"rt":639159131886663618,"dt":639159131886664028}
{"op":"mcm","id":2,"clk":"ALCbAQDXZQDOxQE=","pt":1780316388768,"mc":[{"id":"1.258742455","rc":[{"batb":[],"atb":[[17.5,20.45]],"atl":[[25,1.47],[20,0.93]],"batl":[[2,23,5.12],[1,22,11.8],[0,21,33.02]],"id":99072900}]}],"rt":639159131887756748,"dt":639159131887757142}
{"op":"mcm","id":2,"clk":"ALmbAQDfZQDXxQE=","pt":1780316388867,"mc":[{"id":"1.258742455","rc":[{"atl":[[3.7,220.99]],"batl":[[2,3.7,220.99]],"id":88302242}]}],"rt":639159131888757444,"dt":639159131888757821}
{"op":"mcm","id":2,"clk":"AMGbAQDiZQDgxQE=","pt":1780316388968,"mc":[{"id":"1.258742455","rc":[{"atl":[[3.6,62.43]],"batl":[[0,3.6,62.43]],"id":88302242}]}],"rt":639159131889760621,"dt":639159131889761444}
{"op":"mcm","id":2,"clk":"AOabAQCEZgCWxgE=","pt":1780316389583,"mc":[{"id":"1.258742455","rc":[{"batb":[[0,19.5,1.82]],"atb":[[19.5,1.82]],"id":99072900}]}],"rt":639159131895913212,"dt":639159131895913584}
{"op":"mcm","id":2,"clk":"APObAQCPZgChxgE=","pt":1780316389788,"mc":[{"id":"1.258742455","rc":[{"batb":[[0,19.5,1.91]],"atb":[[19.5,1.91]],"id":99072900},{"batb":[[1,160,5.84]],"atb":[[160,5.84]],"id":99072897}]}],"rt":639159131897962664,"dt":639159131897963074}
{"op":"mcm","id":2,"clk":"AJScAQCnZgDBxgE=","pt":1780316390202,"mc":[{"id":"1.258742455","rc":[{"batb":[[0,19.5,2.04]],"atb":[[19.5,2.04]],"atl":[[20,0.12]],"batl":[[0,21,32.21]],"id":99072900},{"atl":[[200,2.55]],"batl":[[0,200,3.02]],"id":99072897}]}],"rt":639159131902099302,"dt":639159131902099677}
{"op":"mcm","id":2,"clk":"AJecAQCqZgDJxgE=","pt":1780316390304,"mc":[{"id":"1.258742455","rc":[{"batb":[],"atb":[[17.5,22.18]],"id":99072900},{"batb":[[2,150,5.6],[1,160,4.11]],"atb":[[160,4.11],[150,5.6]],"id":99072897}]}],"rt":639159131903123957,"dt":639159131903124337}
{"op":"mcm","id":2,"clk":"AJmcAQCsZgDWxgE=","pt":1780316390404,"mc":[{"id":"1.258742455","rc":[{"atl":[[22,6.62],[20,0.32]],"batl":[[1,22,6.62],[0,21,32.41]],"id":99072900},{"atl":[[9.2,19.18]],"batl":[[0,9.2,19.18]],"id":98117699},{"batb":[[0,170,3.42]],"atb":[[180,0.15]],"atl":[[190,0.34],[270,0]],"batl":[[0,200,2.89]],"id":99072897}]}],"rt":639159131904129273,"dt":639159131904129679}
{"op":"mcm","id":2,"clk":"AJycAQCuZgDdxgE=","pt":1780316390454,"mc":[{"id":"1.258742455","rc":[{"batb":[[0,9,9.44]],"atb":[[9,9.44]],"id":98117699},{"batb":[[0,170,3.29]],"atb":[[180,0.02]],"id":99072897}]}],"rt":639159131904625811,"dt":639159131904626230}
{"op":"mcm","id":2,"clk":"AJ\u002BcAQCzZgDixgE=","pt":1780316390555,"mc":[{"id":"1.258742455","rc":[{"batb":[],"atb":[[17.5,20.45]],"atl":[[20,0.12]],"batl":[[0,21,32.21]],"id":99072900},{"batb":[[0,170,3.27]],"atb":[[180,0]],"id":99072897}]}],"rt":639159131905634084,"dt":639159131905634491}
{"op":"mcm","id":2,"clk":"AKacAQC5ZgDrxgE=","pt":1780316390675,"mc":[{"id":"1.258742455","rc":[{"tv":13293.08,"trd":[[3.6,892.35]],"ltp":3.6,"atl":[[3.6,43.15]],"batl":[[0,3.6,43.15]],"id":88302242},{"atl":[[200,0.55]],"batl":[[1,220,1.13],[0,210,1.64]],"id":99072897}],"tv":38235.09}],"rt":639159131906832828,"dt":639159131906833374}
{"op":"mcm","id":2,"clk":"AKqcAQDCZgD0xgE=","pt":1780316390780,"mc":[{"id":"1.258742455","rc":[{"batb":[[0,19.5,2.29]],"atb":[[19.5,2.29],[18,7.62],[17.5,30.92]],"atl":[[20,0]],"batl":[[0,21,32.09]],"id":99072900},{"batb":[[2,3.45,85.56],[1,3.5,73.58],[0,3.55,13.17]],"atb":[[3.55,13.17]],"id":88302242},{"batb":[],"atb":[[690,0],[700,3.29]],"id":10445502},{"batb":[[1,160,5.84]],"atb":[[160,5.84]],"atl":[[1000,10.75],[190,0.51]],"batl":[[1,220,1.88],[0,200,1.06]],"id":99072897}]}],"rt":639159131907881236,"dt":639159131907881960}
{"op":"mcm","id":2,"clk":"AK\u002BcAQDIZgD5xgE=","pt":1780316390876,"mc":[{"id":"1.258742455","rc":[{"atl":[[5,0.19]],"batl":[[0,5.1,57.26]],"id":99072898},{"atl":[[50,11.69]],"batl":[[0,50,11.69]],"id":97008932},{"batb":[],"atb":[[17.5,29.19]],"id":99072900},{"batb":[[0,95,4.84]],"atb":[[100,0.36]],"id":99072901},{"tv":2354.04,"batb":[[0,9,5.96]],"trd":[[9,56.15]],"atb":[[9,5.96]],"id":98117699},{"batb":[[1,3.5,78.53],[0,3.55,20.79]],"atb":[[3.5,78.53],[3.55,20.79]],"atl":[[3.6,59.47]],"batl":[[0,3.6,59.47]],"id":88302242},{"batb":[[2,160,5.84],[1,170,3.27],[0,180,2.22]],"atb":[[180,2.22]],"id":99072897}],"tv":38237.21}],"rt":639159131908845983,"dt":639159131908847064}
{"op":"mcm","id":2,"clk":"ALScAQDNZgCDxwE=","pt":1780316390973,"mc":[{"id":"1.258742455","rc":[{"batb":[[2,4.7,50.21]],"atb":[[4.7,50.21]],"atl":[[5.8,42.15]],"batl":[],"id":99072898},{"batb":[[0,19.5,2.75]],"atb":[[19.5,2.75]],"id":99072900},{"tv":392.85,"batb":[[0,95,4.55]],"trd":[[100,24.13]],"ltp":100,"atb":[[100,0.07]],"id":99072901},{"batb":[[0,4.7,53.61]],"atb":[[4.7,53.61]],"id":10398159},{"batb":[],"atb":[[8.4,10.21]],"id":98117699},{"tv":13334.66,"batb":[[2,3.4,80.52],[1,3.45,85.56],[0,3.5,78.53]],"trd":[[3.55,757.05]],"ltp":3.55,"atb":[[3.55,0]],"atl":[[3.55,13.95],[4.1,19.28],[3.6,64.85]],"batl":[[2,3.65,49.33],[1,3.6,64.85],[0,3.55,13.95]],"id":88302242},{"batb":[[0,180,4.31]],"atb":[[180,4.31]],"atl":[[1000,9.75],[190,0.38]],"batl":[[1,220,1.13],[0,210,1.68]],"id":99072897}],"tv":38279.37}],"rt":639159131909809872,"dt":639159131909810695}
{"op":"mcm","id":2,"clk":"ALqcAQDRZgCRxwE=","pt":1780316391077,"mc":[{"id":"1.258742455","rc":[{"batb":[[2,4.7,43.08],[1,4.8,49.97],[0,4.9,52.96]],"atb":[[4.7,43.08],[4.9,52.96],[4.5,50.73],[4.8,49.97]],"atl":[[5,12.79]],"batl":[[2,5.2,27.22],[1,5.1,57.07],[0,5,12.79]],"id":99072898},{"batb":[[1,19,9.18]],"atb":[[19,9.18]],"id":99072900},{"tv":392.99,"batb":[[0,95,4.48]],"trd":[[100,24.27]],"atb":[[100,0]],"atl":[[110,6.5],[100,2.03]],"batl":[[2,120,1.83],[1,110,6.5],[0,100,2.03]],"id":99072901},{"batb":[[2,4.5,148.86]],"atb":[[4.4,184.48],[4.3,141.49],[4.5,148.86]],"id":10398159},{"atl":[[3.65,45.58],[3.75,67.44],[3.7,217.22],[3.6,61.1]],"batl":[[2,3.65,45.58],[1,3.6,61.1]],"id":88302242},{"tv":240.98,"batb":[[1,170,5],[0,180,1.86]],"trd":[[180,55.66]],"atb":[[180,1.86],[170,5]],"atl":[[190,0.12]],"batl":[[0,210,1.42]],"id":99072897}],"tv":38284.41}],"rt":639159131910855481,"dt":639159131910856442}
{"op":"mcm","id":2,"clk":"AL6cAQDVZgCTxwE=","pt":1780316391170,"mc":[{"id":"1.258742455","rc":[{"atb":[[1.01,61919.08]],"id":99072898},{"batb":[[0,19.5,4.48]],"atb":[[19.5,4.48]],"id":99072900},{"batb":[[0,9,8.02]],"atb":[[9,8.02]],"id":98117699},{"tv":13353.68,"batb":[],"trd":[[3.55,776.07]],"atb":[[1.17,196.3],[3.3,20.21]],"atl":[[3.55,4.44],[3.6,66.31]],"batl":[[1,3.6,66.31],[0,3.55,4.44]],"id":88302242},{"batb":[[0,180,4.86]],"atb":[[180,4.86]],"atl":[[190,2.57]],"batl":[[2,220,1.13],[1,210,1.3],[0,190,2.57]],"id":99072897}],"tv":38303.43}],"rt":639159131911783354,"dt":639159131911783882}
{"op":"mcm","id":2,"clk":"AMecAQDcZgCbxwE=","pt":1780316391283,"mc":[{"id":"1.258742455","rc":[{"batb":[[0,4.9,52.8]],"atb":[[4.9,52.8]],"atl":[[14,1],[5.1,45.72]],"batl":[[1,5.1,45.72]],"id":99072898},{"tv":558.13,"batb":[[0,48,2.59]],"trd":[[48,55.82]],"ltp":48,"atb":[[48,2.59]],"atl":[[50,11.53]],"batl":[[0,50,11.53]],"id":97008932},{"batb":[[2,18.5,7.86],[0,19.5,10.22]],"atb":[[19.5,10.22],[18.5,7.86]],"atl":[[21,31.75],[20,1]],"batl":[[2,22,6.62],[1,21,31.75],[0,20,1]],"id":99072900},{"tv":396.99,"batb":[[0,95,2.48]],"trd":[[95,38.46]],"ltp":95,"atb":[[95,2.48],[1.01,46940.71]],"id":99072901},{"atb":[[1.01,72827.51]],"atl":[[14,1]],"id":10398159},{"tv":898.04,"batb":[[0,50,11.24]],"trd":[[50,142.04]],"ltp":50,"atb":[[50,11.24]],"id":98464183},{"atl":[[14,2.99]],"id":98117699},{"atb":[[1.17,196.12]],"atl":[[3.65,49.23],[14,2.99],[3.8,89.22]],"batl":[[2,3.65,49.23]],"id":88302242},{"atl":[[14,5.64]],"batl":[],"id":97736949},{"tv":191.12,"batb":[[0,1000,92.03]],"trd":[[1000,146.64]],"atb":[[1000,92.03]],"id":10445502},{"tv":243.14,"batb":[[1,170,3.27],[0,180,3.78]],"trd":[[180,57.82]],"atb":[[180,3.78],[170,3.27],[1.01,92004.55]],"id":99072897}],"tv":38315.59}],"rt":639159131912910103,"dt":639159131912910797}
{"op":"mcm","id":2,"clk":"AMmcAQDeZgChxwE=","pt":1780316391378,"mc":[{"id":"1.258742455","rc":[{"atl":[[5,17.98]],"batl":[[0,5,17.98]],"id":99072898},{"atl":[[55,23.06]],"batl":[[1,55,23.06]],"id":97008932},{"tv":1145.97,"batb":[[2,19,9.18],[1,19.5,10.22],[0,20,2.44]],"trd":[[20,64.03]],"atb":[[20,2.44]],"atl":[[20,0]],"batl":[[2,23,5.12],[1,22,6.62],[0,21,31.75]],"id":99072900},{"batb":[[1,90,8.98]],"atb":[[90,8.98]],"atl":[[100,2.3]],"batl":[[0,100,2.3]],"id":99072901},{"batb":[[0,50,12.14]],"atb":[[50,12.14]],"id":98464183},{"tv":13354.04,"batb":[],"trd":[[3.55,776.43]],"atb":[[3.35,151.04]],"atl":[[3.55,4.26]],"batl":[[0,3.55,4.26]],"id":88302242},{"atl":[[1000,8.75],[190,2.77]],"batl":[[0,190,2.77]],"id":99072897}],"tv":38317.95}],"rt":639159131913863914,"dt":639159131913864504}
{"op":"mcm","id":2,"clk":"ANCcAQDnZgCrxwE=","pt":1780316391485,"mc":[{"id":"1.258742455","rc":[{"batb":[[0,4.9,54.8]],"atb":[[4.9,54.8]],"atl":[[5.5,35.48],[5,20.31]],"batl":[[0,5,20.31]],"id":99072898},{"batb":[[0,48,3.84]],"atb":[[48,3.84]],"atl":[[50,11.69]],"batl":[[0,50,11.69]],"id":97008932},{"atb":[[1.17,2.49]],"id":99072900},{"batb":[[0,95,2.17]],"atb":[[95,2.17],[75,6.3]],"atl":[[100,3.37]],"batl":[[0,100,3.37]],"id":99072901},{"batb":[[0,50,14.24]],"atb":[[50,14.24]],"id":98464183},{"batb":[[0,180,3.45]],"atb":[[180,3.45]],"atl":[[270,1]],"batl":[],"id":99072897}]}],"rt":639159131914926932,"dt":639159131914927600}
{"op":"mcm","id":2,"clk":"ANmcAQDuZgC0xwE=","pt":1780316391593,"mc":[{"id":"1.258742455","rc":[{"atb":[[1.17,2]],"id":99072900},{"batb":[[0,50,15.83]],"atb":[[50,15.83]],"id":98464183},{"tv":13359.23,"batb":[[0,3.5,75.94]],"trd":[[3.5,137.45]],"ltp":3.5,"atb":[[3.5,75.94]],"atl":[[3.75,73.44]],"batl":[],"id":88302242},{"batb":[[2,160,4.11]],"atb":[[160,4.11]],"id":99072897}],"tv":38323.14}],"rt":639159131916009108,"dt":639159131916009618}
{"op":"mcm","id":2,"clk":"AOGcAQDxZgC5xwE=","pt":1780316391688,"mc":[{"id":"1.258742455","rc":[{"batb":[[0,20,2.93]],"atb":[[20,2.93]],"id":99072900},{"batb":[[1,90,7.97]],"atb":[[90,7.97]],"id":99072901},{"batb":[[0,180,3.56]],"atb":[[180,3.56]],"atl":[[270,0]],"batl":[],"id":99072897}]}],"rt":639159131916968105,"dt":639159131916968658}
{"op":"mcm","id":2,"clk":"AOWcAQD0ZgDAxwE=","pt":1780316391790,"mc":[{"id":"1.258742455","rc":[{"atl":[[5.4,40.63]],"batl":[],"id":99072898},{"batb":[[0,48,4.19]],"atb":[[48,4.19]],"id":97008932},{"atl":[[3.55,4.84]],"batl":[[0,3.55,4.84]],"id":88302242}]}],"rt":639159131917982754,"dt":639159131917983283}
{"op":"mcm","id":2,"clk":"AOycAQD4ZgDKxwE=","pt":1780316391891,"mc":[{"id":"1.258742455","rc":[{"atl":[[50,11.61]],"batl":[[0,50,11.61]],"id":97008932},{"batb":[[0,20,3.04]],"atb":[[20,3.04]],"id":99072900}]}],"rt":639159131918990272,"dt":639159131918990634}
{"op":"mcm","id":2,"clk":"AO\u002BcAQD\u002BZgDNxwE=","pt":1780316391992,"mc":[{"id":"1.258742455","rc":[{"batb":[],"atb":[[3.35,145.04]],"id":88302242}]}],"rt":639159131919999904,"dt":639159131920000337}
{"op":"mcm","id":2,"clk":"AIGdAQCIZwDcxwE=","pt":1780316392193,"mc":[{"id":"1.258742455","rc":[{"atl":[[50,11.38]],"batl":[[0,50,11.38]],"id":97008932},{"batb":[[0,20,3.12]],"atb":[[20,3.12]],"id":99072900},{"batb":[],"atb":[[75,6.73]],"atl":[[100,3.5]],"batl":[[0,100,3.5]],"id":99072901},{"batb":[],"atb":[[3.3,26.21]],"atl":[[3.55,5.54]],"batl":[[0,3.55,5.54]],"id":88302242}]}],"rt":639159131922015673,"dt":639159131922016222}
{"op":"mcm","id":2,"clk":"AImdAQCPZwDnxwE=","pt":1780316392302,"mc":[{"id":"1.258742455","rc":[{"atl":[[5.5,32.6]],"batl":[],"id":99072898}]}],"rt":639159131923100108,"dt":639159131923100472}
{"op":"mcm","id":2,"clk":"AJGdAQCTZwDxxwE=","pt":1780316392403,"mc":[{"id":"1.258742455","rc":[{"batb":[[0,4.9,55.82]],"atb":[[4.9,55.82]],"id":99072898},{"batb":[[0,4.7,54.67]],"atb":[[4.7,54.67]],"id":10398159},{"batb":[[0,3.5,77.37]],"atb":[[3.5,77.37]],"id":88302242},{"batb":[[0,1000,92.04]],"atb":[[1000,92.04]],"id":10445502},{"batb":[[0,180,3.45]],"atb":[[180,3.45]],"id":99072897}]}],"rt":639159131924109149,"dt":639159131924109724}
{"op":"mcm","id":2,"clk":"AJadAQCXZwD7xwE=","pt":1780316392506,"mc":[{"id":"1.258742455","rc":[{"tv":8246.37,"batb":[[2,4.6,72.32],[1,4.7,43.08],[0,4.8,49.97]],"trd":[[4.9,481.32]],"atb":[[4.9,0]],"atl":[[4.9,5.67]],"batl":[[2,5.1,45.72],[1,5,20.31],[0,4.9,5.67]],"id":99072898},{"batb":[[0,180,3.48]],"atb":[[180,3.48]],"id":99072897}],"tv":38484.79}],"rt":639159131925142630,"dt":639159131925143034}
{"op":"mcm","id":2,"clk":"AJ6dAQCYZwCIyAE=","pt":1780316392607,"mc":[{"id":"1.258742455","rc":[{"tv":8257.69,"batb":[[0,4.8,50.21]],"trd":[[4.9,492.64]],"atb":[[4.9,0.24]],"atl":[[4.9,0],[5,22.31]],"batl":[[2,5.2,27.22],[1,5.1,45.72],[0,5,22.31]],"id":99072898}],"tv":38496.11}],"rt":639159131926153839,"dt":639159131926154279}
{"op":"mcm","id":2,"clk":"AKSdAQCaZwCRyAE=","pt":1780316392711,"mc":[{"id":"1.258742455","rc":[{"batb":[[2,4.7,43.08],[1,4.8,76.24],[0,4.9,4.04]],"atb":[[4.9,4.04],[4.8,76.24]],"atl":[[5.2,29.1],[5,32.1]],"batl":[[2,5.2,29.1],[0,5,32.1]],"id":99072898},{"batb":[[0,48,8.93]],"atb":[[48,8.93]],"id":97008932},{"batb":[[0,20,6.9]],"atb":[[20,6.9]],"id":99072900},{"batb":[[0,95,3.93]],"atb":[[95,3.93]],"id":99072901},{"batb":[[0,4.7,85.89]],"atb":[[4.7,85.89]],"atl":[[5.2,47.82],[4.8,47.1]],"batl":[[0,4.8,47.1]],"id":10398159},{"batb":[[0,50,18.43]],"atb":[[50,18.43]],"id":98464183},{"batb":[[0,9,29.32]],"atb":[[9,29.32]],"id":98117699},{"batb":[[0,3.5,111.1]],"atb":[[3.5,111.1]],"atl":[[3.55,4.26]],"batl":[[0,3.55,4.26]],"id":88302242},{"batb":[[0,10.5,32.99]],"atb":[[10.5,32.99]],"atl":[[11,5.92]],"batl":[[0,11,5.92]],"id":97736949},{"batb":[[0,180,4.34]],"atb":[[180,4.34]],"id":99072897}]}],"rt":639159131927194445,"dt":639159131927195097}
{"op":"mcm","id":2,"clk":"AKidAQCdZwCZyAE=","pt":1780316392766,"mc":[{"id":"1.258742455","rc":[{"tv":8258.15,"batb":[[1,4.8,75.18],[0,4.9,8.41]],"trd":[[4.9,493.1]],"atb":[[4.9,8.41],[4.8,75.18]],"id":99072898},{"batb":[[0,10.5,33.99]],"atb":[[10.5,33.99]],"atl":[[11,5.55]],"batl":[[0,11,5.55]],"id":97736949},{"batb":[[0,180,4.43]],"atb":[[180,4.43]],"id":99072897}],"tv":38496.57}],"rt":639159131927737028,"dt":639159131927737432}
{"op":"mcm","id":2,"clk":"AK2dAQCiZwCiyAE=","pt":1780316392873,"mc":[{"id":"1.258742455","rc":[{"tv":8266.23,"batb":[[1,4.8,70.19],[0,4.9,18.13]],"trd":[[4.9,501.18]],"atb":[[4.9,18.13],[4.5,53.66],[4.8,70.19]],"atl":[[5,37.51]],"batl":[[0,5,37.51]],"id":99072898},{"batb":[[1,46,13.36]],"atb":[[46,13.36],[38,20.3]],"id":97008932},{"batb":[[0,9,31.82]],"atb":[[9,31.82]],"atl":[[9.2,18.3]],"batl":[[0,9.2,18.3]],"id":98117699}],"tv":38504.65}],"rt":639159131928809217,"dt":639159131928809697}
{"op":"mcm","id":2,"clk":"ALKdAQCkZwCvyAE=","pt":1780316392970,"mc":[{"id":"1.258742455","rc":[{"batb":[[0,48,9.21]],"atb":[[48,9.21]],"atl":[[90,3.56]],"batl":[],"id":97008932},{"tv":1159.77,"batb":[[2,18.5,7.86],[1,19,9.18],[0,19.5,10.22]],"trd":[[20,77.83]],"atb":[[20,0]],"atl":[[20,10.51]],"batl":[[2,22,6.62],[1,21,31.75],[0,20,10.51]],"id":99072900},{"batb":[[0,9,32.92]],"atb":[[9,32.92]],"id":98117699},{"tv":243.34,"batb":[[0,180,4.33]],"trd":[[180,58.02]],"atb":[[180,4.33]],"id":99072897}],"tv":38518.65}],"rt":639159131929783347,"dt":639159131929784068}
{"op":"mcm","id":2,"clk":"AL2dAQCqZwC8yAE=","pt":1780316393077,"mc":[{"id":"1.258742455","rc":[{"batb":[[1,19,11.98],[0,19.5,4.73]],"atb":[[19,11.98],[19.5,4.73]],"atl":[[20,13.24]],"batl":[[0,20,13.24]],"id":99072900},{"atl":[[9.2,17.76]],"batl":[[0,9.2,17.76]],"id":98117699},{"atl":[[11,5.69]],"batl":[[0,11,5.69]],"id":97736949}]}],"rt":639159131930854597,"dt":639159131930855188}
{"op":"mcm","id":2,"clk":"AMOdAQCtZwDHyAE=","pt":1780316393173,"mc":[{"id":"1.258742455","rc":[{"batb":[[1,4.8,72.31]],"atb":[[4.8,72.31]],"id":99072898},{"batb":[[2,18,7.62],[1,18.5,7.86],[0,19,12.93]],"atb":[[19.5,0.95]],"atl":[[24,3.64]],"batl":[],"id":99072900},{"atl":[[9.2,14.93]],"batl":[[0,9.2,14.93]],"id":98117699}]}],"rt":639159131931807832,"dt":639159131931808368}
{"op":"mcm","id":2,"clk":"AMudAQCxZwDTyAE=","pt":1780316393277,"mc":[{"id":"1.258742455","rc":[{"batb":[[0,19,11.98]],"atb":[[19.5,0]],"atl":[[19.5,5.73]],"batl":[[2,21,31.75],[1,20,13.24],[0,19.5,5.73]],"id":99072900}]}],"rt":639159131932856921,"dt":639159131932857334}
{"op":"mcm","id":2,"clk":"ANCdAQC5ZwDdyAE=","pt":1780316393378,"mc":[{"id":"1.258742455","rc":[{"tv":8291.09,"batb":[[0,4.9,5.7]],"trd":[[4.9,526.04]],"atb":[[4.9,5.7]],"id":99072898},{"atl":[[50,11.88]],"batl":[[0,50,11.88]],"id":97008932},{"tv":1164.81,"batb":[[1,18.5,9.64]],"trd":[[19.5,22.75]],"ltp":19.5,"atb":[[18.5,9.64]],"atl":[[20,14.84],[19.5,3.21]],"batl":[[1,20,14.84],[0,19.5,3.21]],"id":99072900},{"atl":[[100,3.88]],"batl":[[0,100,3.88]],"id":99072901},{"atl":[[1000,1.36]],"id":10398159},{"atl":[[55,6.24]],"batl":[[0,55,6.24]],"id":98464183},{"atl":[[9.2,13.81]],"batl":[[0,9.2,13.81]],"id":98117699},{"tv":13367.75,"batb":[[2,3.45,85.56],[1,3.5,111.1],[0,3.55,10.33]],"trd":[[3.55,784.95]],"ltp":3.55,"atb":[[3.55,10.33]],"atl":[[3.55,0]],"batl":[[2,3.7,217.22],[1,3.65,49.23],[0,3.6,66.31]],"id":88302242},{"atl":[[190,2.9]],"batl":[[0,190,2.9]],"id":99072897}],"tv":38557.07}],"rt":639159131933866203,"dt":639159131933867128}
{"op":"mcm","id":2,"clk":"ANWdAQC9ZwDlyAE=","pt":1780316393478,"mc":[{"id":"1.258742455","rc":[{"batb":[[1,4.8,70.19]],"atb":[[4.8,70.19]],"id":99072898},{"batb":[[0,19,8.04]],"atb":[[19,8.04]],"id":99072900},{"atl":[[1000,1.01]],"id":10398159},{"atl":[[55,6.56]],"batl":[[0,55,6.56]],"id":98464183},{"tv":13407.87,"batb":[[1,3.5,103.21],[0,3.55,15.35]],"trd":[[3.5,153.23],[3.55,809.29]],"atb":[[3.5,103.21],[3.55,15.35]],"atl":[[3.7,220.83]],"batl":[[2,3.7,220.83]],"id":88302242},{"tv":2507.82,"batb":[[2,10,38.85],[1,10.5,33.99],[0,11,6.43]],"trd":[[11,102.27]],"atb":[[9.4,14.38],[11,6.43]],"atl":[[11,0]],"batl":[[2,12.5,7.1],[1,12,18.1],[0,11.5,15.03]],"id":97736949}],"tv":38598.09}],"rt":639159131934861260,"dt":639159131934862044}
{"op":"mcm","id":2,"clk":"AN6dAQDBZwDuyAE=","pt":1780316393581,"mc":[{"id":"1.258742455","rc":[{"batb":[[2,4.6,72.32],[1,4.7,43.08],[0,4.8,70.19]],"atb":[[4.9,0]],"id":99072898},{"batb":[[2,18,12.38]],"atb":[[18,12.38]],"id":99072900},{"tv":8585.54,"batb":[[0,4.7,85.54]],"trd":[[4.7,1176.76]],"atb":[[4.7,85.54]],"id":10398159},{"batb":[[0,50,18.48]],"atb":[[50,18.48]],"id":98464183},{"batb":[[0,3.55,33.81]],"atb":[[3.55,33.81]],"atl":[[3.6,69.94]],"batl":[[0,3.6,69.94]],"id":88302242},{"tv":2520.68,"batb":[[0,11,3.42]],"trd":[[11,115.13]],"atb":[[9.4,12.29],[11,3.42]],"atl":[[13,11.57]],"batl":[],"id":97736949}],"tv":38611.65}],"rt":639159131935894344,"dt":639159131935894966}
{"op":"mcm","id":2,"clk":"AOSdAQDDZwD9yAE=","pt":1780316393690,"mc":[{"id":"1.258742455","rc":[{"batb":[[0,4.8,88]],"atb":[[4.8,88]],"atl":[[5.1,47.72]],"batl":[[1,5.1,47.72]],"id":99072898},{"batb":[[0,19,8.45]],"atb":[[19,8.45]],"atl":[[19.5,3.58]],"batl":[[0,19.5,3.58]],"id":99072900},{"batb":[],"atb":[[4.4,188.43]],"id":10398159},{"batb":[],"atb":[[8.4,15.29]],"id":98117699},{"batb":[[1,3.5,118.99]],"atb":[[3.5,118.99]],"atl":[[3.75,67.44],[3.6,67.23]],"batl":[[0,3.6,67.23]],"id":88302242},{"batb":[[1,10.5,35.54]],"atb":[[8.8,9.38],[10.5,35.54]],"atl":[[11.5,11.85]],"batl":[[0,11.5,11.85]],"id":97736949}]}],"rt":639159131936981146,"dt":639159131936981728}
{"op":"mcm","id":2,"clk":"AOedAQDHZwCGyQE=","pt":1780316393791,"mc":[{"id":"1.258742455","rc":[{"batb":[[0,48,6.45]],"atb":[[48,6.45]],"id":97008932},{"batb":[[0,19,4.75]],"atb":[[19,4.75]],"id":99072900},{"batb":[[0,95,2.17]],"atb":[[95,2.17]],"id":99072901},{"batb":[[0,3.55,15.96]],"atb":[[3.55,15.96]],"atl":[[3.6,64.62]],"batl":[[0,3.6,64.62]],"id":88302242},{"batb":[[0,11,8.81]],"atb":[[11,8.81]],"id":97736949}]}],"rt":639159131937989498,"dt":639159131937989988}
{"op":"mcm","id":2,"clk":"AO2dAQDLZwCSyQE=","pt":1780316393898,"mc":[{"id":"1.258742455","rc":[{"batb":[[0,4.8,88.59]],"atb":[[4.5,47.66],[4.8,88.59]],"id":99072898},{"batb":[[1,46,11.63],[0,48,6.49]],"atb":[[48,6.49],[46,11.63]],"id":97008932},{"batb":[[1,18.5,12.63]],"atb":[[18.5,12.63]],"id":99072900},{"tv":13408.37,"batb":[[0,3.55,3.39]],"trd":[[3.55,809.79]],"atb":[[3.55,3.39]],"atl":[[3.8,95.22]],"batl":[],"id":88302242},{"batb":[],"atb":[[9.4,6.29]],"atl":[[13,5.57],[11.5,14.28]],"batl":[[0,11.5,14.28]],"id":97736949}],"tv":38612.15}],"rt":639159131939081263,"dt":639159131939081774}
{"op":"mcm","id":2,"clk":"APOdAQDPZwCayQE=","pt":1780316393997,"mc":[{"id":"1.258742455","rc":[{"batb":[[0,19,4.34]],"atb":[[19,4.34],[17,59.71]],"atl":[[24,1.25],[20,16.17],[19.5,4.12]],"batl":[[1,20,16.17],[0,19.5,4.12]],"id":99072900},{"batb":[],"atb":[[3.3,20.21]],"id":88302242}]}],"rt":639159131940052450,"dt":639159131940052822}
{"op":"mcm","id":2,"clk":"APOdAQDSZwCfyQE=","pt":1780316394094,"mc":[{"id":"1.258742455","rc":[{"batb":[],"atb":[[4.1,14.81]],"id":99072898},{"batb":[],"atb":[[70,7.77]],"id":99072901},{"batb":[[0,3.55,1.48]],"atb":[[3.55,1.48]],"id":88302242},{"batb":[[1,10.5,34.83],[0,11,9.43]],"atb":[[11,9.43],[10.5,34.83]],"id":97736949}]}],"rt":639159131941029977,"dt":639159131941030463}
{"op":"mcm","id":2,"clk":"APidAQDTZwCkyQE=","pt":1780316394197,"mc":[{"id":"1.258742455","rc":[{"batb":[],"atb":[[4.4,25.57]],"id":99072898},{"tv":558.15,"trd":[[50,79.22]],"ltp":50,"atl":[[50,11.87]],"batl":[[0,50,11.87]],"id":97008932},{"tv":898.06,"trd":[[55,99.32]],"ltp":55,"atl":[[55,8.17]],"batl":[[0,55,8.17]],"id":98464183},{"batb":[],"atb":[[8.4,10.21]],"id":98117699},{"batb":[],"atb":[[3.35,151.04]],"id":88302242},{"batb":[],"atb":[[9.6,20.97]],"atl":[[13.5,10.62]],"batl":[],"id":97736949}],"tv":38612.19}],"rt":639159131942051131,"dt":639159131942051735}
{"op":"mcm","id":2,"clk":"AICeAQDcZwCryQE=","pt":1780316394301,"mc":[{"id":"1.258742455","rc":[{"batb":[[0,4.8,89.34]],"atb":[[4.8,89.34]],"id":99072898},{"atb":[[6.6,0.89]],"id":97008932},{"tv":1166.73,"batb":[[0,19,4.48]],"trd":[[19.5,24.67]],"atb":[[19,4.48]],"atl":[[19.5,3.16]],"batl":[[0,19.5,3.16]],"id":99072900},{"atl":[[55,8.97]],"batl":[[0,55,8.97]],"id":98464183},{"atb":[[1.17,196.38]],"id":88302242},{"batb":[[0,180,4.52]],"atb":[[180,4.52]],"id":99072897}],"tv":38614.11}],"rt":639159131943096432,"dt":639159131943096919}
{"op":"mcm","id":2,"clk":"AIieAQDeZwCxyQE=","pt":1780316394406,"mc":[{"id":"1.258742455","rc":[{"atb":[[1.17,196.12]],"atl":[[3.6,68.23]],"batl":[[0,3.6,68.23]],"id":88302242},{"batb":[[1,10.5,34.42]],"atb":[[1.17,2.18],[10.5,34.42]],"id":97736949}]}],"rt":639159131944136481,"dt":639159131944136928}
{"op":"mcm","id":2,"clk":"AJCeAQDoZwC2yQE=","pt":1780316394506,"mc":[{"id":"1.258742455","rc":[{"batb":[[0,19,5.26]],"atb":[[19,5.26]],"atl":[[19.5,2.25]],"batl":[[0,19.5,2.25]],"id":99072900},{"batb":[[1,3.5,119.25]],"atb":[[3.5,119.25]],"id":88302242},{"atb":[[1.17,2]],"id":97736949},{"batb":[[1,170,3.47]],"atb":[[170,3.47]],"id":99072897}]}],"rt":639159131945143688,"dt":639159131945144149}
{"op":"mcm","id":2,"clk":"AJWeAQDpZwC7yQE=","pt":1780316394555,"mc":[{"id":"1.258742455","rc":[{"atl":[[5.1,49.72]],"batl":[[1,5.1,49.72]],"id":99072898},{"tv":1171.23,"trd":[[19.5,29.17]],"atl":[[19.5,0]],"batl":[[2,22,6.62],[1,21,31.75],[0,20,16.17]],"id":99072900},{"batb":[[0,11,9.61]],"atb":[[11,9.61]],"id":97736949}],"tv":38618.61}],"rt":639159131945632643,"dt":639159131945633066}
{"op":"mcm","id":2,"clk":"AJqeAQDuZwDAyQE=","pt":1780316394659,"mc":[{"id":"1.258742455","rc":[{"batb":[[0,19,9.02]],"atb":[[19,9.02]],"id":99072900}]}],"rt":639159131946672093,"dt":639159131946672503}
{"op":"mcm","id":2,"clk":"AKOeAQD3ZwDGyQE=","pt":1780316394763,"mc":[{"id":"1.258742455","rc":[{"atl":[[4.9,3.12]],"batl":[[2,5.1,49.72],[1,5,37.51],[0,4.9,3.12]],"id":99072898},{"batb":[[2,18,13.23],[0,19,11.67]],"atb":[[19,11.67],[18,13.23]],"atl":[[20,14.84]],"batl":[[0,20,14.84]],"id":99072900},{"batb":[[0,11,9.92]],"atb":[[11,9.92]],"id":97736949}]}],"rt":639159131947716195,"dt":639159131947716707}
{"op":"mcm","id":2,"clk":"AKmeAQD8ZwDNyQE=","pt":1780316394866,"mc":[{"id":"1.258742455","rc":[{"atl":[[20,0]],"id":99072898},{"atl":[[19,0.55]],"id":10398159},{"atl":[[85,0]],"id":98117699},{"atl":[[11,24.13],[3.6,64.62]],"batl":[[0,3.6,64.62]],"id":88302242},{"batb":[[2,10,42.32]],"atb":[[10,42.32]],"atl":[[120,0]],"id":97736949}]}],"rt":639159131948743246,"dt":639159131948743897}
{"op":"mcm","id":2,"clk":"ALSeAQCJaADWyQE=","pt":1780316394971,"mc":[{"id":"1.258742455","rc":[{"atl":[[20,13.24]],"batl":[[0,20,13.24]],"id":99072900}]}],"rt":639159131949795053,"dt":639159131949795448}
{"op":"mcm","id":2,"clk":"ALueAQCOaADbyQE=","pt":1780316395072,"mc":[{"id":"1.258742455","rc":[{"atl":[[5.4,34.63]],"batl":[],"id":99072898}]}],"rt":639159131950801882,"dt":639159131950802278}
{"op":"mcm","id":2,"clk":"AL\u002BeAQCRaADhyQE=","pt":1780316395171,"mc":[{"id":"1.258742455","rc":[{"atl":[[20,14.08]],"batl":[[0,20,14.08]],"id":99072900}]}],"rt":639159131951791501,"dt":639159131951791833}
{"op":"mcm","id":2,"clk":"AMeeAQCcaADpyQE=","pt":1780316395278,"mc":[{"id":"1.258742455","rc":[{"atl":[[5.3,22.68]],"batl":[],"id":99072898},{"tv":13413.37,"batb":[[2,3.4,80.52],[1,3.45,85.56],[0,3.5,118.23]],"trd":[[3.5,155.27],[3.55,812.75]],"ltp":3.5,"atb":[[3.5,118.23],[3.55,0]],"id":88302242}],"tv":38623.61}],"rt":639159131952865504,"dt":639159131952866407}
{"op":"mcm","id":2,"clk":"AM6eAQCfaADwyQE=","pt":1780316395378,"mc":[{"id":"1.258742455","rc":[{"atl":[[5.2,31.1],[4.9,20.42]],"batl":[[0,4.9,20.42]],"id":99072898},{"atl":[[3.6,68.22]],"batl":[[0,3.6,68.22]],"id":88302242}]}],"rt":639159131953865262,"dt":639159131953865741}
{"op":"mcm","id":2,"clk":"ANmeAQCkaAD2yQE=","pt":1780316395480,"mc":[{"id":"1.258742455","rc":[{"batb":[[0,4.8,87.11]],"atb":[[4.8,87.11]],"atl":[[4.9,20.98]],"batl":[[0,4.9,20.98]],"id":99072898},{"batb":[],"atb":[[80,5.71]],"id":99072901},{"batb":[[0,11,16.65]],"atb":[[11,16.65]],"id":97736949}]}],"rt":639159131954884724,"dt":639159131954885121}
{"op":"mcm","id":2,"clk":"AOaeAQCtaAD9yQE=","pt":1780316395586,"mc":[{"id":"1.258742455","rc":[{"batb":[[1,90,9.06]],"atb":[[90,9.06]],"id":99072901},{"batb":[[1,3.45,111.53]],"atb":[[3.45,111.53]],"id":88302242}]}],"rt":639159131955937806,"dt":639159131955938191}
{"op":"mcm","id":2,"clk":"AO\u002BeAQCyaACIygE=","pt":1780316395688,"mc":[{"id":"1.258742455","rc":[{"batb":[],"atb":[[3.35,145.04]],"id":88302242},{"batb":[[0,11,17.1]],"atb":[[11,17.1]],"id":97736949}]}],"rt":639159131956963833,"dt":639159131956964272}
{"op":"mcm","id":2,"clk":"APWeAQC9aACVygE=","pt":1780316395799,"mc":[{"id":"1.258742455","rc":[{"batb":[[0,4.8,87.27]],"atb":[[4.8,87.27]],"id":99072898},{"batb":[[2,85,11.45],[1,90,5.31]],"atb":[[90,5.31],[85,11.45]],"id":99072901},{"batb":[[1,10.5,35.42]],"atb":[[9.4,26.23],[10.5,35.42],[9,6.5]],"atl":[[12.5,27.04],[12,8.36]],"batl":[[2,12.5,27.04],[1,12,8.36]],"id":97736949}]}],"rt":639159131958070763,"dt":639159131958071237}
{"op":"mcm","id":2,"clk":"APqeAQDBaACZygE=","pt":1780316395895,"mc":[{"id":"1.258742455","rc":[{"batb":[[0,95,1.17]],"atb":[[95,1.17]],"id":99072901},{"batb":[],"atb":[[3.3,26.21]],"id":88302242},{"batb":[[0,11,20.24]],"atb":[[11,20.24]],"id":97736949}]}],"rt":639159131959026392,"dt":639159131959026759}
{"op":"mcm","id":2,"clk":"AICfAQDHaACfygE=","pt":1780316395995,"mc":[{"id":"1.258742455","rc":[{"atl":[[11.5,11.85]],"batl":[[0,11.5,11.85]],"id":97736949}]}],"rt":639159131960036336,"dt":639159131960036655}
{"op":"mcm","id":2,"clk":"AIafAQDRaACrygE=","pt":1780316396102,"mc":[{"id":"1.258742455","rc":[{"batb":[[0,4.8,88.84]],"atb":[[4.8,88.84]],"atl":[[4.9,33.47]],"batl":[[0,4.9,33.47]],"id":99072898},{"batb":[[0,4.7,86.81]],"atb":[[4.7,86.81]],"id":10398159},{"batb":[[0,9,34.14]],"atb":[[9,34.14]],"id":98117699},{"batb":[[0,3.5,119.94]],"atb":[[3.5,119.94]],"id":88302242},{"batb":[[1,10.5,33.4]],"atb":[[10.5,33.4]],"atl":[[11.5,7.98]],"batl":[[0,11.5,7.98]],"id":97736949}]}],"rt":639159131961106850,"dt":639159131961107352}
{"op":"mcm","id":2,"clk":"AI\u002BfAQDXaAC1ygE=","pt":1780316396201,"mc":[{"id":"1.258742455","rc":[{"atl":[[11.5,9.13]],"batl":[[0,11.5,9.13]],"id":97736949}]}],"rt":639159131962093144,"dt":639159131962093533}
{"op":"mcm","id":2,"clk":"AJKfAQDcaAC8ygE=","pt":1780316396302,"mc":[{"id":"1.258742455","rc":[{"batb":[[0,4.8,88.36]],"atb":[[4.8,88.36]],"atl":[[4.9,34.7]],"batl":[[0,4.9,34.7]],"id":99072898}]}],"rt":639159131963104176,"dt":639159131963104559}
{"op":"mcm","id":2,"clk":"AJ6fAQDmaADJygE=","pt":1780316396460,"mc":[{"id":"1.258742455","rc":[{"batb":[[2,10,38.85]],"atb":[[10,38.85]],"id":97736949}]}],"rt":639159131964678583,"dt":639159131964678916}
{"op":"mcm","id":2,"clk":"AKefAQDuaADSygE=","pt":1780316396566,"mc":[{"id":"1.258742455","rc":[{"batb":[[0,180,4.58]],"atb":[[180,4.58]],"id":99072897}]}],"rt":639159131965737921,"dt":639159131965738255}
{"op":"mcm","id":2,"clk":"AK2fAQDzaADcygE=","pt":1780316396668,"mc":[{"id":"1.258742455","rc":[{"batb":[[2,3.45,111.53],[1,3.5,119.94],[0,3.55,3]],"atb":[[3.55,3]],"id":88302242},{"tv":2528.68,"batb":[[0,11,16.24]],"trd":[[11,123.13]],"atb":[[11,16.24]],"id":97736949}],"tv":38631.61}],"rt":639159131966767663,"dt":639159131966768083}
{"op":"mcm","id":2,"clk":"ALmfAQD8aADhygE=","pt":1780316396772,"mc":[{"id":"1.258742455","rc":[{"atl":[[4.9,36.7]],"batl":[[0,4.9,36.7]],"id":99072898},{"batb":[[0,50,18.54]],"atb":[[50,18.54]],"id":98464183},{"batb":[[0,3.55,3.48]],"atb":[[3.55,3.48]],"id":88302242},{"tv":2531.98,"batb":[[0,11,7.86]],"trd":[[11,126.43]],"atb":[[11,7.86]],"id":97736949}],"tv":38634.91}],"rt":639159131967802822,"dt":639159131967803486}
{"op":"mcm","id":2,"clk":"AL\u002BfAQCBaQDmygE=","pt":1780316396877,"mc":[{"id":"1.258742455","rc":[{"atl":[[4.9,39.34]],"batl":[[0,4.9,39.34]],"id":99072898},{"atl":[[11.5,12.14]],"batl":[[0,11.5,12.14]],"id":97736949}]}],"rt":639159131968853464,"dt":639159131968853882}
{"op":"mcm","id":2,"clk":"AMefAQCJaQDqygE=","pt":1780316396975,"mc":[{"id":"1.258742455","rc":[{"batb":[[1,4.7,45.64],[0,4.8,86.2]],"atb":[[4.7,45.64],[4.8,86.2]],"atl":[[4.9,51.64],[5,33.03]],"batl":[[1,5,33.03],[0,4.9,51.64]],"id":99072898},{"batb":[],"atb":[[15.5,3.58]],"atl":[[1000,6.66],[25,3.46],[24,3.24],[22,6.13],[21,32.34]],"batl":[[2,22,6.13],[1,21,32.34]],"id":99072900},{"batb":[[1,3.5,119.68]],"atb":[[3.5,119.68]],"atl":[[3.6,69.11]],"batl":[[0,3.6,69.11]],"id":88302242},{"batb":[[1,10.5,31.56],[0,11,9.66]],"atb":[[11,9.66],[10.5,31.56]],"atl":[[1000,1.45],[11.5,12.5]],"batl":[[0,11.5,12.5]],"id":97736949}]}],"rt":639159131969836258,"dt":639159131969836841}
{"op":"mcm","id":2,"clk":"AMyfAQCOaQD1ygE=","pt":1780316397078,"mc":[{"id":"1.258742455","rc":[{"atl":[[1000,6.25]],"id":99072900},{"tv":13413.92,"batb":[[0,3.55,4.38]],"trd":[[3.55,813.3]],"ltp":3.55,"atb":[[3.3,20.21],[3.55,4.38]],"id":88302242},{"atl":[[1000,1]],"id":97736949}],"tv":38635.46}],"rt":639159131970861108,"dt":639159131970861522}
{"op":"mcm","id":2,"clk":"ANKfAQCWaQD7ygE=","pt":1780316397184,"mc":[{"id":"1.258742455","rc":[{"atl":[[20,14.49]],"batl":[[0,20,14.49]],"id":99072900},{"atl":[[9.2,9.35]],"batl":[[0,9.2,9.35]],"id":98117699},{"tv":2541.62,"batb":[[0,11,4.84]],"trd":[[11,136.07]],"atb":[[11,4.84]],"atl":[[12,8.81],[11.5,12.68]],"batl":[[1,12,8.81],[0,11.5,12.68]],"id":97736949}],"tv":38645.1}],"rt":639159131971920151,"dt":639159131971920648}
{"op":"mcm","id":2,"clk":"ANmfAQCZaQCDywE=","pt":1780316397285,"mc":[{"id":"1.258742455","rc":[{"batb":[[0,9,34.89]],"atb":[[9,34.89]],"id":98117699},{"batb":[[0,3.55,14.18]],"atb":[[3.55,14.18]],"id":88302242},{"batb":[[0,11,11.76]],"atb":[[11,11.76]],"id":97736949}]}],"rt":639159131972933504,"dt":639159131972933957}
{"op":"mcm","id":2,"clk":"AN\u002BfAQCjaQCMywE=","pt":1780316397388,"mc":[{"id":"1.258742455","rc":[{"atl":[[19.5,1.86]],"id":99072898},{"batb":[[0,48,6.53]],"atb":[[48,6.53]],"id":97008932},{"tv":898.08,"trd":[[55,99.34]],"atl":[[55,8.96]],"batl":[[0,55,8.96]],"id":98464183},{"atl":[[9.2,8.71]],"batl":[[0,9.2,8.71]],"id":98117699},{"batb":[[0,3.55,15.76]],"atb":[[3.55,15.76],[3.35,151.04]],"id":88302242},{"batb":[[0,11,8.72]],"atb":[[11,8.72]],"atl":[[11.5,14.78]],"batl":[[0,11.5,14.78]],"id":97736949},{"batb":[],"atb":[[720,2],[700,1.29]],"id":10445502}],"tv":38645.12}],"rt":639159131973979983,"dt":639159131973980519}
{"op":"mcm","id":2,"clk":"AOafAQCsaQCSywE=","pt":1780316397492,"mc":[{"id":"1.258742455","rc":[{"atl":[[32,2.18]],"id":99072898},{"batb":[[0,4.7,91.9]],"atb":[[4.7,91.9]],"id":10398159},{"batb":[[0,11,8.56]],"atb":[[11,8.56]],"id":97736949}]}],"rt":639159131975002398,"dt":639159131975002769}
{"op":"mcm","id":2,"clk":"AO6fAQC2aQCYywE=","pt":1780316397598,"mc":[{"id":"1.258742455","rc":[{"tv":558.17,"trd":[[50,79.24]],"atl":[[50,11.86]],"batl":[[0,50,11.86]],"id":97008932}],"tv":38645.14}],"rt":639159131976059548,"dt":639159131976059875}
{"op":"mcm","id":2,"clk":"APefAQDCaQCpywE=","pt":1780316397802,"mc":[{"id":"1.258742455","rc":[{"tv":13423.16,"batb":[[0,3.55,11.14]],"trd":[[3.55,822.54]],"atb":[[3.55,11.14]],"id":88302242}],"tv":38654.38}],"rt":639159131978105588,"dt":639159131978106019}
{"op":"mcm","id":2,"clk":"AIGgAQDFaQC2ywE=","pt":1780316397907,"mc":[{"id":"1.258742455","rc":[{"batb":[[0,11,8.65]],"atb":[[11,8.65]],"id":97736949}]}],"rt":639159131979147127,"dt":639159131979147468}
{"op":"mcm","id":2,"clk":"AJWgAQDVaQDQywE=","pt":1780316398168,"mc":[{"id":"1.258742455","rc":[{"atl":[[4.9,52.99]],"batl":[[0,4.9,52.99]],"id":99072898},{"batb":[[0,11,8.9]],"atb":[[11,8.9]],"id":97736949}]}],"rt":639159131981759719,"dt":639159131981760103}
{"op":"mcm","id":2,"clk":"AJagAQDZaQDXywE=","pt":1780316398268,"mc":[{"id":"1.258742455","rc":[{"batb":[],"atb":[[17.5,30.17]],"id":99072900}]}],"rt":639159131982764203,"dt":639159131982764537}
{"op":"mcm","id":2,"clk":"ANGgAQCMagCTzAE=","pt":1780316399088,"mc":[{"id":"1.258742455","rc":[{"tv":8331.09,"trd":[[4.9,566.04]],"atl":[[4.9,32.99]],"batl":[[0,4.9,32.99]],"id":99072898}],"tv":38694.38}],"rt":639159131990968683,"dt":639159131990969029}
{"op":"mcm","id":2,"clk":"ANSgAQCQagCbzAE=","pt":1780316399191,"mc":[{"id":"1.258742455","rc":[{"tv":8372.11,"batb":[[2,4.7,45.64],[1,4.8,88.73],[0,4.9,12.56]],"trd":[[4.9,607.06]],"atb":[[4.9,12.56],[4.8,88.73]],"atl":[[4.9,0]],"batl":[[2,5.2,31.1],[1,5.1,49.72],[0,5,33.03]],"id":99072898},{"atl":[[9.2,8.97]],"batl":[[0,9.2,8.97]],"id":98117699}],"tv":38735.4}],"rt":639159131991994622,"dt":639159131991995082}
{"op":"mcm","id":2,"clk":"ANugAQCVagClzAE=","pt":1780316399293,"mc":[{"id":"1.258742455","rc":[{"batb":[[2,4.7,48.39],[0,4.9,27.32]],"atb":[[4.7,48.39],[4.9,27.32],[4.6,75.07]],"id":99072898},{"atl":[[9.2,12.72]],"batl":[[0,9.2,12.72]],"id":98117699}]}],"rt":639159131993009700,"dt":639159131993010048}
{"op":"mcm","id":2,"clk":"AOegAQCaagCwzAE=","pt":1780316399409,"mc":[{"id":"1.258742455","rc":[{"tv":8376.01,"batb":[[0,4.9,28.12]],"trd":[[4.9,610.96]],"atb":[[4.9,28.12]],"id":99072898},{"atl":[[20,14.99]],"batl":[[0,20,14.99]],"id":99072900},{"batb":[],"atb":[[4.4,184.48]],"id":10398159},{"batb":[[0,3.55,9.56]],"atb":[[3.55,9.56]],"id":88302242},{"batb":[[0,11,8.56]],"atb":[[11,8.56]],"id":97736949}],"tv":38739.3}],"rt":639159131994169443,"dt":639159131994170086}
{"op":"mcm","id":2,"clk":"AOigAQCdagC2zAE=","pt":1780316399499,"mc":[{"id":"1.258742455","rc":[{"batb":[[1,4.8,93.89],[0,4.9,28.82]],"atb":[[4.9,28.82],[4.8,93.89]],"atl":[[5.3,16.68],[5,32.54]],"batl":[[0,5,32.54]],"id":99072898},{"atl":[[20,16.55]],"batl":[[0,20,16.55]],"id":99072900},{"tv":8590.73,"batb":[[0,4.7,89.31]],"trd":[[4.7,1181.95]],"atb":[[4.7,89.31]],"id":10398159},{"atl":[[9.2,13.81]],"batl":[[0,9.2,13.81]],"id":98117699}],"tv":38744.49}],"rt":639159131995076465,"dt":639159131995076983}
{"op":"mcm","id":2,"clk":"APGgAQCnagDEzAE=","pt":1780316399605,"mc":[{"id":"1.258742455","rc":[{"batb":[[0,4.9,28.12]],"atb":[[4.4,19.57],[4.9,28.12]],"id":99072898},{"batb":[[0,48,4.8]],"atb":[[48,4.8]],"id":97008932},{"batb":[[0,4.7,61.63]],"atb":[[4.7,61.63]],"id":10398159},{"batb":[[0,50,15.95]],"atb":[[50,15.95]],"id":98464183},{"batb":[[0,9,27.11]],"atb":[[9,27.11]],"id":98117699},{"batb":[[0,11,9.19]],"atb":[[11,9.19]],"atl":[[11.5,15.66]],"batl":[[0,11.5,15.66]],"id":97736949},{"batb":[[0,180,3.72]],"atb":[[180,3.72]],"id":99072897}]}],"rt":639159131996138320,"dt":639159131996138925}
{"op":"mcm","id":2,"clk":"APWgAQCpagDIzAE=","pt":1780316399704,"mc":[{"id":"1.258742455","rc":[{"atl":[[5.4,40.63]],"batl":[],"id":99072898},{"batb":[[0,48,5.03]],"atb":[[48,5.03]],"id":97008932},{"batb":[[0,19,12.25]],"atb":[[19,12.25]],"id":99072900},{"batb":[[0,95,1.29]],"atb":[[95,1.29]],"id":99072901},{"batb":[[0,50,16.17]],"atb":[[50,16.17]],"id":98464183},{"batb":[[0,11,10.2]],"atb":[[11,10.2]],"id":97736949},{"batb":[[0,180,3.78]],"atb":[[180,3.78]],"id":99072897}]}],"rt":639159131997120065,"dt":639159131997120657}
{"op":"mcm","id":2,"clk":"APugAQCsagDPzAE=","pt":1780316399814,"mc":[{"id":"1.258742455","rc":[{"batb":[[0,4.9,28.34]],"atb":[[4.9,28.34]],"id":99072898},{"atl":[[50,11.89]],"batl":[[0,50,11.89]],"id":97008932},{"atl":[[4.8,47.64]],"batl":[[0,4.8,47.64]],"id":10398159},{"atl":[[9.2,16.26]],"batl":[[0,9.2,16.26]],"id":98117699},{"batb":[[0,3.55,10.35]],"atb":[[3.55,10.35]],"id":88302242},{"tv":2541.99,"trd":[[11.5,54.96]],"ltp":11.5,"atl":[[11.5,15.47]],"batl":[[0,11.5,15.47]],"id":97736949}],"tv":38744.86}],"rt":639159131998220997,"dt":639159131998221535}
{"op":"mcm","id":2,"clk":"AIChAQCyagDTzAE=","pt":1780316399909,"mc":[{"id":"1.258742455","rc":[{"batb":[],"atb":[[4.5,53.66]],"id":99072898},{"batb":[[0,9,26.75]],"atb":[[9,26.75]],"id":98117699},{"atb":[[2.54,4.39]],"id":88302242},{"batb":[[0,11,10.29]],"atb":[[11,10.29]],"id":97736949}]}],"rt":639159131999170115,"dt":639159131999170570}
{"op":"mcm","id":2,"clk":"AIehAQC2agDazAE=","pt":1780316399971,"mc":[{"id":"1.258742455","rc":[{"batb":[[0,4.9,28.58]],"atb":[[4.9,28.58]],"id":99072898},{"batb":[[0,48,5.44]],"atb":[[48,5.44]],"id":97008932},{"batb":[[0,19,14.95]],"atb":[[19,14.95]],"id":99072900},{"batb":[[0,95,1.41]],"atb":[[95,1.41]],"id":99072901},{"batb":[[0,9,24.9]],"atb":[[9,24.9]],"id":98117699},{"tv":13427.16,"batb":[[0,3.55,8.35]],"trd":[[3.55,826.54]],"atb":[[3.55,8.35]],"id":88302242},{"batb":[[0,11,24.04]],"atb":[[11,24.04]],"id":97736949}],"tv":38748.86}],"rt":639159131999842656,"dt":639159131999843289}
{"op":"mcm","id":2,"clk":"AI\u002BhAQC5agDgzAE=","pt":1780316400067,"mc":[{"id":"1.258742455","rc":[{"atl":[[20,20]],"id":99072898},{"atl":[[300,20]],"id":99072900},{"atl":[[19,20.55],[4.8,48.16]],"batl":[[0,4.8,48.16]],"id":10398159},{"batb":[[0,9,22.4]],"atb":[[9,22.4]],"atl":[[80,20]],"id":98117699},{"batb":[[2,3.4,80.52],[1,3.45,111.53],[0,3.5,120.47]],"atb":[[3.55,0.79]],"atl":[[11,44.13]],"id":88302242},{"tv":2542.99,"trd":[[11.5,55.96]],"atl":[[11.5,14.97],[130,20]],"batl":[[0,11.5,14.97]],"id":97736949}],"tv":38749.86}],"rt":639159132000751808,"dt":639159132000752375}
{"op":"mcm","id":2,"clk":"AJehAQC\u002BagDmzAE=","pt":1780316400174,"mc":[{"id":"1.258742455","rc":[{"atl":[[5,30.21]],"batl":[[0,5,30.21]],"id":99072898},{"atl":[[50,11.94]],"batl":[[0,50,11.94]],"id":97008932},{"batb":[[0,9,22.77]],"atb":[[9,22.77]],"atl":[[9.2,16.94]],"batl":[[0,9.2,16.94]],"id":98117699},{"batb":[[0,3.5,110.75]],"atb":[[3.5,110.75],[3.55,0]],"id":88302242},{"batb":[[0,11,27.86]],"atb":[[11,27.86]],"atl":[[11.5,14.1]],"batl":[[0,11.5,14.1]],"id":97736949}]}],"rt":639159132001826623,"dt":639159132001827184}
{"op":"mcm","id":2,"clk":"AJuhAQDEagDrzAE=","pt":1780316400276,"mc":[{"id":"1.258742455","rc":[{"batb":[[2,4.7,51.51]],"atb":[[4.7,51.51]],"id":99072898},{"atl":[[4.8,49.49]],"batl":[[0,4.8,49.49]],"id":10398159},{"batb":[[0,11,36.32]],"atb":[[11,36.32]],"id":97736949}]}],"rt":639159132002844718,"dt":639159132002845196}
{"op":"mcm","id":2,"clk":"AKehAQDGagDzzAE=","pt":1780316400376,"mc":[{"id":"1.258742455","rc":[{"batb":[[0,4.7,66.76]],"atb":[[4.7,66.76]],"id":10398159},{"batb":[[0,9,22.4]],"atb":[[9,22.4]],"id":98117699},{"batb":[],"atb":[[3.35,145.04]],"id":88302242},{"atb":[[1.17,2.25]],"id":97736949}]}],"rt":639159132003842712,"dt":639159132003843203}
{"op":"mcm","id":2,"clk":"AK\u002BhAQDMagD9zAE=","pt":1780316400480,"mc":[{"id":"1.258742455","rc":[{"batb":[[0,48,5.16]],"atb":[[48,5.16]],"atl":[[50,12.02]],"batl":[[0,50,12.02]],"id":97008932},{"batb":[[0,11,37.04]],"atb":[[11,37.04]],"atl":[[13,6.48]],"batl":[],"id":97736949}]}],"rt":639159132004880178,"dt":639159132004880663}
{"op":"mcm","id":2,"clk":"ALOhAQDRagCFzQE=","pt":1780316400581,"mc":[{"id":"1.258742455","rc":[{"batb":[[0,9,12.64]],"atb":[[9,12.64]],"id":98117699},{"batb":[],"atb":[[3.3,26.21]],"id":88302242},{"atb":[[1.17,2]],"id":97736949}]}],"rt":639159132005891530,"dt":639159132005892012}
{"op":"mcm","id":2,"clk":"ALuhAQDWagCNzQE=","pt":1780316400683,"mc":[{"id":"1.258742455","rc":[{"batb":[[0,4.9,28.88]],"atb":[[4.9,28.88]],"id":99072898},{"atl":[[26,2.15],[24,19.21]],"batl":[],"id":99072900},{"batb":[[0,9,9.24]],"atb":[[9,9.24]],"atl":[[9.2,17.99]],"batl":[[0,9.2,17.99]],"id":98117699},{"atl":[[3.55,1]],"batl":[[2,3.65,49.23],[1,3.6,69.11],[0,3.55,1]],"id":88302242},{"batb":[[0,11,37.29]],"atb":[[11,37.29]],"id":97736949}]}],"rt":639159132006913644,"dt":639159132006914267}
{"op":"mcm","id":2,"clk":"ALyhAQDZagCPzQE=","pt":1780316400780,"mc":[{"id":"1.258742455","rc":[{"batb":[],"atb":[[44,8.95]],"id":98464183}]}],"rt":639159132007882759,"dt":639159132007883192}
{"op":"mcm","id":2,"clk":"AMChAQDbagCVzQE=","pt":1780316400880,"mc":[{"id":"1.258742455","rc":[{"atl":[[4.8,48.97]],"batl":[[0,4.8,48.97]],"id":10398159},{"tv":13429.16,"trd":[[3.55,828.54]],"atb":[[1.17,196.49]],"atl":[[3.55,0]],"batl":[[2,3.7,220.83],[1,3.65,49.23],[0,3.6,69.11]],"id":88302242}],"tv":38751.86}],"rt":639159132008883017,"dt":639159132008883494}
{"op":"mcm","id":2,"clk":"AMihAQDiagCbzQE=","pt":1780316400988,"mc":[{"id":"1.258742455","rc":[{"atl":[[11.5,13.22]],"batl":[[0,11.5,13.22]],"id":97736949}]}],"rt":639159132009986302,"dt":639159132009986698}
{"op":"mcm","id":2,"clk":"AM\u002BhAQDqagCizQE=","pt":1780316401087,"mc":[{"id":"1.258742455","rc":[{"atb":[[1.17,196.12]],"id":88302242}]}],"rt":639159132010947195,"dt":639159132010947631}
{"op":"mcm","id":2,"clk":"ANWhAQDsagCszQE=","pt":1780316401187,"mc":[{"id":"1.258742455","rc":[{"batb":[[0,3.5,111.12]],"atb":[[3.55,0.37]],"atl":[[3.8,89.22]],"batl":[],"id":88302242}]}],"rt":639159132011956563,"dt":639159132011957031}
{"op":"mcm","id":2,"clk":"ANmhAQDxagC0zQE=","pt":1780316401299,"mc":[{"id":"1.258742455","rc":[{"atl":[[11.5,15.29]],"batl":[[0,11.5,15.29]],"id":97736949}]}],"rt":639159132013074230,"dt":639159132013074643}
{"op":"mcm","id":2,"clk":"AOChAQDzagC8zQE=","pt":1780316401396,"mc":[{"id":"1.258742455","rc":[{"batb":[],"atb":[[4.2,116.79]],"id":99072898},{"batb":[],"atb":[[4,25.82]],"id":10398159},{"atl":[[3.75,73.44]],"batl":[],"id":88302242}]}],"rt":639159132014046438,"dt":639159132014046795}
{"op":"mcm","id":2,"clk":"AOShAQD4agDFzQE=","pt":1780316401497,"mc":[{"id":"1.258742455","rc":[{"batb":[[0,4.7,71.8]],"atb":[[4.7,71.8]],"id":10398159}]}],"rt":639159132015055426,"dt":639159132015055831}
{"op":"mcm","id":2,"clk":"AO2hAQD7agDPzQE=","pt":1780316401606,"mc":[{"id":"1.258742455","rc":[{"batb":[[0,50,16.22]],"atb":[[50,16.22]],"id":98464183},{"batb":[[0,3.5,110.75]],"atb":[[3.05,297.07],[3.55,0]],"id":88302242},{"batb":[[0,11,36.87]],"atb":[[11,36.87]],"atl":[[1000,1.63]],"id":97736949}]}],"rt":639159132016144323,"dt":639159132016144861}
{"op":"mcm","id":2,"clk":"APKhAQD/agDZzQE=","pt":1780316401709,"mc":[{"id":"1.258742455","rc":[{"atl":[[1000,1]],"id":97736949}]}],"rt":639159132017174161,"dt":639159132017174604}
{"op":"mcm","id":2,"clk":"APWhAQCFawDhzQE=","pt":1780316401807,"mc":[{"id":"1.258742455","rc":[{"batb":[],"atb":[[7.6,124.31]],"id":98117699},{"atl":[[3.6,69.95]],"batl":[[0,3.6,69.95]],"id":88302242},{"batb":[],"atb":[[9.4,25.7]],"atl":[[11.5,15.92]],"batl":[[0,11.5,15.92]],"id":97736949}]}],"rt":639159132018158149,"dt":639159132018158631}
{"op":"mcm","id":2,"clk":"APmhAQCLawDnzQE=","pt":1780316401908,"mc":[{"id":"1.258742455","rc":[{"atl":[[11.5,16.12]],"batl":[[0,11.5,16.12]],"id":97736949}]}],"rt":639159132019163255,"dt":639159132019163621}
{"op":"mcm","id":2,"clk":"AP\u002BhAQCQawDvzQE=","pt":1780316402012,"mc":[{"id":"1.258742455","rc":[{"batb":[],"atb":[[4.2,117.98]],"id":99072898},{"batb":[],"atb":[[40,10.16]],"id":97008932},{"batb":[[2,18,12.95]],"atb":[[18,12.95]],"id":99072900},{"batb":[],"atb":[[4,27.07]],"id":10398159},{"batb":[],"atb":[[7.6,124.97]],"id":98117699},{"batb":[],"atb":[[3.05,298.71]],"atl":[[3.75,67.44]],"batl":[],"id":88302242},{"batb":[],"atb":[[9.8,16.32]],"id":97736949}]}],"rt":639159132020197655,"dt":639159132020198296}
{"op":"mcm","id":2,"clk":"AIaiAQCTawD2zQE=","pt":1780316402112,"mc":[{"id":"1.258742455","rc":[{"batb":[[0,48,5.2]],"atb":[[48,5.2]],"id":97008932},{"tv":2364.04,"batb":[[0,9,4.24]],"trd":[[9,66.15]],"atb":[[9,4.24]],"id":98117699}],"tv":38761.86}],"rt":639159132021207651,"dt":639159132021208085}
{"op":"mcm","id":2,"clk":"AI2iAQCYawD7zQE=","pt":1780316402167,"mc":[{"id":"1.258742455","rc":[{"atl":[[5,140.98]],"batl":[[2,5,140.98]],"id":10398159},{"atl":[[3.8,95.22]],"batl":[],"id":88302242},{"atb":[[6.6,2.88]],"id":97736949}]}],"rt":639159132021750260,"dt":639159132021750654}
{"op":"mcm","id":2,"clk":"AJmiAQCcawCBzgE=","pt":1780316402272,"mc":[{"id":"1.258742455","rc":[{"batb":[],"atb":[[4.5,46.76]],"id":99072898},{"batb":[],"atb":[[42,14.79]],"id":97008932},{"batb":[],"atb":[[16.5,3.9]],"id":99072900},{"tv":898.1,"trd":[[55,99.36]],"atl":[[55,8.95]],"batl":[[0,55,8.95]],"id":98464183},{"tv":2364.5,"batb":[[0,9,4.01]],"trd":[[9,66.61]],"atb":[[8.2,15.4],[9,4.01]],"id":98117699},{"atl":[[3.75,63.78]],"batl":[],"id":88302242}],"tv":38762.34}],"rt":639159132022802846,"dt":639159132022803393}
{"op":"mcm","id":2,"clk":"AJ\u002BiAQCkawCHzgE=","pt":1780316402372,"mc":[{"id":"1.258742455","rc":[{"tv":2366.81,"batb":[[0,9,2.85]],"trd":[[9,68.92]],"atb":[[9,2.85]],"id":98117699}],"tv":38764.65}],"rt":639159132023806587,"dt":639159132023807024}
{"op":"mcm","id":2,"clk":"AKWiAQCqawCOzgE=","pt":1780316402474,"mc":[{"id":"1.258742455","rc":[{"batb":[[0,4.9,38.88]],"atb":[[4.9,38.88]],"id":99072898},{"atl":[[21,33.67]],"batl":[[1,21,33.67]],"id":99072900},{"tv":2372.51,"batb":[[2,8.4,10.21],[1,8.6,18.75],[0,8.8,20.57]],"trd":[[9,74.62]],"atb":[[9,0]],"atl":[[9,5.58]],"batl":[[2,9.4,14.51],[1,9.2,17.99],[0,9,5.58]],"id":98117699},{"batb":[],"atb":[[720,0],[700,3.29]],"id":10445502}],"tv":38770.35}],"rt":639159132024822517,"dt":639159132024823172}
{"op":"mcm","id":2,"clk":"AK2iAQCvawCYzgE=","pt":1780316402581,"mc":[{"id":"1.258742455","rc":[{"atl":[[5,32.21]],"batl":[[0,5,32.21]],"id":99072898},{"batb":[],"atb":[[4.4,187.32]],"id":10398159},{"batb":[[2,8.4,18.98],[0,8.8,19.57]],"atb":[[8.4,18.98],[8.8,19.57]],"atl":[[9.4,11.65],[9,9.17]],"batl":[[2,9.4,11.65],[0,9,9.17]],"id":98117699},{"batb":[[0,3.5,114.5]],"atb":[[3.5,114.5]],"id":88302242}]}],"rt":639159132025894104,"dt":639159132025894522}
{"op":"mcm","id":2,"clk":"ALKiAQC1awCizgE=","pt":1780316402682,"mc":[{"id":"1.258742455","rc":[{"atl":[[10,26.16]],"batl":[],"id":98117699}]}],"rt":639159132026902220,"dt":639159132026902592}
{"op":"mcm","id":2,"clk":"ALuiAQC7awCtzgE=","pt":1780316402786,"mc":[{"id":"1.258742455","rc":[{"atl":[[9.2,9.53],[10,20.16],[9,19.17]],"batl":[[1,9.2,9.53],[0,9,19.17]],"id":98117699},{"atl":[[14,6.64]],"batl":[],"id":97736949}]}],"rt":639159132027944285,"dt":639159132027944660}
{"op":"mcm","id":2,"clk":"AL6iAQC\u002BawC0zgE=","pt":1780316402884,"mc":[{"id":"1.258742455","rc":[{"atl":[[9,19.34]],"batl":[[0,9,19.34]],"id":98117699},{"tv":243.55,"batb":[[0,180,3.68]],"trd":[[180,58.23]],"atb":[[180,3.68]],"id":99072897}],"tv":38770.56}],"rt":639159132028927185,"dt":639159132028927645}
{"op":"mcm","id":2,"clk":"AMeiAQDDawDAzgE=","pt":1780316402988,"mc":[{"id":"1.258742455","rc":[{"batb":[[2,4.7,48.95],[1,4.8,95.79],[0,4.9,40.28]],"atb":[[4.7,48.95],[4.9,40.28],[4.8,95.79]],"atl":[[32,0]],"id":99072898},{"atl":[[20,16.14]],"batl":[[0,20,16.14]],"id":99072900},{"batb":[[0,95,1.29]],"atb":[[95,1.29]],"id":99072901},{"batb":[],"atb":[[8.2,9.4]],"atl":[[9.4,11.4],[1000,6.82],[9.8,16.07],[9.2,9.28]],"batl":[[2,9.4,11.4],[1,9.2,9.28]],"id":98117699},{"batb":[[1,3.45,119.09]],"atb":[[3.45,119.09]],"id":88302242},{"atl":[[1000,1.27]],"id":97736949}]}],"rt":639159132029965269,"dt":639159132029965867}
{"op":"mcm","id":2,"clk":"AMyiAQDFawDGzgE=","pt":1780316403093,"mc":[{"id":"1.258742455","rc":[{"atl":[[19.5,4.04]],"id":99072898},{"tv":906.88,"trd":[[55,108.14]],"atl":[[55,4.56]],"batl":[[0,55,4.56]],"id":98464183},{"atl":[[1000,6.25]],"id":98117699},{"atl":[[1000,1]],"id":97736949}],"tv":38779.34}],"rt":639159132031013286,"dt":639159132031013743}
{"op":"mcm","id":2,"clk":"ANGiAQDGawDOzgE=","pt":1780316403193,"mc":[{"id":"1.258742455","rc":[{"batb":[],"atb":[[8,60.4]],"atl":[[9.2,9.63],[9,19.56]],"batl":[[1,9.2,9.63],[0,9,19.56]],"id":98117699},{"atl":[[11.5,16.39]],"batl":[[0,11.5,16.39]],"id":97736949}]}],"rt":639159132032010351,"dt":639159132032010805}
{"op":"mcm","id":2,"clk":"ANaiAQDMawDTzgE=","pt":1780316403295,"mc":[{"id":"1.258742455","rc":[{"batb":[[0,50,18.28]],"atb":[[50,18.28]],"atl":[[55,5.1]],"batl":[[0,55,5.1]],"id":98464183},{"atl":[[9,19.77]],"batl":[[0,9,19.77]],"id":98117699},{"batb":[[0,1000,92.05]],"atb":[[1000,92.05]],"id":10445502}]}],"rt":639159132033029885,"dt":639159132033030380}
{"op":"mcm","id":2,"clk":"AOOiAQDYawDdzgE=","pt":1780316403498,"mc":[{"id":"1.258742455","rc":[{"batb":[],"atb":[[4.5,44.76]],"id":99072898},{"atl":[[5.1,56.16]],"batl":[],"id":10398159}]}],"rt":639159132035061402,"dt":639159132035061822}
{"op":"mcm","id":2,"clk":"AOuiAQDfawDlzgE=","pt":1780316403604,"mc":[{"id":"1.258742455","rc":[{"batb":[[0,4.9,42.28]],"atb":[[4.9,42.28]],"id":99072898}]}],"rt":639159132036116014,"dt":639159132036116454}
{"op":"mcm","id":2,"clk":"APqiAQDpawCAzwE=","pt":1780316403912,"mc":[{"id":"1.258742455","rc":[{"atl":[[5.1,50.42],[4.8,50.05]],"batl":[[0,4.8,50.05]],"id":10398159}]}],"rt":639159132039199972,"dt":639159132039200441}
{"op":"mcm","id":2,"clk":"AIajAQD1awCVzwE=","pt":1780316404070,"mc":[{"id":"1.258742455","rc":[{"batb":[[2,3.4,88.49]],"atb":[[3.4,88.49]],"atl":[[3.8,102.48]],"batl":[],"id":88302242}]}],"rt":639159132040780692,"dt":639159132040781038}
{"op":"mcm","id":2,"clk":"AJOjAQD8awCbzwE=","pt":1780316404176,"mc":[{"id":"1.258742455","rc":[{"atl":[[5,90.98]],"batl":[[2,5,90.98]],"id":10398159}]}],"rt":639159132041845394,"dt":639159132041845737}
{"op":"mcm","id":2,"clk":"AJ2jAQCBbACozwE=","pt":1780316404280,"mc":[{"id":"1.258742455","rc":[{"atl":[[9,20.77]],"batl":[[0,9,20.77]],"id":98117699}]}],"rt":639159132042882586,"dt":639159132042882972}
{"op":"mcm","id":2,"clk":"AKajAQCEbACuzwE=","pt":1780316404377,"mc":[{"id":"1.258742455","rc":[{"atl":[[9,23.21]],"batl":[[0,9,23.21]],"id":98117699}]}],"rt":639159132043850697,"dt":639159132043851019}
{"op":"mcm","id":2,"clk":"AKmjAQCKbAC6zwE=","pt":1780316404481,"mc":[{"id":"1.258742455","rc":[{"atl":[[5,22.42]],"batl":[[0,5,22.42]],"id":99072898},{"atl":[[50,11.97]],"batl":[[0,50,11.97]],"id":97008932},{"atl":[[22,13.29]],"batl":[[2,22,13.29]],"id":99072900},{"atl":[[4.8,49.51]],"batl":[[0,4.8,49.51]],"id":10398159},{"batb":[[1,8.6,22.61]],"atb":[[8.6,22.61]],"atl":[[9,23.56],[9.6,26.7]],"batl":[[0,9,23.56]],"id":98117699}]}],"rt":639159132044890355,"dt":639159132044890840}
{"op":"mcm","id":2,"clk":"ALujAQCRbADJzwE=","pt":1780316404686,"mc":[{"id":"1.258742455","rc":[{"batb":[[0,4.9,42.84]],"atb":[[4.9,42.84]],"id":99072898},{"batb":[[1,48,11.84]],"atb":[[48,11.84]],"id":98464183},{"batb":[],"atb":[[3.35,153.28]],"atl":[[3.85,39.63]],"batl":[],"id":88302242}]}],"rt":639159132046955304,"dt":639159132046955748}
{"op":"mcm","id":2,"clk":"AMCjAQCSbADRzwE=","pt":1780316404784,"mc":[{"id":"1.258742455","rc":[{"atl":[[5,17.01]],"batl":[[0,5,17.01]],"id":99072898},{"atl":[[60,8.87]],"batl":[[2,60,8.87]],"id":97008932}]}],"rt":639159132047925523,"dt":639159132047925921}
{"op":"mcm","id":2,"clk":"AMejAQCXbADbzwE=","pt":1780316404889,"mc":[{"id":"1.258742455","rc":[{"batb":[[0,4.9,44.84]],"atb":[[4.9,44.84]],"atl":[[5,19.27]],"batl":[[0,5,19.27]],"id":99072898},{"tv":1181.23,"batb":[[0,19,9.95]],"trd":[[19,41.87]],"ltp":19,"atb":[[19,9.95]],"atl":[[29,3.93]],"batl":[],"id":99072900},{"batb":[],"atb":[[8.2,18.17]],"atl":[[11,2.48]],"batl":[],"id":98117699},{"tv":13439.16,"batb":[[0,3.5,109.5]],"trd":[[3.5,165.27]],"ltp":3.5,"atb":[[3.5,109.5]],"id":88302242}],"tv":38799.34}],"rt":639159132048977421,"dt":639159132048977950}
{"op":"mcm","id":2,"clk":"AMqjAQCZbADjzwE=","pt":1780316404991,"mc":[{"id":"1.258742455","rc":[{"atl":[[20,16.83]],"batl":[[0,20,16.83]],"id":99072900}]}],"rt":639159132049989360,"dt":639159132049989797}
{"op":"mcm","id":2,"clk":"AM6jAQCdbADrzwE=","pt":1780316405094,"mc":[{"id":"1.258742455","rc":[{"batb":[[0,4.9,53.24]],"atb":[[4.9,53.24]],"id":99072898},{"batb":[[0,19,13.19]],"atb":[[19,13.19]],"id":99072900},{"batb":[],"atb":[[3.3,34.81]],"atl":[[3.9,16.27]],"batl":[],"id":88302242}]}],"rt":639159132051022392,"dt":639159132051022980}
{"op":"mcm","id":2,"clk":"ANejAQCkbAD9zwE=","pt":1780316405299,"mc":[{"id":"1.258742455","rc":[{"atl":[[110,6.21]],"batl":[[1,110,6.21]],"id":99072901},{"atl":[[190,0.45]],"batl":[[2,230,1.09],[1,220,1.88],[0,200,1]],"id":99072897}]}],"rt":639159132053070422,"dt":639159132053070826}
{"op":"mcm","id":2,"clk":"AN2jAQCqbACM0AE=","pt":1780316405406,"mc":[{"id":"1.258742455","rc":[{"batb":[[0,4.9,53.93]],"atb":[[4.9,53.93]],"id":99072898},{"tv":1184.23,"batb":[[0,19,11.69]],"trd":[[19,44.87]],"atb":[[19,11.69]],"id":99072900}],"tv":38802.34}],"rt":639159132054144808,"dt":639159132054145341}
{"op":"mcm","id":2,"clk":"AOKjAQCtbACX0AE=","pt":1780316405509,"mc":[{"id":"1.258742455","rc":[{"batb":[[0,180,3.78]],"atb":[[180,3.78]],"atl":[[1000,10.75],[190,0.25]],"batl":[[1,220,1.13],[0,210,1.55]],"id":99072897}]}],"rt":639159132055166867,"dt":639159132055167305}
{"op":"mcm","id":2,"clk":"AOyjAQCybACq0AE=","pt":1780316405711,"mc":[{"id":"1.258742455","rc":[{"atl":[[1000,9.75]],"batl":[],"id":99072897}]}],"rt":639159132057194224,"dt":639159132057194595}
{"op":"mcm","id":2,"clk":"APGjAQC2bACy0AE=","pt":1780316405816,"mc":[{"id":"1.258742455","rc":[{"batb":[],"atb":[[7.8,6.03]],"id":98117699}]}],"rt":639159132058237668,"dt":639159132058238068}
{"op":"mcm","id":2,"clk":"APSjAQC4bAC40AE=","pt":1780316405865,"mc":[{"id":"1.258742455","rc":[{"atl":[[1000,8.75]],"batl":[],"id":99072897}]}],"rt":639159132058737521,"dt":639159132058737889}
{"op":"mcm","id":2,"clk":"APmjAQC8bADD0AE=","pt":1780316405971,"mc":[{"id":"1.258742455","rc":[{"atl":[[5,28.58]],"batl":[[0,5,28.58]],"id":99072898},{"tv":1188.47,"batb":[[0,19,6.87]],"trd":[[19,49.11]],"atb":[[19,6.87]],"atl":[[27,5.96]],"batl":[],"id":99072900},{"batb":[[0,8.8,21.03]],"atb":[[8.8,21.03]],"id":98117699},{"atb":[[1.17,196.3]],"id":88302242},{"atl":[[270,1]],"batl":[],"id":99072897}],"tv":38806.58}],"rt":639159132059790878,"dt":639159132059791376}
{"op":"mcm","id":2,"clk":"AICkAQC\u002BbADN0AE=","pt":1780316406072,"mc":[{"id":"1.258742455","rc":[{"atl":[[19.5,3.25]],"batl":[[2,21,33.67],[1,20,16.83],[0,19.5,3.25]],"id":99072900},{"atb":[[1.17,196.12]],"id":88302242}]}],"rt":639159132060804647,"dt":639159132060805051}
{"op":"mcm","id":2,"clk":"AIekAQDEbADW0AE=","pt":1780316406178,"mc":[{"id":"1.258742455","rc":[{"batb":[[0,19,5.55]],"atb":[[19,5.55],[1.01,69860.23],[17,70.52]],"atl":[[23,12.01]],"batl":[],"id":99072900},{"batb":[],"atb":[[7.8,22.61]],"id":98117699},{"batb":[[0,3.5,109.68]],"atb":[[3.5,109.68],[3.15,22.21]],"id":88302242}]}],"rt":639159132061863472,"dt":639159132061863906}
{"op":"mcm","id":2,"clk":"AIykAQDHbADi0AE=","pt":1780316406275,"mc":[{"id":"1.258742455","rc":[{"batb":[[0,19,3.82]],"atb":[[19,3.82]],"id":99072900}]}],"rt":639159132062829286,"dt":639159132062829694}
{"op":"mcm","id":2,"clk":"AJWkAQDPbADu0AE=","pt":1780316406378,"mc":[{"id":"1.258742455","rc":[{"atl":[[50,11.89]],"batl":[[0,50,11.89]],"id":97008932},{"batb":[],"atb":[[17,72.67]],"atl":[[19.5,4.37]],"batl":[[0,19.5,4.37]],"id":99072900}]}],"rt":639159132063865442,"dt":639159132063865847}
{"op":"mcm","id":2,"clk":"AKakAQDWbACC0QE=","pt":1780316406585,"mc":[{"id":"1.258742455","rc":[{"batb":[[2,17.5,30.17],[1,18,12.95],[0,18.5,13.21]],"atb":[[19,0.58]],"id":99072900}]}],"rt":639159132065928367,"dt":639159132065928721}
{"op":"mcm","id":2,"clk":"ALCkAQDabACN0QE=","pt":1780316406689,"mc":[{"id":"1.258742455","rc":[{"tv":2546.3,"batb":[[0,11,35.22]],"trd":[[11,139.38]],"ltp":11,"atb":[[11,35.22]],"id":97736949}],"tv":38809.89}],"rt":639159132066974836,"dt":639159132066975234}
{"op":"mcm","id":2,"clk":"ALqkAQDebACX0QE=","pt":1780316406792,"mc":[{"id":"1.258742455","rc":[{"batb":[],"atb":[[17,61.86]],"id":99072900},{"atl":[[4.8,47.1]],"batl":[[0,4.8,47.1]],"id":10398159},{"batb":[[0,11,28.48]],"atb":[[11,28.48]],"atl":[[12.5,28.07]],"batl":[[2,12.5,28.07]],"id":97736949}]}],"rt":639159132068007955,"dt":639159132068008482}
{"op":"mcm","id":2,"clk":"AMakAQDlbACe0QE=","pt":1780316406895,"mc":[{"id":"1.258742455","rc":[{"tv":8614.79,"trd":[[4.8,527.59]],"ltp":4.8,"atl":[[4.8,35.07]],"batl":[[0,4.8,35.07]],"id":10398159},{"batb":[[0,3.5,110.73]],"atb":[[3.5,110.73]],"id":88302242}],"tv":38833.95}],"rt":639159132069031619,"dt":639159132069032026}
{"op":"mcm","id":2,"clk":"AM2kAQDobACk0QE=","pt":1780316406996,"mc":[{"id":"1.258742455","rc":[{"atl":[[4.8,16.28]],"batl":[[0,4.8,16.28]],"id":10398159}]}],"rt":639159132070044164,"dt":639159132070044598}
{"op":"mcm","id":2,"clk":"ANekAQDsbACt0QE=","pt":1780316407096,"mc":[{"id":"1.258742455","rc":[{"batb":[[0,3.5,119.36]],"atb":[[3.5,119.36]],"id":88302242}]}],"rt":639159132071041410,"dt":639159132071041749}
{"op":"mcm","id":2,"clk":"AOGkAQDwbAC20QE=","pt":1780316407200,"mc":[{"id":"1.258742455","rc":[{"tv":8379.47,"batb":[[0,4.9,52.2]],"trd":[[4.9,614.42]],"atb":[[4.9,52.2]],"id":99072898},{"tv":13489.16,"batb":[[0,3.5,94.36]],"trd":[[3.5,215.27]],"atb":[[3.5,94.36]],"id":88302242}],"tv":38887.41}],"rt":639159132072081802,"dt":639159132072082259}
{"op":"mcm","id":2,"clk":"AOikAQDybADA0QE=","pt":1780316407302,"mc":[{"id":"1.258742455","rc":[{"tv":1189.63,"batb":[[0,18.5,12.63]],"trd":[[19,50.27]],"atb":[[19,0]],"atl":[[19,0.29]],"batl":[[0,19.5,4.66]],"id":99072900}],"tv":38888.57}],"rt":639159132073102846,"dt":639159132073103237}
{"op":"mcm","id":2,"clk":"APKkAQD4bADG0QE=","pt":1780316407404,"mc":[{"id":"1.258742455","rc":[{"atl":[[50,11.86]],"batl":[[0,50,11.86]],"id":97008932},{"tv":1192.2,"batb":[[2,18,12.95],[1,18.5,12.63],[0,19,2.53]],"trd":[[19,52.84]],"atb":[[19,2.53],[17.5,34.94],[16.5,14.88]],"atl":[[19,0]],"batl":[[0,19.5,4.37]],"id":99072900},{"atl":[[5,290.98]],"batl":[[2,5,290.98]],"id":10398159},{"batb":[[0,3.5,116.13]],"atb":[[3.5,116.13]],"id":88302242},{"batb":[],"atb":[[9.6,24.32],[2,33]],"atl":[[14,13.93]],"batl":[],"id":97736949}],"tv":38891.14}],"rt":639159132074119350,"dt":639159132074119875}
{"op":"mcm","id":2,"clk":"AP2kAQD8bADO0QE=","pt":1780316407508,"mc":[{"id":"1.258742455","rc":[{"atl":[[19.5,5.07]],"batl":[[0,19.5,5.07]],"id":99072900}]}],"rt":639159132075157711,"dt":639159132075158059}
{"op":"mcm","id":2,"clk":"AIKlAQCAbQDU0QE=","pt":1780316407610,"mc":[{"id":"1.258742455","rc":[{"atl":[[5,30.58]],"batl":[[0,5,30.58]],"id":99072898},{"batb":[[0,19,5.84]],"atb":[[19,5.84]],"id":99072900},{"atl":[[130,2.65]],"batl":[],"id":99072901},{"atl":[[4.8,17.44]],"batl":[[0,4.8,17.44]],"id":10398159}]}],"rt":639159132076178491,"dt":639159132076178880}
{"op":"mcm","id":2,"clk":"AJOlAQCJbQDi0QE=","pt":1780316407821,"mc":[{"id":"1.258742455","rc":[{"atl":[[19.5,4.93]],"batl":[[0,19.5,4.93]],"id":99072900},{"atl":[[4.8,18.55]],"batl":[[0,4.8,18.55]],"id":10398159},{"tv":13490.89,"batb":[[2,3.45,119.09],[1,3.5,116.13],[0,3.55,9.14]],"trd":[[3.55,830.27]],"ltp":3.55,"atb":[[3.55,9.14]],"id":88302242}],"tv":38892.87}],"rt":639159132078294138,"dt":639159132078294598}
{"op":"mcm","id":2,"clk":"AKilAQCSbQDz0QE=","pt":1780316407979,"mc":[{"id":"1.258742455","rc":[{"batb":[[0,3.55,11.38]],"atb":[[3.55,11.38]],"id":88302242}]}],"rt":639159132079867469,"dt":639159132079867834}
{"op":"mcm","id":2,"clk":"ANalAQCmbQCM0gE=","pt":1780316408382,"mc":[{"id":"1.258742455","rc":[{"batb":[[0,19,6]],"atb":[[19,6]],"id":99072900},{"batb":[],"atb":[[3.3,28.81]],"id":88302242}]}],"rt":639159132083900913,"dt":639159132083901325}
{"op":"mcm","id":2,"clk":"AOGlAQCqbQCS0gE=","pt":1780316408481,"mc":[{"id":"1.258742455","rc":[{"batb":[[0,50,18.34]],"atb":[[50,18.34]],"id":98464183}]}],"rt":639159132084897272,"dt":639159132084897655}
{"op":"mcm","id":2,"clk":"AO2lAQCvbQCZ0gE=","pt":1780316408589,"mc":[{"id":"1.258742455","rc":[{"atl":[[19.5,3.11]],"batl":[[0,19.5,3.11]],"id":99072900},{"batb":[[0,3.55,11.73]],"atb":[[3.55,11.73],[3.35,159.28]],"id":88302242},{"batb":[[2,10,40.71]],"atb":[[10,40.71]],"atl":[[11.5,18.48]],"batl":[[0,11.5,18.48]],"id":97736949}]}],"rt":639159132085967644,"dt":639159132085968191}
{"op":"mcm","id":2,"clk":"APelAQC0bQCg0gE=","pt":1780316408688,"mc":[{"id":"1.258742455","rc":[{"batb":[[0,4.7,76.85]],"atb":[[4.7,76.85]],"id":10398159},{"atl":[[3.6,70.85]],"batl":[[0,3.6,70.85]],"id":88302242}]}],"rt":639159132086957931,"dt":639159132086958371}
{"op":"mcm","id":2,"clk":"AP6lAQC7bQCn0gE=","pt":1780316408791,"mc":[{"id":"1.258742455","rc":[{"atl":[[19.5,3.56]],"batl":[[0,19.5,3.56]],"id":99072900}]}],"rt":639159132087987447,"dt":639159132087987832}
{"op":"mcm","id":2,"clk":"AIimAQDDbQCu0gE=","pt":1780316408897,"mc":[{"id":"1.258742455","rc":[{"atl":[[11.5,18.67]],"batl":[[0,11.5,18.67]],"id":97736949}]}],"rt":639159132089046836,"dt":639159132089047289}
{"op":"mcm","id":2,"clk":"AI\u002BmAQDGbQC10gE=","pt":1780316408998,"mc":[{"id":"1.258742455","rc":[{"batb":[],"atb":[[710,2],[700,1.29]],"id":10445502}]}],"rt":639159132090059903,"dt":639159132090060269}
{"op":"mcm","id":2,"clk":"AJimAQDObQC70gE=","pt":1780316409109,"mc":[{"id":"1.258742455","rc":[{"atl":[[5,31.97]],"batl":[[0,5,31.97]],"id":99072898},{"batb":[[0,48,4.79]],"atb":[[48,4.79]],"id":97008932},{"atl":[[1000,6.86],[21,33.08]],"batl":[[2,21,33.08]],"id":99072900},{"batb":[[0,8.8,23.34]],"atb":[[8.8,23.34]],"atl":[[11,4.47]],"batl":[],"id":98117699},{"batb":[[1,3.5,115.95],[0,3.55,15.84]],"atb":[[3.5,115.95],[3.55,15.84]],"atl":[[1000,3.88]],"id":88302242},{"batb":[[0,180,3.59]],"atb":[[180,3.59]],"id":99072897}]}],"rt":639159132091173748,"dt":639159132091174463}
{"op":"mcm","id":2,"clk":"AJ2mAQDSbQC/0gE=","pt":1780316409205,"mc":[{"id":"1.258742455","rc":[{"atl":[[1000,6.25]],"id":99072900},{"batb":[],"atb":[[70,6.77]],"id":99072901},{"atl":[[1000,3]],"id":88302242}]}],"rt":639159132092132421,"dt":639159132092132891}
{"op":"mcm","id":2,"clk":"AKOmAQDabQDG0gE=","pt":1780316409309,"mc":[{"id":"1.258742455","rc":[{"atl":[[20,17.18],[19.5,3.82]],"batl":[[1,20,17.18],[0,19.5,3.82]],"id":99072900},{"atl":[[3.6,71.73]],"batl":[[0,3.6,71.73]],"id":88302242}]}],"rt":639159132093170646,"dt":639159132093171142}
{"op":"mcm","id":2,"clk":"AKumAQDgbQDR0gE=","pt":1780316409416,"mc":[{"id":"1.258742455","rc":[{"batb":[[2,3.45,113.14],[0,3.55,16.34]],"atb":[[3.55,16.34],[3.45,113.14]],"id":88302242},{"tv":249.31,"batb":[[2,150,5.6],[1,160,4.11],[0,170,4.18]],"trd":[[180,63.99]],"atb":[[180,0.71]],"id":99072897}],"tv":38898.63}],"rt":639159132094238155,"dt":639159132094238700}
{"op":"mcm","id":2,"clk":"ALOmAQDlbQDY0gE=","pt":1780316409519,"mc":[{"id":"1.258742455","rc":[{"batb":[[0,19,5.84]],"atb":[[19,5.84]],"atl":[[19.5,4.2]],"batl":[[0,19.5,4.2]],"id":99072900},{"atl":[[3.6,81.73]],"batl":[[0,3.6,81.73]],"id":88302242},{"tv":253.53,"batb":[[0,170,2.07]],"trd":[[180,65.41],[170,22.96]],"ltp":170,"atb":[[180,0],[170,2.07]],"id":99072897}],"tv":38902.85}],"rt":639159132095274798,"dt":639159132095275251}
{"op":"mcm","id":2,"clk":"ALqmAQDobQDh0gE=","pt":1780316409622,"mc":[{"id":"1.258742455","rc":[{"tv":254.95,"batb":[[0,170,1.36]],"trd":[[170,24.38]],"atb":[[170,1.36]],"atl":[[190,0.69],[180,0.16]],"batl":[[1,220,1.88],[0,200,1.4]],"id":99072897}],"tv":38904.27}],"rt":639159132096302747,"dt":639159132096303231}
{"op":"mcm","id":2,"clk":"AL\u002BmAQDqbQDo0gE=","pt":1780316409722,"mc":[{"id":"1.258742455","rc":[{"batb":[[0,3.55,15.84]],"atb":[[3.55,15.84]],"id":88302242},{"batb":[[0,170,1.19]],"atb":[[170,1.19]],"id":99072897}]}],"rt":639159132097301521,"dt":639159132097302054}
{"op":"mcm","id":2,"clk":"AMamAQDvbQDw0gE=","pt":1780316409828,"mc":[{"id":"1.258742455","rc":[{"batb":[[0,19,5.91]],"atb":[[19,5.91]],"id":99072900}]}],"rt":639159132098365843,"dt":639159132098366237}
{"op":"mcm","id":2,"clk":"AMumAQDxbQD30gE=","pt":1780316409880,"mc":[{"id":"1.258742455","rc":[{"batb":[[1,160,3.46]],"atb":[[160,3.46],[130,0.82]],"atl":[[180,0.39]],"batl":[[2,220,1.13],[1,210,1.3],[0,190,1.08]],"id":99072897}]}],"rt":639159132098882068,"dt":639159132098882399}
{"op":"mcm","id":2,"clk":"ANWmAQD4bQCF0wE=","pt":1780316410074,"mc":[{"id":"1.258742455","rc":[{"tv":13550.89,"batb":[[2,3.4,88.49],[1,3.45,113.14],[0,3.5,101.79]],"trd":[[3.5,243.59],[3.55,861.95]],"ltp":3.5,"atb":[[3.5,101.79],[3.55,0]],"id":88302242}],"tv":38964.27}],"rt":639159132100825622,"dt":639159132100826041}
{"op":"mcm","id":2,"clk":"AN2mAQD6bQCP0wE=","pt":1780316410182,"mc":[{"id":"1.258742455","rc":[{"batb":[[0,19,6.11]],"atb":[[19,6.11]],"id":99072900},{"atl":[[9,23.35]],"batl":[[0,9,23.35]],"id":98117699},{"batb":[[0,3.5,102.28]],"atb":[[3.55,0.49]],"id":88302242},{"batb":[[1,160,3.78]],"atb":[[160,3.78]],"id":99072897}]}],"rt":639159132101901210,"dt":639159132101901695}
{"op":"mcm","id":2,"clk":"AOSmAQD\u002BbQCW0wE=","pt":1780316410285,"mc":[{"id":"1.258742455","rc":[{"batb":[[0,4.9,53.38]],"atb":[[4.9,53.38]],"id":99072898},{"atl":[[4.8,16.28]],"batl":[[0,4.8,16.28]],"id":10398159},{"atl":[[9,22.83]],"batl":[[0,9,22.83]],"id":98117699}]}],"rt":639159132102933890,"dt":639159132102934273}
{"op":"mcm","id":2,"clk":"AOmmAQCAbgCe0wE=","pt":1780316410381,"mc":[{"id":"1.258742455","rc":[{"batb":[[0,3.5,101.79]],"atb":[[3.55,0],[3.35,153.28]],"id":88302242}]}],"rt":639159132103890938,"dt":639159132103891257}
{"op":"mcm","id":2,"clk":"APCmAQCBbgCh0wE=","pt":1780316410482,"mc":[{"id":"1.258742455","rc":[{"batb":[[0,4.9,54.77]],"atb":[[4.9,54.77]],"id":99072898},{"batb":[[0,4.7,78.3]],"atb":[[4.7,78.3]],"id":10398159},{"tv":2384.51,"batb":[[0,8.8,17.34]],"trd":[[8.8,12]],"ltp":8.8,"atb":[[8.8,17.34]],"id":98117699}],"tv":38976.27}],"rt":639159132104904954,"dt":639159132104905476}
{"op":"mcm","id":2,"clk":"APymAQCEbgCr0wE=","pt":1780316410585,"mc":[{"id":"1.258742455","rc":[{"tv":1200.6,"trd":[[19.5,37.57]],"ltp":19.5,"atl":[[20,14.73],[19.5,0]],"batl":[[2,22,13.29],[1,21,33.08],[0,20,14.73]],"id":99072900},{"atl":[[9,23.59]],"batl":[[0,9,23.59]],"id":98117699},{"batb":[[1,3.45,93.12]],"atb":[[3.45,93.12]],"id":88302242},{"atl":[[12,10.01]],"batl":[[1,12,10.01]],"id":97736949}],"tv":38984.67}],"rt":639159132105934916,"dt":639159132105935401}
{"op":"mcm","id":2,"clk":"AICnAQCHbgCw0wE=","pt":1780316410687,"mc":[{"id":"1.258742455","rc":[{"batb":[[0,19,12.27]],"atb":[[19,12.27]],"id":99072900},{"batb":[[1,4.6,150.43]],"atb":[[4.6,150.43]],"id":10398159},{"batb":[[0,8.8,22.77]],"atb":[[8.8,22.77]],"id":98117699},{"batb":[],"atb":[[3.3,34.81]],"id":88302242}]}],"rt":639159132106951639,"dt":639159132106952051}
{"op":"mcm","id":2,"clk":"AIanAQCIbgC20wE=","pt":1780316410791,"mc":[{"id":"1.258742455","rc":[{"batb":[],"atb":[[720,2],[710,0]],"id":10445502}]}],"rt":639159132107991303,"dt":639159132107991683}
{"op":"mcm","id":2,"clk":"AIunAQCPbgC60wE=","pt":1780316410898,"mc":[{"id":"1.258742455","rc":[{"batb":[[0,19,14.35]],"atb":[[19,14.35]],"id":99072900},{"atl":[[9,22.83]],"batl":[[0,9,22.83]],"id":98117699}]}],"rt":639159132109060924,"dt":639159132109061395}
{"op":"mcm","id":2,"clk":"AJGnAQCPbgDC0wE=","pt":1780316410998,"mc":[{"id":"1.258742455","rc":[{"batb":[[2,18.5,12.63],[1,19,15.12],[0,19.5,2.98]],"atb":[[19.5,2.98],[19,15.12]],"id":99072900},{"atl":[[4.8,16.63]],"batl":[[0,4.8,16.63]],"id":10398159},{"batb":[[1,160,3.93]],"atb":[[160,3.93]],"id":99072897}]}],"rt":639159132110059905,"dt":639159132110060390}
{"op":"mcm","id":2,"clk":"AJmnAQCXbgDK0wE=","pt":1780316411105,"mc":[{"id":"1.258742455","rc":[{"atl":[[4.8,13.84]],"batl":[[0,4.8,13.84]],"id":10398159}]}],"rt":639159132111135291,"dt":639159132111135654}
{"op":"mcm","id":2,"clk":"AKSnAQCZbgDT0wE=","pt":1780316411206,"mc":[{"id":"1.258742455","rc":[{"atl":[[20,14.59]],"batl":[[0,20,14.59]],"id":99072900}]}],"rt":639159132112141383,"dt":639159132112141773}
{"op":"mcm","id":2,"clk":"AK2nAQCdbgDc0wE=","pt":1780316411310,"mc":[{"id":"1.258742455","rc":[{"atl":[[180,0.16]],"batl":[[2,230,1.09],[1,220,1.88],[0,200,1.4]],"id":99072897}]}],"rt":639159132113184243,"dt":639159132113184609}
{"op":"mcm","id":2,"clk":"ALSnAQCdbgDf0wE=","pt":1780316411410,"mc":[{"id":"1.258742455","rc":[{"batb":[[0,19.5,3.11]],"atb":[[19.5,3.11]],"atl":[[20,14.09]],"batl":[[0,20,14.09]],"id":99072900},{"atl":[[9,23.1]],"batl":[[0,9,23.1]],"id":98117699},{"atl":[[180,0.25]],"batl":[[0,200,1.49]],"id":99072897}]}],"rt":639159132114183329,"dt":639159132114183768}
{"op":"mcm","id":2,"clk":"ALunAQCgbgDm0wE=","pt":1780316411513,"mc":[{"id":"1.258742455","rc":[{"atl":[[20,12.56]],"batl":[[0,20,12.56]],"id":99072900},{"atl":[[4.8,15.58]],"batl":[[0,4.8,15.58]],"id":10398159}]}],"rt":639159132115210407,"dt":639159132115210835}
{"op":"mcm","id":2,"clk":"AMGnAQCmbgDv0wE=","pt":1780316411565,"mc":[{"id":"1.258742455","rc":[{"batb":[[0,4.9,55.64]],"atb":[[4.9,55.64]],"id":99072898},{"batb":[[0,19.5,3.35]],"atb":[[19.5,3.35]],"atl":[[20,13]],"batl":[[0,20,13]],"id":99072900}]}],"rt":639159132115737318,"dt":639159132115737647}
{"op":"mcm","id":2,"clk":"AMinAQCtbgD30wE=","pt":1780316411669,"mc":[{"id":"1.258742455","rc":[{"atl":[[4.8,16.11]],"batl":[[0,4.8,16.11]],"id":10398159},{"tv":2549.6,"batb":[[0,11,26.83]],"trd":[[11,142.68]],"atb":[[11,26.83]],"id":97736949}],"tv":38987.97}],"rt":639159132116768107,"dt":639159132116768688}
{"op":"mcm","id":2,"clk":"ANGnAQCybgCE1AE=","pt":1780316411770,"mc":[{"id":"1.258742455","rc":[{"batb":[[0,95,2.29]],"atb":[[95,2.29]],"id":99072901},{"batb":[[0,8.8,23.43]],"atb":[[8.8,23.43]],"id":98117699}]}],"rt":639159132117789438,"dt":639159132117789817}
{"op":"mcm","id":2,"clk":"ANynAQC4bgCM1AE=","pt":1780316411874,"mc":[{"id":"1.258742455","rc":[{"batb":[[0,19.5,3.7]],"atb":[[19.5,3.7]],"id":99072900}]}],"rt":639159132118816375,"dt":639159132118816714}
{"op":"mcm","id":2,"clk":"AO2nAQC/bgCj1AE=","pt":1780316412080,"mc":[{"id":"1.258742455","rc":[{"batb":[[1,19,16.82]],"atb":[[19,16.82]],"atl":[[20,12.56]],"batl":[[0,20,12.56]],"id":99072900},{"batb":[[0,4.7,91.87]],"atb":[[4.7,91.87]],"atl":[[4.9,57.94]],"batl":[[1,4.9,57.94]],"id":10398159},{"atl":[[3.65,50.42]],"batl":[[1,3.65,50.42]],"id":88302242},{"batb":[[0,11,30.21]],"atb":[[11,30.21]],"id":97736949}]}],"rt":639159132120882286,"dt":639159132120882925}
{"op":"mcm","id":2,"clk":"APOnAQDDbgCt1AE=","pt":1780316412185,"mc":[{"id":"1.258742455","rc":[{"batb":[[0,170,1.2]],"atb":[[170,1.2]],"atl":[[180,0.16]],"batl":[[0,200,1.4]],"id":99072897}]}],"rt":639159132121934973,"dt":639159132121935339}
{"op":"mcm","id":2,"clk":"APunAQDMbgC21AE=","pt":1780316412307,"mc":[{"id":"1.258742455","rc":[{"atl":[[20,12.87]],"batl":[[0,20,12.87]],"id":99072900},{"atl":[[4.8,15.58]],"batl":[[0,4.8,15.58]],"id":10398159}]}],"rt":639159132123147583,"dt":639159132123148093}
{"op":"mcm","id":2,"clk":"AIKoAQDQbgC91AE=","pt":1780316412389,"mc":[{"id":"1.258742455","rc":[{"batb":[[0,170,1.19]],"atb":[[170,1.19]],"atl":[[180,0.21]],"batl":[[0,200,1.45]],"id":99072897}]}],"rt":639159132123970044,"dt":639159132123970466}
{"op":"mcm","id":2,"clk":"AJ\u002BoAQD0bgDf1AE=","pt":1780316412808,"mc":[{"id":"1.258742455","rc":[{"atl":[[20,13.06]],"batl":[[0,20,13.06]],"id":99072900}]}],"rt":639159132128163249,"dt":639159132128163687}
{"op":"mcm","id":2,"clk":"AKSoAQD6bgDp1AE=","pt":1780316412910,"mc":[{"id":"1.258742455","rc":[{"tv":1209.6,"trd":[[20,86.83]],"ltp":20,"atl":[[20,8.56]],"batl":[[0,20,8.56]],"id":99072900},{"tv":13568.19,"batb":[[0,3.5,93.14]],"trd":[[3.5,260.89]],"atb":[[3.5,93.14]],"id":88302242}],"tv":39014.27}],"rt":639159132129179162,"dt":639159132129179607}
{"op":"mcm","id":2,"clk":"AKioAQCAbwDy1AE=","pt":1780316413015,"mc":[{"id":"1.258742455","rc":[{"tv":8385.47,"batb":[[0,4.9,52.64]],"trd":[[4.9,620.42]],"atb":[[4.9,52.64]],"id":99072898},{"atl":[[20,5.97]],"batl":[[0,20,5.97]],"id":99072900},{"batb":[[0,170,1.2]],"atb":[[170,1.2]],"id":99072897}],"tv":39020.27}],"rt":639159132130234575,"dt":639159132130234973}
{"op":"mcm","id":2,"clk":"AK6oAQCGbwD51AE=","pt":1780316413115,"mc":[{"id":"1.258742455","rc":[{"batb":[[0,19.5,4.15]],"atb":[[19.5,4.15]],"atl":[[23,13.14],[22,6.13],[20,5.47]],"batl":[[2,22,6.13],[0,20,5.47]],"id":99072900},{"atl":[[3.55,0.96],[3.6,86.41]],"batl":[[0,3.6,87.37]],"id":88302242}]}],"rt":639159132131235421,"dt":639159132131235806}
{"op":"mcm","id":2,"clk":"ALeoAQCLbwCD1QE=","pt":1780316413217,"mc":[{"id":"1.258742455","rc":[{"atl":[[20,3.91]],"batl":[[0,20,3.91]],"id":99072900},{"atl":[[4.8,15.23]],"batl":[[0,4.8,15.23]],"id":10398159}]}],"rt":639159132132253694,"dt":639159132132254087}
{"op":"mcm","id":2,"clk":"AMCoAQCRbwCL1QE=","pt":1780316413318,"mc":[{"id":"1.258742455","rc":[{"atl":[[9,22.83]],"batl":[[0,9,22.83]],"id":98117699},{"batb":[[0,3.5,88.19]],"atb":[[3.5,88.19],[2.54,1.99],[2,27]],"atl":[[3.55,5.55]],"batl":[[2,3.65,50.42],[1,3.6,86.41],[0,3.55,5.55]],"id":88302242},{"batb":[[0,170,1.21]],"atb":[[170,1.21]],"id":99072897}]}],"rt":639159132133264022,"dt":639159132133264439}
{"op":"mcm","id":2,"clk":"AMOoAQCRbwCP1QE=","pt":1780316413368,"mc":[{"id":"1.258742455","rc":[{"atl":[[24,20.52]],"batl":[],"id":99072900}]}],"rt":639159132133765039,"dt":639159132133765453}
{"op":"mcm","id":2,"clk":"AOSoAQCdbwCc1QE=","pt":1780316413575,"mc":[{"id":"1.258742455","rc":[{"batb":[[0,3.5,89.06]],"atb":[[3.5,89.06]],"id":88302242}]}],"rt":639159132135839586,"dt":639159132135840111}
{"op":"mcm","id":2,"clk":"AOuoAQChbwCi1QE=","pt":1780316413676,"mc":[{"id":"1.258742455","rc":[{"atl":[[3.8,96.48]],"batl":[],"id":88302242}]}],"rt":639159132136845548,"dt":639159132136845916}
{"op":"mcm","id":2,"clk":"APCoAQCmbwCo1QE=","pt":1780316413781,"mc":[{"id":"1.258742455","rc":[{"atl":[[9,22.94]],"batl":[[0,9,22.94]],"id":98117699}]}],"rt":639159132137891258,"dt":639159132137891664}
{"op":"mcm","id":2,"clk":"APeoAQCnbwCs1QE=","pt":1780316413885,"mc":[{"id":"1.258742455","rc":[{"atl":[[3.75,69.78]],"batl":[],"id":88302242}]}],"rt":639159132138929626,"dt":639159132138930048}
{"op":"mcm","id":2,"clk":"AIOpAQCzbwC51QE=","pt":1780316414090,"mc":[{"id":"1.258742455","rc":[{"batb":[[0,3.5,90.28]],"atb":[[3.5,90.28]],"id":88302242}]}],"rt":639159132140977392,"dt":639159132140977832}
{"op":"mcm","id":2,"clk":"AIypAQC5bwDC1QE=","pt":1780316414189,"mc":[{"id":"1.258742455","rc":[{"batb":[[0,170,1.22]],"atb":[[170,1.22]],"id":99072897}]}],"rt":639159132141976242,"dt":639159132141976641}
{"op":"mcm","id":2,"clk":"AJapAQC\u002BbwDM1QE=","pt":1780316414290,"mc":[{"id":"1.258742455","rc":[{"batb":[[0,3.5,90.97]],"atb":[[3.5,90.97]],"id":88302242}]}],"rt":639159132142983571,"dt":639159132142983940}
{"op":"mcm","id":2,"clk":"AJypAQDBbwDV1QE=","pt":1780316414399,"mc":[{"id":"1.258742455","rc":[{"batb":[[0,3.5,87.22]],"atb":[[3.5,87.22]],"id":88302242}]}],"rt":639159132144075543,"dt":639159132144075869}
{"op":"mcm","id":2,"clk":"ALapAQDHbwDc1QE=","pt":1780316414499,"mc":[{"id":"1.258742455","rc":[{"atl":[[3.6,89.41]],"batl":[[1,3.6,89.41]],"id":88302242}]}],"rt":639159132145070886,"dt":639159132145071273}
{"op":"mcm","id":2,"clk":"AM\u002BpAQDTbwD21QE=","pt":1780316414806,"mc":[{"id":"1.258742455","rc":[{"tv":8622.79,"batb":[[0,4.7,87.87]],"trd":[[4.7,1189.95]],"ltp":4.7,"atb":[[4.7,87.87]],"id":10398159}],"tv":39028.27}],"rt":639159132148147976,"dt":639159132148148483}
{"op":"mcm","id":2,"clk":"ANapAQDYbwD\u002B1QE=","pt":1780316414908,"mc":[{"id":"1.258742455","rc":[{"atl":[[180,0.16]],"batl":[[0,200,1.4]],"id":99072897}]}],"rt":639159132149158751,"dt":639159132149159086}
{"op":"mcm","id":2,"clk":"ANypAQDbbwCG1gE=","pt":1780316415016,"mc":[{"id":"1.258742455","rc":[{"atl":[[5,29.7]],"batl":[[0,5,29.7]],"id":99072898},{"batb":[[1,19,15.12],[0,19.5,5.6]],"atb":[[19,15.12],[19.5,5.6]],"atl":[[21,33.57],[20,3.56]],"batl":[[1,21,33.57],[0,20,3.56]],"id":99072900},{"atl":[[4.8,16.46]],"batl":[[0,4.8,16.46]],"id":10398159},{"atl":[[1000,3.98],[3.65,49.23],[3.6,89.82]],"batl":[[2,3.65,49.23],[1,3.6,89.82]],"id":88302242}]}],"rt":639159132150240719,"dt":639159132150241533}
{"op":"mcm","id":2,"clk":"AOCpAQDebwCL1gE=","pt":1780316415115,"mc":[{"id":"1.258742455","rc":[{"atl":[[4.8,31.99]],"batl":[[0,4.8,31.99]],"id":10398159},{"atl":[[9,22.83]],"batl":[[0,9,22.83]],"id":98117699},{"atl":[[1000,3]],"id":88302242},{"batb":[[0,170,1.24]],"atb":[[170,1.24]],"id":99072897}]}],"rt":639159132151227803,"dt":639159132151228267}
{"op":"mcm","id":2,"clk":"AOWpAQDgbwCQ1gE=","pt":1780316415218,"mc":[{"id":"1.258742455","rc":[{"atl":[[3.55,6.53]],"batl":[[0,3.55,6.53]],"id":88302242},{"batb":[[0,170,1.23]],"atb":[[170,1.23]],"id":99072897}]}],"rt":639159132152264030,"dt":639159132152264409}
{"op":"mcm","id":2,"clk":"APGpAQDpbwCZ1gE=","pt":1780316415323,"mc":[{"id":"1.258742455","rc":[{"atl":[[3.65,58.98]],"batl":[[2,3.65,58.98]],"id":88302242}]}],"rt":639159132153311406,"dt":639159132153311771}
{"op":"mcm","id":2,"clk":"APSpAQDvbwCi1gE=","pt":1780316415374,"mc":[{"id":"1.258742455","rc":[{"atl":[[9,12.83]],"batl":[[0,9,12.83]],"id":98117699}]}],"rt":639159132153821697,"dt":639159132153822094}
{"op":"mcm","id":2,"clk":"APipAQDzbwCt1gE=","pt":1780316415475,"mc":[{"id":"1.258742455","rc":[{"atl":[[180,0.17]],"batl":[[0,200,1.41]],"id":99072897}]}],"rt":639159132154830213,"dt":639159132154830557}
{"op":"mcm","id":2,"clk":"AIiqAQD3bwC51gE=","pt":1780316415581,"mc":[{"id":"1.258742455","rc":[{"batb":[[0,8.8,26.26]],"atb":[[8.8,26.26]],"atl":[[9,10.39]],"batl":[[0,9,10.39]],"id":98117699}]}],"rt":639159132155888910,"dt":639159132155889291}
{"op":"mcm","id":2,"clk":"AJGqAQCAcADE1gE=","pt":1780316415783,"mc":[{"id":"1.258742455","rc":[{"atl":[[25,16.23],[24,4.55]],"batl":[],"id":99072900},{"atl":[[4.8,32.81]],"batl":[[0,4.8,32.81]],"id":10398159}]}],"rt":639159132157907618,"dt":639159132157907967}
{"op":"mcm","id":2,"clk":"AJmqAQCEcADN1gE=","pt":1780316415885,"mc":[{"id":"1.258742455","rc":[{"atl":[[180,0.19]],"batl":[[0,200,1.43]],"id":99072897}]}],"rt":639159132158928900,"dt":639159132158929235}
{"op":"mcm","id":2,"clk":"AJ\u002BqAQCJcADT1gE=","pt":1780316415986,"mc":[{"id":"1.258742455","rc":[{"batb":[[0,170,1.22]],"atb":[[170,1.22]],"id":99072897}]}],"rt":639159132159939236,"dt":639159132159939540}
{"op":"mcm","id":2,"clk":"AKSqAQCPcADc1gE=","pt":1780316416096,"mc":[{"id":"1.258742455","rc":[{"batb":[],"atb":[[70,5.77]],"id":99072901},{"batb":[[0,3.5,85.66]],"atb":[[3.3,40.49],[3.5,85.66]],"id":88302242}]}],"rt":639159132161045338,"dt":639159132161045765}
{"op":"mcm","id":2,"clk":"AKeqAQCVcADh1gE=","pt":1780316416192,"mc":[{"id":"1.258742455","rc":[{"batb":[],"atb":[[4.5,47.5]],"atl":[[5.3,21.15]],"batl":[],"id":99072898},{"batb":[[2,18.5,13.28]],"atb":[[18.5,13.28]],"atl":[[25,16.87]],"batl":[],"id":99072900},{"tv":398.99,"trd":[[100,26.27]],"ltp":100,"atl":[[100,2.88]],"batl":[[0,100,2.88]],"id":99072901},{"batb":[],"atb":[[4.3,144.24]],"atl":[[5.1,55.01]],"batl":[],"id":10398159},{"batb":[],"atb":[[44,9.43]],"atl":[[75,3.81]],"batl":[],"id":98464183},{"batb":[],"atb":[[8.2,19.44]],"atl":[[9.8,17.33]],"batl":[],"id":98117699},{"batb":[],"atb":[[3.35,156.02]],"atl":[[3.75,75.11]],"batl":[],"id":88302242},{"batb":[],"atb":[[9.6,25.68]],"atl":[[13,7.84]],"batl":[],"id":97736949}],"tv":39030.27}],"rt":639159132162004660,"dt":639159132162005263}
{"op":"mcm","id":2,"clk":"AK\u002BqAQCccADp1gE=","pt":1780316416293,"mc":[{"id":"1.258742455","rc":[{"batb":[[0,95,4.18]],"atb":[[95,4.18]],"atl":[[100,2.48]],"batl":[[0,100,2.48]],"id":99072901}]}],"rt":639159132163015616,"dt":639159132163015983}
{"op":"mcm","id":2,"clk":"AMGqAQCqcAD61gE=","pt":1780316416604,"mc":[{"id":"1.258742455","rc":[{"atl":[[100,2.55]],"batl":[[0,100,2.55]],"id":99072901}]}],"rt":639159132166118625,"dt":639159132166118989}
{"op":"mcm","id":2,"clk":"AMaqAQCucACA1wE=","pt":1780316416702,"mc":[{"id":"1.258742455","rc":[{"batb":[[0,3.5,86.2]],"atb":[[3.5,86.2]],"id":88302242}]}],"rt":639159132167103941,"dt":639159132167104315}
{"op":"mcm","id":2,"clk":"AMyqAQC1cACF1wE=","pt":1780316416804,"mc":[{"id":"1.258742455","rc":[{"tv":13628.19,"batb":[[0,3.5,56.2]],"trd":[[3.5,320.89]],"atb":[[3.5,56.2]],"id":88302242}],"tv":39090.27}],"rt":639159132168122937,"dt":639159132168123300}
{"op":"mcm","id":2,"clk":"ANCqAQC7cACM1wE=","pt":1780316416910,"mc":[{"id":"1.258742455","rc":[{"batb":[],"atb":[[3.9,23.05]],"id":10398159},{"batb":[],"atb":[[3.35,144.77]],"atl":[[3.55,25]],"batl":[[0,3.55,25]],"id":88302242}]}],"rt":639159132169184499,"dt":639159132169184902}
{"op":"mcm","id":2,"clk":"ANmqAQDBcACR1wE=","pt":1780316417012,"mc":[{"id":"1.258742455","rc":[{"tv":408.06,"batb":[[2,80,5.71],[1,85,11.45],[0,90,4.95]],"trd":[[95,46.81],[90,34.48]],"ltp":90,"atb":[[95,0],[90,4.95]],"id":99072901},{"batb":[[0,3.5,66.91]],"atb":[[3.3,53.9],[3.5,66.91]],"atl":[[3.55,34.03]],"batl":[[0,3.55,34.03]],"id":88302242},{"batb":[[0,11,30.93]],"atb":[[11,30.93]],"id":97736949},{"batb":[[0,170,1.24]],"atb":[[170,1.24]],"atl":[[180,0.16]],"batl":[[0,200,1.4]],"id":99072897}],"tv":39099.34}],"rt":639159132170204940,"dt":639159132170205410}
{"op":"mcm","id":2,"clk":"ANyqAQDDcACW1wE=","pt":1780316417112,"mc":[{"id":"1.258742455","rc":[{"batb":[[0,90,5.44]],"atb":[[95,0.15],[90,5.29]],"id":99072901}]}],"rt":639159132171208076,"dt":639159132171208516}
{"op":"mcm","id":2,"clk":"AOOqAQDJcACb1wE=","pt":1780316417226,"mc":[{"id":"1.258742455","rc":[{"batb":[[0,90,5.59]],"atb":[[95,0],[90,5.59]],"id":99072901},{"atl":[[3.6,85.41]],"batl":[[1,3.6,85.41]],"id":88302242},{"batb":[[2,730,3.85]],"atb":[[720,0],[730,3.85]],"id":10445502}]}],"rt":639159132172345541,"dt":639159132172346003}
{"op":"mcm","id":2,"clk":"AO6qAQDTcACn1wE=","pt":1780316417367,"mc":[{"id":"1.258742455","rc":[{"atl":[[21,23.57]],"batl":[[1,21,23.57]],"id":99072900},{"batb":[[0,90,5.77]],"atb":[[90,5.77]],"atl":[[100,3]],"batl":[[0,100,3]],"id":99072901},{"atl":[[5,90.98]],"batl":[[2,5,90.98]],"id":10398159}]}],"rt":639159132173754775,"dt":639159132173755283}
{"op":"mcm","id":2,"clk":"APWqAQDZcACw1wE=","pt":1780316417524,"mc":[{"id":"1.258742455","rc":[{"tv":1221.92,"batb":[[2,18,12.95],[1,18.5,13.28],[0,19,15.12]],"trd":[[19.5,49.89]],"ltp":19.5,"atb":[[19.5,0]],"atl":[[19.5,3.84]],"batl":[[2,21,23.57],[1,20,3.56],[0,19.5,3.84]],"id":99072900},{"atl":[[4.9,257.94],[4.8,30.76]],"batl":[[1,4.9,257.94],[0,4.8,30.76]],"id":10398159},{"atl":[[180,0.19]],"batl":[[0,200,1.43]],"id":99072897}],"tv":39111.66}],"rt":639159132175319741,"dt":639159132175320279}
{"op":"mcm","id":2,"clk":"APqqAQDacAC21wE=","pt":1780316417575,"mc":[{"id":"1.258742455","rc":[{"tv":1229.6,"trd":[[19.5,57.57]],"atl":[[20,6.33],[19.5,0]],"batl":[[2,22,6.13],[1,21,23.57],[0,20,6.33]],"id":99072900},{"batb":[[0,8.8,27.34]],"atb":[[8.8,27.34]],"id":98117699},{"batb":[[0,170,1.19]],"atb":[[170,1.19]],"id":99072897}],"tv":39119.34}],"rt":639159132175833923,"dt":639159132175834488}
{"op":"mcm","id":2,"clk":"AIOrAQDhcADB1wE=","pt":1780316417685,"mc":[{"id":"1.258742455","rc":[{"batb":[[1,4.8,68.11],[0,4.9,83.77]],"atb":[[4.9,83.77],[4.8,68.11]],"id":99072898},{"batb":[[0,48,7.39]],"atb":[[48,7.39]],"id":97008932},{"batb":[[2,18.5,13.28],[1,19,21.17],[0,19.5,2.84]],"atb":[[1.17,2.47],[19.5,2.84],[19,21.17]],"atl":[[20,8.28]],"batl":[[0,20,8.28]],"id":99072900},{"batb":[[0,4.7,117.91]],"atb":[[4.7,117.91]],"atl":[[4.8,32.92]],"batl":[[0,4.8,32.92]],"id":10398159},{"batb":[[0,50,20.94]],"atb":[[50,20.94]],"id":98464183},{"batb":[[0,8.8,41.18]],"atb":[[8.8,41.18]],"id":98117699},{"batb":[[1,10.5,23.78],[0,11,43.04]],"atb":[[11,43.04],[10.5,23.78],[1.15,22.5]],"id":97736949},{"batb":[[0,170,2.05]],"atb":[[170,2.05]],"atl":[[180,0.16]],"batl":[[0,200,1.4]],"id":99072897}]}],"rt":639159132176930854,"dt":639159132176931475}
{"op":"mcm","id":2,"clk":"AIirAQDrcADJ1wE=","pt":1780316417793,"mc":[{"id":"1.258742455","rc":[{"atb":[[1.17,2]],"atl":[[200,0],[20,8.81]],"batl":[[0,20,8.81]],"id":99072900},{"batb":[[0,4.7,115.82]],"atb":[[4.7,115.82]],"id":10398159},{"tv":2395.77,"batb":[[0,8.8,42.34]],"trd":[[9,85.88]],"ltp":9,"atb":[[8.8,42.34]],"atl":[[9.2,9.37],[9,4.76]],"batl":[[1,9.2,9.37],[0,9,4.76]],"id":98117699},{"batb":[[0,11,48.04]],"atb":[[11,48.04]],"id":97736949},{"batb":[[0,170,2.12]],"atb":[[170,2.12]],"id":99072897}],"tv":39130.6}],"rt":639159132178012830,"dt":639159132178013315}
{"op":"mcm","id":2,"clk":"AIqrAQDxcADR1wE=","pt":1780316417890,"mc":[{"id":"1.258742455","rc":[{"batb":[[0,19.5,3.31]],"atb":[[19.5,3.31]],"id":99072900},{"atl":[[4.8,36.58]],"batl":[[0,4.8,36.58]],"id":10398159},{"tv":2398.21,"batb":[[2,8.6,22.61],[1,8.8,42.34],[0,9,4.23]],"trd":[[9,88.32]],"atb":[[9,4.23]],"atl":[[9,0]],"batl":[[2,9.6,26.7],[1,9.4,11.4],[0,9.2,9.37]],"id":98117699}],"tv":39133.04}],"rt":639159132178980540,"dt":639159132178981165}
{"op":"mcm","id":2,"clk":"AJSrAQD0cADa1wE=","pt":1780316417998,"mc":[{"id":"1.258742455","rc":[{"atl":[[20,6.33]],"batl":[[0,20,6.33]],"id":99072900},{"batb":[[0,90,5.9]],"atb":[[95,0.13]],"id":99072901},{"batb":[[0,9,15.01]],"atb":[[9,15.01]],"atl":[[9.2,6.55]],"batl":[[0,9.2,6.55]],"id":98117699},{"batb":[[0,3.5,72.97]],"atb":[[3.5,72.97]],"id":88302242},{"batb":[[0,170,2.5]],"atb":[[170,2.5]],"id":99072897}]}],"rt":639159132180058901,"dt":639159132180059327}
{"op":"mcm","id":2,"clk":"AJ6rAQD/cADj1wE=","pt":1780316418106,"mc":[{"id":"1.258742455","rc":[{"batb":[[0,19.5,3.94]],"atb":[[19.5,3.94]],"id":99072900},{"batb":[[0,9,16.13]],"atb":[[9,16.13]],"atl":[[9.2,15.76],[9.6,12.14]],"batl":[[2,9.6,12.14],[0,9.2,15.76]],"id":98117699},{"batb":[[0,170,2.55]],"atb":[[170,2.55]],"id":99072897}]}],"rt":639159132181143554,"dt":639159132181143942}
{"op":"mcm","id":2,"clk":"AKGrAQCEcQDp1wE=","pt":1780316418202,"mc":[{"id":"1.258742455","rc":[{"batb":[[0,90,6.15]],"atb":[[90,6.02]],"id":99072901},{"batb":[[0,9,18.95]],"atb":[[9,18.95]],"id":98117699}]}],"rt":639159132182103923,"dt":639159132182104345}
{"op":"mcm","id":2,"clk":"AKyrAQCNcQD21wE=","pt":1780316418408,"mc":[{"id":"1.258742455","rc":[{"batb":[],"atb":[[8,54.4]],"atl":[[9.2,15.83]],"batl":[[0,9.2,15.83]],"id":98117699}]}],"rt":639159132184167421,"dt":639159132184167781}
{"op":"mcm","id":2,"clk":"ALKrAQCRcQCH2AE=","pt":1780316418610,"mc":[{"id":"1.258742455","rc":[{"batb":[],"atb":[[8.2,25.44]],"id":98117699}]}],"rt":639159132186180614,"dt":639159132186181021}
{"op":"mcm","id":2,"clk":"ALerAQCYcQCP2AE=","pt":1780316418714,"mc":[{"id":"1.258742455","rc":[{"atl":[[9.2,16.23]],"batl":[[0,9.2,16.23]],"id":98117699}]}],"rt":639159132187223826,"dt":639159132187224255}
{"op":"mcm","id":2,"clk":"AL6rAQCccQCW2AE=","pt":1780316418818,"mc":[{"id":"1.258742455","rc":[{"tv":1233.73,"batb":[[0,19.5,1.87]],"trd":[[19.5,61.7]],"atb":[[19.5,1.87]],"id":99072900}],"tv":39137.17}],"rt":639159132188262560,"dt":639159132188263044}
{"op":"mcm","id":2,"clk":"AMKrAQCgcQCf2AE=","pt":1780316418919,"mc":[{"id":"1.258742455","rc":[{"atl":[[20,6.4]],"batl":[[0,20,6.4]],"id":99072900}]}],"rt":639159132189271713,"dt":639159132189272179}
{"op":"mcm","id":2,"clk":"AMSrAQCicQCi2AE=","pt":1780316418970,"mc":[{"id":"1.258742455","rc":[{"batb":[[0,19.5,1.24]],"atb":[[19.5,1.24]],"id":99072900}]}],"rt":639159132189780683,"dt":639159132189781028}
{"op":"mcm","id":2,"clk":"AMurAQCocQCp2AE=","pt":1780316419174,"mc":[{"id":"1.258742455","rc":[{"atl":[[20,7]],"batl":[[0,20,7]],"id":99072900}]}],"rt":639159132191824264,"dt":639159132191824636}
{"op":"mcm","id":2,"clk":"AM\u002BrAQCrcQCx2AE=","pt":1780316419278,"mc":[{"id":"1.258742455","rc":[{"batb":[[2,8.6,26.58]],"atb":[[8.6,26.58]],"id":98117699}]}],"rt":639159132192867391,"dt":639159132192867825}
{"op":"mcm","id":2,"clk":"ANirAQCucQC72AE=","pt":1780316419382,"mc":[{"id":"1.258742455","rc":[{"batb":[[0,19.5,1.41]],"atb":[[19.5,1.41]],"atl":[[20,6.4]],"batl":[[0,20,6.4]],"id":99072900}]}],"rt":639159132193899458,"dt":639159132193899948}
{"op":"mcm","id":2,"clk":"AOSrAQC0cQDD2AE=","pt":1780316419489,"mc":[{"id":"1.258742455","rc":[{"batb":[[1,4.6,157.52]],"atb":[[4.6,157.52]],"id":10398159},{"batb":[[0,9,16.13]],"atb":[[9,16.13]],"id":98117699}]}],"rt":639159132194967275,"dt":639159132194967740}
{"op":"mcm","id":2,"clk":"AOerAQC5cQDN2AE=","pt":1780316419589,"mc":[{"id":"1.258742455","rc":[{"atl":[[20,6.33]],"batl":[[0,20,6.33]],"id":99072900},{"atl":[[9.2,16.58]],"batl":[[0,9.2,16.58]],"id":98117699}]}],"rt":639159132195967883,"dt":639159132195968252}
{"op":"mcm","id":2,"clk":"AOurAQC8cQDT2AE=","pt":1780316419690,"mc":[{"id":"1.258742455","rc":[{"atl":[[20,6.45]],"batl":[[0,20,6.45]],"id":99072900}]}],"rt":639159132196980221,"dt":639159132196980725}
{"op":"mcm","id":2,"clk":"APqrAQDBcQDm2AE=","pt":1780316419900,"mc":[{"id":"1.258742455","rc":[{"batb":[[0,19.5,1.72]],"atb":[[19.5,1.72]],"id":99072900}]}],"rt":639159132199083682,"dt":639159132199084092}
{"op":"mcm","id":2,"clk":"AP\u002BrAQDEcQDr2AE=","pt":1780316419999,"mc":[{"id":"1.258742455","rc":[{"atl":[[20,6.33]],"batl":[[0,20,6.33]],"id":99072900}]}],"rt":639159132200068682,"dt":639159132200069085}
{"op":"mcm","id":2,"clk":"AJGsAQDKcQD82AE=","pt":1780316420207,"mc":[{"id":"1.258742455","rc":[{"atl":[[20,6.44]],"batl":[[0,20,6.44]],"id":99072900},{"atl":[[9,17.35]],"id":88302242}]}],"rt":639159132202149273,"dt":639159132202149750}
{"op":"mcm","id":2,"clk":"AKmsAQDUcQCd2QE=","pt":1780316420613,"mc":[{"id":"1.258742455","rc":[{"atl":[[20,6.53]],"batl":[[0,20,6.53]],"id":99072900}]}],"rt":639159132206215682,"dt":639159132206216166}
{"op":"mcm","id":2,"clk":"ALusAQDbcQC02QE=","pt":1780316420926,"mc":[{"id":"1.258742455","rc":[{"batb":[[1,4.8,66.21]],"atb":[[4.8,66.21]],"atl":[[5,21.27]],"batl":[[0,5,21.27]],"id":99072898},{"atl":[[1000,6.63]],"id":99072900},{"batb":[[0,90,6.02]],"atb":[[95,0]],"id":99072901},{"tv":914.59,"trd":[[55,115.85]],"atl":[[55,1.24]],"batl":[[0,55,1.24]],"id":98464183},{"atl":[[9.4,12.78],[9.2,16.23]],"batl":[[1,9.4,12.78],[0,9.2,16.23]],"id":98117699},{"tv":13633.19,"batb":[[0,3.5,70.47]],"trd":[[3.5,325.89]],"atb":[[3.5,70.47]],"atl":[[3.55,35.03],[3.6,86.88]],"batl":[[1,3.6,86.88],[0,3.55,35.03]],"id":88302242},{"batb":[[2,730,1.85]],"atb":[[710,2],[730,1.85]],"id":10445502},{"batb":[[0,170,2.17]],"atb":[[170,2.17]],"id":99072897}],"tv":39149.88}],"rt":639159132209353636,"dt":639159132209354324}
{"op":"mcm","id":2,"clk":"AMCsAQDgcQC/2QE=","pt":1780316421031,"mc":[{"id":"1.258742455","rc":[{"batb":[[0,4.9,82.37]],"atb":[[4.9,82.37]],"id":99072898},{"atl":[[1000,6.25]],"id":99072900},{"batb":[[0,4.7,119.98]],"atb":[[4.7,119.98]],"id":10398159},{"batb":[[0,50,21.4]],"atb":[[50,21.4]],"id":98464183},{"batb":[[1,8.8,38.57],[0,9,21.78]],"atb":[[8.8,38.57],[9,21.78]],"atl":[[9.2,17.24]],"batl":[[0,9.2,17.24]],"id":98117699},{"batb":[[0,3.5,77.61]],"atb":[[3.5,77.61]],"id":88302242},{"batb":[[0,11,50.47]],"atb":[[11,50.47]],"id":97736949}]}],"rt":639159132210394948,"dt":639159132210395502}
{"op":"mcm","id":2,"clk":"AMesAQDhcQDE2QE=","pt":1780316421079,"mc":[{"id":"1.258742455","rc":[{"tv":8404.19,"batb":[[0,4.9,73.01]],"trd":[[4.9,639.14]],"atb":[[4.9,73.01]],"id":99072898},{"atl":[[20,6.91]],"batl":[[0,20,6.91]],"id":99072900},{"batb":[[0,50,23.24]],"atb":[[50,23.24]],"atl":[[75,4.99]],"batl":[],"id":98464183},{"tv":2408.67,"batb":[[0,9,16.55]],"trd":[[9,98.78]],"atb":[[9,16.55]],"atl":[[9.2,17.68]],"batl":[[0,9.2,17.68]],"id":98117699},{"tv":258.21,"batb":[[2,140,1.71],[1,150,5.6],[0,160,4.47]],"trd":[[170,27.64]],"atb":[[170,0.54]],"id":99072897}],"tv":39182.32}],"rt":639159132210870680,"dt":639159132210871222}
{"op":"mcm","id":2,"clk":"AMusAQDjcQDM2QE=","pt":1780316421182,"mc":[{"id":"1.258742455","rc":[{"tv":8412.61,"batb":[[0,4.9,68.8]],"trd":[[4.9,647.56]],"atb":[[4.9,68.8]],"id":99072898},{"atl":[[180,0.36]],"batl":[[2,220,1.13],[1,210,1.3],[0,190,1.05]],"id":99072897}],"tv":39190.74}],"rt":639159132211900025,"dt":639159132211900409}
{"op":"mcm","id":2,"clk":"ANOsAQDmcQDT2QE=","pt":1780316421292,"mc":[{"id":"1.258742455","rc":[{"batb":[[0,4.9,81.52]],"atb":[[4.9,81.52],[1.01,68849.08]],"id":99072898},{"batb":[[0,19.5,1.25]],"atb":[[19.5,1.25]],"id":99072900},{"batb":[[0,9,15.43]],"atb":[[1.01,98581.23],[9,15.43]],"id":98117699},{"batb":[[1,150,3.91],[0,160,2.81]],"atb":[[170,0.42],[160,2.39],[1.01,119551.55],[150,3.91]],"id":99072897}]}],"rt":639159132213004852,"dt":639159132213005266}
{"op":"mcm","id":2,"clk":"AOCsAQDxcQDl2QE=","pt":1780316421495,"mc":[{"id":"1.258742455","rc":[{"batb":[[0,9,15.97]],"atb":[[9,15.97]],"id":98117699},{"atl":[[180,0.49]],"batl":[[0,190,1.18]],"id":99072897}]}],"rt":639159132215029410,"dt":639159132215029807}
{"op":"mcm","id":2,"clk":"AOesAQDycQDy2QE=","pt":1780316421601,"mc":[{"id":"1.258742455","rc":[{"batb":[[2,18,12.95],[1,18.5,13.28],[0,19,22.11]],"atb":[[19.5,0.94]],"id":99072900}]}],"rt":639159132216095426,"dt":639159132216095841}
{"op":"mcm","id":2,"clk":"APCsAQD3cQCC2gE=","pt":1780316421796,"mc":[{"id":"1.258742455","rc":[{"batb":[[0,19,21.94]],"atb":[[19.5,0.77]],"atl":[[20,7.05]],"batl":[[0,20,7.05]],"id":99072900}]}],"rt":639159132218040644,"dt":639159132218041399}
{"op":"mcm","id":2,"clk":"APysAQD7cQCW2gE=","pt":1780316422002,"mc":[{"id":"1.258742455","rc":[{"batb":[[2,8.6,22.61]],"atb":[[8.6,22.61]],"id":98117699},{"batb":[],"atb":[[130,1.19]],"id":99072897}]}],"rt":639159132220099777,"dt":639159132220100268}
{"op":"mcm","id":2,"clk":"AJGtAQCPcgC12gE=","pt":1780316422309,"mc":[{"id":"1.258742455","rc":[{"atl":[[3.7,217.22]],"batl":[],"id":88302242}]}],"rt":639159132223169829,"dt":639159132223170271}
{"op":"mcm","id":2,"clk":"AJ\u002BtAQCbcgDD2gE=","pt":1780316422519,"mc":[{"id":"1.258742455","rc":[{"atl":[[5.4,17.22]],"batl":[],"id":10398159}]}],"rt":639159132225278639,"dt":639159132225279032}
{"op":"mcm","id":2,"clk":"AKitAQChcgDJ2gE=","pt":1780316422622,"mc":[{"id":"1.258742455","rc":[{"batb":[[0,19,22]],"atb":[[19.5,0.83]],"id":99072900}]}],"rt":639159132226308121,"dt":639159132226308480}
{"op":"mcm","id":2,"clk":"ALutAQCycgDa2gE=","pt":1780316422887,"mc":[{"id":"1.258742455","rc":[{"batb":[[0,19,22.09]],"atb":[[19.5,0.92]],"id":99072900}]}],"rt":639159132228948583,"dt":639159132228948957}
{"op":"mcm","id":2,"clk":"AMGtAQC4cgDk2gE=","pt":1780316423000,"mc":[{"id":"1.258742455","rc":[{"atl":[[20,6.91]],"batl":[[0,20,6.91]],"id":99072900}]}],"rt":639159132230085463,"dt":639159132230085868}
{"op":"mcm","id":2,"clk":"ANKtAQDLcgD12gE=","pt":1780316423300,"mc":[{"id":"1.258742455","rc":[{"batb":[[0,19,21.94]],"atb":[[19.5,0.77]],"id":99072900}]}],"rt":639159132233078714,"dt":639159132233079131}
{"op":"mcm","id":2,"clk":"ANetAQDUcgCA2wE=","pt":1780316423404,"mc":[{"id":"1.258742455","rc":[{"atl":[[20,7.03]],"batl":[[0,20,7.03]],"id":99072900}]}],"rt":639159132234117758,"dt":639159132234118080}
{"op":"mcm","id":2,"clk":"AOCtAQDecgCR2wE=","pt":1780316423606,"mc":[{"id":"1.258742455","rc":[{"tv":1235.27,"batb":[[0,19,21.17]],"trd":[[19.5,63.24]],"atb":[[19.5,0]],"atl":[[19.5,0.23]],"batl":[[0,20,7.26]],"id":99072900}],"tv":39192.28}],"rt":639159132236143924,"dt":639159132236144354}
{"op":"mcm","id":2,"clk":"AO\u002BtAQDmcgCl2wE=","pt":1780316423822,"mc":[{"id":"1.258742455","rc":[{"tv":1235.73,"trd":[[19.5,63.7]],"atl":[[20,9.24],[19.5,0]],"batl":[[0,20,9.24]],"id":99072900},{"batb":[],"atb":[[3.3,82.12]],"id":88302242}],"tv":39192.74}],"rt":639159132238300437,"dt":639159132238300807}
{"op":"mcm","id":2,"clk":"APKtAQDpcgCp2wE=","pt":1780316423919,"mc":[{"id":"1.258742455","rc":[{"batb":[[0,19,21.77]],"atb":[[19.5,0.6]],"id":99072900}]}],"rt":639159132239273253,"dt":639159132239273653}
{"op":"mcm","id":2,"clk":"AIquAQCBcwDD2wE=","pt":1780316424331,"mc":[{"id":"1.258742455","rc":[{"tv":562.17,"trd":[[50,83.24]],"atl":[[50,9.86]],"batl":[[0,50,9.86]],"id":97008932}],"tv":39196.74}],"rt":639159132243394924,"dt":639159132243395280}
{"op":"mcm","id":2,"clk":"AI6uAQCIcwDK2wE=","pt":1780316424429,"mc":[{"id":"1.258742455","rc":[{"tv":1241.83,"trd":[[20,92.93]],"ltp":20,"atl":[[20,2.63]],"batl":[[0,20,2.63]],"id":99072900},{"batb":[[0,9,16.25]],"atb":[[9,16.25]],"id":98117699}],"tv":39202.84}],"rt":639159132244370772,"dt":639159132244371226}
{"op":"mcm","id":2,"clk":"AJiuAQCPcwDS2wE=","pt":1780316424489,"mc":[{"id":"1.258742455","rc":[{"batb":[[0,48,7.74]],"atb":[[48,7.74]],"id":97008932},{"batb":[[2,18.5,13.28],[1,19,21.17],[0,19.5,3.29]],"atb":[[19.5,3.29]],"id":99072900},{"batb":[[0,3.5,78.62]],"atb":[[3.5,78.62]],"id":88302242}]}],"rt":639159132244974701,"dt":639159132244975184}
{"op":"mcm","id":2,"clk":"AKKuAQCScwDf2wE=","pt":1780316424587,"mc":[{"id":"1.258742455","rc":[{"batb":[[0,19.5,4.01]],"atb":[[19.5,4.01]],"atl":[[20,3.07]],"batl":[[0,20,3.07]],"id":99072900}]}],"rt":639159132245948822,"dt":639159132245949198}
{"op":"mcm","id":2,"clk":"AK\u002BuAQCYcwDs2wE=","pt":1780316424791,"mc":[{"id":"1.258742455","rc":[{"tv":2553.73,"batb":[[0,11,48.4]],"trd":[[11,146.81]],"atb":[[11,48.4]],"id":97736949}],"tv":39206.97}],"rt":639159132247990788,"dt":639159132247991172}
{"op":"mcm","id":2,"clk":"AMCuAQCicwD72wE=","pt":1780316425001,"mc":[{"id":"1.258742455","rc":[{"atl":[[20,0.3]],"batl":[[2,23,13.14],[1,22,6.13],[0,21,23.87]],"id":99072900}]}],"rt":639159132250085999,"dt":639159132250086346}
{"op":"mcm","id":2,"clk":"AMiuAQCmcwCE3AE=","pt":1780316425101,"mc":[{"id":"1.258742455","rc":[{"batb":[[0,4.9,88.45]],"atb":[[4.9,88.45]],"id":99072898},{"batb":[[0,19.5,8.8]],"atb":[[19.5,8.8]],"id":99072900},{"batb":[[0,11,52.63]],"atb":[[11,52.63]],"id":97736949}]}],"rt":639159132251092069,"dt":639159132251092614}
{"op":"mcm","id":2,"clk":"ANCuAQCscwCN3AE=","pt":1780316425204,"mc":[{"id":"1.258742455","rc":[{"batb":[[0,19.5,11.15]],"atb":[[19.5,11.15]],"id":99072900},{"batb":[],"atb":[[7.6,124.31]],"id":98117699},{"batb":[],"atb":[[9.8,15.81]],"id":97736949}]}],"rt":639159132252123341,"dt":639159132252123705}
{"op":"mcm","id":2,"clk":"ANmuAQCwcwCV3AE=","pt":1780316425305,"mc":[{"id":"1.258742455","rc":[{"tv":1242.43,"trd":[[20,93.53]],"atl":[[20,0]],"batl":[[0,21,23.57]],"id":99072900},{"batb":[[2,150,3.91],[1,160,4.18],[0,170,2.21]],"atb":[[170,2.21],[160,4.18]],"id":99072897}],"tv":39207.57}],"rt":639159132253130879,"dt":639159132253131284}
{"op":"mcm","id":2,"clk":"AN\u002BuAQCzcwCd3AE=","pt":1780316425408,"mc":[{"id":"1.258742455","rc":[{"batb":[],"atb":[[4.2,116.79]],"id":99072898},{"batb":[[2,19,21.17],[1,19.5,11.15],[0,20,1.24]],"atb":[[20,1.24]],"id":99072900},{"batb":[],"atb":[[4,25.82]],"id":10398159},{"batb":[],"atb":[[7.8,23.25]],"id":98117699},{"batb":[],"atb":[[3.05,297.07]],"id":88302242},{"batb":[],"atb":[[9.4,26.23]],"id":97736949}]}],"rt":639159132254169031,"dt":639159132254169533}
{"op":"mcm","id":2,"clk":"AOauAQC3cwCl3AE=","pt":1780316425514,"mc":[{"id":"1.258742455","rc":[{"atl":[[5,19.01]],"batl":[[0,5,19.01]],"id":99072898},{"batb":[],"atb":[[42,14.67]],"id":97008932},{"batb":[],"atb":[[16.5,14.58]],"id":99072900},{"atl":[[180,0.16]],"batl":[[2,230,1.09],[1,220,1.88],[0,200,1.4]],"id":99072897}]}],"rt":639159132255220682,"dt":639159132255221131}
{"op":"mcm","id":2,"clk":"AO\u002BuAQC5cwCr3AE=","pt":1780316425617,"mc":[{"id":"1.258742455","rc":[{"batb":[],"atb":[[4.2,117.98]],"id":99072898},{"batb":[],"atb":[[4,27.07]],"id":10398159},{"atb":[[2.2,9.51],[3,8.47]],"id":88302242}]}],"rt":639159132256249728,"dt":639159132256250114}
{"op":"mcm","id":2,"clk":"APeuAQC\u002BcwC03AE=","pt":1780316425718,"mc":[{"id":"1.258742455","rc":[{"batb":[],"atb":[[42,14.79]],"id":97008932},{"batb":[],"atb":[[17,62.15]],"id":99072900},{"atl":[[180,0.17]],"batl":[[0,200,1.41]],"id":99072897}]}],"rt":639159132257262871,"dt":639159132257263333}
{"op":"mcm","id":2,"clk":"APyuAQDGcwC93AE=","pt":1780316425820,"mc":[{"id":"1.258742455","rc":[{"batb":[[0,4.9,57.32]],"atb":[[4.9,57.32]],"id":99072898},{"batb":[[0,48,5.14]],"atb":[[48,5.14]],"id":97008932},{"batb":[[0,4.7,87.98]],"atb":[[4.7,87.98]],"id":10398159},{"batb":[[0,50,20.64]],"atb":[[50,20.64]],"id":98464183},{"batb":[[1,8.8,39.57]],"atb":[[8.8,39.57]],"id":98117699},{"batb":[[0,11,40.52]],"atb":[[11,40.52]],"id":97736949}]}],"rt":639159132258282999,"dt":639159132258283520}
{"op":"mcm","id":2,"clk":"AP\u002BuAQDHcwDG3AE=","pt":1780316425924,"mc":[{"id":"1.258742455","rc":[{"batb":[[0,9,20.49]],"atb":[[9,20.49]],"id":98117699},{"atl":[[180,0.16]],"batl":[[0,200,1.4]],"id":99072897}]}],"rt":639159132259323902,"dt":639159132259324347}
{"op":"mcm","id":2,"clk":"AISvAQDPcwDK3AE=","pt":1780316426026,"mc":[{"id":"1.258742455","rc":[{"atl":[[5,20.36]],"batl":[[0,5,20.36]],"id":99072898},{"atl":[[26,14.88],[25,4.1]],"batl":[],"id":99072900},{"batb":[[0,11,35.52]],"atb":[[11,35.52]],"id":97736949},{"batb":[],"atb":[[710,0],[700,3.29]],"id":10445502},{"batb":[[0,170,2.26]],"atb":[[170,2.26]],"id":99072897}]}],"rt":639159132260346551,"dt":639159132260347035}
{"op":"mcm","id":2,"clk":"AImvAQDUcwDU3AE=","pt":1780316426128,"mc":[{"id":"1.258742455","rc":[{"batb":[[0,9,21]],"atb":[[9,21]],"id":98117699}]}],"rt":639159132261366251,"dt":639159132261366588}
{"op":"mcm","id":2,"clk":"AJKvAQDccwDb3AE=","pt":1780316426234,"mc":[{"id":"1.258742455","rc":[{"batb":[[0,3.5,78.92]],"atb":[[3.5,78.92]],"id":88302242}]}],"rt":639159132262423390,"dt":639159132262423762}
{"op":"mcm","id":2,"clk":"AJqvAQDjcwDl3AE=","pt":1780316426292,"mc":[{"id":"1.258742455","rc":[{"atb":[[2.54,4.39]],"id":88302242},{"batb":[[0,170,2.21]],"atb":[[170,2.21]],"id":99072897}]}],"rt":639159132262998777,"dt":639159132262999205}
{"op":"mcm","id":2,"clk":"AKOvAQDncwDr3AE=","pt":1780316426388,"mc":[{"id":"1.258742455","rc":[{"atl":[[5,21.35]],"batl":[[0,5,21.35]],"id":99072898}]}],"rt":639159132263964218,"dt":639159132263964553}
{"op":"mcm","id":2,"clk":"AKmvAQDscwDx3AE=","pt":1780316426490,"mc":[{"id":"1.258742455","rc":[{"batb":[[1,19.5,22.15]],"atb":[[19.5,22.15]],"id":99072900},{"batb":[[0,3.5,79.37]],"atb":[[3.5,79.37]],"id":88302242},{"batb":[[0,170,2.23]],"atb":[[170,2.23]],"id":99072897}]}],"rt":639159132264984561,"dt":639159132264985144}
{"op":"mcm","id":2,"clk":"AK2vAQDvcwD43AE=","pt":1780316426591,"mc":[{"id":"1.258742455","rc":[{"batb":[[0,20,3.97]],"atb":[[20,3.97]],"id":99072900}]}],"rt":639159132265989949,"dt":639159132265990378}
{"op":"mcm","id":2,"clk":"ALSvAQDzcwCA3QE=","pt":1780316426698,"mc":[{"id":"1.258742455","rc":[{"batb":[[1,19.5,22.96]],"atb":[[19.5,22.96]],"id":99072900},{"batb":[[0,170,2.27]],"atb":[[170,2.27]],"id":99072897}]}],"rt":639159132267064766,"dt":639159132267065169}
{"op":"mcm","id":2,"clk":"AL2vAQD4cwCG3QE=","pt":1780316426813,"mc":[{"id":"1.258742455","rc":[{"batb":[],"atb":[[17.5,40.01]],"id":99072900},{"tv":2555.73,"batb":[[0,11,34.52]],"trd":[[11,148.81]],"atb":[[11,34.52]],"id":97736949}],"tv":39209.57}],"rt":639159132268211765,"dt":639159132268212135}
{"op":"mcm","id":2,"clk":"AMKvAQD9cwCM3QE=","pt":1780316426900,"mc":[{"id":"1.258742455","rc":[{"tv":2559.04,"batb":[[0,11,32.87]],"trd":[[11,152.12]],"atb":[[11,32.87]],"id":97736949}],"tv":39212.88}],"rt":639159132269082452,"dt":639159132269082883}
{"op":"mcm","id":2,"clk":"AMevAQD/cwCT3QE=","pt":1780316427002,"mc":[{"id":"1.258742455","rc":[{"batb":[],"atb":[[17,58.33]],"id":99072900},{"atb":[[3.85,63.69]],"id":10398159}]}],"rt":639159132270100966,"dt":639159132270101426}
{"op":"mcm","id":2,"clk":"ANCvAQCIdACc3QE=","pt":1780316427109,"mc":[{"id":"1.258742455","rc":[{"batb":[],"atb":[[42,13.49]],"id":97008932}]}],"rt":639159132271172297,"dt":639159132271172666}
{"op":"mcm","id":2,"clk":"ANivAQCMdACe3QE=","pt":1780316427209,"mc":[{"id":"1.258742455","rc":[{"batb":[[0,48,6.28]],"atb":[[48,6.28]],"id":97008932},{"atl":[[21,23.08]],"batl":[[0,21,23.08]],"id":99072900},{"tv":412.06,"trd":[[100,30.27]],"ltp":100,"atl":[[100,1]],"batl":[[0,100,1]],"id":99072901},{"atl":[[4.9,55.73]],"batl":[[1,4.9,55.73]],"id":10398159},{"tv":13634.92,"batb":[[0,3.5,78.51]],"trd":[[3.5,327.62]],"atb":[[3.5,78.51]],"atl":[[3.55,33.23]],"batl":[[0,3.55,33.23]],"id":88302242}],"tv":39218.61}],"rt":639159132272173088,"dt":639159132272173642}
{"op":"mcm","id":2,"clk":"AOGvAQCQdACq3QE=","pt":1780316427316,"mc":[{"id":"1.258742455","rc":[{"batb":[[0,4.9,58.53]],"atb":[[4.9,58.53]],"id":99072898},{"atl":[[1000,0.34]],"id":97008932},{"batb":[[1,19.5,22.36],[0,20,5.36]],"atb":[[20,5.36],[19.5,22.36]],"atl":[[1000,6.67]],"id":99072900},{"batb":[[0,4.7,73.13]],"atb":[[4.7,73.13]],"id":10398159},{"batb":[[0,9,17.48]],"atb":[[9,17.48]],"id":98117699},{"batb":[[0,3.5,66.53]],"atb":[[3.5,66.53]],"atl":[[3.6,84.37]],"batl":[[1,3.6,84.37]],"id":88302242},{"batb":[[0,11,29.17]],"atb":[[11,29.17]],"id":97736949}]}],"rt":639159132273237144,"dt":639159132273237685}
{"op":"mcm","id":2,"clk":"AOmvAQCUdAC03QE=","pt":1780316427417,"mc":[{"id":"1.258742455","rc":[{"batb":[[0,4.9,57.84]],"atb":[[4.9,57.84]],"id":99072898},{"atl":[[1000,0.22]],"id":97008932},{"atl":[[1000,6.25]],"id":99072900},{"batb":[[0,90,6.23]],"atb":[[90,6.23]],"atl":[[100,0.89]],"batl":[[2,130,2.65],[1,120,1.83],[0,110,7.1]],"id":99072901},{"batb":[[0,4.7,77.22]],"atb":[[4.7,77.22]],"atl":[[4.8,30.76]],"batl":[[0,4.8,30.76]],"id":10398159},{"batb":[[0,3.5,65.78]],"atb":[[3.5,65.78]],"id":88302242}]}],"rt":639159132274248947,"dt":639159132274249509}
{"op":"mcm","id":2,"clk":"APCvAQCZdAC33QE=","pt":1780316427518,"mc":[{"id":"1.258742455","rc":[{"atl":[[50,9.98]],"batl":[[0,50,9.98]],"id":97008932},{"batb":[],"atb":[[17.5,35.24]],"atl":[[22,6.55]],"batl":[[1,22,6.55]],"id":99072900},{"atl":[[3.65,49.23]],"batl":[[2,3.65,49.23]],"id":88302242}]}],"rt":639159132275259136,"dt":639159132275259561}
{"op":"mcm","id":2,"clk":"APavAQCddADD3QE=","pt":1780316427619,"mc":[{"id":"1.258742455","rc":[{"atl":[[100,1.01]],"batl":[[2,120,1.83],[1,110,6.21],[0,100,1.01]],"id":99072901},{"batb":[[0,3.5,57.15]],"atb":[[3.5,57.15]],"id":88302242}]}],"rt":639159132276270308,"dt":639159132276270759}
{"op":"mcm","id":2,"clk":"AImwAQCpdADh3QE=","pt":1780316427926,"mc":[{"id":"1.258742455","rc":[{"batb":[[0,20,5.42]],"atb":[[20,5.42]],"id":99072900},{"atl":[[100,1.1]],"batl":[[0,100,1.1]],"id":99072901}]}],"rt":639159132279336165,"dt":639159132279336561}
{"op":"mcm","id":2,"clk":"AI\u002BwAQCvdADm3QE=","pt":1780316428026,"mc":[{"id":"1.258742455","rc":[{"batb":[[0,20,5.36]],"atb":[[20,5.36]],"id":99072900}]}],"rt":639159132280341407,"dt":639159132280341783}
{"op":"mcm","id":2,"clk":"AJywAQC5dAD03QE=","pt":1780316428183,"mc":[{"id":"1.258742455","rc":[{"batb":[[0,4.9,58.88]],"atb":[[4.9,58.88]],"id":99072898},{"batb":[[0,4.7,78.31]],"atb":[[4.7,78.31]],"id":10398159},{"batb":[[0,50,20.84]],"atb":[[50,20.84]],"id":98464183},{"batb":[[0,170,2.33]],"atb":[[170,2.33]],"id":99072897}]}],"rt":639159132281912283,"dt":639159132281912693}
{"op":"mcm","id":2,"clk":"AKOwAQC\u002BdAD43QE=","pt":1780316428282,"mc":[{"id":"1.258742455","rc":[{"batb":[[0,20,5.42]],"atb":[[20,5.42]],"id":99072900}]}],"rt":639159132282900863,"dt":639159132282901218}
{"op":"mcm","id":2,"clk":"AMSwAQDVdACX3gE=","pt":1780316428795,"mc":[{"id":"1.258742455","rc":[{"batb":[[0,20,5.36]],"atb":[[20,5.36]],"id":99072900}]}],"rt":639159132288029893,"dt":639159132288030365}
{"op":"mcm","id":2,"clk":"ANSwAQDgdACj3gE=","pt":1780316429001,"mc":[{"id":"1.258742455","rc":[{"atl":[[5,24.35]],"batl":[[0,5,24.35]],"id":99072898}]}],"rt":639159132290091823,"dt":639159132290092221}
{"op":"mcm","id":2,"clk":"APqwAQCJdQDW3gE=","pt":1780316429615,"mc":[{"id":"1.258742455","rc":[{"tv":259.91,"batb":[[0,170,2.48]],"trd":[[190,38.22],[180,65.73]],"ltp":190,"atb":[[190,0.15]],"atl":[[190,0],[180,0]],"batl":[[1,220,1.13],[0,210,1.3]],"id":99072897}],"tv":39220.31}],"rt":639159132296234899,"dt":639159132296235347}
{"op":"mcm","id":2,"clk":"AP\u002BwAQCNdQDe3gE=","pt":1780316429721,"mc":[{"id":"1.258742455","rc":[{"atl":[[5.1,47.1]],"batl":[[1,5.1,47.1]],"id":99072898},{"atl":[[50,9.78]],"batl":[[0,50,9.78]],"id":97008932},{"batb":[[1,3.45,84.19]],"atb":[[1.17,196.42],[3.45,84.19]],"id":88302242},{"tv":260.05,"batb":[[0,170,2.41]],"trd":[[190,38.36]],"atb":[[190,0.08]],"id":99072897}],"tv":39220.45}],"rt":639159132297294198,"dt":639159132297294630}
{"op":"mcm","id":2,"clk":"AIWxAQCPdQDn3gE=","pt":1780316429822,"mc":[{"id":"1.258742455","rc":[{"tv":1248.87,"trd":[[21,132.6]],"ltp":21,"atl":[[21,19.86]],"batl":[[0,21,19.86]],"id":99072900},{"batb":[[1,4.6,101.97]],"atb":[[4.6,101.97]],"id":10398159},{"batb":[],"atb":[[1.17,196.12],[3.3,53.9]],"id":88302242},{"tv":260.21,"batb":[[0,170,2.47]],"trd":[[190,38.52]],"atb":[[190,0],[170,2.47]],"atl":[[190,2.48]],"batl":[[2,220,1.13],[1,210,1.3],[0,190,2.48]],"id":99072897}],"tv":39227.05}],"rt":639159132298304564,"dt":639159132298305083}
{"op":"mcm","id":2,"clk":"AIyxAQCUdQDr3gE=","pt":1780316429926,"mc":[{"id":"1.258742455","rc":[{"atl":[[23,6.25]],"batl":[[2,23,6.25]],"id":99072900},{"tv":13635.22,"batb":[[0,3.5,77.3]],"trd":[[3.55,862.25]],"ltp":3.55,"atb":[[3.5,77.3]],"atl":[[3.55,33.08]],"batl":[[0,3.55,33.08]],"id":88302242},{"batb":[[2,150,2.18],[0,170,2.54]],"atb":[[180,0.07],[150,2.18]],"atl":[[190,4.67]],"batl":[[0,190,4.67]],"id":99072897}],"tv":39227.35}],"rt":639159132299341434,"dt":639159132299341979}
{"op":"mcm","id":2,"clk":"AJGxAQCYdQD33gE=","pt":1780316430032,"mc":[{"id":"1.258742455","rc":[{"batb":[[0,20,6.91]],"atb":[[20,6.91],[17.5,30.17]],"atl":[[21,21.16]],"batl":[[0,21,21.16]],"id":99072900},{"tv":2414.67,"batb":[[0,9,14.48]],"trd":[[9,104.78]],"atb":[[9,14.48]],"id":98117699},{"tv":260.35,"batb":[[0,170,2.47]],"trd":[[180,65.87]],"ltp":180,"atb":[[180,0]],"atl":[[190,4.75],[270,0]],"batl":[[0,190,4.75]],"id":99072897}],"tv":39233.49}],"rt":639159132300397935,"dt":639159132300398400}
{"op":"mcm","id":2,"clk":"AJqxAQCbdQCC3wE=","pt":1780316430131,"mc":[{"id":"1.258742455","rc":[{"batb":[[0,20,11.7]],"atb":[[20,11.7]],"id":99072900},{"batb":[[0,170,2.33]],"atb":[[170,2.33]],"id":99072897}]}],"rt":639159132301385706,"dt":639159132301386144}
{"op":"mcm","id":2,"clk":"AKGxAQCfdQCL3wE=","pt":1780316430231,"mc":[{"id":"1.258742455","rc":[{"batb":[[0,48,7.08]],"atb":[[48,7.08]],"atl":[[1000,0.39]],"id":97008932},{"batb":[[0,90,6.49]],"atb":[[90,6.49]],"id":99072901},{"batb":[[0,9,9.96]],"atb":[[9,9.96]],"atl":[[9.2,9.35]],"batl":[[0,9.2,9.35]],"id":98117699},{"batb":[[0,3.5,90.86]],"atb":[[3.5,90.86]],"id":88302242},{"batb":[[0,170,2.27]],"atb":[[170,2.27]],"id":99072897}]}],"rt":639159132302392367,"dt":639159132302392877}
{"op":"mcm","id":2,"clk":"AKWxAQCidQCV3wE=","pt":1780316430285,"mc":[{"id":"1.258742455","rc":[{"batb":[[1,4.8,67.83]],"atb":[[4.8,67.83]],"atl":[[5,31.82]],"batl":[[0,5,31.82]],"id":99072898},{"batb":[[0,20,14.32]],"atb":[[20,14.32]],"atl":[[21,20.2]],"batl":[[0,21,20.2]],"id":99072900},{"tv":260.47,"batb":[[2,140,1.71],[1,150,2.18],[0,160,4.91]],"trd":[[170,27.76]],"ltp":170,"atb":[[170,0.73]],"atl":[[190,4.86],[180,0.13]],"batl":[[0,190,4.99]],"id":99072897}],"tv":39233.61}],"rt":639159132302935499,"dt":639159132302936052}
{"op":"mcm","id":2,"clk":"AK6xAQCldQCa3wE=","pt":1780316430385,"mc":[{"id":"1.258742455","rc":[{"atl":[[1000,0.22]],"id":97008932},{"atl":[[21,17.57]],"batl":[[0,21,17.57]],"id":99072900},{"batb":[],"atb":[[4.4,184.32]],"id":10398159},{"batb":[[0,9,14.39]],"atb":[[9,14.39]],"id":98117699},{"batb":[[0,3.5,91.16]],"atb":[[3.5,91.16]],"id":88302242}]}],"rt":639159132303927471,"dt":639159132303927912}
{"op":"mcm","id":2,"clk":"ALSxAQCqdQCg3wE=","pt":1780316430488,"mc":[{"id":"1.258742455","rc":[{"batb":[[0,4.9,58.64]],"atb":[[4.9,58.64]],"id":99072898},{"atl":[[55,23.23]],"batl":[[1,55,23.23]],"id":97008932},{"batb":[[0,160,4.44]],"atb":[[160,3.71]],"atl":[[190,2.41]],"batl":[[0,190,2.54]],"id":99072897}]}],"rt":639159132304963554,"dt":639159132304963967}
{"op":"mcm","id":2,"clk":"AL2xAQCxdQCu3wE=","pt":1780316430594,"mc":[{"id":"1.258742455","rc":[{"atl":[[180,0.34]],"batl":[[0,190,2.75]],"id":99072897}]}],"rt":639159132306024845,"dt":639159132306025206}
{"op":"mcm","id":2,"clk":"AMGxAQCzdQC13wE=","pt":1780316430695,"mc":[{"id":"1.258742455","rc":[{"batb":[[2,4.5,144.86]],"atb":[[4.5,144.86]],"id":10398159}]}],"rt":639159132307030100,"dt":639159132307030435}
{"op":"mcm","id":2,"clk":"AMSxAQC3dQC\u002B3wE=","pt":1780316430796,"mc":[{"id":"1.258742455","rc":[{"tv":8632.23,"batb":[[0,4.7,73.59]],"trd":[[4.7,1199.39]],"atb":[[4.7,73.59]],"id":10398159}],"tv":39243.05}],"rt":639159132308043797,"dt":639159132308044189}
{"op":"mcm","id":2,"clk":"AMexAQC8dQDF3wE=","pt":1780316430899,"mc":[{"id":"1.258742455","rc":[{"atl":[[4.8,31.11]],"batl":[[0,4.8,31.11]],"id":10398159},{"tv":13673.27,"batb":[[0,3.5,72.13]],"trd":[[3.5,365.67]],"ltp":3.5,"atb":[[3.5,72.13]],"id":88302242},{"batb":[[0,11,30.38]],"atb":[[11,30.38]],"id":97736949},{"batb":[[0,160,4.7]],"atb":[[160,3.97]],"id":99072897}],"tv":39281.1}],"rt":639159132309074056,"dt":639159132309074494}
{"op":"mcm","id":2,"clk":"AMyxAQDCdQDN3wE=","pt":1780316431005,"mc":[{"id":"1.258742455","rc":[{"atl":[[24,5.4]],"batl":[],"id":99072900},{"batb":[],"atb":[[8.4,25.56]],"id":98117699}]}],"rt":639159132310133206,"dt":639159132310133651}
{"op":"mcm","id":2,"clk":"AM6xAQDDdQDT3wE=","pt":1780316431105,"mc":[{"id":"1.258742455","rc":[{"atl":[[21,16.45]],"batl":[[0,21,16.45]],"id":99072900},{"batb":[[0,9,17.35]],"atb":[[9,17.35]],"id":98117699},{"batb":[[0,3.5,58.27]],"atb":[[3.5,58.27]],"id":88302242}]}],"rt":639159132311133956,"dt":639159132311134501}
{"op":"mcm","id":2,"clk":"ANSxAQDIdQDa3wE=","pt":1780316431205,"mc":[{"id":"1.258742455","rc":[{"atl":[[5,28.82]],"batl":[[0,5,28.82]],"id":99072898},{"tv":1271.05,"trd":[[21,154.78]],"atl":[[21,5.36]],"batl":[[0,21,5.36]],"id":99072900},{"tv":13693.27,"batb":[[0,3.5,48.27]],"trd":[[3.5,385.67]],"atb":[[3.5,48.27]],"atl":[[3.55,46.26]],"batl":[[0,3.55,46.26]],"id":88302242},{"atl":[[190,5.99]],"batl":[[0,190,6.33]],"id":99072897}],"tv":39323.28}],"rt":639159132312129761,"dt":639159132312130392}
{"op":"mcm","id":2,"clk":"ANuxAQDMdQDi3wE=","pt":1780316431309,"mc":[{"id":"1.258742455","rc":[{"tv":1281.77,"batb":[[2,19.5,22.36],[1,20,14.32],[0,21,8.03]],"trd":[[21,165.5]],"atb":[[21,8.03]],"atl":[[21,0]],"batl":[[2,24,5.4],[1,23,6.25],[0,22,6.55]],"id":99072900},{"batb":[[1,150,3.98]],"atb":[[150,3.98]],"id":99072897}],"tv":39334}],"rt":639159132313170976,"dt":639159132313171544}
{"op":"mcm","id":2,"clk":"AN\u002BxAQDQdQDo3wE=","pt":1780316431415,"mc":[{"id":"1.258742455","rc":[{"batb":[[1,20,23.33],[0,21,8.62]],"atb":[[21,8.62],[20,23.33]],"atl":[[25,6.52]],"batl":[],"id":99072900},{"atl":[[9.2,6.9]],"batl":[[0,9.2,6.9]],"id":98117699},{"batb":[[1,3.45,65.48],[0,3.5,34.85]],"atb":[[3.5,34.85],[3.45,65.48]],"id":88302242},{"tv":261.33,"batb":[[0,160,4.02]],"trd":[[170,28.62]],"atb":[[170,0.31],[160,3.71]],"id":99072897}],"tv":39334.86}],"rt":639159132314230539,"dt":639159132314231086}
{"op":"mcm","id":2,"clk":"AOqxAQDUdQDy3wE=","pt":1780316431521,"mc":[{"id":"1.258742455","rc":[{"batb":[[0,21,15.29]],"atb":[[21,15.29],[17.5,26.94]],"atl":[[22,4.29]],"batl":[[0,22,4.29]],"id":99072900},{"tv":13722.51,"batb":[[1,3.45,73.33],[0,3.5,20.23]],"trd":[[3.5,414.91]],"atb":[[3.5,20.23],[3.45,73.33]],"id":88302242}],"tv":39364.1}],"rt":639159132315301598,"dt":639159132315301967}
{"op":"mcm","id":2,"clk":"AO6xAQDVdQD73wE=","pt":1780316431620,"mc":[{"id":"1.258742455","rc":[{"tv":8415.71,"batb":[[0,4.9,56.79]],"trd":[[4.9,650.66]],"atb":[[4.9,56.79]],"id":99072898},{"batb":[[0,21,16.25]],"atb":[[21,16.25],[18,8.19]],"atl":[[22,2.71]],"batl":[[0,22,2.71]],"id":99072900},{"batb":[[0,9,17.95]],"atb":[[9,17.95]],"atl":[[9.2,6.83]],"batl":[[0,9.2,6.83]],"id":98117699},{"tv":13762.97,"batb":[[2,3.35,144.77],[1,3.4,88.49],[0,3.45,73.33]],"trd":[[3.5,455.37]],"atb":[[3.5,0]],"atl":[[3.5,17.72],[3.8,81.8]],"batl":[[2,3.6,84.37],[1,3.55,46.26],[0,3.5,17.72]],"id":88302242}],"tv":39407.66}],"rt":639159132316286832,"dt":639159132316287378}
{"op":"mcm","id":2,"clk":"APSxAQDXdQCB4AE=","pt":1780316431720,"mc":[{"id":"1.258742455","rc":[{"atl":[[22,0.42]],"batl":[[2,25,6.52],[1,24,5.4],[0,23,6.67]],"id":99072900},{"atl":[[4.8,30.76]],"batl":[[0,4.8,30.76]],"id":10398159},{"atl":[[9.2,6.48]],"batl":[[0,9.2,6.48]],"id":98117699},{"batb":[[0,3.45,65.48]],"atb":[[3.3,44.19],[3.25,19.03],[3.45,65.48]],"atl":[[3.75,63.84],[3.5,19.89]],"batl":[[0,3.5,19.89]],"id":88302242},{"batb":[[0,160,4.06]],"atb":[[160,3.75]],"id":99072897}]}],"rt":639159132317288348,"dt":639159132317288799}
{"op":"mcm","id":2,"clk":"AP2xAQDbdQCN4AE=","pt":1780316431827,"mc":[{"id":"1.258742455","rc":[{"tv":8443.71,"batb":[[0,4.9,42.78]],"trd":[[4.9,678.66]],"atb":[[4.9,42.78]],"id":99072898},{"tv":1282.61,"batb":[[2,20,23.33],[1,21,16.25],[0,22,2.34]],"trd":[[22,105.46]],"ltp":22,"atb":[[22,2.34]],"atl":[[22,0]],"batl":[[0,23,6.25]],"id":99072900},{"atb":[[1.17,196.8]],"atl":[[3.5,24.47]],"batl":[[0,3.5,24.47]],"id":88302242}],"tv":39436.5}],"rt":639159132318348012,"dt":639159132318348657}
{"op":"mcm","id":2,"clk":"AIayAQDddQCX4AE=","pt":1780316431930,"mc":[{"id":"1.258742455","rc":[{"batb":[[1,4.8,70.48]],"atb":[[4.8,70.48]],"atl":[[5,38.67],[5.1,49.59]],"batl":[[1,5.1,49.59],[0,5,38.67]],"id":99072898},{"batb":[[1,21,17.1]],"atb":[[21,17.1],[18.5,10.29]],"atl":[[26,17.19]],"batl":[],"id":99072900},{"batb":[[2,4.5,147.6]],"atb":[[4.5,147.6]],"id":10398159},{"batb":[],"atb":[[8.4,18.98]],"id":98117699},{"batb":[],"atb":[[1.17,196.12],[3.3,47.88]],"id":88302242}]}],"rt":639159132319382643,"dt":639159132319383245}
{"op":"mcm","id":2,"clk":"AIqyAQDidQCd4AE=","pt":1780316432029,"mc":[{"id":"1.258742455","rc":[{"batb":[[0,4.9,49.11]],"atb":[[4.9,49.11]],"atl":[[5,41.52]],"batl":[[0,5,41.52]],"id":99072898},{"batb":[[0,48,7.33]],"atb":[[48,7.33]],"id":97008932},{"tv":1283.17,"batb":[[1,21,18.5],[0,22,5.86]],"trd":[[22,106.02]],"atb":[[22,5.86],[21,18.5],[18.5,6.53]],"id":99072900},{"batb":[[0,90,6.63]],"atb":[[90,6.63]],"id":99072901},{"atl":[[9.2,6.04]],"batl":[[0,9.2,6.04]],"id":98117699},{"tv":13764.33,"batb":[],"trd":[[3.5,456.73]],"atb":[[3.3,69.68]],"atl":[[3.75,57.84],[3.5,23.79],[4.6,18.68]],"batl":[[0,3.5,23.79]],"id":88302242},{"batb":[[0,11,31.47]],"atb":[[11,31.47]],"id":97736949},{"batb":[[0,1000,92.06]],"atb":[[1000,92.06]],"id":10445502},{"batb":[[0,160,4.19]],"atb":[[160,3.88]],"id":99072897}],"tv":39438.42}],"rt":639159132320373156,"dt":639159132320374056}
{"op":"mcm","id":2,"clk":"AJGyAQDodQCj4AE=","pt":1780316432133,"mc":[{"id":"1.258742455","rc":[{"batb":[[0,4.9,40.71]],"atb":[[4.9,40.71]],"id":99072898},{"tv":1285.49,"batb":[[0,22,4.7]],"trd":[[22,108.34]],"atb":[[22,4.7]],"id":99072900},{"tv":2418.67,"batb":[[0,9,15.95]],"trd":[[9,108.78]],"atb":[[9,15.95]],"id":98117699},{"batb":[[0,3.45,67.34]],"atb":[[3.3,63.68],[3.45,67.34]],"id":88302242}],"tv":39444.74}],"rt":639159132321414417,"dt":639159132321415063}
{"op":"mcm","id":2,"clk":"AJqyAQDsdQCv4AE=","pt":1780316432238,"mc":[{"id":"1.258742455","rc":[{"batb":[[0,4.9,27.99]],"atb":[[4.9,27.99]],"id":99072898},{"atl":[[24,6.33]],"batl":[[1,24,6.33]],"id":99072900},{"atl":[[3.7,223.22]],"batl":[],"id":88302242}]}],"rt":639159132322468976,"dt":639159132322469409}
{"op":"mcm","id":2,"clk":"AJyyAQDtdQC34AE=","pt":1780316432286,"mc":[{"id":"1.258742455","rc":[{"atb":[[5.5,1.11]],"id":97008932},{"batb":[],"atb":[[3.25,25.03]],"atl":[[3.65,45.58]],"batl":[],"id":88302242}]}],"rt":639159132322939249,"dt":639159132322939591}
{"op":"mcm","id":2,"clk":"AKGyAQDzdQC64AE=","pt":1780316432389,"mc":[{"id":"1.258742455","rc":[{"batb":[],"atb":[[75,7.12]],"id":99072901},{"tv":8660.23,"batb":[[0,4.7,59.59]],"trd":[[4.7,1227.39]],"atb":[[4.7,59.59]],"id":10398159},{"batb":[[0,3.45,69.1]],"atb":[[3.45,69.1]],"id":88302242}],"tv":39472.74}],"rt":639159132323978798,"dt":639159132323979229}
{"op":"mcm","id":2,"clk":"AKiyAQD5dQDC4AE=","pt":1780316432497,"mc":[{"id":"1.258742455","rc":[{"batb":[[2,20,24.73]],"atb":[[20,24.73]],"id":99072900},{"atl":[[4.8,31.88]],"batl":[[0,4.8,31.88]],"id":10398159},{"batb":[[0,11,32.07]],"atb":[[11,32.07]],"id":97736949}]}],"rt":639159132325055966,"dt":639159132325056336}
{"op":"mcm","id":2,"clk":"AK6yAQD9dQDF4AE=","pt":1780316432592,"mc":[{"id":"1.258742455","rc":[{"batb":[[2,4.5,148.72],[0,4.7,77.21]],"atb":[[4.7,77.21],[4.5,148.72]],"id":10398159},{"tv":2559.48,"trd":[[11.5,56.4]],"ltp":11.5,"atl":[[11.5,18.45]],"batl":[[0,11.5,18.45]],"id":97736949}],"tv":39473.18}],"rt":639159132325999197,"dt":639159132325999573}
{"op":"mcm","id":2,"clk":"ALKyAQCEdgDO4AE=","pt":1780316432695,"mc":[{"id":"1.258742455","rc":[{"tv":8616.69,"batb":[[2,4.6,75.07],[1,4.7,48.95],[0,4.8,11.98]],"trd":[[4.9,734.64],[4.8,350.11]],"ltp":4.8,"atb":[[4.9,0],[4.8,11.98]],"id":99072898}],"tv":39646.16}],"rt":639159132327034940,"dt":639159132327035382}
{"op":"mcm","id":2,"clk":"ALmyAQCLdgDX4AE=","pt":1780316432808,"mc":[{"id":"1.258742455","rc":[{"atl":[[4.9,25.34]],"batl":[[2,5.1,49.59],[1,5,41.52],[0,4.9,25.34]],"id":99072898},{"atl":[[24,8.8],[23,4.82]],"batl":[[1,24,8.8],[0,23,4.82]],"id":99072900},{"batb":[[0,4.7,88.53]],"atb":[[4.7,88.53]],"atl":[[4.8,30.76]],"batl":[[0,4.8,30.76]],"id":10398159},{"batb":[[0,9,21.17]],"atb":[[9,21.17]],"id":98117699},{"tv":13768.33,"batb":[[0,3.45,67.1]],"trd":[[3.45,24.63]],"ltp":3.45,"atb":[[3.45,67.1]],"atl":[[3.5,6.75]],"batl":[[0,3.5,6.75]],"id":88302242},{"batb":[[0,11,36.87]],"atb":[[11,36.87]],"id":97736949}],"tv":39650.16}],"rt":639159132328163992,"dt":639159132328164577}
{"op":"mcm","id":2,"clk":"AMKyAQCPdgDi4AE=","pt":1780316432911,"mc":[{"id":"1.258742455","rc":[{"tv":8624.4,"batb":[[0,4.8,13.27]],"trd":[[4.8,357.82]],"atb":[[4.4,30.14],[4.8,13.27]],"atl":[[4.9,34.49]],"batl":[[0,4.9,34.49]],"id":99072898},{"batb":[[1,21,19.64]],"atb":[[21,19.64]],"id":99072900},{"batb":[[0,9,22.09]],"atb":[[9,22.09]],"atl":[[9.2,4.76]],"batl":[[0,9.2,4.76]],"id":98117699},{"batb":[[0,3.45,70.41]],"atb":[[3.45,70.41]],"atl":[[3.5,0]],"batl":[[2,3.65,45.58],[1,3.6,84.37],[0,3.55,46.26]],"id":88302242}],"tv":39657.87}],"rt":639159132329190730,"dt":639159132329191235}
{"op":"mcm","id":2,"clk":"AMeyAQCVdgDt4AE=","pt":1780316433016,"mc":[{"id":"1.258742455","rc":[{"tv":8627.41,"batb":[[1,4.7,50.49],[0,4.8,11.77]],"trd":[[4.8,360.83]],"atb":[[4.7,50.49],[4.8,11.77]],"atl":[[5.4,36.74],[4.9,42.46],[5,34.05]],"batl":[[1,5,34.05],[0,4.9,42.46]],"id":99072898},{"atl":[[50,9.66]],"batl":[[0,50,9.66]],"id":97008932},{"batb":[[2,20,23.34]],"atb":[[20,23.34]],"id":99072900},{"batb":[[0,4.7,85.65]],"atb":[[4.7,85.65]],"atl":[[4.9,55.13]],"batl":[[1,4.9,55.13]],"id":10398159},{"batb":[[0,9,19.96]],"atb":[[9,19.96]],"atl":[[9.4,11.75]],"batl":[[1,9.4,11.75]],"id":98117699},{"atl":[[3.55,46.08],[3.6,84.12]],"batl":[[1,3.6,84.12],[0,3.55,46.08]],"id":88302242},{"batb":[[0,11,34.76]],"atb":[[11,34.76]],"id":97736949}],"tv":39660.88}],"rt":639159132330240116,"dt":639159132330240771}
{"op":"mcm","id":2,"clk":"AMyyAQCXdgD24AE=","pt":1780316433111,"mc":[{"id":"1.258742455","rc":[{"batb":[[1,4.7,47.74]],"atb":[[4.7,47.74],[4.5,41.5]],"id":99072898},{"tv":13818.34,"batb":[[2,3.35,148.42],[0,3.45,45.41]],"trd":[[3.45,74.64]],"atb":[[3.35,148.42],[3.45,45.41]],"id":88302242}],"tv":39710.89}],"rt":639159132331187365,"dt":639159132331187823}
{"op":"mcm","id":2,"clk":"ANOyAQCcdgD\u002B4AE=","pt":1780316433215,"mc":[{"id":"1.258742455","rc":[{"tv":8628.19,"batb":[[1,4.7,46.2],[0,4.8,11.38]],"trd":[[4.8,361.61]],"atb":[[4.7,46.2],[4.8,11.38]],"atl":[[5.4,30.74]],"batl":[],"id":99072898},{"tv":1295.13,"batb":[[2,21,19.64],[1,22,4.7],[0,23,2.2]],"trd":[[23,77.42]],"ltp":23,"atb":[[23,2.2]],"atl":[[23,0]],"batl":[[2,26,17.19],[1,25,6.52],[0,24,8.8]],"id":99072900},{"atl":[[3.5,17.38]],"batl":[[2,3.6,84.12],[1,3.55,46.08],[0,3.5,17.38]],"id":88302242}],"tv":39721.31}],"rt":639159132332235863,"dt":639159132332236467}
{"op":"mcm","id":2,"clk":"ANeyAQCjdgCH4QE=","pt":1780316433317,"mc":[{"id":"1.258742455","rc":[{"batb":[[2,4.5,41.5],[1,4.6,75.07],[0,4.7,46.2]],"atb":[[4.4,36.14],[4.8,0]],"atl":[[4.9,49.81]],"batl":[[0,4.9,49.81]],"id":99072898},{"tv":1299.53,"batb":[[2,20,23.34],[1,21,19.64],[0,22,4.7]],"trd":[[23,81.82]],"atb":[[23,0],[19,17.86]],"atl":[[24,9.84]],"batl":[[0,24,9.84]],"id":99072900},{"atl":[[4.8,15.23]],"batl":[[0,4.8,15.23]],"id":10398159},{"batb":[[2,3.35,144.77]],"atb":[[3.35,144.77]],"atl":[[3.5,21.79],[3.55,46.85]],"batl":[[1,3.55,46.85],[0,3.5,21.79]],"id":88302242}],"tv":39725.71}],"rt":639159132333251613,"dt":639159132333252198}
{"op":"mcm","id":2,"clk":"ANqyAQCpdgCS4QE=","pt":1780316433422,"mc":[{"id":"1.258742455","rc":[{"tv":1303.65,"batb":[[2,21,19.64],[1,22,4.7],[0,23,1.92]],"trd":[[23,85.94]],"atb":[[23,1.92],[18,5.36]],"atl":[[25,8.88],[24,7.37]],"batl":[[1,25,8.88],[0,24,7.37]],"id":99072900},{"batb":[[0,3.45,42.1]],"atb":[[3.45,42.1]],"atl":[[3.7,217.22]],"batl":[],"id":88302242},{"atl":[[11.5,18.64]],"batl":[[0,11.5,18.64]],"id":97736949}],"tv":39729.83}],"rt":639159132334306031,"dt":639159132334306563}
{"op":"mcm","id":2,"clk":"AN\u002ByAQCtdgCb4QE=","pt":1780316433525,"mc":[{"id":"1.258742455","rc":[{"batb":[[0,4.7,37.29]],"atb":[[4.7,37.29]],"atl":[[5.3,27.15],[4.8,1.08]],"batl":[[2,5,34.05],[1,4.9,49.81],[0,4.8,1.08]],"id":99072898},{"tv":1307.49,"batb":[[2,20,23.34],[1,21,19.64],[0,22,4.7]],"trd":[[23,89.78]],"atb":[[23,0]],"atl":[[24,9.69]],"batl":[[0,24,9.69]],"id":99072900},{"atl":[[4.9,39.98]],"batl":[[1,4.9,39.98]],"id":10398159},{"tv":13818.82,"batb":[[0,3.45,41.86]],"trd":[[3.45,75.12]],"atb":[[3.45,41.86]],"atl":[[3.5,24.17]],"batl":[[0,3.5,24.17]],"id":88302242}],"tv":39734.15}],"rt":639159132335336752,"dt":639159132335337357}
{"op":"mcm","id":2,"clk":"AOeyAQCzdgCh4QE=","pt":1780316433625,"mc":[{"id":"1.258742455","rc":[{"batb":[[2,4.5,44.22],[1,4.6,72.32]],"atb":[[4.6,72.32],[4.5,44.22]],"id":99072898},{"batb":[[0,22,7.31]],"atb":[[22,7.31]],"id":99072900},{"atl":[[4.8,13.49]],"batl":[[0,4.8,13.49]],"id":10398159},{"atl":[[3.75,63.84]],"batl":[],"id":88302242}]}],"rt":639159132336332366,"dt":639159132336332783}
{"op":"mcm","id":2,"clk":"AOuyAQC4dgCo4QE=","pt":1780316433725,"mc":[{"id":"1.258742455","rc":[{"batb":[[0,4.7,39.24]],"atb":[[4.7,39.24]],"atl":[[4.8,2.38]],"batl":[[0,4.8,2.38]],"id":99072898},{"batb":[[0,22,8.16]],"atb":[[22,8.16]],"atl":[[27,7.84],[23,1.86]],"batl":[[2,25,8.88],[1,24,9.69],[0,23,1.86]],"id":99072900},{"atl":[[4.9,48.04]],"batl":[[1,4.9,48.04]],"id":10398159},{"batb":[[0,3.45,43.53]],"atb":[[3.45,43.53]],"id":88302242}]}],"rt":639159132337335569,"dt":639159132337336056}
{"op":"mcm","id":2,"clk":"APGyAQC5dgCx4QE=","pt":1780316433828,"mc":[{"id":"1.258742455","rc":[{"batb":[[0,4.7,73.84]],"atb":[[4.7,73.84],[4.4,30.14]],"id":99072898},{"batb":[[0,48,9.92]],"atb":[[48,9.92]],"id":97008932},{"tv":1309.21,"batb":[],"trd":[[23,91.5]],"atb":[[19,11.81]],"atl":[[23,1]],"batl":[[0,23,1]],"id":99072900},{"batb":[[0,90,7.49]],"atb":[[95,0.86]],"id":99072901},{"batb":[[0,4.7,120.25]],"atb":[[4.7,120.25]],"id":10398159},{"batb":[[0,50,23.44]],"atb":[[50,23.44]],"atl":[[75,5.65]],"batl":[],"id":98464183},{"batb":[[1,8.8,25.73],[0,9,34.66]],"atb":[[8.8,25.73],[9,34.66]],"id":98117699},{"batb":[[0,3.45,63.42]],"atb":[[3.45,63.42]],"id":88302242},{"batb":[[0,11,48.6]],"atb":[[11,48.6]],"id":97736949}],"tv":39735.87}],"rt":639159132338356978,"dt":639159132338357552}
{"op":"mcm","id":2,"clk":"APuyAQC7dgC\u002B4QE=","pt":1780316433940,"mc":[{"id":"1.258742455","rc":[{"batb":[],"atb":[[4.4,45.94]],"id":99072898},{"batb":[[0,48,12.72]],"atb":[[48,12.72]],"id":97008932},{"batb":[[1,21,19.05],[0,22,7.9]],"atb":[[22,7.9],[21,19.05]],"id":99072900},{"batb":[[0,3.45,82.61]],"atb":[[3.45,82.61]],"id":88302242}]}],"rt":639159132339484795,"dt":639159132339485211}
{"op":"mcm","id":2,"clk":"AP6yAQC7dgDG4QE=","pt":1780316434033,"mc":[{"id":"1.258742455","rc":[{"batb":[[0,4.7,92.72]],"atb":[[4.7,92.72],[4.3,17.42]],"id":99072898},{"batb":[[0,22,8.21]],"atb":[[22,8.21]],"id":99072900},{"atl":[[100,1.01]],"batl":[[0,100,1.01]],"id":99072901},{"batb":[],"atb":[[8.8,10.87]],"id":97736949}]}],"rt":639159132340408396,"dt":639159132340408860}
{"op":"mcm","id":2,"clk":"AISzAQDBdgDR4QE=","pt":1780316434139,"mc":[{"id":"1.258742455","rc":[{"tv":8631.51,"trd":[[4.8,364.93]],"atl":[[5.3,21.15],[4.8,0.72]],"batl":[[2,5.1,49.59],[1,5,34.05],[0,4.9,50.53]],"id":99072898},{"atl":[[3.75,57.84]],"batl":[],"id":88302242}],"tv":39739.19}],"rt":639159132341469091,"dt":639159132341469542}
{"op":"mcm","id":2,"clk":"AI2zAQDFdgDY4QE=","pt":1780316434241,"mc":[{"id":"1.258742455","rc":[{"batb":[[1,4.6,75.02]],"atb":[[4.6,75.02]],"atl":[[4.8,0]],"batl":[[0,4.9,49.81]],"id":99072898}]}],"rt":639159132342492830,"dt":639159132342493259}
{"op":"mcm","id":2,"clk":"AJWzAQDLdgDf4QE=","pt":1780316434293,"mc":[{"id":"1.258742455","rc":[{"batb":[[0,4.7,95.29]],"atb":[[4.7,95.29]],"atl":[[5.2,37.1]],"batl":[],"id":99072898},{"batb":[[0,22,7.9]],"atb":[[22,7.9]],"id":99072900},{"atl":[[3.7,223.22]],"batl":[],"id":88302242}]}],"rt":639159132343008374,"dt":639159132343008800}
{"op":"mcm","id":2,"clk":"AKCzAQDPdgDl4QE=","pt":1780316434428,"mc":[{"id":"1.258742455","rc":[{"atl":[[9.2,4.89]],"batl":[[0,9.2,4.89]],"id":98117699},{"atl":[[3.55,46.08]],"batl":[[1,3.55,46.08]],"id":88302242},{"tv":261.55,"batb":[[0,160,4.08]],"trd":[[170,28.84]],"atb":[[170,0.2]],"id":99072897}],"tv":39739.41}],"rt":639159132344361886,"dt":639159132344362319}
{"op":"mcm","id":2,"clk":"AKazAQDVdgDs4QE=","pt":1780316434498,"mc":[{"id":"1.258742455","rc":[{"atl":[[23,1.08]],"batl":[[0,23,1.08]],"id":99072900},{"atl":[[3.5,6.79]],"batl":[[0,3.5,6.79]],"id":88302242},{"tv":261.75,"batb":[[0,160,3.98]],"trd":[[170,29.04]],"atb":[[170,0.1]],"id":99072897}],"tv":39739.61}],"rt":639159132345059114,"dt":639159132345059524}
{"op":"mcm","id":2,"clk":"AK2zAQDedgD04QE=","pt":1780316434603,"mc":[{"id":"1.258742455","rc":[{"batb":[],"atb":[[19,14.81]],"id":99072900},{"tv":13832.39,"batb":[[2,3.4,88.49],[1,3.45,82.61],[0,3.5,6.98]],"trd":[[3.5,470.3]],"ltp":3.5,"atb":[[3.5,6.98]],"atl":[[3.5,0]],"batl":[[2,3.65,45.58],[1,3.6,84.12],[0,3.55,46.08]],"id":88302242},{"tv":261.95,"batb":[[0,160,3.75]],"trd":[[170,29.24]],"atb":[[120,5.55],[170,0],[160,3.75]],"id":99072897}],"tv":39753.38}],"rt":639159132346107884,"dt":639159132346108474}
{"op":"mcm","id":2,"clk":"ALOzAQDkdgD\u002B4QE=","pt":1780316434702,"mc":[{"id":"1.258742455","rc":[{"batb":[[1,4.6,72.32]],"atb":[[4.6,72.32]],"id":99072898},{"batb":[[1,46,13.36]],"atb":[[46,13.36]],"id":97008932},{"batb":[[1,21,20.78]],"atb":[[21,20.78]],"atl":[[23,1]],"batl":[[0,23,1]],"id":99072900},{"batb":[[0,9,37.51]],"atb":[[9,37.51]],"atl":[[9.2,5.02]],"batl":[[0,9.2,5.02]],"id":98117699},{"tv":13836.01,"batb":[[2,3.4,93.48],[0,3.5,5.17]],"trd":[[3.5,473.92]],"atb":[[3.5,5.17],[3.4,93.48],[3.35,149.82]],"id":88302242},{"tv":2562.78,"batb":[[0,11,49.54]],"trd":[[11,155.42]],"ltp":11,"atb":[[11,49.54]],"id":97736949},{"batb":[[0,160,3.71]],"atb":[[160,3.71]],"id":99072897}],"tv":39760.3}],"rt":639159132347104962,"dt":639159132347105665}
{"op":"mcm","id":2,"clk":"ALizAQDldgCB4gE=","pt":1780316434802,"mc":[{"id":"1.258742455","rc":[{"batb":[],"atb":[[4.4,53.41]],"atl":[[5.2,31.1]],"batl":[],"id":99072898},{"batb":[[0,48,9.92]],"atb":[[48,9.92]],"id":97008932},{"batb":[[0,22,8.1]],"atb":[[22,8.1]],"id":99072900},{"atl":[[3.7,217.22]],"batl":[],"id":88302242},{"batb":[[0,160,3.8]],"atb":[[160,3.8]],"id":99072897}]}],"rt":639159132348102758,"dt":639159132348103301}
{"op":"mcm","id":2,"clk":"AMOzAQDodgCL4gE=","pt":1780316435009,"mc":[{"id":"1.258742455","rc":[{"batb":[[0,22,7.9]],"atb":[[22,7.9]],"id":99072900},{"batb":[[1,3.45,88.72]],"atb":[[3.25,19.03],[3.45,88.72]],"id":88302242}]}],"rt":639159132350173882,"dt":639159132350174277}
{"op":"mcm","id":2,"clk":"AMWzAQDwdgCP4gE=","pt":1780316435107,"mc":[{"id":"1.258742455","rc":[{"atl":[[5.3,27.15]],"batl":[],"id":99072898},{"atl":[[23,1.08]],"batl":[[0,23,1.08]],"id":99072900},{"atl":[[3.75,63.84]],"batl":[],"id":88302242},{"batb":[[0,160,3.97]],"atb":[[160,3.97]],"id":99072897}]}],"rt":639159132351156592,"dt":639159132351157016}
{"op":"mcm","id":2,"clk":"AMuzAQD2dgCV4gE=","pt":1780316435209,"mc":[{"id":"1.258742455","rc":[{"batb":[[0,22,9.87]],"atb":[[22,9.87]],"id":99072900}]}],"rt":639159132352175804,"dt":639159132352176196}
{"op":"mcm","id":2,"clk":"AM\u002BzAQD7dgCe4gE=","pt":1780316435312,"mc":[{"id":"1.258742455","rc":[{"batb":[],"atb":[[3.3,69.68]],"id":88302242}]}],"rt":639159132353205915,"dt":639159132353206246}
{"op":"mcm","id":2,"clk":"ANSzAQD/dgCo4gE=","pt":1780316435420,"mc":[{"id":"1.258742455","rc":[{"batb":[],"atb":[[4.4,45.94]],"id":99072898},{"atl":[[23,1.77]],"batl":[[0,23,1.77]],"id":99072900},{"atl":[[9.2,5.2]],"batl":[[0,9.2,5.2]],"id":98117699},{"atl":[[3.55,46.87]],"batl":[[0,3.55,46.87]],"id":88302242}]}],"rt":639159132354282868,"dt":639159132354283251}
{"op":"mcm","id":2,"clk":"ANuzAQCFdwCu4gE=","pt":1780316435523,"mc":[{"id":"1.258742455","rc":[{"atl":[[11.5,20.54]],"batl":[[0,11.5,20.54]],"id":97736949}]}],"rt":639159132355310282,"dt":639159132355310649}
{"op":"mcm","id":2,"clk":"AOWzAQCPdwDD4gE=","pt":1780316435728,"mc":[{"id":"1.258742455","rc":[{"batb":[[0,4.7,97.6]],"atb":[[4.7,97.6]],"id":99072898},{"batb":[[0,4.7,127.47]],"atb":[[4.7,127.47]],"id":10398159},{"batb":[[0,50,23.65]],"atb":[[50,23.65]],"id":98464183},{"batb":[[0,9,38.98]],"atb":[[9,38.98]],"id":98117699},{"batb":[[0,3.5,8.39]],"atb":[[3.5,8.39]],"id":88302242},{"atl":[[11.5,20.73]],"batl":[[0,11.5,20.73]],"id":97736949},{"batb":[[0,1000,92.07]],"atb":[[1000,92.07]],"id":10445502},{"batb":[[0,160,4.04]],"atb":[[160,4.04]],"id":99072897}]}],"rt":639159132357363130,"dt":639159132357363667}
{"op":"mcm","id":2,"clk":"AOizAQCYdwDK4gE=","pt":1780316435828,"mc":[{"id":"1.258742455","rc":[{"batb":[[0,9,39.98]],"atb":[[9,39.98]],"id":98117699}]}],"rt":639159132358356175,"dt":639159132358356526}
{"op":"mcm","id":2,"clk":"AO2zAQCcdwDR4gE=","pt":1780316435930,"mc":[{"id":"1.258742455","rc":[{"tv":1324.01,"batb":[[0,22,2.47]],"trd":[[22,123.14]],"ltp":22,"atb":[[22,2.47]],"id":99072900},{"tv":13836.6,"batb":[[0,3.5,8.1]],"trd":[[3.5,474.51]],"atb":[[3.5,8.1]],"id":88302242},{"tv":2570.52,"batb":[[0,11,45.67]],"trd":[[11,163.16]],"atb":[[11,45.67]],"id":97736949}],"tv":39783.43}],"rt":639159132359379767,"dt":639159132359380172}
{"op":"mcm","id":2,"clk":"APKzAQCjdwDb4gE=","pt":1780316436035,"mc":[{"id":"1.258742455","rc":[{"atl":[[23,4.23]],"batl":[[0,23,4.23]],"id":99072900},{"tv":2582.53,"batb":[[0,11,39.67]],"trd":[[11,175.17]],"atb":[[11,39.67]],"id":97736949}],"tv":39795.44}],"rt":639159132360428943,"dt":639159132360429391}
{"op":"mcm","id":2,"clk":"APezAQCodwDl4gE=","pt":1780316436136,"mc":[{"id":"1.258742455","rc":[{"atl":[[5.8,12.64],[5.6,63.45]],"batl":[],"id":99072898},{"batb":[[0,22,4.3]],"atb":[[22,4.3],[19,11.81],[19.5,33.52],[1.01,85400.23],[17.5,18.2]],"atl":[[28,14.09],[26,4.46],[23,5.1]],"batl":[[0,23,5.1]],"id":99072900},{"tv":13846.63,"batb":[[0,3.5,3.08]],"trd":[[3.5,484.54]],"atb":[[3.5,3.08]],"id":88302242},{"batb":[[0,11,34.87]],"atb":[[11,34.87]],"id":97736949},{"batb":[],"atb":[[710,2],[700,1.29]],"id":10445502}],"tv":39805.47}],"rt":639159132361449137,"dt":639159132361449645}
{"op":"mcm","id":2,"clk":"AP2zAQCrdwDp4gE=","pt":1780316436238,"mc":[{"id":"1.258742455","rc":[{"atl":[[9.2,1.32]],"batl":[[0,9.2,1.32]],"id":98117699},{"batb":[[2,10,42.77],[0,11,34.15]],"atb":[[11,34.15],[10,42.77]],"atl":[[11.5,21.58]],"batl":[[0,11.5,21.58]],"id":97736949}]}],"rt":639159132362462701,"dt":639159132362463149}
{"op":"mcm","id":2,"clk":"AIS0AQCvdwDv4gE=","pt":1780316436291,"mc":[{"id":"1.258742455","rc":[{"atl":[[5.1,54.56]],"batl":[[2,5.1,54.56]],"id":99072898},{"atl":[[9.2,1.01]],"batl":[[0,9.2,1.01]],"id":98117699}]}],"rt":639159132362994010,"dt":639159132362994349}
{"op":"mcm","id":2,"clk":"AJK0AQC3dwD/4gE=","pt":1780316436497,"mc":[{"id":"1.258742455","rc":[{"tv":13849.93,"batb":[[0,3.5,1.43]],"trd":[[3.5,487.84]],"atb":[[3.5,1.43]],"id":88302242}],"tv":39808.77}],"rt":639159132365053004,"dt":639159132365053368}
{"op":"mcm","id":2,"clk":"AKS0AQDCdwCP4wE=","pt":1780316436704,"mc":[{"id":"1.258742455","rc":[{"tv":13850.73,"batb":[[0,3.5,1.03]],"trd":[[3.5,488.64]],"atb":[[3.5,1.03]],"id":88302242}],"tv":39809.57}],"rt":639159132367120405,"dt":639159132367120787}
{"op":"mcm","id":2,"clk":"ALC0AQDQdwCb4wE=","pt":1780316436909,"mc":[{"id":"1.258742455","rc":[{"tv":8637.51,"batb":[[0,4.7,94.6]],"trd":[[4.7,80.98]],"ltp":4.7,"atb":[[4.7,94.6]],"id":99072898}],"tv":39815.57}],"rt":639159132369169917,"dt":639159132369170273}
{"op":"mcm","id":2,"clk":"ALO0AQDTdwCh4wE=","pt":1780316437008,"mc":[{"id":"1.258742455","rc":[{"atl":[[4.8,3.7]],"batl":[[2,5,34.05],[1,4.9,49.81],[0,4.8,3.7]],"id":99072898}]}],"rt":639159132370165567,"dt":639159132370165956}
{"op":"mcm","id":2,"clk":"AL\u002B0AQDXdwCm4wE=","pt":1780316437111,"mc":[{"id":"1.258742455","rc":[{"batb":[[2,140,3.44]],"atb":[[140,3.44]],"id":99072897}]}],"rt":639159132371194402,"dt":639159132371194750}
{"op":"mcm","id":2,"clk":"AMW0AQDZdwCt4wE=","pt":1780316437214,"mc":[{"id":"1.258742455","rc":[{"atl":[[5.1,49.59],[4.8,3.89]],"batl":[[0,4.8,3.89]],"id":99072898}]}],"rt":639159132372219671,"dt":639159132372220011}
{"op":"mcm","id":2,"clk":"AM60AQDddwCy4wE=","pt":1780316437315,"mc":[{"id":"1.258742455","rc":[{"atb":[[1.31,282.9]],"id":88302242}]}],"rt":639159132373227463,"dt":639159132373227814}
{"op":"mcm","id":2,"clk":"ANe0AQDmdwC84wE=","pt":1780316437523,"mc":[{"id":"1.258742455","rc":[{"atl":[[5.3,21.15]],"batl":[],"id":99072898},{"atb":[[1.17,2.1]],"id":10398159},{"tv":2420.67,"batb":[[0,9,38.98]],"trd":[[9,110.78]],"atb":[[9,38.98]],"id":98117699},{"atl":[[11.5,20.95]],"batl":[[0,11.5,20.95]],"id":97736949}],"tv":39817.57}],"rt":639159132375311040,"dt":639159132375311451}
{"op":"mcm","id":2,"clk":"ANq0AQDqdwDB4wE=","pt":1780316437623,"mc":[{"id":"1.258742455","rc":[{"atb":[[1.17,2.71]],"id":99072898},{"tv":1326.93,"batb":[[0,22,2.84]],"trd":[[22,126.06]],"atb":[[22,2.84]],"atl":[[23,7.29]],"batl":[[0,23,7.29]],"id":99072900}],"tv":39820.49}],"rt":639159132376317518,"dt":639159132376317981}
{"op":"mcm","id":2,"clk":"AOO0AQDvdwDI4wE=","pt":1780316437727,"mc":[{"id":"1.258742455","rc":[{"atb":[[1.17,2.28]],"atl":[[5.2,37.1]],"batl":[],"id":99072898},{"batb":[[0,90,6.55]],"atb":[[90,5.69]],"id":99072901},{"tv":8660.43,"trd":[[4.8,527.79]],"ltp":4.8,"atl":[[4.8,13.39]],"batl":[[0,4.8,13.39]],"id":10398159},{"atl":[[9.2,5.16]],"batl":[[0,9.2,5.16]],"id":98117699}],"tv":39820.69}],"rt":639159132377356828,"dt":639159132377357333}
{"op":"mcm","id":2,"clk":"AOe0AQDzdwDN4wE=","pt":1780316437826,"mc":[{"id":"1.258742455","rc":[{"batb":[[0,4.7,95.03]],"atb":[[4.7,95.03],[1.17,2]],"atl":[[4.8,3.7]],"batl":[[0,4.8,3.7]],"id":99072898},{"tv":414.08,"batb":[[0,90,6.64]],"trd":[[100,32.29]],"atb":[[100,0.09]],"atl":[[100,0]],"batl":[[2,130,2.65],[1,120,1.83],[0,110,6.21]],"id":99072901},{"atb":[[1.17,2]],"id":10398159}],"tv":39822.71}],"rt":639159132378340263,"dt":639159132378340706}
{"op":"mcm","id":2,"clk":"APG0AQD7dwDX4wE=","pt":1780316437932,"mc":[{"id":"1.258742455","rc":[{"tv":8638.07,"trd":[[4.8,365.49]],"ltp":4.8,"atl":[[4.8,3.42]],"batl":[[0,4.8,3.42]],"id":99072898},{"tv":414.26,"batb":[[1,85,8.9],[0,90,7.41]],"trd":[[100,32.47]],"atb":[[100,0],[90,6.55],[85,8.9]],"atl":[[100,0.1]],"batl":[[0,110,6.31]],"id":99072901},{"batb":[[0,4.7,127.57]],"atb":[[4.7,127.57]],"id":10398159},{"atl":[[3.55,47.64]],"batl":[[0,3.55,47.64]],"id":88302242}],"tv":39823.45}],"rt":639159132379401497,"dt":639159132379401997}
{"op":"mcm","id":2,"clk":"APa0AQD\u002BdwDe4wE=","pt":1780316438036,"mc":[{"id":"1.258742455","rc":[{"batb":[[0,90,7.54]],"atb":[[95,0.99]],"atl":[[130,1.62]],"batl":[[2,130,1.62]],"id":99072901},{"tv":8662.01,"batb":[[0,4.7,134.57]],"trd":[[4.8,529.37]],"atb":[[4.7,134.57]],"atl":[[4.8,12.6]],"batl":[[0,4.8,12.6]],"id":10398159},{"atb":[[5.5,15.78]],"id":97736949}],"tv":39825.03}],"rt":639159132380440941,"dt":639159132380441667}
{"op":"mcm","id":2,"clk":"APy0AQCCeADm4wE=","pt":1780316438142,"mc":[{"id":"1.258742455","rc":[{"batb":[[2,85,8.9],[1,90,6.55],[0,95,2]],"atb":[[95,2]],"id":99072901},{"tv":13851.32,"batb":[[2,3.35,149.82],[1,3.4,93.48],[0,3.45,89.46]],"trd":[[3.5,489.23]],"atb":[[3.5,0.74]],"id":88302242}],"tv":39825.62}],"rt":639159132381501984,"dt":639159132381502537}
{"op":"mcm","id":2,"clk":"AIK1AQCDeADu4wE=","pt":1780316438240,"mc":[{"id":"1.258742455","rc":[{"atl":[[4.8,3.72]],"batl":[[0,4.8,3.72]],"id":99072898},{"tv":8668.89,"batb":[[2,4.5,145.98],[0,4.7,139.37]],"trd":[[4.8,536.25]],"atb":[[4.7,139.37],[4.4,181.48],[4.5,145.98]],"atl":[[4.8,9.16]],"batl":[[0,4.8,9.16]],"id":10398159},{"batb":[[0,3.45,94.43]],"atb":[[3.45,93.69]],"id":88302242}],"tv":39832.5}],"rt":639159132382480178,"dt":639159132382480854}
{"op":"mcm","id":2,"clk":"AIq1AQCKeAD14wE=","pt":1780316438337,"mc":[{"id":"1.258742455","rc":[{"tv":8645.51,"batb":[[2,4.6,72.32],[1,4.7,95.03],[0,4.8,7.61]],"trd":[[4.8,372.93]],"atb":[[4.8,7.61]],"atl":[[4.8,0]],"batl":[[2,5.1,49.59],[1,5,34.05],[0,4.9,49.81]],"id":99072898},{"batb":[[0,95,3.8]],"atb":[[95,3.8]],"id":99072901},{"tv":8671.33,"trd":[[4.8,538.69]],"atl":[[4.8,7.94]],"batl":[[0,4.8,7.94]],"id":10398159}],"tv":39842.38}],"rt":639159132383450674,"dt":639159132383451338}
{"op":"mcm","id":2,"clk":"AI61AQCMeAD94wE=","pt":1780316438444,"mc":[{"id":"1.258742455","rc":[{"batb":[[2,4.6,76.34]],"atb":[[4.6,76.34]],"id":99072898},{"tv":8684.67,"trd":[[4.8,552.03]],"atl":[[4.8,1.27]],"batl":[[0,4.8,1.27]],"id":10398159},{"batb":[[0,3.45,89.46]],"atb":[[3.45,88.72]],"id":88302242}],"tv":39855.72}],"rt":639159132384523646,"dt":639159132384524112}
{"op":"mcm","id":2,"clk":"AJO1AQCQeACI5AE=","pt":1780316438505,"mc":[{"id":"1.258742455","rc":[{"batb":[[1,4.7,97.8]],"atb":[[4.7,97.8]],"atl":[[4.9,41.84]],"batl":[[0,4.9,41.84]],"id":99072898},{"batb":[[2,19.5,33.52],[1,20,23.34],[0,21,20.78]],"atb":[[22,0]],"id":99072900},{"batb":[[1,90,7.7],[0,95,3.89]],"atb":[[95,3.89],[90,7.7]],"id":99072901},{"tv":8685.62,"trd":[[4.8,552.98]],"atl":[[4.8,0.8]],"batl":[[2,5.1,55.01],[1,5,90.98],[0,4.9,48.84]],"id":10398159}],"tv":39856.67}],"rt":639159132385130191,"dt":639159132385130614}
{"op":"mcm","id":2,"clk":"AJi1AQCWeACU5AE=","pt":1780316438603,"mc":[{"id":"1.258742455","rc":[{"batb":[[0,48,9.12]],"atb":[[48,9.12]],"atl":[[55,23.06]],"batl":[[1,55,23.06]],"id":97008932},{"batb":[[1,90,7.44],[0,95,5.06]],"atb":[[95,5.06],[90,7.44]],"id":99072901},{"tv":8687.22,"batb":[[0,4.7,139.84]],"trd":[[4.8,554.58]],"atb":[[4.8,0.47]],"atl":[[4.8,0]],"batl":[[0,4.9,48.04]],"id":10398159},{"atl":[[9.2,5.25]],"batl":[[0,9.2,5.25]],"id":98117699},{"batb":[],"atb":[[3.3,63.68]],"atl":[[3.55,48.71]],"batl":[[0,3.55,48.71]],"id":88302242}],"tv":39858.27}],"rt":639159132386109847,"dt":639159132386110570}
{"op":"mcm","id":2,"clk":"AJ21AQCbeACa5AE=","pt":1780316438704,"mc":[{"id":"1.258742455","rc":[{"atl":[[4.9,35.21]],"batl":[[0,4.9,35.21]],"id":99072898},{"batb":[[1,90,6.58]],"atb":[[90,6.58]],"id":99072901},{"tv":13852.54,"trd":[[3.55,863.47]],"ltp":3.55,"atl":[[3.55,58.1]],"batl":[[0,3.55,58.1]],"id":88302242}],"tv":39859.49}],"rt":639159132387120387,"dt":639159132387120921}
{"op":"mcm","id":2,"clk":"AKe1AQCfeACi5AE=","pt":1780316438810,"mc":[{"id":"1.258742455","rc":[{"batb":[[0,4.8,8.72]],"atb":[[4.3,11.42],[4.8,8.72]],"atl":[[5.2,31.1]],"batl":[],"id":99072898},{"tv":2456.69,"batb":[[0,9,20.97]],"trd":[[9,146.8]],"atb":[[9,20.97]],"id":98117699}],"tv":39895.51}],"rt":639159132388175823,"dt":639159132388176377}
{"op":"mcm","id":2,"clk":"AKq1AQCmeACt5AE=","pt":1780316438911,"mc":[{"id":"1.258742455","rc":[{"batb":[],"atb":[[4.4,174.98]],"id":10398159},{"atl":[[9.2,8.12]],"batl":[[0,9.2,8.12]],"id":98117699},{"tv":13882.2,"batb":[],"trd":[[3.55,893.13]],"atb":[[3.25,25.03]],"atl":[[3.55,43.27]],"batl":[[0,3.55,43.27]],"id":88302242}],"tv":39925.17}],"rt":639159132389192479,"dt":639159132389193019}
{"op":"mcm","id":2,"clk":"AKu1AQCpeACw5AE=","pt":1780316439008,"mc":[{"id":"1.258742455","rc":[{"batb":[[0,4.8,9.4]],"atb":[[4.8,9.4]],"atl":[[4.9,37.16]],"batl":[[0,4.9,37.16]],"id":99072898},{"atl":[[5.2,41.82]],"batl":[],"id":10398159},{"batb":[[0,9,23.97]],"atb":[[9,23.97]],"atl":[[9.2,10.9]],"batl":[[0,9.2,10.9]],"id":98117699},{"batb":[[2,3.4,93.48],[1,3.45,88.72],[0,3.5,17.31]],"atb":[[3.5,17.31]],"id":88302242}]}],"rt":639159132390163931,"dt":639159132390164579}
