{"op":"mcm","id":2,"clk":"AJ/kAgCvmwIA0rwC","pt":1743512144861,"mc":[{"id":"1.241629436","rc":[{"atb":[[6.8,225.59]],"atl":[[1000,3.9]],"trd":[[6.8,849.27]],"batb":[[0,6.8,225.59]],"ltp":6.8,"tv":14506.19,"id":26496185},{"atb":[[11,113.36]],"trd":[[11,1702.38]],"batb":[[0,11,113.36]],"tv":5270.94,"id":44049799}],"tv":89145.93}]}
{"op":"mcm","id":2,"clk":"AKfkAgC6mwIA3rwC","pt":1743512144962,"mc":[{"id":"1.241629436","rc":[{"atl":[[7.2,161.23]],"batl":[[1,7.2,161.23]],"id":26496185},{"atl":[[40,0]],"id":44049799}]}]}
{"op":"mcm","id":2,"clk":"ALLkAgDMmwIA6LwC","pt":1743512145074,"mc":[{"id":"1.241629436","rc":[{"atl":[[16.5,10.9]],"id":27115873}]}]}
{"op":"mcm","id":2,"clk":"ALjkAgDZmwIA7LwC","pt":1743512145168,"mc":[{"id":"1.241629436","rc":[{"atl":[[7.2,151.23]],"batl":[[1,7.2,151.23]],"id":26496185}]}]}
{"op":"mcm","id":2,"clk":"AL3kAgDkmwIA+LwC","pt":1743512145282,"mc":[{"id":"1.241629436","rc":[{"atb":[[5.1,235.48]],"atl":[[14,0]],"trd":[[5.1,4778.69]],"batb":[[0,5.1,235.48]],"tv":14052.87,"id":56297029}],"tv":89205.93}]}
{"op":"mcm","id":2,"clk":"AMfkAgDumwIAgb0C","pt":1743512145381,"mc":[{"id":"1.241629436","rc":[{"atl":[[500,0.01]],"id":270592}]}]}
{"op":"mcm","id":2,"clk":"ANHkAgD3mwIAib0C","pt":1743512145488,"mc":[{"id":"1.241629436","rc":[{"atl":[[500,0.02]],"id":270592},{"atl":[[21,2.23]],"id":35856222},{"atb":[[5.1,240.48]],"batb":[[0,5.1,240.48]],"id":56297029}]}]}
{"op":"mcm","id":2,"clk":"ANnkAgCBnAIAk70C","pt":1743512145588,"mc":[{"id":"1.241629436","rc":[{"atl":[[500,0.03]],"id":270592}]}]}
{"op":"mcm","id":2,"clk":"AN7kAgCFnAIAmr0C","pt":1743512145681,"mc":[{"id":"1.241629436","rc":[{"atb":[[4.6,46.89],[5.1,219.24]],"batb":[[0,5.1,219.24]],"id":56297029}]}]}
{"op":"mcm","id":2,"clk":"AOfkAgCQnAIAp70C","pt":1743512145785,"mc":[{"id":"1.241629436","rc":[{"atl":[[48,0]],"id":44049799}]}]}
{"op":"mcm","id":2,"clk":"APDkAgCbnAIArr0C","pt":1743512145884,"mc":[{"id":"1.241629436","rc":[{"atb":[[4.2,146.97]],"batb":[],"id":270592},{"atb":[[6.6,271.7]],"batb":[[1,6.6,271.7]],"id":26496185}]}]}
{"op":"mcm","id":2,"clk":"APbkAgCfnAIAsb0C","pt":1743512145986,"mc":[{"id":"1.241629436","rc":[{"atb":[[5.1,224.24]],"batb":[[0,5.1,224.24]],"id":56297029}]}]}
{"op":"mcm","id":2,"clk":"AP7kAgCpnAIAub0C","pt":1743512146088,"mc":[{"id":"1.241629436","rc":[{"atb":[[11.5,57.9]],"trd":[[11.5,1439.11]],"batb":[[0,11.5,57.9]],"ltp":11.5,"tv":6786.56,"id":40389088},{"atl":[[80,1.99]],"id":58186642}],"tv":89271.92}]}
{"op":"mcm","id":2,"clk":"AIXlAgCvnAIAvr0C","pt":1743512146192,"mc":[{"id":"1.241629436","rc":[{"atb":[[11.5,55.74]],"batb":[[0,11.5,55.74]],"id":40389088},{"atb":[[50,23.32]],"batb":[[0,50,23.32]],"id":59626646},{"atl":[[500,0.01]],"id":56297029},{"atb":[[17.5,33.21]],"trd":[[17.5,269.23]],"batb":[[0,17.5,33.21]],"tv":6277.67,"id":58186642}],"tv":89276.68}]}
{"op":"mcm","id":2,"clk":"AJDlAgC0nAIAxr0C","pt":1743512146294,"mc":[{"id":"1.241629436","rc":[{"atb":[[11.5,67.08]],"atl":[[12,75.48]],"trd":[[12,1429.87]],"batb":[[0,11.5,67.08]],"batl":[[0,12,75.48]],"ltp":12,"tv":6790.94,"id":40389088},{"atb":[[5.1,229.24]],"atl":[[500,0.03]],"batb":[[0,5.1,229.24]],"id":56297029}],"tv":89281.06}]}
{"op":"mcm","id":2,"clk":"AJflAgDBnAIAzL0C","pt":1743512146402,"mc":[{"id":"1.241629436","rc":[{"atb":[[5.9,9.02]],"id":40389088},{"atb":[[5.1,226.24]],"trd":[[5.1,4784.69]],"batb":[[0,5.1,226.24]],"tv":14058.87,"id":56297029}],"tv":89287.06}]}
{"op":"mcm","id":2,"clk":"AKPlAgDFnAIA0r0C","pt":1743512146458,"mc":[{"id":"1.241629436","rc":[{"atb":[[5.1,231.24]],"batb":[[0,5.1,231.24]],"id":56297029}]}]}
{"op":"mcm","id":2,"clk":"ALHlAgDMnAIA270C","pt":1743512146562,"mc":[{"id":"1.241629436","rc":[{"atb":[[1.17,2.68]],"id":40389088}]}]}
{"op":"mcm","id":2,"clk":"ALnlAgDWnAIA5L0C","pt":1743512146661,"mc":[{"id":"1.241629436","rc":[{"atb":[[1.17,2]],"id":40389088},{"atb":[[4.1,108.58]],"batb":[],"id":270592},{"atb":[[5.1,236.24]],"batb":[[0,5.1,236.24]],"id":56297029},{"atl":[[17.5,1.99]],"id":26496185}]}]}
{"op":"mcm","id":2,"clk":"AMHlAgDgnAIA7L0C","pt":1743512146759,"mc":[{"id":"1.241629436","rc":[{"atb":[[11.5,67.76]],"batb":[[0,11.5,67.76]],"id":40389088},{"atl":[[4.7,47.6]],"trd":[[4.7,2684.81]],"batl":[[0,4.7,47.6]],"tv":22691.6,"id":270592},{"atl":[[19.5,10.58]],"batl":[],"id":58186642}],"tv":89289.76}]}
{"op":"mcm","id":2,"clk":"AMzlAgDqnAIA8b0C","pt":1743512146857,"mc":[{"id":"1.241629436","rc":[{"atl":[[4.7,45.6]],"trd":[[4.7,2688.81]],"batl":[[0,4.7,45.6]],"tv":22695.6,"id":270592},{"atb":[[5.1,241.24]],"batb":[[0,5.1,241.24]],"id":56297029},{"atl":[[17.5,6.54]],"id":27115873},{"atb":[[6.6,268.9]],"batb":[[1,6.6,268.9]],"id":26496185}],"tv":89293.76}]}
{"op":"mcm","id":2,"clk":"AOblAgCLnQIAh74C","pt":1743512147165,"mc":[{"id":"1.241629436","rc":[{"atb":[[5.1,246.24]],"atl":[[15,4.26]],"batb":[[0,5.1,246.24]],"id":56297029},{"atl":[[500,0.01]],"id":26496185}]}]}
{"op":"mcm","id":2,"clk":"APDlAgCRnQIAlb4C","pt":1743512147268,"mc":[{"id":"1.241629436","rc":[{"atl":[[500,0.02]],"id":26496185}]}]}
{"op":"mcm","id":2,"clk":"APflAgCXnQIAnL4C","pt":1743512147372,"mc":[{"id":"1.241629436","rc":[{"atb":[[11,77.03]],"batb":[[1,11,77.03]],"id":40389088},{"atb":[[5.1,251.24]],"batb":[[0,5.1,251.24]],"id":56297029},{"atb":[[6.4,275.7]],"atl":[[7,99.02]],"batb":[[2,6.4,275.7]],"batl":[[0,7,99.02]],"id":26496185},{"atb":[[11,112.71]],"batb":[[0,11,112.71]],"id":44049799}]}]}
{"op":"mcm","id":2,"clk":"AIDmAgCenQIApr4C","pt":1743512147476,"mc":[{"id":"1.241629436","rc":[{"atb":[[6.2,26.16]],"id":40389088},{"atb":[[5.1,256.24]],"batb":[[0,5.1,256.24]],"id":56297029},{"atl":[[500,0.03]],"id":26496185}]}]}
{"op":"mcm","id":2,"clk":"AIbmAgCknQIArb4C","pt":1743512147579,"mc":[{"id":"1.241629436","rc":[{"atb":[[9.6,72.84]],"trd":[[9.6,640.38]],"batb":[[0,9.6,72.84]],"tv":10100.1,"id":35856222},{"atb":[[5.1,250.64]],"trd":[[5.1,4795.89]],"batb":[[0,5.1,250.64]],"tv":14070.07,"id":56297029},{"atb":[[10,104.61]],"trd":[[10,835.82]],"batb":[[0,10,104.61]],"tv":7529.73,"id":27115873},{"atl":[[7,103.1]],"batl":[[0,7,103.1]],"id":26496185},{"atb":[[11,110.12]],"trd":[[11,1707.56]],"batb":[[0,11,110.12]],"tv":5276.12,"id":44049799}],"tv":89320.42}]}
{"op":"mcm","id":2,"clk":"AI7mAgCynQIAtb4C","pt":1743512147685,"mc":[{"id":"1.241629436","rc":[{"atl":[[12,73.48]],"trd":[[12,1433.87]],"batl":[[0,12,73.48]],"tv":6794.94,"id":40389088},{"atl":[[5.2,325.72]],"batl":[[0,5.2,325.72]],"id":56297029},{"atb":[[6.8,227.6]],"batb":[[0,6.8,227.6]],"id":26496185}],"tv":89324.42}]}
{"op":"mcm","id":2,"clk":"AJbmAgC3nQIAur4C","pt":1743512147786,"mc":[{"id":"1.241629436","rc":[{"atb":[[5.1,255.64]],"batb":[[0,5.1,255.64]],"id":56297029},{"atb":[[10,113.27]],"batb":[[0,10,113.27]],"id":27115873}]}]}
{"op":"mcm","id":2,"clk":"AJ7mAgC+nQIAw74C","pt":1743512147887,"mc":[{"id":"1.241629436","rc":[{"atb":[[11.5,75.41]],"batb":[[0,11.5,75.41]],"id":40389088}]}]}
{"op":"mcm","id":2,"clk":"AKTmAgDInQIAzb4C","pt":1743512147990,"mc":[{"id":"1.241629436","rc":[{"atl":[[19,6.98]],"id":40389088},{"atb":[[5.1,260.64]],"batb":[[0,5.1,260.64]],"id":56297029}]}]}
{"op":"mcm","id":2,"clk":"AKnmAgDRnQIA0r4C","pt":1743512148094,"mc":[{"id":"1.241629436","rc":[{"atb":[[9.6,71.34]],"trd":[[9.6,643.38]],"batb":[[0,9.6,71.34]],"tv":10103.1,"id":35856222}],"tv":89327.42}]}
{"op":"mcm","id":2,"clk":"ALfmAgDZnQIA4b4C","pt":1743512148195,"mc":[{"id":"1.241629436","rc":[{"atl":[[500,0.01]],"id":35856222},{"atb":[[5.1,266.82]],"atl":[[5.2,308.72]],"trd":[[5.2,3872.59]],"batb":[[0,5.1,266.82]],"batl":[[0,5.2,308.72]],"ltp":5.2,"tv":14104.07,"id":56297029}],"tv":89361.42}]}
{"op":"mcm","id":2,"clk":"AMPmAgDknQIA6r4C","pt":1743512148258,"mc":[{"id":"1.241629436","rc":[{"atl":[[4.8,248.51]],"batl":[[1,4.8,248.51]],"id":270592},{"atb":[[9.6,86.09]],"batb":[[0,9.6,86.09]],"id":35856222}]}]}
{"op":"mcm","id":2,"clk":"AM/mAgDrnQIA874C","pt":1743512148359,"mc":[{"id":"1.241629436","rc":[{"atl":[[500,0.02]],"id":35856222},{"atl":[[55,13.8]],"trd":[[55,362.64]],"batl":[[0,55,13.8]],"ltp":55,"tv":2079.54,"id":59626646},{"atb":[[5.1,271.82]],"batb":[[0,5.1,271.82]],"id":56297029},{"atb":[[11,123.12]],"batb":[[0,11,123.12]],"id":44049799}],"tv":89366.96}]}
{"op":"mcm","id":2,"clk":"ANrmAgDznQIAgL8C","pt":1743512148457,"mc":[{"id":"1.241629436","rc":[{"atb":[[11.5,74.15]],"trd":[[11.5,1441.62]],"batb":[[0,11.5,74.15]],"ltp":11.5,"tv":6797.45,"id":40389088},{"atb":[[4.6,278.61]],"batb":[[0,4.6,278.61]],"id":270592},{"atl":[[55,11.67]],"batl":[[0,55,11.67]],"id":59626646}],"tv":89369.47}]}
{"op":"mcm","id":2,"clk":"AO3mAgCCngIAj78C","pt":1743512148675,"mc":[{"id":"1.241629436","rc":[{"atl":[[500,0.03]],"id":35856222},{"atb":[[5.1,276.82]],"batb":[[0,5.1,276.82]],"id":56297029}]}]}
{"op":"mcm","id":2,"clk":"AP/mAgCNngIApL8C","pt":1743512148870,"mc":[{"id":"1.241629436","rc":[{"atb":[[5.1,281.82]],"batb":[[0,5.1,281.82]],"id":56297029}]}]}
{"op":"mcm","id":2,"clk":"AIrnAgCWngIArr8C","pt":1743512148969,"mc":[{"id":"1.241629436","rc":[{"atb":[[4.6,279.17]],"batb":[[0,4.6,279.17]],"id":270592}]}]}
{"op":"mcm","id":2,"clk":"AJTnAgCfngIAtr8C","pt":1743512149068,"mc":[{"id":"1.241629436","rc":[{"atl":[[70,6.17]],"batl":[],"id":59626646},{"atb":[[5.1,286.82]],"batb":[[0,5.1,286.82]],"id":56297029}]}]}
{"op":"mcm","id":2,"clk":"AJ3nAgCtngIAxr8C","pt":1743512149176,"mc":[{"id":"1.241629436","rc":[{"atl":[[4.7,0]],"trd":[[4.7,2780.01]],"batl":[[2,5,305.84],[1,4.9,292.5],[0,4.8,248.51]],"tv":22786.8,"id":270592},{"atl":[[10,141.18]],"batl":[[1,10,141.18]],"id":35856222},{"atl":[[500,0.01]],"id":27115873},{"atb":[[6,155.56]],"batb":[],"id":26496185}],"tv":89460.67}]}
{"op":"mcm","id":2,"clk":"AKfnAgC7ngIAzL8C","pt":1743512149277,"mc":[{"id":"1.241629436","rc":[{"atb":[[4.6,276.08],[4.5,245.6]],"atl":[[4.8,215.13]],"batb":[[1,4.5,245.6],[0,4.6,276.08]],"batl":[[0,4.8,215.13]],"id":270592},{"atb":[[5.1,290.82]],"trd":[[5.1,4797.89]],"batb":[[0,5.1,290.82]],"ltp":5.1,"tv":14106.07,"id":56297029},{"atl":[[500,0.02]],"id":27115873},{"atb":[[17.5,0]],"atl":[[19.5,13.74],[17.5,0.8]],"trd":[[17.5,335.64]],"batb":[[2,16,11.65],[1,16.5,22.27],[0,17,43.11]],"batl":[[0,18,36.26]],"tv":6344.08,"id":58186642}],"tv":89529.08}]}
{"op":"mcm","id":2,"clk":"AK7nAgDJngIA1L8C","pt":1743512149382,"mc":[{"id":"1.241629436","rc":[{"atb":[[4.6,308.21]],"atl":[[5,304.91]],"batb":[[0,4.6,308.21]],"batl":[[2,5,304.91]],"id":270592},{"atb":[[9.6,96.09]],"batb":[[0,9.6,96.09]],"id":35856222},{"atl":[[500,0.03]],"id":27115873},{"atb":[[17,37.69]],"atl":[[20,14.11],[18.5,25.94],[18,40.96],[17.5,5.02]],"trd":[[17.5,343.56]],"batb":[[0,17,37.69]],"batl":[[2,18.5,25.94],[1,18,40.96],[0,17.5,5.02]],"tv":6352,"id":58186642}],"tv":89537}]}
{"op":"mcm","id":2,"clk":"ALznAgDRngIA478C","pt":1743512149486,"mc":[{"id":"1.241629436","rc":[{"atb":[[15,15.82],[16,6.9],[16.5,19.14]],"atl":[[20,10.06],[18,44.71]],"batb":[[2,16,6.9],[1,16.5,19.14]],"batl":[[1,18,44.71]],"id":58186642}]}]}
{"op":"mcm","id":2,"clk":"AMXnAgDdngIA5b8C","pt":1743512149583,"mc":[{"id":"1.241629436","rc":[{"atb":[[4.6,303.21]],"atl":[[5.1,137.29]],"trd":[[4.6,537.04]],"batb":[[0,4.6,303.21]],"batl":[],"ltp":4.6,"tv":22796.8,"id":270592},{"atb":[[5.1,293.52]],"trd":[[5.1,4802.49]],"batb":[[0,5.1,293.52]],"tv":14110.67,"id":56297029},{"atb":[[16,10.14]],"batb":[[2,16,10.14]],"id":58186642}],"tv":89551.6}]}
{"op":"mcm","id":2,"clk":"ANDnAgDtngIA7L8C","pt":1743512149685,"mc":[{"id":"1.241629436","rc":[{"atb":[[4.6,301.21]],"trd":[[4.6,541.03]],"batb":[[0,4.6,301.21]],"tv":22800.79,"id":270592},{"atb":[[9.6,101.84]],"batb":[[0,9.6,101.84]],"id":35856222},{"atb":[[10,112.27]],"trd":[[10,837.82]],"batb":[[0,10,112.27]],"tv":7531.73,"id":27115873},{"atb":[[16,19.93],[16.5,8.52]],"batb":[[2,16,19.93],[1,16.5,8.52]],"id":58186642},{"atl":[[7,104.1]],"batl":[[0,7,104.1]],"id":26496185}],"tv":89557.59}]}
{"op":"mcm","id":2,"clk":"ANjnAgD6ngIA/b8C","pt":1743512149795,"mc":[{"id":"1.241629436","rc":[{"atl":[[5.3,83.12]],"batl":[[1,5.3,83.12]],"id":56297029},{"atb":[[15.5,31.2]],"batb":[],"id":58186642},{"atb":[[6.6,260.42]],"batb":[[1,6.6,260.42]],"id":26496185},{"atl":[[12,43.36]],"batl":[[1,12,43.36]],"id":44049799}]}]}
{"op":"mcm","id":2,"clk":"AOfnAgCGnwIAg8AC","pt":1743512149892,"mc":[{"id":"1.241629436","rc":[{"atb":[[5.1,298.52]],"batb":[[0,5.1,298.52]],"id":56297029},{"atb":[[6.8,5.63]],"trd":[[6.8,1282.44]],"batb":[[0,6.8,5.63]],"tv":14939.36,"id":26496185}],"tv":89990.76}]}
{"op":"mcm","id":2,"clk":"APbnAgCVnwIAjcAC","pt":1743512150002,"mc":[{"id":"1.241629436","rc":[{"atl":[[9.8,7.61]],"batl":[[0,9.8,7.61]],"id":35856222},{"atl":[[5.2,227.65]],"batl":[[0,5.2,227.65]],"id":56297029},{"atb":[[6.6,233.32]],"atl":[[7,108.57]],"batb":[[1,6.6,233.32]],"batl":[[0,7,108.57]],"id":26496185}]}]}
{"op":"mcm","id":2,"clk":"AIPoAgCinwIAlMAC","pt":1743512150106,"mc":[{"id":"1.241629436","rc":[{"atl":[[4.7,10]],"batl":[[2,4.9,292.5],[1,4.8,215.13],[0,4.7,10]],"id":270592},{"atl":[[5.2,212.82]],"batl":[[0,5.2,212.82]],"id":56297029},{"atb":[[16.5,17.04]],"batb":[[1,16.5,17.04]],"id":58186642},{"atb":[[6.8,21.52]],"atl":[[7,128.17]],"trd":[[6.8,1293.69]],"batb":[[0,6.8,21.52]],"batl":[[0,7,128.17]],"tv":14950.61,"id":26496185}],"tv":90002.01}]}
{"op":"mcm","id":2,"clk":"AJHoAgCynwIAncAC","pt":1743512150177,"mc":[{"id":"1.241629436","rc":[{"atl":[[10.5,48.06]],"batl":[[2,10.5,48.06]],"id":35856222},{"atl":[[500,0.01]],"id":44049799}]}]}
{"op":"mcm","id":2,"clk":"AJzoAgC9nwIAo8AC","pt":1743512150266,"mc":[{"id":"1.241629436","rc":[{"atb":[[4.6,304.3],[4.5,248.85]],"batb":[[1,4.5,248.85],[0,4.6,304.3]],"id":270592},{"atb":[[5.1,333.81]],"batb":[[0,5.1,333.81]],"id":56297029},{"atb":[[6.8,24.57],[6.4,272.71]],"trd":[[6.8,1321.59]],"batb":[[2,6.4,272.71],[0,6.8,24.57]],"tv":14978.51,"id":26496185}],"tv":90029.91}]}
{"op":"mcm","id":2,"clk":"AKjoAgDJnwIAqcAC","pt":1743512150367,"mc":[{"id":"1.241629436","rc":[{"atb":[[11.5,76.56]],"batb":[[0,11.5,76.56]],"id":40389088},{"atb":[[4.6,279.3]],"atl":[[4.7,4.11]],"trd":[[4.7,2791.79]],"batb":[[0,4.6,279.3]],"batl":[[0,4.7,4.11]],"ltp":4.7,"tv":22812.57,"id":270592},{"atl":[[9.8,4.78]],"trd":[[9.8,1084.8]],"batl":[[0,9.8,4.78]],"ltp":9.8,"tv":10108.76,"id":35856222},{"atl":[[55,11.17]],"trd":[[55,363.64]],"batl":[[0,55,11.17]],"tv":2080.54,"id":59626646},{"atb":[[5.1,364.89]],"batb":[[0,5.1,364.89]],"id":56297029},{"atb":[[10,115.04]],"batb":[[0,10,115.04]],"id":27115873},{"atl":[[17.5,3.44]],"trd":[[17.5,346.72]],"batl":[[0,17.5,3.44]],"tv":6355.16,"id":58186642},{"atb":[[6.6,184.81],[6.8,69.62],[6.4,275.7]],"atl":[[7,148.17]],"batb":[[2,6.4,275.7],[1,6.6,184.81],[0,6.8,69.62]],"batl":[[0,7,148.17]],"id":26496185},{"atb":[[11,125.64]],"atl":[[500,0.03]],"batb":[[0,11,125.64]],"id":44049799}],"tv":90051.51}]}
{"op":"mcm","id":2,"clk":"ALToAgDUnwIAr8AC","pt":1743512150472,"mc":[{"id":"1.241629436","rc":[{"atl":[[5.1,136.37]],"batl":[],"id":270592},{"atl":[[7,153.62]],"batl":[[0,7,153.62]],"id":26496185}]}]}
{"op":"mcm","id":2,"clk":"AMDoAgDmnwIAusAC","pt":1743512150576,"mc":[{"id":"1.241629436","rc":[{"atl":[[4.7,2.15]],"trd":[[4.7,2795.71]],"batl":[[0,4.7,2.15]],"tv":22816.49,"id":270592},{"atb":[[6.4,272.71]],"batb":[[2,6.4,272.71]],"id":26496185}],"tv":90055.43}]}
{"op":"mcm","id":2,"clk":"AMnoAgDunwIAysAC","pt":1743512150681,"mc":[{"id":"1.241629436","rc":[{"atl":[[5,305.84]],"batl":[],"id":270592}]}]}
{"op":"mcm","id":2,"clk":"ANnoAgCDoAIA6MAC","pt":1743512150885,"mc":[{"id":"1.241629436","rc":[{"atb":[[5.1,344.24]],"batb":[[0,5.1,344.24]],"id":56297029}]}]}
{"op":"mcm","id":2,"clk":"AOPoAgCHoAIA68AC","pt":1743512150985,"mc":[{"id":"1.241629436","rc":[{"atb":[[4.6,276.09]],"batb":[[0,4.6,276.09]],"id":270592},{"atl":[[7,133.62]],"trd":[[7,1421.63]],"batl":[[0,7,133.62]],"ltp":7,"tv":15018.51,"id":26496185}],"tv":90095.43}]}
{"op":"mcm","id":2,"clk":"AOnoAgCToAIA78AC","pt":1743512151084,"mc":[{"id":"1.241629436","rc":[{"atl":[[4.8,213.27]],"batl":[[1,4.8,213.27]],"id":270592},{"atb":[[6.8,78.52]],"batb":[[0,6.8,78.52]],"id":26496185}]}]}
{"op":"mcm","id":2,"clk":"APLoAgCboAIA+sAC","pt":1743512151188,"mc":[{"id":"1.241629436","rc":[{"atl":[[500,0.01]],"id":40389088},{"atb":[[6.8,82.28]],"batb":[[0,6.8,82.28]],"id":26496185}]}]}
{"op":"mcm","id":2,"clk":"APvoAgCmoAIA/8AC","pt":1743512151291,"mc":[{"id":"1.241629436","rc":[{"atl":[[9.8,19.6]],"batl":[[0,9.8,19.6]],"id":35856222},{"atl":[[5.2,297.77]],"batl":[[0,5.2,297.77]],"id":56297029}]}]}
{"op":"mcm","id":2,"clk":"AITpAgCyoAIAi8EC","pt":1743512151393,"mc":[{"id":"1.241629436","rc":[{"atl":[[500,0.03]],"id":40389088},{"atl":[[9.8,16.03]],"trd":[[9.8,1091.94]],"batl":[[0,9.8,16.03]],"tv":10115.9,"id":35856222},{"atb":[[17,41.04]],"batb":[[0,17,41.04]],"id":58186642}],"tv":90102.57}]}
{"op":"mcm","id":2,"clk":"AKTpAgDWoAIAoMEC","pt":1743512151702,"mc":[{"id":"1.241629436","rc":[{"atb":[[11.5,80.6]],"batb":[[0,11.5,80.6]],"id":40389088},{"atb":[[4.7,7.74]],"atl":[[4.7,0]],"trd":[[4.7,2800.01]],"batb":[[2,4.5,248.85],[1,4.6,276.09],[0,4.7,7.74]],"batl":[[2,5,305.84],[1,4.9,292.5],[0,4.8,213.27]],"tv":22820.79,"id":270592},{"atl":[[9.8,11.29]],"trd":[[9.8,1101.42]],"batl":[[0,9.8,11.29]],"tv":10125.38,"id":35856222},{"atl":[[55,10.32]],"trd":[[55,365.34]],"batl":[[0,55,10.32]],"tv":2082.24,"id":59626646},{"atb":[[5.1,353.35]],"batb":[[0,5.1,353.35]],"id":56297029},{"atb":[[10,119.69]],"batb":[[0,10,119.69]],"id":27115873},{"atl":[[17.5,0.78]],"trd":[[17.5,352.04]],"batl":[[2,19,12.87],[1,18.5,25.94],[0,18,45.49]],"tv":6360.48,"id":58186642},{"atb":[[6.8,89.12]],"batb":[[0,6.8,89.12]],"id":26496185},{"atb":[[11,129.87]],"batb":[[0,11,129.87]],"id":44049799}],"tv":90123.37}]}
{"op":"mcm","id":2,"clk":"AKzpAgDeoAIAq8EC","pt":1743512151757,"mc":[{"id":"1.241629436","rc":[{"atb":[[11.5,38.79]],"trd":[[11.5,1525.26]],"batb":[[0,11.5,38.79]],"tv":6881.09,"id":40389088},{"atb":[[5.1,379.04]],"batb":[[0,5.1,379.04]],"id":56297029}],"tv":90207.01}]}
{"op":"mcm","id":2,"clk":"ALnpAgDqoAIAr8EC","pt":1743512151862,"mc":[{"id":"1.241629436","rc":[{"atb":[[11.5,12.55]],"batb":[[0,11.5,12.55]],"id":40389088},{"atb":[[4.7,40.84],[4.2,115.97],[4.6,273],[4.3,201.04]],"atl":[[5,304.91]],"batb":[[1,4.6,273],[0,4.7,40.84]],"batl":[[2,5,304.91]],"id":270592},{"atl":[[9.8,0]],"batl":[[2,11,27.67],[1,10.5,48.06],[0,10,141.18]],"id":35856222},{"atl":[[13,11.76]],"batl":[],"id":27115873},{"atb":[[6.8,102.55]],"batb":[[0,6.8,102.55]],"id":26496185}]}]}
{"op":"mcm","id":2,"clk":"AMTpAgD5oAIAusEC","pt":1743512151974,"mc":[{"id":"1.241629436","rc":[{"atb":[[11.5,0],[10.5,50.01]],"atl":[[11.5,18.31]],"trd":[[11.5,1550.35]],"batb":[[2,10,71.05],[1,10.5,50.01],[0,11,77.03]],"batl":[[2,12.5,60.86],[1,12,73.48],[0,11.5,18.31]],"tv":6906.18,"id":40389088},{"atb":[[9.8,14.95]],"batb":[[2,9.4,50.78],[1,9.6,101.84],[0,9.8,14.95]],"id":35856222},{"atl":[[7,136.12]],"batl":[[0,7,136.12]],"id":26496185}],"tv":90232.1}]}
{"op":"mcm","id":2,"clk":"AMrpAgCGoQIAwsEC","pt":1743512152069,"mc":[{"id":"1.241629436","rc":[{"atl":[[14.5,10.68],[14,17.23],[11.5,3.42]],"trd":[[11.5,1580.13]],"batl":[[0,11.5,3.42]],"tv":6935.96,"id":40389088},{"atb":[[4.7,35.84],[4.4,255.19]],"atl":[[5.1,137.27]],"trd":[[4.7,2900.01]],"batb":[[0,4.7,35.84]],"batl":[],"tv":22920.79,"id":270592},{"atb":[[9.4,49.48],[9.8,32.09],[9.6,100.6]],"batb":[[2,9.4,49.48],[1,9.6,100.6],[0,9.8,32.09]],"id":35856222},{"atl":[[13,10.09]],"batl":[],"id":27115873}],"tv":90361.88}]}
{"op":"mcm","id":2,"clk":"ANXpAgCRoQIAycEC","pt":1743512152172,"mc":[{"id":"1.241629436","rc":[{"atl":[[14,18.66],[11.5,1.81]],"trd":[[11.5,1583.35]],"batl":[[0,11.5,1.81]],"tv":6939.18,"id":40389088},{"atb":[[9.4,50.78],[9.8,46.09]],"batb":[[2,9.4,50.78],[0,9.8,46.09]],"id":35856222},{"atl":[[500,0.02]],"id":58186642},{"atl":[[7,131.68]],"batl":[[0,7,131.68]],"id":26496185}],"tv":90365.1}]}
{"op":"mcm","id":2,"clk":"AODpAgCdoQIA2sEC","pt":1743512152283,"mc":[{"id":"1.241629436","rc":[{"atl":[[12,67.14],[11.5,10.32]],"batl":[[1,12,67.14],[0,11.5,10.32]],"id":40389088},{"atb":[[4.7,78.2]],"batb":[[0,4.7,78.2]],"id":270592}]}]}
{"op":"mcm","id":2,"clk":"AOnpAgCmoQIA4cEC","pt":1743512152378,"mc":[{"id":"1.241629436","rc":[{"atb":[[10.5,51.01]],"atl":[[11.5,8.51]],"batb":[[1,10.5,51.01]],"batl":[[0,11.5,8.51]],"id":40389088},{"atb":[[4.7,66.64]],"trd":[[4.7,2923.13]],"batb":[[0,4.7,66.64]],"tv":22943.91,"id":270592},{"atb":[[9.8,51.51]],"batb":[[0,9.8,51.51]],"id":35856222},{"atl":[[500,0.03]],"id":58186642},{"atb":[[6.8,120.24]],"batb":[[0,6.8,120.24]],"id":26496185}],"tv":90388.22}]}
{"op":"mcm","id":2,"clk":"APbpAgCzoQIA7cEC","pt":1743512152488,"mc":[{"id":"1.241629436","rc":[{"atb":[[17,40.04]],"trd":[[17,984.86]],"batb":[[0,17,40.04]],"ltp":17,"tv":6362.48,"id":58186642},{"atl":[[7,127.6]],"batl":[[0,7,127.6]],"id":26496185}],"tv":90390.22}]}
{"op":"mcm","id":2,"clk":"AP/pAgC9oQIA/sEC","pt":1743512152583,"mc":[{"id":"1.241629436","rc":[{"atb":[[1.17,2.55]],"atl":[[1000,0.36],[12.5,60.61]],"batl":[[2,12.5,60.61]],"id":40389088},{"atb":[[4.7,61.04],[1.17,1.12],[4.5,248.65]],"trd":[[4.7,2934.33]],"batb":[[2,4.5,248.65],[0,4.7,61.04]],"tv":22955.11,"id":270592},{"atb":[[9.2,79.65],[9.6,90.6]],"batb":[[1,9.6,90.6]],"id":35856222},{"atb":[[5.1,377.93]],"batb":[[0,5.1,377.93]],"id":56297029},{"atl":[[18,44.49],[17.5,0]],"trd":[[18,297.33],[17.5,353.6]],"batl":[[0,18,44.49]],"ltp":18,"tv":6364.48,"id":58186642},{"atb":[[6.8,116.16],[6.4,275.7]],"trd":[[6.8,1329.75]],"batb":[[2,6.4,275.7],[0,6.8,116.16]],"ltp":6.8,"tv":15026.67,"id":26496185}],"tv":90411.58}]}
{"op":"mcm","id":2,"clk":"AIbqAgDHoQIAhcIC","pt":1743512152689,"mc":[{"id":"1.241629436","rc":[{"atb":[[1.17,2]],"atl":[[1000,0.25]],"id":40389088},{"atb":[[9.8,61.51]],"batb":[[0,9.8,61.51]],"id":35856222}]}]}
{"op":"mcm","id":2,"clk":"AIvqAgDSoQIAjsIC","pt":1743512152788,"mc":[{"id":"1.241629436","rc":[{"atb":[[11,77.58]],"atl":[[12,67.25],[11.5,11.35]],"batb":[[0,11,77.58]],"batl":[[1,12,67.25],[0,11.5,11.35]],"id":40389088},{"atb":[[1.17,1]],"id":270592},{"atl":[[5.2,277.77]],"batl":[[0,5.2,277.77]],"id":56297029},{"atb":[[16,16.69]],"batb":[[2,16,16.69]],"id":58186642}]}]}
{"op":"mcm","id":2,"clk":"AJnqAgDboQIAlsIC","pt":1743512152895,"mc":[{"id":"1.241629436","rc":[{"atb":[[4.6,273.12]],"batb":[[1,4.6,273.12]],"id":270592}]}]}
{"op":"mcm","id":2,"clk":"AKLqAgDloQIAocIC","pt":1743512152994,"mc":[{"id":"1.241629436","rc":[{"atb":[[4.3,207.17]],"batb":[],"id":270592},{"atb":[[17.5,5.16]],"batb":[[2,16.5,17.04],[1,17,40.04],[0,17.5,5.16]],"id":58186642}]}]}
{"op":"mcm","id":2,"clk":"ALDqAgDuoQIAp8IC","pt":1743512153098,"mc":[{"id":"1.241629436","rc":[{"atb":[[17,42.34]],"atl":[[18,42.18]],"batb":[[1,17,42.34]],"batl":[[0,18,42.18]],"id":58186642},{"atb":[[6.8,86.16]],"trd":[[6.8,1389.75]],"batb":[[0,6.8,86.16]],"tv":15086.67,"id":26496185}],"tv":90471.58}]}
{"op":"mcm","id":2,"clk":"ALvqAgD0oQIAssIC","pt":1743512153205,"mc":[{"id":"1.241629436","rc":[{"atb":[[11,75.58]],"atl":[[12.5,66.58],[11.5,8.51]],"trd":[[11,312.22]],"batb":[[0,11,75.58]],"batl":[[2,12.5,66.58],[0,11.5,8.51]],"ltp":11,"tv":6943.18,"id":40389088},{"atl":[[4.8,211.26]],"trd":[[4.8,3549.87]],"batl":[[0,4.8,211.26]],"ltp":4.8,"tv":22959.13,"id":270592},{"atb":[[9.4,54.05]],"batb":[[2,9.4,54.05]],"id":35856222},{"atl":[[500,0.01]],"id":59626646},{"atb":[[6.8,68.47]],"atl":[[7,129.6]],"batb":[[0,6.8,68.47]],"batl":[[0,7,129.6]],"id":26496185}],"tv":90479.6}]}
{"op":"mcm","id":2,"clk":"ANLqAgCFogIAwcIC","pt":1743512153405,"mc":[{"id":"1.241629436","rc":[{"atl":[[11.5,9.51]],"batl":[[0,11.5,9.51]],"id":40389088},{"atl":[[500,0.03]],"id":59626646}]}]}
{"op":"mcm","id":2,"clk":"AN3qAgCOogIAysIC","pt":1743512153457,"mc":[{"id":"1.241629436","rc":[{"atb":[[4.7,74.4]],"batb":[[0,4.7,74.4]],"id":270592}]}]}
{"op":"mcm","id":2,"clk":"AO/qAgCkogIA2sIC","pt":1743512153669,"mc":[{"id":"1.241629436","rc":[{"atl":[[7,128.6]],"batl":[[0,7,128.6]],"id":26496185}]}]}
{"op":"mcm","id":2,"clk":"APjqAgCuogIA48IC","pt":1743512153768,"mc":[{"id":"1.241629436","rc":[{"atl":[[11.5,5.27]],"trd":[[11.5,1591.84]],"batl":[[0,11.5,5.27]],"ltp":11.5,"tv":6951.67,"id":40389088},{"atb":[[6.8,42.38]],"trd":[[6.8,1441.94]],"batb":[[0,6.8,42.38]],"tv":15138.86,"id":26496185}],"tv":90540.28}]}
{"op":"mcm","id":2,"clk":"AIHrAgC3ogIA78IC","pt":1743512153881,"mc":[{"id":"1.241629436","rc":[{"atb":[[1.17,2.67]],"atl":[[11.5,6.61]],"batl":[[0,11.5,6.61]],"id":40389088},{"atb":[[1.17,1.98]],"atl":[[4.8,210.51]],"batl":[[0,4.8,210.51]],"id":270592},{"atb":[[8.6,22.96]],"batb":[],"id":35856222},{"atl":[[55,9.67]],"trd":[[55,366.64]],"batl":[[0,55,9.67]],"tv":2083.54,"id":59626646},{"atb":[[5.1,375.99]],"batb":[[0,5.1,375.99]],"id":56297029},{"atb":[[17.5,4.05]],"trd":[[17.5,355.82]],"batb":[[0,17.5,4.05]],"ltp":17.5,"tv":6366.7,"id":58186642},{"atb":[[6.8,33.48]],"batb":[[0,6.8,33.48]],"id":26496185},{"atb":[[11,129.3]],"batb":[[0,11,129.3]],"id":44049799}],"tv":90543.8}]}
{"op":"mcm","id":2,"clk":"AIvrAgC9ogIA98IC","pt":1743512153981,"mc":[{"id":"1.241629436","rc":[{"atb":[[4.7,84.4]],"batb":[[0,4.7,84.4]],"id":270592},{"atb":[[9.8,62.7],[9.6,91.84]],"batb":[[1,9.6,91.84],[0,9.8,62.7]],"id":35856222}]}]}
{"op":"mcm","id":2,"clk":"AJTrAgDLogIAgMMC","pt":1743512154084,"mc":[{"id":"1.241629436","rc":[{"atb":[[1.17,2]],"atl":[[11.5,5.7]],"trd":[[11.5,1593.64]],"batl":[[0,11.5,5.7]],"tv":6953.47,"id":40389088},{"atb":[[1.17,1]],"atl":[[4.8,265.51]],"batl":[[0,4.8,265.51]],"id":270592},{"atb":[[1.27,14]],"id":35856222},{"atl":[[5.2,284.89]],"batl":[[0,5.2,284.89]],"id":56297029},{"atb":[[6.8,36.12]],"batb":[[0,6.8,36.12]],"id":26496185}],"tv":90545.6}]}
{"op":"mcm","id":2,"clk":"AKDrAgDRogIAiMMC","pt":1743512154183,"mc":[{"id":"1.241629436","rc":[{"atl":[[11.5,5.03]],"trd":[[11.5,1594.98]],"batl":[[0,11.5,5.03]],"tv":6954.81,"id":40389088},{"atl":[[4.8,264.53]],"trd":[[4.8,3551.83]],"batl":[[0,4.8,264.53]],"tv":22961.09,"id":270592}],"tv":90548.9}]}
{"op":"mcm","id":2,"clk":"AKrrAgDgogIAkMMC","pt":1743512154289,"mc":[{"id":"1.241629436","rc":[{"atl":[[10,135.43]],"batl":[[0,10,135.43]],"id":35856222},{"atb":[[5.1,374.29]],"trd":[[5.1,4805.89]],"batb":[[0,5.1,374.29]],"tv":14114.07,"id":56297029}],"tv":90552.3}]}
{"op":"mcm","id":2,"clk":"ALTrAgDrogIAlsMC","pt":1743512154391,"mc":[{"id":"1.241629436","rc":[{"atl":[[11.5,2.34]],"batl":[[0,11.5,2.34]],"id":40389088}]}]}
{"op":"mcm","id":2,"clk":"AL3rAgDtogIAmsMC","pt":1743512154491,"mc":[{"id":"1.241629436","rc":[{"atl":[[11.5,4.63]],"batl":[[0,11.5,4.63]],"id":40389088}]}]}
{"op":"mcm","id":2,"clk":"ANbrAgCQowIAsMMC","pt":1743512154788,"mc":[{"id":"1.241629436","rc":[{"atl":[[7,128.56]],"batl":[[0,7,128.56]],"id":26496185}]}]}
{"op":"mcm","id":2,"clk":"ANzrAgCYowIAtsMC","pt":1743512154892,"mc":[{"id":"1.241629436","rc":[{"atl":[[12.5,60.61],[11.5,2.2]],"trd":[[11.5,1599.84]],"batl":[[2,12.5,60.61],[0,11.5,2.2]],"tv":6959.67,"id":40389088},{"atb":[[9.4,50.78]],"batb":[[2,9.4,50.78]],"id":35856222},{"atb":[[5,1171.34]],"batb":[[1,5,1171.34]],"id":56297029}],"tv":90557.16}]}
{"op":"mcm","id":2,"clk":"AOjrAgCiowIAv8MC","pt":1743512154996,"mc":[{"id":"1.241629436","rc":[{"atl":[[11.5,0.27]],"trd":[[11.5,1603.7]],"batl":[[2,13,19.71],[1,12.5,60.61],[0,12,67.52]],"tv":6963.53,"id":40389088},{"atl":[[5.3,134.74],[4.8,268.53]],"batl":[[0,4.8,268.53]],"id":270592},{"atl":[[55,9.15]],"trd":[[55,367.68]],"batl":[[0,55,9.15]],"tv":2084.58,"id":59626646},{"atb":[[5.1,374.03]],"atl":[[5.2,282.43]],"trd":[[5.2,3877.51]],"batb":[[0,5.1,374.03]],"batl":[[0,5.2,282.43]],"ltp":5.2,"tv":14118.99,"id":56297029},{"atb":[[17.5,2.27]],"trd":[[17.5,359.38]],"batb":[[0,17.5,2.27]],"tv":6370.26,"id":58186642},{"atl":[[11.5,88.87]],"trd":[[11.5,1082.51]],"batl":[[0,11.5,88.87]],"ltp":11.5,"tv":5278.56,"id":44049799}],"tv":90572.98}]}
{"op":"mcm","id":2,"clk":"APDrAgCpowIAx8MC","pt":1743512155096,"mc":[{"id":"1.241629436","rc":[{"atb":[[11,73.58]],"atl":[[11.5,0]],"trd":[[11.5,1604.24],[11,316.22]],"batb":[[0,11,73.58]],"batl":[[0,12,67.25]],"tv":6968.07,"id":40389088},{"atb":[[4.5,238.65]],"batb":[[2,4.5,238.65]],"id":270592},{"atb":[[9.8,60.7]],"trd":[[9.8,1105.42]],"batb":[[0,9.8,60.7]],"tv":10129.38,"id":35856222},{"atb":[[50,21.32]],"trd":[[50,85.73]],"batb":[[0,50,21.32]],"ltp":50,"tv":2088.58,"id":59626646},{"atb":[[17.5,0]],"atl":[[17.5,8.25]],"trd":[[17.5,363.92]],"batb":[[2,16,16.69],[1,16.5,17.04],[0,17,42.34]],"batl":[[2,18.5,25.94],[1,18,42.18],[0,17.5,8.25]],"tv":6374.8,"id":58186642},{"atb":[[6.8,14.39]],"trd":[[6.8,1485.39]],"batb":[[0,6.8,14.39]],"tv":15182.31,"id":26496185}],"tv":90633.51}]}
{"op":"mcm","id":2,"clk":"AP3rAgCuowIA0sMC","pt":1743512155204,"mc":[{"id":"1.241629436","rc":[{"atl":[[14,17.23],[12,77]],"batl":[[0,12,77]],"id":40389088},{"atl":[[55,9.63]],"batl":[[0,55,9.63]],"id":59626646},{"atl":[[17.5,4.56]],"trd":[[17.5,371.3]],"batl":[[0,17.5,4.56]],"tv":6382.18,"id":58186642}],"tv":90640.89}]}
{"op":"mcm","id":2,"clk":"AIXsAgC5owIA38MC","pt":1743512155313,"mc":[{"id":"1.241629436","rc":[{"atb":[[10.5,50.01]],"batb":[[1,10.5,50.01]],"id":40389088},{"atb":[[50,22.97]],"batb":[[0,50,22.97]],"id":59626646},{"atb":[[16,17.69]],"batb":[[2,16,17.69]],"id":58186642},{"atb":[[6.8,12.07]],"trd":[[6.8,1490.03]],"batb":[[0,6.8,12.07]],"tv":15186.95,"id":26496185}],"tv":90645.53}]}
{"op":"mcm","id":2,"clk":"AI3sAgC/owIA5MMC","pt":1743512155361,"mc":[{"id":"1.241629436","rc":[{"atb":[[4.3,159.17]],"batb":[],"id":270592},{"atb":[[5.1,403.01]],"batb":[[0,5.1,403.01]],"id":56297029}]}]}
{"op":"mcm","id":2,"clk":"AJbsAgDIowIA8cMC","pt":1743512155473,"mc":[{"id":"1.241629436","rc":[{"atb":[[11.5,1]],"batb":[[2,10.5,50.01],[1,11,73.58],[0,11.5,1]],"id":40389088},{"atb":[[4.5,243.65]],"batb":[[2,4.5,243.65]],"id":270592},{"atb":[[50,21.32]],"batb":[[0,50,21.32]],"id":59626646},{"atl":[[17.5,0]],"batl":[[2,19,12.87],[1,18.5,25.94],[0,18,42.18]],"id":58186642},{"atb":[[11,128.05]],"trd":[[11,1710.06]],"batb":[[0,11,128.05]],"ltp":11,"tv":5281.06,"id":44049799}],"tv":90648.03}]}
{"op":"mcm","id":2,"clk":"AJ7sAgDRowIA+MMC","pt":1743512155570,"mc":[{"id":"1.241629436","rc":[{"atb":[[11.5,13.52]],"atl":[[14,18.66],[13.5,14.62],[13,21.38]],"batb":[[0,11.5,13.52]],"batl":[[2,13,21.38]],"id":40389088},{"atb":[[9.8,66.4]],"batb":[[0,9.8,66.4]],"id":35856222},{"atl":[[13,11.76]],"batl":[],"id":27115873},{"atb":[[6.8,23.64]],"batb":[[0,6.8,23.64]],"id":26496185}]}]}
{"op":"mcm","id":2,"clk":"AKrsAgDaowIAhMQC","pt":1743512155667,"mc":[{"id":"1.241629436","rc":[{"atb":[[11.5,0]],"trd":[[11.5,1631.28]],"batb":[[2,10,71.05],[1,10.5,50.01],[0,11,73.58]],"tv":6995.11,"id":40389088},{"atb":[[16,16.69]],"atl":[[18,44.49]],"batb":[[2,16,16.69]],"batl":[[0,18,44.49]],"id":58186642}],"tv":90675.07}]}
{"op":"mcm","id":2,"clk":"ALjsAgDgowIAkMQC","pt":1743512155782,"mc":[{"id":"1.241629436","rc":[{"atl":[[5.2,197.48]],"batl":[[0,5.2,197.48]],"id":56297029},{"atb":[[17.5,1]],"batb":[[2,16.5,17.04],[1,17,42.34],[0,17.5,1]],"id":58186642},{"atb":[[6.8,21.64]],"trd":[[6.8,1494.03]],"batb":[[0,6.8,21.64]],"tv":15190.95,"id":26496185}],"tv":90679.07}]}
{"op":"mcm","id":2,"clk":"AMLsAgDwowIAncQC","pt":1743512155887,"mc":[{"id":"1.241629436","rc":[{"atl":[[14,17.23],[13.5,13.08],[13,19.71]],"batl":[[2,13,19.71]],"id":40389088},{"atb":[[4,132.69]],"batb":[],"id":270592},{"atl":[[13,10.09]],"batl":[],"id":27115873}]}]}
{"op":"mcm","id":2,"clk":"AMrsAgD6owIAosQC","pt":1743512155988,"mc":[{"id":"1.241629436","rc":[{"atb":[[6.8,16.64]],"trd":[[6.8,1504.03]],"batb":[[0,6.8,16.64]],"tv":15200.95,"id":26496185}],"tv":90689.07}]}
{"op":"mcm","id":2,"clk":"AM/sAgCBpAIAqsQC","pt":1743512156078,"mc":[{"id":"1.241629436","rc":[{"atl":[[7,138.56]],"batl":[[0,7,138.56]],"id":26496185}]}]}
{"op":"mcm","id":2,"clk":"AN3sAgCIpAIAtcQC","pt":1743512156185,"mc":[{"id":"1.241629436","rc":[{"atb":[[9.8,58.4]],"trd":[[9.8,1121.42]],"batb":[[0,9.8,58.4]],"tv":10145.38,"id":35856222}],"tv":90705.07}]}
{"op":"mcm","id":2,"clk":"AOnsAgCWpAIAv8QC","pt":1743512156295,"mc":[{"id":"1.241629436","rc":[{"atb":[[4.1,98.58]],"batb":[],"id":270592},{"atl":[[5.5,67.47]],"batl":[],"id":56297029},{"atb":[[11,126.05]],"trd":[[11,1714.06]],"batb":[[0,11,126.05]],"tv":5285.06,"id":44049799}],"tv":90709.07}]}
{"op":"mcm","id":2,"clk":"AIXtAgC+pAIA1MQC","pt":1743512156602,"mc":[{"id":"1.241629436","rc":[{"atb":[[9.8,51.26]],"trd":[[9.8,1135.7]],"batb":[[0,9.8,51.26]],"tv":10159.66,"id":35856222},{"atb":[[5.1,377.32]],"batb":[[0,5.1,377.32]],"id":56297029}],"tv":90723.35}]}
{"op":"mcm","id":2,"clk":"AI3tAgDApAIA1cQC","pt":1743512156698,"mc":[{"id":"1.241629436","rc":[{"atb":[[9.8,67.87]],"batb":[[0,9.8,67.87]],"id":35856222}]}]}
{"op":"mcm","id":2,"clk":"AKPtAgDQpAIA5MQC","pt":1743512156906,"mc":[{"id":"1.241629436","rc":[{"atb":[[4.2,105.97],[4.4,260.29]],"batb":[],"id":270592}]}]}
{"op":"mcm","id":2,"clk":"ALHtAgDcpAIA8MQC","pt":1743512156969,"mc":[{"id":"1.241629436","rc":[{"atb":[[4.7,94.4]],"batb":[[0,4.7,94.4]],"id":270592}]}]}
{"op":"mcm","id":2,"clk":"ANztAgD0pAIAkMUC","pt":1743512157268,"mc":[{"id":"1.241629436","rc":[{"atb":[[4.7,116.4]],"batb":[[0,4.7,116.4]],"id":270592},{"atl":[[90,1.5]],"id":44049799}]}]}
{"op":"mcm","id":2,"clk":"AOvtAgCEpQIAl8UC","pt":1743512157382,"mc":[{"id":"1.241629436","rc":[{"atb":[[4.3,149.17]],"batb":[],"id":270592},{"atl":[[5.2,284.52]],"batl":[[0,5.2,284.52]],"id":56297029}]}]}
{"op":"mcm","id":2,"clk":"APntAgCNpQIAosUC","pt":1743512157487,"mc":[{"id":"1.241629436","rc":[{"atb":[[10.5,54.78]],"atl":[[12.5,64.61]],"batb":[[1,10.5,54.78]],"batl":[[1,12.5,64.61]],"id":40389088}]}]}
{"op":"mcm","id":2,"clk":"AITuAgCipQIArsUC","pt":1743512157587,"mc":[{"id":"1.241629436","rc":[{"atb":[[1.17,7.96]],"atl":[[1000,0.58]],"id":35856222},{"atb":[[6.8,18.39]],"batb":[[0,6.8,18.39]],"id":26496185},{"atl":[[1000,20.01]],"id":44049799}]}]}
{"op":"mcm","id":2,"clk":"AI7uAgCrpQIAtMUC","pt":1743512157693,"mc":[{"id":"1.241629436","rc":[{"atb":[[1.17,7.15],[9.6,90.27]],"atl":[[1000,0.41],[10,135.04]],"batb":[[1,9.6,90.27]],"batl":[[0,10,135.04]],"id":35856222},{"atl":[[1000,19.87]],"id":44049799}]}]}
{"op":"mcm","id":2,"clk":"AJbuAgCzpQIAv8UC","pt":1743512157788,"mc":[{"id":"1.241629436","rc":[{"atb":[[4.4,250.29]],"batb":[],"id":270592},{"atb":[[9.8,68.68]],"atl":[[10.5,48.23]],"batb":[[0,9.8,68.68]],"batl":[[1,10.5,48.23]],"id":35856222},{"atl":[[11.5,89.01]],"batl":[[0,11.5,89.01]],"id":44049799}]}]}
{"op":"mcm","id":2,"clk":"AKHuAgC7pQIAxcUC","pt":1743512157888,"mc":[{"id":"1.241629436","rc":[{"atb":[[9.8,66.68]],"trd":[[9.8,1139.7]],"batb":[[0,9.8,66.68]],"tv":10163.66,"id":35856222},{"atb":[[6.6,187.2]],"batb":[[1,6.6,187.2]],"id":26496185}],"tv":90727.35}]}
{"op":"mcm","id":2,"clk":"AKzuAgDHpQIAysUC","pt":1743512157995,"mc":[{"id":"1.241629436","rc":[{"atb":[[5.1,403.25]],"batb":[[0,5.1,403.25]],"id":56297029},{"atb":[[6.8,19.39]],"batb":[[0,6.8,19.39]],"id":26496185}]}]}
{"op":"mcm","id":2,"clk":"AM/uAgDspQIA3sUC","pt":1743512158396,"mc":[{"id":"1.241629436","rc":[{"atb":[[4,129.89]],"batb":[],"id":270592},{"atb":[[17,18.34],[17.5,0]],"trd":[[17.5,373.3],[17,1032.86]],"batb":[[2,16,16.69],[1,16.5,17.04],[0,17,18.34]],"ltp":17,"tv":6432.18,"id":58186642}],"tv":90777.35}]}
{"op":"mcm","id":2,"clk":"ANXuAgD0pQIA6MUC","pt":1743512158502,"mc":[{"id":"1.241629436","rc":[{"atl":[[12,76.89]],"batl":[[0,12,76.89]],"id":40389088},{"atb":[[4.6,275.92]],"batb":[[1,4.6,275.92]],"id":270592},{"atb":[[5.1,405.81]],"batb":[[0,5.1,405.81]],"id":56297029},{"atb":[[17,26.88]],"atl":[[17.5,8.29]],"batb":[[0,17,26.88]],"batl":[[2,18.5,25.94],[1,18,44.49],[0,17.5,8.29]],"id":58186642}]}]}
{"op":"mcm","id":2,"clk":"AN7uAgCEpgIA8sUC","pt":1743512158605,"mc":[{"id":"1.241629436","rc":[{"atb":[[10,76.37]],"atl":[[13,23.87]],"batb":[[2,10,76.37]],"batl":[[2,13,23.87]],"id":40389088},{"atl":[[12,29.28]],"batl":[],"id":27115873},{"atb":[[17,24.58]],"atl":[[17.5,7.29]],"trd":[[17.5,375.3]],"batb":[[0,17,24.58]],"batl":[[0,17.5,7.29]],"ltp":17.5,"tv":6434.18,"id":58186642}],"tv":90779.35}]}
{"op":"mcm","id":2,"clk":"AOvuAgCQpgIAgMYC","pt":1743512158714,"mc":[{"id":"1.241629436","rc":[{"atl":[[12,81.3]],"batl":[[0,12,81.3]],"id":40389088}]}]}
{"op":"mcm","id":2,"clk":"AOvvAgD3pgIA4MYC","pt":1743512159905,"mc":[{"id":"1.241629436","rc":[{"atb":[[5.1,404.38]],"trd":[[5.1,4808.75]],"batb":[[0,5.1,404.38]],"ltp":5.1,"tv":14121.85,"id":56297029}],"tv":90782.21}]}
{"op":"mcm","id":2,"clk":"AP3vAgCApwIA7sYC","pt":1743512160104,"mc":[{"id":"1.241629436","rc":[{"atb":[[9.8,36.23]],"atl":[[13.5,17.29]],"batb":[],"batl":[],"id":40389088},{"atb":[[4.7,85.88]],"batb":[[0,4.7,85.88]],"id":270592},{"atb":[[9.8,52.68]],"batb":[[0,9.8,52.68]],"id":35856222},{"atl":[[55,7.2]],"trd":[[55,372.53]],"batl":[[0,55,7.2]],"ltp":55,"tv":2093.43,"id":59626646},{"atb":[[17,19.22]],"atl":[[18.5,29.66]],"batb":[[0,17,19.22]],"batl":[[2,18.5,29.66]],"id":58186642}],"tv":90787.06}]}
{"op":"mcm","id":2,"clk":"AInwAgCKpwIA88YC","pt":1743512160208,"mc":[{"id":"1.241629436","rc":[{"atb":[[10,118.44]],"trd":[[10,840.33]],"batb":[[0,10,118.44]],"tv":7534.24,"id":27115873}],"tv":90789.57}]}
{"op":"mcm","id":2,"clk":"AJLwAgCRpwIAgMcC","pt":1743512160309,"mc":[{"id":"1.241629436","rc":[{"atb":[[10,108.44]],"atl":[[12,29.76]],"trd":[[10,860.33]],"batb":[[0,10,108.44]],"batl":[],"tv":7554.24,"id":27115873}],"tv":90809.57}]}
{"op":"mcm","id":2,"clk":"AKDwAgCYpwIAhMcC","pt":1743512160363,"mc":[{"id":"1.241629436","rc":[{"atb":[[9.8,36.71]],"batb":[],"id":40389088},{"atb":[[4.7,36.14]],"batb":[],"id":56297029},{"atl":[[12.5,278.68]],"batl":[],"id":27115873},{"atb":[[6,156.04]],"batb":[],"id":26496185},{"atb":[[9.6,40.41]],"batb":[],"id":44049799}]}]}
{"op":"mcm","id":2,"clk":"AKfwAgCgpwIAj8cC","pt":1743512160473,"mc":[{"id":"1.241629436","rc":[{"atb":[[4.4,250.78]],"batb":[],"id":270592},{"atb":[[11,123.76]],"trd":[[11,1718.64]],"batb":[[0,11,123.76]],"tv":5289.64,"id":44049799}],"tv":90814.15}]}
{"op":"mcm","id":2,"clk":"AK/wAgCopwIAmccC","pt":1743512160574,"mc":[{"id":"1.241629436","rc":[{"atb":[[1.17,2.78]],"id":40389088},{"atb":[[4.7,92.92]],"atl":[[4.9,293.96]],"batb":[[0,4.7,92.92]],"batl":[[1,4.9,293.96]],"id":270592},{"atl":[[1000,1.67]],"id":58186642},{"atb":[[11,124.69]],"atl":[[1000,20.06],[13.5,16.16]],"batb":[[0,11,124.69]],"batl":[],"id":44049799}]}]}
{"op":"mcm","id":2,"clk":"ALbwAgCtpwIAnscC","pt":1743512160673,"mc":[{"id":"1.241629436","rc":[{"atb":[[1.17,2],[9.6,37.48]],"atl":[[14,21.25]],"batb":[],"batl":[],"id":40389088},{"atb":[[8.6,16.37]],"batb":[],"id":35856222},{"atb":[[10,106.44]],"trd":[[10,864.33]],"batb":[[0,10,106.44]],"tv":7558.24,"id":27115873}],"tv":90818.15}]}
{"op":"mcm","id":2,"clk":"AL7wAgCypwIAqMcC","pt":1743512160775,"mc":[{"id":"1.241629436","rc":[{"atb":[[11,93.07]],"batb":[[0,11,93.07]],"id":40389088},{"atl":[[55,3.51]],"batl":[[0,55,3.51]],"id":59626646},{"atl":[[1000,1.41]],"id":58186642},{"atl":[[1000,19.87]],"id":44049799}]}]}
{"op":"mcm","id":2,"clk":"AMfwAgC4pwIAsMcC","pt":1743512160877,"mc":[{"id":"1.241629436","rc":[{"atb":[[4.4,212.78]],"batb":[],"id":270592},{"atl":[[18,44.75]],"batl":[[1,18,44.75]],"id":58186642},{"atl":[[12,43.55]],"batl":[[1,12,43.55]],"id":44049799}]}]}
{"op":"mcm","id":2,"clk":"AM7wAgC+pwIAuMcC","pt":1743512160987,"mc":[{"id":"1.241629436","rc":[{"atb":[[11,96.67]],"atl":[[12,84.83]],"batb":[[0,11,96.67]],"batl":[[0,12,84.83]],"id":40389088},{"atb":[[4.5,247.77]],"atl":[[5,308.8]],"batb":[[2,4.5,247.77]],"batl":[[2,5,308.8]],"id":270592},{"atb":[[9.4,54.19]],"atl":[[10.5,51.85]],"batb":[[2,9.4,54.19]],"batl":[[1,10.5,51.85]],"id":35856222},{"atb":[[4.9,68.59]],"atl":[[5.4,79.93]],"batb":[[2,4.9,68.59]],"batl":[[2,5.4,79.93]],"id":56297029},{"atb":[[9.8,75.3]],"atl":[[11,73.41]],"batb":[[1,9.8,75.3]],"batl":[[1,11,73.41]],"id":27115873},{"atb":[[16.5,20.5]],"batb":[[1,16.5,20.5]],"id":58186642},{"atb":[[6.6,191.14]],"atl":[[7.2,154.76]],"batb":[[1,6.6,191.14]],"batl":[[1,7.2,154.76]],"id":26496185},{"atb":[[10.5,72.61]],"atl":[[12,46.93]],"batb":[[1,10.5,72.61]],"batl":[[1,12,46.93]],"id":44049799}]}]}
{"op":"mcm","id":2,"clk":"ANbwAgDEpwIAwccC","pt":1743512161091,"mc":[{"id":"1.241629436","rc":[{"atb":[[5.1,401.82]],"batb":[[0,5.1,401.82]],"id":56297029}]}]}
{"op":"mcm","id":2,"clk":"AOPwAgDHpwIAyscC","pt":1743512161183,"mc":[{"id":"1.241629436","rc":[{"atb":[[9.4,31.29]],"atl":[[14.5,14.78]],"batb":[],"batl":[],"id":40389088}]}]}
{"op":"mcm","id":2,"clk":"APTwAgDUpwIA5ccC","pt":1743512161390,"mc":[{"id":"1.241629436","rc":[{"atb":[[6.8,0.63]],"trd":[[6.8,1541.55]],"batb":[[2,6.2,166.4],[1,6.4,275.7],[0,6.6,191.77]],"tv":15238.47,"id":26496185}],"tv":90855.67}]}
{"op":"mcm","id":2,"clk":"APnwAgDapwIA78cC","pt":1743512161492,"mc":[{"id":"1.241629436","rc":[{"atl":[[12,84.64]],"batl":[[0,12,84.64]],"id":40389088},{"atb":[[4.7,98.97]],"batb":[[0,4.7,98.97]],"id":270592},{"atb":[[9.8,46.98]],"batb":[[0,9.8,46.98]],"id":35856222},{"atb":[[5.1,399.82]],"trd":[[5.1,4812.75]],"batb":[[0,5.1,399.82]],"tv":14125.85,"id":56297029},{"atb":[[6.8,0],[6.4,272.71]],"atl":[[7.8,92.96],[6.8,16.05],[7.2,171.56]],"trd":[[6.8,1542.81]],"batb":[[1,6.4,272.71],[0,6.6,191.14]],"batl":[[2,7.2,171.56],[1,7,138.56],[0,6.8,16.05]],"tv":15239.73,"id":26496185}],"tv":90860.93}]}
{"op":"mcm","id":2,"clk":"AIDxAgDgpwIA8scC","pt":1743512161592,"mc":[{"id":"1.241629436","rc":[{"atb":[[9.6,37.97]],"batb":[],"id":40389088},{"atb":[[4.5,237.77]],"atl":[[6,71.24],[4.8,231.03]],"batb":[[2,4.5,237.77]],"batl":[[0,4.8,231.03]],"id":270592},{"atb":[[6.6,213.14],[6.4,275.7]],"batb":[[1,6.4,275.7],[0,6.6,213.14]],"id":26496185}]}]}
{"op":"mcm","id":2,"clk":"AIjxAgDppwIA+8cC","pt":1743512161697,"mc":[{"id":"1.241629436","rc":[{"atb":[[11.5,10.87],[9.2,41.9]],"atl":[[15,20.38]],"batb":[[2,10.5,54.78],[1,11,96.67],[0,11.5,10.87]],"batl":[],"id":40389088},{"atb":[[5.1,373.89]],"batb":[[0,5.1,373.89]],"id":56297029},{"atb":[[6.6,239.07]],"batb":[[0,6.6,239.07]],"id":26496185}]}]}
{"op":"mcm","id":2,"clk":"AI/xAgDwpwIAgcgC","pt":1743512161800,"mc":[{"id":"1.241629436","rc":[{"atb":[[11.5,15.77]],"batb":[[0,11.5,15.77]],"id":40389088},{"atb":[[4.7,110.96],[4.6,285.64]],"batb":[[1,4.6,285.64],[0,4.7,110.96]],"id":270592},{"atb":[[9.8,52.73]],"batb":[[0,9.8,52.73]],"id":35856222},{"atl":[[55,2.49]],"trd":[[55,374.57]],"batl":[[0,55,2.49]],"tv":2095.47,"id":59626646},{"atb":[[5.1,384.94]],"batb":[[0,5.1,384.94]],"id":56297029},{"atb":[[10,112.08]],"batb":[[0,10,112.08]],"id":27115873},{"atl":[[17.5,4.07]],"trd":[[17.5,381.74]],"batl":[[0,17.5,4.07]],"tv":6440.62,"id":58186642},{"atb":[[6.4,266.96]],"atl":[[6.8,7.76],[7.4,45.54]],"trd":[[6.8,1559.39]],"batb":[[1,6.4,266.96]],"batl":[[0,6.8,7.76]],"tv":15256.31,"id":26496185},{"atb":[[11,129.81]],"batb":[[0,11,129.81]],"id":44049799}],"tv":90885.99}]}
{"op":"mcm","id":2,"clk":"AJvxAgD6pwIAjMgC","pt":1743512161899,"mc":[{"id":"1.241629436","rc":[{"atb":[[11.5,28.29]],"atl":[[14,22.68],[13.5,18.83],[13,25.54]],"batb":[[0,11.5,28.29]],"batl":[[2,13,25.54]],"id":40389088},{"atl":[[5.1,137.75]],"batl":[],"id":270592},{"atl":[[11.5,48.79]],"batl":[],"id":35856222},{"atb":[[50,22.11]],"batb":[[0,50,22.11]],"id":59626646},{"atl":[[5.6,40.44]],"batl":[],"id":56297029},{"atl":[[17.5,0]],"batl":[[2,19,12.87],[1,18.5,29.66],[0,18,44.75]],"id":58186642},{"atb":[[6,156.83]],"batb":[],"id":26496185}]}]}
{"op":"mcm","id":2,"clk":"AKHxAgCAqAIAj8gC","pt":1743512162002,"mc":[{"id":"1.241629436","rc":[{"atb":[[4.5,259.77]],"batb":[[2,4.5,259.77]],"id":270592},{"atl":[[65,3.61]],"batl":[[2,65,3.61]],"id":59626646},{"atb":[[1.01,60318.91]],"id":56297029},{"atb":[[17,14.22]],"trd":[[17,1042.86]],"batb":[[0,17,14.22]],"ltp":17,"tv":6450.62,"id":58186642},{"atb":[[6.4,275.22]],"batb":[[1,6.4,275.22]],"id":26496185}],"tv":90895.99}]}
{"op":"mcm","id":2,"clk":"AKrxAgCGqAIAmMgC","pt":1743512162107,"mc":[{"id":"1.241629436","rc":[{"atl":[[4.8,227.73]],"trd":[[4.8,3558.43]],"batl":[[0,4.8,227.73]],"tv":22967.69,"id":270592}],"tv":90902.59}]}
{"op":"mcm","id":2,"clk":"ALXxAgCSqAIAn8gC","pt":1743512162210,"mc":[{"id":"1.241629436","rc":[{"atb":[[9,22.62]],"atl":[[15.5,42.12]],"batb":[],"batl":[],"id":40389088},{"atb":[[4.7,86.71]],"trd":[[4.7,2982.82]],"batb":[[0,4.7,86.71]],"ltp":4.7,"tv":23016.18,"id":270592},{"atb":[[5.1,368.21]],"trd":[[5.1,4846.21]],"batb":[[0,5.1,368.21]],"tv":14159.31,"id":56297029},{"atb":[[17,23.65]],"batb":[[0,17,23.65]],"id":58186642}],"tv":90984.54}]}
{"op":"mcm","id":2,"clk":"AL7xAgCeqAIAo8gC","pt":1743512162317,"mc":[{"id":"1.241629436","rc":[{"atl":[[14.5,16.11]],"batl":[],"id":40389088},{"atl":[[4.9,297.27],[4.8,245.93]],"batl":[[1,4.9,297.27],[0,4.8,245.93]],"id":270592},{"atl":[[18.5,25.94]],"batl":[[1,18.5,25.94]],"id":58186642}]}]}
{"op":"mcm","id":2,"clk":"AMTxAgCpqAIAr8gC","pt":1743512162370,"mc":[{"id":"1.241629436","rc":[{"atb":[[11.5,33.09]],"atl":[[13.5,17.29],[13,23.87]],"batb":[[0,11.5,33.09]],"batl":[[2,13,23.87]],"id":40389088},{"atl":[[5.2,150.86],[4.8,257.78]],"batl":[[0,4.8,257.78]],"id":270592},{"atb":[[9.8,58.43]],"batb":[[0,9.8,58.43]],"id":35856222},{"atb":[[5.1,394.2]],"batb":[[0,5.1,394.2]],"id":56297029},{"atl":[[10.5,126.56]],"batl":[[0,10.5,126.56]],"id":27115873}]}]}
{"op":"mcm","id":2,"clk":"AM3xAgC0qAIAt8gC","pt":1743512162481,"mc":[{"id":"1.241629436","rc":[{"atb":[[11.5,28.29]],"batb":[[0,11.5,28.29]],"id":40389088},{"atb":[[4.7,80.43]],"batb":[[0,4.7,80.43]],"id":270592},{"atb":[[16.5,23.73]],"batb":[[1,16.5,23.73]],"id":58186642}]}]}
{"op":"mcm","id":2,"clk":"ANfxAgC+qAIAwcgC","pt":1743512162585,"mc":[{"id":"1.241629436","rc":[{"atb":[[11.5,24.21]],"trd":[[11.5,1639.44]],"batb":[[0,11.5,24.21]],"tv":7003.27,"id":40389088},{"atl":[[5.2,282.52]],"trd":[[5.2,3881.51]],"batl":[[0,5.2,282.52]],"ltp":5.2,"tv":14163.31,"id":56297029},{"atb":[[17.5,8.53]],"batb":[[2,16.5,23.73],[1,17,23.65],[0,17.5,8.53]],"id":58186642}],"tv":90996.7}]}
{"op":"mcm","id":2,"clk":"AN/xAgDJqAIAzMgC","pt":1743512162686,"mc":[{"id":"1.241629436","rc":[{"atb":[[11.5,25.21]],"atl":[[14,23.16]],"batb":[[0,11.5,25.21]],"batl":[],"id":40389088},{"atb":[[4.7,80.48]],"batb":[[0,4.7,80.48]],"id":270592},{"atl":[[7.2,182.03]],"batl":[[2,7.2,182.03]],"id":26496185}]}]}
{"op":"mcm","id":2,"clk":"AOnxAgDQqAIA1MgC","pt":1743512162790,"mc":[{"id":"1.241629436","rc":[{"atb":[[8.8,27.43]],"atl":[[12,81.11],[16,13.08]],"batb":[],"batl":[[0,12,81.11]],"id":40389088},{"atb":[[17.5,7.39]],"trd":[[17.5,384.02]],"batb":[[0,17.5,7.39]],"ltp":17.5,"tv":6452.9,"id":58186642},{"atb":[[6.6,235.13],[5.8,133.56]],"batb":[[0,6.6,235.13]],"id":26496185}],"tv":90998.98}]}
{"op":"mcm","id":2,"clk":"APTxAgDbqAIA3sgC","pt":1743512162903,"mc":[{"id":"1.241629436","rc":[{"atl":[[10,134.19]],"batl":[[0,10,134.19]],"id":35856222},{"atb":[[17.5,0]],"batb":[[2,16,16.69],[1,16.5,23.73],[0,17,23.65]],"id":58186642}]}]}
{"op":"mcm","id":2,"clk":"AP/xAgDoqAIA6sgC","pt":1743512163007,"mc":[{"id":"1.241629436","rc":[{"atb":[[11.5,31.08],[11,95.89]],"atl":[[12,80.89]],"batb":[[1,11,95.89],[0,11.5,31.08]],"batl":[[0,12,80.89]],"id":40389088},{"atb":[[4.7,50.47]],"trd":[[4.7,3042.82]],"batb":[[0,4.7,50.47]],"tv":23076.18,"id":270592},{"atl":[[1000,1.77],[18,44.49],[17.5,9.66]],"batl":[[2,18.5,25.94],[1,18,44.49],[0,17.5,9.66]],"id":58186642},{"atl":[[7,139.85],[7.2,181.61]],"batl":[[2,7.2,181.61],[1,7,139.85]],"id":26496185},{"atb":[[11,128.88]],"atl":[[12,46.74],[11.5,88.87]],"batb":[[0,11,128.88]],"batl":[[1,12,46.74],[0,11.5,88.87]],"id":44049799}],"tv":91058.98}]}
{"op":"mcm","id":2,"clk":"AIbyAgDwqAIA8sgC","pt":1743512163120,"mc":[{"id":"1.241629436","rc":[{"atb":[[4.7,44.43]],"batb":[[0,4.7,44.43]],"id":270592},{"atl":[[70,7.17]],"batl":[],"id":59626646},{"atb":[[5.1,390.2]],"trd":[[5.1,4854.21]],"batb":[[0,5.1,390.2]],"ltp":5.1,"tv":14171.31,"id":56297029},{"atl":[[1000,1.41]],"id":58186642}],"tv":91066.98}]}
{"op":"mcm","id":2,"clk":"AIzyAgD1qAIA9MgC","pt":1743512163213,"mc":[{"id":"1.241629436","rc":[{"atl":[[4.8,234.24]],"trd":[[4.8,3605.51]],"batl":[[0,4.8,234.24]],"ltp":4.8,"tv":23123.26,"id":270592},{"atl":[[18.5,26.3]],"batl":[[2,18.5,26.3]],"id":58186642},{"atl":[[7.2,171.14]],"batl":[[2,7.2,171.14]],"id":26496185}],"tv":91114.06}]}
{"op":"mcm","id":2,"clk":"AJLyAgD8qAIA/MgC","pt":1743512163318,"mc":[{"id":"1.241629436","rc":[{"atb":[[4.7,56.51]],"batb":[[0,4.7,56.51]],"id":270592},{"atl":[[12,22.69]],"batl":[],"id":35856222}]}]}
{"op":"mcm","id":2,"clk":"AJvyAgCFqQIAh8kC","pt":1743512163419,"mc":[{"id":"1.241629436","rc":[{"atb":[[4.7,78.15]],"batb":[[0,4.7,78.15]],"id":270592},{"atb":[[5.1,364.21]],"batb":[[0,5.1,364.21]],"id":56297029}]}]}
{"op":"mcm","id":2,"clk":"AKfyAgCYqQIAk8kC","pt":1743512163576,"mc":[{"id":"1.241629436","rc":[{"atb":[[1.17,1.52]],"id":26496185}]}]}
{"op":"mcm","id":2,"clk":"AK7yAgCeqQIAlskC","pt":1743512163686,"mc":[{"id":"1.241629436","rc":[{"atl":[[11,28.45]],"batl":[[2,11,28.45]],"id":35856222},{"atb":[[5.1,353.98]],"trd":[[5.1,4874.67]],"batb":[[0,5.1,353.98]],"tv":14191.77,"id":56297029},{"atb":[[1.17,1],[1.26,53.5]],"id":26496185},{"atb":[[11,125.88]],"trd":[[11,1724.64]],"batb":[[0,11,125.88]],"tv":5295.64,"id":44049799}],"tv":91140.52}]}
{"op":"mcm","id":2,"clk":"ALfyAgClqQIAnckC","pt":1743512163781,"mc":[{"id":"1.241629436","rc":[{"atb":[[5.1,380.64]],"atl":[[5.5,87.18]],"batb":[[0,5.1,380.64]],"batl":[],"id":56297029},{"atl":[[6.8,7.24]],"trd":[[6.8,1560.43]],"batl":[[0,6.8,7.24]],"tv":15257.35,"id":26496185}],"tv":91141.56}]}
{"op":"mcm","id":2,"clk":"AMTyAgC0qQIAqskC","pt":1743512163990,"mc":[{"id":"1.241629436","rc":[{"atb":[[4.4,207.68]],"batb":[],"id":270592}]}]}
{"op":"mcm","id":2,"clk":"ANPyAgDFqQIAuMkC","pt":1743512164201,"mc":[{"id":"1.241629436","rc":[{"atb":[[5.9,129.59]],"batb":[],"id":26496185}]}]}
{"op":"mcm","id":2,"clk":"ANvyAgDUqQIAu8kC","pt":1743512164301,"mc":[{"id":"1.241629436","rc":[{"atb":[[1.17,2.31],[11,95.34]],"batb":[[1,11,95.34]],"id":40389088},{"atb":[[5.1,381.65]],"batb":[[0,5.1,381.65]],"id":56297029}]}]}
{"op":"mcm","id":2,"clk":"AOPyAgDbqQIAxskC","pt":1743512164404,"mc":[{"id":"1.241629436","rc":[{"atb":[[1.17,2]],"id":40389088}]}]}
{"op":"mcm","id":2,"clk":"AO3yAgDhqQIAzMkC","pt":1743512164499,"mc":[{"id":"1.241629436","rc":[{"atb":[[11.5,31.39]],"atl":[[12.5,68.03]],"batb":[[0,11.5,31.39]],"batl":[[1,12.5,68.03]],"id":40389088},{"atb":[[6.4,278.91]],"atl":[[6.8,39.19]],"batb":[[1,6.4,278.91]],"batl":[[0,6.8,39.19]],"id":26496185}]}]}
{"op":"mcm","id":2,"clk":"APfyAgDnqQIA0ckC","pt":1743512164600,"mc":[{"id":"1.241629436","rc":[{"atb":[[6.4,270.65]],"atl":[[6.8,47.51]],"batb":[[1,6.4,270.65]],"batl":[[0,6.8,47.51]],"id":26496185}]}]}
{"op":"mcm","id":2,"clk":"AIDzAgDwqQIA2ckC","pt":1743512164702,"mc":[{"id":"1.241629436","rc":[{"atb":[[14.5,1]],"id":59626646},{"atb":[[6.4,278.97]],"batb":[[1,6.4,278.97]],"id":26496185}]}]}
{"op":"mcm","id":2,"clk":"AIXzAgD4qQIA4skC","pt":1743512164803,"mc":[{"id":"1.241629436","rc":[{"atb":[[6.6,215.93]],"batb":[[0,6.6,215.93]],"id":26496185}]}]}
{"op":"mcm","id":2,"clk":"AIvzAgD8qQIA58kC","pt":1743512164905,"mc":[{"id":"1.241629436","rc":[{"atl":[[15,17.67],[14,22.58]],"batl":[],"id":27115873}]}]}
{"op":"mcm","id":2,"clk":"AJPzAgCDqgIA8MkC","pt":1743512165008,"mc":[{"id":"1.241629436","rc":[{"atb":[[5.1,359.83]],"trd":[[5.1,4918.3]],"batb":[[0,5.1,359.83]],"tv":14235.4,"id":56297029},{"atl":[[12.5,280.68]],"batl":[],"id":27115873}],"tv":91185.19}]}
{"op":"mcm","id":2,"clk":"AJrzAgCKqgIA9skC","pt":1743512165114,"mc":[{"id":"1.241629436","rc":[{"atb":[[9.8,57.43]],"trd":[[9.8,1141.7]],"batb":[[0,9.8,57.43]],"tv":10165.66,"id":35856222},{"atb":[[11,124.88]],"trd":[[11,1726.64]],"batb":[[0,11,124.88]],"tv":5297.64,"id":44049799}],"tv":91189.19}]}
{"op":"mcm","id":2,"clk":"AKXzAgCQqgIA/ckC","pt":1743512165213,"mc":[{"id":"1.241629436","rc":[{"atb":[[4.7,78.11]],"batb":[[0,4.7,78.11]],"id":270592},{"atl":[[10,126.24]],"trd":[[10,816.4]],"batl":[[0,10,126.24]],"ltp":10,"tv":10181.55,"id":35856222}],"tv":91205.08}]}
{"op":"mcm","id":2,"clk":"AL/zAgCiqgIAlsoC","pt":1743512165469,"mc":[{"id":"1.241629436","rc":[{"atb":[[4.7,77.11]],"trd":[[4.7,3044.82]],"batb":[[0,4.7,77.11]],"ltp":4.7,"tv":23125.26,"id":270592},{"atb":[[5.1,358.83]],"trd":[[5.1,4920.3]],"batb":[[0,5.1,358.83]],"tv":14237.4,"id":56297029}],"tv":91209.08}]}
{"op":"mcm","id":2,"clk":"ANbzAgC7qgIAsMoC","pt":1743512165790,"mc":[{"id":"1.241629436","rc":[{"atl":[[12,75.07]],"trd":[[12,1445.51]],"batl":[[0,12,75.07]],"ltp":12,"tv":7014.91,"id":40389088},{"atb":[[2,24.85]],"id":58186642}],"tv":91220.72}]}
{"op":"mcm","id":2,"clk":"AN7zAgDCqgIAuMoC","pt":1743512165891,"mc":[{"id":"1.241629436","rc":[{"atb":[[1.46,0]],"id":270592}]}]}
{"op":"mcm","id":2,"clk":"AOjzAgDFqgIAw8oC","pt":1743512165985,"mc":[{"id":"1.241629436","rc":[{"atl":[[17.5,8.15]],"trd":[[17.5,387.04]],"batl":[[0,17.5,8.15]],"tv":6455.92,"id":58186642},{"atb":[[6.6,222.09]],"batb":[[0,6.6,222.09]],"id":26496185}],"tv":91223.74}]}
{"op":"mcm","id":2,"clk":"APfzAgDUqgIA08oC","pt":1743512166189,"mc":[{"id":"1.241629436","rc":[{"atb":[[5.1,378.07]],"batb":[[0,5.1,378.07]],"id":56297029},{"atl":[[17.5,0]],"batl":[[2,19,12.87],[1,18.5,26.3],[0,18,44.49]],"id":58186642}]}]}
{"op":"mcm","id":2,"clk":"AIL0AgDdqgIA3soC","pt":1743512166294,"mc":[{"id":"1.241629436","rc":[{"atb":[[11.5,39.92]],"batb":[[0,11.5,39.92]],"id":40389088},{"atb":[[4.7,97.99]],"batb":[[0,4.7,97.99]],"id":270592},{"atb":[[9.8,67.44]],"batb":[[0,9.8,67.44]],"id":35856222},{"atb":[[50,24.07]],"batb":[[0,50,24.07]],"id":59626646},{"atb":[[10,121.89]],"batb":[[0,10,121.89]],"id":27115873},{"atb":[[17,30.42]],"batb":[[0,17,30.42]],"id":58186642},{"atb":[[6.6,236.96]],"batb":[[0,6.6,236.96]],"id":26496185},{"atb":[[11,133.8]],"batb":[[0,11,133.8]],"id":44049799}]}]}
{"op":"mcm","id":2,"clk":"AIr0AgDmqgIA6MoC","pt":1743512166396,"mc":[{"id":"1.241629436","rc":[{"atb":[[11.5,57.43]],"batb":[[0,11.5,57.43]],"id":40389088},{"atb":[[5.1,368.07]],"trd":[[5.1,4940.3]],"batb":[[0,5.1,368.07]],"tv":14257.4,"id":56297029}],"tv":91243.74}]}
{"op":"mcm","id":2,"clk":"AI/0AgDwqgIA7MoC","pt":1743512166499,"mc":[{"id":"1.241629436","rc":[{"atb":[[5.1,460.36]],"batb":[[0,5.1,460.36]],"id":56297029}]}]}
{"op":"mcm","id":2,"clk":"AKj0AgCUqwIAg8sC","pt":1743512166911,"mc":[{"id":"1.241629436","rc":[{"atb":[[50,9.07]],"trd":[[50,115.73]],"batb":[[0,50,9.07]],"ltp":50,"tv":2125.47,"id":59626646}],"tv":91273.74}]}
{"op":"mcm","id":2,"clk":"ALD0AgCbqwIAi8sC","pt":1743512167012,"mc":[{"id":"1.241629436","rc":[{"atl":[[55,4.23]],"batl":[[0,55,4.23]],"id":59626646}]}]}
{"op":"mcm","id":2,"clk":"ALj0AgCiqwIAkMsC","pt":1743512167115,"mc":[{"id":"1.241629436","rc":[{"atb":[[50,14.17]],"batb":[[0,50,14.17]],"id":59626646}]}]}
{"op":"mcm","id":2,"clk":"AMD0AgCuqwIAlcsC","pt":1743512167216,"mc":[{"id":"1.241629436","rc":[{"atb":[[10,119.31]],"trd":[[10,869.49]],"batb":[[0,10,119.31]],"tv":7563.4,"id":27115873}],"tv":91278.9}]}
{"op":"mcm","id":2,"clk":"AM/0AgC+qwIAo8sC","pt":1743512167381,"mc":[{"id":"1.241629436","rc":[{"atb":[[17,29.42]],"trd":[[17,1044.86]],"batb":[[0,17,29.42]],"ltp":17,"tv":6457.92,"id":58186642}],"tv":91280.9}]}
{"op":"mcm","id":2,"clk":"AN70AgDEqwIArssC","pt":1743512167489,"mc":[{"id":"1.241629436","rc":[{"atl":[[55,4.68]],"batl":[[0,55,4.68]],"id":59626646}]}]}
{"op":"mcm","id":2,"clk":"AOv0AgDLqwIAt8sC","pt":1743512167587,"mc":[{"id":"1.241629436","rc":[{"atb":[[6.6,235.96]],"atl":[[6.8,15.56]],"trd":[[6.6,2238.28]],"batb":[[0,6.6,235.96]],"batl":[[0,6.8,15.56]],"ltp":6.6,"tv":15259.35,"id":26496185}],"tv":91282.9}]}
{"op":"mcm","id":2,"clk":"APb0AgDTqwIAw8sC","pt":1743512167686,"mc":[{"id":"1.241629436","rc":[{"atb":[[6.6,204.01]],"atl":[[6.8,7.24]],"trd":[[6.6,2302.18]],"batb":[[0,6.6,204.01]],"batl":[[0,6.8,7.24]],"tv":15323.25,"id":26496185}],"tv":91346.8}]}
{"op":"mcm","id":2,"clk":"AIP1AgDcqwIAzcsC","pt":1743512167797,"mc":[{"id":"1.241629436","rc":[{"atb":[[11.5,63.48]],"batb":[[0,11.5,63.48]],"id":40389088},{"atb":[[6.6,206.37]],"batb":[[0,6.6,206.37]],"id":26496185}]}]}
{"op":"mcm","id":2,"clk":"AKL1AgDzqwIA48sC","pt":1743512168095,"mc":[{"id":"1.241629436","rc":[{"atl":[[5.5,76.4]],"batl":[],"id":270592},{"atb":[[17,24.42]],"trd":[[17,1054.85]],"batb":[[0,17,24.42]],"tv":6467.91,"id":58186642}],"tv":91356.79}]}
{"op":"mcm","id":2,"clk":"ALH1AgD5qwIA6MsC","pt":1743512168199,"mc":[{"id":"1.241629436","rc":[{"atl":[[17.5,8.13]],"batl":[[2,18.5,26.3],[1,18,44.49],[0,17.5,8.13]],"id":58186642},{"atb":[[6.6,225.57]],"batb":[[0,6.6,225.57]],"id":26496185}]}]}
{"op":"mcm","id":2,"clk":"ALz1AgCErAIA8ssC","pt":1743512168303,"mc":[{"id":"1.241629436","rc":[{"atb":[[6.6,246.57],[5.7,76.92]],"batb":[[0,6.6,246.57]],"id":26496185}]}]}
{"op":"mcm","id":2,"clk":"AO71AgCwrAIAoMwC","pt":1743512168820,"mc":[{"id":"1.241629436","rc":[{"atb":[[4.7,95.34]],"batb":[[0,4.7,95.34]],"id":270592},{"atb":[[9.8,68.45]],"batb":[[0,9.8,68.45]],"id":35856222},{"atb":[[5,1170.5],[5.1,458.98]],"atl":[[5.2,275.89]],"batb":[[1,5,1170.5],[0,5.1,458.98]],"batl":[[0,5.2,275.89]],"id":56297029},{"atl":[[18.5,25.94]],"batl":[[2,18.5,25.94]],"id":58186642}]}]}
{"op":"mcm","id":2,"clk":"APj1AgC6rAIApcwC","pt":1743512168879,"mc":[{"id":"1.241629436","rc":[{"atl":[[7,119.85]],"batl":[[1,7,119.85]],"id":26496185}]}]}
{"op":"mcm","id":2,"clk":"AIX2AgDDrAIAsMwC","pt":1743512168989,"mc":[{"id":"1.241629436","rc":[{"atl":[[7.2,191.14]],"batl":[[2,7.2,191.14]],"id":26496185}]}]}
{"op":"mcm","id":2,"clk":"AIv2AgDKrAIAuswC","pt":1743512169089,"mc":[{"id":"1.241629436","rc":[{"atl":[[12,2.99]],"id":270592}]}]}
{"op":"mcm","id":2,"clk":"ALn2AgDurAIA48wC","pt":1743512169597,"mc":[{"id":"1.241629436","rc":[{"atb":[[11.5,61.48]],"trd":[[11.5,1643.44]],"batb":[[0,11.5,61.48]],"ltp":11.5,"tv":7018.91,"id":40389088},{"atb":[[2,24.92]],"id":58186642}],"tv":91360.79}]}
{"op":"mcm","id":2,"clk":"AMD2AgDzrAIA5swC","pt":1743512169700,"mc":[{"id":"1.241629436","rc":[{"atb":[[4.4,217.68]],"batb":[],"id":270592},{"atl":[[17.5,4.13]],"trd":[[17.5,395.04]],"batl":[[0,17.5,4.13]],"ltp":17.5,"tv":6475.91,"id":58186642}],"tv":91368.79}]}
{"op":"mcm","id":2,"clk":"ANH2AgD9rAIA8MwC","pt":1743512169809,"mc":[{"id":"1.241629436","rc":[{"atl":[[17.5,0]],"batl":[[2,19,12.87],[1,18.5,25.94],[0,18,44.49]],"id":58186642}]}]}
{"op":"mcm","id":2,"clk":"ANr2AgCGrQIA9swC","pt":1743512169911,"mc":[{"id":"1.241629436","rc":[{"atb":[[5.1,456.36]],"trd":[[5.1,4945.54]],"batb":[[0,5.1,456.36]],"tv":14262.64,"id":56297029},{"atl":[[18,40.44]],"trd":[[18,305.43]],"batl":[[0,18,40.44]],"ltp":18,"tv":6484.01,"id":58186642}],"tv":91382.13}]}
{"op":"mcm","id":2,"clk":"AOT2AgCLrQIA+swC","pt":1743512170009,"mc":[{"id":"1.241629436","rc":[{"atb":[[17,26.73]],"batb":[[0,17,26.73]],"id":58186642}]}]}
{"op":"mcm","id":2,"clk":"APr2AgCdrQIAh80C","pt":1743512170218,"mc":[{"id":"1.241629436","rc":[{"atl":[[450,0.01]],"id":270592},{"atl":[[1000,3.41]],"id":58186642}]}]}
{"op":"mcm","id":2,"clk":"AIX3AgCgrQIAjc0C","pt":1743512170322,"mc":[{"id":"1.241629436","rc":[{"atb":[[4.7,90.34]],"atl":[[450,0.02]],"trd":[[4.7,3054.82]],"batb":[[0,4.7,90.34]],"tv":23135.26,"id":270592},{"atb":[[9.8,67.2]],"trd":[[9.8,1144.21]],"batb":[[0,9.8,67.2]],"ltp":9.8,"tv":10184.06,"id":35856222},{"atl":[[1000,2.39]],"id":58186642}],"tv":91394.64}]}
{"op":"mcm","id":2,"clk":"AJH3AgCnrQIAk80C","pt":1743512170374,"mc":[{"id":"1.241629436","rc":[{"atb":[[4.7,90.14]],"atl":[[450,0.03]],"trd":[[4.7,3055.22]],"batb":[[0,4.7,90.14]],"tv":23135.66,"id":270592}],"tv":91395.04}]}
{"op":"mcm","id":2,"clk":"AJf3AgCvrQIAl80C","pt":1743512170472,"mc":[{"id":"1.241629436","rc":[{"atb":[[5.1,456.08]],"trd":[[5.1,4946.1]],"batb":[[0,5.1,456.08]],"tv":14263.2,"id":56297029},{"atl":[[1000,1.41]],"id":58186642}],"tv":91395.6}]}
{"op":"mcm","id":2,"clk":"AKP3AgC6rQIAn80C","pt":1743512170586,"mc":[{"id":"1.241629436","rc":[{"atl":[[17.5,0.98]],"batl":[[0,18,41.42]],"id":58186642}]}]}
{"op":"mcm","id":2,"clk":"AKv3AgDArQIApc0C","pt":1743512170683,"mc":[{"id":"1.241629436","rc":[{"atl":[[4.8,234.37]],"batl":[[0,4.8,234.37]],"id":270592},{"atl":[[17.5,0]],"trd":[[17.5,397]],"batl":[[0,18,40.44]],"ltp":17.5,"tv":6485.97,"id":58186642}],"tv":91397.56}]}
{"op":"mcm","id":2,"clk":"AMD3AgDLrQIAr80C","pt":1743512170888,"mc":[{"id":"1.241629436","rc":[{"atb":[[11.5,60.48]],"trd":[[11.5,1645.45]],"batb":[[0,11.5,60.48]],"tv":7020.92,"id":40389088}],"tv":91399.57}]}
{"op":"mcm","id":2,"clk":"ANb3AgDerQIAvM0C","pt":1743512171095,"mc":[{"id":"1.241629436","rc":[{"atl":[[450,0.01]],"id":56297029},{"atb":[[6.6,226.57]],"trd":[[6.6,2342.18]],"batb":[[0,6.6,226.57]],"tv":15363.25,"id":26496185},{"atl":[[90,1]],"id":44049799}],"tv":91439.57}]}
{"op":"mcm","id":2,"clk":"AOD3AgDnrQIAw80C","pt":1743512171220,"mc":[{"id":"1.241629436","rc":[{"atb":[[4.7,88.14]],"trd":[[4.7,3059.22]],"batb":[[0,4.7,88.14]],"tv":23139.66,"id":270592},{"atl":[[450,0.02]],"id":56297029},{"atl":[[6.8,16.32]],"batl":[[0,6.8,16.32]],"id":26496185},{"atb":[[11,132.3]],"trd":[[11,1729.64]],"batb":[[0,11,132.3]],"tv":5300.64,"id":44049799}],"tv":91446.57}]}
{"op":"mcm","id":2,"clk":"AOz3AgD1rQIAxs0C","pt":1743512171310,"mc":[{"id":"1.241629436","rc":[{"atl":[[450,0.03]],"id":56297029}]}]}
{"op":"mcm","id":2,"clk":"APf3AgCArgIAzc0C","pt":1743512171407,"mc":[{"id":"1.241629436","rc":[{"atb":[[6.6,252.77]],"batb":[[0,6.6,252.77]],"id":26496185}]}]}
{"op":"mcm","id":2,"clk":"AIv4AgCPrgIA2M0C","pt":1743512171606,"mc":[{"id":"1.241629436","rc":[{"atb":[[5.1,454.08]],"trd":[[5.1,4950.1]],"batb":[[0,5.1,454.08]],"tv":14267.2,"id":56297029},{"atb":[[1.52,5]],"id":27115873}],"tv":91450.57}]}
{"op":"mcm","id":2,"clk":"AJ74AgChrgIA4s0C","pt":1743512171814,"mc":[{"id":"1.241629436","rc":[{"atb":[[1.17,2.1]],"id":59626646}]}]}
{"op":"mcm","id":2,"clk":"AKX4AgCqrgIA5c0C","pt":1743512171920,"mc":[{"id":"1.241629436","rc":[{"atb":[[4.7,83.14]],"atl":[[4.8,235.37]],"trd":[[4.7,3069.22]],"batb":[[0,4.7,83.14]],"batl":[[0,4.8,235.37]],"tv":23149.66,"id":270592},{"atb":[[1.17,2]],"id":59626646},{"atb":[[9.6,75.5]],"batb":[[2,9.6,75.5]],"id":27115873},{"atb":[[17,6.73]],"trd":[[17,1094.85]],"batb":[[0,17,6.73]],"ltp":17,"tv":6525.97,"id":58186642},{"atb":[[6.6,242.77]],"atl":[[7,109.85]],"trd":[[6.6,2362.19]],"batb":[[0,6.6,242.77]],"batl":[[1,7,109.85]],"tv":15383.26,"id":26496185}],"tv":91520.58}]}
{"op":"mcm","id":2,"clk":"AKz4AgCyrgIA780C","pt":1743512172024,"mc":[{"id":"1.241629436","rc":[{"atb":[[50,14.27]],"batb":[[0,50,14.27]],"id":59626646},{"atb":[[17,4.42]],"batb":[[0,17,4.42]],"id":58186642},{"atl":[[7,99.85]],"batl":[[1,7,99.85]],"id":26496185}]}]}
{"op":"mcm","id":2,"clk":"ALP4AgC+rgIA880C","pt":1743512172080,"mc":[{"id":"1.241629436","rc":[{"atb":[[17,12.89]],"atl":[[17.5,8.23]],"batb":[[0,17,12.89]],"batl":[[2,18.5,25.94],[1,18,40.44],[0,17.5,8.23]],"id":58186642}]}]}
{"op":"mcm","id":2,"clk":"ALr4AgDHrgIA+s0C","pt":1743512172181,"mc":[{"id":"1.241629436","rc":[{"atb":[[4.7,85.4]],"batb":[[0,4.7,85.4]],"id":270592},{"atb":[[50,13.43]],"trd":[[50,117.41]],"batb":[[0,50,13.43]],"tv":2127.15,"id":59626646},{"atl":[[17.5,11.69]],"batl":[[0,17.5,11.69]],"id":58186642},{"atl":[[450,0.02]],"id":26496185}],"tv":91522.26}]}
{"op":"mcm","id":2,"clk":"AMT4AgDQrgIAg84C","pt":1743512172282,"mc":[{"id":"1.241629436","rc":[{"atl":[[17.5,14.93]],"batl":[[0,17.5,14.93]],"id":58186642},{"atl":[[7.6,53.31]],"batl":[],"id":26496185}]}]}
{"op":"mcm","id":2,"clk":"AM34AgDZrgIAiM4C","pt":1743512172390,"mc":[{"id":"1.241629436","rc":[{"atb":[[16.5,32.4]],"batb":[[1,16.5,32.4]],"id":58186642}]}]}
{"op":"mcm","id":2,"clk":"ANb4AgDergIAks4C","pt":1743512172492,"mc":[{"id":"1.241629436","rc":[{"atb":[[4.7,84.4]],"trd":[[4.7,3071.22]],"batb":[[0,4.7,84.4]],"tv":23151.66,"id":270592},{"atl":[[5.6,42.44]],"batl":[],"id":56297029},{"atl":[[450,0.03]],"id":26496185}],"tv":91524.26}]}
{"op":"mcm","id":2,"clk":"ANv4AgDlrgIAms4C","pt":1743512172590,"mc":[{"id":"1.241629436","rc":[{"atb":[[4.7,104.4]],"atl":[[4.8,236.37]],"batb":[[0,4.7,104.4]],"batl":[[0,4.8,236.37]],"id":270592},{"atl":[[60,3.06]],"batl":[[1,60,3.06]],"id":59626646},{"atl":[[17.5,11.47]],"batl":[[0,17.5,11.47]],"id":58186642}]}]}
{"op":"mcm","id":2,"clk":"AOf4AgCCrwIAss4C","pt":1743512172882,"mc":[{"id":"1.241629436","rc":[{"atb":[[50,7.71]],"atl":[[55,5.99]],"trd":[[50,137.42]],"batb":[[0,50,7.71]],"batl":[[0,55,5.99]],"tv":2147.16,"id":59626646},{"atb":[[17,16.39]],"atl":[[17.5,8.23]],"batb":[[0,17,16.39]],"batl":[[0,17.5,8.23]],"id":58186642}],"con":true,"tv":91544.27}]}
{"op":"mcm","id":2,"clk":"AOr4AgCIrwIAt84C","pt":1743512172905,"mc":[{"id":"1.241629436","rc":[{"atb":[[50,6.25],[48,9.65]],"batb":[[1,48,9.65],[0,50,6.25]],"id":59626646}]}]}
{"op":"mcm","id":2,"clk":"APH4AgCNrwIAus4C","pt":1743512173002,"mc":[{"id":"1.241629436","rc":[{"atb":[[46,9.01]],"batb":[[2,46,9.01]],"id":59626646},{"atl":[[17.5,5.77]],"trd":[[17.5,401.92]],"batl":[[0,17.5,5.77]],"ltp":17.5,"tv":6530.89,"id":58186642}],"tv":91549.19}]}
{"op":"mcm","id":2,"clk":"APr4AgCYrwIAw84C","pt":1743512173104,"mc":[{"id":"1.241629436","rc":[{"atb":[[11.5,58.48]],"trd":[[11.5,1649.45]],"batb":[[0,11.5,58.48]],"tv":7024.92,"id":40389088},{"atb":[[50,4.25]],"trd":[[50,141.42]],"batb":[[0,50,4.25]],"tv":2151.16,"id":59626646},{"atb":[[3.5,22.15]],"id":26496185}],"tv":91557.19}]}
{"op":"mcm","id":2,"clk":"AIL5AgCerwIAyM4C","pt":1743512173213,"mc":[{"id":"1.241629436","rc":[{"atl":[[450,0.01]],"id":35856222},{"atb":[[50,0]],"batb":[[2,44,5.43],[1,46,9.01],[0,48,9.65]],"id":59626646},{"atb":[[17,15.39]],"batb":[[0,17,15.39]],"id":58186642}]}]}
{"op":"mcm","id":2,"clk":"AIz5AgCqrwIA1s4C","pt":1743512173311,"mc":[{"id":"1.241629436","rc":[{"atb":[[11.5,59.48]],"batb":[[0,11.5,59.48]],"id":40389088},{"atl":[[450,0.02]],"id":35856222},{"atb":[[50,1.34]],"batb":[[2,46,9.01],[1,48,9.65],[0,50,1.34]],"id":59626646},{"atb":[[6.6,239.77]],"atl":[[6.8,26.32]],"trd":[[6.6,2368.19]],"batb":[[0,6.6,239.77]],"batl":[[0,6.8,26.32]],"tv":15389.26,"id":26496185}],"tv":91563.19}]}
{"op":"mcm","id":2,"clk":"AJL5AgCvrwIA384C","pt":1743512173410,"mc":[{"id":"1.241629436","rc":[{"atb":[[17,17.9],[2,24.01]],"batb":[[0,17,17.9]],"id":58186642},{"atl":[[7,104.39]],"batl":[[1,7,104.39]],"id":26496185}]}]}
{"op":"mcm","id":2,"clk":"AJz5AgC7rwIA5s4C","pt":1743512173510,"mc":[{"id":"1.241629436","rc":[{"atl":[[450,0.03]],"id":35856222},{"atb":[[17,17.97]],"batb":[[0,17,17.97]],"id":58186642}]}]}
{"op":"mcm","id":2,"clk":"AKT5AgDFrwIA9M4C","pt":1743512173621,"mc":[{"id":"1.241629436","rc":[{"atl":[[4.9,298.27]],"batl":[[1,4.9,298.27]],"id":270592},{"atb":[[9.8,64.2]],"trd":[[9.8,1150.21]],"batb":[[0,9.8,64.2]],"tv":10190.06,"id":35856222},{"atb":[[50,4.87]],"batb":[[0,50,4.87]],"id":59626646},{"atl":[[19,28.82]],"batl":[],"id":58186642}],"tv":91569.19}]}
{"op":"mcm","id":2,"clk":"AMv5AgDkrwIAks8C","pt":1743512173982,"mc":[{"id":"1.241629436","rc":[{"atb":[[11.5,58.48]],"trd":[[11.5,1651.45]],"batb":[[0,11.5,58.48]],"tv":7026.92,"id":40389088},{"atb":[[4.6,48.89]],"batb":[],"id":56297029}],"tv":91571.19}]}
{"op":"mcm","id":2,"clk":"AN/5AgD1rwIAn88C","pt":1743512174182,"mc":[{"id":"1.241629436","rc":[{"atb":[[4.7,100.4]],"trd":[[4.7,3079.22]],"batb":[[0,4.7,100.4]],"tv":23159.66,"id":270592},{"atl":[[450,0.01]],"id":27115873},{"atb":[[6.6,237.77]],"trd":[[6.6,2372.19]],"batb":[[0,6.6,237.77]],"tv":15393.26,"id":26496185}],"tv":91583.19}]}
{"op":"mcm","id":2,"clk":"AOj5AgCBsAIAp88C","pt":1743512174288,"mc":[{"id":"1.241629436","rc":[{"atl":[[5,309.8]],"batl":[[2,5,309.8]],"id":270592},{"atl":[[450,0.03]],"id":27115873},{"atb":[[11,131.29]],"trd":[[11,1731.64]],"batb":[[0,11,131.29]],"tv":5302.64,"id":44049799}],"tv":91585.19}]}
{"op":"mcm","id":2,"clk":"APD5AgCIsAIAsM8C","pt":1743512174395,"mc":[{"id":"1.241629436","rc":[{"atb":[[6.6,237.67]],"trd":[[6.6,2372.39]],"batb":[[0,6.6,237.67]],"tv":15393.46,"id":26496185}],"tv":91585.39}]}
{"op":"mcm","id":2,"clk":"AJP6AgCosAIAz88C","pt":1743512174801,"mc":[{"id":"1.241629436","rc":[{"atb":[[4.7,106.7]],"batb":[[0,4.7,106.7]],"id":270592},{"atb":[[10,118.3]],"trd":[[10,871.49]],"batb":[[0,10,118.3]],"tv":7565.4,"id":27115873}],"tv":91587.39}]}
{"op":"mcm","id":2,"clk":"AKz6AgC4sAIA3c8C","pt":1743512175011,"mc":[{"id":"1.241629436","rc":[{"atl":[[5.1,138.75]],"batl":[],"id":270592}]}]}
{"op":"mcm","id":2,"clk":"ALb6AgDCsAIA6M8C","pt":1743512175114,"mc":[{"id":"1.241629436","rc":[{"atb":[[4.4,222.78]],"batb":[],"id":270592}]}]}
{"op":"mcm","id":2,"clk":"AL76AgDLsAIA688C","pt":1743512175212,"mc":[{"id":"1.241629436","rc":[{"atl":[[10,118.16]],"trd":[[10,832.57]],"batl":[[0,10,118.16]],"ltp":10,"tv":10206.23,"id":35856222},{"atb":[[5.1,436.34]],"trd":[[5.1,4985.58]],"batb":[[0,5.1,436.34]],"tv":14302.68,"id":56297029},{"atb":[[6.6,225.85]],"trd":[[6.6,2396.03]],"batb":[[0,6.6,225.85]],"tv":15417.1,"id":26496185},{"atl":[[450,0.01]],"id":44049799}],"tv":91662.68}]}
{"op":"mcm","id":2,"clk":"AMr6AgDWsAIA9s8C","pt":1743512175322,"mc":[{"id":"1.241629436","rc":[{"atb":[[8.8,34.21],[9.8,70.96]],"batb":[[0,9.8,70.96]],"id":35856222},{"atb":[[1.17,2.99]],"id":56297029},{"atl":[[1000,20.11],[450,0.02]],"id":44049799}]}]}
{"op":"mcm","id":2,"clk":"AND6AgDgsAIA+88C","pt":1743512175418,"mc":[{"id":"1.241629436","rc":[{"atb":[[5.1,450.95]],"batb":[[0,5.1,450.95]],"id":56297029},{"atb":[[6.6,223.05]],"batb":[[0,6.6,223.05]],"id":26496185},{"atl":[[450,0.03]],"id":44049799}]}]}
{"op":"mcm","id":2,"clk":"ANX6AgDtsAIA/88C","pt":1743512175475,"mc":[{"id":"1.241629436","rc":[{"atb":[[1.17,2]],"id":56297029},{"atb":[[6.6,225.85]],"atl":[[6.8,34.63]],"batb":[[0,6.6,225.85]],"batl":[[0,6.8,34.63]],"id":26496185},{"atl":[[1000,19.87]],"id":44049799}]}]}
{"op":"mcm","id":2,"clk":"AN76AgD0sAIAjdAC","pt":1743512175578,"mc":[{"id":"1.241629436","rc":[{"atb":[[5.1,451.94]],"batb":[[0,5.1,451.94]],"id":56297029},{"atl":[[11.5,89.11]],"batl":[[0,11.5,89.11]],"id":44049799}]}]}
{"op":"mcm","id":2,"clk":"AOP6AgD7sAIAktAC","pt":1743512175680,"mc":[{"id":"1.241629436","rc":[{"atb":[[11.5,0]],"trd":[[11.5,1768.42]],"batb":[[2,10,76.37],[1,10.5,54.78],[0,11,95.34]],"tv":7143.89,"id":40389088},{"atb":[[4.7,117.05]],"trd":[[4.7,3082.22]],"batb":[[0,4.7,117.05]],"tv":23162.66,"id":270592}],"tv":91782.65}]}
{"op":"mcm","id":2,"clk":"AO76AgCBsQIAmtAC","pt":1743512175787,"mc":[{"id":"1.241629436","rc":[{"atb":[[11,90.37]],"batb":[[0,11,90.37]],"id":40389088},{"atl":[[10,112.31]],"batl":[[0,10,112.31]],"id":35856222},{"atl":[[60,0.38],[55,0]],"trd":[[60,405.25],[55,386.55]],"batl":[[2,75,5.07],[1,70,7.17],[0,65,3.99]],"ltp":60,"tv":2168.5,"id":59626646},{"atl":[[10.5,112.85]],"batl":[[0,10.5,112.85]],"id":27115873},{"atb":[[17,21.17]],"batb":[[0,17,21.17]],"id":58186642}],"tv":91799.99}]}
{"op":"mcm","id":2,"clk":"APj6AgCIsQIAotAC","pt":1743512175891,"mc":[{"id":"1.241629436","rc":[{"atl":[[14.5,14.78],[14,21.73],[13.5,17.78]],"batl":[],"id":40389088},{"atl":[[4.9,297.66]],"batl":[[1,4.9,297.66]],"id":270592},{"atb":[[50,10.12]],"atl":[[60,21.88],[55,3]],"batb":[[0,50,10.12]],"batl":[[2,65,3.61],[1,60,21.88],[0,55,3]],"id":59626646}]}]}
{"op":"mcm","id":2,"clk":"AIH7AgCPsQIAqNAC","pt":1743512175993,"mc":[{"id":"1.241629436","rc":[{"atb":[[4.7,116.44]],"atl":[[5.2,151.86]],"trd":[[4.7,3083.44]],"batb":[[0,4.7,116.44]],"batl":[],"tv":23163.88,"id":270592},{"atb":[[50,11.51]],"atl":[[60,22.72],[65,5.05]],"batb":[[0,50,11.51]],"batl":[[2,65,5.05],[1,60,22.72]],"id":59626646}],"tv":91801.21}]}
{"op":"mcm","id":2,"clk":"AI37AgCXsQIAq9AC","pt":1743512176092,"mc":[{"id":"1.241629436","rc":[{"atl":[[60,6.88]],"batl":[[1,60,6.88]],"id":59626646}]}]}
{"op":"mcm","id":2,"clk":"AK/7AgCbsQIAsdAC","pt":1743512176196,"mc":[{"id":"1.241629436","rc":[{"atl":[[450,0.01]],"id":40389088},{"atl":[[10,102.31]],"trd":[[10,852.57]],"batl":[[0,10,102.31]],"tv":10226.23,"id":35856222},{"atl":[[60,2.54]],"batl":[[1,60,2.54]],"id":59626646}],"tv":91821.21}]}
{"op":"mcm","id":2,"clk":"ALn7AgCisQIAttAC","pt":1743512176301,"mc":[{"id":"1.241629436","rc":[{"atl":[[10.5,70.7]],"batl":[[1,10.5,70.7]],"id":35856222}]}]}
{"op":"mcm","id":2,"clk":"AL77AgCnsQIAvdAC","pt":1743512176404,"mc":[{"id":"1.241629436","rc":[{"atl":[[450,0.03]],"id":40389088}]}]}
{"op":"mcm","id":2,"clk":"AMf7AgCqsQIAwtAC","pt":1743512176509,"mc":[{"id":"1.241629436","rc":[{"atb":[[5.1,448.67]],"trd":[[5.1,4992.12]],"batb":[[0,5.1,448.67]],"tv":14309.22,"id":56297029}],"tv":91827.75}]}
{"op":"mcm","id":2,"clk":"ANj7AgC6sQIAz9AC","pt":1743512176720,"mc":[{"id":"1.241629436","rc":[{"atl":[[5.3,135.74],[4.8,236.66]],"batl":[[0,4.8,236.66]],"id":270592},{"atl":[[10,102.36]],"batl":[[0,10,102.36]],"id":35856222},{"atl":[[55,3.02]],"batl":[[0,55,3.02]],"id":59626646},{"atl":[[5.2,265.89]],"batl":[[0,5.2,265.89]],"id":56297029}]}]}
{"op":"mcm","id":2,"clk":"AP37AgDesQIA6tAC","pt":1743512177083,"mc":[{"id":"1.241629436","rc":[{"atl":[[12,72.47]],"trd":[[12,1450.71]],"batl":[[0,12,72.47]],"ltp":12,"tv":7149.09,"id":40389088}],"tv":91832.95}]}
{"op":"mcm","id":2,"clk":"AIP8AgDmsQIA8tAC","pt":1743512177181,"mc":[{"id":"1.241629436","rc":[{"atb":[[11.5,1.21]],"batb":[[2,10.5,54.78],[1,11,90.37],[0,11.5,1.21]],"id":40389088},{"atb":[[4.7,116.48]],"batb":[[0,4.7,116.48]],"id":270592},{"atb":[[50,12.01]],"batb":[[0,50,12.01]],"id":59626646},{"atl":[[450,0.01]],"id":58186642}]}]}
{"op":"mcm","id":2,"clk":"AIr8AgDtsQIA99AC","pt":1743512177288,"mc":[{"id":"1.241629436","rc":[{"atl":[[14.5,16.11],[14,23.16]],"batl":[],"id":40389088}]}]}
{"op":"mcm","id":2,"clk":"AJH8AgD2sQIA/NAC","pt":1743512177384,"mc":[{"id":"1.241629436","rc":[{"atl":[[450,0.03]],"id":58186642},{"atl":[[7,104.29]],"batl":[[1,7,104.29]],"id":26496185}]}]}
{"op":"mcm","id":2,"clk":"ALL8AgCHsgIAkdEC","pt":1743512177794,"mc":[{"id":"1.241629436","rc":[{"atb":[[5,1129.7]],"batb":[[1,5,1129.7]],"id":56297029}]}]}
{"op":"mcm","id":2,"clk":"AL78AgCNsgIAmdEC","pt":1743512177899,"mc":[{"id":"1.241629436","rc":[{"atb":[[5.1,445.67]],"trd":[[5.1,4998.12]],"batb":[[0,5.1,445.67]],"tv":14315.22,"id":56297029}],"tv":91838.95}]}
{"op":"mcm","id":2,"clk":"AMj8AgCRsgIAndEC","pt":1743512178006,"mc":[{"id":"1.241629436","rc":[{"atb":[[9.8,68.58]],"trd":[[9.8,1154.97]],"batb":[[0,9.8,68.58]],"ltp":9.8,"tv":10230.99,"id":35856222},{"atb":[[10,115.92]],"trd":[[10,876.25]],"batb":[[0,10,115.92]],"tv":7570.16,"id":27115873}],"tv":91848.47}]}
{"op":"mcm","id":2,"clk":"AM78AgCVsgIApNEC","pt":1743512178102,"mc":[{"id":"1.241629436","rc":[{"atl":[[44,2]],"id":35856222},{"atl":[[44,2.02]],"id":58186642}]}]}
{"op":"mcm","id":2,"clk":"AOL8AgCjsgIAstEC","pt":1743512178313,"mc":[{"id":"1.241629436","rc":[{"atl":[[450,0.01]],"id":59626646},{"atb":[[5,1131.04]],"batb":[[1,5,1131.04]],"id":56297029},{"atb":[[11,132.88]],"atl":[[1000,20.2]],"batb":[[0,11,132.88]],"id":44049799}]}]}
{"op":"mcm","id":2,"clk":"AOv8AgCtsgIAudEC","pt":1743512178417,"mc":[{"id":"1.241629436","rc":[{"atl":[[450,0.03]],"id":59626646},{"atl":[[1000,19.87]],"id":44049799}]}]}
{"op":"mcm","id":2,"clk":"APX8AgC9sgIAxNEC","pt":1743512178528,"mc":[{"id":"1.241629436","rc":[{"atl":[[12,47.07]],"batl":[[1,12,47.07]],"id":44049799}]}]}
{"op":"mcm","id":2,"clk":"AP38AgC+sgIAydEC","pt":1743512178618,"mc":[{"id":"1.241629436","rc":[{"atl":[[5.2,152.86]],"batl":[],"id":270592}]}]}
{"op":"mcm","id":2,"clk":"AIj9AgDDsgIA0dEC","pt":1743512178721,"mc":[{"id":"1.241629436","rc":[{"atb":[[10.5,61.26]],"batb":[[2,10.5,61.26]],"id":40389088}]}]}
{"op":"mcm","id":2,"clk":"AJT9AgDLsgIA3tEC","pt":1743512178830,"mc":[{"id":"1.241629436","rc":[{"atb":[[10.5,54.78]],"batb":[[2,10.5,54.78]],"id":40389088},{"atb":[[5.1,485.67]],"batb":[[0,5.1,485.67]],"id":56297029}]}]}
{"op":"mcm","id":2,"clk":"AKT9AgDcsgIA6dEC","pt":1743512178988,"mc":[{"id":"1.241629436","rc":[{"atb":[[11.5,0],[11,74.86]],"trd":[[11.5,1770.84],[11,347.24]],"batb":[[2,10,76.37],[1,10.5,54.78],[0,11,74.86]],"ltp":11,"tv":7182.53,"id":40389088}],"tv":91881.91}]}
{"op":"mcm","id":2,"clk":"AKz9AgDisgIA8dEC","pt":1743512179096,"mc":[{"id":"1.241629436","rc":[{"atb":[[11,82.04]],"atl":[[14.5,14.78],[14,21.73]],"batb":[[0,11,82.04]],"batl":[],"id":40389088}]}]}
{"op":"mcm","id":2,"clk":"ALX9AgDnsgIA89EC","pt":1743512179190,"mc":[{"id":"1.241629436","rc":[{"atb":[[9.8,60.58]],"trd":[[9.8,1170.97]],"batb":[[0,9.8,60.58]],"tv":10246.99,"id":35856222},{"atl":[[7,102.29]],"batl":[[1,7,102.29]],"id":26496185}],"tv":91897.91}]}
{"op":"mcm","id":2,"clk":"AL/9AgDvsgIA+dEC","pt":1743512179303,"mc":[{"id":"1.241629436","rc":[{"atb":[[9.8,71.84]],"batb":[[0,9.8,71.84]],"id":35856222}]}]}
{"op":"mcm","id":2,"clk":"AOL9AgCVswIAktIC","pt":1743512179810,"mc":[{"id":"1.241629436","rc":[{"atb":[[4.7,88.49]],"trd":[[4.7,3139.43]],"batb":[[0,4.7,88.49]],"tv":23219.87,"id":270592},{"atb":[[9.8,46.84]],"trd":[[9.8,1220.97]],"batb":[[0,9.8,46.84]],"tv":10296.99,"id":35856222}],"tv":92003.9}]}
{"op":"mcm","id":2,"clk":"AOj9AgCeswIAndIC","pt":1743512179910,"mc":[{"id":"1.241629436","rc":[{"atb":[[11,95.04]],"batb":[[0,11,95.04]],"id":40389088},{"atl":[[5.1,139.75]],"batl":[],"id":270592},{"atb":[[9.8,40.08]],"batb":[[0,9.8,40.08]],"id":35856222},{"atb":[[5.1,504.07]],"batb":[[0,5.1,504.07]],"id":56297029},{"atl":[[6.8,25.55]],"batl":[[0,6.8,25.55]],"id":26496185}]}]}
{"op":"mcm","id":2,"clk":"APP9AgCqswIApNIC","pt":1743512180122,"mc":[{"id":"1.241629436","rc":[{"atl":[[5.2,178.85]],"batl":[[0,5.2,178.85]],"id":56297029}]}]}
{"op":"mcm","id":2,"clk":"APn9AgCvswIAqdIC","pt":1743512180219,"mc":[{"id":"1.241629436","rc":[{"atb":[[9.8,0]],"trd":[[9.8,1301.12]],"batb":[[2,9.2,79.65],[1,9.4,54.19],[0,9.6,90.27]],"tv":10377.14,"id":35856222}],"tv":92084.05}]}
{"op":"mcm","id":2,"clk":"AIT+AgC3swIAstIC","pt":1743512180330,"mc":[{"id":"1.241629436","rc":[{"atl":[[10,100.2]],"trd":[[10,868.32]],"batl":[[0,10,100.2]],"ltp":10,"tv":10392.89,"id":35856222},{"atl":[[5.4,68.95],[5.5,98.07]],"batl":[[2,5.4,68.95]],"id":56297029}],"tv":92099.8}]}
{"op":"mcm","id":2,"clk":"AI3+AgC6swIAuNIC","pt":1743512180421,"mc":[{"id":"1.241629436","rc":[{"atb":[[9.4,31.71],[9.2,63.63],[9.6,68.02]],"atl":[[10,105.89]],"batb":[[2,9.2,63.63],[1,9.4,31.71],[0,9.6,68.02]],"batl":[[0,10,105.89]],"id":35856222},{"atl":[[6.8,17.24]],"batl":[[0,6.8,17.24]],"id":26496185}]}]}
{"op":"mcm","id":2,"clk":"AJf+AgDDswIAvtIC","pt":1743512180524,"mc":[{"id":"1.241629436","rc":[{"atl":[[5.5,78.36]],"batl":[],"id":56297029}]}]}
{"op":"mcm","id":2,"clk":"AJ3+AgDGswIAxNIC","pt":1743512180622,"mc":[{"id":"1.241629436","rc":[{"atl":[[12,70.36]],"trd":[[12,1454.93]],"batl":[[0,12,70.36]],"ltp":12,"tv":7186.75,"id":40389088},{"atl":[[17.5,3.66]],"trd":[[17.5,406.14]],"batl":[[0,17.5,3.66]],"tv":6535.11,"id":58186642},{"atl":[[11.5,87]],"trd":[[11.5,1086.73]],"batl":[[0,11.5,87]],"ltp":11.5,"tv":5306.86,"id":44049799}],"tv":92112.46}]}
{"op":"mcm","id":2,"clk":"AKX+AgDNswIAytIC","pt":1743512180733,"mc":[{"id":"1.241629436","rc":[{"atb":[[5.1,477.41]],"batb":[[0,5.1,477.41]],"id":56297029},{"atl":[[17.5,0]],"batl":[[2,19,28.82],[1,18.5,25.94],[0,18,40.44]],"id":58186642}]}]}
{"op":"mcm","id":2,"clk":"ALL+AgDYswIA1dIC","pt":1743512180941,"mc":[{"id":"1.241629436","rc":[{"atb":[[17,29.17]],"batb":[[0,17,29.17]],"id":58186642}]}]}
{"op":"mcm","id":2,"clk":"AMT+AgDmswIA4dIC","pt":1743512181099,"mc":[{"id":"1.241629436","rc":[{"atl":[[12,71.36],[16.5,8.76]],"batl":[[0,12,71.36]],"id":40389088},{"atb":[[4.7,88.39]],"atl":[[12,3.99]],"trd":[[4.7,3139.63]],"batb":[[0,4.7,88.39]],"tv":23220.07,"id":270592},{"atl":[[12,23.69]],"batl":[],"id":35856222},{"atb":[[50,11.01]],"trd":[[50,143.42]],"batb":[[0,50,11.01]],"ltp":50,"tv":2170.5,"id":59626646},{"atl":[[12,1]],"id":56297029},{"atl":[[12,30.76]],"batl":[],"id":27115873},{"atl":[[17.5,1]],"batl":[[2,18.5,25.94],[1,18,40.44],[0,17.5,1]],"id":58186642},{"atl":[[12,28]],"id":26496185},{"atl":[[12,48.07]],"batl":[[1,12,48.07]],"id":44049799}],"tv":92114.66}]}
{"op":"mcm","id":2,"clk":"AM/+AgDsswIA5dIC","pt":1743512181206,"mc":[{"id":"1.241629436","rc":[{"atb":[[50,11.22]],"batb":[[0,50,11.22]],"id":59626646},{"atl":[[19,12.87],[18,37.25]],"batl":[[1,18,37.25]],"id":58186642},{"atl":[[7,99.79]],"batl":[[1,7,99.79]],"id":26496185}]}]}
{"op":"mcm","id":2,"clk":"ANj+AgD6swIA7tIC","pt":1743512181304,"mc":[{"id":"1.241629436","rc":[{"atl":[[6.8,19.74]],"batl":[[0,6.8,19.74]],"id":26496185}]}]}
{"op":"mcm","id":2,"clk":"AN/+AgCBtAIA8NIC","pt":1743512181403,"mc":[{"id":"1.241629436","rc":[{"atb":[[17,25.17]],"trd":[[17,1102.85]],"batb":[[0,17,25.17]],"ltp":17,"tv":6543.11,"id":58186642}],"tv":92122.66}]}
{"op":"mcm","id":2,"clk":"APH+AgCPtAIA9tIC","pt":1743512181609,"mc":[{"id":"1.241629436","rc":[{"atb":[[11,131.29]],"batb":[[0,11,131.29]],"id":44049799}]}]}
{"op":"mcm","id":2,"clk":"APj+AgCZtAIA/NIC","pt":1743512181713,"mc":[{"id":"1.241629436","rc":[{"atl":[[1000,0.36]],"id":40389088},{"atl":[[4.9,296.6],[5.3,185.74]],"batl":[[1,4.9,296.6]],"id":270592},{"atl":[[5.2,178.36]],"batl":[[0,5.2,178.36]],"id":56297029},{"atb":[[6.6,224.18]],"batb":[[0,6.6,224.18]],"id":26496185},{"atl":[[12,47.74],[11.5,86.76]],"batl":[[1,12,47.74],[0,11.5,86.76]],"id":44049799}]}]}
{"op":"mcm","id":2,"clk":"AP/+AgCftAIAhNMC","pt":1743512181814,"mc":[{"id":"1.241629436","rc":[{"atl":[[1000,0.25],[17,7.51]],"id":40389088},{"atb":[[6.6,216.18]],"trd":[[6.6,2412.03]],"batb":[[0,6.6,216.18]],"tv":15433.1,"id":26496185}],"tv":92138.66}]}
{"op":"mcm","id":2,"clk":"AIf/AgCktAIAktMC","pt":1743512181918,"mc":[{"id":"1.241629436","rc":[{"atb":[[1.17,2.62]],"atl":[[1000,0.37],[12,71.47]],"batl":[[0,12,71.47]],"id":40389088},{"atb":[[4.6,285.52]],"batb":[[1,4.6,285.52]],"id":270592},{"atb":[[9.6,69.26]],"batb":[[0,9.6,69.26]],"id":35856222},{"atb":[[5.1,479.06]],"batb":[[0,5.1,479.06]],"id":56297029}]}]}
{"op":"mcm","id":2,"clk":"AI7/AgCvtAIAmdMC","pt":1743512182019,"mc":[{"id":"1.241629436","rc":[{"atb":[[1.17,2]],"atl":[[1000,0.25]],"id":40389088},{"atb":[[6.6,217.42]],"batb":[[0,6.6,217.42]],"id":26496185}]}]}
{"op":"mcm","id":2,"clk":"AJT/AgC6tAIApNMC","pt":1743512182125,"mc":[{"id":"1.241629436","rc":[{"atb":[[11,95.66]],"atl":[[12.5,68.15]],"batb":[[0,11,95.66]],"batl":[[1,12.5,68.15]],"id":40389088},{"atb":[[4.7,85.39]],"trd":[[4.7,3145.63]],"batb":[[0,4.7,85.39]],"tv":23226.07,"id":270592}],"tv":92144.66}]}
{"op":"mcm","id":2,"clk":"AJ7/AgDDtAIArNMC","pt":1743512182234,"mc":[{"id":"1.241629436","rc":[{"atb":[[11,130.29]],"trd":[[11,1733.65]],"batb":[[0,11,130.29]],"ltp":11,"tv":5308.87,"id":44049799}],"tv":92146.67}]}
{"op":"mcm","id":2,"clk":"AKv/AgDMtAIAt9MC","pt":1743512182337,"mc":[{"id":"1.241629436","rc":[{"atl":[[17.5,9.07]],"id":40389088},{"atb":[[4.6,275.52]],"batb":[[1,4.6,275.52]],"id":270592}]}]}
{"op":"mcm","id":2,"clk":"ALv/AgDhtAIAxNMC","pt":1743512182496,"mc":[{"id":"1.241629436","rc":[{"atb":[[5.1,476.66]],"trd":[[5.1,5002.92]],"batb":[[0,5.1,476.66]],"tv":14320.02,"id":56297029}],"tv":92151.47}]}
{"op":"mcm","id":2,"clk":"AMb/AgDqtAIAztMC","pt":1743512182602,"mc":[{"id":"1.241629436","rc":[{"atb":[[2,51.01]],"atl":[[6.8,4.74]],"trd":[[6.8,1590.43]],"batl":[[0,6.8,4.74]],"ltp":6.8,"tv":15463.1,"id":26496185}],"tv":92181.47}]}
{"op":"mcm","id":2,"clk":"ANP/AgDztAIA3dMC","pt":1743512182795,"mc":[{"id":"1.241629436","rc":[{"atb":[[11,129.29]],"trd":[[11,1735.65]],"batb":[[0,11,129.29]],"tv":5310.87,"id":44049799}],"tv":92183.47}]}
{"op":"mcm","id":2,"clk":"AOH/AgD6tAIA8NMC","pt":1743512183002,"mc":[{"id":"1.241629436","rc":[{"atl":[[18,7.84]],"id":40389088}]}]}
{"op":"mcm","id":2,"clk":"AOT/AgCDtQIA+dMC","pt":1743512183108,"mc":[{"id":"1.241629436","rc":[{"atb":[[17,21.17]],"trd":[[17,1110.85]],"batb":[[0,17,21.17]],"tv":6551.11,"id":58186642}],"tv":92191.47}]}
{"op":"mcm","id":2,"clk":"APX/AgCKtQIAj9QC","pt":1743512183312,"mc":[{"id":"1.241629436","rc":[{"atl":[[4.9,297.6]],"batl":[[1,4.9,297.6]],"id":270592},{"atb":[[17,13.17]],"batb":[[0,17,13.17]],"id":58186642}]}]}
{"op":"mcm","id":2,"clk":"AJSAAwCntQIAodQC","pt":1743512183622,"mc":[{"id":"1.241629436","rc":[{"atb":[[4.7,95.39]],"batb":[[0,4.7,95.39]],"id":270592},{"atl":[[6.8,0.74]],"trd":[[6.8,1598.43]],"batl":[[2,7.4,45.54],[1,7.2,191.14],[0,7,100.53]],"tv":15471.1,"id":26496185}],"tv":92199.47}]}
{"op":"mcm","id":2,"clk":"AJ6AAwC0tQIAqtQC","pt":1743512183733,"mc":[{"id":"1.241629436","rc":[{"atl":[[17.5,9.19]],"batl":[[0,17.5,9.19]],"id":58186642},{"atb":[[6.6,214.62],[6.8,20.8],[6.4,275.98]],"atl":[[6.8,0]],"trd":[[6.8,1599.91]],"batb":[[2,6.4,275.98],[1,6.6,214.62],[0,6.8,20.8]],"batl":[[0,7,99.79]],"tv":15472.58,"id":26496185},{"atb":[[11,126.79]],"trd":[[11,1740.65]],"batb":[[0,11,126.79]],"tv":5315.87,"id":44049799}],"tv":92205.95}]}
{"op":"mcm","id":2,"clk":"AKOAAwC5tQIArtQC","pt":1743512183821,"mc":[{"id":"1.241629436","rc":[{"atl":[[18,40.42]],"batl":[[1,18,40.42]],"id":58186642}]}]}
{"op":"mcm","id":2,"clk":"AK6AAwDCtQIAuNQC","pt":1743512183933,"mc":[{"id":"1.241629436","rc":[{"atb":[[6.6,222.79],[6,156.04],[6.4,278.97]],"batb":[[2,6.4,278.97],[1,6.6,222.79]],"id":26496185}]}]}
{"op":"mcm","id":2,"clk":"ALSAAwDJtQIAvdQC","pt":1743512184033,"mc":[{"id":"1.241629436","rc":[{"atb":[[5.9,119.74]],"batb":[],"id":26496185}]}]}
{"op":"mcm","id":2,"clk":"AMiAAwDZtQIAx9QC","pt":1743512184204,"mc":[{"id":"1.241629436","rc":[{"atb":[[11,78.93]],"trd":[[11,380.7]],"batb":[[0,11,78.93]],"ltp":11,"tv":7220.21,"id":40389088},{"atb":[[4.7,30.38]],"trd":[[4.7,3275.64]],"batb":[[0,4.7,30.38]],"tv":23356.08,"id":270592},{"atb":[[6.6,232.79]],"batb":[[1,6.6,232.79]],"id":26496185}],"tv":92369.42}]}
{"op":"mcm","id":2,"clk":"AM2AAwDgtQIAzdQC","pt":1743512184291,"mc":[{"id":"1.241629436","rc":[{"atb":[[4.6,338.37]],"batb":[[1,4.6,338.37]],"id":270592},{"atl":[[10.5,109.43]],"batl":[[0,10.5,109.43]],"id":27115873}]}]}
{"op":"mcm","id":2,"clk":"AOaAAwDvtQIA1tQC","pt":1743512184497,"mc":[{"id":"1.241629436","rc":[{"atb":[[4.7,30.34]],"batb":[[0,4.7,30.34]],"id":270592}]}]}
{"op":"mcm","id":2,"clk":"APSAAwD1tQIA3dQC","pt":1743512184601,"mc":[{"id":"1.241629436","rc":[{"atb":[[4.7,32.24]],"batb":[[0,4.7,32.24]],"id":270592}]}]}
{"op":"mcm","id":2,"clk":"APyAAwCAtgIA4tQC","pt":1743512184707,"mc":[{"id":"1.241629436","rc":[{"atb":[[1.17,2.7]],"id":40389088},{"atb":[[1.17,7.77]],"id":35856222}]}]}
{"op":"mcm","id":2,"clk":"AImBAwCFtgIA6dQC","pt":1743512184808,"mc":[{"id":"1.241629436","rc":[{"atb":[[1.17,2],[1.06,5427.57]],"id":40389088},{"atb":[[1.06,5415.02]],"id":270592},{"atb":[[1.17,7.15],[1.06,5316.34]],"id":35856222},{"atb":[[1.06,5532.11]],"id":59626646},{"atb":[[1.06,5562.22]],"id":56297029},{"atb":[[1.06,5652.54]],"id":27115873},{"atb":[[1.06,5212.63]],"id":58186642},{"atb":[[1.06,5601.53]],"id":26496185},{"atb":[[1.06,6044.78]],"id":44049799}]}]}
{"op":"mcm","id":2,"clk":"AJGBAwCItgIA79QC","pt":1743512184909,"mc":[{"id":"1.241629436","rc":[{"atb":[[11,79.63]],"batb":[[0,11,79.63]],"id":40389088},{"atb":[[9.6,69.88]],"batb":[[0,9.6,69.88]],"id":35856222}]}]}
{"op":"mcm","id":2,"clk":"AJ+BAwCPtgIA99QC","pt":1743512185008,"mc":[{"id":"1.241629436","rc":[{"atb":[[1.06,5426.71]],"id":40389088},{"atb":[[1.06,5414.16]],"atl":[[4.8,238.91]],"batl":[[0,4.8,238.91]],"id":270592},{"atb":[[1.06,5315.48]],"id":35856222},{"atb":[[1.06,5531.25]],"id":59626646},{"atb":[[1.06,5561.36]],"id":56297029},{"atb":[[1.06,5651.68]],"id":27115873},{"atb":[[1.06,5211.77]],"atl":[[1000,2.41]],"id":58186642},{"atb":[[1.06,5600.67]],"atl":[[7,103.79]],"batl":[[0,7,103.79]],"id":26496185},{"atb":[[1.06,6043.92]],"id":44049799}]}]}
{"op":"mcm","id":2,"clk":"AKyBAwCTtgIAiNUC","pt":1743512185116,"mc":[{"id":"1.241629436","rc":[{"atb":[[4.7,0]],"atl":[[4.7,7.76]],"trd":[[4.7,3340.12]],"batb":[[2,4.4,222.78],[1,4.5,259.77],[0,4.6,338.37]],"batl":[[2,4.9,297.6],[1,4.8,238.91],[0,4.7,7.76]],"tv":23420.56,"id":270592},{"atb":[[6.8,72.18],[6.4,297.94]],"batb":[[2,6.4,297.94],[0,6.8,72.18]],"id":26496185}],"tv":92433.9}]}
{"op":"mcm","id":2,"clk":"ALKBAwCetgIAjNUC","pt":1743512185218,"mc":[{"id":"1.241629436","rc":[{"atb":[[1.06,5426.57]],"id":40389088},{"atb":[[4.4,221.62],[1.06,5414.02]],"atl":[[4.7,0.01],[5.1,138.85]],"trd":[[4.7,3355.62]],"batb":[[2,4.4,221.62]],"batl":[[2,5,309.8],[1,4.9,297.6],[0,4.8,238.92]],"tv":23436.06,"id":270592},{"atb":[[9.4,37.45],[1.06,5315.34]],"batb":[[1,9.4,37.45]],"id":35856222},{"atb":[[1.06,5531.11]],"id":59626646},{"atb":[[1.06,5561.22]],"id":56297029},{"atb":[[1.06,5651.54]],"id":27115873},{"atb":[[1.06,5211.63]],"id":58186642},{"atb":[[6.8,101.91],[1.06,5600.53]],"batb":[[0,6.8,101.91]],"id":26496185},{"atb":[[1.06,6043.78]],"id":44049799}],"tv":92449.4}]}
{"op":"mcm","id":2,"clk":"ALqBAwCjtgIAj9UC","pt":1743512185315,"mc":[{"id":"1.241629436","rc":[{"atb":[[1.55,1.88]],"id":40389088},{"atb":[[4.7,11.61],[4.2,106.45],[4.4,216.52],[1.55,2.14],[4.6,336.72]],"atl":[[4.7,0]],"trd":[[4.7,3355.64]],"batb":[[2,4.5,259.77],[1,4.6,336.72],[0,4.7,11.61]],"batl":[[0,4.8,238.91]],"tv":23436.08,"id":270592},{"atb":[[1.55,0.14]],"id":35856222},{"atb":[[1.55,0.14]],"id":59626646},{"atb":[[1.55,0.14]],"atl":[[5.2,176.02]],"batl":[[0,5.2,176.02]],"id":56297029},{"atb":[[1.55,0.14]],"id":27115873},{"atb":[[1.55,0.14]],"id":58186642},{"atb":[[1.55,0.14]],"id":26496185},{"atb":[[1.55,0.14]],"id":44049799}],"tv":92449.42}]}
{"op":"mcm","id":2,"clk":"AMWBAwCptgIAldUC","pt":1743512185420,"mc":[{"id":"1.241629436","rc":[{"atb":[[4.7,0],[4.6,333.63],[4.3,150.36],[4.5,256.52]],"atl":[[4.7,61.43],[5,310.73]],"trd":[[4.7,3378.86]],"batb":[[2,4.4,216.52],[1,4.5,256.52],[0,4.6,333.63]],"batl":[[2,4.9,297.6],[1,4.8,238.91],[0,4.7,61.43]],"tv":23459.3,"id":270592},{"atl":[[5.2,178.36]],"batl":[[0,5.2,178.36]],"id":56297029}],"tv":92472.64}]}
{"op":"mcm","id":2,"clk":"ANCBAwCttgIAo9UC","pt":1743512185527,"mc":[{"id":"1.241629436","rc":[{"atb":[[4.6,336.72],[4.5,247.68]],"batb":[[1,4.5,247.68],[0,4.6,336.72]],"id":270592},{"atl":[[5.5,67.47]],"batl":[],"id":56297029},{"atb":[[6.4,278.97]],"batb":[[2,6.4,278.97]],"id":26496185}]}]}
{"op":"mcm","id":2,"clk":"ANyBAwC1tgIAqtUC","pt":1743512185629,"mc":[{"id":"1.241629436","rc":[{"atb":[[11,84.46]],"batb":[[0,11,84.46]],"id":40389088},{"atl":[[5.2,176.02],[5.6,53.33]],"batl":[[0,5.2,176.02]],"id":56297029}]}]}
{"op":"mcm","id":2,"clk":"AOuBAwC8tgIAsNUC","pt":1743512185728,"mc":[{"id":"1.241629436","rc":[{"atb":[[4.1,148.58]],"atl":[[4.7,63.43]],"batb":[],"batl":[[0,4.7,63.43]],"id":270592},{"atl":[[18,37.25]],"batl":[[1,18,37.25]],"id":58186642}]}]}
{"op":"mcm","id":2,"clk":"APmBAwC/tgIAs9UC","pt":1743512185824,"mc":[{"id":"1.241629436","rc":[{"atl":[[4.7,2]],"batl":[[0,4.7,2]],"id":270592}]}]}
{"op":"mcm","id":2,"clk":"AIOCAwDHtgIAutUC","pt":1743512185882,"mc":[{"id":"1.241629436","rc":[{"atb":[[11,79.63]],"batb":[[0,11,79.63]],"id":40389088},{"atl":[[18,40.48]],"batl":[[1,18,40.48]],"id":58186642}]}]}
{"op":"mcm","id":2,"clk":"AI2CAwDOtgIAwdUC","pt":1743512185982,"mc":[{"id":"1.241629436","rc":[{"atb":[[4.7,33]],"atl":[[4.7,0]],"trd":[[4.7,3382.86]],"batb":[[2,4.5,247.68],[1,4.6,336.72],[0,4.7,33]],"batl":[[2,5,310.73],[1,4.9,297.6],[0,4.8,238.91]],"tv":23463.3,"id":270592}],"tv":92476.64}]}
{"op":"mcm","id":2,"clk":"AJaCAwDXtgIAxtUC","pt":1743512186094,"mc":[{"id":"1.241629436","rc":[{"atb":[[4.7,94.17],[4.6,333.63]],"atl":[[4.8,213.91]],"trd":[[4.8,3655.51]],"batb":[[1,4.6,333.63],[0,4.7,94.17]],"batl":[[0,4.8,213.91]],"ltp":4.8,"tv":23513.3,"id":270592},{"atl":[[5.2,178.36]],"batl":[[0,5.2,178.36]],"id":56297029}],"tv":92526.64}]}
{"op":"mcm","id":2,"clk":"AKCCAwDjtgIAz9UC","pt":1743512186195,"mc":[{"id":"1.241629436","rc":[{"atb":[[4.3,149.17]],"atl":[[5,309.8]],"batb":[],"batl":[[2,5,309.8]],"id":270592}]}]}
{"op":"mcm","id":2,"clk":"AKiCAwDstgIA2dUC","pt":1743512186299,"mc":[{"id":"1.241629436","rc":[{"atb":[[4.4,217.68]],"atl":[[5.1,139.75]],"batb":[],"batl":[],"id":270592}]}]}
{"op":"mcm","id":2,"clk":"AK+CAwD3tgIA4NUC","pt":1743512186399,"mc":[{"id":"1.241629436","rc":[{"atb":[[3.85,116.62]],"id":270592},{"atb":[[5.1,458.66]],"atl":[[5.2,273.22]],"trd":[[5.1,5038.92]],"batb":[[0,5.1,458.66]],"batl":[[0,5.2,273.22]],"tv":14356.02,"id":56297029},{"atb":[[11,124.79]],"trd":[[11,1744.65]],"batb":[[0,11,124.79]],"tv":5319.87,"id":44049799}],"tv":92566.64}]}
{"op":"mcm","id":2,"clk":"ALmCAwD9tgIA5tUC","pt":1743512186505,"mc":[{"id":"1.241629436","rc":[{"atb":[[4.7,100.21]],"batb":[[0,4.7,100.21]],"id":270592}]}]}
{"op":"mcm","id":2,"clk":"AM6CAwCJtwIA9tUC","pt":1743512186702,"mc":[{"id":"1.241629436","rc":[{"atb":[[4.6,374.5]],"batb":[[1,4.6,374.5]],"id":270592},{"atb":[[5.2,89.76]],"id":26496185}]}]}
{"op":"mcm","id":2,"clk":"ANaCAwCQtwIAgNYC","pt":1743512186803,"mc":[{"id":"1.241629436","rc":[{"atb":[[5.1,485.48]],"batb":[[0,5.1,485.48]],"id":56297029}]}]}
{"op":"mcm","id":2,"clk":"ANyCAwCUtwIAhtYC","pt":1743512186905,"mc":[{"id":"1.241629436","rc":[{"atb":[[4.5,259.53]],"batb":[[2,4.5,259.53]],"id":270592},{"atl":[[5.5,78.39]],"batl":[],"id":56297029}]}]}
{"op":"mcm","id":2,"clk":"AOmCAwCbtwIAkNYC","pt":1743512187014,"mc":[{"id":"1.241629436","rc":[{"atb":[[8.4,57.21]],"batb":[],"id":35856222}]}]}
{"op":"mcm","id":2,"clk":"AO6CAwCitwIAndYC","pt":1743512187113,"mc":[{"id":"1.241629436","rc":[{"atl":[[4.8,211.91]],"batl":[[0,4.8,211.91]],"id":270592}]}]}
{"op":"mcm","id":2,"clk":"AIaDAwC8twIAvdYC","pt":1743512187420,"mc":[{"id":"1.241629436","rc":[{"atb":[[7,11.9]],"id":40389088},{"atb":[[9.6,71.07]],"batb":[[0,9.6,71.07]],"id":35856222},{"atb":[[10,50.63]],"id":58186642},{"atb":[[6.6,228.3],[6.8,105.18]],"atl":[[1000,4.64],[7,102.5],[7.2,192.17]],"batb":[[1,6.6,228.3],[0,6.8,105.18]],"batl":[[1,7.2,192.17],[0,7,102.5]],"id":26496185}]}]}
{"op":"mcm","id":2,"clk":"AJWDAwDMtwIAz9YC","pt":1743512187634,"mc":[{"id":"1.241629436","rc":[{"atl":[[18,28.67],[17.5,0]],"trd":[[18,329.05],[17.5,424.52]],"batl":[[2,19,12.87],[1,18.5,25.94],[0,18,28.67]],"ltp":18,"tv":6593.11,"id":58186642},{"atb":[[2,51.51]],"atl":[[1000,3.9]],"id":26496185}],"tv":92608.64}]}
{"op":"mcm","id":2,"clk":"AJ+DAwDatwIA2tYC","pt":1743512187733,"mc":[{"id":"1.241629436","rc":[{"atl":[[11.5,3.1]],"batl":[[2,12.5,68.15],[1,12,71.47],[0,11.5,3.1]],"id":40389088},{"atb":[[46,8.91]],"batb":[[2,46,8.91]],"id":59626646},{"atb":[[17.5,8.76]],"batb":[[2,16.5,32.4],[1,17,13.17],[0,17.5,8.76]],"id":58186642},{"atl":[[7,103.24]],"batl":[[0,7,103.24]],"id":26496185}]}]}
{"op":"mcm","id":2,"clk":"AKWDAwDdtwIA3NYC","pt":1743512187829,"mc":[{"id":"1.241629436","rc":[{"atl":[[11.5,6.21]],"batl":[[0,11.5,6.21]],"id":40389088},{"atb":[[4.5,247.68]],"batb":[[2,4.5,247.68]],"id":270592},{"atb":[[17,35.47],[17.5,21.95]],"atl":[[18,23.13]],"batb":[[1,17,35.47],[0,17.5,21.95]],"batl":[[0,18,23.13]],"id":58186642}]}]}
{"op":"mcm","id":2,"clk":"ALCDAwDqtwIA7tYC","pt":1743512187992,"mc":[{"id":"1.241629436","rc":[{"atl":[[12.5,68.03]],"batl":[[2,12.5,68.03]],"id":40389088},{"atb":[[5.1,483.84]],"batb":[[0,5.1,483.84]],"id":56297029},{"atb":[[17.5,28.34]],"atl":[[18,11.45]],"batb":[[0,17.5,28.34]],"batl":[[0,18,11.45]],"id":58186642}]}]}
{"op":"mcm","id":2,"clk":"ALiDAwDstwIA89YC","pt":1743512188092,"mc":[{"id":"1.241629436","rc":[{"atl":[[1000,6.49],[5.6,103.33]],"batl":[],"id":56297029},{"atl":[[19,16.01],[18.5,22.78]],"batl":[[2,19,16.01],[1,18.5,22.78]],"id":58186642},{"atl":[[1000,4.87]],"id":26496185},{"atl":[[1000,20.35]],"id":44049799}]}]}
{"op":"mcm","id":2,"clk":"AMmDAwD7twIAgtcC","pt":1743512188298,"mc":[{"id":"1.241629436","rc":[{"atb":[[4.7,0],[4.6,324.71]],"trd":[[4.7,3517.28],[4.6,640.61]],"batb":[[2,4.4,217.68],[1,4.5,247.68],[0,4.6,324.71]],"ltp":4.6,"tv":23747.3,"id":270592},{"atb":[[6.8,105.06]],"trd":[[6.8,1600.16]],"batb":[[0,6.8,105.06]],"tv":15472.83,"id":26496185}],"tv":92842.89}]}
{"op":"mcm","id":2,"clk":"ANODAwD/twIAjtcC","pt":1743512188406,"mc":[{"id":"1.241629436","rc":[{"atb":[[4.4,216.52]],"batb":[[2,4.4,216.52]],"id":270592},{"atb":[[18,11.82]],"atl":[[18,0]],"trd":[[18,351.95]],"batb":[[2,17,35.47],[1,17.5,28.34],[0,18,11.82]],"batl":[[2,19.5,13.74],[1,19,16.01],[0,18.5,22.78]],"tv":6616.01,"id":58186642}],"tv":92865.79}]}
{"op":"mcm","id":2,"clk":"AN+DAwCEuAIAkdcC","pt":1743512188506,"mc":[{"id":"1.241629436","rc":[{"atb":[[4.5,244.43]],"atl":[[4.7,60.7]],"batb":[[1,4.5,244.43]],"batl":[[2,4.9,297.6],[1,4.8,211.91],[0,4.7,60.7]],"id":270592},{"atb":[[17.5,17.41]],"atl":[[18.5,20.51]],"batb":[[1,17.5,17.41]],"batl":[[0,18.5,20.51]],"id":58186642}]}]}
{"op":"mcm","id":2,"clk":"AOeDAwCJuAIAmNcC","pt":1743512188605,"mc":[{"id":"1.241629436","rc":[{"atb":[[4.3,150.36],[4.5,247.68]],"atl":[[4.7,72.74]],"batb":[[1,4.5,247.68]],"batl":[[0,4.7,72.74]],"id":270592},{"atl":[[5.5,67.47]],"batl":[],"id":56297029},{"atb":[[18,18.25],[17,32.96]],"batb":[[2,17,32.96],[0,18,18.25]],"id":58186642},{"atl":[[7.2,175.37]],"batl":[[1,7.2,175.37]],"id":26496185}]}]}
{"op":"mcm","id":2,"clk":"AOyDAwCNuAIAoNcC","pt":1743512188699,"mc":[{"id":"1.241629436","rc":[{"atb":[[4.6,327.8]],"batb":[[0,4.6,327.8]],"id":270592},{"atb":[[10,129.41]],"batb":[[0,10,129.41]],"id":27115873},{"atl":[[18.5,17.47]],"batl":[[0,18.5,17.47]],"id":58186642}]}]}
{"op":"mcm","id":2,"clk":"APWDAwCUuAIAqdcC","pt":1743512188806,"mc":[{"id":"1.241629436","rc":[{"atb":[[4.6,333.97]],"atl":[[5.1,138.85]],"batb":[[0,4.6,333.97]],"batl":[],"id":270592},{"atb":[[9.6,73.69]],"batb":[[0,9.6,73.69]],"id":35856222},{"atb":[[1.8,5]],"id":59626646},{"atb":[[18,21.39],[17,35.53]],"batb":[[2,17,35.53],[0,18,21.39]],"id":58186642},{"atb":[[6.8,113.13]],"batb":[[0,6.8,113.13]],"id":26496185}]}]}
{"op":"mcm","id":2,"clk":"APqDAwCcuAIAsdcC","pt":1743512188905,"mc":[{"id":"1.241629436","rc":[{"atl":[[5.5,78.39]],"batl":[],"id":56297029}]}]}
{"op":"mcm","id":2,"clk":"AISEAwCguAIAs9cC","pt":1743512189006,"mc":[{"id":"1.241629436","rc":[{"atl":[[5,310.73]],"batl":[],"id":270592}]}]}
{"op":"mcm","id":2,"clk":"AImEAwCiuAIAvdcC","pt":1743512189109,"mc":[{"id":"1.241629436","rc":[{"atb":[[1.8,4.09]],"id":59626646}]}]}
{"op":"mcm","id":2,"clk":"AJaEAwCnuAIAxdcC","pt":1743512189216,"mc":[{"id":"1.241629436","rc":[{"atb":[[1.03,288.24]],"id":40389088},{"atb":[[1.03,288.24]],"id":270592},{"atb":[[1.03,238.24]],"id":35856222},{"atb":[[1.03,238.24]],"id":59626646},{"atb":[[1.03,288.24]],"atl":[[5.2,270.88]],"batl":[[0,5.2,270.88]],"id":56297029},{"atb":[[1.03,243.73]],"id":27115873},{"atb":[[1.03,243.73]],"id":58186642},{"atb":[[1.03,393.73]],"id":26496185},{"atb":[[1.03,238.24]],"id":44049799}]}]}
{"op":"mcm","id":2,"clk":"AJ6EAwCwuAIA0tcC","pt":1743512189323,"mc":[{"id":"1.241629436","rc":[{"atb":[[1.03,287.54]],"id":40389088},{"atb":[[1.03,287.54]],"id":270592},{"atb":[[1.03,237.54]],"id":35856222},{"atb":[[1.03,237.54],[1.8,4]],"id":59626646},{"atb":[[1.03,287.54]],"id":56297029},{"atb":[[1.03,243.03]],"id":27115873},{"atb":[[1.03,243.03]],"id":58186642},{"atb":[[1.03,393.03]],"id":26496185},{"atb":[[1.03,237.54]],"id":44049799}]}]}
{"op":"mcm","id":2,"clk":"AKiEAwC1uAIA2dcC","pt":1743512189420,"mc":[{"id":"1.241629436","rc":[{"atb":[[1.03,287.24]],"id":40389088},{"atb":[[1.03,287.24]],"id":270592},{"atb":[[1.03,237.24]],"id":35856222},{"atb":[[50,11.31],[1.03,237.24]],"batb":[[0,50,11.31]],"id":59626646},{"atb":[[1.03,287.24]],"id":56297029},{"atb":[[1.03,242.73]],"id":27115873},{"atb":[[1.03,242.73]],"id":58186642},{"atb":[[1.03,392.73]],"id":26496185},{"atb":[[1.03,237.24]],"atl":[[11.5,86.54]],"batl":[[0,11.5,86.54]],"id":44049799}]}]}
{"op":"mcm","id":2,"clk":"ALCEAwC9uAIA6NcC","pt":1743512189532,"mc":[{"id":"1.241629436","rc":[{"atb":[[11,80.47],[1.55,2.18]],"batb":[[0,11,80.47]],"id":40389088},{"atb":[[1.55,2.44]],"id":270592},{"atb":[[1.55,0.44]],"id":35856222},{"atb":[[1.55,0.44]],"id":59626646},{"atb":[[1.55,0.44]],"id":56297029},{"atb":[[1.55,0.44]],"id":27115873},{"atb":[[1.55,0.44]],"id":58186642},{"atb":[[1.55,0.44]],"id":26496185},{"atb":[[1.55,0.44]],"id":44049799}]}]}
{"op":"mcm","id":2,"clk":"AL6EAwDEuAIA8tcC","pt":1743512189630,"mc":[{"id":"1.241629436","rc":[{"atl":[[44,2.25]],"id":35856222},{"atl":[[44,2.22]],"id":58186642}]}]}
{"op":"mcm","id":2,"clk":"AMuEAwDRuAIAg9gC","pt":1743512189693,"mc":[{"id":"1.241629436","rc":[{"atl":[[4.8,262.43]],"batl":[[1,4.8,262.43]],"id":270592}]}]}
{"op":"mcm","id":2,"clk":"ANWEAwDbuAIAjdgC","pt":1743512189804,"mc":[{"id":"1.241629436","rc":[{"atb":[[4.6,363.53]],"batb":[[0,4.6,363.53]],"id":270592},{"atb":[[17.5,25.41]],"batb":[[1,17.5,25.41]],"id":58186642}]}]}
{"op":"mcm","id":2,"clk":"AOKEAwDmuAIAmNgC","pt":1743512189908,"mc":[{"id":"1.241629436","rc":[{"atl":[[12.5,74.01],[11.5,3.18]],"trd":[[11.5,1776.9]],"batl":[[2,12.5,74.01],[0,11.5,3.18]],"ltp":11.5,"tv":7226.27,"id":40389088},{"atl":[[10,100.07]],"trd":[[10,879.96]],"batl":[[0,10,100.07]],"tv":10404.53,"id":35856222},{"atl":[[6.6,33.97]],"id":56297029},{"atb":[[18,15.57]],"trd":[[18,363.59]],"batb":[[0,18,15.57]],"tv":6627.65,"id":58186642}],"tv":92895.13}]}
{"op":"mcm","id":2,"clk":"AOyEAwDsuAIAn9gC","pt":1743512190006,"mc":[{"id":"1.241629436","rc":[{"atl":[[11.5,0]],"batl":[[2,13,23.87],[1,12.5,74.01],[0,12,71.47]],"id":40389088},{"atl":[[4.7,70.74]],"trd":[[4.7,3521.28]],"batl":[[0,4.7,70.74]],"ltp":4.7,"tv":23751.3,"id":270592},{"atl":[[9.8,10]],"batl":[[2,10.5,70.7],[1,10,100.07],[0,9.8,10]],"id":35856222}],"tv":92899.13}]}
{"op":"mcm","id":2,"clk":"APWEAwDvuAIAptgC","pt":1743512190100,"mc":[{"id":"1.241629436","rc":[{"atl":[[5.5,67.47]],"batl":[],"id":56297029},{"atb":[[18,12.43],[16.5,36.12]],"batb":[[0,18,12.43]],"id":58186642},{"atl":[[12.5,37.8]],"batl":[[2,12.5,37.8]],"id":44049799}]}]}
{"op":"mcm","id":2,"clk":"APuEAwD4uAIAw9gC","pt":1743512190206,"mc":[{"id":"1.241629436","rc":[{"atl":[[9.8,28.88]],"batl":[[0,9.8,28.88]],"id":35856222},{"atl":[[14.5,12.72]],"batl":[],"id":44049799}]}]}
{"op":"mcm","id":2,"clk":"AIOFAwCCuQIAxdgC","pt":1743512190305,"mc":[{"id":"1.241629436","rc":[{"atl":[[12.5,68.03]],"batl":[[1,12.5,68.03]],"id":40389088}]}]}
{"op":"mcm","id":2,"clk":"AJGFAwCPuQIA0NgC","pt":1743512190508,"mc":[{"id":"1.241629436","rc":[{"atl":[[15.5,10.04]],"batl":[],"id":40389088},{"atl":[[4.7,57.85]],"trd":[[4.7,3547.06]],"batl":[[0,4.7,57.85]],"tv":23777.08,"id":270592},{"atl":[[5.2,273.6]],"batl":[[0,5.2,273.6]],"id":56297029},{"atl":[[1000,2.81]],"id":58186642}],"tv":92924.91}]}
{"op":"mcm","id":2,"clk":"AJiFAwCWuQIA2NgC","pt":1743512190613,"mc":[{"id":"1.241629436","rc":[{"atl":[[4.7,12.04]],"batl":[[0,4.7,12.04]],"id":270592},{"atl":[[1000,3.81]],"id":58186642}]}]}
{"op":"mcm","id":2,"clk":"AJ+FAwCeuQIA3NgC","pt":1743512190715,"mc":[{"id":"1.241629436","rc":[{"atl":[[4.7,0]],"batl":[[2,5,310.73],[1,4.9,297.6],[0,4.8,262.43]],"id":270592},{"atb":[[18,6.43]],"atl":[[1000,2.85]],"batb":[[0,18,6.43]],"id":58186642}]}]}
{"op":"mcm","id":2,"clk":"AKeFAwCjuQIA4tgC","pt":1743512190817,"mc":[{"id":"1.241629436","rc":[{"atb":[[4.6,360.44],[4.5,244.43]],"batb":[[1,4.5,244.43],[0,4.6,360.44]],"id":270592},{"atb":[[9.4,31.71]],"batb":[[1,9.4,31.71]],"id":35856222},{"atl":[[14.5,9.69]],"batl":[],"id":27115873},{"atb":[[18,3.35]],"batb":[[0,18,3.35]],"id":58186642},{"atb":[[11,123.54]],"trd":[[11,1747.15]],"batb":[[0,11,123.54]],"tv":5322.37,"id":44049799}],"tv":92927.41}]}
{"op":"mcm","id":2,"clk":"ALGFAwCuuQIA59gC","pt":1743512190927,"mc":[{"id":"1.241629436","rc":[{"atl":[[5,309.8]],"batl":[[2,5,309.8]],"id":270592},{"atl":[[1000,2.81],[18.5,20.58]],"batl":[[0,18.5,20.58]],"id":58186642}]}]}
{"op":"mcm","id":2,"clk":"ALmFAwCyuQIA69gC","pt":1743512191026,"mc":[{"id":"1.241629436","rc":[{"atl":[[5.1,139.78],[4.8,260.43]],"trd":[[4.8,3659.51]],"batl":[[0,4.8,260.43]],"ltp":4.8,"tv":23781.08,"id":270592},{"atb":[[18,3.3]],"trd":[[18,363.67]],"batb":[[0,18,3.3]],"tv":6627.73,"id":58186642}],"tv":92931.49}]}
{"op":"mcm","id":2,"clk":"AM+FAwDAuQIA+tgC","pt":1743512191238,"mc":[{"id":"1.241629436","rc":[{"atl":[[9.8,27.88]],"trd":[[9.8,1303.12]],"batl":[[0,9.8,27.88]],"ltp":9.8,"tv":10406.53,"id":35856222},{"atb":[[18,0]],"atl":[[18,1.24]],"trd":[[18,370.27]],"batb":[[2,16.5,36.12],[1,17,35.53],[0,17.5,25.41]],"batl":[[2,19,16.01],[1,18.5,20.58],[0,18,1.24]],"tv":6634.33,"id":58186642}],"tv":92940.09}]}
{"op":"mcm","id":2,"clk":"ANeFAwDFuQIA/dgC","pt":1743512191334,"mc":[{"id":"1.241629436","rc":[{"atl":[[18,11.12]],"trd":[[18,372.75]],"batl":[[0,18,11.12]],"tv":6636.81,"id":58186642}],"tv":92942.57}]}
{"op":"mcm","id":2,"clk":"ANyFAwDKuQIAgtkC","pt":1743512191435,"mc":[{"id":"1.241629436","rc":[{"atl":[[4.8,258.43]],"trd":[[4.8,3663.51]],"batl":[[0,4.8,258.43]],"tv":23785.08,"id":270592},{"atl":[[9.8,33.66]],"batl":[[0,9.8,33.66]],"id":35856222},{"atb":[[17.5,31.87]],"batb":[[0,17.5,31.87]],"id":58186642}],"tv":92946.57}]}
{"op":"mcm","id":2,"clk":"AOWFAwDSuQIAiNkC","pt":1743512191496,"mc":[{"id":"1.241629436","rc":[{"atb":[[9.4,37.48]],"batb":[[1,9.4,37.48]],"id":35856222}]}]}
{"op":"mcm","id":2,"clk":"AO6FAwDcuQIAjNkC","pt":1743512191603,"mc":[{"id":"1.241629436","rc":[{"atb":[[4.7,40]],"batb":[[2,4.5,244.43],[1,4.6,360.44],[0,4.7,40]],"id":270592},{"atl":[[9.8,27.88]],"batl":[[0,9.8,27.88]],"id":35856222}]}]}
{"op":"mcm","id":2,"clk":"APWFAwDluQIAk9kC","pt":1743512191700,"mc":[{"id":"1.241629436","rc":[{"atb":[[4.7,97.16]],"atl":[[4.8,207.91]],"batb":[[0,4.7,97.16]],"batl":[[0,4.8,207.91]],"id":270592},{"atb":[[9.4,31.71]],"batb":[[1,9.4,31.71]],"id":35856222},{"atl":[[18,0]],"batl":[[2,19.5,13.74],[1,19,16.01],[0,18.5,20.58]],"id":58186642},{"atb":[[6.8,93.13]],"trd":[[6.8,1640.16]],"batb":[[0,6.8,93.13]],"tv":15512.83,"id":26496185}],"tv":92986.57}]}
{"op":"mcm","id":2,"clk":"AP2FAwDtuQIAmNkC","pt":1743512191800,"mc":[{"id":"1.241629436","rc":[{"atb":[[4.7,158.23],[4.3,149.17],[4.5,247.68]],"batb":[[2,4.5,247.68],[0,4.7,158.23]],"id":270592},{"atb":[[9.4,37.48],[9.2,49.03],[9.6,59.69]],"batb":[[2,9.2,49.03],[1,9.4,37.48],[0,9.6,59.69]],"id":35856222},{"atl":[[5.4,79.87],[5.2,275.94]],"batl":[[2,5.4,79.87],[0,5.2,275.94]],"id":56297029},{"atl":[[11,68.08]],"batl":[[1,11,68.08]],"id":27115873},{"atb":[[6.8,113.45]],"batb":[[0,6.8,113.45]],"id":26496185}]}]}
{"op":"mcm","id":2,"clk":"AIWGAwD3uQIAodkC","pt":1743512191911,"mc":[{"id":"1.241629436","rc":[{"atb":[[4.4,217.68],[4.5,259.56]],"batb":[[2,4.5,259.56]],"id":270592},{"atl":[[9.8,32.67]],"trd":[[9.8,1305.12]],"batl":[[0,9.8,32.67]],"tv":10408.53,"id":35856222}],"tv":92988.57}]}
{"op":"mcm","id":2,"clk":"AIyGAwD9uQIAp9kC","pt":1743512192011,"mc":[{"id":"1.241629436","rc":[{"atb":[[4.7,103.23],[4.6,350.72]],"batb":[[1,4.6,350.72],[0,4.7,103.23]],"id":270592}]}]}
{"op":"mcm","id":2,"clk":"AJaGAwCBugIArtkC","pt":1743512192112,"mc":[{"id":"1.241629436","rc":[{"atb":[[3,104.53],[4.5,247.68]],"batb":[[2,4.5,247.68]],"id":270592}]}]}
{"op":"mcm","id":2,"clk":"AJ+GAwCJugIAu9kC","pt":1743512192218,"mc":[{"id":"1.241629436","rc":[{"atl":[[10.5,79.18]],"batl":[[2,10.5,79.18]],"id":35856222}]}]}
{"op":"mcm","id":2,"clk":"ALmGAwCougIA29kC","pt":1743512192627,"mc":[{"id":"1.241629436","rc":[{"atb":[[6.6,218.3]],"batb":[[1,6.6,218.3]],"id":26496185}]}]}
{"op":"mcm","id":2,"clk":"ANGGAwC3ugIA8dkC","pt":1743512192934,"mc":[{"id":"1.241629436","rc":[{"atl":[[11.5,27.68]],"batl":[[2,11.5,27.68]],"id":27115873},{"atl":[[11.5,83.54]],"trd":[[11.5,1092.73]],"batl":[[0,11.5,83.54]],"ltp":11.5,"tv":5328.37,"id":44049799}],"tv":92994.57}]}
{"op":"mcm","id":2,"clk":"APWGAwDIugIAmNoC","pt":1743512193306,"mc":[{"id":"1.241629436","rc":[{"atb":[[4.5,255.93]],"batb":[[2,4.5,255.93]],"id":270592},{"atl":[[5.8,107.59]],"batl":[],"id":56297029}]}]}
{"op":"mcm","id":2,"clk":"AP6GAwDOugIAn9oC","pt":1743512193406,"mc":[{"id":"1.241629436","rc":[{"atl":[[12,71.36]],"batl":[[0,12,71.36]],"id":40389088},{"atl":[[1000,0.69],[10.5,79.01]],"batl":[[2,10.5,79.01]],"id":35856222},{"atb":[[5,1129.7],[5.1,468.56]],"atl":[[5.2,273.22]],"trd":[[5.1,5067.5]],"batb":[[1,5,1129.7],[0,5.1,468.56]],"batl":[[0,5.2,273.22]],"tv":14384.6,"id":56297029},{"atl":[[90,1]],"id":27115873},{"atl":[[7,102.5]],"batl":[[0,7,102.5]],"id":26496185}],"tv":93023.15}]}
{"op":"mcm","id":2,"clk":"AIaHAwDRugIAp9oC","pt":1743512193506,"mc":[{"id":"1.241629436","rc":[{"atb":[[4.5,247.68]],"batb":[[2,4.5,247.68]],"id":270592},{"atl":[[1000,0.41]],"id":35856222},{"atl":[[19,12.87]],"batl":[[1,19,12.87]],"id":58186642}]}]}
{"op":"mcm","id":2,"clk":"AIyHAwDXugIAstoC","pt":1743512193611,"mc":[{"id":"1.241629436","rc":[{"atl":[[10,100.35]],"batl":[[1,10,100.35]],"id":35856222}]}]}
{"op":"mcm","id":2,"clk":"AJWHAwDbugIAvNoC","pt":1743512193715,"mc":[{"id":"1.241629436","rc":[{"atl":[[5,314.8]],"batl":[[2,5,314.8]],"id":270592}]}]}
{"op":"mcm","id":2,"clk":"ALSHAwDxugIA1doC","pt":1743512194119,"mc":[{"id":"1.241629436","rc":[{"atl":[[25,6.08]],"id":40389088}]}]}
{"op":"mcm","id":2,"clk":"AMGHAwD0ugIA2doC","pt":1743512194227,"mc":[{"id":"1.241629436","rc":[{"atb":[[2,50.51]],"id":26496185}]}]}
{"op":"mcm","id":2,"clk":"AM2HAwD6ugIA49oC","pt":1743512194331,"mc":[{"id":"1.241629436","rc":[{"atl":[[11.5,83.62]],"batl":[[0,11.5,83.62]],"id":44049799}]}]}
{"op":"mcm","id":2,"clk":"ANSHAwD/ugIA59oC","pt":1743512194427,"mc":[{"id":"1.241629436","rc":[{"atl":[[1000,0.36]],"id":40389088},{"atb":[[5.1,467.54]],"batb":[[0,5.1,467.54]],"id":56297029}]}]}
{"op":"mcm","id":2,"clk":"AN2HAwCJuwIA7doC","pt":1743512194531,"mc":[{"id":"1.241629436","rc":[{"atl":[[1000,0.25]],"id":40389088}]}]}
{"op":"mcm","id":2,"clk":"AOqHAwCTuwIA9doC","pt":1743512194634,"mc":[{"id":"1.241629436","rc":[{"atb":[[8.6,35.6]],"atl":[[12.5,68.14]],"batb":[],"batl":[[1,12.5,68.14]],"id":40389088},{"atl":[[55,0.6]],"trd":[[55,391.4]],"batl":[[2,70,7.17],[1,65,5.05],[0,60,3.14]],"ltp":55,"tv":2175.35,"id":59626646}],"tv":93028}]}
{"op":"mcm","id":2,"clk":"APKHAwCduwIAg9sC","pt":1743512194738,"mc":[{"id":"1.241629436","rc":[{"atl":[[4.9,302.6]],"batl":[[1,4.9,302.6]],"id":270592},{"atl":[[55,0]],"trd":[[55,392.6]],"batl":[[0,60,2.54]],"tv":2176.55,"id":59626646},{"atl":[[6,62.39]],"batl":[],"id":56297029},{"atl":[[19,16]],"batl":[[1,19,16]],"id":58186642}],"tv":93029.2}]}
{"op":"mcm","id":2,"clk":"APiHAwCruwIAkNsC","pt":1743512194848,"mc":[{"id":"1.241629436","rc":[{"atb":[[50,13.97]],"atl":[[55,0.64]],"batb":[[0,50,13.97]],"batl":[[0,60,3.18]],"id":59626646}]}]}
{"op":"mcm","id":2,"clk":"AIOIAwCwuwIAnNsC","pt":1743512194910,"mc":[{"id":"1.241629436","rc":[{"atl":[[60,4.09],[65,3.61]],"batl":[[1,65,3.61],[0,60,4.73]],"id":59626646}]}]}
{"op":"mcm","id":2,"clk":"AJuIAwDQuwIAstsC","pt":1743512195214,"mc":[{"id":"1.241629436","rc":[{"atl":[[400,0.04]],"id":270592}]}]}
{"op":"mcm","id":2,"clk":"AKGIAwDauwIAuNsC","pt":1743512195322,"mc":[{"id":"1.241629436","rc":[{"atb":[[4.4,215.68]],"batb":[],"id":270592},{"atl":[[10.5,107.96]],"trd":[[10.5,685.85]],"batl":[[0,10.5,107.96]],"ltp":10.5,"tv":7573.1,"id":27115873}],"tv":93032.14}]}
{"op":"mcm","id":2,"clk":"AKiIAwDjuwIAvdsC","pt":1743512195416,"mc":[{"id":"1.241629436","rc":[{"atb":[[8.4,50.63]],"atl":[[26,9.04]],"id":40389088},{"atl":[[400,0.05],[4.8,212.91]],"batl":[[0,4.8,212.91]],"id":270592}]}]}
{"op":"mcm","id":2,"clk":"AK6IAwDsuwIAx9sC","pt":1743512195521,"mc":[{"id":"1.241629436","rc":[{"atl":[[6.6,9],[6.2,115.57],[4.8,217.91]],"batl":[[0,4.8,217.91]],"id":270592}]}]}
{"op":"mcm","id":2,"clk":"ALKIAwD2uwIAzdsC","pt":1743512195616,"mc":[{"id":"1.241629436","rc":[{"atl":[[5.7,109.55]],"batl":[],"id":270592}]}]}
{"op":"mcm","id":2,"clk":"AMSIAwCLvAIA19sC","pt":1743512195830,"mc":[{"id":"1.241629436","rc":[{"atb":[[11.5,10]],"batb":[[2,10.5,54.78],[1,11,80.47],[0,11.5,10]],"id":40389088}]}]}
{"op":"mcm","id":2,"clk":"ANCIAwCSvAIA3tsC","pt":1743512195926,"mc":[{"id":"1.241629436","rc":[{"atb":[[11,85.34]],"atl":[[14.5,16.11],[14,23.16]],"batb":[[1,11,85.34]],"batl":[],"id":40389088},{"atb":[[9.6,55.26]],"trd":[[9.6,645.38]],"batb":[[0,9.6,55.26]],"ltp":9.6,"tv":10410.53,"id":35856222},{"atb":[[50,14.61]],"atl":[[60,2.54]],"batb":[[0,50,14.61]],"batl":[[0,60,3.18]],"id":59626646},{"atl":[[13,11.76]],"batl":[],"id":27115873},{"atl":[[18,1],[18.5,26.11]],"batl":[[2,19,16],[1,18.5,26.11],[0,18,1]],"id":58186642}],"tv":93034.14}]}
{"op":"mcm","id":2,"clk":"ANaIAwCfvAIA39sC","pt":1743512196026,"mc":[{"id":"1.241629436","rc":[{"atb":[[11,80.47]],"batb":[[1,11,80.47]],"id":40389088},{"atb":[[9.6,51.82]],"batb":[[0,9.6,51.82]],"id":35856222},{"atl":[[19,12.87]],"batl":[[2,19,12.87]],"id":58186642}]}]}
{"op":"mcm","id":2,"clk":"AN+IAwCqvAIA5tsC","pt":1743512196137,"mc":[{"id":"1.241629436","rc":[{"atb":[[5.1,570.54]],"batb":[[0,5.1,570.54]],"id":56297029},{"atb":[[17.5,23.87]],"batb":[[0,17.5,23.87]],"id":58186642}]}]}
{"op":"mcm","id":2,"clk":"AOiIAwCzvAIA69sC","pt":1743512196242,"mc":[{"id":"1.241629436","rc":[{"atl":[[12,64.67]],"batl":[[0,12,64.67]],"id":40389088},{"atb":[[9.6,47.42]],"batb":[[0,9.6,47.42]],"id":35856222},{"atl":[[400,0.03]],"id":56297029}]}]}
{"op":"mcm","id":2,"clk":"AO2IAwC2vAIA89sC","pt":1743512196336,"mc":[{"id":"1.241629436","rc":[{"atb":[[4.9,70.59]],"batb":[[2,4.9,70.59]],"id":56297029},{"atl":[[19,16]],"batl":[[2,19,16]],"id":58186642}]}]}
{"op":"mcm","id":2,"clk":"APWIAwC9vAIA+9sC","pt":1743512196438,"mc":[{"id":"1.241629436","rc":[{"atb":[[11,85.34]],"batb":[[1,11,85.34]],"id":40389088},{"atb":[[4.7,106.17]],"batb":[[0,4.7,106.17]],"id":270592},{"atl":[[400,0.05]],"id":56297029}]}]}
{"op":"mcm","id":2,"clk":"AICJAwDAvAIAgtwC","pt":1743512196540,"mc":[{"id":"1.241629436","rc":[{"atl":[[4.8,257.91]],"batl":[[0,4.8,257.91]],"id":270592}]}]}
{"op":"mcm","id":2,"clk":"AIeJAwDFvAIAjNwC","pt":1743512196644,"mc":[{"id":"1.241629436","rc":[{"atb":[[6.8,165.35]],"batb":[[0,6.8,165.35]],"id":26496185}]}]}
{"op":"mcm","id":2,"clk":"AJqJAwDTvAIAl9wC","pt":1743512196801,"mc":[{"id":"1.241629436","rc":[{"atb":[[11.5,0]],"atl":[[11.5,0.97]],"trd":[[11.5,1796.9]],"batb":[[2,10,76.37],[1,10.5,54.78],[0,11,85.34]],"batl":[[0,12,65.64]],"tv":7246.27,"id":40389088},{"atl":[[5.2,274.13]],"batl":[[0,5.2,274.13]],"id":56297029},{"atl":[[10.5,121.27]],"batl":[[0,10.5,121.27]],"id":27115873},{"atb":[[6.8,185.2]],"atl":[[7,102.54]],"batb":[[0,6.8,185.2]],"batl":[[0,7,102.54]],"id":26496185},{"atl":[[11.5,87.52]],"batl":[[0,11.5,87.52]],"id":44049799}],"tv":93054.14}]}
{"op":"mcm","id":2,"clk":"AKKJAwDZvAIAmdwC","pt":1743512196905,"mc":[{"id":"1.241629436","rc":[{"atb":[[11,80.47]],"batb":[[0,11,80.47]],"id":40389088},{"atb":[[9.6,37.42]],"trd":[[9.6,665.38]],"batb":[[0,9.6,37.42]],"tv":10430.53,"id":35856222},{"atl":[[19,12.87]],"batl":[[2,19,12.87]],"id":58186642}],"tv":93074.14}]}
{"op":"mcm","id":2,"clk":"AKmJAwDevAIAndwC","pt":1743512197008,"mc":[{"id":"1.241629436","rc":[{"atl":[[14.5,14.78],[14,21.73]],"batl":[],"id":40389088},{"atl":[[9.8,39.53]],"batl":[[0,9.8,39.53]],"id":35856222},{"atb":[[5.1,568.96]],"trd":[[5.1,5070.66]],"batb":[[0,5.1,568.96]],"tv":14387.76,"id":56297029},{"atl":[[13,10.09]],"batl":[],"id":27115873}],"tv":93077.3}]}
{"op":"mcm","id":2,"clk":"AK+JAwDrvAIAo9wC","pt":1743512197117,"mc":[{"id":"1.241629436","rc":[{"atb":[[11.5,9.03]],"atl":[[11.5,0]],"trd":[[11.5,1798.84]],"batb":[[2,10.5,54.78],[1,11,80.47],[0,11.5,9.03]],"batl":[[0,12,64.67]],"tv":7248.21,"id":40389088},{"atl":[[400,0.03]],"id":26496185}],"tv":93079.24}]}
{"op":"mcm","id":2,"clk":"ALeJAwDyvAIAqNwC","pt":1743512197211,"mc":[{"id":"1.241629436","rc":[{"atb":[[11,85.34]],"atl":[[14.5,16.11],[14,23.16]],"batb":[[1,11,85.34]],"batl":[],"id":40389088},{"atl":[[13,11.76]],"batl":[],"id":27115873},{"atl":[[19,16]],"batl":[[2,19,16]],"id":58186642},{"atl":[[400,0.04],[16,3]],"id":26496185}]}]}
{"op":"mcm","id":2,"clk":"AMCJAwD5vAIAr9wC","pt":1743512197319,"mc":[{"id":"1.241629436","rc":[{"atb":[[4.7,1.17],[4.6,360.44],[4.3,152.17]],"trd":[[4.7,3757.06]],"batb":[[1,4.6,360.44],[0,4.7,1.17]],"ltp":4.7,"tv":23995.08,"id":270592},{"atb":[[4.5,100.15]],"batb":[],"id":56297029}],"tv":93289.24}]}
{"op":"mcm","id":2,"clk":"AMqJAwCDvQIAtdwC","pt":1743512197424,"mc":[{"id":"1.241629436","rc":[{"atb":[[4.7,0]],"trd":[[4.7,3759.4]],"batb":[[2,4.4,215.68],[1,4.5,247.68],[0,4.6,360.44]],"tv":23997.42,"id":270592},{"atb":[[10,124.41]],"trd":[[10,886.25]],"batb":[[0,10,124.41]],"ltp":10,"tv":7583.1,"id":27115873}],"tv":93301.58}]}
{"op":"mcm","id":2,"clk":"ANKJAwCFvQIAwNwC","pt":1743512197522,"mc":[{"id":"1.241629436","rc":[{"atl":[[1000,1.59]],"id":40389088},{"atb":[[9.6,0]],"trd":[[9.6,740.21]],"batb":[[2,9,41.58],[1,9.2,49.03],[0,9.4,37.48]],"tv":10505.36,"id":35856222},{"atb":[[1.17,2.12]],"id":56297029},{"atb":[[1.17,2.46]],"atl":[[19,12.87],[18,0.4]],"trd":[[18,373.95]],"batl":[[2,19.5,13.74],[1,19,12.87],[0,18.5,26.51]],"tv":6638.01,"id":58186642}],"tv":93377.61}]}
{"op":"mcm","id":2,"clk":"ANyJAwCOvQIAwdwC","pt":1743512197623,"mc":[{"id":"1.241629436","rc":[{"atl":[[1000,0.25]],"id":40389088},{"atb":[[4.4,214.52],[4.5,244.43]],"batb":[[2,4.4,214.52],[1,4.5,244.43]],"id":270592},{"atb":[[9.4,31.71],[8.8,49.21]],"atl":[[9.8,46.49],[10.5,70.53]],"batb":[[0,9.4,31.71]],"batl":[[2,10.5,70.53],[0,9.8,46.49]],"id":35856222},{"atb":[[46,10.58]],"batb":[[2,46,10.58]],"id":59626646},{"atb":[[1.17,2]],"atl":[[5.2,179.27]],"batl":[[0,5.2,179.27]],"id":56297029},{"atl":[[13,10.09]],"batl":[],"id":27115873},{"atb":[[1.17,2],[17.5,31.87],[16.5,32.4]],"atl":[[19,15.99]],"batb":[[2,16.5,32.4],[0,17.5,31.87]],"batl":[[1,19,15.99]],"id":58186642},{"atl":[[400,0.05]],"id":26496185}]}]}
{"op":"mcm","id":2,"clk":"AOSJAwCSvQIAytwC","pt":1743512197725,"mc":[{"id":"1.241629436","rc":[{"atb":[[11.5,8.49]],"atl":[[12,65.47]],"trd":[[11.5,1799.92]],"batb":[[0,11.5,8.49]],"batl":[[0,12,65.47]],"tv":7249.29,"id":40389088},{"atb":[[5.1,569.08]],"batb":[[0,5.1,569.08]],"id":56297029},{"atb":[[17.5,32.33]],"batb":[[0,17.5,32.33]],"id":58186642}],"tv":93378.69}]}
{"op":"mcm","id":2,"clk":"AOyJAwCbvQIA0NwC","pt":1743512197828,"mc":[{"id":"1.241629436","rc":[{"atb":[[4.3,153.36]],"batb":[],"id":270592},{"atl":[[9.6,16.86]],"batl":[[2,10,100.35],[1,9.8,46.49],[0,9.6,16.86]],"id":35856222}]}]}
{"op":"mcm","id":2,"clk":"APOJAwCnvQIA2NwC","pt":1743512197939,"mc":[{"id":"1.241629436","rc":[{"atb":[[9.4,17.71]],"atl":[[9.6,22.5]],"batb":[[0,9.4,17.71]],"batl":[[0,9.6,22.5]],"id":35856222},{"atb":[[5.1,617.55]],"batb":[[0,5.1,617.55]],"id":56297029}]}]}
{"op":"mcm","id":2,"clk":"APuJAwCrvQIA4NwC","pt":1743512198034,"mc":[{"id":"1.241629436","rc":[{"atl":[[9.6,33.5]],"batl":[[0,9.6,33.5]],"id":35856222},{"atl":[[13,40.08]],"batl":[],"id":44049799}]}]}
{"op":"mcm","id":2,"clk":"AIOKAwCwvQIA6NwC","pt":1743512198136,"mc":[{"id":"1.241629436","rc":[{"atl":[[400,0.03]],"id":35856222},{"atl":[[7,82.94]],"batl":[[0,7,82.94]],"id":26496185}]}]}
{"op":"mcm","id":2,"clk":"AI6KAwC7vQIA7twC","pt":1743512198237,"mc":[{"id":"1.241629436","rc":[{"atl":[[400,0.04]],"id":35856222}]}]}
{"op":"mcm","id":2,"clk":"AKiKAwDJvQIA/dwC","pt":1743512198443,"mc":[{"id":"1.241629436","rc":[{"atl":[[400,0.05]],"id":35856222}]}]}
{"op":"mcm","id":2,"clk":"ALWKAwDRvQIAhd0C","pt":1743512198505,"mc":[{"id":"1.241629436","rc":[{"atb":[[9.4,14.3]],"batb":[[0,9.4,14.3]],"id":35856222}]}]}
{"op":"mcm","id":2,"clk":"ALyKAwDWvQIAi90C","pt":1743512198606,"mc":[{"id":"1.241629436","rc":[{"atl":[[9.6,39.42]],"batl":[[0,9.6,39.42]],"id":35856222}]}]}
{"op":"mcm","id":2,"clk":"ANmKAwDlvQIAmd0C","pt":1743512198910,"mc":[{"id":"1.241629436","rc":[{"atl":[[4.7,2]],"batl":[[2,4.9,302.6],[1,4.8,257.91],[0,4.7,2]],"id":270592},{"atl":[[9.8,48.49]],"batl":[[1,9.8,48.49]],"id":35856222},{"atb":[[10,122.41]],"trd":[[10,890.25]],"batb":[[0,10,122.41]],"tv":7587.1,"id":27115873},{"atl":[[18.5,25.01],[18,0]],"trd":[[18,374.75],[18.5,227.47]],"batl":[[0,18.5,25.01]],"ltp":18.5,"tv":6641.01,"id":58186642},{"atb":[[6.8,183.2]],"trd":[[6.8,1644.16]],"batb":[[0,6.8,183.2]],"tv":15516.83,"id":26496185}],"tv":93389.69}]}
{"op":"mcm","id":2,"clk":"AOOKAwDtvQIApN0C","pt":1743512199022,"mc":[{"id":"1.241629436","rc":[{"atb":[[4.6,363.53],[4.5,247.68]],"batb":[[1,4.5,247.68],[0,4.6,363.53]],"id":270592},{"atb":[[9.4,7.74]],"batb":[[0,9.4,7.74]],"id":35856222},{"atl":[[19,12.87],[18.5,24.01]],"batl":[[1,19,12.87],[0,18.5,24.01]],"id":58186642}]}]}
{"op":"mcm","id":2,"clk":"AOuKAwDvvQIAqd0C","pt":1743512199113,"mc":[{"id":"1.241629436","rc":[{"atb":[[4.6,357.31],[1.01,56965.24]],"atl":[[4.7,0],[5.1,138.85]],"trd":[[4.7,3766.44],[4.6,653.05]],"batb":[[0,4.6,357.31]],"batl":[[2,5,314.8],[1,4.9,302.6],[0,4.8,257.91]],"ltp":4.6,"tv":24016.9,"id":270592},{"atl":[[400,0.03]],"id":27115873}],"tv":93409.17}]}
{"op":"mcm","id":2,"clk":"APeKAwD0vQIAsN0C","pt":1743512199218,"mc":[{"id":"1.241629436","rc":[{"atb":[[11.5,8.19]],"trd":[[11.5,1802.52]],"batb":[[0,11.5,8.19]],"tv":7251.89,"id":40389088},{"atb":[[4.6,354.22],[4.5,244.43]],"batb":[[1,4.5,244.43],[0,4.6,354.22]],"id":270592},{"atb":[[18,1.67]],"batb":[[2,17,35.53],[1,17.5,32.33],[0,18,1.67]],"id":58186642}],"tv":93411.77}]}
{"op":"mcm","id":2,"clk":"AP+KAwD5vQIAuN0C","pt":1743512199328,"mc":[{"id":"1.241629436","rc":[{"atb":[[11.5,9.08],[11,84.64]],"batb":[[1,11,84.64],[0,11.5,9.08]],"id":40389088},{"atb":[[4.4,222.26],[1.01,56965.23]],"atl":[[5,315.73]],"batb":[[2,4.4,222.26]],"batl":[[2,5,315.73]],"id":270592},{"atl":[[1000,0.54],[10,100.07]],"batl":[[2,10,100.07]],"id":35856222},{"atb":[[1.17,2.41]],"id":56297029},{"atl":[[400,0.04]],"id":27115873},{"atb":[[17.5,35.34]],"atl":[[19,16.01],[18.5,21.75]],"batb":[[1,17.5,35.34]],"batl":[[1,19,16.01],[0,18.5,21.75]],"id":58186642},{"atb":[[6.8,185.42]],"atl":[[7,82.9]],"batb":[[0,6.8,185.42]],"batl":[[0,7,82.9]],"id":26496185}]}]}
{"op":"mcm","id":2,"clk":"AIaLAwCAvgIAvd0C","pt":1743512199419,"mc":[{"id":"1.241629436","rc":[{"atl":[[1000,0.41],[9.6,46.08]],"batl":[[0,9.6,46.08]],"id":35856222}]}]}
{"op":"mcm","id":2,"clk":"AJGLAwCMvgIAyN0C","pt":1743512199535,"mc":[{"id":"1.241629436","rc":[{"atb":[[7,5.9]],"id":40389088},{"atb":[[1.01,56964.24]],"id":270592},{"atb":[[9.4,0]],"atl":[[9.8,48.62]],"trd":[[9.4,640.73]],"batb":[[2,8.8,49.21],[1,9,41.58],[0,9.2,49.03]],"batl":[[1,9.8,48.62]],"ltp":9.4,"tv":10520.84,"id":35856222},{"atb":[[1.17,2]],"id":56297029}],"tv":93427.25}]}
{"op":"mcm","id":2,"clk":"AJiLAwCUvgIA0N0C","pt":1743512199635,"mc":[{"id":"1.241629436","rc":[{"atb":[[11.5,15.08]],"batb":[[0,11.5,15.08]],"id":40389088},{"atb":[[4.7,0.99]],"batb":[[0,4.6,355.21]],"id":270592},{"atb":[[7.8,33.81],[8.6,17.94]],"atl":[[44,2]],"batb":[],"id":35856222},{"atb":[[5.1,617.96]],"atl":[[5.2,184.27]],"batb":[[0,5.1,617.96]],"batl":[[0,5.2,184.27]],"id":56297029},{"atl":[[400,0.05]],"id":27115873},{"atl":[[44,2.02],[18.5,19.48]],"batl":[[0,18.5,19.48]],"id":58186642}]}]}
{"op":"mcm","id":2,"clk":"AKaLAwCXvgIA090C","pt":1743512199729,"mc":[{"id":"1.241629436","rc":[{"atb":[[4.7,0],[4.6,354.21]],"atl":[[5,314.8]],"trd":[[4.7,3768.42],[4.6,653.07]],"batb":[[0,4.6,354.21]],"batl":[[2,5,314.8]],"tv":24018.9,"id":270592},{"atb":[[9.2,41.56]],"trd":[[9.2,730.77]],"batb":[[0,9.2,41.56]],"ltp":9.2,"tv":10521.34,"id":35856222},{"atb":[[18,10.45]],"trd":[[18,375.15]],"batb":[[0,18,10.45]],"ltp":18,"tv":6641.41,"id":58186642}],"tv":93430.15}]}
{"op":"mcm","id":2,"clk":"AL6LAwCkvgIA4N0C","pt":1743512199942,"mc":[{"id":"1.241629436","rc":[{"atl":[[5.1,139.78]],"batl":[],"id":270592},{"atb":[[8.4,58.86],[8.8,47.71],[8.2,14.96],[9,40.15]],"batb":[[2,8.8,47.71],[1,9,40.15]],"id":35856222},{"atl":[[19,12.87],[18.5,16.37]],"batl":[[1,19,12.87],[0,18.5,16.37]],"id":58186642},{"atl":[[7,92.9]],"batl":[[0,7,92.9]],"id":26496185}]}]}
{"op":"mcm","id":2,"clk":"AMOLAwCsvgIA490C","pt":1743512200041,"mc":[{"id":"1.241629436","rc":[{"atl":[[4.8,217.91]],"batl":[[0,4.8,217.91]],"id":270592},{"atb":[[5.1,666.44]],"batb":[[0,5.1,666.44]],"id":56297029}]}]}
{"op":"mcm","id":2,"clk":"AMqLAwCzvgIA5d0C","pt":1743512200099,"mc":[{"id":"1.241629436","rc":[{"atl":[[12,32.01]],"trd":[[12,1521.84]],"batl":[[0,12,32.01]],"ltp":12,"tv":7318.8,"id":40389088},{"atb":[[18,13.54],[16.5,43.02]],"batb":[[0,18,13.54]],"id":58186642},{"atl":[[400,0.03]],"id":44049799}],"tv":93497.06}]}
{"op":"mcm","id":2,"clk":"ANSLAwC5vgIA790C","pt":1743512200254,"mc":[{"id":"1.241629436","rc":[{"atb":[[11.5,55.32]],"atl":[[12,27.36]],"batb":[[0,11.5,55.32]],"batl":[[0,12,27.36]],"id":40389088},{"atb":[[9,43.61],[8.6,33.49]],"atl":[[9.4,16.21],[9.6,53.11]],"batb":[[1,9,43.61]],"batl":[[2,9.8,48.62],[1,9.6,53.11],[0,9.4,16.21]],"id":35856222},{"atb":[[46,8.91]],"batb":[[2,46,8.91]],"id":59626646},{"atl":[[400,0.04]],"id":44049799}]}]}
{"op":"mcm","id":2,"clk":"AOeLAwDIvgIA+N0C","pt":1743512200411,"mc":[{"id":"1.241629436","rc":[{"atb":[[1.17,2.1],[11.5,70.97],[11,84.02]],"atl":[[14.5,14.78],[14,21.73],[12.5,68.03],[12,4]],"batb":[[1,11,84.02],[0,11.5,70.97]],"batl":[[1,12.5,68.03],[0,12,4]],"id":40389088},{"atb":[[8.8,49.21],[9.2,27.56],[9,45.04]],"atl":[[9.4,21.63]],"batb":[[2,8.8,49.21],[1,9,45.04],[0,9.2,27.56]],"batl":[[0,9.4,21.63]],"id":35856222},{"atb":[[1.17,2.35]],"atl":[[5.3,82.83]],"batl":[[1,5.3,82.83]],"id":56297029},{"atl":[[11,73.57]],"batl":[[1,11,73.57]],"id":27115873},{"atl":[[400,0.05]],"id":44049799}]}]}
{"op":"mcm","id":2,"clk":"APWLAwDRvgIAgt4C","pt":1743512200517,"mc":[{"id":"1.241629436","rc":[{"atb":[[1.17,2],[11.5,83.56]],"atl":[[12,2.9]],"trd":[[12,1524.04]],"batb":[[0,11.5,83.56]],"batl":[[0,12,2.9]],"tv":7321,"id":40389088},{"atl":[[19,15.96]],"batl":[[1,19,15.96]],"id":58186642}],"tv":93499.26}]}
{"op":"mcm","id":2,"clk":"AP+LAwDXvgIAit4C","pt":1743512200616,"mc":[{"id":"1.241629436","rc":[{"atb":[[12,17.23],[11.5,83.66]],"atl":[[12,0]],"trd":[[12,1529.84]],"batb":[[2,11,84.02],[1,11.5,83.66],[0,12,17.23]],"batl":[[2,13.5,17.78],[1,13,23.87],[0,12.5,68.03]],"tv":7326.8,"id":40389088},{"atl":[[9.6,47.19]],"batl":[[1,9.6,47.19]],"id":35856222},{"atb":[[1.17,2]],"id":56297029}],"tv":93505.06}]}
{"op":"mcm","id":2,"clk":"AImMAwDevgIAkd4C","pt":1743512200713,"mc":[{"id":"1.241629436","rc":[{"atb":[[12,33.87]],"atl":[[15,21.62],[14.5,16.11],[14,23.16],[12.5,63.23]],"batb":[[0,12,33.87]],"batl":[[0,12.5,63.23]],"id":40389088},{"atb":[[5.1,666.79]],"batb":[[0,5.1,666.79]],"id":56297029}]}]}
{"op":"mcm","id":2,"clk":"AJSMAwDrvgIAm94C","pt":1743512200821,"mc":[{"id":"1.241629436","rc":[{"atb":[[12,36.77],[11,65.31]],"atl":[[12.5,104.25]],"batb":[[2,11,65.31],[0,12,36.77]],"batl":[[0,12.5,104.25]],"id":40389088},{"atl":[[60,13.66]],"batl":[[0,60,14.3]],"id":59626646},{"atl":[[18.5,52.42]],"batl":[[0,18.5,52.42]],"id":58186642}]}]}
{"op":"mcm","id":2,"clk":"AKGMAwDyvgIAn94C","pt":1743512200917,"mc":[{"id":"1.241629436","rc":[{"atb":[[18,4.56]],"batb":[[0,18,4.56]],"id":58186642}]}]}
{"op":"mcm","id":2,"clk":"AKqMAwD+vgIApt4C","pt":1743512201023,"mc":[{"id":"1.241629436","rc":[{"atb":[[4.6,364.21]],"batb":[[0,4.6,364.21]],"id":270592},{"atb":[[18,1.47]],"atl":[[18.5,55.5]],"batb":[[0,18,1.47]],"batl":[[0,18.5,55.5]],"id":58186642}]}]}
{"op":"mcm","id":2,"clk":"ALOMAwCHvwIAsd4C","pt":1743512201122,"mc":[{"id":"1.241629436","rc":[{"atl":[[400,0.03]],"id":40389088},{"atl":[[18.5,58.67]],"batl":[[0,18.5,58.67]],"id":58186642}]}]}
{"op":"mcm","id":2,"clk":"ALyMAwCSvwIAu94C","pt":1743512201233,"mc":[{"id":"1.241629436","rc":[{"atb":[[18,0.51]],"trd":[[18,377.07]],"batb":[[2,16.5,43.02],[1,17,35.53],[0,17.5,35.85]],"tv":6643.33,"id":58186642}],"tv":93506.98}]}
{"op":"mcm","id":2,"clk":"AMiMAwCcvwIAxt4C","pt":1743512201340,"mc":[{"id":"1.241629436","rc":[{"atl":[[400,0.05]],"id":40389088},{"atb":[[18,0]],"trd":[[18,378.09]],"batb":[[0,17.5,35.34]],"tv":6644.35,"id":58186642}],"tv":93508}]}
{"op":"mcm","id":2,"clk":"AM2MAwClvwIAzN4C","pt":1743512201437,"mc":[{"id":"1.241629436","rc":[{"atl":[[18.5,55.5]],"batl":[[0,18.5,55.5]],"id":58186642}]}]}
{"op":"mcm","id":2,"clk":"APCMAwC9vwIA3N4C","pt":1743512201759,"mc":[{"id":"1.241629436","rc":[{"atb":[[9.2,28.92]],"batb":[[0,9.2,28.92]],"id":35856222},{"atb":[[6,151.04]],"batb":[],"id":26496185}]}]}
{"op":"mcm","id":2,"clk":"APiMAwDJvwIA4t4C","pt":1743512201852,"mc":[{"id":"1.241629436","rc":[{"atl":[[12.5,98.43]],"trd":[[12.5,511.11]],"batl":[[0,12.5,98.43]],"ltp":12.5,"tv":7338.44,"id":40389088},{"atl":[[9.6,52.19]],"batl":[[1,9.6,52.19]],"id":35856222}],"tv":93519.64}]}
{"op":"mcm","id":2,"clk":"AI6NAwDYvwIA694C","pt":1743512202010,"mc":[{"id":"1.241629436","rc":[{"atb":[[4.6,369.21]],"batb":[[0,4.6,369.21]],"id":270592}]}]}
{"op":"mcm","id":2,"clk":"AJKNAwDgvwIA794C","pt":1743512202105,"mc":[{"id":"1.241629436","rc":[{"atl":[[12.5,95.01]],"batl":[[0,12.5,95.01]],"id":40389088},{"atl":[[9.8,52.04]],"batl":[[2,9.8,52.04]],"id":35856222},{"atb":[[10,112.41]],"trd":[[10,910.25]],"batb":[[0,10,112.41]],"tv":7607.1,"id":27115873},{"atl":[[400,0.03]],"id":58186642}],"tv":93539.64}]}
{"op":"mcm","id":2,"clk":"AJuNAwDovwIA+d4C","pt":1743512202220,"mc":[{"id":"1.241629436","rc":[{"atl":[[14,21.73]],"batl":[],"id":40389088},{"atb":[[10,109.91]],"trd":[[10,915.25]],"batb":[[0,10,109.91]],"tv":7612.1,"id":27115873}],"tv":93544.64}]}
{"op":"mcm","id":2,"clk":"AKSNAwD0vwIAht8C","pt":1743512202319,"mc":[{"id":"1.241629436","rc":[{"atb":[[4.6,374.84]],"batb":[[0,4.6,374.84]],"id":270592},{"atb":[[1.17,7.77]],"id":35856222},{"atb":[[1.17,2.55]],"atl":[[5.2,187.01]],"batl":[[0,5.2,187.01]],"id":56297029},{"atb":[[10,111.52]],"atl":[[10.5,126.76]],"batb":[[0,10,111.52]],"batl":[[0,10.5,126.76]],"id":27115873},{"atb":[[17,36.57]],"atl":[[18.5,60.48]],"batb":[[1,17,36.57]],"batl":[[0,18.5,60.48]],"id":58186642},{"atl":[[7,52.61]],"trd":[[7,1502.21]],"batl":[[0,7,52.61]],"ltp":7,"tv":15597.41,"id":26496185},{"atb":[[1.17,2.12]],"id":44049799}],"tv":93625.22}]}
{"op":"mcm","id":2,"clk":"AK+NAwD8vwIAjN8C","pt":1743512202421,"mc":[{"id":"1.241629436","rc":[{"atl":[[14.5,16.59]],"batl":[],"id":40389088},{"atb":[[1.17,7.15],[9.2,25.39]],"batb":[[0,9.2,25.39]],"id":35856222},{"atb":[[1.17,2]],"id":56297029},{"atb":[[10,125.52]],"batb":[[0,10,125.52]],"id":27115873},{"atl":[[400,0.05]],"id":58186642},{"atl":[[7,27]],"trd":[[7,1544.35]],"batl":[[0,7,27]],"tv":15639.55,"id":26496185},{"atb":[[1.17,2]],"id":44049799}],"tv":93667.36}]}
{"op":"mcm","id":2,"clk":"ALmNAwCEwAIAl98C","pt":1743512202532,"mc":[{"id":"1.241629436","rc":[{"atl":[[5.1,149.78]],"batl":[],"id":270592},{"atl":[[9.4,21.01]],"trd":[[9.4,641.97]],"batl":[[0,9.4,21.01]],"ltp":9.4,"tv":10522.58,"id":35856222},{"atb":[[5,1130.25]],"batb":[[1,5,1130.25]],"id":56297029},{"atl":[[10.5,141.88]],"batl":[[0,10.5,141.88]],"id":27115873},{"atb":[[6.8,212.16],[6.4,279.46]],"atl":[[7,1.33]],"trd":[[7,1598.35]],"batb":[[2,6.4,279.46],[0,6.8,212.16]],"batl":[[0,7,1.33]],"tv":15693.55,"id":26496185},{"atb":[[11,123.66]],"batb":[[0,11,123.66]],"id":44049799}],"tv":93722.6}]}
{"op":"mcm","id":2,"clk":"AMKNAwCKwAIAo98C","pt":1743512202625,"mc":[{"id":"1.241629436","rc":[{"atl":[[4.7,1],[4.8,213.91]],"batl":[[2,4.9,302.6],[1,4.8,213.91],[0,4.7,1]],"id":270592},{"atb":[[1.02,5154.56],[9,38.75]],"batb":[[1,9,38.75]],"id":35856222},{"atl":[[5.2,287.58]],"batl":[[0,5.2,287.58]],"id":56297029},{"atl":[[18.5,63.62]],"batl":[[0,18.5,63.62]],"id":58186642},{"atl":[[7,9.44]],"batl":[[0,7,9.44]],"id":26496185}]}]}
{"op":"mcm","id":2,"clk":"AMqNAwCYwAIAqt8C","pt":1743512202730,"mc":[{"id":"1.241629436","rc":[{"atb":[[4.6,377.93],[4.5,247.68]],"atl":[[4.7,5],[5,305.23]],"batb":[[1,4.5,247.68],[0,4.6,377.93]],"batl":[[0,4.7,5]],"id":270592},{"atb":[[1.02,5154.16]],"id":35856222},{"atl":[[7,0]],"trd":[[7,1617.23]],"batl":[[2,7.6,53.31],[1,7.4,45.54],[0,7.2,175.37]],"tv":15712.43,"id":26496185}],"tv":93741.48}]}
{"op":"mcm","id":2,"clk":"ANKNAwChwAIAtN8C","pt":1743512202832,"mc":[{"id":"1.241629436","rc":[{"atb":[[4.4,210.17],[4.3,165.38]],"batb":[[2,4.4,210.17]],"id":270592},{"atb":[[10,123.52]],"trd":[[10,919.25]],"batb":[[0,10,123.52]],"tv":7616.1,"id":27115873},{"atl":[[7.2,167.45]],"batl":[[0,7.2,167.45]],"id":26496185},{"atl":[[12.5,42.8]],"batl":[[2,12.5,42.8]],"id":44049799}],"tv":93745.48}]}
{"op":"mcm","id":2,"clk":"AN+NAwCpwAIAt98C","pt":1743512202932,"mc":[{"id":"1.241629436","rc":[{"atb":[[1.02,5153.56]],"id":35856222},{"atl":[[5.5,87.18]],"batl":[],"id":56297029},{"atb":[[6.8,222.16],[6.2,163.19],[6.4,276.47]],"batb":[[2,6.4,276.47],[0,6.8,222.16]],"id":26496185}]}]}
{"op":"mcm","id":2,"clk":"AOeNAwCvwAIAwN8C","pt":1743512203031,"mc":[{"id":"1.241629436","rc":[{"atl":[[12.5,99.63]],"batl":[[0,12.5,99.63]],"id":40389088},{"atl":[[9.4,20.41]],"trd":[[9.4,643.17]],"batl":[[0,9.4,20.41]],"tv":10523.78,"id":35856222},{"atl":[[5.3,93.76]],"batl":[[1,5.3,93.76]],"id":56297029},{"atb":[[10,129.03]],"batb":[[0,10,129.03]],"id":27115873},{"atl":[[7.4,37.53]],"batl":[[1,7.4,37.53]],"id":26496185}],"tv":93746.68}]}
{"op":"mcm","id":2,"clk":"APaNAwC4wAIAy98C","pt":1743512203140,"mc":[{"id":"1.241629436","rc":[{"atl":[[12.5,95.01]],"batl":[[0,12.5,95.01]],"id":40389088},{"atl":[[4.9,286.03],[5,294.15],[4.8,196.96]],"batl":[[2,4.9,286.03],[1,4.8,196.96]],"id":270592},{"atl":[[400,0.03]],"id":59626646},{"atl":[[5.4,68.65],[5.2,270.42],[5.3,76.98]],"batl":[[2,5.4,68.65],[1,5.3,76.98],[0,5.2,270.42]],"id":56297029},{"atb":[[9.8,68.67],[10,123.52],[9.6,71.07]],"batb":[[2,9.6,71.07],[1,9.8,68.67],[0,10,123.52]],"id":27115873},{"atb":[[16.5,40.65]],"batb":[[2,16.5,40.65]],"id":58186642},{"atb":[[6.6,195.08],[6.4,260.94]],"batb":[[2,6.4,260.94],[1,6.6,195.08]],"id":26496185},{"atl":[[12.5,36.98],[12,39.04]],"batl":[[2,12.5,36.98],[1,12,39.04]],"id":44049799}]}]}
{"op":"mcm","id":2,"clk":"AICOAwDEwAIA1d8C","pt":1743512203251,"mc":[{"id":"1.241629436","rc":[{"atl":[[12.5,99.65]],"batl":[[0,12.5,99.65]],"id":40389088}]}]}
{"op":"mcm","id":2,"clk":"AIuOAwDOwAIA3d8C","pt":1743512203351,"mc":[{"id":"1.241629436","rc":[{"atl":[[400,0.05]],"id":59626646},{"atb":[[5.9,2],[6.6,1.99],[7,3.55],[5.7,3],[7.6,8.58],[6.8,3],[6,2.47],[7.4,7.11],[6.2,14.42],[5.8,2],[6.4,17.48],[7.2,3.55]],"id":44049799}]}]}
{"op":"mcm","id":2,"clk":"AJyOAwDcwAIA8t8C","pt":1743512203511,"mc":[{"id":"1.241629436","rc":[{"atl":[[5.2,268.42]],"trd":[[5.2,3885.51]],"batl":[[0,5.2,268.42]],"ltp":5.2,"tv":14391.76,"id":56297029}],"tv":93750.68}]}
{"op":"mcm","id":2,"clk":"AKKOAwDiwAIA+98C","pt":1743512203607,"mc":[{"id":"1.241629436","rc":[{"atl":[[9.4,0],[9.6,6.6]],"trd":[[9.4,683.98],[9.6,831.39]],"batl":[[2,10,100.07],[1,9.8,52.04],[0,9.6,6.6]],"ltp":9.6,"tv":10655.77,"id":35856222},{"atb":[[9.6,137.07]],"batb":[[2,9.6,137.07]],"id":27115873}],"tv":93882.67}]}
{"op":"mcm","id":2,"clk":"AKyOAwDnwAIAg+AC","pt":1743512203720,"mc":[{"id":"1.241629436","rc":[{"atl":[[4.7,18.93],[4.9,310.99],[5.1,148.85],[4.8,221.92]],"batl":[[2,4.9,310.99],[1,4.8,221.92],[0,4.7,18.93]],"id":270592},{"atb":[[9.4,21.13],[8.4,59.35],[9.2,53.39]],"atl":[[9.6,5]],"batb":[[2,9,38.75],[1,9.2,53.39],[0,9.4,21.13]],"batl":[[0,9.6,5]],"id":35856222},{"atl":[[5.2,263.42],[5.3,91.8]],"trd":[[5.2,3895.51]],"batl":[[1,5.3,91.8],[0,5.2,263.42]],"tv":14401.76,"id":56297029},{"atb":[[9.8,77.51],[10,132.36]],"batb":[[1,9.8,77.51],[0,10,132.36]],"id":27115873},{"atb":[[19,5.32],[18.5,17.01],[17,39.98],[17.5,38.75]],"atl":[[19,0],[18.5,0]],"trd":[[19,324.01],[18.5,354.71]],"batb":[[2,17.5,38.75],[1,18.5,17.01],[0,19,5.32]],"batl":[[2,21,10.93],[1,20,10.06],[0,19.5,13.74]],"ltp":19,"tv":6803.52,"id":58186642},{"atb":[[6.6,217.19],[7,70.13],[6.8,244.27]],"atl":[[8,56.04]],"batb":[[2,6.6,217.19],[1,6.8,244.27],[0,7,70.13]],"batl":[],"id":26496185},{"atl":[[12,45.98]],"batl":[[1,12,45.98]],"id":44049799}],"tv":94051.84}]}
{"op":"mcm","id":2,"clk":"ALOOAwDxwAIAjuAC","pt":1743512203815,"mc":[{"id":"1.241629436","rc":[{"atb":[[12,20.13]],"atl":[[13,27.24]],"batb":[[0,12,20.13]],"batl":[[1,13,27.24]],"id":40389088},{"atb":[[4.2,118.58],[4.6,348.37],[4.3,153.36]],"atl":[[4.7,86.17],[5,295.08]],"batb":[[0,4.6,348.37]],"batl":[[0,4.7,86.17]],"id":270592},{"atl":[[9.8,46.25],[10,94.35]],"batl":[[2,10,94.35],[1,9.8,46.25]],"id":35856222},{"atb":[[9.8,74.12]],"batb":[[1,9.8,74.12]],"id":27115873},{"atb":[[19,2.76],[18,5.2],[18.5,15.72],[16,14.36]],"atl":[[20,7.1],[19.5,10.58]],"trd":[[19,347.27],[18.5,363.29]],"batb":[[2,18,5.2],[1,18.5,15.72],[0,19,2.76]],"batl":[[1,20,7.1],[0,19.5,10.58]],"tv":6835.36,"id":58186642},{"atb":[[7,78.14]],"batb":[[0,7,78.14]],"id":26496185}],"tv":94083.68}]}
{"op":"mcm","id":2,"clk":"ALyOAwD6wAIAlOAC","pt":1743512203918,"mc":[{"id":"1.241629436","rc":[{"atb":[[12,16.86]],"atl":[[12.5,101.95]],"trd":[[12,1536.38]],"batb":[[0,12,16.86]],"batl":[[0,12.5,101.95]],"ltp":12,"tv":7344.98,"id":40389088},{"atb":[[4.6,345.28]],"atl":[[4.8,231.3]],"batb":[[0,4.6,345.28]],"batl":[[1,4.8,231.3]],"id":270592},{"atl":[[5.2,274.36]],"batl":[[0,5.2,274.36]],"id":56297029},{"atb":[[19,0],[18,22.11],[18.5,16.42],[17,31.28],[17.5,38.29]],"atl":[[1000,3.81],[26,8.79],[25,8.98],[23,7.07],[22,7.96],[20,9.29],[19,6.84]],"trd":[[19,352.79],[18.5,380.49]],"batb":[[2,17.5,38.29],[1,18,22.11],[0,18.5,16.42]],"batl":[[2,20,9.29],[1,19.5,10.58],[0,19,6.84]],"ltp":18.5,"tv":6858.08,"id":58186642},{"atl":[[12,51.02]],"batl":[[1,12,51.02]],"id":44049799}],"tv":94112.94}]}
{"op":"mcm","id":2,"clk":"AMiOAwCBwQIAmuAC","pt":1743512204023,"mc":[{"id":"1.241629436","rc":[{"atb":[[12,2.9]],"batb":[[0,12,2.9]],"id":40389088},{"atb":[[4.6,284.23]],"batb":[[0,4.6,284.23]],"id":270592},{"atb":[[50,12.1]],"atl":[[55,1.93]],"batb":[[0,50,12.1]],"batl":[[2,65,3.61],[1,60,13.66],[0,55,1.93]],"id":59626646},{"atb":[[5.1,638.36]],"batb":[[0,5.1,638.36]],"id":56297029},{"atl":[[13,11.76]],"batl":[],"id":27115873},{"atb":[[18.5,20.39]],"batb":[[0,18.5,20.39]],"id":58186642},{"atb":[[6.2,166.4]],"batb":[],"id":26496185},{"atl":[[12.5,38.8]],"batl":[[2,12.5,38.8]],"id":44049799}]}]}
{"op":"mcm","id":2,"clk":"AM+OAwCLwQIApOAC","pt":1743512204125,"mc":[{"id":"1.241629436","rc":[{"atl":[[4.7,20.16]],"trd":[[4.7,3900.43]],"batl":[[0,4.7,20.16]],"ltp":4.7,"tv":24150.91,"id":270592},{"atb":[[9.4,27.08]],"batb":[[0,9.4,27.08]],"id":35856222},{"atb":[[18,8.5],[18.5,23.39]],"atl":[[1000,3.13],[26,5.76],[25,5.95],[19,4.72]],"trd":[[19,357.03]],"batb":[[1,18,8.5],[0,18.5,23.39]],"batl":[[0,19,4.72]],"ltp":19,"tv":6862.32,"id":58186642}],"tv":94249.19}]}
{"op":"mcm","id":2,"clk":"ANiOAwCTwQIAwOAC","pt":1743512204233,"mc":[{"id":"1.241629436","rc":[{"atb":[[12,1.23]],"trd":[[12,1539.72]],"batb":[[0,12,1.23]],"tv":7348.32,"id":40389088},{"atl":[[4.7,0]],"batl":[[2,5,295.08],[1,4.9,310.99],[0,4.8,231.3]],"id":270592},{"atl":[[70,3.85]],"batl":[],"id":59626646},{"atl":[[5.2,269.36]],"trd":[[5.2,3905.51]],"batl":[[0,5.2,269.36]],"tv":14411.76,"id":56297029},{"atb":[[18.5,26.6]],"batb":[[0,18.5,26.6]],"id":58186642}],"tv":94262.53}]}
{"op":"mcm","id":2,"clk":"AOOOAwCYwQIAxuAC","pt":1743512204335,"mc":[{"id":"1.241629436","rc":[{"atb":[[12,0]],"atl":[[12,18.75]],"trd":[[12,1542.18]],"batb":[[2,10.5,54.78],[1,11,65.31],[0,11.5,83.66]],"batl":[[2,13,27.24],[1,12.5,101.95],[0,12,18.75]],"tv":7350.78,"id":40389088},{"atb":[[4.4,206.75],[4.5,244.43]],"atl":[[4.7,6.74],[4.8,268.8]],"batb":[[2,4.4,206.75],[1,4.5,244.43]],"batl":[[2,4.9,310.99],[1,4.8,268.8],[0,4.7,6.74]],"id":270592},{"atb":[[9.2,52.03]],"atl":[[9.6,1.36]],"trd":[[9.6,838.67]],"batb":[[1,9.2,52.03]],"batl":[[0,9.6,1.36]],"tv":10663.05,"id":35856222},{"atl":[[1000,2.81]],"id":58186642}],"tv":94272.27}]}
{"op":"mcm","id":2,"clk":"AOuOAwCiwQIAyuAC","pt":1743512204438,"mc":[{"id":"1.241629436","rc":[{"atb":[[9.6,39.21]],"atl":[[12,39.59]],"batb":[],"batl":[[0,12,39.59]],"id":40389088},{"atb":[[4.4,210.17],[4.1,152.62],[4.5,247.68]],"batb":[[2,4.4,210.17],[1,4.5,247.68]],"id":270592},{"atb":[[9.2,53.39]],"batb":[[1,9.2,53.39]],"id":35856222},{"atl":[[28,6.84],[19,5.04]],"batl":[[0,19,5.04]],"id":58186642}]}]}
{"op":"mcm","id":2,"clk":"APOOAwCqwQIA0eAC","pt":1743512204537,"mc":[{"id":"1.241629436","rc":[{"atl":[[15,20.38],[14.5,15.26]],"batl":[],"id":40389088},{"atb":[[9.6,13.8]],"atl":[[9.6,0]],"trd":[[9.6,841.39]],"batb":[[2,9.2,53.39],[1,9.4,27.08],[0,9.6,13.8]],"batl":[[2,10.5,70.53],[1,10,94.35],[0,9.8,46.25]],"tv":10665.77,"id":35856222},{"atl":[[5.2,229.36]],"trd":[[5.2,3985.51]],"batl":[[0,5.2,229.36]],"tv":14491.76,"id":56297029},{"atb":[[18.5,25.43]],"trd":[[18.5,382.84]],"batb":[[0,18.5,25.43]],"ltp":18.5,"tv":6864.67,"id":58186642}],"tv":94357.34}]}
{"op":"mcm","id":2,"clk":"AP6OAwCzwQIA1+AC","pt":1743512204647,"mc":[{"id":"1.241629436","rc":[{"atb":[[11.5,73.37]],"batb":[[0,11.5,73.37]],"id":40389088},{"atb":[[4.6,266.59]],"atl":[[4.9,300.99]],"trd":[[4.6,688.34]],"batb":[[0,4.6,266.59]],"batl":[[2,4.9,300.99]],"ltp":4.6,"tv":24186.18,"id":270592},{"atb":[[9.4,30.57],[9.6,8.02]],"trd":[[9.6,852.95]],"batb":[[1,9.4,30.57],[0,9.6,8.02]],"tv":10677.33,"id":35856222},{"atb":[[5.1,625.65]],"atl":[[5.2,10.94]],"trd":[[5.2,4221.22],[5.1,5096.08]],"batb":[[0,5.1,625.65]],"batl":[[0,5.2,10.94]],"ltp":5.1,"tv":14752.89,"id":56297029},{"atl":[[19,14.03]],"batl":[[0,19,14.03]],"id":58186642},{"atb":[[7,69.45]],"trd":[[7,1634.61]],"batb":[[0,7,69.45]],"tv":15729.81,"id":26496185}],"tv":94682.68}]}
{"op":"mcm","id":2,"clk":"AIePAwC7wQIA3OAC","pt":1743512204741,"mc":[{"id":"1.241629436","rc":[{"atl":[[4.7,18.99]],"batl":[[0,4.7,18.99]],"id":270592},{"atb":[[9.2,52.03]],"batb":[[2,9.2,52.03]],"id":35856222}]}]}
{"op":"mcm","id":2,"clk":"AI+PAwDFwQIA6+AC","pt":1743512204859,"mc":[{"id":"1.241629436","rc":[{"atl":[[4.7,17.54]],"trd":[[4.7,3903.32]],"batl":[[0,4.7,17.54]],"ltp":4.7,"tv":24189.07,"id":270592},{"atb":[[9.6,7.88]],"trd":[[9.6,853.23]],"batb":[[0,9.6,7.88]],"tv":10677.61,"id":35856222},{"atb":[[5.2,7]],"atl":[[5.2,0]],"trd":[[5.2,4282.2]],"batb":[[2,5,1130.25],[1,5.1,625.65],[0,5.2,7]],"batl":[[2,5.5,87.18],[1,5.4,68.65],[0,5.3,91.8]],"ltp":5.2,"tv":14813.87,"id":56297029}],"tv":94746.83}]}
{"op":"mcm","id":2,"clk":"AJWPAwDHwQIA7+AC","pt":1743512204949,"mc":[{"id":"1.241629436","rc":[{"atb":[[11.5,68.57]],"batb":[[0,11.5,68.57]],"id":40389088},{"atb":[[4.3,165.51]],"batb":[],"id":270592},{"atb":[[9.4,27.57],[9.6,0]],"trd":[[9.4,689.98]],"batb":[[2,9,38.75],[1,9.2,52.03],[0,9.4,27.57]],"ltp":9.4,"tv":10683.61,"id":35856222},{"atl":[[5.3,80.87]],"batl":[[0,5.3,80.87]],"id":56297029},{"atb":[[9.6,131.25]],"batb":[[2,9.6,131.25]],"id":27115873},{"atl":[[27,7.69]],"batl":[],"id":58186642}],"tv":94752.83}]}
{"op":"mcm","id":2,"clk":"AKKPAwDOwQIA+OAC","pt":1743512205059,"mc":[{"id":"1.241629436","rc":[{"atb":[[11.5,56.02]],"atl":[[12.5,114.27]],"batb":[[0,11.5,56.02]],"batl":[[1,12.5,114.27]],"id":40389088},{"atb":[[4.3,153.36]],"atl":[[4.7,19.7],[4.9,295.99]],"batb":[],"batl":[[2,4.9,295.99],[0,4.7,19.7]],"id":270592},{"atb":[[9.4,42.57],[9,37.32]],"atl":[[44,1],[9.6,2.28]],"batb":[[2,9,37.32],[0,9.4,42.57]],"batl":[[2,10,94.35],[1,9.8,46.25],[0,9.6,2.28]],"id":35856222},{"atb":[[5.2,31.17],[4.8,152.52]],"atl":[[5.4,57.73],[5.5,77.56]],"trd":[[5.2,4307.6]],"batb":[[0,5.2,31.17]],"batl":[[2,5.5,77.56],[1,5.4,57.73]],"tv":14839.27,"id":56297029},{"atb":[[18,17.05]],"atl":[[44,1.02]],"batb":[[1,18,17.05]],"id":58186642},{"atl":[[7.4,45.52]],"batl":[[1,7.4,45.52]],"id":26496185}],"tv":94778.23}]}
{"op":"mcm","id":2,"clk":"AKmPAwDTwQIA/eAC","pt":1743512205116,"mc":[{"id":"1.241629436","rc":[{"atb":[[9,41.79]],"atl":[[10,100.3]],"batb":[[2,9,41.79]],"batl":[[2,10,100.3]],"id":35856222},{"atb":[[5.2,58.72]],"atl":[[5.5,66.65]],"batb":[[0,5.2,58.72]],"batl":[[2,5.5,66.65]],"id":56297029},{"atb":[[10,135.32]],"batb":[[0,10,135.32]],"id":27115873},{"atb":[[18.5,21.43]],"atl":[[26,8.77]],"trd":[[18.5,390.84]],"batb":[[0,18.5,21.43]],"batl":[],"tv":6872.67,"id":58186642}],"tv":94786.23}]}
{"op":"mcm","id":2,"clk":"ALCPAwDWwQIAgOEC","pt":1743512205214,"mc":[{"id":"1.241629436","rc":[{"atb":[[11.5,40.37]],"batb":[[0,11.5,40.37]],"id":40389088},{"atb":[[9.4,27.57],[9,43.22]],"atl":[[9.6,13.68]],"batb":[[2,9,43.22],[0,9.4,27.57]],"batl":[[0,9.6,13.68]],"id":35856222},{"atb":[[5.2,179.36],[4.9,71.6]],"atl":[[5.6,104.14]],"batb":[[0,5.2,179.36]],"batl":[],"id":56297029},{"atb":[[18,28.52],[18.5,18.43]],"atl":[[19,5.04]],"batb":[[1,18,28.52],[0,18.5,18.43]],"batl":[[0,19,5.04]],"id":58186642}]}]}
{"op":"mcm","id":2,"clk":"ALaPAwDfwQIAiOEC","pt":1743512205319,"mc":[{"id":"1.241629436","rc":[{"atl":[[12,49.46]],"batl":[[0,12,49.46]],"id":40389088},{"atl":[[4.7,17.7]],"trd":[[4.7,3907.32]],"batl":[[0,4.7,17.7]],"tv":24193.07,"id":270592},{"atb":[[9.4,16.19],[9.2,53.39]],"atl":[[9.6,20.55]],"batb":[[1,9.2,53.39],[0,9.4,16.19]],"batl":[[0,9.6,20.55]],"id":35856222},{"atb":[[5.2,205.21],[4.9,70.59]],"atl":[[5.7,100.7],[5.6,93.25]],"batb":[[0,5.2,205.21]],"batl":[],"id":56297029}],"tv":94790.23}]}
{"op":"mcm","id":2,"clk":"ALuPAwDlwQIAjeEC","pt":1743512205411,"mc":[{"id":"1.241629436","rc":[{"atl":[[1000,21.23],[4.9,295.59],[5,290.08]],"batl":[[2,4.9,295.59]],"id":270592},{"atl":[[9.8,46.12]],"batl":[[1,9.8,46.12]],"id":35856222},{"atb":[[5,1129.7],[5.1,625.24]],"atl":[[5.3,37.6]],"batb":[[2,5,1129.7],[1,5.1,625.24]],"batl":[[0,5.3,37.6]],"id":56297029},{"atb":[[18,29.82],[18.5,21.43],[17,30.24],[17.5,37.54]],"batb":[[2,17.5,37.54],[1,18,29.82],[0,18.5,21.43]],"id":58186642},{"atb":[[7,73.63],[6.8,238.78]],"atl":[[1000,6.34],[7.2,166.42]],"batb":[[1,6.8,238.78],[0,7,73.63]],"batl":[[0,7.2,166.42]],"id":26496185},{"atb":[[11,123.54]],"batb":[[0,11,123.54]],"id":44049799}]}]}
{"op":"mcm","id":2,"clk":"AL6PAwDxwQIAlOEC","pt":1743512205511,"mc":[{"id":"1.241629436","rc":[{"atb":[[5.2,210.21],[5,1130.68]],"atl":[[5.7,101.19]],"batb":[[2,5,1130.68],[0,5.2,210.21]],"batl":[],"id":56297029}]}]}
{"op":"mcm","id":2,"clk":"AMmPAwD7wQIAoOEC","pt":1743512205625,"mc":[{"id":"1.241629436","rc":[{"atl":[[1000,21.16]],"id":270592},{"atb":[[1.04,1]],"atl":[[5.3,7.6]],"trd":[[5.3,1031.53]],"batl":[[0,5.3,7.6]],"ltp":5.3,"tv":14899.27,"id":56297029},{"atl":[[1000,4.87]],"id":26496185}],"tv":94850.23}]}
{"op":"mcm","id":2,"clk":"ANCPAwCBwgIAquEC","pt":1743512205728,"mc":[{"id":"1.241629436","rc":[{"atb":[[11.5,23.47]],"batb":[[0,11.5,23.47]],"id":40389088},{"atl":[[4.8,268.87]],"batl":[[1,4.8,268.87]],"id":270592},{"atb":[[9.4,12.7]],"batb":[[0,9.4,12.7]],"id":35856222},{"atl":[[6.4,14.29]],"batl":[],"id":56297029},{"atb":[[6.8,228.78]],"atl":[[7.4,46.36],[7.2,163.51]],"batb":[[1,6.8,228.78]],"batl":[[1,7.4,46.36],[0,7.2,163.51]],"id":26496185}]}]}
{"op":"mcm","id":2,"clk":"ANqPAwCLwgIAreEC","pt":1743512205828,"mc":[{"id":"1.241629436","rc":[{"atb":[[1.04,0.57]],"id":56297029},{"atb":[[9.4,66.87]],"batb":[],"id":27115873}]}]}
{"op":"mcm","id":2,"clk":"AOWPAwCVwgIAu+EC","pt":1743512205937,"mc":[{"id":"1.241629436","rc":[{"atb":[[5.2,215.21],[5.1,598.42]],"batb":[[1,5.1,598.42],[0,5.2,215.21]],"id":56297029},{"atb":[[6.6,237.41]],"batb":[[2,6.6,237.41]],"id":26496185}]}]}
{"op":"mcm","id":2,"clk":"AOmPAwCbwgIAw+EC","pt":1743512206028,"mc":[{"id":"1.241629436","rc":[{"atb":[[1.04,0]],"id":56297029}]}]}
{"op":"mcm","id":2,"clk":"APePAwCkwgIAyOEC","pt":1743512206141,"mc":[{"id":"1.241629436","rc":[{"atb":[[5.2,217.11]],"atl":[[5.3,7.03]],"trd":[[5.3,1032.67]],"batb":[[0,5.2,217.11]],"batl":[[0,5.3,7.03]],"tv":14900.41,"id":56297029}],"tv":94851.37}]}
{"op":"mcm","id":2,"clk":"APyPAwCtwgIA0eEC","pt":1743512206232,"mc":[{"id":"1.241629436","rc":[{"atl":[[9.6,19.41]],"trd":[[9.6,855.51]],"batl":[[0,9.6,19.41]],"ltp":9.6,"tv":10685.89,"id":35856222}],"tv":94853.65}]}
{"op":"mcm","id":2,"clk":"AISQAwC1wgIA2OEC","pt":1743512206336,"mc":[{"id":"1.241629436","rc":[{"atl":[[4.8,268.59]],"batl":[[1,4.8,268.59]],"id":270592},{"atl":[[10,100.25],[9.6,25.33]],"batl":[[2,10,100.25],[0,9.6,25.33]],"id":35856222},{"atb":[[18,18.35]],"batb":[[1,18,18.35]],"id":58186642}]}]}
{"op":"mcm","id":2,"clk":"AJOQAwDGwgIA5+EC","pt":1743512206543,"mc":[{"id":"1.241629436","rc":[{"atl":[[4.8,270.59]],"batl":[[1,4.8,270.59]],"id":270592}]}]}
{"op":"mcm","id":2,"clk":"AJyQAwDRwgIA9OEC","pt":1743512206651,"mc":[{"id":"1.241629436","rc":[{"atb":[[18.5,19.76]],"trd":[[18.5,394.18]],"batb":[[0,18.5,19.76]],"tv":6876.01,"id":58186642}],"tv":94856.99}]}
{"op":"mcm","id":2,"clk":"AKWQAwDawgIA++EC","pt":1743512206745,"mc":[{"id":"1.241629436","rc":[{"atl":[[9.6,24.27]],"trd":[[9.6,857.63]],"batl":[[0,9.6,24.27]],"tv":10688.01,"id":35856222},{"atb":[[9.4,61.87]],"batb":[],"id":27115873},{"atl":[[19,13.7]],"batl":[[0,19,13.7]],"id":58186642}],"tv":94859.11}]}
{"op":"mcm","id":2,"clk":"AK6QAwDnwgIAgOIC","pt":1743512206857,"mc":[{"id":"1.241629436","rc":[{"atb":[[1.17,2.11],[5.1,598.07]],"batb":[[1,5.1,598.07]],"id":56297029}]}]}
{"op":"mcm","id":2,"clk":"ALiQAwDuwgIAh+IC","pt":1743512206918,"mc":[{"id":"1.241629436","rc":[{"atb":[[18.5,16.76]],"batb":[[0,18.5,16.76]],"id":58186642}]}]}
{"op":"mcm","id":2,"clk":"AMCQAwD1wgIAjOIC","pt":1743512207011,"mc":[{"id":"1.241629436","rc":[{"atb":[[1.17,2]],"id":56297029}]}]}
{"op":"mcm","id":2,"clk":"AMWQAwD5wgIAjuIC","pt":1743512207110,"mc":[{"id":"1.241629436","rc":[{"atb":[[5.2,217.22]],"batb":[[0,5.2,217.22]],"id":56297029},{"atb":[[18.5,13.55]],"batb":[[0,18.5,13.55]],"id":58186642}]}]}
{"op":"mcm","id":2,"clk":"AMyQAwCGwwIAneIC","pt":1743512207218,"mc":[{"id":"1.241629436","rc":[{"atl":[[4.9,315.82]],"batl":[[2,4.9,315.82]],"id":270592},{"atl":[[10,99.25]],"batl":[[2,10,99.25]],"id":35856222},{"atb":[[5,1158.47]],"batb":[[2,5,1158.47]],"id":56297029},{"atb":[[11,113.54]],"trd":[[11,1767.15]],"batb":[[0,11,113.54]],"ltp":11,"tv":5348.37,"id":44049799}],"tv":94879.11}]}
{"op":"mcm","id":2,"clk":"ANKQAwCKwwIAouIC","pt":1743512207329,"mc":[{"id":"1.241629436","rc":[{"atl":[[5.5,86.4]],"batl":[],"id":270592},{"atl":[[90,1.53]],"id":27115873},{"atl":[[11.5,96.47]],"batl":[[0,11.5,96.47]],"id":44049799}]}]}
{"op":"mcm","id":2,"clk":"ANiQAwCNwwIAquIC","pt":1743512207429,"mc":[{"id":"1.241629436","rc":[{"atl":[[13,35.47]],"batl":[[2,13,35.47]],"id":40389088},{"atb":[[9.4,7.7]],"trd":[[9.4,699.98]],"batb":[[0,9.4,7.7]],"ltp":9.4,"tv":10698.01,"id":35856222},{"atl":[[7.4,49.96]],"batl":[[1,7.4,49.96]],"id":26496185}],"tv":94889.11}]}
{"op":"mcm","id":2,"clk":"AN2QAwCTwwIAr+IC","pt":1743512207519,"mc":[{"id":"1.241629436","rc":[{"atb":[[4.6,269.95],[1.03,288.24]],"batb":[[0,4.6,269.95]],"id":270592},{"atl":[[9.8,52.14]],"batl":[[1,9.8,52.14]],"id":35856222}]}]}
{"op":"mcm","id":2,"clk":"AOSQAwCawwIAs+IC","pt":1743512207621,"mc":[{"id":"1.241629436","rc":[{"atb":[[7,63.63]],"trd":[[7,1654.61]],"batb":[[0,7,63.63]],"tv":15749.81,"id":26496185}],"tv":94909.11}]}
{"op":"mcm","id":2,"clk":"AOyQAwCgwwIAu+IC","pt":1743512207722,"mc":[{"id":"1.241629436","rc":[{"atb":[[11.5,20.97]],"trd":[[11.5,1807.52]],"batb":[[0,11.5,20.97]],"ltp":11.5,"tv":7355.78,"id":40389088},{"atb":[[1.03,287.56]],"id":270592}],"tv":94914.11}]}
{"op":"mcm","id":2,"clk":"APOQAwCnwwIAweIC","pt":1743512207826,"mc":[{"id":"1.241629436","rc":[{"atl":[[5.3,195.74]],"batl":[],"id":270592},{"atb":[[5.2,207.22]],"atl":[[5.3,9.28]],"batb":[[0,5.2,207.22]],"batl":[[0,5.3,9.28]],"id":56297029}]}]}
{"op":"mcm","id":2,"clk":"APmQAwCwwwIAxuIC","pt":1743512207931,"mc":[{"id":"1.241629436","rc":[{"atb":[[1.03,287.24]],"atl":[[4.7,135.15]],"batl":[[0,4.7,135.15]],"id":270592},{"atl":[[10.5,68.53]],"batl":[],"id":35856222}]}]}
{"op":"mcm","id":2,"clk":"AISRAwC4wwIAzeIC","pt":1743512208033,"mc":[{"id":"1.241629436","rc":[{"atl":[[4.7,134.83]],"trd":[[4.7,3907.96]],"batl":[[0,4.7,134.83]],"tv":24193.71,"id":270592}],"tv":94914.75}]}
{"op":"mcm","id":2,"clk":"AIuRAwC9wwIA1eIC","pt":1743512208141,"mc":[{"id":"1.241629436","rc":[{"atb":[[4.6,200.1],[4.3,165.49]],"atl":[[4.7,169.07]],"trd":[[4.6,770.26]],"batb":[[0,4.6,200.1]],"batl":[[0,4.7,169.07]],"ltp":4.6,"tv":24275.63,"id":270592}],"tv":94996.67}]}
{"op":"mcm","id":2,"clk":"AJiRAwDDwwIA3+IC","pt":1743512208234,"mc":[{"id":"1.241629436","rc":[{"atb":[[4.3,153.36]],"batb":[],"id":270592},{"atb":[[9.4,17.7]],"batb":[[0,9.4,17.7]],"id":35856222}]}]}
{"op":"mcm","id":2,"clk":"AKKRAwDNwwIA4eIC","pt":1743512208342,"mc":[{"id":"1.241629436","rc":[{"atb":[[4.6,197.78],[1.01,56966.24],[4.3,165.51]],"atl":[[4.7,166.65]],"trd":[[4.7,3912.81],[4.6,774.9]],"batb":[[0,4.6,197.78]],"batl":[[0,4.7,166.65]],"tv":24285.12,"id":270592},{"atl":[[5.6,103.96]],"batl":[],"id":56297029},{"atb":[[9.4,55.93]],"batb":[],"id":27115873}],"tv":95006.16}]}
{"op":"mcm","id":2,"clk":"AKyRAwDdwwIA8eIC","pt":1743512208453,"mc":[{"id":"1.241629436","rc":[{"atb":[[11,60.44]],"batb":[[1,11,60.44]],"id":40389088},{"atb":[[1.01,56966.23]],"atl":[[5.3,205.74],[4.8,280.59]],"batl":[[1,4.8,280.59]],"id":270592},{"atb":[[9.4,7.7]],"trd":[[9.4,719.98]],"batb":[[0,9.4,7.7]],"tv":10718.01,"id":35856222},{"atl":[[1000,6.92]],"id":56297029},{"atl":[[25,8.98],[19,15.46]],"batl":[[0,19,15.46]],"id":58186642}],"tv":95026.16}]}
{"op":"mcm","id":2,"clk":"ALCRAwDfwwIA+OIC","pt":1743512208544,"mc":[{"id":"1.241629436","rc":[{"atb":[[1.01,56965.23]],"atl":[[4.8,225.59]],"batl":[[1,4.8,225.59]],"id":270592},{"atl":[[11,26.45],[9.6,27.79]],"batl":[[0,9.6,27.79]],"id":35856222},{"atl":[[1000,6.49]],"id":56297029}]}]}
{"op":"mcm","id":2,"clk":"ALmRAwDnwwIAgeMC","pt":1743512208648,"mc":[{"id":"1.241629436","rc":[{"atb":[[11,63.46]],"batb":[[1,11,63.46]],"id":40389088},{"atl":[[4.7,165.65]],"trd":[[4.7,3914.79]],"batl":[[0,4.7,165.65]],"ltp":4.7,"tv":24287.1,"id":270592},{"atb":[[9.4,0]],"atl":[[9.4,1],[9.6,31.31]],"trd":[[9.4,737.98]],"batb":[[2,8.8,49.21],[1,9,43.22],[0,9.2,53.39]],"batl":[[2,9.8,52.14],[1,9.6,31.31],[0,9.4,1]],"tv":10736.01,"id":35856222},{"atb":[[50,11.27]],"trd":[[50,145.08]],"batb":[[0,50,11.27]],"ltp":50,"tv":2178.21,"id":59626646},{"atl":[[5.3,9.71]],"batl":[[0,5.3,9.71]],"id":56297029}],"tv":95047.8}]}
{"op":"mcm","id":2,"clk":"AL6RAwDtwwIAjeMC","pt":1743512208710,"mc":[{"id":"1.241629436","rc":[{"atb":[[1.01,56964.24]],"atl":[[4.7,177.8]],"batl":[[0,4.7,177.8]],"id":270592},{"atb":[[17,33.46]],"atl":[[19,6.8]],"batb":[],"batl":[[0,19,6.8]],"id":58186642},{"atb":[[7,40.63],[2,50.01]],"trd":[[7,1708.61]],"batb":[[0,7,40.63]],"tv":15803.81,"id":26496185},{"atl":[[11.5,101.49]],"batl":[[0,11.5,101.49]],"id":44049799}],"tv":95101.8}]}
{"op":"mcm","id":2,"clk":"AMiRAwD0wwIAlOMC","pt":1743512208858,"mc":[{"id":"1.241629436","rc":[{"atl":[[4.7,174.65],[4.9,303.13]],"trd":[[4.7,3916.77]],"batl":[[2,4.9,303.13],[0,4.7,174.65]],"tv":24289.08,"id":270592},{"atb":[[1.17,7.35],[9,38.75]],"atl":[[9.4,12.52]],"trd":[[9.4,739.98]],"batb":[[1,9,38.75]],"batl":[[0,9.4,12.52]],"tv":10738.01,"id":35856222},{"atl":[[5.3,7.46]],"batl":[[0,5.3,7.46]],"id":56297029},{"atb":[[18.5,19.62]],"atl":[[25,5.95]],"batb":[[0,18.5,19.62]],"batl":[],"id":58186642},{"atb":[[6,151.54]],"batb":[],"id":26496185}],"tv":95105.78}]}
{"op":"mcm","id":2,"clk":"ANeRAwCDxAIAo+MC","pt":1743512209017,"mc":[{"id":"1.241629436","rc":[{"atb":[[1.17,7.15],[9.2,38.39]],"atl":[[9.4,0],[9.6,32.36]],"trd":[[9.4,765.02]],"batb":[[0,9.2,38.39]],"batl":[[2,10,99.25],[1,9.8,52.14],[0,9.6,32.36]],"tv":10763.05,"id":35856222},{"atb":[[7,38.31]],"trd":[[7,1713.25]],"batb":[[0,7,38.31]],"tv":15808.45,"id":26496185}],"tv":95135.46}]}
{"op":"mcm","id":2,"clk":"AOCRAwCLxAIAqeMC","pt":1743512209116,"mc":[{"id":"1.241629436","rc":[{"atb":[[9.4,0.2],[9.2,37.03],[9,37.32]],"batb":[[1,9,37.32],[0,9.2,37.23]],"id":35856222},{"atb":[[7,28.87]],"trd":[[7,1732.13]],"batb":[[0,7,28.87]],"tv":15827.33,"id":26496185}],"tv":95154.34}]}
{"op":"mcm","id":2,"clk":"AOaRAwCRxAIAseMC","pt":1743512209220,"mc":[{"id":"1.241629436","rc":[{"atl":[[9.6,31.31]],"batl":[[0,9.6,31.31]],"id":35856222},{"atb":[[6.8,232.42]],"batb":[[1,6.8,232.42]],"id":26496185}]}]}
{"op":"mcm","id":2,"clk":"AOyRAwCYxAIAuOMC","pt":1743512209322,"mc":[{"id":"1.241629436","rc":[{"atb":[[9.6,37.97]],"batb":[],"id":40389088},{"atl":[[19,5.8]],"trd":[[19,359.03]],"batl":[[0,19,5.8]],"ltp":19,"tv":6878.01,"id":58186642}],"tv":95156.34}]}
{"op":"mcm","id":2,"clk":"AP2RAwCmxAIAyuMC","pt":1743512209526,"mc":[{"id":"1.241629436","rc":[{"atl":[[4.7,179.65]],"batl":[[0,4.7,179.65]],"id":270592},{"atb":[[10.5,71.61]],"batb":[[1,10.5,71.61]],"id":44049799}]}]}
{"op":"mcm","id":2,"clk":"AI+SAwC0xAIA1eMC","pt":1743512209739,"mc":[{"id":"1.241629436","rc":[{"atb":[[11.5,4.97]],"trd":[[11.5,1839.51]],"batb":[[0,11.5,4.97]],"tv":7387.77,"id":40389088},{"atl":[[5.1,158.85]],"batl":[],"id":270592},{"atl":[[70,7.17]],"batl":[],"id":59626646},{"atl":[[7.8,90.96]],"batl":[],"id":26496185}],"tv":95188.33}]}
{"op":"mcm","id":2,"clk":"AJmSAwC7xAIA2+MC","pt":1743512209830,"mc":[{"id":"1.241629436","rc":[{"atb":[[11.5,2.4]],"atl":[[12,55.54]],"trd":[[11.5,1841.81]],"batb":[[0,11.5,2.4]],"batl":[[0,12,55.54]],"tv":7390.07,"id":40389088},{"atl":[[5.3,7.43]],"trd":[[5.3,1032.73]],"batl":[[0,5.3,7.43]],"tv":14900.47,"id":56297029}],"tv":95190.69}]}
{"op":"mcm","id":2,"clk":"AKSSAwDHxAIA5OMC","pt":1743512209944,"mc":[{"id":"1.241629436","rc":[{"atb":[[11.5,0]],"atl":[[11.5,16]],"trd":[[11.5,1846.61]],"batb":[[2,10,76.37],[1,10.5,54.78],[0,11,63.46]],"batl":[[2,12.5,114.27],[1,12,55.54],[0,11.5,16]],"tv":7394.87,"id":40389088},{"atb":[[5.2,204.9]],"atl":[[5.3,9.68]],"trd":[[5.2,4312.24]],"batb":[[0,5.2,204.9]],"batl":[[0,5.3,9.68]],"ltp":5.2,"tv":14905.11,"id":56297029}],"tv":95200.13}]}
{"op":"mcm","id":2,"clk":"AK+SAwDPxAIA7OMC","pt":1743512210042,"mc":[{"id":"1.241629436","rc":[{"atl":[[11.5,20.99]],"batl":[[0,11.5,20.99]],"id":40389088},{"atb":[[9.2,38.12]],"batb":[[0,9.2,38.32]],"id":35856222}]}]}
{"op":"mcm","id":2,"clk":"ALmSAwDWxAIA8+MC","pt":1743512210146,"mc":[{"id":"1.241629436","rc":[{"atb":[[9.4,32.59],[9.6,39.21]],"atl":[[12,48.19]],"batb":[],"batl":[[1,12,48.19]],"id":40389088},{"atb":[[9.2,53.12]],"batb":[[0,9.2,53.32]],"id":35856222},{"atb":[[7,48.87]],"batb":[[0,7,48.87]],"id":26496185}]}]}
{"op":"mcm","id":2,"clk":"AMuSAwDjxAIA/OMC","pt":1743512210346,"mc":[{"id":"1.241629436","rc":[{"atb":[[4.6,232.78]],"batb":[[0,4.6,232.78]],"id":270592},{"atb":[[7,47.87]],"trd":[[7,1734.13]],"batb":[[0,7,47.87]],"tv":15829.33,"id":26496185}],"tv":95202.13}]}
{"op":"mcm","id":2,"clk":"AOWSAwD0xAIAmeQC","pt":1743512210659,"mc":[{"id":"1.241629436","rc":[{"atb":[[15,12.63]],"batb":[],"id":58186642}]}]}
{"op":"mcm","id":2,"clk":"AOqSAwD6xAIAnuQC","pt":1743512210711,"mc":[{"id":"1.241629436","rc":[{"atl":[[13,27.24]],"batl":[],"id":40389088},{"atb":[[4.4,217.77]],"batb":[[2,4.4,217.77]],"id":270592},{"atb":[[4.1,88.76]],"id":56297029},{"atb":[[6.6,235.02]],"batb":[[2,6.6,235.02]],"id":26496185}]}]}
{"op":"mcm","id":2,"clk":"APGSAwCCxQIAp+QC","pt":1743512210817,"mc":[{"id":"1.241629436","rc":[{"atl":[[1000,0.35],[12.5,113.97]],"batl":[[2,12.5,113.97]],"id":40389088},{"atb":[[4.6,238.14]],"atl":[[4.9,313.13],[4.8,227.77]],"batb":[[0,4.6,238.14]],"batl":[[2,4.9,313.13],[1,4.8,227.77]],"id":270592},{"atb":[[9,38.75]],"batb":[[1,9,38.75]],"id":35856222},{"atb":[[5.2,206.37],[4.5,104.15]],"atl":[[5.3,28.1]],"batb":[[0,5.2,206.37]],"batl":[[0,5.3,28.1]],"id":56297029},{"atb":[[18,17.05]],"atl":[[19,4.04]],"batb":[[1,18,17.05]],"batl":[[0,19,4.04]],"id":58186642},{"atb":[[7,46.43]],"atl":[[7.2,162.88]],"batb":[[0,7,46.43]],"batl":[[0,7.2,162.88]],"id":26496185}]}]}
{"op":"mcm","id":2,"clk":"AIWTAwCRxQIAuOQC","pt":1743512211026,"mc":[{"id":"1.241629436","rc":[{"atb":[[11,59.85]],"atl":[[1000,0.25]],"batb":[[0,11,59.85]],"id":40389088}]}]}
{"op":"mcm","id":2,"clk":"AI6TAwCYxQIAv+QC","pt":1743512211129,"mc":[{"id":"1.241629436","rc":[{"atl":[[12,48.29]],"batl":[[1,12,48.29]],"id":40389088}]}]}
{"op":"mcm","id":2,"clk":"AJ+TAwCoxQIA0OQC","pt":1743512211338,"mc":[{"id":"1.241629436","rc":[{"atl":[[4.7,177.16]],"trd":[[4.7,3921.75]],"batl":[[0,4.7,177.16]],"tv":24294.06,"id":270592},{"atb":[[5.2,204.04]],"trd":[[5.2,4316.9]],"batb":[[0,5.2,204.04]],"tv":14909.77,"id":56297029}],"tv":95211.77}]}
{"op":"mcm","id":2,"clk":"AKqTAwC2xQIA2uQC","pt":1743512211536,"mc":[{"id":"1.241629436","rc":[{"atb":[[4.6,240.14]],"batb":[[0,4.6,240.14]],"id":270592},{"atb":[[5.2,203.04]],"trd":[[5.2,4318.9]],"batb":[[0,5.2,203.04]],"tv":14911.77,"id":56297029}],"tv":95213.77}]}
{"op":"mcm","id":2,"clk":"ALWTAwDBxQIA4+QC","pt":1743512211643,"mc":[{"id":"1.241629436","rc":[{"atb":[[4.5,257.68]],"batb":[[1,4.5,257.68]],"id":270592},{"atb":[[9.4,0],[9.2,52.32]],"trd":[[9.4,765.42],[9.2,732.37]],"batb":[[0,9.2,52.32]],"ltp":9.2,"tv":10765.05,"id":35856222},{"atb":[[50,10.43]],"trd":[[50,146.76]],"batb":[[0,50,10.43]],"tv":2179.89,"id":59626646},{"atb":[[7,44.11]],"trd":[[7,1738.77]],"batb":[[0,7,44.11]],"tv":15833.97,"id":26496185}],"tv":95222.09}]}
{"op":"mcm","id":2,"clk":"AMKTAwDMxQIA9uQC","pt":1743512211850,"mc":[{"id":"1.241629436","rc":[{"atb":[[6.8,237.13]],"batb":[[1,6.8,237.13]],"id":26496185}]}]}
{"op":"mcm","id":2,"clk":"AN2TAwDmxQIAjOUC","pt":1743512212153,"mc":[{"id":"1.241629436","rc":[{"atb":[[4.6,238.56]],"trd":[[4.6,778.06]],"batb":[[0,4.6,238.56]],"ltp":4.6,"tv":24297.22,"id":270592}],"tv":95225.25}]}
{"op":"mcm","id":2,"clk":"AOSTAwDyxQIAkuUC","pt":1743512212214,"mc":[{"id":"1.241629436","rc":[{"atb":[[7,35.54]],"trd":[[7,1755.91]],"batb":[[0,7,35.54]],"tv":15851.11,"id":26496185}],"tv":95242.39}]}
{"op":"mcm","id":2,"clk":"APWTAwCGxgIApOUC","pt":1743512212417,"mc":[{"id":"1.241629436","rc":[{"atb":[[5.1,569.09]],"batb":[[1,5.1,569.09]],"id":56297029}]}]}
{"op":"mcm","id":2,"clk":"APuTAwCQxgIAqeUC","pt":1743512212521,"mc":[{"id":"1.241629436","rc":[{"atl":[[7.4,53.96]],"batl":[[1,7.4,53.96]],"id":26496185}]}]}
{"op":"mcm","id":2,"clk":"AIWUAwCkxgIAt+UC","pt":1743512212722,"mc":[{"id":"1.241629436","rc":[{"atb":[[10.5,58.48]],"atl":[[12.5,111.67]],"batb":[[1,10.5,58.48]],"batl":[[2,12.5,111.67]],"id":40389088}]}]}
{"op":"mcm","id":2,"clk":"AIyUAwCuxgIAv+UC","pt":1743512212827,"mc":[{"id":"1.241629436","rc":[{"atb":[[1.17,2.23]],"atl":[[12,50.59]],"batl":[[1,12,50.59]],"id":40389088},{"atb":[[4.5,258.75]],"atl":[[4.7,182.46]],"batb":[[1,4.5,258.75]],"batl":[[0,4.7,182.46]],"id":270592}]}]}
{"op":"mcm","id":2,"clk":"AJSUAwC4xgIAx+UC","pt":1743512212934,"mc":[{"id":"1.241629436","rc":[{"atb":[[1.17,2]],"id":40389088},{"atb":[[9.2,53.68]],"batb":[[0,9.2,53.68]],"id":35856222}]}]}
{"op":"mcm","id":2,"clk":"AJyUAwDBxgIAzOUC","pt":1743512213039,"mc":[{"id":"1.241629436","rc":[{"atb":[[11,43.79]],"trd":[[11,413.28]],"batb":[[0,11,43.79]],"ltp":11,"tv":7427.45,"id":40389088},{"atl":[[4.9,305.59]],"batl":[[2,4.9,305.59]],"id":270592},{"atl":[[9.6,32.36]],"batl":[[0,9.6,32.36]],"id":35856222},{"atb":[[5,1130.68]],"batb":[[2,5,1130.68]],"id":56297029},{"atb":[[17,30.24]],"batb":[],"id":58186642},{"atb":[[6.6,214.8]],"batb":[[2,6.6,214.8]],"id":26496185}],"tv":95274.97}]}
{"op":"mcm","id":2,"clk":"AKSUAwDJxgIA0OUC","pt":1743512213143,"mc":[{"id":"1.241629436","rc":[{"atl":[[11.5,27.21]],"batl":[[0,11.5,27.21]],"id":40389088}]}]}
{"op":"mcm","id":2,"clk":"AK6UAwDVxgIA1+UC","pt":1743512213245,"mc":[{"id":"1.241629436","rc":[{"atb":[[11,59.74]],"batb":[[0,11,59.74]],"id":40389088},{"atl":[[4.7,176.34]],"batl":[[0,4.7,176.34]],"id":270592}]}]}
{"op":"mcm","id":2,"clk":"ALqUAwDhxgIA4uUC","pt":1743512213345,"mc":[{"id":"1.241629436","rc":[{"atb":[[9.4,31.29],[11,64.45],[9.6,37.97]],"batb":[[0,11,64.45]],"id":40389088}]}]}
{"op":"mcm","id":2,"clk":"AMiUAwDkxgIA5eUC","pt":1743512213448,"mc":[{"id":"1.241629436","rc":[{"atb":[[11,67.45]],"batb":[[0,11,67.45]],"id":40389088},{"atb":[[5,1129.7]],"atl":[[5.4,25.83],[5.3,0]],"trd":[[5.4,139.64],[5.3,1088.93]],"batb":[[2,5,1129.7]],"batl":[[2,5.6,103.96],[1,5.5,66.65],[0,5.4,25.83]],"ltp":5.4,"tv":15031.77,"id":56297029},{"atl":[[19,3.03]],"trd":[[19,361.05]],"batl":[[0,19,3.03]],"tv":6880.03,"id":58186642}],"tv":95396.99}]}
{"op":"mcm","id":2,"clk":"ANaUAwDqxgIA7OUC","pt":1743512213550,"mc":[{"id":"1.241629436","rc":[{"atb":[[5.3,2]],"batb":[[2,5.1,569.09],[1,5.2,203.04],[0,5.3,2]],"id":56297029}]}]}
{"op":"mcm","id":2,"clk":"AN+UAwDzxgIA9eUC","pt":1743512213651,"mc":[{"id":"1.241629436","rc":[{"atb":[[9.2,52.32]],"batb":[[0,9.2,52.32]],"id":35856222},{"atb":[[5.3,25.69]],"atl":[[5.6,103.16]],"batb":[[0,5.3,25.69]],"batl":[[2,5.6,103.16]],"id":56297029},{"atl":[[19,2.38]],"trd":[[19,362.35]],"batl":[[0,19,2.38]],"tv":6881.33,"id":58186642}],"tv":95398.29}]}
{"op":"mcm","id":2,"clk":"AOaUAwD9xgIAgOYC","pt":1743512213754,"mc":[{"id":"1.241629436","rc":[{"atb":[[11,66.62]],"batb":[[0,11,66.62]],"id":40389088},{"atb":[[4.6,236.98]],"trd":[[4.6,781.22]],"batb":[[0,4.6,236.98]],"tv":24300.38,"id":270592},{"atb":[[5.3,49.24],[4.8,127.52]],"atl":[[1000,6.86]],"trd":[[5.3,1096.93]],"batb":[[0,5.3,49.24]],"ltp":5.3,"tv":15039.77,"id":56297029},{"atl":[[11.5,96.47]],"batl":[[0,11.5,96.47]],"id":44049799}],"tv":95409.45}]}
{"op":"mcm","id":2,"clk":"AOyUAwCGxwIAieYC","pt":1743512213857,"mc":[{"id":"1.241629436","rc":[{"atb":[[1.17,2.49]],"id":40389088},{"atb":[[5,1130.68],[5.1,571.15]],"atl":[[1000,6.49],[5.9,40.59],[5.7,82.69],[5.8,92.59],[5.6,92.44]],"batb":[[2,5.1,571.15]],"batl":[[2,5.6,92.44]],"id":56297029}]}]}
{"op":"mcm","id":2,"clk":"APSUAwCPxwIAkOYC","pt":1743512213915,"mc":[{"id":"1.241629436","rc":[{"atb":[[11,53.62]],"atl":[[11.5,21.39]],"trd":[[11.5,1858.25],[11,439.28]],"batb":[[0,11,53.62]],"batl":[[0,11.5,21.39]],"tv":7465.09,"id":40389088},{"atb":[[1.08,14.33],[5.3,59.42]],"trd":[[5.3,1097.67]],"batb":[[0,5.3,59.42]],"tv":15040.51,"id":56297029},{"atb":[[18.5,13.8]],"trd":[[18.5,405.82]],"batb":[[0,18.5,13.8]],"ltp":18.5,"tv":6892.97,"id":58186642},{"atl":[[11.5,101.49]],"batl":[[0,11.5,101.49]],"id":44049799}],"tv":95459.47}]}
{"op":"mcm","id":2,"clk":"APeUAwCWxwIAleYC","pt":1743512214012,"mc":[{"id":"1.241629436","rc":[{"atb":[[1.17,2],[11,50.6]],"batb":[[0,11,50.6]],"id":40389088},{"atb":[[2.84,0],[5.3,86.63]],"batb":[[0,5.3,86.63]],"id":56297029}]}]}
{"op":"mcm","id":2,"clk":"AISVAwCfxwIAo+YC","pt":1743512214123,"mc":[{"id":"1.241629436","rc":[{"atb":[[11,51.09]],"batb":[[0,11,51.09]],"id":40389088}]}]}
{"op":"mcm","id":2,"clk":"AImVAwCxxwIAq+YC","pt":1743512214224,"mc":[{"id":"1.241629436","rc":[{"atb":[[5.3,102.06]],"batb":[[0,5.3,102.06]],"id":56297029}]}]}
{"op":"mcm","id":2,"clk":"AJKVAwC2xwIAtOYC","pt":1743512214322,"mc":[{"id":"1.241629436","rc":[{"atb":[[1.08,12.08]],"id":56297029}]}]}
{"op":"mcm","id":2,"clk":"AKCVAwC5xwIAvuYC","pt":1743512214436,"mc":[{"id":"1.241629436","rc":[{"atb":[[7.4,25.95]],"id":27115873}]}]}
{"op":"mcm","id":2,"clk":"AKWVAwDExwIAxeYC","pt":1743512214530,"mc":[{"id":"1.241629436","rc":[{"atb":[[5.1,575.24]],"atl":[[5.4,22.09]],"batb":[[2,5.1,575.24]],"batl":[[0,5.4,22.09]],"id":56297029}]}]}
{"op":"mcm","id":2,"clk":"ALaVAwDPxwIA2OYC","pt":1743512214740,"mc":[{"id":"1.241629436","rc":[{"atl":[[9.6,33.36]],"batl":[[0,9.6,33.36]],"id":35856222},{"atb":[[1.08,12]],"id":56297029}]}]}
{"op":"mcm","id":2,"clk":"ALyVAwDYxwIA3OYC","pt":1743512214840,"mc":[{"id":"1.241629436","rc":[{"atb":[[55,2.47]],"atl":[[55,0]],"trd":[[55,396.46]],"batb":[[2,48,9.65],[1,50,10.43],[0,55,2.47]],"batl":[[2,70,7.17],[1,65,3.61],[0,60,13.66]],"ltp":55,"tv":2183.75,"id":59626646},{"atb":[[2.86,0.08]],"atl":[[5.4,38.04]],"batl":[[0,5.4,38.04]],"id":56297029}],"tv":95463.33}]}
{"op":"mcm","id":2,"clk":"AMWVAwDjxwIA6OYC","pt":1743512214948,"mc":[{"id":"1.241629436","rc":[{"atb":[[9.2,52.59]],"batb":[[0,9.2,52.59]],"id":35856222},{"atb":[[55,0],[50,11.14]],"atl":[[55,3.19],[70,3.85]],"trd":[[55,401.4]],"batb":[[2,46,8.91],[1,48,9.65],[0,50,11.14]],"batl":[[2,65,3.61],[1,60,13.66],[0,55,3.19]],"tv":2188.69,"id":59626646},{"atl":[[5.4,48.94],[5.8,93.07]],"batl":[[0,5.4,48.94]],"id":56297029}],"tv":95468.27}]}
{"op":"mcm","id":2,"clk":"AM2VAwDnxwIA8uYC","pt":1743512215051,"mc":[{"id":"1.241629436","rc":[{"atb":[[50,9.87]],"atl":[[55,3.42],[85,2.63],[80,5.71]],"trd":[[50,149.3]],"batb":[[0,50,9.87]],"batl":[[0,55,3.42]],"ltp":50,"tv":2191.23,"id":59626646},{"atb":[[5.3,97.06]],"trd":[[5.3,1107.67]],"batb":[[0,5.3,97.06]],"tv":15050.51,"id":56297029},{"atb":[[18,18.05]],"batb":[[1,18,18.05]],"id":58186642}],"tv":95480.81}]}
{"op":"mcm","id":2,"clk":"ANyVAwD2xwIA/OYC","pt":1743512215262,"mc":[{"id":"1.241629436","rc":[{"atl":[[4.7,174.34]],"trd":[[4.7,3925.76]],"batl":[[0,4.7,174.34]],"ltp":4.7,"tv":24304.39,"id":270592},{"atb":[[50,14.25]],"atl":[[85,2.25],[80,5.28]],"batb":[[0,50,14.25]],"batl":[],"id":59626646}],"tv":95484.82}]}
{"op":"mcm","id":2,"clk":"AOmVAwCGyAIAhucC","pt":1743512215431,"mc":[{"id":"1.241629436","rc":[{"atb":[[11,67.45]],"batb":[[0,11,67.45]],"id":40389088},{"atb":[[50,9.87]],"batb":[[0,50,9.87]],"id":59626646}]}]}
{"op":"mcm","id":2,"clk":"AP+VAwCWyAIAlecC","pt":1743512215623,"mc":[{"id":"1.241629436","rc":[{"atl":[[9.6,34.36]],"batl":[[0,9.6,34.36]],"id":35856222}]}]}
{"op":"mcm","id":2,"clk":"AJWWAwCkyAIAqOcC","pt":1743512215828,"mc":[{"id":"1.241629436","rc":[{"atl":[[4.7,194.34]],"batl":[[0,4.7,194.34]],"id":270592},{"atb":[[5.2,208.04]],"batb":[[1,5.2,208.04]],"id":56297029}]}]}
{"op":"mcm","id":2,"clk":"AK2WAwCyyAIAuOcC","pt":1743512216028,"mc":[{"id":"1.241629436","rc":[{"atb":[[50,10.93]],"atl":[[55,5.04]],"batb":[[0,50,10.93]],"batl":[[0,55,5.04]],"id":59626646}]}]}
{"op":"mcm","id":2,"clk":"ALmWAwDAyAIAwecC","pt":1743512216134,"mc":[{"id":"1.241629436","rc":[{"atb":[[9.4,32.59],[9.6,39.21]],"batb":[],"id":40389088}]}]}
{"op":"mcm","id":2,"clk":"AL2WAwDJyAIAy+cC","pt":1743512216234,"mc":[{"id":"1.241629436","rc":[{"atb":[[18.5,12.8]],"trd":[[18.5,407.82]],"batb":[[0,18.5,12.8]],"tv":6894.97,"id":58186642}],"tv":95486.82}]}
{"op":"mcm","id":2,"clk":"AMaWAwDNyAIA2OcC","pt":1743512216336,"mc":[{"id":"1.241629436","rc":[{"atl":[[12,53.94]],"batl":[[1,12,53.94]],"id":40389088},{"atl":[[5.6,96.39]],"batl":[[2,5.6,96.39]],"id":56297029},{"atb":[[18.5,20.34]],"atl":[[19,9.72]],"batb":[[0,18.5,20.34]],"batl":[[0,19,9.72]],"id":58186642},{"atb":[[11,118.28]],"batb":[[0,11,118.28]],"id":44049799}]}]}
{"op":"mcm","id":2,"clk":"AM2WAwDWyAIA3ucC","pt":1743512216443,"mc":[{"id":"1.241629436","rc":[{"atb":[[1.17,2.16],[11,66.96]],"atl":[[1000,1.03],[12,53.84]],"batb":[[0,11,66.96]],"batl":[[1,12,53.84]],"id":40389088},{"atb":[[4.6,233.27]],"batb":[[0,4.6,233.27]],"id":270592},{"atb":[[1.17,7.43]],"atl":[[9.6,35.74]],"batl":[[0,9.6,35.74]],"id":35856222},{"atb":[[5.2,207.85],[5.1,573.18]],"atl":[[5.4,55.21]],"batb":[[2,5.1,573.18],[1,5.2,207.85]],"batl":[[0,5.4,55.21]],"id":56297029},{"atb":[[10,132.72]],"atl":[[11,73.27],[10.5,141.59]],"trd":[[10,921.23]],"batb":[[0,10,132.72]],"batl":[[1,11,73.27],[0,10.5,141.59]],"tv":7618.08,"id":27115873},{"atb":[[7,32.8]],"atl":[[7.4,53.12]],"batb":[[0,7,32.8]],"batl":[[1,7.4,53.12]],"id":26496185}],"tv":95488.8}]}
{"op":"mcm","id":2,"clk":"ANOWAwDgyAIA6ecC","pt":1743512216543,"mc":[{"id":"1.241629436","rc":[{"atb":[[1.17,2]],"atl":[[1000,0.25]],"id":40389088},{"atb":[[1.17,7.15]],"id":35856222},{"atb":[[18,19.41]],"atl":[[19,10.55]],"batb":[[1,18,19.41]],"batl":[[0,19,10.55]],"id":58186642},{"atb":[[1.17,2.37]],"atl":[[11.5,98.49]],"trd":[[11.5,1098.73]],"batl":[[0,11.5,98.49]],"ltp":11.5,"tv":5354.37,"id":44049799}],"tv":95494.8}]}
{"op":"mcm","id":2,"clk":"AOCWAwDpyAIA8+cC","pt":1743512216658,"mc":[{"id":"1.241629436","rc":[{"atb":[[10.5,58.64]],"atl":[[11.5,22.17]],"batb":[[1,10.5,58.64]],"batl":[[0,11.5,22.17]],"id":40389088},{"atb":[[9,39.03]],"atl":[[9.6,36.74]],"batb":[[1,9,39.03]],"batl":[[0,9.6,36.74]],"id":35856222},{"atb":[[5.3,96.06]],"trd":[[5.3,1109.67]],"batb":[[0,5.3,96.06]],"tv":15052.51,"id":56297029},{"atb":[[1.17,2]],"id":44049799}],"tv":95496.8}]}
{"op":"mcm","id":2,"clk":"AOWWAwD0yAIA+ucC","pt":1743512216753,"mc":[{"id":"1.241629436","rc":[{"atb":[[11,118.65]],"batb":[[0,11,118.65]],"id":44049799}]}]}
{"op":"mcm","id":2,"clk":"APiWAwCByQIAiOgC","pt":1743512216959,"mc":[{"id":"1.241629436","rc":[{"atb":[[4.6,236.36]],"batb":[[0,4.6,236.36]],"id":270592},{"atl":[[5.4,60.21]],"batl":[[0,5.4,60.21]],"id":56297029}]}]}
{"op":"mcm","id":2,"clk":"AI+XAwCWyQIAmugC","pt":1743512217124,"mc":[{"id":"1.241629436","rc":[{"atb":[[5.3,94.06]],"trd":[[5.3,1113.67]],"batb":[[0,5.3,94.06]],"tv":15056.51,"id":56297029}],"tv":95500.8}]}
{"op":"mcm","id":2,"clk":"AJ+XAwCmyQIAp+gC","pt":1743512217330,"mc":[{"id":"1.241629436","rc":[{"atb":[[4.6,252.36]],"batb":[[0,4.6,252.36]],"id":270592}]}]}
{"op":"mcm","id":2,"clk":"AKiXAwCtyQIAq+gC","pt":1743512217429,"mc":[{"id":"1.241629436","rc":[{"atb":[[4.6,249.27]],"batb":[[0,4.6,249.27]],"id":270592}]}]}
{"op":"mcm","id":2,"clk":"AK6XAwC1yQIAtegC","pt":1743512217534,"mc":[{"id":"1.241629436","rc":[{"atl":[[9.6,37.74]],"batl":[[0,9.6,37.74]],"id":35856222}]}]}
{"op":"mcm","id":2,"clk":"ALaXAwC7yQIAwOgC","pt":1743512217641,"mc":[{"id":"1.241629436","rc":[{"atb":[[5.3,93.06]],"trd":[[5.3,1115.67]],"batb":[[0,5.3,93.06]],"tv":15058.51,"id":56297029}],"tv":95502.8}]}
{"op":"mcm","id":2,"clk":"AL2XAwDByQIAxOgC","pt":1743512217731,"mc":[{"id":"1.241629436","rc":[{"atb":[[7,0],[6.8,224.03]],"trd":[[7,1821.53],[6.8,1670.36]],"batb":[[2,6.4,260.94],[1,6.6,214.8],[0,6.8,224.03]],"ltp":6.8,"tv":15942.93,"id":26496185}],"tv":95594.62}]}
{"op":"mcm","id":2,"clk":"AMOXAwDKyQIAzOgC","pt":1743512217842,"mc":[{"id":"1.241629436","rc":[{"atb":[[4.4,229.88]],"atl":[[4.7,194.13]],"batb":[[2,4.4,229.88]],"batl":[[0,4.7,194.13]],"id":270592},{"atb":[[8.8,49.11]],"atl":[[9.8,46.12]],"batb":[[2,8.8,49.11]],"batl":[[1,9.8,46.12]],"id":35856222},{"atb":[[5.3,91.06]],"atl":[[5.7,71.94],[5.8,103.6]],"trd":[[5.3,1119.67]],"batb":[[0,5.3,91.06]],"batl":[],"tv":15062.51,"id":56297029},{"atb":[[9.4,61.44]],"batb":[],"id":27115873},{"atb":[[6.2,163.19]],"atl":[[7,24.51],[7.2,170.88]],"batb":[],"batl":[[2,7.4,53.12],[1,7.2,170.88],[0,7,24.51]],"id":26496185},{"atl":[[11.5,93.47]],"batl":[[0,11.5,93.47]],"id":44049799}],"tv":95598.62}]}
{"op":"mcm","id":2,"clk":"AMqXAwDSyQIA1OgC","pt":1743512217940,"mc":[{"id":"1.241629436","rc":[{"atl":[[7,32.61]],"batl":[[0,7,32.61]],"id":26496185}]}]}
{"op":"mcm","id":2,"clk":"ANOXAwDZyQIA2ugC","pt":1743512218043,"mc":[{"id":"1.241629436","rc":[{"atb":[[5.3,48.96]],"trd":[[5.3,1203.87]],"batb":[[0,5.3,48.96]],"tv":15146.71,"id":56297029},{"atb":[[6.2,166.4],[6.4,263.93]],"batb":[[2,6.4,263.93]],"id":26496185}],"tv":95682.82}]}
{"op":"mcm","id":2,"clk":"AN2XAwDkyQIA4egC","pt":1743512218154,"mc":[{"id":"1.241629436","rc":[{"atb":[[10,82.37]],"batb":[[2,10,82.37]],"id":40389088},{"atb":[[3.7,28]],"id":270592},{"atb":[[8.4,66.35]],"atl":[[9.6,34.22]],"batb":[],"batl":[[0,9.6,34.22]],"id":35856222},{"atb":[[4.7,35.14],[4.9,69.59],[5.3,75.96],[5,1129.68],[4.8,126.52],[4,204.01]],"atl":[[5.7,82.46],[5.6,106.94]],"batb":[[0,5.3,75.96]],"batl":[[2,5.6,106.94]],"id":56297029},{"atb":[[9,26.26]],"batb":[],"id":27115873},{"atb":[[15,16.63]],"atl":[[26,5.76],[19,3.21]],"batb":[],"batl":[[0,19,3.21]],"id":58186642},{"atb":[[6,161.54]],"batb":[],"id":26496185},{"atb":[[10,92.5]],"batb":[[2,10,92.5]],"id":44049799}]}]}
{"op":"mcm","id":2,"clk":"AOKXAwDuyQIA4+gC","pt":1743512218250,"mc":[{"id":"1.241629436","rc":[{"atb":[[5.3,60.53]],"batb":[[0,5.3,60.53]],"id":56297029}]}]}
{"op":"mcm","id":2,"clk":"AOWXAwD5yQIA7egC","pt":1743512218354,"mc":[{"id":"1.241629436","rc":[{"atl":[[9.6,27.35]],"batl":[[0,9.6,27.35]],"id":35856222},{"atl":[[55,2.04]],"trd":[[55,407.4]],"batl":[[0,55,2.04]],"ltp":55,"tv":2197.23,"id":59626646},{"atb":[[6.8,223.03]],"trd":[[6.8,1672.36]],"batb":[[0,6.8,223.03]],"tv":15944.93,"id":26496185}],"tv":95690.82}]}
{"op":"mcm","id":2,"clk":"AOuXAwCEygIA/ugC","pt":1743512218467,"mc":[{"id":"1.241629436","rc":[{"atl":[[11.5,25.37]],"batl":[[0,11.5,25.37]],"id":40389088},{"atb":[[4.6,329.27]],"batb":[[0,4.6,329.27]],"id":270592},{"atb":[[50,12.43]],"batb":[[0,50,12.43]],"id":59626646},{"atb":[[10,129.13]],"trd":[[10,928.42]],"batb":[[0,10,129.13]],"tv":7625.27,"id":27115873},{"atb":[[11,115.45]],"trd":[[11,1773.55]],"batb":[[0,11,115.45]],"ltp":11,"tv":5360.77,"id":44049799}],"tv":95704.41}]}
{"op":"mcm","id":2,"clk":"APaXAwCPygIAhukC","pt":1743512218563,"mc":[{"id":"1.241629436","rc":[{"atb":[[8.6,33.39]],"batb":[],"id":35856222},{"atb":[[1.04,1.67],[1.08,100.84],[1.03,393.57]],"atl":[[7,32.67]],"batl":[[0,7,32.67]],"id":26496185}]}]}
{"op":"mcm","id":2,"clk":"APuXAwCaygIAj+kC","pt":1743512218621,"mc":[{"id":"1.241629436","rc":[{"atb":[[1.06,5400.34]],"atl":[[9.6,28.35]],"batl":[[0,9.6,28.35]],"id":35856222}]}]}
{"op":"mcm","id":2,"clk":"AISYAwCjygIAk+kC","pt":1743512218723,"mc":[{"id":"1.241629436","rc":[{"atb":[[4.5,257.68]],"batb":[[1,4.5,257.68]],"id":270592},{"atb":[[5.3,62.51]],"atl":[[1000,6.89]],"batb":[[0,5.3,62.51]],"id":56297029},{"atb":[[1.04,0.84],[1.08,100.21],[1.03,393.36]],"id":26496185}]}]}
{"op":"mcm","id":2,"clk":"AIqYAwCsygIAnOkC","pt":1743512218823,"mc":[{"id":"1.241629436","rc":[{"atl":[[1000,0.37]],"id":40389088},{"atl":[[4.7,188.83]],"batl":[[0,4.7,188.83]],"id":270592},{"atb":[[9.2,51.19]],"trd":[[9.2,735.17]],"batb":[[0,9.2,51.19]],"tv":10767.85,"id":35856222},{"atb":[[5.2,207.74]],"atl":[[1000,6.49]],"batb":[[1,5.2,207.74]],"id":56297029}],"tv":95707.21}]}
{"op":"mcm","id":2,"clk":"AI6YAwCyygIAoukC","pt":1743512218922,"mc":[{"id":"1.241629436","rc":[{"atb":[[11,65.56]],"trd":[[11,442.07]],"batb":[[0,11,65.56]],"tv":7467.88,"id":40389088},{"atb":[[9.4,2]],"batb":[[2,9,39.03],[1,9.2,51.19],[0,9.4,2]],"id":35856222},{"atl":[[5.5,67.05]],"batl":[[1,5.5,67.05]],"id":56297029},{"atb":[[1.04,0],[1.08,100],[1.03,392.73]],"id":26496185},{"atb":[[11,114.06]],"trd":[[11,1776.34]],"batb":[[0,11,114.06]],"tv":5363.56,"id":44049799}],"tv":95712.79}]}
{"op":"mcm","id":2,"clk":"AJmYAwC9ygIAqOkC","pt":1743512219034,"mc":[{"id":"1.241629436","rc":[{"atl":[[1000,0.25]],"id":40389088},{"atl":[[9.6,27.3]],"batl":[[0,9.6,27.3]],"id":35856222},{"atl":[[7,30.99]],"trd":[[7,1824.88]],"batl":[[0,7,30.99]],"ltp":7,"tv":15948.28,"id":26496185}],"tv":95716.14}]}
{"op":"mcm","id":2,"clk":"AJ+YAwDHygIAs+kC","pt":1743512219139,"mc":[{"id":"1.241629436","rc":[{"atl":[[12,53.96]],"batl":[[1,12,53.96]],"id":40389088},{"atb":[[9.4,3.3]],"batb":[[0,9.4,3.3]],"id":35856222},{"atl":[[55,2.1]],"batl":[[0,55,2.1]],"id":59626646}]}]}
{"op":"mcm","id":2,"clk":"AKSYAwDQygIAu+kC","pt":1743512219235,"mc":[{"id":"1.241629436","rc":[{"atb":[[4.5,273.68]],"batb":[[1,4.5,273.68]],"id":270592},{"atl":[[1000,6.54]],"id":26496185}]}]}
{"op":"mcm","id":2,"clk":"ALKYAwDXygIAxOkC","pt":1743512219339,"mc":[{"id":"1.241629436","rc":[{"atl":[[7.4,66.09]],"batl":[[2,7.4,66.09]],"id":26496185}]}]}
{"op":"mcm","id":2,"clk":"ALmYAwDgygIAy+kC","pt":1743512219441,"mc":[{"id":"1.241629436","rc":[{"atl":[[1000,4.87]],"id":26496185}]}]}
{"op":"mcm","id":2,"clk":"AL2YAwDqygIA0ukC","pt":1743512219535,"mc":[{"id":"1.241629436","rc":[{"atl":[[9.4,14.32],[7.8,91.59],[8.8,13.5],[8.2,89.92]],"batl":[],"id":26496185}]}]}
{"op":"mcm","id":2,"clk":"AMWYAwDzygIA2+kC","pt":1743512219647,"mc":[{"id":"1.241629436","rc":[{"atl":[[19,10.35]],"batl":[[0,19,10.35]],"id":58186642}]}]}
{"op":"mcm","id":2,"clk":"AMmYAwD5ygIA4OkC","pt":1743512219745,"mc":[{"id":"1.241629436","rc":[{"atb":[[5.3,60.01]],"trd":[[5.3,1208.87]],"batb":[[0,5.3,60.01]],"tv":15151.71,"id":56297029}],"tv":95721.14}]}
{"op":"mcm","id":2,"clk":"ANWYAwCBywIA8ukC","pt":1743512219861,"mc":[{"id":"1.241629436","rc":[{"atl":[[5.6,96.39]],"batl":[[2,5.6,96.39]],"id":56297029},{"atl":[[90,1]],"id":27115873},{"atb":[[6.8,219.39]],"atl":[[7.4,60.86]],"batb":[[0,6.8,219.39]],"batl":[[2,7.4,60.86]],"id":26496185}]}]}
{"op":"mcm","id":2,"clk":"AOGYAwCOywIA/OkC","pt":1743512219970,"mc":[{"id":"1.241629436","rc":[{"atb":[[10,128.6]],"trd":[[10,929.48]],"batb":[[0,10,128.6]],"tv":7626.33,"id":27115873}],"tv":95722.2}]}
{"op":"mcm","id":2,"clk":"AO2YAwCWywIAjeoC","pt":1743512220070,"mc":[{"id":"1.241629436","rc":[{"atb":[[4.6,354.27]],"batb":[[0,4.6,354.27]],"id":270592},{"atl":[[5.6,106.93]],"batl":[[2,5.6,106.93]],"id":56297029}]}]}
{"op":"mcm","id":2,"clk":"AP6YAwCaywIAk+oC","pt":1743512220119,"mc":[{"id":"1.241629436","rc":[{"atl":[[350,0.01]],"id":270592},{"atb":[[6.8,214.98]],"trd":[[6.8,1681.18]],"batb":[[0,6.8,214.98]],"ltp":6.8,"tv":15957.1,"id":26496185}],"tv":95731.02}]}
{"op":"mcm","id":2,"clk":"AImZAwClywIAmeoC","pt":1743512220218,"mc":[{"id":"1.241629436","rc":[{"atb":[[4.6,387.24]],"atl":[[350,0.02]],"batb":[[0,4.6,387.24]],"id":270592},{"atb":[[9.4,12.93]],"atl":[[9.8,47.12]],"trd":[[9.4,769.42]],"batb":[[0,9.4,12.93]],"batl":[[1,9.8,47.12]],"ltp":9.4,"tv":10771.85,"id":35856222},{"atb":[[1.14,1]],"id":56297029}],"tv":95735.02}]}
{"op":"mcm","id":2,"clk":"AJKZAwCtywIAo+oC","pt":1743512220328,"mc":[{"id":"1.241629436","rc":[{"atl":[[350,0.03]],"id":270592},{"atb":[[9.4,12.34]],"trd":[[9.4,770.6]],"batb":[[0,9.4,12.34]],"tv":10773.03,"id":35856222},{"atb":[[6.8,213.98]],"trd":[[6.8,1683.18]],"batb":[[0,6.8,213.98]],"tv":15959.1,"id":26496185}],"tv":95738.2}]}
{"op":"mcm","id":2,"clk":"AJeZAwCyywIAreoC","pt":1743512220427,"mc":[{"id":"1.241629436","rc":[{"atb":[[9.4,11.63],[9.2,49.83]],"batb":[[1,9.2,49.83],[0,9.4,11.63]],"id":35856222},{"atb":[[1.14,0.06],[5.3,58.68]],"trd":[[5.3,1211.53]],"batb":[[0,5.3,58.68]],"tv":15154.37,"id":56297029}],"tv":95740.86}]}
{"op":"mcm","id":2,"clk":"AKGZAwC9ywIAvOoC","pt":1743512220535,"mc":[{"id":"1.241629436","rc":[{"atb":[[4.4,245.88],[1.25,1],[4.6,382.12]],"atl":[[1000,21.94],[5.2,147.86]],"trd":[[4.6,791.46]],"batb":[[2,4.4,245.88],[0,4.6,382.12]],"batl":[],"ltp":4.6,"tv":24314.63,"id":270592},{"atb":[[9.4,11.16]],"trd":[[9.4,771.54]],"batb":[[0,9.4,11.16]],"tv":10773.97,"id":35856222},{"atb":[[4.9,64.29]],"atl":[[5.4,50.39]],"trd":[[5.4,159.28]],"batb":[],"batl":[[0,5.4,50.39]],"ltp":5.4,"tv":15174.01,"id":56297029},{"atb":[[10,128.29]],"trd":[[10,930.1]],"batb":[[0,10,128.29]],"tv":7626.95,"id":27115873},{"atb":[[19,44.65],[18.5,15.34]],"atl":[[19,0]],"trd":[[19,383.05],[18.5,417.82]],"batb":[[2,18,19.41],[1,18.5,15.34],[0,19,44.65]],"batl":[[2,21,10.93],[1,20,9.29],[0,19.5,10.58]],"ltp":19,"tv":6925.67,"id":58186642},{"atb":[[6.4,260.53]],"atl":[[7,27.3]],"trd":[[7,1832.26]],"batb":[[2,6.4,260.53]],"batl":[[0,7,27.3]],"ltp":7,"tv":15966.48,"id":26496185},{"atl":[[13,35.08]],"batl":[],"id":44049799}],"tv":95810.38}]}
{"op":"mcm","id":2,"clk":"AKqZAwDEywIAxOoC","pt":1743512220638,"mc":[{"id":"1.241629436","rc":[{"atb":[[9.4,0]],"batb":[[2,8.8,49.11],[1,9,39.03],[0,9.2,49.83]],"id":35856222},{"atb":[[19,51.89],[18.5,25.52],[16.5,38.35]],"atl":[[27,4.68],[20,16.04],[19.5,8.39]],"trd":[[19,399.47]],"batb":[[1,18.5,25.52],[0,19,51.89]],"batl":[[1,20,16.04],[0,19.5,8.39]],"tv":6942.09,"id":58186642},{"atb":[[6.8,195.34]],"atl":[[7,28.63]],"trd":[[6.8,1683.2]],"batb":[[0,6.8,195.34]],"batl":[[0,7,28.63]],"ltp":6.8,"tv":15966.5,"id":26496185},{"atl":[[12,56.02]],"batl":[[1,12,56.02]],"id":44049799}],"tv":95826.82}]}
{"op":"mcm","id":2,"clk":"ALaZAwDMywIA0OoC","pt":1743512220741,"mc":[{"id":"1.241629436","rc":[{"atb":[[1.25,0.08]],"atl":[[1000,21.16]],"id":270592},{"atb":[[9,37.6]],"batb":[[1,9,37.6]],"id":35856222},{"atb":[[1.14,0]],"atl":[[5.4,111.5],[5.5,77.61]],"batl":[[1,5.5,77.61],[0,5.4,111.5]],"id":56297029},{"atb":[[19,54.59]],"atl":[[28,3.86],[21,13.09],[19.5,0.07]],"batb":[[0,19,54.59]],"batl":[[2,22,7.96],[1,21,13.09],[0,20,16.11]],"id":58186642}]}]}
{"op":"mcm","id":2,"clk":"AL2ZAwDVywIA1+oC","pt":1743512220845,"mc":[{"id":"1.241629436","rc":[{"atb":[[11,80.66]],"atl":[[12.5,58.31]],"batb":[[0,11,80.66]],"batl":[[2,12.5,58.31]],"id":40389088},{"atl":[[6,71.64],[6.2,115.95]],"id":270592},{"atl":[[9.6,34.55]],"batl":[[0,9.6,34.55]],"id":35856222},{"atl":[[55,14.23]],"batl":[[0,55,14.23]],"id":59626646},{"atb":[[5.3,58.74]],"atl":[[5.4,235.02]],"batb":[[0,5.3,58.74]],"batl":[[0,5.4,235.02]],"id":56297029},{"atb":[[19,62.59],[16.5,29.83]],"atl":[[29,8.26],[19.5,34.28]],"batb":[[0,19,62.59]],"batl":[[2,21,13.09],[1,20,16.04],[0,19.5,34.28]],"id":58186642},{"atb":[[6.8,195.33]],"trd":[[6.8,1683.22]],"batb":[[0,6.8,195.33]],"tv":15966.52,"id":26496185}],"tv":95826.84}]}
{"op":"mcm","id":2,"clk":"AMKZAwDbywIA3+oC","pt":1743512220948,"mc":[{"id":"1.241629436","rc":[{"atb":[[1.25,0]],"atl":[[4.7,163.83]],"trd":[[4.7,3975.76]],"batl":[[0,4.7,163.83]],"ltp":4.7,"tv":24364.63,"id":270592},{"atb":[[5.3,0]],"atl":[[5.3,61.76]],"trd":[[5.3,1329.01]],"batb":[[2,5,1129.68],[1,5.1,573.18],[0,5.2,207.74]],"batl":[[2,5.5,77.61],[1,5.4,235.02],[0,5.3,61.76]],"ltp":5.3,"tv":15291.49,"id":56297029},{"atl":[[28,6.77],[19.5,41.22]],"batl":[[0,19.5,41.22]],"id":58186642},{"atb":[[6.4,257.54]],"batb":[[2,6.4,257.54]],"id":26496185}],"tv":95994.32}]}
{"op":"mcm","id":2,"clk":"AM+ZAwDkywIA4+oC","pt":1743512221064,"mc":[{"id":"1.241629436","rc":[{"atb":[[11,85.64]],"batb":[[0,11,85.64]],"id":40389088},{"atb":[[3.4,3.08]],"atl":[[4.7,101.38]],"batl":[[0,4.7,101.38]],"id":270592},{"atl":[[10,93.3]],"batl":[[2,10,93.3]],"id":35856222},{"atb":[[50,16.03]],"batb":[[0,50,16.03]],"id":59626646},{"atb":[[5.2,106.34],[5,1128.7]],"atl":[[5.4,245.7],[5.7,81.67],[5.3,19.24]],"trd":[[5.3,1418.06]],"batb":[[2,5,1128.7],[0,5.2,106.34]],"batl":[[1,5.4,245.7],[0,5.3,19.24]],"tv":15380.54,"id":56297029},{"atb":[[9.6,136.75]],"batb":[[2,9.6,136.75]],"id":27115873},{"atb":[[19,54.59]],"batb":[[0,19,54.59]],"id":58186642},{"atb":[[6.8,221.8]],"batb":[[0,6.8,221.8]],"id":26496185},{"atl":[[12.5,36.98]],"batl":[[2,12.5,36.98]],"id":44049799}],"tv":96083.37}]}
{"op":"mcm","id":2,"clk":"ANaZAwDtywIA6eoC","pt":1743512221157,"mc":[{"id":"1.241629436","rc":[{"atb":[[4.6,385.21],[4.5,285.77]],"atl":[[4.7,67.14]],"batb":[[1,4.5,285.77],[0,4.6,385.21]],"batl":[[0,4.7,67.14]],"id":270592},{"atl":[[9.8,48.12]],"batl":[[1,9.8,48.12]],"id":35856222},{"atl":[[55,15.48]],"batl":[[0,55,15.48]],"id":59626646},{"atb":[[5.2,104],[4.9,65.3]],"atl":[[5.3,32.17],[350,0.01],[5.6,107.73]],"trd":[[5.2,4323.58]],"batb":[[0,5.2,104]],"batl":[[0,5.3,32.17]],"ltp":5.2,"tv":15385.22,"id":56297029},{"atl":[[28,3.86]],"batl":[],"id":58186642}],"tv":96088.05}]}
{"op":"mcm","id":2,"clk":"AOKZAwD6ywIA8OoC","pt":1743512221265,"mc":[{"id":"1.241629436","rc":[{"atb":[[4.6,416.21]],"atl":[[4.8,249.22]],"batb":[[0,4.6,416.21]],"batl":[[1,4.8,249.22]],"id":270592},{"atb":[[5.2,98.76],[5.1,562.29]],"atl":[[350,0.02]],"batb":[[1,5.1,562.29],[0,5.2,98.76]],"id":56297029},{"atb":[[1.08,13]],"id":58186642},{"atl":[[7,0],[7.4,53.12],[7.2,167.91]],"trd":[[7,1873.32],[7.2,44.09]],"batl":[[2,7.6,53.31],[1,7.4,53.12],[0,7.2,167.91]],"ltp":7.2,"tv":16013.52,"id":26496185},{"atb":[[9.6,54.41]],"batb":[],"id":44049799}],"tv":96135.05}]}
{"op":"mcm","id":2,"clk":"AOiZAwCDzAIA9uoC","pt":1743512221361,"mc":[{"id":"1.241629436","rc":[{"atb":[[5.2,106.45]],"atl":[[5.3,36.71],[350,0.03]],"batb":[[0,5.2,106.45]],"batl":[[0,5.3,36.71]],"id":56297029},{"atl":[[11.5,100.79]],"batl":[[0,11.5,100.79]],"id":44049799}]}]}
{"op":"mcm","id":2,"clk":"APCZAwCMzAIA++oC","pt":1743512221468,"mc":[{"id":"1.241629436","rc":[{"atb":[[4.6,413.12]],"batb":[[0,4.6,413.12]],"id":270592},{"atb":[[5.2,103.57]],"trd":[[5.2,4329.34]],"batb":[[0,5.2,103.57]],"tv":15390.98,"id":56297029},{"atb":[[1.08,12.11]],"id":58186642},{"atb":[[6.2,163.19]],"batb":[],"id":26496185}],"tv":96140.81}]}
{"op":"mcm","id":2,"clk":"APaZAwCRzAIA/+oC","pt":1743512221570,"mc":[{"id":"1.241629436","rc":[{"atl":[[75,0.11]],"id":40389088},{"atb":[[4.1,174.21]],"atl":[[75,0.11]],"batb":[],"id":270592},{"atl":[[75,0.11]],"id":35856222},{"atl":[[75,5.17]],"batl":[],"id":59626646},{"atl":[[75,0.11]],"id":56297029},{"atb":[[10,129.29]],"atl":[[75,0.11]],"batb":[[0,10,129.29]],"id":27115873},{"atl":[[75,2.1]],"id":58186642},{"atl":[[75,0.11]],"id":26496185},{"atl":[[75,0.11]],"id":44049799}]}]}
{"op":"mcm","id":2,"clk":"AIGaAwCbzAIAg+sC","pt":1743512221635,"mc":[{"id":"1.241629436","rc":[{"atb":[[5.2,104.14]],"batb":[[0,5.2,104.14]],"id":56297029},{"atb":[[1.08,12]],"id":58186642}]}]}
{"op":"mcm","id":2,"clk":"AIiaAwCkzAIAiOsC","pt":1743512221732,"mc":[{"id":"1.241629436","rc":[{"atb":[[4.6,416.21]],"atl":[[4.7,64.2]],"trd":[[4.7,3981.64]],"batb":[[0,4.6,416.21]],"batl":[[0,4.7,64.2]],"tv":24370.51,"id":270592},{"atb":[[19,54.7],[17.5,47.84]],"atl":[[1000,2.92]],"batb":[[0,19,54.7]],"id":58186642}],"tv":96146.69}]}
{"op":"mcm","id":2,"clk":"AJuaAwC0zAIAlesC","pt":1743512221942,"mc":[{"id":"1.241629436","rc":[{"atb":[[1.42,99.86]],"id":270592}]}]}
{"op":"mcm","id":2,"clk":"AKiaAwC6zAIAmesC","pt":1743512222046,"mc":[{"id":"1.241629436","rc":[{"atl":[[9.8,49.12]],"batl":[[1,9.8,49.12]],"id":35856222},{"atl":[[5.3,8.83]],"trd":[[5.3,1473.82]],"batl":[[0,5.3,8.83]],"ltp":5.3,"tv":15446.74,"id":56297029}],"tv":96202.45}]}
{"op":"mcm","id":2,"clk":"ALGaAwC+zAIAn+sC","pt":1743512222143,"mc":[{"id":"1.241629436","rc":[{"atb":[[5.2,114.83],[5.1,572.99]],"atl":[[5.3,6.79]],"batb":[[1,5.1,572.99],[0,5.2,114.83]],"batl":[[0,5.3,6.79]],"id":56297029},{"atb":[[19,52]],"batb":[[0,19,52]],"id":58186642},{"atl":[[350,0.02]],"id":26496185},{"atl":[[12.5,38.8],[12,58]],"batl":[[2,12.5,38.8],[1,12,58]],"id":44049799}]}]}
{"op":"mcm","id":2,"clk":"AL6aAwDFzAIApusC","pt":1743512222249,"mc":[{"id":"1.241629436","rc":[{"atl":[[9.6,35.6]],"batl":[[0,9.6,35.6]],"id":35856222},{"atl":[[23,7.13]],"batl":[],"id":58186642}]}]}
{"op":"mcm","id":2,"clk":"AMaaAwDLzAIAqesC","pt":1743512222342,"mc":[{"id":"1.241629436","rc":[{"atl":[[4.8,227.77]],"batl":[[1,4.8,227.77]],"id":270592},{"atb":[[9.2,47.83]],"trd":[[9.2,739.17]],"batb":[[0,9.2,47.83]],"ltp":9.2,"tv":10777.97,"id":35856222},{"atb":[[18,32.18]],"batb":[[2,18,32.18]],"id":58186642},{"atl":[[350,0.03]],"id":26496185}],"tv":96206.45}]}
{"op":"mcm","id":2,"clk":"AMyaAwDTzAIAuusC","pt":1743512222446,"mc":[{"id":"1.241629436","rc":[{"atl":[[5.3,21.01]],"batl":[[0,5.3,21.01]],"id":56297029}]}]}
{"op":"mcm","id":2,"clk":"AOCaAwDfzAIAy+sC","pt":1743512222661,"mc":[{"id":"1.241629436","rc":[{"atb":[[4.6,211.21]],"trd":[[4.6,1201.46]],"batb":[[0,4.6,211.21]],"ltp":4.6,"tv":24780.51,"id":270592},{"atb":[[5.2,111.57]],"trd":[[5.2,4335.86]],"batb":[[0,5.2,111.57]],"ltp":5.2,"tv":15453.26,"id":56297029},{"atb":[[6.2,175.75]],"batb":[],"id":26496185}],"tv":96622.97}]}
{"op":"mcm","id":2,"clk":"AOqaAwDkzAIA1+sC","pt":1743512222764,"mc":[{"id":"1.241629436","rc":[{"atb":[[4.6,209.56]],"atl":[[4.7,76.54]],"batb":[[0,4.6,209.56]],"batl":[[0,4.7,76.54]],"id":270592},{"atb":[[5.2,111.42],[5.1,574.52]],"atl":[[5.4,239.43],[5.3,90.9]],"batb":[[1,5.1,574.52],[0,5.2,111.42]],"batl":[[1,5.4,239.43],[0,5.3,90.9]],"id":56297029},{"atb":[[10,130.29]],"batb":[[0,10,130.29]],"id":27115873},{"atb":[[18,30.82],[18.5,27.45]],"batb":[[2,18,30.82],[1,18.5,27.45]],"id":58186642},{"atb":[[11,113.69]],"batb":[[0,11,113.69]],"id":44049799}]}]}
{"op":"mcm","id":2,"clk":"APKaAwDrzAIA3OsC","pt":1743512222861,"mc":[{"id":"1.241629436","rc":[{"atb":[[4.6,215.58]],"atl":[[4.7,172.04]],"batb":[[0,4.6,215.58]],"batl":[[0,4.7,172.04]],"id":270592},{"atl":[[5.3,120.9]],"batl":[[0,5.3,120.9]],"id":56297029}]}]}
{"op":"mcm","id":2,"clk":"APiaAwDwzAIA4OsC","pt":1743512222964,"mc":[{"id":"1.241629436","rc":[{"atl":[[4.8,249.22]],"batl":[[1,4.8,249.22]],"id":270592},{"atb":[[2,135.01]],"id":35856222},{"atl":[[55,11.31]],"trd":[[55,415.75]],"batl":[[0,55,11.31]],"tv":2205.58,"id":59626646},{"atb":[[2,25.01]],"id":58186642}],"tv":96631.32}]}
{"op":"mcm","id":2,"clk":"AP6aAwD6zAIA6esC","pt":1743512223017,"mc":[{"id":"1.241629436","rc":[{"atb":[[4.5,273.68]],"atl":[[4.9,306.15]],"batb":[[1,4.5,273.68]],"batl":[[2,4.9,306.15]],"id":270592},{"atl":[[9.8,50.12]],"batl":[[1,9.8,50.12]],"id":35856222}]}]}
{"op":"mcm","id":2,"clk":"AImbAwD/zAIA8OsC","pt":1743512223134,"mc":[{"id":"1.241629436","rc":[{"atl":[[4.7,181.76]],"batl":[[0,4.7,181.76]],"id":270592},{"atl":[[350,0.01]],"id":35856222},{"atb":[[50,17.82]],"atl":[[55,11.49]],"batb":[[0,50,17.82]],"batl":[[0,55,11.49]],"id":59626646},{"atl":[[5.6,127.23]],"batl":[],"id":56297029},{"atl":[[1000,2.52]],"id":58186642},{"atb":[[6,174.55]],"atl":[[9.6,38.05]],"batb":[],"id":26496185}]}]}
{"op":"mcm","id":2,"clk":"AI+bAwCKzQIA++sC","pt":1743512223234,"mc":[{"id":"1.241629436","rc":[{"atl":[[350,0.02]],"id":35856222},{"atb":[[19,51.6]],"trd":[[19,400.27]],"batb":[[0,19,51.6]],"tv":6942.89,"id":58186642}],"tv":96632.12}]}
{"op":"mcm","id":2,"clk":"AJSbAwCPzQIAgewC","pt":1743512223328,"mc":[{"id":"1.241629436","rc":[{"atb":[[5.2,109.01]],"trd":[[5.2,4340.68]],"batb":[[0,5.2,109.01]],"tv":15458.08,"id":56297029}],"tv":96636.94}]}
{"op":"mcm","id":2,"clk":"AJibAwCVzQIAhuwC","pt":1743512223442,"mc":[{"id":"1.241629436","rc":[{"atb":[[4.2,110.77]],"atl":[[5.3,185.57]],"batb":[],"batl":[],"id":270592},{"atl":[[350,0.03]],"id":35856222},{"atb":[[5.2,109.1]],"atl":[[5.3,123.15]],"trd":[[5.2,4345.36]],"batb":[[0,5.2,109.1]],"batl":[[0,5.3,123.15]],"tv":15462.76,"id":56297029}],"tv":96641.62}]}
{"op":"mcm","id":2,"clk":"AJ2bAwCczQIAjOwC","pt":1743512223540,"mc":[{"id":"1.241629436","rc":[{"atb":[[7,1.9]],"batb":[[2,6.6,214.8],[1,6.8,221.8],[0,7,1.9]],"id":26496185}]}]}
{"op":"mcm","id":2,"clk":"AKibAwCkzQIAkuwC","pt":1743512223636,"mc":[{"id":"1.241629436","rc":[{"atl":[[4.7,175.76]],"trd":[[4.7,3993.64]],"batl":[[0,4.7,175.76]],"ltp":4.7,"tv":24792.51,"id":270592},{"atl":[[9.6,32.42]],"trd":[[9.6,863.99]],"batl":[[0,9.6,32.42]],"ltp":9.6,"tv":10784.33,"id":35856222},{"atl":[[55,9.74]],"trd":[[55,419.25]],"batl":[[0,55,9.74]],"tv":2209.08,"id":59626646},{"atl":[[5.3,120.9]],"batl":[[0,5.3,120.9]],"id":56297029},{"atl":[[10.5,139.71]],"trd":[[10.5,689.61]],"batl":[[0,10.5,139.71]],"ltp":10.5,"tv":7630.71,"id":27115873},{"atb":[[1.01,44318.75]],"id":58186642},{"atb":[[7,3.23],[4.3,60.96]],"batb":[[0,7,3.23]],"id":26496185}],"tv":96667.24}]}
{"op":"mcm","id":2,"clk":"AK+bAwCtzQIAnOwC","pt":1743512223747,"mc":[{"id":"1.241629436","rc":[{"atb":[[9.4,13.06]],"atl":[[9.6,28.9]],"batb":[[2,9,37.6],[1,9.2,47.83],[0,9.4,13.06]],"batl":[[0,9.6,28.9]],"id":35856222},{"atl":[[5.4,223.48]],"batl":[[1,5.4,223.48]],"id":56297029}]}]}
{"op":"mcm","id":2,"clk":"ALWbAwC2zQIAo+wC","pt":1743512223841,"mc":[{"id":"1.241629436","rc":[{"atb":[[4.6,160.92]],"trd":[[4.6,1248.78]],"batb":[[0,4.6,160.92]],"ltp":4.6,"tv":24839.83,"id":270592},{"atb":[[9.4,17.43]],"atl":[[9.6,27.85]],"batb":[[0,9.4,17.43]],"batl":[[0,9.6,27.85]],"id":35856222},{"atl":[[5.3,123.15]],"batl":[[0,5.3,123.15]],"id":56297029},{"atb":[[7.4,19.95],[10,129.29]],"trd":[[10,934.1]],"batb":[[0,10,129.29]],"ltp":10,"tv":7634.71,"id":27115873},{"atb":[[1.01,44318.64]],"atl":[[19.5,32.03]],"trd":[[19.5,91.35]],"batl":[[0,19.5,32.03]],"ltp":19.5,"tv":6961.27,"id":58186642}],"tv":96736.94}]}
{"op":"mcm","id":2,"clk":"AMGbAwC+zQIAqewC","pt":1743512223956,"mc":[{"id":"1.241629436","rc":[{"atb":[[9.4,28.52],[9,39.03]],"batb":[[2,9,39.03],[0,9.4,28.52]],"id":35856222},{"atl":[[10.5,133.71]],"trd":[[10.5,701.61]],"batl":[[0,10.5,133.71]],"ltp":10.5,"tv":7646.71,"id":27115873},{"atl":[[19.5,25.09]],"batl":[[0,19.5,25.09]],"id":58186642},{"atb":[[11,112.69]],"trd":[[11,1778.34]],"batb":[[0,11,112.69]],"tv":5365.56,"id":44049799}],"tv":96750.94}]}
{"op":"mcm","id":2,"clk":"AMebAwDEzQIAs+wC","pt":1743512224046,"mc":[{"id":"1.241629436","rc":[{"atl":[[9.6,20.6]],"batl":[[0,9.6,20.6]],"id":35856222},{"atb":[[19,48.41],[1.01,44317.07]],"trd":[[19,412.41]],"batb":[[0,19,48.41]],"ltp":19,"tv":6973.41,"id":58186642}],"tv":96763.08}]}
{"op":"mcm","id":2,"clk":"ANKbAwDLzQIAwOwC","pt":1743512224153,"mc":[{"id":"1.241629436","rc":[{"atl":[[350,0.01]],"id":27115873},{"atl":[[19.5,30.84]],"trd":[[19.5,94.48]],"batl":[[0,19.5,30.84]],"ltp":19.5,"tv":6976.54,"id":58186642}],"tv":96766.21}]}
{"op":"mcm","id":2,"clk":"ANybAwDSzQIAyewC","pt":1743512224255,"mc":[{"id":"1.241629436","rc":[{"atb":[[9.4,31.59]],"batb":[],"id":40389088},{"atb":[[9.4,27.52]],"trd":[[9.4,773.54]],"batb":[[0,9.4,27.52]],"ltp":9.4,"tv":10786.33,"id":35856222},{"atl":[[1000,14.28]],"id":59626646},{"atb":[[5.2,106.99]],"trd":[[5.2,4349.58]],"batb":[[0,5.2,106.99]],"tv":15466.98,"id":56297029},{"atl":[[350,0.02]],"id":27115873},{"atl":[[7.2,165.13]],"trd":[[7.2,49.65]],"batl":[[0,7.2,165.13]],"tv":16019.08,"id":26496185},{"atb":[[8,36.16]],"id":44049799}],"tv":96777.99}]}
{"op":"mcm","id":2,"clk":"AOSbAwDXzQIA1uwC","pt":1743512224357,"mc":[{"id":"1.241629436","rc":[{"atb":[[11,75.42]],"trd":[[11,464.51]],"batb":[[0,11,75.42]],"tv":7490.32,"id":40389088},{"atb":[[10,127.29]],"atl":[[350,0.03]],"trd":[[10,938.1]],"batb":[[0,10,127.29]],"ltp":10,"tv":7650.71,"id":27115873},{"atb":[[9,14.47]],"batb":[],"id":44049799}],"tv":96804.43}]}
{"op":"mcm","id":2,"clk":"AOqbAwDbzQIA1uwC","pt":1743512224454,"mc":[{"id":"1.241629436","rc":[{"atl":[[1000,11.95]],"id":59626646}]}]}
{"op":"mcm","id":2,"clk":"AO6bAwDjzQIA3+wC","pt":1743512224561,"mc":[{"id":"1.241629436","rc":[{"atb":[[9.4,17.52]],"trd":[[9.4,793.54]],"batb":[[0,9.4,17.52]],"tv":10806.33,"id":35856222},{"atl":[[1000,11.86]],"id":59626646}],"tv":96824.43}]}
{"op":"mcm","id":2,"clk":"APSbAwDpzQIA6uwC","pt":1743512224669,"mc":[{"id":"1.241629436","rc":[{"atl":[[9.6,24.11]],"batl":[[0,9.6,24.11]],"id":35856222},{"atb":[[50,17.72]],"trd":[[50,149.49]],"batb":[[0,50,17.72]],"ltp":50,"tv":2209.27,"id":59626646},{"atl":[[5.3,120.9]],"batl":[[0,5.3,120.9]],"id":56297029},{"atb":[[7,0.73]],"trd":[[7,1878.32]],"batb":[[2,6.4,257.54],[1,6.6,214.8],[0,6.8,222.53]],"ltp":7,"tv":16024.08,"id":26496185}],"tv":96829.62}]}
{"op":"mcm","id":2,"clk":"APqbAwDwzQIA8uwC","pt":1743512224769,"mc":[{"id":"1.241629436","rc":[{"atl":[[9.6,27.63]],"batl":[[0,9.6,27.63]],"id":35856222}]}]}
{"op":"mcm","id":2,"clk":"AIycAwD+zQIAhe0C","pt":1743512224924,"mc":[{"id":"1.241629436","rc":[{"atl":[[5.3,123.15]],"batl":[[0,5.3,123.15]],"id":56297029},{"atl":[[19.5,23.53]],"batl":[[0,19.5,23.53]],"id":58186642}]}]}
{"op":"mcm","id":2,"clk":"AI6cAwCFzgIAje0C","pt":1743512225023,"mc":[{"id":"1.241629436","rc":[{"atl":[[4.7,185.76]],"batl":[[0,4.7,185.76]],"id":270592},{"atb":[[9.4,18.58]],"batb":[[0,9.4,18.58]],"id":35856222},{"atb":[[5.9,117.98],[6,172.85],[5.8,131.73]],"batb":[],"id":26496185}]}]}
{"op":"mcm","id":2,"clk":"AKGcAwCLzgIAl+0C","pt":1743512225140,"mc":[{"id":"1.241629436","rc":[{"atl":[[12,53.84]],"batl":[[1,12,53.84]],"id":40389088},{"atb":[[5.2,106.61]],"trd":[[5.2,4353.8]],"batb":[[0,5.2,106.61]],"tv":15471.2,"id":56297029},{"atb":[[5.9,119.74]],"batb":[],"id":26496185},{"atl":[[350,0.01]],"id":44049799}],"tv":96833.84}]}
{"op":"mcm","id":2,"clk":"AKqcAwCSzgIAoO0C","pt":1743512225241,"mc":[{"id":"1.241629436","rc":[{"atl":[[11.5,38.29]],"batl":[[0,11.5,38.29]],"id":40389088},{"atl":[[1000,6.85],[5.5,77.21]],"batl":[[2,5.5,77.21]],"id":56297029},{"atb":[[11,113.77]],"batb":[[0,11,113.77]],"id":44049799}]}]}
{"op":"mcm","id":2,"clk":"ALScAwCdzgIAr+0C","pt":1743512225355,"mc":[{"id":"1.241629436","rc":[{"atl":[[1000,6.49]],"id":56297029},{"atl":[[350,0.03]],"id":44049799}]}]}
{"op":"mcm","id":2,"clk":"ALycAwCozgIAuu0C","pt":1743512225444,"mc":[{"id":"1.241629436","rc":[{"atl":[[11.5,25.37]],"batl":[[0,11.5,25.37]],"id":40389088},{"atl":[[4.7,187.76]],"batl":[[0,4.7,187.76]],"id":270592},{"atl":[[5.4,223.84],[5.3,120.9]],"batl":[[1,5.4,223.84],[0,5.3,120.9]],"id":56297029}]}]}
{"op":"mcm","id":2,"clk":"AMicAwCwzgIAxe0C","pt":1743512225554,"mc":[{"id":"1.241629436","rc":[{"atl":[[5.3,123.15]],"batl":[[0,5.3,123.15]],"id":56297029}]}]}
{"op":"mcm","id":2,"clk":"AM+cAwC3zgIA0O0C","pt":1743512225647,"mc":[{"id":"1.241629436","rc":[{"atb":[[4.6,110.92]],"trd":[[4.6,1348.78]],"batb":[[0,4.6,110.92]],"tv":24939.83,"id":270592},{"atl":[[1000,1.41],[9.6,26.25]],"batl":[[0,9.6,26.25]],"id":35856222},{"atb":[[1.17,2.57],[5.2,56.61]],"atl":[[5.3,122.46]],"trd":[[5.2,4453.8]],"batb":[[0,5.2,56.61]],"batl":[[0,5.3,122.46]],"tv":15571.2,"id":56297029},{"atb":[[11,113.65]],"batb":[[0,11,113.65]],"id":44049799}],"tv":97033.84}]}
{"op":"mcm","id":2,"clk":"ANucAwDAzgIA3e0C","pt":1743512225753,"mc":[{"id":"1.241629436","rc":[{"atl":[[1000,1.17]],"id":35856222},{"atb":[[50,18.01]],"batb":[[0,50,18.01]],"id":59626646},{"atb":[[1.17,2],[5.2,51.09]],"atl":[[5.3,128.01]],"batb":[[0,5.2,51.09]],"batl":[[0,5.3,128.01]],"id":56297029},{"atb":[[1.17,1.1]],"atl":[[1000,1.65]],"id":27115873},{"atl":[[27,7.57],[19.5,33.16]],"batl":[[0,19.5,33.16]],"id":58186642},{"atb":[[6.6,218.64]],"batb":[[1,6.6,218.64]],"id":26496185}]}]}
{"op":"mcm","id":2,"clk":"AOWcAwDFzgIA6O0C","pt":1743512225854,"mc":[{"id":"1.241629436","rc":[{"atb":[[4.4,280.88],[4.6,112.59]],"batb":[[2,4.4,280.88],[0,4.6,112.59]],"id":270592},{"atl":[[1000,0.41]],"id":35856222},{"atb":[[5.2,78.66]],"atl":[[5.3,143.73]],"batb":[[0,5.2,78.66]],"batl":[[0,5.3,143.73]],"id":56297029},{"atb":[[1.17,1]],"atl":[[1000,1.16]],"id":27115873}]}]}
{"op":"mcm","id":2,"clk":"AOucAwDMzgIA9+0C","pt":1743512225954,"mc":[{"id":"1.241629436","rc":[{"atl":[[11.5,19.55]],"trd":[[11.5,1869.89]],"batl":[[0,11.5,19.55]],"ltp":11.5,"tv":7501.96,"id":40389088},{"atb":[[9.4,17.82],[9,42.5]],"trd":[[9.4,795.06]],"batb":[[2,9,42.5],[0,9.4,17.82]],"tv":10807.85,"id":35856222},{"atb":[[8.4,59.67],[9.8,74.22]],"atl":[[10.5,134.2]],"batb":[[1,9.8,74.22]],"batl":[[0,10.5,134.2]],"id":27115873},{"atb":[[19,42.59]],"atl":[[19.5,40.58]],"trd":[[19,424.05]],"batb":[[0,19,42.59]],"batl":[[0,19.5,40.58]],"ltp":19,"tv":6988.18,"id":58186642}],"tv":97058.64}]}
{"op":"mcm","id":2,"clk":"APOcAwDUzgIAhO4C","pt":1743512226058,"mc":[{"id":"1.241629436","rc":[{"atb":[[50,14.01]],"trd":[[50,157.49]],"batb":[[0,50,14.01]],"tv":2217.27,"id":59626646}],"tv":97066.64}]}
{"op":"mcm","id":2,"clk":"APucAwDbzgIAjO4C","pt":1743512226165,"mc":[{"id":"1.241629436","rc":[{"atb":[[10,84.05]],"atl":[[350,0.01]],"batb":[[2,10,84.05]],"id":40389088},{"atb":[[4,132.84]],"batb":[],"id":270592},{"atb":[[9.4,18.88]],"batb":[[0,9.4,18.88]],"id":35856222},{"atl":[[55,12.23]],"batl":[[0,55,12.23]],"id":59626646},{"atb":[[5.2,127.14]],"batb":[[0,5.2,127.14]],"id":56297029},{"atb":[[10,129.97]],"batb":[[0,10,129.97]],"id":27115873},{"atb":[[19,39.71]],"batb":[[0,19,39.71]],"id":58186642},{"atb":[[6,173.95]],"batb":[],"id":26496185},{"atb":[[10,94.18]],"batb":[[2,10,94.18]],"id":44049799}]}]}
