{"op":"mcm","id":2,"initialClk":"ggKcgdT/DYQClK/i6A34AeuFk/4N","clk":"AAAAAAAA","conflateMs":0,"heartbeatMs":5000,"pt":1743511672980,"ct":"SUB_IMAGE","mc":[{"id":"1.241629436","marketDefinition":{"bspMarket":true,"turnInPlayEnabled":true,"persistenceEnabled":true,"marketBaseRate":5,"eventId":"34173357","eventTypeId":"7","numberOfWinners":1,"bettingType":"ODDS","marketType":"WIN","marketTime":"2025-04-01T13:02:00.000Z","suspendTime":"2025-04-01T13:02:00.000Z","bspReconciled":false,"complete":true,"inPlay":false,"crossMatching":true,"runnersVoidable":false,"numberOfActiveRunners":9,"betDelay":0,"status":"OPEN","runners":[{"adjustmentFactor":20.833,"status":"ACTIVE","sortPriority":1,"id":270592},{"adjustmentFactor":18.719,"status":"ACTIVE","sortPriority":2,"id":56297029},{"adjustmentFactor":16.223,"status":"ACTIVE","sortPriority":3,"id":26496185},{"adjustmentFactor":9.734,"status":"ACTIVE","sortPriority":4,"id":35856222},{"adjustmentFactor":9.27,"status":"ACTIVE","sortPriority":5,"id":27115873},{"adjustmentFactor":8.849,"status":"ACTIVE","sortPriority":6,"id":44049799},{"adjustmentFactor":8.112,"status":"ACTIVE","sortPriority":7,"id":40389088},{"adjustmentFactor":6.489,"status":"ACTIVE","sortPriority":8,"id":58186642},{"adjustmentFactor":1.77,"status":"ACTIVE","sortPriority":9,"id":59626646}],"regulators":["MR_INT"],"venue":"Lingfield","countryCode":"GB","discountAllowed":true,"timezone":"Europe/London","openDate":"2025-04-01T13:02:00.000Z","version":6537458050,"raceType":"Flat","priceLadderDefinition":{"type":"CLASSIC"}},"rc":[{"atb":[[11.5,55.61],[8.4,35],[8.2,4.36],[7.2,13.03],[3.4,4891.7],[1.44,7847.29],[11,84],[1.17,2],[9.6,27.36],[9.8,24.23],[10,45.9],[1.01,53787.92],[10.5,38.37],[2,24.01],[1.83,5464],[1.1,9],[1.6,76.53],[7,14.9],[1.8,4],[1.75,1],[7.8,22.82],[7.4,13.33],[8.6,28.15],[6,45.63],[1.2,0.48],[9.2,29.87],[9,7.47],[1.26,0.5],[1.02,5163.24],[5.6,18.06],[2.06,12],[1.03,287.24],[6.8,8.78],[1.06,5421.57],[1.61,80],[9.4,3],[6.4,21.57],[5.4,3],[6.6,12.72],[7.6,13.62],[6.2,30.39],[1.23,3],[1.99,3],[5.1,8.65],[1.05,1628.57],[2.9,10.12],[8,12.25],[4,51],[1.7,25],[1.35,15],[5.2,3],[5.3,3.08],[5,3.67],[5.9,13.22],[8.8,15],[1.11,1],[2.1,22],[1.42,50],[5.7,9.68],[5.8,8.15],[4.3,1],[3,52.5],[1.68,1],[2.3,1],[2.92,51.56],[3.3,129.13],[3.5,79.2],[4.4,3.55],[3.8,3.55],[3.1,130],[1.55,1.74],[4.2,2],[4.7,2],[4.9,3],[5.5,2],[4.6,2],[4.5,2],[3.9,0.28],[2.14,14.04],[2.26,12.7],[2.32,12.12],[2.58,19.62],[2.66,3.75],[2.46,32.88],[2.86,2.75],[1.51,98.04],[2.04,72.12],[1.5,10],[4.8,2.11]],"atl":[[12,14.67],[32,1.99],[12.5,28.94],[1000,0.25],[14.5,22.57],[13,12.05],[200,50],[13.5,13.08],[15,24.6],[14,12.25],[16,4.3],[24,2.99],[15.5,35.51],[800,0.05],[180,0.1],[50,2.09],[16.5,1.99],[17,1],[980,0.16],[23,2.99],[17.5,2.55],[18,1.5],[25,2.5],[34,18.24],[19,1.99],[20,2.5],[18.5,5.84],[26,3.99],[330,0.1],[19.5,1],[70,1.99],[65,1],[44,2.03],[60,1.99],[48,1],[46,1.99],[42,1.99],[150,1],[100,0.84],[40,1],[38,1],[36,1.99],[21,6],[30,1.99],[950,0.01],[29,1],[28,1.99],[27,1],[230,0.2],[22,1.99],[75,0.01],[400,0.02],[160,2],[55,21]],"trd":[[11.5,678.1],[12,1275.65],[12.5,456.04],[8.8,192.6],[7.6,164.43],[16.5,103.72],[16,70.5],[14.5,49.45],[8.4,141.77],[14,214.93],[7.8,82.7],[13.5,262.3],[13,227.2],[10,129.27],[8.6,123.58],[9.6,168.67],[9.2,98.85],[15,141.65],[15.5,134.33],[17,42.64],[17.5,4.93],[9.4,107.38],[11,45.15],[9,205.04],[8,57.3],[7.4,80.85],[8.2,56.94],[10.5,91.31],[9.8,103.54],[7.2,12.49],[5.9,1.74],[6,13.14],[6.4,5.46],[6.6,2.54],[5.8,3.02],[1.63,16.86],[1.62,1.04],[1.6,2.1]],"batb":[[0,11.5,55.61],[1,11,84],[2,10.5,38.37]],"batl":[[0,12,14.67],[1,12.5,28.94],[2,13,12.05]],"ltp":11.5,"tv":5569.21,"id":40389088},{"atb":[[4.9,233.5],[5.2,82.98],[5.1,327.58],[4.7,116.2],[4.8,215.59],[5,275.68],[1.17,1],[1.44,7981.1],[2.54,4926.28],[4.4,105.95],[4.3,63.77],[4.5,43.18],[4.1,16.17],[2.84,0.08],[4.6,61.05],[2,26.88],[1.83,5464],[1.04,4.12],[1.1,9],[1.01,56964.24],[1.6,76.53],[4.2,37.91],[3.75,12],[3.8,41.87],[3.95,17.17],[2.02,35.69],[1.03,287.24],[1.8,4],[1.2,0.48],[1.75,1],[1.55,2],[1.22,3],[1.02,5178.56],[3.65,57.23],[1.26,0.5],[3,39.53],[3.85,91.31],[1.05,599.17],[2.5,1],[4,70.1],[1.06,5409.02],[1.23,3],[2.96,1.99],[3.9,13.53],[2.98,2],[1.7,26],[1.35,10],[3.15,1.99],[3.2,3],[3.25,1],[3.3,2],[1.5,11],[3.4,3],[3.35,3],[3.45,1.99],[3.05,2.55],[2.58,125.32],[2.66,178.92],[2.46,89.04],[2.74,116.54],[2.86,3.55],[1.42,50],[1.68,1],[2.3,1],[3.55,8.29],[3.5,4],[3.7,12],[3.6,8],[2.14,14.04],[2.2,13.33],[2.34,35.82],[3.1,35.71],[1.51,98.04],[2.04,72.12]],"atl":[[1000,21.16],[5.4,83.05],[5.3,403.19],[5.5,67.21],[5.8,29.67],[5.6,38.15],[9.2,1],[5.7,140.94],[6.2,124.67],[5.9,55.41],[200,50],[6,223.73],[16,2],[9,6.54],[110,0.3],[14,1.4],[24,0.4],[10,25.24],[8.6,21],[8,5.55],[800,0.05],[180,0.1],[50,1.6],[7.4,3.35],[8.4,3.55],[990,0.16],[7.8,11.66],[10.5,1.16],[6.4,46.36],[8.8,5.75],[13.5,1],[7.6,23],[8.2,5.54],[9.6,1],[330,0.1],[11,1.12],[6.6,10],[6.8,1],[7,2.99],[150,1],[12,1.99],[7.2,1],[950,0.01],[900,1],[11.5,3.66],[230,0.2],[22,1],[21,1.99],[20,1],[9.8,4.55],[19.5,1.99],[19,1.99],[18.5,1.99],[18,1.99],[17.5,1.99],[16.5,1],[15.5,1],[9.4,1.99],[15,1],[14.5,1.99],[13,1],[12.5,1],[75,0.01],[400,0.02],[160,2],[55,21],[17,18],[34,19.5],[65,2.5],[40,1.5],[30,1.5]],"trd":[[5.2,1244.4],[5.1,1142.86],[5.3,84.89],[5,2021.88],[4.9,2176.21],[4.8,2759.89],[4.7,1111.23],[7.6,20.21],[5.6,380.11],[7.8,109.19],[5.8,145.4],[7,60.93],[5.7,112.81],[6,511.87],[5.5,329.57],[6.2,799.64],[5.4,158.91],[5.9,118.75],[7.4,41.05],[6.4,872.09],[6.6,473.79],[7.2,118.3],[6.8,112.95],[8,22.65],[8.2,10.19]],"batb":[[0,5.2,82.98],[1,5.1,327.58],[2,5,275.68]],"batl":[[1,5.4,83.05],[0,5.3,403.19],[2,5.5,67.21]],"ltp":5.2,"tv":14939.77,"id":270592},{"atb":[[8.4,66.43],[8.8,23.3],[8.6,75.14],[8.2,24.46],[8,59.35],[7.6,37.02],[7.8,29.86],[2.98,4924.31],[1.44,8269.63],[1.17,7.15],[2,124.01],[2.2,2],[7.4,27.18],[1.83,5464],[4.4,2],[1.1,9],[1.6,76.53],[4.6,2],[4.7,1],[4.8,2],[5,2.84],[6,5.87],[7.2,26.62],[7,22.73],[1.01,59222.42],[1.04,4.12],[1.8,4],[1.75,1],[1.2,0.48],[1.26,0.5],[1.02,5153.56],[5.5,5.76],[1.03,237.24],[6.4,18.49],[4.3,0.08],[1.05,1358.57],[6.8,41],[4.1,63.87],[1.11,35],[1.06,5310.34],[1.23,3],[2.4,2],[5.1,7.66],[2.02,6],[1.09,1],[1.9,1],[1.7,25],[4,50],[5.2,1],[6.6,5.55],[1.42,50],[1.68,1],[2.3,1],[3.75,36],[3.95,33.56],[4.9,71.17],[4.5,85.11],[6.2,15.82],[5.7,2],[5.6,1.99],[5.4,3.45],[5.9,2],[5.3,1.99],[5.8,1],[2.48,10.81],[2.66,9.64],[2.6,10],[2.8,26.67],[3.5,2.75],[3,3.75],[2.92,16.15],[1.51,98.04],[2.04,72.12],[3.1,35.71],[1.5,10]],"atl":[[44,1],[9.2,57.99],[1000,0.41],[9,13.54],[9.6,49.14],[11,22.01],[10,102.19],[200,50],[12,36.72],[9.8,19.52],[10.5,51.54],[11.5,54.03],[13,11.99],[9.4,19.4],[12.5,18.28],[13.5,2],[14,18.02],[14.5,2.99],[16,2.99],[15,177.6],[19,2.99],[16.5,2.5],[17,21.48],[800,0.05],[180,0.1],[50,0.1],[18.5,8.39],[17.5,8.52],[21,3.73],[330,0.1],[15.5,2.99],[22,2.03],[150,1.1],[18,71.5],[950,0.01],[48,1.99],[46,1],[42,1],[40,1.99],[38,1],[230,0.2],[36,1.99],[30,1.99],[29,1.99],[28,1],[27,3.49],[26,1],[25,1],[24,1],[23,1.99],[20,1.99],[19.5,1.99],[32,1.99],[75,0.01],[400,0.02],[160,2],[55,21],[34,19.5]],"trd":[[8.8,161.63],[9,255.5],[8.6,186.25],[9.2,594.43],[9.4,289.25],[9.6,157.68],[9.8,478.51],[10,774.51],[10.5,1752.49],[11,2213.06],[11.5,322.77],[12,198.83],[7,12.45],[14.5,68.38],[8.4,16.64],[14,248.76],[13.5,142.01],[13,286.47],[7.2,8.2],[12.5,63.45],[8,28.61],[15,37.28],[7.6,7.8],[7.4,1.36],[7.8,2.5]],"batb":[[2,8.4,66.43],[1,8.6,75.14],[0,8.8,23.3]],"batl":[[1,9.2,57.99],[0,9,13.54],[2,9.4,19.4]],"ltp":8.8,"tv":8308.82,"id":35856222},{"atb":[[15,3],[28,2],[50,14.9],[46,7.08],[40,20.3],[19.5,1],[34,7.82],[17,2.06],[60,21.03],[55,13.97],[1.44,7652.42],[5.1,4965.29],[12,4],[48,2.42],[17.5,1.37],[1.03,237.24],[16.5,9.77],[1.01,41642.97],[16,10.86],[2,23.16],[1.83,5464],[1.17,2],[1.1,111],[1.6,76.53],[29,1],[26,1.99],[38,12.54],[44,3.34],[1.02,5121.68],[1.8,4],[1.75,1],[42,7.04],[1.04,4.12],[1.05,28.57],[20,2.42],[1.2,0.48],[1.26,0.5],[10,28.35],[21,9.35],[5,5.01],[1.9,45],[18.5,9.13],[18,5.25],[23,1.99],[36,4],[19,7.55],[22,4.21],[15.5,6.03],[1.06,5526.11],[14.5,2],[30,5.8],[9.8,1.08],[14,3.55],[9.6,34.53],[9.4,2],[13.5,1.99],[4,50.01],[1.7,25],[9.2,2.15],[13,2.55],[32,1.99],[5.2,7.38],[2.2,44],[3.9,10],[27,1.04],[25,1],[2.02,100],[9,22],[3.05,20],[1.42,50],[1.68,1],[12.5,1.99],[10.5,9.52],[2.3,1],[11.5,3.91],[24,3.35],[8.6,2],[2.7,5],[3.5,11.4],[4.5,5],[1.11,90],[8.8,25.38],[7.6,15],[11,27.3],[8.4,13.38],[7.2,2.75],[6.2,14.42],[3.8,5.71],[3.95,5.42],[4.6,13.33],[5.6,3.75],[1.51,98.04],[2.04,72.12],[3.1,35.71],[1.5,10]],"atl":[[65,17.61],[95,9.01],[70,8.98],[75,4.94],[1000,11.86],[80,3.96],[85,1],[800,0.05],[180,1.1],[90,1.96],[110,2.41],[120,1],[100,1.99],[330,0.1],[150,2],[950,0.01],[360,0.1],[200,1],[190,1],[170,1.99],[140,1.99],[130,1],[230,0.2],[400,0.02],[160,2],[340,0.2],[890,1]],"trd":[[60,300.78],[65,35.52],[55,152.62],[50,47.9],[28,14.23],[26,23.26],[22,34.86],[21,59.98],[19.5,91.46],[48,52.51],[46,42.33],[44,63.05],[42,175.41],[40,81.25],[24,30.78],[19,45.25],[36,32.23],[32,7.14],[38,37.76],[18.5,24.05],[34,21.41],[20,11.19],[30,17.45],[27,4.6],[25,50.16],[23,9.86],[29,6.98],[18,7.92]],"batb":[[2,50,14.9],[0,60,21.03],[1,55,13.97]],"batl":[[0,65,17.61],[2,75,4.94],[1,70,8.98]],"ltp":60,"tv":1481.94,"id":59626646},{"atb":[[1.17,2.79],[5.1,91.38],[4.7,46.26],[4.5,62.68],[5,1120.43],[2.52,4936.86],[1.44,8279.67],[4.4,61.32],[4.6,92.41],[4.1,92.76],[4.9,76.31],[4.8,85.68],[3.4,22.47],[2,39.37],[1.83,5464],[1.01,51462.91],[1.6,76.53],[4.3,36.78],[1.8,64],[1.75,1],[1.2,0.48],[4.2,64.58],[3.2,3.16],[1.05,28.57],[3.85,60.52],[1.26,0.5],[1.02,5153.56],[2.9,2],[3.95,13.82],[1.03,287.24],[2.2,3],[4,209.01],[3,25],[1.06,5556.22],[1.23,3],[2.6,6],[1.27,12],[1.54,6],[1.72,3],[2.04,75.12],[2.4,3],[2.7,3],[3.1,38.71],[2.84,0.08],[1.7,48.86],[3.9,11.69],[1.35,41],[1.9,3.75],[3.45,27.54],[1.87,113.79],[2.14,3.55],[1.93,212.9],[1.91,108.79],[1.97,306.19],[2.3,3.55],[2.02,194.12],[1.42,50],[3.35,13.96],[3.5,10.48],[3.55,8.29],[3.65,5.36],[3.6,7.26],[3.75,4.93],[3.8,5.4],[3.7,6.59],[1.68,1],[1.89,1],[2.92,1.99],[2.94,3],[2.96,1.99],[3.15,3],[3.05,1],[3.3,1.99],[2.98,1.99],[3.25,1.32],[1.86,36.05],[1.64,25],[1.73,21.92],[1.51,98.04],[1.5,10]],"atl":[[1000,4.68],[5.3,121.1],[5.4,89.71],[5.2,47.18],[5.6,37.79],[6,1.7],[9.4,2],[5.5,50.66],[5.9,14.01],[6.2,4.78],[200,50],[5.7,64],[16,1],[5.8,41.19],[9,7.12],[10,26.99],[6.6,67.16],[9.2,3.09],[15,5.76],[800,0.05],[180,0.1],[50,0.1],[8.8,7.69],[6.8,3.55],[9.8,2.39],[7.2,23.4],[990,0.16],[14,1.5],[8.4,6.75],[8.6,5.55],[6.4,1.99],[7,1.99],[22,1.04],[330,0.1],[150,1],[7.8,8.39],[11.5,2.99],[950,0.01],[11,1.99],[10.5,1.06],[30,1],[230,0.2],[8,1.99],[9.6,2.05],[8.2,2],[7.4,3.55],[7.6,3.55],[75,0.01],[400,0.02],[17,20.5],[160,2],[55,21],[34,18],[12.5,3.4],[13.5,1],[21,1.5]],"trd":[[5.1,2732.21],[5.2,3421.07],[5.3,971.53],[5,929.13],[6.6,55.89],[8.8,2.51],[5.7,85.32],[5.5,70.97],[4.6,164.3],[4.5,42.91],[7.2,46.2],[5.4,75.84],[5.9,49.75],[4.9,673.32],[6.8,65.15],[5.8,71.7],[6.4,88.04],[4.8,939.32],[4.7,799.29],[7,61.21],[6,59.93],[6.2,60.74],[7.4,35.8],[5.6,83.62],[7.6,2.04],[8.6,1.08]],"batb":[[0,5.1,91.38],[1,5,1120.43],[2,4.9,76.31]],"batl":[[1,5.3,121.1],[2,5.4,89.71],[0,5.2,47.18]],"ltp":5.1,"tv":11588.87,"id":56297029},{"atb":[[10,68.79],[6.6,7.04],[7.8,4.84],[8.8,5.51],[7.4,14.43],[8.4,31.24],[9.6,39.05],[3.25,4909.26],[1.44,8275.49],[9.8,36.46],[1.17,1],[9,16.78],[9.4,42.43],[1.01,79262.31],[2,24.01],[1.83,5464],[1.1,9],[1.6,76.53],[7.6,5.27],[6,6.73],[8.2,9.67],[8,20],[1.8,4],[1.75,1],[4.8,3.89],[1.2,0.48],[6.2,25.05],[1.03,242.73],[2.02,10],[7.2,13.24],[8.6,7.21],[1.04,35],[9.2,16.59],[1.26,20.5],[1.02,5225.22],[1.11,23],[6.4,41.02],[1.05,2990.17],[1.3,5],[3.7,17.56],[1.06,5646.54],[6.8,12.33],[1.23,3],[7,25.19],[5.1,12.21],[4.7,2.08],[4.6,3.25],[2.92,10.1],[4.5,76.57],[1.7,25],[3,5],[4,50],[1.09,1],[1.12,81.2],[1.16,5],[1.42,50],[1.21,9],[4.3,3],[5.7,10.69],[5.8,6.15],[5.9,10.58],[1.68,1],[4.4,1.99],[1.32,25],[2.3,1],[4.9,1],[5,3],[3.75,36],[3.55,38.82],[4.1,95.81],[3.85,69.47],[1.64,1.61],[5.2,2],[5.3,2],[5.4,1],[5.5,3],[5.6,1],[3.4,29.41],[2.6,10],[2.42,11.27],[2.74,27.59],[2.54,10.39],[2.94,3.75],[3.35,2.75],[2.86,16.67],[1.51,98.04],[2.04,72.12],[3.1,35.71],[1.5,10],[3.15,31.74]],"atl":[[32,1],[11.5,38.24],[10.5,79.81],[11,64.29],[1000,3.66],[12,39.57],[13,5.13],[12.5,273.7],[14,16.68],[200,50],[13.5,22.59],[16,16.63],[19,2.55],[800,0.05],[180,0.1],[50,5.1],[14.5,36.77],[25,9.46],[15,11.23],[19.5,2.49],[18.5,5.25],[18,3.7],[17.5,8.04],[16.5,5.44],[15.5,3.58],[100,15.57],[46,1],[34,18],[330,0.1],[22,2.58],[150,1],[950,0.01],[28,1.99],[17,18],[230,0.2],[48,1],[44,1],[42,1.99],[40,1],[30,1.99],[29,1],[27,1.99],[26,1],[24,1],[23,1],[21,1.99],[20,3.49],[38,1],[36,1],[75,0.01],[400,0.02],[160,2],[55,21]],"trd":[[10.5,532.99],[10,155.62],[11,1247.25],[11.5,347.26],[12,661.34],[12.5,808.85],[8.8,232.88],[9.8,39.84],[14.5,22.02],[7.8,252.57],[13,648.73],[9,187.91],[8,76.23],[7.2,10.82],[9.6,67.38],[9.2,151.95],[13.5,172.65],[14,3.42],[9.4,99.75],[8.4,32.76],[8.6,84.65],[7.6,25.63],[7,15.84],[7.4,4.74],[8.2,2.44],[6.8,12.64],[5.7,2.86],[6.4,1.82],[5.6,0.94],[6.2,0.97]],"batb":[[0,10,68.79],[2,9.6,39.05],[1,9.8,36.46]],"batl":[[2,11.5,38.24],[0,10.5,79.81],[1,11,64.29]],"ltp":10.5,"tv":5904.75,"id":27115873},{"atb":[[17,21.92],[16,11.88],[1.01,44317.07],[16.5,31.97],[17.5,1],[15.5,29.7],[14.5,33.39],[12,23.09],[4.1,4996.24],[1.44,7908.34],[14,2],[13,3.78],[5.9,1.31],[5.7,1],[12.5,27.67],[11.5,9.14],[15,9.38],[9.8,4],[10,65.04],[5.4,2],[13.5,29.78],[1.05,4378.57],[2,24.01],[1.83,5464],[1.02,5153.56],[1.1,9],[5.2,70.71],[1.6,76.53],[1.17,2],[1.8,4],[1.75,1],[5.1,6.66],[1.2,0.48],[11,43.74],[9.4,27.66],[10.5,9.11],[9.6,2],[5,3.75],[4.8,52.11],[1.26,0.5],[2.02,12],[9,22.99],[1.03,242.73],[8.4,4],[8.6,4],[8.8,2.99],[9.2,2],[1.9,10],[1.61,80],[4.6,36.11],[6,8.75],[1.06,5206.63],[1.23,3],[1.7,25],[4.5,22.22],[5.5,1.99],[2.1,19],[4,66],[1.71,2],[3.05,1],[1.42,50],[1.68,1],[2.3,1],[5.8,3],[6.6,1.19],[1.11,33],[6.8,1],[7,1.99],[7.6,1.99],[7.2,1.99],[7.8,2],[7.4,3],[8.2,1],[4.2,30.94],[8,2.55],[6.4,3.55],[5.6,43.04],[3.65,6.04],[3.5,6.4],[3.2,7.27],[1.51,98.04],[2.04,72.12],[3.1,35.71],[6.2,14.42],[1.5,10]],"atl":[[22,6.57],[18,19.79],[19,19.06],[21,13.82],[18.5,12.46],[20,14.46],[1000,1.41],[200,50],[25,3.93],[19.5,19.62],[90,1],[85,1.99],[80,3.49],[24,4.01],[34,20.99],[30,10.6],[800,0.05],[180,0.1],[50,2.09],[60,1.99],[26,3.86],[23,4.89],[55,21],[330,0.1],[44,2.52],[150,1],[27,2.79],[950,0.01],[230,0.2],[29,3.66],[28,2.05],[75,2],[70,1.99],[65,2.5],[48,1.99],[46,1.99],[42,1.99],[40,1],[38,1.99],[36,1.99],[32,2.51],[400,0.02],[160,2]],"trd":[[18,92.22],[18.5,66.43],[19,123.8],[19.5,72.97],[20,8.14],[17.5,61.79],[17,358.92],[16.5,268.33],[16,477.42],[15.5,417.89],[15,449.42],[14.5,321.33],[14,166.71],[13.5,247.37],[13,575.01],[12.5,561.72],[12,249.95],[23,17.89],[11.5,3.92],[22,2],[21,10]],"batb":[[1,17,21.92],[2,16.5,31.97],[0,17.5,1]],"batl":[[0,18,19.79],[2,19,19.06],[1,18.5,12.46]],"ltp":18,"tv":4553.23,"id":58186642},{"atb":[[6.4,80.25],[5.7,78.92],[6.2,127.67],[6,184.84],[5.9,29.77],[5.2,80.57],[5.3,29.45],[4.8,20.45],[2,50.01],[2.74,4883.37],[1.44,8335.7],[5.4,18.47],[5.5,125],[5.8,91.94],[3.7,2.17],[1.05,28.57],[5.6,86.24],[1.83,5464],[1.1,9],[1.26,45.5],[1.01,46366.67],[1.6,76.53],[1.52,10],[3.1,40.71],[4.6,51.83],[3.9,11.52],[5,59.2],[1.8,5],[1.75,1],[4,68.47],[1.03,292.73],[4.9,65.32],[1.02,5153.56],[1.17,1],[1.09,1],[1.5,11],[2.4,20],[5.1,8.89],[3.2,1.08],[3.15,2.32],[1.11,1],[4.2,25.2],[1.06,5595.53],[4.1,36.64],[4.5,19.37],[4.4,134.9],[4.3,33.96],[1.23,3],[1.16,5],[1.7,25],[1.35,10],[4.7,30.43],[3.75,3],[2.26,78.57],[2.58,6.3],[2.18,124.58],[2.46,135.62],[2.38,218.97],[2.3,177.16],[1.42,50],[3.85,10.87],[3.95,9.32],[1.68,1],[1.36,1.98],[1.76,18],[2.98,1],[3,2],[3.65,3],[3.4,1],[3.45,2],[3.05,3],[3.3,1],[3.5,1.99],[3.55,2],[3.25,3],[3.8,1],[3.35,2],[1.93,17.2],[2.04,87.5],[1.99,16.16],[1.51,98.04],[3.6,18]],"atl":[[6.6,64.91],[7.2,42.19],[12,27],[8.4,1],[7.6,2],[8.6,1],[6.8,81.7],[11,26],[7,32.54],[7.4,38.1],[7.8,1],[200,50],[1000,2.9],[9.8,22],[11.5,26.99],[10.5,26.99],[10,45],[9.6,22],[16,2],[9,5.34],[8,21],[800,0.05],[180,0.1],[50,1.1],[8.2,64],[9.4,1.06],[8.8,1.99],[9.2,1.99],[15,3.26],[980,0.16],[25,1.5],[13,5.24],[13.5,5],[12.5,5.99],[330,0.1],[14,2.03],[150,1],[16.5,3.49],[15.5,1.99],[950,0.01],[55,21.1],[14.5,1],[230,0.2],[75,0.01],[400,0.02],[160,2],[17,18],[34,18],[17.5,1.5],[20,1.5]],"trd":[[6.4,2749.39],[6.6,1567.62],[6.2,2272.17],[6,1857.97],[6.8,439.28],[7,95.31],[7.2,7.72],[4.7,8.33],[5.2,137.08],[5.5,217.03],[5,140.9],[5.1,67.64],[5.6,286.43],[5.9,260.66],[5.3,181.37],[5.8,401.64],[5.7,461.06],[5.4,56.79],[4.9,10.73],[4.8,19.38]],"batb":[[0,6.4,80.25],[1,6.2,127.67],[2,6,184.84]],"batl":[[0,6.6,64.91],[1,6.8,81.7],[2,7,32.54]],"ltp":6.4,"tv":11238.5,"id":26496185},{"atb":[[10.5,52],[9,5.29],[1.17,2],[3.3,4925.98],[1.44,7805.47],[9.8,24.4],[10,57.2],[9.6,31.4],[2,23.01],[1.83,5464],[1.01,43243.23],[1.1,9],[1.6,76.53],[8.6,14.52],[6,6.21],[1.8,4],[1.02,5161.8],[1.75,1],[9.4,21.34],[8.2,28.88],[9.2,15.66],[1.26,0.5],[8.8,37.62],[4.3,3.08],[5.5,1.21],[1.03,237.24],[1.9,7],[6.4,20.01],[8.4,3],[7.6,9.3],[1.06,6038.78],[7.8,7.26],[7.4,7.99],[1.23,3],[4.1,3.55],[8,38.5],[5.1,9.66],[1.05,28.57],[4,50],[3.95,0.27],[1.7,25],[1.11,1],[7.2,4.63],[7,4.9],[1.09,1],[6.8,4.67],[6.6,4.05],[4.4,3],[4.5,1.99],[4.6,2],[4.7,1.99],[4.8,2],[1.42,50],[5.7,8.99],[5.8,7.15],[5.9,6.41],[6.2,17.51],[1.68,1],[2.3,13.31],[5,2.48],[3.05,48.29],[3.25,44],[3.75,72],[3.55,116.47],[4.9,3.55],[3.35,84.26],[5.2,2],[5.6,1.99],[5.4,3],[5.3,2],[2.62,19.14],[2.18,13.56],[2.5,32],[2.36,11.76],[2.7,3.75],[2.9,2.75],[1.51,98.04],[2.04,72.12],[3.1,35.71],[1.5,10]],"atl":[[11,79.82],[13,23.99],[11.5,59.06],[14,8],[13.5,2.99],[12.5,38.71],[12,26.9],[25,2.2],[1000,18.87],[200,50],[16,4.03],[19,3.23],[15,19.23],[36,3.49],[800,0.05],[180,0.1],[50,0.1],[14.5,17.09],[48,1.5],[990,0.16],[17.5,2.77],[29,1.99],[23,1.99],[28,1],[330,0.1],[15.5,2.99],[22,2.17],[150,1],[950,0.01],[120,0.1],[18,1],[30,1.99],[32,1.99],[230,0.2],[27,1.99],[26,2.5],[24,1.99],[21,1],[20,1],[19.5,1],[18.5,1],[17,1],[16.5,1.99],[290,1],[75,1.51],[400,0.02],[34,18],[160,2],[55,21],[60,1.5],[40,1.5]],"trd":[[10.5,406.81],[11,1084.67],[11.5,502.89],[12,47.4],[8.8,72.95],[9.6,191.14],[9.4,249.59],[14.5,1.07],[8.4,83.12],[12.5,27.46],[10,402.8],[9.2,360.96],[9,147.06],[9.8,249.25],[8.6,27.42],[13,24.48],[14,18.82],[13.5,16.79],[8.2,5.26],[8,0.44]],"batb":[[0,10.5,52],[2,9.8,24.4],[1,10,57.2]],"batl":[[0,11,79.82],[1,11.5,59.06],[2,12,26.9]],"ltp":10.5,"tv":3920.38,"id":44049799}],"img":true,"tv":67505.47}]}
{"op":"mcm","id":2,"clk":"AAMABAAE","pt":1743511673000,"mc":[{"id":"1.241629436","rc":[{"atb":[[1.17,2]],"atl":[[1000,4.52]],"id":56297029}]}]}
{"op":"mcm","id":2,"clk":"AAwABwAK","pt":1743511673103,"mc":[{"id":"1.241629436","rc":[{"atb":[[5.1,112.17]],"atl":[[5.3,121.26]],"batb":[[0,5.1,112.17]],"batl":[[1,5.3,121.26]],"id":56297029}]}]}
{"op":"mcm","id":2,"clk":"ACcAGAAi","pt":1743511673409,"mc":[{"id":"1.241629436","rc":[{"atl":[[5.3,401.1]],"trd":[[5.3,89.07]],"batl":[[0,5.3,401.1]],"ltp":5.3,"tv":14943.95,"id":270592},{"atb":[[8.4,60.71]],"batb":[[2,8.4,60.71]],"id":35856222}],"tv":67509.65}]}
{"op":"mcm","id":2,"clk":"ADwALwA2","pt":1743511673723,"mc":[{"id":"1.241629436","rc":[{"atb":[[5.2,139.47]],"batb":[[0,5.2,139.47]],"id":270592}]}]}
{"op":"mcm","id":2,"clk":"AEsAOwBL","pt":1743511673935,"mc":[{"id":"1.241629436","rc":[{"atl":[[1000,23.16]],"id":270592}]}]}
{"op":"mcm","id":2,"clk":"AFUASwBW","pt":1743511674134,"mc":[{"id":"1.241629436","rc":[{"atl":[[1000,21.16]],"id":270592}]}]}
{"op":"mcm","id":2,"clk":"AGYAWABk","pt":1743511674340,"mc":[{"id":"1.241629436","rc":[{"atl":[[5.2,51.18]],"batl":[[0,5.2,51.18]],"id":56297029}]}]}
{"op":"mcm","id":2,"clk":"AHoAcACFAQ==","pt":1743511674601,"mc":[{"id":"1.241629436","rc":[{"atl":[[5.2,76.18]],"batl":[[0,5.2,76.18]],"id":56297029}]}]}
{"op":"mcm","id":2,"clk":"AIkBAHoAlwE=","pt":1743511674814,"mc":[{"id":"1.241629436","rc":[{"atb":[[8,57.51]],"batb":[],"id":35856222}]}]}
{"op":"mcm","id":2,"clk":"AI8BAIIBAJ4B","pt":1743511674915,"mc":[{"id":"1.241629436","rc":[{"atb":[[8,59.35]],"batb":[],"id":35856222}]}]}
{"op":"mcm","id":2,"clk":"AJ0BAJIBALEB","pt":1743511675109,"mc":[{"id":"1.241629436","rc":[{"atl":[[65,0.24]],"trd":[[65,70.26]],"batl":[[2,80,3.96],[1,75,4.94],[0,70,9.22]],"ltp":65,"tv":1516.68,"id":59626646},{"atb":[[10,66.79]],"trd":[[10,159.62]],"batb":[[0,10,66.79]],"ltp":10,"tv":5908.75,"id":27115873},{"atb":[[17,16.31],[17.5,5.93]],"batb":[[1,17,16.31],[0,17.5,5.93]],"id":58186642}],"tv":67548.39}]}
{"op":"mcm","id":2,"clk":"AKEBAJ0BALoB","pt":1743511675217,"mc":[{"id":"1.241629436","rc":[{"atb":[[5.2,159.47]],"batb":[[0,5.2,159.47]],"id":270592},{"atb":[[60,20.75],[65,2.59]],"atl":[[65,0]],"trd":[[65,70.74]],"batb":[[2,55,13.97],[1,60,20.75],[0,65,2.59]],"batl":[[0,70,8.98]],"tv":1517.16,"id":59626646},{"atb":[[10,68.35]],"batb":[[0,10,68.35]],"id":27115873}],"tv":67548.87}]}
{"op":"mcm","id":2,"clk":"AK4BAKYBAMIB","pt":1743511675328,"mc":[{"id":"1.241629436","rc":[{"atb":[[60,23.87],[65,1.36]],"atl":[[95,9.31],[90,2.3]],"trd":[[65,73.2]],"batb":[[1,60,23.87],[0,65,1.36]],"batl":[],"tv":1519.62,"id":59626646}],"tv":67551.33}]}
{"op":"mcm","id":2,"clk":"ALYBAKsBAMcB","pt":1743511675424,"mc":[{"id":"1.241629436","rc":[{"atb":[[60,26.91],[65,0]],"atl":[[1000,12.86],[65,0.09]],"trd":[[65,75.92]],"batb":[[2,50,14.9],[1,55,13.97],[0,60,26.91]],"batl":[[0,70,9.07]],"tv":1522.34,"id":59626646},{"atb":[[6.4,120.59]],"batb":[[0,6.4,120.59]],"id":26496185}],"tv":67554.05}]}
{"op":"mcm","id":2,"clk":"AL8BALIBANAB","pt":1743511675528,"mc":[{"id":"1.241629436","rc":[{"atb":[[60,27.39],[55,13.47],[65,1.29]],"atl":[[1000,11.91],[65,0]],"trd":[[65,76.1]],"batb":[[2,55,13.47],[1,60,27.39],[0,65,1.29]],"batl":[[0,70,8.98]],"tv":1522.52,"id":59626646},{"atb":[[5.1,111.05]],"trd":[[5.1,2734.45]],"batb":[[0,5.1,111.05]],"tv":11591.11,"id":56297029},{"atb":[[10.5,55.76]],"batb":[[0,10.5,55.76]],"id":44049799}],"tv":67556.47}]}
{"op":"mcm","id":2,"clk":"AMQBALMBANYB","pt":1743511675629,"mc":[{"id":"1.241629436","rc":[{"atb":[[60,24.35],[65,3.02]],"atl":[[1000,11.86],[95,9.01],[90,1.96]],"trd":[[65,77.82]],"batb":[[1,60,24.35],[0,65,3.02]],"batl":[],"tv":1524.24,"id":59626646},{"atb":[[8.4,32.39]],"batb":[],"id":27115873}],"tv":67558.19}]}
{"op":"mcm","id":2,"clk":"AM0BAL0BANwB","pt":1743511675728,"mc":[{"id":"1.241629436","rc":[{"atb":[[65,2.97]],"atl":[[95,9.31],[90,2.3]],"trd":[[65,77.92]],"batb":[[0,65,2.97]],"batl":[],"tv":1524.34,"id":59626646}],"tv":67558.29}]}
{"op":"mcm","id":2,"clk":"ANIBAMEBAOEB","pt":1743511675830,"mc":[{"id":"1.241629436","rc":[{"atb":[[17.5,1]],"batb":[[0,17.5,1]],"id":58186642}]}]}
{"op":"mcm","id":2,"clk":"ANoBAMkBAOwB","pt":1743511675943,"mc":[{"id":"1.241629436","rc":[{"atb":[[50,19.92]],"batb":[],"id":59626646},{"atl":[[6.8,86]],"batl":[[1,6.8,86]],"id":26496185}]}]}
{"op":"mcm","id":2,"clk":"AOMBAM8BAPEB","pt":1743511676036,"mc":[{"id":"1.241629436","rc":[{"atb":[[17.5,0]],"atl":[[20,5.5],[17.5,5.44]],"trd":[[17.5,63.79]],"batb":[[2,16,11.88],[1,16.5,31.97],[0,17,16.31]],"batl":[[2,18.5,12.46],[1,18,19.79],[0,17.5,5.44]],"ltp":17.5,"tv":4555.23,"id":58186642},{"atl":[[25,0]],"id":26496185}],"tv":67560.29}]}
{"op":"mcm","id":2,"clk":"AOkBANMBAPgB","pt":1743511676136,"mc":[{"id":"1.241629436","rc":[{"atl":[[17.5,4.29]],"trd":[[17.5,66.09]],"batl":[[0,17.5,4.29]],"tv":4557.53,"id":58186642}],"tv":67562.59}]}
{"op":"mcm","id":2,"clk":"APUBANoBAPwB","pt":1743511676241,"mc":[{"id":"1.241629436","rc":[{"atb":[[11.5,53.61]],"trd":[[11.5,682.1]],"batb":[[0,11.5,53.61]],"tv":5573.21,"id":40389088},{"atb":[[5.1,131.05]],"batb":[[0,5.1,131.05]],"id":56297029},{"atb":[[16,14.2]],"batb":[[2,16,14.2]],"id":58186642},{"atb":[[10.5,53.76]],"trd":[[10.5,410.81]],"batb":[[0,10.5,53.76]],"tv":3924.38,"id":44049799}],"tv":67570.59}]}
{"op":"mcm","id":2,"clk":"AP0BAOABAIgC","pt":1743511676354,"mc":[{"id":"1.241629436","rc":[{"atl":[[65,1]],"id":270592},{"atb":[[17,20.69]],"atl":[[17.5,3.29]],"trd":[[17.5,68.09]],"batb":[[0,17,20.69]],"batl":[[0,17.5,3.29]],"tv":4559.53,"id":58186642}],"tv":67572.59}]}
{"op":"mcm","id":2,"clk":"AIECAOQBAIwC","pt":1743511676443,"mc":[{"id":"1.241629436","rc":[{"atl":[[12,20.69]],"batl":[[0,12,20.69]],"id":40389088}]}]}
{"op":"mcm","id":2,"clk":"AJUCAO0BAJ8C","pt":1743511676608,"mc":[{"id":"1.241629436","rc":[{"atb":[[11.5,48.61]],"atl":[[12,32.9]],"trd":[[11.5,692.1]],"batb":[[0,11.5,48.61]],"batl":[[0,12,32.9]],"tv":5583.21,"id":40389088},{"atb":[[30,0],[34,6.8]],"id":59626646},{"atl":[[25,7.96]],"id":27115873}],"tv":67582.59}]}
{"op":"mcm","id":2,"clk":"AJwCAPQBAKQC","pt":1743511676706,"mc":[{"id":"1.241629436","rc":[{"atb":[[11.5,30.97]],"batb":[[0,11.5,30.97]],"id":40389088},{"atb":[[10,68.25]],"trd":[[10,159.82]],"batb":[[0,10,68.25]],"tv":5908.95,"id":27115873}],"tv":67582.79}]}
{"op":"mcm","id":2,"clk":"AKMCAPgBAKsC","pt":1743511676810,"mc":[{"id":"1.241629436","rc":[{"atl":[[25,1]],"id":40389088},{"atl":[[7,36.84]],"batl":[[2,7,36.84]],"id":26496185}]}]}
{"op":"mcm","id":2,"clk":"ALYCAIACALoC","pt":1743511677020,"mc":[{"id":"1.241629436","rc":[{"atb":[[11.5,84.73]],"atl":[[12.5,34.75]],"batb":[[0,11.5,84.73]],"batl":[[1,12.5,34.75]],"id":40389088},{"atl":[[70,18.51]],"batl":[[0,70,18.51]],"id":59626646},{"atl":[[21,0]],"id":56297029}]}]}
{"op":"mcm","id":2,"clk":"AMACAIcCAMIC","pt":1743511677111,"mc":[{"id":"1.241629436","rc":[{"atl":[[5.3,275.25]],"batl":[[0,5.3,275.25]],"id":270592}]}]}
{"op":"mcm","id":2,"clk":"AMkCAIoCAMoC","pt":1743511677215,"mc":[{"id":"1.241629436","rc":[{"atl":[[34,18]],"id":35856222}]}]}
{"op":"mcm","id":2,"clk":"ANICAI8CANAC","pt":1743511677314,"mc":[{"id":"1.241629436","rc":[{"atl":[[12.5,28.94]],"batl":[[1,12.5,28.94]],"id":40389088},{"atl":[[5.7,142.84]],"batl":[],"id":270592}]}]}
{"op":"mcm","id":2,"clk":"AN0CAJQCANYC","pt":1743511677417,"mc":[{"id":"1.241629436","rc":[{"atl":[[12,20.69]],"batl":[[0,12,20.69]],"id":40389088},{"atl":[[75,0.01]],"id":44049799}]}]}
{"op":"mcm","id":2,"clk":"AO8CAJgCAN0C","pt":1743511677525,"mc":[{"id":"1.241629436","rc":[{"atb":[[11.5,89.58]],"batb":[[0,11.5,89.58]],"id":40389088}]}]}
{"op":"mcm","id":2,"clk":"AIkDAKYCAPQC","pt":1743511677827,"mc":[{"id":"1.241629436","rc":[{"atl":[[1000,23.16]],"id":270592}]}]}
{"op":"mcm","id":2,"clk":"AJIDAK4CAP0C","pt":1743511677936,"mc":[{"id":"1.241629436","rc":[{"atl":[[7.2,46.49]],"batl":[],"id":26496185}]}]}
{"op":"mcm","id":2,"clk":"AJoDALECAIAD","pt":1743511678038,"mc":[{"id":"1.241629436","rc":[{"atl":[[1000,21.16]],"id":270592}]}]}
{"op":"mcm","id":2,"clk":"AJ0DALMCAIYD","pt":1743511678131,"mc":[{"id":"1.241629436","rc":[{"atb":[[6.4,118.57]],"trd":[[6.4,2753.43]],"batb":[[0,6.4,118.57]],"tv":11242.54,"id":26496185}],"tv":67586.83}]}
{"op":"mcm","id":2,"clk":"AKkDALwCAI4D","pt":1743511678237,"mc":[{"id":"1.241629436","rc":[{"atb":[[5.1,130.05]],"trd":[[5.1,2736.45]],"batb":[[0,5.1,130.05]],"tv":11593.11,"id":56297029}],"tv":67588.83}]}
{"op":"mcm","id":2,"clk":"ALgDAMwCAJ0D","pt":1743511678447,"mc":[{"id":"1.241629436","rc":[{"atb":[[8.8,28.3]],"batb":[[0,8.8,28.3]],"id":35856222}]}]}
{"op":"mcm","id":2,"clk":"AL8DANICAKID","pt":1743511678544,"mc":[{"id":"1.241629436","rc":[{"atb":[[8.8,27.3]],"trd":[[8.8,163.63]],"batb":[[0,8.8,27.3]],"tv":8310.82,"id":35856222},{"atl":[[70,21.65]],"batl":[[0,70,21.65]],"id":59626646}],"tv":67590.83}]}
{"op":"mcm","id":2,"clk":"AMkDANYCAKcD","pt":1743511678648,"mc":[{"id":"1.241629436","rc":[{"atl":[[9,12.98]],"batl":[[0,9,12.98]],"id":35856222}]}]}
{"op":"mcm","id":2,"clk":"ANIDAN4CAK8D","pt":1743511678755,"mc":[{"id":"1.241629436","rc":[{"atl":[[1000,5.39]],"id":56297029}]}]}
{"op":"mcm","id":2,"clk":"ANsDAOICALMD","pt":1743511678806,"mc":[{"id":"1.241629436","rc":[{"atl":[[1000,4.52]],"id":56297029}]}]}
{"op":"mcm","id":2,"clk":"AOQDAOgCALwD","pt":1743511678911,"mc":[{"id":"1.241629436","rc":[{"atl":[[5.3,122.13]],"batl":[[1,5.3,122.13]],"id":56297029}]}]}
{"op":"mcm","id":2,"clk":"AP4DAP8CANMD","pt":1743511679312,"mc":[{"id":"1.241629436","rc":[{"atl":[[1000,23.16]],"id":270592}]}]}
{"op":"mcm","id":2,"clk":"AIUEAIYDANUD","pt":1743511679422,"mc":[{"id":"1.241629436","rc":[{"atl":[[7.4,42.4]],"batl":[],"id":26496185}]}]}
{"op":"mcm","id":2,"clk":"AIkEAIoDAOAD","pt":1743511679516,"mc":[{"id":"1.241629436","rc":[{"atl":[[1000,21.16]],"id":270592}]}]}
{"op":"mcm","id":2,"clk":"AKwEAKMDAP4D","pt":1743511680027,"mc":[{"id":"1.241629436","rc":[{"atb":[[5.2,159.37]],"trd":[[5.2,1244.6]],"batb":[[0,5.2,159.37]],"ltp":5.2,"tv":14944.15,"id":270592}],"tv":67591.03}]}
{"op":"mcm","id":2,"clk":"ALsEALIDAJME","pt":1743511680243,"mc":[{"id":"1.241629436","rc":[{"atb":[[5.2,157.87]],"trd":[[5.2,1247.6]],"batb":[[0,5.2,157.87]],"tv":14947.15,"id":270592}],"tv":67594.03}]}
{"op":"mcm","id":2,"clk":"APoEAOMDAMQE","pt":1743511681050,"mc":[{"id":"1.241629436","rc":[{"atl":[[6.6,66.41]],"batl":[[0,6.6,66.41]],"id":26496185}]}]}
{"op":"mcm","id":2,"clk":"AIAFAOYDAMUE","pt":1743511681102,"mc":[{"id":"1.241629436","rc":[{"atl":[[5.3,276.75]],"batl":[[0,5.3,276.75]],"id":270592},{"atl":[[5.2,77.68]],"batl":[[0,5.2,77.68]],"id":56297029}]}]}
{"op":"mcm","id":2,"clk":"AIkFAOkDAMwE","pt":1743511681206,"mc":[{"id":"1.241629436","rc":[{"atl":[[5.2,76.16]],"trd":[[5.2,3424.11]],"batl":[[0,5.2,76.16]],"ltp":5.2,"tv":11596.15,"id":56297029},{"atl":[[10.5,79.57]],"trd":[[10.5,533.47]],"batl":[[0,10.5,79.57]],"ltp":10.5,"tv":5909.43,"id":27115873}],"tv":67597.55}]}
{"op":"mcm","id":2,"clk":"AKAFAPMDANgE","pt":1743511681412,"mc":[{"id":"1.241629436","rc":[{"atb":[[5.1,131.05]],"batb":[[0,5.1,131.05]],"id":56297029},{"atb":[[17,20.34]],"atl":[[18,14.73],[17.5,4.44]],"batb":[[0,17,20.34]],"batl":[[1,18,14.73],[0,17.5,4.44]],"id":58186642},{"atb":[[10.5,51.98]],"batb":[[0,10.5,51.98]],"id":44049799}]}]}
{"op":"mcm","id":2,"clk":"AKYFAPYDAN8E","pt":1743511681514,"mc":[{"id":"1.241629436","rc":[{"atl":[[7,29.2]],"batl":[[2,7,29.2]],"id":26496185}]}]}
{"op":"mcm","id":2,"clk":"ALcFAP8DAOsE","pt":1743511681723,"mc":[{"id":"1.241629436","rc":[{"atb":[[60,24.31]],"batb":[[1,60,24.31]],"id":59626646}]}]}
{"op":"mcm","id":2,"clk":"AMkFAIQEAPEE","pt":1743511681825,"mc":[{"id":"1.241629436","rc":[{"atl":[[9,0]],"trd":[[9,281.46]],"batl":[[2,9.6,49.14],[1,9.4,19.4],[0,9.2,57.99]],"ltp":9,"tv":8336.78,"id":35856222}],"tv":67623.51}]}
{"op":"mcm","id":2,"clk":"ANAFAIYEAPUE","pt":1743511681924,"mc":[{"id":"1.241629436","rc":[{"atb":[[8.8,34.63]],"atl":[[9.2,51.64]],"batb":[[0,8.8,34.63]],"batl":[[0,9.2,51.64]],"id":35856222},{"atb":[[60,24.02]],"batb":[[1,60,24.02]],"id":59626646},{"atb":[[5.1,151.05]],"batb":[[0,5.1,151.05]],"id":56297029},{"atb":[[6.4,115.5]],"batb":[[0,6.4,115.5]],"id":26496185},{"atb":[[10.5,64.81]],"batb":[[0,10.5,64.81]],"id":44049799}]}]}
{"op":"mcm","id":2,"clk":"AN8FAIsEAP8E","pt":1743511682030,"mc":[{"id":"1.241629436","rc":[{"atb":[[7.8,27.92],[8,57.51]],"atl":[[10.5,53.92],[9.2,43.02]],"batb":[],"batl":[[0,9.2,43.02]],"id":35856222},{"atb":[[65,3.26]],"batb":[[0,65,3.26]],"id":59626646},{"atb":[[6.4,118.57]],"batb":[[0,6.4,118.57]],"id":26496185}]}]}
{"op":"mcm","id":2,"clk":"AOYFAJMEAIYF","pt":1743511682130,"mc":[{"id":"1.241629436","rc":[{"atb":[[60,25.71]],"batb":[[1,60,25.71]],"id":59626646}]}]}
{"op":"mcm","id":2,"clk":"APsFAKEEAJcF","pt":1743511682337,"mc":[{"id":"1.241629436","rc":[{"atb":[[11.5,88.32]],"trd":[[11.5,694.61]],"batb":[[0,11.5,88.32]],"tv":5585.72,"id":40389088}],"tv":67626.02}]}
{"op":"mcm","id":2,"clk":"AIMGAKgEAKAF","pt":1743511682441,"mc":[{"id":"1.241629436","rc":[{"atb":[[8.8,34.53]],"trd":[[8.8,163.83]],"batb":[[0,8.8,34.53]],"ltp":8.8,"tv":8336.98,"id":35856222}],"tv":67626.22}]}
{"op":"mcm","id":2,"clk":"AI8GAK0EAKgF","pt":1743511682554,"mc":[{"id":"1.241629436","rc":[{"atb":[[11.5,87.95]],"batb":[[0,11.5,87.95]],"id":40389088}]}]}
{"op":"mcm","id":2,"clk":"AKAGALoEALYF","pt":1743511682758,"mc":[{"id":"1.241629436","rc":[{"atb":[[5,1164.43]],"batb":[[1,5,1164.43]],"id":56297029}]}]}
{"op":"mcm","id":2,"clk":"AK8GAMAEAMAF","pt":1743511682902,"mc":[{"id":"1.241629436","rc":[{"atb":[[4.8,84.65]],"batb":[],"id":56297029}]}]}
{"op":"mcm","id":2,"clk":"ALwGAMgEAMsF","pt":1743511683105,"mc":[{"id":"1.241629436","rc":[{"atb":[[4.9,77.32]],"batb":[[2,4.9,77.32]],"id":56297029}]}]}
{"op":"mcm","id":2,"clk":"AMoGAM4EANMF","pt":1743511683215,"mc":[{"id":"1.241629436","rc":[{"atl":[[1000,23.16]],"id":270592},{"atb":[[6.4,102.57]],"trd":[[6.4,2785.43]],"batb":[[0,6.4,102.57]],"tv":11274.54,"id":26496185}],"tv":67658.22}]}
{"op":"mcm","id":2,"clk":"ANIGANIEANcF","pt":1743511683315,"mc":[{"id":"1.241629436","rc":[{"atl":[[5.2,70.55]],"batl":[[0,5.2,70.55]],"id":56297029},{"atl":[[17.5,0]],"trd":[[17.5,76.97]],"batl":[[2,19,19.06],[1,18.5,12.46],[0,18,14.73]],"tv":4568.41,"id":58186642},{"atl":[[6.6,75.71]],"batl":[[0,6.6,75.71]],"id":26496185}],"tv":67667.1}]}
{"op":"mcm","id":2,"clk":"AN8GANcEAN0F","pt":1743511683434,"mc":[{"id":"1.241629436","rc":[{"atl":[[1000,21.16]],"id":270592},{"atb":[[17,27.55]],"batb":[[0,17,27.55]],"id":58186642},{"atb":[[6.4,121.57]],"batb":[[0,6.4,121.57]],"id":26496185}]}]}
{"op":"mcm","id":2,"clk":"AOcGANwEAOIF","pt":1743511683517,"mc":[{"id":"1.241629436","rc":[{"atb":[[65,29.26]],"batb":[[0,65,29.26]],"id":59626646},{"atb":[[6.2,124.46]],"batb":[[1,6.2,124.46]],"id":26496185}]}]}
{"op":"mcm","id":2,"clk":"APAGAOEEAOMF","pt":1743511683624,"mc":[{"id":"1.241629436","rc":[{"atl":[[10.5,56.32],[9.2,49.46]],"batl":[[0,9.2,49.46]],"id":35856222},{"atl":[[70,21.36]],"batl":[[0,70,21.36]],"id":59626646}]}]}
{"op":"mcm","id":2,"clk":"APYGAOYEAOYF","pt":1743511683719,"mc":[{"id":"1.241629436","rc":[{"atb":[[8.8,36.16]],"batb":[[0,8.8,36.16]],"id":35856222}]}]}
{"op":"mcm","id":2,"clk":"AIMHAOsEAOoF","pt":1743511683826,"mc":[{"id":"1.241629436","rc":[{"atb":[[5.1,319.04]],"batb":[[1,5.1,319.04]],"id":270592},{"atl":[[20,0]],"id":26496185}]}]}
{"op":"mcm","id":2,"clk":"AJEHAPYEAPgF","pt":1743511684026,"mc":[{"id":"1.241629436","rc":[{"atb":[[5.1,327.58]],"atl":[[50,0.1]],"batb":[[1,5.1,327.58]],"id":270592},{"atb":[[5.1,150.83]],"batb":[[0,5.1,150.83]],"id":56297029}]}]}
{"op":"mcm","id":2,"clk":"AJoHAPsEAP4F","pt":1743511684132,"mc":[{"id":"1.241629436","rc":[{"atl":[[5.3,254.5]],"trd":[[5.3,133.56]],"batl":[[0,5.3,254.5]],"ltp":5.3,"tv":14991.64,"id":270592}],"tv":67711.59}]}
{"op":"mcm","id":2,"clk":"AKMHAIEFAIQG","pt":1743511684241,"mc":[{"id":"1.241629436","rc":[{"atl":[[20,1.99]],"id":27115873}]}]}
{"op":"mcm","id":2,"clk":"AKoHAIYFAI0G","pt":1743511684334,"mc":[{"id":"1.241629436","rc":[{"atb":[[5.1,154.61]],"batb":[[0,5.1,154.61]],"id":56297029}]}]}
{"op":"mcm","id":2,"clk":"ALQHAIoFAJMG","pt":1743511684434,"mc":[{"id":"1.241629436","rc":[{"atl":[[20,1]],"id":40389088},{"atb":[[10,72.5]],"batb":[[0,10,72.5]],"id":27115873},{"atl":[[6.6,58.53]],"trd":[[6.6,1601.99]],"batl":[[0,6.6,58.53]],"ltp":6.6,"tv":11308.91,"id":26496185}],"tv":67745.96}]}
{"op":"mcm","id":2,"clk":"AL4HAI8FAJoG","pt":1743511684541,"mc":[{"id":"1.241629436","rc":[{"atl":[[6.6,53.88]],"batl":[[0,6.6,53.88]],"id":26496185},{"atb":[[10.5,66.3]],"batb":[[0,10.5,66.3]],"id":44049799}]}]}
{"op":"mcm","id":2,"clk":"AMUHAJIFAJwG","pt":1743511684642,"mc":[{"id":"1.241629436","rc":[{"atb":[[11.5,91.46]],"batb":[[0,11.5,91.46]],"id":40389088},{"atb":[[8.4,31.24]],"batb":[],"id":27115873},{"atb":[[17.5,3.58]],"batb":[[2,16.5,31.97],[1,17,27.55],[0,17.5,3.58]],"id":58186642},{"atl":[[6.6,49.23]],"batl":[[0,6.6,49.23]],"id":26496185},{"atl":[[13.5,4.53],[13,25.66],[12.5,40.53]],"batl":[],"id":44049799}]}]}
{"op":"mcm","id":2,"clk":"ANEHAJkFAKQG","pt":1743511684749,"mc":[{"id":"1.241629436","rc":[{"atl":[[1000,23.16]],"id":270592},{"atl":[[70,19.91]],"trd":[[70,2.9]],"batl":[[0,70,19.91]],"ltp":70,"tv":1527.24,"id":59626646},{"atl":[[17,19]],"id":56297029}],"tv":67748.86}]}
{"op":"mcm","id":2,"clk":"ANgHAJsFAKcG","pt":1743511684842,"mc":[{"id":"1.241629436","rc":[{"atb":[[11.5,86.61]],"batb":[[0,11.5,86.61]],"id":40389088},{"atb":[[30,1]],"id":59626646}]}]}
{"op":"mcm","id":2,"clk":"AOAHAJ4FAK4G","pt":1743511684949,"mc":[{"id":"1.241629436","rc":[{"atl":[[1000,21.16]],"id":270592},{"atl":[[9.2,43.02]],"batl":[[0,9.2,43.02]],"id":35856222},{"atb":[[65,32.02]],"batb":[[0,65,32.02]],"id":59626646},{"atl":[[6.6,54.23]],"batl":[[0,6.6,54.23]],"id":26496185}]}]}
{"op":"mcm","id":2,"clk":"AOkHAKMFALEG","pt":1743511685004,"mc":[{"id":"1.241629436","rc":[{"atl":[[27,1.99]],"id":35856222}]}]}
{"op":"mcm","id":2,"clk":"AIAIAKoFALwG","pt":1743511685215,"mc":[{"id":"1.241629436","rc":[{"atl":[[60,0]],"id":44049799}]}]}
{"op":"mcm","id":2,"clk":"AL0IANIFAOsG","pt":1743511685920,"mc":[{"id":"1.241629436","rc":[{"atl":[[9.2,45.44]],"batl":[[0,9.2,45.44]],"id":35856222},{"atb":[[6.2,127.67]],"batb":[[1,6.2,127.67]],"id":26496185}]}]}
{"op":"mcm","id":2,"clk":"AMwIAN4FAPcG","pt":1743511686126,"mc":[{"id":"1.241629436","rc":[{"atb":[[4.7,118],[4.9,235.3],[4.6,62.85],[4.8,217.39]],"batb":[],"id":270592},{"atl":[[9.2,43.02]],"batl":[[0,9.2,43.02]],"id":35856222},{"atb":[[5.1,154.51]],"trd":[[5.1,2736.65]],"batb":[[0,5.1,154.51]],"ltp":5.1,"tv":11596.35,"id":56297029}],"tv":67749.06}]}
{"op":"mcm","id":2,"clk":"ANIIAOYFAP0G","pt":1743511686230,"mc":[{"id":"1.241629436","rc":[{"atb":[[4.2,39.71],[4.4,107.75],[4.1,17.97],[4.3,65.57],[4.5,44.98],[4,71.9]],"batb":[],"id":270592}]}]}
{"op":"mcm","id":2,"clk":"AOoIAPYFAI0H","pt":1743511686542,"mc":[{"id":"1.241629436","rc":[{"atl":[[95,9.01],[90,1.96]],"batl":[],"id":59626646}]}]}
{"op":"mcm","id":2,"clk":"AIMJAIUGAJ8H","pt":1743511686751,"mc":[{"id":"1.241629436","rc":[{"atb":[[11.5,85.35]],"batb":[[0,11.5,85.35]],"id":40389088},{"atb":[[5.2,153.87]],"trd":[[5.2,1255.6]],"batb":[[0,5.2,153.87]],"ltp":5.2,"tv":14999.64,"id":270592},{"atl":[[1000,1.88]],"id":58186642}],"tv":67757.06}]}
{"op":"mcm","id":2,"clk":"AJYJAJMGAK8H","pt":1743511686958,"mc":[{"id":"1.241629436","rc":[{"atl":[[1000,1.41]],"id":58186642}]}]}
{"op":"mcm","id":2,"clk":"AJsJAJsGALAH","pt":1743511687010,"mc":[{"id":"1.241629436","rc":[{"atb":[[17.5,3.11]],"trd":[[17.5,77.91]],"batb":[[0,17.5,3.11]],"tv":4569.35,"id":58186642}],"tv":67758}]}
{"op":"mcm","id":2,"clk":"AKAJAKQGALYH","pt":1743511687111,"mc":[{"id":"1.241629436","rc":[{"atb":[[4.9,214.45]],"batb":[],"id":270592},{"atb":[[6.4,123.12]],"batb":[[0,6.4,123.12]],"id":26496185}]}]}
{"op":"mcm","id":2,"clk":"AKwJAKsGAL4H","pt":1743511687214,"mc":[{"id":"1.241629436","rc":[{"atb":[[5,283.43]],"batb":[[2,5,283.43]],"id":270592},{"atb":[[65,33.34]],"batb":[[0,65,33.34]],"id":59626646}]}]}
{"op":"mcm","id":2,"clk":"ALcJALAGAMQH","pt":1743511687328,"mc":[{"id":"1.241629436","rc":[{"atl":[[9.2,49.45]],"batl":[[0,9.2,49.45]],"id":35856222},{"atb":[[6,163.26]],"batb":[[2,6,163.26]],"id":26496185}]}]}
{"op":"mcm","id":2,"clk":"AL4JALcGAMcH","pt":1743511687425,"mc":[{"id":"1.241629436","rc":[{"atb":[[11.5,85.16]],"trd":[[11.5,694.99]],"batb":[[0,11.5,85.16]],"tv":5586.1,"id":40389088}],"tv":67758.38}]}
{"op":"mcm","id":2,"clk":"AMkJAMAGAM0H","pt":1743511687528,"mc":[{"id":"1.241629436","rc":[{"atb":[[1.17,2.22],[11.5,83.8]],"atl":[[12.5,28.67],[12,21.59]],"batb":[[0,11.5,83.8]],"batl":[[1,12.5,28.67],[0,12,21.59]],"id":40389088},{"atb":[[1.17,7.41],[8.8,34.68]],"batb":[[0,8.8,34.68]],"id":35856222},{"atl":[[70,21.37]],"batl":[[0,70,21.37]],"id":59626646},{"atb":[[5.1,152.72]],"atl":[[1000,4.93],[5.3,121.97]],"batb":[[0,5.1,152.72]],"batl":[[1,5.3,121.97]],"id":56297029},{"atb":[[10,70.57]],"batb":[[0,10,70.57]],"id":27115873},{"atb":[[6.4,118.73]],"batb":[[0,6.4,118.73]],"id":26496185},{"atb":[[10.5,60.21]],"batb":[[0,10.5,60.21]],"id":44049799}]}]}
{"op":"mcm","id":2,"clk":"ANEJAMcGANMH","pt":1743511687625,"mc":[{"id":"1.241629436","rc":[{"atb":[[1.17,2],[11.5,81.77]],"trd":[[11.5,699.05]],"batb":[[0,11.5,81.77]],"tv":5590.16,"id":40389088},{"atb":[[1.17,7.15]],"atl":[[9.2,43.02]],"batl":[[0,9.2,43.02]],"id":35856222},{"atl":[[1000,4.52]],"id":56297029},{"atb":[[10,69.74]],"batb":[[0,10,69.74]],"id":27115873}],"tv":67762.44}]}
{"op":"mcm","id":2,"clk":"ANkJAMwGANkH","pt":1743511687731,"mc":[{"id":"1.241629436","rc":[{"atb":[[11,84.22]],"batb":[[1,11,84.22]],"id":40389088},{"atb":[[8.6,75.4]],"atl":[[9,1]],"batb":[[1,8.6,75.4]],"batl":[[2,9.4,19.4],[1,9.2,43.02],[0,9,1]],"id":35856222},{"atl":[[5.2,70.96]],"batl":[[0,5.2,70.96]],"id":56297029}]}]}
{"op":"mcm","id":2,"clk":"AOMJANIGAN8H","pt":1743511687834,"mc":[{"id":"1.241629436","rc":[{"atb":[[11.5,86.61]],"batb":[[0,11.5,86.61]],"id":40389088},{"atb":[[7.8,29.86],[8,59.35]],"atl":[[9.2,49.47],[9,5.86]],"batb":[],"batl":[[1,9.2,49.47],[0,9,5.86]],"id":35856222}]}]}
{"op":"mcm","id":2,"clk":"AJIKAO0GAIEI","pt":1743511688445,"mc":[{"id":"1.241629436","rc":[{"atl":[[1000,23.16]],"id":270592}]}]}
{"op":"mcm","id":2,"clk":"AJsKAPEGAIYI","pt":1743511688543,"mc":[{"id":"1.241629436","rc":[{"atl":[[9.2,51.86]],"batl":[[1,9.2,51.86]],"id":35856222}]}]}
{"op":"mcm","id":2,"clk":"AKIKAPUGAI4I","pt":1743511688649,"mc":[{"id":"1.241629436","rc":[{"atb":[[5.1,147.72]],"trd":[[5.1,2746.65]],"batb":[[0,5.1,147.72]],"tv":11606.35,"id":56297029}],"tv":67772.44}]}
{"op":"mcm","id":2,"clk":"AKwKAPgGAJQI","pt":1743511688753,"mc":[{"id":"1.241629436","rc":[{"atb":[[5.1,197.99]],"batb":[[0,5.1,197.99]],"id":56297029}]}]}
{"op":"mcm","id":2,"clk":"ALcKAP0GAJsI","pt":1743511688854,"mc":[{"id":"1.241629436","rc":[{"atl":[[1000,21.16]],"id":270592},{"atb":[[5.7,63.92]],"batb":[],"id":26496185}]}]}
{"op":"mcm","id":2,"clk":"ALwKAIEHAKII","pt":1743511688955,"mc":[{"id":"1.241629436","rc":[{"atb":[[11.5,81.77]],"batb":[[0,11.5,81.77]],"id":40389088},{"atb":[[4.9,76.31]],"batb":[[2,4.9,76.31]],"id":56297029}]}]}
{"op":"mcm","id":2,"clk":"AMUKAIgHAK8I","pt":1743511689009,"mc":[{"id":"1.241629436","rc":[{"atb":[[5,1165.42]],"batb":[[1,5,1165.42]],"id":56297029}]}]}
{"op":"mcm","id":2,"clk":"ANYKAI8HAMII","pt":1743511689222,"mc":[{"id":"1.241629436","rc":[{"atl":[[12,28.88]],"batl":[[2,12,28.88]],"id":44049799}]}]}
{"op":"mcm","id":2,"clk":"APUKAJ4HANsI","pt":1743511689523,"mc":[{"id":"1.241629436","rc":[{"atl":[[12.5,28.5]],"batl":[[1,12.5,28.5]],"id":40389088},{"atb":[[5.1,200.77]],"batb":[[0,5.1,200.77]],"id":56297029}]}]}
{"op":"mcm","id":2,"clk":"AIkLAKgHAOsI","pt":1743511689731,"mc":[{"id":"1.241629436","rc":[{"atb":[[10,59.3]],"trd":[[10,180.71]],"batb":[[0,10,59.3]],"ltp":10,"tv":5930.32,"id":27115873},{"atl":[[11.5,61.23]],"batl":[[1,11.5,61.23]],"id":44049799}],"tv":67793.33}]}
{"op":"mcm","id":2,"clk":"AJALAK4HAPUI","pt":1743511689828,"mc":[{"id":"1.241629436","rc":[{"atb":[[10,76.84]],"atl":[[10.5,85.17]],"batb":[[0,10,76.84]],"batl":[[0,10.5,85.17]],"id":27115873},{"atb":[[17,30.83]],"batb":[[1,17,30.83]],"id":58186642}]}]}
{"op":"mcm","id":2,"clk":"AKULAL0HAJIJ","pt":1743511690143,"mc":[{"id":"1.241629436","rc":[{"atl":[[1000,23.16]],"id":270592}]}]}
{"op":"mcm","id":2,"clk":"AKsLAMAHAJQJ","pt":1743511690237,"mc":[{"id":"1.241629436","rc":[{"atl":[[9.2,54.26]],"batl":[[1,9.2,54.26]],"id":35856222}]}]}
{"op":"mcm","id":2,"clk":"ALcLAMYHAKEJ","pt":1743511690341,"mc":[{"id":"1.241629436","rc":[{"atl":[[1000,21.16]],"id":270592}]}]}
{"op":"mcm","id":2,"clk":"AMgLANMHALgJ","pt":1743511690542,"mc":[{"id":"1.241629436","rc":[{"atb":[[17,31.92]],"atl":[[18,19.89]],"batb":[[1,17,31.92]],"batl":[[0,18,19.89]],"id":58186642}]}]}
{"op":"mcm","id":2,"clk":"ANALANgHAL4J","pt":1743511690644,"mc":[{"id":"1.241629436","rc":[{"atb":[[17,28.64]],"batb":[[1,17,28.64]],"id":58186642}]}]}
{"op":"mcm","id":2,"clk":"AOQLAOQHAM8J","pt":1743511690849,"mc":[{"id":"1.241629436","rc":[{"atb":[[5.2,165.2]],"batb":[[0,5.2,165.2]],"id":270592},{"atb":[[6.4,127.58]],"batb":[[0,6.4,127.58]],"id":26496185}]}]}
{"op":"mcm","id":2,"clk":"APoLAO0HAOMJ","pt":1743511691011,"mc":[{"id":"1.241629436","rc":[{"atb":[[11.5,83.03]],"batb":[[0,11.5,83.03]],"id":40389088}]}]}
{"op":"mcm","id":2,"clk":"AIUMAPIHAOgJ","pt":1743511691111,"mc":[{"id":"1.241629436","rc":[{"atb":[[65,34.11]],"batb":[[0,65,34.11]],"id":59626646}]}]}
{"op":"mcm","id":2,"clk":"AIsMAPYHAPAJ","pt":1743511691215,"mc":[{"id":"1.241629436","rc":[{"atb":[[11.5,87.9]],"batb":[[0,11.5,87.9]],"id":40389088},{"atl":[[11,87.95]],"batl":[[0,11,87.95]],"id":44049799}]}]}
{"op":"mcm","id":2,"clk":"AL0MAJcIAKMK","pt":1743511691930,"mc":[{"id":"1.241629436","rc":[{"atb":[[5.9,39.62]],"batb":[],"id":26496185}]}]}
{"op":"mcm","id":2,"clk":"ANAMAJ8IALIK","pt":1743511692132,"mc":[{"id":"1.241629436","rc":[{"atb":[[8.6,70.46]],"atl":[[10.5,53.94],[9.2,56.67]],"batb":[[1,8.6,70.46]],"batl":[[1,9.2,56.67]],"id":35856222}]}]}
{"op":"mcm","id":2,"clk":"AOQMAKsIAMIK","pt":1743511692348,"mc":[{"id":"1.241629436","rc":[{"atb":[[5.2,170.43],[5,274.74]],"batb":[[2,5,274.74],[0,5.2,170.43]],"id":270592},{"atb":[[8.6,69.37]],"batb":[[1,8.6,69.37]],"id":35856222},{"atb":[[6.4,131.22]],"batb":[[0,6.4,131.22]],"id":26496185}]}]}
{"op":"mcm","id":2,"clk":"AOoMAK8IAMUK","pt":1743511692440,"mc":[{"id":"1.241629436","rc":[{"atb":[[17.5,4.84]],"batb":[[0,17.5,4.84]],"id":58186642}]}]}
{"op":"mcm","id":2,"clk":"APMMALQIAMkK","pt":1743511692546,"mc":[{"id":"1.241629436","rc":[{"atb":[[11.5,83.03]],"batb":[[0,11.5,83.03]],"id":40389088},{"atb":[[8.8,40.44]],"batb":[[0,8.8,40.44]],"id":35856222},{"atb":[[17,31.92]],"batb":[[1,17,31.92]],"id":58186642}]}]}
{"op":"mcm","id":2,"clk":"APoMALcIAM4K","pt":1743511692643,"mc":[{"id":"1.241629436","rc":[{"atb":[[17.5,2.44]],"trd":[[17.5,82.71]],"batb":[[0,17.5,2.44]],"tv":4574.15,"id":58186642}],"tv":67798.13}]}
{"op":"mcm","id":2,"clk":"AIINALsIANQK","pt":1743511692753,"mc":[{"id":"1.241629436","rc":[{"atb":[[11.5,87.9]],"batb":[[0,11.5,87.9]],"id":40389088},{"atb":[[17,28.64]],"batb":[[1,17,28.64]],"id":58186642}]}]}
{"op":"mcm","id":2,"clk":"AKgNAM0IAO0K","pt":1743511693156,"mc":[{"id":"1.241629436","rc":[{"atb":[[1.17,2.33],[11,84]],"atl":[[12,20.49]],"batb":[[1,11,84]],"batl":[[0,12,20.49]],"id":40389088},{"atb":[[5.2,169.43]],"trd":[[5.2,1257.6]],"batb":[[0,5.2,169.43]],"tv":15001.64,"id":270592},{"atb":[[1.17,7.76],[8.6,69.11]],"batb":[[1,8.6,69.11]],"id":35856222},{"atl":[[70,20.1]],"batl":[[0,70,20.1]],"id":59626646},{"atl":[[1000,4.84],[5.2,70.55]],"batl":[[0,5.2,70.55]],"id":56297029},{"atb":[[10,75.66]],"batb":[[0,10,75.66]],"id":27115873},{"atl":[[18,21.16]],"batl":[[0,18,21.16]],"id":58186642},{"atb":[[6.4,129.34]],"batb":[[0,6.4,129.34]],"id":26496185}],"tv":67800.13}]}
{"op":"mcm","id":2,"clk":"AK0NANQIAPMK","pt":1743511693217,"mc":[{"id":"1.241629436","rc":[{"atb":[[1.17,2]],"id":40389088},{"atb":[[1.17,7.15]],"id":35856222},{"atl":[[1000,4.52]],"id":56297029}]}]}
{"op":"mcm","id":2,"clk":"ALMNANkIAPcK","pt":1743511693316,"mc":[{"id":"1.241629436","rc":[{"atb":[[11.5,88.23]],"batb":[[0,11.5,88.23]],"id":40389088},{"atb":[[8.8,41.05]],"atl":[[9.2,50.22]],"batb":[[0,8.8,41.05]],"batl":[[1,9.2,50.22]],"id":35856222},{"atl":[[5.3,122.29]],"batl":[[1,5.3,122.29]],"id":56297029}]}]}
{"op":"mcm","id":2,"clk":"AMoNAOIIAIAL","pt":1743511693519,"mc":[{"id":"1.241629436","rc":[{"atb":[[8.4,32.39]],"batb":[],"id":27115873}]}]}
{"op":"mcm","id":2,"clk":"ANoNAOUIAIUL","pt":1743511693623,"mc":[{"id":"1.241629436","rc":[{"atb":[[11.5,86.14]],"batb":[[0,11.5,86.14]],"id":40389088},{"atb":[[5.1,197.15]],"batb":[[0,5.1,197.15]],"id":56297029}]}]}
{"op":"mcm","id":2,"clk":"APINAPEIAJEL","pt":1743511693830,"mc":[{"id":"1.241629436","rc":[{"atl":[[1000,23.16]],"id":270592}]}]}
{"op":"mcm","id":2,"clk":"AP0NAPUIAJkL","pt":1743511693933,"mc":[{"id":"1.241629436","rc":[{"atb":[[5.1,193.15]],"trd":[[5.1,2754.65]],"batb":[[0,5.1,193.15]],"tv":11614.35,"id":56297029},{"atb":[[10,73.66]],"trd":[[10,184.71]],"batb":[[0,10,73.66]],"tv":5934.32,"id":27115873}],"tv":67812.13}]}
{"op":"mcm","id":2,"clk":"AIcOAP0IAKkL","pt":1743511694036,"mc":[{"id":"1.241629436","rc":[{"atb":[[5.2,170.96]],"batb":[[0,5.2,170.96]],"id":270592}]}]}
{"op":"mcm","id":2,"clk":"AJgOAIQJALYL","pt":1743511694240,"mc":[{"id":"1.241629436","rc":[{"atl":[[5.3,252.5]],"trd":[[5.3,137.56]],"batl":[[0,5.3,252.5]],"ltp":5.3,"tv":15005.64,"id":270592},{"atl":[[10.5,51.54]],"batl":[],"id":35856222},{"atb":[[65,32.11]],"trd":[[65,81.92]],"batb":[[0,65,32.11]],"ltp":65,"tv":1531.24,"id":59626646},{"atl":[[5.2,90.55]],"batl":[[0,5.2,90.55]],"id":56297029}],"tv":67820.13}]}
{"op":"mcm","id":2,"clk":"AKIOAIwJAL0L","pt":1743511694341,"mc":[{"id":"1.241629436","rc":[{"atl":[[1000,21.16]],"id":270592},{"atb":[[65,34.58]],"batb":[[0,65,34.58]],"id":59626646}]}]}
{"op":"mcm","id":2,"clk":"AK0OAJMJAMYL","pt":1743511694446,"mc":[{"id":"1.241629436","rc":[{"atl":[[9.2,59.06]],"batl":[[1,9.2,59.06]],"id":35856222}]}]}
{"op":"mcm","id":2,"clk":"AMYOAKMJANoL","pt":1743511694750,"mc":[{"id":"1.241629436","rc":[{"atb":[[6.4,127.34]],"trd":[[6.4,2789.43]],"batb":[[0,6.4,127.34]],"ltp":6.4,"tv":11312.91,"id":26496185}],"tv":67824.13}]}
{"op":"mcm","id":2,"clk":"AMwOAKcJAOEL","pt":1743511694849,"mc":[{"id":"1.241629436","rc":[{"atb":[[6.4,124.27]],"batb":[[0,6.4,124.27]],"id":26496185}]}]}
{"op":"mcm","id":2,"clk":"ANUOAK4JAOcL","pt":1743511694949,"mc":[{"id":"1.241629436","rc":[{"atb":[[6.4,127.34]],"batb":[[0,6.4,127.34]],"id":26496185}]}]}
{"op":"mcm","id":2,"clk":"AOUOALQJAPML","pt":1743511695153,"mc":[{"id":"1.241629436","rc":[{"atl":[[6.2,99.67]],"batl":[],"id":270592},{"atb":[[8,57.51]],"batb":[],"id":35856222}]}]}
{"op":"mcm","id":2,"clk":"AO8OALoJAPkL","pt":1743511695253,"mc":[{"id":"1.241629436","rc":[{"atl":[[6,248.73]],"batl":[],"id":270592},{"atb":[[8,59.35]],"batb":[],"id":35856222}]}]}
{"op":"mcm","id":2,"clk":"AP8OAMgJAIsM","pt":1743511695464,"mc":[{"id":"1.241629436","rc":[{"atl":[[9,7.86]],"batl":[[0,9,7.86]],"id":35856222},{"atb":[[60,18.94]],"batb":[[1,60,18.94]],"id":59626646}]}]}
{"op":"mcm","id":2,"clk":"AKsPAOUJALMM","pt":1743511696124,"mc":[{"id":"1.241629436","rc":[{"atb":[[5.1,194.72]],"batb":[[0,5.1,194.72]],"id":56297029},{"atb":[[10.5,63.95]],"batb":[[0,10.5,63.95]],"id":44049799}]}]}
{"op":"mcm","id":2,"clk":"ALUPAOwJAL4M","pt":1743511696286,"mc":[{"id":"1.241629436","rc":[{"atl":[[9.2,61.46],[10,88.25]],"batl":[[1,9.2,61.46]],"id":35856222}]}]}
{"op":"mcm","id":2,"clk":"AMwPAPoJANEM","pt":1743511696547,"mc":[{"id":"1.241629436","rc":[{"atb":[[8.6,20.6],[5.6,0.21]],"id":40389088},{"atb":[[4.3,42.32]],"batb":[],"id":270592},{"atb":[[7.8,21.53],[4.9,50.77],[7.2,12.74]],"batb":[],"id":35856222},{"atb":[[18.5,5.62],[16.5,3.71]],"id":59626646},{"atb":[[4.7,32.44],[4.4,38.6],[4,184.01]],"batb":[],"id":56297029},{"atb":[[3.15,0],[3.4,0],[3.7,0]],"id":27115873},{"atb":[[11,37.84],[10,55.04],[4.5,0]],"id":58186642},{"atb":[[4.4,112.18],[4.1,12.25],[4.8,6.91]],"id":26496185},{"atb":[[8.8,30.24],[8,26]],"batb":[],"id":44049799}]}]}
{"op":"mcm","id":2,"clk":"AOMPAJQKAO0M","pt":1743511696952,"mc":[{"id":"1.241629436","rc":[{"atl":[[5.3,243.5]],"trd":[[5.3,155.56]],"batl":[[0,5.3,243.5]],"tv":15023.64,"id":270592}],"tv":67842.13}]}
{"op":"mcm","id":2,"clk":"AIMQAKQKAIEN","pt":1743511697261,"mc":[{"id":"1.241629436","rc":[{"atl":[[18,58.22]],"batl":[[0,18,58.22]],"id":58186642}]}]}
{"op":"mcm","id":2,"clk":"AIwQAKoKAIgN","pt":1743511697314,"mc":[{"id":"1.241629436","rc":[{"atb":[[17.5,0]],"atl":[[17.5,5.85]],"trd":[[17.5,87.59]],"batb":[[2,16,14.2],[1,16.5,31.97],[0,17,28.64]],"batl":[[2,18.5,12.46],[1,18,58.22],[0,17.5,5.85]],"tv":4579.03,"id":58186642}],"tv":67847.01}]}
{"op":"mcm","id":2,"clk":"AJUQAK0KAIwN","pt":1743511697424,"mc":[{"id":"1.241629436","rc":[{"atb":[[5,1164.43]],"batb":[[1,5,1164.43]],"id":56297029},{"atb":[[17,21.43]],"atl":[[20,7]],"batb":[[0,17,21.43]],"batl":[],"id":58186642}]}]}
{"op":"mcm","id":2,"clk":"AJ0QALMKAJQN","pt":1743511697539,"mc":[{"id":"1.241629436","rc":[{"atb":[[4.9,77.32]],"batb":[[2,4.9,77.32]],"id":56297029},{"atl":[[17.5,7.81]],"batl":[[0,17.5,7.81]],"id":58186642}]}]}
{"op":"mcm","id":2,"clk":"AK8QAMEKAKEN","pt":1743511697731,"mc":[{"id":"1.241629436","rc":[{"atb":[[10,71.66]],"trd":[[10,188.71]],"batb":[[0,10,71.66]],"tv":5938.32,"id":27115873},{"atb":[[17,14.43]],"batb":[[0,17,14.43]],"id":58186642},{"atb":[[6.4,124.35]],"trd":[[6.4,2795.43]],"batb":[[0,6.4,124.35]],"tv":11318.91,"id":26496185}],"tv":67857.01}]}
{"op":"mcm","id":2,"clk":"ALIQAMgKAKQN","pt":1743511697826,"mc":[{"id":"1.241629436","rc":[{"atb":[[4.9,76.31]],"batb":[[2,4.9,76.31]],"id":56297029}]}]}
{"op":"mcm","id":2,"clk":"ALgQAM4KALAN","pt":1743511697931,"mc":[{"id":"1.241629436","rc":[{"atb":[[5,1165.42]],"batb":[[1,5,1165.42]],"id":56297029}]}]}
{"op":"mcm","id":2,"clk":"AMYQANkKALsN","pt":1743511698146,"mc":[{"id":"1.241629436","rc":[{"atl":[[5.3,218.5]],"trd":[[5.3,205.56]],"batl":[[0,5.3,218.5]],"tv":15073.64,"id":270592}],"tv":67907.01}]}
{"op":"mcm","id":2,"clk":"ANMQAOIKAMgN","pt":1743511698342,"mc":[{"id":"1.241629436","rc":[{"atb":[[17,15.43]],"batb":[[0,17,15.43]],"id":58186642}]}]}
{"op":"mcm","id":2,"clk":"ANoQAOYKAM4N","pt":1743511698449,"mc":[{"id":"1.241629436","rc":[{"atb":[[5.6,3.21]],"id":40389088},{"atb":[[6.4,128.35]],"batb":[[0,6.4,128.35]],"id":26496185}]}]}
{"op":"mcm","id":2,"clk":"AOgQAPEKANkN","pt":1743511698644,"mc":[{"id":"1.241629436","rc":[{"atb":[[6.4,135.35]],"batb":[[0,6.4,135.35]],"id":26496185}]}]}
{"op":"mcm","id":2,"clk":"APgQAPgKAOsN","pt":1743511698856,"mc":[{"id":"1.241629436","rc":[{"atl":[[1000,0.43]],"id":40389088},{"atb":[[8.8,42.17]],"batb":[[0,8.8,42.17]],"id":35856222},{"atl":[[70,19.03]],"batl":[[0,70,19.03]],"id":59626646},{"atb":[[5.1,196.49]],"batb":[[0,5.1,196.49]],"id":56297029},{"atb":[[17,14.95],[16.5,32.83]],"atl":[[18,51.79],[17.5,10.54]],"batb":[[1,16.5,32.83],[0,17,14.95]],"batl":[[1,18,51.79],[0,17.5,10.54]],"id":58186642},{"atb":[[10.5,60.21]],"atl":[[11.5,60.28],[11,87.23]],"batb":[[0,10.5,60.21]],"batl":[[1,11.5,60.28],[0,11,87.23]],"id":44049799}]}]}
{"op":"mcm","id":2,"clk":"AIwRAIELAP4N","pt":1743511699062,"mc":[{"id":"1.241629436","rc":[{"atl":[[1000,0.25]],"id":40389088},{"atl":[[18.5,16.93]],"batl":[[2,18.5,16.93]],"id":58186642}]}]}
{"op":"mcm","id":2,"clk":"AJYRAIgLAIgO","pt":1743511699165,"mc":[{"id":"1.241629436","rc":[{"atl":[[12,20.67]],"batl":[[0,12,20.67]],"id":40389088}]}]}
{"op":"mcm","id":2,"clk":"AJ0RAIwLAJIO","pt":1743511699267,"mc":[{"id":"1.241629436","rc":[{"atl":[[1000,23.16]],"id":270592}]}]}
{"op":"mcm","id":2,"clk":"AK0RAJMLAJ4O","pt":1743511699416,"mc":[{"id":"1.241629436","rc":[{"atl":[[1000,21.16]],"id":270592},{"atl":[[18.5,12.46]],"batl":[[2,18.5,12.46]],"id":58186642}]}]}
{"op":"mcm","id":2,"clk":"ALURAJULAKcO","pt":1743511699521,"mc":[{"id":"1.241629436","rc":[{"atl":[[1000,23.16]],"id":270592}]}]}
{"op":"mcm","id":2,"clk":"AL8RAJoLALQO","pt":1743511699720,"mc":[{"id":"1.241629436","rc":[{"atl":[[1000,21.16]],"id":270592}]}]}
{"op":"mcm","id":2,"clk":"AOgRAK4LANkO","pt":1743511700245,"mc":[{"id":"1.241629436","rc":[{"atb":[[5,322.74]],"batb":[[2,5,322.74]],"id":270592}]}]}
{"op":"mcm","id":2,"clk":"AO8RALALAN4O","pt":1743511700345,"mc":[{"id":"1.241629436","rc":[{"atb":[[7.8,19.59],[8,57.51]],"batb":[],"id":35856222}]}]}
{"op":"mcm","id":2,"clk":"APgRALMLAOQO","pt":1743511700437,"mc":[{"id":"1.241629436","rc":[{"atl":[[70,9.43]],"trd":[[70,22.09]],"batl":[[0,70,9.43]],"ltp":70,"tv":1550.43,"id":59626646}],"tv":67926.2}]}
{"op":"mcm","id":2,"clk":"AIASALQLAOoO","pt":1743511700547,"mc":[{"id":"1.241629436","rc":[{"atb":[[7.8,21.53]],"atl":[[9.2,55.02]],"batb":[],"batl":[[1,9.2,55.02]],"id":35856222},{"atb":[[65,36.1]],"batb":[[0,65,36.1]],"id":59626646},{"atb":[[17,12.65]],"batb":[[0,17,12.65]],"id":58186642}]}]}
{"op":"mcm","id":2,"clk":"AIgSALgLAPYO","pt":1743511700648,"mc":[{"id":"1.241629436","rc":[{"atb":[[60,17.42]],"batb":[[1,60,17.42]],"id":59626646},{"atb":[[5.1,195.49]],"trd":[[5.1,2756.65]],"batb":[[0,5.1,195.49]],"tv":11616.35,"id":56297029},{"atl":[[21,10.95],[17.5,10.83]],"batl":[[0,17.5,10.83]],"id":58186642}],"tv":67928.2}]}
{"op":"mcm","id":2,"clk":"AJASALwLAIIP","pt":1743511700755,"mc":[{"id":"1.241629436","rc":[{"atl":[[17.5,17.83]],"batl":[[0,17.5,17.83]],"id":58186642}]}]}
{"op":"mcm","id":2,"clk":"AJkSAL8LAIoP","pt":1743511700855,"mc":[{"id":"1.241629436","rc":[{"atl":[[5.2,81.55]],"trd":[[5.2,3442.11]],"batl":[[0,5.2,81.55]],"ltp":5.2,"tv":11634.35,"id":56297029},{"atb":[[17,12.36]],"batb":[[0,17,12.36]],"id":58186642},{"atb":[[6.4,139.35]],"batb":[[0,6.4,139.35]],"id":26496185}],"tv":67946.2}]}
{"op":"mcm","id":2,"clk":"AKcSAMoLAJQP","pt":1743511701058,"mc":[{"id":"1.241629436","rc":[{"atb":[[5.1,197.02]],"batb":[[0,5.1,197.02]],"id":56297029}]}]}
{"op":"mcm","id":2,"clk":"AKsSAMwLAJsP","pt":1743511701160,"mc":[{"id":"1.241629436","rc":[{"atb":[[5,314.99]],"batb":[[2,5,314.99]],"id":270592}]}]}
{"op":"mcm","id":2,"clk":"AMESAN0LALkP","pt":1743511701473,"mc":[{"id":"1.241629436","rc":[{"atb":[[2,134.01]],"id":35856222},{"atb":[[6.4,139.02]],"trd":[[6.4,2796.08]],"batb":[[0,6.4,139.02]],"tv":11319.56,"id":26496185}],"tv":67946.85}]}
{"op":"mcm","id":2,"clk":"AMcSAOILALwP","pt":1743511701571,"mc":[{"id":"1.241629436","rc":[{"atb":[[5,1166.42]],"batb":[[1,5,1166.42]],"id":56297029},{"atl":[[11.5,58.45]],"batl":[[1,11.5,58.45]],"id":44049799}]}]}
{"op":"mcm","id":2,"clk":"ANESAOcLAMUP","pt":1743511701631,"mc":[{"id":"1.241629436","rc":[{"atl":[[17.5,16.4]],"trd":[[17.5,90.45]],"batl":[[0,17.5,16.4]],"tv":4581.89,"id":58186642}],"tv":67949.71}]}
{"op":"mcm","id":2,"clk":"ANkSAO8LAMsP","pt":1743511701730,"mc":[{"id":"1.241629436","rc":[{"atl":[[11,89.14]],"batl":[[0,11,89.14]],"id":44049799}]}]}
{"op":"mcm","id":2,"clk":"AOISAPILANIP","pt":1743511701835,"mc":[{"id":"1.241629436","rc":[{"atl":[[1000,0.49]],"id":40389088},{"atb":[[5.2,176.41]],"atl":[[5.4,84.16]],"batb":[[0,5.2,176.41]],"batl":[[1,5.4,84.16]],"id":270592}]}]}
{"op":"mcm","id":2,"clk":"APwSAIAMAOgP","pt":1743511702046,"mc":[{"id":"1.241629436","rc":[{"atl":[[1000,0.25]],"id":40389088}]}]}
{"op":"mcm","id":2,"clk":"AJoTAIoMAPcP","pt":1743511702143,"mc":[{"id":"1.241629436","rc":[{"atl":[[1000,0.44],[12.5,28.74]],"batl":[[1,12.5,28.74]],"id":40389088},{"atb":[[5.1,198.44]],"batb":[[0,5.1,198.44]],"id":56297029}]}]}
{"op":"mcm","id":2,"clk":"AKoTAJAMAIQQ","pt":1743511702342,"mc":[{"id":"1.241629436","rc":[{"atl":[[1000,0.25]],"id":40389088}]}]}
{"op":"mcm","id":2,"clk":"ALATAJQMAIsQ","pt":1743511702448,"mc":[{"id":"1.241629436","rc":[{"atl":[[12.5,28.93]],"batl":[[1,12.5,28.93]],"id":40389088}]}]}
{"op":"mcm","id":2,"clk":"AL4TAJkMAJwQ","pt":1743511702648,"mc":[{"id":"1.241629436","rc":[{"atb":[[11.5,84.88]],"batb":[[0,11.5,84.88]],"id":40389088}]}]}
{"op":"mcm","id":2,"clk":"AKsUAOwMAPcQ","pt":1743511703469,"mc":[{"id":"1.241629436","rc":[{"atb":[[11.5,83.88]],"trd":[[11.5,701.05]],"batb":[[0,11.5,83.88]],"tv":5592.16,"id":40389088}],"tv":67951.71}]}
{"op":"mcm","id":2,"clk":"AOAUAP4MAKwR","pt":1743511703938,"mc":[{"id":"1.241629436","rc":[{"atl":[[17.5,14.4]],"trd":[[17.5,94.45]],"batl":[[0,17.5,14.4]],"tv":4585.89,"id":58186642}],"tv":67955.71}]}
{"op":"mcm","id":2,"clk":"APAUAIENALIR","pt":1743511704035,"mc":[{"id":"1.241629436","rc":[{"atl":[[6.6,51.23]],"trd":[[6.6,1607.99]],"batl":[[0,6.6,51.23]],"ltp":6.6,"tv":11325.56,"id":26496185}],"tv":67961.71}]}
{"op":"mcm","id":2,"clk":"AJ8VALMNANQR","pt":1743511704148,"mc":[{"id":"1.241629436","rc":[{"atl":[[5.4,89.16]],"batl":[[1,5.4,89.16]],"id":270592}]}]}
{"op":"mcm","id":2,"clk":"ANkVAMgNAI4S","pt":1743511704649,"mc":[{"id":"1.241629436","rc":[{"atl":[[1000,23.16]],"id":270592}]}]}
{"op":"mcm","id":2,"clk":"AOAVAM0NAJkS","pt":1743511704752,"mc":[{"id":"1.241629436","rc":[{"atl":[[70,11.75]],"batl":[[0,70,11.75]],"id":59626646}]}]}
{"op":"mcm","id":2,"clk":"AOkVANANAKAS","pt":1743511704861,"mc":[{"id":"1.241629436","rc":[{"atl":[[1000,21.16]],"id":270592},{"atl":[[6.6,41.23]],"trd":[[6.6,1627.99]],"batl":[[0,6.6,41.23]],"tv":11345.56,"id":26496185}],"tv":67981.71}]}
{"op":"mcm","id":2,"clk":"AO8VANINAKMS","pt":1743511704955,"mc":[{"id":"1.241629436","rc":[{"atl":[[1000,23.16]],"id":270592},{"atl":[[70,10.45]],"batl":[[0,70,10.45]],"id":59626646},{"atl":[[17.5,15.76]],"batl":[[0,17.5,15.76]],"id":58186642},{"atb":[[6.4,172.66]],"batb":[[0,6.4,172.66]],"id":26496185}]}]}
{"op":"mcm","id":2,"clk":"AKoWAIIOAOoS","pt":1743511705167,"mc":[{"id":"1.241629436","rc":[{"atl":[[1000,21.16]],"id":270592},{"atb":[[10,65.96]],"trd":[[10,200.11]],"batb":[[0,10,65.96]],"tv":5949.72,"id":27115873},{"atl":[[17.5,8.76]],"batl":[[0,17.5,8.76]],"id":58186642}],"tv":67993.11}]}
{"op":"mcm","id":2,"clk":"ALEWAJIOAIET","pt":1743511705264,"mc":[{"id":"1.241629436","rc":[{"atb":[[17,5.37]],"trd":[[17,372.91]],"batb":[[0,17,5.37]],"ltp":17,"tv":4599.88,"id":58186642}],"tv":68007.1}]}
{"op":"mcm","id":2,"clk":"AMYWAJsOAI8T","pt":1743511705464,"mc":[{"id":"1.241629436","rc":[{"atb":[[9,1.14]],"atl":[[9,0]],"trd":[[9,297.18]],"batb":[[2,8.6,69.11],[1,8.8,42.17],[0,9,1.14]],"batl":[[2,9.6,49.14],[1,9.4,19.4],[0,9.2,55.02]],"ltp":9,"tv":8352.7,"id":35856222},{"atb":[[17,5.07]],"batb":[[0,17,5.07]],"id":58186642}],"tv":68022.82}]}
{"op":"mcm","id":2,"clk":"ANIWAKQOAJMT","pt":1743511705575,"mc":[{"id":"1.241629436","rc":[{"atl":[[1000,23.16]],"id":270592},{"atb":[[9,0]],"trd":[[9,299.46]],"batb":[[2,8.4,60.71],[1,8.6,69.11],[0,8.8,42.17]],"tv":8354.98,"id":35856222},{"atb":[[13.5,26.32]],"batb":[],"id":58186642},{"atb":[[10.5,60.11]],"trd":[[10.5,411.01]],"batb":[[0,10.5,60.11]],"tv":3924.58,"id":44049799}],"tv":68025.3}]}
{"op":"mcm","id":2,"clk":"AN0WAKcOAJkT","pt":1743511705623,"mc":[{"id":"1.241629436","rc":[{"atb":[[3.5,14.2]],"id":270592},{"atb":[[7.8,19.59]],"atl":[[9.8,21.96],[9.2,49.47],[9,6.04]],"batb":[],"batl":[[2,9.4,19.4],[1,9.2,49.47],[0,9,6.04]],"id":35856222}]}]}
{"op":"mcm","id":2,"clk":"AOQWAKsOAKAT","pt":1743511705721,"mc":[{"id":"1.241629436","rc":[{"atl":[[1000,21.16]],"id":270592},{"atb":[[7.8,21.53],[7.6,34.98]],"batb":[],"id":35856222},{"atl":[[17.5,7.06]],"trd":[[17.5,97.85]],"batl":[[0,17.5,7.06]],"ltp":17.5,"tv":4603.28,"id":58186642}],"tv":68028.7}]}
{"op":"mcm","id":2,"clk":"AO4WAK8OAKgT","pt":1743511705826,"mc":[{"id":"1.241629436","rc":[{"atl":[[9.2,43.02]],"batl":[[1,9.2,43.02]],"id":35856222}]}]}
{"op":"mcm","id":2,"clk":"APgWALEOALMT","pt":1743511705929,"mc":[{"id":"1.241629436","rc":[{"atl":[[6.8,90]],"batl":[[1,6.8,90]],"id":26496185}]}]}
{"op":"mcm","id":2,"clk":"ALUXANYOAOkT","pt":1743511706145,"mc":[{"id":"1.241629436","rc":[{"atl":[[9,0]],"batl":[[2,9.6,49.14],[1,9.4,19.4],[0,9.2,43.02]],"id":35856222}]}]}
{"op":"mcm","id":2,"clk":"AN8XAIcPAJIU","pt":1743511706343,"mc":[{"id":"1.241629436","rc":[{"atb":[[7.8,19.59]],"batb":[],"id":35856222},{"atb":[[6.4,171.66]],"trd":[[6.4,2798.08]],"batb":[[0,6.4,171.66]],"ltp":6.4,"tv":11347.56,"id":26496185}],"tv":68030.7}]}
{"op":"mcm","id":2,"clk":"APsXAJsPALEU","pt":1743511706750,"mc":[{"id":"1.241629436","rc":[{"atl":[[7,33.2]],"batl":[[2,7,33.2]],"id":26496185}]}]}
{"op":"mcm","id":2,"clk":"ANMYANQPAJUV","pt":1743511707260,"mc":[{"id":"1.241629436","rc":[{"atl":[[9.2,45.48]],"batl":[[0,9.2,45.48]],"id":35856222}]}]}
{"op":"mcm","id":2,"clk":"AOYYAOAPAKUV","pt":1743511707469,"mc":[{"id":"1.241629436","rc":[{"atl":[[9.2,43.02]],"batl":[[0,9.2,43.02]],"id":35856222}]}]}
{"op":"mcm","id":2,"clk":"APIYAOkPALIV","pt":1743511707674,"mc":[{"id":"1.241629436","rc":[{"atb":[[11.5,81.88]],"trd":[[11.5,705.05]],"batb":[[0,11.5,81.88]],"tv":5596.16,"id":40389088},{"atb":[[5.1,196.63]],"batb":[[0,5.1,196.63]],"id":56297029}],"tv":68034.7}]}
{"op":"mcm","id":2,"clk":"APkYAO0PALQV","pt":1743511707721,"mc":[{"id":"1.241629436","rc":[{"atb":[[11.5,83.14]],"batb":[[0,11.5,83.14]],"id":40389088}]}]}
{"op":"mcm","id":2,"clk":"AIMZAPMPAL4V","pt":1743511707829,"mc":[{"id":"1.241629436","rc":[{"atb":[[11.5,78.27]],"batb":[[0,11.5,78.27]],"id":40389088}]}]}
{"op":"mcm","id":2,"clk":"ALkZAKQQAPAV","pt":1743511708136,"mc":[{"id":"1.241629436","rc":[{"atb":[[10,64.96]],"trd":[[10,202.11]],"batb":[[0,10,64.96]],"tv":5951.72,"id":27115873}],"tv":68036.7}]}
{"op":"mcm","id":2,"clk":"AM8ZAMYQAI4W","pt":1743511708247,"mc":[{"id":"1.241629436","rc":[{"atb":[[5.1,191.63]],"trd":[[5.1,2766.65]],"batb":[[0,5.1,191.63]],"ltp":5.1,"tv":11644.35,"id":56297029}],"tv":68046.7}]}
{"op":"mcm","id":2,"clk":"ANgZAMkQAJYW","pt":1743511708349,"mc":[{"id":"1.241629436","rc":[{"atl":[[5.2,75.93]],"batl":[[0,5.2,75.93]],"id":56297029}]}]}
{"op":"mcm","id":2,"clk":"APQZANkQAKkW","pt":1743511708650,"mc":[{"id":"1.241629436","rc":[{"atb":[[11.5,0],[11,82.27]],"trd":[[11.5,861.59],[11,48.6]],"batb":[[2,10,45.9],[1,10.5,38.37],[0,11,82.27]],"ltp":11,"tv":5756.15,"id":40389088}],"tv":68206.69}]}
{"op":"mcm","id":2,"clk":"APYZAN0QAK8W","pt":1743511708747,"mc":[{"id":"1.241629436","rc":[{"atb":[[11.5,10.61],[11,112.04]],"atl":[[14.5,21.24],[12,47.31]],"trd":[[11.5,863.57]],"batb":[[2,10.5,38.37],[1,11,112.04],[0,11.5,10.61]],"batl":[[0,12,47.31]],"ltp":11.5,"tv":5758.13,"id":40389088},{"atb":[[5.2,208.24]],"batb":[[0,5.2,208.24]],"id":270592},{"atb":[[8.8,59.54]],"batb":[[0,8.8,59.54]],"id":35856222},{"atb":[[5,1165.43],[5.1,205.58]],"batb":[[1,5,1165.43],[0,5.1,205.58]],"id":56297029}],"tv":68208.67}]}
{"op":"mcm","id":2,"clk":"AP0ZAOQQALsW","pt":1743511708853,"mc":[{"id":"1.241629436","rc":[{"atb":[[11.5,0]],"atl":[[14.5,22.57]],"trd":[[11.5,910.81]],"batb":[[2,10,45.9],[1,10.5,38.37],[0,11,112.04]],"batl":[],"tv":5805.37,"id":40389088},{"atl":[[5.5,87.21]],"batl":[[2,5.5,87.21]],"id":270592}],"tv":68255.91}]}
{"op":"mcm","id":2,"clk":"AIIaAOkQAMAW","pt":1743511708953,"mc":[{"id":"1.241629436","rc":[{"atb":[[11.5,27.69],[11,99.15]],"batb":[[2,10.5,38.37],[1,11,99.15],[0,11.5,27.69]],"id":40389088},{"atb":[[5,1166.42]],"batb":[[1,5,1166.42]],"id":56297029}]}]}
{"op":"mcm","id":2,"clk":"AJgaAO8QANAW","pt":1743511709063,"mc":[{"id":"1.241629436","rc":[{"atb":[[11.5,39.3]],"atl":[[14.5,21.24],[14,13.68],[12.5,41.26]],"batb":[[0,11.5,39.3]],"batl":[[1,12.5,41.26]],"id":40389088}]}]}
{"op":"mcm","id":2,"clk":"AMQaAJARAP8W","pt":1743511709169,"mc":[{"id":"1.241629436","rc":[{"atb":[[11.5,40.3]],"atl":[[14.5,22.57]],"batb":[[0,11.5,40.3]],"batl":[],"id":40389088}]}]}
{"op":"mcm","id":2,"clk":"AOYaALARAK0X","pt":1743511709261,"mc":[{"id":"1.241629436","rc":[{"atb":[[11.5,24.21]],"batb":[[0,11.5,24.21]],"id":40389088}]}]}
{"op":"mcm","id":2,"clk":"AP8aAL8RAMYX","pt":1743511709571,"mc":[{"id":"1.241629436","rc":[{"atb":[[11.5,44.21]],"batb":[[0,11.5,44.21]],"id":40389088},{"atb":[[5.2,264.84]],"batb":[[0,5.2,264.84]],"id":270592},{"atb":[[8.8,92.87]],"atl":[[9.8,24.48]],"batb":[[0,8.8,92.87]],"batl":[],"id":35856222},{"atb":[[65,40.71]],"batb":[[0,65,40.71]],"id":59626646},{"atb":[[5.1,263.27]],"batb":[[0,5.1,263.27]],"id":56297029},{"atb":[[10,88.03]],"batb":[[0,10,88.03]],"id":27115873},{"atb":[[16.5,50.47]],"batb":[[1,16.5,50.47]],"id":58186642},{"atb":[[6.4,217.11]],"batb":[[0,6.4,217.11]],"id":26496185},{"atb":[[10.5,87.38]],"batb":[[0,10.5,87.38]],"id":44049799}]}]}
{"op":"mcm","id":2,"clk":"AIYbAMURAM0X","pt":1743511709670,"mc":[{"id":"1.241629436","rc":[{"atb":[[11.5,43.21]],"batb":[[0,11.5,43.21]],"id":40389088}]}]}
{"op":"mcm","id":2,"clk":"AKobANYRAO8X","pt":1743511710037,"mc":[{"id":"1.241629436","rc":[{"atl":[[1000,23.16]],"id":270592}]}]}
{"op":"mcm","id":2,"clk":"AMkbAO4RAJgY","pt":1743511710137,"mc":[{"id":"1.241629436","rc":[{"atl":[[5.6,42.9]],"batl":[],"id":270592}]}]}
{"op":"mcm","id":2,"clk":"APMbAKQSALEY","pt":1743511710239,"mc":[{"id":"1.241629436","rc":[{"atl":[[1000,21.16]],"id":270592}]}]}
{"op":"mcm","id":2,"clk":"AKYcAPISAP0Y","pt":1743511710444,"mc":[{"id":"1.241629436","rc":[{"atb":[[44,2.74]],"batb":[],"id":59626646}]}]}
{"op":"mcm","id":2,"clk":"AKscAPUSAIIZ","pt":1743511710545,"mc":[{"id":"1.241629436","rc":[{"atb":[[48,3.02]],"batb":[],"id":59626646}]}]}
{"op":"mcm","id":2,"clk":"AMYcAPkSAKIZ","pt":1743511710857,"mc":[{"id":"1.241629436","rc":[{"atb":[[11.5,59.17]],"batb":[[0,11.5,59.17]],"id":40389088}]}]}
{"op":"mcm","id":2,"clk":"AM0cAP4SAKkZ","pt":1743511710954,"mc":[{"id":"1.241629436","rc":[{"atl":[[1000,23.16]],"id":270592}]}]}
{"op":"mcm","id":2,"clk":"ANIcAIETAK8Z","pt":1743511711059,"mc":[{"id":"1.241629436","rc":[{"atl":[[9.8,26.99]],"batl":[],"id":35856222}]}]}
{"op":"mcm","id":2,"clk":"AIEdAKMTAN0Z","pt":1743511711175,"mc":[{"id":"1.241629436","rc":[{"atl":[[1000,21.16]],"id":270592}]}]}
{"op":"mcm","id":2,"clk":"AJYdAMMTAPgZ","pt":1743511711270,"mc":[{"id":"1.241629436","rc":[{"atl":[[70,4.65]],"trd":[[70,33.69]],"batl":[[0,70,4.65]],"tv":1562.03,"id":59626646}],"tv":68267.51}]}
{"op":"mcm","id":2,"clk":"AJsdAMUTAPsZ","pt":1743511711369,"mc":[{"id":"1.241629436","rc":[{"atl":[[70,2.33]],"batl":[[0,70,2.33]],"id":59626646}]}]}
{"op":"mcm","id":2,"clk":"AKIdAMgTAIEa","pt":1743511711468,"mc":[{"id":"1.241629436","rc":[{"atb":[[11.5,47.56]],"batb":[[0,11.5,47.56]],"id":40389088},{"atb":[[70,0.63]],"atl":[[70,0]],"trd":[[70,38.35]],"batb":[[0,65,41.34]],"batl":[[2,85,1],[1,80,3.96],[0,75,4.94]],"tv":1566.69,"id":59626646}],"tv":68272.17}]}
{"op":"mcm","id":2,"clk":"AKgdAM0TAIga","pt":1743511711571,"mc":[{"id":"1.241629436","rc":[{"atb":[[5.2,260.37]],"batb":[[0,5.2,260.37]],"id":270592},{"atl":[[1000,0.64],[9.2,42.6]],"batl":[[0,9.2,42.6]],"id":35856222},{"atb":[[5.1,260.62]],"batb":[[0,5.1,260.62]],"id":56297029},{"atb":[[17,4.46]],"atl":[[17.5,5.44]],"batb":[[0,17,4.46]],"batl":[[0,17.5,5.44]],"id":58186642},{"atb":[[6.4,216.02]],"batb":[[0,6.4,216.02]],"id":26496185},{"atl":[[11,90.26]],"batl":[[0,11,90.26]],"id":44049799}]}]}
{"op":"mcm","id":2,"clk":"AK4dANQTAI0a","pt":1743511711627,"mc":[{"id":"1.241629436","rc":[{"atb":[[50,16.59],[38,12.18],[70,3.12],[65,41]],"batb":[[2,60,17.42],[1,65,41],[0,70,3.12]],"id":59626646}]}]}
{"op":"mcm","id":2,"clk":"AL4dANkTAJga","pt":1743511711738,"mc":[{"id":"1.241629436","rc":[{"atl":[[1000,0.41]],"id":35856222},{"atb":[[50,13.59],[70,5.97]],"trd":[[70,39.01]],"batb":[[0,70,5.97]],"tv":1567.35,"id":59626646},{"atb":[[17,4.75]],"batb":[[0,17,4.75]],"id":58186642}],"tv":68272.83}]}
{"op":"mcm","id":2,"clk":"AMkdAN4TAJ0a","pt":1743511711834,"mc":[{"id":"1.241629436","rc":[{"atb":[[8.8,91.87]],"atl":[[9.4,19.63]],"trd":[[8.8,165.83]],"batb":[[0,8.8,91.87]],"batl":[[1,9.4,19.63]],"ltp":8.8,"tv":8356.98,"id":35856222},{"atb":[[65,39.69]],"atl":[[80,5.57],[75,2.66]],"batb":[[1,65,39.69]],"batl":[[1,80,5.57],[0,75,2.66]],"id":59626646},{"atb":[[5.5,122.94]],"batb":[],"id":26496185}],"tv":68274.83}]}
{"op":"mcm","id":2,"clk":"AN0dAOkTAK4a","pt":1743511712039,"mc":[{"id":"1.241629436","rc":[{"atb":[[1.01,41645.29],[16.5,2.94]],"id":59626646}]}]}
{"op":"mcm","id":2,"clk":"AJ0eAIoUAOEa","pt":1743511712244,"mc":[{"id":"1.241629436","rc":[{"atb":[[5.1,269.14]],"batb":[[0,5.1,269.14]],"id":56297029}]}]}
{"op":"mcm","id":2,"clk":"ALEeAJQUAO0a","pt":1743511712459,"mc":[{"id":"1.241629436","rc":[{"atb":[[1.01,41643.74]],"id":59626646}]}]}
{"op":"mcm","id":2,"clk":"ALgeAJsUAPIa","pt":1743511712555,"mc":[{"id":"1.241629436","rc":[{"atl":[[5.6,38.15]],"batl":[],"id":270592},{"atb":[[5.9,38.37]],"batb":[],"id":26496185}]}]}
{"op":"mcm","id":2,"clk":"ANEeAKMUAIgb","pt":1743511712855,"mc":[{"id":"1.241629436","rc":[{"atb":[[1.01,41642.97]],"id":59626646}]}]}
{"op":"mcm","id":2,"clk":"ANkeAKUUAI0b","pt":1743511712957,"mc":[{"id":"1.241629436","rc":[{"atb":[[70,4.97],[17,2.84]],"trd":[[70,41.01]],"batb":[[0,70,4.97]],"tv":1569.35,"id":59626646},{"atb":[[17,3.75]],"trd":[[17,374.91]],"batb":[[0,17,3.75]],"ltp":17,"tv":4605.28,"id":58186642}],"tv":68278.83}]}
{"op":"mcm","id":2,"clk":"AOYeAKcUAJcb","pt":1743511713068,"mc":[{"id":"1.241629436","rc":[{"atb":[[70,1.72],[65,33.66]],"trd":[[70,50.95],[65,84.44]],"batb":[[1,65,33.66],[0,70,1.72]],"ltp":65,"tv":1581.81,"id":59626646},{"atl":[[5.2,72.12]],"trd":[[5.2,3449.73]],"batl":[[0,5.2,72.12]],"ltp":5.2,"tv":11651.97,"id":56297029},{"atb":[[16,17.59]],"batb":[[2,16,17.59]],"id":58186642}],"tv":68298.91}]}
{"op":"mcm","id":2,"clk":"APgeAMIUAKYb","pt":1743511713165,"mc":[{"id":"1.241629436","rc":[{"atb":[[17,5.89]],"batb":[[0,17,5.89]],"id":58186642}]}]}
{"op":"mcm","id":2,"clk":"AIAfAMcUAKsb","pt":1743511713265,"mc":[{"id":"1.241629436","rc":[{"atb":[[70,4.33],[65,38.82]],"atl":[[75,2.73]],"batb":[[1,65,38.82],[0,70,4.33]],"batl":[[0,75,2.73]],"id":59626646}]}]}
{"op":"mcm","id":2,"clk":"AJEfAMsUAMEb","pt":1743511713426,"mc":[{"id":"1.241629436","rc":[{"atl":[[75,2.66]],"batl":[[0,75,2.66]],"id":59626646}]}]}
{"op":"mcm","id":2,"clk":"AJsfANAUAMgb","pt":1743511713535,"mc":[{"id":"1.241629436","rc":[{"atb":[[5.5,5.86]],"id":35856222}]}]}
{"op":"mcm","id":2,"clk":"AKIfANMUAM4b","pt":1743511713627,"mc":[{"id":"1.241629436","rc":[{"atb":[[10,86.03]],"trd":[[10,206.11]],"batb":[[0,10,86.03]],"tv":5955.72,"id":27115873},{"atb":[[10.5,86.38]],"trd":[[10.5,413.01]],"batb":[[0,10.5,86.38]],"tv":3926.58,"id":44049799}],"tv":68304.91}]}
{"op":"mcm","id":2,"clk":"AKsfANUUANcb","pt":1743511713737,"mc":[{"id":"1.241629436","rc":[{"atb":[[1.17,2.4]],"atl":[[12.5,41.07]],"batl":[[1,12.5,41.07]],"id":40389088},{"atb":[[65,35.66]],"batb":[[1,65,35.66]],"id":59626646},{"atb":[[5.1,268.11]],"batb":[[0,5.1,268.11]],"id":56297029},{"atb":[[10,101.33]],"batb":[[0,10,101.33]],"id":27115873}]}]}
{"op":"mcm","id":2,"clk":"ALQfANgUAN0b","pt":1743511713833,"mc":[{"id":"1.241629436","rc":[{"atb":[[1.17,2]],"id":40389088},{"atb":[[5.1,261.11]],"trd":[[5.1,2780.65]],"batb":[[0,5.1,261.11]],"ltp":5.1,"tv":11665.97,"id":56297029}],"tv":68318.91}]}
{"op":"mcm","id":2,"clk":"AL8fAN4UAOcb","pt":1743511713937,"mc":[{"id":"1.241629436","rc":[{"atb":[[11.5,47.96]],"batb":[[0,11.5,47.96]],"id":40389088}]}]}
{"op":"mcm","id":2,"clk":"AM4fAOYUAPYb","pt":1743511714145,"mc":[{"id":"1.241629436","rc":[{"atb":[[5.6,2.09]],"id":35856222}]}]}
{"op":"mcm","id":2,"clk":"ANYfAOgUAPwb","pt":1743511714251,"mc":[{"id":"1.241629436","rc":[{"atb":[[5.1,319.04]],"batb":[[1,5.1,319.04]],"id":270592},{"atb":[[8.6,69.1]],"batb":[[1,8.6,69.1]],"id":35856222},{"atb":[[6.4,212.95]],"batb":[[0,6.4,212.95]],"id":26496185}]}]}
{"op":"mcm","id":2,"clk":"ANkfAOwUAIMc","pt":1743511714347,"mc":[{"id":"1.241629436","rc":[{"atb":[[5.7,2.1],[8.8,91.88]],"batb":[[0,8.8,91.88]],"id":35856222},{"atb":[[6.4,216.02]],"batb":[[0,6.4,216.02]],"id":26496185}]}]}
{"op":"mcm","id":2,"clk":"AOQfAPMUAIwc","pt":1743511714452,"mc":[{"id":"1.241629436","rc":[{"atb":[[5.1,327.58]],"batb":[[1,5.1,327.58]],"id":270592}]}]}
{"op":"mcm","id":2,"clk":"AOsfAPYUAJgc","pt":1743511714557,"mc":[{"id":"1.241629436","rc":[{"atb":[[1.17,2.72]],"id":40389088},{"atb":[[10.5,93.85]],"atl":[[11.5,60]],"batb":[[0,10.5,93.85]],"batl":[[1,11.5,60]],"id":44049799}]}]}
{"op":"mcm","id":2,"clk":"APMfAPsUAJwc","pt":1743511714652,"mc":[{"id":"1.241629436","rc":[{"atb":[[1.17,2],[11.5,42.56]],"trd":[[11.5,921.61]],"batb":[[0,11.5,42.56]],"tv":5816.17,"id":40389088}],"tv":68329.71}]}
{"op":"mcm","id":2,"clk":"AIEgAP8UAKgc","pt":1743511714767,"mc":[{"id":"1.241629436","rc":[{"atb":[[11.5,43.28]],"batb":[[0,11.5,43.28]],"id":40389088}]}]}
{"op":"mcm","id":2,"clk":"AIogAIUVAK8c","pt":1743511714869,"mc":[{"id":"1.241629436","rc":[{"atb":[[5.8,1.1]],"id":35856222}]}]}
{"op":"mcm","id":2,"clk":"AJUgAI8VALwc","pt":1743511715069,"mc":[{"id":"1.241629436","rc":[{"atl":[[9,1]],"batl":[[2,9.4,19.63],[1,9.2,42.6],[0,9,1]],"id":35856222}]}]}
{"op":"mcm","id":2,"clk":"AKIgAJMVAMYc","pt":1743511715170,"mc":[{"id":"1.241629436","rc":[{"atb":[[9,5.98]],"atl":[[9,0]],"trd":[[9,301.46]],"batb":[[2,8.6,69.1],[1,8.8,91.88],[0,9,5.98]],"batl":[[2,9.6,49.14],[1,9.4,19.63],[0,9.2,42.6]],"ltp":9,"tv":8358.98,"id":35856222}],"tv":68331.71}]}
{"op":"mcm","id":2,"clk":"AK0gAJkVAMgc","pt":1743511715269,"mc":[{"id":"1.241629436","rc":[{"atl":[[12.5,19.36],[12,0]],"trd":[[12.5,499.47],[12,1370.28]],"batl":[[2,13.5,13.08],[1,13,12.05],[0,12.5,19.36]],"ltp":12.5,"tv":5954.23,"id":40389088},{"atb":[[1.17,7.65],[7.8,21.53],[5.8,1.2],[9,1]],"trd":[[9,313.42]],"batb":[[0,9,1]],"tv":8370.94,"id":35856222}],"tv":68481.73}]}
{"op":"mcm","id":2,"clk":"ALQgAJ8VANUc","pt":1743511715374,"mc":[{"id":"1.241629436","rc":[{"atb":[[11.5,51.16]],"atl":[[15,25.84],[12.5,24.61]],"batb":[[0,11.5,51.16]],"batl":[[0,12.5,24.61]],"id":40389088},{"atb":[[5.2,228.54]],"batb":[[0,5.2,228.54]],"id":270592},{"atb":[[1.17,7.15],[8.8,90.21]],"atl":[[9.2,49.09]],"batb":[[1,8.8,90.21]],"batl":[[0,9.2,49.09]],"id":35856222},{"atb":[[70,5.58]],"batb":[[0,70,5.58]],"id":59626646},{"atl":[[5.2,77.73]],"batl":[[0,5.2,77.73]],"id":56297029},{"atb":[[17,11.01]],"batb":[[0,17,11.01]],"id":58186642}]}]}
{"op":"mcm","id":2,"clk":"AL4gAKIVANkc","pt":1743511715475,"mc":[{"id":"1.241629436","rc":[{"atb":[[12,30.78],[11.5,64.21]],"atl":[[14,12.25],[12.5,59.36]],"batb":[[2,11,99.15],[1,11.5,64.21],[0,12,30.78]],"batl":[[0,12.5,59.36]],"id":40389088},{"atl":[[1000,23.16]],"id":270592},{"atb":[[8.4,76.08],[7.8,19.59],[9,0]],"atl":[[9,43.26]],"trd":[[9,316.42]],"batb":[[2,8.4,76.08],[1,8.6,69.1],[0,8.8,90.21]],"batl":[[2,9.4,19.63],[1,9.2,49.09],[0,9,43.26]],"tv":8373.94,"id":35856222},{"atl":[[5.2,83.35]],"batl":[[0,5.2,83.35]],"id":56297029}],"tv":68484.73}]}
{"op":"mcm","id":2,"clk":"AMYgAKUVAN4c","pt":1743511715532,"mc":[{"id":"1.241629436","rc":[{"atl":[[12.5,66.32]],"batl":[[0,12.5,66.32]],"id":40389088},{"atb":[[8.8,72.84]],"batb":[[0,8.8,72.84]],"id":35856222}]}]}
{"op":"mcm","id":2,"clk":"ANAgAKkVAOMc","pt":1743511715677,"mc":[{"id":"1.241629436","rc":[{"atb":[[12,40.78]],"atl":[[14,13.68],[13.5,14.62],[13,16.08],[12.5,75.5]],"batb":[[0,12,40.78]],"batl":[[2,13.5,14.62],[1,13,16.08],[0,12.5,75.5]],"id":40389088},{"atl":[[1000,21.16]],"id":270592},{"atb":[[7.8,21.53],[8.8,78.71]],"atl":[[10.5,44.73],[9.2,42.6],[9,6.03]],"trd":[[9,402.94]],"batb":[[0,8.8,78.71]],"batl":[[1,9.2,42.6],[0,9,6.03]],"tv":8460.46,"id":35856222}],"tv":68571.25}]}
{"op":"mcm","id":2,"clk":"ANkgALIVAOkc","pt":1743511715737,"mc":[{"id":"1.241629436","rc":[{"atl":[[12.5,63.17]],"batl":[[0,12.5,63.17]],"id":40389088},{"atb":[[5.2,225.54]],"trd":[[5.2,1263.6]],"batb":[[0,5.2,225.54]],"ltp":5.2,"tv":15079.64,"id":270592},{"atb":[[5.1,260.12]],"trd":[[5.1,2782.63]],"batb":[[0,5.1,260.12]],"tv":11667.95,"id":56297029},{"atl":[[6.6,45.87]],"batl":[[0,6.6,45.87]],"id":26496185}],"tv":68579.23}]}
{"op":"mcm","id":2,"clk":"AOkgALYVAO4c","pt":1743511715845,"mc":[{"id":"1.241629436","rc":[{"atb":[[12,33.6]],"atl":[[14,12.25],[13.5,13.08]],"batb":[[0,12,33.6]],"batl":[[2,13.5,13.08]],"id":40389088},{"atb":[[8.8,79.28],[6,5.97]],"atl":[[9.2,34.08]],"batb":[[0,8.8,79.28]],"batl":[[1,9.2,34.08]],"id":35856222},{"atb":[[5,1155.26],[5.1,254.48]],"batb":[[1,5,1155.26],[0,5.1,254.48]],"id":56297029},{"atb":[[16.5,47.21]],"batb":[[1,16.5,47.21]],"id":58186642},{"atb":[[6.4,194.72]],"atl":[[6.6,50.51]],"batb":[[0,6.4,194.72]],"batl":[[0,6.6,50.51]],"id":26496185}]}]}
{"op":"mcm","id":2,"clk":"AO8gALsVAPQc","pt":1743511715938,"mc":[{"id":"1.241629436","rc":[{"atb":[[12,28.87]],"batb":[[0,12,28.87]],"id":40389088},{"atb":[[4.8,222.99]],"batb":[],"id":270592},{"atl":[[9,0]],"trd":[[9,415]],"batl":[[2,9.6,49.14],[1,9.4,19.63],[0,9.2,34.08]],"tv":8472.52,"id":35856222},{"atb":[[5.6,91.84]],"batb":[],"id":26496185}],"tv":68591.29}]}
{"op":"mcm","id":2,"clk":"APogAL4VAPwc","pt":1743511716044,"mc":[{"id":"1.241629436","rc":[{"atb":[[8.4,60.71],[7.8,19.59],[9,6.11]],"batb":[[2,8.6,69.1],[1,8.8,79.28],[0,9,6.11]],"id":35856222}]}]}
{"op":"mcm","id":2,"clk":"AIEhAL8VAIYd","pt":1743511716145,"mc":[{"id":"1.241629436","rc":[{"atl":[[5.6,40.13]],"batl":[],"id":270592},{"atb":[[9,3.49]],"trd":[[9,420.24]],"batb":[[0,9,3.49]],"tv":8477.76,"id":35856222},{"atb":[[4.9,77.31]],"batb":[[2,4.9,77.31]],"id":56297029}],"tv":68596.53}]}
{"op":"mcm","id":2,"clk":"AJchAMcVAJEd","pt":1743511716350,"mc":[{"id":"1.241629436","rc":[{"atl":[[1000,23.16]],"id":270592},{"atb":[[6.2,15.92]],"id":35856222}]}]}
{"op":"mcm","id":2,"clk":"AKUhAM4VAJod","pt":1743511716458,"mc":[{"id":"1.241629436","rc":[{"atb":[[70,1.58]],"trd":[[70,58.95]],"batb":[[0,70,1.58]],"ltp":70,"tv":1589.81,"id":59626646}],"tv":68604.53}]}
{"op":"mcm","id":2,"clk":"AKshANMVAKAd","pt":1743511716556,"mc":[{"id":"1.241629436","rc":[{"atb":[[12,33.6]],"batb":[[0,12,33.6]],"id":40389088},{"atl":[[75,2.73]],"batl":[[0,75,2.73]],"id":59626646},{"atb":[[5.1,254.29]],"trd":[[5.1,2783.01]],"batb":[[0,5.1,254.29]],"tv":11668.33,"id":56297029},{"atb":[[16.5,50.56]],"batb":[[1,16.5,50.56]],"id":58186642}],"tv":68604.91}]}
{"op":"mcm","id":2,"clk":"ALghANYVAKYd","pt":1743511716658,"mc":[{"id":"1.241629436","rc":[{"atl":[[1000,21.16]],"id":270592}]}]}
{"op":"mcm","id":2,"clk":"AL0hANwVAKwd","pt":1743511716759,"mc":[{"id":"1.241629436","rc":[{"atb":[[1.17,2.82]],"atl":[[1000,0.41],[12.5,62.93]],"batl":[[0,12.5,62.93]],"id":40389088},{"atb":[[5.2,224.56]],"batb":[[0,5.2,224.56]],"id":270592},{"atb":[[8.8,77.55],[9,4.71]],"batb":[[1,8.8,77.55],[0,9,4.71]],"id":35856222},{"atb":[[60,16.94],[65,36.24]],"batb":[[2,60,16.94],[1,65,36.24]],"id":59626646},{"atb":[[5.1,253.6]],"atl":[[5.3,121.97]],"batb":[[0,5.1,253.6]],"batl":[[1,5.3,121.97]],"id":56297029},{"atl":[[17.5,3.25]],"batl":[[0,17.5,3.25]],"id":58186642}]}]}
{"op":"mcm","id":2,"clk":"AMkhAOAVALMd","pt":1743511716860,"mc":[{"id":"1.241629436","rc":[{"atb":[[1.17,2],[11.5,63.49]],"atl":[[1000,0.25]],"batb":[[1,11.5,63.49]],"id":40389088},{"atl":[[5.4,88.05]],"batl":[[1,5.4,88.05]],"id":270592},{"atb":[[16.5,47.21]],"atl":[[17.5,2.96]],"batb":[[1,16.5,47.21]],"batl":[[0,17.5,2.96]],"id":58186642}]}]}
{"op":"mcm","id":2,"clk":"ANQhAOoVALsd","pt":1743511716968,"mc":[{"id":"1.241629436","rc":[{"atb":[[12,34.42]],"atl":[[13,16.24]],"batb":[[0,12,34.42]],"batl":[[1,13,16.24]],"id":40389088}]}]}
{"op":"mcm","id":2,"clk":"AN4hAOwVAMAd","pt":1743511717062,"mc":[{"id":"1.241629436","rc":[{"atb":[[11,104.62]],"batb":[[2,11,104.62]],"id":40389088},{"atb":[[6.4,18.59]],"id":35856222},{"atb":[[16.5,50.56]],"batb":[[1,16.5,50.56]],"id":58186642}]}]}
{"op":"mcm","id":2,"clk":"APMhAPUVAM4d","pt":1743511717273,"mc":[{"id":"1.241629436","rc":[{"atl":[[12.5,116.29]],"batl":[[0,12.5,116.29]],"id":40389088},{"atl":[[75,11.62]],"batl":[[0,75,11.62]],"id":59626646},{"atl":[[17.5,41.07]],"batl":[[0,17.5,41.07]],"id":58186642}]}]}
{"op":"mcm","id":2,"clk":"AIEiAPgVANUd","pt":1743511717375,"mc":[{"id":"1.241629436","rc":[{"atb":[[70,0]],"atl":[[70,1.53]],"trd":[[70,62.1]],"batb":[[2,55,13.47],[1,60,16.94],[0,65,36.24]],"batl":[[2,80,5.57],[1,75,11.62],[0,70,1.53]],"tv":1592.96,"id":59626646},{"atb":[[5,1166.36]],"batb":[[1,5,1166.36]],"id":56297029},{"atb":[[17,0]],"atl":[[17,5.84],[17.5,41.36]],"trd":[[17,396.93]],"batb":[[2,15.5,29.7],[1,16,17.59],[0,16.5,50.56]],"batl":[[2,18,51.79],[1,17.5,41.36],[0,17,5.84]],"tv":4627.3,"id":58186642}],"tv":68630.08}]}
{"op":"mcm","id":2,"clk":"AIsiAIQWAOAd","pt":1743511717490,"mc":[{"id":"1.241629436","rc":[{"atb":[[16.5,47.21]],"atl":[[19.5,5.48],[17,0]],"trd":[[17,408.61]],"batb":[[0,16.5,47.21]],"batl":[[2,18.5,12.46],[1,18,51.79],[0,17.5,41.36]],"tv":4638.98,"id":58186642}],"tv":68641.76}]}
{"op":"mcm","id":2,"clk":"AJEiAIcWAOId","pt":1743511717583,"mc":[{"id":"1.241629436","rc":[{"atb":[[12,29.69]],"batb":[[0,12,29.69]],"id":40389088},{"atb":[[5,1155.26]],"batb":[[1,5,1155.26]],"id":56297029},{"atb":[[17,1],[16.5,51.76]],"batb":[[2,16,17.59],[1,16.5,51.76],[0,17,1]],"id":58186642}]}]}
{"op":"mcm","id":2,"clk":"AJoiAIoWAOkd","pt":1743511717630,"mc":[{"id":"1.241629436","rc":[{"atl":[[28,2]],"id":35856222},{"atb":[[15.5,40.05]],"batb":[],"id":58186642}]}]}
{"op":"mcm","id":2,"clk":"AKMiAI8WAPAd","pt":1743511717737,"mc":[{"id":"1.241629436","rc":[{"atb":[[6.6,5.65]],"id":35856222},{"atb":[[5,1166.36]],"batb":[[1,5,1166.36]],"id":56297029},{"atb":[[15.5,43.53],[16,14.2]],"batb":[[2,16,14.2]],"id":58186642}]}]}
{"op":"mcm","id":2,"clk":"AK8iAJYWAPgd","pt":1743511717845,"mc":[{"id":"1.241629436","rc":[{"atb":[[12,15.02]],"batb":[[0,12,15.02]],"id":40389088},{"atb":[[17,0]],"batb":[[2,15.5,43.53],[1,16,14.2],[0,16.5,51.76]],"id":58186642}]}]}
{"op":"mcm","id":2,"clk":"ALwiAJgWAIQe","pt":1743511717943,"mc":[{"id":"1.241629436","rc":[{"atb":[[5,1155.26]],"batb":[[1,5,1155.26]],"id":56297029},{"atb":[[16,17.58]],"batb":[[1,16,17.58]],"id":58186642}]}]}
{"op":"mcm","id":2,"clk":"AMYiAJ8WAIoe","pt":1743511718044,"mc":[{"id":"1.241629436","rc":[{"atb":[[5.2,222.56]],"trd":[[5.2,1267.6]],"batb":[[0,5.2,222.56]],"tv":15083.64,"id":270592},{"atl":[[5.2,98.35]],"batl":[[0,5.2,98.35]],"id":56297029}],"tv":68645.76}]}
{"op":"mcm","id":2,"clk":"AM8iAKMWAJge","pt":1743511718149,"mc":[{"id":"1.241629436","rc":[{"atb":[[6.8,41.1],[8.6,75.83]],"batb":[[2,8.6,75.83]],"id":35856222}]}]}
{"op":"mcm","id":2,"clk":"ANciAKcWAKAe","pt":1743511718249,"mc":[{"id":"1.241629436","rc":[{"atl":[[1000,2.25]],"id":40389088},{"atb":[[8.4,76.08],[9,2.71]],"trd":[[9,424.24]],"batb":[[0,9,2.71]],"tv":8481.76,"id":35856222}],"tv":68649.76}]}
{"op":"mcm","id":2,"clk":"AOgiAK0WAKYe","pt":1743511718358,"mc":[{"id":"1.241629436","rc":[{"atb":[[5.2,220.56]],"trd":[[5.2,1271.6]],"batb":[[0,5.2,220.56]],"tv":15087.64,"id":270592},{"atb":[[10,100.33]],"trd":[[10,208.11]],"batb":[[0,10,100.33]],"tv":5957.72,"id":27115873}],"tv":68655.76}]}
{"op":"mcm","id":2,"clk":"APMiAK8WAKwe","pt":1743511718461,"mc":[{"id":"1.241629436","rc":[{"atl":[[1000,0.98]],"id":40389088},{"atb":[[36,0],[65,15.01]],"batb":[[0,65,15.01]],"id":59626646},{"atl":[[10.5,86.34]],"batl":[[0,10.5,86.34]],"id":27115873}]}]}
{"op":"mcm","id":2,"clk":"APkiALIWALIe","pt":1743511718562,"mc":[{"id":"1.241629436","rc":[{"atb":[[5,1166.36]],"batb":[[1,5,1166.36]],"id":56297029}]}]}
{"op":"mcm","id":2,"clk":"AIQjALcWALse","pt":1743511718662,"mc":[{"id":"1.241629436","rc":[{"atl":[[1000,0.25]],"id":40389088},{"atb":[[7,22.83]],"id":35856222}]}]}
{"op":"mcm","id":2,"clk":"AI4jALoWAMEe","pt":1743511718765,"mc":[{"id":"1.241629436","rc":[{"atb":[[12,14.29]],"trd":[[12,1371.74]],"batb":[[0,12,14.29]],"ltp":12,"tv":5955.69,"id":40389088},{"atb":[[7.4,10.66]],"batb":[],"id":35856222}],"tv":68657.22}]}
{"op":"mcm","id":2,"clk":"AJojAMAWANEe","pt":1743511718960,"mc":[{"id":"1.241629436","rc":[{"atb":[[17,1.1]],"batb":[[2,16,17.58],[1,16.5,51.76],[0,17,1.1]],"id":58186642}]}]}
{"op":"mcm","id":2,"clk":"ALAjANAWAOIe","pt":1743511719275,"mc":[{"id":"1.241629436","rc":[{"atb":[[11,99.15]],"batb":[[2,11,99.15]],"id":40389088}]}]}
{"op":"mcm","id":2,"clk":"AMAjANQWAO4e","pt":1743511719476,"mc":[{"id":"1.241629436","rc":[{"atb":[[6.4,144.71]],"trd":[[6.4,2898.09]],"batb":[[0,6.4,144.71]],"tv":11447.57,"id":26496185}],"tv":68757.23}]}
{"op":"mcm","id":2,"clk":"AMsjANYWAPUe","pt":1743511719579,"mc":[{"id":"1.241629436","rc":[{"atb":[[11.5,63.09]],"atl":[[1000,0.4]],"batb":[[1,11.5,63.09]],"id":40389088},{"atb":[[5.1,252.24]],"batb":[[0,5.1,252.24]],"id":56297029}]}]}
{"op":"mcm","id":2,"clk":"ANMjANoWAIAf","pt":1743511719689,"mc":[{"id":"1.241629436","rc":[{"atl":[[1000,0.25]],"id":40389088},{"atb":[[17,2.1]],"batb":[[0,17,2.1]],"id":58186642}]}]}
{"op":"mcm","id":2,"clk":"ANUjANoWAIAf","pt":1743511719731,"mc":[{"id":"1.241629436","rc":[{"atl":[[12.5,116.44]],"batl":[[0,12.5,116.44]],"id":40389088}]}]}
{"op":"mcm","id":2,"clk":"AN8jAN8WAIsf","pt":1743511719847,"mc":[{"id":"1.241629436","rc":[{"atb":[[12,4.29]],"batb":[[0,12,4.29]],"id":40389088},{"atb":[[5.9,2.1]],"id":35856222},{"atl":[[75,12.58]],"batl":[[1,75,12.58]],"id":59626646}]}]}
{"op":"mcm","id":2,"clk":"AOgjAOAWAJIf","pt":1743511719943,"mc":[{"id":"1.241629436","rc":[{"atl":[[12.5,121.24]],"batl":[[0,12.5,121.24]],"id":40389088},{"atl":[[9.4,13.43]],"batl":[[1,9.4,13.43]],"id":35856222}]}]}
{"op":"mcm","id":2,"clk":"APAjAOIWAJkf","pt":1743511720051,"mc":[{"id":"1.241629436","rc":[{"atb":[[12,0]],"atl":[[12,14.44]],"trd":[[12,1380.32]],"batb":[[2,10.5,38.37],[1,11,99.15],[0,11.5,63.09]],"batl":[[2,13,16.24],[1,12.5,121.24],[0,12,14.44]],"tv":5964.27,"id":40389088}],"tv":68765.81}]}
{"op":"mcm","id":2,"clk":"APgjAOcWAJ0f","pt":1743511720145,"mc":[{"id":"1.241629436","rc":[{"atb":[[11.5,53.01],[10.5,49.8],[9.6,28.6]],"atl":[[15,24.6],[14.5,21.24],[12.5,94.76]],"batb":[[2,10.5,49.8],[0,11.5,53.01]],"batl":[[1,12.5,94.76]],"id":40389088},{"atl":[[5.6,38.15]],"batl":[],"id":270592}]}]}
{"op":"mcm","id":2,"clk":"AIIkAPAWAKQf","pt":1743511720253,"mc":[{"id":"1.241629436","rc":[{"atb":[[6.4,167.68]],"batb":[[0,6.4,167.68]],"id":26496185}]}]}
{"op":"mcm","id":2,"clk":"AJskAPwWALMf","pt":1743511720456,"mc":[{"id":"1.241629436","rc":[{"atb":[[10.5,38.37]],"batb":[[2,10.5,38.37]],"id":40389088},{"atb":[[5.2,210.56]],"trd":[[5.2,1291.6]],"batb":[[0,5.2,210.56]],"tv":15107.64,"id":270592}],"tv":68785.81}]}
{"op":"mcm","id":2,"clk":"AKIkAIEXALcf","pt":1743511720549,"mc":[{"id":"1.241629436","rc":[{"atb":[[5.8,1]],"id":35856222}]}]}
{"op":"mcm","id":2,"clk":"AKwkAIMXALwf","pt":1743511720652,"mc":[{"id":"1.241629436","rc":[{"atl":[[5.2,92.73]],"batl":[[0,5.2,92.73]],"id":56297029}]}]}
{"op":"mcm","id":2,"clk":"ALYkAIkXAMMf","pt":1743511720766,"mc":[{"id":"1.241629436","rc":[{"atb":[[5.2,208.56]],"trd":[[5.2,1295.6]],"batb":[[0,5.2,208.56]],"tv":15111.64,"id":270592}],"tv":68789.81}]}
{"op":"mcm","id":2,"clk":"AL4kAI0XAMof","pt":1743511720859,"mc":[{"id":"1.241629436","rc":[{"atl":[[1000,23.16]],"id":270592}]}]}
{"op":"mcm","id":2,"clk":"AMwkAI8XANIf","pt":1743511720966,"mc":[{"id":"1.241629436","rc":[{"atb":[[5.2,208.46]],"trd":[[5.2,1295.8]],"batb":[[0,5.2,208.46]],"tv":15111.84,"id":270592}],"tv":68790.01}]}
{"op":"mcm","id":2,"clk":"ANAkAJQXANYf","pt":1743511721063,"mc":[{"id":"1.241629436","rc":[{"atl":[[1000,21.16]],"id":270592}]}]}
{"op":"mcm","id":2,"clk":"ANQkAJkXANsf","pt":1743511721163,"mc":[{"id":"1.241629436","rc":[{"atb":[[5.2,206.46]],"trd":[[5.2,1299.8]],"batb":[[0,5.2,206.46]],"tv":15115.84,"id":270592}],"tv":68794.01}]}
{"op":"mcm","id":2,"clk":"ANskAJ8XAOQf","pt":1743511721269,"mc":[{"id":"1.241629436","rc":[{"atb":[[17,1.1]],"batb":[[0,17,1.1]],"id":58186642}]}]}
{"op":"mcm","id":2,"clk":"AOkkAKgXAOwf","pt":1743511721373,"mc":[{"id":"1.241629436","rc":[{"atb":[[5.1,252.14]],"trd":[[5.1,2783.21]],"batb":[[0,5.1,252.14]],"tv":11668.53,"id":56297029}],"tv":68794.21}]}
{"op":"mcm","id":2,"clk":"APQkAK8XAPof","pt":1743511721475,"mc":[{"id":"1.241629436","rc":[{"atb":[[7.2,12.84]],"batb":[],"id":35856222},{"atl":[[11,85.26]],"trd":[[11,1094.67]],"batl":[[0,11,85.26]],"ltp":11,"tv":3936.58,"id":44049799}],"tv":68804.21}]}
{"op":"mcm","id":2,"clk":"AIklALYXAIEg","pt":1743511721678,"mc":[{"id":"1.241629436","rc":[{"atl":[[11,103.99]],"batl":[[0,11,103.99]],"id":44049799}]}]}
{"op":"mcm","id":2,"clk":"AJslAMMXAJEg","pt":1743511721887,"mc":[{"id":"1.241629436","rc":[{"atl":[[1000,23.16]],"id":270592},{"atb":[[17,0.1]],"trd":[[17,410.62]],"batb":[[2,15.5,43.53],[1,16,17.58],[0,16.5,51.86]],"tv":4640.99,"id":58186642}],"tv":68806.22}]}
{"op":"mcm","id":2,"clk":"AKMlAMkXAJYg","pt":1743511721938,"mc":[{"id":"1.241629436","rc":[{"atb":[[7.4,10.76]],"batb":[],"id":35856222}]}]}
{"op":"mcm","id":2,"clk":"AKwlAMwXAJ4g","pt":1743511722040,"mc":[{"id":"1.241629436","rc":[{"atl":[[1000,21.16]],"id":270592},{"atl":[[9.4,17.92]],"batl":[[1,9.4,17.92]],"id":35856222},{"atb":[[17,0]],"atl":[[17,1.67]],"trd":[[17,410.82]],"batb":[[0,16.5,51.76]],"batl":[[2,18,51.79],[1,17.5,41.36],[0,17,1.67]],"tv":4641.19,"id":58186642}],"tv":68806.42}]}
{"op":"mcm","id":2,"clk":"ALolANEXAKMg","pt":1743511722143,"mc":[{"id":"1.241629436","rc":[{"atl":[[13,21.74],[12,15.44]],"batl":[[2,13,21.74],[0,12,15.44]],"id":40389088},{"atb":[[16.5,55.1]],"batb":[[0,16.5,55.1]],"id":58186642}]}]}
{"op":"mcm","id":2,"clk":"ANElANkXALAg","pt":1743511722345,"mc":[{"id":"1.241629436","rc":[{"atb":[[5.2,207.8]],"batb":[[0,5.2,207.8]],"id":270592},{"atb":[[7.6,35.08]],"batb":[],"id":35856222}]}]}
{"op":"mcm","id":2,"clk":"AOAlAN8XALog","pt":1743511722456,"mc":[{"id":"1.241629436","rc":[{"atb":[[9,3.78]],"batb":[[0,9,3.78]],"id":35856222}]}]}
{"op":"mcm","id":2,"clk":"AIwmAPcXAOQg","pt":1743511723062,"mc":[{"id":"1.241629436","rc":[{"atl":[[13,16.24]],"batl":[[2,13,16.24]],"id":40389088},{"atb":[[7.8,19.69],[8.6,69.1]],"atl":[[28,2.03]],"batb":[[2,8.6,69.1]],"id":35856222},{"atb":[[10,80.33]],"trd":[[10,248.11]],"batb":[[0,10,80.33]],"tv":5997.72,"id":27115873},{"atl":[[6.6,44.87]],"trd":[[6.6,1639.27]],"batl":[[0,6.6,44.87]],"ltp":6.6,"tv":11458.85,"id":26496185}],"tv":68857.7}]}
{"op":"mcm","id":2,"clk":"AJMmAP4XAOsg","pt":1743511723164,"mc":[{"id":"1.241629436","rc":[{"atl":[[10.5,98.88]],"batl":[[0,10.5,98.88]],"id":27115873}]}]}
{"op":"mcm","id":2,"clk":"AJwmAIUYAPQg","pt":1743511723270,"mc":[{"id":"1.241629436","rc":[{"atl":[[13,16.08]],"batl":[[2,13,16.08]],"id":40389088},{"atb":[[60,17.69],[65,14.43]],"atl":[[75,11.62],[70,2.07]],"batb":[[1,60,17.69],[0,65,14.43]],"batl":[[1,75,11.62],[0,70,2.07]],"id":59626646},{"atb":[[1.17,2.49],[16,18.25],[16.5,54.24]],"atl":[[17.5,41.08]],"batb":[[1,16,18.25],[0,16.5,54.24]],"batl":[[1,17.5,41.08]],"id":58186642},{"atb":[[6.4,164.68]],"trd":[[6.4,2904.09]],"batb":[[0,6.4,164.68]],"ltp":6.4,"tv":11464.85,"id":26496185},{"atb":[[10.5,91.59]],"batb":[[0,10.5,91.59]],"id":44049799}],"tv":68863.7}]}
{"op":"mcm","id":2,"clk":"AKAmAIkYAPog","pt":1743511723366,"mc":[{"id":"1.241629436","rc":[{"atb":[[1.17,2]],"id":58186642}]}]}
{"op":"mcm","id":2,"clk":"AKcmAJIYAI4h","pt":1743511723484,"mc":[{"id":"1.241629436","rc":[{"atl":[[5.2,90.73]],"trd":[[5.2,3453.73]],"batl":[[0,5.2,90.73]],"ltp":5.2,"tv":11672.53,"id":56297029},{"atb":[[16.5,54.73]],"batb":[[0,16.5,54.73]],"id":58186642},{"atb":[[6.4,199.59]],"batb":[[0,6.4,199.59]],"id":26496185}],"tv":68867.7}]}
{"op":"mcm","id":2,"clk":"AKomAJkYAJMh","pt":1743511723583,"mc":[{"id":"1.241629436","rc":[{"atb":[[8,57.61]],"batb":[],"id":35856222},{"atb":[[6.2,125.85]],"batb":[[1,6.2,125.85]],"id":26496185}]}]}
{"op":"mcm","id":2,"clk":"ALImAJwYAJ0h","pt":1743511723685,"mc":[{"id":"1.241629436","rc":[{"atl":[[5.2,157.02]],"batl":[[0,5.2,157.02]],"id":56297029},{"atb":[[6,160.17]],"batb":[[2,6,160.17]],"id":26496185}]}]}
{"op":"mcm","id":2,"clk":"ALgmAKEYAKMh","pt":1743511723780,"mc":[{"id":"1.241629436","rc":[{"atb":[[6.4,194.18]],"trd":[[6.4,2914.91]],"batb":[[0,6.4,194.18]],"tv":11475.67,"id":26496185}],"tv":68878.52}]}
{"op":"mcm","id":2,"clk":"AMgmAKYYALIh","pt":1743511723939,"mc":[{"id":"1.241629436","rc":[{"atl":[[10,90.86]],"batl":[],"id":35856222}]}]}
{"op":"mcm","id":2,"clk":"ANImAKsYALch","pt":1743511724042,"mc":[{"id":"1.241629436","rc":[{"atb":[[6.4,189.18]],"trd":[[6.4,2924.91]],"batb":[[0,6.4,189.18]],"tv":11485.67,"id":26496185}],"tv":68888.52}]}
{"op":"mcm","id":2,"clk":"ANkmALAYALsh","pt":1743511724140,"mc":[{"id":"1.241629436","rc":[{"atl":[[5.2,151.41]],"batl":[[0,5.2,151.41]],"id":56297029}]}]}
{"op":"mcm","id":2,"clk":"AOImALQYAMUh","pt":1743511724247,"mc":[{"id":"1.241629436","rc":[{"atl":[[9.2,32.13]],"trd":[[9.2,598.33]],"batl":[[0,9.2,32.13]],"ltp":9.2,"tv":8485.66,"id":35856222}],"tv":68892.42}]}
{"op":"mcm","id":2,"clk":"AOsmALkYAMgh","pt":1743511724353,"mc":[{"id":"1.241629436","rc":[{"atb":[[8.8,71.78]],"batb":[[1,8.8,71.78]],"id":35856222}]}]}
{"op":"mcm","id":2,"clk":"APMmAL0YAM4h","pt":1743511724444,"mc":[{"id":"1.241629436","rc":[{"atb":[[5.2,241.84]],"batb":[[0,5.2,241.84]],"id":270592}]}]}
{"op":"mcm","id":2,"clk":"APsmAMMYANgh","pt":1743511724548,"mc":[{"id":"1.241629436","rc":[{"atb":[[5.8,1.1]],"id":35856222}]}]}
{"op":"mcm","id":2,"clk":"AIInAMgYAN0h","pt":1743511724653,"mc":[{"id":"1.241629436","rc":[{"atb":[[10.5,86.59]],"trd":[[10.5,423.01]],"batb":[[0,10.5,86.59]],"ltp":10.5,"tv":3946.58,"id":44049799}],"tv":68902.42}]}
{"op":"mcm","id":2,"clk":"AIknAM8YAOMh","pt":1743511724753,"mc":[{"id":"1.241629436","rc":[{"atb":[[5.2,246.28]],"batb":[[0,5.2,246.28]],"id":270592},{"atb":[[9,11.06]],"batb":[[0,9,11.06]],"id":35856222},{"atb":[[5.1,256.66]],"batb":[[0,5.1,256.66]],"id":56297029},{"atb":[[16.5,58.7]],"batb":[[0,16.5,58.7]],"id":58186642},{"atb":[[6.4,192.79]],"batb":[[0,6.4,192.79]],"id":26496185}]}]}
{"op":"mcm","id":2,"clk":"AJEnANcYAPAh","pt":1743511724860,"mc":[{"id":"1.241629436","rc":[{"atb":[[5.2,257.61]],"batb":[[0,5.2,257.61]],"id":270592},{"atb":[[9,25.67],[8,42.61]],"atl":[[9.4,13.43]],"batb":[[0,9,25.67]],"batl":[[1,9.4,13.43]],"id":35856222},{"atb":[[6.4,190.79]],"trd":[[6.4,2928.91]],"batb":[[0,6.4,190.79]],"tv":11489.67,"id":26496185}],"tv":68906.42}]}
{"op":"mcm","id":2,"clk":"AJYnANoYAPUh","pt":1743511724956,"mc":[{"id":"1.241629436","rc":[{"atb":[[16.5,66.36]],"batb":[[0,16.5,66.36]],"id":58186642}]}]}
{"op":"mcm","id":2,"clk":"AKInAOQYAP4h","pt":1743511725063,"mc":[{"id":"1.241629436","rc":[{"atl":[[9.2,31.59]],"batl":[[0,9.2,31.59]],"id":35856222},{"atb":[[5.1,260.44]],"batb":[[0,5.1,260.44]],"id":56297029}]}]}
{"op":"mcm","id":2,"clk":"AKUnAOsYAIMi","pt":1743511725163,"mc":[{"id":"1.241629436","rc":[{"atb":[[4.9,87.56]],"batb":[[2,4.9,87.56]],"id":56297029}]}]}
{"op":"mcm","id":2,"clk":"AKonAO4YAIoi","pt":1743511725264,"mc":[{"id":"1.241629436","rc":[{"atl":[[10,93.47]],"batl":[],"id":35856222},{"atl":[[6.6,36.27]],"trd":[[6.6,1656.46]],"batl":[[0,6.6,36.27]],"ltp":6.6,"tv":11506.86,"id":26496185}],"tv":68923.61}]}
{"op":"mcm","id":2,"clk":"ALMnAPMYAJgi","pt":1743511725373,"mc":[{"id":"1.241629436","rc":[{"atb":[[10,84.58]],"batb":[[0,10,84.58]],"id":27115873},{"atl":[[6.6,55.44]],"batl":[[0,6.6,55.44]],"id":26496185}]}]}
{"op":"mcm","id":2,"clk":"ALYnAPoYAKEi","pt":1743511725470,"mc":[{"id":"1.241629436","rc":[{"atb":[[16,19.25]],"batb":[[1,16,19.25]],"id":58186642}]}]}
{"op":"mcm","id":2,"clk":"ALwnAPsYAKUi","pt":1743511725571,"mc":[{"id":"1.241629436","rc":[{"atb":[[10.5,88.08]],"batb":[[0,10.5,88.08]],"id":44049799}]}]}
{"op":"mcm","id":2,"clk":"AMEnAIAZAKsi","pt":1743511725673,"mc":[{"id":"1.241629436","rc":[{"atb":[[11.5,56.53]],"batb":[[0,11.5,56.53]],"id":40389088},{"atb":[[5.1,265.5]],"batb":[[0,5.1,265.5]],"id":56297029}]}]}
{"op":"mcm","id":2,"clk":"AMknAIkZALYi","pt":1743511725780,"mc":[{"id":"1.241629436","rc":[{"atb":[[1.17,2.71]],"id":40389088},{"atl":[[70,1.34]],"trd":[[70,63.56]],"batl":[[0,70,1.34]],"tv":1594.42,"id":59626646},{"atl":[[17,0.57]],"trd":[[17,413.02]],"batl":[[2,18.5,12.46],[1,18,51.79],[0,17.5,41.65]],"tv":4643.39,"id":58186642}],"tv":68927.27}]}
{"op":"mcm","id":2,"clk":"AM8nAIwZALki","pt":1743511725839,"mc":[{"id":"1.241629436","rc":[{"atb":[[1.17,2]],"id":40389088},{"atb":[[36,1.99]],"id":59626646}]}]}
{"op":"mcm","id":2,"clk":"ANknAJIZAMIi","pt":1743511725943,"mc":[{"id":"1.241629436","rc":[{"atb":[[11.5,57.24]],"batb":[[0,11.5,57.24]],"id":40389088},{"atb":[[16.5,63.03]],"batb":[[0,16.5,63.03]],"id":58186642}]}]}
{"op":"mcm","id":2,"clk":"AO8nAKoZANci","pt":1743511726249,"mc":[{"id":"1.241629436","rc":[{"atb":[[1.17,2.38]],"id":40389088},{"atl":[[1000,23.16]],"id":270592},{"atb":[[1.17,2.24]],"id":56297029},{"atb":[[10,88.31]],"batb":[[0,10,88.31]],"id":27115873},{"atb":[[6.4,197.82]],"batb":[[0,6.4,197.82]],"id":26496185}]}]}
{"op":"mcm","id":2,"clk":"AIMoALQZAN8i","pt":1743511726453,"mc":[{"id":"1.241629436","rc":[{"atb":[[1.17,2]],"id":40389088},{"atl":[[1000,21.16]],"id":270592}]}]}
{"op":"mcm","id":2,"clk":"AIooALgZAOQi","pt":1743511726551,"mc":[{"id":"1.241629436","rc":[{"atb":[[11.5,57.62]],"batb":[[0,11.5,57.62]],"id":40389088}]}]}
{"op":"mcm","id":2,"clk":"AJMoAL4ZAOoi","pt":1743511726656,"mc":[{"id":"1.241629436","rc":[{"atb":[[1.17,2]],"id":56297029}]}]}
{"op":"mcm","id":2,"clk":"AJgoAMMZAPUi","pt":1743511726756,"mc":[{"id":"1.241629436","rc":[{"atb":[[5.1,265.74]],"batb":[[0,5.1,265.74]],"id":56297029}]}]}
{"op":"mcm","id":2,"clk":"ALgoAOMZAJwj","pt":1743511727267,"mc":[{"id":"1.241629436","rc":[{"atl":[[1000,23.16]],"id":270592},{"atb":[[9,22.67]],"trd":[[9,430.24]],"batb":[[0,9,22.67]],"ltp":9,"tv":8491.66,"id":35856222},{"atb":[[65,13.43]],"trd":[[65,86.44]],"batb":[[0,65,13.43]],"ltp":65,"tv":1596.42,"id":59626646},{"atb":[[10,86.31]],"trd":[[10,252.11]],"batb":[[0,10,86.31]],"tv":6001.72,"id":27115873}],"tv":68939.27}]}
{"op":"mcm","id":2,"clk":"AL8oAOUZAKEj","pt":1743511727373,"mc":[{"id":"1.241629436","rc":[{"atb":[[9,28.64]],"batb":[[0,9,28.64]],"id":35856222}]}]}
{"op":"mcm","id":2,"clk":"AMcoAOwZAKgj","pt":1743511727475,"mc":[{"id":"1.241629436","rc":[{"atl":[[1000,21.16]],"id":270592},{"atb":[[8.8,73.05]],"batb":[[1,8.8,73.05]],"id":35856222},{"atb":[[65,19.98]],"batb":[[0,65,19.98]],"id":59626646}]}]}
{"op":"mcm","id":2,"clk":"AOAoAP4ZAMAj","pt":1743511727784,"mc":[{"id":"1.241629436","rc":[{"atb":[[8.8,39.72]],"batb":[[1,8.8,39.72]],"id":35856222}]}]}
{"op":"mcm","id":2,"clk":"AOUoAP8ZAMYj","pt":1743511727880,"mc":[{"id":"1.241629436","rc":[{"atb":[[9,61.97]],"batb":[[0,9,61.97]],"id":35856222}]}]}
{"op":"mcm","id":2,"clk":"AO4oAIMaAMoj","pt":1743511727981,"mc":[{"id":"1.241629436","rc":[{"atb":[[9,68.26]],"batb":[[0,9,68.26]],"id":35856222}]}]}
{"op":"mcm","id":2,"clk":"AMgpAK8aAKkk","pt":1743511729062,"mc":[{"id":"1.241629436","rc":[{"atb":[[11.5,57.24]],"batb":[[0,11.5,57.24]],"id":40389088},{"atl":[[9.4,13.2]],"batl":[[1,9.4,13.2]],"id":35856222},{"atb":[[16.5,62.54]],"batb":[[0,16.5,62.54]],"id":58186642},{"atb":[[10.5,82.87]],"atl":[[11.5,58.45],[11,102.87]],"batb":[[0,10.5,82.87]],"batl":[[1,11.5,58.45],[0,11,102.87]],"id":44049799}]}]}
{"op":"mcm","id":2,"clk":"AOIpALkaAMgk","pt":1743511729465,"mc":[{"id":"1.241629436","rc":[{"atb":[[5.2,255.61]],"trd":[[5.2,1303.8]],"batb":[[0,5.2,255.61]],"tv":15119.84,"id":270592}],"tv":68943.27}]}
{"op":"mcm","id":2,"clk":"APQpAL4aANUk","pt":1743511729673,"mc":[{"id":"1.241629436","rc":[{"atb":[[65,16.79]],"batb":[[0,65,16.79]],"id":59626646}]}]}
{"op":"mcm","id":2,"clk":"APwpAMUaAN0k","pt":1743511729777,"mc":[{"id":"1.241629436","rc":[{"atb":[[5.2,253.61]],"trd":[[5.2,1307.8]],"batb":[[0,5.2,253.61]],"tv":15123.84,"id":270592}],"tv":68947.27}]}
{"op":"mcm","id":2,"clk":"AI4qANYaAO4k","pt":1743511729987,"mc":[{"id":"1.241629436","rc":[{"atb":[[5.2,251.11]],"trd":[[5.2,1312.8]],"batb":[[0,5.2,251.11]],"tv":15128.84,"id":270592}],"tv":68952.27}]}
{"op":"mcm","id":2,"clk":"AKwqAO4aAIIl","pt":1743511730290,"mc":[{"id":"1.241629436","rc":[{"atl":[[28,1]],"id":35856222}]}]}
{"op":"mcm","id":2,"clk":"ALEqAPMaAI4l","pt":1743511730396,"mc":[{"id":"1.241629436","rc":[{"atb":[[9,68.23]],"trd":[[9,430.3]],"batb":[[0,9,68.23]],"tv":8491.72,"id":35856222}],"tv":68952.33}]}
{"op":"mcm","id":2,"clk":"AOMqAIQbAMEl","pt":1743511730966,"mc":[{"id":"1.241629436","rc":[{"atb":[[8.8,39.71]],"batb":[[1,8.8,39.71]],"id":35856222},{"atb":[[6.4,194.75]],"batb":[[0,6.4,194.75]],"id":26496185}]}]}
{"op":"mcm","id":2,"clk":"AOgqAIUbAMgl","pt":1743511731057,"mc":[{"id":"1.241629436","rc":[{"atb":[[9,68.24]],"batb":[[0,9,68.24]],"id":35856222},{"atb":[[4.8,85.65]],"batb":[],"id":56297029},{"atb":[[6.4,197.82]],"batb":[[0,6.4,197.82]],"id":26496185}]}]}
{"op":"mcm","id":2,"clk":"APEqAIgbANAl","pt":1743511731168,"mc":[{"id":"1.241629436","rc":[{"atb":[[11.5,37.24]],"trd":[[11.5,961.61]],"batb":[[0,11.5,37.24]],"ltp":11.5,"tv":6004.27,"id":40389088}],"tv":68992.33}]}
{"op":"mcm","id":2,"clk":"APoqAIsbANYl","pt":1743511731266,"mc":[{"id":"1.241629436","rc":[{"atb":[[11.5,42.28]],"atl":[[12,21.49]],"batb":[[0,11.5,42.28]],"batl":[[0,12,21.49]],"id":40389088}]}]}
{"op":"mcm","id":2,"clk":"AIMrAI0bAN4l","pt":1743511731367,"mc":[{"id":"1.241629436","rc":[{"atl":[[14.5,22.57],[12.5,101.5]],"batl":[[1,12.5,101.5]],"id":40389088}]}]}
{"op":"mcm","id":2,"clk":"AJQrAJQbAO0l","pt":1743511731578,"mc":[{"id":"1.241629436","rc":[{"atb":[[9.6,27.36]],"atl":[[14,13.68],[12.5,94.54],[12,27.83]],"batb":[],"batl":[[1,12.5,94.54],[0,12,27.83]],"id":40389088}]}]}
{"op":"mcm","id":2,"clk":"AJ0rAJUbAPIl","pt":1743511731671,"mc":[{"id":"1.241629436","rc":[{"atl":[[14,12.25]],"batl":[],"id":40389088},{"atl":[[1000,23.16]],"id":270592},{"atb":[[7.4,8.57]],"batb":[],"id":35856222}]}]}
{"op":"mcm","id":2,"clk":"AKIrAJ0bAPkl","pt":1743511731775,"mc":[{"id":"1.241629436","rc":[{"atb":[[16.5,61.54]],"trd":[[16.5,270.33]],"batb":[[0,16.5,61.54]],"ltp":16.5,"tv":4645.39,"id":58186642},{"atl":[[6.6,67.04]],"batl":[[0,6.6,67.04]],"id":26496185}],"tv":68994.33}]}
{"op":"mcm","id":2,"clk":"AKkrAKIbAIEm","pt":1743511731877,"mc":[{"id":"1.241629436","rc":[{"atl":[[12,21.49]],"batl":[[0,12,21.49]],"id":40389088},{"atl":[[1000,21.16]],"id":270592},{"atb":[[6.4,197.04]],"batb":[[0,6.4,197.04]],"id":26496185}]}]}
{"op":"mcm","id":2,"clk":"ALArAKcbAIkm","pt":1743511731979,"mc":[{"id":"1.241629436","rc":[{"atl":[[14.5,21.24]],"batl":[],"id":40389088},{"atb":[[6.4,174.07]],"batb":[[0,6.4,174.07]],"id":26496185},{"atb":[[10.5,75.87]],"trd":[[10.5,437.01]],"batb":[[0,10.5,75.87]],"tv":3960.58,"id":44049799}],"tv":69008.33}]}
{"op":"mcm","id":2,"clk":"ALsrAKwbAJAm","pt":1743511732083,"mc":[{"id":"1.241629436","rc":[{"atl":[[14.5,22.57]],"batl":[],"id":40389088},{"atb":[[5.2,252.15]],"atl":[[1000,21.38]],"batb":[[0,5.2,252.15]],"id":270592},{"atb":[[1.17,7.4]],"id":35856222},{"atl":[[1000,4.71]],"id":56297029}]}]}
{"op":"mcm","id":2,"clk":"AMErALIbAJkm","pt":1743511732184,"mc":[{"id":"1.241629436","rc":[{"atb":[[9.8,30.52]],"batb":[[2,9.8,30.52]],"id":44049799}]}]}
{"op":"mcm","id":2,"clk":"AMwrALkbAKEm","pt":1743511732290,"mc":[{"id":"1.241629436","rc":[{"atl":[[1000,21.16]],"id":270592},{"atb":[[1.17,7.15]],"id":35856222},{"atl":[[1000,4.52]],"id":56297029}]}]}
{"op":"mcm","id":2,"clk":"ANgrAL4bAKYm","pt":1743511732345,"mc":[{"id":"1.241629436","rc":[{"atl":[[5.4,88.27]],"batl":[[1,5.4,88.27]],"id":270592},{"atb":[[9,68.49]],"batb":[[0,9,68.49]],"id":35856222},{"atl":[[5.3,122.16]],"batl":[[1,5.3,122.16]],"id":56297029}]}]}
{"op":"mcm","id":2,"clk":"AOgrAMcbALgm","pt":1743511732547,"mc":[{"id":"1.241629436","rc":[{"atl":[[1000,23.16]],"id":270592},{"atb":[[8.8,31.81],[9,68.44]],"trd":[[9,430.4]],"batb":[[1,8.8,31.81],[0,9,68.44]],"tv":8491.82,"id":35856222},{"atb":[[5.1,240.73]],"trd":[[5.1,2833.21]],"batb":[[0,5.1,240.73]],"ltp":5.1,"tv":11722.53,"id":56297029}],"tv":69058.43}]}
{"op":"mcm","id":2,"clk":"APkrANQbAMgm","pt":1743511732751,"mc":[{"id":"1.241629436","rc":[{"atl":[[1000,21.16]],"id":270592},{"atb":[[4.5,68.28]],"batb":[],"id":56297029}]}]}
{"op":"mcm","id":2,"clk":"AIYsAOMbANUm","pt":1743511732953,"mc":[{"id":"1.241629436","rc":[{"atb":[[10,84.31]],"trd":[[10,256.11]],"batb":[[0,10,84.31]],"tv":6005.72,"id":27115873}],"tv":69062.43}]}
{"op":"mcm","id":2,"clk":"AKMsAPobAPIm","pt":1743511733364,"mc":[{"id":"1.241629436","rc":[{"atb":[[5.9,39.62]],"batb":[],"id":26496185}]}]}
{"op":"mcm","id":2,"clk":"AKgsAP0bAPwm","pt":1743511733465,"mc":[{"id":"1.241629436","rc":[{"atl":[[12.5,95.57]],"batl":[[1,12.5,95.57]],"id":40389088}]}]}
{"op":"mcm","id":2,"clk":"AOcsAJ0cAK8n","pt":1743511734179,"mc":[{"id":"1.241629436","rc":[{"atb":[[11.5,40.28]],"trd":[[11.5,965.61]],"batb":[[0,11.5,40.28]],"tv":6008.27,"id":40389088}],"tv":69066.43}]}
{"op":"mcm","id":2,"clk":"AL4tAMQcAPQn","pt":1743511735070,"mc":[{"id":"1.241629436","rc":[{"atb":[[5.2,251.11]],"atl":[[5.4,88.05]],"batb":[[0,5.2,251.11]],"batl":[[1,5.4,88.05]],"id":270592},{"atb":[[9,68.19]],"batb":[[0,9,68.19]],"id":35856222},{"atb":[[5.1,240.49]],"atl":[[5.3,121.97]],"batb":[[0,5.1,240.49]],"batl":[[1,5.3,121.97]],"id":56297029},{"atl":[[1000,19.21]],"id":44049799}]}]}
{"op":"mcm","id":2,"clk":"AMktAMkcAPYn","pt":1743511735153,"mc":[{"id":"1.241629436","rc":[{"atb":[[16.5,41.54]],"trd":[[16.5,310.32]],"batb":[[0,16.5,41.54]],"tv":4685.38,"id":58186642}],"tv":69106.42}]}
{"op":"mcm","id":2,"clk":"ANItAM8cAP4n","pt":1743511735259,"mc":[{"id":"1.241629436","rc":[{"atl":[[17,9.93]],"batl":[[2,18,51.79],[1,17.5,41.08],[0,17,9.93]],"id":58186642},{"atl":[[6.6,62.4]],"batl":[[0,6.6,62.4]],"id":26496185},{"atl":[[1000,18.87]],"id":44049799}]}]}
{"op":"mcm","id":2,"clk":"AN8tANUcAIUo","pt":1743511735360,"mc":[{"id":"1.241629436","rc":[{"atb":[[16.5,51.19]],"atl":[[17,0]],"trd":[[17,432.88]],"batb":[[0,16.5,51.19]],"batl":[[2,18.5,12.46],[1,18,51.79],[0,17.5,41.08]],"ltp":17,"tv":4705.24,"id":58186642},{"atl":[[6.6,57.76]],"batl":[[0,6.6,57.76]],"id":26496185},{"atl":[[11,103.21]],"batl":[[0,11,103.21]],"id":44049799}],"tv":69126.28}]}
{"op":"mcm","id":2,"clk":"AOctANscAI0o","pt":1743511735470,"mc":[{"id":"1.241629436","rc":[{"atb":[[17,7.87]],"batb":[[2,16,19.25],[1,16.5,51.19],[0,17,7.87]],"id":58186642}]}]}
{"op":"mcm","id":2,"clk":"AO8tAOIcAJUo","pt":1743511735575,"mc":[{"id":"1.241629436","rc":[{"atb":[[16,18.25],[16.5,51.49]],"batb":[[2,16,18.25],[1,16.5,51.49]],"id":58186642}]}]}
{"op":"mcm","id":2,"clk":"AIMuAO0cAKIo","pt":1743511735773,"mc":[{"id":"1.241629436","rc":[{"atb":[[9,72.19]],"batb":[[0,9,72.19]],"id":35856222}]}]}
{"op":"mcm","id":2,"clk":"AJouAPYcALAo","pt":1743511735974,"mc":[{"id":"1.241629436","rc":[{"atb":[[17,8.87]],"batb":[[0,17,8.87]],"id":58186642}]}]}
{"op":"mcm","id":2,"clk":"AIUvAKodAIwp","pt":1743511737058,"mc":[{"id":"1.241629436","rc":[{"atl":[[1000,23.16]],"id":270592}]}]}
{"op":"mcm","id":2,"clk":"AJovALEdAJ0p","pt":1743511737263,"mc":[{"id":"1.241629436","rc":[{"atl":[[1000,21.16]],"id":270592},{"atl":[[10.5,99.88]],"batl":[[0,10.5,99.88]],"id":27115873}]}]}
{"op":"mcm","id":2,"clk":"ALIvALkdAK4p","pt":1743511737463,"mc":[{"id":"1.241629436","rc":[{"atl":[[12.5,42.21]],"batl":[[1,12.5,42.21]],"id":40389088},{"atb":[[8.6,50.6]],"batb":[[2,8.6,50.6]],"id":35856222},{"atl":[[70,10.87]],"batl":[[0,70,10.87]],"id":59626646},{"atl":[[18,14.73]],"batl":[[1,18,14.73]],"id":58186642}]}]}
{"op":"mcm","id":2,"clk":"ALgvAMAdALUp","pt":1743511737569,"mc":[{"id":"1.241629436","rc":[{"atb":[[5.2,244.59]],"trd":[[5.2,1325.84]],"batb":[[0,5.2,244.59]],"tv":15141.88,"id":270592},{"atb":[[9,90.69]],"batb":[[0,9,90.69]],"id":35856222},{"atb":[[65,16.71]],"batb":[[0,65,16.71]],"id":59626646},{"atl":[[6.8,110]],"batl":[[1,6.8,110]],"id":26496185}],"tv":69139.32}]}
{"op":"mcm","id":2,"clk":"AMAvAMkdAL0p","pt":1743511737673,"mc":[{"id":"1.241629436","rc":[{"atb":[[5.1,237.35]],"batb":[[0,5.1,237.35]],"id":56297029},{"atb":[[16,21.97]],"batb":[[2,16,21.97]],"id":58186642},{"atb":[[6.4,164.06]],"trd":[[6.4,2948.91]],"batb":[[0,6.4,164.06]],"ltp":6.4,"tv":11526.86,"id":26496185}],"tv":69159.32}]}
{"op":"mcm","id":2,"clk":"AMcvANAdAMMp","pt":1743511737773,"mc":[{"id":"1.241629436","rc":[{"atl":[[6.6,67.05]],"batl":[[0,6.6,67.05]],"id":26496185}]}]}
{"op":"mcm","id":2,"clk":"AM8vANAdAMsp","pt":1743511737870,"mc":[{"id":"1.241629436","rc":[{"atl":[[1000,23.16]],"id":270592}]}]}
{"op":"mcm","id":2,"clk":"ANcvANUdANAp","pt":1743511737972,"mc":[{"id":"1.241629436","rc":[{"atl":[[5.7,69.6]],"batl":[],"id":56297029}]}]}
{"op":"mcm","id":2,"clk":"AOAvANwdANop","pt":1743511738081,"mc":[{"id":"1.241629436","rc":[{"atl":[[1000,0.36]],"id":40389088},{"atl":[[1000,21.16]],"id":270592},{"atl":[[1000,1.6]],"id":58186642},{"atb":[[10.5,78.12]],"atl":[[1000,19.33]],"batb":[[0,10.5,78.12]],"id":44049799}]}]}
{"op":"mcm","id":2,"clk":"AOgvAOEdAOEp","pt":1743511738172,"mc":[{"id":"1.241629436","rc":[{"atl":[[1000,0.25]],"id":40389088},{"atl":[[1000,1.41]],"id":58186642},{"atl":[[1000,18.87]],"id":44049799}]}]}
{"op":"mcm","id":2,"clk":"APAvAOgdAOop","pt":1743511738278,"mc":[{"id":"1.241629436","rc":[{"atl":[[12,21.6]],"batl":[[0,12,21.6]],"id":40389088},{"atl":[[5.7,75.21]],"batl":[],"id":56297029},{"atb":[[17,8.68]],"trd":[[17,433.26]],"batb":[[0,17,8.68]],"tv":4705.62,"id":58186642},{"atl":[[11.5,58.91]],"batl":[[1,11.5,58.91]],"id":44049799}],"tv":69159.7}]}
{"op":"mcm","id":2,"clk":"APcvAPAdAO8p","pt":1743511738382,"mc":[{"id":"1.241629436","rc":[{"atb":[[9,87.69]],"trd":[[9,436.4]],"batb":[[0,9,87.69]],"tv":8497.82,"id":35856222}],"tv":69165.7}]}
{"op":"mcm","id":2,"clk":"AP4vAPUdAPkp","pt":1743511738486,"mc":[{"id":"1.241629436","rc":[{"atb":[[17,9.34]],"batb":[[0,17,9.34]],"id":58186642}]}]}
{"op":"mcm","id":2,"clk":"AIwwAP8dAIwq","pt":1743511738685,"mc":[{"id":"1.241629436","rc":[{"atb":[[9.8,45.96]],"batb":[[1,9.8,45.96]],"id":27115873}]}]}
{"op":"mcm","id":2,"clk":"AJ8wAIseAJ4q","pt":1743511738886,"mc":[{"id":"1.241629436","rc":[{"atb":[[17,8.35]],"trd":[[17,435.24]],"batb":[[0,17,8.35]],"tv":4707.6,"id":58186642}],"tv":69167.68}]}
{"op":"mcm","id":2,"clk":"ALowAJ0eALQq","pt":1743511739200,"mc":[{"id":"1.241629436","rc":[{"atl":[[9.2,28.84]],"trd":[[9.2,603.83]],"batl":[[0,9.2,28.84]],"ltp":9.2,"tv":8503.32,"id":35856222}],"tv":69173.18}]}
{"op":"mcm","id":2,"clk":"AMgwAKUeAMMq","pt":1743511739364,"mc":[{"id":"1.241629436","rc":[{"atl":[[9.2,25.19]],"batl":[[0,9.2,25.19]],"id":35856222}]}]}
{"op":"mcm","id":2,"clk":"AM8wAKkeAM0q","pt":1743511739457,"mc":[{"id":"1.241629436","rc":[{"atl":[[9.8,33.26],[9.6,43.02]],"batl":[[2,9.6,43.02]],"id":35856222},{"atb":[[16,18.25]],"batb":[[2,16,18.25]],"id":58186642}]}]}
{"op":"mcm","id":2,"clk":"ANowALMeANsq","pt":1743511739662,"mc":[{"id":"1.241629436","rc":[{"atb":[[17,6.35]],"trd":[[17,439.24]],"batb":[[0,17,6.35]],"tv":4711.6,"id":58186642}],"tv":69177.18}]}
{"op":"mcm","id":2,"clk":"AOAwALUeAOEq","pt":1743511739760,"mc":[{"id":"1.241629436","rc":[{"atl":[[18,17.07]],"batl":[[1,18,17.07]],"id":58186642},{"atb":[[6.4,139.06]],"trd":[[6.4,2998.91]],"batb":[[0,6.4,139.06]],"tv":11576.86,"id":26496185}],"tv":69227.18}]}
{"op":"mcm","id":2,"clk":"AOYwALoeAOoq","pt":1743511739866,"mc":[{"id":"1.241629436","rc":[{"atb":[[48,2.42]],"batb":[],"id":59626646},{"atl":[[22,4.45]],"batl":[],"id":58186642}]}]}
{"op":"mcm","id":2,"clk":"APEwAL0eAPMq","pt":1743511739969,"mc":[{"id":"1.241629436","rc":[{"atb":[[50,14.19]],"batb":[],"id":59626646}]}]}
{"op":"mcm","id":2,"clk":"AMgxAPceALAr","pt":1743511740999,"mc":[{"id":"1.241629436","rc":[{"atl":[[5.3,134.87]],"trd":[[5.3,372.83]],"batl":[[0,5.3,134.87]],"ltp":5.3,"tv":15309.15,"id":270592}],"tv":69394.45}]}
{"op":"mcm","id":2,"clk":"AMwxAP0eALcr","pt":1743511741097,"mc":[{"id":"1.241629436","rc":[{"atb":[[17,6.25]],"trd":[[17,439.44]],"batb":[[0,17,6.25]],"tv":4711.8,"id":58186642}],"tv":69394.65}]}
{"op":"mcm","id":2,"clk":"ANIxAIMfAL4r","pt":1743511741198,"mc":[{"id":"1.241629436","rc":[{"atl":[[12.5,45.24],[12,21.49]],"batl":[[1,12.5,45.24],[0,12,21.49]],"id":40389088},{"atb":[[5.3,65.11],[4.8,153.42]],"atl":[[5.4,160.34],[5.3,0]],"trd":[[5.3,578.13]],"batb":[[2,5.1,327.58],[1,5.2,244.59],[0,5.3,65.11]],"batl":[[2,5.6,38.15],[1,5.5,87.21],[0,5.4,160.34]],"tv":15514.45,"id":270592},{"atl":[[70,13.84]],"batl":[[0,70,13.84]],"id":59626646},{"atb":[[16,17.58],[16.5,52.77]],"batb":[[2,16,17.58],[1,16.5,52.77]],"id":58186642},{"atb":[[10.5,80.56]],"batb":[[0,10.5,80.56]],"id":44049799}],"tv":69599.95}]}
{"op":"mcm","id":2,"clk":"ANkxAIcfAMgr","pt":1743511741253,"mc":[{"id":"1.241629436","rc":[{"atl":[[5.6,40.13]],"batl":[[2,5.6,40.13]],"id":270592},{"atb":[[5,1165.37]],"batb":[[1,5,1165.37]],"id":56297029}]}]}
{"op":"mcm","id":2,"clk":"AOMxAI0fAM8r","pt":1743511741362,"mc":[{"id":"1.241629436","rc":[{"atb":[[5.2,245.53],[4.9,178.78],[5.3,8.23],[4.6,59.76],[4.8,124.42]],"atl":[[5.4,149.36],[5.9,74.3],[5.7,153.84],[5.5,84.25]],"trd":[[5.3,739.89]],"batb":[[1,5.2,245.53],[0,5.3,8.23]],"batl":[[1,5.5,84.25],[0,5.4,149.36]],"tv":15676.21,"id":270592},{"atl":[[9.6,49.3]],"batl":[[2,9.6,49.3]],"id":35856222},{"atb":[[5.1,247.4]],"batb":[[0,5.1,247.4]],"id":56297029},{"atb":[[10,91.13]],"batb":[[0,10,91.13]],"id":27115873},{"atb":[[17,0]],"atl":[[17,8.93]],"trd":[[17,451.94]],"batb":[[2,15.5,43.53],[1,16,17.58],[0,16.5,52.77]],"batl":[[2,18,17.07],[1,17.5,41.08],[0,17,8.93]],"tv":4724.3,"id":58186642},{"atb":[[6.4,154.67]],"batb":[[0,6.4,154.67]],"id":26496185}],"tv":69774.21}]}
{"op":"mcm","id":2,"clk":"AOkxAJAfANYr","pt":1743511741457,"mc":[{"id":"1.241629436","rc":[{"atb":[[4.9,177.78],[5.3,3.78]],"atl":[[5.4,155.19],[5.6,44.79]],"trd":[[5.4,168.91],[5.3,748.79]],"batb":[[0,5.3,3.78]],"batl":[[2,5.6,44.79],[0,5.4,155.19]],"tv":15695.11,"id":270592},{"atb":[[16,19.27],[16.5,45.11]],"atl":[[17,0.09]],"trd":[[17,469.62]],"batb":[[1,16,19.27],[0,16.5,45.11]],"batl":[[2,18.5,12.46],[1,18,17.07],[0,17.5,41.17]],"tv":4741.98,"id":58186642}],"tv":69810.79}]}
{"op":"mcm","id":2,"clk":"APQxAKAfAOUr","pt":1743511741666,"mc":[{"id":"1.241629436","rc":[{"atb":[[1.08,2.33],[2.84,0],[5.3,50],[5,315.97]],"atl":[[5.7,154.64],[5.8,35.28]],"batb":[[0,5.3,50]],"batl":[],"id":270592},{"atb":[[17,2.05]],"atl":[[17,0]],"batb":[[2,16,19.27],[1,16.5,45.11],[0,17,2.05]],"batl":[[0,17.5,41.08]],"id":58186642}]}]}
{"op":"mcm","id":2,"clk":"AP4xAKYfAO0r","pt":1743511741772,"mc":[{"id":"1.241629436","rc":[{"atl":[[5.4,144.36]],"batl":[[0,5.4,144.36]],"id":270592},{"atb":[[5,1166.36]],"batb":[[1,5,1166.36]],"id":56297029}]}]}
{"op":"mcm","id":2,"clk":"AIkyAKofAPQr","pt":1743511741872,"mc":[{"id":"1.241629436","rc":[{"atb":[[5.3,48]],"trd":[[5.3,752.79]],"batb":[[0,5.3,48]],"tv":15699.11,"id":270592},{"atb":[[16,17.58]],"batb":[[2,16,17.58]],"id":58186642}],"tv":69814.79}]}
{"op":"mcm","id":2,"clk":"AJgyAK4fAPsr","pt":1743511741976,"mc":[{"id":"1.241629436","rc":[{"atb":[[17,3.56]],"batb":[[0,17,3.56]],"id":58186642}]}]}
{"op":"mcm","id":2,"clk":"AJ0yALIfAIEs","pt":1743511742075,"mc":[{"id":"1.241629436","rc":[{"atb":[[1.08,0.08],[5.3,72]],"atl":[[5.9,79.91]],"batb":[[0,5.3,72]],"batl":[],"id":270592}]}]}
{"op":"mcm","id":2,"clk":"AJ8yALQfAIks","pt":1743511742172,"mc":[{"id":"1.241629436","rc":[{"atb":[[10,89.13]],"trd":[[10,260.11]],"batb":[[0,10,89.13]],"tv":6009.72,"id":27115873}],"tv":69818.79}]}
{"op":"mcm","id":2,"clk":"ALMyAMEfAJYs","pt":1743511742376,"mc":[{"id":"1.241629436","rc":[{"atl":[[9.2,0]],"trd":[[9.2,654.21]],"batl":[[2,9.8,33.26],[1,9.6,49.3],[0,9.4,13.2]],"tv":8553.7,"id":35856222},{"atb":[[5.1,237.41]],"atl":[[5.6,43.4]],"trd":[[5.1,2853.21]],"batb":[[0,5.1,237.41]],"batl":[],"tv":11742.53,"id":56297029}],"tv":69889.17}]}
{"op":"mcm","id":2,"clk":"ALoyAMUfAJss","pt":1743511742480,"mc":[{"id":"1.241629436","rc":[{"atb":[[1.08,0]],"atl":[[1000,23.16]],"id":270592},{"atb":[[9.2,8.16],[9,88.25]],"atl":[[9.6,43.02]],"batb":[[2,8.8,31.81],[1,9,88.25],[0,9.2,8.16]],"batl":[[1,9.6,43.02]],"id":35856222},{"atl":[[17.5,43.42]],"batl":[[0,17.5,43.42]],"id":58186642}]}]}
{"op":"mcm","id":2,"clk":"AMIyAMofAKEs","pt":1743511742585,"mc":[{"id":"1.241629436","rc":[{"atb":[[2.86,3.63]],"atl":[[5.4,155.1]],"batl":[[0,5.4,155.1]],"id":270592},{"atl":[[9.4,27.45]],"batl":[[0,9.4,27.45]],"id":35856222},{"atb":[[5.1,206.9]],"trd":[[5.1,2914.23]],"batb":[[0,5.1,206.9]],"tv":11803.55,"id":56297029},{"atb":[[10,78.13]],"batb":[[0,10,78.13]],"id":27115873}],"tv":69950.19}]}
{"op":"mcm","id":2,"clk":"AM0yAM4fAKQs","pt":1743511742696,"mc":[{"id":"1.241629436","rc":[{"atb":[[11.5,32.32]],"trd":[[11.5,981.53]],"batb":[[0,11.5,32.32]],"tv":6024.19,"id":40389088},{"atb":[[5.3,82.73]],"batb":[[0,5.3,82.73]],"id":270592},{"atb":[[5,1165.37]],"batb":[[1,5,1165.37]],"id":56297029},{"atb":[[6.4,147.04]],"trd":[[6.4,3014.17]],"batb":[[0,6.4,147.04]],"tv":11592.12,"id":26496185}],"tv":69981.37}]}
{"op":"mcm","id":2,"clk":"AM8yANQfAKos","pt":1743511742785,"mc":[{"id":"1.241629436","rc":[{"atb":[[5.3,155.36]],"atl":[[1000,21.16]],"batb":[[0,5.3,155.36]],"id":270592},{"atl":[[9.4,18.2]],"batl":[[0,9.4,18.2]],"id":35856222}]}]}
{"op":"mcm","id":2,"clk":"ANgyANsfALAs","pt":1743511742888,"mc":[{"id":"1.241629436","rc":[{"atb":[[4.9,88.57]],"batb":[[2,4.9,88.57]],"id":56297029}]}]}
{"op":"mcm","id":2,"clk":"AOAyAN0fALgs","pt":1743511742991,"mc":[{"id":"1.241629436","rc":[{"atb":[[5.3,160.21]],"batb":[[0,5.3,160.21]],"id":270592}]}]}
{"op":"mcm","id":2,"clk":"APAyAOofAMMs","pt":1743511743203,"mc":[{"id":"1.241629436","rc":[{"atb":[[4.8,158.17]],"atl":[[1000,23.16],[5.9,81.67],[5.6,42.81]],"batb":[],"batl":[[2,5.6,42.81]],"id":270592}]}]}
{"op":"mcm","id":2,"clk":"AIIzAPEfAM8s","pt":1743511743401,"mc":[{"id":"1.241629436","rc":[{"atl":[[1000,21.16],[5.6,44.79]],"batl":[[2,5.6,44.79]],"id":270592}]}]}
{"op":"mcm","id":2,"clk":"AJYzAPgfAN8s","pt":1743511743566,"mc":[{"id":"1.241629436","rc":[{"atb":[[4.8,124.42]],"batb":[],"id":270592}]}]}
{"op":"mcm","id":2,"clk":"AKIzAIIgAOos","pt":1743511743768,"mc":[{"id":"1.241629436","rc":[{"atb":[[11.5,32.95]],"batb":[[0,11.5,32.95]],"id":40389088},{"atb":[[4.2,16.33]],"atl":[[5.4,156.22]],"batl":[[0,5.4,156.22]],"id":270592},{"atb":[[10.5,81.25]],"batb":[[0,10.5,81.25]],"id":44049799}]}]}
{"op":"mcm","id":2,"clk":"AL0zAJcgAP8s","pt":1743511744079,"mc":[{"id":"1.241629436","rc":[{"atb":[[5.3,158.21]],"atl":[[5.6,42.81]],"trd":[[5.3,756.79]],"batb":[[0,5.3,158.21]],"batl":[[2,5.6,42.81]],"tv":15703.11,"id":270592}],"tv":69985.37}]}
{"op":"mcm","id":2,"clk":"AMMzAJsgAIYt","pt":1743511744173,"mc":[{"id":"1.241629436","rc":[{"atb":[[1.17,1.43]],"id":270592},{"atb":[[1.17,7.26]],"id":35856222},{"atl":[[17.5,49.62]],"batl":[[0,17.5,49.62]],"id":58186642}]}]}
{"op":"mcm","id":2,"clk":"AM0zAKEgAIst","pt":1743511744277,"mc":[{"id":"1.241629436","rc":[{"atb":[[5.1,200.9]],"trd":[[5.1,2926.23]],"batb":[[0,5.1,200.9]],"tv":11815.55,"id":56297029}],"tv":69997.37}]}
{"op":"mcm","id":2,"clk":"ANUzAKogAJMt","pt":1743511744384,"mc":[{"id":"1.241629436","rc":[{"atb":[[1.17,1]],"atl":[[5.6,44.79]],"batl":[[2,5.6,44.79]],"id":270592},{"atb":[[1.17,7.15]],"id":35856222}]}]}
{"op":"mcm","id":2,"clk":"ANszALAgAJct","pt":1743511744478,"mc":[{"id":"1.241629436","rc":[{"atb":[[5.2,245.96],[5.3,156.21]],"trd":[[5.3,760.79]],"batb":[[1,5.2,245.96],[0,5.3,156.21]],"tv":15707.11,"id":270592},{"atb":[[9,88.36]],"batb":[[1,9,88.36]],"id":35856222}],"tv":70001.37}]}
{"op":"mcm","id":2,"clk":"AOQzALMgAJ0t","pt":1743511744581,"mc":[{"id":"1.241629436","rc":[{"atb":[[5.1,319.04]],"batb":[[2,5.1,319.04]],"id":270592}]}]}
{"op":"mcm","id":2,"clk":"APozAMIgAK4t","pt":1743511744804,"mc":[{"id":"1.241629436","rc":[{"atb":[[5.2,254.29]],"batb":[[1,5.2,254.29]],"id":270592},{"atb":[[10,76.13]],"trd":[[10,264.11]],"batb":[[0,10,76.13]],"tv":6013.72,"id":27115873}],"tv":70005.37}]}
{"op":"mcm","id":2,"clk":"AIU0AMogALUt","pt":1743511744896,"mc":[{"id":"1.241629436","rc":[{"atl":[[5.2,150.41]],"trd":[[5.2,3455.73]],"batl":[[0,5.2,150.41]],"ltp":5.2,"tv":11817.55,"id":56297029}],"tv":70007.37}]}
{"op":"mcm","id":2,"clk":"AIk0AMsgALst","pt":1743511744993,"mc":[{"id":"1.241629436","rc":[{"atb":[[9.8,47.96]],"batb":[[1,9.8,47.96]],"id":27115873}]}]}
{"op":"mcm","id":2,"clk":"AKc0ANkgANQt","pt":1743511745309,"mc":[{"id":"1.241629436","rc":[{"atl":[[5.2,170.41]],"batl":[[0,5.2,170.41]],"id":56297029}]}]}
{"op":"mcm","id":2,"clk":"AMI0AOcgAOwt","pt":1743511745670,"mc":[{"id":"1.241629436","rc":[{"atb":[[9.2,0]],"trd":[[9.2,670.53]],"batb":[[2,8.6,50.6],[1,8.8,31.81],[0,9,88.36]],"tv":8570.02,"id":35856222}],"tv":70023.69}]}
{"op":"mcm","id":2,"clk":"AMs0AOwgAPUt","pt":1743511745774,"mc":[{"id":"1.241629436","rc":[{"atl":[[9.4,19.27]],"batl":[[0,9.4,19.27]],"id":35856222}]}]}
{"op":"mcm","id":2,"clk":"ANY0AO4gAPst","pt":1743511745869,"mc":[{"id":"1.241629436","rc":[{"atb":[[6.2,121.47]],"atl":[[6.6,61.08]],"trd":[[6.6,1668.41]],"batb":[[1,6.2,121.47]],"batl":[[0,6.6,61.08]],"ltp":6.6,"tv":11604.07,"id":26496185}],"tv":70035.64}]}
{"op":"mcm","id":2,"clk":"AOE0APUgAIQu","pt":1743511746070,"mc":[{"id":"1.241629436","rc":[{"atb":[[5.3,221.21]],"batb":[[0,5.3,221.21]],"id":270592}]}]}
{"op":"mcm","id":2,"clk":"AOc0APogAIsu","pt":1743511746175,"mc":[{"id":"1.241629436","rc":[{"atb":[[6.4,155.87]],"batb":[[0,6.4,155.87]],"id":26496185}]}]}
{"op":"mcm","id":2,"clk":"AIE1AIshAKgu","pt":1743511746578,"mc":[{"id":"1.241629436","rc":[{"atb":[[10,74.12]],"trd":[[10,268.12]],"batb":[[0,10,74.12]],"tv":6017.73,"id":27115873}],"tv":70039.65}]}
{"op":"mcm","id":2,"clk":"AIs1AJghALMu","pt":1743511746782,"mc":[{"id":"1.241629436","rc":[{"atb":[[9.8,49.96]],"batb":[[1,9.8,49.96]],"id":27115873}]}]}
{"op":"mcm","id":2,"clk":"AJY1AKYhAMEu","pt":1743511746989,"mc":[{"id":"1.241629436","rc":[{"atb":[[9,88.25]],"batb":[[0,9,88.25]],"id":35856222},{"atb":[[6.2,123.47],[6.4,154.63]],"batb":[[1,6.2,123.47],[0,6.4,154.63]],"id":26496185}]}]}
{"op":"mcm","id":2,"clk":"AJw1AKohAMcu","pt":1743511747094,"mc":[{"id":"1.241629436","rc":[{"atl":[[5.5,95.86]],"batl":[[1,5.5,95.86]],"id":270592}]}]}
{"op":"mcm","id":2,"clk":"AKQ1AKwhAM0u","pt":1743511747194,"mc":[{"id":"1.241629436","rc":[{"atb":[[17,2.57]],"trd":[[17,471.6]],"batb":[[0,17,2.57]],"tv":4743.96,"id":58186642}],"tv":70041.63}]}
{"op":"mcm","id":2,"clk":"AK81ALEhANYu","pt":1743511747300,"mc":[{"id":"1.241629436","rc":[{"atb":[[5.2,266.12]],"batb":[[1,5.2,266.12]],"id":270592},{"atb":[[17,0]],"atl":[[17,8.57]],"trd":[[17,476.74]],"batb":[[2,15.5,43.53],[1,16,17.58],[0,16.5,45.11]],"batl":[[2,18,17.07],[1,17.5,49.62],[0,17,8.57]],"tv":4749.1,"id":58186642}],"tv":70046.77}]}
{"op":"mcm","id":2,"clk":"ALQ1ALYhAN0u","pt":1743511747396,"mc":[{"id":"1.241629436","rc":[{"atl":[[17,9.96]],"trd":[[17,481.72]],"batl":[[0,17,9.96]],"tv":4754.08,"id":58186642}],"tv":70051.75}]}
{"op":"mcm","id":2,"clk":"ALs1ALkhAOYu","pt":1743511747498,"mc":[{"id":"1.241629436","rc":[{"atb":[[9,100.11]],"batb":[[0,9,100.11]],"id":35856222},{"atb":[[16,18.58]],"batb":[[1,16,18.58]],"id":58186642}]}]}
{"op":"mcm","id":2,"clk":"ANY1AMshAP4u","pt":1743511747858,"mc":[{"id":"1.241629436","rc":[{"atb":[[5.2,331.12]],"batb":[[1,5.2,331.12]],"id":270592}]}]}
{"op":"mcm","id":2,"clk":"ANw1AM8hAIYv","pt":1743511747966,"mc":[{"id":"1.241629436","rc":[{"atl":[[1000,23.16]],"id":270592}]}]}
{"op":"mcm","id":2,"clk":"AOw1ANkhAJkv","pt":1743511748172,"mc":[{"id":"1.241629436","rc":[{"atl":[[1000,21.16]],"id":270592}]}]}
{"op":"mcm","id":2,"clk":"AIU2AOUhALMv","pt":1743511748474,"mc":[{"id":"1.241629436","rc":[{"atl":[[1000,23.16]],"id":270592}]}]}
{"op":"mcm","id":2,"clk":"AI82AOkhALsv","pt":1743511748579,"mc":[{"id":"1.241629436","rc":[{"atb":[[5,250.97]],"atl":[[1000,25.16]],"batb":[],"id":270592}]}]}
{"op":"mcm","id":2,"clk":"AJ02APAhAMcv","pt":1743511748681,"mc":[{"id":"1.241629436","rc":[{"atl":[[1000,23.16]],"id":270592}]}]}
{"op":"mcm","id":2,"clk":"AKg2APYhAM8v","pt":1743511748792,"mc":[{"id":"1.241629436","rc":[{"atl":[[1000,21.16]],"id":270592}]}]}
{"op":"mcm","id":2,"clk":"AK02APkhANUv","pt":1743511748886,"mc":[{"id":"1.241629436","rc":[{"atb":[[6.4,152.63]],"trd":[[6.4,3018.17]],"batb":[[0,6.4,152.63]],"ltp":6.4,"tv":11608.07,"id":26496185}],"tv":70055.75}]}
{"op":"mcm","id":2,"clk":"AL02AP8hAOcv","pt":1743511749087,"mc":[{"id":"1.241629436","rc":[{"atb":[[5.3,201.28]],"trd":[[5.3,800.65]],"batb":[[0,5.3,201.28]],"tv":15746.97,"id":270592},{"atb":[[4.9,78.32]],"batb":[[2,4.9,78.32]],"id":56297029}],"tv":70095.61}]}
{"op":"mcm","id":2,"clk":"ANg2AI8iAIsw","pt":1743511749398,"mc":[{"id":"1.241629436","rc":[{"atl":[[5.4,151.22]],"trd":[[5.4,178.91]],"batl":[[0,5.4,151.22]],"ltp":5.4,"tv":15756.97,"id":270592},{"atb":[[5.1,198.9]],"trd":[[5.1,2930.23]],"batb":[[0,5.1,198.9]],"ltp":5.1,"tv":11821.55,"id":56297029}],"tv":70109.61}]}
{"op":"mcm","id":2,"clk":"AOM2AJIiAJAw","pt":1743511749498,"mc":[{"id":"1.241629436","rc":[{"atb":[[5.3,195.88]],"trd":[[5.3,811.45]],"batb":[[0,5.3,195.88]],"ltp":5.3,"tv":15767.77,"id":270592}],"tv":70120.41}]}
{"op":"mcm","id":2,"clk":"APc2AJoiAJ8w","pt":1743511749708,"mc":[{"id":"1.241629436","rc":[{"atb":[[5.3,193.88],[5,256.37]],"trd":[[5.3,815.45]],"batb":[[0,5.3,193.88]],"tv":15771.77,"id":270592}],"tv":70124.41}]}
{"op":"mcm","id":2,"clk":"AJA3AKwiALUw","pt":1743511749966,"mc":[{"id":"1.241629436","rc":[{"atl":[[1000,0.57]],"id":40389088},{"atl":[[1000,21.68]],"id":270592},{"atl":[[1000,0.64]],"id":35856222}]}]}
{"op":"mcm","id":2,"clk":"AJY3ALEiAL8w","pt":1743511750065,"mc":[{"id":"1.241629436","rc":[{"atl":[[1000,0.25]],"id":40389088},{"atl":[[1000,21.16]],"id":270592},{"atl":[[1000,0.41]],"id":35856222}]}]}
{"op":"mcm","id":2,"clk":"AJw3ALkiAMcw","pt":1743511750169,"mc":[{"id":"1.241629436","rc":[{"atl":[[12,21.81]],"batl":[[0,12,21.81]],"id":40389088},{"atl":[[5.4,151.74]],"batl":[[0,5.4,151.74]],"id":270592},{"atl":[[9.4,19.5]],"batl":[[0,9.4,19.5]],"id":35856222}]}]}
{"op":"mcm","id":2,"clk":"AKM3AMEiAM8w","pt":1743511750281,"mc":[{"id":"1.241629436","rc":[{"atb":[[65,15.71]],"trd":[[65,88.44]],"batb":[[0,65,15.71]],"tv":1598.42,"id":59626646}],"tv":70126.41}]}
{"op":"mcm","id":2,"clk":"AKo3AMoiANYw","pt":1743511750386,"mc":[{"id":"1.241629436","rc":[{"atb":[[65,14.95]],"batb":[[0,65,14.95]],"id":59626646}]}]}
{"op":"mcm","id":2,"clk":"AL43ANwiAOgw","pt":1743511750683,"mc":[{"id":"1.241629436","rc":[{"atl":[[20,4]],"batl":[],"id":58186642},{"atb":[[6.4,150.64]],"trd":[[6.4,3022.17]],"batb":[[0,6.4,150.64]],"tv":11612.07,"id":26496185}],"tv":70130.41}]}
{"op":"mcm","id":2,"clk":"AMQ3AOEiAO8w","pt":1743511750786,"mc":[{"id":"1.241629436","rc":[{"atl":[[6,48.73]],"batl":[],"id":270592}]}]}
{"op":"mcm","id":2,"clk":"ANA3AOQiAPcw","pt":1743511750890,"mc":[{"id":"1.241629436","rc":[{"atb":[[11.5,26.19]],"trd":[[11.5,995.05]],"batb":[[0,11.5,26.19]],"tv":6037.71,"id":40389088}],"tv":70143.93}]}
{"op":"mcm","id":2,"clk":"ANo3AOYiAP4w","pt":1743511750999,"mc":[{"id":"1.241629436","rc":[{"atb":[[4.9,80.32]],"batb":[[2,4.9,80.32]],"id":56297029}]}]}
{"op":"mcm","id":2,"clk":"AOI3AOoiAIYx","pt":1743511751099,"mc":[{"id":"1.241629436","rc":[{"atb":[[11.5,21.01]],"trd":[[11.5,1005.41]],"batb":[[0,11.5,21.01]],"tv":6048.07,"id":40389088}],"tv":70154.29}]}
{"op":"mcm","id":2,"clk":"APE3APQiAJgx","pt":1743511751301,"mc":[{"id":"1.241629436","rc":[{"atb":[[11.5,16.11]],"batb":[[0,11.5,16.11]],"id":40389088}]}]}
{"op":"mcm","id":2,"clk":"AP43APoiAKAx","pt":1743511751403,"mc":[{"id":"1.241629436","rc":[{"atl":[[12,22.23]],"batl":[[0,12,22.23]],"id":40389088}]}]}
{"op":"mcm","id":2,"clk":"AIk4AIQjALIx","pt":1743511751604,"mc":[{"id":"1.241629436","rc":[{"atb":[[10,63.42]],"trd":[[10,289.52]],"batb":[[0,10,63.42]],"tv":6039.13,"id":27115873}],"tv":70175.69}]}
{"op":"mcm","id":2,"clk":"AJI4AIYjALcx","pt":1743511751706,"mc":[{"id":"1.241629436","rc":[{"atb":[[9.8,55.59],[9.6,44.7]],"batb":[[2,9.6,44.7],[1,9.8,55.59]],"id":27115873}]}]}
{"op":"mcm","id":2,"clk":"AJo4AIojAMAx","pt":1743511751759,"mc":[{"id":"1.241629436","rc":[{"atb":[[9.8,49.96]],"batb":[[1,9.8,49.96]],"id":27115873}]}]}
{"op":"mcm","id":2,"clk":"AK84AJcjANIx","pt":1743511752087,"mc":[{"id":"1.241629436","rc":[{"atb":[[11.5,15.15]],"trd":[[11.5,1007.33]],"batb":[[0,11.5,15.15]],"tv":6049.99,"id":40389088},{"atb":[[5.3,121.25]],"atl":[[5.4,226.74],[5.6,42.81]],"batb":[[0,5.3,121.25]],"batl":[[2,5.6,42.81],[0,5.4,226.74]],"id":270592}],"con":true,"tv":70177.61}]}
{"op":"mcm","id":2,"clk":"ALg4AKAjANgx","pt":1743511752176,"mc":[{"id":"1.241629436","rc":[{"atb":[[9.8,55.59]],"batb":[[1,9.8,55.59]],"id":27115873}]}]}
{"op":"mcm","id":2,"clk":"AMY4AKcjAN8x","pt":1743511752274,"mc":[{"id":"1.241629436","rc":[{"atb":[[11.5,26.77]],"batb":[[0,11.5,26.77]],"id":40389088},{"atb":[[5.2,324.55]],"batb":[[1,5.2,324.55]],"id":270592}]}]}
{"op":"mcm","id":2,"clk":"AM44AKwjAOUx","pt":1743511752382,"mc":[{"id":"1.241629436","rc":[{"atb":[[11.5,25.81]],"trd":[[11.5,1009.26]],"batb":[[0,11.5,25.81]],"tv":6051.92,"id":40389088},{"atb":[[9.8,49.96]],"batb":[[1,9.8,49.96]],"id":27115873}],"tv":70179.54}]}
{"op":"mcm","id":2,"clk":"AOI4ALEjAPYx","pt":1743511752589,"mc":[{"id":"1.241629436","rc":[{"atb":[[5.3,108.23]],"atl":[[5.4,223.69]],"trd":[[5.4,185.02],[5.3,841.49]],"batb":[[0,5.3,108.23]],"batl":[[0,5.4,223.69]],"tv":15803.92,"id":270592}],"tv":70211.69}]}
{"op":"mcm","id":2,"clk":"AOc4ALUjAPsx","pt":1743511752681,"mc":[{"id":"1.241629436","rc":[{"atb":[[5.3,106.23]],"trd":[[5.3,845.49]],"batb":[[0,5.3,106.23]],"tv":15807.92,"id":270592}],"tv":70215.69}]}
{"op":"mcm","id":2,"clk":"AOs4ALwjAIQy","pt":1743511752782,"mc":[{"id":"1.241629436","rc":[{"atl":[[12,21.91]],"batl":[[0,12,21.91]],"id":40389088},{"atb":[[5.2,324.12]],"atl":[[5.4,223.17]],"batb":[[1,5.2,324.12]],"batl":[[0,5.4,223.17]],"id":270592},{"atl":[[17.5,43.42],[17,13.45]],"batl":[[1,17.5,43.42],[0,17,13.45]],"id":58186642},{"atb":[[10.5,79.1]],"batb":[[0,10.5,79.1]],"id":44049799}]}]}
{"op":"mcm","id":2,"clk":"APU4AL4jAIky","pt":1743511752887,"mc":[{"id":"1.241629436","rc":[{"atb":[[1.17,1.21]],"id":270592},{"atl":[[9.4,19.27]],"batl":[[0,9.4,19.27]],"id":35856222},{"atb":[[16,19.77],[16.5,44.69]],"batb":[[1,16,19.77],[0,16.5,44.69]],"id":58186642}]}]}
{"op":"mcm","id":2,"clk":"APw4AMEjAJEy","pt":1743511752987,"mc":[{"id":"1.241629436","rc":[{"atb":[[1.17,1],[5.3,104.23]],"atl":[[5.6,44.79]],"trd":[[5.3,849.49]],"batb":[[0,5.3,104.23]],"batl":[[2,5.6,44.79]],"tv":15811.92,"id":270592},{"atb":[[4.7,35.44]],"batb":[],"id":56297029}],"tv":70219.69}]}
{"op":"mcm","id":2,"clk":"AIQ5AMcjAJUy","pt":1743511753087,"mc":[{"id":"1.241629436","rc":[{"atb":[[5.3,104.44]],"batb":[[0,5.3,104.44]],"id":270592},{"atb":[[9.8,55.58]],"batb":[[1,9.8,55.58]],"id":27115873}]}]}
{"op":"mcm","id":2,"clk":"AIs5AMojAJsy","pt":1743511753196,"mc":[{"id":"1.241629436","rc":[{"atb":[[5.3,93.71]],"batb":[[0,5.3,93.71]],"id":270592},{"atl":[[28,2]],"id":35856222}]}]}
{"op":"mcm","id":2,"clk":"AJU5ANIjAKQy","pt":1743511753294,"mc":[{"id":"1.241629436","rc":[{"atb":[[5.3,91.29]],"trd":[[5.3,854.33]],"batb":[[0,5.3,91.29]],"tv":15816.76,"id":270592}],"tv":70224.53}]}
{"op":"mcm","id":2,"clk":"AKQ5ANsjALAy","pt":1743511753500,"mc":[{"id":"1.241629436","rc":[{"atb":[[6.4,135]],"trd":[[6.4,3053.45]],"batb":[[0,6.4,135]],"tv":11643.35,"id":26496185}],"tv":70255.81}]}
{"op":"mcm","id":2,"clk":"AMA5AO8jAM0y","pt":1743511753869,"mc":[{"id":"1.241629436","rc":[{"atl":[[1000,23.16]],"id":270592}]}]}
{"op":"mcm","id":2,"clk":"AMk5APYjANYy","pt":1743511753972,"mc":[{"id":"1.241629436","rc":[{"atl":[[1000,25.16]],"id":270592}]}]}
{"op":"mcm","id":2,"clk":"ANE5APsjAN4y","pt":1743511754072,"mc":[{"id":"1.241629436","rc":[{"atl":[[1000,23.16]],"id":270592},{"atb":[[10.5,78.11]],"trd":[[10.5,438.99]],"batb":[[0,10.5,78.11]],"tv":3962.56,"id":44049799}],"tv":70257.79}]}
{"op":"mcm","id":2,"clk":"ANc5AIAkAOUy","pt":1743511754176,"mc":[{"id":"1.241629436","rc":[{"atl":[[1000,21.16]],"id":270592}]}]}
{"op":"mcm","id":2,"clk":"AP45AJQkAP8y","pt":1743511754594,"mc":[{"id":"1.241629436","rc":[{"atb":[[5.3,87.17]],"trd":[[5.3,862.57]],"batb":[[0,5.3,87.17]],"tv":15825,"id":270592}],"tv":70266.03}]}
{"op":"mcm","id":2,"clk":"AJ86AKckAKcz","pt":1743511755096,"mc":[{"id":"1.241629436","rc":[{"atl":[[5.8,134.28]],"batl":[],"id":270592}]}]}
{"op":"mcm","id":2,"clk":"AM06ANEkANsz","pt":1743511755606,"mc":[{"id":"1.241629436","rc":[{"atl":[[5.7,56.64]],"batl":[],"id":270592}]}]}
{"op":"mcm","id":2,"clk":"ANM6ANMkAOQz","pt":1743511755710,"mc":[{"id":"1.241629436","rc":[{"atb":[[5.3,81.67]],"trd":[[5.3,873.57]],"batb":[[0,5.3,81.67]],"tv":15836,"id":270592},{"atb":[[6.4,131]],"trd":[[6.4,3061.45]],"batb":[[0,6.4,131]],"tv":11651.35,"id":26496185},{"atb":[[10.5,76.11]],"trd":[[10.5,442.99]],"batb":[[0,10.5,76.11]],"tv":3966.56,"id":44049799}],"tv":70289.03}]}
{"op":"mcm","id":2,"clk":"ANk6ANgkAOoz","pt":1743511755811,"mc":[{"id":"1.241629436","rc":[{"atb":[[5.3,83.67]],"batb":[[0,5.3,83.67]],"id":270592},{"atb":[[5.1,201.64]],"batb":[[0,5.1,201.64]],"id":56297029}]}]}
{"op":"mcm","id":2,"clk":"AOE6AN0kAPAz","pt":1743511755912,"mc":[{"id":"1.241629436","rc":[{"atb":[[5,271.86]],"batb":[],"id":270592},{"atb":[[1.17,7.33]],"id":35856222},{"atb":[[5.1,199.64]],"atl":[[1000,5.09]],"trd":[[5.1,2934.23]],"batb":[[0,5.1,199.64]],"tv":11825.55,"id":56297029}],"tv":70293.03}]}
{"op":"mcm","id":2,"clk":"AO46AOAkAP8z","pt":1743511756073,"mc":[{"id":"1.241629436","rc":[{"atl":[[5.6,42.81]],"batl":[[2,5.6,42.81]],"id":270592},{"atb":[[1.17,7.15]],"id":35856222},{"atl":[[1000,4.52]],"id":56297029}]}]}
{"op":"mcm","id":2,"clk":"AII7AOQkAIg0","pt":1743511756179,"mc":[{"id":"1.241629436","rc":[{"atb":[[11,101.15]],"batb":[[1,11,101.15]],"id":40389088},{"atb":[[9,100.29]],"batb":[[0,9,100.29]],"id":35856222},{"atl":[[5.3,122.54]],"batl":[[1,5.3,122.54]],"id":56297029}]}]}
{"op":"mcm","id":2,"clk":"AKQ7AIUlAKQ0","pt":1743511756291,"mc":[{"id":"1.241629436","rc":[{"atb":[[11.5,30.15],[11,105.69]],"atl":[[12.5,49.23],[12,26.07]],"batb":[[1,11,105.69],[0,11.5,30.15]],"batl":[[1,12.5,49.23],[0,12,26.07]],"id":40389088},{"atb":[[5.2,343.24]],"atl":[[5.4,241.58],[5.6,44.79]],"batb":[[1,5.2,343.24]],"batl":[[2,5.6,44.79],[0,5.4,241.58]],"id":270592},{"atb":[[9,107.67]],"atl":[[9.6,49.94]],"batb":[[0,9,107.67]],"batl":[[1,9.6,49.94]],"id":35856222},{"atb":[[60,19.46]],"atl":[[75,13.03]],"batb":[[1,60,19.46]],"batl":[[1,75,13.03]],"id":59626646},{"atb":[[5.1,211.35]],"atl":[[5.3,133.81]],"batb":[[0,5.1,211.35]],"batl":[[1,5.3,133.81]],"id":56297029},{"atb":[[9.8,65.82],[9.6,55.15]],"atl":[[11,73.41],[10.5,109.44]],"batb":[[2,9.6,55.15],[1,9.8,65.82]],"batl":[[1,11,73.41],[0,10.5,109.44]],"id":27115873},{"atb":[[16.5,47.41]],"atl":[[17.5,45.99]],"batb":[[0,16.5,47.41]],"batl":[[1,17.5,45.99]],"id":58186642},{"atb":[[6.4,142.88]],"atl":[[6.8,121.18]],"batb":[[0,6.4,142.88]],"batl":[[1,6.8,121.18]],"id":26496185},{"atb":[[9.8,38.69],[10,65.21]],"atl":[[11.5,65.88],[11,110.49]],"batb":[[2,9.8,38.69],[1,10,65.21]],"batl":[[1,11.5,65.88],[0,11,110.49]],"id":44049799}]}]}
{"op":"mcm","id":2,"clk":"AKc7AIklAKg0","pt":1743511756380,"mc":[{"id":"1.241629436","rc":[{"atb":[[5.1,338.54]],"atl":[[5.5,113.94]],"batb":[[2,5.1,338.54]],"batl":[[1,5.5,113.94]],"id":270592},{"atb":[[8.8,39.35]],"atl":[[9.8,40.03]],"batb":[[1,8.8,39.35]],"batl":[[2,9.8,40.03]],"id":35856222},{"atb":[[55,15.4]],"atl":[[80,6.89]],"batb":[[2,55,15.4]],"batl":[[2,80,6.89]],"id":59626646},{"atb":[[5,1177.31]],"atl":[[5.4,100.77]],"batb":[[1,5,1177.31]],"batl":[[2,5.4,100.77]],"id":56297029},{"atb":[[16,22.58]],"atl":[[18,19.57]],"batb":[[1,16,22.58]],"batl":[[2,18,19.57]],"id":58186642},{"atb":[[6.2,135.73]],"atl":[[7,44.06]],"batb":[[1,6.2,135.73]],"batl":[[2,7,44.06]],"id":26496185}]}]}
{"op":"mcm","id":2,"clk":"ALI7AI4lAK00","pt":1743511756482,"mc":[{"id":"1.241629436","rc":[{"atb":[[5.2,338.8],[4.3,19.3]],"batb":[[1,5.2,338.8]],"id":270592}]}]}
{"op":"mcm","id":2,"clk":"AMw7AKElAMU0","pt":1743511756896,"mc":[{"id":"1.241629436","rc":[{"atb":[[5.3,90.06]],"batb":[[0,5.3,90.06]],"id":270592},{"atb":[[10,66.81]],"batb":[[0,10,66.81]],"id":27115873}]}]}
{"op":"mcm","id":2,"clk":"ANs7AKslANY0","pt":1743511757103,"mc":[{"id":"1.241629436","rc":[{"atb":[[10.5,43.12]],"atl":[[13,19.92]],"batb":[[2,10.5,43.12]],"batl":[[2,13,19.92]],"id":40389088},{"atb":[[5,291.72]],"atl":[[5.6,62.53]],"batb":[],"batl":[[2,5.6,62.53]],"id":270592},{"atb":[[8.6,58.51]],"atl":[[10,100.27]],"batb":[[2,8.6,58.51]],"batl":[],"id":35856222},{"atb":[[50,16.31]],"atl":[[85,2.25]],"batb":[],"batl":[],"id":59626646},{"atb":[[4.9,92.51]],"atl":[[5.5,61.52]],"batb":[[2,4.9,92.51]],"batl":[],"id":56297029},{"atb":[[9.4,53.1]],"atl":[[11.5,46.96]],"batb":[],"batl":[[2,11.5,46.96]],"id":27115873},{"atb":[[15.5,46.43]],"atl":[[18.5,14.89]],"batb":[[2,15.5,46.43]],"batl":[],"id":58186642},{"atb":[[6,172.84]],"atl":[[7.2,57.05]],"batb":[[2,6,172.84]],"batl":[],"id":26496185},{"atb":[[9.6,39.74]],"atl":[[12,35.55]],"batb":[],"batl":[[2,12,35.55]],"id":44049799}]}]}
{"op":"mcm","id":2,"clk":"AOM7AK8lAN40","pt":1743511757204,"mc":[{"id":"1.241629436","rc":[{"atl":[[5.5,63.52]],"batl":[],"id":56297029}]}]}
{"op":"mcm","id":2,"clk":"APA7ALQlAOo0","pt":1743511757407,"mc":[{"id":"1.241629436","rc":[{"atb":[[5.3,102.45]],"batb":[[0,5.3,102.45]],"id":270592},{"atb":[[10,79.81]],"batb":[[0,10,79.81]],"id":27115873}]}]}
{"op":"mcm","id":2,"clk":"APU7ALglAPA0","pt":1743511757509,"mc":[{"id":"1.241629436","rc":[{"atb":[[5.3,113.16]],"batb":[[0,5.3,113.16]],"id":270592}]}]}
{"op":"mcm","id":2,"clk":"APk7ALolAPg0","pt":1743511757610,"mc":[{"id":"1.241629436","rc":[{"atb":[[10,50.98]],"atl":[[13.5,16.85]],"batb":[],"batl":[],"id":40389088},{"atb":[[4.9,198.42]],"atl":[[5.7,74.38]],"batb":[],"batl":[],"id":270592},{"atb":[[8.4,84.34]],"atl":[[10.5,51.34]],"batb":[],"batl":[],"id":35856222},{"atb":[[48,4.68]],"atl":[[95,10.15]],"batb":[],"batl":[],"id":59626646},{"atb":[[4.8,98.37]],"atl":[[5.6,54.3]],"batb":[],"batl":[],"id":56297029},{"atb":[[9.2,27.77],[9.6,58.4]],"atl":[[12,48.14]],"batb":[[2,9.6,58.4]],"batl":[],"id":27115873},{"atb":[[15,12.46]],"atl":[[19,21.49]],"batb":[],"batl":[],"id":58186642},{"atb":[[5.9,52.79]],"atl":[[7.4,52.9]],"batb":[],"batl":[],"id":26496185},{"atb":[[9.4,30.05]],"atl":[[12.5,47.08]],"batb":[],"batl":[],"id":44049799}]}]}
{"op":"mcm","id":2,"clk":"AIA8AL0lAIE1","pt":1743511757712,"mc":[{"id":"1.241629436","rc":[{"atl":[[5.4,365.1]],"batl":[[0,5.4,365.1]],"id":270592},{"atl":[[75,4.14]],"batl":[[1,75,4.14]],"id":59626646},{"atl":[[17.5,7.88]],"batl":[[1,17.5,7.88]],"id":58186642}]}]}
{"op":"mcm","id":2,"clk":"AIY8AMIlAIc1","pt":1743511757774,"mc":[{"id":"1.241629436","rc":[{"atl":[[6.6,65.08]],"batl":[[0,6.6,65.08]],"id":26496185}]}]}
{"op":"mcm","id":2,"clk":"AJU8AMklAJI1","pt":1743511757975,"mc":[{"id":"1.241629436","rc":[{"atl":[[28,2.01]],"id":35856222}]}]}
{"op":"mcm","id":2,"clk":"AJs8AMwlAJo1","pt":1743511758073,"mc":[{"id":"1.241629436","rc":[{"atb":[[4.8,145.47]],"atl":[[5.8,151.7]],"batb":[],"batl":[],"id":270592},{"atb":[[8.2,33.1]],"atl":[[11,28.45]],"batb":[],"batl":[],"id":35856222}]}]}
{"op":"mcm","id":2,"clk":"AKI8ANElAKA1","pt":1743511758176,"mc":[{"id":"1.241629436","rc":[{"atb":[[9.8,29.42]],"atl":[[14,15.88]],"batb":[],"batl":[],"id":40389088},{"atb":[[46,9.44]],"batb":[],"id":59626646},{"atb":[[4.7,48.43]],"atl":[[5.7,85.92]],"batb":[],"batl":[],"id":56297029},{"atb":[[9,28.22]],"atl":[[12.5,281.94]],"batb":[],"batl":[],"id":27115873},{"atb":[[14.5,36.58]],"atl":[[19.5,7.85]],"batb":[],"batl":[],"id":58186642},{"atb":[[5.8,105.34]],"atl":[[7.6,12.23]],"batb":[],"batl":[],"id":26496185},{"atb":[[9.2,24.56]],"atl":[[13,31.96]],"batb":[],"batl":[],"id":44049799}]}]}
{"op":"mcm","id":2,"clk":"AKw8ANglAKs1","pt":1743511758382,"mc":[{"id":"1.241629436","rc":[{"atb":[[5.3,108.16]],"trd":[[5.3,883.57]],"batb":[[0,5.3,108.16]],"tv":15846,"id":270592}],"tv":70303.03}]}
{"op":"mcm","id":2,"clk":"ALs8AOIlALg1","pt":1743511758591,"mc":[{"id":"1.241629436","rc":[{"atb":[[5.3,97.45]],"batb":[[0,5.3,97.45]],"id":270592},{"atb":[[9.6,55.15]],"batb":[[2,9.6,55.15]],"id":27115873},{"atl":[[17,7.37]],"batl":[[0,17,7.37]],"id":58186642}]}]}
{"op":"mcm","id":2,"clk":"AMU8AOYlAME1","pt":1743511758687,"mc":[{"id":"1.241629436","rc":[{"atl":[[1000,2.25]],"id":40389088},{"atl":[[17,4.51]],"batl":[[0,17,4.51]],"id":58186642}]}]}
{"op":"mcm","id":2,"clk":"AMk8AOklAMg1","pt":1743511758790,"mc":[{"id":"1.241629436","rc":[{"atb":[[9.6,32.79]],"atl":[[14.5,26.16]],"batb":[],"batl":[],"id":40389088},{"atb":[[4.7,139.89],[5.3,0]],"atl":[[5.9,99.11],[5.3,61.7]],"trd":[[5.3,1078.47]],"batb":[[2,5,291.72],[1,5.1,338.54],[0,5.2,338.8]],"batl":[[2,5.5,113.94],[1,5.4,365.1],[0,5.3,61.7]],"tv":16040.9,"id":270592},{"atb":[[8,51.68]],"atl":[[11.5,60.34]],"batb":[],"batl":[],"id":35856222},{"atb":[[44,5.28]],"batb":[],"id":59626646},{"atb":[[4.6,106.01]],"atl":[[5.8,51.98]],"batb":[],"batl":[],"id":56297029},{"atb":[[8.8,17.59]],"atl":[[13,13.3]],"batb":[],"batl":[],"id":27115873},{"atb":[[14,5.4],[17,10.92],[16.5,50.79]],"atl":[[20,6.38],[17,0]],"trd":[[17,490.74]],"batb":[[2,16,22.58],[1,16.5,50.79],[0,17,10.92]],"batl":[[2,18.5,14.89],[1,18,19.57],[0,17.5,7.88]],"tv":4763.1,"id":58186642},{"atb":[[5.7,77.85]],"atl":[[7.8,11.18]],"batb":[],"batl":[],"id":26496185},{"atb":[[9,14.62]],"atl":[[13.5,10.75]],"batb":[],"batl":[],"id":44049799}],"tv":70506.95}]}
{"op":"mcm","id":2,"clk":"ANE8AO8lAM01","pt":1743511758897,"mc":[{"id":"1.241629436","rc":[{"atb":[[11.5,34.06]],"atl":[[1000,1.01]],"trd":[[11.5,1011.23]],"batb":[[0,11.5,34.06]],"tv":6053.89,"id":40389088},{"atb":[[5,290.74]],"atl":[[5.7,73.58],[5.3,72.55]],"batb":[[2,5,290.74]],"batl":[[0,5.3,72.55]],"id":270592},{"atb":[[17,22.56],[16.5,49.93]],"atl":[[17.5,5.54]],"batb":[[1,16.5,49.93],[0,17,22.56]],"batl":[[0,17.5,5.54]],"id":58186642},{"atl":[[7,40.06]],"batl":[[2,7,40.06]],"id":26496185}],"tv":70508.92}]}
{"op":"mcm","id":2,"clk":"ANY8APQlANI1","pt":1743511758997,"mc":[{"id":"1.241629436","rc":[{"atl":[[5.6,60.55]],"batl":[],"id":270592},{"atb":[[9.8,60.2]],"batb":[[1,9.8,60.2]],"id":27115873},{"atb":[[17,25.02],[16,21.58]],"atl":[[17.5,3.29]],"trd":[[17,492.46]],"batb":[[2,16,21.58],[0,17,25.02]],"batl":[[0,17.5,3.29]],"tv":4764.82,"id":58186642},{"atb":[[10.5,73.96]],"batb":[[0,10.5,73.96]],"id":44049799}],"tv":70510.64}]}
{"op":"mcm","id":2,"clk":"AN08APglANc1","pt":1743511759099,"mc":[{"id":"1.241629436","rc":[{"atl":[[1000,0.25]],"id":40389088},{"atb":[[4.9,199.42]],"atl":[[5.6,61.36]],"batb":[],"batl":[],"id":270592},{"atb":[[5.1,198]],"trd":[[5.1,2960.93]],"batb":[[0,5.1,198]],"tv":11852.25,"id":56297029},{"atb":[[14.5,32.94],[17,27.83]],"atl":[[17.5,0.72]],"batb":[[0,17,27.83]],"batl":[[2,19,21.49],[1,18.5,14.89],[0,18,20.29]],"id":58186642}],"tv":70537.34}]}
{"op":"mcm","id":2,"clk":"AOE8APwlANw1","pt":1743511759201,"mc":[{"id":"1.241629436","rc":[{"atb":[[11.5,33.3]],"trd":[[11.5,1012.75]],"batb":[[0,11.5,33.3]],"tv":6055.41,"id":40389088},{"atb":[[5.2,304.76]],"batb":[[0,5.2,304.76]],"id":270592},{"atb":[[9.8,65.82]],"batb":[[1,9.8,65.82]],"id":27115873},{"atb":[[17,29.69]],"atl":[[17.5,0]],"batb":[[0,17,29.69]],"batl":[[0,18,19.57]],"id":58186642}],"tv":70538.86}]}
{"op":"mcm","id":2,"clk":"AOY8AIAmAOQ1","pt":1743511759306,"mc":[{"id":"1.241629436","rc":[{"atb":[[9.4,8.65]],"atl":[[15,28.14]],"batb":[],"batl":[],"id":40389088},{"atb":[[4.6,88.2],[4.8,151.07]],"atl":[[1000,23.16],[6,66.24]],"batb":[],"batl":[],"id":270592},{"atb":[[7.8,29.39]],"atl":[[12,43.02]],"batb":[],"batl":[],"id":35856222},{"atb":[[4.5,82.54]],"atl":[[5.9,24.88],[5.2,182.75]],"batb":[],"batl":[[0,5.2,182.75]],"id":56297029},{"atb":[[8.6,19.96]],"atl":[[13.5,30.71]],"batb":[],"batl":[],"id":27115873},{"atb":[[13.5,29.94],[17,37.49]],"atl":[[21,13.28]],"batb":[[0,17,37.49]],"batl":[],"id":58186642},{"atb":[[5.6,106.37]],"atl":[[8,31.17]],"batb":[],"batl":[],"id":26496185},{"atb":[[8.8,40.05]],"atl":[[14,14.17]],"batb":[],"batl":[],"id":44049799}]}]}
{"op":"mcm","id":2,"clk":"AOs8AIImAO01","pt":1743511759411,"mc":[{"id":"1.241629436","rc":[{"atl":[[1000,25.16]],"id":270592},{"atb":[[42,9.73]],"batb":[],"id":59626646},{"atb":[[17,35.63]],"batb":[[0,17,35.63]],"id":58186642}]}]}
{"op":"mcm","id":2,"clk":"APE8AIcmAPQ1","pt":1743511759517,"mc":[{"id":"1.241629436","rc":[{"atl":[[1000,23.16]],"id":270592},{"atb":[[9.8,60.2]],"batb":[[1,9.8,60.2]],"id":27115873}]}]}
{"op":"mcm","id":2,"clk":"APo8AIwmAPs1","pt":1743511759618,"mc":[{"id":"1.241629436","rc":[{"atl":[[1000,21.16]],"id":270592},{"atb":[[17.5,1.79]],"batb":[[2,16.5,49.93],[1,17,35.63],[0,17.5,1.79]],"id":58186642},{"atl":[[6.6,58.08]],"trd":[[6.6,1682.4]],"batl":[[0,6.6,58.08]],"ltp":6.6,"tv":11665.34,"id":26496185}],"tv":70552.85}]}
{"op":"mcm","id":2,"clk":"AP48AI4mAIA2","pt":1743511759716,"mc":[{"id":"1.241629436","rc":[{"atb":[[17,32.31]],"batb":[[1,17,32.31]],"id":58186642},{"atl":[[6.6,66.91]],"batl":[[0,6.6,66.91]],"id":26496185}]}]}
{"op":"mcm","id":2,"clk":"AIk9AJImAIo2","pt":1743511759823,"mc":[{"id":"1.241629436","rc":[{"atb":[[9.2,35.65]],"atl":[[15.5,38.94]],"batb":[],"batl":[],"id":40389088},{"atl":[[6.2,116.57]],"batl":[],"id":270592},{"atb":[[7.6,45.03]],"atl":[[12.5,24.33]],"batb":[],"batl":[],"id":35856222},{"atb":[[40,23.13]],"batb":[],"id":59626646},{"atb":[[4.4,53.18]],"atl":[[6,12.39]],"batb":[],"batl":[],"id":56297029},{"atb":[[8.4,45.45]],"atl":[[14,24.51]],"batb":[],"batl":[],"id":27115873},{"atb":[[17,32.6]],"atl":[[22,6.7]],"batb":[[1,17,32.6]],"batl":[],"id":58186642},{"atb":[[5.5,137.73]],"atl":[[8.2,73.92]],"batb":[],"batl":[],"id":26496185},{"atb":[[8.6,24.56]],"atl":[[14.5,23.05]],"batb":[],"batl":[],"id":44049799}]}]}
{"op":"mcm","id":2,"clk":"AJE9AJgmAJE2","pt":1743511759879,"mc":[{"id":"1.241629436","rc":[{"atb":[[17.5,1.48]],"trd":[[17.5,98.47]],"batb":[[0,17.5,1.48]],"ltp":17.5,"tv":4765.44,"id":58186642}],"tv":70553.47}]}
{"op":"mcm","id":2,"clk":"AJk9AJsmAJk2","pt":1743511759981,"mc":[{"id":"1.241629436","rc":[{"atb":[[17.5,0]],"trd":[[17.5,101.43]],"batb":[[2,16,21.58],[1,16.5,49.93],[0,17,32.6]],"tv":4768.4,"id":58186642}],"tv":70556.43}]}
{"op":"mcm","id":2,"clk":"AKI9AKAmAKE2","pt":1743511760082,"mc":[{"id":"1.241629436","rc":[{"atb":[[17,35.89]],"batb":[[0,17,35.89]],"id":58186642}]}]}
{"op":"mcm","id":2,"clk":"AKg9AKwmAKc2","pt":1743511760190,"mc":[{"id":"1.241629436","rc":[{"atl":[[17.5,7.67]],"batl":[[2,18.5,14.89],[1,18,19.57],[0,17.5,7.67]],"id":58186642}]}]}
{"op":"mcm","id":2,"clk":"ALU9ALImAK42","pt":1743511760294,"mc":[{"id":"1.241629436","rc":[{"atl":[[5.5,142.66]],"batl":[[2,5.5,142.66]],"id":270592},{"atb":[[6.4,141.88]],"trd":[[6.4,3063.45]],"batb":[[0,6.4,141.88]],"ltp":6.4,"tv":11667.34,"id":26496185}],"tv":70558.43}]}
{"op":"mcm","id":2,"clk":"ALs9ALgmALY2","pt":1743511760394,"mc":[{"id":"1.241629436","rc":[{"atb":[[9,13.49]],"atl":[[12.5,51.23],[16,7.69]],"batb":[],"batl":[[1,12.5,51.23]],"id":40389088},{"atb":[[7.4,19.14]],"atl":[[13,18.01]],"batb":[],"batl":[],"id":35856222},{"atb":[[38,15.17]],"batb":[],"id":59626646},{"atl":[[6.2,15.3]],"batl":[],"id":56297029},{"atb":[[8.2,23.27]],"atl":[[14.5,44.46]],"batb":[],"batl":[],"id":27115873},{"atl":[[23,7.07],[17.5,6.67]],"trd":[[17.5,103.43]],"batl":[[0,17.5,6.67]],"tv":4770.4,"id":58186642},{"atb":[[5.4,33.85]],"atl":[[8.4,10.89]],"batb":[],"batl":[],"id":26496185},{"atb":[[8.4,13.48]],"atl":[[15,25.1]],"batb":[],"batl":[],"id":44049799}],"tv":70560.43}]}
{"op":"mcm","id":2,"clk":"AMI9ALomALo2","pt":1743511760488,"mc":[{"id":"1.241629436","rc":[{"atb":[[5.1,197.9]],"trd":[[5.1,2961.13]],"batb":[[0,5.1,197.9]],"tv":11852.45,"id":56297029},{"atl":[[17.5,0]],"batl":[[2,19,21.49],[1,18.5,14.89],[0,18,19.57]],"id":58186642}],"tv":70560.63}]}
{"op":"mcm","id":2,"clk":"ANw9AMQmAN82","pt":1743511760902,"mc":[{"id":"1.241629436","rc":[{"atl":[[5.5,113.94]],"batl":[[2,5.5,113.94]],"id":270592},{"atb":[[5.1,194.4]],"trd":[[5.1,2968.13]],"batb":[[0,5.1,194.4]],"tv":11859.45,"id":56297029}],"tv":70567.63}]}
{"op":"mcm","id":2,"clk":"AO09AMkmAO82","pt":1743511761119,"mc":[{"id":"1.241629436","rc":[{"atb":[[8.8,21.16]],"atl":[[16.5,5.27]],"batb":[],"batl":[],"id":40389088},{"atb":[[7.2,23.71]],"batb":[],"id":35856222},{"atb":[[36,5.15]],"id":59626646},{"atb":[[8,33.94]],"atl":[[15,18.67]],"batl":[],"id":27115873},{"atl":[[24,6.1]],"batl":[],"id":58186642},{"atb":[[5.3,45.12]],"atl":[[8.6,10.66]],"batb":[],"id":26496185},{"atb":[[8.2,39.62]],"atl":[[15.5,8.67]],"batl":[],"id":44049799}]}]}
{"op":"mcm","id":2,"clk":"AJM+AN4mAI03","pt":1743511761419,"mc":[{"id":"1.241629436","rc":[{"atb":[[9,102.67]],"trd":[[9,446.41]],"batb":[[0,9,102.67]],"ltp":9,"tv":8580.03,"id":35856222}],"tv":70577.64}]}
{"op":"mcm","id":2,"clk":"AJ8+AOcmAJ43","pt":1743511761626,"mc":[{"id":"1.241629436","rc":[{"atl":[[17,4.23]],"id":40389088},{"atb":[[34,10.16]],"id":59626646},{"atb":[[7.8,19.36]],"atl":[[15.5,10.89]],"id":27115873},{"atb":[[2.1,10],[5.2,96.79]],"id":26496185},{"atb":[[8,37.16]],"atl":[[16,9.61]],"id":44049799}]}]}
{"op":"mcm","id":2,"clk":"AK4+AO8mAKs3","pt":1743511761823,"mc":[{"id":"1.241629436","rc":[{"atb":[[17,40.95],[16.5,45.37]],"batb":[[1,16.5,45.37],[0,17,40.95]],"id":58186642}]}]}
{"op":"mcm","id":2,"clk":"AL4+APwmALw3","pt":1743511761988,"mc":[{"id":"1.241629436","rc":[{"atb":[[1.17,1.21]],"id":270592}]}]}
{"op":"mcm","id":2,"clk":"AMU+AIInAMI3","pt":1743511762089,"mc":[{"id":"1.241629436","rc":[{"atl":[[1000,3.41]],"id":58186642}]}]}
{"op":"mcm","id":2,"clk":"AMw+AIYnAMs3","pt":1743511762190,"mc":[{"id":"1.241629436","rc":[{"atl":[[17.5,5.69]],"id":40389088},{"atb":[[1.17,1]],"id":270592},{"atb":[[32,5.56]],"id":59626646},{"atb":[[7.6,20.17]],"atl":[[16,23.71]],"id":27115873},{"atl":[[25,5.95]],"batl":[],"id":58186642},{"atb":[[7.8,18.71]],"atl":[[16.5,7.4]],"id":44049799}]}]}
{"op":"mcm","id":2,"clk":"ANE+AIonANU3","pt":1743511762289,"mc":[{"id":"1.241629436","rc":[{"atl":[[5.3,72.34]],"trd":[[5.3,1078.89]],"batl":[[0,5.3,72.34]],"tv":16041.32,"id":270592},{"atl":[[1000,1.51]],"id":58186642}],"tv":70578.06}]}
{"op":"mcm","id":2,"clk":"AN4+AJMnAOM3","pt":1743511762488,"mc":[{"id":"1.241629436","rc":[{"atl":[[1000,1.41]],"id":58186642}]}]}
{"op":"mcm","id":2,"clk":"AOE+AJQnAOk3","pt":1743511762597,"mc":[{"id":"1.241629436","rc":[{"atl":[[17.5,0.1]],"batl":[[0,18,19.67]],"id":58186642}]}]}
{"op":"mcm","id":2,"clk":"AOo+AJcnAPY3","pt":1743511762696,"mc":[{"id":"1.241629436","rc":[{"atl":[[18,20.57]],"batl":[[0,18,20.67]],"id":58186642}]}]}
{"op":"mcm","id":2,"clk":"APE+AJsnAIA4","pt":1743511762814,"mc":[{"id":"1.241629436","rc":[{"atl":[[18,4.59]],"id":40389088},{"atl":[[5.6,72.96]],"batl":[],"id":270592},{"atb":[[7.4,29.95]],"atl":[[16.5,12.4]],"id":27115873},{"atl":[[17,6.32]],"id":44049799}]}]}
{"op":"mcm","id":2,"clk":"APo+AJ0nAIk4","pt":1743511762908,"mc":[{"id":"1.241629436","rc":[{"atb":[[5.2,154.76]],"trd":[[5.2,1563.29]],"batb":[[0,5.2,154.76]],"ltp":5.2,"tv":16278.77,"id":270592},{"atb":[[5.1,189.4]],"trd":[[5.1,2978.13]],"batb":[[0,5.1,189.4]],"tv":11869.45,"id":56297029}],"tv":70825.51}]}
{"op":"mcm","id":2,"clk":"AIQ/AKEnAJI4","pt":1743511763007,"mc":[{"id":"1.241629436","rc":[{"atl":[[5.3,71.61]],"trd":[[5.3,1102.53]],"batl":[[0,5.3,71.61]],"ltp":5.3,"tv":16302.41,"id":270592}],"tv":70849.15}]}
{"op":"mcm","id":2,"clk":"AI0/AKMnAJQ4","pt":1743511763103,"mc":[{"id":"1.241629436","rc":[{"atb":[[5.2,218.87]],"atl":[[5.3,91.81]],"batb":[[0,5.2,218.87]],"batl":[[0,5.3,91.81]],"id":270592},{"atb":[[9.8,65.81]],"batb":[[1,9.8,65.81]],"id":27115873}]}]}
{"op":"mcm","id":2,"clk":"AKM/AK8nAKo4","pt":1743511763318,"mc":[{"id":"1.241629436","rc":[{"atb":[[5.2,242.87],[4.5,68.76]],"batb":[[0,5.2,242.87]],"id":270592},{"atb":[[7.2,29.19]],"id":27115873}]}]}
{"op":"mcm","id":2,"clk":"AK8/ALUnALA4","pt":1743511763415,"mc":[{"id":"1.241629436","rc":[{"atb":[[5.1,209.4]],"batb":[[0,5.1,209.4]],"id":56297029}]}]}
{"op":"mcm","id":2,"clk":"ALw/AMQnAMY4","pt":1743511763718,"mc":[{"id":"1.241629436","rc":[{"atl":[[1000,3.41]],"id":58186642}]}]}
{"op":"mcm","id":2,"clk":"AM8/ANAnANQ4","pt":1743511763881,"mc":[{"id":"1.241629436","rc":[{"atl":[[1000,1.51]],"id":58186642}]}]}
{"op":"mcm","id":2,"clk":"AOI/ANsnAOA4","pt":1743511764083,"mc":[{"id":"1.241629436","rc":[{"atl":[[1000,1.41]],"id":58186642}]}]}
{"op":"mcm","id":2,"clk":"AOk/AOEnAOg4","pt":1743511764181,"mc":[{"id":"1.241629436","rc":[{"atl":[[18,20.67]],"batl":[[0,18,20.77]],"id":58186642}]}]}
{"op":"mcm","id":2,"clk":"AP4/AOwnAP84","pt":1743511764493,"mc":[{"id":"1.241629436","rc":[{"atl":[[1000,3.41]],"id":58186642}]}]}
{"op":"mcm","id":2,"clk":"AI5AAPUnAI05","pt":1743511764697,"mc":[{"id":"1.241629436","rc":[{"atl":[[1000,23.16]],"id":270592},{"atl":[[13.5,8.37]],"id":35856222},{"atl":[[5.2,202.75]],"batl":[[0,5.2,202.75]],"id":56297029},{"atl":[[1000,1.51]],"id":58186642}]}]}
{"op":"mcm","id":2,"clk":"AJJAAPknAJU5","pt":1743511764800,"mc":[{"id":"1.241629436","rc":[{"atl":[[1000,25.16]],"id":270592},{"atl":[[1000,1.41]],"id":58186642}]}]}
{"op":"mcm","id":2,"clk":"AJdAAP4nAJ05","pt":1743511764904,"mc":[{"id":"1.241629436","rc":[{"atl":[[1000,23.16]],"id":270592},{"atb":[[9,102.49]],"batb":[[0,9,102.49]],"id":35856222},{"atb":[[5.1,206.66]],"atl":[[5.3,133.24]],"batb":[[0,5.1,206.66]],"batl":[[1,5.3,133.24]],"id":56297029},{"atb":[[16,20.39],[16.5,46.18]],"atl":[[18.5,14.99]],"batb":[[2,16,20.39],[1,16.5,46.18]],"batl":[[1,18.5,14.99]],"id":58186642},{"atb":[[10.5,73.57]],"batb":[[0,10.5,73.57]],"id":44049799}]}]}
{"op":"mcm","id":2,"clk":"AKNAAIIoAKY5","pt":1743511765011,"mc":[{"id":"1.241629436","rc":[{"atb":[[11,103.69]],"batb":[[1,11,103.69]],"id":40389088},{"atl":[[1000,21.16]],"id":270592}]}]}
{"op":"mcm","id":2,"clk":"AMFAAKEoAMc5","pt":1743511765417,"mc":[{"id":"1.241629436","rc":[{"atb":[[16.5,28.54]],"atl":[[1000,3.41]],"batb":[[1,16.5,28.54]],"id":58186642}]}]}
{"op":"mcm","id":2,"clk":"AM5AAKgoANA5","pt":1743511765523,"mc":[{"id":"1.241629436","rc":[{"atl":[[28,1]],"id":35856222},{"atb":[[17,58.59]],"atl":[[1000,1.51]],"batb":[[0,17,58.59]],"id":58186642}]}]}
{"op":"mcm","id":2,"clk":"ANVAAKsoANU5","pt":1743511765622,"mc":[{"id":"1.241629436","rc":[{"atl":[[1000,23.16]],"id":270592},{"atb":[[9,102.48]],"trd":[[9,446.43]],"batb":[[0,9,102.48]],"tv":8580.05,"id":35856222}],"tv":70849.17}]}
{"op":"mcm","id":2,"clk":"ANxAALUoAOM5","pt":1743511765721,"mc":[{"id":"1.241629436","rc":[{"atb":[[5,378.74]],"batb":[[2,5,378.74]],"id":270592},{"atb":[[7,35.4]],"id":35856222},{"atl":[[1000,1.41]],"id":58186642}]}]}
{"op":"mcm","id":2,"clk":"AOJAALkoAOQ5","pt":1743511765785,"mc":[{"id":"1.241629436","rc":[{"atl":[[1000,21.16]],"id":270592}]}]}
{"op":"mcm","id":2,"clk":"AOlAAMEoAO85","pt":1743511765885,"mc":[{"id":"1.241629436","rc":[{"atl":[[19,21.59]],"batl":[[2,19,21.59]],"id":58186642}]}]}
{"op":"mcm","id":2,"clk":"AO9AAMcoAPs5","pt":1743511765984,"mc":[{"id":"1.241629436","rc":[{"atl":[[5.3,71.61]],"batl":[[0,5.3,71.61]],"id":270592}]}]}
{"op":"mcm","id":2,"clk":"APZAAM0oAII6","pt":1743511766093,"mc":[{"id":"1.241629436","rc":[{"atl":[[10.5,108.44]],"batl":[[0,10.5,108.44]],"id":27115873},{"atl":[[6.6,76.91]],"batl":[[0,6.6,76.91]],"id":26496185}]}]}
{"op":"mcm","id":2,"clk":"AP5AANUoAIo6","pt":1743511766192,"mc":[{"id":"1.241629436","rc":[{"atl":[[5.7,79.19]],"batl":[],"id":270592}]}]}
{"op":"mcm","id":2,"clk":"AIFBANooAJc6","pt":1743511766287,"mc":[{"id":"1.241629436","rc":[{"atl":[[9.4,18.6]],"trd":[[9.4,290.59]],"batl":[[0,9.4,18.6]],"ltp":9.4,"tv":8581.39,"id":35856222}],"tv":70850.51}]}
{"op":"mcm","id":2,"clk":"AIxBAOcoAKc6","pt":1743511766497,"mc":[{"id":"1.241629436","rc":[{"atb":[[6.4,136.88]],"trd":[[6.4,3073.45]],"batb":[[0,6.4,136.88]],"tv":11677.34,"id":26496185}],"tv":70860.51}]}
{"op":"mcm","id":2,"clk":"AJ1BAPgoALo6","pt":1743511766699,"mc":[{"id":"1.241629436","rc":[{"atl":[[5.5,111.94]],"batl":[[2,5.5,111.94]],"id":270592}]}]}
{"op":"mcm","id":2,"clk":"AKNBAIEpAMU6","pt":1743511766801,"mc":[{"id":"1.241629436","rc":[{"atl":[[5.3,73.61]],"batl":[[0,5.3,73.61]],"id":270592},{"atb":[[9,101.49]],"trd":[[9,448.41]],"batb":[[0,9,101.49]],"ltp":9,"tv":8583.37,"id":35856222}],"tv":70862.49}]}
{"op":"mcm","id":2,"clk":"ALZBAJUpAN86","pt":1743511767109,"mc":[{"id":"1.241629436","rc":[{"atl":[[5.3,170.64]],"trd":[[5.3,1104.47]],"batl":[[0,5.3,170.64]],"tv":16304.35,"id":270592}],"tv":70864.43}]}
{"op":"mcm","id":2,"clk":"AMRBAJ4pAPM6","pt":1743511767319,"mc":[{"id":"1.241629436","rc":[{"atl":[[5.3,191.32]],"batl":[[0,5.3,191.32]],"id":270592}]}]}
{"op":"mcm","id":2,"clk":"AM1BAKMpAPY6","pt":1743511767417,"mc":[{"id":"1.241629436","rc":[{"atl":[[5.2,222.75]],"batl":[[0,5.2,222.75]],"id":56297029}]}]}
{"op":"mcm","id":2,"clk":"ANBBAKYpAPw6","pt":1743511767518,"mc":[{"id":"1.241629436","rc":[{"atl":[[5.4,366.07],[5.5,131.65]],"batl":[[2,5.5,131.65],[1,5.4,366.07]],"id":270592}]}]}
{"op":"mcm","id":2,"clk":"ANlBAKkpAIU7","pt":1743511767621,"mc":[{"id":"1.241629436","rc":[{"atl":[[5.8,157.3]],"batl":[],"id":270592}]}]}
{"op":"mcm","id":2,"clk":"AOFBAK8pAIk7","pt":1743511767722,"mc":[{"id":"1.241629436","rc":[{"atl":[[1000,3.41]],"id":58186642}]}]}
{"op":"mcm","id":2,"clk":"AOtBALUpAI47","pt":1743511767825,"mc":[{"id":"1.241629436","rc":[{"atl":[[1000,1.51]],"id":58186642}]}]}
{"op":"mcm","id":2,"clk":"APFBALopAJU7","pt":1743511767876,"mc":[{"id":"1.241629436","rc":[{"atl":[[1000,0.41]],"id":40389088},{"atb":[[1.17,1.57]],"atl":[[1000,21.28]],"id":270592}]}]}
{"op":"mcm","id":2,"clk":"APlBAL8pAKQ7","pt":1743511767989,"mc":[{"id":"1.241629436","rc":[{"atl":[[1000,0.25]],"id":40389088},{"atb":[[1.17,1]],"atl":[[1000,21.16]],"id":270592},{"atl":[[1000,1.41]],"id":58186642}]}]}
{"op":"mcm","id":2,"clk":"AIFCAMMpAKs7","pt":1743511768085,"mc":[{"id":"1.241629436","rc":[{"atl":[[12,26.23]],"batl":[[0,12,26.23]],"id":40389088},{"atb":[[5.2,243.44]],"atl":[[5.4,291.19]],"batb":[[0,5.2,243.44]],"batl":[[1,5.4,291.19]],"id":270592},{"atl":[[19.5,7.95]],"batl":[],"id":58186642}]}]}
{"op":"mcm","id":2,"clk":"AJRCAMkpALw7","pt":1743511768291,"mc":[{"id":"1.241629436","rc":[{"atb":[[1.01,46368.67]],"id":26496185}]}]}
{"op":"mcm","id":2,"clk":"AKJCAM4pAMA7","pt":1743511768394,"mc":[{"id":"1.241629436","rc":[{"atl":[[1000,3.41]],"id":58186642}]}]}
{"op":"mcm","id":2,"clk":"AKtCANMpAM07","pt":1743511768500,"mc":[{"id":"1.241629436","rc":[{"atl":[[5.4,297.25]],"batl":[[1,5.4,297.25]],"id":270592}]}]}
{"op":"mcm","id":2,"clk":"ALhCANgpANQ7","pt":1743511768605,"mc":[{"id":"1.241629436","rc":[{"atl":[[5.9,80.21]],"batl":[],"id":270592},{"atl":[[1000,1.51]],"id":58186642}]}]}
{"op":"mcm","id":2,"clk":"ALxCAN4pAN07","pt":1743511768705,"mc":[{"id":"1.241629436","rc":[{"atb":[[65,5.66]],"trd":[[65,107.02]],"batb":[[0,65,5.66]],"tv":1617,"id":59626646},{"atb":[[10.5,50.8]],"trd":[[10.5,488.53]],"batb":[[0,10.5,50.8]],"tv":4012.1,"id":44049799}],"tv":70928.55}]}
{"op":"mcm","id":2,"clk":"AMFCAOIpAOI7","pt":1743511768805,"mc":[{"id":"1.241629436","rc":[{"atl":[[70,13.91]],"batl":[[0,70,13.91]],"id":59626646},{"atb":[[16.5,30.86]],"atl":[[1000,3.41]],"batb":[[1,16.5,30.86]],"id":58186642},{"atl":[[6.6,68.08]],"batl":[[0,6.6,68.08]],"id":26496185}]}]}
{"op":"mcm","id":2,"clk":"AMhCAOUpAOk7","pt":1743511768902,"mc":[{"id":"1.241629436","rc":[{"atl":[[17.5,0.2]],"batl":[[0,18,20.87]],"id":58186642},{"atl":[[11,112.88]],"batl":[[0,11,112.88]],"id":44049799}]}]}
{"op":"mcm","id":2,"clk":"AM5CAOopAPE7","pt":1743511769004,"mc":[{"id":"1.241629436","rc":[{"atl":[[1000,1.51]],"id":58186642}]}]}
{"op":"mcm","id":2,"clk":"ANNCAO4pAPg7","pt":1743511769111,"mc":[{"id":"1.241629436","rc":[{"atb":[[11.5,30.31]],"trd":[[11.5,1018.73]],"batb":[[0,11.5,30.31]],"tv":6061.39,"id":40389088},{"atb":[[5.2,236.83]],"trd":[[5.2,1576.51]],"batb":[[0,5.2,236.83]],"ltp":5.2,"tv":16317.57,"id":270592},{"atl":[[90,3.26]],"batl":[],"id":59626646},{"atb":[[5.1,199.92]],"trd":[[5.1,2991.61]],"batb":[[0,5.1,199.92]],"tv":11882.93,"id":56297029},{"atb":[[6.4,131.51]],"trd":[[6.4,3084.19]],"batb":[[0,6.4,131.51]],"tv":11688.08,"id":26496185},{"atb":[[10.5,47.52]],"trd":[[10.5,495.09]],"batb":[[0,10.5,47.52]],"tv":4018.66,"id":44049799}],"tv":70978.53}]}
{"op":"mcm","id":2,"clk":"AN5CAPIpAP87","pt":1743511769215,"mc":[{"id":"1.241629436","rc":[{"atl":[[1000,1.41]],"id":58186642}]}]}
{"op":"mcm","id":2,"clk":"AOhCAPYpAIc8","pt":1743511769318,"mc":[{"id":"1.241629436","rc":[{"atl":[[5.3,192.82]],"batl":[[0,5.3,192.82]],"id":270592},{"atl":[[95,10.45],[90,3.6]],"batl":[],"id":59626646},{"atl":[[18,20.77]],"batl":[[0,18,20.97]],"id":58186642}]}]}
{"op":"mcm","id":2,"clk":"APZCAPwpAJI8","pt":1743511769426,"mc":[{"id":"1.241629436","rc":[{"atl":[[1000,3.41]],"id":58186642}]}]}
{"op":"mcm","id":2,"clk":"APhCAP4pAJs8","pt":1743511769518,"mc":[{"id":"1.241629436","rc":[{"atl":[[1000,1.51]],"id":58186642}]}]}
{"op":"mcm","id":2,"clk":"AIBDAIEqAKY8","pt":1743511769619,"mc":[{"id":"1.241629436","rc":[{"atl":[[100,3.16]],"batl":[],"id":59626646}]}]}
{"op":"mcm","id":2,"clk":"AIhDAIYqAK48","pt":1743511769728,"mc":[{"id":"1.241629436","rc":[{"atl":[[1000,1.41]],"id":58186642}]}]}
{"op":"mcm","id":2,"clk":"AI9DAIwqALY8","pt":1743511769825,"mc":[{"id":"1.241629436","rc":[{"atl":[[18.5,15.09]],"batl":[[1,18.5,15.09]],"id":58186642}]}]}
{"op":"mcm","id":2,"clk":"AJRDAJAqAL08","pt":1743511769887,"mc":[{"id":"1.241629436","rc":[{"atb":[[5.1,219.92]],"batb":[[0,5.1,219.92]],"id":56297029}]}]}
{"op":"mcm","id":2,"clk":"AJtDAJQqAMM8","pt":1743511769989,"mc":[{"id":"1.241629436","rc":[{"atb":[[10.5,59.52]],"batb":[[0,10.5,59.52]],"id":44049799}]}]}
{"op":"mcm","id":2,"clk":"AKBDAJgqAMk8","pt":1743511770087,"mc":[{"id":"1.241629436","rc":[{"atl":[[1000,23.16]],"id":270592},{"atl":[[1000,3.41]],"id":58186642}]}]}
{"op":"mcm","id":2,"clk":"AK1DAJ4qANM8","pt":1743511770287,"mc":[{"id":"1.241629436","rc":[{"atb":[[5.2,229.33]],"atl":[[1000,21.16]],"trd":[[5.2,1591.51]],"batb":[[0,5.2,229.33]],"tv":16332.57,"id":270592},{"atl":[[1000,1.51]],"id":58186642}],"tv":70993.53}]}
{"op":"mcm","id":2,"clk":"ALJDAKEqANw8","pt":1743511770391,"mc":[{"id":"1.241629436","rc":[{"atb":[[10.5,79.84]],"batb":[[0,10.5,79.84]],"id":44049799}]}]}
{"op":"mcm","id":2,"clk":"ALdDAKUqAOI8","pt":1743511770489,"mc":[{"id":"1.241629436","rc":[{"atl":[[1000,1.41]],"id":58186642}]}]}
{"op":"mcm","id":2,"clk":"ALxDAKkqAO08","pt":1743511770597,"mc":[{"id":"1.241629436","rc":[{"atl":[[19,21.69]],"batl":[[2,19,21.69]],"id":58186642}]}]}
{"op":"mcm","id":2,"clk":"AM5DALAqAIA9","pt":1743511770902,"mc":[{"id":"1.241629436","rc":[{"atl":[[1000,23.16]],"id":270592}]}]}
{"op":"mcm","id":2,"clk":"ANtDALgqAJo9","pt":1743511771113,"mc":[{"id":"1.241629436","rc":[{"atl":[[1000,21.16]],"id":270592},{"atl":[[1000,3.41]],"id":58186642}]}]}
{"op":"mcm","id":2,"clk":"AOFDALsqAJw9","pt":1743511771228,"mc":[{"id":"1.241629436","rc":[{"atb":[[6,50.63]],"id":40389088},{"atb":[[5.2,230.32]],"batb":[[0,5.2,230.32]],"id":270592},{"atl":[[1000,1.51]],"id":58186642}]}]}
{"op":"mcm","id":2,"clk":"AOhDAMAqAKk9","pt":1743511771315,"mc":[{"id":"1.241629436","rc":[{"atl":[[1000,1.41]],"id":58186642}]}]}
{"op":"mcm","id":2,"clk":"APBDAMMqALE9","pt":1743511771423,"mc":[{"id":"1.241629436","rc":[{"atl":[[19.5,8.05]],"batl":[],"id":58186642}]}]}
{"op":"mcm","id":2,"clk":"AJFEANkqANQ9","pt":1743511771793,"mc":[{"id":"1.241629436","rc":[{"atl":[[1000,3.41]],"id":58186642}]}]}
{"op":"mcm","id":2,"clk":"AKBEAOYqAOM9","pt":1743511771990,"mc":[{"id":"1.241629436","rc":[{"atb":[[5.1,339.56]],"batb":[[1,5.1,339.56]],"id":270592},{"atb":[[65,7.68]],"batb":[[0,65,7.68]],"id":59626646},{"atl":[[1000,1.51]],"id":58186642}]}]}
{"op":"mcm","id":2,"clk":"AK1EAPQqAPQ9","pt":1743511772191,"mc":[{"id":"1.241629436","rc":[{"atl":[[1000,1.41]],"id":58186642}]}]}
{"op":"mcm","id":2,"clk":"ALtEAPsqAPo9","pt":1743511772300,"mc":[{"id":"1.241629436","rc":[{"atl":[[1000,3.41],[17.5,0.3]],"batl":[[0,18,21.07]],"id":58186642}]}]}
{"op":"mcm","id":2,"clk":"AL9EAIMrAII+","pt":1743511772392,"mc":[{"id":"1.241629436","rc":[{"atb":[[5.2,222.58]],"trd":[[5.2,1606.98]],"batb":[[0,5.2,222.58]],"tv":16348.04,"id":270592},{"atl":[[1000,1.51]],"id":58186642}],"tv":71009}]}
{"op":"mcm","id":2,"clk":"AM9EAI4rAJA+","pt":1743511772601,"mc":[{"id":"1.241629436","rc":[{"atl":[[1000,1.41]],"id":58186642}]}]}
{"op":"mcm","id":2,"clk":"ANNEAJYrAJY+","pt":1743511772699,"mc":[{"id":"1.241629436","rc":[{"atb":[[5,386.47]],"batb":[[2,5,386.47]],"id":270592},{"atl":[[18,20.87]],"batl":[[0,18,21.17]],"id":58186642}]}]}
{"op":"mcm","id":2,"clk":"ANxEAJkrAKM+","pt":1743511772810,"mc":[{"id":"1.241629436","rc":[{"atb":[[1.17,2.63]],"id":40389088}]}]}
{"op":"mcm","id":2,"clk":"AOVEAJ0rAK4+","pt":1743511772907,"mc":[{"id":"1.241629436","rc":[{"atb":[[1.17,2]],"id":40389088},{"atb":[[5.1,218]],"atl":[[5.3,132.37]],"batb":[[0,5.1,218]],"batl":[[1,5.3,132.37]],"id":56297029},{"atb":[[10.5,81.17]],"batb":[[0,10.5,81.17]],"id":44049799}]}]}
{"op":"mcm","id":2,"clk":"AOtEAKMrALc+","pt":1743511773007,"mc":[{"id":"1.241629436","rc":[{"atb":[[11.5,30.94]],"batb":[[0,11.5,30.94]],"id":40389088}]}]}
{"op":"mcm","id":2,"clk":"AIZFALArAM4+","pt":1743511773316,"mc":[{"id":"1.241629436","rc":[{"atl":[[1000,3.41]],"id":58186642}]}]}
{"op":"mcm","id":2,"clk":"AJBFALcrANg+","pt":1743511773425,"mc":[{"id":"1.241629436","rc":[{"atb":[[5.1,216.03]],"trd":[[5.1,2995.55]],"batb":[[0,5.1,216.03]],"tv":11886.87,"id":56297029},{"atl":[[1000,1.51]],"id":58186642}],"tv":71012.94}]}
{"op":"mcm","id":2,"clk":"AJhFALgrAOE+","pt":1743511773522,"mc":[{"id":"1.241629436","rc":[{"atl":[[1000,1.41]],"id":58186642}]}]}
{"op":"mcm","id":2,"clk":"AKJFAL4rAOY+","pt":1743511773621,"mc":[{"id":"1.241629436","rc":[{"atl":[[18.5,15.19]],"batl":[[1,18.5,15.19]],"id":58186642}]}]}
{"op":"mcm","id":2,"clk":"AMhFAM4rAIQ/","pt":1743511773989,"mc":[{"id":"1.241629436","rc":[{"atl":[[1000,3.41]],"id":58186642},{"atb":[[10.5,84.47]],"batb":[[0,10.5,84.47]],"id":44049799}]}]}
{"op":"mcm","id":2,"clk":"ANNFANgrAJE/","pt":1743511774187,"mc":[{"id":"1.241629436","rc":[{"atl":[[1000,1.51]],"id":58186642}]}]}
{"op":"mcm","id":2,"clk":"AOpFAOYrAKM/","pt":1743511774397,"mc":[{"id":"1.241629436","rc":[{"atl":[[1000,1.41]],"id":58186642}]}]}
{"op":"mcm","id":2,"clk":"APRFAOwrAKs/","pt":1743511774506,"mc":[{"id":"1.241629436","rc":[{"atl":[[1000,3.41],[19,21.79]],"batl":[[2,19,21.79]],"id":58186642}]}]}
{"op":"mcm","id":2,"clk":"APZFAPArALQ/","pt":1743511774602,"mc":[{"id":"1.241629436","rc":[{"atl":[[1000,1.51]],"id":58186642}]}]}
{"op":"mcm","id":2,"clk":"APpFAPQrAL0/","pt":1743511774709,"mc":[{"id":"1.241629436","rc":[{"atl":[[14,25.24]],"id":35856222},{"atl":[[1000,1.41]],"id":58186642}]}]}
{"op":"mcm","id":2,"clk":"AP1FAPorAME/","pt":1743511774802,"mc":[{"id":"1.241629436","rc":[{"atl":[[19.5,8.15]],"batl":[],"id":58186642}]}]}
{"op":"mcm","id":2,"clk":"AJFGAIIsANA/","pt":1743511775015,"mc":[{"id":"1.241629436","rc":[{"atb":[[5.2,214.25]],"batb":[[0,5.2,214.25]],"id":270592},{"atb":[[6.4,121.16]],"trd":[[6.4,3104.89]],"batb":[[0,6.4,121.16]],"tv":11708.78,"id":26496185}],"tv":71033.64}]}
{"op":"mcm","id":2,"clk":"AJVGAIcsANc/","pt":1743511775112,"mc":[{"id":"1.241629436","rc":[{"atb":[[5.1,214.23]],"trd":[[5.1,2999.15]],"batb":[[0,5.1,214.23]],"tv":11890.47,"id":56297029},{"atb":[[6.4,143]],"batb":[[0,6.4,143]],"id":26496185}],"tv":71037.24}]}
{"op":"mcm","id":2,"clk":"AJ5GAIksAN4/","pt":1743511775214,"mc":[{"id":"1.241629436","rc":[{"atb":[[10.5,84.37]],"trd":[[10.5,495.29]],"batb":[[0,10.5,84.37]],"tv":4018.86,"id":44049799}],"tv":71037.44}]}
{"op":"mcm","id":2,"clk":"ALNGAJYsAPo/","pt":1743511775522,"mc":[{"id":"1.241629436","rc":[{"atl":[[1000,23.16]],"id":270592}]}]}
{"op":"mcm","id":2,"clk":"AMdGAJwsAIZA","pt":1743511775727,"mc":[{"id":"1.241629436","rc":[{"atl":[[1000,21.16]],"id":270592}]}]}
{"op":"mcm","id":2,"clk":"AM5GAJ4sAI1A","pt":1743511775828,"mc":[{"id":"1.241629436","rc":[{"atl":[[12,28.23]],"batl":[[0,12,28.23]],"id":40389088}]}]}
{"op":"mcm","id":2,"clk":"APNGAKssALdA","pt":1743511776301,"mc":[{"id":"1.241629436","rc":[{"atl":[[1000,23.16]],"id":270592}]}]}
{"op":"mcm","id":2,"clk":"AP9GAK4sAL9A","pt":1743511776398,"mc":[{"id":"1.241629436","rc":[{"atb":[[5.2,215.78]],"batb":[[0,5.2,215.78]],"id":270592}]}]}
{"op":"mcm","id":2,"clk":"AIdHALIsAMdA","pt":1743511776509,"mc":[{"id":"1.241629436","rc":[{"atl":[[1000,21.16]],"id":270592}]}]}
{"op":"mcm","id":2,"clk":"AKVHAMgsAOdA","pt":1743511776908,"mc":[{"id":"1.241629436","rc":[{"atl":[[12.5,49.23]],"batl":[[1,12.5,49.23]],"id":40389088}]}]}
{"op":"mcm","id":2,"clk":"AKpHAMwsAPFA","pt":1743511777010,"mc":[{"id":"1.241629436","rc":[{"atb":[[5,388.56]],"batb":[[2,5,388.56]],"id":270592}]}]}
{"op":"mcm","id":2,"clk":"ANJHAN4sAKVB","pt":1743511777522,"mc":[{"id":"1.241629436","rc":[{"atb":[[6,45.63]],"id":40389088}]}]}
{"op":"mcm","id":2,"clk":"AN5HAOYsALlB","pt":1743511777726,"mc":[{"id":"1.241629436","rc":[{"atb":[[10.5,64.37]],"trd":[[10.5,535.29]],"batb":[[0,10.5,64.37]],"tv":4058.86,"id":44049799}],"tv":71077.44}]}
{"op":"mcm","id":2,"clk":"AOhHAOssAMJB","pt":1743511777834,"mc":[{"id":"1.241629436","rc":[{"atl":[[9.4,14.35]],"trd":[[9.4,299.09]],"batl":[[0,9.4,14.35]],"ltp":9.4,"tv":8591.87,"id":35856222},{"atb":[[65,7.48]],"trd":[[65,107.42]],"batb":[[0,65,7.48]],"tv":1617.4,"id":59626646},{"atl":[[18,18.88],[17.5,0]],"trd":[[18,96.2],[17.5,104.03]],"batl":[[0,18,18.88]],"ltp":18,"tv":4774.98,"id":58186642},{"atb":[[10.5,44.05]],"batb":[[0,10.5,44.05]],"id":44049799}],"tv":71090.92}]}
{"op":"mcm","id":2,"clk":"AOxHAO4sAM1B","pt":1743511777931,"mc":[{"id":"1.241629436","rc":[{"atl":[[5.4,173.73]],"batl":[[1,5.4,173.73]],"id":270592},{"atb":[[16,21.39]],"atl":[[17.5,38.11]],"batb":[[2,16,21.39]],"batl":[[2,18.5,15.19],[1,18,18.88],[0,17.5,38.11]],"id":58186642},{"atl":[[6.6,58.08]],"batl":[[0,6.6,58.08]],"id":26496185}]}]}
{"op":"mcm","id":2,"clk":"APdHAPUsANZB","pt":1743511778031,"mc":[{"id":"1.241629436","rc":[{"atb":[[9.2,8.55]],"atl":[[9.4,22.72]],"batb":[[2,8.8,39.35],[1,9,101.49],[0,9.2,8.55]],"batl":[[0,9.4,22.72]],"id":35856222},{"atb":[[17,58.3]],"atl":[[17.5,46.21]],"batb":[[0,17,58.3]],"batl":[[0,17.5,46.21]],"id":58186642}]}]}
{"op":"mcm","id":2,"clk":"AIhIAIItAOlB","pt":1743511778192,"mc":[{"id":"1.241629436","rc":[{"atl":[[5.6,74.94]],"batl":[],"id":270592},{"atl":[[9.4,21.65]],"batl":[[0,9.4,21.65]],"id":35856222},{"atb":[[5.1,194.23]],"batb":[[0,5.1,194.23]],"id":56297029},{"atl":[[8.8,13.08]],"id":26496185}]}]}
{"op":"mcm","id":2,"clk":"AJFIAIgtAPRB","pt":1743511778297,"mc":[{"id":"1.241629436","rc":[{"atl":[[5.4,185.33]],"batl":[[1,5.4,185.33]],"id":270592},{"atl":[[95,10.15],[90,3.26]],"batl":[],"id":59626646}]}]}
{"op":"mcm","id":2,"clk":"AMBIAKctAJ9C","pt":1743511778815,"mc":[{"id":"1.241629436","rc":[{"atb":[[10.5,42.52]],"trd":[[10.5,538.35]],"batb":[[0,10.5,42.52]],"tv":4061.92,"id":44049799}],"tv":71093.98}]}
{"op":"mcm","id":2,"clk":"ANBIALAtAK5C","pt":1743511779014,"mc":[{"id":"1.241629436","rc":[{"atb":[[9.8,32.57]],"batb":[[2,9.8,32.57]],"id":44049799}]}]}
{"op":"mcm","id":2,"clk":"ANlIALMtALZC","pt":1743511779116,"mc":[{"id":"1.241629436","rc":[{"atl":[[12,26.23]],"batl":[[0,12,26.23]],"id":40389088},{"atb":[[5.1,199.17]],"atl":[[5.3,133.4]],"batb":[[0,5.1,199.17]],"batl":[[1,5.3,133.4]],"id":56297029}]}]}
{"op":"mcm","id":2,"clk":"AOBIALctALtC","pt":1743511779217,"mc":[{"id":"1.241629436","rc":[{"atb":[[10.5,49.64]],"batb":[[0,10.5,49.64]],"id":44049799}]}]}
{"op":"mcm","id":2,"clk":"AOtIALwtAMNC","pt":1743511779320,"mc":[{"id":"1.241629436","rc":[{"atl":[[5.3,202.25]],"batl":[[0,5.3,202.25]],"id":270592},{"atb":[[10.5,47.95]],"trd":[[10.5,541.73]],"batb":[[0,10.5,47.95]],"tv":4065.3,"id":44049799}],"tv":71097.36}]}
{"op":"mcm","id":2,"clk":"APFIAMEtAMlC","pt":1743511779422,"mc":[{"id":"1.241629436","rc":[{"atl":[[9.4,14.65]],"trd":[[9.4,313.09]],"batl":[[0,9.4,14.65]],"tv":8605.87,"id":35856222}],"tv":71111.36}]}
{"op":"mcm","id":2,"clk":"AIVJAMctANpC","pt":1743511779638,"mc":[{"id":"1.241629436","rc":[{"atl":[[1000,2.25]],"id":40389088}]}]}
{"op":"mcm","id":2,"clk":"AI9JAMwtAN5C","pt":1743511779731,"mc":[{"id":"1.241629436","rc":[{"atl":[[1000,1.01]],"id":40389088},{"atl":[[1000,1.52]],"id":58186642},{"atl":[[11,110.49]],"batl":[[0,11,110.49]],"id":44049799}]}]}
{"op":"mcm","id":2,"clk":"AJRJANMtAOxC","pt":1743511779838,"mc":[{"id":"1.241629436","rc":[{"atl":[[1000,0.25]],"id":40389088},{"atl":[[1000,1.41]],"id":58186642},{"atl":[[11,112.88]],"batl":[[0,11,112.88]],"id":44049799}]}]}
{"op":"mcm","id":2,"clk":"AJpJANQtAPJC","pt":1743511779883,"mc":[{"id":"1.241629436","rc":[{"atb":[[11.5,30.18]],"trd":[[11.5,1020.25]],"batb":[[0,11.5,30.18]],"tv":6062.91,"id":40389088},{"atl":[[17.5,46.32]],"batl":[[0,17.5,46.32]],"id":58186642}],"tv":71112.88}]}
{"op":"mcm","id":2,"clk":"AJ5JANYtAPxC","pt":1743511779992,"mc":[{"id":"1.241629436","rc":[{"atb":[[1.5,34]],"id":35856222},{"atb":[[17,50.5]],"batb":[[0,17,50.5]],"id":58186642},{"atl":[[11,110.49]],"batl":[[0,11,110.49]],"id":44049799}]}]}
{"op":"mcm","id":2,"clk":"AKtJAOUtAIZD","pt":1743511780192,"mc":[{"id":"1.241629436","rc":[{"atb":[[5.1,348.1]],"batb":[[1,5.1,348.1]],"id":270592},{"atb":[[8.8,47.07]],"batb":[[2,8.8,47.07]],"id":35856222},{"atb":[[10.5,46.95]],"atl":[[11,112.88]],"trd":[[10.5,543.73]],"batb":[[0,10.5,46.95]],"batl":[[0,11,112.88]],"tv":4067.3,"id":44049799}],"tv":71114.88}]}
{"op":"mcm","id":2,"clk":"ALNJAO0tAJhD","pt":1743511780305,"mc":[{"id":"1.241629436","rc":[{"atl":[[5.2,206.79]],"trd":[[5.2,3487.63]],"batl":[[0,5.2,206.79]],"ltp":5.2,"tv":11922.37,"id":56297029},{"atb":[[10,78.81]],"trd":[[10,291.52]],"batb":[[0,10,78.81]],"tv":6041.13,"id":27115873}],"tv":71148.78}]}
{"op":"mcm","id":2,"clk":"ALxJAPQtAJ5D","pt":1743511780402,"mc":[{"id":"1.241629436","rc":[{"atb":[[5.1,195.17]],"trd":[[5.1,3007.15]],"batb":[[0,5.1,195.17]],"ltp":5.1,"tv":11930.37,"id":56297029}],"tv":71156.78}]}
{"op":"mcm","id":2,"clk":"AMVJAPgtAKJD","pt":1743511780500,"mc":[{"id":"1.241629436","rc":[{"atb":[[5.1,206.25]],"atl":[[5.2,217.88]],"batb":[[0,5.1,206.25]],"batl":[[0,5.2,217.88]],"id":56297029},{"atl":[[6.6,66.88]],"batl":[[0,6.6,66.88]],"id":26496185},{"atl":[[11,110.49]],"batl":[[0,11,110.49]],"id":44049799}]}]}
{"op":"mcm","id":2,"clk":"AMtJAP0tAKtD","pt":1743511780604,"mc":[{"id":"1.241629436","rc":[{"atb":[[5.1,336.84]],"batb":[[1,5.1,336.84]],"id":270592},{"atl":[[5.8,57.59]],"batl":[],"id":56297029},{"atb":[[9.8,60.2]],"batb":[[1,9.8,60.2]],"id":27115873}]}]}
{"op":"mcm","id":2,"clk":"AOBJAIQuAMBD","pt":1743511780909,"mc":[{"id":"1.241629436","rc":[{"atl":[[1000,23.16]],"id":270592}]}]}
{"op":"mcm","id":2,"clk":"AO1JAIwuANFD","pt":1743511781115,"mc":[{"id":"1.241629436","rc":[{"atl":[[1000,21.16]],"id":270592},{"atb":[[5.1,106.25]],"trd":[[5.1,3207.15]],"batb":[[0,5.1,106.25]],"tv":12130.37,"id":56297029}],"tv":71356.78}]}
{"op":"mcm","id":2,"clk":"APNJAJIuANZD","pt":1743511781220,"mc":[{"id":"1.241629436","rc":[{"atb":[[5.2,215.68]],"trd":[[5.2,1607.18]],"batb":[[0,5.2,215.68]],"tv":16348.24,"id":270592},{"atb":[[5.1,182.77]],"batb":[[0,5.1,182.77]],"id":56297029},{"atb":[[10.5,67.46]],"batb":[[0,10.5,67.46]],"id":44049799}],"tv":71356.98}]}
{"op":"mcm","id":2,"clk":"APxJAJguAN9D","pt":1743511781322,"mc":[{"id":"1.241629436","rc":[{"atb":[[8.8,39.35]],"batb":[[2,8.8,39.35]],"id":35856222},{"atb":[[4.9,91.5],[5.1,159.98]],"batb":[[2,4.9,91.5],[0,5.1,159.98]],"id":56297029},{"atl":[[6.6,58.08]],"batl":[[0,6.6,58.08]],"id":26496185}]}]}
{"op":"mcm","id":2,"clk":"AINKAJwuAOtD","pt":1743511781431,"mc":[{"id":"1.241629436","rc":[{"atl":[[6.6,66.88]],"batl":[[0,6.6,66.88]],"id":26496185}]}]}
{"op":"mcm","id":2,"clk":"AItKAKIuAO5D","pt":1743511781533,"mc":[{"id":"1.241629436","rc":[{"atb":[[4.9,92.51]],"batb":[[2,4.9,92.51]],"id":56297029}]}]}
{"op":"mcm","id":2,"clk":"AJdKAK8uAIVE","pt":1743511781735,"mc":[{"id":"1.241629436","rc":[{"atl":[[1000,23.16]],"id":270592}]}]}
{"op":"mcm","id":2,"clk":"AK1KALwuAJZE","pt":1743511781896,"mc":[{"id":"1.241629436","rc":[{"atl":[[1000,21.16]],"id":270592},{"atl":[[10,100.37]],"batl":[],"id":35856222}]}]}
{"op":"mcm","id":2,"clk":"AMhKANMuALFE","pt":1743511782202,"mc":[{"id":"1.241629436","rc":[{"atl":[[5.4,185.21]],"batl":[[1,5.4,185.21]],"id":270592},{"atl":[[17.5,52.63]],"batl":[[0,17.5,52.63]],"id":58186642},{"atb":[[6.4,141.93]],"batb":[[0,6.4,141.93]],"id":26496185}]}]}
{"op":"mcm","id":2,"clk":"AOlKAOguAMtE","pt":1743511782511,"mc":[{"id":"1.241629436","rc":[{"atb":[[5.2,222.47]],"batb":[[0,5.2,222.47]],"id":270592},{"atb":[[17,48.5]],"trd":[[17,496.46]],"batb":[[0,17,48.5]],"ltp":17,"tv":4778.98,"id":58186642},{"atl":[[11.5,63.71]],"batl":[[1,11.5,63.71]],"id":44049799}],"tv":71360.98}]}
{"op":"mcm","id":2,"clk":"APZKAPAuAM9E","pt":1743511782613,"mc":[{"id":"1.241629436","rc":[{"atb":[[5.1,161.29]],"batb":[[0,5.1,161.29]],"id":56297029}]}]}
{"op":"mcm","id":2,"clk":"AP1KAPkuANlE","pt":1743511782723,"mc":[{"id":"1.241629436","rc":[{"atb":[[6.4,143.19]],"batb":[[0,6.4,143.19]],"id":26496185},{"atb":[[10.5,68.8]],"batb":[[0,10.5,68.8]],"id":44049799}]}]}
{"op":"mcm","id":2,"clk":"AJBLAIQvAOdE","pt":1743511782928,"mc":[{"id":"1.241629436","rc":[{"atb":[[11.5,31.5]],"batb":[[0,11.5,31.5]],"id":40389088}]}]}
{"op":"mcm","id":2,"clk":"AJpLAIgvAOtE","pt":1743511783028,"mc":[{"id":"1.241629436","rc":[{"atb":[[6,50.63]],"id":40389088},{"atl":[[10,100.27]],"batl":[],"id":35856222}]}]}
{"op":"mcm","id":2,"clk":"ANpLAKsvAJxF","pt":1743511783740,"mc":[{"id":"1.241629436","rc":[{"atl":[[12,27.23]],"batl":[[0,12,27.23]],"id":40389088},{"atl":[[12,33.57]],"batl":[[2,12,33.57]],"id":44049799}]}]}
{"op":"mcm","id":2,"clk":"AO1LALgvAKlF","pt":1743511783900,"mc":[{"id":"1.241629436","rc":[{"atb":[[1.46,35.62]],"id":270592}]}]}
{"op":"mcm","id":2,"clk":"AIRMAMUvAL9F","pt":1743511784202,"mc":[{"id":"1.241629436","rc":[{"atl":[[10,100.37]],"batl":[],"id":35856222}]}]}
{"op":"mcm","id":2,"clk":"AJRMAM4vANJF","pt":1743511784510,"mc":[{"id":"1.241629436","rc":[{"atl":[[10,100.47]],"batl":[],"id":35856222}]}]}
{"op":"mcm","id":2,"clk":"AKlMANgvAOlF","pt":1743511784818,"mc":[{"id":"1.241629436","rc":[{"atl":[[10,100.57]],"batl":[],"id":35856222}]}]}
{"op":"mcm","id":2,"clk":"ALtMAOQvAIJG","pt":1743511785123,"mc":[{"id":"1.241629436","rc":[{"atl":[[10,100.67]],"batl":[],"id":35856222}]}]}
{"op":"mcm","id":2,"clk":"AMFMAOcvAI1G","pt":1743511785224,"mc":[{"id":"1.241629436","rc":[{"atl":[[13,20.92]],"batl":[[2,13,20.92]],"id":40389088},{"atb":[[5,340.56]],"batb":[[2,5,340.56]],"id":270592},{"atl":[[1000,0.51],[10,100.77]],"batl":[],"id":35856222},{"atb":[[5.1,162.82]],"atl":[[1000,4.84]],"batb":[[0,5.1,162.82]],"id":56297029}]}]}
{"op":"mcm","id":2,"clk":"AM1MAOovAJFG","pt":1743511785331,"mc":[{"id":"1.241629436","rc":[{"atb":[[5.1,384.84]],"batb":[[1,5.1,384.84]],"id":270592},{"atl":[[1000,0.41]],"id":35856222},{"atl":[[1000,4.52]],"id":56297029}]}]}
{"op":"mcm","id":2,"clk":"ANBMAO0vAJhG","pt":1743511785433,"mc":[{"id":"1.241629436","rc":[{"atl":[[9.4,14.75]],"batl":[[0,9.4,14.75]],"id":35856222},{"atl":[[5.3,133.72]],"batl":[[1,5.3,133.72]],"id":56297029}]}]}
{"op":"mcm","id":2,"clk":"ANhMAPAvAJ9G","pt":1743511785590,"mc":[{"id":"1.241629436","rc":[{"atb":[[6,45.63]],"id":40389088}]}]}
{"op":"mcm","id":2,"clk":"AOVMAPUvAK5G","pt":1743511785754,"mc":[{"id":"1.241629436","rc":[{"atb":[[6.4,103.19]],"trd":[[6.4,3184.89]],"batb":[[0,6.4,103.19]],"tv":11788.78,"id":26496185}],"tv":71440.98}]}
{"op":"mcm","id":2,"clk":"AO5MAPkvALRG","pt":1743511785896,"mc":[{"id":"1.241629436","rc":[{"atb":[[6.2,137.51]],"atl":[[6.6,81.96]],"batb":[[1,6.2,137.51]],"batl":[[0,6.6,81.96]],"id":26496185}]}]}
{"op":"mcm","id":2,"clk":"AIlNAIgwAMZG","pt":1743511786315,"mc":[{"id":"1.241629436","rc":[{"atl":[[1000,23.16]],"id":270592}]}]}
{"op":"mcm","id":2,"clk":"AJRNAJAwANdG","pt":1743511786516,"mc":[{"id":"1.241629436","rc":[{"atl":[[1000,21.16]],"id":270592}]}]}
{"op":"mcm","id":2,"clk":"AJxNAJowAOVG","pt":1743511786724,"mc":[{"id":"1.241629436","rc":[{"atb":[[11.5,30.87]],"atl":[[14.5,24.16]],"batb":[[0,11.5,30.87]],"batl":[],"id":40389088},{"atl":[[5.4,184.09]],"batl":[[1,5.4,184.09]],"id":270592},{"atb":[[10.5,68.11]],"batb":[[0,10.5,68.11]],"id":44049799}]}]}
{"op":"mcm","id":2,"clk":"AMlNAKkwAPxG","pt":1743511787134,"mc":[{"id":"1.241629436","rc":[{"atl":[[1000,23.16]],"id":270592},{"atl":[[19.5,7.85]],"batl":[],"id":58186642}]}]}
{"op":"mcm","id":2,"clk":"ANJNAK4wAIdH","pt":1743511787244,"mc":[{"id":"1.241629436","rc":[{"atl":[[17.5,52.93]],"batl":[[0,17.5,52.93]],"id":58186642}]}]}
{"op":"mcm","id":2,"clk":"AN1NALEwAIxH","pt":1743511787346,"mc":[{"id":"1.241629436","rc":[{"atl":[[1000,21.16]],"id":270592}]}]}
{"op":"mcm","id":2,"clk":"AOZNALQwAJNH","pt":1743511787448,"mc":[{"id":"1.241629436","rc":[{"atl":[[10,100.27]],"batl":[],"id":35856222}]}]}
{"op":"mcm","id":2,"clk":"AJJOAMkwALVH","pt":1743511787913,"mc":[{"id":"1.241629436","rc":[{"atl":[[11,109.49]],"trd":[[11,1096.67]],"batl":[[0,11,109.49]],"ltp":11,"tv":4069.3,"id":44049799}],"tv":71442.98}]}
{"op":"mcm","id":2,"clk":"AJtOAM4wALtH","pt":1743511788017,"mc":[{"id":"1.241629436","rc":[{"atb":[[6.4,102.12]],"batb":[[0,6.4,102.12]],"id":26496185}]}]}
{"op":"mcm","id":2,"clk":"AKNOANMwAMRH","pt":1743511788115,"mc":[{"id":"1.241629436","rc":[{"atl":[[14,16.88]],"batl":[],"id":40389088}]}]}
{"op":"mcm","id":2,"clk":"ANVOAOcwAN9H","pt":1743511788627,"mc":[{"id":"1.241629436","rc":[{"atb":[[6,50.63]],"id":40389088}]}]}
{"op":"mcm","id":2,"clk":"APZOAPswAIRI","pt":1743511789143,"mc":[{"id":"1.241629436","rc":[{"atl":[[11,25.86]],"trd":[[11,1263.93]],"batl":[[0,11,25.86]],"tv":4236.56,"id":44049799}],"tv":71610.24}]}
{"op":"mcm","id":2,"clk":"APlOAP0wAIlI","pt":1743511789242,"mc":[{"id":"1.241629436","rc":[{"atb":[[9.2,0]],"batb":[[2,8.6,58.51],[1,8.8,39.35],[0,9,101.49]],"id":35856222},{"atb":[[4.9,91.5]],"batb":[[2,4.9,91.5]],"id":56297029},{"atb":[[10,58.81]],"trd":[[10,331.52]],"batb":[[0,10,58.81]],"tv":6081.13,"id":27115873},{"atl":[[17.5,56.23]],"batl":[[0,17.5,56.23]],"id":58186642},{"atb":[[6.4,81.39]],"batb":[[0,6.4,81.39]],"id":26496185},{"atb":[[10.5,76.6]],"atl":[[11,5.58]],"trd":[[11,1280.67]],"batb":[[0,10.5,76.6]],"batl":[[0,11,5.58]],"tv":4253.3,"id":44049799}],"tv":71666.98}]}
{"op":"mcm","id":2,"clk":"APxOAIIxAI9I","pt":1743511789345,"mc":[{"id":"1.241629436","rc":[{"atl":[[5.6,72.96]],"batl":[],"id":270592},{"atl":[[9.4,23.9]],"batl":[[0,9.4,23.9]],"id":35856222},{"atb":[[10,79.63]],"batb":[[0,10,79.63]],"id":27115873},{"atb":[[17,45.69]],"atl":[[17.5,59.5]],"batb":[[0,17,45.69]],"batl":[[0,17.5,59.5]],"id":58186642},{"atb":[[10.5,86.46]],"atl":[[11,0],[17.5,8.69]],"trd":[[11,1291.83]],"batb":[[0,10.5,86.46]],"batl":[[2,12.5,47.08],[1,12,33.57],[0,11.5,63.71]],"tv":4264.46,"id":44049799}],"tv":71678.14}]}
{"op":"mcm","id":2,"clk":"AIdPAIkxAJdI","pt":1743511789464,"mc":[{"id":"1.241629436","rc":[{"atb":[[4.8,99.4]],"batb":[],"id":56297029},{"atb":[[17,37.63]],"batb":[[0,17,37.63]],"id":58186642},{"atb":[[6.4,69.51]],"batb":[[0,6.4,69.51]],"id":26496185},{"atb":[[11.5,18.13],[11,44.83],[10.5,96.39]],"atl":[[14,15.6],[11.5,0]],"trd":[[11.5,586.49]],"batb":[[2,10.5,96.39],[1,11,44.83],[0,11.5,18.13]],"batl":[[2,13,31.96],[1,12.5,47.08],[0,12,33.57]],"ltp":11.5,"tv":4348.06,"id":44049799}],"tv":71761.74}]}
{"op":"mcm","id":2,"clk":"AIxPAIwxAJpI","pt":1743511789555,"mc":[{"id":"1.241629436","rc":[{"atb":[[5,350.66]],"batb":[[2,5,350.66]],"id":270592},{"atb":[[5.1,178.77]],"batb":[[0,5.1,178.77]],"id":56297029},{"atb":[[17,26.35]],"batb":[[0,17,26.35]],"id":58186642},{"atl":[[13,30.29],[12.5,45.26]],"batl":[[2,13,30.29],[1,12.5,45.26]],"id":44049799}]}]}
{"op":"mcm","id":2,"clk":"AKBPAI4xAJ1I","pt":1743511789655,"mc":[{"id":"1.241629436","rc":[{"atb":[[11.5,25.97]],"atl":[[12,32.17]],"batb":[[0,11.5,25.97]],"batl":[[0,12,32.17]],"id":40389088},{"atb":[[5.2,203.35]],"atl":[[5.6,74.94]],"batb":[[0,5.2,203.35]],"batl":[],"id":270592},{"atl":[[9.6,56.22]],"batl":[[1,9.6,56.22]],"id":35856222},{"atb":[[9.4,58.75],[10,66.63],[9.6,49.5]],"batb":[[2,9.6,49.5],[0,10,66.63]],"id":27115873},{"atb":[[17,25.15]],"trd":[[17,498.86]],"batb":[[0,17,25.15]],"tv":4781.38,"id":58186642},{"atb":[[6.4,45.06]],"batb":[[0,6.4,45.06]],"id":26496185},{"atb":[[11.5,1.24],[11,106.85],[10,65.69]],"atl":[[13.5,15.73],[12.5,50.57],[12,31.72]],"trd":[[11.5,620.27]],"batb":[[1,11,106.85],[0,11.5,1.24]],"batl":[[1,12.5,50.57],[0,12,31.72]],"tv":4381.84,"id":44049799}],"tv":71797.92}]}
{"op":"mcm","id":2,"clk":"AKlPAJIxAKVI","pt":1743511789711,"mc":[{"id":"1.241629436","rc":[{"atl":[[15,16.97],[12.5,53.8]],"batl":[[1,12.5,53.8]],"id":40389088},{"atb":[[17,0]],"atl":[[17,10.56]],"trd":[[17,549.16]],"batb":[[2,15.5,46.43],[1,16,21.39],[0,16.5,30.86]],"batl":[[2,18,18.88],[1,17.5,59.5],[0,17,10.56]],"tv":4831.68,"id":58186642},{"atb":[[11,107.28]],"atl":[[12.5,52.39]],"batb":[[1,11,107.28]],"batl":[[1,12.5,52.39]],"id":44049799}],"tv":71848.22}]}
{"op":"mcm","id":2,"clk":"ALFPAJ4xAK9I","pt":1743511789872,"mc":[{"id":"1.241629436","rc":[{"atb":[[11.5,1.95],[8.6,28.02]],"atl":[[14,18.31],[13.5,18.39]],"batb":[[0,11.5,1.95]],"batl":[],"id":40389088},{"atb":[[5.2,179.35]],"batb":[[0,5.2,179.35]],"id":270592},{"atb":[[5.1,152.77],[4.8,98.37]],"batb":[[0,5.1,152.77]],"id":56297029},{"atb":[[9.6,55.12]],"batb":[[2,9.6,55.12]],"id":27115873},{"atb":[[13,8.17],[16.5,20.77]],"atl":[[17.5,59.79],[17,10.3]],"trd":[[17,556.48]],"batb":[[0,16.5,20.77]],"batl":[[1,17.5,59.79],[0,17,10.3]],"tv":4839,"id":58186642},{"atb":[[5.1,28.44]],"atl":[[6.6,82.72]],"batl":[[0,6.6,82.72]],"id":26496185},{"atb":[[11.5,9.05],[11,91.85],[10,64.04],[9.6,27.74]],"atl":[[13,38.45],[12.5,47.08],[18,6.79]],"trd":[[11.5,627.47]],"batb":[[1,11,91.85],[0,11.5,9.05]],"batl":[[2,13,38.45],[1,12.5,47.08]],"tv":4389.04,"id":44049799}],"tv":71862.74}]}
{"op":"mcm","id":2,"clk":"ALhPAKAxALNI","pt":1743511789918,"mc":[{"id":"1.241629436","rc":[{"atb":[[16.5,26.09]],"batb":[[0,16.5,26.09]],"id":58186642},{"atl":[[13,35.02]],"batl":[[2,13,35.02]],"id":44049799}]}]}
{"op":"mcm","id":2,"clk":"AL1PAKYxALpI","pt":1743511790014,"mc":[{"id":"1.241629436","rc":[{"atb":[[11.5,14.6]],"batb":[[0,11.5,14.6]],"id":40389088},{"atb":[[5.2,204.35]],"batb":[[0,5.2,204.35]],"id":270592},{"atb":[[5.1,178.77],[4.8,99.4]],"batb":[[0,5.1,178.77]],"id":56297029},{"atb":[[16.5,25.79]],"batb":[[0,16.5,25.79]],"id":58186642},{"atb":[[6.4,74.92]],"batb":[[0,6.4,74.92]],"id":26496185},{"atb":[[11.5,6.47],[11,94.21]],"batb":[[1,11,94.21],[0,11.5,6.47]],"id":44049799}]}]}
{"op":"mcm","id":2,"clk":"AMtPAKwxAMRI","pt":1743511790129,"mc":[{"id":"1.241629436","rc":[{"atl":[[14.5,12.78]],"batl":[],"id":40389088},{"atl":[[9.4,31.05]],"batl":[[0,9.4,31.05]],"id":35856222},{"atb":[[4.8,98.37]],"batb":[],"id":56297029},{"atl":[[6.6,81.96]],"batl":[[0,6.6,81.96]],"id":26496185}]}]}
{"op":"mcm","id":2,"clk":"ANVPALAxAMxI","pt":1743511790230,"mc":[{"id":"1.241629436","rc":[{"atb":[[4.9,92.51]],"batb":[[2,4.9,92.51]],"id":56297029},{"atb":[[6.2,134.3],[6.4,93.09]],"trd":[[6.4,3186.89]],"batb":[[1,6.2,134.3],[0,6.4,93.09]],"tv":11790.78,"id":26496185},{"atb":[[11.5,19.12]],"batb":[[0,11.5,19.12]],"id":44049799}],"tv":71864.74}]}
{"op":"mcm","id":2,"clk":"AOFPALoxANRI","pt":1743511790327,"mc":[{"id":"1.241629436","rc":[{"atl":[[12,46.22]],"batl":[[0,12,46.22]],"id":40389088},{"atb":[[11.5,16.77]],"atl":[[12.5,45.26],[12,29.74]],"trd":[[11.5,634.17]],"batb":[[0,11.5,16.77]],"batl":[[1,12.5,45.26],[0,12,29.74]],"tv":4395.74,"id":44049799}],"tv":71871.44}]}
{"op":"mcm","id":2,"clk":"AOdPAL8xAN5I","pt":1743511790426,"mc":[{"id":"1.241629436","rc":[{"atb":[[11.5,13.18]],"trd":[[11.5,1023.09]],"batb":[[0,11.5,13.18]],"tv":6065.75,"id":40389088},{"atb":[[9.6,49.5]],"batb":[[2,9.6,49.5]],"id":27115873},{"atl":[[12.5,47.08],[12,31.72],[19,8.86]],"batl":[[1,12.5,47.08],[0,12,31.72]],"id":44049799}],"tv":71874.28}]}
{"op":"mcm","id":2,"clk":"APFPAMUxAOlI","pt":1743511790532,"mc":[{"id":"1.241629436","rc":[{"atb":[[11.5,0]],"atl":[[11.5,10.39]],"trd":[[11.5,1049.45]],"batb":[[2,10,50.98],[1,10.5,43.12],[0,11,103.69]],"batl":[[2,12.5,53.8],[1,12,46.22],[0,11.5,10.39]],"tv":6092.11,"id":40389088}],"tv":71900.64}]}
{"op":"mcm","id":2,"clk":"APxPAMwxAO9I","pt":1743511790646,"mc":[{"id":"1.241629436","rc":[{"atb":[[10,62.98]],"batb":[[2,10,62.98]],"id":40389088},{"atb":[[9.6,55.12]],"batb":[[2,9.6,55.12]],"id":27115873},{"atb":[[6.2,137.51]],"batb":[[1,6.2,137.51]],"id":26496185}]}]}
{"op":"mcm","id":2,"clk":"AIdQANExAPhI","pt":1743511790753,"mc":[{"id":"1.241629436","rc":[{"atl":[[14.5,11.45],[14,16.88],[13.5,16.85],[11.5,13.3]],"trd":[[11.5,1055.81]],"batl":[[0,11.5,13.3]],"tv":6098.47,"id":40389088},{"atl":[[19.5,7.93]],"batl":[],"id":58186642}],"tv":71907}]}
{"op":"mcm","id":2,"clk":"AItQANYxAP9I","pt":1743511790838,"mc":[{"id":"1.241629436","rc":[{"atl":[[12.5,45.26],[12,29.74]],"batl":[[1,12.5,45.26],[0,12,29.74]],"id":44049799}]}]}
{"op":"mcm","id":2,"clk":"AJZQAN0xAIZJ","pt":1743511790950,"mc":[{"id":"1.241629436","rc":[{"atb":[[1.17,2.87],[10,66.05]],"atl":[[1000,0.5],[12.5,53.65]],"batb":[[2,10,66.05]],"batl":[[2,12.5,53.65]],"id":40389088},{"atb":[[1.5,34]],"id":27115873},{"atb":[[1.17,2.55],[10.5,95.06],[10,77.98]],"atl":[[1000,18.98],[12.5,47.08],[12,31.72]],"batb":[[2,10.5,95.06]],"batl":[[1,12.5,47.08],[0,12,31.72]],"id":44049799}]}]}
{"op":"mcm","id":2,"clk":"AJtQAOMxAIpJ","pt":1743511791046,"mc":[{"id":"1.241629436","rc":[{"atb":[[1.17,2],[6,45.63]],"atl":[[1000,0.25]],"id":40389088},{"atb":[[1.17,2]],"atl":[[1000,18.87]],"id":44049799}]}]}
{"op":"mcm","id":2,"clk":"AKZQAOcxAJBJ","pt":1743511791149,"mc":[{"id":"1.241629436","rc":[{"atb":[[11,104.56]],"atl":[[12,46.47]],"batb":[[0,11,104.56]],"batl":[[1,12,46.47]],"id":40389088},{"atb":[[11.5,17.32]],"atl":[[12.5,47.19]],"batb":[[0,11.5,17.32]],"batl":[[1,12.5,47.19]],"id":44049799}]}]}
{"op":"mcm","id":2,"clk":"ALdQAPsxAJlJ","pt":1743511791351,"mc":[{"id":"1.241629436","rc":[{"atl":[[5.3,199.53]],"trd":[[5.3,1109.91]],"batl":[[0,5.3,199.53]],"ltp":5.3,"tv":16353.68,"id":270592},{"atb":[[5.1,176.77]],"trd":[[5.1,3211.15]],"batb":[[0,5.1,176.77]],"tv":12134.37,"id":56297029},{"atl":[[18,23.85]],"batl":[[2,18,23.85]],"id":58186642},{"atb":[[10,86.46]],"batb":[],"id":44049799}],"tv":71916.44}]}
{"op":"mcm","id":2,"clk":"AMdQAIIyAKhJ","pt":1743511791561,"mc":[{"id":"1.241629436","rc":[{"atb":[[9.6,31.76]],"atl":[[14,15.85]],"batb":[],"batl":[],"id":40389088},{"atb":[[9,94.99]],"trd":[[9,461.41]],"batb":[[0,9,94.99]],"ltp":9,"tv":8618.87,"id":35856222},{"atl":[[12.5,45.37],[12,29.74]],"batl":[[1,12.5,45.37],[0,12,29.74]],"id":44049799}],"tv":71929.44}]}
{"op":"mcm","id":2,"clk":"ANBQAIcyALRJ","pt":1743511791659,"mc":[{"id":"1.241629436","rc":[{"atb":[[5.2,201.02]],"atl":[[1000,23.16]],"trd":[[5.2,1613.84]],"batb":[[0,5.2,201.02]],"ltp":5.2,"tv":16360.34,"id":270592},{"atl":[[10,113.07]],"batl":[],"id":35856222}],"tv":71936.1}]}
{"op":"mcm","id":2,"clk":"ANdQAIsyALZJ","pt":1743511791714,"mc":[{"id":"1.241629436","rc":[{"atl":[[9.2,1.11]],"batl":[[2,9.6,56.22],[1,9.4,31.05],[0,9.2,1.11]],"id":35856222}]}]}
{"op":"mcm","id":2,"clk":"AOFQAJAyALpJ","pt":1743511791810,"mc":[{"id":"1.241629436","rc":[{"atl":[[1000,21.16]],"id":270592},{"atl":[[9.4,31.58],[9.2,17.15]],"trd":[[9.2,672.75]],"batl":[[1,9.4,31.58],[0,9.2,17.15]],"ltp":9.2,"tv":8621.09,"id":35856222},{"atb":[[11.5,34.58]],"atl":[[12.5,47.19],[12,31.72]],"batb":[[0,11.5,34.58]],"batl":[[1,12.5,47.19],[0,12,31.72]],"id":44049799}],"tv":71938.32}]}
{"op":"mcm","id":2,"clk":"AOlQAJoyAMBJ","pt":1743511791916,"mc":[{"id":"1.241629436","rc":[{"atb":[[1.17,7.32]],"atl":[[9.2,16.78]],"trd":[[9.2,673.49]],"batl":[[0,9.2,16.78]],"tv":8621.83,"id":35856222},{"atb":[[11.5,39.49]],"atl":[[14,20.51],[13.5,10.75]],"batb":[[0,11.5,39.49]],"batl":[],"id":44049799}],"tv":71939.06}]}
{"op":"mcm","id":2,"clk":"APNQAJ0yAMZJ","pt":1743511792021,"mc":[{"id":"1.241629436","rc":[{"atl":[[5.3,198.53]],"trd":[[5.3,1111.91]],"batl":[[0,5.3,198.53]],"ltp":5.3,"tv":16362.34,"id":270592},{"atb":[[10,77.98]],"atl":[[12,30.05]],"batb":[],"batl":[[0,12,30.05]],"id":44049799}],"tv":71941.06}]}
{"op":"mcm","id":2,"clk":"AP9QAKAyAMtJ","pt":1743511792123,"mc":[{"id":"1.241629436","rc":[{"atb":[[1.17,7.15]],"id":35856222},{"atl":[[12,20.67],[18.5,6.63]],"trd":[[12,66.15]],"batl":[[0,12,20.67]],"ltp":12,"tv":4414.49,"id":44049799}],"tv":71959.81}]}
{"op":"mcm","id":2,"clk":"AIZRAKMyANRJ","pt":1743511792223,"mc":[{"id":"1.241629436","rc":[{"atl":[[9.2,16.61]],"trd":[[9.2,673.83]],"batl":[[0,9.2,16.61]],"tv":8622.17,"id":35856222},{"atb":[[11.5,39.92]],"batb":[[0,11.5,39.92]],"id":44049799}],"tv":71960.15}]}
{"op":"mcm","id":2,"clk":"AJBRAK4yANtJ","pt":1743511792335,"mc":[{"id":"1.241629436","rc":[{"atb":[[1.17,2.28]],"id":40389088},{"atb":[[5.2,200.45]],"batb":[[0,5.2,200.45]],"id":270592},{"atl":[[9.2,14.92]],"trd":[[9.2,677.21]],"batl":[[0,9.2,14.92]],"tv":8625.55,"id":35856222},{"atl":[[70,14.15]],"batl":[[0,70,14.15]],"id":59626646},{"atb":[[5.1,176.18]],"batb":[[0,5.1,176.18]],"id":56297029},{"atb":[[16.5,25.65]],"batb":[[0,16.5,25.65]],"id":58186642},{"atb":[[11.5,39.37]],"atl":[[12.5,45.37],[12,18.69]],"batb":[[0,11.5,39.37]],"batl":[[1,12.5,45.37],[0,12,18.69]],"id":44049799}],"tv":71963.53}]}
{"op":"mcm","id":2,"clk":"AJlRALIyAOJJ","pt":1743511792428,"mc":[{"id":"1.241629436","rc":[{"atb":[[16.5,23.33]],"batb":[[0,16.5,23.33]],"id":58186642}]}]}
{"op":"mcm","id":2,"clk":"AKVRALsyAOhJ","pt":1743511792530,"mc":[{"id":"1.241629436","rc":[{"atb":[[1.17,2]],"id":40389088},{"atl":[[1000,23.16]],"id":270592},{"atl":[[18,18.88]],"batl":[[2,18,18.88]],"id":58186642},{"atb":[[11.5,34.25]],"atl":[[12,23.59]],"trd":[[11.5,644.41]],"batb":[[0,11.5,34.25]],"batl":[[0,12,23.59]],"ltp":11.5,"tv":4424.73,"id":44049799}],"tv":71973.77}]}
{"op":"mcm","id":2,"clk":"ALBRAMMyAPBJ","pt":1743511792645,"mc":[{"id":"1.241629436","rc":[{"atl":[[11.5,33.02]],"trd":[[11.5,1056.37]],"batl":[[0,11.5,33.02]],"tv":6099.03,"id":40389088},{"atl":[[5.4,103.77]],"batl":[[2,5.4,103.77]],"id":56297029},{"atl":[[12,24.74]],"batl":[[0,12,24.74]],"id":44049799}],"tv":71974.33}]}
{"op":"mcm","id":2,"clk":"ALdRAMkyAPNJ","pt":1743511792737,"mc":[{"id":"1.241629436","rc":[{"atl":[[12.5,57.62]],"batl":[[2,12.5,57.62]],"id":40389088}]}]}
{"op":"mcm","id":2,"clk":"AMBRAM8yAPdJ","pt":1743511792837,"mc":[{"id":"1.241629436","rc":[{"atl":[[1000,21.16]],"id":270592}]}]}
{"op":"mcm","id":2,"clk":"AM9RANkyAIdK","pt":1743511793044,"mc":[{"id":"1.241629436","rc":[{"atl":[[10,100.27]],"batl":[],"id":35856222}]}]}
{"op":"mcm","id":2,"clk":"AOdRAOgyAJNK","pt":1743511793278,"mc":[{"id":"1.241629436","rc":[{"atb":[[8.4,42.72]],"id":40389088}]}]}
{"op":"mcm","id":2,"clk":"AO9RAO8yAJpK","pt":1743511793364,"mc":[{"id":"1.241629436","rc":[{"atb":[[6.4,92.81]],"trd":[[6.4,3187.45]],"batb":[[0,6.4,92.81]],"tv":11791.34,"id":26496185}],"tv":71974.89}]}
{"op":"mcm","id":2,"clk":"AIlSAP4yAK1K","pt":1743511793611,"mc":[{"id":"1.241629436","rc":[{"atl":[[13,46.63]],"batl":[[2,13,46.63]],"id":44049799}]}]}
{"op":"mcm","id":2,"clk":"AJtSAIgzAMBK","pt":1743511793814,"mc":[{"id":"1.241629436","rc":[{"atb":[[11.5,46.36]],"batb":[[0,11.5,46.36]],"id":44049799}]}]}
{"op":"mcm","id":2,"clk":"AKhSAJAzAMpK","pt":1743511793926,"mc":[{"id":"1.241629436","rc":[{"atl":[[12.5,47.19]],"batl":[[1,12.5,47.19]],"id":44049799}]}]}
{"op":"mcm","id":2,"clk":"ALJSAJYzANRK","pt":1743511794025,"mc":[{"id":"1.241629436","rc":[{"atl":[[5.5,66.52]],"batl":[],"id":56297029},{"atl":[[19.5,7.85]],"batl":[],"id":58186642},{"atb":[[11,106.34]],"batb":[[1,11,106.34]],"id":44049799}]}]}
{"op":"mcm","id":2,"clk":"ANZSAKUzAO1K","pt":1743511794343,"mc":[{"id":"1.241629436","rc":[{"atl":[[9.2,22.02]],"batl":[[0,9.2,22.02]],"id":35856222}]}]}
{"op":"mcm","id":2,"clk":"ANxSAKwzAPJK","pt":1743511794442,"mc":[{"id":"1.241629436","rc":[{"atb":[[12,23.22]],"batb":[],"id":58186642}]}]}
{"op":"mcm","id":2,"clk":"APhSALgzAIZL","pt":1743511794740,"mc":[{"id":"1.241629436","rc":[{"atl":[[12,46.31]],"batl":[[1,12,46.31]],"id":40389088},{"atl":[[9.4,31.48]],"batl":[[1,9.4,31.48]],"id":35856222},{"atb":[[60,18.71]],"atl":[[70,10.64]],"batb":[[1,60,18.71]],"batl":[[0,70,10.64]],"id":59626646},{"atb":[[16,22.22],[16.5,23.38]],"atl":[[17.5,53.37],[17,13.91]],"batb":[[1,16,22.22],[0,16.5,23.38]],"batl":[[1,17.5,53.37],[0,17,13.91]],"id":58186642},{"atb":[[10.5,91.76]],"batb":[[2,10.5,91.76]],"id":44049799}]}]}
{"op":"mcm","id":2,"clk":"AIZTAMMzAJdL","pt":1743511794946,"mc":[{"id":"1.241629436","rc":[{"atb":[[5.2,199.45]],"trd":[[5.2,1615.84]],"batb":[[0,5.2,199.45]],"ltp":5.2,"tv":16364.34,"id":270592}],"tv":71976.89}]}
{"op":"mcm","id":2,"clk":"AJxTAMozAK1L","pt":1743511795248,"mc":[{"id":"1.241629436","rc":[{"atb":[[5.2,211.45]],"atl":[[5.3,210.53]],"batb":[[0,5.2,211.45]],"batl":[[0,5.3,210.53]],"id":270592}]}]}
{"op":"mcm","id":2,"clk":"AKtTANUzALhL","pt":1743511795407,"mc":[{"id":"1.241629436","rc":[{"atb":[[4.7,145.5]],"batb":[],"id":270592}]}]}
{"op":"mcm","id":2,"clk":"AL5TAOIzAMNL","pt":1743511795616,"mc":[{"id":"1.241629436","rc":[{"atl":[[5.5,137.71]],"batl":[[2,5.5,137.71]],"id":270592}]}]}
{"op":"mcm","id":2,"clk":"AMdTAOczAMpL","pt":1743511795725,"mc":[{"id":"1.241629436","rc":[{"atb":[[4.9,96.23]],"batb":[[2,4.9,96.23]],"id":56297029}]}]}
{"op":"mcm","id":2,"clk":"AOtTAIQ0APFL","pt":1743511796325,"mc":[{"id":"1.241629436","rc":[{"atl":[[10,113.07]],"batl":[],"id":35856222}]}]}
{"op":"mcm","id":2,"clk":"AO9TAIk0APlL","pt":1743511796423,"mc":[{"id":"1.241629436","rc":[{"atb":[[16.5,13.38]],"trd":[[16.5,330.32]],"batb":[[0,16.5,13.38]],"ltp":16.5,"tv":4859,"id":58186642}],"tv":71996.89}]}
{"op":"mcm","id":2,"clk":"APNTAJI0AIFM","pt":1743511796529,"mc":[{"id":"1.241629436","rc":[{"atb":[[16,31.16],[16.5,8.76]],"atl":[[17,17.59]],"batb":[[1,16,31.16],[0,16.5,8.76]],"batl":[[0,17,17.59]],"id":58186642}]}]}
{"op":"mcm","id":2,"clk":"APxTAJw0AIpM","pt":1743511796635,"mc":[{"id":"1.241629436","rc":[{"atb":[[16.5,0]],"atl":[[19,11.29],[16.5,11.38]],"trd":[[16.5,342.4]],"batb":[[2,15,12.46],[1,15.5,46.43],[0,16,31.16]],"batl":[[2,17.5,53.37],[1,17,17.59],[0,16.5,11.38]],"tv":4871.08,"id":58186642}],"tv":72008.97}]}
{"op":"mcm","id":2,"clk":"AIRUAJ80AI9M","pt":1743511796735,"mc":[{"id":"1.241629436","rc":[{"atb":[[9,102.9]],"batb":[[0,9,102.9]],"id":35856222},{"atb":[[10,79.63]],"batb":[[0,10,79.63]],"id":27115873},{"atb":[[15,21.46],[16,27.78]],"atl":[[21,11.11],[17,19.99],[16.5,14.88]],"batb":[[2,15,21.46],[0,16,27.78]],"batl":[[1,17,19.99],[0,16.5,14.88]],"id":58186642},{"atb":[[11.5,55.09]],"batb":[[0,11.5,55.09]],"id":44049799}]}]}
{"op":"mcm","id":2,"clk":"AItUAKU0AJVM","pt":1743511796835,"mc":[{"id":"1.241629436","rc":[{"atb":[[15.5,35.44]],"batb":[[1,15.5,35.44]],"id":58186642}]}]}
{"op":"mcm","id":2,"clk":"AJZUAK80AJtM","pt":1743511796942,"mc":[{"id":"1.241629436","rc":[{"atb":[[16,25.79]],"batb":[[0,16,25.79]],"id":58186642},{"atl":[[12,18.07]],"batl":[[0,12,18.07]],"id":44049799}]}]}
