{"op":"mcm","id":2,"clk":"AJ1UALc0AKJM","pt":1743511797043,"mc":[{"id":"1.241629436","rc":[{"atl":[[1000,23.16]],"id":270592}]}]}
{"op":"mcm","id":2,"clk":"ALhUAMU0ALlM","pt":1743511797361,"mc":[{"id":"1.241629436","rc":[{"atb":[[6,50.63]],"id":40389088},{"atl":[[1000,21.16]],"id":270592},{"atl":[[10,100.27]],"batl":[],"id":35856222},{"atb":[[5.1,172.52]],"batb":[[0,5.1,172.52]],"id":56297029},{"atb":[[11.5,56.45]],"batb":[[0,11.5,56.45]],"id":44049799}]}]}
{"op":"mcm","id":2,"clk":"ANFUANc0ANRM","pt":1743511797712,"mc":[{"id":"1.241629436","rc":[{"atb":[[1.17,2.23]],"id":40389088},{"atb":[[1.17,1.72]],"atl":[[1000,21.31]],"id":270592},{"atb":[[1.17,7.62]],"id":35856222}]}]}
{"op":"mcm","id":2,"clk":"ANpUANw0ANpM","pt":1743511797816,"mc":[{"id":"1.241629436","rc":[{"atb":[[1.17,1]],"atl":[[1000,21.16]],"id":270592},{"atb":[[1.17,7.15]],"id":35856222}]}]}
{"op":"mcm","id":2,"clk":"AOVUAOk0AONM","pt":1743511797922,"mc":[{"id":"1.241629436","rc":[{"atb":[[1.17,2]],"id":40389088},{"atb":[[5.2,212.17]],"atl":[[5.4,184.24]],"batb":[[0,5.2,212.17]],"batl":[[1,5.4,184.24]],"id":270592},{"atb":[[9,103.37]],"batb":[[0,9,103.37]],"id":35856222}]}]}
{"op":"mcm","id":2,"clk":"AOpUAO00AOlM","pt":1743511798014,"mc":[{"id":"1.241629436","rc":[{"atb":[[11,104.79]],"batb":[[0,11,104.79]],"id":40389088},{"atl":[[1000,23.16]],"id":270592}]}]}
{"op":"mcm","id":2,"clk":"APFUAPM0APFM","pt":1743511798117,"mc":[{"id":"1.241629436","rc":[{"atb":[[16,67.48]],"atl":[[17.5,15.26]],"batb":[[0,16,67.48]],"batl":[[2,17.5,15.26]],"id":58186642},{"atb":[[11.5,51.51]],"atl":[[12,73.65]],"trd":[[11.5,654.29]],"batb":[[0,11.5,51.51]],"batl":[[0,12,73.65]],"tv":4434.61,"id":44049799}],"tv":72018.85}]}
{"op":"mcm","id":2,"clk":"APpUAPk0APxM","pt":1743511798233,"mc":[{"id":"1.241629436","rc":[{"atl":[[1000,21.16]],"id":270592},{"atb":[[16,70.96]],"atl":[[16.5,12.64]],"trd":[[16.5,346.88]],"batb":[[0,16,70.96]],"batl":[[0,16.5,12.64]],"tv":4875.56,"id":58186642},{"atb":[[11.5,42.35]],"atl":[[12,81.99]],"batb":[[0,11.5,42.35]],"batl":[[0,12,81.99]],"id":44049799}],"tv":72023.33}]}
{"op":"mcm","id":2,"clk":"AIJVAP40AINN","pt":1743511798326,"mc":[{"id":"1.241629436","rc":[{"atb":[[5.1,169.88]],"trd":[[5.1,3216.43]],"batb":[[0,5.1,169.88]],"tv":12139.65,"id":56297029},{"atb":[[15,23.87]],"atl":[[16.5,0]],"batb":[[2,15,23.87]],"batl":[[2,18,18.88],[1,17.5,15.26],[0,17,19.99]],"id":58186642},{"atb":[[11.5,25.09]],"batb":[[0,11.5,25.09]],"id":44049799}],"tv":72028.61}]}
{"op":"mcm","id":2,"clk":"AItVAII1AI5N","pt":1743511798433,"mc":[{"id":"1.241629436","rc":[{"atb":[[4.9,95.22]],"batb":[[2,4.9,95.22]],"id":56297029},{"atb":[[16.5,15.54],[16,69.96]],"batb":[[2,15.5,35.44],[1,16,69.96],[0,16.5,15.54]],"id":58186642},{"atl":[[12,82.41]],"batl":[[0,12,82.41]],"id":44049799}]}]}
{"op":"mcm","id":2,"clk":"AJZVAIQ1AJRN","pt":1743511798532,"mc":[{"id":"1.241629436","rc":[{"atb":[[4.9,96.23]],"batb":[[2,4.9,96.23]],"id":56297029},{"atb":[[16.5,23.54]],"atl":[[17,14.2]],"batb":[[0,16.5,23.54]],"batl":[[0,17,14.2]],"id":58186642},{"atb":[[11.5,31.38]],"batb":[[0,11.5,31.38]],"id":44049799}]}]}
{"op":"mcm","id":2,"clk":"AJ5VAIs1AJ9N","pt":1743511798637,"mc":[{"id":"1.241629436","rc":[{"atb":[[16.5,27.12]],"batb":[[0,16.5,27.12]],"id":58186642}]}]}
{"op":"mcm","id":2,"clk":"AK1VAJs1AKxN","pt":1743511798841,"mc":[{"id":"1.241629436","rc":[{"atb":[[6,45.63]],"id":40389088},{"atb":[[4.9,94.23]],"batb":[[2,4.9,94.23]],"id":56297029}]}]}
{"op":"mcm","id":2,"clk":"ALRVAKI1ALFN","pt":1743511798945,"mc":[{"id":"1.241629436","rc":[{"atb":[[11.5,30.38]],"trd":[[11.5,656.29]],"batb":[[0,11.5,30.38]],"tv":4436.61,"id":44049799}],"tv":72030.61}]}
{"op":"mcm","id":2,"clk":"ALtVAKo1ALpN","pt":1743511799044,"mc":[{"id":"1.241629436","rc":[{"atl":[[10,113.07]],"batl":[],"id":35856222}]}]}
{"op":"mcm","id":2,"clk":"ANlVALs1ANBN","pt":1743511799356,"mc":[{"id":"1.241629436","rc":[{"atl":[[11,65.41]],"batl":[[1,11,65.41]],"id":27115873}]}]}
{"op":"mcm","id":2,"clk":"AOBVAL41ANdN","pt":1743511799459,"mc":[{"id":"1.241629436","rc":[{"atb":[[11.5,27.34]],"trd":[[11.5,662.37]],"batb":[[0,11.5,27.34]],"tv":4442.69,"id":44049799}],"tv":72036.69}]}
{"op":"mcm","id":2,"clk":"APFVAMY1AN9N","pt":1743511799618,"mc":[{"id":"1.241629436","rc":[{"atb":[[4.7,46.43]],"batb":[],"id":56297029}]}]}
{"op":"mcm","id":2,"clk":"AJlWANA1APhN","pt":1743511800025,"mc":[{"id":"1.241629436","rc":[{"atl":[[10,100.27]],"batl":[],"id":35856222}]}]}
{"op":"mcm","id":2,"clk":"ALdWAN81AJNO","pt":1743511800444,"mc":[{"id":"1.241629436","rc":[{"atl":[[13,44.96],[12.5,45.37]],"batl":[[2,13,44.96],[1,12.5,45.37]],"id":44049799}]}]}
{"op":"mcm","id":2,"clk":"AL9WAOY1AJtO","pt":1743511800546,"mc":[{"id":"1.241629436","rc":[{"atl":[[14.5,24.38]],"batl":[],"id":44049799}]}]}
{"op":"mcm","id":2,"clk":"AMZWAO01AKZO","pt":1743511800651,"mc":[{"id":"1.241629436","rc":[{"atb":[[11,104.56]],"atl":[[12.5,53.65]],"batb":[[0,11,104.56]],"batl":[[2,12.5,53.65]],"id":40389088},{"atb":[[5.2,211.45]],"atl":[[5.4,184.09]],"batb":[[0,5.2,211.45]],"batl":[[1,5.4,184.09]],"id":270592},{"atb":[[9,102.9]],"batb":[[0,9,102.9]],"id":35856222},{"atl":[[10.5,104.57]],"trd":[[10.5,541.21]],"batl":[[0,10.5,104.57]],"ltp":10.5,"tv":6088.87,"id":27115873},{"atb":[[1.17,2.42]],"id":58186642},{"atb":[[6.4,91.61]],"batb":[[0,6.4,91.61]],"id":26496185},{"atl":[[13,46.63],[12.5,47.19]],"batl":[[2,13,46.63],[1,12.5,47.19]],"id":44049799}],"tv":72044.43}]}
{"op":"mcm","id":2,"clk":"ANFWAPE1AKxO","pt":1743511800751,"mc":[{"id":"1.241629436","rc":[{"atb":[[1.17,2]],"atl":[[17.5,17.63]],"batl":[[1,17.5,17.63]],"id":58186642},{"atl":[[13,44.96],[12.5,45.37]],"batl":[[2,13,44.96],[1,12.5,45.37]],"id":44049799}]}]}
{"op":"mcm","id":2,"clk":"ANlWAPU1ALBO","pt":1743511800847,"mc":[{"id":"1.241629436","rc":[{"atb":[[16.5,27.54]],"batb":[[0,16.5,27.54]],"id":58186642}]}]}
{"op":"mcm","id":2,"clk":"AONWAPo1ALZO","pt":1743511800952,"mc":[{"id":"1.241629436","rc":[{"atl":[[13.5,15.68],[13,46.63],[12.5,47.19]],"batl":[[2,13,46.63],[1,12.5,47.19]],"id":44049799}]}]}
{"op":"mcm","id":2,"clk":"AO1WAP81AL1O","pt":1743511801061,"mc":[{"id":"1.241629436","rc":[{"atb":[[11.5,22.43]],"batb":[[0,11.5,22.43]],"id":44049799}]}]}
{"op":"mcm","id":2,"clk":"APdWAIQ2AMlO","pt":1743511801257,"mc":[{"id":"1.241629436","rc":[{"atl":[[6.6,48.96]],"trd":[[6.6,1748.4]],"batl":[[0,6.6,48.96]],"ltp":6.6,"tv":11857.34,"id":26496185}],"tv":72110.43}]}
{"op":"mcm","id":2,"clk":"AP5WAIg2ANFO","pt":1743511801360,"mc":[{"id":"1.241629436","rc":[{"atb":[[6.4,96.26]],"batb":[[0,6.4,96.26]],"id":26496185},{"atb":[[11.5,0]],"atl":[[11.5,15.75]],"trd":[[11.5,707.22]],"batb":[[2,10,77.98],[1,10.5,91.76],[0,11,106.34]],"batl":[[2,12.5,47.19],[1,12,82.41],[0,11.5,15.75]],"tv":4487.54,"id":44049799}],"tv":72155.28}]}
{"op":"mcm","id":2,"clk":"AIJXAI82ANVO","pt":1743511801409,"mc":[{"id":"1.241629436","rc":[{"atb":[[6.4,111.97]],"batb":[[0,6.4,111.97]],"id":26496185},{"atl":[[11.5,14.75]],"trd":[[11.5,709.22]],"batl":[[0,11.5,14.75]],"tv":4489.54,"id":44049799}],"tv":72157.28}]}
{"op":"mcm","id":2,"clk":"AItXAJk2AONO","pt":1743511801575,"mc":[{"id":"1.241629436","rc":[{"atl":[[5.6,72.96]],"batl":[],"id":270592},{"atb":[[4.9,93.22],[5.1,172.32]],"batb":[[2,4.9,93.22],[0,5.1,172.32]],"id":56297029},{"atb":[[11,122.7]],"atl":[[13,44.96],[12.5,45.37]],"batb":[[0,11,122.7]],"batl":[[2,12.5,45.37]],"id":44049799}]}]}
{"op":"mcm","id":2,"clk":"AJJXAJ42AOZO","pt":1743511801626,"mc":[{"id":"1.241629436","rc":[{"atb":[[1.17,7.97],[9,104.14]],"atl":[[10,113.07]],"batb":[[0,9,104.14]],"batl":[],"id":35856222},{"atl":[[17,13.75]],"batl":[[0,17,13.75]],"id":58186642},{"atb":[[9.8,33.57]],"batb":[],"id":44049799}]}]}
{"op":"mcm","id":2,"clk":"AJxXAKc2AO9O","pt":1743511801725,"mc":[{"id":"1.241629436","rc":[{"atb":[[4.8,99.4]],"batb":[],"id":56297029},{"atb":[[10.5,70.74]],"batb":[[1,10.5,70.74]],"id":44049799}]}]}
{"op":"mcm","id":2,"clk":"AKVXAK02APRO","pt":1743511801827,"mc":[{"id":"1.241629436","rc":[{"atb":[[1.17,7.15]],"id":35856222},{"atb":[[9.8,32.57],[11,143.72]],"batb":[[0,11,143.72]],"id":44049799}]}]}
{"op":"mcm","id":2,"clk":"AK5XALg2APtO","pt":1743511801938,"mc":[{"id":"1.241629436","rc":[{"atl":[[9.2,21.2]],"trd":[[9.2,678.85]],"batl":[[0,9.2,21.2]],"tv":8627.19,"id":35856222},{"atl":[[13,46.63],[12.5,47.19]],"batl":[[2,12.5,47.19]],"id":44049799}],"tv":72158.92}]}
{"op":"mcm","id":2,"clk":"AMZXAMc2AIZP","pt":1743511802146,"mc":[{"id":"1.241629436","rc":[{"atb":[[11,99.56]],"trd":[[11,58.61]],"batb":[[0,11,99.56]],"ltp":11,"tv":6109.04,"id":40389088},{"atl":[[11.5,18.08]],"batl":[[0,11.5,18.08]],"id":44049799}],"tv":72168.93}]}
{"op":"mcm","id":2,"clk":"ANJXANc2AJNP","pt":1743511802344,"mc":[{"id":"1.241629436","rc":[{"atb":[[1.01,53842.38]],"id":40389088}]}]}
{"op":"mcm","id":2,"clk":"ANtXANw2AJlP","pt":1743511802446,"mc":[{"id":"1.241629436","rc":[{"atl":[[1000,23.16]],"id":270592}]}]}
{"op":"mcm","id":2,"clk":"AOJXAN42AKNP","pt":1743511802550,"mc":[{"id":"1.241629436","rc":[{"atb":[[28,0],[8.8,0],[7.6,0],[22,2.21],[21,7.16],[4.6,0],[18,2.7],[18.5,3.62],[5.6,0],[15.5,3.13],[8.4,0],[14,0],[1.51,0],[3.8,0],[2.04,0],[11.5,0],[11,0],[10.5,0],[5.2,0],[6.2,0],[3.95,0],[7.2,0],[65,7.27],[9.6,0],[3.5,5],[3.1,0]],"atl":[[160,0]],"trd":[[65,107.84]],"batb":[[0,65,7.27]],"tv":1617.82,"id":59626646}],"tv":72169.35}]}
{"op":"mcm","id":2,"clk":"AO5XAOU2AKtP","pt":1743511802658,"mc":[{"id":"1.241629436","rc":[{"atl":[[1000,21.16]],"id":270592},{"atl":[[10,100.27]],"batl":[],"id":35856222}]}]}
{"op":"mcm","id":2,"clk":"APRXAOs2ALNP","pt":1743511802763,"mc":[{"id":"1.241629436","rc":[{"atb":[[10.5,72.1]],"atl":[[13,44.96],[12.5,45.37]],"batb":[[1,10.5,72.1]],"batl":[[2,12.5,45.37]],"id":44049799}]}]}
{"op":"mcm","id":2,"clk":"AJJYAPc2AMVP","pt":1743511803019,"mc":[{"id":"1.241629436","rc":[{"atb":[[6.4,159.65]],"batb":[[0,6.4,159.65]],"id":26496185}]}]}
{"op":"mcm","id":2,"clk":"AJtYAPw2AM1P","pt":1743511803122,"mc":[{"id":"1.241629436","rc":[{"atb":[[6.4,160.43]],"atl":[[6.6,33.88]],"batb":[[0,6.4,160.43]],"batl":[[0,6.6,33.88]],"id":26496185},{"atb":[[11,144.86]],"atl":[[1000,19.1],[13,46.63],[12.5,47.08]],"batb":[[0,11,144.86]],"batl":[[2,12.5,47.08]],"id":44049799}]}]}
{"op":"mcm","id":2,"clk":"ALRYAIs3AN5P","pt":1743511803335,"mc":[{"id":"1.241629436","rc":[{"atl":[[1000,18.87],[12.5,53.05]],"batl":[[2,12.5,53.05]],"id":44049799}]}]}
{"op":"mcm","id":2,"clk":"AL5YAJI3AOVP","pt":1743511803430,"mc":[{"id":"1.241629436","rc":[{"atl":[[1000,23.16]],"id":270592},{"atb":[[6.4,159.43]],"trd":[[6.4,3189.45]],"batb":[[0,6.4,159.43]],"ltp":6.4,"tv":11859.34,"id":26496185},{"atl":[[12,82.64]],"batl":[[1,12,82.64]],"id":44049799}],"tv":72171.35}]}
{"op":"mcm","id":2,"clk":"AMhYAJc3APBP","pt":1743511803536,"mc":[{"id":"1.241629436","rc":[{"atl":[[70,9.41]],"trd":[[70,66.02]],"batl":[[0,70,9.41]],"ltp":70,"tv":1620.28,"id":59626646},{"atl":[[6.6,35.38]],"batl":[[0,6.6,35.38]],"id":26496185}],"tv":72173.81}]}
{"op":"mcm","id":2,"clk":"AM9YAJ43APhP","pt":1743511803632,"mc":[{"id":"1.241629436","rc":[{"atl":[[1000,0.56]],"id":40389088},{"atl":[[1000,21.16]],"id":270592},{"atl":[[1000,0.61]],"id":35856222},{"atb":[[60,19.46]],"atl":[[70,13.07]],"batb":[[1,60,19.46]],"batl":[[0,70,13.07]],"id":59626646}]}]}
{"op":"mcm","id":2,"clk":"ANlYAKQ3AIFQ","pt":1743511803741,"mc":[{"id":"1.241629436","rc":[{"atl":[[1000,0.25]],"id":40389088},{"atl":[[1000,0.41]],"id":35856222},{"atl":[[70,14.62]],"batl":[[0,70,14.62]],"id":59626646}]}]}
{"op":"mcm","id":2,"clk":"AONYAKs3AIZQ","pt":1743511803841,"mc":[{"id":"1.241629436","rc":[{"atl":[[11.5,33.33]],"batl":[[0,11.5,33.33]],"id":40389088},{"atl":[[9.2,21.4]],"batl":[[0,9.2,21.4]],"id":35856222}]}]}
{"op":"mcm","id":2,"clk":"AO1YALQ3AIpQ","pt":1743511803943,"mc":[{"id":"1.241629436","rc":[{"atb":[[10,83.63]],"batb":[[0,10,83.63]],"id":27115873}]}]}
{"op":"mcm","id":2,"clk":"APdYALo3AI9Q","pt":1743511804050,"mc":[{"id":"1.241629436","rc":[{"atl":[[10,113.07]],"batl":[],"id":35856222}]}]}
{"op":"mcm","id":2,"clk":"AIRZAMc3AJ5Q","pt":1743511804251,"mc":[{"id":"1.241629436","rc":[{"atb":[[4.8,114.72]],"batb":[],"id":270592},{"atl":[[13,44.96],[12.5,51.23]],"batl":[[2,12.5,51.23]],"id":44049799}]}]}
{"op":"mcm","id":2,"clk":"AItZAMw3AKNQ","pt":1743511804350,"mc":[{"id":"1.241629436","rc":[{"atb":[[19,2.55]],"id":59626646}]}]}
{"op":"mcm","id":2,"clk":"AJRZANc3AKpQ","pt":1743511804452,"mc":[{"id":"1.241629436","rc":[{"atb":[[16.5,7.94]],"id":59626646}]}]}
{"op":"mcm","id":2,"clk":"AKZZAOU3ALxQ","pt":1743511804661,"mc":[{"id":"1.241629436","rc":[{"atb":[[8.4,44.3]],"batb":[],"id":27115873}]}]}
{"op":"mcm","id":2,"clk":"ALBZAOw3AMdQ","pt":1743511804767,"mc":[{"id":"1.241629436","rc":[{"atl":[[75,5.14]],"batl":[[1,75,5.14]],"id":59626646}]}]}
{"op":"mcm","id":2,"clk":"ALtZAPU3ANBQ","pt":1743511804826,"mc":[{"id":"1.241629436","rc":[{"atl":[[13,46.63],[12.5,53.05]],"batl":[[2,12.5,53.05]],"id":44049799}]}]}
{"op":"mcm","id":2,"clk":"AMlZAIU4AORQ","pt":1743511805024,"mc":[{"id":"1.241629436","rc":[{"atl":[[10,100.27]],"batl":[],"id":35856222}]}]}
{"op":"mcm","id":2,"clk":"AO1ZAJo4AIFR","pt":1743511805430,"mc":[{"id":"1.241629436","rc":[{"atb":[[10,77.63]],"trd":[[10,343.52]],"batb":[[0,10,77.63]],"ltp":10,"tv":6100.87,"id":27115873},{"atl":[[13,44.96],[12.5,51.23]],"batl":[[2,12.5,51.23]],"id":44049799}],"tv":72185.81}]}
{"op":"mcm","id":2,"clk":"APVZAJ04AIdR","pt":1743511805537,"mc":[{"id":"1.241629436","rc":[{"atb":[[10.5,70.61]],"batb":[[1,10.5,70.61]],"id":44049799}]}]}
{"op":"mcm","id":2,"clk":"AL1aAMA4AOBR","pt":1743511806461,"mc":[{"id":"1.241629436","rc":[{"atl":[[9.2,21.2]],"batl":[[0,9.2,21.2]],"id":35856222},{"atb":[[16.5,27.12]],"batb":[[0,16.5,27.12]],"id":58186642},{"atl":[[1000,19.14]],"id":44049799}]}]}
{"op":"mcm","id":2,"clk":"AMlaAMM4AOlR","pt":1743511806565,"mc":[{"id":"1.241629436","rc":[{"atl":[[11.5,33.02]],"batl":[[0,11.5,33.02]],"id":40389088}]}]}
{"op":"mcm","id":2,"clk":"AM5aAMw4APVR","pt":1743511806661,"mc":[{"id":"1.241629436","rc":[{"atb":[[9,107.1]],"batb":[[0,9,107.1]],"id":35856222},{"atl":[[70,14.38]],"batl":[[0,70,14.38]],"id":59626646},{"atl":[[1000,18.87]],"id":44049799}]}]}
{"op":"mcm","id":2,"clk":"ANZaANI4AP1R","pt":1743511806721,"mc":[{"id":"1.241629436","rc":[{"atb":[[5.1,177.59]],"batb":[[0,5.1,177.59]],"id":56297029},{"atl":[[11.5,18.35]],"batl":[[0,11.5,18.35]],"id":44049799}]}]}
{"op":"mcm","id":2,"clk":"AOVaANc4AIVS","pt":1743511806824,"mc":[{"id":"1.241629436","rc":[{"atb":[[65,6.27]],"trd":[[65,109.84]],"batb":[[0,65,6.27]],"ltp":65,"tv":1622.28,"id":59626646}],"tv":72187.81}]}
{"op":"mcm","id":2,"clk":"AMJbAIw5ANRS","pt":1743511807848,"mc":[{"id":"1.241629436","rc":[{"atl":[[1000,23.16]],"id":270592}]}]}
{"op":"mcm","id":2,"clk":"AMxbAJI5ANxS","pt":1743511807956,"mc":[{"id":"1.241629436","rc":[{"atb":[[28,1.99]],"atl":[[160,1]],"id":59626646}]}]}
{"op":"mcm","id":2,"clk":"ANRbAJU5AOBS","pt":1743511808051,"mc":[{"id":"1.241629436","rc":[{"atl":[[1000,21.16]],"id":270592},{"atl":[[5.3,83.72]],"batl":[[1,5.3,83.72]],"id":56297029}]}]}
{"op":"mcm","id":2,"clk":"AIRcAK45AIxT","pt":1743511808564,"mc":[{"id":"1.241629436","rc":[{"atl":[[1000,23.16]],"id":270592}]}]}
{"op":"mcm","id":2,"clk":"AI5cALA5AJZT","pt":1743511808616,"mc":[{"id":"1.241629436","rc":[{"atl":[[6.6,35.08]],"trd":[[6.6,1749]],"batl":[[0,6.6,35.08]],"ltp":6.6,"tv":11859.94,"id":26496185}],"tv":72188.41}]}
{"op":"mcm","id":2,"clk":"AJdcALU5AKFT","pt":1743511808726,"mc":[{"id":"1.241629436","rc":[{"atl":[[1000,21.16]],"id":270592}]}]}
{"op":"mcm","id":2,"clk":"AKFcALs5AKxT","pt":1743511808824,"mc":[{"id":"1.241629436","rc":[{"atl":[[1000,23.16]],"id":270592}]}]}
{"op":"mcm","id":2,"clk":"ALdcAMc5ALpT","pt":1743511809025,"mc":[{"id":"1.241629436","rc":[{"atl":[[1000,21.16]],"id":270592}]}]}
{"op":"mcm","id":2,"clk":"ANdcANM5AM9T","pt":1743511809335,"mc":[{"id":"1.241629436","rc":[{"atl":[[12,94.24]],"batl":[[1,12,94.24]],"id":44049799}]}]}
{"op":"mcm","id":2,"clk":"AOJcANk5ANZT","pt":1743511809437,"mc":[{"id":"1.241629436","rc":[{"atl":[[6.6,53.69]],"batl":[[0,6.6,53.69]],"id":26496185},{"atb":[[11,146.63]],"batb":[[0,11,146.63]],"id":44049799}]}]}
{"op":"mcm","id":2,"clk":"AO1cAN85AN5T","pt":1743511809542,"mc":[{"id":"1.241629436","rc":[{"atb":[[1.17,7.36]],"id":35856222},{"atb":[[5.1,193.35]],"batb":[[0,5.1,193.35]],"id":56297029},{"atl":[[1000,19.24]],"id":44049799}]}]}
{"op":"mcm","id":2,"clk":"APZcAOI5AONT","pt":1743511809643,"mc":[{"id":"1.241629436","rc":[{"atl":[[1000,18.87]],"id":44049799}]}]}
{"op":"mcm","id":2,"clk":"AP5cAOc5AOlT","pt":1743511809745,"mc":[{"id":"1.241629436","rc":[{"atb":[[1.17,7.15]],"id":35856222},{"atl":[[12,94.61]],"batl":[[1,12,94.61]],"id":44049799}]}]}
{"op":"mcm","id":2,"clk":"AIddAOw5APBT","pt":1743511809848,"mc":[{"id":"1.241629436","rc":[{"atb":[[9,107.31]],"batb":[[0,9,107.31]],"id":35856222}]}]}
{"op":"mcm","id":2,"clk":"AJRdAPA5APtT","pt":1743511809961,"mc":[{"id":"1.241629436","rc":[{"atb":[[10,67.63]],"trd":[[10,363.52]],"batb":[[0,10,67.63]],"tv":6120.87,"id":27115873},{"atl":[[17,11.11]],"trd":[[17,561.76]],"batl":[[0,17,11.11]],"ltp":17,"tv":4880.84,"id":58186642}],"tv":72213.69}]}
{"op":"mcm","id":2,"clk":"AJldAPM5AIFU","pt":1743511810064,"mc":[{"id":"1.241629436","rc":[{"atl":[[5.3,199.53]],"trd":[[5.3,1133.91]],"batl":[[0,5.3,199.53]],"ltp":5.3,"tv":16386.34,"id":270592}],"tv":72235.69}]}
{"op":"mcm","id":2,"clk":"AKtdAPg5AI9U","pt":1743511810259,"mc":[{"id":"1.241629436","rc":[{"atb":[[5.2,236.24]],"batb":[[0,5.2,236.24]],"id":270592}]}]}
{"op":"mcm","id":2,"clk":"ALhdAPs5AJhU","pt":1743511810362,"mc":[{"id":"1.241629436","rc":[{"atb":[[5.1,376.3]],"batb":[[1,5.1,376.3]],"id":270592},{"atb":[[16.5,30.51]],"batb":[[0,16.5,30.51]],"id":58186642}]}]}
{"op":"mcm","id":2,"clk":"AM1dAIQ6AKlU","pt":1743511810566,"mc":[{"id":"1.241629436","rc":[{"atb":[[5.1,384.84]],"batb":[[1,5.1,384.84]],"id":270592},{"atb":[[4.8,98.37]],"batb":[],"id":56297029},{"atl":[[17,10.82]],"batl":[[0,17,10.82]],"id":58186642}]}]}
{"op":"mcm","id":2,"clk":"ANZdAIY6AK9U","pt":1743511810622,"mc":[{"id":"1.241629436","rc":[{"atb":[[4.9,94.23]],"batb":[[2,4.9,94.23]],"id":56297029},{"atb":[[6.4,160.98]],"batb":[[0,6.4,160.98]],"id":26496185}]}]}
{"op":"mcm","id":2,"clk":"AOFdAIs6ALdU","pt":1743511810772,"mc":[{"id":"1.241629436","rc":[{"atl":[[5.3,189.51]],"trd":[[5.3,1153.95]],"batl":[[0,5.3,189.51]],"tv":16406.38,"id":270592}],"tv":72255.73}]}
{"op":"mcm","id":2,"clk":"AOldAJA6AL5U","pt":1743511810819,"mc":[{"id":"1.241629436","rc":[{"atb":[[5.1,202.4]],"batb":[[0,5.1,202.4]],"id":56297029}]}]}
{"op":"mcm","id":2,"clk":"APJdAJU6AMdU","pt":1743511810934,"mc":[{"id":"1.241629436","rc":[{"atl":[[6.6,38.73]],"trd":[[6.6,1778.93]],"batl":[[0,6.6,38.73]],"tv":11889.87,"id":26496185},{"atl":[[11.5,15.02]],"batl":[[0,11.5,15.02]],"id":44049799}],"tv":72285.66}]}
{"op":"mcm","id":2,"clk":"APtdAJk6AM1U","pt":1743511811032,"mc":[{"id":"1.241629436","rc":[{"atl":[[9.2,19.13]],"trd":[[9.2,683]],"batl":[[0,9.2,19.13]],"tv":8631.34,"id":35856222},{"atb":[[10,68.74]],"batb":[[0,10,68.74]],"id":27115873},{"atl":[[6.6,32.91]],"batl":[[0,6.6,32.91]],"id":26496185},{"atb":[[11,143.3]],"trd":[[11,1298.49]],"batb":[[0,11,143.3]],"ltp":11,"tv":4496.2,"id":44049799}],"tv":72296.47}]}
{"op":"mcm","id":2,"clk":"AIReAJs6ANVU","pt":1743511811138,"mc":[{"id":"1.241629436","rc":[{"atb":[[1.1,9.84]],"id":44049799}]}]}
{"op":"mcm","id":2,"clk":"AJBeAKA6ANdU","pt":1743511811236,"mc":[{"id":"1.241629436","rc":[{"atl":[[17,7.1]],"trd":[[17,569.2]],"batl":[[0,17,7.1]],"tv":4888.28,"id":58186642}],"tv":72303.91}]}
{"op":"mcm","id":2,"clk":"AJdeAKc6AOBU","pt":1743511811340,"mc":[{"id":"1.241629436","rc":[{"atb":[[1.1,111.84]],"id":59626646},{"atl":[[17,6.56]],"batl":[[0,17,6.56]],"id":58186642},{"atb":[[1.1,9.17]],"id":44049799}]}]}
{"op":"mcm","id":2,"clk":"AKpeALM6APNU","pt":1743511811545,"mc":[{"id":"1.241629436","rc":[{"atb":[[1.1,111.18]],"id":59626646},{"atb":[[1.1,9]],"id":44049799}]}]}
{"op":"mcm","id":2,"clk":"ALReALg6AIFV","pt":1743511811652,"mc":[{"id":"1.241629436","rc":[{"atb":[[11,143.47]],"batb":[[0,11,143.47]],"id":44049799}]}]}
{"op":"mcm","id":2,"clk":"AMFeALo6AIdV","pt":1743511811751,"mc":[{"id":"1.241629436","rc":[{"atb":[[1.1,111]],"id":59626646},{"atb":[[6.4,150.98]],"trd":[[6.4,3209.45]],"batb":[[0,6.4,150.98]],"ltp":6.4,"tv":11909.87,"id":26496185}],"tv":72323.91}]}
{"op":"mcm","id":2,"clk":"AMheAME6AI5V","pt":1743511811852,"mc":[{"id":"1.241629436","rc":[{"atb":[[65,6.45]],"batb":[[0,65,6.45]],"id":59626646},{"atl":[[6.6,37.55]],"batl":[[0,6.6,37.55]],"id":26496185}]}]}
{"op":"mcm","id":2,"clk":"AIlfAPI6AL5V","pt":1743511812566,"mc":[{"id":"1.241629436","rc":[{"atl":[[5.4,107.27]],"batl":[[2,5.4,107.27]],"id":56297029}]}]}
{"op":"mcm","id":2,"clk":"AKlfAI47AN5V","pt":1743511812930,"mc":[{"id":"1.241629436","rc":[{"atl":[[17,5.25]],"batl":[[0,17,5.25]],"id":58186642},{"atl":[[11.5,17.02]],"batl":[[0,11.5,17.02]],"id":44049799}]}]}
{"op":"mcm","id":2,"clk":"ALVfAJU7AOZV","pt":1743511813039,"mc":[{"id":"1.241629436","rc":[{"atl":[[11.5,34.02]],"batl":[[0,11.5,34.02]],"id":40389088},{"atl":[[5.3,85.72]],"batl":[[1,5.3,85.72]],"id":56297029}]}]}
{"op":"mcm","id":2,"clk":"ALxfAJk7AO1V","pt":1743511813144,"mc":[{"id":"1.241629436","rc":[{"atl":[[5.4,103.77]],"batl":[[2,5.4,103.77]],"id":56297029}]}]}
{"op":"mcm","id":2,"clk":"APxfAMI7AKdW","pt":1743511813959,"mc":[{"id":"1.241629436","rc":[{"atl":[[1000,23.16]],"id":270592}]}]}
{"op":"mcm","id":2,"clk":"AIJgAMc7ALJW","pt":1743511814063,"mc":[{"id":"1.241629436","rc":[{"atl":[[9.2,0]],"trd":[[9.2,721.26]],"batl":[[2,9.8,40.03],[1,9.6,56.22],[0,9.4,31.48]],"tv":8669.6,"id":35856222}],"tv":72362.17}]}
{"op":"mcm","id":2,"clk":"AI5gAM47ALZW","pt":1743511814161,"mc":[{"id":"1.241629436","rc":[{"atb":[[1.01,53787.92]],"id":40389088},{"atl":[[1000,21.16]],"id":270592}]}]}
{"op":"mcm","id":2,"clk":"AJhgANA7AL1W","pt":1743511814264,"mc":[{"id":"1.241629436","rc":[{"atl":[[1000,23.16]],"id":270592},{"atl":[[9.4,39.13]],"batl":[[0,9.4,39.13]],"id":35856222},{"atb":[[5.1,199.96]],"batb":[[0,5.1,199.96]],"id":56297029}]}]}
{"op":"mcm","id":2,"clk":"AKJgANQ7AMVW","pt":1743511814366,"mc":[{"id":"1.241629436","rc":[{"atl":[[11.5,29.24]],"trd":[[11.5,1065.93]],"batl":[[0,11.5,29.24]],"ltp":11.5,"tv":6118.6,"id":40389088},{"atb":[[6.2,143.12]],"batb":[[1,6.2,143.12]],"id":26496185}],"tv":72371.73}]}
{"op":"mcm","id":2,"clk":"AK1gANk7AMpW","pt":1743511814474,"mc":[{"id":"1.241629436","rc":[{"atb":[[5.1,336.84]],"atl":[[1000,21.16]],"batb":[[1,5.1,336.84]],"id":270592}]}]}
{"op":"mcm","id":2,"clk":"ALpgAN07ANBW","pt":1743511814529,"mc":[{"id":"1.241629436","rc":[{"atb":[[16.5,85.51]],"batb":[[0,16.5,85.51]],"id":58186642}]}]}
{"op":"mcm","id":2,"clk":"AMJgAOU7ANZW","pt":1743511814626,"mc":[{"id":"1.241629436","rc":[{"atb":[[5.2,237.54]],"batb":[[0,5.2,237.54]],"id":270592},{"atb":[[9,110.31]],"batb":[[0,9,110.31]],"id":35856222},{"atb":[[17,7.57]],"atl":[[17,0]],"trd":[[17,579.71]],"batb":[[2,16,69.96],[1,16.5,85.51],[0,17,7.57]],"batl":[[2,18.5,15.19],[1,18,18.88],[0,17.5,17.63]],"tv":4898.79,"id":58186642},{"atb":[[10.5,69.27]],"batb":[[1,10.5,69.27]],"id":44049799}],"tv":72382.24}]}
{"op":"mcm","id":2,"clk":"AM1gAOs7AN1W","pt":1743511814737,"mc":[{"id":"1.241629436","rc":[{"atb":[[17,27.54],[16.5,82.22]],"atl":[[17.5,11.96]],"batb":[[1,16.5,82.22],[0,17,27.54]],"batl":[[0,17.5,11.96]],"id":58186642}]}]}
{"op":"mcm","id":2,"clk":"ANlgAPI7AOVW","pt":1743511814840,"mc":[{"id":"1.241629436","rc":[{"atb":[[9.2,11.97]],"batb":[[2,8.8,39.35],[1,9,110.31],[0,9.2,11.97]],"id":35856222},{"atl":[[5.2,213.58]],"trd":[[5.2,3496.22]],"batl":[[0,5.2,213.58]],"ltp":5.2,"tv":12148.24,"id":56297029},{"atb":[[9.6,49.5]],"batb":[[2,9.6,49.5]],"id":27115873},{"atb":[[17,30.97]],"atl":[[18,15.64]],"batb":[[0,17,30.97]],"batl":[[1,18,15.64]],"id":58186642}],"tv":72390.83}]}
{"op":"mcm","id":2,"clk":"AOBgAPg7AO9W","pt":1743511814945,"mc":[{"id":"1.241629436","rc":[{"atl":[[5.6,74.94]],"batl":[],"id":270592},{"atl":[[10.5,103.57]],"trd":[[10.5,543.21]],"batl":[[0,10.5,103.57]],"ltp":10.5,"tv":6122.87,"id":27115873},{"atb":[[17,24.47]],"atl":[[17.5,0.3]],"batb":[[0,17,24.47]],"batl":[[2,19,11.29],[1,18.5,15.19],[0,18,15.94]],"id":58186642},{"atb":[[11,127.11]],"batb":[[0,11,127.11]],"id":44049799}],"tv":72392.83}]}
{"op":"mcm","id":2,"clk":"AOpgAP07APZW","pt":1743511815045,"mc":[{"id":"1.241629436","rc":[{"atb":[[10,55.74]],"atl":[[10.5,104.86]],"batb":[[0,10,55.74]],"batl":[[0,10.5,104.86]],"id":27115873},{"atb":[[17,30.87]],"batb":[[0,17,30.87]],"id":58186642}]}]}
{"op":"mcm","id":2,"clk":"APdgAIY8AIZX","pt":1743511815241,"mc":[{"id":"1.241629436","rc":[{"atb":[[17,34.8]],"batb":[[0,17,34.8]],"id":58186642}]}]}
{"op":"mcm","id":2,"clk":"AINhAIw8AI1X","pt":1743511815344,"mc":[{"id":"1.241629436","rc":[{"atl":[[18.5,12.7]],"batl":[[1,18.5,12.7]],"id":58186642}]}]}
{"op":"mcm","id":2,"clk":"AJNhAJY8AJlX","pt":1743511815553,"mc":[{"id":"1.241629436","rc":[{"atb":[[5.8,120.34]],"batb":[],"id":26496185}]}]}
{"op":"mcm","id":2,"clk":"AJ5hAJ48AKJX","pt":1743511815659,"mc":[{"id":"1.241629436","rc":[{"atb":[[5.1,198.96]],"trd":[[5.1,3218.43]],"batb":[[0,5.1,198.96]],"ltp":5.1,"tv":12150.24,"id":56297029}],"tv":72394.83}]}
{"op":"mcm","id":2,"clk":"ALlhAK48ALdX","pt":1743511815963,"mc":[{"id":"1.241629436","rc":[{"atl":[[14,18.17],[12,46.06]],"batl":[[1,12,46.06]],"id":40389088},{"atb":[[15.5,46.43]],"batb":[],"id":58186642}]}]}
{"op":"mcm","id":2,"clk":"AMNhALM8AMNX","pt":1743511816066,"mc":[{"id":"1.241629436","rc":[{"atb":[[5.1,198.27]],"batb":[[0,5.1,198.27]],"id":56297029}]}]}
{"op":"mcm","id":2,"clk":"AM5hALY8AMtX","pt":1743511816165,"mc":[{"id":"1.241629436","rc":[{"atb":[[16,74.68]],"batb":[[2,16,74.68]],"id":58186642}]}]}
{"op":"mcm","id":2,"clk":"AOFhAMU8AN9X","pt":1743511816375,"mc":[{"id":"1.241629436","rc":[{"atl":[[70,12.34]],"trd":[[70,70.1]],"batl":[[0,70,12.34]],"ltp":70,"tv":1626.36,"id":59626646}],"tv":72398.91}]}
{"op":"mcm","id":2,"clk":"AJJiAOI8AIhY","pt":1743511816937,"mc":[{"id":"1.241629436","rc":[{"atl":[[5.2,202.58]],"trd":[[5.2,3518.22]],"batl":[[0,5.2,202.58]],"ltp":5.2,"tv":12172.24,"id":56297029}],"tv":72420.91}]}
{"op":"mcm","id":2,"clk":"ALFiAPY8AKRY","pt":1743511817361,"mc":[{"id":"1.241629436","rc":[{"atb":[[11,98.06]],"trd":[[11,61.61]],"batb":[[0,11,98.06]],"ltp":11,"tv":6121.6,"id":40389088},{"atb":[[9.2,0]],"batb":[[2,8.6,58.51],[1,8.8,39.35],[0,9,110.31]],"id":35856222}],"tv":72423.91}]}
{"op":"mcm","id":2,"clk":"ALhiAPk8AK1Y","pt":1743511817456,"mc":[{"id":"1.241629436","rc":[{"atl":[[18.5,15.99]],"batl":[[1,18.5,15.99]],"id":58186642},{"atl":[[13,50.02]],"batl":[],"id":44049799}]}]}
{"op":"mcm","id":2,"clk":"AL5iAPw8ALRY","pt":1743511817564,"mc":[{"id":"1.241629436","rc":[{"atl":[[5.6,72.96]],"batl":[],"id":270592}]}]}
{"op":"mcm","id":2,"clk":"ANpiAI49ANJY","pt":1743511817963,"mc":[{"id":"1.241629436","rc":[{"atb":[[65,4.45]],"trd":[[65,113.84]],"batb":[[0,65,4.45]],"ltp":65,"tv":1630.36,"id":59626646}],"tv":72427.91}]}
{"op":"mcm","id":2,"clk":"AN1iAJQ9ANxY","pt":1743511818067,"mc":[{"id":"1.241629436","rc":[{"atb":[[16,69.96]],"atl":[[18.5,12.7]],"batb":[[2,16,69.96]],"batl":[[1,18.5,12.7]],"id":58186642}]}]}
{"op":"mcm","id":2,"clk":"AOJiAJc9AOJY","pt":1743511818165,"mc":[{"id":"1.241629436","rc":[{"atb":[[8.8,48.83]],"batb":[[1,8.8,48.83]],"id":35856222},{"atl":[[70,14.81]],"batl":[[0,70,14.81]],"id":59626646},{"atb":[[16,28.27]],"atl":[[17.5,38.41]],"batb":[[2,16,28.27]],"batl":[[2,18.5,12.7],[1,18,15.64],[0,17.5,38.41]],"id":58186642},{"atl":[[11.5,75.02]],"batl":[[0,11.5,75.02]],"id":44049799}]}]}
{"op":"mcm","id":2,"clk":"AOxiAJw9AOxY","pt":1743511818272,"mc":[{"id":"1.241629436","rc":[{"atb":[[65,6.45]],"batb":[[0,65,6.45]],"id":59626646},{"atl":[[18.5,16.02]],"batl":[[2,18.5,16.02]],"id":58186642},{"atb":[[11,126.68],[10.5,69.72]],"batb":[[1,10.5,69.72],[0,11,126.68]],"id":44049799}]}]}
{"op":"mcm","id":2,"clk":"APZiAKI9AO5Y","pt":1743511818373,"mc":[{"id":"1.241629436","rc":[{"atl":[[5.3,190.21]],"batl":[[0,5.3,190.21]],"id":270592},{"atb":[[17,31.37]],"atl":[[17.5,49.34]],"batb":[[0,17,31.37]],"batl":[[0,17.5,49.34]],"id":58186642}]}]}
{"op":"mcm","id":2,"clk":"AP5iAKQ9APNY","pt":1743511818473,"mc":[{"id":"1.241629436","rc":[{"atb":[[8.8,39.35]],"batb":[[1,8.8,39.35]],"id":35856222}]}]}
{"op":"mcm","id":2,"clk":"AIZjAKg9APxY","pt":1743511818540,"mc":[{"id":"1.241629436","rc":[{"atb":[[17,21.67]],"batb":[[0,17,21.67]],"id":58186642}]}]}
{"op":"mcm","id":2,"clk":"AKBjALc9AJFZ","pt":1743511818844,"mc":[{"id":"1.241629436","rc":[{"atb":[[11,97.06]],"trd":[[11,63.61]],"batb":[[0,11,97.06]],"tv":6123.6,"id":40389088},{"atb":[[5.1,197.15]],"trd":[[5.1,3220.67]],"batb":[[0,5.1,197.15]],"ltp":5.1,"tv":12174.48,"id":56297029}],"tv":72432.15}]}
{"op":"mcm","id":2,"clk":"ANZjANY9ALxZ","pt":1743511819350,"mc":[{"id":"1.241629436","rc":[{"atl":[[1000,23.16]],"id":270592}]}]}
{"op":"mcm","id":2,"clk":"AN5jANg9AMZZ","pt":1743511819453,"mc":[{"id":"1.241629436","rc":[{"atb":[[9,110.1]],"batb":[[0,9,110.1]],"id":35856222},{"atb":[[5.1,196.02]],"atl":[[5.3,85.4]],"batb":[[0,5.1,196.02]],"batl":[[1,5.3,85.4]],"id":56297029},{"atb":[[16,27.44],[16.5,83.26]],"batb":[[2,16,27.44],[1,16.5,83.26]],"id":58186642},{"atb":[[6.4,149.63]],"batb":[[0,6.4,149.63]],"id":26496185},{"atb":[[11,127.92]],"batb":[[0,11,127.92]],"id":44049799}]}]}
{"op":"mcm","id":2,"clk":"AOljAN89AM5Z","pt":1743511819553,"mc":[{"id":"1.241629436","rc":[{"atl":[[1000,21.16]],"id":270592}]}]}
{"op":"mcm","id":2,"clk":"APBjAOQ9ANZZ","pt":1743511819653,"mc":[{"id":"1.241629436","rc":[{"atl":[[1000,23.16]],"id":270592}]}]}
{"op":"mcm","id":2,"clk":"AINkAO89AOVZ","pt":1743511819868,"mc":[{"id":"1.241629436","rc":[{"atl":[[1000,21.16]],"id":270592}]}]}
{"op":"mcm","id":2,"clk":"AMNkAJI+AJBa","pt":1743511820634,"mc":[{"id":"1.241629436","rc":[{"atl":[[12.5,45.26]],"batl":[[2,12.5,45.26]],"id":44049799}]}]}
{"op":"mcm","id":2,"clk":"ANJkAJg+AJ5a","pt":1743511820840,"mc":[{"id":"1.241629436","rc":[{"atb":[[11,101.92]],"batb":[[0,11,101.92]],"id":40389088},{"atb":[[5.2,241.33]],"batb":[[0,5.2,241.33]],"id":270592},{"atb":[[9,113.49]],"batb":[[0,9,113.49]],"id":35856222},{"atb":[[5.1,202]],"batb":[[0,5.1,202]],"id":56297029},{"atb":[[6.4,154.4]],"batb":[[0,6.4,154.4]],"id":26496185},{"atb":[[11,132.79]],"batb":[[0,11,132.79]],"id":44049799}]}]}
{"op":"mcm","id":2,"clk":"ANhkAJ4+AKZa","pt":1743511820941,"mc":[{"id":"1.241629436","rc":[{"atl":[[5.3,185.2]],"trd":[[5.3,1163.97]],"batl":[[0,5.3,185.2]],"tv":16416.4,"id":270592}],"tv":72442.17}]}
{"op":"mcm","id":2,"clk":"AOlkAKM+AK5a","pt":1743511821045,"mc":[{"id":"1.241629436","rc":[{"atb":[[9.2,1.04]],"batb":[[2,8.8,39.35],[1,9,113.49],[0,9.2,1.04]],"id":35856222},{"atl":[[6.6,30.07]],"trd":[[6.6,1793.88]],"batl":[[0,6.6,30.07]],"ltp":6.6,"tv":11924.82,"id":26496185}],"tv":72457.12}]}
{"op":"mcm","id":2,"clk":"AO1kAKY+ALRa","pt":1743511821141,"mc":[{"id":"1.241629436","rc":[{"atl":[[13.5,14.23],[11.5,35.45]],"batl":[[0,11.5,35.45]],"id":40389088},{"atb":[[9.2,0]],"trd":[[9.2,723.33]],"batb":[[2,8.6,58.51],[1,8.8,39.35],[0,9,113.49]],"tv":8671.67,"id":35856222},{"atl":[[5.2,200.91]],"trd":[[5.2,3521.56]],"batl":[[0,5.2,200.91]],"ltp":5.2,"tv":12177.82,"id":56297029},{"atb":[[17,23.54]],"batb":[[0,17,23.54]],"id":58186642},{"atl":[[6.6,31.18]],"batl":[[0,6.6,31.18]],"id":26496185}],"tv":72462.53}]}
{"op":"mcm","id":2,"clk":"APZkAKo+AL5a","pt":1743511821247,"mc":[{"id":"1.241629436","rc":[{"atl":[[5.6,74.94]],"batl":[],"id":270592}]}]}
{"op":"mcm","id":2,"clk":"AIxlALM+ANBa","pt":1743511821445,"mc":[{"id":"1.241629436","rc":[{"atl":[[5.6,72.96]],"batl":[],"id":270592}]}]}
{"op":"mcm","id":2,"clk":"AJNlALU+ANda","pt":1743511821551,"mc":[{"id":"1.241629436","rc":[{"atb":[[5.2,230.39]],"trd":[[5.2,1637.72]],"batb":[[0,5.2,230.39]],"ltp":5.2,"tv":16438.28,"id":270592}],"tv":72484.41}]}
{"op":"mcm","id":2,"clk":"AJplAL8+ANxa","pt":1743511821655,"mc":[{"id":"1.241629436","rc":[{"atb":[[11,130.79]],"trd":[[11,1302.49]],"batb":[[0,11,130.79]],"tv":4500.2,"id":44049799}],"tv":72488.41}]}
{"op":"mcm","id":2,"clk":"ALRlAMU+AOta","pt":1743511821867,"mc":[{"id":"1.241629436","rc":[{"atb":[[10,54.24]],"trd":[[10,366.52]],"batb":[[0,10,54.24]],"ltp":10,"tv":6125.87,"id":27115873}],"tv":72491.41}]}
{"op":"mcm","id":2,"clk":"AMtlANQ+AIJb","pt":1743511822170,"mc":[{"id":"1.241629436","rc":[{"atl":[[1000,0.59]],"id":40389088},{"atb":[[5.1,205.58]],"batb":[[0,5.1,205.58]],"id":56297029}]}]}
{"op":"mcm","id":2,"clk":"ANJlANs+AItb","pt":1743511822273,"mc":[{"id":"1.241629436","rc":[{"atl":[[1000,0.25]],"id":40389088}]}]}
{"op":"mcm","id":2,"clk":"AN1lAOI+AJNb","pt":1743511822375,"mc":[{"id":"1.241629436","rc":[{"atl":[[12,46.4]],"batl":[[1,12,46.4]],"id":40389088}]}]}
{"op":"mcm","id":2,"clk":"AOplAOU+AJlb","pt":1743511822478,"mc":[{"id":"1.241629436","rc":[{"atl":[[1000,0.65]],"id":40389088},{"atb":[[1.17,1.48]],"atl":[[1000,21.26]],"id":270592},{"atl":[[1000,0.72]],"id":35856222},{"atl":[[17.5,54.54]],"batl":[[0,17.5,54.54]],"id":58186642}]}]}
{"op":"mcm","id":2,"clk":"APVlAO0+AKNb","pt":1743511822591,"mc":[{"id":"1.241629436","rc":[{"atl":[[1000,0.25]],"id":40389088},{"atb":[[1.17,1]],"atl":[[1000,21.16]],"id":270592},{"atl":[[1000,0.41]],"id":35856222}]}]}
{"op":"mcm","id":2,"clk":"APllAPI+AKpb","pt":1743511822639,"mc":[{"id":"1.241629436","rc":[{"atl":[[11.5,35.85]],"batl":[[0,11.5,35.85]],"id":40389088},{"atb":[[5.2,230.87]],"atl":[[5.4,184.19]],"batb":[[0,5.2,230.87]],"batl":[[1,5.4,184.19]],"id":270592},{"atl":[[9.4,39.44]],"batl":[[0,9.4,39.44]],"id":35856222}]}]}
{"op":"mcm","id":2,"clk":"AIJmAPU+ALNb","pt":1743511822741,"mc":[{"id":"1.241629436","rc":[{"atl":[[70,12.81]],"trd":[[70,74.1]],"batl":[[0,70,12.81]],"ltp":70,"tv":1634.36,"id":59626646}],"tv":72495.41}]}
{"op":"mcm","id":2,"clk":"APBmANU/AJ9c","pt":1743511824274,"mc":[{"id":"1.241629436","rc":[{"atl":[[11.5,26.35]],"trd":[[11.5,1084.93]],"batl":[[0,11.5,26.35]],"ltp":11.5,"tv":6142.6,"id":40389088},{"atb":[[17,22.54]],"trd":[[17,581.71]],"batb":[[0,17,22.54]],"tv":4900.79,"id":58186642}],"tv":72516.41}]}
{"op":"mcm","id":2,"clk":"APhmANo/AKRc","pt":1743511824378,"mc":[{"id":"1.241629436","rc":[{"atl":[[11.5,23.24]],"batl":[[0,11.5,23.24]],"id":40389088},{"atb":[[17,15.97]],"batb":[[0,17,15.97]],"id":58186642}]}]}
{"op":"mcm","id":2,"clk":"APtmAOA/AK1c","pt":1743511824476,"mc":[{"id":"1.241629436","rc":[{"atl":[[11.5,20.14]],"batl":[[0,11.5,20.14]],"id":40389088}]}]}
{"op":"mcm","id":2,"clk":"AIxnAPA/AMNc","pt":1743511824636,"mc":[{"id":"1.241629436","rc":[{"atb":[[5.1,217.41]],"batb":[[0,5.1,217.41]],"id":56297029},{"atb":[[17,0]],"atl":[[17,8.29]],"trd":[[17,613.64]],"batb":[[2,15.5,46.43],[1,16,27.44],[0,16.5,83.26]],"batl":[[2,18,15.64],[1,17.5,54.54],[0,17,8.29]],"tv":4932.72,"id":58186642}],"tv":72548.34}]}
{"op":"mcm","id":2,"clk":"AJJnAPY/AMtc","pt":1743511824744,"mc":[{"id":"1.241629436","rc":[{"atl":[[11.5,25.21]],"batl":[[0,11.5,25.21]],"id":40389088},{"atl":[[1000,23.16]],"id":270592},{"atl":[[17.5,54.83]],"batl":[[1,17.5,54.83]],"id":58186642},{"atb":[[6.4,182.52]],"batb":[[0,6.4,182.52]],"id":26496185}]}]}
{"op":"mcm","id":2,"clk":"AJ5nAPw/ANdc","pt":1743511824846,"mc":[{"id":"1.241629436","rc":[{"atb":[[16,28.44]],"batb":[[1,16,28.44]],"id":58186642},{"atb":[[6.4,194.49]],"batb":[[0,6.4,194.49]],"id":26496185},{"atl":[[11.5,70.02]],"trd":[[11.5,719.22]],"batl":[[0,11.5,70.02]],"ltp":11.5,"tv":4510.2,"id":44049799}],"tv":72558.34}]}
{"op":"mcm","id":2,"clk":"AKlnAINAAN9c","pt":1743511824947,"mc":[{"id":"1.241629436","rc":[{"atl":[[1000,21.16]],"id":270592},{"atb":[[8.4,45.45]],"batb":[],"id":27115873}]}]}
{"op":"mcm","id":2,"clk":"ALVnAIlAAOtc","pt":1743511825055,"mc":[{"id":"1.241629436","rc":[{"atl":[[1000,23.16]],"id":270592},{"atb":[[6.4,184.49]],"trd":[[6.4,3229.45]],"batb":[[0,6.4,184.49]],"ltp":6.4,"tv":11944.82,"id":26496185}],"tv":72578.34}]}
{"op":"mcm","id":2,"clk":"AMBnAI5AAPpc","pt":1743511825155,"mc":[{"id":"1.241629436","rc":[{"atb":[[6.4,185.58]],"batb":[[0,6.4,185.58]],"id":26496185}]}]}
{"op":"mcm","id":2,"clk":"AMxnAJdAAIFd","pt":1743511825253,"mc":[{"id":"1.241629436","rc":[{"atl":[[1000,21.16]],"id":270592},{"atb":[[5.1,217.01]],"batb":[[0,5.1,217.01]],"id":56297029},{"atb":[[16,29.48],[16.5,83]],"atl":[[17.5,49.63],[17,11.19]],"batb":[[1,16,29.48],[0,16.5,83]],"batl":[[1,17.5,49.63],[0,17,11.19]],"id":58186642},{"atb":[[6.4,184.48]],"batb":[[0,6.4,184.48]],"id":26496185}]}]}
{"op":"mcm","id":2,"clk":"ANpnAKFAAIld","pt":1743511825362,"mc":[{"id":"1.241629436","rc":[{"atb":[[5.2,225.88]],"trd":[[5.2,1647.72]],"batb":[[0,5.2,225.88]],"tv":16448.28,"id":270592}],"tv":72588.34}]}
{"op":"mcm","id":2,"clk":"AN9nAKZAAJBd","pt":1743511825459,"mc":[{"id":"1.241629436","rc":[{"atl":[[11.5,20.14]],"batl":[[0,11.5,20.14]],"id":40389088}]}]}
{"op":"mcm","id":2,"clk":"AOhnALBAAJVd","pt":1743511825563,"mc":[{"id":"1.241629436","rc":[{"atb":[[1.01,56989.98]],"id":270592}]}]}
{"op":"mcm","id":2,"clk":"AIhoAL9AAKpd","pt":1743511825871,"mc":[{"id":"1.241629436","rc":[{"atb":[[15.5,45.43]],"batb":[[2,15.5,45.43]],"id":58186642}]}]}
{"op":"mcm","id":2,"clk":"AJFoAMRAALJd","pt":1743511825971,"mc":[{"id":"1.241629436","rc":[{"atb":[[16,30.48]],"batb":[[1,16,30.48]],"id":58186642}]}]}
{"op":"mcm","id":2,"clk":"ALxoAORAAN5d","pt":1743511826438,"mc":[{"id":"1.241629436","rc":[{"atb":[[10,47.73]],"trd":[[10,379.54]],"batb":[[0,10,47.73]],"tv":6138.89,"id":27115873},{"atb":[[16.5,28]],"batb":[[0,16.5,28]],"id":58186642}],"tv":72601.36}]}
{"op":"mcm","id":2,"clk":"AMNoAOdAAOld","pt":1743511826541,"mc":[{"id":"1.241629436","rc":[{"atb":[[65,5.45]],"trd":[[65,115.84]],"batb":[[0,65,5.45]],"ltp":65,"tv":1636.36,"id":59626646},{"atl":[[18,19.02]],"batl":[[2,18,19.02]],"id":58186642}],"tv":72603.36}]}
{"op":"mcm","id":2,"clk":"AJVpAKlBALle","pt":1743511827466,"mc":[{"id":"1.241629436","rc":[{"atl":[[1000,23.16]],"id":270592},{"atb":[[6,167.84],[6.2,138.12]],"atl":[[6.6,31.03]],"trd":[[6.6,1794.19]],"batb":[[2,6,167.84],[1,6.2,138.12]],"batl":[[0,6.6,31.03]],"ltp":6.6,"tv":11945.13,"id":26496185}],"tv":72603.67}]}
{"op":"mcm","id":2,"clk":"AKhpALVBAMte","pt":1743511827669,"mc":[{"id":"1.241629436","rc":[{"atl":[[1000,21.16]],"id":270592}]}]}
{"op":"mcm","id":2,"clk":"AP9pAOZBAKpf","pt":1743511828542,"mc":[{"id":"1.241629436","rc":[{"atb":[[6.4,183.48]],"trd":[[6.4,3231.45]],"batb":[[0,6.4,183.48]],"ltp":6.4,"tv":11947.13,"id":26496185}],"tv":72605.67}]}
{"op":"mcm","id":2,"clk":"AK5qAINCANxf","pt":1743511829157,"mc":[{"id":"1.241629436","rc":[{"atb":[[5.2,225.78]],"trd":[[5.2,1647.92]],"batb":[[0,5.2,225.78]],"tv":16448.48,"id":270592}],"tv":72605.87}]}
{"op":"mcm","id":2,"clk":"AOZqALJCAJNg","pt":1743511829873,"mc":[{"id":"1.241629436","rc":[{"atl":[[17.5,40.82],[17,0]],"trd":[[17,636.02],[17.5,121.65]],"batl":[[2,18.5,16.02],[1,18,19.02],[0,17.5,40.82]],"ltp":17.5,"tv":4972.72,"id":58186642}],"tv":72645.87}]}
{"op":"mcm","id":2,"clk":"AOxqALVCAJpg","pt":1743511829976,"mc":[{"id":"1.241629436","rc":[{"atb":[[17,8.68],[16.5,40.7]],"batb":[[2,16,30.48],[1,16.5,40.7],[0,17,8.68]],"id":58186642}]}]}
{"op":"mcm","id":2,"clk":"APNqALpCAJ9g","pt":1743511830079,"mc":[{"id":"1.241629436","rc":[{"atb":[[5.1,211.74]],"batb":[[0,5.1,211.74]],"id":56297029},{"atl":[[10.5,94.44]],"trd":[[10.5,564.05]],"batl":[[0,10.5,94.44]],"ltp":10.5,"tv":6159.73,"id":27115873},{"atb":[[16,29.48]],"batb":[[2,16,29.48]],"id":58186642}],"tv":72666.71}]}
{"op":"mcm","id":2,"clk":"APxqAMNCAKlg","pt":1743511830186,"mc":[{"id":"1.241629436","rc":[{"atl":[[1000,23.16]],"id":270592},{"atb":[[9,110.53]],"batb":[[0,9,110.53]],"id":35856222},{"atl":[[18,15.64]],"batl":[[1,18,15.64]],"id":58186642},{"atl":[[13,44.96],[11.5,73.12]],"batl":[[0,11.5,73.12]],"id":44049799}]}]}
{"op":"mcm","id":2,"clk":"AINrAMhCALJg","pt":1743511830288,"mc":[{"id":"1.241629436","rc":[{"atl":[[9.4,28.16]],"trd":[[9.4,335.64]],"batl":[[0,9.4,28.16]],"ltp":9.4,"tv":8694.22,"id":35856222},{"atb":[[65,3.94]],"trd":[[65,118.86]],"batb":[[0,65,3.94]],"tv":1639.38,"id":59626646},{"atb":[[17,9.76]],"batb":[[0,17,9.76]],"id":58186642}],"tv":72692.28}]}
{"op":"mcm","id":2,"clk":"AItrAMxCALZg","pt":1743511830339,"mc":[{"id":"1.241629436","rc":[{"atl":[[1000,21.16]],"id":270592}]}]}
{"op":"mcm","id":2,"clk":"AJtrAM5CAL1g","pt":1743511830440,"mc":[{"id":"1.241629436","rc":[{"atb":[[9.2,13.51]],"atl":[[9.4,37.16]],"batb":[[2,8.8,39.35],[1,9,110.53],[0,9.2,13.51]],"batl":[[0,9.4,37.16]],"id":35856222},{"atb":[[6.4,178.83]],"batb":[[0,6.4,178.83]],"id":26496185}]}]}
{"op":"mcm","id":2,"clk":"AKdrANFCAMNg","pt":1743511830547,"mc":[{"id":"1.241629436","rc":[{"atl":[[5.6,74.94]],"batl":[],"id":270592}]}]}
{"op":"mcm","id":2,"clk":"AMBrANxCANNg","pt":1743511830749,"mc":[{"id":"1.241629436","rc":[{"atb":[[9.2,11.51]],"trd":[[9.2,727.33]],"batb":[[0,9.2,11.51]],"ltp":9.2,"tv":8698.22,"id":35856222},{"atl":[[12,50.12]],"batl":[],"id":27115873}],"tv":72696.28}]}
{"op":"mcm","id":2,"clk":"ANFrAOFCAOVg","pt":1743511830954,"mc":[{"id":"1.241629436","rc":[{"atb":[[5.2,225.3]],"atl":[[5.4,184.09]],"batb":[[0,5.2,225.3]],"batl":[[1,5.4,184.09]],"id":270592},{"atb":[[16.5,41.06]],"batb":[[1,16.5,41.06]],"id":58186642}]}]}
{"op":"mcm","id":2,"clk":"ANxrAONCAOtg","pt":1743511831057,"mc":[{"id":"1.241629436","rc":[{"atl":[[5.3,182.69]],"trd":[[5.3,1168.99]],"batl":[[0,5.3,182.69]],"ltp":5.3,"tv":16453.5,"id":270592},{"atb":[[1.05,1678.57]],"id":35856222},{"atl":[[10.5,91.12]],"trd":[[10.5,570.69]],"batl":[[0,10.5,91.12]],"tv":6166.37,"id":27115873},{"atb":[[16,28.44]],"batb":[[2,16,28.44]],"id":58186642}],"tv":72707.94}]}
{"op":"mcm","id":2,"clk":"AOZrAOdCAPhg","pt":1743511831157,"mc":[{"id":"1.241629436","rc":[{"atb":[[5.2,222.29]],"trd":[[5.2,1653.92]],"batb":[[0,5.2,222.29]],"ltp":5.2,"tv":16459.5,"id":270592},{"atb":[[5.1,208.74]],"trd":[[5.1,3226.67]],"batb":[[0,5.1,208.74]],"ltp":5.1,"tv":12183.82,"id":56297029},{"atl":[[6.6,27.29]],"trd":[[6.6,1801.66]],"batl":[[0,6.6,27.29]],"ltp":6.6,"tv":11954.6,"id":26496185}],"tv":72727.41}]}
{"op":"mcm","id":2,"clk":"APBrAOlCAIJh","pt":1743511831260,"mc":[{"id":"1.241629436","rc":[{"atb":[[5.2,221.29],[5,339.16]],"trd":[[5.2,1655.92]],"batb":[[2,5,339.16],[0,5.2,221.29]],"tv":16461.5,"id":270592},{"atb":[[1.04,4.96]],"id":35856222},{"atl":[[10.5,109.88]],"batl":[[0,10.5,109.88]],"id":27115873},{"atl":[[6.6,25.86]],"batl":[[0,6.6,25.86]],"id":26496185}],"tv":72729.41}]}
{"op":"mcm","id":2,"clk":"APdrAO9CAIxh","pt":1743511831363,"mc":[{"id":"1.241629436","rc":[{"atb":[[9.2,10.04]],"trd":[[9.2,730.27]],"batb":[[0,9.2,10.04]],"tv":8701.16,"id":35856222}],"tv":72732.35}]}
{"op":"mcm","id":2,"clk":"AIJsAPRCAJVh","pt":1743511831467,"mc":[{"id":"1.241629436","rc":[{"atl":[[5.3,136.7]],"trd":[[5.3,1260.98]],"batl":[[0,5.3,136.7]],"ltp":5.3,"tv":16553.49,"id":270592},{"atb":[[1.04,4.64]],"id":35856222}],"tv":72824.34}]}
{"op":"mcm","id":2,"clk":"AIpsAPpCAJ9h","pt":1743511831572,"mc":[{"id":"1.241629436","rc":[{"atl":[[11.5,28.29]],"batl":[[0,11.5,28.29]],"id":40389088},{"atb":[[5,350],[5.1,347.68]],"atl":[[5.3,225.48]],"batb":[[2,5,350],[1,5.1,347.68]],"batl":[[0,5.3,225.48]],"id":270592},{"atb":[[5,1166.21]],"batb":[[1,5,1166.21]],"id":56297029},{"atb":[[9.4,53.1],[9.2,33.39]],"batb":[],"id":27115873},{"atl":[[18,18.99]],"batl":[[1,18,18.99]],"id":58186642},{"atl":[[13,50.02]],"batl":[],"id":44049799}]}]}
{"op":"mcm","id":2,"clk":"AI9sAIFDAK1h","pt":1743511831679,"mc":[{"id":"1.241629436","rc":[{"atl":[[11.5,43.09]],"batl":[[0,11.5,43.09]],"id":40389088},{"atb":[[5.2,214.92]],"atl":[[5.3,204.8]],"trd":[[5.2,1668.66]],"batb":[[0,5.2,214.92]],"batl":[[0,5.3,204.8]],"ltp":5.2,"tv":16566.23,"id":270592},{"atb":[[1.04,4.12]],"id":35856222},{"atb":[[4.9,93.22]],"batb":[[2,4.9,93.22]],"id":56297029},{"atb":[[9.4,58.71]],"batb":[],"id":27115873}],"tv":72837.08}]}
{"op":"mcm","id":2,"clk":"AJhsAIdDALZh","pt":1743511831786,"mc":[{"id":"1.241629436","rc":[{"atb":[[9.2,10.56]],"batb":[[0,9.2,10.56]],"id":35856222}]}]}
{"op":"mcm","id":2,"clk":"AKRsAIxDAMBh","pt":1743511831886,"mc":[{"id":"1.241629436","rc":[{"atl":[[5.3,228.78]],"batl":[[0,5.3,228.78]],"id":270592},{"atb":[[4.8,99.4]],"batb":[],"id":56297029}]}]}
{"op":"mcm","id":2,"clk":"AMBsAJlDAONh","pt":1743511832189,"mc":[{"id":"1.241629436","rc":[{"atb":[[11,101.99]],"batb":[[0,11,101.99]],"id":40389088},{"atb":[[5.2,214.78]],"trd":[[5.2,1668.94]],"batb":[[0,5.2,214.78]],"tv":16566.51,"id":270592},{"atb":[[65,3.93]],"trd":[[65,118.88]],"batb":[[0,65,3.93]],"tv":1639.4,"id":59626646},{"atb":[[10,47.8]],"batb":[[0,10,47.8]],"id":27115873}],"tv":72837.38}]}
{"op":"mcm","id":2,"clk":"ANNsAK5DAPlh","pt":1743511832358,"mc":[{"id":"1.241629436","rc":[{"atl":[[9.4,29.51]],"batl":[[0,9.4,29.51]],"id":35856222}]}]}
{"op":"mcm","id":2,"clk":"AOVsALpDAIBi","pt":1743511832444,"mc":[{"id":"1.241629436","rc":[{"atb":[[9.4,53.1]],"batb":[],"id":27115873}]}]}
{"op":"mcm","id":2,"clk":"AJVtANdDAKdi","pt":1743511832856,"mc":[{"id":"1.241629436","rc":[{"atl":[[1000,23.16]],"id":270592}]}]}
{"op":"mcm","id":2,"clk":"AJ1tAOVDALJi","pt":1743511832959,"mc":[{"id":"1.241629436","rc":[{"atl":[[10.5,82.9]],"trd":[[10.5,624.64]],"batl":[[0,10.5,82.9]],"tv":6220.32,"id":27115873}],"tv":72891.33}]}
{"op":"mcm","id":2,"clk":"AKhtAOxDAL1i","pt":1743511833058,"mc":[{"id":"1.241629436","rc":[{"atl":[[1000,21.16]],"id":270592},{"atb":[[4.8,98.37]],"batb":[],"id":56297029},{"atb":[[10,54.42]],"batb":[[0,10,54.42]],"id":27115873}]}]}
{"op":"mcm","id":2,"clk":"ALFtAPVDAMZi","pt":1743511833164,"mc":[{"id":"1.241629436","rc":[{"atb":[[9.4,58.71]],"batb":[],"id":27115873}]}]}
{"op":"mcm","id":2,"clk":"ALZtAP9DAM5i","pt":1743511833263,"mc":[{"id":"1.241629436","rc":[{"atb":[[4.9,94.23]],"batb":[[2,4.9,94.23]],"id":56297029}]}]}
{"op":"mcm","id":2,"clk":"AMRtAIlEANhi","pt":1743511833377,"mc":[{"id":"1.241629436","rc":[{"atl":[[5.9,85.82]],"batl":[],"id":270592}]}]}
{"op":"mcm","id":2,"clk":"AOltAKNEAPpi","pt":1743511833778,"mc":[{"id":"1.241629436","rc":[{"atb":[[9.4,23.5]],"atl":[[9.4,0]],"trd":[[9.4,394.65]],"batb":[[2,9,110.53],[1,9.2,10.56],[0,9.4,23.5]],"batl":[[2,10,100.27],[1,9.8,40.03],[0,9.6,56.22]],"ltp":9.4,"tv":8760.17,"id":35856222}],"tv":72950.34}]}
{"op":"mcm","id":2,"clk":"AO9tAK1EAIlj","pt":1743511833885,"mc":[{"id":"1.241629436","rc":[{"atb":[[9.4,0],[9.2,14.62],[8.6,40.46],[8,47.9]],"atl":[[9.4,31.28],[9.8,39.51],[11.5,62.51],[11,30.84],[9.6,49.42]],"trd":[[9.4,441.65]],"batb":[[2,8.8,39.35],[1,9,110.53],[0,9.2,14.62]],"batl":[[2,9.8,39.51],[1,9.6,49.42],[0,9.4,31.28]],"tv":8807.17,"id":35856222},{"atb":[[9.4,53.1]],"batb":[],"id":27115873},{"atb":[[17,1.08]],"atl":[[17.5,43.17]],"batb":[[0,17,1.08]],"batl":[[0,17.5,43.17]],"id":58186642},{"atb":[[6.4,150.71]],"batb":[[0,6.4,150.71]],"id":26496185},{"atb":[[11,127.71]],"batb":[[0,11,127.71]],"id":44049799}],"tv":72997.34}]}
{"op":"mcm","id":2,"clk":"APhtALNEAJZj","pt":1743511833988,"mc":[{"id":"1.241629436","rc":[{"atb":[[8.8,54.33],[8.2,18.1],[9.2,40.2]],"atl":[[9.4,0],[9.6,35.16]],"trd":[[9.4,510.09]],"batb":[[2,8.8,54.33],[0,9.2,40.2]],"batl":[[2,10,100.27],[1,9.8,39.51],[0,9.6,35.16]],"tv":8875.61,"id":35856222},{"atb":[[5.1,210.01]],"atl":[[1000,4.79]],"batb":[[0,5.1,210.01]],"id":56297029},{"atb":[[9.4,58.68]],"batb":[],"id":27115873},{"atb":[[16.5,37.68]],"atl":[[17.5,51.76]],"batb":[[1,16.5,37.68]],"batl":[[0,17.5,51.76]],"id":58186642},{"atb":[[6.4,156.42]],"batb":[[0,6.4,156.42]],"id":26496185}],"tv":73065.78}]}
{"op":"mcm","id":2,"clk":"AIRuALhEAJtj","pt":1743511834087,"mc":[{"id":"1.241629436","rc":[{"atl":[[9.4,12.1],[11,28.45]],"batl":[[2,9.8,39.51],[1,9.6,35.16],[0,9.4,12.1]],"id":35856222},{"atl":[[1000,4.52]],"id":56297029},{"atb":[[8.4,44.3]],"batb":[],"id":27115873}]}]}
{"op":"mcm","id":2,"clk":"AI1uALpEAKFj","pt":1743511834187,"mc":[{"id":"1.241629436","rc":[{"atb":[[9.4,6.23],[9.2,46.3]],"atl":[[9.4,0],[9.8,33.24],[11.5,60.34]],"trd":[[9.4,534.29]],"batb":[[2,9,110.53],[1,9.2,46.3],[0,9.4,6.23]],"batl":[[2,10,100.27],[1,9.8,33.24],[0,9.6,35.16]],"tv":8899.81,"id":35856222},{"atl":[[5.3,85.67]],"batl":[[1,5.3,85.67]],"id":56297029},{"atb":[[17,0]],"atl":[[17,12.89]],"trd":[[17,638.18]],"batb":[[2,15.5,45.43],[1,16,28.44],[0,16.5,37.68]],"batl":[[2,18,18.99],[1,17.5,51.76],[0,17,12.89]],"ltp":17,"tv":4974.88,"id":58186642}],"tv":73092.14}]}
{"op":"mcm","id":2,"clk":"AJtuAMREAKlj","pt":1743511834243,"mc":[{"id":"1.241629436","rc":[{"atl":[[12,46.06]],"batl":[[1,12,46.06]],"id":40389088},{"atb":[[9.4,18.24]],"batb":[[0,9.4,18.24]],"id":35856222},{"atb":[[16.5,41.06]],"atl":[[17,21.18]],"batb":[[0,16.5,41.06]],"batl":[[0,17,21.18]],"id":58186642}]}]}
{"op":"mcm","id":2,"clk":"AKhuAMpEALRj","pt":1743511834353,"mc":[{"id":"1.241629436","rc":[{"atb":[[9.4,12.01]],"trd":[[9.4,546.75]],"batb":[[0,9.4,12.01]],"tv":8912.27,"id":35856222},{"atb":[[9.4,53.1]],"batb":[],"id":27115873},{"atb":[[16.5,28.04]],"batb":[[0,16.5,28.04]],"id":58186642},{"atl":[[6.6,34.51]],"batl":[[0,6.6,34.51]],"id":26496185}],"tv":73104.6}]}
{"op":"mcm","id":2,"clk":"AK9uANBEALdj","pt":1743511834445,"mc":[{"id":"1.241629436","rc":[{"atb":[[9.4,3.53]],"trd":[[9.4,563.71]],"batb":[[0,9.4,3.53]],"tv":8929.23,"id":35856222},{"atl":[[17,24.71]],"batl":[[0,17,24.71]],"id":58186642}],"tv":73121.56}]}
{"op":"mcm","id":2,"clk":"AMRuANdEAMNj","pt":1743511834558,"mc":[{"id":"1.241629436","rc":[{"atb":[[9.4,0]],"atl":[[9.4,1.73],[9.8,39.37]],"trd":[[9.4,570.77]],"batb":[[2,8.8,54.33],[1,9,110.53],[0,9.2,46.3]],"batl":[[2,9.8,39.37],[1,9.6,35.16],[0,9.4,1.73]],"tv":8936.29,"id":35856222},{"atb":[[16,29.92],[16.5,25.7]],"batb":[[1,16,29.92],[0,16.5,25.7]],"id":58186642},{"atl":[[6.6,25.86]],"batl":[[0,6.6,25.86]],"id":26496185}],"tv":73128.62}]}
{"op":"mcm","id":2,"clk":"AMtuAOJEAMpj","pt":1743511834653,"mc":[{"id":"1.241629436","rc":[{"atl":[[9.8,33.24]],"batl":[[2,9.8,33.24]],"id":35856222},{"atb":[[10,67.42]],"batb":[[0,10,67.42]],"id":27115873},{"atb":[[16.5,18.88]],"batb":[[0,16.5,18.88]],"id":58186642}]}]}
{"op":"mcm","id":2,"clk":"ANRuAOdEANNj","pt":1743511834755,"mc":[{"id":"1.241629436","rc":[{"atb":[[9.2,62.32]],"batb":[[0,9.2,62.32]],"id":35856222}]}]}
{"op":"mcm","id":2,"clk":"APBuAP5EAPZj","pt":1743511835068,"mc":[{"id":"1.241629436","rc":[{"atb":[[9,110.52]],"batb":[[1,9,110.52]],"id":35856222},{"atb":[[6.4,153.35]],"batb":[[0,6.4,153.35]],"id":26496185}]}]}
{"op":"mcm","id":2,"clk":"APxuAIRFAP5j","pt":1743511835175,"mc":[{"id":"1.241629436","rc":[{"atb":[[9.2,62.33]],"batb":[[0,9.2,62.33]],"id":35856222},{"atb":[[6.4,156.42]],"batb":[[0,6.4,156.42]],"id":26496185}]}]}
{"op":"mcm","id":2,"clk":"AKBvAJdFAKJk","pt":1743511835584,"mc":[{"id":"1.241629436","rc":[{"atl":[[1000,23.16]],"id":270592}]}]}
{"op":"mcm","id":2,"clk":"AK9vAKhFAK9k","pt":1743511835785,"mc":[{"id":"1.241629436","rc":[{"atl":[[1000,21.16]],"id":270592},{"atb":[[9.4,18.63]],"atl":[[9.4,0]],"trd":[[9.4,574.23]],"batb":[[2,9,110.52],[1,9.2,62.33],[0,9.4,18.63]],"batl":[[2,10,100.27],[1,9.8,33.24],[0,9.6,35.16]],"tv":8939.75,"id":35856222}],"tv":73132.08}]}
{"op":"mcm","id":2,"clk":"ALRvAKpFALlk","pt":1743511835880,"mc":[{"id":"1.241629436","rc":[{"atl":[[5.3,227.09]],"trd":[[5.3,1264.36]],"batl":[[0,5.3,227.09]],"ltp":5.3,"tv":16569.89,"id":270592}],"tv":73135.46}]}
{"op":"mcm","id":2,"clk":"ALxvALBFAMFk","pt":1743511835984,"mc":[{"id":"1.241629436","rc":[{"atb":[[9.4,30.23]],"batb":[[0,9.4,30.23]],"id":35856222}]}]}
{"op":"mcm","id":2,"clk":"AM1vAL1FAM1k","pt":1743511836198,"mc":[{"id":"1.241629436","rc":[{"atl":[[9.8,25.77]],"batl":[[1,9.8,25.77]],"id":35856222}]}]}
{"op":"mcm","id":2,"clk":"ANNvAL5FANZk","pt":1743511836248,"mc":[{"id":"1.241629436","rc":[{"atl":[[1000,2.25]],"id":40389088}]}]}
{"op":"mcm","id":2,"clk":"ANtvAMJFAN9k","pt":1743511836353,"mc":[{"id":"1.241629436","rc":[{"atb":[[9,109.28]],"batb":[[2,9,109.28]],"id":35856222}]}]}
{"op":"mcm","id":2,"clk":"AOFvAMhFAOdk","pt":1743511836447,"mc":[{"id":"1.241629436","rc":[{"atl":[[1000,1.04]],"id":40389088}]}]}
{"op":"mcm","id":2,"clk":"APFvANFFAPlk","pt":1743511836650,"mc":[{"id":"1.241629436","rc":[{"atl":[[1000,0.25]],"id":40389088},{"atb":[[1.01,56964.24]],"id":270592}]}]}
{"op":"mcm","id":2,"clk":"APlvANRFAIBl","pt":1743511836759,"mc":[{"id":"1.241629436","rc":[{"atb":[[11,101.2]],"trd":[[11,65.19]],"batb":[[0,11,101.2]],"ltp":11,"tv":6144.18,"id":40389088}],"tv":73137.04}]}
{"op":"mcm","id":2,"clk":"AIFwANtFAIll","pt":1743511836859,"mc":[{"id":"1.241629436","rc":[{"atl":[[5.3,222.18]],"trd":[[5.3,1274.18]],"batl":[[0,5.3,222.18]],"tv":16579.71,"id":270592}],"tv":73146.86}]}
{"op":"mcm","id":2,"clk":"AJtwAOxFALJl","pt":1743511837271,"mc":[{"id":"1.241629436","rc":[{"atl":[[5.2,160.91]],"batl":[[0,5.2,160.91]],"id":56297029}]}]}
{"op":"mcm","id":2,"clk":"AKdwAPBFALpl","pt":1743511837371,"mc":[{"id":"1.241629436","rc":[{"atl":[[6.6,34.51]],"batl":[[0,6.6,34.51]],"id":26496185}]}]}
{"op":"mcm","id":2,"clk":"AMNwAP5FANFl","pt":1743511837677,"mc":[{"id":"1.241629436","rc":[{"atb":[[9.4,26.55]],"atl":[[9.6,40.68]],"trd":[[9.4,581.59]],"batb":[[0,9.4,26.55]],"batl":[[0,9.6,40.68]],"tv":8947.11,"id":35856222},{"atl":[[17,20.71]],"trd":[[17,646.18]],"batl":[[0,17,20.71]],"tv":4982.88,"id":58186642},{"atb":[[6.4,151.42]],"trd":[[6.4,3241.45]],"batb":[[0,6.4,151.42]],"ltp":6.4,"tv":11964.6,"id":26496185}],"tv":73172.22}]}
{"op":"mcm","id":2,"clk":"AM1wAINGANhl","pt":1743511837780,"mc":[{"id":"1.241629436","rc":[{"atl":[[11.5,42.69]],"batl":[[0,11.5,42.69]],"id":40389088},{"atb":[[9.4,14.95]],"batb":[[0,9.4,14.95]],"id":35856222},{"atb":[[5.1,208.74]],"atl":[[5.3,85.4]],"batb":[[0,5.1,208.74]],"batl":[[1,5.3,85.4]],"id":56297029},{"atb":[[1.17,2.54],[16.5,17.74]],"atl":[[17.5,46.6],[17,22.22]],"batb":[[0,16.5,17.74]],"batl":[[1,17.5,46.6],[0,17,22.22]],"id":58186642}]}]}
{"op":"mcm","id":2,"clk":"AOFwAJFGAOpl","pt":1743511837987,"mc":[{"id":"1.241629436","rc":[{"atb":[[4.9,93.22]],"atl":[[5.2,148.57]],"batb":[[2,4.9,93.22]],"batl":[[0,5.2,148.57]],"id":56297029},{"atb":[[1.17,2]],"id":58186642},{"atl":[[6.6,25.86]],"batl":[[0,6.6,25.86]],"id":26496185}]}]}
{"op":"mcm","id":2,"clk":"AOtwAJhGAPJl","pt":1743511838086,"mc":[{"id":"1.241629436","rc":[{"atb":[[4.8,99.4]],"batb":[],"id":56297029},{"atb":[[16,30.23],[16.5,17.97]],"batb":[[1,16,30.23],[0,16.5,17.97]],"id":58186642}]}]}
{"op":"mcm","id":2,"clk":"APJwAJxGAPxl","pt":1743511838190,"mc":[{"id":"1.241629436","rc":[{"atl":[[70,14.81]],"batl":[[0,70,14.81]],"id":59626646},{"atl":[[10.5,112.91]],"batl":[[0,10.5,112.91]],"id":27115873},{"atl":[[17,61.46]],"batl":[[0,17,61.46]],"id":58186642},{"atb":[[6.2,193.12]],"batb":[[1,6.2,193.12]],"id":26496185},{"atb":[[11,129.15]],"atl":[[12,39.03]],"batb":[[0,11,129.15]],"batl":[[1,12,39.03]],"id":44049799}]}]}
{"op":"mcm","id":2,"clk":"APxwAKFGAIFm","pt":1743511838293,"mc":[{"id":"1.241629436","rc":[{"atb":[[5.1,291.08]],"atl":[[1000,23.16]],"batb":[[1,5.1,291.08]],"id":270592},{"atb":[[9.4,9.95]],"trd":[[9.4,591.59]],"batb":[[0,9.4,9.95]],"tv":8957.11,"id":35856222},{"atb":[[4.8,98.37]],"batb":[],"id":56297029},{"atl":[[17,61.75]],"batl":[[0,17,61.75]],"id":58186642}],"tv":73182.22}]}
{"op":"mcm","id":2,"clk":"AIdxAKZGAIpm","pt":1743511838351,"mc":[{"id":"1.241629436","rc":[{"atb":[[5.2,271.38]],"batb":[[0,5.2,271.38]],"id":270592},{"atb":[[10,54.42]],"batb":[[0,10,54.42]],"id":27115873}]}]}
{"op":"mcm","id":2,"clk":"AJNxAKtGAJBm","pt":1743511838461,"mc":[{"id":"1.241629436","rc":[{"atl":[[1000,21.16]],"id":270592},{"atb":[[4.9,94.23]],"batb":[[2,4.9,94.23]],"id":56297029}]}]}
{"op":"mcm","id":2,"clk":"ANdxAN1GAMxm","pt":1743511839171,"mc":[{"id":"1.241629436","rc":[{"atb":[[10,52.42]],"trd":[[10,383.54]],"batb":[[0,10,52.42]],"ltp":10,"tv":6224.32,"id":27115873}],"tv":73186.22}]}
{"op":"mcm","id":2,"clk":"AO9xAO9GAOFm","pt":1743511839475,"mc":[{"id":"1.241629436","rc":[{"atb":[[16.5,12.34]],"batb":[[0,16.5,12.34]],"id":58186642}]}]}
{"op":"mcm","id":2,"clk":"APhxAPJGAOdm","pt":1743511839575,"mc":[{"id":"1.241629436","rc":[{"atb":[[16.5,0.23]],"batb":[[2,15,23.87],[1,15.5,45.43],[0,16,30.46]],"id":58186642}]}]}
{"op":"mcm","id":2,"clk":"AIJyAPtGAPFm","pt":1743511839679,"mc":[{"id":"1.241629436","rc":[{"atl":[[17,65.25]],"batl":[[0,17,65.25]],"id":58186642}]}]}
{"op":"mcm","id":2,"clk":"AIhyAIBHAPxm","pt":1743511839784,"mc":[{"id":"1.241629436","rc":[{"atb":[[16,34.44]],"batb":[[0,16,34.67]],"id":58186642}]}]}
{"op":"mcm","id":2,"clk":"AJ9yAJFHAIxn","pt":1743511839991,"mc":[{"id":"1.241629436","rc":[{"atb":[[16.5,1.31]],"batb":[[2,15.5,45.43],[1,16,34.44],[0,16.5,1.31]],"id":58186642}]}]}
{"op":"mcm","id":2,"clk":"AK5yAJtHAJtn","pt":1743511840196,"mc":[{"id":"1.241629436","rc":[{"atb":[[16,30.96],[16.5,0.87]],"trd":[[16.5,347.76]],"batb":[[2,15,23.87],[1,15.5,45.43],[0,16,31.83]],"ltp":16.5,"tv":4983.76,"id":58186642}],"tv":73187.1}]}
{"op":"mcm","id":2,"clk":"ALpyAJ9HAKRn","pt":1743511840295,"mc":[{"id":"1.241629436","rc":[{"atl":[[12,65.12]],"batl":[],"id":27115873},{"atb":[[16,34.46]],"batb":[[0,16,35.33]],"id":58186642}]}]}
{"op":"mcm","id":2,"clk":"AMhyAKRHAK1n","pt":1743511840404,"mc":[{"id":"1.241629436","rc":[{"atb":[[16.5,0]],"atl":[[16.5,0.57]],"trd":[[16.5,349.5]],"batb":[[0,16,34.46]],"batl":[[0,17,65.82]],"tv":4985.5,"id":58186642}],"tv":73188.84}]}
{"op":"mcm","id":2,"clk":"AMxyAKVHALNn","pt":1743511840452,"mc":[{"id":"1.241629436","rc":[{"atl":[[1000,0.46]],"id":40389088},{"atb":[[5.1,209.74]],"batb":[[0,5.1,209.74]],"id":56297029},{"atb":[[6.4,178.26]],"batb":[[0,6.4,178.26]],"id":26496185}]}]}
{"op":"mcm","id":2,"clk":"ANRyAKtHALln","pt":1743511840555,"mc":[{"id":"1.241629436","rc":[{"atb":[[16.5,0.43]],"atl":[[17,64.15],[16.5,0]],"trd":[[17,648.38],[16.5,350.64]],"batb":[[0,16,34.89]],"batl":[[0,17,64.15]],"ltp":17,"tv":4988.84,"id":58186642}],"tv":73192.18}]}
{"op":"mcm","id":2,"clk":"AN1yALNHAMRn","pt":1743511840666,"mc":[{"id":"1.241629436","rc":[{"atl":[[1000,0.25]],"id":40389088},{"atb":[[5.1,282.54]],"batb":[[1,5.1,282.54]],"id":270592},{"atb":[[15.5,34.44]],"batb":[[1,15.5,34.44]],"id":58186642}]}]}
{"op":"mcm","id":2,"clk":"AOZyALdHAM5n","pt":1743511840762,"mc":[{"id":"1.241629436","rc":[{"atl":[[12,46.27]],"batl":[[1,12,46.27]],"id":40389088},{"atb":[[1.17,7.33]],"id":35856222},{"atl":[[5.2,148.67]],"batl":[[0,5.2,148.67]],"id":56297029},{"atb":[[16.5,0]],"batb":[[0,16,34.46]],"id":58186642}]}]}
{"op":"mcm","id":2,"clk":"AOtyALpHANdn","pt":1743511840859,"mc":[{"id":"1.241629436","rc":[{"atb":[[5.1,291.08]],"atl":[[5.3,222.88]],"batb":[[1,5.1,291.08]],"batl":[[0,5.3,222.88]],"id":270592},{"atb":[[1.17,7.15]],"id":35856222}]}]}
{"op":"mcm","id":2,"clk":"APFyAMFHAN9n","pt":1743511840965,"mc":[{"id":"1.241629436","rc":[{"atl":[[1000,23.16]],"id":270592},{"atb":[[9.4,10.13]],"batb":[[0,9.4,10.13]],"id":35856222}]}]}
{"op":"mcm","id":2,"clk":"APdyAMtHAOZn","pt":1743511841070,"mc":[{"id":"1.241629436","rc":[{"atl":[[17,10.15]],"trd":[[17,756.38]],"batl":[[0,17,10.15]],"tv":5096.84,"id":58186642}],"tv":73300.18}]}
{"op":"mcm","id":2,"clk":"AP5yANBHAOxn","pt":1743511841171,"mc":[{"id":"1.241629436","rc":[{"atl":[[1000,21.16]],"id":270592},{"atb":[[16.5,18.05]],"atl":[[17,7.65]],"batb":[[2,15.5,34.44],[1,16,34.46],[0,16.5,18.05]],"batl":[[0,17,7.65]],"id":58186642}]}]}
{"op":"mcm","id":2,"clk":"AIZzANhHAPZn","pt":1743511841274,"mc":[{"id":"1.241629436","rc":[{"atl":[[5.3,221.63]],"trd":[[5.3,1276.68]],"batl":[[0,5.3,221.63]],"tv":16582.21,"id":270592},{"atb":[[11,128.15]],"trd":[[11,1304.49]],"batb":[[0,11,128.15]],"ltp":11,"tv":4512.2,"id":44049799}],"tv":73304.68}]}
{"op":"mcm","id":2,"clk":"AJFzAORHAIJo","pt":1743511841387,"mc":[{"id":"1.241629436","rc":[{"atb":[[17,7.99],[16.5,19.01]],"atl":[[17,0]],"trd":[[17,771.68]],"batb":[[2,16,34.46],[1,16.5,19.01],[0,17,7.99]],"batl":[[2,18.5,16.02],[1,18,18.99],[0,17.5,46.6]],"tv":5112.14,"id":58186642},{"atl":[[6.6,23.98]],"trd":[[6.6,1805.42]],"batl":[[0,6.6,23.98]],"ltp":6.6,"tv":11968.36,"id":26496185}],"tv":73323.74}]}
{"op":"mcm","id":2,"clk":"AJhzAO5HAJRo","pt":1743511841493,"mc":[{"id":"1.241629436","rc":[{"atb":[[8.2,14.8],[11,99.98]],"batb":[[0,11,99.98]],"id":40389088},{"atb":[[17,1.55],[16.5,30.68]],"atl":[[17.5,40.82]],"trd":[[17,784.56]],"batb":[[1,16.5,30.68],[0,17,1.55]],"batl":[[0,17.5,40.82]],"tv":5125.02,"id":58186642}],"tv":73336.62}]}
{"op":"mcm","id":2,"clk":"AJxzAPJHAJpo","pt":1743511841585,"mc":[{"id":"1.241629436","rc":[{"atb":[[65,2.18]],"batb":[[0,65,2.18]],"id":59626646},{"atb":[[17,0]],"atl":[[17,0.89]],"trd":[[17,787.66]],"batb":[[2,15.5,34.44],[1,16,34.46],[0,16.5,30.68]],"batl":[[0,17.5,41.71]],"tv":5128.12,"id":58186642}],"tv":73339.72}]}
{"op":"mcm","id":2,"clk":"AKFzAPpHAKVo","pt":1743511841687,"mc":[{"id":"1.241629436","rc":[{"atb":[[17,0.45],[16.5,33.91]],"atl":[[17,0]],"trd":[[17,790.86]],"batb":[[0,16.5,34.36]],"batl":[[0,17.5,40.82]],"tv":5131.32,"id":58186642}],"tv":73342.92}]}
{"op":"mcm","id":2,"clk":"AKxzAIBIAKpo","pt":1743511841793,"mc":[{"id":"1.241629436","rc":[{"atb":[[10.5,29.55]],"batb":[[1,10.5,29.55]],"id":40389088},{"atl":[[70,16.17]],"batl":[[0,70,16.17]],"id":59626646},{"atb":[[16.5,37.29]],"atl":[[18,15.64]],"batb":[[0,16.5,37.74]],"batl":[[1,18,15.64]],"id":58186642}]}]}
{"op":"mcm","id":2,"clk":"AMdzAKVIANZo","pt":1743511842199,"mc":[{"id":"1.241629436","rc":[{"atb":[[5.5,5.76]],"id":35856222}]}]}
{"op":"mcm","id":2,"clk":"ANRzALRIAOVo","pt":1743511842360,"mc":[{"id":"1.241629436","rc":[{"atl":[[12.5,284.94]],"batl":[],"id":27115873}]}]}
{"op":"mcm","id":2,"clk":"ANpzALlIAPFo","pt":1743511842463,"mc":[{"id":"1.241629436","rc":[{"atl":[[5.6,78.94]],"batl":[],"id":270592}]}]}
{"op":"mcm","id":2,"clk":"AOtzAL1IAP1o","pt":1743511842570,"mc":[{"id":"1.241629436","rc":[{"atb":[[17,0],[16.5,27.75]],"trd":[[17,791.76],[16.5,369.74]],"batb":[[0,16.5,27.75]],"ltp":16.5,"tv":5151.32,"id":58186642}],"tv":73362.92}]}
{"op":"mcm","id":2,"clk":"APJzAMFIAIhp","pt":1743511842665,"mc":[{"id":"1.241629436","rc":[{"atb":[[5.6,1.99]],"id":35856222},{"atb":[[16.5,32.9]],"atl":[[17.5,43.17]],"batb":[[0,16.5,32.9]],"batl":[[0,17.5,43.17]],"id":58186642}]}]}
{"op":"mcm","id":2,"clk":"APhzAMNIAJFp","pt":1743511842770,"mc":[{"id":"1.241629436","rc":[{"atb":[[9,105.89]],"batb":[[2,9,105.89]],"id":35856222}]}]}
{"op":"mcm","id":2,"clk":"AIl0ANBIAJ1p","pt":1743511842970,"mc":[{"id":"1.241629436","rc":[{"atl":[[5.3,222.33]],"batl":[[0,5.3,222.33]],"id":270592}]}]}
{"op":"mcm","id":2,"clk":"AJF0ANdIAKpp","pt":1743511843073,"mc":[{"id":"1.241629436","rc":[{"atb":[[5.7,2]],"id":35856222},{"atb":[[6.4,168.25]],"trd":[[6.4,3261.45]],"batb":[[0,6.4,168.25]],"ltp":6.4,"tv":11988.36,"id":26496185}],"tv":73382.92}]}
{"op":"mcm","id":2,"clk":"AJt0AN5IALNp","pt":1743511843176,"mc":[{"id":"1.241629436","rc":[{"atb":[[6.4,163.25]],"atl":[[6.6,32]],"trd":[[6.4,3271.46]],"batb":[[0,6.4,163.25]],"batl":[[0,6.6,32]],"tv":11998.37,"id":26496185}],"tv":73392.93}]}
{"op":"mcm","id":2,"clk":"AKd0AOdIAL9p","pt":1743511843278,"mc":[{"id":"1.241629436","rc":[{"atb":[[6.4,136.41]],"batb":[[0,6.4,136.41]],"id":26496185}]}]}
{"op":"mcm","id":2,"clk":"ALB0AOlIAMtp","pt":1743511843389,"mc":[{"id":"1.241629436","rc":[{"atb":[[11,129.42]],"batb":[[0,11,129.42]],"id":44049799}]}]}
{"op":"mcm","id":2,"clk":"ALp0APJIANVp","pt":1743511843489,"mc":[{"id":"1.241629436","rc":[{"atb":[[5.8,1]],"id":35856222},{"atb":[[1.17,2.18]],"id":58186642}]}]}
{"op":"mcm","id":2,"clk":"AMJ0AP1IAN5p","pt":1743511843591,"mc":[{"id":"1.241629436","rc":[{"atl":[[5.2,128.67]],"trd":[[5.2,3561.56]],"batl":[[0,5.2,128.67]],"ltp":5.2,"tv":12223.82,"id":56297029}],"tv":73432.93}]}
{"op":"mcm","id":2,"clk":"AMx0AIJJAOpp","pt":1743511843694,"mc":[{"id":"1.241629436","rc":[{"atl":[[1000,23.16]],"id":270592},{"atb":[[1.17,2]],"id":58186642}]}]}
{"op":"mcm","id":2,"clk":"ANV0AIpJAPVp","pt":1743511843793,"mc":[{"id":"1.241629436","rc":[{"atb":[[17,1],[16.5,33.08]],"batb":[[2,16,34.46],[1,16.5,33.08],[0,17,1]],"id":58186642}]}]}
{"op":"mcm","id":2,"clk":"AN10AI9JAINq","pt":1743511843897,"mc":[{"id":"1.241629436","rc":[{"atl":[[1000,21.16]],"id":270592},{"atb":[[5.9,2]],"id":35856222},{"atb":[[5.1,212.18]],"batb":[[0,5.1,212.18]],"id":56297029},{"atb":[[16.5,30.69]],"atl":[[18,19.09]],"batb":[[1,16.5,30.69]],"batl":[[1,18,19.09]],"id":58186642}]}]}
{"op":"mcm","id":2,"clk":"AOR0AJ5JAI1q","pt":1743511844006,"mc":[{"id":"1.241629436","rc":[{"atb":[[17,0]],"trd":[[17,793.76]],"batb":[[2,15.5,34.44],[1,16,34.46],[0,16.5,30.69]],"ltp":17,"tv":5153.32,"id":58186642}],"tv":73434.93}]}
{"op":"mcm","id":2,"clk":"APp0AKxJAJtq","pt":1743511844160,"mc":[{"id":"1.241629436","rc":[{"atb":[[16.5,34.08]],"atl":[[18,15.64]],"batb":[[0,16.5,34.08]],"batl":[[1,18,15.64]],"id":58186642}]}]}
{"op":"mcm","id":2,"clk":"AI11ALpJAKxq","pt":1743511844363,"mc":[{"id":"1.241629436","rc":[{"atb":[[6,5.87]],"id":35856222}]}]}
{"op":"mcm","id":2,"clk":"AKV1AMxJAMRq","pt":1743511844665,"mc":[{"id":"1.241629436","rc":[{"atb":[[5.2,270.38]],"trd":[[5.2,1670.94]],"batb":[[0,5.2,270.38]],"ltp":5.2,"tv":16584.21,"id":270592}],"tv":73436.93}]}
{"op":"mcm","id":2,"clk":"AKt1ANFJAMpq","pt":1743511844769,"mc":[{"id":"1.241629436","rc":[{"atl":[[5.6,74.94]],"batl":[],"id":270592},{"atl":[[5.2,130.17]],"batl":[[0,5.2,130.17]],"id":56297029}]}]}
{"op":"mcm","id":2,"clk":"AMN1AOlJAOdq","pt":1743511845091,"mc":[{"id":"1.241629436","rc":[{"atb":[[6.2,15.82]],"atl":[[9.6,50.01]],"batl":[[0,9.6,50.01]],"id":35856222},{"atl":[[11.5,72.45]],"trd":[[11.5,720.57]],"batl":[[0,11.5,72.45]],"ltp":11.5,"tv":4513.55,"id":44049799}],"tv":73438.28}]}
{"op":"mcm","id":2,"clk":"AM51AOxJAOxq","pt":1743511845194,"mc":[{"id":"1.241629436","rc":[{"atb":[[8.4,45.45]],"batb":[],"id":27115873}]}]}
{"op":"mcm","id":2,"clk":"AOh1APxJAJJr","pt":1743511845600,"mc":[{"id":"1.241629436","rc":[{"atb":[[6.4,18.49]],"id":35856222}]}]}
{"op":"mcm","id":2,"clk":"AKp2AJlKANdr","pt":1743511846379,"mc":[{"id":"1.241629436","rc":[{"atl":[[1000,23.16]],"id":270592}]}]}
{"op":"mcm","id":2,"clk":"AK52AJ5KAN1r","pt":1743511846476,"mc":[{"id":"1.241629436","rc":[{"atb":[[1.17,2.15]],"id":40389088},{"atb":[[5.2,271.89]],"batb":[[0,5.2,271.89]],"id":270592},{"atl":[[17.5,44.36]],"batl":[[0,17.5,44.36]],"id":58186642}]}]}
{"op":"mcm","id":2,"clk":"ALN2AKVKAOlr","pt":1743511846580,"mc":[{"id":"1.241629436","rc":[{"atb":[[1.17,2]],"id":40389088},{"atl":[[1000,21.47]],"id":270592}]}]}
{"op":"mcm","id":2,"clk":"ALt2AKtKAPZr","pt":1743511846686,"mc":[{"id":"1.241629436","rc":[{"atb":[[11,100.13]],"batb":[[0,11,100.13]],"id":40389088},{"atl":[[5.3,222.53]],"batl":[[0,5.3,222.53]],"id":270592},{"atl":[[5.3,88.4]],"batl":[[1,5.3,88.4]],"id":56297029}]}]}
{"op":"mcm","id":2,"clk":"AL92AK1KAPxr","pt":1743511846784,"mc":[{"id":"1.241629436","rc":[{"atl":[[1000,21.16]],"id":270592}]}]}
{"op":"mcm","id":2,"clk":"AMh2ALJKAINs","pt":1743511846886,"mc":[{"id":"1.241629436","rc":[{"atl":[[5.4,184.4]],"batl":[[1,5.4,184.4]],"id":270592}]}]}
{"op":"mcm","id":2,"clk":"AOp2AMZKAKRs","pt":1743511847298,"mc":[{"id":"1.241629436","rc":[{"atb":[[5.2,270.38]],"batb":[[0,5.2,270.38]],"id":270592},{"atb":[[5.1,210.94]],"batb":[[0,5.1,210.94]],"id":56297029}]}]}
{"op":"mcm","id":2,"clk":"AP12AM9KALVs","pt":1743511847506,"mc":[{"id":"1.241629436","rc":[{"atl":[[17.5,40.36]],"trd":[[17.5,129.65]],"batl":[[0,17.5,40.36]],"ltp":17.5,"tv":5161.32,"id":58186642},{"atl":[[6.6,30]],"trd":[[6.6,1809.42]],"batl":[[0,6.6,30]],"ltp":6.6,"tv":12002.37,"id":26496185}],"tv":73450.28}]}
{"op":"mcm","id":2,"clk":"AIN3ANdKALls","pt":1743511847556,"mc":[{"id":"1.241629436","rc":[{"atb":[[5.1,208.5]],"atl":[[5.2,135.8]],"batb":[[0,5.1,208.5]],"batl":[[0,5.2,135.8]],"id":56297029}]}]}
{"op":"mcm","id":2,"clk":"AIp3ANtKAMRs","pt":1743511847658,"mc":[{"id":"1.241629436","rc":[{"atb":[[17,10.32]],"batb":[[2,16,34.46],[1,16.5,34.08],[0,17,10.32]],"id":58186642},{"atl":[[6.6,32.76]],"batl":[[0,6.6,32.76]],"id":26496185}]}]}
{"op":"mcm","id":2,"clk":"AJh3AOFKAMps","pt":1743511847812,"mc":[{"id":"1.241629436","rc":[{"atb":[[4.9,93.22]],"batb":[[2,4.9,93.22]],"id":56297029},{"atb":[[17,17.78],[16.5,36.43]],"batb":[[1,16.5,36.43],[0,17,17.78]],"id":58186642},{"atl":[[6.8,123.12]],"batl":[[1,6.8,123.12]],"id":26496185}]}]}
{"op":"mcm","id":2,"clk":"AJp3AOZKANFs","pt":1743511847863,"mc":[{"id":"1.241629436","rc":[{"atb":[[4.8,99.4]],"batb":[],"id":56297029}]}]}
{"op":"mcm","id":2,"clk":"AKB3AOpKANZs","pt":1743511847961,"mc":[{"id":"1.241629436","rc":[{"atl":[[18.5,12.7]],"batl":[[2,18.5,12.7]],"id":58186642}]}]}
{"op":"mcm","id":2,"clk":"AKd3AO5KANxs","pt":1743511848070,"mc":[{"id":"1.241629436","rc":[{"atb":[[5.8,119.34]],"atl":[[6.6,30.76]],"trd":[[6.6,1813.42]],"batb":[],"batl":[[0,6.6,30.76]],"tv":12006.37,"id":26496185}],"tv":73454.28}]}
{"op":"mcm","id":2,"clk":"AKx3AO9KAORs","pt":1743511848169,"mc":[{"id":"1.241629436","rc":[{"atb":[[17,7.46]],"batb":[[0,17,7.46]],"id":58186642},{"atb":[[6.4,137.41]],"batb":[[0,6.4,137.41]],"id":26496185}]}]}
{"op":"mcm","id":2,"clk":"ALV3APJKAPBs","pt":1743511848277,"mc":[{"id":"1.241629436","rc":[{"atl":[[18.5,16.07]],"batl":[[2,18.5,16.07]],"id":58186642},{"atl":[[6.8,125.06]],"batl":[[1,6.8,125.06]],"id":26496185}]}]}
{"op":"mcm","id":2,"clk":"ALd3APhKAPps","pt":1743511848375,"mc":[{"id":"1.241629436","rc":[{"atb":[[5.1,208.4]],"trd":[[5.1,3226.87]],"batb":[[0,5.1,208.4]],"ltp":5.1,"tv":12224.02,"id":56297029}],"tv":73454.48}]}
{"op":"mcm","id":2,"clk":"AL53APtKAIJt","pt":1743511848475,"mc":[{"id":"1.241629436","rc":[{"atb":[[9.2,66.33]],"batb":[[1,9.2,66.33]],"id":35856222}]}]}
{"op":"mcm","id":2,"clk":"AMp3AIFLAI1t","pt":1743511848583,"mc":[{"id":"1.241629436","rc":[{"atl":[[6.6,28.76]],"trd":[[6.6,1817.42]],"batl":[[0,6.6,28.76]],"tv":12010.37,"id":26496185}],"tv":73458.48}]}
{"op":"mcm","id":2,"clk":"AN13AIlLAKBt","pt":1743511848782,"mc":[{"id":"1.241629436","rc":[{"atb":[[17,0]],"batb":[[2,15.5,34.44],[1,16,34.46],[0,16.5,36.43]],"id":58186642},{"atl":[[6.8,127]],"batl":[[1,6.8,127]],"id":26496185}]}]}
{"op":"mcm","id":2,"clk":"APN3AI9LALJt","pt":1743511848990,"mc":[{"id":"1.241629436","rc":[{"atl":[[5.6,138.94]],"batl":[],"id":270592},{"atb":[[15.5,45.43]],"batb":[[2,15.5,45.43]],"id":58186642}]}]}
{"op":"mcm","id":2,"clk":"APt3AJVLALht","pt":1743511849090,"mc":[{"id":"1.241629436","rc":[{"atb":[[5.2,275.31]],"atl":[[1000,23.16]],"batb":[[0,5.2,275.31]],"id":270592},{"atb":[[17,13.97]],"batb":[[2,16,34.46],[1,16.5,36.43],[0,17,13.97]],"id":58186642}]}]}
{"op":"mcm","id":2,"clk":"AIF4AJpLAMFt","pt":1743511849190,"mc":[{"id":"1.241629436","rc":[{"atb":[[11,99.98]],"batb":[[0,11,99.98]],"id":40389088},{"atb":[[9.4,9.95]],"batb":[[0,9.4,9.95]],"id":35856222},{"atb":[[16.5,36.25]],"atl":[[17.5,43.1]],"batb":[[1,16.5,36.25]],"batl":[[0,17.5,43.1]],"id":58186642}]}]}
{"op":"mcm","id":2,"clk":"AI94AJxLAMxt","pt":1743511849299,"mc":[{"id":"1.241629436","rc":[{"atl":[[1000,21.16],[5.3,222.73]],"batl":[[0,5.3,222.73]],"id":270592},{"atb":[[17,21.53]],"atl":[[18.5,12.7],[17.5,40.75]],"batb":[[0,17,21.53]],"batl":[[2,18.5,12.7],[0,17.5,40.75]],"id":58186642}]}]}
{"op":"mcm","id":2,"clk":"AJV4AJ9LANFt","pt":1743511849396,"mc":[{"id":"1.241629436","rc":[{"atl":[[9.6,40.68]],"batl":[[0,9.6,40.68]],"id":35856222}]}]}
{"op":"mcm","id":2,"clk":"AJx4AKZLANlt","pt":1743511849503,"mc":[{"id":"1.241629436","rc":[{"atb":[[6.4,139.41]],"batb":[[0,6.4,139.41]],"id":26496185}]}]}
{"op":"mcm","id":2,"clk":"AMF4AMZLAP9t","pt":1743511849971,"mc":[{"id":"1.241629436","rc":[{"atb":[[6.4,141.41]],"batb":[[0,6.4,141.41]],"id":26496185}]}]}
{"op":"mcm","id":2,"clk":"AOt4ANhLAJxu","pt":1743511850385,"mc":[{"id":"1.241629436","rc":[{"atb":[[6.4,143.41]],"batb":[[0,6.4,143.41]],"id":26496185}]}]}
{"op":"mcm","id":2,"clk":"APN4AOJLAKNu","pt":1743511850485,"mc":[{"id":"1.241629436","rc":[{"atl":[[5.7,89.44]],"batl":[],"id":270592},{"atl":[[9.6,30.14]],"trd":[[9.6,178.76]],"batl":[[0,9.6,30.14]],"ltp":9.6,"tv":8978.19,"id":35856222},{"atb":[[65,0.54]],"trd":[[65,122.17]],"batb":[[2,50,16.31],[1,55,15.4],[0,60,20]],"tv":1642.69,"id":59626646}],"tv":73482.85}]}
{"op":"mcm","id":2,"clk":"AIJ5AOZLAKlu","pt":1743511850592,"mc":[{"id":"1.241629436","rc":[{"atb":[[9.4,18.78]],"batb":[[0,9.4,18.78]],"id":35856222},{"atb":[[65,0]],"atl":[[65,2.15]],"trd":[[65,123.25]],"batb":[[0,60,19.46]],"batl":[[2,75,5.14],[1,70,16.17],[0,65,2.15]],"tv":1643.77,"id":59626646},{"atb":[[17,13.97]],"batb":[[0,17,13.97]],"id":58186642}],"tv":73483.93}]}
{"op":"mcm","id":2,"clk":"AId5AOpLALNu","pt":1743511850693,"mc":[{"id":"1.241629436","rc":[{"atl":[[65,3.76]],"batl":[[0,65,3.76]],"id":59626646},{"atb":[[6.4,139.41]],"trd":[[6.4,3279.46]],"batb":[[0,6.4,139.41]],"ltp":6.4,"tv":12018.37,"id":26496185}],"tv":73491.93}]}
{"op":"mcm","id":2,"clk":"AI55AO5LALlu","pt":1743511850790,"mc":[{"id":"1.241629436","rc":[{"atb":[[1.17,3]],"id":59626646},{"atb":[[6.2,213.84]],"batb":[[1,6.2,213.84]],"id":26496185}]}]}
{"op":"mcm","id":2,"clk":"AJZ5APJLAMFu","pt":1743511850897,"mc":[{"id":"1.241629436","rc":[{"atb":[[1.17,2.05]],"id":59626646},{"atb":[[6.4,158.2]],"batb":[[0,6.4,158.2]],"id":26496185}]}]}
{"op":"mcm","id":2,"clk":"AJt5APdLAMhu","pt":1743511851000,"mc":[{"id":"1.241629436","rc":[{"atb":[[17,7.97]],"trd":[[17,805.76]],"batb":[[0,17,7.97]],"ltp":17,"tv":5173.32,"id":58186642}],"tv":73503.93}]}
{"op":"mcm","id":2,"clk":"AKB5APpLANBu","pt":1743511851101,"mc":[{"id":"1.241629436","rc":[{"atb":[[1.17,2]],"id":59626646},{"atb":[[17,0.04]],"atl":[[18.5,16.08]],"trd":[[17,821.62]],"batb":[[2,15.5,45.43],[1,16,34.46],[0,16.5,36.29]],"batl":[[2,18.5,16.08]],"tv":5189.18,"id":58186642}],"tv":73519.79}]}
{"op":"mcm","id":2,"clk":"AKd5AP9LANhu","pt":1743511851210,"mc":[{"id":"1.241629436","rc":[{"atl":[[65,3.71]],"trd":[[65,123.35]],"batl":[[0,65,3.71]],"tv":1643.87,"id":59626646},{"atb":[[17,0]],"atl":[[17.5,43.1]],"trd":[[17,821.7]],"batb":[[0,16.5,36.25]],"batl":[[0,17.5,43.1]],"tv":5189.26,"id":58186642},{"atb":[[6.2,215.84]],"batb":[[1,6.2,215.84]],"id":26496185}],"tv":73519.97}]}
{"op":"mcm","id":2,"clk":"ALN5AIVMAOBu","pt":1743511851363,"mc":[{"id":"1.241629436","rc":[{"atl":[[17,7.52]],"batl":[[2,18,15.64],[1,17.5,43.1],[0,17,7.52]],"id":58186642}]}]}
{"op":"mcm","id":2,"clk":"AL95AIdMAOxu","pt":1743511851469,"mc":[{"id":"1.241629436","rc":[{"atb":[[6.2,217.84]],"batb":[[1,6.2,217.84]],"id":26496185}]}]}
{"op":"mcm","id":2,"clk":"AM95AJBMAPtu","pt":1743511851670,"mc":[{"id":"1.241629436","rc":[{"atl":[[5.2,132.8]],"trd":[[5.2,3567.56]],"batl":[[0,5.2,132.8]],"ltp":5.2,"tv":12230.02,"id":56297029}],"tv":73525.97}]}
{"op":"mcm","id":2,"clk":"ANh5AJNMAP9u","pt":1743511851766,"mc":[{"id":"1.241629436","rc":[{"atb":[[1.03,288.08]],"atl":[[1000,23.16]],"id":270592},{"atb":[[5.1,207.4]],"trd":[[5.1,3228.87]],"batb":[[0,5.1,207.4]],"ltp":5.1,"tv":12232.02,"id":56297029},{"atl":[[6.6,27.82]],"trd":[[6.6,1819.29]],"batl":[[0,6.6,27.82]],"ltp":6.6,"tv":12020.24,"id":26496185}],"tv":73529.84}]}
{"op":"mcm","id":2,"clk":"AOF5AJdMAIdv","pt":1743511851873,"mc":[{"id":"1.241629436","rc":[{"atb":[[5.1,208.93]],"batb":[[0,5.1,208.93]],"id":56297029},{"atb":[[6.2,219.84]],"batb":[[1,6.2,219.84]],"id":26496185}]}]}
{"op":"mcm","id":2,"clk":"AOl5AJxMAI1v","pt":1743511851976,"mc":[{"id":"1.241629436","rc":[{"atb":[[1.03,287.87]],"atl":[[1000,21.16]],"id":270592}]}]}
{"op":"mcm","id":2,"clk":"APF5AKBMAJJv","pt":1743511852077,"mc":[{"id":"1.241629436","rc":[{"atb":[[1.03,287.24]],"id":270592},{"atl":[[17,7.22]],"trd":[[17,822.3]],"batl":[[0,17,7.22]],"tv":5189.86,"id":58186642}],"tv":73530.44}]}
{"op":"mcm","id":2,"clk":"AP55AKZMAJtv","pt":1743511852186,"mc":[{"id":"1.241629436","rc":[{"atl":[[1000,0.44]],"id":40389088},{"atb":[[1.17,1.62]],"atl":[[5.3,222.1]],"trd":[[5.3,1277.94]],"batl":[[0,5.3,222.1]],"ltp":5.3,"tv":16585.47,"id":270592},{"atb":[[5.1,210.22]],"atl":[[1000,4.79]],"batb":[[0,5.1,210.22]],"id":56297029}],"tv":73531.7}]}
{"op":"mcm","id":2,"clk":"AIF6AKtMAKBv","pt":1743511852285,"mc":[{"id":"1.241629436","rc":[{"atl":[[1000,0.25]],"id":40389088},{"atb":[[1.17,1]],"id":270592},{"atl":[[1000,4.52]],"id":56297029}]}]}
{"op":"mcm","id":2,"clk":"AIt6ALBMAKZv","pt":1743511852383,"mc":[{"id":"1.241629436","rc":[{"atl":[[11.5,42.88]],"batl":[[0,11.5,42.88]],"id":40389088},{"atb":[[5.2,275.93]],"batb":[[0,5.2,275.93]],"id":270592},{"atl":[[5.3,88.67]],"batl":[[1,5.3,88.67]],"id":56297029}]}]}
{"op":"mcm","id":2,"clk":"AJJ6ALRMALFv","pt":1743511852489,"mc":[{"id":"1.241629436","rc":[{"atl":[[90,7.01]],"batl":[],"id":59626646}]}]}
{"op":"mcm","id":2,"clk":"AJh6ALpMALdv","pt":1743511852589,"mc":[{"id":"1.241629436","rc":[{"atb":[[6,169.84]],"batb":[[2,6,169.84]],"id":26496185}]}]}
{"op":"mcm","id":2,"clk":"AKJ6AMBMAMBv","pt":1743511852695,"mc":[{"id":"1.241629436","rc":[{"atl":[[12,46.06]],"batl":[[1,12,46.06]],"id":40389088}]}]}
{"op":"mcm","id":2,"clk":"AL56ANBMANpv","pt":1743511853000,"mc":[{"id":"1.241629436","rc":[{"atb":[[6,171.84]],"batb":[[2,6,171.84]],"id":26496185}]}]}
{"op":"mcm","id":2,"clk":"AM56ANpMAOhv","pt":1743511853207,"mc":[{"id":"1.241629436","rc":[{"atb":[[6,173.84]],"batb":[[2,6,173.84]],"id":26496185}]}]}
{"op":"mcm","id":2,"clk":"AN16AORMAPVv","pt":1743511853313,"mc":[{"id":"1.241629436","rc":[{"atl":[[17.5,43.18]],"batl":[[1,17.5,43.18]],"id":58186642}]}]}
{"op":"mcm","id":2,"clk":"AOJ6AOlMAPZv","pt":1743511853411,"mc":[{"id":"1.241629436","rc":[{"atb":[[11,97.49]],"trd":[[11,68.43]],"batb":[[0,11,97.49]],"tv":6147.42,"id":40389088},{"atb":[[9.2,66.32]],"batb":[[1,9.2,66.32]],"id":35856222},{"atb":[[6.4,155.13]],"batb":[[0,6.4,155.13]],"id":26496185}],"tv":73534.94}]}
{"op":"mcm","id":2,"clk":"AOl6AO5MAP1v","pt":1743511853462,"mc":[{"id":"1.241629436","rc":[{"atb":[[9.4,18.79]],"batb":[[0,9.4,18.79]],"id":35856222},{"atb":[[6.4,158.2]],"batb":[[0,6.4,158.2]],"id":26496185}]}]}
{"op":"mcm","id":2,"clk":"APV6APFMAIVw","pt":1743511853572,"mc":[{"id":"1.241629436","rc":[{"atl":[[90,3.26]],"batl":[],"id":59626646}]}]}
{"op":"mcm","id":2,"clk":"AJR7AIJNAJdw","pt":1743511853883,"mc":[{"id":"1.241629436","rc":[{"atb":[[10,25.45]],"trd":[[10,437.49]],"batb":[[0,10,25.45]],"tv":6278.27,"id":27115873}],"tv":73588.89}]}
{"op":"mcm","id":2,"clk":"AJ17AIZNAKNw","pt":1743511853999,"mc":[{"id":"1.241629436","rc":[{"atl":[[9.6,26.62]],"batl":[[0,9.6,26.62]],"id":35856222},{"atb":[[10,0]],"atl":[[10,2.64]],"trd":[[10,457.86]],"batb":[[2,9.4,53.1],[1,9.6,49.5],[0,9.8,60.2]],"batl":[[2,11,65.41],[1,10.5,112.91],[0,10,2.64]],"tv":6298.64,"id":27115873},{"atb":[[6.4,186.19]],"batb":[[0,6.4,186.19]],"id":26496185}],"tv":73609.26}]}
{"op":"mcm","id":2,"clk":"AKh7AI9NAKpw","pt":1743511854089,"mc":[{"id":"1.241629436","rc":[{"atb":[[9.8,78.56],[9.2,47.39]],"atl":[[10,4.31]],"batb":[[0,9.8,78.56]],"batl":[[0,10,4.31]],"id":27115873}]}]}
{"op":"mcm","id":2,"clk":"ALB7AJNNALFw","pt":1743511854196,"mc":[{"id":"1.241629436","rc":[{"atb":[[9.4,15.79]],"trd":[[9.4,597.59]],"batb":[[0,9.4,15.79]],"ltp":9.4,"tv":8984.19,"id":35856222},{"atb":[[5.1,212.66]],"batb":[[0,5.1,212.66]],"id":56297029},{"atb":[[9.8,68.32],[9.6,67.91]],"atl":[[12,55.85],[10.5,111.62],[10,18.05]],"trd":[[10,467.24]],"batb":[[1,9.6,67.91],[0,9.8,68.32]],"batl":[[1,10.5,111.62],[0,10,18.05]],"tv":6308.02,"id":27115873}],"tv":73624.64}]}
{"op":"mcm","id":2,"clk":"ALN7AJlNALdw","pt":1743511854290,"mc":[{"id":"1.241629436","rc":[{"atb":[[9,110.61]],"batb":[[2,9,110.61]],"id":35856222},{"atb":[[9.4,38.67]],"atl":[[10.5,112.1]],"batb":[[2,9.4,38.67]],"batl":[[1,10.5,112.1]],"id":27115873}]}]}
{"op":"mcm","id":2,"clk":"ALx7AKJNAL1w","pt":1743511854393,"mc":[{"id":"1.241629436","rc":[{"atl":[[1000,23.16]],"id":270592},{"atl":[[10,36.63]],"batl":[[0,10,36.63]],"id":27115873}]}]}
{"op":"mcm","id":2,"clk":"AL97AKpNAMBw","pt":1743511854490,"mc":[{"id":"1.241629436","rc":[{"atl":[[12.5,281.94]],"batl":[],"id":27115873}]}]}
{"op":"mcm","id":2,"clk":"AMl7ALFNAMhw","pt":1743511854601,"mc":[{"id":"1.241629436","rc":[{"atl":[[1000,21.16]],"id":270592},{"atl":[[65,3.06]],"trd":[[65,124.65]],"batl":[[0,65,3.06]],"tv":1645.17,"id":59626646},{"atb":[[5.1,235.16]],"batb":[[0,5.1,235.16]],"id":56297029},{"atb":[[9.8,57.32]],"batb":[[0,9.8,57.32]],"id":27115873}],"tv":73625.94}]}
{"op":"mcm","id":2,"clk":"AM57ALlNAMlw","pt":1743511854696,"mc":[{"id":"1.241629436","rc":[{"atl":[[9.6,21.78]],"batl":[[0,9.6,21.78]],"id":35856222},{"atb":[[5.1,244.11]],"batb":[[0,5.1,244.11]],"id":56297029},{"atb":[[16.5,38.85]],"batb":[[0,16.5,38.85]],"id":58186642}]}]}
{"op":"mcm","id":2,"clk":"AOB7AMdNANtw","pt":1743511854906,"mc":[{"id":"1.241629436","rc":[{"atl":[[5.4,184.09]],"batl":[[1,5.4,184.09]],"id":270592},{"atb":[[60,18.71]],"batb":[[0,60,18.71]],"id":59626646},{"atb":[[5.1,245.33]],"batb":[[0,5.1,245.33]],"id":56297029},{"atl":[[10.5,111.7]],"batl":[[1,10.5,111.7]],"id":27115873},{"atb":[[11,126.41]],"atl":[[11.5,72.18]],"batb":[[0,11,126.41]],"batl":[[0,11.5,72.18]],"id":44049799}]}]}
{"op":"mcm","id":2,"clk":"AOt7AM9NAOZw","pt":1743511855006,"mc":[{"id":"1.241629436","rc":[{"atb":[[5.2,275.31]],"batb":[[0,5.2,275.31]],"id":270592},{"atb":[[60,19.09],[55,15.91]],"atl":[[70,12.51],[65,4.13]],"batb":[[1,55,15.91],[0,60,19.09]],"batl":[[1,70,12.51],[0,65,4.13]],"id":59626646},{"atl":[[1000,4.21],[11,64.83]],"batl":[[2,11,64.83]],"id":27115873},{"atl":[[17.5,39.25],[17,8.9]],"batl":[[1,17.5,39.25],[0,17,8.9]],"id":58186642},{"atl":[[12,38.66]],"batl":[[1,12,38.66]],"id":44049799}]}]}
{"op":"mcm","id":2,"clk":"APR7ANNNAO5w","pt":1743511855108,"mc":[{"id":"1.241629436","rc":[{"atb":[[11,142.77]],"batb":[[0,11,142.77]],"id":44049799}]}]}
{"op":"mcm","id":2,"clk":"APx7ANhNAPZw","pt":1743511855207,"mc":[{"id":"1.241629436","rc":[{"atl":[[1000,3.66]],"id":27115873}]}]}
{"op":"mcm","id":2,"clk":"AIx8AN1NAP1w","pt":1743511855316,"mc":[{"id":"1.241629436","rc":[{"atl":[[10.5,112.25]],"batl":[[1,10.5,112.25]],"id":27115873}]}]}
{"op":"mcm","id":2,"clk":"AJp8AONNAIZx","pt":1743511855417,"mc":[{"id":"1.241629436","rc":[{"atb":[[9,105.89]],"batb":[[2,9,105.89]],"id":35856222}]}]}
{"op":"mcm","id":2,"clk":"ANB8AIdOAK9x","pt":1743511855981,"mc":[{"id":"1.241629436","rc":[{"atl":[[17,7.9]],"trd":[[17,824.3]],"batl":[[0,17,7.9]],"tv":5191.86,"id":58186642}],"tv":73627.94}]}
{"op":"mcm","id":2,"clk":"AOh8AKBOAMhx","pt":1743511856286,"mc":[{"id":"1.241629436","rc":[{"atb":[[1.01,60187.92]],"id":40389088}]}]}
{"op":"mcm","id":2,"clk":"APh8AKxOANhx","pt":1743511856490,"mc":[{"id":"1.241629436","rc":[{"atb":[[6,11.6]],"id":27115873}]}]}
{"op":"mcm","id":2,"clk":"AP18ALFOAN9x","pt":1743511856596,"mc":[{"id":"1.241629436","rc":[{"atb":[[6.2,175.84]],"batb":[[1,6.2,175.84]],"id":26496185}]}]}
{"op":"mcm","id":2,"clk":"AIN9ALdOAOhx","pt":1743511856697,"mc":[{"id":"1.241629436","rc":[{"atb":[[6.4,230.19]],"batb":[[0,6.4,230.19]],"id":26496185}]}]}
{"op":"mcm","id":2,"clk":"AJx9AMtOAIJy","pt":1743511857006,"mc":[{"id":"1.241629436","rc":[{"atl":[[10,113.07]],"batl":[[2,10,113.07]],"id":35856222}]}]}
{"op":"mcm","id":2,"clk":"AKh9ANROAIdy","pt":1743511857120,"mc":[{"id":"1.241629436","rc":[{"atl":[[1000,23.16]],"id":270592},{"atb":[[9.4,25.79]],"atl":[[9.6,0.78]],"trd":[[9.6,220.77]],"batb":[[0,9.4,25.79]],"batl":[[2,10.5,51.34],[1,10,113.07],[0,9.8,26.55]],"ltp":9.6,"tv":9026.2,"id":35856222},{"atb":[[16.5,37.85]],"atl":[[19.5,7.93]],"trd":[[16.5,371.74]],"batb":[[0,16.5,37.85]],"batl":[],"ltp":16.5,"tv":5193.86,"id":58186642}],"tv":73671.95}]}
{"op":"mcm","id":2,"clk":"AK99ANpOAIdy","pt":1743511857210,"mc":[{"id":"1.241629436","rc":[{"atl":[[5.3,221.9]],"batl":[[0,5.3,221.9]],"id":270592},{"atb":[[9.4,41.31],[8.2,14.37]],"atl":[[9.8,32.91],[9.6,0]],"trd":[[9.6,222.33]],"batb":[[0,9.4,41.31]],"batl":[[0,9.8,32.91]],"tv":9027.76,"id":35856222},{"atb":[[9.8,54.14]],"batb":[[0,9.8,54.14]],"id":27115873},{"atl":[[17,10.22]],"batl":[[0,17,10.22]],"id":58186642}],"tv":73673.51}]}
{"op":"mcm","id":2,"clk":"ALl9AOBOAI9y","pt":1743511857316,"mc":[{"id":"1.241629436","rc":[{"atl":[[1000,21.16]],"id":270592},{"atb":[[9.4,74.83],[8.4,70.34]],"atl":[[9.8,43.23],[12,45],[10.5,57.36]],"batb":[[0,9.4,74.83]],"batl":[[2,10.5,57.36],[0,9.8,43.23]],"id":35856222},{"atb":[[5.1,242.89],[4.8,98.37]],"batb":[[0,5.1,242.89]],"id":56297029},{"atb":[[9.8,35.78]],"batb":[[0,9.8,35.78]],"id":27115873}]}]}
{"op":"mcm","id":2,"clk":"AMB9AOlOAJRy","pt":1743511857416,"mc":[{"id":"1.241629436","rc":[{"atb":[[9.4,75.36]],"atl":[[10,106.71]],"batb":[[0,9.4,75.36]],"batl":[[1,10,106.71]],"id":35856222},{"atb":[[4.9,94.23]],"batb":[[2,4.9,94.23]],"id":56297029}]}]}
{"op":"mcm","id":2,"clk":"AMl9AO1OAJly","pt":1743511857479,"mc":[{"id":"1.241629436","rc":[{"atb":[[8.6,36.8],[9.6,7.28]],"atl":[[10,107.22]],"batb":[[2,9.2,66.32],[1,9.4,75.36],[0,9.6,7.28]],"batl":[[1,10,107.22]],"id":35856222}]}]}
{"op":"mcm","id":2,"clk":"ANR9APJOAJ1y","pt":1743511857583,"mc":[{"id":"1.241629436","rc":[{"atl":[[11.5,62.51]],"batl":[],"id":35856222},{"atb":[[9.8,0]],"trd":[[9.8,111.4]],"batb":[[2,9.2,47.39],[1,9.4,38.67],[0,9.6,67.91]],"ltp":9.8,"tv":6379.58,"id":27115873},{"atb":[[16.5,35.5]],"batb":[[0,16.5,35.5]],"id":58186642},{"atl":[[6.8,123]],"batl":[[1,6.8,123]],"id":26496185}],"tv":73745.07}]}
{"op":"mcm","id":2,"clk":"ANt9APhOAKRy","pt":1743511857689,"mc":[{"id":"1.241629436","rc":[{"atb":[[9.2,41.77],[9,34.05]],"atl":[[9.8,17.92],[12,53.87],[10,43.49]],"batb":[[2,9.2,41.77]],"batl":[[2,10.5,112.25],[1,10,43.49],[0,9.8,17.92]],"id":27115873},{"atl":[[6.6,31.82]],"batl":[[0,6.6,31.82]],"id":26496185}]}]}
{"op":"mcm","id":2,"clk":"AOF9APlOAKty","pt":1743511857784,"mc":[{"id":"1.241629436","rc":[{"atb":[[9.4,57.32]],"atl":[[14.5,43.66],[9.8,23.76],[12.5,279.74],[12,37.32],[10,55.34]],"batb":[[1,9.4,57.32]],"batl":[[1,10,55.34],[0,9.8,23.76]],"id":27115873},{"atb":[[16,35.46]],"batb":[[1,16,35.46]],"id":58186642}]}]}
{"op":"mcm","id":2,"clk":"AOh9APxOAK9y","pt":1743511857883,"mc":[{"id":"1.241629436","rc":[{"atb":[[5.1,245.33]],"batb":[[0,5.1,245.33]],"id":56297029},{"atb":[[9.6,65.71]],"atl":[[9.8,14.38]],"trd":[[9.8,130.15],[9.6,71.78]],"batb":[[0,9.6,65.71]],"batl":[[0,9.8,14.38]],"tv":6402.73,"id":27115873}],"tv":73768.22}]}
{"op":"mcm","id":2,"clk":"APN9AIFPALly","pt":1743511857994,"mc":[{"id":"1.241629436","rc":[{"atl":[[10,94.42]],"batl":[[1,10,94.42]],"id":35856222},{"atb":[[9.4,60.77],[9.2,27.17]],"batb":[[2,9.2,27.17],[1,9.4,60.77]],"id":27115873}]}]}
{"op":"mcm","id":2,"clk":"AIB+AIhPAMxy","pt":1743511858196,"mc":[{"id":"1.241629436","rc":[{"atl":[[5.3,347.75]],"batl":[[0,5.3,347.75]],"id":270592},{"atl":[[65,14.39]],"batl":[[0,65,14.39]],"id":59626646}]}]}
{"op":"mcm","id":2,"clk":"AIV+AJBPANNy","pt":1743511858294,"mc":[{"id":"1.241629436","rc":[{"atb":[[1.17,2.31],[11,96.16]],"trd":[[11,71.09]],"batb":[[0,11,96.16]],"tv":6150.08,"id":40389088},{"atl":[[10.5,48.73]],"batl":[[2,10.5,48.73]],"id":27115873},{"atl":[[17.5,13.65]],"batl":[[1,17.5,13.65]],"id":58186642}],"tv":73770.88}]}
{"op":"mcm","id":2,"clk":"AIp+AJlPANdy","pt":1743511858393,"mc":[{"id":"1.241629436","rc":[{"atb":[[60,17.24],[30,4]],"batb":[[0,60,17.24]],"id":59626646}]}]}
{"op":"mcm","id":2,"clk":"AJV+AJ1PANty","pt":1743511858498,"mc":[{"id":"1.241629436","rc":[{"atb":[[1.17,2]],"id":40389088},{"atb":[[5.2,250.52]],"batb":[[0,5.2,250.52]],"id":270592},{"atb":[[9.6,17.28]],"batb":[[0,9.6,17.28]],"id":35856222}]}]}
{"op":"mcm","id":2,"clk":"AJx+AKNPAOJy","pt":1743511858599,"mc":[{"id":"1.241629436","rc":[{"atb":[[11,96.47]],"batb":[[0,11,96.47]],"id":40389088}]}]}
{"op":"mcm","id":2,"clk":"AK5+ALBPAPBy","pt":1743511858808,"mc":[{"id":"1.241629436","rc":[{"atb":[[8.8,32.56]],"batb":[],"id":27115873}]}]}
{"op":"mcm","id":2,"clk":"AM9+AMNPAIhz","pt":1743511859127,"mc":[{"id":"1.241629436","rc":[{"atl":[[17,4]],"batl":[[0,17,4]],"id":58186642}]}]}
{"op":"mcm","id":2,"clk":"ANl+AM5PAJRz","pt":1743511859321,"mc":[{"id":"1.241629436","rc":[{"atb":[[16.5,34.5]],"batb":[[0,16.5,34.5]],"id":58186642}]}]}
{"op":"mcm","id":2,"clk":"APR+AOBPAKRz","pt":1743511859579,"mc":[{"id":"1.241629436","rc":[{"atb":[[9.4,65.36]],"batb":[[1,9.4,65.36]],"id":35856222}]}]}
{"op":"mcm","id":2,"clk":"AIB/AOdPAK9z","pt":1743511859782,"mc":[{"id":"1.241629436","rc":[{"atb":[[5.2,250.42]],"atl":[[1000,23.16]],"trd":[[5.2,1671.14]],"batb":[[0,5.2,250.42]],"ltp":5.2,"tv":16585.67,"id":270592}],"tv":73771.08}]}
{"op":"mcm","id":2,"clk":"AIx/APNPAMBz","pt":1743511859989,"mc":[{"id":"1.241629436","rc":[{"atl":[[1000,21.16]],"id":270592}]}]}
{"op":"mcm","id":2,"clk":"ALJ/AIRQAOFz","pt":1743511860400,"mc":[{"id":"1.241629436","rc":[{"atl":[[5.4,100.77]],"batl":[[2,5.4,100.77]],"id":56297029}]}]}
{"op":"mcm","id":2,"clk":"ALp/AIhQAOdz","pt":1743511860505,"mc":[{"id":"1.241629436","rc":[{"atl":[[11.5,42.69]],"batl":[[0,11.5,42.69]],"id":40389088},{"atb":[[5.1,242.82]],"atl":[[5.3,88.4]],"batb":[[0,5.1,242.82]],"batl":[[1,5.3,88.4]],"id":56297029},{"atb":[[9,48.05]],"atl":[[1000,4.31],[10.5,48.18]],"batb":[],"batl":[[2,10.5,48.18]],"id":27115873},{"atb":[[6.4,231.41]],"batb":[[0,6.4,231.41]],"id":26496185},{"atl":[[1000,19.22]],"id":44049799}]}]}
{"op":"mcm","id":2,"clk":"AMJ/AItQAOxz","pt":1743511860607,"mc":[{"id":"1.241629436","rc":[{"atl":[[1000,3.66],[12.5,274.63]],"batl":[],"id":27115873},{"atl":[[1000,18.87]],"id":44049799}]}]}
{"op":"mcm","id":2,"clk":"AMl/AJNQAPFz","pt":1743511860708,"mc":[{"id":"1.241629436","rc":[{"atl":[[10,55.99]],"batl":[[1,10,55.99]],"id":27115873},{"atl":[[11.5,72.53]],"batl":[[0,11.5,72.53]],"id":44049799}]}]}
{"op":"mcm","id":2,"clk":"ANJ/AJdQAPZz","pt":1743511860812,"mc":[{"id":"1.241629436","rc":[{"atl":[[22,6.76]],"batl":[],"id":58186642}]}]}
{"op":"mcm","id":2,"clk":"AOF/AKNQAIp0","pt":1743511861017,"mc":[{"id":"1.241629436","rc":[{"atl":[[5.5,63.52]],"batl":[],"id":56297029},{"atl":[[9.8,11.03]],"trd":[[9.8,136.85]],"batl":[[0,9.8,11.03]],"tv":6409.43,"id":27115873}],"tv":73777.78}]}
{"op":"mcm","id":2,"clk":"AOV/AKdQAI90","pt":1743511861118,"mc":[{"id":"1.241629436","rc":[{"atl":[[5.3,347.74]],"trd":[[5.3,1277.96]],"batl":[[0,5.3,347.74]],"ltp":5.3,"tv":16585.69,"id":270592},{"atl":[[5.2,132.79]],"trd":[[5.2,3567.58]],"batl":[[0,5.2,132.79]],"ltp":5.2,"tv":12232.04,"id":56297029}],"tv":73777.82}]}
{"op":"mcm","id":2,"clk":"APJ/AK5QAJd0","pt":1743511861228,"mc":[{"id":"1.241629436","rc":[{"atb":[[5.1,232.82]],"trd":[[5.1,3248.87]],"batb":[[0,5.1,232.82]],"ltp":5.1,"tv":12252.04,"id":56297029},{"atb":[[9.2,30.61]],"batb":[[2,9.2,30.61]],"id":27115873}],"tv":73797.82}]}
{"op":"mcm","id":2,"clk":"APh/ALRQAJx0","pt":1743511861278,"mc":[{"id":"1.241629436","rc":[{"atb":[[9.4,23.08]],"batb":[],"id":40389088}]}]}
{"op":"mcm","id":2,"clk":"AIqAAQDCUACudA==","pt":1743511861487,"mc":[{"id":"1.241629436","rc":[{"atl":[[11.5,60.34]],"batl":[],"id":35856222},{"atb":[[9.8,15.95]],"atl":[[9.8,0]],"trd":[[9.8,158.91]],"batb":[[2,9.4,60.77],[1,9.6,65.71],[0,9.8,15.95]],"batl":[[2,11,64.83],[1,10.5,48.18],[0,10,55.99]],"tv":6431.49,"id":27115873}],"tv":73819.88}]}
{"op":"mcm","id":2,"clk":"AJKAAQDGUAC6dA==","pt":1743511861591,"mc":[{"id":"1.241629436","rc":[{"atb":[[5.1,230.38]],"batb":[[0,5.1,230.38]],"id":56297029},{"atb":[[9.2,36.41]],"atl":[[12,39.3]],"batb":[],"batl":[],"id":27115873}]}]}
{"op":"mcm","id":2,"clk":"AJuAAQDJUADDdA==","pt":1743511861694,"mc":[{"id":"1.241629436","rc":[{"atb":[[9.4,66.56]],"atl":[[10.5,47.7],[10,31.29]],"batb":[[2,9.4,66.56]],"batl":[[1,10.5,47.7],[0,10,31.29]],"id":27115873}]}]}
{"op":"mcm","id":2,"clk":"AKOAAQDOUADSdA==","pt":1743511861799,"mc":[{"id":"1.241629436","rc":[{"atb":[[9.8,31.97]],"batb":[[0,9.8,31.97]],"id":27115873}]}]}
{"op":"mcm","id":2,"clk":"AK+AAQDUUADbdA==","pt":1743511861907,"mc":[{"id":"1.241629436","rc":[{"atb":[[1.06,5409.86]],"id":270592},{"atb":[[9.6,71.49]],"batb":[[1,9.6,71.49]],"id":27115873},{"atb":[[1.04,0.84]],"id":26496185}]}]}
{"op":"mcm","id":2,"clk":"ALiAAQDXUADhdA==","pt":1743511862003,"mc":[{"id":"1.241629436","rc":[{"atb":[[1.03,243.57]],"atl":[[10.5,60.07]],"batl":[[1,10.5,60.07]],"id":27115873}]}]}
{"op":"mcm","id":2,"clk":"AMKAAQDbUADodA==","pt":1743511862105,"mc":[{"id":"1.241629436","rc":[{"atb":[[1.06,5409.34]],"id":270592},{"atl":[[9.8,50.23]],"batl":[[0,9.8,50.23]],"id":35856222},{"atb":[[1.04,0.47]],"id":26496185}]}]}
{"op":"mcm","id":2,"clk":"AMqAAQDeUAD0dA==","pt":1743511862204,"mc":[{"id":"1.241629436","rc":[{"atb":[[1.03,243.3]],"id":27115873}]}]}
{"op":"mcm","id":2,"clk":"ANSAAQDjUACAdQ==","pt":1743511862304,"mc":[{"id":"1.241629436","rc":[{"atb":[[1.06,5409.02]],"id":270592},{"atb":[[1.04,0],[1.23,4]],"id":26496185},{"atb":[[11,140.77]],"trd":[[11,1308.49]],"batb":[[0,11,140.77]],"ltp":11,"tv":4517.55,"id":44049799}],"tv":73823.88}]}
{"op":"mcm","id":2,"clk":"AOCAAQDnUACIdQ==","pt":1743511862412,"mc":[{"id":"1.241629436","rc":[{"atb":[[5.2,250.74]],"batb":[[0,5.2,250.74]],"id":270592},{"atb":[[1.03,242.73]],"id":27115873},{"atl":[[21,11.18]],"batl":[],"id":58186642},{"atb":[[1.23,3.09]],"atl":[[6.6,31.35]],"trd":[[6.6,1820.23]],"batl":[[0,6.6,31.35]],"tv":12021.18,"id":26496185}],"tv":73824.82}]}
{"op":"mcm","id":2,"clk":"AOyAAQDrUACRdQ==","pt":1743511862512,"mc":[{"id":"1.241629436","rc":[{"atl":[[1000,23.16]],"id":270592},{"atb":[[9.8,32.54]],"batb":[[0,9.8,32.54]],"id":27115873},{"atb":[[1.23,3]],"id":26496185}]}]}
{"op":"mcm","id":2,"clk":"APaAAQDvUACXdQ==","pt":1743511862619,"mc":[{"id":"1.241629436","rc":[{"atl":[[5.4,183.12]],"batl":[[1,5.4,183.12]],"id":270592},{"atl":[[6.6,31.26]],"trd":[[6.6,1820.41]],"batl":[[0,6.6,31.26]],"tv":12021.36,"id":26496185}],"tv":73825}]}
{"op":"mcm","id":2,"clk":"AP2AAQDyUACddQ==","pt":1743511862716,"mc":[{"id":"1.241629436","rc":[{"atl":[[1000,2.25]],"id":40389088},{"atl":[[1000,21.16]],"id":270592}]}]}
{"op":"mcm","id":2,"clk":"AIiBAQD3UACodQ==","pt":1743511862824,"mc":[{"id":"1.241629436","rc":[{"atb":[[5.2,249.75]],"trd":[[5.2,1673.12]],"batb":[[0,5.2,249.75]],"ltp":5.2,"tv":16587.67,"id":270592}],"tv":73826.98}]}
{"op":"mcm","id":2,"clk":"AIyBAQD9UACxdQ==","pt":1743511862916,"mc":[{"id":"1.241629436","rc":[{"atl":[[1000,1.04]],"id":40389088},{"atb":[[5.2,248.76],[5,347.91],[5.1,290.06]],"batb":[[2,5,347.91],[1,5.1,290.06],[0,5.2,248.76]],"id":270592}]}]}
{"op":"mcm","id":2,"clk":"AJmBAQCCUQC4dQ==","pt":1743511863029,"mc":[{"id":"1.241629436","rc":[{"atb":[[5.2,247.98]],"trd":[[5.2,1674.68]],"batb":[[0,5.2,247.98]],"tv":16589.23,"id":270592}],"tv":73828.54}]}
{"op":"mcm","id":2,"clk":"AJ6BAQCFUQC+dQ==","pt":1743511863075,"mc":[{"id":"1.241629436","rc":[{"atl":[[1000,0.25]],"id":40389088},{"atl":[[5.3,347.93]],"batl":[[0,5.3,347.93]],"id":270592}]}]}
{"op":"mcm","id":2,"clk":"AKuBAQCHUQDBdQ==","pt":1743511863176,"mc":[{"id":"1.241629436","rc":[{"atb":[[11,95.68]],"trd":[[11,72.67]],"batb":[[0,11,95.68]],"tv":6151.66,"id":40389088}],"tv":73830.12}]}
{"op":"mcm","id":2,"clk":"AL+BAQCRUQDadQ==","pt":1743511863489,"mc":[{"id":"1.241629436","rc":[{"atb":[[1.17,2.33]],"id":40389088},{"atb":[[1.17,7.75]],"atl":[[1000,0.53]],"id":35856222},{"atb":[[9.6,74.34]],"batb":[[1,9.6,74.34]],"id":27115873},{"atb":[[11,143.07]],"atl":[[1000,19.34]],"batb":[[0,11,143.07]],"id":44049799}]}]}
{"op":"mcm","id":2,"clk":"AMOBAQCUUQDldQ==","pt":1743511863590,"mc":[{"id":"1.241629436","rc":[{"atb":[[1.17,2]],"id":40389088},{"atb":[[1.17,7.15]],"atl":[[1000,0.41]],"id":35856222},{"atl":[[1000,18.87]],"id":44049799}]}]}
{"op":"mcm","id":2,"clk":"AMqBAQCaUQDsdQ==","pt":1743511863698,"mc":[{"id":"1.241629436","rc":[{"atb":[[11,96.01]],"batb":[[0,11,96.01]],"id":40389088},{"atb":[[9.6,17.88]],"atl":[[10,94.54]],"batb":[[0,9.6,17.88]],"batl":[[1,10,94.54]],"id":35856222},{"atl":[[12,39.13]],"batl":[[1,12,39.13]],"id":44049799}]}]}
{"op":"mcm","id":2,"clk":"ANSBAQCeUQD1dQ==","pt":1743511863796,"mc":[{"id":"1.241629436","rc":[{"atl":[[10,107.34]],"batl":[[1,10,107.34]],"id":35856222}]}]}
{"op":"mcm","id":2,"clk":"AJeCAQDRUQDDdg==","pt":1743511864821,"mc":[{"id":"1.241629436","rc":[{"atb":[[5.1,260.38]],"batb":[[0,5.1,260.38]],"id":56297029},{"atb":[[6.4,229.41]],"trd":[[6.4,3283.46]],"batb":[[0,6.4,229.41]],"ltp":6.4,"tv":12025.36,"id":26496185}],"tv":73834.12}]}
{"op":"mcm","id":2,"clk":"AJ6CAQDXUQDKdg==","pt":1743511864921,"mc":[{"id":"1.241629436","rc":[{"atl":[[10,94.54]],"batl":[[1,10,94.54]],"id":35856222}]}]}
{"op":"mcm","id":2,"clk":"AK+CAQDmUQDZdg==","pt":1743511865126,"mc":[{"id":"1.241629436","rc":[{"atl":[[1000,23.16]],"id":270592}]}]}
{"op":"mcm","id":2,"clk":"AMCCAQDsUQDodg==","pt":1743511865282,"mc":[{"id":"1.241629436","rc":[{"atl":[[1000,21.16]],"id":270592}]}]}
{"op":"mcm","id":2,"clk":"AMeCAQDwUQDudg==","pt":1743511865435,"mc":[{"id":"1.241629436","rc":[{"atl":[[11.5,36.87]],"trd":[[11.5,1096.57]],"batl":[[0,11.5,36.87]],"ltp":11.5,"tv":6163.3,"id":40389088},{"atl":[[9.8,47.81]],"trd":[[9.8,483.36]],"batl":[[0,9.8,47.81]],"ltp":9.8,"tv":9032.61,"id":35856222},{"atl":[[65,8.57]],"trd":[[65,136.28]],"batl":[[0,65,8.57]],"tv":1656.8,"id":59626646},{"atb":[[5.1,257.96]],"trd":[[5.1,3253.72]],"batb":[[0,5.1,257.96]],"tv":12256.89,"id":56297029},{"atb":[[9.8,30.11]],"trd":[[9.8,163.75]],"batb":[[0,9.8,30.11]],"tv":6436.33,"id":27115873},{"atb":[[16.5,32.08]],"trd":[[16.5,376.58]],"batb":[[0,16.5,32.08]],"tv":5198.7,"id":58186642},{"atb":[[11,140.65]],"trd":[[11,1313.33]],"batb":[[0,11,140.65]],"tv":4522.39,"id":44049799}],"tv":73881.61}]}
{"op":"mcm","id":2,"clk":"ANWCAQD3UQD+dg==","pt":1743511865589,"mc":[{"id":"1.241629436","rc":[{"atb":[[9.6,48.88]],"batb":[[0,9.6,48.88]],"id":35856222},{"atl":[[65,10.47]],"batl":[[0,65,10.47]],"id":59626646},{"atl":[[12,38.07],[10.5,63.49]],"batl":[[1,10.5,63.49]],"id":27115873},{"atb":[[16.5,39.52]],"atl":[[17,11.73]],"batb":[[0,16.5,39.52]],"batl":[[0,17,11.73]],"id":58186642}]}]}
{"op":"mcm","id":2,"clk":"AOOCAQCCUgCOdw==","pt":1743511865814,"mc":[{"id":"1.241629436","rc":[{"atl":[[9.8,47.3]],"batl":[[0,9.8,47.3]],"id":35856222}]}]}
{"op":"mcm","id":2,"clk":"AOuCAQCGUgCZdw==","pt":1743511865895,"mc":[{"id":"1.241629436","rc":[{"atl":[[5.7,79.19]],"batl":[],"id":270592}]}]}
{"op":"mcm","id":2,"clk":"AIuDAQCdUgC4dw==","pt":1743511866418,"mc":[{"id":"1.241629436","rc":[{"atl":[[10.5,63.42]],"batl":[[1,10.5,63.42]],"id":27115873}]}]}
{"op":"mcm","id":2,"clk":"AJCDAQChUgDFdw==","pt":1743511866521,"mc":[{"id":"1.241629436","rc":[{"atl":[[10,32.29]],"batl":[[0,10,32.29]],"id":27115873}]}]}
{"op":"mcm","id":2,"clk":"AJmDAQCpUgDKdw==","pt":1743511866620,"mc":[{"id":"1.241629436","rc":[{"atl":[[5.2,162.79]],"batl":[[0,5.2,162.79]],"id":56297029},{"atl":[[10.5,63.92],[10,31.36]],"batl":[[1,10.5,63.92],[0,10,31.36]],"id":27115873}]}]}
{"op":"mcm","id":2,"clk":"AJ+DAQCvUgDRdw==","pt":1743511866724,"mc":[{"id":"1.241629436","rc":[{"atb":[[9.2,65.8]],"batb":[[2,9.2,65.8]],"id":35856222},{"atb":[[5.1,256.96]],"trd":[[5.1,3255.72]],"batb":[[0,5.1,256.96]],"tv":12258.89,"id":56297029},{"atl":[[6.6,21.26]],"trd":[[6.6,1840.41]],"batl":[[0,6.6,21.26]],"ltp":6.6,"tv":12045.36,"id":26496185}],"tv":73903.61}]}
{"op":"mcm","id":2,"clk":"AKiDAQCxUgDUdw==","pt":1743511866819,"mc":[{"id":"1.241629436","rc":[{"atb":[[11,95.68]],"batb":[[0,11,95.68]],"id":40389088},{"atl":[[10,94.42]],"batl":[[1,10,94.42]],"id":35856222},{"atb":[[60,16.86]],"batb":[[0,60,16.86]],"id":59626646},{"atb":[[9.8,32.61],[9.6,71.49]],"atl":[[1000,4.55],[10,30.71]],"batb":[[1,9.6,71.49],[0,9.8,32.61]],"batl":[[0,10,30.71]],"id":27115873},{"atb":[[11,139.54]],"batb":[[0,11,139.54]],"id":44049799}]}]}
{"op":"mcm","id":2,"clk":"ALCDAQC2UgDcdw==","pt":1743511866920,"mc":[{"id":"1.241629436","rc":[{"atl":[[10,114.22]],"batl":[[1,10,114.22]],"id":35856222},{"atl":[[1000,3.66],[10,26.71]],"trd":[[10,475.24]],"batl":[[0,10,26.71]],"ltp":10,"tv":6444.33,"id":27115873},{"atb":[[11,123.18]],"batb":[[0,11,123.18]],"id":44049799}],"tv":73911.61}]}
{"op":"mcm","id":2,"clk":"ALyDAQDAUgDodw==","pt":1743511867026,"mc":[{"id":"1.241629436","rc":[{"atl":[[10.5,64.43],[10,27.09]],"batl":[[1,10.5,64.43],[0,10,27.09]],"id":27115873},{"atl":[[14,20.61]],"batl":[],"id":44049799}]}]}
{"op":"mcm","id":2,"clk":"AMWDAQDJUgDtdw==","pt":1743511867129,"mc":[{"id":"1.241629436","rc":[{"atl":[[10.5,63.93]],"batl":[[1,10.5,63.93]],"id":27115873}]}]}
{"op":"mcm","id":2,"clk":"ANuDAQDYUgD7dw==","pt":1743511867383,"mc":[{"id":"1.241629436","rc":[{"atb":[[5.2,245.98],[4.6,120.2]],"trd":[[5.2,1678.68]],"batb":[[0,5.2,245.98]],"tv":16593.23,"id":270592}],"tv":73915.61}]}
{"op":"mcm","id":2,"clk":"AO+DAQDpUgCUeA==","pt":1743511867700,"mc":[{"id":"1.241629436","rc":[{"atb":[[5.2,243.98]],"trd":[[5.2,1682.68]],"batb":[[0,5.2,243.98]],"tv":16597.23,"id":270592}],"tv":73919.61}]}
{"op":"mcm","id":2,"clk":"APyDAQD6UgCjeA==","pt":1743511867904,"mc":[{"id":"1.241629436","rc":[{"atl":[[1000,23.16]],"id":270592}]}]}
{"op":"mcm","id":2,"clk":"AIWEAQD/UgCpeA==","pt":1743511868012,"mc":[{"id":"1.241629436","rc":[{"atl":[[10,101.42]],"batl":[[1,10,101.42]],"id":35856222}]}]}
{"op":"mcm","id":2,"clk":"AI2EAQCEUwC1eA==","pt":1743511868108,"mc":[{"id":"1.241629436","rc":[{"atl":[[1000,21.16]],"id":270592}]}]}
{"op":"mcm","id":2,"clk":"AJaEAQCJUwDGeA==","pt":1743511868219,"mc":[{"id":"1.241629436","rc":[{"atb":[[9.4,65.35]],"batb":[[1,9.4,65.35]],"id":35856222},{"atb":[[9.8,29.61]],"atl":[[10,54.07]],"trd":[[9.8,169.75]],"batb":[[0,9.8,29.61]],"batl":[[0,10,54.07]],"ltp":9.8,"tv":6450.33,"id":27115873},{"atb":[[6.4,226.34]],"batb":[[0,6.4,226.34]],"id":26496185}],"tv":73925.61}]}
{"op":"mcm","id":2,"clk":"AJyEAQCTUwDKeA==","pt":1743511868315,"mc":[{"id":"1.241629436","rc":[{"atb":[[9.6,48.89]],"batb":[[0,9.6,48.89]],"id":35856222},{"atb":[[9.6,65.71]],"atl":[[10.5,64.43]],"batb":[[1,9.6,65.71]],"batl":[[1,10.5,64.43]],"id":27115873},{"atb":[[6.4,229.41]],"batb":[[0,6.4,229.41]],"id":26496185}]}]}
{"op":"mcm","id":2,"clk":"AKuEAQCZUwDVeA==","pt":1743511868419,"mc":[{"id":"1.241629436","rc":[{"atl":[[1000,23.16]],"id":270592},{"atb":[[9.8,13.59]],"batb":[[0,9.8,13.59]],"id":27115873}]}]}
{"op":"mcm","id":2,"clk":"ALuEAQChUwDveA==","pt":1743511868626,"mc":[{"id":"1.241629436","rc":[{"atl":[[1000,21.16]],"id":270592},{"atl":[[10,62.41]],"batl":[[0,10,62.41]],"id":27115873}]}]}
{"op":"mcm","id":2,"clk":"AMKEAQCoUwDzeA==","pt":1743511868726,"mc":[{"id":"1.241629436","rc":[{"atl":[[6.6,11.26]],"trd":[[6.6,1860.41]],"batl":[[0,6.6,11.26]],"tv":12065.36,"id":26496185}],"tv":73945.61}]}
{"op":"mcm","id":2,"clk":"AMiEAQCvUwCBeQ==","pt":1743511868828,"mc":[{"id":"1.241629436","rc":[{"atb":[[5.1,279.22]],"batb":[[1,5.1,279.22]],"id":270592},{"atb":[[6.4,238.15]],"atl":[[6.6,31.09]],"batb":[[0,6.4,238.15]],"batl":[[0,6.6,31.09]],"id":26496185}]}]}
{"op":"mcm","id":2,"clk":"AJWFAQDnUwDaeQ==","pt":1743511869806,"mc":[{"id":"1.241629436","rc":[{"atb":[[1.17,1.38]],"id":270592},{"atl":[[65,12.42]],"batl":[[0,65,12.42]],"id":59626646},{"atl":[[6.8,138.1]],"batl":[[1,6.8,138.1]],"id":26496185},{"atl":[[16,9.7]],"batl":[],"id":44049799}]}]}
{"op":"mcm","id":2,"clk":"AJyFAQDsUwDdeQ==","pt":1743511869905,"mc":[{"id":"1.241629436","rc":[{"atb":[[1.17,1]],"id":270592},{"atb":[[9.6,54.76]],"batb":[[0,9.6,54.76]],"id":35856222},{"atb":[[60,13.95]],"batb":[[0,60,13.95]],"id":59626646}]}]}
{"op":"mcm","id":2,"clk":"AKiFAQD0UwDqeQ==","pt":1743511870015,"mc":[{"id":"1.241629436","rc":[{"atb":[[5.2,244.36]],"batb":[[0,5.2,244.36]],"id":270592}]}]}
{"op":"mcm","id":2,"clk":"AMGFAQCAVACAeg==","pt":1743511870315,"mc":[{"id":"1.241629436","rc":[{"atb":[[6.4,218.15]],"trd":[[6.4,3323.46]],"batb":[[0,6.4,218.15]],"ltp":6.4,"tv":12105.36,"id":26496185}],"tv":73985.61}]}
{"op":"mcm","id":2,"clk":"AMmFAQCGVACNeg==","pt":1743511870425,"mc":[{"id":"1.241629436","rc":[{"atl":[[6.6,40.38]],"batl":[[0,6.6,40.38]],"id":26496185}]}]}
{"op":"mcm","id":2,"clk":"AM+FAQCKVACVeg==","pt":1743511870529,"mc":[{"id":"1.241629436","rc":[{"atl":[[1000,23.16]],"id":270592},{"atb":[[9.4,77.2]],"atl":[[9.8,54.3]],"batb":[[1,9.4,77.2]],"batl":[[0,9.8,54.3]],"id":35856222},{"atb":[[6.4,219.93]],"batb":[[0,6.4,219.93]],"id":26496185}]}]}
{"op":"mcm","id":2,"clk":"ANWFAQCQVACXeg==","pt":1743511870622,"mc":[{"id":"1.241629436","rc":[{"atb":[[8.4,63.86],[3,7.75]],"atl":[[9.8,44.35]],"trd":[[9.8,503.27]],"batb":[],"batl":[[0,9.8,44.35]],"tv":9052.52,"id":35856222},{"atb":[[60,12.31]],"trd":[[60,304.06]],"batb":[[0,60,12.31]],"ltp":60,"tv":1660.08,"id":59626646},{"atb":[[6.2,174.06],[6.4,191.94]],"batb":[[1,6.2,174.06],[0,6.4,191.94]],"id":26496185}],"tv":74008.8}]}
{"op":"mcm","id":2,"clk":"ANqFAQCVVACneg==","pt":1743511870729,"mc":[{"id":"1.241629436","rc":[{"atl":[[1000,21.16]],"id":270592},{"atl":[[10,108.92]],"batl":[[1,10,108.92]],"id":35856222}]}]}
{"op":"mcm","id":2,"clk":"AO2FAQCYVACxeg==","pt":1743511870834,"mc":[{"id":"1.241629436","rc":[{"atb":[[9.6,61.37]],"atl":[[9.8,30.6]],"trd":[[9.8,530.77]],"batb":[[0,9.6,61.37]],"batl":[[0,9.8,30.6]],"tv":9080.02,"id":35856222},{"atl":[[10,64.41]],"batl":[[0,10,64.41]],"id":27115873}],"tv":74036.3}]}
{"op":"mcm","id":2,"clk":"AIKGAQClVADDeg==","pt":1743511871040,"mc":[{"id":"1.241629436","rc":[{"atb":[[5.1,270.68]],"batb":[[1,5.1,270.68]],"id":270592},{"atl":[[9.8,23.81],[10.5,57.87],[10,108.41]],"batl":[[2,10.5,57.87],[1,10,108.41],[0,9.8,23.81]],"id":35856222},{"atb":[[6.4,212.94]],"batb":[[0,6.4,212.94]],"id":26496185}]}]}
{"op":"mcm","id":2,"clk":"AI6GAQCwVADQeg==","pt":1743511871191,"mc":[{"id":"1.241629436","rc":[{"atb":[[5.1,279.22]],"atl":[[5.3,353.99]],"batb":[[1,5.1,279.22]],"batl":[[0,5.3,353.99]],"id":270592},{"atb":[[9.6,61.89]],"batb":[[0,9.6,61.89]],"id":35856222},{"atl":[[7,43.31]],"batl":[[2,7,43.31]],"id":26496185}]}]}
{"op":"mcm","id":2,"clk":"AKCGAQC9VADleg==","pt":1743511871394,"mc":[{"id":"1.241629436","rc":[{"atl":[[14.5,24.48]],"batl":[],"id":44049799}]}]}
{"op":"mcm","id":2,"clk":"AK6GAQDHVAD5eg==","pt":1743511871596,"mc":[{"id":"1.241629436","rc":[{"atb":[[11,98.93]],"batb":[[0,11,98.93]],"id":40389088}]}]}
{"op":"mcm","id":2,"clk":"AM6GAQDTVACRew==","pt":1743511871911,"mc":[{"id":"1.241629436","rc":[{"atl":[[65,12.45]],"batl":[[0,65,12.45]],"id":59626646}]}]}
{"op":"mcm","id":2,"clk":"ANOGAQDUVACYew==","pt":1743511872003,"mc":[{"id":"1.241629436","rc":[{"atb":[[1.04,0.84]],"id":26496185}]}]}
{"op":"mcm","id":2,"clk":"AOeGAQDaVACqew==","pt":1743511872215,"mc":[{"id":"1.241629436","rc":[{"atb":[[1.04,0.47]],"id":26496185}]}]}
{"op":"mcm","id":2,"clk":"AOqGAQDbVACvew==","pt":1743511872317,"mc":[{"id":"1.241629436","rc":[{"atb":[[5.2,243.58]],"trd":[[5.2,1684.24]],"batb":[[0,5.2,243.58]],"tv":16598.79,"id":270592}],"tv":74037.86}]}
{"op":"mcm","id":2,"clk":"APOGAQDgVAC1ew==","pt":1743511872412,"mc":[{"id":"1.241629436","rc":[{"atl":[[5.4,133.12]],"batl":[[1,5.4,133.12]],"id":270592},{"atl":[[10.5,64.87]],"batl":[[2,10.5,64.87]],"id":35856222},{"atb":[[1.04,0]],"id":26496185}]}]}
{"op":"mcm","id":2,"clk":"AIGHAQDjVADAew==","pt":1743511872515,"mc":[{"id":"1.241629436","rc":[{"atl":[[5.3,403.99]],"batl":[[0,5.3,403.99]],"id":270592},{"atl":[[6.6,39.91]],"trd":[[6.6,1861.35]],"batl":[[0,6.6,39.91]],"ltp":6.6,"tv":12106.3,"id":26496185}],"tv":74038.8}]}
{"op":"mcm","id":2,"clk":"AIiHAQDlVADGew==","pt":1743511872616,"mc":[{"id":"1.241629436","rc":[{"atl":[[7,40.06]],"batl":[[2,7,40.06]],"id":26496185}]}]}
{"op":"mcm","id":2,"clk":"AKWHAQDwVADeew==","pt":1743511872928,"mc":[{"id":"1.241629436","rc":[{"atb":[[11,122.07]],"batb":[[0,11,122.07]],"id":44049799}]}]}
{"op":"mcm","id":2,"clk":"ANuHAQCGVQCFfA==","pt":1743511873494,"mc":[{"id":"1.241629436","rc":[{"atb":[[9.6,30.64]],"trd":[[9.6,284.83]],"batb":[[0,9.6,30.64]],"ltp":9.6,"tv":9142.52,"id":35856222}],"tv":74101.3}]}
{"op":"mcm","id":2,"clk":"AOOHAQCNVQCPfA==","pt":1743511873598,"mc":[{"id":"1.241629436","rc":[{"atb":[[9,72.06],[9.6,24.77]],"atl":[[9.8,41.56]],"batb":[[0,9.6,24.77]],"batl":[[0,9.8,41.56]],"id":35856222},{"atl":[[17,4]],"batl":[[0,17,4]],"id":58186642}]}]}
{"op":"mcm","id":2,"clk":"AO6HAQCTVQCUfA==","pt":1743511873705,"mc":[{"id":"1.241629436","rc":[{"atb":[[9,68.06],[9.6,13.68]],"atl":[[9.8,49.44],[10,108.92]],"trd":[[9.6,293.79]],"batb":[[0,9.6,13.68]],"batl":[[1,10,108.92],[0,9.8,49.44]],"tv":9151.48,"id":35856222}],"tv":74110.26}]}
{"op":"mcm","id":2,"clk":"APSHAQCbVQCYfA==","pt":1743511873802,"mc":[{"id":"1.241629436","rc":[{"atl":[[1000,23.16]],"id":270592},{"atb":[[9.6,10.95]],"trd":[[9.6,298.21]],"batb":[[0,9.6,10.95]],"tv":9155.9,"id":35856222}],"tv":74114.68}]}
{"op":"mcm","id":2,"clk":"APqHAQCfVQCefA==","pt":1743511873906,"mc":[{"id":"1.241629436","rc":[{"atl":[[11.5,27.87]],"trd":[[11.5,1114.57]],"batl":[[0,11.5,27.87]],"tv":6181.3,"id":40389088},{"atb":[[9.6,0]],"atl":[[11.5,62.51],[9.6,17.25]],"trd":[[9.6,320.1]],"batb":[[2,9,68.06],[1,9.2,65.8],[0,9.4,77.2]],"batl":[[2,10,108.92],[1,9.8,49.44],[0,9.6,17.25]],"tv":9177.79,"id":35856222}],"tv":74154.57}]}
{"op":"mcm","id":2,"clk":"APyHAQCiVQCufA==","pt":1743511874007,"mc":[{"id":"1.241629436","rc":[{"atl":[[11.5,13.07]],"batl":[[0,11.5,13.07]],"id":40389088},{"atl":[[1000,21.16]],"id":270592},{"atl":[[9.8,49.95]],"batl":[[1,9.8,49.95]],"id":35856222},{"atb":[[11,138.43]],"batb":[[0,11,138.43]],"id":44049799}]}]}
{"op":"mcm","id":2,"clk":"AIOIAQCnVQC1fA==","pt":1743511874109,"mc":[{"id":"1.241629436","rc":[{"atl":[[9.8,40.14],[9.6,25.35]],"batl":[[1,9.8,40.14],[0,9.6,25.35]],"id":35856222}]}]}
{"op":"mcm","id":2,"clk":"AIiIAQCsVQDAfA==","pt":1743511874220,"mc":[{"id":"1.241629436","rc":[{"atb":[[11.5,15.2],[11,97.93]],"atl":[[11.5,0]],"trd":[[11.5,1140.72],[11,74.67]],"batb":[[2,10.5,29.55],[1,11,97.93],[0,11.5,15.2]],"batl":[[2,13,20.92],[1,12.5,53.65],[0,12,46.06]],"tv":6209.45,"id":40389088},{"atl":[[9.8,39.63],[11.5,60.34]],"batl":[[1,9.8,39.63]],"id":35856222}],"tv":74182.72}]}
{"op":"mcm","id":2,"clk":"AIyIAQCxVQDKfA==","pt":1743511874320,"mc":[{"id":"1.241629436","rc":[{"atb":[[9.4,73.72]],"atl":[[10,114.9]],"batb":[[0,9.4,73.72]],"batl":[[2,10,114.9]],"id":35856222}]}]}
{"op":"mcm","id":2,"clk":"AJGIAQC1VQDZfA==","pt":1743511874430,"mc":[{"id":"1.241629436","rc":[{"atb":[[11.5,27.57]],"atl":[[14.5,12.78],[14,19.6],[13.5,15.77],[12,52.06]],"batb":[[0,11.5,27.57]],"batl":[[0,12,52.06]],"id":40389088},{"atb":[[9.4,59.72]],"batb":[[0,9.4,59.72]],"id":35856222}]}]}
{"op":"mcm","id":2,"clk":"AJeIAQC5VQDefA==","pt":1743511874517,"mc":[{"id":"1.241629436","rc":[{"atb":[[11.5,25.57]],"atl":[[12,47.12]],"trd":[[11.5,1144.72]],"batb":[[0,11.5,25.57]],"batl":[[0,12,47.12]],"tv":6213.45,"id":40389088},{"atb":[[5,1163.65]],"batb":[[1,5,1163.65]],"id":56297029}],"tv":74186.72}]}
{"op":"mcm","id":2,"clk":"AJ6IAQC9VQDkfA==","pt":1743511874620,"mc":[{"id":"1.241629436","rc":[{"atb":[[9.4,44.2]],"batb":[[0,9.4,44.2]],"id":35856222},{"atl":[[10,66.41]],"batl":[[0,10,66.41]],"id":27115873},{"atb":[[11,122.07]],"batb":[[0,11,122.07]],"id":44049799}]}]}
{"op":"mcm","id":2,"clk":"ALOIAQDMVQD/fA==","pt":1743511874928,"mc":[{"id":"1.241629436","rc":[{"atb":[[4.6,109.1]],"batb":[],"id":56297029},{"atl":[[17.5,14.65]],"batl":[[1,17.5,14.65]],"id":58186642}]}]}
{"op":"mcm","id":2,"clk":"ALeIAQDQVQCIfQ==","pt":1743511875029,"mc":[{"id":"1.241629436","rc":[{"atb":[[4.9,91.55]],"batb":[[2,4.9,91.55]],"id":56297029}]}]}
{"op":"mcm","id":2,"clk":"AMGIAQDYVQCVfQ==","pt":1743511875188,"mc":[{"id":"1.241629436","rc":[{"atl":[[10,127.7]],"batl":[[2,10,127.7]],"id":35856222},{"atl":[[6.8,157.51]],"batl":[[1,6.8,157.51]],"id":26496185}]}]}
{"op":"mcm","id":2,"clk":"AOCIAQDzVQC3fQ==","pt":1743511875705,"mc":[{"id":"1.241629436","rc":[{"atb":[[5.2,239.39]],"trd":[[5.2,1692.62]],"batb":[[0,5.2,239.39]],"tv":16607.17,"id":270592}],"tv":74195.1}]}
{"op":"mcm","id":2,"clk":"AOeIAQD4VQC+fQ==","pt":1743511875809,"mc":[{"id":"1.241629436","rc":[{"atb":[[5.2,234.39]],"trd":[[5.2,1702.62]],"batb":[[0,5.2,234.39]],"tv":16617.17,"id":270592}],"tv":74205.1}]}
{"op":"mcm","id":2,"clk":"APOIAQD8VQDFfQ==","pt":1743511875909,"mc":[{"id":"1.241629436","rc":[{"atl":[[1000,23.16]],"id":270592}]}]}
{"op":"mcm","id":2,"clk":"AP+IAQD9VQDMfQ==","pt":1743511876011,"mc":[{"id":"1.241629436","rc":[{"atl":[[10,114.9]],"batl":[[2,10,114.9]],"id":35856222}]}]}
{"op":"mcm","id":2,"clk":"AIqJAQCCVgDUfQ==","pt":1743511876124,"mc":[{"id":"1.241629436","rc":[{"atl":[[1000,21.16]],"id":270592}]}]}
{"op":"mcm","id":2,"clk":"AKmJAQCSVgDnfQ==","pt":1743511876429,"mc":[{"id":"1.241629436","rc":[{"atb":[[6.4,208.89]],"trd":[[6.4,3331.56]],"batb":[[0,6.4,208.89]],"ltp":6.4,"tv":12114.4,"id":26496185}],"tv":74213.2}]}
{"op":"mcm","id":2,"clk":"AK+JAQCWVgDqfQ==","pt":1743511876525,"mc":[{"id":"1.241629436","rc":[{"atb":[[10.5,37.53]],"batb":[[2,10.5,37.53]],"id":40389088},{"atl":[[10,119.12]],"batl":[[2,10,119.12]],"id":35856222}]}]}
{"op":"mcm","id":2,"clk":"AMyJAQCyVgCMfg==","pt":1743511876934,"mc":[{"id":"1.241629436","rc":[{"atb":[[1.17,2.41],[11,97.56]],"batb":[[1,11,97.56]],"id":40389088}]}]}
{"op":"mcm","id":2,"clk":"ANqJAQC6VgCWfg==","pt":1743511877139,"mc":[{"id":"1.241629436","rc":[{"atb":[[1.17,2]],"id":40389088},{"atl":[[19,10.99]],"batl":[],"id":58186642}]}]}
{"op":"mcm","id":2,"clk":"AN+JAQDBVgCXfg==","pt":1743511877189,"mc":[{"id":"1.241629436","rc":[{"atb":[[11.5,25.98]],"batb":[[0,11.5,25.98]],"id":40389088},{"atl":[[17.5,14.95]],"batl":[[1,17.5,14.95]],"id":58186642}]}]}
{"op":"mcm","id":2,"clk":"AOqJAQDHVgCdfg==","pt":1743511877299,"mc":[{"id":"1.241629436","rc":[{"atb":[[6.4,206.47]],"trd":[[6.4,3336.4]],"batb":[[0,6.4,206.47]],"tv":12119.24,"id":26496185}],"tv":74218.04}]}
{"op":"mcm","id":2,"clk":"AO+JAQDLVgCkfg==","pt":1743511877397,"mc":[{"id":"1.241629436","rc":[{"atl":[[10,131.92]],"batl":[[2,10,131.92]],"id":35856222}]}]}
{"op":"mcm","id":2,"clk":"APyJAQDYVgC2fg==","pt":1743511877600,"mc":[{"id":"1.241629436","rc":[{"atl":[[1000,1.25]],"id":40389088},{"atl":[[1000,22.16]],"id":270592},{"atl":[[1000,1.41]],"id":35856222},{"atl":[[1000,5.52]],"id":56297029},{"atl":[[1000,3.9]],"id":26496185}]}]}
{"op":"mcm","id":2,"clk":"AISKAQDgVgC+fg==","pt":1743511877707,"mc":[{"id":"1.241629436","rc":[{"atl":[[1000,4.66]],"id":27115873}]}]}
{"op":"mcm","id":2,"clk":"AJ+KAQD5VgDUfg==","pt":1743511878110,"mc":[{"id":"1.241629436","rc":[{"atl":[[10,119.12]],"batl":[[2,10,119.12]],"id":35856222}]}]}
{"op":"mcm","id":2,"clk":"ALSKAQCGVwDhfg==","pt":1743511878327,"mc":[{"id":"1.241629436","rc":[{"atl":[[1000,0.53]],"id":40389088},{"atl":[[1000,21.78]],"id":270592},{"atl":[[1000,0.75]],"id":35856222},{"atl":[[1000,5.15]],"id":56297029},{"atl":[[1000,3.99]],"id":27115873},{"atl":[[1000,3.4]],"id":26496185}]}]}
{"op":"mcm","id":2,"clk":"ALmKAQCJVwDpfg==","pt":1743511878424,"mc":[{"id":"1.241629436","rc":[{"atl":[[12,102.7]],"batl":[[0,12,102.7]],"id":40389088},{"atl":[[5.3,278.14]],"batl":[[0,5.3,278.14]],"id":270592},{"atl":[[70,2.98],[65,14.14]],"batl":[[1,70,2.98],[0,65,14.14]],"id":59626646},{"atl":[[10,133.11]],"batl":[[0,10,133.11]],"id":27115873}]}]}
{"op":"mcm","id":2,"clk":"AM2KAQCPVwD1fg==","pt":1743511878630,"mc":[{"id":"1.241629436","rc":[{"atb":[[1.17,2.14],[11.5,0]],"atl":[[11.5,3.18]],"trd":[[11.5,1145.54]],"batb":[[2,10,66.05],[1,10.5,37.53],[0,11,97.56]],"batl":[[2,12.5,53.65],[1,12,102.7],[0,11.5,3.18]],"tv":6214.27,"id":40389088},{"atl":[[1000,21.94]],"id":270592},{"atb":[[1.17,7.45]],"id":35856222},{"atb":[[9.8,7.34]],"atl":[[10,132.73]],"trd":[[9.8,182.25]],"batb":[[0,9.8,7.34]],"batl":[[0,10,132.73]],"tv":6462.83,"id":27115873},{"atb":[[11,121.99]],"atl":[[12,38.66],[11.5,72.18]],"batb":[[0,11,121.99]],"batl":[[1,12,38.66],[0,11.5,72.18]],"id":44049799}],"tv":74231.36}]}
{"op":"mcm","id":2,"clk":"ANSKAQCTVwD7fg==","pt":1743511878732,"mc":[{"id":"1.241629436","rc":[{"atb":[[1.17,2]],"id":40389088},{"atl":[[1000,21.78]],"id":270592},{"atb":[[1.17,7.15]],"id":35856222},{"atb":[[9.8,0]],"atl":[[9.8,13.79]],"trd":[[9.8,196.95]],"batb":[[2,9.2,36.41],[1,9.4,66.56],[0,9.6,65.71]],"batl":[[2,10.5,64.43],[1,10,132.73],[0,9.8,13.79]],"tv":6477.53,"id":27115873},{"atb":[[11,138.35]],"batb":[[0,11,138.35]],"id":44049799}],"tv":74246.06}]}
{"op":"mcm","id":2,"clk":"ANWKAQCYVwCBfw==","pt":1743511878831,"mc":[{"id":"1.241629436","rc":[{"atb":[[9.4,24.38],[9.6,33]],"atl":[[14.5,11.45],[14,18.17],[13.5,14.23],[12,107.71],[11.5,6.49]],"trd":[[11.5,1145.82]],"batb":[],"batl":[[1,12,107.71],[0,11.5,6.49]],"tv":6214.55,"id":40389088},{"atl":[[5.4,133.28]],"batl":[[1,5.4,133.28]],"id":270592},{"atb":[[9.4,44.5],[9,71.57]],"batb":[[2,9,71.57],[0,9.4,44.5]],"id":35856222},{"atb":[[4.9,94.23]],"batb":[[2,4.9,94.23]],"id":56297029},{"atl":[[9.8,25.23]],"batl":[[0,9.8,25.23]],"id":27115873}],"tv":74246.34}]}
{"op":"mcm","id":2,"clk":"AOCKAQCdVwCGfw==","pt":1743511878931,"mc":[{"id":"1.241629436","rc":[{"atl":[[5.6,136.96]],"batl":[],"id":270592},{"atb":[[4.9,91.55]],"batb":[[2,4.9,91.55]],"id":56297029},{"atl":[[9.8,20.06],[12,36.09],[10.5,52.06]],"trd":[[9.8,207.29]],"batl":[[2,10.5,52.06],[0,9.8,20.06]],"tv":6487.87,"id":27115873}],"tv":74256.68}]}
{"op":"mcm","id":2,"clk":"APGKAQCoVwCVfw==","pt":1743511879135,"mc":[{"id":"1.241629436","rc":[{"atl":[[1000,0.25]],"id":40389088},{"atl":[[1000,21.16]],"id":270592},{"atl":[[1000,0.41]],"id":35856222},{"atl":[[1000,4.52]],"id":56297029},{"atb":[[8.6,35.13]],"atl":[[1000,3.66],[9.8,35.27]],"batb":[],"batl":[[0,9.8,35.27]],"id":27115873},{"atl":[[1000,2.9]],"id":26496185}]}]}
{"op":"mcm","id":2,"clk":"APeKAQCuVwCdfw==","pt":1743511879246,"mc":[{"id":"1.241629436","rc":[{"atb":[[10.5,29.55]],"atl":[[11.5,6.77]],"batb":[[1,10.5,29.55]],"batl":[[0,11.5,6.77]],"id":40389088},{"atb":[[5.2,233.77]],"atl":[[1000,23.16]],"trd":[[5.2,1703.86]],"batb":[[0,5.2,233.77]],"tv":16618.41,"id":270592},{"atb":[[9.4,44.16]],"trd":[[9.4,598.27]],"batb":[[0,9.4,44.16]],"ltp":9.4,"tv":9178.47,"id":35856222},{"atb":[[5.1,256.33]],"trd":[[5.1,3256.98]],"batb":[[0,5.1,256.33]],"tv":12260.15,"id":56297029},{"atl":[[9.8,35.6]],"batl":[[0,9.8,35.6]],"id":27115873},{"atb":[[6.4,205.97]],"trd":[[6.4,3337.4]],"batb":[[0,6.4,205.97]],"tv":12120.24,"id":26496185}],"tv":74260.86}]}
{"op":"mcm","id":2,"clk":"AISLAQC0VwCpfw==","pt":1743511879392,"mc":[{"id":"1.241629436","rc":[{"atl":[[1000,21.16]],"id":270592},{"atb":[[4.9,87.83]],"batb":[[2,4.9,87.83]],"id":56297029},{"atb":[[9.6,55.26]],"batb":[[0,9.6,55.26]],"id":27115873}]}]}
{"op":"mcm","id":2,"clk":"AIaLAQC3VwCwfw==","pt":1743511879493,"mc":[{"id":"1.241629436","rc":[{"atl":[[9.8,42.54]],"batl":[[0,9.8,42.54]],"id":27115873}]}]}
{"op":"mcm","id":2,"clk":"AJGLAQC7VwC5fw==","pt":1743511879597,"mc":[{"id":"1.241629436","rc":[{"atb":[[11,128.35]],"trd":[[11,1333.33]],"batb":[[0,11,128.35]],"tv":4542.39,"id":44049799}],"tv":74280.86}]}
{"op":"mcm","id":2,"clk":"AJ6LAQDFVwDEfw==","pt":1743511879800,"mc":[{"id":"1.241629436","rc":[{"atl":[[12,101.72]],"batl":[[1,12,101.72]],"id":40389088}]}]}
{"op":"mcm","id":2,"clk":"AKKLAQDLVwDKfw==","pt":1743511879905,"mc":[{"id":"1.241629436","rc":[{"atb":[[11,127.33]],"trd":[[11,1335.37]],"batb":[[0,11,127.33]],"tv":4544.43,"id":44049799}],"tv":74282.9}]}
{"op":"mcm","id":2,"clk":"AKyLAQDRVwDRfw==","pt":1743511880008,"mc":[{"id":"1.241629436","rc":[{"atl":[[10,114.9]],"batl":[[2,10,114.9]],"id":35856222}]}]}
{"op":"mcm","id":2,"clk":"ALOLAQDbVwDefw==","pt":1743511880209,"mc":[{"id":"1.241629436","rc":[{"atb":[[16.5,36.52]],"trd":[[16.5,382.58]],"batb":[[0,16.5,36.52]],"tv":5204.7,"id":58186642}],"tv":74288.9}]}
{"op":"mcm","id":2,"clk":"ALSLAQDlVwDqfw==","pt":1743511880312,"mc":[{"id":"1.241629436","rc":[{"atb":[[9.6,44.26]],"batb":[[0,9.6,44.26]],"id":27115873},{"atb":[[11,117.33]],"trd":[[11,1355.37]],"batb":[[0,11,117.33]],"tv":4564.43,"id":44049799}],"tv":74308.9}]}
{"op":"mcm","id":2,"clk":"AM6LAQD6VwCGgAE=","pt":1743511880724,"mc":[{"id":"1.241629436","rc":[{"atb":[[5.1,252.14]],"trd":[[5.1,3265.36]],"batb":[[0,5.1,252.14]],"tv":12268.53,"id":56297029}],"tv":74317.28}]}
{"op":"mcm","id":2,"clk":"ANuLAQCDWACTgAE=","pt":1743511880937,"mc":[{"id":"1.241629436","rc":[{"atb":[[3,9]],"id":27115873}]}]}
{"op":"mcm","id":2,"clk":"AOuLAQCLWACagAE=","pt":1743511881139,"mc":[{"id":"1.241629436","rc":[{"atb":[[16.5,17.77]],"trd":[[16.5,420.08]],"batb":[[0,16.5,17.77]],"tv":5242.2,"id":58186642}],"tv":74354.78}]}
{"op":"mcm","id":2,"clk":"APuLAQCRWAClgAE=","pt":1743511881341,"mc":[{"id":"1.241629436","rc":[{"atl":[[1000,23.16]],"id":270592},{"atb":[[16,34.46],[16.5,29.21]],"atl":[[17,10.5]],"batb":[[1,16,34.46],[0,16.5,29.21]],"batl":[[0,17,10.5]],"id":58186642}]}]}
{"op":"mcm","id":2,"clk":"AIGMAQCTWACrgAE=","pt":1743511881438,"mc":[{"id":"1.241629436","rc":[{"atb":[[11,107.33]],"trd":[[11,1375.37]],"batb":[[0,11,107.33]],"tv":4584.43,"id":44049799}],"tv":74374.78}]}
{"op":"mcm","id":2,"clk":"AK2MAQCiWADPgAE=","pt":1743511881507,"mc":[{"id":"1.241629436","rc":[{"atl":[[1000,21.16],[5.3,273.9]],"trd":[[5.3,1286.44]],"batl":[[0,5.3,273.9]],"ltp":5.3,"tv":16626.89,"id":270592},{"atb":[[16,36.33]],"batb":[[1,16,36.33]],"id":58186642},{"atb":[[6.4,234.09]],"batb":[[0,6.4,234.09]],"id":26496185}],"tv":74383.26}]}
{"op":"mcm","id":2,"clk":"AMGMAQC2WADZgAE=","pt":1743511881707,"mc":[{"id":"1.241629436","rc":[{"atb":[[2.02,40.69]],"id":270592}]}]}
{"op":"mcm","id":2,"clk":"AMqMAQC6WADfgAE=","pt":1743511881804,"mc":[{"id":"1.241629436","rc":[{"atb":[[1.06,5409.86]],"id":270592},{"atl":[[5.2,153.91]],"trd":[[5.2,3585.34]],"batl":[[0,5.2,153.91]],"ltp":5.2,"tv":12286.29,"id":56297029}],"tv":74401.02}]}
{"op":"mcm","id":2,"clk":"ANOMAQC/WADsgAE=","pt":1743511881912,"mc":[{"id":"1.241629436","rc":[{"atl":[[12,43.02],[9.6,16.26]],"trd":[[9.6,322.08]],"batl":[[0,9.6,16.26]],"ltp":9.6,"tv":9180.45,"id":35856222},{"atb":[[16,30.63]],"batb":[[1,16,30.63]],"id":58186642}],"tv":74403}]}
{"op":"mcm","id":2,"clk":"AN6MAQDDWADxgAE=","pt":1743511882008,"mc":[{"id":"1.241629436","rc":[{"atb":[[1.06,5409.34]],"id":270592},{"atb":[[9.4,74.85]],"atl":[[9.6,14.83]],"trd":[[9.6,324.94]],"batb":[[0,9.4,74.85]],"batl":[[0,9.6,14.83]],"tv":9183.31,"id":35856222},{"atb":[[1.03,243.57]],"id":27115873},{"atl":[[17,9.56]],"trd":[[17,826.18]],"batl":[[0,17,9.56]],"ltp":17,"tv":5244.08,"id":58186642}],"tv":74407.74}]}
{"op":"mcm","id":2,"clk":"AOOMAQDLWAD5gAE=","pt":1743511882109,"mc":[{"id":"1.241629436","rc":[{"atl":[[9.8,40.14],[10,108.92]],"batl":[[2,10,108.92],[1,9.8,40.14]],"id":35856222},{"atb":[[1.09,0.84]],"id":59626646}]}]}
{"op":"mcm","id":2,"clk":"AO+MAQDOWACAgQE=","pt":1743511882217,"mc":[{"id":"1.241629436","rc":[{"atb":[[1.06,5409.02]],"id":270592},{"atb":[[1.03,243.32]],"id":27115873},{"atb":[[1.08,100]],"id":26496185}]}]}
{"op":"mcm","id":2,"clk":"APWMAQDUWACJgQE=","pt":1743511882316,"mc":[{"id":"1.241629436","rc":[{"atb":[[5.2,234.09]],"batb":[[0,5.2,234.09]],"id":270592},{"atb":[[1.09,0.19]],"id":59626646}]}]}
{"op":"mcm","id":2,"clk":"AIuNAQD3WACggQE=","pt":1743511882519,"mc":[{"id":"1.241629436","rc":[{"atb":[[1.17,2.69]],"atl":[[1000,0.39]],"id":40389088},{"atb":[[1.09,0]],"id":59626646},{"atb":[[5.1,249.53]],"batb":[[0,5.1,249.53]],"id":56297029},{"atb":[[1.03,242.73]],"id":27115873}]}]}
{"op":"mcm","id":2,"clk":"AJWNAQD+WACtgQE=","pt":1743511882626,"mc":[{"id":"1.241629436","rc":[{"atb":[[60,12.5]],"batb":[[0,60,12.5]],"id":59626646},{"atb":[[9.6,44.85]],"batb":[[0,9.6,44.85]],"id":27115873}]}]}
{"op":"mcm","id":2,"clk":"AJmNAQCDWQCzgQE=","pt":1743511882721,"mc":[{"id":"1.241629436","rc":[{"atb":[[1.17,2]],"atl":[[1000,0.25]],"id":40389088},{"atb":[[5.2,233.99]],"trd":[[5.2,1704.06]],"batb":[[0,5.2,233.99]],"ltp":5.2,"tv":16627.09,"id":270592}],"tv":74407.94}]}
{"op":"mcm","id":2,"clk":"AKiNAQCMWQC9gQE=","pt":1743511882930,"mc":[{"id":"1.241629436","rc":[{"atb":[[11,98.25]],"atl":[[12,101.86]],"batb":[[0,11,98.25]],"batl":[[1,12,101.86]],"id":40389088}]}]}
{"op":"mcm","id":2,"clk":"ALaNAQCSWQDKgQE=","pt":1743511883134,"mc":[{"id":"1.241629436","rc":[{"atb":[[4.8,95.57]],"batb":[],"id":56297029}]}]}
{"op":"mcm","id":2,"clk":"AN+NAQC8WQDvgQE=","pt":1743511883592,"mc":[{"id":"1.241629436","rc":[{"atl":[[1000,2.25]],"id":40389088}]}]}
{"op":"mcm","id":2,"clk":"AOqNAQDAWQD7gQE=","pt":1743511883707,"mc":[{"id":"1.241629436","rc":[{"atl":[[1000,1.04]],"id":40389088}]}]}
{"op":"mcm","id":2,"clk":"APCNAQDDWQD/gQE=","pt":1743511883796,"mc":[{"id":"1.241629436","rc":[{"atl":[[1000,0.25]],"id":40389088},{"atb":[[5.1,240.58]],"batb":[[0,5.1,240.58]],"id":56297029},{"atb":[[16.5,26.61]],"batb":[[0,16.5,26.61]],"id":58186642}]}]}
{"op":"mcm","id":2,"clk":"APiNAQDHWQCDggE=","pt":1743511883908,"mc":[{"id":"1.241629436","rc":[{"atb":[[11,97.46]],"trd":[[11,76.25]],"batb":[[0,11,97.46]],"ltp":11,"tv":6216.13,"id":40389088}],"tv":74409.52}]}
{"op":"mcm","id":2,"clk":"AICOAQDMWQCKggE=","pt":1743511884007,"mc":[{"id":"1.241629436","rc":[{"atl":[[17,7.17]],"batl":[[0,17,7.17]],"id":58186642}]}]}
{"op":"mcm","id":2,"clk":"AIuOAQDUWQCRggE=","pt":1743511884208,"mc":[{"id":"1.241629436","rc":[{"atb":[[5.2,233.61]],"atl":[[5.4,133.12]],"batb":[[0,5.2,233.61]],"batl":[[1,5.4,133.12]],"id":270592},{"atl":[[1000,4.1],[10.5,51.55]],"batl":[[2,10.5,51.55]],"id":27115873},{"atl":[[1000,19.19]],"id":44049799}]}]}
{"op":"mcm","id":2,"clk":"AJmOAQDaWQCdggE=","pt":1743511884412,"mc":[{"id":"1.241629436","rc":[{"atl":[[1000,3.66]],"id":27115873},{"atl":[[1000,18.87]],"id":44049799}]}]}
{"op":"mcm","id":2,"clk":"AMOOAQDxWQCtggE=","pt":1743511884514,"mc":[{"id":"1.241629436","rc":[{"atl":[[10,133.17]],"batl":[[1,10,133.17]],"id":27115873},{"atl":[[11.5,72.5]],"batl":[[0,11.5,72.5]],"id":44049799}]}]}
{"op":"mcm","id":2,"clk":"AM2OAQCFWgDEggE=","pt":1743511884626,"mc":[{"id":"1.241629436","rc":[{"atl":[[1000,23.16]],"id":270592},{"atb":[[5.1,238.42]],"trd":[[5.1,3269.68]],"batb":[[0,5.1,238.42]],"ltp":5.1,"tv":12290.61,"id":56297029}],"tv":74413.84}]}
{"op":"mcm","id":2,"clk":"ANmOAQCPWgDPggE=","pt":1743511884828,"mc":[{"id":"1.241629436","rc":[{"atl":[[1000,21.16]],"id":270592}]}]}
{"op":"mcm","id":2,"clk":"APuOAQCjWgD0ggE=","pt":1743511885334,"mc":[{"id":"1.241629436","rc":[{"atb":[[6.4,231.02]],"batb":[[0,6.4,231.02]],"id":26496185}]}]}
{"op":"mcm","id":2,"clk":"AIOPAQCnWgD4ggE=","pt":1743511885436,"mc":[{"id":"1.241629436","rc":[{"atb":[[6.4,234.09]],"batb":[[0,6.4,234.09]],"id":26496185}]}]}
{"op":"mcm","id":2,"clk":"AIePAQCsWgD+ggE=","pt":1743511885535,"mc":[{"id":"1.241629436","rc":[{"atl":[[1000,23.16]],"id":270592}]}]}
{"op":"mcm","id":2,"clk":"AJePAQC5WgCHgwE=","pt":1743511885741,"mc":[{"id":"1.241629436","rc":[{"atl":[[1000,21.16]],"id":270592}]}]}
{"op":"mcm","id":2,"clk":"AKOPAQC9WgCOgwE=","pt":1743511885847,"mc":[{"id":"1.241629436","rc":[{"atl":[[5.3,285.5]],"batl":[[0,5.3,285.5]],"id":270592}]}]}
{"op":"mcm","id":2,"clk":"AKiPAQC/WgCUgwE=","pt":1743511885945,"mc":[{"id":"1.241629436","rc":[{"atl":[[11.5,7.77]],"batl":[[0,11.5,7.77]],"id":40389088}]}]}
{"op":"mcm","id":2,"clk":"ALKPAQDFWgCZgwE=","pt":1743511886054,"mc":[{"id":"1.241629436","rc":[{"atb":[[9.4,70.86]],"atl":[[9.6,2.98]],"trd":[[9.4,606.25],[9.6,348.64]],"batb":[[0,9.4,70.86]],"batl":[[0,9.6,2.98]],"ltp":9.4,"tv":9214.99,"id":35856222},{"atb":[[6.4,229.9]],"trd":[[6.4,3345.78]],"batb":[[0,6.4,229.9]],"tv":12128.62,"id":26496185}],"tv":74453.9}]}
{"op":"mcm","id":2,"clk":"AMWPAQDSWgCpgwE=","pt":1743511886303,"mc":[{"id":"1.241629436","rc":[{"atb":[[9.6,39.05]],"trd":[[9.6,83.38]],"batb":[[0,9.6,39.05]],"ltp":9.6,"tv":6499.47,"id":27115873}],"tv":74465.5}]}
{"op":"mcm","id":2,"clk":"AMyPAQDWWgCvgwE=","pt":1743511886405,"mc":[{"id":"1.241629436","rc":[{"atb":[[5.1,227.87]],"trd":[[5.1,3290.78]],"batb":[[0,5.1,227.87]],"tv":12311.71,"id":56297029},{"atb":[[9.6,35.79]],"atl":[[9.8,43.05]],"batb":[[0,9.6,35.79]],"batl":[[0,9.8,43.05]],"id":27115873}],"tv":74486.6}]}
{"op":"mcm","id":2,"clk":"ANSPAQDdWgC3gwE=","pt":1743511886519,"mc":[{"id":"1.241629436","rc":[{"atb":[[9.6,16.59]],"batb":[[0,9.6,16.59]],"id":27115873},{"atl":[[1000,3.41]],"id":58186642}]}]}
{"op":"mcm","id":2,"clk":"ANmPAQDlWgC9gwE=","pt":1743511886617,"mc":[{"id":"1.241629436","rc":[{"atb":[[4.9,86.82]],"batb":[[2,4.9,86.82]],"id":56297029},{"atb":[[9.4,60.77]],"batb":[[1,9.4,60.77]],"id":27115873}]}]}
{"op":"mcm","id":2,"clk":"AOOPAQDqWgDHgwE=","pt":1743511886731,"mc":[{"id":"1.241629436","rc":[{"atl":[[1000,23.16]],"id":270592},{"atb":[[9.6,11.19]],"trd":[[9.6,94.18]],"batb":[[0,9.6,11.19]],"tv":6510.27,"id":27115873},{"atl":[[1000,1.51]],"id":58186642}],"tv":74497.4}]}
{"op":"mcm","id":2,"clk":"AOaPAQDuWgDQgwE=","pt":1743511886815,"mc":[{"id":"1.241629436","rc":[{"atb":[[4.8,96.6]],"batb":[],"id":56297029},{"atb":[[9.6,0]],"trd":[[9.6,116.56]],"batb":[[2,9,48.05],[1,9.2,36.41],[0,9.4,60.77]],"tv":6532.65,"id":27115873},{"atl":[[1000,1.41]],"id":58186642}],"tv":74519.78}]}
{"op":"mcm","id":2,"clk":"APSPAQDzWgDZgwE=","pt":1743511886922,"mc":[{"id":"1.241629436","rc":[{"atl":[[1000,21.16]],"id":270592},{"atb":[[8.8,46.56]],"atl":[[9.8,49.99],[12.5,272.81],[11.5,43.65],[9.6,11.81]],"batb":[],"batl":[[2,10,133.17],[1,9.8,49.99],[0,9.6,11.81]],"id":27115873},{"atl":[[17,7.27]],"batl":[[0,17,7.27]],"id":58186642}]}]}
{"op":"mcm","id":2,"clk":"AP6PAQD7WgDmgwE=","pt":1743511887030,"mc":[{"id":"1.241629436","rc":[{"atl":[[14,23.58],[11.5,27.05],[9.6,15.76]],"batl":[[0,9.6,15.76]],"id":27115873}]}]}
{"op":"mcm","id":2,"clk":"AIiQAQCDWwDrgwE=","pt":1743511887135,"mc":[{"id":"1.241629436","rc":[{"atb":[[4.8,99.4]],"batb":[],"id":56297029}]}]}
{"op":"mcm","id":2,"clk":"AIyQAQCJWwDvgwE=","pt":1743511887228,"mc":[{"id":"1.241629436","rc":[{"atb":[[9,33.26]],"atl":[[9.6,13.63]],"trd":[[9.6,120.82]],"batb":[[2,9,33.26]],"batl":[[0,9.6,13.63]],"tv":6536.91,"id":27115873},{"atb":[[11,109.44]],"atl":[[1000,19.31]],"batb":[[0,11,109.44]],"id":44049799}],"tv":74524.04}]}
{"op":"mcm","id":2,"clk":"AJWQAQCQWwDzgwE=","pt":1743511887333,"mc":[{"id":"1.241629436","rc":[{"atb":[[9,36.76]],"batb":[[2,9,36.76]],"id":27115873},{"atl":[[1000,18.87]],"id":44049799}]}]}
{"op":"mcm","id":2,"clk":"AJuQAQCSWwD4gwE=","pt":1743511887435,"mc":[{"id":"1.241629436","rc":[{"atb":[[5.2,253.24]],"batb":[[0,5.2,253.24]],"id":270592},{"atb":[[6.4,222.09]],"trd":[[6.4,3361.4]],"batb":[[0,6.4,222.09]],"tv":12144.24,"id":26496185},{"atl":[[12,39.1]],"batl":[[1,12,39.1]],"id":44049799}],"tv":74539.66}]}
{"op":"mcm","id":2,"clk":"AJ+QAQCUWwD/gwE=","pt":1743511887532,"mc":[{"id":"1.241629436","rc":[{"atb":[[5.1,247.89],[4.8,96.6]],"batb":[[0,5.1,247.89]],"id":56297029},{"atb":[[6.4,245.76]],"batb":[[0,6.4,245.76]],"id":26496185}]}]}
{"op":"mcm","id":2,"clk":"AKWQAQCbWwCBhAE=","pt":1743511887637,"mc":[{"id":"1.241629436","rc":[{"atb":[[5.2,278.73]],"batb":[[0,5.2,278.73]],"id":270592},{"atb":[[9.4,81.72]],"batb":[[0,9.4,81.72]],"id":35856222},{"atl":[[1000,3.41]],"id":58186642},{"atl":[[6.6,24.44],[6.8,138.1]],"trd":[[6.6,1892.29]],"batl":[[1,6.8,138.1],[0,6.6,24.44]],"ltp":6.6,"tv":12175.18,"id":26496185}],"tv":74570.6}]}
{"op":"mcm","id":2,"clk":"AK+QAQCgWwCFhAE=","pt":1743511887740,"mc":[{"id":"1.241629436","rc":[{"atb":[[9.4,71.63]],"batb":[[0,9.4,71.63]],"id":27115873},{"atl":[[1000,1.51]],"id":58186642},{"atl":[[6.6,27.97]],"batl":[[0,6.6,27.97]],"id":26496185}]}]}
{"op":"mcm","id":2,"clk":"ALaQAQCmWwCLhAE=","pt":1743511887845,"mc":[{"id":"1.241629436","rc":[{"atl":[[6.6,23.32],[6.8,160.12]],"batl":[[1,6.8,160.12],[0,6.6,23.32]],"id":26496185},{"atb":[[11,118.72]],"batb":[[0,11,118.72]],"id":44049799}]}]}
{"op":"mcm","id":2,"clk":"ALqQAQCpWwCOhAE=","pt":1743511887941,"mc":[{"id":"1.241629436","rc":[{"atb":[[11,106.74]],"batb":[[0,11,106.74]],"id":40389088},{"atl":[[1000,1.41],[17,1.26]],"trd":[[17,838.2]],"batl":[[0,17,1.26]],"tv":5256.1,"id":58186642}],"tv":74582.62}]}
{"op":"mcm","id":2,"clk":"AL+QAQCsWwCThAE=","pt":1743511888044,"mc":[{"id":"1.241629436","rc":[{"atb":[[11,110.15]],"batb":[[0,11,110.15]],"id":40389088},{"atl":[[9.6,11.41]],"batl":[[0,9.6,11.41]],"id":35856222},{"atb":[[60,14.2]],"batb":[[0,60,14.2]],"id":59626646},{"atb":[[5.1,256.41]],"batb":[[0,5.1,256.41]],"id":56297029},{"atb":[[17,5.87],[16.5,36.17]],"atl":[[17.5,15.05],[17,0]],"trd":[[17,838.4]],"batb":[[2,16,30.63],[1,16.5,36.17],[0,17,5.87]],"batl":[[2,18.5,16.08],[1,18,15.64],[0,17.5,15.05]],"tv":5256.3,"id":58186642}],"tv":74582.82}]}
{"op":"mcm","id":2,"clk":"AMaQAQCuWwCYhAE=","pt":1743511888142,"mc":[{"id":"1.241629436","rc":[{"atl":[[100,1.33]],"id":270592},{"atb":[[5.1,255.68],[4.8,95.57]],"atl":[[5.3,87.37]],"batb":[[0,5.1,255.68]],"batl":[[1,5.3,87.37]],"id":56297029},{"atb":[[16.5,38.82]],"batb":[[1,16.5,38.82]],"id":58186642}]}]}
{"op":"mcm","id":2,"clk":"ANOQAQC2WwCfhAE=","pt":1743511888246,"mc":[{"id":"1.241629436","rc":[{"atb":[[4.9,87.83]],"batb":[[2,4.9,87.83]],"id":56297029},{"atb":[[17,13.29],[16,28.76]],"atl":[[17.5,7.48]],"trd":[[17,840.3]],"batb":[[2,16,28.76],[0,17,13.29]],"batl":[[0,17.5,7.48]],"tv":5258.2,"id":58186642}],"tv":74584.72}]}
{"op":"mcm","id":2,"clk":"AOOQAQC/WwCohAE=","pt":1743511888413,"mc":[{"id":"1.241629436","rc":[{"atb":[[17,16.59]],"atl":[[17.5,5.39]],"trd":[[17.5,133.83]],"batb":[[0,17,16.59]],"batl":[[0,17.5,5.39]],"ltp":17.5,"tv":5262.38,"id":58186642}],"tv":74588.9}]}
{"op":"mcm","id":2,"clk":"AOqQAQDCWwCthAE=","pt":1743511888504,"mc":[{"id":"1.241629436","rc":[{"atb":[[11,106.65]],"trd":[[11,83.25]],"batb":[[0,11,106.65]],"tv":6223.13,"id":40389088},{"atb":[[9.4,78.22]],"trd":[[9.4,613.25]],"batb":[[0,9.4,78.22]],"tv":9221.99,"id":35856222},{"atb":[[5.1,252.18]],"trd":[[5.1,3297.77]],"batb":[[0,5.1,252.18]],"tv":12318.7,"id":56297029},{"atb":[[9.4,68.18]],"atl":[[10,136.67]],"batb":[[0,9.4,68.18]],"batl":[[2,10,136.67]],"id":27115873},{"atl":[[1000,3.41],[17.5,1.48]],"batl":[[0,17.5,1.48]],"id":58186642},{"atb":[[6.2,170.85]],"batb":[[1,6.2,170.85]],"id":26496185}],"tv":74609.89}]}
{"op":"mcm","id":2,"clk":"APGQAQDDWwC0hAE=","pt":1743511888607,"mc":[{"id":"1.241629436","rc":[{"atl":[[10,114.86]],"batl":[[2,10,114.86]],"id":35856222},{"atb":[[5.1,251.18]],"trd":[[5.1,3299.77]],"batb":[[0,5.1,251.18]],"tv":12320.7,"id":56297029},{"atb":[[17,20.9]],"atl":[[1000,1.51]],"batb":[[0,17,20.9]],"id":58186642},{"atb":[[6.2,174.06]],"batb":[[1,6.2,174.06]],"id":26496185}],"tv":74611.89}]}
{"op":"mcm","id":2,"clk":"APyQAQDGWwC7hAE=","pt":1743511888716,"mc":[{"id":"1.241629436","rc":[{"atl":[[1000,1.41],[18.5,12.7]],"batl":[[2,18.5,12.7]],"id":58186642}]}]}
{"op":"mcm","id":2,"clk":"AIeRAQDIWwDChAE=","pt":1743511888813,"mc":[{"id":"1.241629436","rc":[{"atb":[[9.4,67.18]],"trd":[[9.4,101.75]],"batb":[[0,9.4,67.18]],"ltp":9.4,"tv":6538.91,"id":27115873},{"atb":[[17,28.09]],"atl":[[18,15.74]],"batb":[[0,17,28.09]],"batl":[[1,18,15.74]],"id":58186642}],"tv":74613.89}]}
{"op":"mcm","id":2,"clk":"ANKRAQD4WwDlhAE=","pt":1743511889530,"mc":[{"id":"1.241629436","rc":[{"atl":[[1000,3.41]],"id":58186642}]}]}
{"op":"mcm","id":2,"clk":"ANqRAQD9WwDthAE=","pt":1743511889629,"mc":[{"id":"1.241629436","rc":[{"atl":[[1000,1.51]],"id":58186642}]}]}
{"op":"mcm","id":2,"clk":"AOeRAQCCXAD0hAE=","pt":1743511889736,"mc":[{"id":"1.241629436","rc":[{"atb":[[8.4,44.3]],"batb":[],"id":27115873}]}]}
{"op":"mcm","id":2,"clk":"AO6RAQCJXAD9hAE=","pt":1743511889843,"mc":[{"id":"1.241629436","rc":[{"atb":[[8,35.09]],"batb":[],"id":27115873},{"atl":[[1000,1.41]],"id":58186642}]}]}
{"op":"mcm","id":2,"clk":"APaRAQCMXACEhQE=","pt":1743511889942,"mc":[{"id":"1.241629436","rc":[{"atl":[[1000,23.16]],"id":270592},{"atl":[[18.5,12.8]],"batl":[[2,18.5,12.8]],"id":58186642}]}]}
{"op":"mcm","id":2,"clk":"APqRAQCQXACOhQE=","pt":1743511890044,"mc":[{"id":"1.241629436","rc":[{"atb":[[9.4,77.23]],"trd":[[9.4,615.23]],"batb":[[0,9.4,77.23]],"tv":9223.97,"id":35856222}],"tv":74615.87}]}
{"op":"mcm","id":2,"clk":"AIGSAQCYXACUhQE=","pt":1743511890146,"mc":[{"id":"1.241629436","rc":[{"atl":[[1000,21.16]],"id":270592},{"atl":[[10,108.92]],"batl":[[2,10,108.92]],"id":35856222}]}]}
{"op":"mcm","id":2,"clk":"AJ2SAQCoXACwhQE=","pt":1743511890506,"mc":[{"id":"1.241629436","rc":[{"atb":[[4.7,43.49]],"batb":[],"id":56297029},{"atl":[[6.8,170.12]],"batl":[[1,6.8,170.12]],"id":26496185}]}]}
{"op":"mcm","id":2,"clk":"AKGSAQCsXAC5hQE=","pt":1743511890615,"mc":[{"id":"1.241629436","rc":[{"atl":[[12.5,60.71]],"batl":[[2,12.5,60.71]],"id":40389088},{"atb":[[5.2,259.95]],"trd":[[5.2,1741.62]],"batb":[[0,5.2,259.95]],"tv":16664.65,"id":270592},{"atl":[[10.5,73.27],[9.6,0.71]],"trd":[[9.6,370.04]],"batl":[[2,10.5,73.27],[1,10,108.92],[0,9.8,40.85]],"ltp":9.6,"tv":9245.37,"id":35856222},{"atl":[[5.2,170.88]],"batl":[[0,5.2,170.88]],"id":56297029},{"atl":[[12.5,279.87],[12,30.95]],"batl":[],"id":27115873},{"atb":[[6.4,231.05]],"trd":[[6.4,3390.82]],"batb":[[0,6.4,231.05]],"ltp":6.4,"tv":12204.6,"id":26496185},{"atb":[[11,110.71]],"trd":[[11,1391.41]],"batb":[[0,11,110.71]],"tv":4600.47,"id":44049799}],"tv":74720.29}]}
{"op":"mcm","id":2,"clk":"AKqSAQCxXAC+hQE=","pt":1743511890711,"mc":[{"id":"1.241629436","rc":[{"atb":[[9.4,76.93]],"atl":[[9.8,49.19],[9.6,0]],"trd":[[9.6,371.46]],"batb":[[0,9.4,76.93]],"batl":[[0,9.8,49.19]],"tv":9246.79,"id":35856222},{"atb":[[60,12.56]],"trd":[[60,307.34]],"batb":[[0,60,12.56]],"tv":1663.36,"id":59626646},{"atb":[[4.7,46.43]],"batb":[],"id":56297029},{"atb":[[9.4,65.18]],"atl":[[1000,3.97],[10,136.23]],"trd":[[9.4,105.75]],"batb":[[0,9.4,65.18]],"batl":[[2,10,136.23]],"tv":6542.91,"id":27115873},{"atb":[[16,28.45],[16.5,39.46]],"batb":[[2,16,28.45],[1,16.5,39.46]],"id":58186642},{"atb":[[6.4,245.64]],"atl":[[6.6,32.61]],"batb":[[0,6.4,245.64]],"batl":[[0,6.6,32.61]],"id":26496185},{"atb":[[11,131.15]],"atl":[[12.5,50.31]],"batb":[[0,11,131.15]],"batl":[[2,12.5,50.31]],"id":44049799}],"tv":74728.99}]}
{"op":"mcm","id":2,"clk":"ALGSAQC3XADIhQE=","pt":1743511890815,"mc":[{"id":"1.241629436","rc":[{"atb":[[9.4,74.43]],"trd":[[9.4,620.23]],"batb":[[0,9.4,74.43]],"ltp":9.4,"tv":9251.79,"id":35856222},{"atl":[[1000,3.66],[10,109.25]],"batl":[[2,10,109.25]],"id":27115873}],"tv":74733.99}]}
{"op":"mcm","id":2,"clk":"ALWSAQC8XADOhQE=","pt":1743511890910,"mc":[{"id":"1.241629436","rc":[{"atl":[[1000,23.16]],"id":270592},{"atl":[[9.8,50.3]],"batl":[[1,9.8,50.3]],"id":27115873}]}]}
{"op":"mcm","id":2,"clk":"ALuSAQDAXADYhQE=","pt":1743511891019,"mc":[{"id":"1.241629436","rc":[{"atb":[[4.7,43.49]],"batb":[],"id":56297029}]}]}
{"op":"mcm","id":2,"clk":"AMKSAQDEXADdhQE=","pt":1743511891126,"mc":[{"id":"1.241629436","rc":[{"atl":[[1000,21.16]],"id":270592},{"atl":[[9.8,49.97]],"batl":[[1,9.8,49.97]],"id":27115873}]}]}
{"op":"mcm","id":2,"clk":"AMiSAQDIXADhhQE=","pt":1743511891226,"mc":[{"id":"1.241629436","rc":[{"atb":[[9.4,64.85]],"trd":[[9.4,106.41]],"batb":[[0,9.4,64.85]],"tv":6543.57,"id":27115873}],"tv":74734.65}]}
{"op":"mcm","id":2,"clk":"AMySAQDMXADphQE=","pt":1743511891319,"mc":[{"id":"1.241629436","rc":[{"atb":[[1.03,392.73]],"id":26496185}]}]}
{"op":"mcm","id":2,"clk":"ANSSAQDSXADvhQE=","pt":1743511891418,"mc":[{"id":"1.241629436","rc":[{"atb":[[16.5,41.85]],"batb":[[1,16.5,41.85]],"id":58186642}]}]}
{"op":"mcm","id":2,"clk":"AIGTAQCHXQCfhgE=","pt":1743511891627,"mc":[{"id":"1.241629436","rc":[{"atl":[[1000,3.41]],"id":58186642}]}]}
{"op":"mcm","id":2,"clk":"AIqTAQCSXQCqhgE=","pt":1743511891832,"mc":[{"id":"1.241629436","rc":[{"atl":[[10,107.25]],"batl":[[2,10,107.25]],"id":27115873},{"atl":[[1000,1.51]],"id":58186642}]}]}
{"op":"mcm","id":2,"clk":"AJiTAQCYXQCyhgE=","pt":1743511891938,"mc":[{"id":"1.241629436","rc":[{"atl":[[100,3.19]],"batl":[],"id":59626646},{"atl":[[1000,1.41]],"id":58186642}]}]}
{"op":"mcm","id":2,"clk":"AKCTAQCdXQC0hgE=","pt":1743511892037,"mc":[{"id":"1.241629436","rc":[{"atl":[[17.5,1.58]],"batl":[[0,17.5,1.58]],"id":58186642}]}]}
{"op":"mcm","id":2,"clk":"AL6TAQCrXQDMhgE=","pt":1743511892349,"mc":[{"id":"1.241629436","rc":[{"atl":[[7,50.06]],"batl":[[2,7,50.06]],"id":26496185}]}]}
{"op":"mcm","id":2,"clk":"AN+TAQDHXQDohgE=","pt":1743511892801,"mc":[{"id":"1.241629436","rc":[{"atb":[[5.2,254.95]],"trd":[[5.2,1751.62]],"batb":[[0,5.2,254.95]],"tv":16674.65,"id":270592}],"tv":74744.65}]}
{"op":"mcm","id":2,"clk":"APKTAQDQXQCBhwE=","pt":1743511893105,"mc":[{"id":"1.241629436","rc":[{"atb":[[2.7,2]],"id":40389088},{"atb":[[1.5,13]],"id":270592},{"atb":[[1.9,3]],"id":35856222},{"atb":[[5,7.01]],"id":59626646},{"atb":[[1.5,12]],"id":56297029},{"atb":[[1.9,2]],"id":27115873},{"atb":[[4,68]],"id":58186642},{"atb":[[1.6,78.53]],"id":26496185},{"atb":[[2.7,5.75]],"id":44049799}]}]}
{"op":"mcm","id":2,"clk":"AIGUAQDXXQCPhwE=","pt":1743511893318,"mc":[{"id":"1.241629436","rc":[{"atl":[[9.8,40.14]],"batl":[[0,9.8,40.14]],"id":35856222}]}]}
{"op":"mcm","id":2,"clk":"ALCUAQCQXgC9hwE=","pt":1743511893620,"mc":[{"id":"1.241629436","rc":[{"atl":[[100,3.16]],"batl":[],"id":59626646}]}]}
{"op":"mcm","id":2,"clk":"ALWUAQCUXgDBhwE=","pt":1743511893719,"mc":[{"id":"1.241629436","rc":[{"atl":[[1000,0.54]],"id":40389088},{"atl":[[1000,0.59]],"id":35856222},{"atb":[[9.4,66.35]],"batb":[[0,9.4,66.35]],"id":27115873},{"atl":[[1000,1.48]],"id":58186642}]}]}
{"op":"mcm","id":2,"clk":"ALuUAQCWXgDGhwE=","pt":1743511893819,"mc":[{"id":"1.241629436","rc":[{"atl":[[1000,0.25],[12,101.72]],"batl":[[1,12,101.72]],"id":40389088},{"atl":[[1000,0.41]],"id":35856222},{"atb":[[5.1,254.96]],"atl":[[1000,5.28]],"batb":[[0,5.1,254.96]],"id":56297029},{"atl":[[1000,1.41]],"id":58186642}]}]}
{"op":"mcm","id":2,"clk":"AMGUAQCdXgDPhwE=","pt":1743511893927,"mc":[{"id":"1.241629436","rc":[{"atl":[[11.5,8.06]],"batl":[[0,11.5,8.06]],"id":40389088},{"atl":[[9.6,0.18]],"batl":[[0,9.8,40.32]],"id":35856222},{"atl":[[17.5,1.65]],"batl":[[0,17.5,1.65]],"id":58186642}]}]}
{"op":"mcm","id":2,"clk":"AMWUAQCgXgDZhwE=","pt":1743511894026,"mc":[{"id":"1.241629436","rc":[{"atl":[[1000,4.52]],"id":56297029}]}]}
{"op":"mcm","id":2,"clk":"AM6UAQCjXgDhhwE=","pt":1743511894129,"mc":[{"id":"1.241629436","rc":[{"atl":[[5.3,88.13]],"batl":[[1,5.3,88.13]],"id":56297029},{"atb":[[17,26.09]],"trd":[[17,844.3]],"batb":[[0,17,26.09]],"ltp":17,"tv":5266.38,"id":58186642}],"tv":74748.65}]}
{"op":"mcm","id":2,"clk":"AOGUAQC0XgDxhwE=","pt":1743511894430,"mc":[{"id":"1.241629436","rc":[{"atl":[[11,59.96]],"batl":[],"id":27115873},{"atl":[[1000,3.41]],"id":58186642}]}]}
{"op":"mcm","id":2,"clk":"AOmUAQC5XgCQiAE=","pt":1743511894542,"mc":[{"id":"1.241629436","rc":[{"atl":[[9.6,18.5]],"batl":[[0,9.6,18.5]],"id":27115873}]}]}
{"op":"mcm","id":2,"clk":"AO6UAQC9XgCZiAE=","pt":1743511894637,"mc":[{"id":"1.241629436","rc":[{"atl":[[1000,1.51]],"id":58186642}]}]}
{"op":"mcm","id":2,"clk":"APSUAQDEXgCdiAE=","pt":1743511894738,"mc":[{"id":"1.241629436","rc":[{"atl":[[1000,1.41]],"id":58186642}]}]}
{"op":"mcm","id":2,"clk":"AP+UAQDLXgCniAE=","pt":1743511894842,"mc":[{"id":"1.241629436","rc":[{"atl":[[17.5,1.75]],"batl":[[0,17.5,1.75]],"id":58186642}]}]}
{"op":"mcm","id":2,"clk":"AIuVAQDVXgC2iAE=","pt":1743511895046,"mc":[{"id":"1.241629436","rc":[{"atl":[[18,14.74]],"batl":[[1,18,14.74]],"id":58186642}]}]}
{"op":"mcm","id":2,"clk":"AJiVAQDbXgDAiAE=","pt":1743511895253,"mc":[{"id":"1.241629436","rc":[{"atl":[[1000,23.16]],"id":270592},{"atl":[[9.8,29.87],[9.6,0]],"trd":[[9.8,551.3],[9.6,371.82]],"batl":[[0,9.8,29.87]],"ltp":9.8,"tv":9272.68,"id":35856222},{"atb":[[5.1,231.31]],"trd":[[5.1,3347.07]],"batb":[[0,5.1,231.31]],"tv":12368,"id":56297029},{"atl":[[9.6,7.48]],"trd":[[9.6,142.86]],"batl":[[0,9.6,7.48]],"ltp":9.6,"tv":6565.61,"id":27115873}],"tv":74838.88}]}
{"op":"mcm","id":2,"clk":"AKKVAQDiXgDHiAE=","pt":1743511895359,"mc":[{"id":"1.241629436","rc":[{"atb":[[9.4,69.85]],"batb":[[0,9.4,69.85]],"id":27115873}]}]}
{"op":"mcm","id":2,"clk":"AKSVAQDiXgDKiAE=","pt":1743511895451,"mc":[{"id":"1.241629436","rc":[{"atl":[[1000,21.16]],"id":270592},{"atb":[[9.6,7.7]],"trd":[[9.6,375.82]],"batb":[[2,9.2,65.8],[1,9.4,74.43],[0,9.6,7.7]],"ltp":9.6,"tv":9276.68,"id":35856222},{"atl":[[9.6,17.81]],"batl":[[0,9.6,17.81]],"id":27115873}],"tv":74842.88}]}
{"op":"mcm","id":2,"clk":"AKyVAQDoXgDRiAE=","pt":1743511895508,"mc":[{"id":"1.241629436","rc":[{"atl":[[5.6,138.94]],"batl":[],"id":270592},{"atl":[[9.6,0]],"trd":[[9.6,178.48]],"batl":[[2,10.5,51.55],[1,10,107.25],[0,9.8,49.97]],"tv":6601.23,"id":27115873}],"tv":74878.5}]}
{"op":"mcm","id":2,"clk":"ALOVAQDtXgDXiAE=","pt":1743511895612,"mc":[{"id":"1.241629436","rc":[{"atb":[[9.4,75.79]],"atl":[[9.8,49.46],[10,107.76]],"batb":[[0,9.4,75.79]],"batl":[[1,10,107.76],[0,9.8,49.46]],"id":27115873}]}]}
{"op":"mcm","id":2,"clk":"AL6VAQD0XgDniAE=","pt":1743511895815,"mc":[{"id":"1.241629436","rc":[{"atl":[[5.7,87.82]],"batl":[],"id":56297029}]}]}
{"op":"mcm","id":2,"clk":"AMSVAQD4XgDwiAE=","pt":1743511895922,"mc":[{"id":"1.241629436","rc":[{"atl":[[1000,3.41]],"id":58186642}]}]}
{"op":"mcm","id":2,"clk":"ANCVAQD/XgD5iAE=","pt":1743511896116,"mc":[{"id":"1.241629436","rc":[{"atb":[[4.6,106.01]],"atl":[[5.6,56.28]],"batb":[],"batl":[],"id":56297029},{"atb":[[9.2,41.41]],"batb":[[1,9.2,41.41]],"id":27115873},{"atl":[[1000,1.51]],"id":58186642}]}]}
{"op":"mcm","id":2,"clk":"ANyVAQCEXwD/iAE=","pt":1743511896221,"mc":[{"id":"1.241629436","rc":[{"atl":[[1000,1.41]],"id":58186642}]}]}
{"op":"mcm","id":2,"clk":"AOWVAQCJXwCFiQE=","pt":1743511896328,"mc":[{"id":"1.241629436","rc":[{"atl":[[1000,23.16]],"id":270592},{"atl":[[18,14.84]],"batl":[[1,18,14.84]],"id":58186642}]}]}
{"op":"mcm","id":2,"clk":"APSVAQCYXwCRiQE=","pt":1743511896554,"mc":[{"id":"1.241629436","rc":[{"atl":[[1000,21.16]],"id":270592}]}]}
{"op":"mcm","id":2,"clk":"AIKWAQCmXwCeiQE=","pt":1743511896838,"mc":[{"id":"1.241629436","rc":[{"atl":[[1000,4.19],[9.8,49.15]],"batl":[[0,9.8,49.15]],"id":27115873},{"atl":[[1000,3.41]],"id":58186642}]}]}
{"op":"mcm","id":2,"clk":"AIeWAQCqXwCiiQE=","pt":1743511896933,"mc":[{"id":"1.241629436","rc":[{"atl":[[9.8,49.66]],"batl":[[0,9.8,49.66]],"id":27115873}]}]}
{"op":"mcm","id":2,"clk":"AIuWAQCzXwCniQE=","pt":1743511897036,"mc":[{"id":"1.241629436","rc":[{"atl":[[1000,3.66],[9.8,41.69]],"trd":[[9.8,223.23]],"batl":[[0,9.8,41.69]],"ltp":9.8,"tv":6617.17,"id":27115873},{"atl":[[1000,1.51]],"id":58186642}],"tv":74894.44}]}
{"op":"mcm","id":2,"clk":"AJKWAQC3XwCwiQE=","pt":1743511897141,"mc":[{"id":"1.241629436","rc":[{"atb":[[8.6,38.37]],"batb":[],"id":35856222},{"atb":[[9.6,10.37]],"atl":[[9.8,41.91],[10,108.07]],"batb":[[2,9.2,41.41],[1,9.4,75.79],[0,9.6,10.37]],"batl":[[1,10,108.07],[0,9.8,41.91]],"id":27115873}]}]}
{"op":"mcm","id":2,"clk":"AJ+WAQC9XwC2iQE=","pt":1743511897257,"mc":[{"id":"1.241629436","rc":[{"atb":[[60,11.54]],"trd":[[60,309.38]],"batb":[[0,60,11.54]],"tv":1665.4,"id":59626646},{"atl":[[1000,1.41]],"id":58186642}],"tv":74896.48}]}
{"op":"mcm","id":2,"clk":"AKWWAQDCXwC6iQE=","pt":1743511897351,"mc":[{"id":"1.241629436","rc":[{"atl":[[18.5,12.9]],"batl":[[2,18.5,12.9]],"id":58186642},{"atb":[[3,4]],"id":44049799}]}]}
{"op":"mcm","id":2,"clk":"ALeWAQDOXwDQiQE=","pt":1743511897653,"mc":[{"id":"1.241629436","rc":[{"atb":[[9.2,72.02]],"batb":[[2,9.2,72.02]],"id":35856222},{"atb":[[1.4,1]],"id":56297029}]}]}
{"op":"mcm","id":2,"clk":"AMOWAQDZXwDfiQE=","pt":1743511897860,"mc":[{"id":"1.241629436","rc":[{"atb":[[9.2,65.8]],"batb":[[2,9.2,65.8]],"id":35856222}]}]}
{"op":"mcm","id":2,"clk":"AN+WAQDpXwD4iQE=","pt":1743511898126,"mc":[{"id":"1.241629436","rc":[{"atl":[[5.5,65.58]],"batl":[],"id":56297029}]}]}
{"op":"mcm","id":2,"clk":"AJSXAQCMYACpigE=","pt":1743511898737,"mc":[{"id":"1.241629436","rc":[{"atb":[[5.2,319.95]],"batb":[[0,5.2,319.95]],"id":270592}]}]}
{"op":"mcm","id":2,"clk":"AKmXAQCjYADEigE=","pt":1743511899040,"mc":[{"id":"1.241629436","rc":[{"atl":[[12,46.14]],"batl":[[1,12,46.14]],"id":40389088},{"atl":[[10,41.37]],"batl":[[1,10,41.37]],"id":27115873},{"atl":[[17.5,39.86]],"batl":[[0,17.5,39.86]],"id":58186642}]}]}
{"op":"mcm","id":2,"clk":"ALeXAQCxYADPigE=","pt":1743511899150,"mc":[{"id":"1.241629436","rc":[{"atl":[[12,60.14]],"batl":[[1,12,60.14]],"id":40389088},{"atl":[[5.3,304.5]],"batl":[[0,5.3,304.5]],"id":270592},{"atb":[[4.9,86.82]],"atl":[[5.2,190.88]],"batb":[[2,4.9,86.82]],"batl":[[0,5.2,190.88]],"id":56297029},{"atb":[[9.6,18.37]],"atl":[[10.5,66.55]],"batb":[[0,9.6,18.37]],"batl":[[2,10.5,66.55]],"id":27115873},{"atb":[[17,4.31]],"trd":[[17,868.3]],"batb":[[0,17,4.31]],"tv":5290.38,"id":58186642},{"atl":[[6.6,57.61]],"batl":[[0,6.6,57.61]],"id":26496185}],"tv":74920.48}]}
{"op":"mcm","id":2,"clk":"AMCXAQC1YADaigE=","pt":1743511899246,"mc":[{"id":"1.241629436","rc":[{"atb":[[4.8,96.6]],"batb":[],"id":56297029},{"atl":[[10,40.86]],"batl":[[1,10,40.86]],"id":27115873},{"atb":[[17,1]],"atl":[[18.5,16.21],[18,18.2],[17.5,43.26]],"batb":[[0,17,1]],"batl":[[2,18.5,16.21],[1,18,18.2],[0,17.5,43.26]],"id":58186642},{"atb":[[6.4,217.52]],"batb":[[0,6.4,217.52]],"id":26496185}]}]}
{"op":"mcm","id":2,"clk":"AMmXAQDAYADjigE=","pt":1743511899353,"mc":[{"id":"1.241629436","rc":[{"atb":[[11,105.65]],"trd":[[11,85.25]],"batb":[[0,11,105.65]],"tv":6225.13,"id":40389088},{"atb":[[9.2,46.88]],"batb":[[2,9.2,46.88]],"id":27115873},{"atb":[[17,0]],"atl":[[17,1.21],[17.5,46.06]],"trd":[[17,870.3]],"batb":[[2,15.5,45.43],[1,16,28.45],[0,16.5,41.85]],"batl":[[2,18,18.2],[1,17.5,46.06],[0,17,1.21]],"tv":5292.38,"id":58186642}],"tv":74924.48}]}
{"op":"mcm","id":2,"clk":"ANeXAQDOYADvigE=","pt":1743511899556,"mc":[{"id":"1.241629436","rc":[{"atb":[[16.5,34.53]],"atl":[[18,14.84],[17,3.17]],"trd":[[17,872.3]],"batb":[[0,16.5,34.53]],"batl":[[2,18,14.84],[0,17,3.17]],"tv":5294.38,"id":58186642}],"tv":74926.48}]}
{"op":"mcm","id":2,"clk":"AOCXAQDYYADzigE=","pt":1743511899656,"mc":[{"id":"1.241629436","rc":[{"atl":[[18,18.18]],"batl":[[2,18,18.18]],"id":58186642}]}]}
{"op":"mcm","id":2,"clk":"AOaXAQDfYAD3igE=","pt":1743511899757,"mc":[{"id":"1.241629436","rc":[{"atl":[[17.5,53.7]],"batl":[[1,17.5,53.7]],"id":58186642}]}]}
{"op":"mcm","id":2,"clk":"AO+XAQDlYAD7igE=","pt":1743511899815,"mc":[{"id":"1.241629436","rc":[{"atl":[[1000,0.53]],"id":35856222},{"atb":[[5.1,227.53]],"atl":[[5.3,87.37]],"batb":[[0,5.1,227.53]],"batl":[[1,5.3,87.37]],"id":56297029}]}]}
{"op":"mcm","id":2,"clk":"AIGYAQD0YACNiwE=","pt":1743511900033,"mc":[{"id":"1.241629436","rc":[{"atl":[[11.5,7.78]],"batl":[[0,11.5,7.78]],"id":40389088},{"atl":[[1000,0.41]],"id":35856222}]}]}
{"op":"mcm","id":2,"clk":"AJKYAQD3YACZiwE=","pt":1743511900127,"mc":[{"id":"1.241629436","rc":[{"atb":[[11,105.37]],"trd":[[11,85.81]],"batb":[[0,11,105.37]],"tv":6225.69,"id":40389088},{"atl":[[9.8,29.99]],"batl":[[0,9.8,29.99]],"id":35856222}],"tv":74927.04}]}
{"op":"mcm","id":2,"clk":"ALaYAQCMYQC2iwE=","pt":1743511900444,"mc":[{"id":"1.241629436","rc":[{"atl":[[100,3.22]],"batl":[],"id":59626646}]}]}
{"op":"mcm","id":2,"clk":"AMKYAQCTYQDBiwE=","pt":1743511900544,"mc":[{"id":"1.241629436","rc":[{"atb":[[5.1,202.53]],"trd":[[5.1,3397.07]],"batb":[[0,5.1,202.53]],"tv":12418,"id":56297029}],"tv":74977.04}]}
{"op":"mcm","id":2,"clk":"AMSYAQCdYQDIiwE=","pt":1743511900638,"mc":[{"id":"1.241629436","rc":[{"atl":[[1000,23.16]],"id":270592},{"atl":[[18,21.65]],"batl":[[2,18,21.65]],"id":58186642}]}]}
{"op":"mcm","id":2,"clk":"ANWYAQCpYQDSiwE=","pt":1743511900750,"mc":[{"id":"1.241629436","rc":[{"atl":[[5.2,205.04]],"batl":[[0,5.2,205.04]],"id":56297029},{"atl":[[10,67.84]],"batl":[[1,10,67.84]],"id":27115873}]}]}
{"op":"mcm","id":2,"clk":"AOOYAQC0YQDfiwE=","pt":1743511900948,"mc":[{"id":"1.241629436","rc":[{"atl":[[1000,21.16]],"id":270592}]}]}
{"op":"mcm","id":2,"clk":"AP2YAQDFYQDyiwE=","pt":1743511901159,"mc":[{"id":"1.241629436","rc":[{"atb":[[1.02,5353.56]],"id":26496185}]}]}
{"op":"mcm","id":2,"clk":"AI6ZAQDRYQCIjAE=","pt":1743511901358,"mc":[{"id":"1.241629436","rc":[{"atl":[[11.5,3.9]],"trd":[[11.5,1153.57]],"batl":[[0,11.5,3.9]],"ltp":11.5,"tv":6233.44,"id":40389088},{"atl":[[9.8,41.59]],"batl":[[0,9.8,41.59]],"id":35856222},{"atl":[[65,8.32]],"trd":[[65,147.92]],"batl":[[0,65,8.32]],"ltp":65,"tv":1677.04,"id":59626646}],"tv":74996.43}]}
{"op":"mcm","id":2,"clk":"AJiZAQDcYQCPjAE=","pt":1743511901413,"mc":[{"id":"1.241629436","rc":[{"atl":[[6.6,59.61]],"batl":[[0,6.6,59.61]],"id":26496185}]}]}
{"op":"mcm","id":2,"clk":"AKKZAQDkYQCZjAE=","pt":1743511901523,"mc":[{"id":"1.241629436","rc":[{"atl":[[12,55.12]],"batl":[[1,12,55.12]],"id":40389088}]}]}
{"op":"mcm","id":2,"clk":"ALGZAQDoYQCijAE=","pt":1743511901626,"mc":[{"id":"1.241629436","rc":[{"atb":[[5.1,270.68]],"batb":[[1,5.1,270.68]],"id":270592},{"atb":[[9.6,7.07]],"trd":[[9.6,377.08]],"batb":[[0,9.6,7.07]],"tv":9277.94,"id":35856222},{"atb":[[5.2,99.33]],"id":26496185}],"tv":74997.69}]}
{"op":"mcm","id":2,"clk":"ALuZAQDuYQC1jAE=","pt":1743511901727,"mc":[{"id":"1.241629436","rc":[{"atl":[[1000,23.16]],"id":270592},{"atb":[[9.6,0]],"batb":[[2,9,71.57],[1,9.2,65.8],[0,9.4,74.43]],"id":35856222}]}]}
{"op":"mcm","id":2,"clk":"AMKZAQD1YQDBjAE=","pt":1743511901830,"mc":[{"id":"1.241629436","rc":[{"atl":[[12,60.14]],"batl":[[1,12,60.14]],"id":40389088},{"atb":[[8.4,65.51]],"batb":[],"id":35856222}]}]}
{"op":"mcm","id":2,"clk":"AM2ZAQD5YQDPjAE=","pt":1743511901932,"mc":[{"id":"1.241629436","rc":[{"atl":[[1000,21.16],[5.6,136.96]],"batl":[],"id":270592},{"atb":[[8.6,36.8]],"batb":[],"id":35856222}]}]}
{"op":"mcm","id":2,"clk":"ANCZAQD+YQDVjAE=","pt":1743511902026,"mc":[{"id":"1.241629436","rc":[{"atb":[[5.1,152.53]],"trd":[[5.1,3497.07]],"batb":[[0,5.1,152.53]],"tv":12518,"id":56297029}],"tv":75097.69}]}
{"op":"mcm","id":2,"clk":"AOSZAQCSYgDkjAE=","pt":1743511902247,"mc":[{"id":"1.241629436","rc":[{"atl":[[12,55.12]],"batl":[[1,12,55.12]],"id":40389088},{"atl":[[17,2.17]],"trd":[[17,874.3]],"batl":[[0,17,2.17]],"tv":5296.38,"id":58186642}],"tv":75099.69}]}
{"op":"mcm","id":2,"clk":"AO6ZAQCXYgDrjAE=","pt":1743511902340,"mc":[{"id":"1.241629436","rc":[{"atb":[[10.5,30.55]],"batb":[[1,10.5,30.55]],"id":40389088}]}]}
{"op":"mcm","id":2,"clk":"APeZAQCjYgDzjAE=","pt":1743511902442,"mc":[{"id":"1.241629436","rc":[{"atb":[[5.1,136.77]],"batb":[[0,5.1,136.77]],"id":56297029},{"atb":[[8,33.94]],"batb":[],"id":27115873}]}]}
{"op":"mcm","id":2,"clk":"AP2ZAQCwYgD6jAE=","pt":1743511902541,"mc":[{"id":"1.241629436","rc":[{"atb":[[5.1,128.41]],"trd":[[5.1,3513.79]],"batb":[[0,5.1,128.41]],"tv":12534.72,"id":56297029},{"atb":[[8.4,45.45]],"batb":[],"id":27115873}],"tv":75116.41}]}
{"op":"mcm","id":2,"clk":"AIuaAQC2YgCDjQE=","pt":1743511902654,"mc":[{"id":"1.241629436","rc":[{"atl":[[11.5,3.61]],"batl":[[0,11.5,3.61]],"id":40389088},{"atl":[[1000,0.52],[9.8,41.47]],"batl":[[0,9.8,41.47]],"id":35856222},{"atb":[[5.1,194.91]],"batb":[[0,5.1,194.91]],"id":56297029},{"atb":[[9.4,74.29],[9.6,20.52]],"batb":[[1,9.4,74.29],[0,9.6,20.52]],"id":27115873},{"atb":[[16.5,33.89]],"atl":[[17.5,53.63]],"batb":[[0,16.5,33.89]],"batl":[[1,17.5,53.63]],"id":58186642},{"atb":[[11,130.45]],"atl":[[12,38.66],[11.5,72.18]],"batb":[[0,11,130.45]],"batl":[[1,12,38.66],[0,11.5,72.18]],"id":44049799}]}]}
{"op":"mcm","id":2,"clk":"AJSaAQC7YgCOjQE=","pt":1743511902763,"mc":[{"id":"1.241629436","rc":[{"atl":[[12,60.14]],"batl":[[1,12,60.14]],"id":40389088},{"atl":[[1000,0.41]],"id":35856222}]}]}
{"op":"mcm","id":2,"clk":"AJ2aAQDEYgCSjQE=","pt":1743511902854,"mc":[{"id":"1.241629436","rc":[{"atl":[[10,109.03]],"batl":[[1,10,109.03]],"id":35856222},{"atl":[[5.4,102.92],[5.2,219.19]],"batl":[[2,5.4,102.92],[0,5.2,219.19]],"id":56297029}]}]}
{"op":"mcm","id":2,"clk":"APqaAQCpYwD7jQE=","pt":1743511904038,"mc":[{"id":"1.241629436","rc":[{"atl":[[110,2.47]],"batl":[],"id":59626646}]}]}
{"op":"mcm","id":2,"clk":"AIObAQCvYwD/jQE=","pt":1743511904134,"mc":[{"id":"1.241629436","rc":[{"atb":[[6.4,197.52]],"trd":[[6.4,3430.82]],"batb":[[0,6.4,197.52]],"tv":12244.6,"id":26496185}],"tv":75156.41}]}
{"op":"mcm","id":2,"clk":"AJWbAQC+YwCMjgE=","pt":1743511904347,"mc":[{"id":"1.241629436","rc":[{"atl":[[12,55.12]],"batl":[[1,12,55.12]],"id":40389088}]}]}
{"op":"mcm","id":2,"clk":"ALWbAQDdYwCkjgE=","pt":1743511904747,"mc":[{"id":"1.241629436","rc":[{"atl":[[7.2,60.05]],"batl":[],"id":26496185}]}]}
{"op":"mcm","id":2,"clk":"AO2bAQCgZADpjgE=","pt":1743511905472,"mc":[{"id":"1.241629436","rc":[{"atl":[[65,0.12]],"trd":[[65,161.29]],"batl":[[2,80,6.89],[1,75,5.14],[0,70,3.1]],"tv":1690.41,"id":59626646}],"tv":75169.78}]}
{"op":"mcm","id":2,"clk":"AP+bAQCtZADyjgE=","pt":1743511905628,"mc":[{"id":"1.241629436","rc":[{"atb":[[1.17,2.3]],"atl":[[12,60.14]],"batl":[[1,12,60.14]],"id":40389088},{"atb":[[5.2,322.02]],"atl":[[1000,21.59]],"batb":[[0,5.2,322.02]],"id":270592},{"atb":[[1.17,7.68],[8.6,38.37]],"batb":[],"id":35856222},{"atb":[[60,13.13]],"atl":[[65,0]],"trd":[[65,161.53]],"batb":[[0,60,13.13]],"batl":[[0,70,2.98]],"tv":1690.65,"id":59626646}],"tv":75170.02}]}
{"op":"mcm","id":2,"clk":"AIucAQC7ZAD1jgE=","pt":1743511905734,"mc":[{"id":"1.241629436","rc":[{"atl":[[1000,21.16]],"id":270592},{"atb":[[65,4.9]],"atl":[[70,5.55]],"batb":[[2,55,15.91],[1,60,13.13],[0,65,4.9]],"batl":[[0,70,5.55]],"id":59626646},{"atb":[[5.1,199.19]],"atl":[[1000,5.41]],"batb":[[0,5.1,199.19]],"id":56297029}]}]}
{"op":"mcm","id":2,"clk":"AJGcAQDDZAD/jgE=","pt":1743511905832,"mc":[{"id":"1.241629436","rc":[{"atb":[[1.17,2]],"id":40389088},{"atl":[[5.4,133.55]],"batl":[[1,5.4,133.55]],"id":270592},{"atb":[[1.17,7.15]],"id":35856222},{"atb":[[60,11.69],[65,8.78]],"batb":[[1,60,11.69],[0,65,8.78]],"id":59626646}]}]}
{"op":"mcm","id":2,"clk":"AJycAQDMZACMjwE=","pt":1743511905943,"mc":[{"id":"1.241629436","rc":[{"atb":[[11,105.67]],"batb":[[0,11,105.67]],"id":40389088},{"atb":[[9.4,74.96]],"batb":[[0,9.4,74.96]],"id":35856222},{"atl":[[70,5.48]],"batl":[[0,70,5.48]],"id":59626646},{"atl":[[1000,4.52]],"id":56297029}]}]}
{"op":"mcm","id":2,"clk":"AKGcAQDSZACSjwE=","pt":1743511906032,"mc":[{"id":"1.241629436","rc":[{"atl":[[70,4.12]],"batl":[[0,70,4.12]],"id":59626646},{"atl":[[5.3,88.26]],"batl":[[1,5.3,88.26]],"id":56297029}]}]}
{"op":"mcm","id":2,"clk":"AKucAQDYZACajwE=","pt":1743511906142,"mc":[{"id":"1.241629436","rc":[{"atl":[[1000,23.16]],"id":270592}]}]}
{"op":"mcm","id":2,"clk":"ALicAQDnZACyjwE=","pt":1743511906351,"mc":[{"id":"1.241629436","rc":[{"atl":[[1000,21.16]],"id":270592}]}]}
{"op":"mcm","id":2,"clk":"ANOcAQD4ZAC+jwE=","pt":1743511906549,"mc":[{"id":"1.241629436","rc":[{"atb":[[9.4,72.45]],"trd":[[9.4,625.25]],"batb":[[0,9.4,72.45]],"ltp":9.4,"tv":9282.96,"id":35856222},{"atb":[[6.4,248.71]],"batb":[[0,6.4,248.71]],"id":26496185}],"tv":75175.04}]}
{"op":"mcm","id":2,"clk":"AOmcAQCMZQDTjwE=","pt":1743511906754,"mc":[{"id":"1.241629436","rc":[{"atb":[[65,5.4]],"batb":[[0,65,5.4]],"id":59626646}]}]}
{"op":"mcm","id":2,"clk":"APWcAQCUZQDcjwE=","pt":1743511906858,"mc":[{"id":"1.241629436","rc":[{"atb":[[5.1,279.22]],"batb":[[1,5.1,279.22]],"id":270592}]}]}
{"op":"mcm","id":2,"clk":"AI2dAQCiZQDrjwE=","pt":1743511907060,"mc":[{"id":"1.241629436","rc":[{"atl":[[1000,23.16]],"id":270592}]}]}
{"op":"mcm","id":2,"clk":"AKOdAQCxZQCDkAE=","pt":1743511907268,"mc":[{"id":"1.241629436","rc":[{"atl":[[1000,21.16]],"id":270592}]}]}
{"op":"mcm","id":2,"clk":"ALGdAQC4ZQCGkAE=","pt":1743511907329,"mc":[{"id":"1.241629436","rc":[{"atb":[[4,76.9]],"id":270592}]}]}
{"op":"mcm","id":2,"clk":"ALqdAQC+ZQCQkAE=","pt":1743511907443,"mc":[{"id":"1.241629436","rc":[{"atb":[[4.6,56.01]],"batb":[],"id":56297029},{"atb":[[9.6,12.52]],"batb":[[0,9.6,12.52]],"id":27115873}]}]}
{"op":"mcm","id":2,"clk":"AMKdAQDCZQCVkAE=","pt":1743511907527,"mc":[{"id":"1.241629436","rc":[{"atl":[[9.8,33.91]],"trd":[[9.8,239.22]],"batl":[[0,9.8,33.91]],"tv":6633.16,"id":27115873}],"tv":75191.03}]}
{"op":"mcm","id":2,"clk":"ANedAQDYZQCskAE=","pt":1743511907743,"mc":[{"id":"1.241629436","rc":[{"atl":[[9.8,26.97]],"batl":[[0,9.8,26.97]],"id":27115873}]}]}
{"op":"mcm","id":2,"clk":"ANmdAQDfZQC9kAE=","pt":1743511907840,"mc":[{"id":"1.241629436","rc":[{"atl":[[5.3,215.5]],"trd":[[5.3,1464.44]],"batl":[[0,5.3,215.5]],"ltp":5.3,"tv":16852.65,"id":270592},{"atl":[[9.8,35.19]],"batl":[[0,9.8,35.19]],"id":27115873}],"tv":75369.03}]}
{"op":"mcm","id":2,"clk":"AOOdAQDpZQDEkAE=","pt":1743511907946,"mc":[{"id":"1.241629436","rc":[{"atl":[[5.3,137.56]],"batl":[[0,5.3,137.56]],"id":270592}]}]}
{"op":"mcm","id":2,"clk":"AOidAQDzZQDQkAE=","pt":1743511908046,"mc":[{"id":"1.241629436","rc":[{"atl":[[5.3,113.58]],"batl":[[0,5.3,113.58]],"id":270592},{"atl":[[17,1.17]],"trd":[[17,876.3]],"batl":[[0,17,1.17]],"tv":5298.38,"id":58186642}],"tv":75371.03}]}
{"op":"mcm","id":2,"clk":"APWdAQD4ZQDbkAE=","pt":1743511908166,"mc":[{"id":"1.241629436","rc":[{"atb":[[11,105.37]],"batb":[[0,11,105.37]],"id":40389088},{"atb":[[5.2,320.91]],"atl":[[5.4,133.12]],"batb":[[0,5.2,320.91]],"batl":[[1,5.4,133.12]],"id":270592},{"atb":[[9.4,71.92]],"atl":[[10,108.92]],"batb":[[0,9.4,71.92]],"batl":[[1,10,108.92]],"id":35856222},{"atb":[[60,12.36],[55,15.4]],"batb":[[2,55,15.4],[1,60,12.36]],"id":59626646},{"atl":[[9.8,34.97]],"batl":[[0,9.8,34.97]],"id":27115873},{"atl":[[1000,19.12]],"id":44049799}]}]}
{"op":"mcm","id":2,"clk":"APmdAQCAZgDlkAE=","pt":1743511908248,"mc":[{"id":"1.241629436","rc":[{"atl":[[1000,18.87]],"id":44049799}]}]}
{"op":"mcm","id":2,"clk":"AIOeAQCGZgDrkAE=","pt":1743511908363,"mc":[{"id":"1.241629436","rc":[{"atb":[[16.5,31.82]],"trd":[[16.5,424.22]],"batb":[[0,16.5,31.82]],"ltp":16.5,"tv":5302.52,"id":58186642},{"atl":[[11.5,72.43]],"batl":[[0,11.5,72.43]],"id":44049799}],"tv":75375.17}]}
{"op":"mcm","id":2,"clk":"AIueAQCOZgD5kAE=","pt":1743511908464,"mc":[{"id":"1.241629436","rc":[{"atl":[[6.4,66.54]],"batl":[],"id":270592}]}]}
{"op":"mcm","id":2,"clk":"AJCeAQCTZgD/kAE=","pt":1743511908559,"mc":[{"id":"1.241629436","rc":[{"atb":[[16,30.2]],"batb":[[1,16,30.2]],"id":58186642}]}]}
{"op":"mcm","id":2,"clk":"ANSeAQDGZgDEkQE=","pt":1743511909238,"mc":[{"id":"1.241629436","rc":[{"atb":[[5.1,193.19]],"trd":[[5.1,3525.79]],"batb":[[0,5.1,193.19]],"tv":12546.72,"id":56297029}],"tv":75387.17}]}
{"op":"mcm","id":2,"clk":"APmeAQDgZgD1kQE=","pt":1743511909646,"mc":[{"id":"1.241629436","rc":[{"atl":[[9.8,33.59]],"batl":[[0,9.8,33.59]],"id":35856222}]}]}
{"op":"mcm","id":2,"clk":"AICfAQDjZgD9kQE=","pt":1743511909743,"mc":[{"id":"1.241629436","rc":[{"atb":[[3,56.5]],"id":40389088},{"atb":[[6.4,247.71]],"trd":[[6.4,3432.82]],"batb":[[0,6.4,247.71]],"tv":12246.6,"id":26496185}],"tv":75389.17}]}
{"op":"mcm","id":2,"clk":"AJGfAQDxZgCXkgE=","pt":1743511909951,"mc":[{"id":"1.241629436","rc":[{"atl":[[18,18.18],[17,0]],"trd":[[17,878.64]],"batl":[[2,18.5,16.21],[1,18,18.18],[0,17.5,53.63]],"ltp":17,"tv":5304.86,"id":58186642}],"tv":75391.51}]}
{"op":"mcm","id":2,"clk":"ALmfAQCMZwC7kgE=","pt":1743511910460,"mc":[{"id":"1.241629436","rc":[{"atl":[[11.5,9.61]],"batl":[[0,11.5,9.61]],"id":40389088},{"atb":[[5.1,243.19]],"batb":[[0,5.1,243.19]],"id":56297029}]}]}
{"op":"mcm","id":2,"clk":"AMOfAQCWZwDHkgE=","pt":1743511910560,"mc":[{"id":"1.241629436","rc":[{"atl":[[10,40.86]],"batl":[[1,10,40.86]],"id":27115873}]}]}
{"op":"mcm","id":2,"clk":"AMufAQCaZwDRkgE=","pt":1743511910671,"mc":[{"id":"1.241629436","rc":[{"atl":[[9.8,12.08]],"trd":[[9.8,594.31]],"batl":[[0,9.8,12.08]],"ltp":9.8,"tv":9325.97,"id":35856222},{"atb":[[5.1,235.83]],"trd":[[5.1,3569.33]],"batb":[[0,5.1,235.83]],"tv":12590.26,"id":56297029},{"atl":[[9.8,23.95]],"trd":[[9.8,261.26]],"batl":[[0,9.8,23.95]],"tv":6655.2,"id":27115873}],"tv":75500.1}]}
{"op":"mcm","id":2,"clk":"ANCfAQCiZwDYkgE=","pt":1743511910770,"mc":[{"id":"1.241629436","rc":[{"atl":[[5.3,195.56]],"batl":[[0,5.3,195.56]],"id":270592},{"atb":[[65,4.01]],"trd":[[65,164.31]],"batb":[[0,65,4.01]],"tv":1693.43,"id":59626646},{"atl":[[17.5,55.98]],"batl":[[0,17.5,55.98]],"id":58186642},{"atb":[[6.4,245.42]],"trd":[[6.4,3437.42]],"batb":[[0,6.4,245.42]],"tv":12251.2,"id":26496185}],"tv":75507.48}]}
{"op":"mcm","id":2,"clk":"ANmfAQClZwDekgE=","pt":1743511910874,"mc":[{"id":"1.241629436","rc":[{"atb":[[9.6,32.25]],"atl":[[9.8,22.97],[10,108.41]],"batb":[[2,9.2,65.8],[1,9.4,71.92],[0,9.6,32.25]],"batl":[[1,10,108.41],[0,9.8,22.97]],"id":35856222},{"atl":[[70,4.19]],"batl":[[0,70,4.19]],"id":59626646},{"atb":[[4.9,75.56],[5.1,261.83],[4.8,107.63]],"batb":[[2,4.9,75.56],[0,5.1,261.83]],"id":56297029},{"atl":[[9.8,15.73]],"batl":[[0,9.8,15.73]],"id":27115873}]}]}
{"op":"mcm","id":2,"clk":"AOOfAQCtZwDokgE=","pt":1743511910941,"mc":[{"id":"1.241629436","rc":[{"atb":[[8.8,54.56]],"batb":[],"id":35856222}]}]}
{"op":"mcm","id":2,"clk":"AO2fAQC0ZwDwkgE=","pt":1743511911036,"mc":[{"id":"1.241629436","rc":[{"atl":[[5.6,138.94]],"batl":[],"id":270592},{"atb":[[9,73]],"atl":[[9.8,21.94]],"batb":[],"batl":[[0,9.8,21.94]],"id":35856222},{"atb":[[9.6,18.07]],"batb":[[0,9.6,18.07]],"id":27115873}]}]}
{"op":"mcm","id":2,"clk":"APGfAQC7ZwD1kgE=","pt":1743511911132,"mc":[{"id":"1.241629436","rc":[{"atb":[[11,103.37]],"atl":[[1000,0.41]],"trd":[[11,89.81]],"batb":[[0,11,103.37]],"ltp":11,"tv":6237.44,"id":40389088},{"atb":[[9.6,22.25]],"atl":[[9.8,11.6]],"trd":[[9.6,397.08]],"batb":[[0,9.6,22.25]],"batl":[[0,9.8,11.6]],"ltp":9.6,"tv":9345.97,"id":35856222},{"atl":[[70,5.63]],"batl":[[0,70,5.63]],"id":59626646},{"atb":[[9.6,22.23]],"batb":[[0,9.6,22.23]],"id":27115873},{"atb":[[1.17,2.21]],"atl":[[17,0.76]],"batl":[[0,17.5,56.74]],"id":58186642},{"atb":[[11,132.09]],"atl":[[1000,19.2]],"batb":[[0,11,132.09]],"id":44049799}],"tv":75531.48}]}
{"op":"mcm","id":2,"clk":"APefAQC/ZwD8kgE=","pt":1743511911232,"mc":[{"id":"1.241629436","rc":[{"atb":[[8.8,53.06],[9,71.57]],"atl":[[9.8,21.88]],"batb":[],"batl":[[0,9.8,21.88]],"id":35856222},{"atl":[[9.8,8.79],[10,35.13]],"batl":[[1,10,35.13],[0,9.8,8.79]],"id":27115873},{"atb":[[1.17,2]],"id":58186642}]}]}
{"op":"mcm","id":2,"clk":"AIGgAQDEZwCEkwE=","pt":1743511911337,"mc":[{"id":"1.241629436","rc":[{"atl":[[1000,0.25]],"id":40389088},{"atl":[[9.8,22.88]],"batl":[[0,9.8,22.88]],"id":35856222},{"atl":[[10,35.06]],"batl":[[1,10,35.06]],"id":27115873},{"atb":[[16,30.41]],"batb":[[1,16,30.41]],"id":58186642},{"atl":[[1000,18.87]],"id":44049799}]}]}
{"op":"mcm","id":2,"clk":"AIigAQDMZwCNkwE=","pt":1743511911445,"mc":[{"id":"1.241629436","rc":[{"atl":[[11.5,9.77]],"batl":[[0,11.5,9.77]],"id":40389088},{"atb":[[8.8,54.56],[9,73]],"atl":[[12.5,23.33]],"batb":[],"batl":[],"id":35856222},{"atl":[[9.8,9.79]],"batl":[[0,9.8,9.79]],"id":27115873},{"atl":[[12,38.99]],"batl":[[1,12,38.99]],"id":44049799}]}]}
{"op":"mcm","id":2,"clk":"AI+gAQDTZwCSkwE=","pt":1743511911546,"mc":[{"id":"1.241629436","rc":[{"atl":[[1000,0.39]],"id":40389088},{"atl":[[1000,23.16]],"id":270592},{"atl":[[10.5,74.27]],"batl":[[2,10.5,74.27]],"id":35856222},{"atl":[[9.8,8.86]],"batl":[[0,9.8,8.86]],"id":27115873},{"atb":[[17,0.24]],"atl":[[17,0]],"trd":[[17,880.16]],"batb":[[0,16.5,32.06]],"batl":[[0,17.5,55.98]],"tv":5306.38,"id":58186642}],"tv":75533}]}
{"op":"mcm","id":2,"clk":"AJWgAQDaZwCYkwE=","pt":1743511911647,"mc":[{"id":"1.241629436","rc":[{"atl":[[1000,0.25]],"id":40389088}]}]}
{"op":"mcm","id":2,"clk":"AJegAQDgZwCckwE=","pt":1743511911744,"mc":[{"id":"1.241629436","rc":[{"atl":[[12,60.28]],"batl":[[1,12,60.28]],"id":40389088},{"atl":[[1000,21.16]],"id":270592},{"atb":[[5.1,258.53]],"batb":[[0,5.1,258.53]],"id":56297029}]}]}
{"op":"mcm","id":2,"clk":"AL+gAQD9ZwDKkwE=","pt":1743511912359,"mc":[{"id":"1.241629436","rc":[{"atl":[[9.8,35.84]],"batl":[[0,9.8,35.84]],"id":27115873}]}]}
{"op":"mcm","id":2,"clk":"AMugAQCDaADSkwE=","pt":1743511912467,"mc":[{"id":"1.241629436","rc":[{"atl":[[1000,23.16]],"id":270592},{"atl":[[9.8,43.08]],"batl":[[0,9.8,43.08]],"id":27115873}]}]}
{"op":"mcm","id":2,"clk":"ANWgAQCMaADakwE=","pt":1743511912570,"mc":[{"id":"1.241629436","rc":[{"atl":[[10,109.41]],"batl":[[1,10,109.41]],"id":35856222},{"atb":[[9.6,16.68]],"atl":[[9.8,48.48]],"batb":[[0,9.6,16.68]],"batl":[[0,9.8,48.48]],"id":27115873}]}]}
{"op":"mcm","id":2,"clk":"ANygAQCQaADdkwE=","pt":1743511912672,"mc":[{"id":"1.241629436","rc":[{"atl":[[1000,21.16]],"id":270592},{"atl":[[10,40.96]],"batl":[[1,10,40.96]],"id":27115873}]}]}
{"op":"mcm","id":2,"clk":"AOqgAQCcaADlkwE=","pt":1743511912866,"mc":[{"id":"1.241629436","rc":[{"atl":[[11.5,10.77]],"batl":[[0,11.5,10.77]],"id":40389088},{"atb":[[9.2,41.41]],"batb":[[2,9.2,41.41]],"id":27115873}]}]}
{"op":"mcm","id":2,"clk":"APGgAQCfaADskwE=","pt":1743511912924,"mc":[{"id":"1.241629436","rc":[{"atb":[[11,98.37]],"trd":[[11,99.81]],"batb":[[0,11,98.37]],"tv":6247.44,"id":40389088}],"tv":75543}]}
{"op":"mcm","id":2,"clk":"APygAQCkaAD0kwE=","pt":1743511913035,"mc":[{"id":"1.241629436","rc":[{"atl":[[5.3,90.51]],"batl":[[1,5.3,90.51]],"id":56297029}]}]}
{"op":"mcm","id":2,"clk":"AIihAQCsaACFlAE=","pt":1743511913231,"mc":[{"id":"1.241629436","rc":[{"atb":[[6.4,242.42]],"trd":[[6.4,3443.42]],"batb":[[0,6.4,242.42]],"tv":12257.2,"id":26496185}],"tv":75549}]}
{"op":"mcm","id":2,"clk":"AJqhAQC7aACPlAE=","pt":1743511913434,"mc":[{"id":"1.241629436","rc":[{"atl":[[10.5,75.27]],"batl":[[2,10.5,75.27]],"id":35856222}]}]}
{"op":"mcm","id":2,"clk":"AMChAQDVaACvlAE=","pt":1743511913853,"mc":[{"id":"1.241629436","rc":[{"atb":[[1.13,50]],"id":35856222}]}]}
{"op":"mcm","id":2,"clk":"AMmhAQDcaAC4lAE=","pt":1743511913961,"mc":[{"id":"1.241629436","rc":[{"atb":[[65,4.85]],"batb":[[0,65,4.85]],"id":59626646},{"atb":[[11,131.1]],"trd":[[11,1393.39]],"batb":[[0,11,131.1]],"tv":4602.45,"id":44049799}],"tv":75550.98}]}
{"op":"mcm","id":2,"clk":"APuhAQCDaQDslAE=","pt":1743511914566,"mc":[{"id":"1.241629436","rc":[{"atl":[[11,29.45]],"batl":[],"id":35856222}]}]}
{"op":"mcm","id":2,"clk":"AJOiAQCNaQD1lAE=","pt":1743511914769,"mc":[{"id":"1.241629436","rc":[{"atb":[[9.6,15.58]],"batb":[[0,9.6,15.58]],"id":27115873},{"atb":[[16,30.2]],"batb":[[1,16,30.2]],"id":58186642},{"atb":[[6.4,240.77]],"batb":[[0,6.4,240.77]],"id":26496185}]}]}
{"op":"mcm","id":2,"clk":"AKWiAQCZaQD/lAE=","pt":1743511914929,"mc":[{"id":"1.241629436","rc":[{"atb":[[11,136.14]],"batb":[[0,11,136.14]],"id":44049799}]}]}
{"op":"mcm","id":2,"clk":"AL6iAQCraQCXlQE=","pt":1743511915136,"mc":[{"id":"1.241629436","rc":[{"atl":[[9.8,40.21]],"trd":[[9.8,277.8]],"batl":[[0,9.8,40.21]],"tv":6671.74,"id":27115873}],"tv":75567.52}]}
{"op":"mcm","id":2,"clk":"AOCiAQC7aQCrlQE=","pt":1743511915435,"mc":[{"id":"1.241629436","rc":[{"atl":[[11.5,61.34]],"batl":[],"id":35856222}]}]}
{"op":"mcm","id":2,"clk":"APSiAQDKaQC6lQE=","pt":1743511915647,"mc":[{"id":"1.241629436","rc":[{"atb":[[10.5,29.55]],"batb":[[1,10.5,29.55]],"id":40389088}]}]}
{"op":"mcm","id":2,"clk":"APyiAQDVaQC/lQE=","pt":1743511915755,"mc":[{"id":"1.241629436","rc":[{"atb":[[5.2,270.91]],"trd":[[5.2,1851.62]],"batb":[[0,5.2,270.91]],"ltp":5.2,"tv":16952.65,"id":270592}],"tv":75667.52}]}
{"op":"mcm","id":2,"clk":"AIqjAQDXaQDKlQE=","pt":1743511915849,"mc":[{"id":"1.241629436","rc":[{"atb":[[9.6,19.02]],"batb":[[0,9.6,19.02]],"id":27115873}]}]}
{"op":"mcm","id":2,"clk":"AJKjAQDZaQDQlQE=","pt":1743511915943,"mc":[{"id":"1.241629436","rc":[{"atl":[[10,35.06]],"batl":[[1,10,35.06]],"id":27115873}]}]}
{"op":"mcm","id":2,"clk":"AJ+jAQDbaQDalQE=","pt":1743511916054,"mc":[{"id":"1.241629436","rc":[{"atb":[[5.2,250.91],[3,44.53]],"trd":[[5.2,1891.62]],"batb":[[0,5.2,250.91]],"tv":16992.65,"id":270592},{"atl":[[11.5,71.76]],"trd":[[11.5,721.91]],"batl":[[0,11.5,71.76]],"ltp":11.5,"tv":4603.79,"id":44049799}],"tv":75708.86}]}
{"op":"mcm","id":2,"clk":"AKqjAQDiaQDulQE=","pt":1743511916258,"mc":[{"id":"1.241629436","rc":[{"atl":[[12,44.02]],"batl":[],"id":35856222},{"atb":[[9.6,16.51]],"trd":[[9.6,183.5]],"batb":[[0,9.6,16.51]],"ltp":9.6,"tv":6676.76,"id":27115873}],"tv":75713.88}]}
{"op":"mcm","id":2,"clk":"ALSjAQDoaQD4lQE=","pt":1743511916353,"mc":[{"id":"1.241629436","rc":[{"atl":[[10,40.96]],"batl":[[1,10,40.96]],"id":27115873},{"atb":[[17,4.24]],"batb":[[2,16,30.2],[1,16.5,31.82],[0,17,4.24]],"id":58186642}]}]}
{"op":"mcm","id":2,"clk":"AMajAQD2aQCKlgE=","pt":1743511916567,"mc":[{"id":"1.241629436","rc":[{"atb":[[17,3.14]],"trd":[[17,882.36]],"batb":[[0,17,3.14]],"tv":5308.58,"id":58186642}],"tv":75716.08}]}
{"op":"mcm","id":2,"clk":"AM+jAQD/aQCVlgE=","pt":1743511916669,"mc":[{"id":"1.241629436","rc":[{"atb":[[4.9,86.57]],"batb":[[2,4.9,86.57]],"id":56297029}]}]}
{"op":"mcm","id":2,"clk":"ANOjAQCHagCblgE=","pt":1743511916766,"mc":[{"id":"1.241629436","rc":[{"atb":[[8.4,44.3]],"batb":[],"id":27115873},{"atb":[[17,1.6]],"trd":[[17,885.44]],"batb":[[0,17,1.6]],"tv":5311.66,"id":58186642}],"tv":75719.16}]}
{"op":"mcm","id":2,"clk":"AOKjAQCQagCnlgE=","pt":1743511916878,"mc":[{"id":"1.241629436","rc":[{"atb":[[8,35.09]],"atl":[[10,35.06]],"batb":[],"batl":[[1,10,35.06]],"id":27115873},{"atb":[[17,0.64],[16.5,28.43]],"atl":[[17.5,59.41]],"trd":[[17,887.36]],"batb":[[2,15.5,45.43],[1,16,30.2],[0,16.5,29.07]],"batl":[[0,17.5,59.41]],"tv":5313.58,"id":58186642}],"tv":75721.08}]}
{"op":"mcm","id":2,"clk":"AOejAQCVagCslgE=","pt":1743511916973,"mc":[{"id":"1.241629436","rc":[{"atl":[[1000,23.16]],"id":270592},{"atb":[[17,0]],"atl":[[17,6.26]],"trd":[[17,888.64]],"batb":[[0,16.5,28.43]],"batl":[[2,18,18.18],[1,17.5,59.41],[0,17,6.26]],"tv":5314.86,"id":58186642}],"tv":75722.36}]}
{"op":"mcm","id":2,"clk":"APKjAQCcagC5lgE=","pt":1743511917075,"mc":[{"id":"1.241629436","rc":[{"atb":[[4.9,75.56]],"batb":[[2,4.9,75.56]],"id":56297029},{"atl":[[10,40.96]],"batl":[[1,10,40.96]],"id":27115873},{"atb":[[16.5,31.81]],"atl":[[17.5,55.98]],"batb":[[0,16.5,31.81]],"batl":[[1,17.5,55.98]],"id":58186642}]}]}
{"op":"mcm","id":2,"clk":"AP6jAQCjagDClgE=","pt":1743511917132,"mc":[{"id":"1.241629436","rc":[{"atb":[[11,95.37]],"trd":[[11,105.81]],"batb":[[0,11,95.37]],"tv":6253.44,"id":40389088},{"atl":[[1000,21.16]],"id":270592},{"atb":[[4,72]],"id":58186642}],"tv":75728.36}]}
{"op":"mcm","id":2,"clk":"AISkAQCsagDIlgE=","pt":1743511917235,"mc":[{"id":"1.241629436","rc":[{"atb":[[5.2,248.91]],"trd":[[5.2,1895.62]],"batb":[[0,5.2,248.91]],"tv":16996.65,"id":270592}],"tv":75732.36}]}
{"op":"mcm","id":2,"clk":"ALmkAQDSagDnlgE=","pt":1743511917750,"mc":[{"id":"1.241629436","rc":[{"atb":[[1.17,2.13]],"id":40389088},{"atb":[[1.17,7.27]],"atl":[[1000,0.99]],"id":35856222},{"atl":[[17.5,59.78]],"batl":[[1,17.5,59.78]],"id":58186642}]}]}
{"op":"mcm","id":2,"clk":"AL+kAQDYagDulgE=","pt":1743511917850,"mc":[{"id":"1.241629436","rc":[{"atb":[[1.17,2]],"id":40389088},{"atl":[[1000,23.16]],"id":270592},{"atb":[[1.17,7.15]],"atl":[[1000,0.41]],"id":35856222}]}]}
{"op":"mcm","id":2,"clk":"AMykAQDeagDzlgE=","pt":1743511917955,"mc":[{"id":"1.241629436","rc":[{"atb":[[10.5,29.68]],"batb":[[1,10.5,29.68]],"id":40389088},{"atb":[[9.4,72.04]],"atl":[[9.8,23.46]],"batb":[[1,9.4,72.04]],"batl":[[0,9.8,23.46]],"id":35856222},{"atb":[[5.1,257.55]],"batb":[[0,5.1,257.55]],"id":56297029}]}]}
{"op":"mcm","id":2,"clk":"ANmkAQDkagD+lgE=","pt":1743511918066,"mc":[{"id":"1.241629436","rc":[{"atl":[[1000,21.16]],"id":270592}]}]}
{"op":"mcm","id":2,"clk":"AOukAQDyagCVlwE=","pt":1743511918266,"mc":[{"id":"1.241629436","rc":[{"atb":[[5.2,244.91]],"trd":[[5.2,1903.62]],"batb":[[0,5.2,244.91]],"tv":17004.65,"id":270592}],"tv":75740.36}]}
{"op":"mcm","id":2,"clk":"AJKlAQCSawCulwE=","pt":1743511918677,"mc":[{"id":"1.241629436","rc":[{"atb":[[5.9,54.79]],"batb":[],"id":26496185}]}]}
{"op":"mcm","id":2,"clk":"ANulAQDBawDZlwE=","pt":1743511919442,"mc":[{"id":"1.241629436","rc":[{"atb":[[9.6,11.51]],"trd":[[9.6,193.5]],"batb":[[0,9.6,11.51]],"tv":6686.76,"id":27115873},{"atb":[[1.02,5155.56]],"id":58186642}],"tv":75750.36}]}
{"op":"mcm","id":2,"clk":"AOKlAQDJawDglwE=","pt":1743511919543,"mc":[{"id":"1.241629436","rc":[{"atl":[[15.5,38.5],[15,16.54],[14.5,10.68],[14,17.23],[13.5,13.08],[13,19.71],[12.5,60.31],[12,59.86],[16,7.39]],"batl":[[2,12.5,60.31],[1,12,59.86]],"id":40389088},{"atb":[[5.2,243.95],[4.9,198.4],[4.6,115.94],[5,346.91],[5.1,278.24],[4.8,113.7]],"atl":[[5.7,76.74],[5.6,136.22]],"batb":[[2,5,346.91],[1,5.1,278.24],[0,5.2,243.95]],"batl":[],"id":270592},{"atb":[[9.4,71.51],[8.4,64.93],[8.8,53.99],[8.2,13.77],[9.2,65.27],[9,72.44],[8.6,37.8]],"atl":[[11.5,60.91],[11,28.97],[10.5,74.76]],"batb":[[2,9.2,65.27],[1,9.4,71.51]],"batl":[[2,10.5,74.76]],"id":35856222},{"atb":[[60,12.28],[55,15.32],[50,15.95],[48,4.26],[46,9.01],[44,4.83],[42,9.28],[40,22.63]],"atl":[[80,6.83],[75,5.07],[70,5.56]],"batb":[[2,55,15.32],[1,60,12.28]],"batl":[[2,80,6.83],[1,75,5.07],[0,70,5.56]],"id":59626646},{"atb":[[4.7,40.5],[4.9,74.56],[4.6,52.69],[5,1162.65],[4.5,79.15],[4.8,104.55]],"atl":[[5.4,100.07],[5.3,89.57],[5.5,64.82],[5.6,54.96]],"batb":[[2,4.9,74.56],[1,5,1162.65]],"batl":[[2,5.4,100.07],[1,5.3,89.57]],"id":56297029},{"atb":[[9.6,8.07]],"atl":[[13.5,29.17],[13,11.76],[9.8,39.7],[12.5,278.2],[12,29.28],[11.5,25.31],[11,59.51],[10.5,66.05]],"batb":[[0,9.6,8.07]],"batl":[[2,10.5,66.05],[0,9.8,39.7]],"id":27115873},{"atb":[[15.5,45.11],[15,23.54],[1.02,5154.06],[16,29.89],[16.5,31.51]],"atl":[[22,6.51],[21,10.93],[20,6.12],[19.5,7.67],[19,10.73],[18.5,15.94],[18,17.9],[17.5,59.49]],"batb":[[2,15.5,45.11],[1,16,29.89],[0,16.5,31.51]],"batl":[[2,18,17.9],[1,17.5,59.49]],"id":58186642},{"atb":[[5.7,77.74],[5.5,136.85],[6.2,173.28],[6.4,239.99],[5.6,105.23]],"atl":[[6.6,55.2],[7,47.12],[6.8,167.09],[7.4,50.04],[7.2,58.57]],"trd":[[6.6,1901.11]],"batb":[[1,6.2,173.28],[0,6.4,239.99]],"batl":[[2,7,47.12],[1,6.8,167.09],[0,6.6,55.2]],"ltp":6.6,"tv":12266.02,"id":26496185},{"atb":[[9.4,29.11],[8.8,38.94],[9.8,31.4],[10.5,69.27],[9.2,23.5],[10,77.5],[9,13.47],[9.6,26.93]],"atl":[[12.5,48.64],[12,38.57]],"batb":[[2,10,77.5],[1,10.5,69.27]],"batl":[[2,12.5,48.64],[1,12,38.57]],"id":44049799}],"tv":75759.18}]}
{"op":"mcm","id":2,"clk":"AOulAQDUawDnlwE=","pt":1743511919645,"mc":[{"id":"1.241629436","rc":[{"atl":[[70,15.09]],"batl":[[0,70,15.09]],"id":59626646},{"atl":[[9.8,107.76]],"batl":[[0,9.8,107.76]],"id":27115873}]}]}
{"op":"mcm","id":2,"clk":"APSlAQDgawDylwE=","pt":1743511919753,"mc":[{"id":"1.241629436","rc":[{"atl":[[70,16.39]],"batl":[[0,70,16.39]],"id":59626646},{"atb":[[9.6,1.24]],"trd":[[9.6,201.44]],"batb":[[0,9.6,1.24]],"tv":6694.7,"id":27115873},{"atb":[[1.02,5153.56]],"atl":[[17.5,21.38]],"batl":[[1,17.5,21.38]],"id":58186642}],"tv":75767.12}]}
{"op":"mcm","id":2,"clk":"AP6lAQDpawD5lwE=","pt":1743511919863,"mc":[{"id":"1.241629436","rc":[{"atb":[[9.6,28.1]],"batb":[[0,9.6,28.1]],"id":35856222},{"atb":[[9.4,68.35],[9.6,0]],"atl":[[9.6,9.03]],"trd":[[9.6,203.92]],"batb":[[2,9,36.76],[1,9.2,41.41],[0,9.4,68.35]],"batl":[[2,10,40.96],[1,9.8,107.76],[0,9.6,9.03]],"tv":6697.18,"id":27115873},{"atb":[[16.5,32.01]],"batb":[[0,16.5,32.01]],"id":58186642}],"tv":75769.6}]}
{"op":"mcm","id":2,"clk":"AI2mAQCHbACHmAE=","pt":1743511920144,"mc":[{"id":"1.241629436","rc":[{"atl":[[5.6,134.24]],"batl":[],"id":270592},{"atb":[[8.4,59.67],[9.4,74.29]],"atl":[[9.6,7.47]],"trd":[[9.6,207.04]],"batb":[[0,9.4,74.29]],"batl":[[0,9.6,7.47]],"tv":6700.3,"id":27115873}],"con":true,"tv":75772.72}]}
{"op":"mcm","id":2,"clk":"AJKmAQCJbACJmAE=","pt":1743511920164,"mc":[{"id":"1.241629436","rc":[{"atl":[[11.5,12.7]],"batl":[[0,11.5,12.7]],"id":40389088},{"atb":[[9.6,29.17]],"batb":[[0,9.6,29.17]],"id":35856222},{"atl":[[70,16.44]],"batl":[[0,70,16.44]],"id":59626646},{"atl":[[5.2,219.6]],"batl":[[0,5.2,219.6]],"id":56297029},{"atl":[[9.8,107.75],[9.6,10.35]],"trd":[[9.6,221.98]],"batl":[[1,9.8,107.75],[0,9.6,10.35]],"tv":6715.24,"id":27115873},{"atl":[[17,6.81]],"batl":[[0,17,6.81]],"id":58186642}],"tv":75787.66}]}
{"op":"mcm","id":2,"clk":"AJ6mAQCPbACTmAE=","pt":1743511920278,"mc":[{"id":"1.241629436","rc":[{"atl":[[5.3,193.97]],"batl":[[0,5.3,193.97]],"id":270592},{"atl":[[5.2,218.76]],"trd":[[5.2,3587.02]],"batl":[[0,5.2,218.76]],"ltp":5.2,"tv":12591.94,"id":56297029},{"atb":[[11,124.02]],"trd":[[11,1417.63]],"batb":[[0,11,124.02]],"ltp":11,"tv":4628.03,"id":44049799}],"tv":75813.58}]}
{"op":"mcm","id":2,"clk":"AKKmAQCYbACWmAE=","pt":1743511920374,"mc":[{"id":"1.241629436","rc":[{"atb":[[5.2,246.33]],"atl":[[5.3,192.97]],"trd":[[5.3,1466.44]],"batb":[[0,5.2,246.33]],"batl":[[0,5.3,192.97]],"ltp":5.3,"tv":17006.65,"id":270592},{"atb":[[9.6,37.19]],"batb":[[0,9.6,37.19]],"id":35856222},{"atl":[[9.6,11.78]],"batl":[[0,9.6,11.78]],"id":27115873}],"tv":75815.58}]}
{"op":"mcm","id":2,"clk":"AK2mAQCgbAChmAE=","pt":1743511920487,"mc":[{"id":"1.241629436","rc":[{"atb":[[11,122.02]],"trd":[[11,1421.63]],"batb":[[0,11,122.02]],"tv":4632.03,"id":44049799}],"tv":75819.58}]}
{"op":"mcm","id":2,"clk":"ALWmAQChbAClmAE=","pt":1743511920579,"mc":[{"id":"1.241629436","rc":[{"atl":[[5.5,138.68]],"batl":[[2,5.5,138.68]],"id":270592},{"atb":[[9.6,36.19]],"trd":[[9.6,399.08]],"batb":[[0,9.6,36.19]],"tv":9347.97,"id":35856222},{"atb":[[50,16.01]],"batb":[],"id":59626646},{"atl":[[7,49.12]],"batl":[[2,7,49.12]],"id":26496185}],"tv":75821.58}]}
{"op":"mcm","id":2,"clk":"AMOmAQC0bACzmAE=","pt":1743511920789,"mc":[{"id":"1.241629436","rc":[{"atb":[[9.6,44.93]],"batb":[[0,9.6,44.93]],"id":35856222}]}]}
{"op":"mcm","id":2,"clk":"AMqmAQC/bAC/mAE=","pt":1743511920892,"mc":[{"id":"1.241629436","rc":[{"atb":[[5.2,245.33]],"trd":[[5.2,1905.62]],"batb":[[0,5.2,245.33]],"ltp":5.2,"tv":17008.65,"id":270592}],"tv":75823.58}]}
{"op":"mcm","id":2,"clk":"ANKmAQDCbADDmAE=","pt":1743511920940,"mc":[{"id":"1.241629436","rc":[{"atb":[[8.2,12.35]],"id":40389088}]}]}
{"op":"mcm","id":2,"clk":"APGmAQDPbADcmAE=","pt":1743511921256,"mc":[{"id":"1.241629436","rc":[{"atb":[[11,97.03],[10.5,29.55]],"atl":[[1000,0.84],[11.5,12.54]],"batb":[[1,10.5,29.55],[0,11,97.03]],"batl":[[0,11.5,12.54]],"id":40389088},{"atb":[[9.4,71.39],[9.6,47.06]],"atl":[[1000,0.84],[9.8,22.88]],"batb":[[1,9.4,71.39],[0,9.6,47.06]],"batl":[[0,9.8,22.88]],"id":35856222},{"atl":[[70,18.1]],"batl":[[0,70,18.1]],"id":59626646},{"atl":[[1000,4.41],[10,44.65]],"batl":[[2,10,44.65]],"id":27115873},{"atl":[[17.5,17.58],[17,7.46]],"batl":[[1,17.5,17.58],[0,17,7.46]],"id":58186642},{"atb":[[6.4,242.14]],"batb":[[0,6.4,242.14]],"id":26496185},{"atb":[[11,120.38]],"atl":[[12,38.24],[11.5,71.51]],"batb":[[0,11,120.38]],"batl":[[1,12,38.24],[0,11.5,71.51]],"id":44049799}]}]}
{"op":"mcm","id":2,"clk":"APimAQDUbADjmAE=","pt":1743511921359,"mc":[{"id":"1.241629436","rc":[{"atl":[[1000,0.25]],"id":40389088},{"atl":[[1000,0.41]],"id":35856222},{"atb":[[65,4.76]],"trd":[[65,164.49]],"batb":[[0,65,4.76]],"tv":1693.61,"id":59626646},{"atl":[[5.2,217.92]],"trd":[[5.2,3588.69]],"batl":[[0,5.2,217.92]],"tv":12593.61,"id":56297029}],"tv":75825.43}]}
{"op":"mcm","id":2,"clk":"AP+mAQDabADpmAE=","pt":1743511921458,"mc":[{"id":"1.241629436","rc":[{"atl":[[12,60.2],[11.5,12.79]],"batl":[[1,12,60.2],[0,11.5,12.79]],"id":40389088},{"atl":[[10,109.84]],"batl":[[1,10,109.84]],"id":35856222},{"atb":[[65,4.49]],"trd":[[65,165.03]],"batb":[[0,65,4.49]],"tv":1694.15,"id":59626646},{"atl":[[1000,3.66]],"id":27115873}],"tv":75825.97}]}
{"op":"mcm","id":2,"clk":"AISnAQDebADtmAE=","pt":1743511921556,"mc":[{"id":"1.241629436","rc":[{"atl":[[9.8,108.5]],"batl":[[1,9.8,108.5]],"id":27115873}]}]}
{"op":"mcm","id":2,"clk":"AI2nAQDjbAD0mAE=","pt":1743511921677,"mc":[{"id":"1.241629436","rc":[{"atb":[[11,93.62]],"batb":[[0,11,93.62]],"id":40389088},{"atb":[[65,4.18]],"trd":[[65,165.65]],"batb":[[0,65,4.18]],"tv":1694.77,"id":59626646},{"atb":[[5.1,249.03]],"batb":[[0,5.1,249.03]],"id":56297029},{"atb":[[16.5,29.77]],"batb":[[0,16.5,29.77]],"id":58186642}],"tv":75826.59}]}
{"op":"mcm","id":2,"clk":"AJinAQDsbAD7mAE=","pt":1743511921769,"mc":[{"id":"1.241629436","rc":[{"atl":[[10,40.65]],"batl":[[2,10,40.65]],"id":27115873}]}]}
{"op":"mcm","id":2,"clk":"AKKnAQDybACDmQE=","pt":1743511921873,"mc":[{"id":"1.241629436","rc":[{"atb":[[5.2,180.33],[5,258.91],[5.1,223.24]],"batb":[[2,5,258.91],[1,5.1,223.24],[0,5.2,180.33]],"id":270592},{"atb":[[9.6,45.06]],"trd":[[9.6,403.08]],"batb":[[0,9.6,45.06]],"tv":9351.97,"id":35856222},{"atb":[[5.1,269.03]],"batb":[[0,5.1,269.03]],"id":56297029}],"tv":75830.59}]}
{"op":"mcm","id":2,"clk":"AK2nAQD6bACGmQE=","pt":1743511921979,"mc":[{"id":"1.241629436","rc":[{"atb":[[65,4]],"trd":[[65,166.01]],"batb":[[0,65,4]],"tv":1695.13,"id":59626646},{"atl":[[9.6,5.24]],"batl":[[0,9.6,5.24]],"id":27115873}],"tv":75830.95}]}
{"op":"mcm","id":2,"clk":"ALSnAQCCbQCMmQE=","pt":1743511922085,"mc":[{"id":"1.241629436","rc":[{"atb":[[5.2,175.33]],"atl":[[5.3,216.88]],"trd":[[5.2,1915.62]],"batb":[[0,5.2,175.33]],"batl":[[0,5.3,216.88]],"tv":17018.65,"id":270592}],"tv":75840.95}]}
{"op":"mcm","id":2,"clk":"ALunAQCGbQCWmQE=","pt":1743511922185,"mc":[{"id":"1.241629436","rc":[{"atb":[[65,2.12]],"batb":[[0,65,2.12]],"id":59626646}]}]}
{"op":"mcm","id":2,"clk":"AL6nAQCIbQCYmQE=","pt":1743511922280,"mc":[{"id":"1.241629436","rc":[{"atb":[[10.5,30.55]],"batb":[[1,10.5,30.55]],"id":40389088},{"atl":[[5.3,185.81]],"trd":[[5.3,1528.58]],"batl":[[0,5.3,185.81]],"ltp":5.3,"tv":17080.79,"id":270592},{"atl":[[17,1.2]],"batl":[[0,17,1.2]],"id":58186642}],"tv":75903.09}]}
{"op":"mcm","id":2,"clk":"AMqnAQCNbQCimQE=","pt":1743511922345,"mc":[{"id":"1.241629436","rc":[{"atb":[[5.1,234.05]],"atl":[[1000,23.16],[5.3,196.62]],"batb":[[1,5.1,234.05]],"batl":[[0,5.3,196.62]],"id":270592},{"atb":[[65,1.97]],"trd":[[65,166.31]],"batb":[[0,65,1.97]],"tv":1695.43,"id":59626646}],"tv":75903.39}]}
{"op":"mcm","id":2,"clk":"ANKnAQCWbQCrmQE=","pt":1743511922494,"mc":[{"id":"1.241629436","rc":[{"atb":[[65,0.07]],"trd":[[65,170.11]],"batb":[[2,50,16.01],[1,55,15.32],[0,60,12.35]],"tv":1699.23,"id":59626646}],"tv":75907.19}]}
{"op":"mcm","id":2,"clk":"ANmnAQCcbQCumQE=","pt":1743511922547,"mc":[{"id":"1.241629436","rc":[{"atl":[[1000,21.16]],"id":270592},{"atb":[[65,0]],"trd":[[65,170.25]],"batb":[[0,60,12.28]],"tv":1699.37,"id":59626646},{"atl":[[5.2,217.08]],"trd":[[5.2,3590.37]],"batl":[[0,5.2,217.08]],"tv":12595.29,"id":56297029}],"tv":75909.01}]}
{"op":"mcm","id":2,"clk":"AN2nAQCgbQC1mQE=","pt":1743511922645,"mc":[{"id":"1.241629436","rc":[{"atl":[[65,6.77]],"batl":[[2,75,5.07],[1,70,18.1],[0,65,6.77]],"id":59626646}]}]}
{"op":"mcm","id":2,"clk":"AOSnAQCpbQC8mQE=","pt":1743511922751,"mc":[{"id":"1.241629436","rc":[{"atl":[[70,18.05],[65,8.2]],"batl":[[1,70,18.05],[0,65,8.2]],"id":59626646}]}]}
{"op":"mcm","id":2,"clk":"AOinAQCxbQDBmQE=","pt":1743511922852,"mc":[{"id":"1.241629436","rc":[{"atl":[[10.5,73.76]],"batl":[[2,10.5,73.76]],"id":35856222}]}]}
{"op":"mcm","id":2,"clk":"AO+nAQC5bQDKmQE=","pt":1743511922957,"mc":[{"id":"1.241629436","rc":[{"atl":[[11.5,15.66]],"batl":[[0,11.5,15.66]],"id":40389088},{"atb":[[5.2,166.1]],"trd":[[5.2,1934.08]],"batb":[[0,5.2,166.1]],"ltp":5.2,"tv":17099.25,"id":270592},{"atl":[[9.8,27.12]],"batl":[[0,9.8,27.12]],"id":35856222},{"atl":[[65,9.46]],"batl":[[0,65,9.46]],"id":59626646},{"atb":[[5.1,257.55]],"trd":[[5.1,3592.3]],"batb":[[0,5.1,257.55]],"ltp":5.1,"tv":12618.26,"id":56297029},{"atb":[[8.4,61.32],[8.6,36.7]],"atl":[[9.6,8.19]],"batb":[],"batl":[[0,9.6,8.19]],"id":27115873},{"atl":[[17,3.72]],"batl":[[0,17,3.72]],"id":58186642},{"atl":[[11.5,78.6]],"batl":[[0,11.5,78.6]],"id":44049799}],"tv":75950.44}]}
{"op":"mcm","id":2,"clk":"AISoAQDFbQDYmQE=","pt":1743511923259,"mc":[{"id":"1.241629436","rc":[{"atl":[[1000,23.16]],"id":270592}]}]}
{"op":"mcm","id":2,"clk":"AJWoAQDPbQDjmQE=","pt":1743511923467,"mc":[{"id":"1.241629436","rc":[{"atl":[[1000,21.16]],"id":270592}]}]}
{"op":"mcm","id":2,"clk":"AJ2oAQDVbQDqmQE=","pt":1743511923568,"mc":[{"id":"1.241629436","rc":[{"atb":[[5.1,252.81]],"trd":[[5.1,3601.78]],"batb":[[0,5.1,252.81]],"tv":12627.74,"id":56297029},{"atb":[[16.5,0]],"atl":[[16.5,0.23]],"trd":[[16.5,483.76]],"batb":[[2,15,23.54],[1,15.5,45.11],[0,16,29.89]],"batl":[[0,17,3.95]],"ltp":16.5,"tv":5374.4,"id":58186642}],"tv":76019.46}]}
{"op":"mcm","id":2,"clk":"AKKoAQDbbQDwmQE=","pt":1743511923669,"mc":[{"id":"1.241629436","rc":[{"atb":[[5.2,176.9]],"batb":[[0,5.2,176.9]],"id":270592},{"atb":[[60,10.02]],"atl":[[65,10.26]],"trd":[[60,310.73]],"batb":[[0,60,10.02]],"batl":[[0,65,10.26]],"ltp":60,"tv":1700.72,"id":59626646},{"atl":[[5.2,216.24]],"trd":[[5.2,3592.05]],"batl":[[0,5.2,216.24]],"ltp":5.2,"tv":12629.42,"id":56297029},{"atb":[[9.4,75.72]],"batb":[[0,9.4,75.72]],"id":27115873},{"atl":[[17.5,21.01],[17,7.24],[16.5,6.44]],"trd":[[16.5,485.78]],"batl":[[2,17.5,21.01],[1,17,7.24],[0,16.5,6.44]],"tv":5376.42,"id":58186642},{"atl":[[11.5,80.36]],"batl":[[0,11.5,80.36]],"id":44049799}],"tv":76024.51}]}
{"op":"mcm","id":2,"clk":"AK+oAQDgbQD0mQE=","pt":1743511923775,"mc":[{"id":"1.241629436","rc":[{"atb":[[9.6,63.81]],"batb":[[0,9.6,63.81]],"id":35856222},{"atl":[[5.3,87.32]],"batl":[[1,5.3,87.32]],"id":56297029},{"atb":[[16,26.4]],"atl":[[17,10.65]],"batb":[[0,16,26.4]],"batl":[[1,17,10.65]],"id":58186642},{"atb":[[6.4,270.26]],"batb":[[0,6.4,270.26]],"id":26496185}]}]}
{"op":"mcm","id":2,"clk":"ALWoAQDpbQD4mQE=","pt":1743511923869,"mc":[{"id":"1.241629436","rc":[{"atb":[[60,9.85]],"trd":[[60,311.07]],"batb":[[0,60,9.85]],"tv":1701.06,"id":59626646},{"atb":[[9.4,72.72]],"trd":[[9.4,112.41]],"batb":[[0,9.4,72.72]],"ltp":9.4,"tv":6721.24,"id":27115873}],"tv":76030.85}]}
{"op":"mcm","id":2,"clk":"ALyoAQDubQCBmgE=","pt":1743511923975,"mc":[{"id":"1.241629436","rc":[{"atb":[[8.6,23.8],[9.6,77.81]],"batb":[[0,9.6,77.81]],"id":35856222},{"atb":[[5.1,257.81]],"batb":[[0,5.1,257.81]],"id":56297029},{"atl":[[9.6,15.57]],"batl":[[0,9.6,15.57]],"id":27115873}]}]}
{"op":"mcm","id":2,"clk":"AMmoAQD4bQCOmgE=","pt":1743511924086,"mc":[{"id":"1.241629436","rc":[{"atb":[[10.5,31.55]],"batb":[[1,10.5,31.55]],"id":40389088}]}]}
{"op":"mcm","id":2,"clk":"ANKoAQCCbgCUmgE=","pt":1743511924192,"mc":[{"id":"1.241629436","rc":[{"atl":[[7.2,68.57]],"batl":[],"id":26496185}]}]}
{"op":"mcm","id":2,"clk":"ANeoAQCIbgCcmgE=","pt":1743511924290,"mc":[{"id":"1.241629436","rc":[{"atb":[[9.8,30.61],[10,67.18]],"batb":[[2,10,67.18]],"id":40389088},{"atb":[[5.1,270.76]],"atl":[[5.3,89.98]],"batb":[[0,5.1,270.76]],"batl":[[1,5.3,89.98]],"id":56297029},{"atb":[[9.4,76.39]],"batb":[[0,9.4,76.39]],"id":27115873},{"atb":[[1.17,2.14]],"atl":[[1000,3.41]],"id":58186642}]}]}
{"op":"mcm","id":2,"clk":"ANuoAQCKbgCfmgE=","pt":1743511924379,"mc":[{"id":"1.241629436","rc":[{"atl":[[10.5,1.03]],"id":56297029},{"atb":[[1.17,2]],"atl":[[28,2.02]],"id":58186642},{"atl":[[9.4,1]],"id":26496185}]}]}
{"op":"mcm","id":2,"clk":"AOGoAQCSbgCnmgE=","pt":1743511924492,"mc":[{"id":"1.241629436","rc":[{"atb":[[16,26.54]],"atl":[[1000,1.9]],"batb":[[0,16,26.54]],"id":58186642}]}]}
{"op":"mcm","id":2,"clk":"AO6oAQCgbgCumgE=","pt":1743511924647,"mc":[{"id":"1.241629436","rc":[{"atl":[[1000,1.41]],"id":58186642}]}]}
{"op":"mcm","id":2,"clk":"APaoAQCmbgCymgE=","pt":1743511924759,"mc":[{"id":"1.241629436","rc":[{"atb":[[5.2,251.9]],"batb":[[0,5.2,251.9]],"id":270592},{"atl":[[5.2,215.4]],"trd":[[5.2,3593.72]],"batl":[[0,5.2,215.4]],"tv":12631.09,"id":56297029},{"atl":[[17,11.14]],"batl":[[1,17,11.14]],"id":58186642}],"tv":76032.52}]}
{"op":"mcm","id":2,"clk":"APyoAQCrbgC2mgE=","pt":1743511924862,"mc":[{"id":"1.241629436","rc":[{"atb":[[9.4,74.96]],"trd":[[9.4,115.27]],"batb":[[0,9.4,74.96]],"tv":6724.1,"id":27115873},{"atl":[[17,12.14],[16.5,8.59]],"batl":[[1,17,12.14],[0,16.5,8.59]],"id":58186642}],"tv":76035.38}]}
{"op":"mcm","id":2,"clk":"AIepAQCwbgC8mgE=","pt":1743511924964,"mc":[{"id":"1.241629436","rc":[{"atl":[[10.5,74.76]],"batl":[[2,10.5,74.76]],"id":35856222},{"atl":[[17,9.62]],"batl":[[1,17,9.62]],"id":58186642}]}]}
{"op":"mcm","id":2,"clk":"AJWpAQDAbgDGmgE=","pt":1743511925157,"mc":[{"id":"1.241629436","rc":[{"atl":[[16.5,11.19]],"batl":[[0,16.5,11.19]],"id":58186642}]}]}
{"op":"mcm","id":2,"clk":"AJqpAQDIbgDLmgE=","pt":1743511925263,"mc":[{"id":"1.241629436","rc":[{"atb":[[16,24.22]],"batb":[[0,16,24.22]],"id":58186642}]}]}
{"op":"mcm","id":2,"clk":"AMOpAQDzbgDkmgE=","pt":1743511925776,"mc":[{"id":"1.241629436","rc":[{"atl":[[11,29.97]],"batl":[],"id":35856222}]}]}
{"op":"mcm","id":2,"clk":"AMipAQD4bgDlmgE=","pt":1743511925873,"mc":[{"id":"1.241629436","rc":[{"atl":[[5.2,214.56]],"trd":[[5.2,3595.4]],"batl":[[0,5.2,214.56]],"tv":12632.77,"id":56297029}],"tv":76037.06}]}
{"op":"mcm","id":2,"clk":"ANGpAQD/bgDpmgE=","pt":1743511925976,"mc":[{"id":"1.241629436","rc":[{"atb":[[11,96.02]],"batb":[[0,11,96.02]],"id":40389088},{"atl":[[9.8,16.34]],"trd":[[9.8,615.86]],"batl":[[0,9.8,16.34]],"ltp":9.8,"tv":9373.52,"id":35856222},{"atb":[[5.1,253.12]],"trd":[[5.1,3649.07]],"batb":[[0,5.1,253.12]],"ltp":5.1,"tv":12680.06,"id":56297029},{"atl":[[9.6,4.55]],"trd":[[9.6,244.02]],"batl":[[0,9.6,4.55]],"ltp":9.6,"tv":6746.14,"id":27115873},{"atb":[[16,25.22]],"batb":[[0,16,25.22]],"id":58186642}],"tv":76127.94}]}
{"op":"mcm","id":2,"clk":"ANypAQCNbwDxmgE=","pt":1743511926142,"mc":[{"id":"1.241629436","rc":[{"atl":[[9.8,6.06]],"batl":[[0,9.8,6.06]],"id":35856222},{"atb":[[8.4,59.67],[8.6,35.13]],"atl":[[9.6,1]],"batb":[],"batl":[[0,9.6,1]],"id":27115873}]}]}
{"op":"mcm","id":2,"clk":"AOKpAQCVbwD1mgE=","pt":1743511926242,"mc":[{"id":"1.241629436","rc":[{"atb":[[8.4,61.32]],"batb":[],"id":27115873}]}]}
{"op":"mcm","id":2,"clk":"AOipAQCcbwD4mgE=","pt":1743511926339,"mc":[{"id":"1.241629436","rc":[{"atb":[[5.1,302.05]],"batb":[[1,5.1,302.05]],"id":270592}]}]}
{"op":"mcm","id":2,"clk":"AO2pAQCnbwD9mgE=","pt":1743511926448,"mc":[{"id":"1.241629436","rc":[{"atb":[[9.8,29.42],[10,66.05]],"batb":[[2,10,66.05]],"id":40389088},{"atb":[[4,189.01]],"id":56297029}]}]}
{"op":"mcm","id":2,"clk":"APGpAQCubwCAmwE=","pt":1743511926552,"mc":[{"id":"1.241629436","rc":[{"atb":[[8.4,59.67]],"batb":[],"id":27115873},{"atb":[[3,4]],"id":58186642}]}]}
{"op":"mcm","id":2,"clk":"APWpAQC0bwCFmwE=","pt":1743511926645,"mc":[{"id":"1.241629436","rc":[{"atb":[[5.1,250.89]],"batb":[[0,5.1,250.89]],"id":56297029}]}]}
{"op":"mcm","id":2,"clk":"AIaqAQDDbwCTmwE=","pt":1743511926868,"mc":[{"id":"1.241629436","rc":[{"atl":[[5.2,213.72]],"trd":[[5.2,3597.07]],"batl":[[0,5.2,213.72]],"ltp":5.2,"tv":12681.73,"id":56297029},{"atl":[[7.6,28.5],[6.8,149.73]],"batl":[[1,6.8,149.73]],"id":26496185}],"tv":76129.61}]}
{"op":"mcm","id":2,"clk":"AJqqAQDdbwChmwE=","pt":1743511926970,"mc":[{"id":"1.241629436","rc":[{"atl":[[70,14.95]],"batl":[[1,70,14.95]],"id":59626646},{"atb":[[5.1,239.97]],"batb":[[0,5.1,239.97]],"id":56297029},{"atb":[[16,25.08]],"batb":[[0,16,25.08]],"id":58186642},{"atb":[[6.4,272.87]],"batb":[[0,6.4,272.87]],"id":26496185},{"atl":[[11.5,81.25]],"batl":[[0,11.5,81.25]],"id":44049799}]}]}
{"op":"mcm","id":2,"clk":"AKmqAQDsbwCzmwE=","pt":1743511927062,"mc":[{"id":"1.241629436","rc":[{"atb":[[60,9.18]],"batb":[[0,60,9.18]],"id":59626646},{"atl":[[5.3,87.74]],"batl":[[1,5.3,87.74]],"id":56297029},{"atl":[[17,8.97]],"batl":[[1,17,8.97]],"id":58186642}]}]}
{"op":"mcm","id":2,"clk":"AN6qAQCucAD1mwE=","pt":1743511927386,"mc":[{"id":"1.241629436","rc":[{"atl":[[7.2,63.57]],"batl":[],"id":26496185}]}]}
{"op":"mcm","id":2,"clk":"AO+qAQDBcACDnAE=","pt":1743511927535,"mc":[{"id":"1.241629436","rc":[{"atl":[[16.5,0.69]],"trd":[[16.5,506.78]],"batl":[[2,18,17.9],[1,17.5,21.01],[0,17,9.66]],"tv":5397.42,"id":58186642}],"tv":76150.61}]}
{"op":"mcm","id":2,"clk":"AP2qAQDacACVnAE=","pt":1743511927651,"mc":[{"id":"1.241629436","rc":[{"atb":[[5,350.41]],"batb":[[2,5,350.41]],"id":270592},{"atl":[[9.8,14.88]],"batl":[[0,9.8,14.88]],"id":35856222},{"atb":[[16,29.88]],"atl":[[17,15.25],[16.5,0]],"trd":[[16.5,508.16]],"batb":[[0,16,29.88]],"batl":[[0,17,15.25]],"tv":5398.8,"id":58186642}],"tv":76151.99}]}
{"op":"mcm","id":2,"clk":"AIirAQDncACbnAE=","pt":1743511927751,"mc":[{"id":"1.241629436","rc":[{"atb":[[5.2,253.4]],"atl":[[1000,23.16]],"batb":[[0,5.2,253.4]],"id":270592},{"atb":[[16,33.32]],"batb":[[0,16,33.32]],"id":58186642}]}]}
{"op":"mcm","id":2,"clk":"AJerAQDzcACmnAE=","pt":1743511927855,"mc":[{"id":"1.241629436","rc":[{"atl":[[5.2,212.22]],"trd":[[5.2,3600.07]],"batl":[[0,5.2,212.22]],"tv":12684.73,"id":56297029},{"atb":[[16,32.32]],"batb":[[0,16,32.32]],"id":58186642}],"tv":76154.99}]}
{"op":"mcm","id":2,"clk":"AJyrAQD+cACsnAE=","pt":1743511927958,"mc":[{"id":"1.241629436","rc":[{"atl":[[1000,21.16]],"id":270592},{"atl":[[5.2,211.38]],"trd":[[5.2,3601.75]],"batl":[[0,5.2,211.38]],"tv":12686.41,"id":56297029},{"atl":[[6.6,53.7]],"trd":[[6.6,1904.11]],"batl":[[0,6.6,53.7]],"tv":12269.02,"id":26496185}],"tv":76159.67}]}
{"op":"mcm","id":2,"clk":"AMCrAQCRcQDInAE=","pt":1743511928184,"mc":[{"id":"1.241629436","rc":[{"atl":[[9.8,13.38]],"trd":[[9.8,618.86]],"batl":[[0,9.8,13.38]],"tv":9376.52,"id":35856222},{"atb":[[16.5,1]],"batb":[[2,15.5,45.11],[1,16,32.32],[0,16.5,1]],"id":58186642}],"tv":76162.67}]}
{"op":"mcm","id":2,"clk":"AMirAQCXcQDUnAE=","pt":1743511928291,"mc":[{"id":"1.241629436","rc":[{"atb":[[5.1,224.97]],"trd":[[5.1,3679.07]],"batb":[[0,5.1,224.97]],"ltp":5.1,"tv":12716.41,"id":56297029}],"tv":76192.67}]}
{"op":"mcm","id":2,"clk":"ANKrAQCccQDcnAE=","pt":1743511928390,"mc":[{"id":"1.241629436","rc":[{"atl":[[5.3,89.99]],"batl":[[1,5.3,89.99]],"id":56297029},{"atb":[[9.6,0.5]],"atl":[[9.6,0]],"trd":[[9.6,246.02]],"batb":[[0,9.4,75.46]],"batl":[[2,10.5,66.05],[1,10,40.65],[0,9.8,108.5]],"tv":6748.14,"id":27115873},{"atb":[[16,28.88],[16.5,0]],"atl":[[17,14.25]],"trd":[[16.5,510.16]],"batb":[[2,15,23.54],[1,15.5,45.11],[0,16,28.88]],"batl":[[0,17,14.25]],"tv":5400.8,"id":58186642}],"tv":76196.67}]}
{"op":"mcm","id":2,"clk":"AOKrAQCkcQDqnAE=","pt":1743511928452,"mc":[{"id":"1.241629436","rc":[{"atb":[[1.85,5.5]],"id":40389088},{"atl":[[1000,23.16]],"id":270592},{"atb":[[1.85,5.5]],"id":35856222},{"atb":[[1.85,5.5]],"id":59626646},{"atl":[[5.2,213.72]],"batl":[[0,5.2,213.72]],"id":56297029},{"atb":[[1.85,5.5]],"id":27115873},{"atb":[[1.85,5.5]],"id":58186642},{"atb":[[1.85,5.5],[11,121.88]],"batb":[[0,11,121.88]],"id":44049799}]}]}
{"op":"mcm","id":2,"clk":"AOmrAQCpcQD1nAE=","pt":1743511928554,"mc":[{"id":"1.241629436","rc":[{"atb":[[5.2,252.95]],"atl":[[5.3,271.62]],"trd":[[5.2,1934.98]],"batb":[[0,5.2,252.95]],"batl":[[0,5.3,271.62]],"tv":17100.15,"id":270592},{"atb":[[9.6,0]],"trd":[[9.6,247.02]],"batb":[[0,9.4,74.96]],"tv":6749.14,"id":27115873},{"atb":[[16,32.32]],"batb":[[0,16,32.32]],"id":58186642},{"atl":[[6.8,167.09]],"batl":[[1,6.8,167.09]],"id":26496185}],"tv":76198.57}]}
{"op":"mcm","id":2,"clk":"APWrAQCycQCAnQE=","pt":1743511928657,"mc":[{"id":"1.241629436","rc":[{"atb":[[11,97.52]],"batb":[[0,11,97.52]],"id":40389088}]}]}
{"op":"mcm","id":2,"clk":"AIOsAQC8cQCanQE=","pt":1743511928872,"mc":[{"id":"1.241629436","rc":[{"atl":[[1000,21.16]],"id":270592},{"atb":[[16.5,1.5]],"batb":[[2,15.5,45.11],[1,16,32.32],[0,16.5,1.5]],"id":58186642}]}]}
{"op":"mcm","id":2,"clk":"AJOsAQDJcQCrnQE=","pt":1743511929079,"mc":[{"id":"1.241629436","rc":[{"atb":[[60,10.68]],"batb":[[0,60,10.68]],"id":59626646},{"atl":[[5.2,212.88]],"trd":[[5.2,3603.43]],"batl":[[0,5.2,212.88]],"ltp":5.2,"tv":12718.09,"id":56297029},{"atb":[[16.5,9.9]],"batb":[[0,16.5,9.9]],"id":58186642}],"tv":76200.25}]}
{"op":"mcm","id":2,"clk":"AJysAQDTcQC5nQE=","pt":1743511929179,"mc":[{"id":"1.241629436","rc":[{"atb":[[2.1,0],[11,87.52]],"atl":[[21,1]],"trd":[[11,125.81]],"batb":[[0,11,87.52]],"tv":6273.44,"id":40389088},{"atb":[[5.2,250.95]],"trd":[[5.2,1938.98]],"batb":[[0,5.2,250.95]],"tv":17104.15,"id":270592},{"atb":[[9.6,67.81]],"trd":[[9.6,423.08]],"batb":[[0,9.6,67.81]],"ltp":9.6,"tv":9396.52,"id":35856222},{"atl":[[17,11.85]],"batl":[[0,17,11.85]],"id":58186642},{"atb":[[6.4,252.86]],"trd":[[6.4,3483.42]],"batb":[[0,6.4,252.86]],"ltp":6.4,"tv":12309.02,"id":26496185},{"atb":[[11,120.88]],"trd":[[11,1423.63]],"batb":[[0,11,120.88]],"tv":4634.03,"id":44049799}],"tv":76286.25}]}
{"op":"mcm","id":2,"clk":"AKmsAQDgcQDCnQE=","pt":1743511929290,"mc":[{"id":"1.241629436","rc":[{"atb":[[11,82.52]],"atl":[[11.5,36.27]],"trd":[[11,135.81]],"batb":[[0,11,82.52]],"batl":[[0,11.5,36.27]],"tv":6283.44,"id":40389088},{"atb":[[16.5,16.27]],"batb":[[0,16.5,16.27]],"id":58186642}],"tv":76296.25}]}
{"op":"mcm","id":2,"clk":"ALOsAQDrcQDQnQE=","pt":1743511929391,"mc":[{"id":"1.241629436","rc":[{"atl":[[65,11.26]],"batl":[[0,65,11.26]],"id":59626646}]}]}
{"op":"mcm","id":2,"clk":"ALusAQD2cQDWnQE=","pt":1743511929445,"mc":[{"id":"1.241629436","rc":[{"atb":[[16.5,19.65]],"batb":[[0,16.5,19.65]],"id":58186642}]}]}
{"op":"mcm","id":2,"clk":"AMysAQCLcgDznQE=","pt":1743511929663,"mc":[{"id":"1.241629436","rc":[{"atb":[[5.1,201.97]],"trd":[[5.1,3729.07]],"batb":[[0,5.1,201.97]],"ltp":5.1,"tv":12768.09,"id":56297029},{"atb":[[16,40.2]],"atl":[[17.5,5.95],[17,0]],"trd":[[17,912.34],[17.5,163.95]],"batb":[[1,16,40.2]],"batl":[[2,18.5,15.94],[1,18,17.9],[0,17.5,5.95]],"ltp":17.5,"tv":5454.62,"id":58186642}],"tv":76400.07}]}
{"op":"mcm","id":2,"clk":"ANWsAQCRcgD8nQE=","pt":1743511929766,"mc":[{"id":"1.241629436","rc":[{"atb":[[9.2,71]],"batb":[[2,9.2,71]],"id":35856222},{"atb":[[17,10.91],[16.5,32.11]],"atl":[[17.5,3.59]],"batb":[[2,16,40.2],[1,16.5,32.11],[0,17,10.91]],"batl":[[0,17.5,3.59]],"id":58186642}]}]}
{"op":"mcm","id":2,"clk":"AN2sAQCacgCHngE=","pt":1743511929866,"mc":[{"id":"1.241629436","rc":[{"atb":[[17,25.02],[16.5,35.4]],"atl":[[17.5,0.16]],"batb":[[1,16.5,35.4],[0,17,25.02]],"batl":[[2,19,10.73],[1,18.5,15.94],[0,18,18.06]],"id":58186642},{"atl":[[12,43.29]],"batl":[[1,12,43.29]],"id":44049799}]}]}
