{"op":"mcm","id":2,"clk":"AOusAQCkcgCRngE=","pt":1743511929975,"mc":[{"id":"1.241629436","rc":[{"atl":[[12,60.06]],"batl":[[1,12,60.06]],"id":40389088},{"atb":[[5.2,240.15]],"atl":[[5.6,136.22]],"batb":[[0,5.2,240.15]],"batl":[],"id":270592},{"atb":[[5.1,195.85]],"trd":[[5.1,3741.31]],"batb":[[0,5.1,195.85]],"tv":12780.33,"id":56297029},{"atb":[[17.5,2.64],[17,28.3]],"atl":[[18,5.34],[17.5,0]],"trd":[[17.5,170.51]],"batb":[[2,16.5,35.4],[1,17,28.3],[0,17.5,2.64]],"batl":[[0,18,5.34]],"tv":5461.18,"id":58186642},{"atb":[[11,126.83]],"atl":[[12,44.49]],"batb":[[0,11,126.83]],"batl":[[1,12,44.49]],"id":44049799}],"tv":76418.87}]}
{"op":"mcm","id":2,"clk":"APisAQCscgCdngE=","pt":1743511930078,"mc":[{"id":"1.241629436","rc":[{"atb":[[17,31.53]],"atl":[[18,0.37]],"trd":[[18,106.13]],"batb":[[1,17,31.53]],"batl":[[2,19.5,7.67],[1,19,10.73],[0,18.5,16.31]],"ltp":18,"tv":5471.11,"id":58186642}],"tv":76428.8}]}
{"op":"mcm","id":2,"clk":"AImtAQC2cgCvngE=","pt":1743511930189,"mc":[{"id":"1.241629436","rc":[{"atb":[[5.1,193.95]],"atl":[[5.2,212.04]],"trd":[[5.2,3605.1],[5.1,3745.11]],"batb":[[0,5.1,193.95]],"batl":[[0,5.2,212.04]],"ltp":5.2,"tv":12785.8,"id":56297029},{"atb":[[15,12.13],[17,22.92],[17.5,11.04]],"batb":[[1,17,22.92],[0,17.5,11.04]],"id":58186642},{"atb":[[6.4,224.74]],"batb":[[0,6.4,224.74]],"id":26496185},{"atb":[[11,110.47]],"batb":[[0,11,110.47]],"id":44049799}],"tv":76434.27}]}
{"op":"mcm","id":2,"clk":"AJOtAQC5cgC5ngE=","pt":1743511930284,"mc":[{"id":"1.241629436","rc":[{"atb":[[5.1,179.54]],"batb":[[0,5.1,179.54]],"id":56297029},{"atl":[[18,2.11]],"batl":[[2,19,10.73],[1,18.5,15.94],[0,18,2.11]],"id":58186642}]}]}
{"op":"mcm","id":2,"clk":"ALGtAQDFcgDVngE=","pt":1743511930457,"mc":[{"id":"1.241629436","rc":[{"atb":[[17.5,14.24]],"batb":[[0,17.5,14.24]],"id":58186642}]}]}
{"op":"mcm","id":2,"clk":"ALqtAQDOcgDlngE=","pt":1743511930555,"mc":[{"id":"1.241629436","rc":[{"atl":[[9.8,16.38]],"batl":[[0,9.8,16.38]],"id":35856222},{"atl":[[18.5,12.63]],"batl":[[1,18.5,12.63]],"id":58186642}]}]}
{"op":"mcm","id":2,"clk":"ANmtAQDmcgCAnwE=","pt":1743511930774,"mc":[{"id":"1.241629436","rc":[{"atb":[[9.6,45.81]],"trd":[[9.6,467.08]],"batb":[[0,9.6,45.81]],"tv":9440.52,"id":35856222}],"tv":76478.27}]}
{"op":"mcm","id":2,"clk":"AOGtAQDwcgCQnwE=","pt":1743511930864,"mc":[{"id":"1.241629436","rc":[{"atl":[[8.8,5.72]],"id":270592},{"atb":[[9.6,37.07]],"atl":[[9.8,23.31]],"batb":[[0,9.6,37.07]],"batl":[[0,9.8,23.31]],"id":35856222},{"atl":[[22,2.14]],"id":44049799}]}]}
{"op":"mcm","id":2,"clk":"AOqtAQD+cgCdnwE=","pt":1743511930969,"mc":[{"id":"1.241629436","rc":[{"atb":[[5.2,250.95]],"atl":[[8.8,5.69]],"batb":[[0,5.2,250.95]],"id":270592},{"atb":[[9.6,28.92]],"atl":[[9.8,26.11],[10,115.7]],"trd":[[9.8,624.98]],"batb":[[0,9.6,28.92]],"batl":[[1,10,115.7],[0,9.8,26.11]],"ltp":9.8,"tv":9446.64,"id":35856222},{"atl":[[12,39.44]],"batl":[[1,12,39.44]],"id":44049799}],"tv":76484.39}]}
{"op":"mcm","id":2,"clk":"AO+tAQCNcwClnwE=","pt":1743511931071,"mc":[{"id":"1.241629436","rc":[{"atb":[[9.6,34.21]],"batb":[[0,9.6,34.21]],"id":35856222}]}]}
{"op":"mcm","id":2,"clk":"APqtAQCYcwC1nwE=","pt":1743511931179,"mc":[{"id":"1.241629436","rc":[{"atb":[[9.6,28.36]],"batb":[[0,9.6,28.36]],"id":35856222}]}]}
{"op":"mcm","id":2,"clk":"AJKuAQCxcwDOnwE=","pt":1743511931391,"mc":[{"id":"1.241629436","rc":[{"atl":[[5.2,211.2]],"trd":[[5.2,3606.78]],"batl":[[0,5.2,211.2]],"tv":12787.48,"id":56297029}],"tv":76486.07}]}
{"op":"mcm","id":2,"clk":"AJuuAQC5cwDXnwE=","pt":1743511931495,"mc":[{"id":"1.241629436","rc":[{"atl":[[18,0.97]],"trd":[[18,108.41]],"batl":[[2,19.5,7.67],[1,19,10.73],[0,18.5,13.6]],"tv":5473.39,"id":58186642}],"tv":76488.35}]}
{"op":"mcm","id":2,"clk":"AKOuAQC/cwDknwE=","pt":1743511931545,"mc":[{"id":"1.241629436","rc":[{"atb":[[60,10.88]],"batb":[[0,60,10.88]],"id":59626646},{"atb":[[5.1,175.72]],"batb":[[0,5.1,175.72]],"id":56297029}]}]}
{"op":"mcm","id":2,"clk":"ALauAQDWcwDxnwE=","pt":1743511931762,"mc":[{"id":"1.241629436","rc":[{"atl":[[1000,2.25]],"id":40389088}]}]}
{"op":"mcm","id":2,"clk":"AMOuAQDecwD7nwE=","pt":1743511931865,"mc":[{"id":"1.241629436","rc":[{"atb":[[4.9,59.56]],"atl":[[5.2,222.8]],"batb":[[2,4.9,59.56]],"batl":[[0,5.2,222.8]],"id":56297029}]}]}
{"op":"mcm","id":2,"clk":"AM+uAQDpcwCGoAE=","pt":1743511931978,"mc":[{"id":"1.241629436","rc":[{"atl":[[1000,1.04]],"id":40389088}]}]}
{"op":"mcm","id":2,"clk":"ANGuAQDxcwCMoAE=","pt":1743511932067,"mc":[{"id":"1.241629436","rc":[{"atb":[[5.2,230.95]],"trd":[[5.2,1978.98]],"batb":[[0,5.2,230.95]],"tv":17144.15,"id":270592},{"atb":[[9.6,40.21]],"batb":[[0,9.6,40.21]],"id":35856222},{"atb":[[5.1,173.72]],"batb":[[0,5.1,173.72]],"id":56297029}],"tv":76528.35}]}
{"op":"mcm","id":2,"clk":"AN6uAQD2cwCaoAE=","pt":1743511932177,"mc":[{"id":"1.241629436","rc":[{"atb":[[11,78.52]],"atl":[[1000,0.25]],"trd":[[11,143.81]],"batb":[[0,11,78.52]],"tv":6291.44,"id":40389088}],"tv":76536.35}]}
{"op":"mcm","id":2,"clk":"AOiuAQD8cwCmoAE=","pt":1743511932287,"mc":[{"id":"1.241629436","rc":[{"atb":[[11,77.73]],"trd":[[11,145.39]],"batb":[[0,11,77.73]],"tv":6293.02,"id":40389088},{"atb":[[5.2,305.83]],"batb":[[0,5.2,305.83]],"id":270592}],"tv":76537.93}]}
{"op":"mcm","id":2,"clk":"APKuAQCHdACpoAE=","pt":1743511932393,"mc":[{"id":"1.241629436","rc":[{"atl":[[5.2,221.96]],"trd":[[5.2,3608.46]],"batl":[[0,5.2,221.96]],"tv":12789.16,"id":56297029}],"tv":76539.61}]}
{"op":"mcm","id":2,"clk":"AICvAQCUdAC0oAE=","pt":1743511932594,"mc":[{"id":"1.241629436","rc":[{"atb":[[11,76.07]],"atl":[[1000,0.71],[12,59.72],[11.5,36.02]],"batb":[[0,11,76.07]],"batl":[[1,12,59.72],[0,11.5,36.02]],"id":40389088},{"atb":[[9.6,38.08]],"atl":[[1000,0.76],[10,115.27]],"batb":[[0,9.6,38.08]],"batl":[[1,10,115.27]],"id":35856222},{"atb":[[60,11.13]],"batb":[[0,60,11.13]],"id":59626646},{"atb":[[5.1,171.69]],"atl":[[5.3,89.57]],"batb":[[0,5.1,171.69]],"batl":[[1,5.3,89.57]],"id":56297029},{"atb":[[9.4,72.41]],"atl":[[1000,4.05],[9.8,107.75]],"batb":[[0,9.4,72.41]],"batl":[[0,9.8,107.75]],"id":27115873},{"atb":[[6.4,221.35]],"batb":[[0,6.4,221.35]],"id":26496185},{"atb":[[11,105.43]],"atl":[[12,38.43]],"batb":[[0,11,105.43]],"batl":[[1,12,38.43]],"id":44049799}]}]}
{"op":"mcm","id":2,"clk":"AIyvAQCcdAC/oAE=","pt":1743511932650,"mc":[{"id":"1.241629436","rc":[{"atl":[[1000,0.25]],"id":40389088},{"atl":[[1000,0.41]],"id":35856222},{"atl":[[1000,3.66]],"id":27115873}]}]}
{"op":"mcm","id":2,"clk":"AJuvAQCndADJoAE=","pt":1743511932760,"mc":[{"id":"1.241629436","rc":[{"atl":[[11.5,36.48]],"batl":[[0,11.5,36.48]],"id":40389088},{"atl":[[9.8,26.46]],"batl":[[0,9.8,26.46]],"id":35856222},{"atl":[[9.8,107.92],[10,40.87]],"batl":[[1,10,40.87],[0,9.8,107.92]],"id":27115873}]}]}
{"op":"mcm","id":2,"clk":"AKqvAQCwdADSoAE=","pt":1743511932870,"mc":[{"id":"1.241629436","rc":[{"atb":[[50,15.95]],"batb":[[2,50,15.95]],"id":59626646}]}]}
{"op":"mcm","id":2,"clk":"AMavAQDIdADroAE=","pt":1743511933183,"mc":[{"id":"1.241629436","rc":[{"atb":[[11,74.07]],"trd":[[11,149.39]],"batb":[[0,11,74.07]],"tv":6297.02,"id":40389088}],"tv":76543.61}]}
{"op":"mcm","id":2,"clk":"ANOvAQDQdADzoAE=","pt":1743511933278,"mc":[{"id":"1.241629436","rc":[{"atl":[[5.6,39.96]],"batl":[],"id":56297029}]}]}
{"op":"mcm","id":2,"clk":"AN+vAQDVdAD7oAE=","pt":1743511933386,"mc":[{"id":"1.241629436","rc":[{"atl":[[5.3,273.12]],"batl":[[0,5.3,273.12]],"id":270592},{"atl":[[5.2,221.12]],"trd":[[5.2,3610.13]],"batl":[[0,5.2,221.12]],"tv":12790.83,"id":56297029}],"tv":76545.28}]}
{"op":"mcm","id":2,"clk":"AISwAQDzdACboQE=","pt":1743511933656,"mc":[{"id":"1.241629436","rc":[{"atb":[[5.1,161.46]],"trd":[[5.1,3765.58]],"batb":[[0,5.1,161.46]],"ltp":5.1,"tv":12811.3,"id":56297029}],"tv":76565.75}]}
{"op":"mcm","id":2,"clk":"AKCwAQCIdQCuoQE=","pt":1743511933877,"mc":[{"id":"1.241629436","rc":[{"atl":[[1000,23.16]],"id":270592},{"atb":[[5.1,160.33]],"trd":[[5.1,3767.84]],"batb":[[0,5.1,160.33]],"tv":12813.56,"id":56297029}],"tv":76568.01}]}
{"op":"mcm","id":2,"clk":"ALmwAQCfdQDFoQE=","pt":1743511934086,"mc":[{"id":"1.241629436","rc":[{"atb":[[6.4,213.35]],"trd":[[6.4,3499.42]],"batb":[[0,6.4,213.35]],"tv":12325.02,"id":26496185},{"atl":[[11.5,76.13]],"trd":[[11.5,732.15]],"batl":[[0,11.5,76.13]],"ltp":11.5,"tv":4644.27,"id":44049799}],"tv":76594.25}]}
{"op":"mcm","id":2,"clk":"ANCwAQCydQDRoQE=","pt":1743511934288,"mc":[{"id":"1.241629436","rc":[{"atl":[[1000,21.16]],"id":270592},{"atb":[[5.1,159.07]],"trd":[[5.1,3770.36]],"batb":[[0,5.1,159.07]],"tv":12816.08,"id":56297029}],"tv":76596.77}]}
{"op":"mcm","id":2,"clk":"AOCwAQC8dQDaoQE=","pt":1743511934397,"mc":[{"id":"1.241629436","rc":[{"atl":[[6.6,56.64]],"batl":[[0,6.6,56.64]],"id":26496185}]}]}
{"op":"mcm","id":2,"clk":"AIixAQDddQD6oQE=","pt":1743511934657,"mc":[{"id":"1.241629436","rc":[{"atb":[[4.7,146.46]],"batb":[],"id":270592}]}]}
{"op":"mcm","id":2,"clk":"AJexAQDidQCDogE=","pt":1743511934765,"mc":[{"id":"1.241629436","rc":[{"atl":[[5.3,270.92]],"trd":[[5.3,1532.98]],"batl":[[0,5.3,270.92]],"ltp":5.3,"tv":17148.55,"id":270592},{"atb":[[5.1,156.96]],"trd":[[5.1,3774.58]],"batb":[[0,5.1,156.96]],"tv":12820.3,"id":56297029}],"tv":76605.39}]}
{"op":"mcm","id":2,"clk":"AKuxAQDqdQCLogE=","pt":1743511934870,"mc":[{"id":"1.241629436","rc":[{"atb":[[60,11.16]],"batb":[[0,60,11.16]],"id":59626646}]}]}
{"op":"mcm","id":2,"clk":"ALSxAQDzdQCZogE=","pt":1743511934976,"mc":[{"id":"1.241629436","rc":[{"atb":[[5.1,156.55]],"trd":[[5.1,3775.4]],"batb":[[0,5.1,156.55]],"tv":12821.12,"id":56297029}],"tv":76606.21}]}
{"op":"mcm","id":2,"clk":"AOmxAQCidgDWogE=","pt":1743511935490,"mc":[{"id":"1.241629436","rc":[{"atb":[[14,5.5]],"batb":[],"id":58186642}]}]}
{"op":"mcm","id":2,"clk":"APCxAQCudgDfogE=","pt":1743511935596,"mc":[{"id":"1.241629436","rc":[{"atb":[[5.2,306.83]],"atl":[[1000,21.36]],"batb":[[0,5.2,306.83]],"id":270592},{"atb":[[55,15.67]],"atl":[[65,12.92]],"batb":[[1,55,15.67]],"batl":[[0,65,12.92]],"id":59626646},{"atb":[[3,30]],"id":56297029},{"atb":[[17,23.85]],"atl":[[1000,1.75]],"batb":[[1,17,23.85]],"id":58186642}]}]}
{"op":"mcm","id":2,"clk":"AP6xAQC1dgDpogE=","pt":1743511935693,"mc":[{"id":"1.241629436","rc":[{"atl":[[1000,21.16]],"id":270592},{"atl":[[1000,1.41]],"id":58186642}]}]}
{"op":"mcm","id":2,"clk":"AIiyAQC/dgD0ogE=","pt":1743511935798,"mc":[{"id":"1.241629436","rc":[{"atl":[[5.4,133.32]],"batl":[[1,5.4,133.32]],"id":270592},{"atl":[[18,1.31]],"batl":[[2,19,10.73],[1,18.5,12.63],[0,18,1.31]],"id":58186642}]}]}
{"op":"mcm","id":2,"clk":"AJ+yAQDQdgCFowE=","pt":1743511935960,"mc":[{"id":"1.241629436","rc":[{"atb":[[9.6,47.24]],"batb":[[0,9.6,47.24]],"id":35856222}]}]}
{"op":"mcm","id":2,"clk":"AKuyAQDYdgCOowE=","pt":1743511936064,"mc":[{"id":"1.241629436","rc":[{"atl":[[5.2,241.12]],"batl":[[0,5.2,241.12]],"id":56297029}]}]}
{"op":"mcm","id":2,"clk":"AMayAQDvdgClowE=","pt":1743511936275,"mc":[{"id":"1.241629436","rc":[{"atb":[[5.1,155.37]],"batb":[[0,5.1,155.37]],"id":56297029}]}]}
{"op":"mcm","id":2,"clk":"ANGyAQD6dgCzowE=","pt":1743511936384,"mc":[{"id":"1.241629436","rc":[{"atb":[[11,64.61]],"trd":[[11,162.13]],"batb":[[0,11,64.61]],"tv":6309.76,"id":40389088},{"atb":[[17.5,15.87]],"batb":[[0,17.5,15.87]],"id":58186642}],"tv":76618.95}]}
{"op":"mcm","id":2,"clk":"AN2yAQCAdwC3owE=","pt":1743511936483,"mc":[{"id":"1.241629436","rc":[{"atb":[[4.7,147.42]],"batb":[],"id":270592}]}]}
{"op":"mcm","id":2,"clk":"AOiyAQCJdwDNowE=","pt":1743511936592,"mc":[{"id":"1.241629436","rc":[{"atb":[[1.01,72187.92]],"id":40389088}]}]}
{"op":"mcm","id":2,"clk":"AO6yAQCSdwDRowE=","pt":1743511936687,"mc":[{"id":"1.241629436","rc":[{"atl":[[6.6,55.09]],"trd":[[6.6,1907.21]],"batl":[[0,6.6,55.09]],"ltp":6.6,"tv":12328.12,"id":26496185}],"tv":76622.05}]}
{"op":"mcm","id":2,"clk":"AJmzAQDAdwCJpAE=","pt":1743511937060,"mc":[{"id":"1.241629436","rc":[{"atb":[[5.2,305.83],[5.1,293.51]],"trd":[[5.2,1980.98]],"batb":[[1,5.1,293.51],[0,5.2,305.83]],"ltp":5.2,"tv":17150.55,"id":270592}],"tv":76624.05}]}
{"op":"mcm","id":2,"clk":"AKezAQDJdwCYpAE=","pt":1743511937171,"mc":[{"id":"1.241629436","rc":[{"atb":[[4.6,55.47]],"atl":[[5.7,89.95]],"batb":[],"batl":[],"id":56297029}]}]}
{"op":"mcm","id":2,"clk":"ALOzAQDRdwChpAE=","pt":1743511937264,"mc":[{"id":"1.241629436","rc":[{"atb":[[5.1,302.05]],"batb":[[1,5.1,302.05]],"id":270592},{"atb":[[5.1,155.27]],"trd":[[5.1,3775.6]],"batb":[[0,5.1,155.27]],"tv":12821.32,"id":56297029}],"tv":76624.25}]}
{"op":"mcm","id":2,"clk":"AMCzAQDddwCtpAE=","pt":1743511937370,"mc":[{"id":"1.241629436","rc":[{"atl":[[11.5,30.66]],"trd":[[11.5,1165.21]],"batl":[[0,11.5,30.66]],"ltp":11.5,"tv":6321.4,"id":40389088},{"atb":[[5.2,303.41]],"trd":[[5.2,1985.82]],"batb":[[0,5.2,303.41]],"tv":17155.39,"id":270592},{"atl":[[65,7.23]],"trd":[[65,181.64]],"batl":[[0,65,7.23]],"ltp":65,"tv":1712.45,"id":59626646},{"atl":[[9.6,1]],"batl":[[2,10,40.87],[1,9.8,107.92],[0,9.6,1]],"id":27115873}],"tv":76652.12}]}
{"op":"mcm","id":2,"clk":"AMuzAQDndwCzpAE=","pt":1743511937472,"mc":[{"id":"1.241629436","rc":[{"atl":[[11.5,31.96]],"batl":[[0,11.5,31.96]],"id":40389088},{"atb":[[5,346.91]],"batb":[[2,5,346.91]],"id":270592},{"atb":[[9.6,1]],"atl":[[9.6,0]],"trd":[[9.6,249.02]],"batb":[[2,9.2,41.41],[1,9.4,72.41],[0,9.6,1]],"batl":[[2,10.5,66.05],[1,10,40.87],[0,9.8,107.92]],"tv":6751.14,"id":27115873},{"atb":[[17.5,19.06]],"batb":[[0,17.5,19.06]],"id":58186642}],"tv":76654.12}]}
{"op":"mcm","id":2,"clk":"ANazAQDxdwC+pAE=","pt":1743511937576,"mc":[{"id":"1.241629436","rc":[{"atb":[[9.4,66.47],[1.17,1.44],[9.6,0]],"atl":[[9.8,113.96]],"trd":[[9.6,251.02]],"batb":[[2,9,36.76],[1,9.2,41.41],[0,9.4,66.47]],"batl":[[0,9.8,113.96]],"tv":6753.14,"id":27115873}],"tv":76656.12}]}
{"op":"mcm","id":2,"clk":"AOazAQD5dwDKpAE=","pt":1743511937686,"mc":[{"id":"1.241629436","rc":[{"atb":[[10.5,30.55]],"batb":[[1,10.5,30.55]],"id":40389088},{"atb":[[9.4,72.42],[1.17,1]],"atl":[[9.8,107.92]],"batb":[[0,9.4,72.42]],"batl":[[0,9.8,107.92]],"id":27115873}]}]}
{"op":"mcm","id":2,"clk":"AO6zAQD+dwDYpAE=","pt":1743511937784,"mc":[{"id":"1.241629436","rc":[{"atb":[[9.6,0.44]],"batb":[[0,9.4,72.86]],"id":27115873}]}]}
{"op":"mcm","id":2,"clk":"AP6zAQCEeADgpAE=","pt":1743511937886,"mc":[{"id":"1.241629436","rc":[{"atl":[[7.2,23.43]],"id":56297029},{"atb":[[17.5,6.97]],"trd":[[17.5,194.69]],"batb":[[0,17.5,6.97]],"ltp":17.5,"tv":5497.57,"id":58186642}],"tv":76680.3}]}
{"op":"mcm","id":2,"clk":"AIO0AQCNeADopAE=","pt":1743511937987,"mc":[{"id":"1.241629436","rc":[{"atb":[[17.5,3.78]],"atl":[[28,1.99],[18,3.31]],"batb":[[0,17.5,3.78]],"batl":[[0,18,3.31]],"id":58186642}]}]}
{"op":"mcm","id":2,"clk":"AI+0AQCWeADtpAE=","pt":1743511938089,"mc":[{"id":"1.241629436","rc":[{"atl":[[18.5,15.89],[18,5.36]],"batl":[[1,18.5,15.89],[0,18,5.36]],"id":58186642}]}]}
{"op":"mcm","id":2,"clk":"AJa0AQCjeAD5pAE=","pt":1743511938197,"mc":[{"id":"1.241629436","rc":[{"atl":[[5.5,59.66]],"batl":[],"id":56297029},{"atb":[[17.5,1.63]],"atl":[[18,8.27]],"batb":[[0,17.5,1.63]],"batl":[[0,18,8.27]],"id":58186642}]}]}
{"op":"mcm","id":2,"clk":"AKO0AQCveACDpQE=","pt":1743511938300,"mc":[{"id":"1.241629436","rc":[{"atb":[[5.1,150.11]],"trd":[[5.1,3785.92]],"batb":[[0,5.1,150.11]],"tv":12831.64,"id":56297029},{"atl":[[18,14.15]],"batl":[[0,18,14.15]],"id":58186642}],"tv":76690.62}]}
{"op":"mcm","id":2,"clk":"ALO0AQCzeACMpQE=","pt":1743511938366,"mc":[{"id":"1.241629436","rc":[{"atb":[[17,20.57]],"batb":[[1,17,20.57]],"id":58186642}]}]}
{"op":"mcm","id":2,"clk":"AMC0AQDAeACWpQE=","pt":1743511938472,"mc":[{"id":"1.241629436","rc":[{"atb":[[4.8,114.64]],"batb":[],"id":270592},{"atb":[[17.5,0.94]],"trd":[[17.5,196.07]],"batb":[[2,16,40.2],[1,16.5,35.4],[0,17,21.51]],"tv":5498.95,"id":58186642}],"tv":76692}]}
{"op":"mcm","id":2,"clk":"AMW0AQDHeACbpQE=","pt":1743511938566,"mc":[{"id":"1.241629436","rc":[{"atb":[[17,23.83]],"batb":[[0,17,24.77]],"id":58186642}]}]}
{"op":"mcm","id":2,"clk":"AN60AQDZeACtpQE=","pt":1743511938779,"mc":[{"id":"1.241629436","rc":[{"atl":[[10.5,75.76]],"batl":[[2,10.5,75.76]],"id":35856222}]}]}
{"op":"mcm","id":2,"clk":"AOe0AQDjeAC5pQE=","pt":1743511938879,"mc":[{"id":"1.241629436","rc":[{"atb":[[4.8,115.58]],"batb":[],"id":270592}]}]}
{"op":"mcm","id":2,"clk":"APa0AQDreADBpQE=","pt":1743511938985,"mc":[{"id":"1.241629436","rc":[{"atb":[[60,10.91]],"atl":[[65,6.13]],"batb":[[0,60,10.91]],"batl":[[0,65,6.13]],"id":59626646},{"atb":[[9.4,71.3]],"batb":[[0,9.4,71.74]],"id":27115873},{"atl":[[18,18.76]],"batl":[[0,18,18.76]],"id":58186642},{"atb":[[6.4,210.28]],"batb":[[0,6.4,210.28]],"id":26496185},{"atb":[[11,104.52]],"batb":[[0,11,104.52]],"id":44049799}]}]}
{"op":"mcm","id":2,"clk":"APy0AQDzeADOpQE=","pt":1743511939083,"mc":[{"id":"1.241629436","rc":[{"atl":[[1000,1.16]],"id":27115873}]}]}
{"op":"mcm","id":2,"clk":"AIO1AQD4eADXpQE=","pt":1743511939186,"mc":[{"id":"1.241629436","rc":[{"atb":[[9.4,69.24],[9.6,0]],"trd":[[9.4,119.39],[9.6,251.9]],"batb":[[0,9.4,69.24]],"ltp":9.4,"tv":6758.14,"id":27115873}],"tv":76697}]}
{"op":"mcm","id":2,"clk":"AI+1AQD8eADlpQE=","pt":1743511939290,"mc":[{"id":"1.241629436","rc":[{"atl":[[1000,23.16]],"id":270592},{"atb":[[17,24.83]],"batb":[[0,17,25.77]],"id":58186642}]}]}
{"op":"mcm","id":2,"clk":"AJe1AQCNeQDspQE=","pt":1743511939389,"mc":[{"id":"1.241629436","rc":[{"atb":[[5.1,148.11]],"trd":[[5.1,3789.92]],"batb":[[0,5.1,148.11]],"tv":12835.64,"id":56297029}],"tv":76701}]}
{"op":"mcm","id":2,"clk":"AKa1AQCWeQD3pQE=","pt":1743511939496,"mc":[{"id":"1.241629436","rc":[{"atl":[[1000,25.16]],"id":270592}]}]}
{"op":"mcm","id":2,"clk":"ALG1AQCfeQD/pQE=","pt":1743511939561,"mc":[{"id":"1.241629436","rc":[{"atl":[[1000,23.16]],"id":270592}]}]}
{"op":"mcm","id":2,"clk":"ALq1AQCmeQCLpgE=","pt":1743511939669,"mc":[{"id":"1.241629436","rc":[{"atl":[[1000,21.16]],"id":270592},{"atl":[[65,16.39]],"batl":[[0,65,16.39]],"id":59626646},{"atb":[[9.2,46.38]],"batb":[[1,9.2,46.38]],"id":27115873},{"atb":[[17.5,0]],"atl":[[17.5,37.17]],"trd":[[17.5,197.95]],"batb":[[0,17,24.83]],"batl":[[2,18.5,15.89],[1,18,18.76],[0,17.5,37.17]],"tv":5500.83,"id":58186642}],"tv":76702.88}]}
{"op":"mcm","id":2,"clk":"AMO1AQCueQCUpgE=","pt":1743511939766,"mc":[{"id":"1.241629436","rc":[{"atb":[[9.2,41.41]],"batb":[[1,9.2,41.41]],"id":27115873},{"atb":[[1.02,5155.56],[17,22.53]],"atl":[[18,20.1],[17.5,39.77]],"batb":[[0,17,22.53]],"batl":[[1,18,20.1],[0,17.5,39.77]],"id":58186642}]}]}
{"op":"mcm","id":2,"clk":"ANG1AQC6eQCipgE=","pt":1743511939883,"mc":[{"id":"1.241629436","rc":[{"atb":[[17,16.42]],"batb":[[0,17,16.42]],"id":58186642}]}]}
{"op":"mcm","id":2,"clk":"ANi1AQDAeQCrpgE=","pt":1743511939979,"mc":[{"id":"1.241629436","rc":[{"atb":[[1.02,5154.06],[17,13.16]],"batb":[[0,17,13.16]],"id":58186642}]}]}
{"op":"mcm","id":2,"clk":"AN+1AQDNeQC0pgE=","pt":1743511940085,"mc":[{"id":"1.241629436","rc":[{"atb":[[9,14.49]],"batb":[],"id":40389088}]}]}
{"op":"mcm","id":2,"clk":"AOu1AQDdeQC9pgE=","pt":1743511940195,"mc":[{"id":"1.241629436","rc":[{"atl":[[9.8,25.15]],"trd":[[9.8,627.6]],"batl":[[0,9.8,25.15]],"tv":9449.26,"id":35856222},{"atb":[[5.1,145.15]],"trd":[[5.1,3795.83]],"batb":[[0,5.1,145.15]],"tv":12841.55,"id":56297029},{"atl":[[9.8,106.67]],"trd":[[9.8,280.3]],"batl":[[0,9.8,106.67]],"ltp":9.8,"tv":6760.64,"id":27115873},{"atb":[[1.02,5153.56]],"id":58186642}],"tv":76713.91}]}
{"op":"mcm","id":2,"clk":"APO1AQDpeQDGpgE=","pt":1743511940294,"mc":[{"id":"1.241629436","rc":[{"atb":[[16.5,35.9]],"batb":[[1,16.5,35.9]],"id":58186642}]}]}
{"op":"mcm","id":2,"clk":"AIO2AQD4eQDYpgE=","pt":1743511940409,"mc":[{"id":"1.241629436","rc":[{"atb":[[1.02,5155.56]],"id":58186642},{"atb":[[11,92.4]],"trd":[[11,1447.87]],"batb":[[0,11,92.4]],"ltp":11,"tv":4668.51,"id":44049799}],"tv":76738.15}]}
{"op":"mcm","id":2,"clk":"AI22AQCBegDipgE=","pt":1743511940463,"mc":[{"id":"1.241629436","rc":[{"atb":[[5.2,304.94]],"batb":[[0,5.2,304.94]],"id":270592},{"atb":[[1.02,5154.06]],"id":58186642}]}]}
{"op":"mcm","id":2,"clk":"AJy2AQCOegDwpgE=","pt":1743511940572,"mc":[{"id":"1.241629436","rc":[{"atb":[[10.5,31.55]],"batb":[[1,10.5,31.55]],"id":40389088},{"atb":[[1.02,5153.56]],"atl":[[17.5,41.77]],"batl":[[0,17.5,41.77]],"id":58186642},{"atb":[[11,102.06]],"batb":[[0,11,102.06]],"id":44049799}]}]}
{"op":"mcm","id":2,"clk":"AKa2AQCWegD7pgE=","pt":1743511940672,"mc":[{"id":"1.241629436","rc":[{"atb":[[9.6,46.24]],"trd":[[9.6,469.08]],"batb":[[0,9.6,46.24]],"ltp":9.6,"tv":9451.26,"id":35856222},{"atb":[[17,13.66]],"batb":[[0,17,13.66]],"id":58186642}],"tv":76740.15}]}
{"op":"mcm","id":2,"clk":"ALm2AQChegCFpwE=","pt":1743511940783,"mc":[{"id":"1.241629436","rc":[{"atb":[[60,9.24]],"trd":[[60,314.41]],"batb":[[0,60,9.24]],"ltp":60,"tv":1715.79,"id":59626646},{"atb":[[17,10.31]],"trd":[[17,919.03]],"batb":[[0,17,10.31]],"ltp":17,"tv":5507.52,"id":58186642}],"tv":76750.18}]}
{"op":"mcm","id":2,"clk":"AMS2AQCvegCOpwE=","pt":1743511940882,"mc":[{"id":"1.241629436","rc":[{"atb":[[11,67.73]],"batb":[[0,11,67.73]],"id":40389088},{"atb":[[5.1,121.94]],"trd":[[5.1,3842.25]],"batb":[[0,5.1,121.94]],"tv":12887.97,"id":56297029},{"atl":[[18,23.43]],"batl":[[1,18,23.43]],"id":58186642}],"tv":76796.6}]}
{"op":"mcm","id":2,"clk":"ANO2AQC4egCbpwE=","pt":1743511940990,"mc":[{"id":"1.241629436","rc":[{"atl":[[9.8,21.68]],"batl":[[0,9.8,21.68]],"id":35856222},{"atb":[[60,10.96]],"batb":[[0,60,10.96]],"id":59626646},{"atb":[[17,11.31]],"batb":[[0,17,11.31]],"id":58186642},{"atb":[[11,118.42]],"batb":[[0,11,118.42]],"id":44049799}]}]}
{"op":"mcm","id":2,"clk":"AOG2AQC9egCipwE=","pt":1743511941097,"mc":[{"id":"1.241629436","rc":[{"atl":[[9.8,10.91]],"trd":[[9.8,649.14]],"batl":[[0,9.8,10.91]],"ltp":9.8,"tv":9472.8,"id":35856222},{"atb":[[5.1,98.29]],"trd":[[5.1,3889.55]],"batb":[[0,5.1,98.29]],"tv":12935.27,"id":56297029},{"atl":[[9.8,96.31]],"trd":[[9.8,301.02]],"batl":[[0,9.8,96.31]],"tv":6781.36,"id":27115873}],"tv":76886.16}]}
{"op":"mcm","id":2,"clk":"APi2AQDPegC8pwE=","pt":1743511941303,"mc":[{"id":"1.241629436","rc":[{"atl":[[9.8,7.44]],"batl":[[0,9.8,7.44]],"id":35856222},{"atb":[[9.6,10.44]],"batb":[[2,9.2,41.41],[1,9.4,69.24],[0,9.6,10.44]],"id":27115873}]}]}
{"op":"mcm","id":2,"clk":"AJC3AQDpegDKpwE=","pt":1743511941506,"mc":[{"id":"1.241629436","rc":[{"atb":[[5.1,169.89]],"batb":[[0,5.1,169.89]],"id":56297029}]}]}
{"op":"mcm","id":2,"clk":"AKS3AQD9egDZpwE=","pt":1743511941669,"mc":[{"id":"1.241629436","rc":[{"atb":[[16,32.32]],"batb":[[2,16,32.32]],"id":58186642}]}]}
{"op":"mcm","id":2,"clk":"ALa3AQCRewDopwE=","pt":1743511941869,"mc":[{"id":"1.241629436","rc":[{"atl":[[10.5,68.05]],"batl":[[2,10.5,68.05]],"id":27115873},{"atb":[[1.02,5155.56],[17,10.31]],"batb":[[0,17,10.31]],"id":58186642}]}]}
{"op":"mcm","id":2,"clk":"AMG3AQCYewDxpwE=","pt":1743511941976,"mc":[{"id":"1.241629436","rc":[{"atb":[[9.6,52.04]],"batb":[[0,9.6,52.04]],"id":35856222},{"atb":[[5.1,139.89]],"trd":[[5.1,3949.55]],"batb":[[0,5.1,139.89]],"tv":12995.27,"id":56297029},{"atb":[[6.4,209.87]],"trd":[[6.4,3500.24]],"batb":[[0,6.4,209.87]],"ltp":6.4,"tv":12328.94,"id":26496185}],"tv":76946.98}]}
{"op":"mcm","id":2,"clk":"AMK3AQCgewD9pwE=","pt":1743511942072,"mc":[{"id":"1.241629436","rc":[{"atb":[[5.1,139.79]],"trd":[[5.1,3949.75]],"batb":[[0,5.1,139.79]],"tv":12995.47,"id":56297029},{"atb":[[1.02,5154.06]],"id":58186642}],"tv":76947.18}]}
{"op":"mcm","id":2,"clk":"ANe3AQCoewCLqAE=","pt":1743511942187,"mc":[{"id":"1.241629436","rc":[{"atb":[[1.17,2.33]],"id":40389088},{"atb":[[1.17,2.32]],"atl":[[5.3,88.68]],"batl":[[1,5.3,88.68]],"id":56297029},{"atb":[[6.4,204.87]],"trd":[[6.4,3510.24]],"batb":[[0,6.4,204.87]],"tv":12338.94,"id":26496185}],"tv":76957.18}]}
{"op":"mcm","id":2,"clk":"AOO3AQCwewCWqAE=","pt":1743511942292,"mc":[{"id":"1.241629436","rc":[{"atb":[[1.17,2]],"id":40389088},{"atb":[[1.17,2]],"id":56297029},{"atb":[[1.02,5153.56]],"id":58186642}]}]}
{"op":"mcm","id":2,"clk":"AOu3AQC8ewCcqAE=","pt":1743511942395,"mc":[{"id":"1.241629436","rc":[{"atb":[[11,68.06]],"batb":[[0,11,68.06]],"id":40389088},{"atb":[[5.1,140.11]],"batb":[[0,5.1,140.11]],"id":56297029},{"atb":[[16.5,36.4]],"batb":[[1,16.5,36.4]],"id":58186642}]}]}
{"op":"mcm","id":2,"clk":"APO3AQDJewCsqAE=","pt":1743511942494,"mc":[{"id":"1.241629436","rc":[{"atl":[[9.8,16.36]],"batl":[[0,9.8,16.36]],"id":35856222}]}]}
{"op":"mcm","id":2,"clk":"AIe4AQDXewC9qAE=","pt":1743511942693,"mc":[{"id":"1.241629436","rc":[{"atb":[[9.6,46.24]],"batb":[[0,9.6,46.24]],"id":35856222}]}]}
{"op":"mcm","id":2,"clk":"ALC4AQD4ewDfqAE=","pt":1743511943069,"mc":[{"id":"1.241629436","rc":[{"atb":[[9.4,67.81]],"batb":[[1,9.4,67.81]],"id":27115873}]}]}
{"op":"mcm","id":2,"clk":"AL24AQCBfADpqAE=","pt":1743511943173,"mc":[{"id":"1.241629436","rc":[{"atb":[[9.6,11.82]],"batb":[[0,9.6,11.82]],"id":27115873}]}]}
{"op":"mcm","id":2,"clk":"AJC5AQDJfAC4qQE=","pt":1743511944000,"mc":[{"id":"1.241629436","rc":[{"atl":[[7.2,23.4]],"id":56297029}]}]}
{"op":"mcm","id":2,"clk":"AJi5AQDQfADBqQE=","pt":1743511944098,"mc":[{"id":"1.241629436","rc":[{"atl":[[10.5,1]],"id":56297029}]}]}
{"op":"mcm","id":2,"clk":"AKu5AQDpfADcqQE=","pt":1743511944266,"mc":[{"id":"1.241629436","rc":[{"atl":[[5.2,251.12]],"batl":[[0,5.2,251.12]],"id":56297029}]}]}
{"op":"mcm","id":2,"clk":"AMm5AQD/fAD6qQE=","pt":1743511944573,"mc":[{"id":"1.241629436","rc":[{"atl":[[11.5,31.5]],"batl":[[0,11.5,31.5]],"id":40389088},{"atb":[[5.2,303.94]],"atl":[[5.4,133.12]],"batb":[[0,5.2,303.94]],"batl":[[1,5.4,133.12]],"id":270592},{"atl":[[9.8,16.01]],"batl":[[0,9.8,16.01]],"id":35856222},{"atb":[[1.17,2.55],[17,9.38]],"atl":[[18,18.48],[17.5,44.43]],"batb":[[0,17,9.38]],"batl":[[1,18,18.48],[0,17.5,44.43]],"id":58186642},{"atb":[[6.4,202.32]],"batb":[[0,6.4,202.32]],"id":26496185}]}]}
{"op":"mcm","id":2,"clk":"ANy5AQCOfQCFqgE=","pt":1743511944685,"mc":[{"id":"1.241629436","rc":[{"atb":[[1.17,2]],"id":58186642}]}]}
{"op":"mcm","id":2,"clk":"AOG5AQCSfQCSqgE=","pt":1743511944774,"mc":[{"id":"1.241629436","rc":[{"atl":[[1000,25.16]],"id":270592},{"atb":[[17,6.15],[16.5,36.95]],"atl":[[17.5,47.3]],"batb":[[1,16.5,36.95],[0,17,6.15]],"batl":[[0,17.5,47.3]],"id":58186642}]}]}
{"op":"mcm","id":2,"clk":"APe5AQCtfQC2qgE=","pt":1743511944992,"mc":[{"id":"1.241629436","rc":[{"atl":[[1000,21.16]],"id":270592}]}]}
{"op":"mcm","id":2,"clk":"AP+5AQC6fQC5qgE=","pt":1743511945088,"mc":[{"id":"1.241629436","rc":[{"atb":[[1.02,5155.56]],"id":58186642}]}]}
{"op":"mcm","id":2,"clk":"AJa6AQDVfQDNqgE=","pt":1743511945293,"mc":[{"id":"1.241629436","rc":[{"atb":[[9.6,10.82]],"trd":[[9.6,253.9]],"batb":[[0,9.6,10.82]],"ltp":9.6,"tv":6783.36,"id":27115873},{"atb":[[1.02,5154.06]],"id":58186642}],"tv":76959.18}]}
{"op":"mcm","id":2,"clk":"AK+6AQDtfQDhqgE=","pt":1743511945502,"mc":[{"id":"1.241629436","rc":[{"atl":[[1000,23.16]],"id":270592},{"atb":[[1.02,5153.56]],"id":58186642}]}]}
{"op":"mcm","id":2,"clk":"ALq6AQD1fQDqqgE=","pt":1743511945561,"mc":[{"id":"1.241629436","rc":[{"atb":[[15.5,45.61]],"batb":[],"id":58186642},{"atb":[[4,73.47]],"id":26496185}]}]}
{"op":"mcm","id":2,"clk":"AN+6AQCPfgCEqwE=","pt":1743511945670,"mc":[{"id":"1.241629436","rc":[{"atl":[[1000,21.16]],"id":270592}]}]}
{"op":"mcm","id":2,"clk":"AOu6AQCdfgCOqwE=","pt":1743511945768,"mc":[{"id":"1.241629436","rc":[{"atl":[[9.8,17.01]],"batl":[[0,9.8,17.01]],"id":35856222},{"atb":[[9.6,8.82]],"trd":[[9.6,257.9]],"batb":[[0,9.6,8.82]],"tv":6787.36,"id":27115873}],"tv":76963.18}]}
{"op":"mcm","id":2,"clk":"AJO7AQC/fgCwqwE=","pt":1743511946086,"mc":[{"id":"1.241629436","rc":[{"atb":[[1.02,5155.56]],"id":58186642}]}]}
{"op":"mcm","id":2,"clk":"AJm7AQDOfgDDqwE=","pt":1743511946183,"mc":[{"id":"1.241629436","rc":[{"atb":[[1.02,5154.06]],"id":58186642}]}]}
{"op":"mcm","id":2,"clk":"ALa7AQDgfgDWqwE=","pt":1743511946412,"mc":[{"id":"1.241629436","rc":[{"atb":[[1.02,5153.56]],"id":58186642}]}]}
{"op":"mcm","id":2,"clk":"AL27AQDnfgDhqwE=","pt":1743511946490,"mc":[{"id":"1.241629436","rc":[{"atb":[[15,12.63]],"batb":[],"id":58186642}]}]}
{"op":"mcm","id":2,"clk":"ANq7AQD8fgCCrAE=","pt":1743511946801,"mc":[{"id":"1.241629436","rc":[{"atb":[[1.02,5155.56]],"id":58186642}]}]}
{"op":"mcm","id":2,"clk":"AO+7AQCBfwCMrAE=","pt":1743511946909,"mc":[{"id":"1.241629436","rc":[{"atb":[[1.02,5154.06]],"id":58186642}]}]}
{"op":"mcm","id":2,"clk":"APu7AQCIfwCYrAE=","pt":1743511947009,"mc":[{"id":"1.241629436","rc":[{"atl":[[5.3,266.92]],"trd":[[5.3,1540.98]],"batl":[[0,5.3,266.92]],"ltp":5.3,"tv":17163.39,"id":270592},{"atb":[[1.02,5153.56]],"id":58186642}],"tv":76971.18}]}
{"op":"mcm","id":2,"clk":"AIe8AQCPfwCgrAE=","pt":1743511947070,"mc":[{"id":"1.241629436","rc":[{"atb":[[14.5,33.44]],"batb":[],"id":58186642}]}]}
{"op":"mcm","id":2,"clk":"AMu8AQC2fwDPrAE=","pt":1743511947488,"mc":[{"id":"1.241629436","rc":[{"atl":[[6.6,56.59]],"batl":[[0,6.6,56.59]],"id":26496185}]}]}
{"op":"mcm","id":2,"clk":"ANW8AQC+fwDVrAE=","pt":1743511947593,"mc":[{"id":"1.241629436","rc":[{"atb":[[1.17,7.34]],"id":35856222},{"atb":[[1.17,2.47]],"atl":[[1000,4.62]],"id":56297029},{"atb":[[9.6,10.47]],"batb":[[0,9.6,10.47]],"id":27115873},{"atb":[[11,120.45]],"batb":[[0,11,120.45]],"id":44049799}]}]}
{"op":"mcm","id":2,"clk":"APG8AQDWfwDrrAE=","pt":1743511947693,"mc":[{"id":"1.241629436","rc":[{"atb":[[5.1,140.01]],"trd":[[5.1,3949.95]],"batb":[[0,5.1,140.01]],"tv":12995.67,"id":56297029}],"tv":76971.38}]}
{"op":"mcm","id":2,"clk":"AIK9AQDkfwD5rAE=","pt":1743511947808,"mc":[{"id":"1.241629436","rc":[{"atb":[[1.17,7.15]],"id":35856222},{"atb":[[1.17,2]],"atl":[[1000,4.52]],"id":56297029}]}]}
{"op":"mcm","id":2,"clk":"AIm9AQDqfwD7rAE=","pt":1743511947898,"mc":[{"id":"1.241629436","rc":[{"atb":[[9.6,46.43]],"batb":[[0,9.6,46.43]],"id":35856222},{"atb":[[5.1,140.48]],"atl":[[5.3,88.78]],"batb":[[0,5.1,140.48]],"batl":[[1,5.3,88.78]],"id":56297029}]}]}
{"op":"mcm","id":2,"clk":"AJW9AQD3fwCIrQE=","pt":1743511948006,"mc":[{"id":"1.241629436","rc":[{"atb":[[11,119.45]],"trd":[[11,1449.87]],"batb":[[0,11,119.45]],"tv":4670.51,"id":44049799}],"tv":76973.38}]}
{"op":"mcm","id":2,"clk":"AM+9AQCegAEAvq0B","pt":1743511948482,"mc":[{"id":"1.241629436","rc":[{"atb":[[9.6,46.02]],"trd":[[9.6,469.9]],"batb":[[0,9.6,46.02]],"ltp":9.6,"tv":9473.62,"id":35856222}],"tv":76974.2}]}
{"op":"mcm","id":2,"clk":"AN69AQCkgAEAxq0B","pt":1743511948585,"mc":[{"id":"1.241629436","rc":[{"atb":[[4,52.01]],"id":59626646}]}]}
{"op":"mcm","id":2,"clk":"ALa+AQDagAEA/a0B","pt":1743511949304,"mc":[{"id":"1.241629436","rc":[{"atb":[[6.4,201.32]],"trd":[[6.4,3512.24]],"batb":[[0,6.4,201.32]],"tv":12340.94,"id":26496185}],"tv":76976.2}]}
{"op":"mcm","id":2,"clk":"AMS+AQDegAEAiq4B","pt":1743511949405,"mc":[{"id":"1.241629436","rc":[{"atb":[[7,15.9]],"id":40389088}]}]}
{"op":"mcm","id":2,"clk":"AOC+AQDwgAEAnK4B","pt":1743511949570,"mc":[{"id":"1.241629436","rc":[{"atb":[[5.2,300.59]],"trd":[[5.2,1992.52]],"batb":[[0,5.2,300.59]],"ltp":5.2,"tv":17170.09,"id":270592}],"tv":76982.9}]}
{"op":"mcm","id":2,"clk":"AIy/AQCagQEAvK4B","pt":1743511949982,"mc":[{"id":"1.241629436","rc":[{"atb":[[17,4.15]],"trd":[[17,923.03]],"batb":[[0,17,4.15]],"tv":5511.52,"id":58186642}],"tv":76986.9}]}
{"op":"mcm","id":2,"clk":"AKK/AQClgQEAw64B","pt":1743511950089,"mc":[{"id":"1.241629436","rc":[{"atb":[[16.5,29.16]],"batb":[[1,16.5,29.16]],"id":58186642}]}]}
{"op":"mcm","id":2,"clk":"AK2/AQCqgQEA0q4B","pt":1743511950192,"mc":[{"id":"1.241629436","rc":[{"atl":[[1000,23.16]],"id":270592},{"atb":[[6.4,231.32]],"batb":[[0,6.4,231.32]],"id":26496185}]}]}
{"op":"mcm","id":2,"clk":"AMW/AQDIgQEA6a4B","pt":1743511950498,"mc":[{"id":"1.241629436","rc":[{"atl":[[1000,21.16]],"id":270592}]}]}
{"op":"mcm","id":2,"clk":"AM6/AQDOgQEA8a4B","pt":1743511950603,"mc":[{"id":"1.241629436","rc":[{"atb":[[9.6,8.82]],"batb":[[0,9.6,8.82]],"id":27115873}]}]}
{"op":"mcm","id":2,"clk":"AO+/AQDvgQEAj68B","pt":1743511950864,"mc":[{"id":"1.241629436","rc":[{"atl":[[1000,23.16]],"id":270592}]}]}
{"op":"mcm","id":2,"clk":"AP+/AQD3gQEAl68B","pt":1743511950977,"mc":[{"id":"1.241629436","rc":[{"atl":[[22,2.11]],"id":44049799}]}]}
{"op":"mcm","id":2,"clk":"AI7AAQCBggEAm68B","pt":1743511951076,"mc":[{"id":"1.241629436","rc":[{"atl":[[1000,21.16]],"id":270592}]}]}
{"op":"mcm","id":2,"clk":"ALzAAQCaggEAva8B","pt":1743511951394,"mc":[{"id":"1.241629436","rc":[{"atl":[[9.8,91.31]],"trd":[[9.8,311.02]],"batl":[[0,9.8,91.31]],"ltp":9.8,"tv":6797.36,"id":27115873},{"atb":[[17,1.15]],"trd":[[17,929.03]],"batb":[[0,17,1.15]],"tv":5517.52,"id":58186642}],"tv":77002.9}]}
{"op":"mcm","id":2,"clk":"ANXAAQCvggEA0K8B","pt":1743511951598,"mc":[{"id":"1.241629436","rc":[{"atb":[[17,0]],"trd":[[17,931.33]],"batb":[[2,15.5,45.61],[1,16,32.32],[0,16.5,29.16]],"tv":5519.82,"id":58186642},{"atb":[[6.4,231.22]],"trd":[[6.4,3512.44]],"batb":[[0,6.4,231.22]],"tv":12341.14,"id":26496185}],"tv":77005.4}]}
{"op":"mcm","id":2,"clk":"AN7AAQC5ggEA2q8B","pt":1743511951697,"mc":[{"id":"1.241629436","rc":[{"atb":[[1.01,86013.31]],"id":27115873},{"atl":[[17,6.24]],"batl":[[2,18,18.48],[1,17.5,47.3],[0,17,6.24]],"id":58186642}]}]}
{"op":"mcm","id":2,"clk":"APHAAQDFggEA468B","pt":1743511951815,"mc":[{"id":"1.241629436","rc":[{"atl":[[17,5.24]],"trd":[[17,933.33]],"batl":[[0,17,5.24]],"tv":5521.82,"id":58186642}],"tv":77007.4}]}
{"op":"mcm","id":2,"clk":"AJ/BAQDxggEAhLAB","pt":1743511952181,"mc":[{"id":"1.241629436","rc":[{"atb":[[4.7,145.5],[4.2,12.05],[3.9,5],[4.4,104.9],[4.1,12.79],[3.95,9.85],[4.6,114.07],[3.85,81.44],[4.3,15.8],[4.5,66.45],[4.8,113.7],[4,70.67]],"batb":[],"id":270592}]}]}
{"op":"mcm","id":2,"clk":"ANDBAQCXgwEAo7AB","pt":1743511952588,"mc":[{"id":"1.241629436","rc":[{"atl":[[1000,2.25]],"id":40389088}]}]}
{"op":"mcm","id":2,"clk":"AOnBAQCngwEAtLAB","pt":1743511952793,"mc":[{"id":"1.241629436","rc":[{"atl":[[1000,1.04]],"id":40389088}]}]}
{"op":"mcm","id":2,"clk":"AO/BAQCwgwEAvLAB","pt":1743511952894,"mc":[{"id":"1.241629436","rc":[{"atl":[[1000,0.25]],"id":40389088},{"atl":[[5.2,241.12]],"batl":[[0,5.2,241.12]],"id":56297029}]}]}
{"op":"mcm","id":2,"clk":"AP3BAQC9gwEAxLAB","pt":1743511953011,"mc":[{"id":"1.241629436","rc":[{"atb":[[11,67.27]],"atl":[[11.5,21.78]],"trd":[[11.5,1184.65],[11,163.71]],"batb":[[0,11,67.27]],"batl":[[0,11.5,21.78]],"tv":6342.42,"id":40389088},{"atb":[[9.2,65.27]],"batb":[[2,9.2,65.27]],"id":35856222},{"atl":[[7.2,60.57]],"batl":[],"id":26496185}],"tv":77028.42}]}
{"op":"mcm","id":2,"clk":"AIjCAQC/gwEAybAB","pt":1743511953109,"mc":[{"id":"1.241629436","rc":[{"atl":[[11.5,18.81]],"batl":[[0,11.5,18.81]],"id":40389088}]}]}
{"op":"mcm","id":2,"clk":"AJHCAQDJgwEA1LAB","pt":1743511953215,"mc":[{"id":"1.241629436","rc":[{"atl":[[11.5,3.35]],"batl":[[0,11.5,3.35]],"id":40389088},{"atb":[[6.4,230.22]],"trd":[[6.4,3514.44]],"batb":[[0,6.4,230.22]],"tv":12343.14,"id":26496185}],"tv":77030.42}]}
{"op":"mcm","id":2,"clk":"AKXCAQDTgwEA5bAB","pt":1743511953371,"mc":[{"id":"1.241629436","rc":[{"atb":[[6.4,236.62]],"batb":[[0,6.4,236.62]],"id":26496185}]}]}
{"op":"mcm","id":2,"clk":"AL3CAQDlgwEA77AB","pt":1743511953579,"mc":[{"id":"1.241629436","rc":[{"atb":[[5.2,290.59]],"trd":[[5.2,2012.52]],"batb":[[0,5.2,290.59]],"tv":17190.09,"id":270592},{"atb":[[11,118.45]],"trd":[[11,1451.87]],"batb":[[0,11,118.45]],"tv":4672.51,"id":44049799}],"tv":77052.42}]}
{"op":"mcm","id":2,"clk":"AMjCAQDzgwEA9rAB","pt":1743511953693,"mc":[{"id":"1.241629436","rc":[{"atl":[[1000,3.41]],"id":58186642}]}]}
{"op":"mcm","id":2,"clk":"ANLCAQCAhAEA/bAB","pt":1743511953789,"mc":[{"id":"1.241629436","rc":[{"atl":[[1000,1.9]],"id":58186642}]}]}
{"op":"mcm","id":2,"clk":"AN7CAQCMhAEAhLEB","pt":1743511953896,"mc":[{"id":"1.241629436","rc":[{"atl":[[1000,1.41]],"id":58186642}]}]}
{"op":"mcm","id":2,"clk":"AOXCAQCZhAEAjLEB","pt":1743511953996,"mc":[{"id":"1.241629436","rc":[{"atl":[[17.5,47.79]],"batl":[[1,17.5,47.79]],"id":58186642}]}]}
{"op":"mcm","id":2,"clk":"APPCAQCuhAEAoLEB","pt":1743511954197,"mc":[{"id":"1.241629436","rc":[{"atb":[[11,63.82]],"trd":[[11,170.61]],"batb":[[0,11,63.82]],"ltp":11,"tv":6349.32,"id":40389088},{"atb":[[9.6,5.37]],"trd":[[9.6,264.8]],"batb":[[0,9.6,5.37]],"ltp":9.6,"tv":6804.26,"id":27115873},{"atb":[[6.4,233.17]],"trd":[[6.4,3521.34]],"batb":[[0,6.4,233.17]],"tv":12350.04,"id":26496185}],"tv":77073.12}]}
{"op":"mcm","id":2,"clk":"APzCAQC6hAEAp7EB","pt":1743511954299,"mc":[{"id":"1.241629436","rc":[{"atb":[[5.1,138.48]],"trd":[[5.1,3953.95]],"batb":[[0,5.1,138.48]],"tv":12999.67,"id":56297029}],"tv":77077.12}]}
{"op":"mcm","id":2,"clk":"AJXDAQDThAEAxLEB","pt":1743511954605,"mc":[{"id":"1.241629436","rc":[{"atb":[[6.4,234.72]],"batb":[[0,6.4,234.72]],"id":26496185}]}]}
{"op":"mcm","id":2,"clk":"AJ3DAQDZhAEAyrEB","pt":1743511954663,"mc":[{"id":"1.241629436","rc":[{"atl":[[1000,0.38]],"id":40389088},{"atb":[[5.1,142.19]],"atl":[[1000,5.34]],"batb":[[0,5.1,142.19]],"id":56297029}]}]}
{"op":"mcm","id":2,"clk":"AKPDAQDmhAEA1bEB","pt":1743511954818,"mc":[{"id":"1.241629436","rc":[{"atl":[[1000,0.25]],"id":40389088},{"atl":[[1000,4.52]],"id":56297029},{"atb":[[6.4,214.73]],"trd":[[6.4,3561.34]],"batb":[[0,6.4,214.73]],"tv":12390.04,"id":26496185}],"tv":77117.12}]}
{"op":"mcm","id":2,"clk":"AK/DAQDphAEA4rEB","pt":1743511954878,"mc":[{"id":"1.241629436","rc":[{"atl":[[12,59.85]],"batl":[[1,12,59.85]],"id":40389088},{"atl":[[5.3,89.6]],"batl":[[1,5.3,89.6]],"id":56297029}]}]}
{"op":"mcm","id":2,"clk":"ALvDAQDwhAEA6bEB","pt":1743511954975,"mc":[{"id":"1.241629436","rc":[{"atb":[[15,13.63]],"batb":[],"id":58186642}]}]}
{"op":"mcm","id":2,"clk":"ANLDAQCHhQEA/LEB","pt":1743511955178,"mc":[{"id":"1.241629436","rc":[{"atb":[[3,7]],"id":26496185}]}]}
{"op":"mcm","id":2,"clk":"AObDAQCUhQEAhbIB","pt":1743511955290,"mc":[{"id":"1.241629436","rc":[{"atb":[[5.2,270.59]],"trd":[[5.2,2052.52]],"batb":[[0,5.2,270.59]],"tv":17230.09,"id":270592},{"atl":[[10.5,66.05]],"batl":[[2,10.5,66.05]],"id":27115873},{"atl":[[6.6,58.53]],"batl":[[0,6.6,58.53]],"id":26496185}],"tv":77157.12}]}
{"op":"mcm","id":2,"clk":"APTDAQCZhQEAi7IB","pt":1743511955399,"mc":[{"id":"1.241629436","rc":[{"atl":[[9.8,15.72]],"trd":[[9.8,651.73]],"batl":[[0,9.8,15.72]],"ltp":9.8,"tv":9476.21,"id":35856222},{"atb":[[5.1,139.23]],"trd":[[5.1,3959.87]],"batb":[[0,5.1,139.23]],"tv":13005.59,"id":56297029},{"atl":[[9.8,90.05]],"trd":[[9.8,313.54]],"batl":[[0,9.8,90.05]],"ltp":9.8,"tv":6806.78,"id":27115873},{"atl":[[6.6,60.47]],"batl":[[0,6.6,60.47]],"id":26496185}],"tv":77168.15}]}
{"op":"mcm","id":2,"clk":"AIPEAQCkhQEAmrIB","pt":1743511955506,"mc":[{"id":"1.241629436","rc":[{"atb":[[5.2,267.59]],"trd":[[5.2,2058.52]],"batb":[[0,5.2,267.59]],"tv":17236.09,"id":270592},{"atl":[[6.6,62.41]],"batl":[[0,6.6,62.41]],"id":26496185}],"tv":77174.15}]}
{"op":"mcm","id":2,"clk":"AIfEAQCuhQEAoLIB","pt":1743511955599,"mc":[{"id":"1.241629436","rc":[{"atb":[[5.1,138.23]],"trd":[[5.1,3961.87]],"batb":[[0,5.1,138.23]],"tv":13007.59,"id":56297029},{"atb":[[6.4,213.73]],"trd":[[6.4,3563.34]],"batb":[[0,6.4,213.73]],"tv":12392.04,"id":26496185},{"atb":[[11,117.45]],"trd":[[11,1453.87]],"batb":[[0,11,117.45]],"tv":4674.51,"id":44049799}],"tv":77180.15}]}
{"op":"mcm","id":2,"clk":"AJnEAQC5hQEAprIB","pt":1743511955711,"mc":[{"id":"1.241629436","rc":[{"atl":[[1000,23.16]],"id":270592}]}]}
{"op":"mcm","id":2,"clk":"AKXEAQDIhQEAsrIB","pt":1743511955821,"mc":[{"id":"1.241629436","rc":[{"atl":[[6.6,92.41]],"batl":[[0,6.6,92.41]],"id":26496185}]}]}
{"op":"mcm","id":2,"clk":"AK7EAQDJhQEAtbIB","pt":1743511955911,"mc":[{"id":"1.241629436","rc":[{"atl":[[1000,21.16]],"id":270592},{"atl":[[9.8,81.36]],"trd":[[9.8,330.92]],"batl":[[0,9.8,81.36]],"tv":6824.16,"id":27115873}],"tv":77197.53}]}
{"op":"mcm","id":2,"clk":"ALnEAQDVhQEAvbIB","pt":1743511956019,"mc":[{"id":"1.241629436","rc":[{"atb":[[9.6,4.96]],"trd":[[9.6,265.62]],"batb":[[0,9.6,4.96]],"ltp":9.6,"tv":6824.98,"id":27115873}],"tv":77198.35}]}
{"op":"mcm","id":2,"clk":"ANnEAQDuhQEA1bIB","pt":1743511956290,"mc":[{"id":"1.241629436","rc":[{"atl":[[1000,23.16]],"id":270592}]}]}
{"op":"mcm","id":2,"clk":"AO7EAQCGhgEA6LIB","pt":1743511956490,"mc":[{"id":"1.241629436","rc":[{"atl":[[1000,21.16]],"id":270592},{"atb":[[5.1,131.2]],"trd":[[5.1,3975.93]],"batb":[[0,5.1,131.2]],"tv":13021.65,"id":56297029},{"atb":[[9,41.76]],"batb":[],"id":27115873},{"atb":[[11,116.45]],"trd":[[11,1455.87]],"batb":[[0,11,116.45]],"tv":4676.51,"id":44049799}],"tv":77214.41}]}
{"op":"mcm","id":2,"clk":"APzEAQCShgEA87IB","pt":1743511956599,"mc":[{"id":"1.241629436","rc":[{"atl":[[90,3.32],[65,17.51]],"batl":[[0,65,17.51]],"id":59626646},{"atb":[[5.1,133.14]],"batb":[[0,5.1,133.14]],"id":56297029},{"atl":[[9.8,81.19]],"batl":[[0,9.8,81.19]],"id":27115873},{"atb":[[16,33.43],[16.5,29.4]],"atl":[[17.5,45.13],[17,7.07]],"batb":[[1,16,33.43],[0,16.5,29.4]],"batl":[[1,17.5,45.13],[0,17,7.07]],"id":58186642}]}]}
{"op":"mcm","id":2,"clk":"AIjFAQCghgEA+7IB","pt":1743511956702,"mc":[{"id":"1.241629436","rc":[{"atb":[[9.4,72.69],[9.2,66.63]],"batb":[[2,9.2,66.63],[1,9.4,72.69]],"id":35856222},{"atb":[[5.1,129.86]],"trd":[[5.1,3982.49]],"batb":[[0,5.1,129.86]],"tv":13028.21,"id":56297029},{"atb":[[16.5,27.4]],"trd":[[16.5,514.16]],"batb":[[0,16.5,27.4]],"ltp":16.5,"tv":5525.82,"id":58186642}],"tv":77224.97}]}
{"op":"mcm","id":2,"clk":"AJbFAQCmhgEAgLMB","pt":1743511956800,"mc":[{"id":"1.241629436","rc":[{"atb":[[16.5,25.07]],"batb":[[0,16.5,25.07]],"id":58186642}]}]}
{"op":"mcm","id":2,"clk":"AJ/FAQCyhgEAhbMB","pt":1743511956897,"mc":[{"id":"1.241629436","rc":[{"atl":[[17,8.07]],"batl":[[0,17,8.07]],"id":58186642}]}]}
{"op":"mcm","id":2,"clk":"ALvFAQDIhgEAlbMB","pt":1743511957020,"mc":[{"id":"1.241629436","rc":[{"atb":[[6.6,5.55]],"id":35856222},{"atb":[[16.5,22.73]],"batb":[[0,16.5,22.73]],"id":58186642},{"atb":[[6.4,215.73]],"atl":[[6.6,104.01]],"batb":[[0,6.4,215.73]],"batl":[[0,6.6,104.01]],"id":26496185}]}]}
{"op":"mcm","id":2,"clk":"AMfFAQDVhgEAo7MB","pt":1743511957115,"mc":[{"id":"1.241629436","rc":[{"atb":[[9.6,47.26]],"atl":[[9.8,14.54]],"trd":[[9.8,654.1]],"batb":[[0,9.6,47.26]],"batl":[[0,9.8,14.54]],"tv":9478.58,"id":35856222}],"tv":77227.34}]}
{"op":"mcm","id":2,"clk":"ANXFAQDjhgEAqLMB","pt":1743511957177,"mc":[{"id":"1.241629436","rc":[{"atb":[[9.6,53.07]],"batb":[[0,9.6,53.07]],"id":35856222}]}]}
{"op":"mcm","id":2,"clk":"AN7FAQDthgEAubMB","pt":1743511957291,"mc":[{"id":"1.241629436","rc":[{"atb":[[5.1,126.58]],"trd":[[5.1,3989.05]],"batb":[[0,5.1,126.58]],"tv":13034.77,"id":56297029}],"tv":77233.9}]}
{"op":"mcm","id":2,"clk":"APfFAQCBhwEAyrMB","pt":1743511957491,"mc":[{"id":"1.241629436","rc":[{"atb":[[6.8,41]],"id":35856222},{"atb":[[6.4,217.73]],"batb":[[0,6.4,217.73]],"id":26496185}]}]}
{"op":"mcm","id":2,"clk":"AP7FAQCGhwEA07MB","pt":1743511957594,"mc":[{"id":"1.241629436","rc":[{"atb":[[9.4,71.39],[9.6,51.83]],"batb":[[1,9.4,71.39],[0,9.6,51.83]],"id":35856222},{"atb":[[6.4,219.73]],"batb":[[0,6.4,219.73]],"id":26496185}]}]}
{"op":"mcm","id":2,"clk":"AJXGAQCYhwEA57MB","pt":1743511957794,"mc":[{"id":"1.241629436","rc":[{"atb":[[9.6,50.83]],"trd":[[9.6,471.9]],"batb":[[0,9.6,50.83]],"ltp":9.6,"tv":9480.58,"id":35856222}],"tv":77235.9}]}
{"op":"mcm","id":2,"clk":"ALPGAQC7hwEAibQB","pt":1743511958101,"mc":[{"id":"1.241629436","rc":[{"atb":[[9.6,47.83]],"trd":[[9.6,477.9]],"batb":[[0,9.6,47.83]],"tv":9486.58,"id":35856222}],"tv":77241.9}]}
{"op":"mcm","id":2,"clk":"AMTGAQDVhwEAlLQB","pt":1743511958219,"mc":[{"id":"1.241629436","rc":[{"atb":[[5.2,266.59]],"trd":[[5.2,2060.52]],"batb":[[0,5.2,266.59]],"tv":17238.09,"id":270592},{"atb":[[9.6,46.83]],"trd":[[9.6,479.9]],"batb":[[0,9.6,46.83]],"tv":9488.58,"id":35856222},{"atb":[[5.1,125.58]],"trd":[[5.1,3991.05]],"batb":[[0,5.1,125.58]],"tv":13036.77,"id":56297029},{"atb":[[9.6,3.96]],"trd":[[9.6,267.62]],"batb":[[0,9.6,3.96]],"tv":6826.98,"id":27115873},{"atb":[[6.4,218.73]],"trd":[[6.4,3565.34]],"batb":[[0,6.4,218.73]],"tv":12394.04,"id":26496185}],"tv":77251.9}]}
{"op":"mcm","id":2,"clk":"AObGAQCAiAEAurQB","pt":1743511958629,"mc":[{"id":"1.241629436","rc":[{"atb":[[4.8,114.95]],"batb":[],"id":270592}]}]}
{"op":"mcm","id":2,"clk":"AO/GAQCKiAEAw7QB","pt":1743511958680,"mc":[{"id":"1.241629436","rc":[{"atb":[[5,4.67]],"id":40389088},{"atb":[[4.7,147.02],[4.6,115.94]],"batb":[],"id":270592},{"atb":[[16.5,0]],"trd":[[16.5,559.62]],"batb":[[2,15,13.63],[1,15.5,45.61],[0,16,33.43]],"tv":5571.28,"id":58186642}],"tv":77297.36}]}
{"op":"mcm","id":2,"clk":"APnGAQCWiAEAybQB","pt":1743511958779,"mc":[{"id":"1.241629436","rc":[{"atb":[[4.4,107.75],[4.5,68.76]],"batb":[],"id":270592},{"atl":[[9.8,9.92]],"batl":[[0,9.8,9.92]],"id":35856222},{"atb":[[15,17.05],[16,29.99]],"atl":[[17,18.68]],"batb":[[2,15,17.05],[0,16,29.99]],"batl":[[0,17,18.68]],"id":58186642}]}]}
{"op":"mcm","id":2,"clk":"AP/GAQCgiAEA1bQB","pt":1743511958889,"mc":[{"id":"1.241629436","rc":[{"atl":[[12,54.83]],"batl":[[1,12,54.83]],"id":40389088},{"atb":[[4.2,16.33],[4.3,19.3]],"batb":[],"id":270592},{"atb":[[5.1,125.25]],"trd":[[5.1,3991.7]],"batb":[[0,5.1,125.25]],"tv":13037.42,"id":56297029},{"atb":[[15.5,42.13],[15,16.05],[14.5,36.87]],"atl":[[16.5,6.87]],"batb":[[2,15,16.05],[1,15.5,42.13]],"batl":[[2,17.5,45.13],[1,17,18.68],[0,16.5,6.87]],"id":58186642}],"tv":77298.01}]}
{"op":"mcm","id":2,"clk":"AIjHAQCjiAEA2rQB","pt":1743511958986,"mc":[{"id":"1.241629436","rc":[{"atb":[[4.1,17.97],[3.95,17.17],[4,76.9]],"id":270592},{"atb":[[15,12.63],[16,27.59]],"atl":[[16.5,5.87]],"trd":[[16.5,561.62]],"batb":[[2,15,12.63],[0,16,27.59]],"batl":[[0,16.5,5.87]],"tv":5573.28,"id":58186642}],"tv":77300.01}]}
{"op":"mcm","id":2,"clk":"AJDHAQCtiAEA5bQB","pt":1743511959090,"mc":[{"id":"1.241629436","rc":[{"atb":[[3.9,13.53],[3.85,91.31]],"id":270592},{"atb":[[15,15.04]],"batb":[[2,15,15.04]],"id":58186642}]}]}
{"op":"mcm","id":2,"clk":"AJ3HAQC1iAEA77QB","pt":1743511959199,"mc":[{"id":"1.241629436","rc":[{"atb":[[15.5,31.15]],"batb":[[1,15.5,31.15]],"id":58186642}]}]}
{"op":"mcm","id":2,"clk":"ALnHAQDJiAEAgLUB","pt":1743511959456,"mc":[{"id":"1.241629436","rc":[{"atb":[[15,16.04]],"batb":[[2,15,16.04]],"id":58186642}]}]}
{"op":"mcm","id":2,"clk":"AMLHAQDPiAEAhbUB","pt":1743511959506,"mc":[{"id":"1.241629436","rc":[{"atb":[[1.08,12]],"id":40389088},{"atb":[[1.08,12]],"id":270592},{"atb":[[1.08,12]],"id":56297029},{"atb":[[1.08,12]],"id":58186642}]}]}
{"op":"mcm","id":2,"clk":"ANPHAQDXiAEAi7UB","pt":1743511959621,"mc":[{"id":"1.241629436","rc":[{"atb":[[5.2,267.72]],"atl":[[1000,21.39]],"batb":[[0,5.2,267.72]],"id":270592},{"atb":[[9.6,5.39]],"batb":[[0,9.6,5.39]],"id":27115873},{"atb":[[15,15.04]],"batb":[[2,15,15.04]],"id":58186642}]}]}
{"op":"mcm","id":2,"clk":"AN3HAQDliAEAlLUB","pt":1743511959713,"mc":[{"id":"1.241629436","rc":[{"atl":[[1000,21.16]],"id":270592},{"atb":[[9.6,73.17]],"batb":[[0,9.6,73.17]],"id":35856222},{"atl":[[70,5.42],[65,17.03]],"trd":[[65,182.6]],"batl":[[1,70,5.42],[0,65,17.03]],"ltp":65,"tv":1716.75,"id":59626646},{"atb":[[16,69.28]],"atl":[[1000,5.41],[17.5,7.96]],"batb":[[0,16,69.28]],"batl":[[2,17.5,7.96]],"id":58186642},{"atb":[[6.4,264.77]],"batb":[[0,6.4,264.77]],"id":26496185}],"tv":77300.97}]}
{"op":"mcm","id":2,"clk":"AOrHAQDuiAEAorUB","pt":1743511959818,"mc":[{"id":"1.241629436","rc":[{"atl":[[12,59.83]],"batl":[[1,12,59.83]],"id":40389088},{"atl":[[5.4,133.35]],"batl":[[1,5.4,133.35]],"id":270592},{"atb":[[5.1,122.25]],"trd":[[5.1,3997.7]],"batb":[[0,5.1,122.25]],"tv":13043.42,"id":56297029},{"atl":[[1000,2.39]],"id":58186642}],"tv":77306.97}]}
{"op":"mcm","id":2,"clk":"AO7HAQD8iAEArLUB","pt":1743511959927,"mc":[{"id":"1.241629436","rc":[{"atb":[[16,69.42]],"atl":[[16.5,4.87]],"trd":[[16.5,563.62]],"batb":[[0,16,69.42]],"batl":[[0,16.5,4.87]],"tv":5575.28,"id":58186642},{"atb":[[11,111.45]],"trd":[[11,1465.87]],"batb":[[0,11,111.45]],"tv":4686.51,"id":44049799}],"tv":77318.97}]}
{"op":"mcm","id":2,"clk":"AITIAQCHiQEAuLUB","pt":1743511959983,"mc":[{"id":"1.241629436","rc":[{"atl":[[1000,1.41],[16.5,3.19]],"trd":[[16.5,566.98]],"batl":[[0,16.5,3.19]],"tv":5578.64,"id":58186642}],"tv":77322.33}]}
{"op":"mcm","id":2,"clk":"AI7IAQCRiQEAw7UB","pt":1743511960083,"mc":[{"id":"1.241629436","rc":[{"atb":[[16.5,8.03]],"atl":[[17,19.66],[16.5,0]],"batb":[[2,15.5,31.15],[1,16,69.42],[0,16.5,8.03]],"batl":[[2,18,18.48],[1,17.5,7.96],[0,17,19.66]],"id":58186642}]}]}
{"op":"mcm","id":2,"clk":"AJTIAQCZiQEAzLUB","pt":1743511960181,"mc":[{"id":"1.241629436","rc":[{"atb":[[5.1,115.11]],"trd":[[5.1,4011.98]],"batb":[[0,5.1,115.11]],"tv":13057.7,"id":56297029},{"atl":[[10,34.97]],"batl":[[1,10,34.97]],"id":27115873},{"atb":[[16.5,11.2]],"atl":[[17,16.55]],"batb":[[0,16.5,11.2]],"batl":[[0,17,16.55]],"id":58186642}],"tv":77336.61}]}
{"op":"mcm","id":2,"clk":"ALfIAQC7iQEA6LUB","pt":1743511960397,"mc":[{"id":"1.241629436","rc":[{"atl":[[17,14.15]],"batl":[[0,17,14.15]],"id":58186642}]}]}
{"op":"mcm","id":2,"clk":"AMbIAQDGiQEA+bUB","pt":1743511960504,"mc":[{"id":"1.241629436","rc":[{"atl":[[10,40.88]],"batl":[[1,10,40.88]],"id":27115873}]}]}
{"op":"mcm","id":2,"clk":"ANDIAQDUiQEA/LUB","pt":1743511960604,"mc":[{"id":"1.241629436","rc":[{"atb":[[11,99.94]],"trd":[[11,1488.89]],"batb":[[0,11,99.94]],"tv":4709.53,"id":44049799}],"tv":77359.63}]}
{"op":"mcm","id":2,"clk":"AOLIAQDdiQEAibYB","pt":1743511960714,"mc":[{"id":"1.241629436","rc":[{"atl":[[10,34.97]],"batl":[[1,10,34.97]],"id":27115873}]}]}
{"op":"mcm","id":2,"clk":"AOzIAQDxiQEAkrYB","pt":1743511960810,"mc":[{"id":"1.241629436","rc":[{"atb":[[5.2,259]],"trd":[[5.2,2077.96]],"batb":[[0,5.2,259]],"tv":17255.53,"id":270592},{"atb":[[9.6,67.17]],"trd":[[9.6,491.9]],"batb":[[0,9.6,67.17]],"tv":9500.58,"id":35856222},{"atl":[[65,19.03]],"batl":[[0,65,19.03]],"id":59626646},{"atl":[[17,18.15]],"batl":[[0,17,18.15]],"id":58186642},{"atb":[[11,94.94]],"trd":[[11,1498.89]],"batb":[[0,11,94.94]],"tv":4719.53,"id":44049799}],"tv":77399.07}]}
{"op":"mcm","id":2,"clk":"APjIAQD2iQEAnbYB","pt":1743511960915,"mc":[{"id":"1.241629436","rc":[{"atb":[[9.6,24.14]],"batb":[[0,9.6,24.14]],"id":27115873}]}]}
{"op":"mcm","id":2,"clk":"AIzJAQD5iQEArbYB","pt":1743511961025,"mc":[{"id":"1.241629436","rc":[{"atb":[[5.1,109.1]],"batb":[[0,5.1,109.1]],"id":56297029}]}]}
{"op":"mcm","id":2,"clk":"AJXJAQCEigEArbYB","pt":1743511961118,"mc":[{"id":"1.241629436","rc":[{"atl":[[1000,23.16]],"id":270592}]}]}
{"op":"mcm","id":2,"clk":"AKnJAQCbigEAxLYB","pt":1743511961325,"mc":[{"id":"1.241629436","rc":[{"atl":[[1000,21.16]],"id":270592},{"atb":[[15.5,35.37]],"batb":[[2,15.5,35.37]],"id":58186642}]}]}
{"op":"mcm","id":2,"clk":"ALfJAQCligEA0LYB","pt":1743511961379,"mc":[{"id":"1.241629436","rc":[{"atb":[[9.4,72.69]],"batb":[[1,9.4,72.69]],"id":35856222},{"atl":[[11.5,87.73]],"batl":[[0,11.5,87.73]],"id":44049799}]}]}
{"op":"mcm","id":2,"clk":"AMfJAQC0igEA3bYB","pt":1743511961494,"mc":[{"id":"1.241629436","rc":[{"atl":[[5.4,75.07]],"batl":[[2,5.4,75.07]],"id":56297029},{"atb":[[16.5,12.2]],"batb":[[0,16.5,12.2]],"id":58186642}]}]}
{"op":"mcm","id":2,"clk":"ANnJAQDEigEA6LYB","pt":1743511961607,"mc":[{"id":"1.241629436","rc":[{"atb":[[9.6,67.07]],"trd":[[9.6,492.1]],"batb":[[0,9.6,67.07]],"tv":9500.78,"id":35856222},{"atb":[[6.4,261.77]],"trd":[[6.4,3571.34]],"batb":[[0,6.4,261.77]],"tv":12400.04,"id":26496185}],"tv":77405.27}]}
{"op":"mcm","id":2,"clk":"AO3JAQDUigEA8bYB","pt":1743511961708,"mc":[{"id":"1.241629436","rc":[{"atl":[[1000,23.16]],"id":270592}]}]}
{"op":"mcm","id":2,"clk":"APnJAQDeigEA+LYB","pt":1743511961798,"mc":[{"id":"1.241629436","rc":[{"atl":[[65,18.03]],"batl":[[0,65,18.03]],"id":59626646}]}]}
{"op":"mcm","id":2,"clk":"AInKAQDtigEAiLcB","pt":1743511961911,"mc":[{"id":"1.241629436","rc":[{"atl":[[1000,21.16]],"id":270592},{"atb":[[60,9.96]],"trd":[[60,316.41]],"batb":[[0,60,9.96]],"ltp":60,"tv":1718.75,"id":59626646}],"tv":77407.27}]}
{"op":"mcm","id":2,"clk":"AJTKAQD3igEAmbcB","pt":1743511962014,"mc":[{"id":"1.241629436","rc":[{"atl":[[17,15.74]],"batl":[[0,17,15.74]],"id":58186642}]}]}
{"op":"mcm","id":2,"clk":"AKvKAQCSiwEAsrcB","pt":1743511962215,"mc":[{"id":"1.241629436","rc":[{"atl":[[1000,0.36]],"id":40389088},{"atl":[[65,19.65]],"batl":[[0,65,19.65]],"id":59626646},{"atb":[[5.1,106.69]],"atl":[[5.3,89.5]],"batb":[[0,5.1,106.69]],"batl":[[1,5.3,89.5]],"id":56297029},{"atb":[[16,68.31]],"atl":[[17,14.23]],"batb":[[1,16,68.31]],"batl":[[0,17,14.23]],"id":58186642},{"atb":[[6.4,263.03]],"batb":[[0,6.4,263.03]],"id":26496185},{"atb":[[11,97.63]],"batb":[[0,11,97.63]],"id":44049799}]}]}
{"op":"mcm","id":2,"clk":"ALbKAQCciwEAu7cB","pt":1743511962322,"mc":[{"id":"1.241629436","rc":[{"atl":[[1000,0.25]],"id":40389088}]}]}
{"op":"mcm","id":2,"clk":"AMbKAQCniwEAzLcB","pt":1743511962423,"mc":[{"id":"1.241629436","rc":[{"atl":[[11.5,3.46]],"batl":[[0,11.5,3.46]],"id":40389088},{"atb":[[16,68.17]],"batb":[[1,16,68.17]],"id":58186642}]}]}
{"op":"mcm","id":2,"clk":"AOjKAQDCiwEA/bcB","pt":1743511962692,"mc":[{"id":"1.241629436","rc":[{"atb":[[6.4,262.03]],"trd":[[6.4,3573.34]],"batb":[[0,6.4,262.03]],"tv":12402.04,"id":26496185}],"tv":77409.27}]}
{"op":"mcm","id":2,"clk":"AIXLAQDpiwEAtbgB","pt":1743511963010,"mc":[{"id":"1.241629436","rc":[{"atb":[[10.5,30.55]],"batb":[[1,10.5,30.55]],"id":40389088}]}]}
{"op":"mcm","id":2,"clk":"AJDLAQDviwEAw7gB","pt":1743511963110,"mc":[{"id":"1.241629436","rc":[{"atb":[[11,64.82]],"batb":[[0,11,64.82]],"id":40389088},{"atb":[[15.5,31.15]],"batb":[[2,15.5,31.15]],"id":58186642}]}]}
{"op":"mcm","id":2,"clk":"AJrLAQD8iwEA17gB","pt":1743511963217,"mc":[{"id":"1.241629436","rc":[{"atb":[[4.9,243.4]],"atl":[[5.6,181.22]],"batb":[],"batl":[],"id":270592},{"atb":[[4.8,149.55]],"atl":[[5.5,104.66]],"batb":[],"batl":[],"id":56297029},{"atb":[[5.9,99.79]],"atl":[[7.2,105.57]],"batb":[],"batl":[],"id":26496185}]}]}
{"op":"mcm","id":2,"clk":"AM7LAQC5jAEAkrkB","pt":1743511963625,"mc":[{"id":"1.241629436","rc":[{"atb":[[9.6,59]],"trd":[[9.6,508.24]],"batb":[[0,9.6,59]],"tv":9516.92,"id":35856222}],"tv":77425.41}]}
{"op":"mcm","id":2,"clk":"AN/LAQDGjAEAoLkB","pt":1743511963684,"mc":[{"id":"1.241629436","rc":[{"atl":[[1000,5.52]],"id":56297029},{"atl":[[1000,3.9]],"id":26496185}]}]}
{"op":"mcm","id":2,"clk":"AITMAQDnjAEAwbkB","pt":1743511963997,"mc":[{"id":"1.241629436","rc":[{"atb":[[60,0]],"atl":[[60,0.04]],"trd":[[60,336.33]],"batb":[[2,48,4.26],[1,50,15.95],[0,55,15.67]],"batl":[[0,65,19.69]],"tv":1738.67,"id":59626646}],"tv":77445.33}]}
{"op":"mcm","id":2,"clk":"AJHMAQDzjAEAybkB","pt":1743511964103,"mc":[{"id":"1.241629436","rc":[{"atl":[[60,4.79],[65,20.67]],"batl":[[2,70,5.42],[1,65,20.67],[0,60,4.79]],"id":59626646}]}]}
{"op":"mcm","id":2,"clk":"AKHMAQCAjQEA0bkB","pt":1743511964199,"mc":[{"id":"1.241629436","rc":[{"atb":[[9.6,60.31]],"batb":[[0,9.6,60.31]],"id":35856222},{"atb":[[55,17.3]],"atl":[[60,7.42]],"batb":[[0,55,17.3]],"batl":[[0,60,7.42]],"id":59626646},{"atb":[[5.1,107.93]],"batb":[[0,5.1,107.93]],"id":56297029},{"atb":[[9.6,25.47]],"batb":[[0,9.6,25.47]],"id":27115873}]}]}
{"op":"mcm","id":2,"clk":"ALPMAQCLjQEA4LkB","pt":1743511964300,"mc":[{"id":"1.241629436","rc":[{"atl":[[60,6.41]],"trd":[[60,338.35]],"batl":[[0,60,6.41]],"tv":1740.69,"id":59626646}],"tv":77447.35}]}
{"op":"mcm","id":2,"clk":"ANnMAQCtjQEAhLoB","pt":1743511964610,"mc":[{"id":"1.241629436","rc":[{"atb":[[4.9,84.56]],"batb":[[2,4.9,84.56]],"id":56297029}]}]}
{"op":"mcm","id":2,"clk":"APvMAQDKjQEAr7oB","pt":1743511964923,"mc":[{"id":"1.241629436","rc":[{"atl":[[65,19.87]],"batl":[[1,65,19.87]],"id":59626646}]}]}
{"op":"mcm","id":2,"clk":"AIjNAQDWjQEAuLoB","pt":1743511965021,"mc":[{"id":"1.241629436","rc":[{"atl":[[60,6.44]],"batl":[[0,60,6.44]],"id":59626646}]}]}
{"op":"mcm","id":2,"clk":"AJTNAQDnjQEAxboB","pt":1743511965131,"mc":[{"id":"1.241629436","rc":[{"atb":[[9.6,57.31]],"trd":[[9.6,514.24]],"batb":[[0,9.6,57.31]],"tv":9522.92,"id":35856222},{"atb":[[6.4,256.03]],"trd":[[6.4,3585.34]],"batb":[[0,6.4,256.03]],"tv":12414.04,"id":26496185}],"tv":77465.35}]}
{"op":"mcm","id":2,"clk":"AKPNAQDvjQEAzLoB","pt":1743511965192,"mc":[{"id":"1.241629436","rc":[{"atb":[[1.17,2.73],[11,66.5]],"atl":[[1000,0.4]],"batb":[[0,11,66.5]],"id":40389088},{"atl":[[1000,0.63]],"id":35856222},{"atl":[[65,18.61]],"batl":[[1,65,18.61]],"id":59626646},{"atb":[[5.1,112.12]],"batb":[[0,5.1,112.12]],"id":56297029}]}]}
{"op":"mcm","id":2,"clk":"AK3NAQD+jQEA2roB","pt":1743511965292,"mc":[{"id":"1.241629436","rc":[{"atb":[[1.17,2]],"atl":[[1000,0.25]],"id":40389088},{"atb":[[9.6,61.48]],"atl":[[1000,0.41]],"batb":[[0,9.6,61.48]],"id":35856222},{"atl":[[60,7.81]],"batl":[[0,60,7.81]],"id":59626646}]}]}
{"op":"mcm","id":2,"clk":"ALzNAQCKjgEA6boB","pt":1743511965405,"mc":[{"id":"1.241629436","rc":[{"atb":[[11,67.23]],"atl":[[12,59.98]],"batb":[[0,11,67.23]],"batl":[[1,12,59.98]],"id":40389088},{"atl":[[10,115.49]],"batl":[[1,10,115.49]],"id":35856222},{"atl":[[17,13.23]],"batl":[[0,17,13.23]],"id":58186642}]}]}
{"op":"mcm","id":2,"clk":"AMPNAQCWjgEA9LoB","pt":1743511965502,"mc":[{"id":"1.241629436","rc":[{"atl":[[12,82.98]],"batl":[[1,12,82.98]],"id":40389088},{"atb":[[16.5,11.2]],"trd":[[16.5,568.98]],"batb":[[0,16.5,11.2]],"tv":5580.64,"id":58186642}],"tv":77467.35}]}
{"op":"mcm","id":2,"clk":"AM/NAQChjgEA/boB","pt":1743511965597,"mc":[{"id":"1.241629436","rc":[{"atb":[[9,43.11]],"batb":[],"id":27115873},{"atb":[[16.5,29.48]],"atl":[[17.5,10.33]],"batb":[[0,16.5,29.48]],"batl":[[1,17.5,10.33]],"id":58186642}]}]}
{"op":"mcm","id":2,"clk":"ANrNAQCtjgEAh7sB","pt":1743511965699,"mc":[{"id":"1.241629436","rc":[{"atb":[[16,66.42]],"batb":[[1,16,66.42]],"id":58186642}]}]}
{"op":"mcm","id":2,"clk":"AOnNAQC3jgEAkrsB","pt":1743511965804,"mc":[{"id":"1.241629436","rc":[{"atb":[[4.7,47.5]],"batb":[],"id":56297029}]}]}
{"op":"mcm","id":2,"clk":"APPNAQDAjgEAlrsB","pt":1743511965910,"mc":[{"id":"1.241629436","rc":[{"atb":[[9.6,14.61]],"trd":[[9.6,286.48]],"batb":[[0,9.6,14.61]],"tv":6845.84,"id":27115873}],"tv":77486.21}]}
{"op":"mcm","id":2,"clk":"AIrOAQDVjgEAq7sB","pt":1743511966114,"mc":[{"id":"1.241629436","rc":[{"atb":[[1.01,96333.31]],"id":27115873},{"atb":[[16.5,18.32]],"batb":[[0,16.5,18.32]],"id":58186642}]}]}
{"op":"mcm","id":2,"clk":"AJvOAQDgjgEAtbsB","pt":1743511966224,"mc":[{"id":"1.241629436","rc":[{"atl":[[12,77.98]],"batl":[[1,12,77.98]],"id":40389088},{"atb":[[6.4,255.03]],"trd":[[6.4,3587.34]],"batb":[[0,6.4,255.03]],"tv":12416.04,"id":26496185}],"tv":77488.21}]}
{"op":"mcm","id":2,"clk":"ALPOAQDzjgEAw7sB","pt":1743511966423,"mc":[{"id":"1.241629436","rc":[{"atl":[[12,77.85]],"batl":[[1,12,77.85]],"id":40389088},{"atb":[[6.4,253.03]],"trd":[[6.4,3591.34]],"batb":[[0,6.4,253.03]],"tv":12420.04,"id":26496185}],"tv":77492.21}]}
{"op":"mcm","id":2,"clk":"ALnOAQD+jgEAyrsB","pt":1743511966481,"mc":[{"id":"1.241629436","rc":[{"atl":[[1000,23.16]],"id":270592}]}]}
{"op":"mcm","id":2,"clk":"ANPOAQCVjwEA2rsB","pt":1743511966689,"mc":[{"id":"1.241629436","rc":[{"atl":[[1000,21.16]],"id":270592}]}]}
{"op":"mcm","id":2,"clk":"AOjOAQCqjwEA77sB","pt":1743511966896,"mc":[{"id":"1.241629436","rc":[{"atb":[[9,44.46]],"batb":[],"id":27115873}]}]}
{"op":"mcm","id":2,"clk":"APnOAQC/jwEA+7sB","pt":1743511967094,"mc":[{"id":"1.241629436","rc":[{"atl":[[1000,23.16]],"id":270592}]}]}
{"op":"mcm","id":2,"clk":"AJHPAQDTjwEAkLwB","pt":1743511967310,"mc":[{"id":"1.241629436","rc":[{"atl":[[1000,21.16]],"id":270592}]}]}
{"op":"mcm","id":2,"clk":"AJfPAQDZjwEAnLwB","pt":1743511967410,"mc":[{"id":"1.241629436","rc":[{"atb":[[9.8,28.42]],"batb":[],"id":40389088}]}]}
{"op":"mcm","id":2,"clk":"AKHPAQDijwEAqLwB","pt":1743511967508,"mc":[{"id":"1.241629436","rc":[{"atb":[[11,68.23]],"batb":[[0,11,68.23]],"id":40389088},{"atb":[[5.1,293.51]],"batb":[[1,5.1,293.51]],"id":270592},{"atb":[[9.6,14.63]],"batb":[[0,9.6,14.63]],"id":27115873}]}]}
{"op":"mcm","id":2,"clk":"ALnPAQD6jwEAuLwB","pt":1743511967718,"mc":[{"id":"1.241629436","rc":[{"atb":[[5.1,302.05]],"batb":[[1,5.1,302.05]],"id":270592}]}]}
{"op":"mcm","id":2,"clk":"ANfPAQCakAEA4LwB","pt":1743511967982,"mc":[{"id":"1.241629436","rc":[{"atb":[[9.2,42.76]],"batb":[[2,9.2,42.76]],"id":27115873}]}]}
{"op":"mcm","id":2,"clk":"AOPPAQCjkAEA67wB","pt":1743511968088,"mc":[{"id":"1.241629436","rc":[{"atl":[[5.2,238.78]],"batl":[[0,5.2,238.78]],"id":56297029}]}]}
{"op":"mcm","id":2,"clk":"AO/PAQCvkAEA+rwB","pt":1743511968192,"mc":[{"id":"1.241629436","rc":[{"atl":[[5.4,72.92],[5.7,88.05],[5.3,87.25],[5.5,102.6],[5.6,37.98]],"batl":[[2,5.4,72.92],[1,5.3,87.25]],"id":56297029}]}]}
{"op":"mcm","id":2,"clk":"AP3PAQC5kAEAhr0B","pt":1743511968296,"mc":[{"id":"1.241629436","rc":[{"atl":[[5.2,224.63]],"batl":[[0,5.2,224.63]],"id":56297029}]}]}
{"op":"mcm","id":2,"clk":"AITQAQDFkAEAkb0B","pt":1743511968401,"mc":[{"id":"1.241629436","rc":[{"atl":[[5.3,261.92]],"trd":[[5.3,1550.98]],"batl":[[0,5.3,261.92]],"ltp":5.3,"tv":17265.53,"id":270592}],"tv":77502.21}]}
{"op":"mcm","id":2,"clk":"AJPQAQDOkAEAoL0B","pt":1743511968505,"mc":[{"id":"1.241629436","rc":[{"atl":[[5.4,75.07],[5.3,89.5],[5.5,104.66]],"batl":[[2,5.4,75.07],[1,5.3,89.5]],"id":56297029}]}]}
{"op":"mcm","id":2,"clk":"AJ3QAQDZkAEApL0B","pt":1743511968606,"mc":[{"id":"1.241629436","rc":[{"atl":[[5.2,242.65]],"batl":[[0,5.2,242.65]],"id":56297029}]}]}
{"op":"mcm","id":2,"clk":"AKTQAQDikAEAq70B","pt":1743511968706,"mc":[{"id":"1.241629436","rc":[{"atb":[[9.6,22.89]],"batb":[[0,9.6,22.89]],"id":27115873},{"atb":[[15.5,32.15]],"batb":[[2,15.5,32.15]],"id":58186642}]}]}
{"op":"mcm","id":2,"clk":"ALfQAQDtkAEAwb0B","pt":1743511968822,"mc":[{"id":"1.241629436","rc":[{"atl":[[12,82.85]],"batl":[[1,12,82.85]],"id":40389088},{"atl":[[60,0],[65,16.75]],"trd":[[60,353.97],[65,186.32]],"batl":[[2,75,5.07],[1,70,5.42],[0,65,16.75]],"ltp":65,"tv":1760.03,"id":59626646}],"tv":77521.55}]}
{"op":"mcm","id":2,"clk":"AMrQAQD8kAEA070B","pt":1743511969028,"mc":[{"id":"1.241629436","rc":[{"atb":[[9.8,29.61],[1.5,30],[10,67.18]],"batb":[[2,10,67.18]],"id":40389088},{"atb":[[1.5,33]],"id":270592},{"atb":[[1.5,54]],"id":35856222},{"atb":[[1.5,30]],"atl":[[65,21.62]],"batl":[[0,65,21.62]],"id":59626646},{"atb":[[1.5,32]],"id":56297029},{"atb":[[1.5,54]],"id":27115873},{"atb":[[1.5,30]],"id":58186642},{"atb":[[1.5,31]],"id":26496185},{"atb":[[1.5,30]],"id":44049799}]}]}
{"op":"mcm","id":2,"clk":"ANXQAQCFkQEA4b0B","pt":1743511969134,"mc":[{"id":"1.241629436","rc":[{"atl":[[11.5,3.35]],"batl":[[0,11.5,3.35]],"id":40389088},{"atb":[[5.2,257.87]],"atl":[[5.4,133.12]],"batb":[[0,5.2,257.87]],"batl":[[1,5.4,133.12]],"id":270592},{"atb":[[55,16.95],[50,16.3]],"batb":[[1,50,16.3],[0,55,16.95]],"id":59626646},{"atl":[[17,12.91]],"batl":[[0,17,12.91]],"id":58186642},{"atb":[[11,95.48]],"batb":[[0,11,95.48]],"id":44049799}]}]}
{"op":"mcm","id":2,"clk":"AN/QAQCSkQEA570B","pt":1743511969185,"mc":[{"id":"1.241629436","rc":[{"atl":[[65,20.06]],"batl":[[0,65,20.06]],"id":59626646},{"atb":[[9.4,68.81]],"batb":[[1,9.4,68.81]],"id":27115873}]}]}
{"op":"mcm","id":2,"clk":"APXQAQCnkQEA970B","pt":1743511969398,"mc":[{"id":"1.241629436","rc":[{"atl":[[5.4,72.92],[5.7,89.95],[5.3,87.25],[5.5,102.6]],"batl":[[2,5.4,72.92],[1,5.3,87.25]],"id":56297029}]}]}
{"op":"mcm","id":2,"clk":"AJnRAQDBkQEAk74B","pt":1743511969695,"mc":[{"id":"1.241629436","rc":[{"atb":[[9.8,28.42],[10,66.05]],"batb":[[2,10,66.05]],"id":40389088},{"atl":[[5.2,224.63]],"batl":[[0,5.2,224.63]],"id":56297029}]}]}
{"op":"mcm","id":2,"clk":"AKDRAQDGkQEAnb4B","pt":1743511969805,"mc":[{"id":"1.241629436","rc":[{"atl":[[5.4,75.07],[5.3,89.5],[5.5,104.66]],"batl":[[2,5.4,75.07],[1,5.3,89.5]],"id":56297029}]}]}
{"op":"mcm","id":2,"clk":"AKrRAQDRkQEAqr4B","pt":1743511969906,"mc":[{"id":"1.241629436","rc":[{"atl":[[5.2,241.52]],"batl":[[0,5.2,241.52]],"id":56297029}]}]}
{"op":"mcm","id":2,"clk":"ALbRAQDakQEAq74B","pt":1743511970009,"mc":[{"id":"1.241629436","rc":[{"atb":[[9.4,71.39],[9.2,65.27]],"batb":[[2,9.2,65.27],[1,9.4,71.39]],"id":35856222},{"atb":[[9.6,22.87]],"batb":[[0,9.6,22.87]],"id":27115873}]}]}
{"op":"mcm","id":2,"clk":"ALzRAQDjkQEAuL4B","pt":1743511970117,"mc":[{"id":"1.241629436","rc":[{"atb":[[9.4,72.69],[9.2,66.63]],"batb":[[2,9.2,66.63],[1,9.4,72.69]],"id":35856222},{"atl":[[65,20.22]],"batl":[[0,65,20.22]],"id":59626646},{"atl":[[5.4,72.92],[5.7,88.05],[5.2,224.63],[5.3,87.25],[5.5,102.6]],"batl":[[2,5.4,72.92],[1,5.3,87.25],[0,5.2,224.63]],"id":56297029},{"atb":[[11,94.48]],"trd":[[11,1500.89]],"batb":[[0,11,94.48]],"tv":4721.53,"id":44049799}],"tv":77523.55}]}
{"op":"mcm","id":2,"clk":"AMnRAQDrkQEAw74B","pt":1743511970220,"mc":[{"id":"1.241629436","rc":[{"atb":[[3,57.5]],"id":40389088}]}]}
{"op":"mcm","id":2,"clk":"ANbRAQD8kQEA0L4B","pt":1743511970329,"mc":[{"id":"1.241629436","rc":[{"atl":[[65,20.28]],"batl":[[0,65,20.28]],"id":59626646}]}]}
{"op":"mcm","id":2,"clk":"AN/RAQCEkgEA2b4B","pt":1743511970420,"mc":[{"id":"1.241629436","rc":[{"atl":[[65,18.28]],"batl":[[0,65,18.28]],"id":59626646},{"atl":[[17,8.91]],"batl":[[0,17,8.91]],"id":58186642}]}]}
{"op":"mcm","id":2,"clk":"AOjRAQCPkgEA674B","pt":1743511970528,"mc":[{"id":"1.241629436","rc":[{"atl":[[9.8,8.68]],"trd":[[9.8,656.58]],"batl":[[0,9.8,8.68]],"ltp":9.8,"tv":9525.4,"id":35856222},{"atl":[[60,2]],"batl":[[2,70,5.42],[1,65,18.28],[0,60,2]],"id":59626646},{"atb":[[5.1,109.16]],"trd":[[5.1,4017.9]],"batb":[[0,5.1,109.16]],"tv":13063.62,"id":56297029},{"atl":[[9.8,79.85]],"trd":[[9.8,333.6]],"batl":[[0,9.8,79.85]],"ltp":9.8,"tv":6848.52,"id":27115873},{"atb":[[16.5,14.32]],"trd":[[16.5,576.98]],"batb":[[0,16.5,14.32]],"tv":5588.64,"id":58186642}],"tv":77542.63}]}
{"op":"mcm","id":2,"clk":"APfRAQCikgEA/74B","pt":1743511970686,"mc":[{"id":"1.241629436","rc":[{"atb":[[9.4,23.08],[9.6,31.76]],"batb":[],"id":40389088},{"atl":[[65,15.55]],"batl":[[1,65,15.55]],"id":59626646}]}]}
{"op":"mcm","id":2,"clk":"AKzSAQDJkgEAr78B","pt":1743511971106,"mc":[{"id":"1.241629436","rc":[{"atb":[[11,93.64]],"trd":[[11,1502.57]],"batb":[[0,11,93.64]],"tv":4723.21,"id":44049799}],"tv":77544.31}]}
{"op":"mcm","id":2,"clk":"AI3TAQCWkwEAiMAB","pt":1743511971890,"mc":[{"id":"1.241629436","rc":[{"atl":[[1000,23.16]],"id":270592},{"atb":[[16,67.42]],"batb":[[1,16,67.42]],"id":58186642}]}]}
{"op":"mcm","id":2,"clk":"AJzTAQCnkwEAnMAB","pt":1743511972098,"mc":[{"id":"1.241629436","rc":[{"atl":[[1000,21.16]],"id":270592},{"atb":[[9.6,24.63]],"batb":[[0,9.6,24.63]],"id":27115873}]}]}
{"op":"mcm","id":2,"clk":"ALTTAQCzkwEAqMAB","pt":1743511972211,"mc":[{"id":"1.241629436","rc":[{"atl":[[5.7,89.95],[5.2,243.45]],"batl":[[0,5.2,243.45]],"id":56297029}]}]}
{"op":"mcm","id":2,"clk":"ANPTAQDSkwEAw8AB","pt":1743511972512,"mc":[{"id":"1.241629436","rc":[{"atl":[[1000,23.16]],"id":270592}]}]}
{"op":"mcm","id":2,"clk":"AO/TAQDrkwEA1cAB","pt":1743511972722,"mc":[{"id":"1.241629436","rc":[{"atl":[[1000,21.16]],"id":270592},{"atl":[[65,15.39]],"batl":[[1,65,15.39]],"id":59626646}]}]}
{"op":"mcm","id":2,"clk":"APnTAQDwkwEA38AB","pt":1743511972817,"mc":[{"id":"1.241629436","rc":[{"atb":[[8,33.94],[9.6,24.65]],"batb":[[0,9.6,24.65]],"id":27115873}]}]}
{"op":"mcm","id":2,"clk":"AIjUAQD3kwEA6cAB","pt":1743511972923,"mc":[{"id":"1.241629436","rc":[{"atl":[[1000,2.25]],"id":40389088},{"atb":[[8.4,60.82]],"batb":[],"id":27115873}]}]}
{"op":"mcm","id":2,"clk":"AJLUAQCBlAEA9cAB","pt":1743511973030,"mc":[{"id":"1.241629436","rc":[{"atl":[[1000,1.04]],"id":40389088}]}]}
{"op":"mcm","id":2,"clk":"AKLUAQCGlAEA/MAB","pt":1743511973082,"mc":[{"id":"1.241629436","rc":[{"atl":[[1000,0.25]],"id":40389088}]}]}
{"op":"mcm","id":2,"clk":"AK7UAQCNlAEAiMEB","pt":1743511973187,"mc":[{"id":"1.241629436","rc":[{"atb":[[11,67.44]],"trd":[[11,172.19]],"batb":[[0,11,67.44]],"tv":6350.9,"id":40389088}],"tv":77545.89}]}
{"op":"mcm","id":2,"clk":"AOLUAQC7lAEAt8EB","pt":1743511973609,"mc":[{"id":"1.241629436","rc":[{"atl":[[9.8,7.68]],"trd":[[9.8,658.58]],"batl":[[0,9.8,7.68]],"tv":9527.4,"id":35856222}],"tv":77547.89}]}
{"op":"mcm","id":2,"clk":"AO3UAQDIlAEAx8EB","pt":1743511973710,"mc":[{"id":"1.241629436","rc":[{"atb":[[11,65.8]],"trd":[[11,175.47]],"batb":[[0,11,65.8]],"tv":6354.18,"id":40389088}],"tv":77551.17}]}
{"op":"mcm","id":2,"clk":"AJDVAQDnlAEA58EB","pt":1743511974023,"mc":[{"id":"1.241629436","rc":[{"atl":[[5.4,73.42]],"batl":[[2,5.4,73.42]],"id":56297029}]}]}
{"op":"mcm","id":2,"clk":"ALjVAQCDlQEAg8IB","pt":1743511974328,"mc":[{"id":"1.241629436","rc":[{"atb":[[9.6,20.65]],"trd":[[9.6,294.48]],"batb":[[0,9.6,20.65]],"ltp":9.6,"tv":6856.52,"id":27115873}],"tv":77559.17}]}
{"op":"mcm","id":2,"clk":"AKbWAQDYlQEA8sIB","pt":1743511975212,"mc":[{"id":"1.241629436","rc":[{"atl":[[7.2,120.57]],"batl":[],"id":26496185}]}]}
{"op":"mcm","id":2,"clk":"ANvWAQCFlgEAosMB","pt":1743511975626,"mc":[{"id":"1.241629436","rc":[{"atb":[[50,15.95]],"atl":[[65,14.14]],"batb":[[1,50,15.95]],"batl":[[1,65,14.14]],"id":59626646},{"atb":[[11,91.73]],"batb":[[0,11,91.73]],"id":44049799}]}]}
{"op":"mcm","id":2,"clk":"AOjWAQCSlgEAqMMB","pt":1743511975730,"mc":[{"id":"1.241629436","rc":[{"atl":[[5.6,39.96]],"batl":[],"id":56297029}]}]}
{"op":"mcm","id":2,"clk":"AIXXAQCvlgEAucMB","pt":1743511975930,"mc":[{"id":"1.241629436","rc":[{"atb":[[11,64.12]],"batb":[[0,11,64.12]],"id":40389088},{"atl":[[5.5,104.66]],"batl":[],"id":56297029}]}]}
{"op":"mcm","id":2,"clk":"AJLXAQC9lgEAwsMB","pt":1743511976032,"mc":[{"id":"1.241629436","rc":[{"atb":[[5.1,104.97]],"batb":[[0,5.1,104.97]],"id":56297029},{"atl":[[6.6,103.01]],"trd":[[6.6,1909.21]],"batl":[[0,6.6,103.01]],"ltp":6.6,"tv":12422.04,"id":26496185}],"tv":77561.17}]}
{"op":"mcm","id":2,"clk":"ANPXAQDilgEA88MB","pt":1743511976404,"mc":[{"id":"1.241629436","rc":[{"atl":[[9.4,11.16]],"id":270592}]}]}
{"op":"mcm","id":2,"clk":"AO7XAQCAlwEAkMQB","pt":1743511976609,"mc":[{"id":"1.241629436","rc":[{"atl":[[9.8,0.01]],"trd":[[9.8,673.92]],"batl":[[2,11,29.97],[1,10.5,75.76],[0,10,115.5]],"tv":9542.74,"id":35856222},{"atl":[[60,0]],"batl":[[2,75,5.07],[1,70,5.42],[0,65,14.14]],"id":59626646}],"tv":77576.51}]}
{"op":"mcm","id":2,"clk":"APjXAQCOlwEAm8QB","pt":1743511976717,"mc":[{"id":"1.241629436","rc":[{"atl":[[9.8,0]],"trd":[[9.8,673.94]],"batl":[[0,10,115.49]],"tv":9542.76,"id":35856222},{"atb":[[55,14.95]],"trd":[[55,156.62]],"batb":[[0,55,14.95]],"ltp":55,"tv":1764.03,"id":59626646}],"tv":77580.53}]}
{"op":"mcm","id":2,"clk":"AIXYAQCalwEAq8QB","pt":1743511976827,"mc":[{"id":"1.241629436","rc":[{"atb":[[9.4,71.39],[9.2,65.27],[9.6,79.97]],"atl":[[10,118.27]],"batb":[[2,9.2,65.27],[1,9.4,71.39],[0,9.6,79.97]],"batl":[[0,10,118.27]],"id":35856222},{"atb":[[55,18.48]],"batb":[[0,55,18.48]],"id":59626646},{"atl":[[5.4,75.57]],"batl":[[2,5.4,75.57]],"id":56297029},{"atl":[[11.5,97.02]],"batl":[[0,11.5,97.02]],"id":44049799}]}]}
{"op":"mcm","id":2,"clk":"AJLYAQCmlwEAssQB","pt":1743511976923,"mc":[{"id":"1.241629436","rc":[{"atb":[[55,28.26]],"batb":[[0,55,28.26]],"id":59626646}]}]}
{"op":"mcm","id":2,"clk":"AJ7YAQC4lwEAwcQB","pt":1743511977029,"mc":[{"id":"1.241629436","rc":[{"atb":[[55,28.54],[50,15.3]],"batb":[[1,50,15.3],[0,55,28.54]],"id":59626646}]}]}
{"op":"mcm","id":2,"clk":"ALDYAQDRlwEA1cQB","pt":1743511977226,"mc":[{"id":"1.241629436","rc":[{"atb":[[6.8,41.1]],"id":35856222},{"atl":[[12,37.11]],"batl":[[1,12,37.11]],"id":44049799}]}]}
{"op":"mcm","id":2,"clk":"ALrYAQDflwEA5MQB","pt":1743511977342,"mc":[{"id":"1.241629436","rc":[{"atl":[[1000,23.16]],"id":270592}]}]}
{"op":"mcm","id":2,"clk":"AM/YAQD0lwEA/sQB","pt":1743511977496,"mc":[{"id":"1.241629436","rc":[{"atb":[[5.2,256.87]],"atl":[[1000,21.16]],"trd":[[5.2,2079.96]],"batb":[[0,5.2,256.87]],"ltp":5.2,"tv":17267.53,"id":270592}],"tv":77582.53}]}
{"op":"mcm","id":2,"clk":"AN3YAQCAmAEAh8UB","pt":1743511977601,"mc":[{"id":"1.241629436","rc":[{"atb":[[55,21.48]],"batb":[[0,55,21.48]],"id":59626646}]}]}
{"op":"mcm","id":2,"clk":"AOvYAQCRmAEAlcUB","pt":1743511977711,"mc":[{"id":"1.241629436","rc":[{"atl":[[65,14.3]],"batl":[[0,65,14.3]],"id":59626646}]}]}
{"op":"mcm","id":2,"clk":"APTYAQCimAEAnMUB","pt":1743511977808,"mc":[{"id":"1.241629436","rc":[{"atb":[[3.95,15.32]],"id":26496185}]}]}
{"op":"mcm","id":2,"clk":"AP/YAQCvmAEAosUB","pt":1743511977915,"mc":[{"id":"1.241629436","rc":[{"atl":[[1000,23.16]],"id":270592}]}]}
{"op":"mcm","id":2,"clk":"AI3ZAQC/mAEArMUB","pt":1743511978023,"mc":[{"id":"1.241629436","rc":[{"atb":[[6.6,5.65]],"id":35856222}]}]}
{"op":"mcm","id":2,"clk":"AJnZAQDJmAEAssUB","pt":1743511978120,"mc":[{"id":"1.241629436","rc":[{"atl":[[1000,21.16]],"id":270592}]}]}
{"op":"mcm","id":2,"clk":"ANHZAQCOmQEA6MUB","pt":1743511978637,"mc":[{"id":"1.241629436","rc":[{"atb":[[1.17,1.42]],"id":270592},{"atb":[[5.1,107.49]],"atl":[[1000,6.03]],"batb":[[0,5.1,107.49]],"id":56297029},{"atb":[[16,68.45]],"atl":[[17,12.03]],"batb":[[1,16,68.45]],"batl":[[0,17,12.03]],"id":58186642}]}]}
{"op":"mcm","id":2,"clk":"AObZAQCVmQEA/MUB","pt":1743511978749,"mc":[{"id":"1.241629436","rc":[{"atb":[[1.17,1]],"id":270592},{"atb":[[8.6,23.9]],"atl":[[9.8,5]],"batb":[],"batl":[[2,10.5,75.76],[1,10,118.27],[0,9.8,5]],"id":35856222},{"atl":[[1000,5.52]],"id":56297029}]}]}
{"op":"mcm","id":2,"clk":"AO7ZAQCjmQEAg8YB","pt":1743511978795,"mc":[{"id":"1.241629436","rc":[{"atb":[[5.2,257.29]],"batb":[[0,5.2,257.29]],"id":270592},{"atl":[[5.3,87.76]],"batl":[[1,5.3,87.76]],"id":56297029},{"atb":[[11,75.37]],"batb":[[0,11,75.37]],"id":44049799}]}]}
{"op":"mcm","id":2,"clk":"AP3ZAQCsmQEAjsYB","pt":1743511978894,"mc":[{"id":"1.241629436","rc":[{"atb":[[9.4,72.69],[9.2,66.63],[9.6,61.48]],"atl":[[9.8,13.46]],"batb":[[2,9.2,66.63],[1,9.4,72.69],[0,9.6,61.48]],"batl":[[0,9.8,13.46]],"id":35856222}]}]}
{"op":"mcm","id":2,"clk":"AJ7aAQDJmQEAs8YB","pt":1743511979209,"mc":[{"id":"1.241629436","rc":[{"atb":[[9.4,73.69],[8.8,54.09]],"batb":[[1,9.4,73.69]],"id":35856222},{"atb":[[5.1,95.49]],"trd":[[5.1,4041.9]],"batb":[[0,5.1,95.49]],"tv":13087.62,"id":56297029}],"tv":77606.53}]}
{"op":"mcm","id":2,"clk":"AKnaAQDRmQEAusYB","pt":1743511979311,"mc":[{"id":"1.241629436","rc":[{"atb":[[9.6,15.31]],"trd":[[9.6,305.16]],"batb":[[0,9.6,15.31]],"tv":6867.2,"id":27115873}],"tv":77617.21}]}
{"op":"mcm","id":2,"clk":"AMHaAQDvmQEA1MYB","pt":1743511979610,"mc":[{"id":"1.241629436","rc":[{"atb":[[2.5,0]],"id":270592}]}]}
{"op":"mcm","id":2,"clk":"AIfbAQCtmgEAlMcB","pt":1743511980234,"mc":[{"id":"1.241629436","rc":[{"atb":[[9.6,15.29]],"batb":[[0,9.6,15.29]],"id":27115873}]}]}
{"op":"mcm","id":2,"clk":"AKvbAQDFmgEAsMcB","pt":1743511980493,"mc":[{"id":"1.241629436","rc":[{"atb":[[16,26.76]],"batb":[[1,16,26.76]],"id":58186642}]}]}
{"op":"mcm","id":2,"clk":"ALXbAQDOmgEAvscB","pt":1743511980598,"mc":[{"id":"1.241629436","rc":[{"atb":[[11,63.25]],"trd":[[11,1526.81]],"batb":[[0,11,63.25]],"tv":4747.45,"id":44049799}],"tv":77641.45}]}
{"op":"mcm","id":2,"clk":"ANPbAQDhmgEA08cB","pt":1743511980817,"mc":[{"id":"1.241629436","rc":[{"atb":[[5.2,257.19]],"trd":[[5.2,2080.16]],"batb":[[0,5.2,257.19]],"tv":17267.73,"id":270592},{"atb":[[9.6,59.48]],"trd":[[9.6,518.24]],"batb":[[0,9.6,59.48]],"ltp":9.6,"tv":9546.76,"id":35856222},{"atb":[[6.4,252.03]],"trd":[[6.4,3593.34]],"batb":[[0,6.4,252.03]],"ltp":6.4,"tv":12424.04,"id":26496185},{"atb":[[11,53.59]],"batb":[[0,11,53.59]],"id":44049799}],"tv":77647.65}]}
{"op":"mcm","id":2,"clk":"AN/bAQDqmgEA2ccB","pt":1743511980908,"mc":[{"id":"1.241629436","rc":[{"atb":[[9.6,60.72]],"atl":[[9.8,12.27]],"trd":[[9.8,676.32]],"batb":[[0,9.6,60.72]],"batl":[[0,9.8,12.27]],"ltp":9.8,"tv":9549.14,"id":35856222},{"atb":[[11,31.74]],"batb":[[0,11,31.74]],"id":44049799}],"tv":77650.03}]}
{"op":"mcm","id":2,"clk":"AOjbAQD0mgEA4ccB","pt":1743511981009,"mc":[{"id":"1.241629436","rc":[{"atb":[[9.6,10.92]],"trd":[[9.6,310.38]],"batb":[[0,9.6,10.92]],"tv":6872.42,"id":27115873},{"atb":[[10.5,67.91]],"batb":[[1,10.5,67.91]],"id":44049799}],"tv":77655.25}]}
{"op":"mcm","id":2,"clk":"APbbAQD8mgEA7McB","pt":1743511981122,"mc":[{"id":"1.241629436","rc":[{"atl":[[12,77.85]],"batl":[[1,12,77.85]],"id":40389088},{"atb":[[9.6,2.66]],"batb":[[0,9.6,2.66]],"id":27115873},{"atb":[[11,37.04]],"batb":[[0,11,37.04]],"id":44049799}]}]}
{"op":"mcm","id":2,"clk":"AP7bAQCDmwEA9McB","pt":1743511981216,"mc":[{"id":"1.241629436","rc":[{"atb":[[9.4,72.39],[9.2,65.27],[9.6,59.48]],"batb":[[2,9.2,65.27],[1,9.4,72.39],[0,9.6,59.48]],"id":35856222},{"atb":[[9.6,20.07]],"atl":[[10,40.88]],"batb":[[0,9.6,20.07]],"batl":[[1,10,40.88]],"id":27115873}]}]}
{"op":"mcm","id":2,"clk":"AIXcAQCKmwEAgMgB","pt":1743511981319,"mc":[{"id":"1.241629436","rc":[{"atb":[[9.6,28.16]],"atl":[[10,34.97]],"batb":[[0,9.6,28.16]],"batl":[[1,10,34.97]],"id":27115873}]}]}
{"op":"mcm","id":2,"clk":"AI/cAQCbmwEAiMgB","pt":1743511981426,"mc":[{"id":"1.241629436","rc":[{"atl":[[12,82.85]],"batl":[[1,12,82.85]],"id":40389088}]}]}
{"op":"mcm","id":2,"clk":"AKDcAQClmwEAlMgB","pt":1743511981533,"mc":[{"id":"1.241629436","rc":[{"atl":[[5.3,90.01]],"batl":[[1,5.3,90.01]],"id":56297029}]}]}
{"op":"mcm","id":2,"clk":"AKzcAQCwmwEAnsgB","pt":1743511981635,"mc":[{"id":"1.241629436","rc":[{"atb":[[9.6,51.95]],"trd":[[9.6,533.29]],"batb":[[0,9.6,51.95]],"ltp":9.6,"tv":9564.19,"id":35856222}],"tv":77670.3}]}
{"op":"mcm","id":2,"clk":"ALTcAQDAmwEAp8gB","pt":1743511981734,"mc":[{"id":"1.241629436","rc":[{"atb":[[11,65.8]],"batb":[[0,11,65.8]],"id":40389088},{"atb":[[9.4,73.69],[9.2,66.63]],"batb":[[2,9.2,66.63],[1,9.4,73.69]],"id":35856222},{"atb":[[5.1,99.68]],"batb":[[0,5.1,99.68]],"id":56297029},{"atl":[[1000,1.93],[9.8,81]],"batl":[[0,9.8,81]],"id":27115873},{"atl":[[17,11.03]],"batl":[[0,17,11.03]],"id":58186642}]}]}
{"op":"mcm","id":2,"clk":"AL/cAQDGmwEAscgB","pt":1743511981839,"mc":[{"id":"1.241629436","rc":[{"atb":[[11,65.07]],"atl":[[1000,0.36],[12,82.7]],"batb":[[0,11,65.07]],"batl":[[1,12,82.7]],"id":40389088},{"atb":[[5.2,256.36]],"trd":[[5.2,2080.98]],"batb":[[0,5.2,256.36]],"tv":17268.55,"id":270592},{"atb":[[9.6,51.76]],"atl":[[10,118.05]],"batb":[[0,9.6,51.76]],"batl":[[1,10,118.05]],"id":35856222},{"atb":[[1.17,2.11]],"atl":[[65,14.86]],"batl":[[0,65,14.86]],"id":59626646},{"atb":[[5.1,98.65]],"batb":[[0,5.1,98.65]],"id":56297029},{"atb":[[9.6,29.22]],"batb":[[0,9.6,29.22]],"id":27115873},{"atb":[[6.4,250.57]],"batb":[[0,6.4,250.57]],"id":26496185},{"atb":[[11,36.38]],"atl":[[12,36.92],[11.5,96.13]],"batb":[[0,11,36.38]],"batl":[[1,12,36.92],[0,11.5,96.13]],"id":44049799}],"tv":77671.12}]}
{"op":"mcm","id":2,"clk":"AM7cAQDWmwEAtMgB","pt":1743511981901,"mc":[{"id":"1.241629436","rc":[{"atb":[[9.6,10.48]],"atl":[[1000,1.16]],"batb":[[0,9.6,10.48]],"id":27115873}]}]}
{"op":"mcm","id":2,"clk":"ANXcAQDbmwEAvsgB","pt":1743511982001,"mc":[{"id":"1.241629436","rc":[{"atl":[[1000,0.25],[12,77.7]],"batl":[[1,12,77.7]],"id":40389088},{"atb":[[1.17,2]],"id":59626646},{"atb":[[9.4,84.47],[9.6,1.62]],"trd":[[9.6,311.92]],"batb":[[1,9.4,84.47],[0,9.6,1.62]],"tv":6873.96,"id":27115873}],"tv":77672.66}]}
{"op":"mcm","id":2,"clk":"AODcAQDomwEAzsgB","pt":1743511982107,"mc":[{"id":"1.241629436","rc":[{"atl":[[11.5,3.46]],"batl":[[0,11.5,3.46]],"id":40389088},{"atb":[[50,15.41]],"batb":[[1,50,15.41]],"id":59626646},{"atl":[[10,40.89]],"batl":[[1,10,40.89]],"id":27115873},{"atl":[[7.8,13.18]],"batl":[],"id":26496185}]}]}
{"op":"mcm","id":2,"clk":"AO/cAQD8mwEA4sgB","pt":1743511982303,"mc":[{"id":"1.241629436","rc":[{"atb":[[5.1,93.65]],"trd":[[5.1,4051.9]],"batb":[[0,5.1,93.65]],"tv":13097.62,"id":56297029}],"tv":77682.66}]}
{"op":"mcm","id":2,"clk":"APjcAQCGnAEA7cgB","pt":1743511982410,"mc":[{"id":"1.241629436","rc":[{"atb":[[9.6,20.37]],"batb":[[0,9.6,20.37]],"id":27115873}]}]}
{"op":"mcm","id":2,"clk":"AITdAQCUnAEAg8kB","pt":1743511982528,"mc":[{"id":"1.241629436","rc":[{"atb":[[9.6,28.48]],"atl":[[10,34.97]],"batb":[[0,9.6,28.48]],"batl":[[1,10,34.97]],"id":27115873}]}]}
{"op":"mcm","id":2,"clk":"AIndAQCfnAEAkskB","pt":1743511982624,"mc":[{"id":"1.241629436","rc":[{"atb":[[5.1,83.43]],"trd":[[5.1,4072.34]],"batb":[[0,5.1,83.43]],"tv":13118.06,"id":56297029}],"tv":77703.1}]}
{"op":"mcm","id":2,"clk":"AI/dAQCrnAEArskB","pt":1743511982731,"mc":[{"id":"1.241629436","rc":[{"atl":[[1000,23.16]],"id":270592},{"atb":[[9.4,84.69],[8.4,59.67]],"batb":[[1,9.4,84.69]],"id":27115873}]}]}
{"op":"mcm","id":2,"clk":"AJndAQC3nAEAxckB","pt":1743511982836,"mc":[{"id":"1.241629436","rc":[{"atb":[[5.1,11.83]],"batb":[[0,5.1,11.83]],"id":56297029},{"atb":[[8,35.09]],"batb":[],"id":27115873}]}]}
{"op":"mcm","id":2,"clk":"AKXdAQDDnAEAx8kB","pt":1743511982945,"mc":[{"id":"1.241629436","rc":[{"atl":[[1000,21.16]],"id":270592},{"atb":[[9.4,72.39],[9.2,65.27]],"batb":[[2,9.2,65.27],[1,9.4,72.39]],"id":35856222},{"atb":[[1.01,104589.31]],"id":27115873}]}]}
{"op":"mcm","id":2,"clk":"AK3dAQDPnAEA08kB","pt":1743511983036,"mc":[{"id":"1.241629436","rc":[{"atb":[[9.6,9.73]],"batb":[[0,9.6,9.73]],"id":27115873}]}]}
{"op":"mcm","id":2,"clk":"AMrdAQD0nAEA9skB","pt":1743511983350,"mc":[{"id":"1.241629436","rc":[{"atb":[[6,46.63]],"id":40389088},{"atl":[[1000,23.16]],"id":270592},{"atb":[[9.2,66.63]],"batb":[[2,9.2,66.63]],"id":35856222},{"atb":[[4.7,40.5]],"batb":[],"id":56297029},{"atb":[[4.9,66.16]],"id":26496185}],"con":true}]}
{"op":"mcm","id":2,"clk":"AN3dAQCNnQEAjcoB","pt":1743511983520,"mc":[{"id":"1.241629436","rc":[{"atl":[[1000,21.16]],"id":270592}]}]}
{"op":"mcm","id":2,"clk":"AIreAQC/nQEAzsoB","pt":1743511984029,"mc":[{"id":"1.241629436","rc":[{"atb":[[11,64.23]],"trd":[[11,177.14]],"batb":[[0,11,64.23]],"tv":6355.85,"id":40389088},{"atb":[[1.1,9.84]],"id":44049799}],"tv":77704.77}]}
{"op":"mcm","id":2,"clk":"AJzeAQDWnQEA48oB","pt":1743511984191,"mc":[{"id":"1.241629436","rc":[{"atb":[[1.1,9.17]],"id":44049799}]}]}
{"op":"mcm","id":2,"clk":"ALPeAQDsnQEA+soB","pt":1743511984399,"mc":[{"id":"1.241629436","rc":[{"atb":[[1.1,9]],"id":44049799}]}]}
{"op":"mcm","id":2,"clk":"ALneAQD3nQEAh8sB","pt":1743511984517,"mc":[{"id":"1.241629436","rc":[{"atb":[[5.2,255.36],[4.9,231.56],[5,335.08],[5.1,290.22]],"atl":[[5.4,121.52],[5.3,250.32],[5.5,127.08],[5.6,169.62]],"trd":[[5.2,2082.98]],"batb":[[2,5,335.08],[1,5.1,290.22],[0,5.2,255.36]],"batl":[[2,5.5,127.08],[1,5.4,121.52],[0,5.3,250.32]],"tv":17270.55,"id":270592},{"atb":[[9.4,60.54],[9,60.58],[9.6,46.79]],"atl":[[12.5,11.73],[12,32.41],[11.5,49.31],[11,18.37],[10,106.44]],"batb":[[1,9.4,60.54],[0,9.6,46.79]],"batl":[[1,10,106.44]],"id":35856222},{"atb":[[4.9,72.72],[5,1150.82]],"atl":[[5.4,63.97],[5.2,231.85],[5.3,78.41],[5.5,93.05]],"batb":[[2,4.9,72.72],[1,5,1150.82]],"batl":[[2,5.4,63.97],[1,5.3,78.41],[0,5.2,231.85]],"id":56297029},{"atl":[[6.6,91.41],[7,37.52],[6.8,155.48],[7.4,38.43],[7.2,108.97]],"batl":[[2,7,37.52],[1,6.8,155.48],[0,6.6,91.41]],"id":26496185},{"atb":[[11,36.55]],"atl":[[13,38.41],[12.5,37.03],[12,25.32],[11.5,84.53]],"batb":[[0,11,36.55]],"batl":[[2,12.5,37.03],[1,12,25.32],[0,11.5,84.53]],"id":44049799}],"tv":77706.77}]}
{"op":"mcm","id":2,"clk":"AMLeAQCCngEAj8sB","pt":1743511984613,"mc":[{"id":"1.241629436","rc":[{"atb":[[11,73.22]],"batb":[[0,11,73.22]],"id":44049799}]}]}
{"op":"mcm","id":2,"clk":"AMneAQCJngEAncsB","pt":1743511984715,"mc":[{"id":"1.241629436","rc":[{"atl":[[5.3,216.82]],"trd":[[5.3,1617.98]],"batl":[[0,5.3,216.82]],"ltp":5.3,"tv":17337.55,"id":270592}],"tv":77773.77}]}
{"op":"mcm","id":2,"clk":"ANDeAQCSngEAqssB","pt":1743511984833,"mc":[{"id":"1.241629436","rc":[{"atb":[[5.2,289.97]],"batb":[[0,5.2,289.97]],"id":270592},{"atb":[[11,82.72]],"batb":[[0,11,82.72]],"id":44049799}]}]}
{"op":"mcm","id":2,"clk":"ANneAQCcngEArssB","pt":1743511984923,"mc":[{"id":"1.241629436","rc":[{"atl":[[5.2,209.31]],"trd":[[5.2,3655.21]],"batl":[[0,5.2,209.31]],"ltp":5.2,"tv":13163.14,"id":56297029},{"atb":[[9.6,1.62]],"batb":[[0,9.6,1.62]],"id":27115873}],"tv":77818.85}]}
{"op":"mcm","id":2,"clk":"AOfeAQCmngEAtssB","pt":1743511985031,"mc":[{"id":"1.241629436","rc":[{"atl":[[5.3,192.91]],"batl":[[0,5.3,192.91]],"id":270592},{"atb":[[5.1,76.94]],"batb":[[0,5.1,76.94]],"id":56297029},{"atl":[[10,40.88]],"batl":[[1,10,40.88]],"id":27115873}]}]}
{"op":"mcm","id":2,"clk":"APLeAQCxngEAwMsB","pt":1743511985129,"mc":[{"id":"1.241629436","rc":[{"atl":[[5.3,182.1]],"batl":[[0,5.3,182.1]],"id":270592},{"atb":[[9.8,14.86]],"atl":[[9.8,0]],"trd":[[9.8,700.87]],"batb":[[2,9.4,60.54],[1,9.6,46.79],[0,9.8,14.86]],"batl":[[2,11,18.37],[1,10.5,75.76],[0,10,106.44]],"ltp":9.8,"tv":9588.74,"id":35856222}],"tv":77843.4}]}
{"op":"mcm","id":2,"clk":"AIDfAQC+ngEAy8sB","pt":1743511985230,"mc":[{"id":"1.241629436","rc":[{"atb":[[8.4,61.26],[9.8,0],[9.2,65.27]],"trd":[[9.8,730.59]],"batb":[[2,9.2,65.27],[1,9.4,60.54],[0,9.6,46.79]],"tv":9618.46,"id":35856222},{"atb":[[9.4,84.47]],"batb":[[1,9.4,84.47]],"id":27115873}],"tv":77873.12}]}
{"op":"mcm","id":2,"clk":"AInfAQDJngEA1csB","pt":1743511985337,"mc":[{"id":"1.241629436","rc":[{"atb":[[9,59.15],[9.6,50.23]],"batb":[[0,9.6,50.23]],"id":35856222},{"atb":[[15,16.04]],"batb":[],"id":58186642}]}]}
{"op":"mcm","id":2,"clk":"AI/fAQDOngEA2csB","pt":1743511985432,"mc":[{"id":"1.241629436","rc":[{"atl":[[9.8,7.81]],"batl":[[2,10.5,75.76],[1,10,106.44],[0,9.8,7.81]],"id":35856222},{"atl":[[11.5,69.53]],"trd":[[11.5,762.15]],"batl":[[0,11.5,69.53]],"ltp":11.5,"tv":4777.45,"id":44049799}],"tv":77903.12}]}
{"op":"mcm","id":2,"clk":"AKDfAQDZngEA5ssB","pt":1743511985541,"mc":[{"id":"1.241629436","rc":[{"atl":[[11.5,90.43]],"batl":[[0,11.5,90.43]],"id":44049799}]}]}
{"op":"mcm","id":2,"clk":"AK/fAQDingEA7MsB","pt":1743511985643,"mc":[{"id":"1.241629436","rc":[{"atb":[[9.2,66.63],[9,60.58]],"atl":[[9.8,6.43]],"trd":[[9.8,733.34]],"batb":[[2,9.2,66.63]],"batl":[[0,9.8,6.43]],"tv":9621.21,"id":35856222},{"atb":[[5.1,73.99]],"trd":[[5.1,4078.25]],"batb":[[0,5.1,73.99]],"ltp":5.1,"tv":13169.05,"id":56297029},{"atl":[[9.8,79.73]],"trd":[[9.8,336.14]],"batl":[[0,9.8,79.73]],"ltp":9.8,"tv":6876.5,"id":27115873}],"tv":77914.32}]}
{"op":"mcm","id":2,"clk":"AMXfAQD1ngEAhcwB","pt":1743511985810,"mc":[{"id":"1.241629436","rc":[{"atb":[[5.1,8.88]],"batb":[[0,5.1,8.88]],"id":56297029}]}]}
{"op":"mcm","id":2,"clk":"ANDfAQD8ngEAjMwB","pt":1743511985922,"mc":[{"id":"1.241629436","rc":[{"atb":[[5.1,8.78]],"trd":[[5.1,4078.45]],"batb":[[0,5.1,8.78]],"tv":13169.25,"id":56297029}],"tv":77914.52}]}
{"op":"mcm","id":2,"clk":"ANzfAQCDnwEAlswB","pt":1743511986018,"mc":[{"id":"1.241629436","rc":[{"atb":[[5.1,10.69]],"batb":[[0,5.1,10.69]],"id":56297029}]}]}
{"op":"mcm","id":2,"clk":"AOPfAQCLnwEAncwB","pt":1743511986116,"mc":[{"id":"1.241629436","rc":[{"atb":[[5.1,23.86]],"batb":[[0,5.1,23.86]],"id":56297029}]}]}
{"op":"mcm","id":2,"clk":"AP7fAQCfnwEArswB","pt":1743511986326,"mc":[{"id":"1.241629436","rc":[{"atb":[[11,66.23],[10.5,32.55]],"batb":[[1,10.5,32.55],[0,11,66.23]],"id":40389088},{"atb":[[5.2,314.97]],"batb":[[0,5.2,314.97]],"id":270592},{"atb":[[55,22.48],[50,18.41]],"batb":[[1,50,18.41],[0,55,22.48]],"id":59626646},{"atb":[[4.9,78.72],[5,1156.82],[5.1,49.29],[4.8,153.55]],"batb":[[2,4.9,78.72],[1,5,1156.82],[0,5.1,49.29]],"id":56297029},{"atb":[[9.4,85.47]],"batb":[[1,9.4,85.47]],"id":27115873},{"atb":[[16.5,22.32]],"batb":[[0,16.5,22.32]],"id":58186642},{"atb":[[5.9,103.79]],"batb":[],"id":26496185},{"atb":[[9.8,34.4],[11,94.72],[10,80.5]],"batb":[[2,10,80.5],[0,11,94.72]],"id":44049799}]}]}
{"op":"mcm","id":2,"clk":"AI3gAQConwEAvMwB","pt":1743511986430,"mc":[{"id":"1.241629436","rc":[{"atb":[[9.2,65.29],[9,59.58]],"batb":[[2,9.2,65.29]],"id":35856222}]}]}
{"op":"mcm","id":2,"clk":"AKLgAQDDnwEA08wB","pt":1743511986633,"mc":[{"id":"1.241629436","rc":[{"atb":[[9.6,0]],"trd":[[9.6,315.16]],"batb":[[2,9,44.46],[1,9.2,42.76],[0,9.4,85.47]],"ltp":9.6,"tv":6879.74,"id":27115873}],"tv":77917.76}]}
{"op":"mcm","id":2,"clk":"ALPgAQDTnwEA3MwB","pt":1743511986733,"mc":[{"id":"1.241629436","rc":[{"atb":[[5.1,108.02]],"batb":[[0,5.1,108.02]],"id":56297029}]}]}
{"op":"mcm","id":2,"clk":"ALvgAQDfnwEA5cwB","pt":1743511986831,"mc":[{"id":"1.241629436","rc":[{"atl":[[12,82.7]],"batl":[[1,12,82.7]],"id":40389088},{"atb":[[9.6,64.23]],"batb":[[0,9.6,64.23]],"id":35856222}]}]}
{"op":"mcm","id":2,"clk":"AMjgAQDvnwEA68wB","pt":1743511986938,"mc":[{"id":"1.241629436","rc":[{"atl":[[10,34.97]],"batl":[[1,10,34.97]],"id":27115873}]}]}
{"op":"mcm","id":2,"clk":"AKjhAQDPoAEAvM0B","pt":1743511987623,"mc":[{"id":"1.241629436","rc":[{"atl":[[1000,0.56],[11.5,3.35]],"batl":[[0,11.5,3.35]],"id":40389088},{"atb":[[50,17.7]],"atl":[[65,14.3]],"batb":[[1,50,17.7]],"batl":[[0,65,14.3]],"id":59626646},{"atb":[[5.1,106.53]],"batb":[[0,5.1,106.53]],"id":56297029},{"atl":[[17,9.78]],"batl":[[0,17,9.78]],"id":58186642}]}]}
{"op":"mcm","id":2,"clk":"AK/hAQDaoAEA2c0B","pt":1743511987732,"mc":[{"id":"1.241629436","rc":[{"atl":[[5.3,181.35]],"trd":[[5.3,1619.48]],"batl":[[0,5.3,181.35]],"tv":17339.05,"id":270592},{"atb":[[48,4.86]],"batb":[[2,48,4.86]],"id":59626646},{"atl":[[5.2,208.73]],"trd":[[5.2,3656.37]],"batl":[[0,5.2,208.73]],"ltp":5.2,"tv":13170.41,"id":56297029},{"atb":[[9.4,85.69]],"batb":[[0,9.4,85.69]],"id":27115873},{"atl":[[6.6,90.96]],"trd":[[6.6,1910.11]],"batl":[[0,6.6,90.96]],"ltp":6.6,"tv":12424.94,"id":26496185}],"tv":77921.32}]}
{"op":"mcm","id":2,"clk":"AL3hAQDqoAEA5s0B","pt":1743511987834,"mc":[{"id":"1.241629436","rc":[{"atl":[[1000,0.25]],"id":40389088},{"atl":[[11.5,80.43]],"trd":[[11.5,782.15]],"batl":[[0,11.5,80.43]],"tv":4797.45,"id":44049799}],"tv":77941.32}]}
{"op":"mcm","id":2,"clk":"AMfhAQDzoAEA980B","pt":1743511987937,"mc":[{"id":"1.241629436","rc":[{"atl":[[12,82.91],[11.5,3.45]],"batl":[[1,12,82.91],[0,11.5,3.45]],"id":40389088},{"atb":[[55,2.48]],"trd":[[55,196.62]],"batb":[[0,55,2.48]],"tv":1804.03,"id":59626646},{"atl":[[11.5,77.32]],"batl":[[0,11.5,77.32]],"id":44049799}],"tv":77981.32}]}
{"op":"mcm","id":2,"clk":"ANnhAQD3oAEA/M0B","pt":1743511988040,"mc":[{"id":"1.241629436","rc":[{"atb":[[11,71.23]],"batb":[[0,11,71.23]],"id":40389088},{"atb":[[16.5,18.32]],"trd":[[16.5,584.98]],"batb":[[0,16.5,18.32]],"tv":5596.64,"id":58186642}],"tv":77989.32}]}
{"op":"mcm","id":2,"clk":"AOfhAQCHoQEAhc4B","pt":1743511988143,"mc":[{"id":"1.241629436","rc":[{"atl":[[12,77.91]],"batl":[[1,12,77.91]],"id":40389088},{"atl":[[1000,23.16]],"id":270592},{"atb":[[55,14.01],[50,19.37]],"atl":[[60,1.89],[65,17.06]],"batb":[[1,50,19.37],[0,55,14.01]],"batl":[[2,70,5.42],[1,65,17.06],[0,60,1.89]],"id":59626646}]}]}
{"op":"mcm","id":2,"clk":"APDhAQCRoQEAks4B","pt":1743511988242,"mc":[{"id":"1.241629436","rc":[{"atb":[[55,15.46],[50,18.67]],"batb":[[1,50,18.67],[0,55,15.46]],"id":59626646}]}]}
{"op":"mcm","id":2,"clk":"AIDiAQCfoQEAmc4B","pt":1743511988353,"mc":[{"id":"1.241629436","rc":[{"atl":[[12,82.91]],"batl":[[1,12,82.91]],"id":40389088},{"atl":[[1000,21.16]],"id":270592},{"atb":[[29,3.92]],"id":59626646},{"atb":[[16.5,23.81]],"batb":[[0,16.5,23.81]],"id":58186642}]}]}
{"op":"mcm","id":2,"clk":"AIziAQCkoQEAoM4B","pt":1743511988401,"mc":[{"id":"1.241629436","rc":[{"atl":[[9.6,1]],"batl":[[2,10,34.97],[1,9.8,79.73],[0,9.6,1]],"id":27115873}]}]}
{"op":"mcm","id":2,"clk":"AJriAQCwoQEAr84B","pt":1743511988517,"mc":[{"id":"1.241629436","rc":[{"atl":[[5.3,192.1],[5.6,167.64]],"batl":[[0,5.3,192.1]],"id":270592},{"atl":[[9.6,0]],"trd":[[9.6,317.16]],"batl":[[2,10.5,66.05],[1,10,34.97],[0,9.8,79.73]],"tv":6881.74,"id":27115873}],"tv":77991.32}]}
{"op":"mcm","id":2,"clk":"AKPiAQC8oQEAtM4B","pt":1743511988617,"mc":[{"id":"1.241629436","rc":[{"atb":[[8.4,61.9]],"batb":[],"id":35856222},{"atl":[[9.6,8.14]],"batl":[[2,10,34.97],[1,9.8,79.73],[0,9.6,8.14]],"id":27115873}]}]}
{"op":"mcm","id":2,"clk":"ALbiAQDLoQEAys4B","pt":1743511988729,"mc":[{"id":"1.241629436","rc":[{"atl":[[1000,23.16],[5.6,169.62]],"batl":[],"id":270592},{"atb":[[8.2,14.55],[8,48.86]],"batb":[],"id":35856222},{"atb":[[55,8.24]],"batb":[[0,55,8.24]],"id":59626646}]}]}
{"op":"mcm","id":2,"clk":"AMLiAQDZoQEAz84B","pt":1743511988824,"mc":[{"id":"1.241629436","rc":[{"atb":[[7.8,30.58],[7.6,46.5]],"batb":[],"id":35856222}]}]}
{"op":"mcm","id":2,"clk":"ANDiAQDjoQEA1M4B","pt":1743511988930,"mc":[{"id":"1.241629436","rc":[{"atl":[[1000,21.16],[5.3,181.35],[5.6,167.64]],"batl":[[0,5.3,181.35]],"id":270592},{"atb":[[7.4,20.95],[7.2,25.92]],"id":35856222},{"atl":[[9.6,0]],"batl":[[2,10.5,66.05],[1,10,34.97],[0,9.8,79.73]],"id":27115873}]}]}
{"op":"mcm","id":2,"clk":"AOLiAQDsoQEA3c4B","pt":1743511989032,"mc":[{"id":"1.241629436","rc":[{"atb":[[6.6,9.51],[7,38.08],[6.8,44.32]],"id":35856222}]}]}
{"op":"mcm","id":2,"clk":"AOviAQD7oQEA6M4B","pt":1743511989138,"mc":[{"id":"1.241629436","rc":[{"atl":[[5.6,169.62]],"batl":[],"id":270592},{"atb":[[6.2,21.23],[6.4,23.07]],"id":35856222}]}]}
{"op":"mcm","id":2,"clk":"AIDjAQCTogEA8c4B","pt":1743511989338,"mc":[{"id":"1.241629436","rc":[{"atb":[[9.8,1.57]],"atl":[[9.8,0]],"trd":[[9.8,746.2]],"batb":[[2,9.4,60.54],[1,9.6,64.23],[0,9.8,1.57]],"batl":[[2,11,18.37],[1,10.5,75.76],[0,10,106.44]],"tv":9634.07,"id":35856222},{"atb":[[9.4,78.16]],"trd":[[9.4,134.45]],"batb":[[0,9.4,78.16]],"ltp":9.4,"tv":6896.8,"id":27115873},{"atl":[[11.5,74.12]],"trd":[[11.5,788.55]],"batl":[[0,11.5,74.12]],"tv":4803.85,"id":44049799}],"tv":78025.64}]}
{"op":"mcm","id":2,"clk":"AIrjAQCbogEAgc8B","pt":1743511989438,"mc":[{"id":"1.241629436","rc":[{"atl":[[12,77.91]],"batl":[[1,12,77.91]],"id":40389088},{"atl":[[17.5,13.68]],"batl":[[1,17.5,13.68]],"id":58186642}]}]}
{"op":"mcm","id":2,"clk":"AJDjAQCjogEAjs8B","pt":1743511989540,"mc":[{"id":"1.241629436","rc":[{"atb":[[9.2,63.93]],"batb":[],"id":35856222},{"atb":[[5.1,105.69]],"trd":[[5.1,4080.13]],"batb":[[0,5.1,105.69]],"ltp":5.1,"tv":13172.09,"id":56297029},{"atl":[[9.6,8.4]],"batl":[[2,10,34.97],[1,9.8,79.73],[0,9.6,8.4]],"id":27115873},{"atb":[[6.2,174.28]],"batb":[[1,6.2,174.28]],"id":26496185}],"tv":78027.32}]}
{"op":"mcm","id":2,"clk":"AKnjAQDHogEAoM8B","pt":1743511989748,"mc":[{"id":"1.241629436","rc":[{"atb":[[9.4,62.5]],"batb":[[0,9.4,62.5]],"id":27115873}]}]}
{"op":"mcm","id":2,"clk":"AMHjAQDsogEAvs8B","pt":1743511990022,"mc":[{"id":"1.241629436","rc":[{"atl":[[6.6,100.96]],"batl":[[0,6.6,100.96]],"id":26496185}]}]}
{"op":"mcm","id":2,"clk":"AMvjAQD6ogEAxs8B","pt":1743511990115,"mc":[{"id":"1.241629436","rc":[{"atb":[[9.4,61.84],[9.2,65.29]],"batb":[[2,9.4,61.84]],"id":35856222},{"atb":[[55,8.27]],"batb":[[0,55,8.27]],"id":59626646}]}]}
{"op":"mcm","id":2,"clk":"AOTjAQCRowEA1s8B","pt":1743511990326,"mc":[{"id":"1.241629436","rc":[{"atl":[[65,16.9]],"batl":[[1,65,16.9]],"id":59626646}]}]}
{"op":"mcm","id":2,"clk":"APnjAQCuowEA7s8B","pt":1743511990535,"mc":[{"id":"1.241629436","rc":[{"atl":[[1000,23.16]],"id":270592},{"atb":[[8.4,61.26],[6.6,5.65],[7.8,29.39],[7,35.4],[7.6,45.03],[6.8,41.1],[7.4,19.14],[8.2,13.77],[6.2,15.82],[6.4,18.49],[7.2,23.71],[8,47.9]],"batb":[],"id":35856222}]}]}
{"op":"mcm","id":2,"clk":"AIjkAQDDowEA9c8B","pt":1743511990639,"mc":[{"id":"1.241629436","rc":[{"atb":[[1.17,2.67]],"id":40389088},{"atb":[[5.2,318.2]],"atl":[[1000,23.84]],"batb":[[0,5.2,318.2]],"id":270592},{"atb":[[1.17,8.11]],"atl":[[1000,0.61]],"id":35856222},{"atb":[[9.4,64.06]],"batb":[[0,9.4,64.06]],"id":27115873}]}]}
{"op":"mcm","id":2,"clk":"AJLkAQDOowEAgtAB","pt":1743511990742,"mc":[{"id":"1.241629436","rc":[{"atb":[[1.17,2]],"id":40389088},{"atl":[[1000,21.84]],"id":270592},{"atb":[[9.4,66.31],[1.17,7.15]],"batb":[[2,9.4,66.31]],"id":35856222},{"atl":[[11.5,64.83]],"batl":[[0,11.5,64.83]],"id":44049799}]}]}
{"op":"mcm","id":2,"clk":"AKDkAQDeowEAi9AB","pt":1743511990850,"mc":[{"id":"1.241629436","rc":[{"atb":[[11,71.9]],"batb":[[0,11,71.9]],"id":40389088},{"atl":[[1000,21.16]],"id":270592},{"atb":[[9.6,65.19]],"atl":[[1000,0.41]],"batb":[[1,9.6,65.19]],"id":35856222},{"atb":[[55,9.74]],"batb":[[0,55,9.74]],"id":59626646}]}]}
{"op":"mcm","id":2,"clk":"AKjkAQDlowEAj9AB","pt":1743511990942,"mc":[{"id":"1.241629436","rc":[{"atl":[[5.4,122.2]],"batl":[[1,5.4,122.2]],"id":270592},{"atb":[[9.8,1.19],[9.6,66.43]],"atl":[[10,106.64]],"trd":[[9.8,749.34]],"batb":[[1,9.6,66.43],[0,9.8,1.19]],"batl":[[0,10,106.64]],"tv":9637.21,"id":35856222}],"tv":78030.46}]}
{"op":"mcm","id":2,"clk":"ALPkAQDwowEAmNAB","pt":1743511991043,"mc":[{"id":"1.241629436","rc":[{"atl":[[1000,0.37]],"id":40389088},{"atb":[[5.1,101.59]],"trd":[[5.1,4088.33]],"batb":[[0,5.1,101.59]],"tv":13180.29,"id":56297029}],"tv":78038.66}]}
{"op":"mcm","id":2,"clk":"AM/kAQCEpAEAq9AB","pt":1743511991212,"mc":[{"id":"1.241629436","rc":[{"atb":[[11,70.22]],"atl":[[1000,0.25]],"batb":[[0,11,70.22]],"id":40389088},{"atl":[[60,0],[65,2.03]],"trd":[[60,357.75],[65,216.06]],"batl":[[2,75,5.07],[1,70,5.42],[0,65,2.03]],"ltp":65,"tv":1837.55,"id":59626646},{"atb":[[5.1,99.24]],"batb":[[0,5.1,99.24]],"id":56297029}],"tv":78072.18}]}
{"op":"mcm","id":2,"clk":"ANvkAQCOpAEAsNAB","pt":1743511991312,"mc":[{"id":"1.241629436","rc":[{"atl":[[12,78.03],[11.5,9.66]],"batl":[[1,12,78.03],[0,11.5,9.66]],"id":40389088},{"atb":[[60,3.63],[55,13.01]],"atl":[[65,30.39]],"batb":[[2,50,18.67],[1,55,13.01],[0,60,3.63]],"batl":[[0,65,30.39]],"id":59626646},{"atb":[[9.4,60.57]],"batb":[[0,9.4,60.57]],"id":27115873}]}]}
{"op":"mcm","id":2,"clk":"AOnkAQCcpAEAvdAB","pt":1743511991423,"mc":[{"id":"1.241629436","rc":[{"atb":[[9.8,0]],"trd":[[9.8,751.72]],"batb":[[2,9.2,65.29],[1,9.4,66.31],[0,9.6,66.43]],"tv":9639.59,"id":35856222},{"atb":[[55,11.81]],"atl":[[65,32.94]],"batb":[[1,55,11.81]],"batl":[[0,65,32.94]],"id":59626646}],"tv":78074.56}]}
{"op":"mcm","id":2,"clk":"APXkAQCfpAEAxtAB","pt":1743511991523,"mc":[{"id":"1.241629436","rc":[{"atl":[[12,80.33],[11.5,20.98]],"batl":[[1,12,80.33],[0,11.5,20.98]],"id":40389088},{"atb":[[60,1.2]],"trd":[[60,360.05]],"batb":[[0,60,1.2]],"ltp":60,"tv":1839.85,"id":59626646}],"tv":78076.86}]}
{"op":"mcm","id":2,"clk":"APvkAQCspAEAytAB","pt":1743511991623,"mc":[{"id":"1.241629436","rc":[{"atl":[[5.6,167.64]],"batl":[],"id":270592},{"atb":[[9.6,65.19]],"atl":[[9.8,8.79]],"batb":[[0,9.6,65.19]],"batl":[[2,10.5,75.76],[1,10,106.64],[0,9.8,8.79]],"id":35856222},{"atb":[[60,0.79]],"trd":[[60,360.87]],"batb":[[2,48,4.86],[1,50,18.67],[0,55,12.6]],"tv":1840.67,"id":59626646}],"tv":78077.68}]}
{"op":"mcm","id":2,"clk":"AIPlAQC2pAEA4NAB","pt":1743511991731,"mc":[{"id":"1.241629436","rc":[{"atl":[[12,85.34]],"batl":[[1,12,85.34]],"id":40389088},{"atb":[[9.6,66.43]],"atl":[[9.8,7.6]],"trd":[[9.8,754.1]],"batb":[[0,9.6,66.43]],"batl":[[0,9.8,7.6]],"tv":9641.97,"id":35856222}],"tv":78080.06}]}
{"op":"mcm","id":2,"clk":"AIrlAQDFpAEA6NAB","pt":1743511991836,"mc":[{"id":"1.241629436","rc":[{"atb":[[55,13.44]],"batb":[[0,55,14.23]],"id":59626646}]}]}
{"op":"mcm","id":2,"clk":"AJLlAQDRpAEA+dAB","pt":1743511991944,"mc":[{"id":"1.241629436","rc":[{"atb":[[9.4,61.84]],"batb":[[1,9.4,61.84]],"id":35856222}]}]}
{"op":"mcm","id":2,"clk":"AJrlAQDXpAEAgtEB","pt":1743511992044,"mc":[{"id":"1.241629436","rc":[{"atl":[[9.8,4.16]],"trd":[[9.8,760.98]],"batl":[[0,9.8,4.16]],"tv":9648.85,"id":35856222}],"tv":78086.94}]}
{"op":"mcm","id":2,"clk":"AKHlAQDdpAEAidEB","pt":1743511992148,"mc":[{"id":"1.241629436","rc":[{"atb":[[9.4,60.54],[9.6,65.19]],"batb":[[1,9.4,60.54],[0,9.6,65.19]],"id":35856222}]}]}
{"op":"mcm","id":2,"clk":"ALDlAQDzpAEAm9EB","pt":1743511992309,"mc":[{"id":"1.241629436","rc":[{"atb":[[9.4,61.84],[9.6,66.43]],"batb":[[1,9.4,61.84],[0,9.6,66.43]],"id":35856222}]}]}
{"op":"mcm","id":2,"clk":"AMXlAQCGpQEAr9EB","pt":1743511992529,"mc":[{"id":"1.241629436","rc":[{"atb":[[9.4,60.54],[9.6,65.19]],"batb":[[1,9.4,60.54],[0,9.6,65.19]],"id":35856222},{"atb":[[6.4,260.57]],"batb":[[0,6.4,260.57]],"id":26496185}]}]}
{"op":"mcm","id":2,"clk":"AMzlAQCMpQEAutEB","pt":1743511992627,"mc":[{"id":"1.241629436","rc":[{"atl":[[9.8,2.36]],"trd":[[9.8,764.58]],"batl":[[0,9.8,2.36]],"tv":9652.45,"id":35856222}],"tv":78090.54}]}
{"op":"mcm","id":2,"clk":"ANvlAQCbpQEAwdEB","pt":1743511992734,"mc":[{"id":"1.241629436","rc":[{"atl":[[11.5,65.83]],"batl":[[0,11.5,65.83]],"id":44049799}]}]}
{"op":"mcm","id":2,"clk":"AOPlAQChpQEAyNEB","pt":1743511992837,"mc":[{"id":"1.241629436","rc":[{"atl":[[9.8,0]],"batl":[[2,11,18.37],[1,10.5,75.76],[0,10,106.64]],"id":35856222},{"atl":[[65,33.09]],"batl":[[0,65,33.09]],"id":59626646}]}]}
{"op":"mcm","id":2,"clk":"APTlAQCppQEA1NEB","pt":1743511992938,"mc":[{"id":"1.241629436","rc":[{"atb":[[5.1,79.24]],"trd":[[5.1,4128.33]],"batb":[[0,5.1,79.24]],"tv":13220.29,"id":56297029}],"tv":78130.54}]}
{"op":"mcm","id":2,"clk":"AIDmAQC0pQEA4NEB","pt":1743511993051,"mc":[{"id":"1.241629436","rc":[{"atl":[[5.6,169.62]],"batl":[],"id":270592},{"atb":[[9.2,63.93],[9,58.15]],"batb":[[2,9.2,63.93]],"id":35856222},{"atb":[[16.5,22.81]],"trd":[[16.5,586.98]],"batb":[[0,16.5,22.81]],"tv":5598.64,"id":58186642}],"tv":78132.54}]}
{"op":"mcm","id":2,"clk":"AJDmAQC9pQEA69EB","pt":1743511993106,"mc":[{"id":"1.241629436","rc":[{"atb":[[5.1,20.51]],"batb":[[0,5.1,20.51]],"id":56297029}]}]}
{"op":"mcm","id":2,"clk":"AKDmAQDFpQEAgtIB","pt":1743511993220,"mc":[{"id":"1.241629436","rc":[{"atl":[[12,80.33]],"batl":[[1,12,80.33]],"id":40389088},{"atb":[[16.5,24.56]],"batb":[[0,16.5,24.56]],"id":58186642}]}]}
{"op":"mcm","id":2,"clk":"AKvmAQDNpQEAjdIB","pt":1743511993319,"mc":[{"id":"1.241629436","rc":[{"atb":[[15,19.39]],"atl":[[17,7.09]],"batb":[],"batl":[[0,17,7.09]],"id":58186642},{"atb":[[6.4,261.8]],"batb":[[0,6.4,261.8]],"id":26496185}]}]}
{"op":"mcm","id":2,"clk":"AL3mAQDppQEAoNIB","pt":1743511993528,"mc":[{"id":"1.241629436","rc":[{"atb":[[9.6,35.19]],"trd":[[9.6,593.29]],"batb":[[0,9.6,35.19]],"ltp":9.6,"tv":9712.45,"id":35856222}],"tv":78192.54}]}
{"op":"mcm","id":2,"clk":"AMnmAQD3pQEAr9IB","pt":1743511993646,"mc":[{"id":"1.241629436","rc":[{"atb":[[11,69.55]],"atl":[[12,80.12],[11.5,20.88]],"batb":[[0,11,69.55]],"batl":[[1,12,80.12],[0,11.5,20.88]],"id":40389088},{"atb":[[5.2,314.97]],"atl":[[5.4,121.52]],"batb":[[0,5.2,314.97]],"batl":[[1,5.4,121.52]],"id":270592},{"atb":[[9.6,31.75]],"atl":[[9.8,9.54],[10,106.44]],"batb":[[0,9.6,31.75]],"batl":[[2,10.5,75.76],[1,10,106.44],[0,9.8,9.54]],"id":35856222},{"atb":[[60,0],[55,11.72]],"trd":[[60,362.45],[55,200.06]],"batb":[[0,55,11.72]],"ltp":55,"tv":1845.69,"id":59626646},{"atl":[[5.3,77.9]],"batl":[[1,5.3,77.9]],"id":56297029},{"atl":[[1000,1.31],[10,34.75]],"batl":[[2,10,34.75]],"id":27115873},{"atb":[[6.4,260.43]],"batb":[[0,6.4,260.43]],"id":26496185},{"atl":[[1000,19.1]],"id":44049799}],"tv":78197.56}]}
{"op":"mcm","id":2,"clk":"ANPmAQCEpgEAtNIB","pt":1743511993742,"mc":[{"id":"1.241629436","rc":[{"atb":[[9.2,65.29],[9,59.58],[9.6,41.55]],"batb":[[2,9.2,65.29],[0,9.6,41.55]],"id":35856222},{"atl":[[1000,1.16]],"id":27115873},{"atl":[[1000,18.87]],"id":44049799}]}]}
{"op":"mcm","id":2,"clk":"AOPmAQCQpgEAwdIB","pt":1743511993847,"mc":[{"id":"1.241629436","rc":[{"atl":[[5.6,167.64]],"batl":[],"id":270592},{"atb":[[9.4,54.55]],"atl":[[9.8,12.73]],"batb":[[1,9.4,54.55]],"batl":[[0,9.8,12.73]],"id":35856222},{"atb":[[55,22.79]],"batb":[[0,55,22.79]],"id":59626646},{"atl":[[9.8,79.88]],"batl":[[1,9.8,79.88]],"id":27115873},{"atl":[[11.5,66.06]],"batl":[[0,11.5,66.06]],"id":44049799}]}]}
{"op":"mcm","id":2,"clk":"AOrmAQCapgEAzNIB","pt":1743511993950,"mc":[{"id":"1.241629436","rc":[{"atb":[[55,25.79]],"batb":[[0,55,25.79]],"id":59626646}]}]}
{"op":"mcm","id":2,"clk":"APTmAQCmpgEA1dIB","pt":1743511994058,"mc":[{"id":"1.241629436","rc":[{"atb":[[9.4,55.85]],"batb":[[1,9.4,55.85]],"id":35856222}]}]}
{"op":"mcm","id":2,"clk":"AP3mAQCspgEA29IB","pt":1743511994105,"mc":[{"id":"1.241629436","rc":[{"atl":[[1000,23.16]],"id":270592}]}]}
{"op":"mcm","id":2,"clk":"AJnnAQC/pgEA9tIB","pt":1743511994320,"mc":[{"id":"1.241629436","rc":[{"atl":[[1000,21.16]],"id":270592}]}]}
{"op":"mcm","id":2,"clk":"AKvnAQDSpgEAitMB","pt":1743511994525,"mc":[{"id":"1.241629436","rc":[{"atb":[[4.7,47.5]],"batb":[],"id":56297029}]}]}
{"op":"mcm","id":2,"clk":"ALLnAQDcpgEAktMB","pt":1743511994632,"mc":[{"id":"1.241629436","rc":[{"atb":[[9.4,54.55],[9.2,63.93]],"batb":[[2,9.2,63.93],[1,9.4,54.55]],"id":35856222}]}]}
{"op":"mcm","id":2,"clk":"AMPnAQDxpgEAq9MB","pt":1743511994841,"mc":[{"id":"1.241629436","rc":[{"atb":[[8.4,62.02],[8.6,24.53]],"batb":[],"id":35856222},{"atl":[[10,41.72]],"batl":[[2,10,41.72]],"id":27115873},{"atb":[[6.4,251.26]],"trd":[[6.4,3611.68]],"batb":[[0,6.4,251.26]],"ltp":6.4,"tv":12443.28,"id":26496185}],"tv":78215.9}]}
{"op":"mcm","id":2,"clk":"AM/nAQD5pgEAsNMB","pt":1743511994932,"mc":[{"id":"1.241629436","rc":[{"atb":[[8.2,14.7],[8,49.05]],"batb":[],"id":35856222},{"atb":[[1.01,41742.97]],"id":59626646}]}]}
{"op":"mcm","id":2,"clk":"ANnnAQCDpwEAvdMB","pt":1743511995045,"mc":[{"id":"1.241629436","rc":[{"atb":[[7.8,30.81],[7.6,46.78],[7.4,21.28]],"batb":[],"id":35856222},{"atb":[[55,18.41]],"batb":[[0,55,18.41]],"id":59626646},{"atl":[[1000,19.87]],"id":44049799}]}]}
{"op":"mcm","id":2,"clk":"AOLnAQCPpwEAx9MB","pt":1743511995154,"mc":[{"id":"1.241629436","rc":[{"atb":[[7,38.52],[7.2,26.3]],"id":35856222}]}]}
{"op":"mcm","id":2,"clk":"APDnAQCYpwEAztMB","pt":1743511995247,"mc":[{"id":"1.241629436","rc":[{"atb":[[6.6,10.07],[6.8,44.82]],"id":35856222}]}]}
{"op":"mcm","id":2,"clk":"APnnAQCepwEA2dMB","pt":1743511995352,"mc":[{"id":"1.241629436","rc":[{"atb":[[6.4,23.7]],"id":35856222}]}]}
{"op":"mcm","id":2,"clk":"AJroAQCzpwEA9NMB","pt":1743511995643,"mc":[{"id":"1.241629436","rc":[{"atb":[[5.1,73.59]],"trd":[[5.1,4134.23]],"batb":[[0,5.1,73.59]],"tv":13226.19,"id":56297029}],"tv":78221.8}]}
{"op":"mcm","id":2,"clk":"ALzoAQDGpwEAjdQB","pt":1743511995929,"mc":[{"id":"1.241629436","rc":[{"atl":[[1000,23.16]],"id":270592}]}]}
{"op":"mcm","id":2,"clk":"AM3oAQDZpwEAl9QB","pt":1743511996128,"mc":[{"id":"1.241629436","rc":[{"atl":[[1000,21.16]],"id":270592}]}]}
{"op":"mcm","id":2,"clk":"AIPpAQCFqAEAytQB","pt":1743511996654,"mc":[{"id":"1.241629436","rc":[{"atb":[[55,18.69]],"atl":[[65,34.71]],"batb":[[0,55,18.69]],"batl":[[0,65,34.71]],"id":59626646},{"atb":[[11,96.23]],"atl":[[1000,20.18]],"batb":[[0,11,96.23]],"id":44049799}]}]}
{"op":"mcm","id":2,"clk":"AInpAQCOqAEAzdQB","pt":1743511996704,"mc":[{"id":"1.241629436","rc":[{"atl":[[1000,19.87]],"id":44049799}]}]}
{"op":"mcm","id":2,"clk":"AJfpAQCrqAEA09QB","pt":1743511996819,"mc":[{"id":"1.241629436","rc":[{"atb":[[9.2,65.29]],"batb":[[2,9.2,65.29]],"id":35856222},{"atb":[[60,0.06]],"batb":[[0,55,18.75]],"id":59626646},{"atl":[[12,25.63]],"batl":[[1,12,25.63]],"id":44049799}]}]}
{"op":"mcm","id":2,"clk":"ANfpAQDkqAEAltUB","pt":1743511997144,"mc":[{"id":"1.241629436","rc":[{"atb":[[9.2,23.67]],"batb":[],"id":44049799}]}]}
{"op":"mcm","id":2,"clk":"AMrqAQDuqQEAkNYB","pt":1743511997385,"mc":[{"id":"1.241629436","rc":[{"atb":[[11,78.5]],"batb":[[0,11,78.5]],"id":40389088},{"atb":[[5.2,333.9]],"batb":[[0,5.2,333.9]],"id":270592},{"atb":[[9.6,51.8]],"batb":[[0,9.6,51.8]],"id":35856222},{"atb":[[55,20.48]],"batb":[[0,55,20.54]],"id":59626646},{"atb":[[5.1,92.89]],"batb":[[0,5.1,92.89]],"id":56297029},{"atb":[[9.4,71.04]],"batb":[[0,9.4,71.04]],"id":27115873},{"atb":[[16.5,30.53]],"batb":[[0,16.5,30.53]],"id":58186642},{"atb":[[6.4,266.64]],"batb":[[0,6.4,266.64]],"id":26496185},{"atb":[[11,105.18]],"batb":[[0,11,105.18]],"id":44049799}]}]}
{"op":"mcm","id":2,"clk":"AJbrAQCjqgEAxtYB","pt":1743511997453,"mc":[{"id":"1.241629436","rc":[{"atl":[[12,80]],"batl":[[1,12,80]],"id":40389088},{"atb":[[5.1,96.19]],"batb":[[0,5.1,96.19]],"id":56297029},{"atb":[[6.4,318.49]],"batb":[[0,6.4,318.49]],"id":26496185}]}]}
{"op":"mcm","id":2,"clk":"AM/rAQDTqgEA79YB","pt":1743511997569,"mc":[{"id":"1.241629436","rc":[{"atl":[[11.5,15.06]],"trd":[[11.5,1196.29]],"batl":[[0,11.5,15.06]],"ltp":11.5,"tv":6367.49,"id":40389088}],"tv":78233.44}]}
{"op":"mcm","id":2,"clk":"APvrAQCFqwEAq9cB","pt":1743511997744,"mc":[{"id":"1.241629436","rc":[{"atl":[[11.5,0]],"batl":[[2,13,19.71],[1,12.5,60.31],[0,12,80]],"id":40389088}]}]}
{"op":"mcm","id":2,"clk":"AJTsAQCkqwEAt9cB","pt":1743511997859,"mc":[{"id":"1.241629436","rc":[{"atb":[[5.1,281.68]],"batb":[[1,5.1,281.68]],"id":270592}]}]}
{"op":"mcm","id":2,"clk":"AKfsAQCzqwEAxdcB","pt":1743511997951,"mc":[{"id":"1.241629436","rc":[{"atb":[[10.5,31.55]],"batb":[[1,10.5,31.55]],"id":40389088},{"atl":[[5.6,169.62]],"batl":[],"id":270592}]}]}
{"op":"mcm","id":2,"clk":"AL/sAQDNqwEA3NcB","pt":1743511998019,"mc":[{"id":"1.241629436","rc":[{"atb":[[5.1,290.22]],"batb":[[1,5.1,290.22]],"id":270592}]}]}
{"op":"mcm","id":2,"clk":"ANTsAQDkqwEA8NcB","pt":1743511998126,"mc":[{"id":"1.241629436","rc":[{"atb":[[11.5,1.09]],"batb":[[2,10.5,31.55],[1,11,78.5],[0,11.5,1.09]],"id":40389088},{"atb":[[9.6,13.6]],"atl":[[9.6,0]],"trd":[[9.6,333.96]],"batb":[[2,9.2,42.76],[1,9.4,71.04],[0,9.6,13.6]],"batl":[[2,10.5,66.05],[1,10,41.72],[0,9.8,79.88]],"ltp":9.6,"tv":6913.6,"id":27115873}],"tv":78250.24}]}
{"op":"mcm","id":2,"clk":"AOPsAQD1qwEAidgB","pt":1743511998232,"mc":[{"id":"1.241629436","rc":[{"atb":[[11.5,0]],"trd":[[11.5,1198.47]],"batb":[[2,10,66.05],[1,10.5,31.55],[0,11,78.5]],"tv":6369.67,"id":40389088},{"atb":[[9.6,37.8]],"batb":[[0,9.6,37.8]],"id":35856222},{"atb":[[60,0]],"atl":[[60,1.94]],"trd":[[60,362.57]],"batb":[[0,55,20.48]],"batl":[[2,70,5.42],[1,65,34.71],[0,60,1.94]],"ltp":60,"tv":1845.81,"id":59626646},{"atb":[[9.4,74.52]],"batb":[[1,9.4,74.52]],"id":27115873},{"atb":[[16.5,29.53]],"batb":[[0,16.5,29.53]],"id":58186642}],"tv":78252.54}]}
{"op":"mcm","id":2,"clk":"APTsAQCErAEAotgB","pt":1743511998346,"mc":[{"id":"1.241629436","rc":[{"atl":[[14.5,12.01]],"batl":[],"id":40389088},{"atb":[[9.2,63.93]],"batb":[[2,9.2,63.93]],"id":35856222},{"atl":[[17,9.46]],"batl":[[0,17,9.46]],"id":58186642}]}]}
{"op":"mcm","id":2,"clk":"AP/sAQCMrAEAr9gB","pt":1743511998442,"mc":[{"id":"1.241629436","rc":[{"atb":[[11.5,1]],"batb":[[2,10.5,31.55],[1,11,78.5],[0,11.5,1]],"id":40389088},{"atl":[[65,6.35]],"batl":[[1,65,6.35]],"id":59626646}]}]}
{"op":"mcm","id":2,"clk":"AJLtAQCbrAEAx9gB","pt":1743511998551,"mc":[{"id":"1.241629436","rc":[{"atb":[[11.5,0]],"trd":[[11.5,1200.47]],"batb":[[2,10,66.05],[1,10.5,31.55],[0,11,78.5]],"tv":6371.67,"id":40389088}],"tv":78254.54}]}
{"op":"mcm","id":2,"clk":"AKDtAQCkrAEA0NgB","pt":1743511998620,"mc":[{"id":"1.241629436","rc":[{"atl":[[17,16.96]],"batl":[[0,17,16.96]],"id":58186642}]}]}
{"op":"mcm","id":2,"clk":"AK/tAQC9rAEA59gB","pt":1743511998729,"mc":[{"id":"1.241629436","rc":[{"atl":[[1000,2.25],[14.5,10.68],[18.5,9.77]],"batl":[],"id":40389088},{"atb":[[9.6,24.47]],"batb":[[0,9.6,24.47]],"id":27115873}]}]}
{"op":"mcm","id":2,"clk":"ALztAQDJrAEA8dgB","pt":1743511998828,"mc":[{"id":"1.241629436","rc":[{"atl":[[10,34.75]],"batl":[[1,10,34.75]],"id":27115873}]}]}
{"op":"mcm","id":2,"clk":"AM/tAQDXrAEAhtkB","pt":1743511998945,"mc":[{"id":"1.241629436","rc":[{"atl":[[1000,1.01]],"id":40389088},{"atb":[[9.2,65.29]],"batb":[[2,9.2,65.29]],"id":35856222},{"atb":[[9.4,79.52]],"batb":[[1,9.4,79.52]],"id":27115873}]}]}
{"op":"mcm","id":2,"clk":"AOPtAQDvrAEAndkB","pt":1743511999106,"mc":[{"id":"1.241629436","rc":[{"atb":[[5,1157.82]],"batb":[[1,5,1157.82]],"id":56297029},{"atb":[[16.5,28.53]],"trd":[[16.5,588.98]],"batb":[[0,16.5,28.53]],"tv":5600.64,"id":58186642}],"tv":78256.54}]}
{"op":"mcm","id":2,"clk":"AOjtAQDyrAEAntkB","pt":1743511999161,"mc":[{"id":"1.241629436","rc":[{"atl":[[1000,0.25]],"id":40389088},{"atb":[[11,104.18]],"trd":[[11,1528.81]],"batb":[[0,11,104.18]],"ltp":11,"tv":4805.85,"id":44049799}],"tv":78258.54}]}
{"op":"mcm","id":2,"clk":"APLtAQCBrQEArdkB","pt":1743511999221,"mc":[{"id":"1.241629436","rc":[{"atl":[[11.5,0.76]],"batl":[[0,12,80.76]],"id":40389088}]}]}
{"op":"mcm","id":2,"clk":"AI7uAQChrQEAzNkB","pt":1743511999450,"mc":[{"id":"1.241629436","rc":[{"atb":[[55,20.2]],"batb":[[0,55,20.2]],"id":59626646},{"atb":[[9.4,77.96],[1.17,1.85]],"atl":[[1000,1.54]],"batb":[[1,9.4,77.96]],"id":27115873},{"atb":[[6.4,317.33]],"batb":[[0,6.4,317.33]],"id":26496185}]}]}
{"op":"mcm","id":2,"clk":"AJzuAQCwrQEA0tkB","pt":1743511999558,"mc":[{"id":"1.241629436","rc":[{"atl":[[1000,23.16]],"id":270592},{"atl":[[65,4.73]],"batl":[[1,65,4.73]],"id":59626646},{"atb":[[1.17,1]],"atl":[[1000,1.41],[9.8,79.73]],"batl":[[0,9.8,79.73]],"id":27115873}]}]}
{"op":"mcm","id":2,"clk":"AKXuAQC2rQEA4tkB","pt":1743511999658,"mc":[{"id":"1.241629436","rc":[{"atb":[[2.08,10]],"id":270592},{"atb":[[9.6,25.32]],"atl":[[1000,1.16],[9.8,79.86]],"batb":[[0,9.6,25.32]],"batl":[[0,9.8,79.86]],"id":27115873}]}]}
{"op":"mcm","id":2,"clk":"ALDuAQDArQEA5NkB","pt":1743511999756,"mc":[{"id":"1.241629436","rc":[{"atl":[[11.5,0]],"batl":[[0,12,80]],"id":40389088},{"atl":[[1000,21.16]],"id":270592},{"atb":[[4.7,40.5]],"batb":[],"id":56297029},{"atl":[[10,35]],"batl":[[1,10,35]],"id":27115873}]}]}
{"op":"mcm","id":2,"clk":"ANTuAQDorQEAidoB","pt":1743512000024,"mc":[{"id":"1.241629436","rc":[{"atl":[[65,4.58]],"batl":[[1,65,4.58]],"id":59626646},{"atb":[[9.4,77.74]],"batb":[[1,9.4,77.74]],"id":27115873}]}]}
{"op":"mcm","id":2,"clk":"AOXuAQD2rQEAkdoB","pt":1743512000129,"mc":[{"id":"1.241629436","rc":[{"atl":[[6.6,99.96]],"trd":[[6.6,1912.11]],"batl":[[0,6.6,99.96]],"ltp":6.6,"tv":12445.28,"id":26496185}],"tv":78260.54}]}
{"op":"mcm","id":2,"clk":"AOzuAQCIrgEAq9oB","pt":1743512000241,"mc":[{"id":"1.241629436","rc":[{"atb":[[9.6,25.34]],"batb":[[0,9.6,25.34]],"id":27115873}]}]}
{"op":"mcm","id":2,"clk":"AJPvAQCgrgEAydoB","pt":1743512000556,"mc":[{"id":"1.241629436","rc":[{"atl":[[12,135.58]],"batl":[[0,12,135.58]],"id":40389088},{"atb":[[9.6,33.95]],"batb":[[0,9.6,33.95]],"id":35856222},{"atl":[[60,13.06]],"batl":[[0,60,13.06]],"id":59626646},{"atb":[[6.4,313.97]],"batb":[[0,6.4,313.97]],"id":26496185},{"atl":[[11.5,88.97]],"batl":[[0,11.5,88.97]],"id":44049799}]}]}
{"op":"mcm","id":2,"clk":"AKjvAQC3rgEA3doB","pt":1743512000759,"mc":[{"id":"1.241629436","rc":[{"atl":[[9.8,11.35]],"trd":[[9.8,767.34]],"batl":[[0,9.8,11.35]],"ltp":9.8,"tv":9715.21,"id":35856222},{"atl":[[60,15.04]],"batl":[[0,60,15.04]],"id":59626646},{"atb":[[5.1,93.26]],"trd":[[5.1,4140.08]],"batb":[[0,5.1,93.26]],"tv":13232.04,"id":56297029},{"atl":[[9.8,78.48]],"trd":[[9.8,338.9]],"batl":[[0,9.8,78.48]],"ltp":9.8,"tv":6916.36,"id":27115873},{"atb":[[11,93.87]],"trd":[[11,1549.42]],"batb":[[0,11,93.87]],"tv":4826.46,"id":44049799}],"tv":78292.52}]}
{"op":"mcm","id":2,"clk":"ALPvAQC+rgEA69oB","pt":1743512000817,"mc":[{"id":"1.241629436","rc":[{"atl":[[9.8,47.95]],"trd":[[9.8,399.96]],"batl":[[0,9.8,47.95]],"tv":6977.42,"id":27115873}],"tv":78353.58}]}
{"op":"mcm","id":2,"clk":"ALzvAQDMrgEA89oB","pt":1743512000924,"mc":[{"id":"1.241629436","rc":[{"atl":[[19,5.98]],"id":40389088},{"atb":[[9.6,30.45]],"atl":[[9.8,6.2]],"trd":[[9.8,483.46]],"batb":[[0,9.6,30.45]],"batl":[[0,9.8,6.2]],"tv":7060.92,"id":27115873}],"tv":78437.08}]}
{"op":"mcm","id":2,"clk":"AMXvAQDargEAgdsB","pt":1743512001027,"mc":[{"id":"1.241629436","rc":[{"atb":[[5.1,47.6]],"batb":[[0,5.1,47.6]],"id":56297029},{"atb":[[9.8,16.62],[9.6,57.13]],"atl":[[9.8,0]],"trd":[[9.8,495.86]],"batb":[[2,9.4,77.74],[1,9.6,57.13],[0,9.8,16.62]],"batl":[[2,11,59.51],[1,10.5,66.05],[0,10,35]],"tv":7073.32,"id":27115873}],"tv":78449.48}]}
{"op":"mcm","id":2,"clk":"ANPvAQDlrgEAitsB","pt":1743512001133,"mc":[{"id":"1.241629436","rc":[{"atb":[[9.2,63.93]],"batb":[[2,9.2,63.93]],"id":35856222},{"atl":[[10,7.19]],"trd":[[10,502.76]],"batl":[[0,10,7.19]],"ltp":10,"tv":7100.84,"id":27115873},{"atb":[[6.2,171.07],[6.4,323.14]],"batb":[[1,6.2,171.07],[0,6.4,323.14]],"id":26496185}],"tv":78477}]}
{"op":"mcm","id":2,"clk":"ANnvAQDwrgEAl9sB","pt":1743512001232,"mc":[{"id":"1.241629436","rc":[{"atb":[[9.8,22.17],[10,6.79]],"atl":[[12.5,280.02],[12,31.26],[10,0]],"trd":[[10,517.14]],"batb":[[2,9.6,57.13],[1,9.8,22.17],[0,10,6.79]],"batl":[[2,11.5,25.31],[1,11,59.51],[0,10.5,66.05]],"tv":7115.22,"id":27115873}],"tv":78491.38}]}
{"op":"mcm","id":2,"clk":"AOHvAQD7rgEAptsB","pt":1743512001343,"mc":[{"id":"1.241629436","rc":[{"atl":[[1000,23.16]],"id":270592},{"atl":[[9.8,18.28]],"batl":[[0,9.8,18.28]],"id":35856222},{"atb":[[9.8,39.76],[10,7.71],[9,40.96]],"atl":[[12,29.28]],"trd":[[10,519.14]],"batb":[[1,9.8,39.76],[0,10,7.71]],"batl":[],"tv":7117.22,"id":27115873},{"atb":[[15,16.04]],"batb":[],"id":58186642}],"tv":78493.38}]}
{"op":"mcm","id":2,"clk":"AO7vAQCFrwEArdsB","pt":1743512001449,"mc":[{"id":"1.241629436","rc":[{"atb":[[5.1,0]],"atl":[[5.1,8.53]],"trd":[[5.1,4235.28]],"batb":[[2,4.8,153.55],[1,4.9,78.72],[0,5,1157.82]],"batl":[[2,5.3,77.9],[1,5.2,208.73],[0,5.1,8.53]],"tv":13327.24,"id":56297029},{"atb":[[9.2,57.36],[10,1.45]],"atl":[[11.5,28.68]],"trd":[[10,531.66]],"batb":[[0,10,1.45]],"batl":[[2,11.5,28.68]],"tv":7129.74,"id":27115873}],"tv":78601.1}]}
{"op":"mcm","id":2,"clk":"APPvAQCNrwEAtdsB","pt":1743512001543,"mc":[{"id":"1.241629436","rc":[{"atb":[[8,21.68]],"id":40389088},{"atl":[[1000,21.16]],"id":270592},{"atl":[[5.2,211.07]],"batl":[[1,5.2,211.07]],"id":56297029},{"atb":[[8.8,32.56],[9.8,38.56],[10,0]],"atl":[[12.5,278.2]],"trd":[[10,534.56]],"batb":[[2,9.4,77.74],[1,9.6,57.13],[0,9.8,38.56]],"batl":[],"tv":7132.64,"id":27115873},{"atb":[[16.5,13]],"trd":[[16.5,604.04]],"batb":[[0,16.5,13]],"tv":5615.7,"id":58186642}],"tv":78619.06}]}
{"op":"mcm","id":2,"clk":"AP7vAQCerwEAw9sB","pt":1743512001658,"mc":[{"id":"1.241629436","rc":[{"atb":[[9.2,65.29]],"batb":[[2,9.2,65.29]],"id":35856222},{"atl":[[5.2,208.32],[5.1,25.84]],"batl":[[1,5.2,208.32],[0,5.1,25.84]],"id":56297029},{"atb":[[9.8,43.63],[10,10.13]],"batb":[[2,9.6,57.13],[1,9.8,43.63],[0,10,10.13]],"id":27115873},{"atb":[[15,19.41],[16.5,0.22]],"trd":[[16.5,619.04]],"batb":[[2,15,19.41],[1,15.5,32.15],[0,16,26.98]],"tv":5630.7,"id":58186642},{"atb":[[6.2,174.28]],"batb":[[1,6.2,174.28]],"id":26496185}],"tv":78634.06}]}
{"op":"mcm","id":2,"clk":"AIvwAQCrrwEAydsB","pt":1743512001755,"mc":[{"id":"1.241629436","rc":[{"atl":[[5.6,167.64]],"batl":[],"id":270592},{"atb":[[4.8,152.52]],"atl":[[5.2,189.5],[5.5,92.21],[5.1,17.31]],"batb":[[2,4.8,152.52]],"batl":[[1,5.2,189.5],[0,5.1,17.31]],"id":56297029},{"atb":[[10,8.96]],"atl":[[13,10.09],[10.5,60.45]],"trd":[[10,536.9]],"batb":[[0,10,8.96]],"batl":[[0,10.5,60.45]],"tv":7134.98,"id":27115873},{"atb":[[15,16.04]],"atl":[[17,22.28]],"batb":[[2,15,16.04]],"batl":[[0,17,22.28]],"id":58186642}],"tv":78636.4}]}
{"op":"mcm","id":2,"clk":"AJfwAQC1rwEA19sB","pt":1743512001864,"mc":[{"id":"1.241629436","rc":[{"atl":[[13,11.76],[12.5,280.02]],"batl":[],"id":27115873},{"atb":[[15,15.04],[16.5,0]],"atl":[[20,3.88],[17,24.68],[16.5,5.06]],"trd":[[16.5,619.48]],"batb":[[2,15,15.04],[0,16,26.76]],"batl":[[2,17.5,13.68],[1,17,24.68],[0,16.5,5.06]],"tv":5631.14,"id":58186642}],"tv":78636.84}]}
{"op":"mcm","id":2,"clk":"AJ3wAQC5rwEA2dsB","pt":1743512001913,"mc":[{"id":"1.241629436","rc":[{"atb":[[4.7,41.56]],"atl":[[5.4,64.82]],"batb":[],"batl":[],"id":56297029}]}]}
{"op":"mcm","id":2,"clk":"AKjwAQDCrwEA8dsB","pt":1743512002025,"mc":[{"id":"1.241629436","rc":[{"atl":[[19.5,5.03]],"id":40389088},{"atl":[[16.5,6.75]],"batl":[[0,16.5,6.75]],"id":58186642}]}]}
{"op":"mcm","id":2,"clk":"ALDwAQDMrwEA+dsB","pt":1743512002132,"mc":[{"id":"1.241629436","rc":[{"atb":[[15,18.5]],"atl":[[16.5,4.08]],"trd":[[16.5,624.82]],"batb":[[2,15,18.5]],"batl":[[0,16.5,4.08]],"tv":5636.48,"id":58186642}],"tv":78642.18}]}
{"op":"mcm","id":2,"clk":"AMnwAQDgrwEAiNwB","pt":1743512002335,"mc":[{"id":"1.241629436","rc":[{"atb":[[15,19.5]],"batb":[[2,15,19.5]],"id":58186642}]}]}
{"op":"mcm","id":2,"clk":"ANLwAQDurwEAk9wB","pt":1743512002440,"mc":[{"id":"1.241629436","rc":[{"atl":[[6.6,72.49]],"id":56297029},{"atb":[[9.4,82.21]],"batb":[],"id":27115873}]}]}
{"op":"mcm","id":2,"clk":"APPwAQCPsAEAsdwB","pt":1743512002749,"mc":[{"id":"1.241629436","rc":[{"atb":[[9.6,57.11]],"batb":[[2,9.6,57.11]],"id":27115873}]}]}
{"op":"mcm","id":2,"clk":"AP7wAQCZsAEAtNwB","pt":1743512002847,"mc":[{"id":"1.241629436","rc":[{"atl":[[5.1,47.31]],"batl":[[0,5.1,47.31]],"id":56297029},{"atb":[[10,9.96]],"batb":[[0,10,9.96]],"id":27115873},{"atb":[[16,26.89]],"batb":[[0,16,26.89]],"id":58186642},{"atb":[[11,93.77]],"trd":[[11,1549.62]],"batb":[[0,11,93.77]],"tv":4826.66,"id":44049799}],"tv":78642.38}]}
{"op":"mcm","id":2,"clk":"AInxAQCksAEAvtwB","pt":1743512002949,"mc":[{"id":"1.241629436","rc":[{"atl":[[5.3,94.87]],"batl":[[2,5.3,94.87]],"id":56297029}]}]}
{"op":"mcm","id":2,"clk":"AKrxAQC6sAEA0NwB","pt":1743512003157,"mc":[{"id":"1.241629436","rc":[{"atb":[[7.8,33.28]],"atl":[[20,5.08]],"id":40389088},{"atb":[[9.4,77.74]],"batb":[],"id":27115873}]}]}
{"op":"mcm","id":2,"clk":"ANjxAQDwsAEAh90B","pt":1743512003534,"mc":[{"id":"1.241629436","rc":[{"atb":[[5,1190.89]],"atl":[[1000,6.16],[5.3,94.05]],"batb":[[0,5,1190.89]],"batl":[[2,5.3,94.05]],"id":56297029},{"atb":[[11,94.71]],"batb":[[0,11,94.71]],"id":44049799}]}]}
{"op":"mcm","id":2,"clk":"AOrxAQCDsQEAod0B","pt":1743512003654,"mc":[{"id":"1.241629436","rc":[{"atl":[[9.8,19.28]],"batl":[[0,9.8,19.28]],"id":35856222},{"atl":[[1000,5.52],[5.3,91.02]],"batl":[[2,5.3,91.02]],"id":56297029}]}]}
{"op":"mcm","id":2,"clk":"APPxAQCMsQEAod0B","pt":1743512003758,"mc":[{"id":"1.241629436","rc":[{"atb":[[5.2,326.9]],"trd":[[5.2,2096.98]],"batb":[[0,5.2,326.9]],"ltp":5.2,"tv":17353.05,"id":270592},{"atl":[[5.2,190.14]],"batl":[[1,5.2,190.14]],"id":56297029}],"tv":78656.38}]}
{"op":"mcm","id":2,"clk":"AKTyAQCssQEAud0B","pt":1743512003945,"mc":[{"id":"1.241629436","rc":[{"atb":[[6,6.73]],"id":27115873}]}]}
{"op":"mcm","id":2,"clk":"AL/yAQDLsQEA090B","pt":1743512004161,"mc":[{"id":"1.241629436","rc":[{"atl":[[11.5,87.97]],"batl":[[0,11.5,87.97]],"id":44049799}]}]}
{"op":"mcm","id":2,"clk":"ANfyAQDmsQEA490B","pt":1743512004323,"mc":[{"id":"1.241629436","rc":[{"atl":[[21,5.02]],"id":40389088}]}]}
{"op":"mcm","id":2,"clk":"AJ7zAQCosgEAjt4B","pt":1743512004748,"mc":[{"id":"1.241629436","rc":[{"atl":[[12.5,278.2]],"batl":[],"id":27115873}]}]}
{"op":"mcm","id":2,"clk":"ALTzAQC7sgEArd4B","pt":1743512004958,"mc":[{"id":"1.241629436","rc":[{"atl":[[1000,23.16]],"id":270592}]}]}
{"op":"mcm","id":2,"clk":"AMvzAQDGsgEAv94B","pt":1743512005028,"mc":[{"id":"1.241629436","rc":[{"atb":[[5,1195.89]],"batb":[[0,5,1195.89]],"id":56297029}]}]}
{"op":"mcm","id":2,"clk":"AOPzAQDXsgEAyN4B","pt":1743512005137,"mc":[{"id":"1.241629436","rc":[{"atl":[[1000,21.16]],"id":270592}]}]}
{"op":"mcm","id":2,"clk":"AJn0AQCEswEA594B","pt":1743512005453,"mc":[{"id":"1.241629436","rc":[{"atl":[[1000,23.16]],"id":270592}]}]}
{"op":"mcm","id":2,"clk":"AKn0AQCZswEAgN8B","pt":1743512005566,"mc":[{"id":"1.241629436","rc":[{"atb":[[6.4,320.11]],"atl":[[6.6,95.66]],"trd":[[6.6,1920.71]],"batb":[[0,6.4,320.11]],"batl":[[0,6.6,95.66]],"tv":12453.88,"id":26496185}],"tv":78664.98}]}
{"op":"mcm","id":2,"clk":"AL70AQCpswEAht8B","pt":1743512005621,"mc":[{"id":"1.241629436","rc":[{"atl":[[1000,21.16]],"id":270592},{"atb":[[1.17,7.36],[9.6,32.99]],"batb":[[0,9.6,32.99]],"id":35856222},{"atb":[[48,4.26]],"batb":[[2,48,4.26]],"id":59626646},{"atb":[[9.6,56.26]],"batb":[[2,9.6,56.26]],"id":27115873},{"atb":[[1.17,2.83],[16,25.86]],"atl":[[17,23.81]],"batb":[[0,16,25.86]],"batl":[[1,17,23.81]],"id":58186642},{"atb":[[11,93.2]],"atl":[[12,25.32],[11.5,87.74]],"batb":[[0,11,93.2]],"batl":[[1,12,25.32],[0,11.5,87.74]],"id":44049799}]}]}
{"op":"mcm","id":2,"clk":"AND0AQDGswEAkt8B","pt":1743512005742,"mc":[{"id":"1.241629436","rc":[{"atb":[[46,9.61]],"batb":[],"id":59626646}]}]}
{"op":"mcm","id":2,"clk":"AOD0AQDMswEAnN8B","pt":1743512005837,"mc":[{"id":"1.241629436","rc":[{"atb":[[1.17,7.15]],"id":35856222},{"atb":[[1.17,2]],"id":58186642}]}]}
{"op":"mcm","id":2,"clk":"AOv0AQDcswEApd8B","pt":1743512005942,"mc":[{"id":"1.241629436","rc":[{"atb":[[9.4,54.76]],"batb":[[1,9.4,54.76]],"id":35856222},{"atb":[[15.5,32.63],[16,26.21]],"batb":[[1,15.5,32.63],[0,16,26.21]],"id":58186642}]}]}
{"op":"mcm","id":2,"clk":"ALX1AQC6tAEA398B","pt":1743512006449,"mc":[{"id":"1.241629436","rc":[{"atb":[[9.6,30.99]],"atl":[[12,31.41]],"trd":[[9.6,597.29]],"batb":[[0,9.6,30.99]],"batl":[],"ltp":9.6,"tv":9719.21,"id":35856222}],"tv":78668.98}]}
{"op":"mcm","id":2,"clk":"AMj1AQDTtAEA998B","pt":1743512006654,"mc":[{"id":"1.241629436","rc":[{"atb":[[7.6,25.43]],"atl":[[22,6.07]],"id":40389088}]}]}
{"op":"mcm","id":2,"clk":"AOD1AQDktAEAg+AB","pt":1743512006726,"mc":[{"id":"1.241629436","rc":[{"atl":[[1000,23.16],[5.3,159.35]],"trd":[[5.3,1663.48]],"batl":[[0,5.3,159.35]],"ltp":5.3,"tv":17397.05,"id":270592}],"tv":78712.98}]}
{"op":"mcm","id":2,"clk":"AP/1AQCQtQEAouAB","pt":1743512006934,"mc":[{"id":"1.241629436","rc":[{"atl":[[1000,21.16]],"id":270592}]}]}
{"op":"mcm","id":2,"clk":"ANr2AQDitQEA4uAB","pt":1743512007559,"mc":[{"id":"1.241629436","rc":[{"atb":[[5.2,321.9]],"trd":[[5.2,2106.98]],"batb":[[0,5.2,321.9]],"ltp":5.2,"tv":17407.05,"id":270592}],"tv":78722.98}]}
{"op":"mcm","id":2,"clk":"AN33AQDstgEAv+EB","pt":1743512008658,"mc":[{"id":"1.241629436","rc":[{"atb":[[1.17,2.21]],"atl":[[12,136.63]],"batl":[[0,12,136.63]],"id":40389088},{"atb":[[5.1,291.43]],"atl":[[5.3,165.33]],"batb":[[1,5.1,291.43]],"batl":[[0,5.3,165.33]],"id":270592},{"atl":[[9.8,20.31]],"batl":[[0,9.8,20.31]],"id":35856222},{"atl":[[1000,1.51]],"id":27115873}]}]}
{"op":"mcm","id":2,"clk":"AOn3AQDytgEA0eEB","pt":1743512008755,"mc":[{"id":"1.241629436","rc":[{"atl":[[60,15.37]],"batl":[[0,60,15.37]],"id":59626646}]}]}
{"op":"mcm","id":2,"clk":"APT3AQCBtwEA4eEB","pt":1743512008862,"mc":[{"id":"1.241629436","rc":[{"atb":[[1.17,2],[7.4,26.06]],"atl":[[23,7.09]],"id":40389088},{"atl":[[1000,1.16]],"id":27115873}]}]}
{"op":"mcm","id":2,"clk":"AID4AQCHtwEA6eEB","pt":1743512008919,"mc":[{"id":"1.241629436","rc":[{"atb":[[10.5,31.76]],"batb":[[1,10.5,31.76]],"id":40389088},{"atl":[[65,4.64]],"batl":[[1,65,4.64]],"id":59626646},{"atl":[[10.5,60.8]],"batl":[[0,10.5,60.8]],"id":27115873}]}]}
{"op":"mcm","id":2,"clk":"ANn4AQDGtwEAquIB","pt":1743512009738,"mc":[{"id":"1.241629436","rc":[{"atb":[[5.2,311.9]],"trd":[[5.2,2126.98]],"batb":[[0,5.2,311.9]],"tv":17427.05,"id":270592}],"tv":78742.98}]}
{"op":"mcm","id":2,"clk":"APf4AQDjtwEAwOIB","pt":1743512009949,"mc":[{"id":"1.241629436","rc":[{"atb":[[5,1199.9]],"batb":[[0,5,1199.9]],"id":56297029}]}]}
{"op":"mcm","id":2,"clk":"AKL5AQCAuAEA2+IB","pt":1743512010351,"mc":[{"id":"1.241629436","rc":[{"atb":[[6.4,318.11]],"trd":[[6.4,3615.68]],"batb":[[0,6.4,318.11]],"ltp":6.4,"tv":12457.88,"id":26496185}],"tv":78746.98}]}
{"op":"mcm","id":2,"clk":"ALf5AQCOuAEA6eIB","pt":1743512010563,"mc":[{"id":"1.241629436","rc":[{"atl":[[5.1,41.65]],"trd":[[5.1,4246.61]],"batl":[[0,5.1,41.65]],"tv":13338.57,"id":56297029}],"tv":78758.31}]}
{"op":"mcm","id":2,"clk":"AMH5AQCXuAEA7+IB","pt":1743512010658,"mc":[{"id":"1.241629436","rc":[{"atb":[[9.6,25.79]],"trd":[[9.6,607.69]],"batb":[[0,9.6,25.79]],"tv":9729.61,"id":35856222},{"atl":[[19.5,4.63]],"batl":[],"id":58186642}],"tv":78768.71}]}
{"op":"mcm","id":2,"clk":"ANj5AQCquAEA/+IB","pt":1743512010831,"mc":[{"id":"1.241629436","rc":[{"atl":[[1000,23.16]],"id":270592},{"atl":[[9.8,26.38]],"batl":[[0,9.8,26.38]],"id":35856222}]}]}
{"op":"mcm","id":2,"clk":"AOX5AQCuuAEAiOMB","pt":1743512010936,"mc":[{"id":"1.241629436","rc":[{"atb":[[11,78.17]],"batb":[[0,11,78.17]],"id":40389088},{"atb":[[10,13.29]],"batb":[[0,10,13.29]],"id":27115873}]}]}
{"op":"mcm","id":2,"clk":"AO/5AQC0uAEAkuMB","pt":1743512011030,"mc":[{"id":"1.241629436","rc":[{"atl":[[12,141.62],[11.5,12.3]],"batl":[[2,12.5,60.31],[1,12,141.62],[0,11.5,12.3]],"id":40389088},{"atl":[[1000,21.16]],"id":270592},{"atb":[[5.1,82.33]],"atl":[[5.1,0]],"trd":[[5.1,4329.91]],"batb":[[2,4.9,78.72],[1,5,1199.9],[0,5.1,82.33]],"batl":[[2,5.4,64.82],[1,5.3,91.02],[0,5.2,190.14]],"tv":13421.87,"id":56297029}],"tv":78852.01}]}
{"op":"mcm","id":2,"clk":"AP35AQDHuAEAnuMB","pt":1743512011135,"mc":[{"id":"1.241629436","rc":[{"atl":[[24,7.07],[11.5,12.28]],"trd":[[11.5,1200.5]],"batl":[[0,11.5,12.28]],"tv":6371.7,"id":40389088},{"atb":[[5.2,311.43]],"trd":[[5.2,2127.91]],"batb":[[0,5.2,311.43]],"tv":17427.98,"id":270592},{"atb":[[9.6,21.37]],"trd":[[9.6,608.2]],"batb":[[0,9.6,21.37]],"tv":9730.12,"id":35856222},{"atb":[[55,20.16]],"trd":[[55,200.15]],"batb":[[0,55,20.16]],"ltp":55,"tv":1845.9,"id":59626646},{"atb":[[5.1,107.33]],"batb":[[0,5.1,107.33]],"id":56297029},{"atb":[[10,9.96]],"batb":[[0,10,9.96]],"id":27115873},{"atb":[[6.4,315.11]],"trd":[[6.4,3621.68]],"batb":[[0,6.4,315.11]],"tv":12463.88,"id":26496185}],"tv":78859.57}]}
{"op":"mcm","id":2,"clk":"AI76AQDSuAEAquMB","pt":1743512011238,"mc":[{"id":"1.241629436","rc":[{"atb":[[10.5,45.23]],"batb":[[1,10.5,45.23]],"id":40389088},{"atl":[[5.6,169.62]],"batl":[],"id":270592},{"atb":[[9.2,63.93],[9.6,11.57]],"batb":[[2,9.2,63.93],[0,9.6,11.57]],"id":35856222},{"atl":[[5.2,208.4]],"batl":[[0,5.2,208.4]],"id":56297029},{"atb":[[6.2,171.07]],"batb":[[1,6.2,171.07]],"id":26496185}]}]}
{"op":"mcm","id":2,"clk":"AJ36AQDduAEAsuMB","pt":1743512011341,"mc":[{"id":"1.241629436","rc":[{"atb":[[4.7,40.5]],"atl":[[5.4,63.97]],"batb":[],"batl":[[2,5.4,63.97]],"id":56297029}]}]}
{"op":"mcm","id":2,"clk":"AKn6AQDguAEAtuMB","pt":1743512011438,"mc":[{"id":"1.241629436","rc":[{"atl":[[12,140.57],[11.5,13.33]],"batl":[[1,12,140.57],[0,11.5,13.33]],"id":40389088},{"atl":[[5.3,77.08]],"batl":[[1,5.3,77.08]],"id":56297029},{"atb":[[16,25.86]],"atl":[[16.5,5.51]],"batb":[[0,16,25.86]],"batl":[[0,16.5,5.51]],"id":58186642},{"atb":[[6.4,314.47]],"batb":[[0,6.4,314.47]],"id":26496185}]}]}
{"op":"mcm","id":2,"clk":"ALf6AQDwuAEAveMB","pt":1743512011556,"mc":[{"id":"1.241629436","rc":[{"atb":[[4.8,153.55]],"atl":[[5.5,93.03]],"batb":[],"batl":[],"id":56297029}]}]}
{"op":"mcm","id":2,"clk":"AMP6AQD5uAEAx+MB","pt":1743512011651,"mc":[{"id":"1.241629436","rc":[{"atb":[[10,7.96]],"trd":[[10,540.9]],"batb":[[0,10,7.96]],"tv":7138.98,"id":27115873}],"tv":78863.57}]}
{"op":"mcm","id":2,"clk":"AMr6AQCEuQEAz+MB","pt":1743512011749,"mc":[{"id":"1.241629436","rc":[{"atl":[[1000,2.25]],"id":40389088}]}]}
{"op":"mcm","id":2,"clk":"AOH6AQCUuQEA5+MB","pt":1743512011953,"mc":[{"id":"1.241629436","rc":[{"atl":[[1000,1.04]],"id":40389088}]}]}
{"op":"mcm","id":2,"clk":"APD6AQCbuQEA+eMB","pt":1743512012067,"mc":[{"id":"1.241629436","rc":[{"atl":[[1000,0.25]],"id":40389088}]}]}
{"op":"mcm","id":2,"clk":"AP/6AQCpuQEA/OMB","pt":1743512012164,"mc":[{"id":"1.241629436","rc":[{"atb":[[11,77.38]],"trd":[[11,178.72]],"batb":[[0,11,77.38]],"ltp":11,"tv":6373.28,"id":40389088},{"atl":[[1000,23.16]],"id":270592},{"atb":[[8,33.94]],"id":27115873}],"tv":78865.15}]}
{"op":"mcm","id":2,"clk":"AIv7AQCuuQEAhOQB","pt":1743512012269,"mc":[{"id":"1.241629436","rc":[{"atb":[[1.01,97187.92]],"id":40389088},{"atb":[[8.4,60.82],[1.01,111312.31]],"batb":[],"id":27115873},{"atb":[[15,18.5]],"batb":[[2,15,18.5]],"id":58186642}]}]}
{"op":"mcm","id":2,"clk":"AJf7AQC3uQEAi+QB","pt":1743512012322,"mc":[{"id":"1.241629436","rc":[{"atl":[[1000,21.16]],"id":270592},{"atb":[[5.1,137.33]],"batb":[[0,5.1,137.33]],"id":56297029}]}]}
{"op":"mcm","id":2,"clk":"AMf7AQDhuQEAqOQB","pt":1743512012745,"mc":[{"id":"1.241629436","rc":[{"atb":[[5.1,135.33]],"trd":[[5.1,4333.91]],"batb":[[0,5.1,135.33]],"tv":13425.87,"id":56297029}],"tv":78869.15}]}
{"op":"mcm","id":2,"clk":"AM77AQDouQEAruQB","pt":1743512012845,"mc":[{"id":"1.241629436","rc":[{"atl":[[9.8,35.38]],"batl":[[0,9.8,35.38]],"id":35856222}]}]}
{"op":"mcm","id":2,"clk":"ANj7AQDyuQEAteQB","pt":1743512012943,"mc":[{"id":"1.241629436","rc":[{"atb":[[5,1169.9]],"batb":[[1,5,1169.9]],"id":56297029}]}]}
{"op":"mcm","id":2,"clk":"APP7AQCNugEAy+QB","pt":1743512013251,"mc":[{"id":"1.241629436","rc":[{"atl":[[12.5,66.56]],"batl":[[2,12.5,66.56]],"id":40389088}]}]}
{"op":"mcm","id":2,"clk":"AIv8AQCgugEA3+QB","pt":1743512013452,"mc":[{"id":"1.241629436","rc":[{"atl":[[7.6,32.8]],"batl":[],"id":26496185}]}]}
{"op":"mcm","id":2,"clk":"AJP8AQCougEA6uQB","pt":1743512013558,"mc":[{"id":"1.241629436","rc":[{"atb":[[5.1,165.33]],"batb":[[0,5.1,165.33]],"id":56297029}]}]}
{"op":"mcm","id":2,"clk":"AJ/8AQCwugEA8uQB","pt":1743512013658,"mc":[{"id":"1.241629436","rc":[{"atb":[[55,0.16]],"trd":[[55,240.15]],"batb":[[2,46,9.61],[1,48,4.26],[0,50,18.83]],"tv":1885.9,"id":59626646}],"tv":78909.15}]}
{"op":"mcm","id":2,"clk":"AKr8AQDBugEA9+QB","pt":1743512013766,"mc":[{"id":"1.241629436","rc":[{"atl":[[9.4,1.99]],"id":270592},{"atb":[[55,0]],"atl":[[60,18.37],[55,2.04]],"trd":[[55,240.47]],"batb":[[0,50,18.67]],"batl":[[2,65,4.64],[1,60,18.37],[0,55,2.04]],"tv":1886.22,"id":59626646},{"atb":[[9.4,72.74]],"batb":[],"id":27115873}],"tv":78909.47}]}
{"op":"mcm","id":2,"clk":"ALP8AQDJugEA/+QB","pt":1743512013865,"mc":[{"id":"1.241629436","rc":[{"atb":[[5.2,189.44]],"trd":[[5.2,2266.29]],"batb":[[0,5.2,189.44]],"tv":17566.36,"id":270592},{"atb":[[50,13.06]],"atl":[[60,19.62],[80,5.28]],"batb":[[0,50,13.06]],"batl":[[1,60,19.62]],"id":59626646},{"atb":[[5.1,155.33]],"trd":[[5.1,4353.91]],"batb":[[0,5.1,155.33]],"tv":13445.87,"id":56297029},{"atb":[[10,12.96]],"batb":[[0,10,12.96]],"id":27115873}],"tv":79067.85}]}
{"op":"mcm","id":2,"clk":"ALr8AQDRugEAgeUB","pt":1743512013964,"mc":[{"id":"1.241629436","rc":[{"atl":[[12.5,60.31]],"batl":[[2,12.5,60.31]],"id":40389088},{"atb":[[50,13.37],[48,7.26],[42,10.31]],"atl":[[60,24.52],[55,3.06]],"batb":[[1,48,7.26],[0,50,13.37]],"batl":[[1,60,24.52],[0,55,3.06]],"id":59626646},{"atb":[[5,1165.89]],"batb":[[1,5,1165.89]],"id":56297029}]}]}
{"op":"mcm","id":2,"clk":"AMH8AQDdugEAieUB","pt":1743512014078,"mc":[{"id":"1.241629436","rc":[{"atl":[[5.3,190.93]],"batl":[[0,5.3,190.93]],"id":270592},{"atl":[[60,24.58]],"batl":[[1,60,24.58]],"id":59626646},{"atl":[[5.2,212.4]],"batl":[[0,5.2,212.4]],"id":56297029},{"atb":[[10,17.29]],"batb":[[0,10,17.29]],"id":27115873},{"atb":[[15,19.5]],"atl":[[16.5,3.82]],"batb":[[2,15,19.5]],"batl":[[0,16.5,3.82]],"id":58186642}]}]}
{"op":"mcm","id":2,"clk":"AM/8AQDougEAi+UB","pt":1743512014125,"mc":[{"id":"1.241629436","rc":[{"atl":[[60,19.68],[55,6.33]],"batl":[[1,60,19.68],[0,55,6.33]],"id":59626646}]}]}
{"op":"mcm","id":2,"clk":"ANj8AQDxugEAkuUB","pt":1743512014274,"mc":[{"id":"1.241629436","rc":[{"atb":[[50,8.37]],"atl":[[55,7.97]],"trd":[[50,57.89]],"batb":[[0,50,8.37]],"batl":[[0,55,7.97]],"ltp":50,"tv":1896.21,"id":59626646}],"tv":79077.84}]}
{"op":"mcm","id":2,"clk":"AOv8AQCDuwEAoeUB","pt":1743512014437,"mc":[{"id":"1.241629436","rc":[{"atb":[[28,4.61],[50,14.43]],"atl":[[55,14.6]],"batb":[[0,50,14.43]],"batl":[[0,55,14.6]],"id":59626646},{"atb":[[10,30.73],[9,26.96]],"batb":[[0,10,30.73]],"id":27115873}]}]}
{"op":"mcm","id":2,"clk":"APT8AQCJuwEAqeUB","pt":1743512014541,"mc":[{"id":"1.241629436","rc":[{"atl":[[55,15.92]],"batl":[[0,55,15.92]],"id":59626646}]}]}
{"op":"mcm","id":2,"clk":"APz8AQCOuwEAteUB","pt":1743512014648,"mc":[{"id":"1.241629436","rc":[{"atb":[[50,12.46]],"batb":[[0,50,12.46]],"id":59626646},{"atb":[[5.1,177.33]],"batb":[[0,5.1,177.33]],"id":56297029}]}]}
{"op":"mcm","id":2,"clk":"AIT9AQCVuwEAt+UB","pt":1743512014737,"mc":[{"id":"1.241629436","rc":[{"atb":[[48,9.65]],"batb":[[1,48,9.65]],"id":59626646},{"atl":[[16.5,5.49]],"batl":[[0,16.5,5.49]],"id":58186642}]}]}
{"op":"mcm","id":2,"clk":"AKv9AQCtuwEA1eUB","pt":1743512015154,"mc":[{"id":"1.241629436","rc":[{"atl":[[11.5,12.74]],"batl":[[0,11.5,12.74]],"id":40389088},{"atb":[[50,13.35]],"batb":[[0,50,13.35]],"id":59626646},{"atl":[[18.5,15.39]],"batl":[],"id":58186642}]}]}
{"op":"mcm","id":2,"clk":"ALT9AQCzuwEA2+UB","pt":1743512015260,"mc":[{"id":"1.241629436","rc":[{"atl":[[10.5,60.53]],"batl":[[0,10.5,60.53]],"id":27115873},{"atl":[[18,18.98]],"batl":[],"id":58186642},{"atb":[[11,92.94]],"batb":[[0,11,92.94]],"id":44049799}]}]}
{"op":"mcm","id":2,"clk":"AML9AQC6uwEA3eUB","pt":1743512015364,"mc":[{"id":"1.241629436","rc":[{"atl":[[55,19.89]],"batl":[[0,55,19.89]],"id":59626646}]}]}
{"op":"mcm","id":2,"clk":"AND9AQDBuwEA4OUB","pt":1743512015462,"mc":[{"id":"1.241629436","rc":[{"atb":[[48,11.32]],"batb":[[1,48,11.32]],"id":59626646}]}]}
{"op":"mcm","id":2,"clk":"ANv9AQDJuwEA4+UB","pt":1743512015561,"mc":[{"id":"1.241629436","rc":[{"atb":[[50,11.68]],"batb":[[0,50,11.68]],"id":59626646},{"atl":[[16.5,3.82]],"batl":[[0,16.5,3.82]],"id":58186642}]}]}
{"op":"mcm","id":2,"clk":"AOj9AQDRuwEA6OUB","pt":1743512015667,"mc":[{"id":"1.241629436","rc":[{"atb":[[1.17,2.25]],"id":40389088},{"atb":[[1.17,2.23],[5,1162.82]],"batb":[[1,5,1162.82]],"id":56297029}]}]}
{"op":"mcm","id":2,"clk":"APb9AQDZuwEA9eUB","pt":1743512015776,"mc":[{"id":"1.241629436","rc":[{"atb":[[1.17,2]],"id":40389088},{"atb":[[1.17,2]],"atl":[[5.2,211.76]],"batl":[[0,5.2,211.76]],"id":56297029}]}]}
{"op":"mcm","id":2,"clk":"AIH+AQDhuwEAgOYB","pt":1743512015877,"mc":[{"id":"1.241629436","rc":[{"atb":[[11,77.63]],"batb":[[0,11,77.63]],"id":40389088},{"atb":[[5.1,177.56]],"batb":[[0,5.1,177.56]],"id":56297029}]}]}
{"op":"mcm","id":2,"clk":"AIv+AQDruwEAgeYB","pt":1743512015936,"mc":[{"id":"1.241629436","rc":[{"atb":[[5.1,171.92]],"trd":[[5.1,4365.19]],"batb":[[0,5.1,171.92]],"tv":13457.15,"id":56297029}],"tv":79089.12}]}
{"op":"mcm","id":2,"clk":"AJT+AQDyuwEAieYB","pt":1743512016029,"mc":[{"id":"1.241629436","rc":[{"atb":[[50,7.89]],"batb":[[0,50,7.89]],"id":59626646}]}]}
{"op":"mcm","id":2,"clk":"AJv+AQD4uwEAj+YB","pt":1743512016131,"mc":[{"id":"1.241629436","rc":[{"atb":[[10,20.73]],"trd":[[10,560.9]],"batb":[[0,10,20.73]],"tv":7158.98,"id":27115873}],"tv":79109.12}]}
{"op":"mcm","id":2,"clk":"AKb+AQCBvAEAl+YB","pt":1743512016243,"mc":[{"id":"1.241629436","rc":[{"atl":[[1000,23.16]],"id":270592}]}]}
{"op":"mcm","id":2,"clk":"ALH+AQCJvAEAnOYB","pt":1743512016336,"mc":[{"id":"1.241629436","rc":[{"atl":[[11.5,12.28]],"batl":[[0,11.5,12.28]],"id":40389088},{"atl":[[9.8,34.92]],"batl":[[0,9.8,34.92]],"id":35856222},{"atb":[[50,8.48]],"batb":[[0,50,8.48]],"id":59626646},{"atb":[[5.1,171.69]],"batb":[[0,5.1,171.69]],"id":56297029},{"atl":[[10.5,60.45]],"batl":[[0,10.5,60.45]],"id":27115873}]}]}
{"op":"mcm","id":2,"clk":"ALz+AQCOvAEAouYB","pt":1743512016442,"mc":[{"id":"1.241629436","rc":[{"atl":[[1000,21.16]],"id":270592},{"atb":[[9.6,17.84]],"batb":[[0,9.6,17.84]],"id":35856222}]}]}
{"op":"mcm","id":2,"clk":"AMb+AQCXvAEAqeYB","pt":1743512016541,"mc":[{"id":"1.241629436","rc":[{"atl":[[10,26.24]],"id":270592}]}]}
{"op":"mcm","id":2,"clk":"AOH+AQCwvAEAw+YB","pt":1743512016862,"mc":[{"id":"1.241629436","rc":[{"atl":[[55,0.25]],"trd":[[55,279.75]],"batl":[[2,70,5.42],[1,65,4.64],[0,60,19.93]],"ltp":55,"tv":1935.49,"id":59626646}],"tv":79148.4}]}
{"op":"mcm","id":2,"clk":"AOr+AQC2vAEAyuYB","pt":1743512016964,"mc":[{"id":"1.241629436","rc":[{"atb":[[50,10.15]],"atl":[[60,9.43],[55,0]],"trd":[[60,383.07],[55,280.25]],"batb":[[0,50,10.15]],"batl":[[0,60,9.43]],"ltp":60,"tv":1956.49,"id":59626646}],"tv":79169.4}]}
{"op":"mcm","id":2,"clk":"APL+AQC9vAEAy+YB","pt":1743512017057,"mc":[{"id":"1.241629436","rc":[{"atb":[[50,22.16]],"atl":[[55,2.1]],"batb":[[0,50,22.16]],"batl":[[2,65,4.64],[1,60,9.43],[0,55,2.1]],"id":59626646},{"atb":[[5.1,131.69]],"trd":[[5.1,4445.19]],"batb":[[0,5.1,131.69]],"tv":13537.15,"id":56297029},{"atb":[[10,7.29]],"batb":[[0,10,7.29]],"id":27115873}],"tv":79249.4}]}
{"op":"mcm","id":2,"clk":"APr+AQDDvAEA1eYB","pt":1743512017158,"mc":[{"id":"1.241629436","rc":[{"atb":[[55,5.72]],"atl":[[60,13.03],[55,0],[70,2.85],[65,2.61]],"trd":[[55,284.45]],"batb":[[2,48,11.32],[1,50,22.16],[0,55,5.72]],"batl":[[2,70,2.85],[1,65,2.61],[0,60,13.03]],"ltp":55,"tv":1960.69,"id":59626646},{"atb":[[10,2.96]],"batb":[[0,10,2.96]],"id":27115873}],"tv":79253.6}]}
{"op":"mcm","id":2,"clk":"AID/AQDIvAEA2eYB","pt":1743512017258,"mc":[{"id":"1.241629436","rc":[{"atb":[[55,8.72]],"batb":[[0,55,8.72]],"id":59626646}]}]}
{"op":"mcm","id":2,"clk":"AIv/AQDUvAEA4eYB","pt":1743512017368,"mc":[{"id":"1.241629436","rc":[{"atb":[[55,5.23],[50,21.85]],"batb":[[1,50,21.85],[0,55,5.23]],"id":59626646}]}]}
{"op":"mcm","id":2,"clk":"AJr/AQDavAEA6uYB","pt":1743512017571,"mc":[{"id":"1.241629436","rc":[{"atl":[[1000,23.16]],"id":270592},{"atb":[[55,6.6]],"atl":[[60,11.78]],"batb":[[0,55,6.6]],"batl":[[0,60,11.78]],"id":59626646},{"atl":[[7.8,35.01]],"batl":[],"id":26496185}]}]}
{"op":"mcm","id":2,"clk":"AKP/AQDmvAEA8uYB","pt":1743512017676,"mc":[{"id":"1.241629436","rc":[{"atb":[[50,20.43]],"batb":[[1,50,20.43]],"id":59626646},{"atl":[[16.5,3.39]],"batl":[[0,16.5,3.39]],"id":58186642}]}]}
{"op":"mcm","id":2,"clk":"AK3/AQDuvAEA9eYB","pt":1743512017738,"mc":[{"id":"1.241629436","rc":[{"atl":[[1000,21.16]],"id":270592}]}]}
{"op":"mcm","id":2,"clk":"AMj/AQCBvQEAi+cB","pt":1743512018033,"mc":[{"id":"1.241629436","rc":[{"atb":[[42,10.92]],"batb":[],"id":59626646}]}]}
{"op":"mcm","id":2,"clk":"AND/AQCGvQEAlecB","pt":1743512018138,"mc":[{"id":"1.241629436","rc":[{"atl":[[11.5,13.26]],"batl":[[0,11.5,13.26]],"id":40389088},{"atb":[[5.1,290.22]],"atl":[[5.3,184.95]],"batb":[[1,5.1,290.22]],"batl":[[0,5.3,184.95]],"id":270592},{"atb":[[50,23.01]],"atl":[[60,11.45]],"batb":[[1,50,23.01]],"batl":[[0,60,11.45]],"id":59626646},{"atb":[[5,1164.51]],"atl":[[5.2,220.09]],"batb":[[1,5,1164.51]],"batl":[[0,5.2,220.09]],"id":56297029},{"atl":[[1000,1.55]],"id":27115873},{"atb":[[6.4,318.95]],"batb":[[0,6.4,318.95]],"id":26496185}]}]}
{"op":"mcm","id":2,"clk":"ANv/AQCNvQEAoecB","pt":1743512018246,"mc":[{"id":"1.241629436","rc":[{"atb":[[5,1205.31]],"batb":[[1,5,1205.31]],"id":56297029},{"atl":[[1000,1.16]],"id":27115873}]}]}
{"op":"mcm","id":2,"clk":"AOP/AQCQvQEApucB","pt":1743512018344,"mc":[{"id":"1.241629436","rc":[{"atb":[[48,11.79],[46,10.12],[44,5.39]],"batb":[[2,48,11.79]],"id":59626646},{"atl":[[10.5,60.84]],"batl":[[0,10.5,60.84]],"id":27115873}]}]}
{"op":"mcm","id":2,"clk":"AJ6AAgC4vQEAz+cB","pt":1743512018857,"mc":[{"id":"1.241629436","rc":[{"atl":[[11.5,15.56]],"batl":[[0,11.5,15.56]],"id":40389088},{"atb":[[15.5,37.73]],"batb":[[1,15.5,37.73]],"id":58186642}]}]}
{"op":"mcm","id":2,"clk":"AKSAAgC9vQEA2ecB","pt":1743512018962,"mc":[{"id":"1.241629436","rc":[{"atb":[[5.2,254.44]],"batb":[[0,5.2,254.44]],"id":270592},{"atb":[[48,11.32],[46,9.61],[44,4.83]],"batb":[[2,48,11.32]],"id":59626646}]}]}
{"op":"mcm","id":2,"clk":"AN6AAgDivQEAhOgB","pt":1743512019533,"mc":[{"id":"1.241629436","rc":[{"atb":[[5.1,130.69]],"trd":[[5.1,4447.19]],"batb":[[0,5.1,130.69]],"tv":13539.15,"id":56297029}],"tv":79255.6}]}
{"op":"mcm","id":2,"clk":"APuAAgDzvQEAm+gB","pt":1743512019843,"mc":[{"id":"1.241629436","rc":[{"atl":[[7.8,13.18]],"batl":[],"id":26496185}]}]}
{"op":"mcm","id":2,"clk":"AImBAgCAvgEApegB","pt":1743512020055,"mc":[{"id":"1.241629436","rc":[{"atb":[[9.6,15.84]],"trd":[[9.6,612.2]],"batb":[[0,9.6,15.84]],"tv":9734.12,"id":35856222}],"tv":79259.6}]}
{"op":"mcm","id":2,"clk":"AI+BAgCMvgEAq+gB","pt":1743512020148,"mc":[{"id":"1.241629436","rc":[{"atb":[[9.6,9.57]],"batb":[[0,9.6,9.57]],"id":35856222}]}]}
{"op":"mcm","id":2,"clk":"AJmBAgCWvgEAsOgB","pt":1743512020255,"mc":[{"id":"1.241629436","rc":[{"atb":[[5.2,280.12]],"batb":[[0,5.2,280.12]],"id":270592}]}]}
{"op":"mcm","id":2,"clk":"ALGBAgCpvgEAw+gB","pt":1743512020557,"mc":[{"id":"1.241629436","rc":[{"atb":[[11,102]],"atl":[[12,84.99]],"batb":[[0,11,102]],"batl":[[1,12,84.99]],"id":40389088},{"atl":[[60,19.76]],"batl":[[0,60,19.76]],"id":59626646},{"atl":[[5.2,348.36]],"batl":[[0,5.2,348.36]],"id":56297029},{"atl":[[10.5,124.36]],"batl":[[0,10.5,124.36]],"id":27115873},{"atb":[[6.4,306.19]],"batb":[[0,6.4,306.19]],"id":26496185}]}]}
{"op":"mcm","id":2,"clk":"ALaBAgCtvgEAx+gB","pt":1743512020657,"mc":[{"id":"1.241629436","rc":[{"atb":[[10,0]],"trd":[[10,566.82]],"batb":[[2,9.4,72.74],[1,9.6,56.26],[0,9.8,43.63]],"tv":7164.9,"id":27115873}],"tv":79265.52}]}
{"op":"mcm","id":2,"clk":"AL2BAgC2vgEAz+gB","pt":1743512020764,"mc":[{"id":"1.241629436","rc":[{"atl":[[60,21.02]],"batl":[[0,60,21.02]],"id":59626646}]}]}
{"op":"mcm","id":2,"clk":"AMSBAgC+vgEA0+gB","pt":1743512020866,"mc":[{"id":"1.241629436","rc":[{"atb":[[5.1,291.22]],"batb":[[1,5.1,291.22]],"id":270592},{"atl":[[13.5,27.63],[13,10.09]],"batl":[],"id":27115873}]}]}
{"op":"mcm","id":2,"clk":"ANOBAgDHvgEA4egB","pt":1743512021071,"mc":[{"id":"1.241629436","rc":[{"atl":[[10,26.34]],"id":270592},{"atb":[[50,22.12]],"batb":[[1,50,22.12]],"id":59626646},{"atb":[[2.88,2]],"id":58186642}]}]}
{"op":"mcm","id":2,"clk":"AOKBAgDUvgEA9+gB","pt":1743512021281,"mc":[{"id":"1.241629436","rc":[{"atb":[[5.1,133.84]],"atl":[[1000,6.17]],"batb":[[0,5.1,133.84]],"id":56297029}]}]}
{"op":"mcm","id":2,"clk":"APaBAgDcvgEAg+kB","pt":1743512021443,"mc":[{"id":"1.241629436","rc":[{"atl":[[1000,5.52]],"id":56297029}]}]}
{"op":"mcm","id":2,"clk":"APyBAgDhvgEAi+kB","pt":1743512021541,"mc":[{"id":"1.241629436","rc":[{"atl":[[5.3,77.73]],"batl":[[1,5.3,77.73]],"id":56297029}]}]}
{"op":"mcm","id":2,"clk":"AIGCAgDovgEAj+kB","pt":1743512021639,"mc":[{"id":"1.241629436","rc":[{"atl":[[1000,23.16]],"id":270592}]}]}
{"op":"mcm","id":2,"clk":"AI+CAgDwvgEAqukB","pt":1743512021848,"mc":[{"id":"1.241629436","rc":[{"atl":[[1000,21.16]],"id":270592},{"atb":[[55,5],[50,21.53]],"trd":[[55,287.65]],"batb":[[1,50,21.53],[0,55,5]],"tv":1963.89,"id":59626646}],"tv":79268.72}]}
{"op":"mcm","id":2,"clk":"AJiCAgD1vgEAsOkB","pt":1743512021946,"mc":[{"id":"1.241629436","rc":[{"atb":[[9.6,15.18]],"batb":[[0,9.6,15.18]],"id":35856222},{"atb":[[9.8,43.7]],"batb":[[0,9.8,43.7]],"id":27115873}]}]}
{"op":"mcm","id":2,"clk":"AN2CAgC8vwEAhOoB","pt":1743512022937,"mc":[{"id":"1.241629436","rc":[{"atl":[[1000,23.16]],"id":270592}]}]}
{"op":"mcm","id":2,"clk":"AO+CAgDHvwEAleoB","pt":1743512023137,"mc":[{"id":"1.241629436","rc":[{"atl":[[1000,21.16]],"id":270592},{"atb":[[9.6,61.72]],"batb":[[1,9.6,61.72]],"id":27115873}]}]}
{"op":"mcm","id":2,"clk":"APWCAgDOvwEAmeoB","pt":1743512023243,"mc":[{"id":"1.241629436","rc":[{"atb":[[9.8,48.99]],"batb":[[0,9.8,48.99]],"id":27115873},{"atb":[[16,26.95]],"batb":[[0,16,26.95]],"id":58186642}]}]}
{"op":"mcm","id":2,"clk":"AJeDAgD+vwEAvOoB","pt":1743512023758,"mc":[{"id":"1.241629436","rc":[{"atb":[[1.17,2.7],[10.5,45.02]],"atl":[[1000,0.51],[11.5,14.58]],"batb":[[1,10.5,45.02]],"batl":[[0,11.5,14.58]],"id":40389088},{"atb":[[5.2,279.12]],"trd":[[5.2,2268.29]],"batb":[[0,5.2,279.12]],"tv":17568.36,"id":270592},{"atb":[[9.4,54.55],[1.17,8.03]],"atl":[[9.8,34.35]],"batb":[[1,9.4,54.55]],"batl":[[0,9.8,34.35]],"id":35856222},{"atl":[[5.2,343.38]],"batl":[[0,5.2,343.38]],"id":56297029},{"atl":[[1000,1.66],[10.5,123.97]],"batl":[[0,10.5,123.97]],"id":27115873},{"atb":[[15.5,37.25]],"atl":[[16.5,2.39]],"batb":[[1,15.5,37.25]],"batl":[[0,16.5,2.39]],"id":58186642},{"atb":[[6.4,309.03]],"batb":[[0,6.4,309.03]],"id":26496185}],"tv":79270.72}]}
{"op":"mcm","id":2,"clk":"AJ+DAgCAwAEAweoB","pt":1743512023856,"mc":[{"id":"1.241629436","rc":[{"atb":[[1.17,2]],"atl":[[1000,0.36]],"id":40389088},{"atl":[[1000,1.45]],"id":27115873}]}]}
{"op":"mcm","id":2,"clk":"AKmDAgCMwAEAyuoB","pt":1743512023961,"mc":[{"id":"1.241629436","rc":[{"atb":[[11,102.7]],"atl":[[1000,0.25],[12,85.14]],"batb":[[0,11,102.7]],"batl":[[1,12,85.14]],"id":40389088},{"atb":[[1.17,7.15]],"id":35856222},{"atl":[[1000,1.16],[10.5,124.18]],"batl":[[0,10.5,124.18]],"id":27115873}]}]}
{"op":"mcm","id":2,"clk":"ALKDAgCRwAEA1eoB","pt":1743512024064,"mc":[{"id":"1.241629436","rc":[{"atl":[[11.5,14.69]],"batl":[[0,11.5,14.69]],"id":40389088},{"atb":[[9.6,16.06]],"batb":[[0,9.6,16.06]],"id":35856222},{"atl":[[11,59.8]],"batl":[[1,11,59.8]],"id":27115873}]}]}
{"op":"mcm","id":2,"clk":"ALmDAgCYwAEA2OoB","pt":1743512024162,"mc":[{"id":"1.241629436","rc":[{"atb":[[5.1,138.23]],"batb":[[0,5.1,138.23]],"id":56297029}]}]}
{"op":"mcm","id":2,"clk":"AMKDAgCZwAEA3uoB","pt":1743512024263,"mc":[{"id":"1.241629436","rc":[{"atb":[[5.1,116.23]],"batb":[[0,5.1,116.23]],"id":56297029}]}]}
{"op":"mcm","id":2,"clk":"AMuDAgCfwAEA4+oB","pt":1743512024366,"mc":[{"id":"1.241629436","rc":[{"atl":[[5.2,321.38]],"trd":[[5.2,3700.37]],"batl":[[0,5.2,321.38]],"ltp":5.2,"tv":13583.15,"id":56297029}],"tv":79314.72}]}
{"op":"mcm","id":2,"clk":"APeDAgDIwAEAmesB","pt":1743512025135,"mc":[{"id":"1.241629436","rc":[{"atl":[[10.5,125.18]],"batl":[[0,10.5,125.18]],"id":27115873}]}]}
{"op":"mcm","id":2,"clk":"AICEAgDWwAEApesB","pt":1743512025253,"mc":[{"id":"1.241629436","rc":[{"atl":[[10,25.34]],"id":270592}]}]}
{"op":"mcm","id":2,"clk":"AJiEAgDmwAEAtusB","pt":1743512025549,"mc":[{"id":"1.241629436","rc":[{"atb":[[55,0]],"trd":[[55,297.65]],"batb":[[2,46,9.61],[1,48,11.32],[0,50,21.53]],"tv":1973.89,"id":59626646}],"tv":79324.72}]}
{"op":"mcm","id":2,"clk":"AKGEAgDrwAEAwesB","pt":1743512025659,"mc":[{"id":"1.241629436","rc":[{"atb":[[42,10.31],[40,23.31]],"batb":[],"id":59626646}]}]}
{"op":"mcm","id":2,"clk":"AKyEAgDwwAEAxusB","pt":1743512025767,"mc":[{"id":"1.241629436","rc":[{"atb":[[50,23.21],[40,22.63]],"batb":[[0,50,23.21]],"id":59626646}]}]}
{"op":"mcm","id":2,"clk":"ALSEAgD5wAEA0OsB","pt":1743512025859,"mc":[{"id":"1.241629436","rc":[{"atb":[[8.4,61.26],[6.6,5.65],[7.8,29.39],[7,35.4],[7.6,45.03],[6.8,41.1],[7.4,19.14],[8.2,13.77],[6.4,18.49],[8.6,23.9],[7.2,23.71],[8,47.9]],"batb":[],"id":35856222}]}]}
{"op":"mcm","id":2,"clk":"ALyEAgD7wAEA1esB","pt":1743512025961,"mc":[{"id":"1.241629436","rc":[{"atb":[[50,23.52]],"batb":[[0,50,23.52]],"id":59626646}]}]}
{"op":"mcm","id":2,"clk":"ANeEAgCKwQEA6usB","pt":1743512026271,"mc":[{"id":"1.241629436","rc":[{"atb":[[11,81.32]],"trd":[[11,219.58]],"batb":[[0,11,81.32]],"tv":6414.14,"id":40389088},{"atb":[[5.1,104.23]],"trd":[[5.1,4460.11]],"batb":[[0,5.1,104.23]],"ltp":5.1,"tv":13596.07,"id":56297029}],"tv":79378.5}]}
{"op":"mcm","id":2,"clk":"AOGEAgCPwQEA8+sB","pt":1743512026376,"mc":[{"id":"1.241629436","rc":[{"atb":[[11,86.32],[10.5,50.01]],"atl":[[11.5,25.82]],"batb":[[1,10.5,50.01],[0,11,86.32]],"batl":[[0,11.5,25.82]],"id":40389088},{"atb":[[15.5,40.68]],"batb":[[1,15.5,40.68]],"id":58186642}]}]}
{"op":"mcm","id":2,"clk":"AOWEAgCTwQEA+OsB","pt":1743512026478,"mc":[{"id":"1.241629436","rc":[{"atb":[[11,81.32],[1.01,121187.92]],"batb":[[0,11,81.32]],"id":40389088},{"atb":[[1.01,56382.91]],"id":56297029}]}]}
{"op":"mcm","id":2,"clk":"AP6EAgCjwQEAkewB","pt":1743512026742,"mc":[{"id":"1.241629436","rc":[{"atb":[[5.2,282.39]],"atl":[[1000,21.84]],"batb":[[0,5.2,282.39]],"id":270592},{"atb":[[9.8,50.41]],"batb":[[0,9.8,50.41]],"id":27115873}]}]}
{"op":"mcm","id":2,"clk":"AIeFAgCmwQEAlOwB","pt":1743512026836,"mc":[{"id":"1.241629436","rc":[{"atl":[[1000,21.16]],"id":270592},{"atb":[[8.6,24.53]],"batb":[],"id":35856222}]}]}
{"op":"mcm","id":2,"clk":"AJCFAgCvwQEAnOwB","pt":1743512026951,"mc":[{"id":"1.241629436","rc":[{"atl":[[5.4,122.2]],"batl":[[1,5.4,122.2]],"id":270592},{"atb":[[8.4,62.02],[8.2,14.7]],"batb":[],"id":35856222},{"atb":[[9.8,42.41]],"trd":[[9.8,511.86]],"batb":[[0,9.8,42.41]],"ltp":9.8,"tv":7180.9,"id":27115873}],"tv":79394.5}]}
{"op":"mcm","id":2,"clk":"AJaFAgC0wQEAp+wB","pt":1743512027051,"mc":[{"id":"1.241629436","rc":[{"atl":[[1000,23.16]],"id":270592},{"atb":[[7.8,30.81],[8,49.05]],"batb":[],"id":35856222}]}]}
{"op":"mcm","id":2,"clk":"AKCFAgC3wQEAquwB","pt":1743512027149,"mc":[{"id":"1.241629436","rc":[{"atb":[[7.6,46.78],[7.4,21.28]],"id":35856222}]}]}
{"op":"mcm","id":2,"clk":"AKSFAgC/wQEAs+wB","pt":1743512027264,"mc":[{"id":"1.241629436","rc":[{"atb":[[1.17,2.29]],"id":40389088},{"atl":[[1000,21.16]],"id":270592},{"atb":[[7,38.52],[7.2,26.3]],"id":35856222},{"atb":[[5.1,106.75]],"batb":[[0,5.1,106.75]],"id":56297029}]}]}
{"op":"mcm","id":2,"clk":"AKqFAgDCwQEAuOwB","pt":1743512027367,"mc":[{"id":"1.241629436","rc":[{"atb":[[6.6,10.07],[6.8,44.82]],"id":35856222},{"atl":[[55,1]],"batl":[[2,65,2.61],[1,60,21.02],[0,55,1]],"id":59626646}]}]}
{"op":"mcm","id":2,"clk":"ALCFAgDIwQEAwuwB","pt":1743512027468,"mc":[{"id":"1.241629436","rc":[{"atb":[[1.17,2]],"id":40389088},{"atb":[[6.4,23.7]],"id":35856222},{"atl":[[5.2,320.38]],"trd":[[5.2,3702.37]],"batl":[[0,5.2,320.38]],"ltp":5.2,"tv":13598.07,"id":56297029}],"tv":79396.5}]}
{"op":"mcm","id":2,"clk":"ALiFAgDVwQEAxewB","pt":1743512027572,"mc":[{"id":"1.241629436","rc":[{"atb":[[11,81.61]],"batb":[[0,11,81.61]],"id":40389088},{"atb":[[44,5.39],[42,10.92],[40,23.31]],"batb":[],"id":59626646}]}]}
{"op":"mcm","id":2,"clk":"AL6FAgDcwQEAzuwB","pt":1743512027669,"mc":[{"id":"1.241629436","rc":[{"atl":[[60,14.42]],"batl":[[1,60,14.42]],"id":59626646}]}]}
{"op":"mcm","id":2,"clk":"AMSFAgDewQEAz+wB","pt":1743512027759,"mc":[{"id":"1.241629436","rc":[{"atb":[[6,183.84]],"batb":[[2,6,183.84]],"id":26496185}]}]}
{"op":"mcm","id":2,"clk":"ANqFAgDywQEA4ewB","pt":1743512028072,"mc":[{"id":"1.241629436","rc":[{"atb":[[9.6,15.06]],"trd":[[9.6,614.2]],"batb":[[0,9.6,15.06]],"tv":9736.12,"id":35856222}],"tv":79398.5}]}
{"op":"mcm","id":2,"clk":"AOGFAgCAwgEA7OwB","pt":1743512028176,"mc":[{"id":"1.241629436","rc":[{"atl":[[5.2,319.38]],"trd":[[5.2,3704.37]],"batl":[[0,5.2,319.38]],"tv":13600.07,"id":56297029}],"tv":79400.5}]}
{"op":"mcm","id":2,"clk":"AOqFAgCGwgEA9+wB","pt":1743512028284,"mc":[{"id":"1.241629436","rc":[{"atb":[[5.2,0],[5.1,0]],"atl":[[5.4,133.67],[5.2,77.03],[5.3,197.25],[5.5,137.12],[5.1,87.98]],"trd":[[5.2,2833.07],[5.1,1708.22]],"batb":[[2,4.8,114.95],[1,4.9,231.56],[0,5,335.08]],"batl":[[2,5.3,197.25],[1,5.2,77.03],[0,5.1,87.98]],"ltp":5.1,"tv":18698.5,"id":270592},{"atl":[[5.4,81.42],[5.2,340.76],[5.3,97.66]],"batl":[[2,5.4,81.42],[1,5.3,97.66],[0,5.2,340.76]],"id":56297029},{"atb":[[9.4,76.69],[9.8,47.25],[9.6,66.23]],"batb":[[2,9.4,76.69],[1,9.6,66.23],[0,9.8,47.25]],"id":27115873},{"atb":[[15.5,43.2],[15,21.71],[17,6.5],[16.5,0.65],[16,29.66]],"atl":[[17,0],[16.5,0]],"trd":[[17,980.96],[16.5,629.6]],"batb":[[2,15.5,43.2],[1,16,30.31],[0,17,6.5]],"batl":[[2,18.5,15.39],[1,18,18.98],[0,17.5,13.68]],"ltp":17,"tv":5688.89,"id":58186642},{"atb":[[6.6,12.73],[6,200.62],[6.2,190.23],[6.4,329.59]],"atl":[[6.6,0]],"trd":[[6.6,2138.78]],"batb":[[2,6.2,190.23],[1,6.4,329.59],[0,6.6,12.73]],"batl":[[2,7.2,108.97],[1,7,37.52],[0,6.8,155.48]],"ltp":6.6,"tv":12681.95,"id":26496185},{"atl":[[12.5,41.79],[12,30.76]],"batl":[[2,12.5,41.79],[1,12,30.76]],"id":44049799}],"tv":80801.12}]}
{"op":"mcm","id":2,"clk":"AO2FAgCJwgEA+ewB","pt":1743512028381,"mc":[{"id":"1.241629436","rc":[{"atl":[[1000,23.16],[5.2,82.7]],"batl":[[1,5.2,82.7]],"id":270592},{"atb":[[9.8,65.61]],"batb":[[0,9.8,65.61]],"id":27115873},{"atb":[[17,28.41],[16.5,2.32]],"atl":[[17.5,12.14]],"trd":[[17.5,201.03]],"batb":[[2,16,29.66],[1,16.5,2.32],[0,17,28.41]],"batl":[[0,17.5,12.14]],"ltp":17.5,"tv":5691.97,"id":58186642}],"tv":80804.2}]}
{"op":"mcm","id":2,"clk":"APuFAgCYwgEAh+0B","pt":1743512028504,"mc":[{"id":"1.241629436","rc":[{"atb":[[11,91.61]],"batb":[[0,11,91.61]],"id":40389088},{"atb":[[4.7,175.96],[4.9,230.56],[4.6,119.03],[5,294.72],[4.8,140.95]],"atl":[[5.7,74.84],[5.2,119.43],[5.1,143.47],[5.6,166.83]],"trd":[[5.1,1754.64]],"batb":[[2,4.8,140.95],[1,4.9,230.56],[0,5,294.72]],"batl":[[1,5.2,119.43],[0,5.1,143.47]],"tv":18744.92,"id":270592},{"atb":[[9.2,65.29]],"atl":[[9.8,27.42]],"batb":[[2,9.2,65.29]],"batl":[[0,9.8,27.42]],"id":35856222},{"atb":[[44,4.83],[42,10.31],[40,22.63]],"batb":[],"id":59626646},{"atb":[[4.9,89.72]],"atl":[[5.2,338.42]],"batb":[[2,4.9,89.72]],"batl":[[0,5.2,338.42]],"id":56297029},{"atb":[[10,5.08]],"batb":[[2,9.6,66.23],[1,9.8,65.61],[0,10,5.08]],"id":27115873},{"atb":[[15,20.71],[17.5,9.42],[17,36.86],[16.5,30.65]],"atl":[[18.5,12.13],[18,15.65],[17.5,0]],"trd":[[17.5,214.41]],"batb":[[2,16.5,30.65],[1,17,36.86],[0,17.5,9.42]],"batl":[[2,19,10.73],[1,18.5,12.13],[0,18,15.65]],"tv":5705.35,"id":58186642},{"atb":[[5.9,102.98],[6.6,90.57],[5.8,131.34]],"atl":[[7,46.01],[6.8,146.52]],"trd":[[6.6,2151.89]],"batb":[[0,6.6,90.57]],"batl":[[1,7,46.01],[0,6.8,146.52]],"tv":12695.06,"id":26496185}],"tv":80877.11}]}
{"op":"mcm","id":2,"clk":"APyFAgCYwgEAh+0B","pt":1743512028536,"mc":[{"id":"1.241629436","rc":[{"atb":[[10.5,51.01]],"batb":[[1,10.5,51.01]],"id":40389088},{"atb":[[4.9,218.85],[5,231.03]],"atl":[[1000,21.16]],"batb":[[1,4.9,218.85],[0,5,231.03]],"id":270592},{"atb":[[50,21.84]],"batb":[[0,50,21.84]],"id":59626646},{"atb":[[17,40.11]],"atl":[[19.5,7.88],[19,7.66]],"batb":[[1,17,40.11]],"batl":[[2,19,7.66]],"id":58186642},{"atb":[[5.9,93.13],[6.6,50.57]],"atl":[[7.2,117.49]],"trd":[[6.6,2231.88]],"batb":[[0,6.6,50.57]],"batl":[[2,7.2,117.49]],"tv":12775.05,"id":26496185}],"tv":80957.1}]}
{"op":"mcm","id":2,"clk":"AIGGAgCnwgEAke0B","pt":1743512028696,"mc":[{"id":"1.241629436","rc":[{"atb":[[4.7,177.02],[4.4,137.99],[5,231.07],[4.8,146.65]],"atl":[[5.4,134.51],[5.6,168.81]],"batb":[[2,4.8,146.65],[0,5,231.07]],"batl":[],"id":270592},{"atb":[[4.9,78.72]],"batb":[[2,4.9,78.72]],"id":56297029},{"atb":[[10,3.48]],"atl":[[13,11.76],[12.5,280.02],[17,24.98]],"trd":[[10,570.02]],"batb":[[0,10,3.48]],"batl":[],"ltp":10,"tv":7184.1,"id":27115873},{"atb":[[15,18.29],[18,7.19],[17,44.26],[17.5,19.86],[16.5,19.27]],"atl":[[20,7.09],[19.5,4.63],[18,0]],"trd":[[18,135.09],[17.5,233.25],[17,982.86]],"batb":[[2,17,44.26],[1,17.5,19.86],[0,18,7.19]],"batl":[[2,19.5,4.63],[1,19,7.66],[0,18.5,12.13]],"ltp":18,"tv":5752.77,"id":58186642},{"atb":[[6.6,60.19]],"atl":[[7,37.52],[6.8,141.69],[9,20.32]],"trd":[[6.8,448.94]],"batb":[[0,6.6,60.19]],"batl":[[1,7,37.52],[0,6.8,141.69]],"ltp":6.8,"tv":12784.71,"id":26496185}],"tv":81017.38}]}
{"op":"mcm","id":2,"clk":"AIqGAgCwwgEAme0B","pt":1743512028754,"mc":[{"id":"1.241629436","rc":[{"atb":[[4.7,174.08],[4.6,115.94],[5,189.6],[4.8,125.2]],"atl":[[5.1,169.43]],"trd":[[5,2034.12]],"batb":[[2,4.8,125.2],[0,5,189.6]],"batl":[[0,5.1,169.43]],"ltp":5,"tv":18757.16,"id":270592},{"atl":[[5.2,337.42]],"trd":[[5.2,3706.37]],"batl":[[0,5.2,337.42]],"tv":13602.07,"id":56297029},{"atb":[[15.5,54.18]],"batb":[],"id":58186642},{"atb":[[6,201.41]],"atl":[[6.8,124.33]],"batb":[],"batl":[[0,6.8,124.33]],"id":26496185}],"tv":81031.62}]}
{"op":"mcm","id":2,"clk":"AJKGAgC0wgEAoO0B","pt":1743512028850,"mc":[{"id":"1.241629436","rc":[{"atb":[[11,88.49]],"batb":[[0,11,88.49]],"id":40389088},{"atb":[[5,187.58],[4.5,65.51]],"trd":[[5,2038.16]],"batb":[[0,5,187.58]],"tv":18761.2,"id":270592},{"atl":[[9.8,34.35]],"batl":[[0,9.8,34.35]],"id":35856222},{"atb":[[4,53.01]],"id":59626646},{"atb":[[4.9,89.72]],"atl":[[5.2,339.76]],"batb":[[2,4.9,89.72]],"batl":[[0,5.2,339.76]],"id":56297029},{"atb":[[10,0]],"atl":[[10.5,132.97],[10,7.46]],"trd":[[10,576.98]],"batb":[[2,9.4,76.69],[1,9.6,66.23],[0,9.8,65.61]],"batl":[[2,11,59.8],[1,10.5,132.97],[0,10,7.46]],"tv":7191.06,"id":27115873},{"atb":[[15.5,51.83],[18,3.59],[17.5,16.58]],"atl":[[21,14.06],[20,3.88],[19,12.28],[18.5,2.43]],"trd":[[18,142.29]],"batb":[[1,17.5,16.58],[0,18,3.59]],"batl":[[1,19,12.28],[0,18.5,2.43]],"tv":5759.97,"id":58186642},{"atb":[[6.6,66.25]],"atl":[[7,42.66]],"batb":[[0,6.6,66.25]],"batl":[[1,7,42.66]],"id":26496185}],"tv":81049.82}]}
{"op":"mcm","id":2,"clk":"AJuGAgC7wgEAou0B","pt":1743512028953,"mc":[{"id":"1.241629436","rc":[{"atb":[[5,0]],"atl":[[5.2,139.84],[5,68.67]],"trd":[[5,2413.32]],"batb":[[2,4.7,174.08],[1,4.8,125.2],[0,4.9,218.85]],"batl":[[2,5.2,139.84],[1,5.1,169.43],[0,5,68.67]],"tv":19136.36,"id":270592},{"atb":[[15.5,43.83],[18,11.04]],"batb":[[0,18,11.04]],"id":58186642}],"tv":81424.98}]}
{"op":"mcm","id":2,"clk":"AKSGAgDDwgEAq+0B","pt":1743512029062,"mc":[{"id":"1.241629436","rc":[{"atb":[[4.7,184.39],[4.4,143.6],[4.6,121.55],[4.5,71.12],[4.8,113.23]],"atl":[[5.4,133.67],[5.8,155.47],[5,80.04],[5.6,166.83]],"batb":[[2,4.7,184.39],[1,4.8,113.23]],"batl":[[0,5,80.04]],"id":270592},{"atb":[[4.9,78.72],[5.1,112.38]],"atl":[[5.2,337.42]],"batb":[[2,4.9,78.72],[0,5.1,112.38]],"batl":[[0,5.2,337.42]],"id":56297029},{"atl":[[10.5,130.9]],"batl":[[1,10.5,130.9]],"id":27115873},{"atb":[[18.5,4.74],[18,14.11]],"atl":[[18.5,0]],"trd":[[18.5,71.29]],"batb":[[2,17.5,16.58],[1,18,14.11],[0,18.5,4.74]],"batl":[[2,20,3.88],[1,19.5,4.63],[0,19,12.28]],"ltp":18.5,"tv":5764.83,"id":58186642},{"atb":[[6.6,71.85],[5.7,83.35],[6,206.28]],"batb":[[0,6.6,71.85]],"id":26496185}],"tv":81429.84}]}
{"op":"mcm","id":2,"clk":"AKyGAgDKwgEAsO0B","pt":1743512029162,"mc":[{"id":"1.241629436","rc":[{"atb":[[4.6,150.64],[4.5,74.37]],"batb":[],"id":270592},{"atb":[[9.8,65.54],[6,11.6]],"batb":[[0,9.8,65.54]],"id":27115873},{"atb":[[18.5,0],[17.5,20.02],[16,29.53]],"atl":[[22,9.56],[21,10.93],[19.5,9.12],[19,9.05],[18.5,1]],"trd":[[18.5,80.77]],"batb":[[2,17,44.26],[1,17.5,20.02],[0,18,14.11]],"batl":[[2,19.5,9.12],[1,19,9.05],[0,18.5,1]],"tv":5774.31,"id":58186642}],"tv":81439.32}]}
{"op":"mcm","id":2,"clk":"ALeGAgDPwgEAuO0B","pt":1743512029265,"mc":[{"id":"1.241629436","rc":[{"atb":[[4.6,151.73],[4.3,49.68]],"atl":[[5.3,198.11],[10,25.24]],"batb":[],"batl":[],"id":270592},{"atb":[[4.9,89.71]],"batb":[[2,4.9,89.71]],"id":56297029},{"atb":[[18.5,5.72],[17.5,20.66]],"atl":[[26,5.76],[18.5,0]],"trd":[[18.5,82.77]],"batb":[[2,17.5,20.66],[1,18,14.11],[0,18.5,5.72]],"batl":[[2,20,3.88],[1,19.5,9.12],[0,19,9.05]],"tv":5776.31,"id":58186642},{"atb":[[6.6,96.85]],"batb":[[0,6.6,96.85]],"id":26496185}],"tv":81441.32}]}
{"op":"mcm","id":2,"clk":"ALuGAgDVwgEAwO0B","pt":1743512029361,"mc":[{"id":"1.241629436","rc":[{"atl":[[5.2,139.94]],"batl":[[2,5.2,139.94]],"id":270592},{"atl":[[10,8.46]],"batl":[[0,10,8.46]],"id":27115873},{"atb":[[18,16.32],[18.5,13.17],[16,19.55]],"batb":[[1,18,16.32],[0,18.5,13.17]],"id":58186642},{"atl":[[6.8,125.6]],"batl":[[0,6.8,125.6]],"id":26496185}]}]}
{"op":"mcm","id":2,"clk":"AMeGAgDdwgEAx+0B","pt":1743512029471,"mc":[{"id":"1.241629436","rc":[{"atl":[[12,84.99],[11.5,25.71]],"batl":[[1,12,84.99],[0,11.5,25.71]],"id":40389088},{"atl":[[1000,22.09],[5.4,132.99]],"batl":[],"id":270592},{"atb":[[5,1203.62]],"atl":[[5.2,334.07]],"batb":[[1,5,1203.62]],"batl":[[0,5.2,334.07]],"id":56297029},{"atl":[[1000,1.42],[11,59.51],[10.5,130.69]],"batl":[[2,11,59.51],[1,10.5,130.69]],"id":27115873},{"atb":[[18.5,11.07]],"atl":[[19,4.43]],"trd":[[18.5,86.97]],"batb":[[0,18.5,11.07]],"batl":[[0,19,4.43]],"tv":5780.51,"id":58186642},{"atb":[[6.6,103.66],[6.4,322.27]],"atl":[[7,44.03],[6.8,125.12]],"batb":[[1,6.4,322.27],[0,6.6,103.66]],"batl":[[1,7,44.03],[0,6.8,125.12]],"id":26496185}],"tv":81445.52}]}
{"op":"mcm","id":2,"clk":"ANWGAgDowgEA0u0B","pt":1743512029578,"mc":[{"id":"1.241629436","rc":[{"atl":[[1000,21.16]],"id":270592},{"atb":[[18,19.12],[18.5,14.07],[17.5,17.22]],"atl":[[20,6.08],[19,9.02]],"batb":[[2,17.5,17.22],[1,18,19.12],[0,18.5,14.07]],"batl":[[2,20,6.08],[0,19,9.02]],"id":58186642}]}]}
{"op":"mcm","id":2,"clk":"AN2GAgDvwgEA1O0B","pt":1743512029675,"mc":[{"id":"1.241629436","rc":[{"atb":[[4.4,149.2],[4.5,79.97]],"atl":[[5.8,136.39],[5,80.43],[5.1,169.97]],"batb":[],"batl":[[1,5.1,169.97],[0,5,80.43]],"id":270592},{"atl":[[1000,1.16]],"id":27115873},{"atb":[[6,224.98]],"batb":[],"id":26496185}]}]}
{"op":"mcm","id":2,"clk":"AOmGAgD5wgEA1+0B","pt":1743512029779,"mc":[{"id":"1.241629436","rc":[{"atl":[[10.5,130.95]],"batl":[[1,10.5,130.95]],"id":27115873},{"atb":[[17.5,21.69]],"atl":[[27,4.68]],"batb":[[2,17.5,21.69]],"batl":[],"id":58186642}]}]}
{"op":"mcm","id":2,"clk":"AO+GAgD/wgEA3+0B","pt":1743512029882,"mc":[{"id":"1.241629436","rc":[{"atl":[[10,9.46]],"batl":[[0,10,9.46]],"id":27115873}]}]}
{"op":"mcm","id":2,"clk":"APqGAgCJwwEA4e0B","pt":1743512029985,"mc":[{"id":"1.241629436","rc":[{"atl":[[5.4,157.21]],"batl":[],"id":270592},{"atb":[[17,54.71]],"batb":[],"id":58186642}]}]}
{"op":"mcm","id":2,"clk":"AIuHAgCawwEA6O0B","pt":1743512030144,"mc":[{"id":"1.241629436","rc":[{"atl":[[11,69.48]],"batl":[[2,11,69.48]],"id":27115873}]}]}
{"op":"mcm","id":2,"clk":"AJWHAgCiwwEA6u0B","pt":1743512030253,"mc":[{"id":"1.241629436","rc":[{"atl":[[620,1]],"id":59626646},{"atb":[[5.1,110.38]],"trd":[[5.1,4464.11]],"batb":[[0,5.1,110.38]],"ltp":5.1,"tv":13606.07,"id":56297029}],"tv":81449.52}]}
{"op":"mcm","id":2,"clk":"AJ2HAgCowwEA8u0B","pt":1743512030348,"mc":[{"id":"1.241629436","rc":[{"atl":[[19,4.43]],"batl":[[0,19,4.43]],"id":58186642},{"atb":[[6.6,133.66]],"batb":[[0,6.6,133.66]],"id":26496185}]}]}
{"op":"mcm","id":2,"clk":"AKaHAgCxwwEA9+0B","pt":1743512030456,"mc":[{"id":"1.241629436","rc":[{"atb":[[18.5,15.07]],"batb":[[0,18.5,15.07]],"id":58186642},{"atb":[[6.6,135.66]],"batb":[[0,6.6,135.66]],"id":26496185}]}]}
{"op":"mcm","id":2,"clk":"ALiHAgC/wwEAhe4B","pt":1743512030666,"mc":[{"id":"1.241629436","rc":[{"atl":[[5,43.71]],"trd":[[5,2486.76]],"batl":[[0,5,43.71]],"tv":19209.8,"id":270592},{"atb":[[5.1,110.28]],"trd":[[5.1,4464.31]],"batb":[[0,5.1,110.28]],"tv":13606.27,"id":56297029},{"atb":[[9.4,80.19]],"atl":[[21,7.84]],"batb":[[2,9.4,80.19]],"id":27115873},{"atb":[[15.5,40.4],[15,14.84],[14.5,33.44]],"batb":[],"id":58186642}],"tv":81523.16}]}
{"op":"mcm","id":2,"clk":"AMCHAgDGwwEAh+4B","pt":1743512030760,"mc":[{"id":"1.241629436","rc":[{"atl":[[5,11.76]],"batl":[[0,5,11.76]],"id":270592},{"atl":[[19,8.93]],"batl":[[0,19,8.93]],"id":58186642}]}]}
{"op":"mcm","id":2,"clk":"AMyHAgDKwwEAje4B","pt":1743512030861,"mc":[{"id":"1.241629436","rc":[{"atl":[[5,0]],"trd":[[5,2510.28]],"batl":[[2,5.3,198.11],[1,5.2,139.94],[0,5.1,169.97]],"tv":19233.32,"id":270592},{"atb":[[5.9,98.74]],"batb":[],"id":26496185}],"tv":81546.68}]}
{"op":"mcm","id":2,"clk":"ANiHAgDSwwEAku4B","pt":1743512030963,"mc":[{"id":"1.241629436","rc":[{"atb":[[4.9,230.2],[4.8,124.59]],"batb":[[1,4.8,124.59],[0,4.9,230.2]],"id":270592},{"atb":[[4.9,78.72]],"batb":[[2,4.9,78.72]],"id":56297029},{"atb":[[16.5,22.52]],"atl":[[22,14.03],[21,13.94]],"batb":[],"batl":[],"id":58186642},{"atb":[[6.6,137.66]],"batb":[[0,6.6,137.66]],"id":26496185}]}]}
{"op":"mcm","id":2,"clk":"AOSHAgDcwwEAn+4B","pt":1743512031071,"mc":[{"id":"1.241629436","rc":[{"atb":[[4.6,148.64]],"atl":[[5.4,132.99],[5.9,84.06]],"batb":[],"batl":[],"id":270592},{"atb":[[9.2,59.19]],"batb":[[2,9.2,59.19]],"id":35856222},{"atb":[[6.6,139.66]],"batb":[[0,6.6,139.66]],"id":26496185}]}]}
{"op":"mcm","id":2,"clk":"AOqHAgDhwwEAoO4B","pt":1743512031169,"mc":[{"id":"1.241629436","rc":[{"atb":[[4.9,80.2],[4.5,102.45]],"trd":[[4.9,2476.21]],"batb":[[0,4.9,80.2]],"ltp":4.9,"tv":19533.32,"id":270592},{"atb":[[16.5,33.15]],"batb":[],"id":58186642}],"tv":81846.68}]}
{"op":"mcm","id":2,"clk":"APOHAgDrwwEAqO4B","pt":1743512031277,"mc":[{"id":"1.241629436","rc":[{"atb":[[4.7,190],[4.9,106.2]],"atl":[[5.3,197.25],[5,84.48],[5.1,205.26],[5.6,161.34]],"batb":[[2,4.7,190],[0,4.9,106.2]],"batl":[[2,5.2,139.94],[1,5.1,205.26],[0,5,84.48]],"id":270592},{"atb":[[9.2,65.05]],"atl":[[9.8,30.89]],"batb":[[2,9.2,65.05]],"batl":[[0,9.8,30.89]],"id":35856222},{"atl":[[5.2,328.44]],"batl":[[0,5.2,328.44]],"id":56297029},{"atl":[[19,4.43]],"batl":[[0,19,4.43]],"id":58186642}]}]}
{"op":"mcm","id":2,"clk":"AIGIAgDwwwEAqe4B","pt":1743512031381,"mc":[{"id":"1.241629436","rc":[{"atb":[[11,83.49]],"trd":[[11,229.58]],"batb":[[0,11,83.49]],"tv":6424.14,"id":40389088},{"atb":[[4.6,151.73]],"atl":[[5.3,198.11],[5,95.88]],"batb":[],"batl":[[0,5,95.88]],"id":270592},{"atl":[[5.2,338.44]],"batl":[[0,5.2,338.44]],"id":56297029},{"atb":[[6.6,161.66]],"batb":[[0,6.6,161.66]],"id":26496185}],"tv":81856.68}]}
{"op":"mcm","id":2,"clk":"AImIAgD4wwEAru4B","pt":1743512031485,"mc":[{"id":"1.241629436","rc":[{"atb":[[4.9,94.84]],"atl":[[5,120.94]],"batb":[[0,4.9,94.84]],"batl":[[0,5,120.94]],"id":270592},{"atl":[[9.8,22.73]],"batl":[[0,9.8,22.73]],"id":35856222},{"atl":[[21,10.93]],"batl":[],"id":58186642}]}]}
{"op":"mcm","id":2,"clk":"AI6IAgD8wwEAs+4B","pt":1743512031584,"mc":[{"id":"1.241629436","rc":[{"atl":[[9.8,19.26]],"batl":[[0,9.8,19.26]],"id":35856222},{"atb":[[19,4.45]],"atl":[[19,0]],"trd":[[19,132.66]],"batb":[[2,18,19.12],[1,18.5,15.07],[0,19,4.45]],"batl":[[2,21,10.93],[1,20,6.08],[0,19.5,9.12]],"ltp":19,"tv":5789.37,"id":58186642},{"atb":[[6.6,182.01]],"batb":[[0,6.6,182.01]],"id":26496185}],"tv":81865.54}]}
{"op":"mcm","id":2,"clk":"AJSIAgCDxAEAtu4B","pt":1743512031652,"mc":[{"id":"1.241629436","rc":[{"atb":[[9.6,20.87]],"batb":[[0,9.6,20.87]],"id":35856222},{"atl":[[55,0.2]],"trd":[[55,299.25]],"batl":[[2,70,2.85],[1,65,2.61],[0,60,14.62]],"tv":1975.49,"id":59626646},{"atb":[[19,4.37]],"trd":[[19,132.82]],"batb":[[0,19,4.37]],"tv":5789.53,"id":58186642}],"tv":81867.3}]}
{"op":"mcm","id":2,"clk":"AJ6IAgCIxAEAu+4B","pt":1743512031753,"mc":[{"id":"1.241629436","rc":[{"atb":[[4.9,74.2]],"batb":[[0,4.9,74.2]],"id":270592},{"atl":[[55,0]],"trd":[[55,299.65]],"batl":[[0,60,14.42]],"tv":1975.89,"id":59626646},{"atb":[[19,0],[18.5,17.25],[16.5,30.8]],"atl":[[22,9.56],[19.5,6.93]],"trd":[[19,141.56]],"batb":[[2,17.5,21.69],[1,18,19.12],[0,18.5,17.25]],"batl":[[0,19.5,6.93]],"tv":5798.27,"id":58186642}],"tv":81876.44}]}
{"op":"mcm","id":2,"clk":"AKWIAgCNxAEAwO4B","pt":1743512031844,"mc":[{"id":"1.241629436","rc":[{"atb":[[4.9,0]],"atl":[[4.9,0.8]],"trd":[[4.9,2624.61]],"batb":[[2,4.6,151.73],[1,4.7,190],[0,4.8,124.59]],"batl":[[0,5,121.74]],"tv":19681.72,"id":270592},{"atb":[[1.01,59224.84]],"id":35856222},{"atb":[[18.5,17.31]],"atl":[[21,13.1]],"batb":[[0,18.5,17.31]],"batl":[[2,21,13.1]],"id":58186642}],"tv":82024.84}]}
{"op":"mcm","id":2,"clk":"ALOIAgCQxAEAyO4B","pt":1743512031948,"mc":[{"id":"1.241629436","rc":[{"atb":[[4.6,150.64],[4.5,79.97]],"atl":[[4.9,0]],"trd":[[4.9,2626.21]],"batb":[[2,4.6,150.64]],"batl":[[0,5,120.94]],"tv":19683.32,"id":270592},{"atl":[[9.8,11.4]],"trd":[[9.8,770.92]],"batl":[[0,9.8,11.4]],"ltp":9.8,"tv":9739.7,"id":35856222},{"atb":[[55,3.45]],"batb":[[2,48,11.32],[1,50,21.84],[0,55,3.45]],"id":59626646},{"atb":[[5,1205.66]],"batb":[[1,5,1205.66]],"id":56297029}],"tv":82030.02}]}
{"op":"mcm","id":2,"clk":"ALuIAgCWxAEAzO4B","pt":1743512032055,"mc":[{"id":"1.241629436","rc":[{"atb":[[4.6,147.55],[4.3,69.41],[4.5,106.97],[4.8,140.45]],"atl":[[4.9,62.85],[5,141.85]],"batb":[[2,4.6,147.55],[0,4.8,140.45]],"batl":[[2,5.1,205.26],[1,5,141.85],[0,4.9,62.85]],"id":270592},{"atb":[[55,5.27]],"batb":[[0,55,5.27]],"id":59626646},{"atl":[[12.5,278.2]],"batl":[],"id":27115873}]}]}
{"op":"mcm","id":2,"clk":"AMaIAgCdxAEA0e4B","pt":1743512032158,"mc":[{"id":"1.241629436","rc":[{"atb":[[4.6,150.64],[4.5,108.1]],"atl":[[4.9,74.45]],"batb":[[2,4.6,150.64]],"batl":[[0,4.9,74.45]],"id":270592},{"atb":[[9.4,60.35]],"batb":[[1,9.4,60.35]],"id":35856222},{"atb":[[50,21.53]],"batb":[[1,50,21.53]],"id":59626646},{"atb":[[6.6,192.01]],"batb":[[0,6.6,192.01]],"id":26496185}]}]}
{"op":"mcm","id":2,"clk":"ANOIAgCgxAEA2O4B","pt":1743512032263,"mc":[{"id":"1.241629436","rc":[{"atl":[[9.8,9.61]],"trd":[[9.8,774.5]],"batl":[[0,9.8,9.61]],"tv":9743.28,"id":35856222},{"atl":[[6.8,113.94]],"batl":[[0,6.8,113.94]],"id":26496185}],"tv":82033.6}]}
{"op":"mcm","id":2,"clk":"ANiIAgCjxAEA3O4B","pt":1743512032360,"mc":[{"id":"1.241629436","rc":[{"atb":[[4.2,21.93],[4.6,156.24],[4.3,75.02]],"batb":[[2,4.6,156.24]],"id":270592},{"atl":[[9.8,7.82]],"trd":[[9.8,778.08]],"batl":[[0,9.8,7.82]],"tv":9746.86,"id":35856222},{"atb":[[19,4.44]],"batb":[[2,18,19.12],[1,18.5,17.31],[0,19,4.44]],"id":58186642},{"atb":[[6.6,189.81]],"trd":[[6.6,2236.28]],"batb":[[0,6.6,189.81]],"ltp":6.6,"tv":12789.11,"id":26496185}],"tv":82041.58}]}
{"op":"mcm","id":2,"clk":"AOCIAgCqxAEA5O4B","pt":1743512032463,"mc":[{"id":"1.241629436","rc":[{"atb":[[1.17,2.42]],"id":40389088},{"atb":[[4.2,51.11],[4.8,129.08]],"atl":[[1000,23.16],[4.9,60.97],[5,120.94]],"trd":[[4.9,2653.17]],"batb":[[0,4.8,129.08]],"batl":[[1,5,120.94],[0,4.9,60.97]],"tv":19710.28,"id":270592},{"atl":[[1000,0.55],[9.8,11.03]],"batl":[[0,9.8,11.03]],"id":35856222},{"atb":[[19,8.72],[18,19.86],[16.5,22.35]],"trd":[[19,147.9]],"batb":[[2,18,19.86],[0,19,8.72]],"tv":5804.61,"id":58186642}],"tv":82074.88}]}
{"op":"mcm","id":2,"clk":"AOmIAgC4xAEA6+4B","pt":1743512032573,"mc":[{"id":"1.241629436","rc":[{"atl":[[4.9,11.6],[5.3,197.25]],"batl":[[0,4.9,11.6]],"id":270592},{"atb":[[19,11.63],[18.5,20.13]],"batb":[[1,18.5,20.13],[0,19,11.63]],"id":58186642},{"atb":[[6.6,193.67]],"batb":[[0,6.6,193.67]],"id":26496185}]}]}
{"op":"mcm","id":2,"clk":"APCIAgC9xAEA8O4B","pt":1743512032670,"mc":[{"id":"1.241629436","rc":[{"atb":[[1.17,2]],"id":40389088},{"atb":[[4.8,140.67]],"atl":[[1000,21.16],[5.2,140.81]],"batb":[[0,4.8,140.67]],"batl":[],"id":270592},{"atl":[[1000,0.41]],"id":35856222},{"atb":[[16.5,19.1]],"batb":[],"id":58186642}]}]}
{"op":"mcm","id":2,"clk":"APWIAgDExAEA9+4B","pt":1743512032770,"mc":[{"id":"1.241629436","rc":[{"atb":[[11,83.91]],"batb":[[0,11,83.91]],"id":40389088},{"atl":[[4.9,0]],"trd":[[4.9,2676.37]],"batl":[[2,5.2,140.81],[1,5.1,205.26],[0,5,120.94]],"tv":19733.48,"id":270592},{"atb":[[9,57.58]],"atl":[[9.8,9.24],[10,106.58]],"trd":[[9.8,781.66]],"batb":[],"batl":[[1,10,106.58],[0,9.8,9.24]],"tv":9750.44,"id":35856222}],"tv":82101.66}]}
{"op":"mcm","id":2,"clk":"AImJAgDVxAEAhO8B","pt":1743512032976,"mc":[{"id":"1.241629436","rc":[{"atb":[[4.6,153.15]],"batb":[[2,4.6,153.15]],"id":270592},{"atl":[[10.5,136.6]],"batl":[[1,10.5,136.6]],"id":27115873},{"atl":[[28,3.86]],"batl":[],"id":58186642},{"atl":[[7,52.43]],"batl":[[1,7,52.43]],"id":26496185}]}]}
{"op":"mcm","id":2,"clk":"AJGJAgDbxAEAie8B","pt":1743512033079,"mc":[{"id":"1.241629436","rc":[{"atb":[[2.2,19.6]],"id":270592},{"atb":[[1.01,59223.39]],"id":35856222},{"atl":[[21,16.02]],"batl":[[2,21,16.02]],"id":58186642},{"atb":[[6.6,203.67]],"batb":[[0,6.6,203.67]],"id":26496185},{"atl":[[12,35.76]],"batl":[[1,12,35.76]],"id":44049799}]}]}
{"op":"mcm","id":2,"clk":"AJmJAgDlxAEAkO8B","pt":1743512033185,"mc":[{"id":"1.241629436","rc":[{"atl":[[5,109.54]],"batl":[[0,5,109.54]],"id":270592},{"atl":[[10.5,138.6]],"batl":[[1,10.5,138.6]],"id":27115873}]}]}
{"op":"mcm","id":2,"clk":"AKSJAgDuxAEAmO8B","pt":1743512033247,"mc":[{"id":"1.241629436","rc":[{"atl":[[19.5,4.56]],"batl":[[0,19.5,4.56]],"id":58186642},{"atb":[[6,222.98]],"batb":[],"id":26496185}]}]}
{"op":"mcm","id":2,"clk":"AK2JAgD0xAEAn+8B","pt":1743512033345,"mc":[{"id":"1.241629436","rc":[{"atl":[[5.2,139.94]],"batl":[[2,5.2,139.94]],"id":270592},{"atl":[[9.8,7.45]],"trd":[[9.8,785.24]],"batl":[[0,9.8,7.45]],"tv":9754.02,"id":35856222},{"atb":[[6,218.98]],"batb":[],"id":26496185}],"tv":82105.24}]}
{"op":"mcm","id":2,"clk":"ALmJAgD8xAEApe8B","pt":1743512033449,"mc":[{"id":"1.241629436","rc":[{"atb":[[4.7,199.46],[4.8,171.4]],"atl":[[5.3,198.13]],"batb":[[1,4.7,199.46],[0,4.8,171.4]],"batl":[],"id":270592}]}]}
{"op":"mcm","id":2,"clk":"AMKJAgCExQEAre8B","pt":1743512033553,"mc":[{"id":"1.241629436","rc":[{"atl":[[11.5,19.89]],"trd":[[11.5,1212.14]],"batl":[[0,11.5,19.89]],"ltp":11.5,"tv":6435.78,"id":40389088},{"atl":[[11,59.51]],"batl":[[2,11,59.51]],"id":27115873},{"atb":[[19,5.93]],"trd":[[19,159.29]],"batb":[[0,19,5.93]],"tv":5816,"id":58186642}],"tv":82128.27}]}
{"op":"mcm","id":2,"clk":"AMyJAgCIxQEAtO8B","pt":1743512033653,"mc":[{"id":"1.241629436","rc":[{"atb":[[4.4,154.8]],"batb":[],"id":270592},{"atl":[[9.8,5.66]],"trd":[[9.8,788.82]],"batl":[[0,9.8,5.66]],"tv":9757.6,"id":35856222},{"atb":[[19,0]],"batb":[[2,17.5,21.69],[1,18,19.86],[0,18.5,20.13]],"id":58186642}],"tv":82131.85}]}
{"op":"mcm","id":2,"clk":"ANSJAgCOxQEAve8B","pt":1743512033762,"mc":[{"id":"1.241629436","rc":[{"atl":[[1000,23.16]],"id":270592},{"atl":[[19.5,7.22]],"batl":[[0,19.5,7.22]],"id":58186642}]}]}
{"op":"mcm","id":2,"clk":"ANmJAgCSxQEAwu8B","pt":1743512033859,"mc":[{"id":"1.241629436","rc":[{"atl":[[1000,0.4]],"id":40389088},{"atb":[[1.17,1.92]],"id":270592},{"atl":[[9.8,3.87]],"trd":[[9.8,792.4]],"batl":[[0,9.8,3.87]],"tv":9761.18,"id":35856222},{"atb":[[5.1,111.33]],"batb":[[0,5.1,111.33]],"id":56297029}],"tv":82135.43}]}
{"op":"mcm","id":2,"clk":"AOGJAgCVxQEAze8B","pt":1743512033963,"mc":[{"id":"1.241629436","rc":[{"atb":[[5.1,109.81]],"trd":[[5.1,4467.35]],"batb":[[0,5.1,109.81]],"tv":13609.31,"id":56297029},{"atb":[[6.6,213.67]],"batb":[[0,6.6,213.67]],"id":26496185}],"tv":82138.47}]}
{"op":"mcm","id":2,"clk":"AO2JAgCaxQEA0e8B","pt":1743512034064,"mc":[{"id":"1.241629436","rc":[{"atl":[[1000,0.25]],"id":40389088},{"atb":[[1.17,1],[4.4,160.41]],"atl":[[1000,21.16]],"batb":[],"id":270592},{"atb":[[1.01,59222.42]],"id":35856222}]}]}
{"op":"mcm","id":2,"clk":"APWJAgCgxQEA3O8B","pt":1743512034177,"mc":[{"id":"1.241629436","rc":[{"atl":[[12,85.14]],"batl":[[1,12,85.14]],"id":40389088},{"atb":[[4.7,200.38]],"atl":[[1000,23.58]],"batb":[[1,4.7,200.38]],"id":270592},{"atl":[[9.8,2.9]],"trd":[[9.8,794.33]],"batl":[[0,9.8,2.9]],"tv":9763.11,"id":35856222}],"tv":82140.4}]}
{"op":"mcm","id":2,"clk":"AP6JAgCkxQEA4u8B","pt":1743512034274,"mc":[{"id":"1.241629436","rc":[{"atb":[[4.7,116.77],[4.8,0]],"trd":[[4.7,1278.45],[4.8,3102.67]],"batb":[[2,4.5,108.1],[1,4.6,153.15],[0,4.7,116.77]],"ltp":4.7,"tv":20243.48,"id":270592},{"atl":[[19,4.31]],"batl":[[2,20,6.08],[1,19.5,7.22],[0,19,4.31]],"id":58186642},{"atb":[[2.88,2]],"id":44049799}],"tv":82650.4}]}
{"op":"mcm","id":2,"clk":"AIiKAgCpxQEA5e8B","pt":1743512034376,"mc":[{"id":"1.241629436","rc":[{"atl":[[11.5,13.67]],"batl":[[0,11.5,13.67]],"id":40389088},{"atb":[[4.5,103.72],[4.8,2.4]],"atl":[[4.9,72.07],[5.5,131.55],[5,139.11]],"batb":[[2,4.6,153.15],[1,4.7,116.77],[0,4.8,2.4]],"batl":[[2,5.1,205.26],[1,5,139.11],[0,4.9,72.07]],"id":270592},{"atb":[[9.8,7.27],[9.6,43]],"atl":[[9.8,0]],"batb":[[2,9.4,60.35],[1,9.6,43],[0,9.8,7.27]],"batl":[[2,11,18.37],[1,10.5,75.76],[0,10,106.58]],"id":35856222},{"atl":[[60,14.44]],"batl":[[0,60,14.44]],"id":59626646},{"atl":[[5.3,95.41]],"batl":[[1,5.3,95.41]],"id":56297029}]}]}
{"op":"mcm","id":2,"clk":"AJCKAgCwxQEA6e8B","pt":1743512034479,"mc":[{"id":"1.241629436","rc":[{"atb":[[4.2,54.93],[4.6,156.24],[4.5,106.97],[4.8,0]],"atl":[[5.4,128.82],[4.9,111.49],[5,150.7],[4.8,3.61]],"trd":[[4.8,3107.47]],"batb":[[2,4.5,106.97],[1,4.6,156.24],[0,4.7,116.77]],"batl":[[2,5,150.7],[1,4.9,111.49],[0,4.8,3.61]],"ltp":4.8,"tv":20248.28,"id":270592},{"atb":[[9.4,61.65],[8.8,52.46],[9.8,9.06],[9.6,62.77]],"batb":[[2,9.4,61.65],[1,9.6,62.77],[0,9.8,9.06]],"id":35856222},{"atl":[[5.3,97.66]],"batl":[[1,5.3,97.66]],"id":56297029},{"atl":[[10.5,132.95]],"batl":[[1,10.5,132.95]],"id":27115873},{"atb":[[18.5,19.13]],"trd":[[18.5,88.97]],"batb":[[0,18.5,19.13]],"ltp":18.5,"tv":5818,"id":58186642},{"atl":[[7,44.03]],"batl":[[1,7,44.03]],"id":26496185},{"atl":[[12,30.76]],"batl":[[1,12,30.76]],"id":44049799}],"tv":82657.2}]}
{"op":"mcm","id":2,"clk":"AJeKAgC2xQEA7u8B","pt":1743512034574,"mc":[{"id":"1.241629436","rc":[{"atb":[[11,100.27]],"batb":[[0,11,100.27]],"id":40389088},{"atb":[[4.1,51.12]],"atl":[[4.9,143.12],[5.3,197.25],[4.8,0]],"trd":[[4.9,2679.15],[4.8,3114.69]],"batb":[],"batl":[[2,5.1,205.26],[1,5,150.7],[0,4.9,143.12]],"ltp":4.9,"tv":20258.28,"id":270592},{"atl":[[21,13.1]],"batl":[],"id":58186642},{"atb":[[6.6,240.77]],"batb":[[0,6.6,240.77]],"id":26496185}],"tv":82667.2}]}
{"op":"mcm","id":2,"clk":"AJyKAgDAxQEA+O8B","pt":1743512034676,"mc":[{"id":"1.241629436","rc":[{"atl":[[11.5,7.21]],"batl":[[0,11.5,7.21]],"id":40389088},{"atb":[[4.7,119.71]],"batb":[[0,4.7,119.71]],"id":270592},{"atb":[[8.4,60.37],[9.6,64.01]],"batb":[[1,9.6,64.01]],"id":35856222},{"atb":[[6.2,193.44]],"batb":[[2,6.2,193.44]],"id":26496185}]}]}
{"op":"mcm","id":2,"clk":"AKSKAgDHxQEA+u8B","pt":1743512034781,"mc":[{"id":"1.241629436","rc":[{"atl":[[11.5,2.3]],"batl":[[0,11.5,2.3]],"id":40389088},{"atb":[[4.7,116.77],[4.2,76.86],[4.4,161.56],[4.1,56.72],[4.6,131.11],[4.3,80.62],[4.5,112.58],[4.8,2.83]],"atl":[[5.2,151.01],[4.9,169.8]],"batb":[[2,4.6,131.11],[1,4.7,116.77],[0,4.8,2.83]],"batl":[[0,4.9,169.8]],"id":270592},{"atb":[[9.2,79.65],[9.6,62.77]],"batb":[[1,9.6,62.77]],"id":35856222},{"atl":[[10.5,130.95]],"batl":[[1,10.5,130.95]],"id":27115873},{"atb":[[6.6,250.77],[6.2,190.23]],"batb":[[2,6.2,190.23],[0,6.6,250.77]],"id":26496185}]}]}
{"op":"mcm","id":2,"clk":"AKqKAgDMxQEAgPAB","pt":1743512034880,"mc":[{"id":"1.241629436","rc":[{"atb":[[4.6,134.2],[4.8,0]],"atl":[[4.8,61.89]],"trd":[[4.8,3120.35]],"batb":[[2,4.5,112.58],[1,4.6,134.2],[0,4.7,116.77]],"batl":[[2,5,150.7],[1,4.9,169.8],[0,4.8,61.89]],"ltp":4.8,"tv":20263.94,"id":270592},{"atl":[[21,16.05]],"batl":[],"id":58186642}],"tv":82672.86}]}
{"op":"mcm","id":2,"clk":"ALGKAgDUxQEAhvAB","pt":1743512034982,"mc":[{"id":"1.241629436","rc":[{"atl":[[5.4,56.53]],"batl":[],"id":270592},{"atl":[[1000,3.41]],"id":58186642}]}]}
{"op":"mcm","id":2,"clk":"ALyKAgDYxQEAi/AB","pt":1743512035085,"mc":[{"id":"1.241629436","rc":[{"atb":[[4.7,119.71]],"atl":[[4.9,148.61],[4.8,73.69]],"batb":[[0,4.7,119.71]],"batl":[[1,4.9,148.61],[0,4.8,73.69]],"id":270592},{"atb":[[9.6,64.01]],"batb":[[1,9.6,64.01]],"id":35856222},{"atl":[[21,13.1]],"batl":[],"id":58186642},{"atb":[[6.2,193.44]],"batb":[[2,6.2,193.44]],"id":26496185}]}]}
{"op":"mcm","id":2,"clk":"AMqKAgDgxQEAj/AB","pt":1743512035148,"mc":[{"id":"1.241629436","rc":[{"atb":[[11,113.65]],"batb":[[0,11,113.65]],"id":40389088},{"atb":[[4.7,187.38]],"atl":[[1000,22.13]],"batb":[[0,4.7,187.38]],"id":270592},{"atb":[[9.8,23.28]],"batb":[[0,9.8,23.28]],"id":35856222},{"atb":[[55,10.29]],"batb":[[0,55,10.29]],"id":59626646},{"atb":[[5.1,143.27]],"batb":[[0,5.1,143.27]],"id":56297029},{"atb":[[9.4,76.69],[9.8,91.46]],"batb":[[2,9.4,76.69],[0,9.8,91.46]],"id":27115873},{"atb":[[18.5,26.66]],"atl":[[1000,1.94]],"batb":[[0,18.5,26.66]],"id":58186642},{"atb":[[6.6,299.28],[6,204.37]],"batb":[[0,6.6,299.28]],"id":26496185},{"atb":[[11,121.37]],"batb":[[0,11,121.37]],"id":44049799}]}]}
{"op":"mcm","id":2,"clk":"ANGKAgDmxQEAlfAB","pt":1743512035246,"mc":[{"id":"1.241629436","rc":[{"atb":[[4.7,192.98],[4.6,146.01]],"atl":[[5.2,150.11]],"batb":[[1,4.6,146.01],[0,4.7,192.98]],"batl":[],"id":270592},{"atb":[[9.8,20.33]],"trd":[[9.8,834.33]],"batb":[[0,9.8,20.33]],"tv":9803.11,"id":35856222},{"atl":[[60,13.18]],"batl":[[0,60,13.18]],"id":59626646},{"atb":[[18.5,24.48]],"batb":[[0,18.5,24.48]],"id":58186642}],"tv":82712.86}]}
{"op":"mcm","id":2,"clk":"ANiKAgDwxQEAoPAB","pt":1743512035357,"mc":[{"id":"1.241629436","rc":[{"atl":[[5.1,206.16]],"batl":[],"id":270592},{"atl":[[1000,1.41]],"id":58186642}]}]}
{"op":"mcm","id":2,"clk":"AN6KAgD3xQEAqPAB","pt":1743512035461,"mc":[{"id":"1.241629436","rc":[{"atb":[[11,112.65]],"trd":[[11,231.58]],"batb":[[0,11,112.65]],"ltp":11,"tv":6437.78,"id":40389088},{"atl":[[4.8,64.05]],"trd":[[4.8,3139.63]],"batl":[[0,4.8,64.05]],"tv":20283.22,"id":270592},{"atl":[[19,4.84]],"batl":[[0,19,4.84]],"id":58186642}],"tv":82734.14}]}
{"op":"mcm","id":2,"clk":"AOaKAgCBxgEAsPAB","pt":1743512035561,"mc":[{"id":"1.241629436","rc":[{"atl":[[4.8,11.8]],"batl":[[0,4.8,11.8]],"id":270592}]}]}
{"op":"mcm","id":2,"clk":"AO+KAgCGxgEAt/AB","pt":1743512035661,"mc":[{"id":"1.241629436","rc":[{"atb":[[1.17,2.23],[11,112.23]],"batb":[[0,11,112.23]],"id":40389088},{"atl":[[5.1,205.62]],"batl":[],"id":270592},{"atb":[[9.8,90.04]],"atl":[[1000,1.61],[10.5,130.69]],"batb":[[0,9.8,90.04]],"batl":[[1,10.5,130.69]],"id":27115873},{"atb":[[18,21.34]],"batb":[[1,18,21.34]],"id":58186642},{"atb":[[6.6,296.74]],"batb":[[0,6.6,296.74]],"id":26496185}]}]}
{"op":"mcm","id":2,"clk":"APuKAgCVxgEAxvAB","pt":1743512035782,"mc":[{"id":"1.241629436","rc":[{"atb":[[1.17,2]],"id":40389088},{"atb":[[7.6,30.5]],"id":35856222},{"atl":[[1000,1.16]],"id":27115873}]}]}
{"op":"mcm","id":2,"clk":"AIWLAgCaxgEAzPAB","pt":1743512035872,"mc":[{"id":"1.241629436","rc":[{"atb":[[10.5,51.24]],"batb":[[1,10.5,51.24]],"id":40389088},{"atl":[[10,9.91]],"batl":[[0,10,9.91]],"id":27115873}]}]}
{"op":"mcm","id":2,"clk":"AJSLAgCrxgEA0vAB","pt":1743512036098,"mc":[{"id":"1.241629436","rc":[{"atb":[[5.1,140.76]],"trd":[[5.1,4472.37]],"batb":[[0,5.1,140.76]],"tv":13614.33,"id":56297029}],"tv":82739.16}]}
{"op":"mcm","id":2,"clk":"AKGLAgCvxgEA1fAB","pt":1743512036187,"mc":[{"id":"1.241629436","rc":[{"atb":[[1.06,5426.57]],"id":40389088},{"atb":[[1.06,5414.02]],"atl":[[1000,21.16]],"id":270592},{"atb":[[1.06,5315.34]],"id":35856222},{"atb":[[1.06,5531.11]],"id":59626646},{"atb":[[1.06,5561.22]],"id":56297029},{"atb":[[1.06,5651.54]],"id":27115873},{"atb":[[1.06,5211.63]],"id":58186642},{"atb":[[1.06,5600.53],[4.6,66.04]],"id":26496185},{"atb":[[1.06,6043.78]],"id":44049799}]}]}
{"op":"mcm","id":2,"clk":"AKmLAgC3xgEA2fAB","pt":1743512036281,"mc":[{"id":"1.241629436","rc":[{"atl":[[4.8,12.77]],"batl":[[0,4.8,12.77]],"id":270592},{"atb":[[5.4,0]],"id":58186642},{"atb":[[5.4,25.38]],"batb":[],"id":26496185}]}]}
{"op":"mcm","id":2,"clk":"ALOLAgC/xgEA3PAB","pt":1743512036387,"mc":[{"id":"1.241629436","rc":[{"atl":[[5.2,150.01]],"batl":[],"id":270592},{"atb":[[5,1208.17]],"batb":[[1,5,1208.17]],"id":56297029},{"atl":[[10,8.91]],"batl":[[0,10,8.91]],"id":27115873}]}]}
{"op":"mcm","id":2,"clk":"AL2LAgDHxgEA5vAB","pt":1743512036487,"mc":[{"id":"1.241629436","rc":[{"atl":[[4.9,148.71],[5,171.61]],"batl":[[2,5,171.61],[1,4.9,148.71]],"id":270592},{"atb":[[15.5,35.3]],"batb":[],"id":58186642}]}]}
{"op":"mcm","id":2,"clk":"ANyLAgDexgEA/PAB","pt":1743512036755,"mc":[{"id":"1.241629436","rc":[{"atl":[[10,7.42]],"trd":[[10,579.96]],"batl":[[0,10,7.42]],"tv":7194.04,"id":27115873}],"tv":82742.14}]}
{"op":"mcm","id":2,"clk":"AOqLAgDnxgEAg/EB","pt":1743512036858,"mc":[{"id":"1.241629436","rc":[{"atb":[[4.4,189.56]],"batb":[],"id":270592},{"atb":[[9,41.58]],"batb":[],"id":35856222},{"atl":[[60,13.16]],"batl":[[0,60,13.16]],"id":59626646},{"atb":[[18.5,22.33]],"trd":[[18.5,93.27]],"batb":[[0,18.5,22.33]],"tv":5822.3,"id":58186642}],"tv":82746.44}]}
{"op":"mcm","id":2,"clk":"APOLAgDrxgEAjvEB","pt":1743512036952,"mc":[{"id":"1.241629436","rc":[{"atb":[[4.7,193.27]],"batb":[[0,4.7,193.27]],"id":270592},{"atb":[[9.6,80.01]],"batb":[[1,9.6,80.01]],"id":35856222}]}]}
{"op":"mcm","id":2,"clk":"AI+MAgD7xgEApPEB","pt":1743512037264,"mc":[{"id":"1.241629436","rc":[{"atl":[[5.7,55.55]],"batl":[],"id":270592},{"atb":[[15.5,35.39]],"batb":[],"id":58186642}]}]}
{"op":"mcm","id":2,"clk":"AJmMAgCFxwEAqfEB","pt":1743512037372,"mc":[{"id":"1.241629436","rc":[{"atb":[[4.4,191.56]],"batb":[],"id":270592},{"atl":[[10,8.42]],"batl":[[0,10,8.42]],"id":27115873}]}]}
{"op":"mcm","id":2,"clk":"AJ+MAgCMxwEArvEB","pt":1743512037468,"mc":[{"id":"1.241629436","rc":[{"atb":[[4.7,215.66]],"batb":[[0,4.7,215.66]],"id":270592},{"atb":[[5.1,161.39]],"batb":[[0,5.1,161.39]],"id":56297029},{"atb":[[6.6,274.74]],"batb":[[0,6.6,274.74]],"id":26496185}]}]}
{"op":"mcm","id":2,"clk":"AKWMAgCaxwEAtvEB","pt":1743512037579,"mc":[{"id":"1.241629436","rc":[{"atb":[[4.7,210.66]],"trd":[[4.7,1288.45]],"batb":[[0,4.7,210.66]],"ltp":4.7,"tv":20293.22,"id":270592},{"atl":[[6.8,76.47]],"trd":[[6.8,523.88]],"batl":[[0,6.8,76.47]],"ltp":6.8,"tv":12864.05,"id":26496185}],"tv":82831.38}]}
{"op":"mcm","id":2,"clk":"AK2MAgChxwEAuPEB","pt":1743512037676,"mc":[{"id":"1.241629436","rc":[{"atl":[[19.5,9.41]],"batl":[[1,19.5,9.41]],"id":58186642}]}]}
{"op":"mcm","id":2,"clk":"ALOMAgCpxwEAxvEB","pt":1743512037778,"mc":[{"id":"1.241629436","rc":[{"atl":[[5.2,219.1],[4.8,69.06]],"trd":[[4.8,3141.64]],"batl":[[0,4.8,69.06]],"ltp":4.8,"tv":20295.23,"id":270592},{"atb":[[9.8,31.06]],"batb":[[0,9.8,31.06]],"id":35856222},{"atb":[[9.8,100.78]],"batb":[[0,9.8,100.78]],"id":27115873},{"atb":[[6.8,28.02]],"atl":[[7,71.25],[6.8,0]],"trd":[[6.8,632.78]],"batb":[[2,6.4,322.27],[1,6.6,274.74],[0,6.8,28.02]],"batl":[[2,7.4,38.43],[1,7.2,117.49],[0,7,71.25]],"tv":12972.95,"id":26496185},{"atb":[[11,130.94]],"batb":[[0,11,130.94]],"id":44049799}],"tv":82942.29}]}
{"op":"mcm","id":2,"clk":"ALqMAgC0xwEAzPEB","pt":1743512037890,"mc":[{"id":"1.241629436","rc":[{"atb":[[11,121.8]],"atl":[[11.5,3.97]],"batb":[[0,11,121.8]],"batl":[[0,11.5,3.97]],"id":40389088},{"atb":[[4.7,196.35]],"atl":[[1000,23.16]],"batb":[[0,4.7,196.35]],"id":270592},{"atb":[[9.6,78.77]],"batb":[[1,9.6,78.77]],"id":35856222},{"atb":[[55,12.2]],"batb":[[0,55,12.2]],"id":59626646},{"atb":[[19,0.7]],"atl":[[21,16.08],[19,0]],"trd":[[19,168.97]],"batb":[[0,18.5,23.03]],"batl":[[2,21,16.08],[1,20,6.08],[0,19.5,9.41]],"ltp":19,"tv":5831.98,"id":58186642},{"atb":[[6.8,55.22],[6,178.27],[6.2,190.23]],"atl":[[7,69.92]],"batb":[[0,6.8,55.22]],"batl":[[0,7,69.92]],"id":26496185}],"tv":82951.97}]}
{"op":"mcm","id":2,"clk":"AMSMAgC5xwEA0fEB","pt":1743512037988,"mc":[{"id":"1.241629436","rc":[{"atb":[[4.7,216.35]],"batb":[[0,4.7,216.35]],"id":270592},{"atb":[[19,0]],"trd":[[19,170.37]],"batb":[[0,18.5,22.33]],"tv":5833.38,"id":58186642},{"atb":[[5.9,78.74]],"atl":[[9.2,16.55]],"batb":[],"id":26496185}],"tv":82953.37}]}
{"op":"mcm","id":2,"clk":"AMqMAgDHxwEA1fEB","pt":1743512038093,"mc":[{"id":"1.241629436","rc":[{"atb":[[4.7,211.35]],"atl":[[1000,21.16],[5.1,170.33]],"trd":[[4.7,1298.45]],"batb":[[0,4.7,211.35]],"batl":[],"ltp":4.7,"tv":20305.23,"id":270592},{"atb":[[9.6,67.57]],"batb":[[1,9.6,67.57]],"id":27115873},{"atb":[[19,15.92]],"batb":[[2,18,21.34],[1,18.5,22.33],[0,19,15.92]],"id":58186642},{"atb":[[6.8,76.52]],"batb":[[0,6.8,76.52]],"id":26496185}],"tv":82963.37}]}
{"op":"mcm","id":2,"clk":"ANKMAgDNxwEA3fEB","pt":1743512038189,"mc":[{"id":"1.241629436","rc":[{"atl":[[4.8,81.08]],"batl":[[0,4.8,81.08]],"id":270592},{"atb":[[9.4,64.65]],"batb":[[2,9.4,64.65]],"id":35856222},{"atb":[[19,18.85],[18.5,24.5]],"atl":[[19.5,4.56]],"batb":[[1,18.5,24.5],[0,19,18.85]],"batl":[[0,19.5,4.56]],"id":58186642},{"atb":[[6.8,73.12]],"trd":[[6.8,639.58]],"batb":[[0,6.8,73.12]],"tv":12979.75,"id":26496185}],"tv":82970.17}]}
{"op":"mcm","id":2,"clk":"ANmMAgDYxwEA4vEB","pt":1743512038294,"mc":[{"id":"1.241629436","rc":[{"atb":[[19,14.19]],"atl":[[21,13.1],[20,10.13]],"batb":[[0,19,14.19]],"batl":[[2,21,13.1],[1,20,10.13]],"id":58186642},{"atb":[[6.4,325.67]],"atl":[[7.4,42.9],[7.2,100.7]],"batb":[[2,6.4,325.67]],"batl":[[2,7.4,42.9],[1,7.2,100.7]],"id":26496185}]}]}
{"op":"mcm","id":2,"clk":"AOKMAgDdxwEA6fEB","pt":1743512038393,"mc":[{"id":"1.241629436","rc":[{"atb":[[19,16.81]],"batb":[[0,19,16.81]],"id":58186642},{"atl":[[7,68.85]],"trd":[[7,97.45]],"batl":[[0,7,68.85]],"ltp":7,"tv":12981.89,"id":26496185}],"tv":82972.31}]}
{"op":"mcm","id":2,"clk":"AOiMAgDmxwEA8PEB","pt":1743512038449,"mc":[{"id":"1.241629436","rc":[{"atb":[[4,108.55]],"batb":[],"id":270592},{"atb":[[6.8,78.73],[6.2,195.83]],"batb":[[0,6.8,78.73]],"id":26496185}]}]}
{"op":"mcm","id":2,"clk":"AP6MAgDzxwEAgPIB","pt":1743512038666,"mc":[{"id":"1.241629436","rc":[{"atl":[[1000,1.06]],"id":40389088},{"atb":[[19,15.3]],"trd":[[19,173.39]],"batb":[[0,19,15.3]],"tv":5836.4,"id":58186642},{"atb":[[1.17,2.43]],"id":44049799}],"tv":82975.33}]}
{"op":"mcm","id":2,"clk":"AIeNAgD5xwEAhfIB","pt":1743512038761,"mc":[{"id":"1.241629436","rc":[{"atl":[[1000,0.25]],"id":40389088},{"atb":[[1.17,2]],"id":44049799}]}]}
{"op":"mcm","id":2,"clk":"AJCNAgCByAEAk/IB","pt":1743512038866,"mc":[{"id":"1.241629436","rc":[{"atl":[[11.5,4.78]],"batl":[[0,11.5,4.78]],"id":40389088},{"atb":[[4.7,201.45]],"trd":[[4.7,1318.25]],"batb":[[0,4.7,201.45]],"tv":20325.03,"id":270592},{"atb":[[9.4,61.65]],"batb":[[2,9.4,61.65]],"id":35856222},{"atb":[[5.1,163.39]],"batb":[[0,5.1,163.39]],"id":56297029},{"atb":[[11,131.37]],"batb":[[0,11,131.37]],"id":44049799}],"tv":82995.13}]}
{"op":"mcm","id":2,"clk":"AJiNAgCMyAEAmPIB","pt":1743512038970,"mc":[{"id":"1.241629436","rc":[{"atb":[[4.7,196.44]],"trd":[[4.7,1328.25]],"batb":[[0,4.7,196.44]],"tv":20335.03,"id":270592}],"tv":83005.13}]}
{"op":"mcm","id":2,"clk":"AJ+NAgCQyAEAnfIB","pt":1743512039066,"mc":[{"id":"1.241629436","rc":[{"atl":[[29,5.38]],"id":58186642},{"atb":[[6.8,82.73]],"batb":[[0,6.8,82.73]],"id":26496185}]}]}
{"op":"mcm","id":2,"clk":"AKWNAgCUyAEApfIB","pt":1743512039174,"mc":[{"id":"1.241629436","rc":[{"atb":[[6.8,80.73]],"trd":[[6.8,643.58]],"batb":[[0,6.8,80.73]],"ltp":6.8,"tv":12985.89,"id":26496185}],"tv":83009.13}]}
{"op":"mcm","id":2,"clk":"AKuNAgCZyAEArPIB","pt":1743512039276,"mc":[{"id":"1.241629436","rc":[{"atl":[[1000,23.16]],"id":270592},{"atl":[[10,105.58]],"trd":[[10,776.51]],"batl":[[0,10,105.58]],"ltp":10,"tv":9805.11,"id":35856222}],"tv":83011.13}]}
{"op":"mcm","id":2,"clk":"ALSNAgCeyAEAr/IB","pt":1743512039382,"mc":[{"id":"1.241629436","rc":[{"atb":[[4.7,195.52],[1.17,1.74]],"batb":[[0,4.7,195.52]],"id":270592},{"atb":[[5.5,145.85]],"batb":[],"id":26496185}]}]}
{"op":"mcm","id":2,"clk":"ALqNAgCiyAEAtPIB","pt":1743512039481,"mc":[{"id":"1.241629436","rc":[{"atb":[[4.7,250.52]],"atl":[[5.1,175.5]],"batb":[[0,4.7,250.52]],"batl":[],"id":270592}]}]}
{"op":"mcm","id":2,"clk":"AMCNAgCmyAEAt/IB","pt":1743512039578,"mc":[{"id":"1.241629436","rc":[{"atb":[[1.17,1]],"atl":[[1000,21.16],[4.8,80.08]],"trd":[[4.8,3143.64]],"batl":[[0,4.8,80.08]],"ltp":4.8,"tv":20337.03,"id":270592},{"atb":[[9.4,60.35],[9.2,78.29]],"batb":[[2,9.4,60.35]],"id":35856222},{"atb":[[9.6,68.92]],"batb":[[1,9.6,68.92]],"id":27115873},{"atb":[[18.5,24.45]],"batb":[[1,18.5,24.45]],"id":58186642}],"tv":83013.13}]}
{"op":"mcm","id":2,"clk":"AMSNAgCryAEAv/IB","pt":1743512039679,"mc":[{"id":"1.241629436","rc":[{"atb":[[11,119.73]],"trd":[[11,235.72]],"batb":[[0,11,119.73]],"tv":6441.92,"id":40389088},{"atb":[[4.7,262.38]],"batb":[[0,4.7,262.38]],"id":270592},{"atl":[[60,13.18]],"batl":[[0,60,13.18]],"id":59626646},{"atb":[[5,1206.13]],"batb":[[1,5,1206.13]],"id":56297029},{"atl":[[7,69.11]],"batl":[[0,7,69.11]],"id":26496185}],"tv":83017.27}]}
{"op":"mcm","id":2,"clk":"AM2NAgCuyAEAxPIB","pt":1743512039793,"mc":[{"id":"1.241629436","rc":[{"atb":[[4.6,146.75]],"batb":[[1,4.6,146.75]],"id":270592}]}]}
{"op":"mcm","id":2,"clk":"ANKNAgC0yAEAyfIB","pt":1743512039840,"mc":[{"id":"1.241629436","rc":[{"atb":[[4.1,58.72]],"batb":[],"id":270592}]}]}
{"op":"mcm","id":2,"clk":"AOiNAgDOyAEA5vIB","pt":1743512040165,"mc":[{"id":"1.241629436","rc":[{"atl":[[7,67.1]],"trd":[[7,101.46]],"batl":[[0,7,67.1]],"ltp":7,"tv":12989.9,"id":26496185}],"tv":83021.28}]}
{"op":"mcm","id":2,"clk":"APCNAgDWyAEA7/IB","pt":1743512040265,"mc":[{"id":"1.241629436","rc":[{"atb":[[4.7,272.38]],"batb":[[0,4.7,272.38]],"id":270592}]}]}
{"op":"mcm","id":2,"clk":"APaNAgDgyAEA9PIB","pt":1743512040373,"mc":[{"id":"1.241629436","rc":[{"atl":[[4.8,70.07]],"trd":[[4.8,3163.64]],"batl":[[0,4.8,70.07]],"tv":20357.03,"id":270592},{"atl":[[7.2,102.64]],"batl":[[1,7.2,102.64]],"id":26496185}],"tv":83041.28}]}
{"op":"mcm","id":2,"clk":"AP2NAgDlyAEA+/IB","pt":1743512040472,"mc":[{"id":"1.241629436","rc":[{"atl":[[11.5,10.99]],"batl":[[0,11.5,10.99]],"id":40389088},{"atl":[[10.5,72.8]],"batl":[[1,10.5,72.8]],"id":27115873},{"atb":[[19,12.3]],"atl":[[21,16.03],[19.5,38.77]],"trd":[[19,179.39]],"batb":[[0,19,12.3]],"batl":[[2,21,16.03],[0,19.5,38.77]],"tv":5842.4,"id":58186642},{"atb":[[6.4,295.75]],"atl":[[7,76.02]],"batb":[[2,6.4,295.75]],"batl":[[0,7,76.02]],"id":26496185}],"tv":83047.28}]}
{"op":"mcm","id":2,"clk":"AIOOAgDryAEA//IB","pt":1743512040573,"mc":[{"id":"1.241629436","rc":[{"atb":[[9.6,73]],"atl":[[1000,2.83]],"batb":[[1,9.6,73]],"id":35856222},{"atb":[[19,0]],"trd":[[19,186.65]],"batb":[[2,17.5,21.69],[1,18,21.34],[0,18.5,24.45]],"tv":5849.66,"id":58186642},{"atb":[[6.8,81.82]],"atl":[[7,74.02]],"trd":[[7,105.46]],"batb":[[0,6.8,81.82]],"batl":[[0,7,74.02]],"tv":12993.9,"id":26496185},{"atl":[[12,35.76]],"batl":[[1,12,35.76]],"id":44049799}],"tv":83058.54}]}
{"op":"mcm","id":2,"clk":"AI6OAgD2yAEAhvMB","pt":1743512040680,"mc":[{"id":"1.241629436","rc":[{"atl":[[4.8,12.78]],"batl":[[0,4.8,12.78]],"id":270592},{"atb":[[16.5,17.43]],"atl":[[19,13.82],[19.5,41.31]],"batb":[],"batl":[[2,20,10.13],[1,19.5,41.31],[0,19,13.82]],"id":58186642},{"atl":[[7.2,104.58]],"batl":[[1,7.2,104.58]],"id":26496185}]}]}
{"op":"mcm","id":2,"clk":"AJSOAgD8yAEAh/MB","pt":1743512040776,"mc":[{"id":"1.241629436","rc":[{"atb":[[11,119.44]],"batb":[[0,11,119.44]],"id":40389088},{"atb":[[18.5,14.82]],"batb":[[0,18.5,14.82]],"id":58186642},{"atb":[[6.8,85.82],[6.2,199.04]],"atl":[[7,72.02]],"trd":[[7,109.46]],"batb":[[0,6.8,85.82]],"batl":[[0,7,72.02]],"tv":12997.9,"id":26496185},{"atl":[[12,30.76]],"batl":[[1,12,30.76]],"id":44049799}],"tv":83062.54}]}
{"op":"mcm","id":2,"clk":"AJyOAgCGyQEAivMB","pt":1743512040884,"mc":[{"id":"1.241629436","rc":[{"atl":[[11.5,25.1]],"batl":[[0,11.5,25.1]],"id":40389088},{"atl":[[4.9,137.08],[4.8,7.95]],"trd":[[4.8,3173.31]],"batl":[[1,4.9,137.08],[0,4.8,7.95]],"tv":20366.7,"id":270592},{"atb":[[55,11.2]],"trd":[[55,301.65]],"batb":[[0,55,11.2]],"tv":1977.89,"id":59626646},{"atl":[[20,13.14]],"batl":[[2,20,13.14]],"id":58186642},{"atb":[[6.8,90.28]],"batb":[[0,6.8,90.28]],"id":26496185}],"tv":83074.21}]}
{"op":"mcm","id":2,"clk":"AKaOAgCSyQEAjfMB","pt":1743512040987,"mc":[{"id":"1.241629436","rc":[{"atb":[[11,103.08]],"batb":[[0,11,103.08]],"id":40389088},{"atb":[[4.7,254.05],[4.6,143.66],[4.5,122.58]],"atl":[[4.8,0.94]],"trd":[[4.8,3175.31]],"batb":[[2,4.5,122.58],[1,4.6,143.66],[0,4.7,254.05]],"batl":[[2,5.1,175.5],[1,5,171.61],[0,4.9,138.02]],"tv":20368.7,"id":270592},{"atb":[[18.5,12]],"batb":[[0,18.5,12]],"id":58186642}],"tv":83076.21}]}
{"op":"mcm","id":2,"clk":"ALGOAgCXyQEAkfMB","pt":1743512041093,"mc":[{"id":"1.241629436","rc":[{"atb":[[4.1,56.72],[4.5,119.33]],"atl":[[5.1,174.6],[4.8,0]],"batb":[[2,4.5,119.33]],"batl":[[2,5.1,174.6],[0,4.9,137.08]],"id":270592},{"atb":[[18.5,9]],"batb":[[0,18.5,9]],"id":58186642},{"atb":[[6.2,195.83]],"batb":[],"id":26496185}]}]}
{"op":"mcm","id":2,"clk":"ALqOAgCcyQEAmfMB","pt":1743512041193,"mc":[{"id":"1.241629436","rc":[{"atl":[[5.2,220]],"batl":[],"id":270592},{"atl":[[7.2,106.52]],"batl":[[1,7.2,106.52]],"id":26496185}]}]}
{"op":"mcm","id":2,"clk":"AM2OAgCoyQEApfMB","pt":1743512041394,"mc":[{"id":"1.241629436","rc":[{"atb":[[11,89.7]],"batb":[[0,11,89.7]],"id":40389088},{"atb":[[4.7,204.71]],"batb":[[0,4.7,204.71]],"id":270592},{"atb":[[55,6.18]],"batb":[[0,55,6.18]],"id":59626646},{"atb":[[5.1,129.93]],"batb":[[0,5.1,129.93]],"id":56297029},{"atb":[[9.8,74.85]],"batb":[[0,9.8,74.85]],"id":27115873},{"atb":[[18.5,1.47]],"batb":[[0,18.5,1.47]],"id":58186642},{"atb":[[11,102.93]],"batb":[[0,11,102.93]],"id":44049799}]}]}
{"op":"mcm","id":2,"clk":"ANOOAgCuyQEArfMB","pt":1743512041502,"mc":[{"id":"1.241629436","rc":[{"atb":[[4.5,122.58]],"atl":[[4.8,2]],"batb":[[2,4.5,122.58]],"batl":[[2,5,171.61],[1,4.9,137.08],[0,4.8,2]],"id":270592},{"atl":[[1000,1.2]],"id":35856222},{"atb":[[6.8,92.28]],"batb":[[0,6.8,92.28]],"id":26496185}]}]}
{"op":"mcm","id":2,"clk":"ANuOAgC4yQEAsPMB","pt":1743512041606,"mc":[{"id":"1.241629436","rc":[{"atl":[[5.4,131.42]],"batl":[[2,5.4,131.42]],"id":56297029}]}]}
{"op":"mcm","id":2,"clk":"AOOOAgC6yQEAtvMB","pt":1743512041661,"mc":[{"id":"1.241629436","rc":[{"atb":[[4.6,146.75],[4.3,96.23]],"batb":[[1,4.6,146.75]],"id":270592},{"atb":[[9.8,44.03]],"batb":[[0,9.8,44.03]],"id":35856222},{"atb":[[6.2,199.04]],"batb":[],"id":26496185}]}]}
{"op":"mcm","id":2,"clk":"AOmOAgDDyQEAvfMB","pt":1743512041766,"mc":[{"id":"1.241629436","rc":[{"atl":[[5.2,219.1],[4.8,0]],"trd":[[4.8,3179.31]],"batl":[[2,5.1,174.6],[1,5,171.61],[0,4.9,137.08]],"tv":20372.7,"id":270592},{"atl":[[10,98.78]],"batl":[[0,10,98.78]],"id":35856222},{"atb":[[1.01,44319.07]],"id":58186642}],"tv":83080.21}]}
{"op":"mcm","id":2,"clk":"APeOAgDNyQEAwvMB","pt":1743512041867,"mc":[{"id":"1.241629436","rc":[{"atb":[[17,59.61]],"batb":[],"id":58186642}]}]}
{"op":"mcm","id":2,"clk":"AIGPAgDRyQEAz/MB","pt":1743512041971,"mc":[{"id":"1.241629436","rc":[{"atb":[[4.6,143.66]],"atl":[[5.2,220]],"batb":[[1,4.6,143.66]],"batl":[],"id":270592},{"atb":[[1.17,2.7]],"atl":[[5.2,340.78]],"batl":[[0,5.2,340.78]],"id":56297029},{"atb":[[9.8,70.85]],"atl":[[10,7.97]],"trd":[[9.8,519.86]],"batb":[[0,9.8,70.85]],"batl":[[0,10,7.97]],"ltp":9.8,"tv":7202.04,"id":27115873},{"atb":[[1.01,44318.07],[18,19.63]],"batb":[[1,18,19.63]],"id":58186642},{"atb":[[6.6,270.47],[6.8,94.67],[6.2,195.83]],"atl":[[7,70.65],[7.2,107.54]],"batb":[[1,6.6,270.47],[0,6.8,94.67]],"batl":[[1,7.2,107.54],[0,7,70.65]],"id":26496185},{"atb":[[11,102.5]],"batb":[[0,11,102.5]],"id":44049799}],"tv":83088.21}]}
{"op":"mcm","id":2,"clk":"AImPAgDbyQEA2fMB","pt":1743512042069,"mc":[{"id":"1.241629436","rc":[{"atb":[[9.8,67.47]],"batb":[[0,9.8,67.47]],"id":27115873},{"atb":[[6.8,98.67]],"batb":[[0,6.8,98.67]],"id":26496185}]}]}
{"op":"mcm","id":2,"clk":"AJCPAgDeyQEA3fMB","pt":1743512042176,"mc":[{"id":"1.241629436","rc":[{"atb":[[1.17,2]],"id":56297029},{"atb":[[1.01,44317.07],[18.5,0.47]],"batb":[[2,17,59.61],[1,17.5,21.69],[0,18,20.1]],"id":58186642}]}]}
{"op":"mcm","id":2,"clk":"AJmPAgDoyQEA6/MB","pt":1743512042279,"mc":[{"id":"1.241629436","rc":[{"atb":[[5.1,130.63]],"batb":[[0,5.1,130.63]],"id":56297029},{"atb":[[16.5,18.43]],"batb":[],"id":58186642}]}]}
{"op":"mcm","id":2,"clk":"AKKPAgDxyQEA7/MB","pt":1743512042379,"mc":[{"id":"1.241629436","rc":[{"atl":[[5.4,62.14]],"batl":[],"id":270592},{"atb":[[9.6,57]],"atl":[[1000,0.41]],"batb":[[1,9.6,57]],"id":35856222},{"atb":[[18.5,0]],"batb":[[0,18,19.63]],"id":58186642}]}]}
{"op":"mcm","id":2,"clk":"AKqPAgD5yQEA+fMB","pt":1743512042488,"mc":[{"id":"1.241629436","rc":[{"atb":[[4.1,66.72]],"batb":[],"id":270592},{"atb":[[9.8,60.03]],"atl":[[12,32.2]],"batb":[[0,9.8,60.03]],"batl":[],"id":35856222}]}]}
{"op":"mcm","id":2,"clk":"ALCPAgCDygEAgPQB","pt":1743512042586,"mc":[{"id":"1.241629436","rc":[{"atb":[[1.01,130787.92]],"id":40389088},{"atb":[[9.6,62.7]],"batb":[[1,9.6,62.7]],"id":35856222},{"atb":[[18.5,0.06]],"batb":[[0,18,19.69]],"id":58186642}]}]}
{"op":"mcm","id":2,"clk":"ALyPAgCHygEAiPQB","pt":1743512042691,"mc":[{"id":"1.241629436","rc":[{"atb":[[9,25.61]],"batb":[],"id":27115873},{"atb":[[18,20.63]],"batb":[[0,18,20.69]],"id":58186642}]}]}
