{"op":"mcm","id":2,"clk":"AMOPAgCSygEAjfQB","pt":1743512042786,"mc":[{"id":"1.241629436","rc":[{"atb":[[11,95.22]],"batb":[[0,11,95.22]],"id":40389088},{"atb":[[4.7,245.22]],"batb":[[0,4.7,245.22]],"id":270592},{"atb":[[9.8,65.25]],"batb":[[0,9.8,65.25]],"id":35856222},{"atb":[[5.1,152.63]],"batb":[[0,5.1,152.63]],"id":56297029},{"atb":[[6.2,189.83],[6.4,317.75]],"batb":[[2,6.4,317.75]],"id":26496185},{"atb":[[11,107.72]],"batb":[[0,11,107.72]],"id":44049799}]}]}
{"op":"mcm","id":2,"clk":"ANSPAgCfygEAmfQB","pt":1743512042991,"mc":[{"id":"1.241629436","rc":[{"atb":[[5.1,142.4]],"trd":[[5.1,4492.83]],"batb":[[0,5.1,142.4]],"tv":13634.79,"id":56297029},{"atb":[[6.6,240.47]],"batb":[[1,6.6,240.47]],"id":26496185}],"tv":83108.67}]}
{"op":"mcm","id":2,"clk":"AOOPAgCsygEArPQB","pt":1743512043204,"mc":[{"id":"1.241629436","rc":[{"atl":[[5.5,98.53]],"batl":[],"id":56297029},{"atb":[[6.4,287.75]],"batb":[[2,6.4,287.75]],"id":26496185}]}]}
{"op":"mcm","id":2,"clk":"AOuPAgCvygEArvQB","pt":1743512043253,"mc":[{"id":"1.241629436","rc":[{"atl":[[1000,23.16]],"id":270592}]}]}
{"op":"mcm","id":2,"clk":"APWPAgC2ygEAt/QB","pt":1743512043360,"mc":[{"id":"1.241629436","rc":[{"atb":[[6.8,93.67]],"trd":[[6.8,653.58]],"batb":[[0,6.8,93.67]],"ltp":6.8,"tv":13007.9,"id":26496185}],"tv":83118.67}]}
{"op":"mcm","id":2,"clk":"AP2PAgC7ygEAvfQB","pt":1743512043460,"mc":[{"id":"1.241629436","rc":[{"atl":[[1000,21.16],[4.9,136.98]],"batl":[[0,4.9,136.98]],"id":270592},{"atb":[[6.8,76.95]],"trd":[[6.8,687.02]],"batb":[[0,6.8,76.95]],"tv":13041.34,"id":26496185}],"tv":83152.11}]}
{"op":"mcm","id":2,"clk":"AIWQAgDGygEAx/QB","pt":1743512043564,"mc":[{"id":"1.241629436","rc":[{"atb":[[4.7,245.12]],"trd":[[4.7,1328.45]],"batb":[[0,4.7,245.12]],"ltp":4.7,"tv":20372.9,"id":270592},{"atl":[[10,96.36]],"batl":[[0,10,96.36]],"id":35856222},{"atb":[[6.8,70.61]],"trd":[[6.8,690.78]],"batb":[[0,6.8,70.61]],"tv":13045.1,"id":26496185}],"tv":83156.07}]}
{"op":"mcm","id":2,"clk":"AIuQAgDKygEAzfQB","pt":1743512043664,"mc":[{"id":"1.241629436","rc":[{"atb":[[4.1,74.78]],"batb":[],"id":270592}]}]}
{"op":"mcm","id":2,"clk":"AJCQAgDTygEA1fQB","pt":1743512043766,"mc":[{"id":"1.241629436","rc":[{"atb":[[4.7,247.17]],"atl":[[1000,22.18]],"batb":[[0,4.7,247.17]],"id":270592},{"atb":[[17,54.71]],"batb":[[2,17,54.71]],"id":58186642}]}]}
{"op":"mcm","id":2,"clk":"AJuQAgDZygEA4fQB","pt":1743512043963,"mc":[{"id":"1.241629436","rc":[{"atl":[[1000,21.18]],"id":270592}]}]}
{"op":"mcm","id":2,"clk":"AK+QAgDoygEA7/QB","pt":1743512044178,"mc":[{"id":"1.241629436","rc":[{"atl":[[1000,21.16]],"id":270592},{"atl":[[5.5,93.03]],"batl":[],"id":56297029},{"atb":[[6.8,99.73]],"batb":[[0,6.8,99.73]],"id":26496185}]}]}
{"op":"mcm","id":2,"clk":"ALyQAgD0ygEA9/QB","pt":1743512044287,"mc":[{"id":"1.241629436","rc":[{"atb":[[4.7,247.15]],"atl":[[5.2,230]],"trd":[[4.7,1328.49]],"batb":[[0,4.7,247.15]],"batl":[],"tv":20372.94,"id":270592},{"atb":[[6.8,124.15]],"batb":[[0,6.8,124.15]],"id":26496185}],"tv":83156.11}]}
{"op":"mcm","id":2,"clk":"AMSQAgD6ygEA/PQB","pt":1743512044383,"mc":[{"id":"1.241629436","rc":[{"atb":[[4.2,84.67]],"batb":[],"id":270592},{"atb":[[9,24.26]],"batb":[],"id":27115873}]}]}
{"op":"mcm","id":2,"clk":"ANOQAgCIywEAhfUB","pt":1743512044495,"mc":[{"id":"1.241629436","rc":[{"atb":[[6.8,142.64]],"batb":[[0,6.8,142.64]],"id":26496185}]}]}
{"op":"mcm","id":2,"clk":"APCQAgCaywEAmPUB","pt":1743512044806,"mc":[{"id":"1.241629436","rc":[{"atb":[[4.7,197.13]],"atl":[[1000,23.16]],"trd":[[4.7,1428.5]],"batb":[[0,4.7,197.13]],"tv":20472.95,"id":270592}],"tv":83256.12}]}
{"op":"mcm","id":2,"clk":"APeQAgCgywEAnvUB","pt":1743512044909,"mc":[{"id":"1.241629436","rc":[{"atl":[[4.8,4.03]],"trd":[[4.8,3183.31]],"batl":[[2,5,171.61],[1,4.9,136.98],[0,4.8,4.03]],"ltp":4.8,"tv":20476.95,"id":270592},{"atb":[[55,4.18]],"trd":[[55,305.65]],"batb":[[0,55,4.18]],"tv":1981.89,"id":59626646}],"tv":83264.12}]}
{"op":"mcm","id":2,"clk":"APuQAgChywEAn/UB","pt":1743512044994,"mc":[{"id":"1.241629436","rc":[{"atb":[[4.7,233.07]],"atl":[[1000,21.16],[5,173.21],[4.8,63.51]],"batb":[[0,4.7,233.07]],"batl":[[2,5,173.21],[0,4.8,63.51]],"id":270592},{"atb":[[1.17,2.98]],"atl":[[5.2,345.45]],"batl":[[0,5.2,345.45]],"id":56297029},{"atl":[[19,18.66]],"batl":[[0,19,18.66]],"id":58186642}]}]}
{"op":"mcm","id":2,"clk":"AIiRAgCsywEApPUB","pt":1743512045097,"mc":[{"id":"1.241629436","rc":[{"atb":[[4.6,146.75]],"atl":[[4.8,58.52]],"trd":[[4.8,3193.31]],"batb":[[1,4.6,146.75]],"batl":[[0,4.8,58.52]],"tv":20486.95,"id":270592},{"atb":[[1.17,2]],"atl":[[5.2,343.45]],"trd":[[5.2,3710.37]],"batl":[[0,5.2,343.45]],"ltp":5.2,"tv":13638.79,"id":56297029},{"atb":[[6.2,193.04]],"atl":[[7,59.79]],"batb":[],"batl":[[0,7,59.79]],"id":26496185}],"tv":83278.12}]}
{"op":"mcm","id":2,"clk":"AI6RAgCyywEArvUB","pt":1743512045152,"mc":[{"id":"1.241629436","rc":[{"atb":[[4.3,103.81]],"atl":[[5.2,235.06],[4.9,142.36],[4.8,64]],"batb":[],"batl":[[1,4.9,142.36],[0,4.8,64]],"id":270592},{"atb":[[5,1207.11]],"batb":[[1,5,1207.11]],"id":56297029}]}]}
{"op":"mcm","id":2,"clk":"AJqRAgC3ywEAt/UB","pt":1743512045264,"mc":[{"id":"1.241629436","rc":[{"atb":[[3.95,52.18]],"atl":[[4.8,61.58]],"trd":[[4.8,3198.15]],"batb":[],"batl":[[0,4.8,61.58]],"tv":20491.79,"id":270592}],"tv":83282.96}]}
{"op":"mcm","id":2,"clk":"AKKRAgC/ywEAwPUB","pt":1743512045370,"mc":[{"id":"1.241629436","rc":[{"atl":[[4.8,8.12]],"batl":[[0,4.8,8.12]],"id":270592}]}]}
{"op":"mcm","id":2,"clk":"AKqRAgDIywEAyfUB","pt":1743512045466,"mc":[{"id":"1.241629436","rc":[{"atb":[[9.8,66.69]],"trd":[[9.8,521.42]],"batb":[[0,9.8,66.69]],"tv":7203.6,"id":27115873}],"tv":83284.52}]}
{"op":"mcm","id":2,"clk":"ALKRAgDPywEAz/UB","pt":1743512045570,"mc":[{"id":"1.241629436","rc":[{"atl":[[4.8,5.7]],"trd":[[4.8,3203]],"batl":[[0,4.8,5.7]],"tv":20496.64,"id":270592},{"atl":[[19,12.06]],"trd":[[19,199.85]],"batl":[[0,19,12.06]],"tv":5862.86,"id":58186642}],"tv":83302.57}]}
{"op":"mcm","id":2,"clk":"ALqRAgDTywEA0vUB","pt":1743512045668,"mc":[{"id":"1.241629436","rc":[{"atb":[[18.5,5.43]],"batb":[[2,17.5,21.69],[1,18,20.63],[0,18.5,5.43]],"id":58186642},{"atb":[[6.4,284.68]],"batb":[[2,6.4,284.68]],"id":26496185}]}]}
{"op":"mcm","id":2,"clk":"AMORAgDfywEA2/UB","pt":1743512045777,"mc":[{"id":"1.241629436","rc":[{"atb":[[11,96.36]],"batb":[[0,11,96.36]],"id":40389088},{"atl":[[5.2,234.16]],"batl":[],"id":270592},{"atb":[[6.8,145.71]],"batb":[[0,6.8,145.71]],"id":26496185}]}]}
{"op":"mcm","id":2,"clk":"AM2RAgDsywEA6fUB","pt":1743512045980,"mc":[{"id":"1.241629436","rc":[{"atl":[[5.1,175.5]],"batl":[],"id":270592}]}]}
{"op":"mcm","id":2,"clk":"ANORAgD0ywEA7PUB","pt":1743512046083,"mc":[{"id":"1.241629436","rc":[{"atl":[[11.5,24.29]],"batl":[[0,11.5,24.29]],"id":40389088},{"atb":[[55,4.61]],"batb":[[0,55,4.61]],"id":59626646},{"atb":[[5.1,139.72]],"batb":[[0,5.1,139.72]],"id":56297029},{"atl":[[10,5.12]],"trd":[[10,585.66]],"batl":[[0,10,5.12]],"ltp":10,"tv":7209.3,"id":27115873},{"atl":[[1000,1.61]],"id":58186642}],"tv":83308.27}]}
{"op":"mcm","id":2,"clk":"ANiRAgD5ywEA8fUB","pt":1743512046183,"mc":[{"id":"1.241629436","rc":[{"atb":[[18.5,0.06]],"batb":[[2,17,54.71],[1,17.5,21.69],[0,18,20.69]],"id":58186642}]}]}
{"op":"mcm","id":2,"clk":"AN+RAgD9ywEA8vUB","pt":1743512046282,"mc":[{"id":"1.241629436","rc":[{"atl":[[1000,1.41]],"id":58186642}]}]}
{"op":"mcm","id":2,"clk":"AOWRAgCEzAEA/fUB","pt":1743512046394,"mc":[{"id":"1.241629436","rc":[{"atl":[[10,3.73]],"trd":[[10,588.44]],"batl":[[0,10,3.73]],"tv":7212.08,"id":27115873},{"atb":[[18.5,0]],"atl":[[18.5,0.14]],"trd":[[18.5,93.39]],"batb":[[0,18,20.63]],"batl":[[0,19,12.2]],"ltp":18.5,"tv":5862.98,"id":58186642}],"tv":83311.17}]}
{"op":"mcm","id":2,"clk":"APiRAgCTzAEAh/YB","pt":1743512046595,"mc":[{"id":"1.241629436","rc":[{"atb":[[6.4,287.67]],"batb":[[2,6.4,287.67]],"id":26496185}]}]}
{"op":"mcm","id":2,"clk":"AJSSAgDCzAEAmPYB","pt":1743512046908,"mc":[{"id":"1.241629436","rc":[{"atb":[[4.1,124.78]],"batb":[],"id":270592}]}]}
{"op":"mcm","id":2,"clk":"AJ6SAgDKzAEAofYB","pt":1743512047059,"mc":[{"id":"1.241629436","rc":[{"atb":[[4.7,243.07]],"batb":[[0,4.7,243.07]],"id":270592}]}]}
{"op":"mcm","id":2,"clk":"AKWSAgDUzAEApfYB","pt":1743512047161,"mc":[{"id":"1.241629436","rc":[{"atb":[[4.7,245.07]],"batb":[[0,4.7,245.07]],"id":270592}]}]}
{"op":"mcm","id":2,"clk":"AK2SAgDbzAEArvYB","pt":1743512047267,"mc":[{"id":"1.241629436","rc":[{"atl":[[7.2,111.54]],"batl":[[1,7.2,111.54]],"id":26496185}]}]}
{"op":"mcm","id":2,"clk":"ALeSAgDpzAEAuPYB","pt":1743512047467,"mc":[{"id":"1.241629436","rc":[{"atl":[[60,13.16]],"batl":[[0,60,13.16]],"id":59626646},{"atb":[[4.7,35.65],[4.3,31.93]],"atl":[[5.8,107.59]],"batb":[],"batl":[],"id":56297029},{"atl":[[11.5,82.24]],"trd":[[11.5,799.55]],"batl":[[0,11.5,82.24]],"ltp":11.5,"tv":4837.66,"id":44049799}],"tv":83322.17}]}
{"op":"mcm","id":2,"clk":"AMGSAgDxzAEAxfYB","pt":1743512047675,"mc":[{"id":"1.241629436","rc":[{"atb":[[11,105.73]],"trd":[[11,1553.62]],"batb":[[0,11,105.73]],"ltp":11,"tv":4841.66,"id":44049799}],"tv":83326.17}]}
{"op":"mcm","id":2,"clk":"AOGSAgCJzQEA5vYB","pt":1743512048077,"mc":[{"id":"1.241629436","rc":[{"atb":[[4.7,243.85]],"batb":[[0,4.7,243.85]],"id":270592},{"atb":[[5.1,139.02]],"atl":[[5.2,339.93]],"batb":[[0,5.1,139.02]],"batl":[[0,5.2,339.93]],"id":56297029},{"atl":[[19,7.22]],"batl":[[0,19,7.36]],"id":58186642},{"atb":[[6.8,150.25]],"batb":[[0,6.8,150.25]],"id":26496185}]}]}
{"op":"mcm","id":2,"clk":"AOySAgCQzQEA+PYB","pt":1743512048198,"mc":[{"id":"1.241629436","rc":[{"atb":[[1.17,2.64],[10.5,51.01]],"atl":[[1000,0.35]],"batb":[[1,10.5,51.01]],"id":40389088},{"atl":[[4.9,143.67],[5,171.61]],"batl":[[2,5,171.61],[1,4.9,143.67]],"id":270592},{"atb":[[1.17,7.93],[9.6,61.82]],"atl":[[1000,0.65],[10,96.22]],"batb":[[1,9.6,61.82]],"batl":[[0,10,96.22]],"id":35856222},{"atb":[[5,1206.13]],"atl":[[5.2,337.93]],"trd":[[5.2,3714.37]],"batb":[[1,5,1206.13]],"batl":[[0,5.2,337.93]],"tv":13642.79,"id":56297029},{"atb":[[18,20.12]],"batb":[[0,18,20.12]],"id":58186642}],"tv":83330.17}]}
{"op":"mcm","id":2,"clk":"APeSAgCezQEAg/cB","pt":1743512048367,"mc":[{"id":"1.241629436","rc":[{"atb":[[1.17,2]],"atl":[[1000,0.25]],"id":40389088},{"atl":[[5.2,165.07]],"batl":[],"id":270592},{"atb":[[1.17,7.15]],"atl":[[1000,0.41]],"id":35856222}]}]}
{"op":"mcm","id":2,"clk":"AICTAgCgzQEAiPcB","pt":1743512048399,"mc":[{"id":"1.241629436","rc":[{"atb":[[11,97]],"atl":[[11.5,24.39]],"batb":[[0,11,97]],"batl":[[0,11.5,24.39]],"id":40389088},{"atb":[[9.8,66.03]],"atl":[[10.5,76]],"batb":[[0,9.8,66.03]],"batl":[[1,10.5,76]],"id":35856222},{"atl":[[5.9,20.03],[5.5,88.18]],"batl":[],"id":56297029}]}]}
{"op":"mcm","id":2,"clk":"AIqTAgCjzQEAk/cB","pt":1743512048509,"mc":[{"id":"1.241629436","rc":[{"atl":[[1000,23.16]],"id":270592},{"atb":[[9.8,61.69]],"trd":[[9.8,531.42]],"batb":[[0,9.8,61.69]],"ltp":9.8,"tv":7222.08,"id":27115873}],"tv":83340.17}]}
{"op":"mcm","id":2,"clk":"AI+TAgCtzQEAnfcB","pt":1743512048605,"mc":[{"id":"1.241629436","rc":[{"atb":[[4.8,2]],"atl":[[1000,25.16],[4.9,124.25],[4.8,0]],"trd":[[4.9,2717.99],[4.8,3214.4]],"batb":[[2,4.6,146.75],[1,4.7,243.85],[0,4.8,2]],"batl":[[2,5.1,175.5],[1,5,171.61],[0,4.9,124.25]],"ltp":4.9,"tv":20546.88,"id":270592}],"tv":83390.41}]}
{"op":"mcm","id":2,"clk":"AJ2TAgCzzQEApPcB","pt":1743512048714,"mc":[{"id":"1.241629436","rc":[{"atl":[[1000,23.16],[5.2,155.07]],"batl":[],"id":270592},{"atl":[[6,62.39]],"batl":[],"id":56297029}]}]}
{"op":"mcm","id":2,"clk":"AKuTAgC8zQEArfcB","pt":1743512048771,"mc":[{"id":"1.241629436","rc":[{"atb":[[4.8,0]],"atl":[[1000,21.16],[4.9,134.25]],"trd":[[4.8,3218.39]],"batb":[[2,4.5,122.58],[1,4.6,146.75],[0,4.7,243.85]],"batl":[[0,4.9,134.25]],"ltp":4.8,"tv":20550.87,"id":270592}],"tv":83394.4}]}
{"op":"mcm","id":2,"clk":"ALOTAgDGzQEAsfcB","pt":1743512048885,"mc":[{"id":"1.241629436","rc":[{"atl":[[4.9,140.19]],"batl":[[0,4.9,140.19]],"id":270592},{"atl":[[7,48.79]],"trd":[[7,131.46]],"batl":[[0,7,48.79]],"ltp":7,"tv":13067.1,"id":26496185}],"tv":83416.4}]}
{"op":"mcm","id":2,"clk":"ALyTAgDQzQEAu/cB","pt":1743512048988,"mc":[{"id":"1.241629436","rc":[{"atb":[[4.6,143.66]],"batb":[[1,4.6,143.66]],"id":270592}]}]}
{"op":"mcm","id":2,"clk":"AMOTAgDXzQEAvPcB","pt":1743512049078,"mc":[{"id":"1.241629436","rc":[{"atb":[[4.2,134.67]],"atl":[[4.8,5.6]],"batb":[],"batl":[[2,5,171.61],[1,4.9,140.19],[0,4.8,5.6]],"id":270592}]}]}
{"op":"mcm","id":2,"clk":"AMyTAgDezQEAxvcB","pt":1743512049190,"mc":[{"id":"1.241629436","rc":[{"atb":[[4.6,146.75]],"batb":[[1,4.6,146.75]],"id":270592}]}]}
{"op":"mcm","id":2,"clk":"APCTAgDvzQEA1fcB","pt":1743512049496,"mc":[{"id":"1.241629436","rc":[{"atb":[[55,4.55]],"trd":[[55,305.77]],"batb":[[0,55,4.55]],"tv":1982.01,"id":59626646}],"tv":83416.52}]}
{"op":"mcm","id":2,"clk":"APmTAgD2zQEA2vcB","pt":1743512049601,"mc":[{"id":"1.241629436","rc":[{"atl":[[4.8,4.6]],"trd":[[4.8,3220.39]],"batl":[[0,4.8,4.6]],"tv":20552.87,"id":270592}],"tv":83418.52}]}
{"op":"mcm","id":2,"clk":"AIuUAgCKzgEA6vcB","pt":1743512049810,"mc":[{"id":"1.241629436","rc":[{"atl":[[7,0]],"trd":[[7,229.04]],"batl":[[2,7.6,32.8],[1,7.4,42.9],[0,7.2,111.54]],"tv":13164.68,"id":26496185}],"tv":83516.1}]}
{"op":"mcm","id":2,"clk":"AJaUAgCRzgEA8fcB","pt":1743512049870,"mc":[{"id":"1.241629436","rc":[{"atb":[[5.1,133.39]],"batb":[[0,5.1,133.39]],"id":56297029}]}]}
{"op":"mcm","id":2,"clk":"AKKUAgCVzgEA9/cB","pt":1743512049966,"mc":[{"id":"1.241629436","rc":[{"atb":[[4.7,257.47]],"batb":[[0,4.7,257.47]],"id":270592},{"atb":[[55,7.16]],"batb":[[0,55,7.16]],"id":59626646},{"atb":[[7,19.46],[6,157.27],[6.2,189.83],[6.4,284.68]],"atl":[[9.4,14.11],[7.2,132.99]],"batb":[[2,6.6,240.47],[1,6.8,150.25],[0,7,19.46]],"batl":[[0,7.2,132.99]],"id":26496185}]}]}
{"op":"mcm","id":2,"clk":"AK2UAgCezgEA/vcB","pt":1743512050073,"mc":[{"id":"1.241629436","rc":[{"atb":[[11,95]],"trd":[[11,239.72]],"batb":[[0,11,95]],"tv":6445.92,"id":40389088},{"atl":[[5,176.61],[4.8,6.71]],"batl":[[2,5,176.61],[0,4.8,6.71]],"id":270592},{"atb":[[55,3.34]],"trd":[[55,309.77]],"batb":[[0,55,3.34]],"tv":1986.01,"id":59626646},{"atb":[[7,0.74],[6.2,172.36],[6.4,287.67]],"atl":[[7.4,50.91],[7.2,124.46]],"trd":[[7,266.48]],"batb":[[2,6.4,287.67],[1,6.6,240.47],[0,6.8,150.99]],"batl":[[1,7.4,50.91],[0,7.2,124.46]],"tv":13202.12,"id":26496185},{"atl":[[12,35.76]],"batl":[[1,12,35.76]],"id":44049799}],"tv":83561.54}]}
{"op":"mcm","id":2,"clk":"ALaUAgCizgEAgvgB","pt":1743512050172,"mc":[{"id":"1.241629436","rc":[{"atl":[[1000,23.16]],"id":270592},{"atl":[[7.6,37.19],[7.2,132.55]],"batl":[[2,7.6,37.19],[0,7.2,132.55]],"id":26496185},{"atl":[[12,30.76]],"batl":[[1,12,30.76]],"id":44049799}]}]}
{"op":"mcm","id":2,"clk":"AMOUAgCmzgEAj/gB","pt":1743512050281,"mc":[{"id":"1.241629436","rc":[{"atl":[[60,14.36]],"batl":[[0,60,14.36]],"id":59626646},{"atb":[[7,0],[6.8,150.2],[6.4,284.68]],"atl":[[7.4,34.39]],"trd":[[7,267.96],[6.8,690.86]],"batb":[[2,6.4,284.68],[0,6.8,150.2]],"batl":[[1,7.4,34.39]],"ltp":6.8,"tv":13203.68,"id":26496185}],"tv":83563.1}]}
{"op":"mcm","id":2,"clk":"AM2UAgCtzgEAmPgB","pt":1743512050385,"mc":[{"id":"1.241629436","rc":[{"atl":[[1000,21.16]],"id":270592},{"atb":[[1.08,102.33],[6.8,163.4],[3.2,1]],"batb":[[0,6.8,163.4]],"id":26496185}]}]}
{"op":"mcm","id":2,"clk":"ANiUAgC0zgEAmfgB","pt":1743512050486,"mc":[{"id":"1.241629436","rc":[{"atb":[[5.1,134.57]],"batb":[[0,5.1,134.57]],"id":56297029}]}]}
{"op":"mcm","id":2,"clk":"APaUAgDOzgEAp/gB","pt":1743512050797,"mc":[{"id":"1.241629436","rc":[{"atl":[[4.8,2.32]],"trd":[[4.8,3230.4]],"batl":[[0,4.8,2.32]],"tv":20562.88,"id":270592},{"atb":[[1.08,100.08]],"id":26496185}],"tv":83573.11}]}
{"op":"mcm","id":2,"clk":"AIGVAgDYzgEAsvgB","pt":1743512050906,"mc":[{"id":"1.241629436","rc":[{"atb":[[7,5.6]],"batb":[[2,6.6,240.47],[1,6.8,163.4],[0,7,5.6]],"id":26496185}]}]}
{"op":"mcm","id":2,"clk":"AJOVAgDgzgEAtfgB","pt":1743512051006,"mc":[{"id":"1.241629436","rc":[{"atb":[[7,0]],"atl":[[7,21.32]],"trd":[[7,279.16]],"batb":[[2,6.4,284.68],[1,6.6,240.47],[0,6.8,163.4]],"batl":[[2,7.4,34.39],[1,7.2,132.55],[0,7,21.32]],"ltp":7,"tv":13214.88,"id":26496185}],"tv":83584.31}]}
{"op":"mcm","id":2,"clk":"AKuVAgCEzwEAw/gB","pt":1743512051114,"mc":[{"id":"1.241629436","rc":[{"atl":[[1000,0.38]],"id":40389088},{"atb":[[5.1,133.57]],"trd":[[5.1,4494.83]],"batb":[[0,5.1,133.57]],"ltp":5.1,"tv":13644.79,"id":56297029},{"atl":[[1000,1.45]],"id":27115873},{"atb":[[6.4,287.67]],"atl":[[7.8,29.21],[7,0.53]],"trd":[[7,320.74]],"batb":[[2,6.4,287.67]],"batl":[[2,7.6,37.19],[1,7.4,34.39],[0,7.2,133.08]],"tv":13256.46,"id":26496185}],"tv":83627.89}]}
{"op":"mcm","id":2,"clk":"AMGVAgCRzwEAzvgB","pt":1743512051177,"mc":[{"id":"1.241629436","rc":[{"atl":[[1000,0.25]],"id":40389088},{"atb":[[9.8,63.09]],"atl":[[1000,1.16]],"batb":[[0,9.8,63.09]],"id":27115873},{"atb":[[1.08,100],[6.6,243.27],[5.7,81.45]],"batb":[[1,6.6,243.27]],"id":26496185}]}]}
{"op":"mcm","id":2,"clk":"AOWVAgC+zwEA+PgB","pt":1743512051286,"mc":[{"id":"1.241629436","rc":[{"atl":[[12,85.27]],"batl":[[1,12,85.27]],"id":40389088},{"atb":[[5.1,132.68]],"batb":[[0,5.1,132.68]],"id":56297029},{"atl":[[10.5,73.09]],"batl":[[1,10.5,73.09]],"id":27115873},{"atb":[[6.6,240.47],[7,19.46],[3.25,3.08],[6.4,284.68]],"atl":[[7,0]],"trd":[[7,321.8]],"batb":[[2,6.6,240.47],[1,6.8,163.4],[0,7,19.46]],"batl":[[0,7.2,132.55]],"tv":13257.52,"id":26496185}],"tv":83628.95}]}
{"op":"mcm","id":2,"clk":"APOVAgDVzwEAj/kB","pt":1743512051389,"mc":[{"id":"1.241629436","rc":[{"atb":[[4.4,197.68]],"batb":[],"id":270592},{"atb":[[7,26.84],[6.8,169.01],[6.2,177.96],[6.4,293.28]],"atl":[[7.2,124.46]],"batb":[[1,6.8,169.01],[0,7,26.84]],"batl":[[0,7.2,124.46]],"id":26496185},{"atl":[[12,35.76]],"batl":[[1,12,35.76]],"id":44049799}]}]}
{"op":"mcm","id":2,"clk":"AI2WAgD+zwEAtvkB","pt":1743512051599,"mc":[{"id":"1.241629436","rc":[{"atb":[[6.4,288.51]],"batb":[],"id":26496185}]}]}
{"op":"mcm","id":2,"clk":"AK2WAgCa0AEA1PkB","pt":1743512051912,"mc":[{"id":"1.241629436","rc":[{"atl":[[7.8,34.24]],"batl":[],"id":26496185}]}]}
{"op":"mcm","id":2,"clk":"AMaWAgCr0AEA5vkB","pt":1743512052069,"mc":[{"id":"1.241629436","rc":[{"atb":[[6,160.21]],"batb":[],"id":26496185}]}]}
{"op":"mcm","id":2,"clk":"ANiWAgC20AEA8fkB","pt":1743512052174,"mc":[{"id":"1.241629436","rc":[{"atb":[[4.7,254.63]],"atl":[[4.8,1.32]],"trd":[[4.7,1434.18],[4.8,3232.4]],"batb":[[0,4.7,254.63]],"batl":[[0,4.8,1.32]],"tv":20570.56,"id":270592},{"atb":[[7,30.84]],"batb":[[0,7,30.84]],"id":26496185}],"tv":83636.63}]}
{"op":"mcm","id":2,"clk":"AOGWAgDD0AEA/PkB","pt":1743512052267,"mc":[{"id":"1.241629436","rc":[{"atl":[[4.8,0.61]],"batl":[[2,5.1,175.5],[1,5,176.61],[0,4.9,140.8]],"id":270592},{"atl":[[10,2.28]],"trd":[[10,591.34]],"batl":[[0,10,2.28]],"ltp":10,"tv":7224.98,"id":27115873},{"atb":[[7,39.83]],"batb":[[0,7,39.83]],"id":26496185}],"tv":83639.53}]}
{"op":"mcm","id":2,"clk":"AO2WAgDL0AEAiPoB","pt":1743512052372,"mc":[{"id":"1.241629436","rc":[{"atb":[[4.7,254.34],[4.6,143.66]],"batb":[[1,4.6,143.66],[0,4.7,254.34]],"id":270592},{"atb":[[50,21.59]],"batb":[[1,50,21.59]],"id":59626646},{"atb":[[7,31.84]],"batb":[[0,7,31.84]],"id":26496185}]}]}
{"op":"mcm","id":2,"clk":"APeWAgDd0AEAj/oB","pt":1743512052476,"mc":[{"id":"1.241629436","rc":[{"atb":[[4.6,198.66]],"batb":[[1,4.6,198.66]],"id":270592},{"atl":[[60,14.41]],"batl":[[0,60,14.41]],"id":59626646},{"atb":[[7,33.84]],"batb":[[0,7,33.84]],"id":26496185}]}]}
{"op":"mcm","id":2,"clk":"AI+XAgDu0AEAovoB","pt":1743512052789,"mc":[{"id":"1.241629436","rc":[{"atb":[[4.7,235.83]],"batb":[[0,4.7,235.83]],"id":270592},{"atb":[[7,35.84]],"batb":[[0,7,35.84]],"id":26496185}]}]}
{"op":"mcm","id":2,"clk":"AJmXAgDy0AEAp/oB","pt":1743512052896,"mc":[{"id":"1.241629436","rc":[{"atb":[[5.1,220.43]],"batb":[[0,5.1,220.43]],"id":56297029}]}]}
{"op":"mcm","id":2,"clk":"AKuXAgD20AEAq/oB","pt":1743512053002,"mc":[{"id":"1.241629436","rc":[{"atl":[[5.1,174.6]],"batl":[[2,5.1,174.6]],"id":270592},{"atl":[[5.2,333.93]],"batl":[[0,5.2,333.93]],"id":56297029},{"atb":[[18,18.12]],"trd":[[18,146.29]],"batb":[[0,18,18.12]],"ltp":18,"tv":5866.98,"id":58186642}],"tv":83643.53}]}
{"op":"mcm","id":2,"clk":"ALOXAgCB0QEAsPoB","pt":1743512053095,"mc":[{"id":"1.241629436","rc":[{"atl":[[18.5,5.62]],"batl":[[2,19.5,41.31],[1,19,7.22],[0,18.5,5.62]],"id":58186642},{"atb":[[7,30.84]],"trd":[[7,331.8]],"batb":[[0,7,30.84]],"tv":13267.52,"id":26496185}],"tv":83653.53}]}
{"op":"mcm","id":2,"clk":"AL+XAgCQ0QEAtfoB","pt":1743512053206,"mc":[{"id":"1.241629436","rc":[{"atl":[[5.2,155.97]],"batl":[],"id":270592},{"atb":[[18,15.91]],"batb":[[0,18,15.91]],"id":58186642}]}]}
{"op":"mcm","id":2,"clk":"AMqXAgCU0QEAtvoB","pt":1743512053302,"mc":[{"id":"1.241629436","rc":[{"atl":[[19,10.85]],"batl":[[1,19,10.85]],"id":58186642},{"atb":[[6.4,287.28]],"atl":[[17.5,3.49]],"batb":[],"id":26496185}]}]}
{"op":"mcm","id":2,"clk":"ANOXAgCf0QEAwfoB","pt":1743512053407,"mc":[{"id":"1.241629436","rc":[{"atb":[[16,18.46]],"batb":[],"id":58186642}]}]}
{"op":"mcm","id":2,"clk":"AOGXAgCx0QEAzfoB","pt":1743512053605,"mc":[{"id":"1.241629436","rc":[{"atl":[[4.8,55.61]],"batl":[[2,5,176.61],[1,4.9,140.19],[0,4.8,55.61]],"id":270592},{"atb":[[7,25.84]],"trd":[[7,341.8]],"batb":[[0,7,25.84]],"tv":13277.52,"id":26496185}],"tv":83663.53}]}
{"op":"mcm","id":2,"clk":"AOmXAgC70QEA0voB","pt":1743512053719,"mc":[{"id":"1.241629436","rc":[{"atl":[[4.8,35.61]],"trd":[[4.8,3272.4]],"batl":[[0,4.8,35.61]],"tv":20610.56,"id":270592},{"atb":[[9.8,65.25]],"batb":[[0,9.8,65.25]],"id":35856222},{"atb":[[18,12.28]],"trd":[[18,153.55]],"batb":[[0,18,12.28]],"tv":5874.24,"id":58186642},{"atb":[[7,17.28]],"trd":[[7,358.92]],"batb":[[0,7,17.28]],"tv":13294.64,"id":26496185}],"tv":83727.91}]}
{"op":"mcm","id":2,"clk":"APGXAgDD0QEA1foB","pt":1743512053768,"mc":[{"id":"1.241629436","rc":[{"atb":[[4.6,201.75]],"atl":[[4.8,31.38]],"trd":[[4.8,3280.86]],"batb":[[1,4.6,201.75]],"batl":[[0,4.8,31.38]],"tv":20619.02,"id":270592},{"atb":[[17.5,27.48]],"batb":[[1,17.5,27.48]],"id":58186642}],"tv":83736.37}]}
{"op":"mcm","id":2,"clk":"AP2XAgDM0QEA3voB","pt":1743512053884,"mc":[{"id":"1.241629436","rc":[{"atl":[[1000,23.16],[4.8,24.8]],"trd":[[4.8,3294.02]],"batl":[[0,4.8,24.8]],"tv":20632.18,"id":270592},{"atb":[[18,0]],"atl":[[19,13.08],[18,5.62],[18.5,7.49]],"trd":[[18,178.11]],"batb":[[2,16.5,18.43],[1,17,54.71],[0,17.5,27.48]],"batl":[[2,19,13.08],[1,18.5,7.49],[0,18,5.62]],"tv":5898.8,"id":58186642},{"atb":[[7,0]],"atl":[[7,20.46],[7.2,127.8]],"trd":[[7,393.49]],"batb":[[2,6.4,287.28],[1,6.6,240.47],[0,6.8,169.01]],"batl":[[2,7.4,34.39],[1,7.2,127.8],[0,7,20.46]],"tv":13329.21,"id":26496185},{"atl":[[12,30.76]],"batl":[[1,12,30.76]],"id":44049799}],"tv":83808.66}]}
{"op":"mcm","id":2,"clk":"AISYAgDW0QEA5PoB","pt":1743512053979,"mc":[{"id":"1.241629436","rc":[{"atl":[[1000,25.16],[5.2,155.07]],"batl":[],"id":270592},{"atb":[[8.8,37.88],[9.8,78.25]],"batb":[[0,9.8,78.25]],"id":35856222},{"atb":[[17.5,32.63]],"batb":[[0,17.5,32.63]],"id":58186642},{"atb":[[6.4,265.75]],"atl":[[7.2,135.9]],"batb":[[2,6.4,265.75]],"batl":[[1,7.2,135.9]],"id":26496185}]}]}
{"op":"mcm","id":2,"clk":"AIeYAgDg0QEA6foB","pt":1743512054073,"mc":[{"id":"1.241629436","rc":[{"atb":[[4.7,238.77]],"atl":[[1000,23.16],[5.1,175.5]],"batb":[[0,4.7,238.77]],"batl":[],"id":270592},{"atb":[[17,51.46],[16,21.58],[16.5,15.13]],"batb":[[2,16.5,15.13],[1,17,51.46]],"id":58186642},{"atb":[[6.8,190.54],[6.4,268.74]],"batb":[[2,6.4,268.74],[0,6.8,190.54]],"id":26496185}]}]}
{"op":"mcm","id":2,"clk":"AJSYAgDp0QEA9PoB","pt":1743512054185,"mc":[{"id":"1.241629436","rc":[{"atl":[[1000,21.16]],"id":270592},{"atb":[[4.9,92.72]],"batb":[[2,4.9,92.72]],"id":56297029},{"atb":[[17,41]],"batb":[[1,17,41]],"id":58186642},{"atl":[[7.2,129.74]],"batl":[[1,7.2,129.74]],"id":26496185}]}]}
{"op":"mcm","id":2,"clk":"AJ+YAgDv0QEA+foB","pt":1743512054290,"mc":[{"id":"1.241629436","rc":[{"atb":[[5.1,236.24]],"batb":[[0,5.1,236.24]],"id":56297029},{"atl":[[7.2,131.68]],"batl":[[1,7.2,131.68]],"id":26496185}]}]}
{"op":"mcm","id":2,"clk":"AKqYAgD30QEA/voB","pt":1743512054393,"mc":[{"id":"1.241629436","rc":[{"atb":[[17.5,28.16]],"batb":[[0,17.5,28.16]],"id":58186642},{"atl":[[7,19.6]],"trd":[[7,395.21]],"batl":[[0,7,19.6]],"tv":13330.93,"id":26496185},{"atb":[[11,99.84]],"trd":[[11,1565.4]],"batb":[[0,11,99.84]],"tv":4853.44,"id":44049799}],"tv":83822.16}]}
{"op":"mcm","id":2,"clk":"ALKYAgD80QEAivsB","pt":1743512054506,"mc":[{"id":"1.241629436","rc":[{"atl":[[7.2,139.79],[8,36.07]],"batl":[[1,7.2,139.79]],"id":26496185}]}]}
{"op":"mcm","id":2,"clk":"AMCYAgCE0gEAjfsB","pt":1743512054604,"mc":[{"id":"1.241629436","rc":[{"atb":[[16,36.02]],"batb":[],"id":58186642}]}]}
{"op":"mcm","id":2,"clk":"AMaYAgCK0gEAk/sB","pt":1743512054695,"mc":[{"id":"1.241629436","rc":[{"atl":[[7,17.6]],"trd":[[7,399.21]],"batl":[[0,7,17.6]],"tv":13334.93,"id":26496185}],"tv":83826.16}]}
{"op":"mcm","id":2,"clk":"AM2YAgCP0gEAmPsB","pt":1743512054802,"mc":[{"id":"1.241629436","rc":[{"atl":[[12,85.14],[11.5,24.29]],"batl":[[1,12,85.14],[0,11.5,24.29]],"id":40389088},{"atb":[[4.7,237.71]],"batb":[[0,4.7,237.71]],"id":270592},{"atl":[[10.5,75.76]],"batl":[[1,10.5,75.76]],"id":35856222},{"atb":[[17.5,29.24]],"batb":[[0,17.5,29.24]],"id":58186642},{"atb":[[6.8,188.39]],"atl":[[7,0]],"trd":[[7,401.61]],"batb":[[0,6.8,188.39]],"batl":[[2,7.6,37.19],[1,7.4,34.39],[0,7.2,139.79]],"tv":13337.33,"id":26496185}],"tv":83828.56}]}
{"op":"mcm","id":2,"clk":"ANWYAgCV0gEAnvsB","pt":1743512054903,"mc":[{"id":"1.241629436","rc":[{"atb":[[55,5.07]],"batb":[[0,55,5.07]],"id":59626646},{"atb":[[6.8,178.39]],"trd":[[6.8,710.86]],"batb":[[0,6.8,178.39]],"ltp":6.8,"tv":13357.33,"id":26496185}],"tv":83848.56}]}
{"op":"mcm","id":2,"clk":"AN6YAgCb0gEArfsB","pt":1743512055013,"mc":[{"id":"1.241629436","rc":[{"atb":[[4.7,234.77]],"batb":[[0,4.7,234.77]],"id":270592},{"atl":[[60,14.36]],"batl":[[0,60,14.36]],"id":59626646},{"atb":[[16.5,18.26]],"batb":[[2,16.5,18.26]],"id":58186642},{"atb":[[7,19.47],[6.8,186.42],[6.2,174.75],[6.4,265.75]],"atl":[[7.2,131.68]],"batb":[[2,6.6,240.47],[1,6.8,186.42],[0,7,19.47]],"batl":[[0,7.2,131.68]],"id":26496185}]}]}
{"op":"mcm","id":2,"clk":"AOWYAgCj0gEAsPsB","pt":1743512055108,"mc":[{"id":"1.241629436","rc":[{"atb":[[9.8,30.42]],"batb":[],"id":40389088},{"atl":[[4.8,19.8]],"trd":[[4.8,3304.02]],"batl":[[0,4.8,19.8]],"tv":20642.18,"id":270592},{"atb":[[9.8,58.26]],"trd":[[9.8,874.33]],"batb":[[0,9.8,58.26]],"ltp":9.8,"tv":9845.11,"id":35856222}],"tv":83898.56}]}
{"op":"mcm","id":2,"clk":"AO+YAgCn0gEAu/sB","pt":1743512055211,"mc":[{"id":"1.241629436","rc":[{"atb":[[4.7,255.12]],"batb":[[0,4.7,255.12]],"id":270592},{"atl":[[12,22.2]],"batl":[],"id":35856222},{"atb":[[9.8,62.08]],"trd":[[9.8,533.42]],"batb":[[0,9.8,62.08]],"ltp":9.8,"tv":7226.98,"id":27115873},{"atb":[[7,0],[6.2,177.96]],"atl":[[7,13.51],[7.2,139.67]],"trd":[[7,453.56]],"batb":[[2,6.4,265.75],[1,6.6,240.47],[0,6.8,186.42]],"batl":[[2,7.4,34.39],[1,7.2,139.67],[0,7,13.51]],"ltp":7,"tv":13409.28,"id":26496185}],"tv":83952.51}]}
{"op":"mcm","id":2,"clk":"APuYAgCv0gEAw/sB","pt":1743512055275,"mc":[{"id":"1.241629436","rc":[{"atl":[[11,28.37]],"batl":[[2,11,28.37]],"id":35856222},{"atl":[[1000,6.35]],"id":56297029},{"atb":[[6.4,259.75]],"atl":[[7,15.51]],"batb":[[2,6.4,259.75]],"batl":[[0,7,15.51]],"id":26496185}]}]}
{"op":"mcm","id":2,"clk":"AIaZAgCy0gEAzPsB","pt":1743512055377,"mc":[{"id":"1.241629436","rc":[{"atb":[[4.7,258.06]],"atl":[[4.8,20.41]],"batb":[[0,4.7,258.06]],"batl":[[0,4.8,20.41]],"id":270592},{"atb":[[9.8,63.94]],"batb":[[0,9.8,63.94]],"id":35856222},{"atb":[[6.8,178.39],[6.4,262.74]],"atl":[[7,20.03]],"batb":[[2,6.4,262.74],[0,6.8,178.39]],"batl":[[0,7,20.03]],"id":26496185}]}]}
{"op":"mcm","id":2,"clk":"AI6ZAgC30gEA0/sB","pt":1743512055485,"mc":[{"id":"1.241629436","rc":[{"atb":[[55,4.07]],"trd":[[55,311.77]],"batb":[[0,55,4.07]],"tv":1988.01,"id":59626646},{"atl":[[1000,5.6]],"id":56297029}],"tv":83954.51}]}
{"op":"mcm","id":2,"clk":"AJmZAgC90gEA3PsB","pt":1743512055579,"mc":[{"id":"1.241629436","rc":[{"atl":[[5.2,330.93]],"trd":[[5.2,3720.37]],"batl":[[0,5.2,330.93]],"ltp":5.2,"tv":13650.79,"id":56297029}],"tv":83960.51}]}
{"op":"mcm","id":2,"clk":"AKKZAgDD0gEA4/sB","pt":1743512055683,"mc":[{"id":"1.241629436","rc":[{"atb":[[4.9,103.64]],"batb":[[2,4.9,103.64]],"id":56297029}]}]}
{"op":"mcm","id":2,"clk":"AKuZAgDJ0gEA5/sB","pt":1743512055784,"mc":[{"id":"1.241629436","rc":[{"atl":[[4.8,19.41]],"trd":[[4.8,3306.02]],"batl":[[0,4.8,19.41]],"tv":20644.18,"id":270592}],"tv":83962.51}]}
{"op":"mcm","id":2,"clk":"ALWZAgDR0gEA6/sB","pt":1743512055889,"mc":[{"id":"1.241629436","rc":[{"atb":[[9.4,25.08]],"batb":[],"id":40389088},{"atl":[[1000,5.52]],"id":56297029}]}]}
{"op":"mcm","id":2,"clk":"AL6ZAgDW0gEA8fsB","pt":1743512055989,"mc":[{"id":"1.241629436","rc":[{"atb":[[5.1,236.16]],"trd":[[5.1,4494.99]],"batb":[[0,5.1,236.16]],"ltp":5.1,"tv":13650.95,"id":56297029}],"tv":83962.67}]}
{"op":"mcm","id":2,"clk":"AMaZAgDg0gEA+vsB","pt":1743512056098,"mc":[{"id":"1.241629436","rc":[{"atb":[[6.8,149.27]],"batb":[[0,6.8,149.27]],"id":26496185}]}]}
{"op":"mcm","id":2,"clk":"AOSZAgD80gEAkvwB","pt":1743512056404,"mc":[{"id":"1.241629436","rc":[{"atb":[[9,16.49]],"batb":[],"id":40389088},{"atb":[[4.7,238.05]],"trd":[[4.7,1474.19]],"batb":[[0,4.7,238.05]],"ltp":4.7,"tv":20684.19,"id":270592},{"atb":[[1.01,56383.74]],"id":56297029}],"tv":84002.68}]}
{"op":"mcm","id":2,"clk":"AO6ZAgCK0wEAnfwB","pt":1743512056543,"mc":[{"id":"1.241629436","rc":[{"atb":[[16.5,20.53]],"batb":[[2,16.5,20.53]],"id":58186642},{"atl":[[7.4,46.37]],"batl":[[2,7.4,46.37]],"id":26496185}]}]}
{"op":"mcm","id":2,"clk":"APaZAgCO0wEAnfwB","pt":1743512056604,"mc":[{"id":"1.241629436","rc":[{"atb":[[4.7,198.16],[4.5,128.34]],"trd":[[4.7,1553.97]],"batb":[[2,4.5,128.34],[0,4.7,198.16]],"tv":20763.97,"id":270592}],"tv":84082.46}]}
{"op":"mcm","id":2,"clk":"AP+ZAgCg0wEArfwB","pt":1743512056715,"mc":[{"id":"1.241629436","rc":[{"atl":[[4.8,81.05]],"batl":[[0,4.8,81.05]],"id":270592},{"atb":[[1.01,56382.91]],"id":56297029}]}]}
{"op":"mcm","id":2,"clk":"AISaAgCp0wEArvwB","pt":1743512056816,"mc":[{"id":"1.241629436","rc":[{"atl":[[4.9,145.19]],"batl":[[1,4.9,145.19]],"id":270592},{"atb":[[5.1,238.86]],"batb":[[0,5.1,238.86]],"id":56297029}]}]}
{"op":"mcm","id":2,"clk":"AJOaAgCw0wEAtPwB","pt":1743512056915,"mc":[{"id":"1.241629436","rc":[{"atl":[[4.9,150.57]],"batl":[[1,4.9,150.57]],"id":270592},{"atl":[[10.5,67.46]],"batl":[[1,10.5,67.46]],"id":27115873}]}]}
{"op":"mcm","id":2,"clk":"AJ+aAgC90wEAvPwB","pt":1743512056981,"mc":[{"id":"1.241629436","rc":[{"atb":[[11,100.1]],"batb":[[0,11,100.1]],"id":40389088}]}]}
{"op":"mcm","id":2,"clk":"AKuaAgDG0wEAxfwB","pt":1743512057083,"mc":[{"id":"1.241629436","rc":[{"atb":[[4.7,169.89]],"atl":[[5.2,160.07],[4.8,114.93]],"batb":[[0,4.7,169.89]],"batl":[[0,4.8,114.93]],"id":270592},{"atl":[[10.5,73.04]],"batl":[[1,10.5,73.04]],"id":27115873}]}]}
{"op":"mcm","id":2,"clk":"ALWaAgDQ0wEAzPwB","pt":1743512057182,"mc":[{"id":"1.241629436","rc":[{"atb":[[6.8,151.27]],"batb":[[0,6.8,151.27]],"id":26496185}]}]}
{"op":"mcm","id":2,"clk":"ALuaAgDc0wEA1PwB","pt":1743512057284,"mc":[{"id":"1.241629436","rc":[{"atb":[[4.7,171.89]],"atl":[[4.8,120.41]],"batb":[[0,4.7,171.89]],"batl":[[0,4.8,120.41]],"id":270592},{"atl":[[7.8,84.24]],"batl":[],"id":26496185}]}]}
{"op":"mcm","id":2,"clk":"AMSaAgDn0wEA2fwB","pt":1743512057384,"mc":[{"id":"1.241629436","rc":[{"atl":[[10.5,67.46]],"batl":[[1,10.5,67.46]],"id":27115873}]}]}
{"op":"mcm","id":2,"clk":"AM6aAgDy0wEA5fwB","pt":1743512057493,"mc":[{"id":"1.241629436","rc":[{"atl":[[10,0.58]],"trd":[[10,594.74]],"batl":[[2,11.5,28.68],[1,11,59.51],[0,10.5,68.04]],"ltp":10,"tv":7230.38,"id":27115873}],"tv":84085.86}]}
{"op":"mcm","id":2,"clk":"ANaaAgD80wEA7PwB","pt":1743512057597,"mc":[{"id":"1.241629436","rc":[{"atl":[[10,0]],"trd":[[10,595.9]],"batl":[[0,10.5,67.46]],"tv":7231.54,"id":27115873}],"tv":84087.02}]}
{"op":"mcm","id":2,"clk":"AOGaAgCI1AEA9PwB","pt":1743512057699,"mc":[{"id":"1.241629436","rc":[{"atb":[[4.7,192]],"batb":[[0,4.7,192]],"id":270592},{"atl":[[13,10.09]],"batl":[],"id":27115873}]}]}
{"op":"mcm","id":2,"clk":"AO6aAgCV1AEAg/0B","pt":1743512057812,"mc":[{"id":"1.241629436","rc":[{"atl":[[4.8,119.41]],"trd":[[4.8,3308.02]],"batl":[[0,4.8,119.41]],"ltp":4.8,"tv":20765.97,"id":270592},{"atb":[[1.17,7.4]],"id":35856222},{"atb":[[5.1,260.1]],"batb":[[0,5.1,260.1]],"id":56297029},{"atb":[[10,5.08]],"trd":[[10,597.9]],"batb":[[2,9.6,68.92],[1,9.8,62.08],[0,10,5.08]],"tv":7233.54,"id":27115873},{"atb":[[17,42.51]],"atl":[[18,7.59]],"batb":[[1,17,42.51]],"batl":[[0,18,7.59]],"id":58186642},{"atb":[[6.8,143.27]],"batb":[[0,6.8,143.27]],"id":26496185}],"tv":84091.02}]}
{"op":"mcm","id":2,"clk":"APaaAgCe1AEAhv0B","pt":1743512057906,"mc":[{"id":"1.241629436","rc":[{"atb":[[1.17,7.15]],"id":35856222},{"atb":[[9.8,65.47],[10,6.78]],"batb":[[1,9.8,65.47],[0,10,6.78]],"id":27115873},{"atb":[[6.8,159.19]],"batb":[[0,6.8,159.19]],"id":26496185}]}]}
{"op":"mcm","id":2,"clk":"AIObAgCr1AEAk/0B","pt":1743512058019,"mc":[{"id":"1.241629436","rc":[{"atb":[[4.7,203.38]],"trd":[[4.7,1559.97]],"batb":[[0,4.7,203.38]],"ltp":4.7,"tv":20771.97,"id":270592},{"atb":[[9.8,72.24]],"trd":[[9.8,880.33]],"batb":[[0,9.8,72.24]],"tv":9851.11,"id":35856222},{"atb":[[10,22.9]],"atl":[[13,11.76]],"batb":[[0,10,22.9]],"batl":[],"id":27115873},{"atb":[[6.8,157.19]],"atl":[[7,21.36]],"trd":[[6.8,714.86]],"batb":[[0,6.8,157.19]],"batl":[[0,7,21.36]],"ltp":6.8,"tv":13413.28,"id":26496185}],"tv":84107.02}]}
{"op":"mcm","id":2,"clk":"AI2bAgCz1AEAlf0B","pt":1743512058109,"mc":[{"id":"1.241629436","rc":[{"atb":[[9.8,76.52]],"batb":[[1,9.8,76.52]],"id":27115873},{"atb":[[11,109.68]],"batb":[[0,11,109.68]],"id":44049799}]}]}
{"op":"mcm","id":2,"clk":"AJObAgC41AEAn/0B","pt":1743512058214,"mc":[{"id":"1.241629436","rc":[{"atb":[[11,109.94]],"batb":[[0,11,109.94]],"id":40389088},{"atl":[[18,1.97]],"batl":[[0,18,1.97]],"id":58186642},{"atb":[[6.8,159.87]],"atl":[[7,19.36],[7.4,34.39]],"batb":[[0,6.8,159.87]],"batl":[[2,7.4,34.39],[0,7,19.36]],"id":26496185}]}]}
{"op":"mcm","id":2,"clk":"AJybAgDF1AEAqf0B","pt":1743512058320,"mc":[{"id":"1.241629436","rc":[{"atb":[[4.7,203.28]],"trd":[[4.7,1560.17]],"batb":[[0,4.7,203.28]],"tv":20772.17,"id":270592},{"atb":[[18,11.57]],"atl":[[18.5,2.01],[18,0]],"trd":[[18,182.05]],"batb":[[2,17,42.51],[1,17.5,29.24],[0,18,11.57]],"batl":[[2,19.5,41.31],[1,19,13.08],[0,18.5,2.01]],"tv":5902.74,"id":58186642},{"atb":[[6.8,157.87]],"trd":[[6.8,718.86]],"batb":[[0,6.8,157.87]],"tv":13417.28,"id":26496185},{"atl":[[11.5,61.34]],"batl":[[0,11.5,61.34]],"id":44049799}],"tv":84115.16}]}
{"op":"mcm","id":2,"clk":"AKSbAgDM1AEAsP0B","pt":1743512058420,"mc":[{"id":"1.241629436","rc":[{"atb":[[55,8.24]],"batb":[[0,55,8.24]],"id":59626646},{"atb":[[18,10.57],[16,21.58]],"trd":[[18,184.05]],"batb":[[0,18,10.57]],"tv":5904.74,"id":58186642}],"tv":84117.16}]}
{"op":"mcm","id":2,"clk":"AKqbAgDV1AEAtv0B","pt":1743512058472,"mc":[{"id":"1.241629436","rc":[{"atb":[[55,6.51]],"batb":[[0,55,6.51]],"id":59626646},{"atb":[[4.9,92.72]],"batb":[[2,4.9,92.72]],"id":56297029},{"atb":[[18,20.44],[17,45.58]],"batb":[[2,17,45.58],[0,18,20.44]],"id":58186642}]}]}
{"op":"mcm","id":2,"clk":"ALabAgDi1AEAwP0B","pt":1743512058583,"mc":[{"id":"1.241629436","rc":[{"atb":[[4.5,122.58]],"batb":[[2,4.5,122.58]],"id":270592},{"atb":[[18,33.58]],"atl":[[19,16.12],[18.5,0.14]],"batb":[[0,18,33.58]],"batl":[[2,20,13.14],[1,19.5,41.31],[0,19,16.26]],"id":58186642},{"atb":[[11.5,19.33]],"atl":[[11.5,0]],"trd":[[11.5,922.24]],"batb":[[2,10.5,67.91],[1,11,109.68],[0,11.5,19.33]],"batl":[[2,13,38.41],[1,12.5,41.79],[0,12,30.76]],"ltp":11.5,"tv":4976.13,"id":44049799}],"tv":84239.85}]}
{"op":"mcm","id":2,"clk":"AL+bAgDt1AEA0P0B","pt":1743512058693,"mc":[{"id":"1.241629436","rc":[{"atb":[[4.7,210.04]],"batb":[[0,4.7,210.04]],"id":270592},{"atb":[[9.8,53.56]],"batb":[[0,9.8,53.56]],"id":35856222},{"atb":[[10,21.2]],"atl":[[10.5,73.05]],"batb":[[0,10,21.2]],"batl":[[0,10.5,73.05]],"id":27115873},{"atb":[[18.5,5.24]],"atl":[[18.5,0]],"trd":[[18.5,93.67]],"batb":[[2,17.5,29.24],[1,18,33.58],[0,18.5,5.24]],"batl":[[0,19,16.12]],"ltp":18.5,"tv":5905.02,"id":58186642},{"atb":[[11.5,22.11]],"atl":[[13,40.08],[12.5,38.56]],"trd":[[11.5,958.58]],"batb":[[0,11.5,22.11]],"batl":[[2,13,40.08],[1,12.5,38.56]],"tv":5012.47,"id":44049799}],"tv":84276.47}]}
{"op":"mcm","id":2,"clk":"AMybAgD11AEA2f0B","pt":1743512058796,"mc":[{"id":"1.241629436","rc":[{"atb":[[4.7,212.04]],"batb":[[0,4.7,212.04]],"id":270592},{"atb":[[9.8,46.27]],"batb":[[0,9.8,46.27]],"id":35856222},{"atb":[[18.5,0]],"atl":[[19,15.12]],"trd":[[18.5,104.15]],"batb":[[2,17,45.58],[1,17.5,29.24],[0,18,33.58]],"batl":[[0,19,15.12]],"tv":5915.5,"id":58186642},{"atb":[[11,104.38]],"batb":[[1,11,104.38]],"id":44049799}],"tv":84286.95}]}
{"op":"mcm","id":2,"clk":"ANybAgCE1QEA4v0B","pt":1743512058905,"mc":[{"id":"1.241629436","rc":[{"atb":[[3,59.53]],"id":270592},{"atb":[[11.5,12.16]],"batb":[[0,11.5,12.16]],"id":44049799}]}]}
{"op":"mcm","id":2,"clk":"AOqbAgCJ1QEA6P0B","pt":1743512059003,"mc":[{"id":"1.241629436","rc":[{"atl":[[4.8,118.41]],"trd":[[4.8,3310.02]],"batl":[[0,4.8,118.41]],"ltp":4.8,"tv":20774.17,"id":270592},{"atl":[[18.5,6.86]],"batl":[[2,19.5,41.31],[1,19,15.12],[0,18.5,6.86]],"id":58186642},{"atb":[[11.5,20.75]],"batb":[[0,11.5,20.75]],"id":44049799}],"tv":84288.95}]}
{"op":"mcm","id":2,"clk":"APabAgCX1QEA8P0B","pt":1743512059105,"mc":[{"id":"1.241629436","rc":[{"atl":[[4.9,151.18]],"batl":[[1,4.9,151.18]],"id":270592},{"atb":[[5.1,256.1]],"trd":[[5.1,4502.99]],"batb":[[0,5.1,256.1]],"tv":13658.95,"id":56297029},{"atb":[[9.6,73.89]],"batb":[[2,9.6,73.89]],"id":27115873}],"tv":84296.95}]}
{"op":"mcm","id":2,"clk":"AIGcAgCi1QEA9v0B","pt":1743512059204,"mc":[{"id":"1.241629436","rc":[{"atl":[[18.5,12.27]],"batl":[[0,18.5,12.27]],"id":58186642}]}]}
{"op":"mcm","id":2,"clk":"AI6cAgCx1QEAgf4B","pt":1743512059312,"mc":[{"id":"1.241629436","rc":[{"atl":[[1000,25.16]],"id":270592},{"atb":[[18,32.58]],"atl":[[18.5,15.34]],"trd":[[18,186.05]],"batb":[[0,18,32.58]],"batl":[[0,18.5,15.34]],"ltp":18,"tv":5917.5,"id":58186642}],"tv":84298.95}]}
{"op":"mcm","id":2,"clk":"AJ6cAgC81QEAif4B","pt":1743512059410,"mc":[{"id":"1.241629436","rc":[{"atb":[[18,25.58]],"batb":[[0,18,25.58]],"id":58186642}]}]}
{"op":"mcm","id":2,"clk":"AKmcAgDM1QEAlP4B","pt":1743512059520,"mc":[{"id":"1.241629436","rc":[{"atl":[[1000,21.16]],"id":270592},{"atl":[[18.5,17.34]],"batl":[[0,18.5,17.34]],"id":58186642}]}]}
{"op":"mcm","id":2,"clk":"ALOcAgDX1QEAnP4B","pt":1743512059576,"mc":[{"id":"1.241629436","rc":[{"atb":[[4.7,210]],"trd":[[4.7,1564.25]],"batb":[[0,4.7,210]],"ltp":4.7,"tv":20778.25,"id":270592},{"atb":[[5.1,251.95]],"trd":[[5.1,4511.29]],"batb":[[0,5.1,251.95]],"tv":13667.25,"id":56297029},{"atb":[[17,42.51]],"batb":[[2,17,42.51]],"id":58186642},{"atb":[[6.8,155.87]],"trd":[[6.8,722.86]],"batb":[[0,6.8,155.87]],"tv":13421.28,"id":26496185},{"atl":[[12,37.77]],"batl":[[0,12,37.77]],"id":44049799}],"tv":84315.33}]}
{"op":"mcm","id":2,"clk":"ALucAgDi1QEAqP4B","pt":1743512059676,"mc":[{"id":"1.241629436","rc":[{"atb":[[9.6,68.92]],"atl":[[12,30.28]],"batb":[[2,9.6,68.92]],"batl":[],"id":27115873},{"atb":[[6.8,139.16]],"trd":[[6.8,756.29]],"batb":[[0,6.8,139.16]],"tv":13454.71,"id":26496185},{"atb":[[11.5,16.13]],"trd":[[11.5,969.82]],"batb":[[0,11.5,16.13]],"tv":5023.71,"id":44049799}],"tv":84360}]}
{"op":"mcm","id":2,"clk":"AMicAgDs1QEArv4B","pt":1743512059784,"mc":[{"id":"1.241629436","rc":[{"atb":[[9.8,61.91]],"batb":[[0,9.8,61.91]],"id":35856222},{"atb":[[55,8.25]],"batb":[[0,55,8.25]],"id":59626646},{"atb":[[6.8,137.07]],"atl":[[7,28.22]],"trd":[[6.8,760.47]],"batb":[[0,6.8,137.07]],"batl":[[0,7,28.22]],"tv":13458.89,"id":26496185},{"atb":[[11.5,7.33]],"trd":[[11.5,987.42]],"batb":[[0,11.5,7.33]],"tv":5041.31,"id":44049799}],"tv":84381.78}]}
{"op":"mcm","id":2,"clk":"ANWcAgD41QEAvv4B","pt":1743512059890,"mc":[{"id":"1.241629436","rc":[{"atb":[[6.8,156.07]],"batb":[[0,6.8,156.07]],"id":26496185},{"atb":[[11.5,5.56]],"atl":[[12,39.25]],"trd":[[11.5,990.96]],"batb":[[0,11.5,5.56]],"batl":[[0,12,39.25]],"tv":5044.85,"id":44049799}],"tv":84385.32}]}
{"op":"mcm","id":2,"clk":"AOKcAgCC1gEAxP4B","pt":1743512059995,"mc":[{"id":"1.241629436","rc":[{"atl":[[4.9,171.18]],"batl":[[1,4.9,171.18]],"id":270592},{"atl":[[60,14.38]],"batl":[[0,60,14.38]],"id":59626646},{"atl":[[12,29.28]],"batl":[],"id":27115873},{"atl":[[7,28.26]],"batl":[[0,7,28.26]],"id":26496185},{"atb":[[11.5,15.5]],"atl":[[12,48.59]],"trd":[[11.5,994.02]],"batb":[[0,11.5,15.5]],"batl":[[0,12,48.59]],"tv":5047.91,"id":44049799}],"tv":84388.38}]}
{"op":"mcm","id":2,"clk":"AO2cAgCM1gEAz/4B","pt":1743512060100,"mc":[{"id":"1.241629436","rc":[{"atl":[[4.8,117.41]],"trd":[[4.8,3312.02]],"batl":[[0,4.8,117.41]],"ltp":4.8,"tv":20780.25,"id":270592},{"atb":[[6.4,264.74]],"batb":[[2,6.4,264.74]],"id":26496185}],"tv":84390.38}]}
{"op":"mcm","id":2,"clk":"APacAgCQ1gEA0P4B","pt":1743512060196,"mc":[{"id":"1.241629436","rc":[{"atb":[[11.5,13.97],[10.5,77.64]],"trd":[[11.5,997.09]],"batb":[[2,10.5,77.64],[0,11.5,13.97]],"tv":5050.98,"id":44049799}],"tv":84393.45}]}
{"op":"mcm","id":2,"clk":"AP6cAgCf1gEA2P4B","pt":1743512060295,"mc":[{"id":"1.241629436","rc":[{"atl":[[4.8,102.41]],"trd":[[4.8,3342.02]],"batl":[[0,4.8,102.41]],"tv":20810.25,"id":270592}],"tv":84423.45}]}
{"op":"mcm","id":2,"clk":"AJKdAgC11gEA8v4B","pt":1743512060505,"mc":[{"id":"1.241629436","rc":[{"atb":[[9.8,60.91]],"trd":[[9.8,882.33]],"batb":[[0,9.8,60.91]],"tv":9853.11,"id":35856222},{"atb":[[5.1,249.95]],"trd":[[5.1,4515.29]],"batb":[[0,5.1,249.95]],"tv":13671.25,"id":56297029},{"atb":[[6.4,266.74]],"batb":[[2,6.4,266.74]],"id":26496185}],"tv":84429.45}]}
{"op":"mcm","id":2,"clk":"AJ+dAgDE1gEAhf8B","pt":1743512060615,"mc":[{"id":"1.241629436","rc":[{"atb":[[11,85.57]],"batb":[[0,11,85.57]],"id":40389088},{"atl":[[5.2,202.66]],"batl":[[0,5.2,202.66]],"id":56297029},{"atl":[[10.5,136.57]],"batl":[[0,10.5,136.57]],"id":27115873},{"atl":[[19.5,7.1]],"batl":[[2,19.5,7.1]],"id":58186642},{"atb":[[6.8,173.93]],"batb":[[0,6.8,173.93]],"id":26496185},{"atl":[[12,104.17]],"batl":[[0,12,104.17]],"id":44049799}]}]}
{"op":"mcm","id":2,"clk":"AKudAgDN1gEAkP8B","pt":1743512060713,"mc":[{"id":"1.241629436","rc":[{"atb":[[1.17,2.13],[11,84.93]],"batb":[[0,11,84.93]],"id":40389088},{"atb":[[4.7,211],[4.6,211.75]],"batb":[[1,4.6,211.75],[0,4.7,211]],"id":270592},{"atb":[[1.17,7.31],[9.8,60.66]],"batb":[[0,9.8,60.66]],"id":35856222},{"atb":[[5.1,251.02]],"batb":[[0,5.1,251.02]],"id":56297029},{"atb":[[9.8,75.12]],"atl":[[10.5,136.28]],"batb":[[1,9.8,75.12]],"batl":[[0,10.5,136.28]],"id":27115873},{"atb":[[17,41],[17.5,29.9]],"batb":[[2,17,41],[1,17.5,29.9]],"id":58186642},{"atb":[[6.8,171.75]],"batb":[[0,6.8,171.75]],"id":26496185}]}]}
{"op":"mcm","id":2,"clk":"ALmdAgDY1gEAoP8B","pt":1743512060819,"mc":[{"id":"1.241629436","rc":[{"atl":[[4.8,52.82]],"batl":[[0,4.8,52.82]],"id":270592},{"atb":[[5.1,261.38]],"atl":[[5.2,188.5]],"batb":[[0,5.1,261.38]],"batl":[[0,5.2,188.5]],"id":56297029},{"atb":[[10,2.65]],"batb":[[0,10,2.65]],"id":27115873},{"atb":[[6.4,268.74]],"batb":[[2,6.4,268.74]],"id":26496185},{"atb":[[11.5,0]],"atl":[[12,97.16],[11.5,19.37]],"trd":[[11.5,1025.03]],"batb":[[2,10,80.5],[1,10.5,77.64],[0,11,104.38]],"batl":[[2,12.5,38.56],[1,12,97.16],[0,11.5,19.37]],"tv":5078.92,"id":44049799}],"tv":84457.39}]}
{"op":"mcm","id":2,"clk":"AMWdAgDl1gEAp/8B","pt":1743512060883,"mc":[{"id":"1.241629436","rc":[{"atb":[[1.17,2]],"id":40389088},{"atb":[[1.17,7.15]],"id":35856222}]}]}
{"op":"mcm","id":2,"clk":"ANSdAgD41gEAtf8B","pt":1743512061031,"mc":[{"id":"1.241629436","rc":[{"atb":[[10.5,51.14]],"batb":[[1,10.5,51.14]],"id":40389088},{"atb":[[9.6,61.98]],"batb":[[1,9.6,61.98]],"id":35856222},{"atb":[[4.9,103.62]],"batb":[[2,4.9,103.62]],"id":56297029},{"atb":[[10,3.65]],"batb":[[0,10,3.65]],"id":27115873},{"atb":[[18,32.58],[17,44.07]],"batb":[[2,17,44.07],[0,18,32.58]],"id":58186642},{"atb":[[10.5,78.64]],"atl":[[13,38.41],[12.5,41.71],[12,95.68],[11.5,28.52]],"batb":[[1,10.5,78.64]],"batl":[[2,12.5,41.71],[1,12,95.68],[0,11.5,28.52]],"id":44049799}]}]}
{"op":"mcm","id":2,"clk":"AOedAgCK1wEAy/8B","pt":1743512061187,"mc":[{"id":"1.241629436","rc":[{"atb":[[6.8,169.78]],"atl":[[8,51.88]],"trd":[[6.8,764.41]],"batb":[[0,6.8,169.78]],"batl":[],"tv":13462.83,"id":26496185},{"atb":[[10.5,68.91]],"batb":[[1,10.5,68.91]],"id":44049799}],"tv":84461.33}]}
{"op":"mcm","id":2,"clk":"APGdAgCZ1wEA1f8B","pt":1743512061293,"mc":[{"id":"1.241629436","rc":[{"atl":[[5,182.36],[4.8,97.41]],"trd":[[4.8,3352.84]],"batl":[[2,5,182.36],[0,4.8,97.41]],"tv":20821.07,"id":270592}],"tv":84472.15}]}
{"op":"mcm","id":2,"clk":"AIGeAgC01wEA5P8B","pt":1743512061508,"mc":[{"id":"1.241629436","rc":[{"atl":[[4.8,91.39]],"batl":[[0,4.8,91.39]],"id":270592},{"atl":[[18.5,14.27]],"batl":[[0,18.5,14.27]],"id":58186642}]}]}
{"op":"mcm","id":2,"clk":"AI2eAgDN1wEA9f8B","pt":1743512061702,"mc":[{"id":"1.241629436","rc":[{"atl":[[4.9,171.79]],"batl":[[1,4.9,171.79]],"id":270592}]}]}
{"op":"mcm","id":2,"clk":"AJaeAgDb1wEA/f8B","pt":1743512061808,"mc":[{"id":"1.241629436","rc":[{"atb":[[4.7,193.14]],"atl":[[5,176.61]],"trd":[[4.7,1599.97]],"batb":[[0,4.7,193.14]],"batl":[[2,5,176.61]],"ltp":4.7,"tv":20856.79,"id":270592},{"atb":[[6.8,167.28]],"trd":[[6.8,769.41]],"batb":[[0,6.8,167.28]],"tv":13467.83,"id":26496185}],"tv":84512.87}]}
{"op":"mcm","id":2,"clk":"AJ+eAgDi1wEAi4AC","pt":1743512061907,"mc":[{"id":"1.241629436","rc":[{"atl":[[4.8,141.47]],"batl":[[0,4.8,141.47]],"id":270592}]}]}
{"op":"mcm","id":2,"clk":"AKieAgDs1wEAlYAC","pt":1743512062012,"mc":[{"id":"1.241629436","rc":[{"atb":[[4.1,74.78]],"batb":[],"id":270592}]}]}
{"op":"mcm","id":2,"clk":"ALyeAgCQ2AEAs4AC","pt":1743512062268,"mc":[{"id":"1.241629436","rc":[{"atb":[[4.5,132.58]],"batb":[[2,4.5,132.58]],"id":270592}]}]}
{"op":"mcm","id":2,"clk":"AMmeAgCj2AEAyIAC","pt":1743512062487,"mc":[{"id":"1.241629436","rc":[{"atl":[[60,14.36]],"batl":[[0,60,14.36]],"id":59626646},{"atl":[[7,28.22]],"batl":[[0,7,28.22]],"id":26496185}]}]}
{"op":"mcm","id":2,"clk":"ANKeAgCw2AEA04AC","pt":1743512062584,"mc":[{"id":"1.241629436","rc":[{"atl":[[11.5,28.59]],"batl":[[0,11.5,28.59]],"id":44049799}]}]}
{"op":"mcm","id":2,"clk":"ANieAgC32AEA2IAC","pt":1743512062680,"mc":[{"id":"1.241629436","rc":[{"atl":[[4.8,132.48]],"trd":[[4.8,3370.83]],"batl":[[0,4.8,132.48]],"ltp":4.8,"tv":20874.78,"id":270592},{"atl":[[5.2,187.1]],"trd":[[5.2,3723.17]],"batl":[[0,5.2,187.1]],"ltp":5.2,"tv":13674.05,"id":56297029},{"atl":[[11.5,29.59]],"batl":[[0,11.5,29.59]],"id":44049799}],"tv":84533.66}]}
{"op":"mcm","id":2,"clk":"AOeeAgDE2AEA74AC","pt":1743512062896,"mc":[{"id":"1.241629436","rc":[{"atl":[[4.9,191.79]],"batl":[[1,4.9,191.79]],"id":270592},{"atb":[[18,12.58]],"trd":[[18,226.05]],"batb":[[0,18,12.58]],"tv":5957.5,"id":58186642}],"tv":84573.66}]}
{"op":"mcm","id":2,"clk":"APGeAgDN2AEA+YAC","pt":1743512063001,"mc":[{"id":"1.241629436","rc":[{"atl":[[11.5,23.95]],"trd":[[11.5,1212.82]],"batl":[[0,11.5,23.95]],"ltp":11.5,"tv":6446.6,"id":40389088},{"atb":[[4.7,158.05]],"atl":[[4.8,84]],"trd":[[4.7,1670.15],[4.8,3467.79]],"batb":[[0,4.7,158.05]],"batl":[[0,4.8,84]],"ltp":4.7,"tv":21041.92,"id":270592},{"atl":[[60,14.2]],"trd":[[60,383.39]],"batl":[[0,60,14.2]],"ltp":60,"tv":1988.33,"id":59626646},{"atb":[[5.1,260.12]],"batb":[[0,5.1,260.12]],"id":56297029},{"atb":[[17,41]],"atl":[[19.5,9.35],[18.5,17.35]],"batb":[[2,17,41]],"batl":[[2,19.5,9.35],[0,18.5,17.35]],"id":58186642},{"atb":[[11,95.3]],"trd":[[11,1583.56]],"batb":[[0,11,95.3]],"ltp":11,"tv":5097.08,"id":44049799}],"tv":84759.96}]}
{"op":"mcm","id":2,"clk":"AICfAgDT2AEA/IAC","pt":1743512063106,"mc":[{"id":"1.241629436","rc":[{"atb":[[11,83.93]],"trd":[[11,241.72]],"batb":[[0,11,83.93]],"ltp":11,"tv":6448.6,"id":40389088},{"atb":[[4.7,164.04]],"atl":[[4.8,33.92]],"batb":[[0,4.7,164.04]],"batl":[[0,4.8,33.92]],"id":270592},{"atb":[[9.8,66.34]],"batb":[[0,9.8,66.34]],"id":35856222},{"atb":[[50,22.05]],"batb":[[1,50,22.05]],"id":59626646},{"atb":[[10,5.32]],"atl":[[10.5,130.69]],"batb":[[0,10,5.32]],"batl":[[0,10.5,130.69]],"id":27115873},{"atb":[[18,0],[17,44.09]],"atl":[[18,5.67]],"trd":[[18,251.21]],"batb":[[2,16.5,20.53],[1,17,44.09],[0,17.5,29.9]],"batl":[[2,19,15.12],[1,18.5,17.35],[0,18,5.67]],"tv":5982.66,"id":58186642},{"atl":[[12,100.65]],"batl":[[1,12,100.65]],"id":44049799}],"tv":84787.12}]}
{"op":"mcm","id":2,"clk":"AIyfAgDb2AEAg4EC","pt":1743512063211,"mc":[{"id":"1.241629436","rc":[{"atl":[[4.8,56.65]],"trd":[[4.8,3469.79]],"batl":[[0,4.8,56.65]],"ltp":4.8,"tv":21043.92,"id":270592},{"atl":[[26,3]],"id":35856222},{"atb":[[10,6.41]],"batb":[[0,10,6.41]],"id":27115873},{"atb":[[17,41]],"batb":[[1,17,41]],"id":58186642}],"tv":84789.12}]}
{"op":"mcm","id":2,"clk":"AJafAgDi2AEAhoEC","pt":1743512063303,"mc":[{"id":"1.241629436","rc":[{"atb":[[10,8.55]],"batb":[[0,10,8.55]],"id":27115873},{"atb":[[17.5,32.07]],"atl":[[18.5,20.34]],"batb":[[0,17.5,32.07]],"batl":[[1,18.5,20.34]],"id":58186642},{"atl":[[12.5,45.21]],"batl":[[2,12.5,45.21]],"id":44049799}]}]}
{"op":"mcm","id":2,"clk":"AKKfAgDr2AEAk4EC","pt":1743512063410,"mc":[{"id":"1.241629436","rc":[{"atb":[[9.8,65.34]],"trd":[[9.8,884.33]],"batb":[[0,9.8,65.34]],"tv":9855.11,"id":35856222}],"tv":84791.12}]}
{"op":"mcm","id":2,"clk":"ALufAgD92AEAnYEC","pt":1743512063625,"mc":[{"id":"1.241629436","rc":[{"atb":[[17.5,29.9]],"batb":[[0,17.5,29.9]],"id":58186642}]}]}
{"op":"mcm","id":2,"clk":"AMefAgCC2QEAnoEC","pt":1743512063718,"mc":[{"id":"1.241629436","rc":[{"atl":[[1000,0.85]],"id":40389088},{"atl":[[1000,1.17]],"id":35856222},{"atb":[[5,1207.56],[5.1,256.52]],"atl":[[5.2,194.2]],"trd":[[5.1,4522.49]],"batb":[[1,5,1207.56],[0,5.1,256.52]],"batl":[[0,5.2,194.2]],"ltp":5.1,"tv":13681.25,"id":56297029},{"atl":[[18.5,26.41]],"batl":[[1,18.5,26.41]],"id":58186642}],"tv":84798.32}]}
{"op":"mcm","id":2,"clk":"ANafAgCN2QEAqoEC","pt":1743512063820,"mc":[{"id":"1.241629436","rc":[{"atl":[[1000,0.25]],"id":40389088},{"atl":[[1000,0.41]],"id":35856222},{"atb":[[16,23.97]],"batb":[],"id":58186642}]}]}
{"op":"mcm","id":2,"clk":"AOGfAgCV2QEAq4EC","pt":1743512063921,"mc":[{"id":"1.241629436","rc":[{"atl":[[11.5,24.55]],"batl":[[0,11.5,24.55]],"id":40389088},{"atl":[[10,96.98]],"batl":[[0,10,96.98]],"id":35856222},{"atb":[[17.5,21.62]],"batb":[[0,17.5,21.62]],"id":58186642}]}]}
{"op":"mcm","id":2,"clk":"APafAgCj2QEAu4EC","pt":1743512064087,"mc":[{"id":"1.241629436","rc":[{"atb":[[16,21.58]],"batb":[],"id":58186642}]}]}
{"op":"mcm","id":2,"clk":"AISgAgCr2QEAyIEC","pt":1743512064189,"mc":[{"id":"1.241629436","rc":[{"atb":[[4.7,161.04]],"trd":[[4.7,1676.15]],"batb":[[0,4.7,161.04]],"ltp":4.7,"tv":21049.92,"id":270592},{"atb":[[17.5,23.81]],"batb":[[0,17.5,23.81]],"id":58186642}],"tv":84804.32}]}
{"op":"mcm","id":2,"clk":"AJygAgDA2QEA4YEC","pt":1743512064397,"mc":[{"id":"1.241629436","rc":[{"atb":[[4.2,141.72]],"atl":[[4.8,55.65]],"trd":[[4.8,3471.79]],"batb":[],"batl":[[0,4.8,55.65]],"ltp":4.8,"tv":21051.92,"id":270592}],"tv":84806.32}]}
{"op":"mcm","id":2,"clk":"AKSgAgDH2QEA6YEC","pt":1743512064490,"mc":[{"id":"1.241629436","rc":[{"atb":[[11,81.93]],"trd":[[11,245.72]],"batb":[[0,11,81.93]],"tv":6452.6,"id":40389088},{"atb":[[1.5,38.8]],"id":270592},{"atb":[[10,23.55]],"trd":[[10,603.9]],"batb":[[0,10,23.55]],"tv":7239.54,"id":27115873},{"atb":[[6.8,164.28]],"trd":[[6.8,775.41]],"batb":[[0,6.8,164.28]],"tv":13473.83,"id":26496185}],"tv":84822.32}]}
{"op":"mcm","id":2,"clk":"AK+gAgDZ2QEA9oEC","pt":1743512064604,"mc":[{"id":"1.241629436","rc":[{"atb":[[10,36.55]],"batb":[[0,10,36.55]],"id":27115873}]}]}
{"op":"mcm","id":2,"clk":"ALagAgDf2QEA+4EC","pt":1743512064696,"mc":[{"id":"1.241629436","rc":[{"atb":[[11,97.36]],"batb":[[0,11,97.36]],"id":40389088},{"atl":[[1000,25.16]],"id":270592}]}]}
{"op":"mcm","id":2,"clk":"AL+gAgDv2QEAgYIC","pt":1743512064812,"mc":[{"id":"1.241629436","rc":[{"atb":[[11,101.28]],"batb":[[0,11,101.28]],"id":40389088}]}]}
{"op":"mcm","id":2,"clk":"AMmgAgD62QEAjYIC","pt":1743512064918,"mc":[{"id":"1.241629436","rc":[{"atl":[[1000,21.16]],"id":270592}]}]}
{"op":"mcm","id":2,"clk":"ANmgAgCG2gEAl4IC","pt":1743512065023,"mc":[{"id":"1.241629436","rc":[{"atb":[[55,6.25]],"trd":[[55,315.77]],"batb":[[0,55,6.25]],"ltp":55,"tv":1992.33,"id":59626646}],"tv":84826.32}]}
{"op":"mcm","id":2,"clk":"AOCgAgCI2gEAmoIC","pt":1743512065111,"mc":[{"id":"1.241629436","rc":[{"atl":[[60,11.2]],"trd":[[60,389.39]],"batl":[[0,60,11.2]],"ltp":60,"tv":1998.33,"id":59626646},{"atl":[[7.6,87.19]],"batl":[],"id":26496185}],"tv":84832.32}]}
{"op":"mcm","id":2,"clk":"AOqgAgCS2gEAoIIC","pt":1743512065217,"mc":[{"id":"1.241629436","rc":[{"atb":[[55,9.52]],"batb":[[0,55,9.52]],"id":59626646}]}]}
{"op":"mcm","id":2,"clk":"APqgAgCf2gEAqYIC","pt":1743512065321,"mc":[{"id":"1.241629436","rc":[{"atb":[[17.5,19.81]],"trd":[[17.5,241.25]],"batb":[[0,17.5,19.81]],"ltp":17.5,"tv":5990.66,"id":58186642}],"tv":84840.32}]}
{"op":"mcm","id":2,"clk":"AIihAgCo2gEAr4IC","pt":1743512065423,"mc":[{"id":"1.241629436","rc":[{"atl":[[60,10]],"batl":[[0,60,10]],"id":59626646},{"atb":[[17.5,17.55]],"atl":[[21,13.85],[18.5,28.68]],"batb":[[0,17.5,17.55]],"batl":[[1,18.5,28.68]],"id":58186642}]}]}
{"op":"mcm","id":2,"clk":"AJKhAgC02gEAtoIC","pt":1743512065480,"mc":[{"id":"1.241629436","rc":[{"atl":[[1000,23.16]],"id":270592}]}]}
{"op":"mcm","id":2,"clk":"AKahAgDM2gEAwIIC","pt":1743512065682,"mc":[{"id":"1.241629436","rc":[{"atl":[[1000,21.16]],"id":270592}]}]}
{"op":"mcm","id":2,"clk":"ALGhAgDX2gEAxoIC","pt":1743512065787,"mc":[{"id":"1.241629436","rc":[{"atl":[[5.2,154.21]],"trd":[[5.2,3803.17]],"batl":[[0,5.2,154.21]],"ltp":5.2,"tv":13761.25,"id":56297029},{"atl":[[18.5,15.82],[18,0]],"trd":[[18,262.55],[18.5,129.87]],"batl":[[2,19.5,9.35],[1,19,15.12],[0,18.5,15.82]],"ltp":18.5,"tv":6027.72,"id":58186642}],"tv":84957.38}]}
{"op":"mcm","id":2,"clk":"ALuhAgDh2gEA0oIC","pt":1743512065898,"mc":[{"id":"1.241629436","rc":[{"atl":[[4.8,105.73]],"batl":[[0,4.8,105.73]],"id":270592},{"atb":[[6,6.73]],"id":27115873},{"atb":[[17.5,30.9]],"atl":[[18.5,13.55]],"batb":[[0,17.5,30.9]],"batl":[[0,18.5,13.55]],"id":58186642}]}]}
{"op":"mcm","id":2,"clk":"AMehAgDr2gEA2YIC","pt":1743512066001,"mc":[{"id":"1.241629436","rc":[{"atl":[[11.5,16.54]],"trd":[[11.5,1228.83]],"batl":[[0,11.5,16.54]],"ltp":11.5,"tv":6468.61,"id":40389088},{"atl":[[5.2,240.45]],"batl":[[0,5.2,240.45]],"id":56297029},{"atb":[[18,6.03]],"atl":[[18.5,19.42]],"batb":[[2,17,41],[1,17.5,30.9],[0,18,6.03]],"batl":[[0,18.5,19.42]],"id":58186642},{"atl":[[11.5,21.59]],"trd":[[11.5,1041.03]],"batl":[[0,11.5,21.59]],"ltp":11.5,"tv":5113.08,"id":44049799}],"tv":84989.39}]}
{"op":"mcm","id":2,"clk":"AM+hAgD32gEA34IC","pt":1743512066107,"mc":[{"id":"1.241629436","rc":[{"atb":[[11,106.25]],"atl":[[11.5,7.4]],"batb":[[0,11,106.25]],"batl":[[0,11.5,7.4]],"id":40389088},{"atb":[[9.8,59.66]],"batb":[[0,9.8,59.66]],"id":35856222},{"atl":[[18.5,16.43]],"batl":[[0,18.5,16.43]],"id":58186642},{"atl":[[11.5,24.7]],"batl":[[0,11.5,24.7]],"id":44049799}]}]}
{"op":"mcm","id":2,"clk":"ANihAgCB2wEA5oIC","pt":1743512066210,"mc":[{"id":"1.241629436","rc":[{"atb":[[11,122.61]],"atl":[[11.5,22.12]],"batb":[[0,11,122.61]],"batl":[[0,11.5,22.12]],"id":40389088},{"atl":[[5.4,50.67],[5.2,83.04],[5.3,184.95],[5.5,121.51],[5.1,110.73]],"batl":[],"id":270592},{"atl":[[5.4,113.97],[5.2,219.07],[5.3,77.73]],"batl":[[2,5.4,113.97],[1,5.3,77.73],[0,5.2,219.07]],"id":56297029},{"atb":[[9.4,72.74],[9.8,70.28],[9.6,64.41]],"batb":[[2,9.6,64.41],[1,9.8,70.28]],"id":27115873},{"atb":[[15.5,32.87],[15,12.63],[17,35.45],[16,18.87],[16.5,19.88]],"batb":[[2,17,35.45]],"id":58186642},{"atb":[[6,143.43],[6.2,158.8],[6.4,248.18]],"batb":[[2,6.4,248.18]],"id":26496185},{"atl":[[12.5,40.45],[12,95.21]],"batl":[[2,12.5,40.45],[1,12,95.21]],"id":44049799}]}]}
{"op":"mcm","id":2,"clk":"APqhAgCc2wEAgoMC","pt":1743512066525,"mc":[{"id":"1.241629436","rc":[{"atb":[[11,124.91]],"batb":[[0,11,124.91]],"id":40389088},{"atb":[[4.7,0],[4.2,91.72]],"atl":[[4.7,32.6],[4.9,208.36],[5,187.69],[4.8,122.68]],"trd":[[4.7,1998.21]],"batb":[[2,4.4,197.68],[1,4.5,132.58],[0,4.6,211.75]],"batl":[[2,4.9,208.36],[1,4.8,122.68],[0,4.7,32.6]],"ltp":4.7,"tv":21373.98,"id":270592},{"atl":[[5.4,125.19],[5.2,236.23],[5.3,94.51]],"batl":[[2,5.4,125.19],[1,5.3,94.51],[0,5.2,236.23]],"id":56297029},{"atb":[[9.8,76.91],[10,43.33],[9.6,68.84]],"batb":[[2,9.6,68.84],[1,9.8,76.91],[0,10,43.33]],"id":27115873},{"atb":[[18.5,15.32],[18,12.85],[17,38.99],[17.5,34.52],[16.5,22.25]],"atl":[[18.5,0]],"trd":[[18.5,162.73]],"batb":[[2,17.5,34.52],[1,18,12.85],[0,18.5,15.32]],"batl":[[2,20,13.14],[1,19.5,9.35],[0,19,15.12]],"tv":6060.58,"id":58186642},{"atb":[[6.6,263.69],[7,5.71],[6.8,188.02],[6.4,263.71]],"atl":[[7,0]],"trd":[[7,510]],"batb":[[2,6.6,263.69],[1,6.8,188.02],[0,7,5.71]],"batl":[[2,7.6,87.19],[1,7.4,34.39],[0,7.2,139.67]],"ltp":7,"tv":13530.27,"id":26496185},{"atl":[[12.5,46.27],[12,103.91]],"batl":[[2,12.5,46.27],[1,12,103.91]],"id":44049799}],"tv":85400.75}]}
{"op":"mcm","id":2,"clk":"AIGiAgCn2wEAhoMC","pt":1743512066622,"mc":[{"id":"1.241629436","rc":[{"atl":[[4.7,31.68],[4.9,220.19],[4.8,128.7]],"trd":[[4.7,2021.88]],"batl":[[2,4.9,220.19],[1,4.8,128.7],[0,4.7,31.68]],"tv":21397.65,"id":270592},{"atb":[[9.8,65.34]],"batb":[[0,9.8,65.34]],"id":35856222},{"atb":[[18,18.07],[18.5,10.69],[17,42.11],[17.5,37.64]],"atl":[[19,12.89]],"trd":[[18.5,171.99]],"batb":[[2,17.5,37.64],[1,18,18.07],[0,18.5,10.69]],"batl":[[0,19,12.89]],"tv":6069.84,"id":58186642},{"atb":[[7,0],[6.8,196.03]],"atl":[[7,2.39]],"trd":[[7,521.42]],"batb":[[2,6.4,263.71],[1,6.6,263.69],[0,6.8,196.03]],"batl":[[2,7.4,34.39],[1,7.2,139.67],[0,7,2.39]],"tv":13541.69,"id":26496185}],"tv":85445.1}]}
{"op":"mcm","id":2,"clk":"AIuiAgCz2wEAk4MC","pt":1743512066726,"mc":[{"id":"1.241629436","rc":[{"atb":[[4.4,196.52],[4.1,92.26],[4.6,218.31],[4.3,131.81],[4.5,144.64]],"atl":[[4.7,70.47],[5.3,102.97],[5.1,109.83]],"trd":[[4.7,2043.24]],"batb":[[2,4.4,196.52],[1,4.5,144.64],[0,4.6,218.31]],"batl":[[0,4.7,70.47]],"tv":21419.01,"id":270592},{"atb":[[9.8,59.66],[9.2,79.65]],"batb":[[0,9.8,59.66]],"id":35856222},{"atb":[[55,13.51]],"batb":[[0,55,13.51]],"id":59626646},{"atl":[[5.2,233.89]],"batl":[[0,5.2,233.89]],"id":56297029},{"atb":[[18,28.13],[18.5,10.68]],"atl":[[21,10.93],[20,10.13],[19,2.63]],"trd":[[18.5,183.73]],"batb":[[1,18,28.13],[0,18.5,10.68]],"batl":[[2,20,10.13],[0,19,2.63]],"tv":6081.58,"id":58186642},{"atb":[[7,32.23],[6.4,260.72]],"atl":[[7,0],[8.2,89.5]],"trd":[[7,526.21]],"batb":[[2,6.6,263.69],[1,6.8,196.03],[0,7,32.23]],"batl":[[2,7.6,87.19],[1,7.4,34.39],[0,7.2,139.67]],"tv":13546.48,"id":26496185}],"tv":85482.99}]}
{"op":"mcm","id":2,"clk":"AJKiAgC92wEAlYMC","pt":1743512066827,"mc":[{"id":"1.241629436","rc":[{"atl":[[5.1,119.83]],"batl":[],"id":270592},{"atb":[[19,9.13],[18.5,18.91],[16,9.93]],"atl":[[19,0]],"trd":[[19,204.3]],"batb":[[2,18,28.13],[1,18.5,18.91],[0,19,9.13]],"batl":[[2,21,10.93],[1,20,10.13],[0,19.5,9.35]],"ltp":19,"tv":6086.03,"id":58186642},{"atb":[[7,40.2],[6.4,263.71]],"atl":[[7.2,131.68]],"batb":[[0,7,40.2]],"batl":[[0,7.2,131.68]],"id":26496185}],"tv":85487.44}]}
{"op":"mcm","id":2,"clk":"AJ2iAgDJ2wEAoIMC","pt":1743512066942,"mc":[{"id":"1.241629436","rc":[{"atb":[[2.94,1],[4.3,133]],"atl":[[5,188.61],[4.8,148.7]],"batb":[],"batl":[[1,4.8,148.7]],"id":270592},{"atb":[[9.2,78.29]],"batb":[],"id":35856222},{"atl":[[5.2,236.23]],"batl":[[0,5.2,236.23]],"id":56297029},{"atb":[[10,42.68]],"batb":[[0,10,42.68]],"id":27115873},{"atb":[[19,7.85],[18,25.91],[18.5,25.91]],"trd":[[19,206.86]],"batb":[[2,18,25.91],[1,18.5,25.91],[0,19,7.85]],"tv":6088.59,"id":58186642},{"atb":[[11,94.3]],"trd":[[11,1585.56]],"batb":[[0,11,94.3]],"ltp":11,"tv":5115.08,"id":44049799}],"tv":85492}]}
{"op":"mcm","id":2,"clk":"AKiiAgDR2wEAq4MC","pt":1743512066991,"mc":[{"id":"1.241629436","rc":[{"atl":[[11.5,21.52]],"batl":[[0,11.5,21.52]],"id":40389088},{"atb":[[4.2,97.33],[4.4,208.62],[4.1,97.87],[4.5,132.58]],"atl":[[4.9,218.88],[4.8,151.6]],"batb":[[2,4.4,208.62],[1,4.5,132.58]],"batl":[[2,4.9,218.88],[1,4.8,151.6]],"id":270592},{"atb":[[1.17,7.96]],"atl":[[1000,0.58]],"id":35856222},{"atb":[[5,1206.51]],"atl":[[5.2,231]],"batb":[[1,5,1206.51]],"batl":[[0,5.2,231]],"id":56297029},{"atb":[[18,28.1],[18.5,33.51],[17.5,35.9]],"atl":[[23,10.01],[22,6.51]],"batb":[[2,18,28.1],[1,18.5,33.51]],"batl":[],"id":58186642},{"atb":[[6.4,260.72]],"atl":[[7.2,130.66]],"batb":[],"batl":[[0,7.2,130.66]],"id":26496185}]}]}
{"op":"mcm","id":2,"clk":"ALSiAgDa2wEAtoMC","pt":1743512067099,"mc":[{"id":"1.241629436","rc":[{"atb":[[1.17,2.78],[10.5,51.01]],"atl":[[1000,0.53]],"batb":[[1,10.5,51.01]],"id":40389088},{"atb":[[4.1,80.39]],"atl":[[5,198.09]],"batb":[],"batl":[],"id":270592},{"atb":[[1.17,7.15],[9.6,61.82]],"atl":[[10,96.22]],"batb":[[1,9.6,61.82]],"batl":[[0,10,96.22]],"id":35856222},{"atl":[[1000,1.38]],"id":27115873},{"atb":[[6.8,193.43]],"atl":[[1000,5.38]],"batb":[[1,6.8,193.43]],"id":26496185}]}]}
{"op":"mcm","id":2,"clk":"ALuiAgDg2wEAu4MC","pt":1743512067195,"mc":[{"id":"1.241629436","rc":[{"atb":[[1.17,2]],"atl":[[1000,0.25]],"id":40389088},{"atb":[[4.5,144.67]],"atl":[[4.7,69.47]],"trd":[[4.7,2045.24]],"batb":[[1,4.5,144.67]],"batl":[[0,4.7,69.47]],"tv":21421.01,"id":270592},{"atb":[[9.8,60.47]],"atl":[[1000,0.41]],"batb":[[0,9.8,60.47]],"id":35856222},{"atb":[[6.2,40]],"id":59626646},{"atl":[[1000,1.16]],"id":27115873}],"tv":85494}]}
{"op":"mcm","id":2,"clk":"AMeiAgDr2wEAyIMC","pt":1743512067306,"mc":[{"id":"1.241629436","rc":[{"atb":[[11,125.69]],"atl":[[12,85.3],[11.5,21.64]],"batb":[[0,11,125.69]],"batl":[[1,12,85.3],[0,11.5,21.64]],"id":40389088},{"atl":[[4.8,152.21]],"batl":[[1,4.8,152.21]],"id":270592},{"atl":[[10.5,75.93]],"batl":[[1,10.5,75.93]],"id":35856222},{"atl":[[10.5,130.91]],"batl":[[0,10.5,130.91]],"id":27115873},{"atb":[[7,68.49]],"atl":[[1000,3.9]],"batb":[[0,7,68.49]],"id":26496185}]}]}
{"op":"mcm","id":2,"clk":"ANSiAgDx2wEAyIMC","pt":1743512067401,"mc":[{"id":"1.241629436","rc":[{"atb":[[11,109.33]],"batb":[[0,11,109.33]],"id":40389088},{"atl":[[7.4,35.24],[7.2,131.29]],"batl":[[1,7.4,35.24],[0,7.2,131.29]],"id":26496185}]}]}
{"op":"mcm","id":2,"clk":"ANyiAgD52wEA1YMC","pt":1743512067507,"mc":[{"id":"1.241629436","rc":[{"atb":[[4.4,214.22]],"batb":[[2,4.4,214.22]],"id":270592},{"atl":[[60,10.05]],"batl":[[0,60,10.05]],"id":59626646}]}]}
{"op":"mcm","id":2,"clk":"AP+iAgCl3AEA9IMC","pt":1743512067921,"mc":[{"id":"1.241629436","rc":[{"atl":[[4.8,173.66]],"batl":[[1,4.8,173.66]],"id":270592},{"atb":[[17.5,46.2]],"batb":[],"id":58186642}]}]}
{"op":"mcm","id":2,"clk":"AIajAgCv3AEA/YMC","pt":1743512068027,"mc":[{"id":"1.241629436","rc":[{"atb":[[7,78.49]],"batb":[[0,7,78.49]],"id":26496185}]}]}
{"op":"mcm","id":2,"clk":"AKijAgDM3AEAkoQC","pt":1743512068330,"mc":[{"id":"1.241629436","rc":[{"atl":[[4.7,71.47]],"batl":[[0,4.7,71.47]],"id":270592},{"atb":[[7,68.49]],"trd":[[7,546.21]],"batb":[[0,7,68.49]],"tv":13566.48,"id":26496185}],"tv":85514}]}
{"op":"mcm","id":2,"clk":"AMKjAgDc3AEApoQC","pt":1743512068487,"mc":[{"id":"1.241629436","rc":[{"atb":[[4.4,224.22]],"batb":[[2,4.4,224.22]],"id":270592},{"atb":[[19,15.32]],"batb":[[0,19,15.32]],"id":58186642},{"atb":[[7,80.41]],"batb":[[0,7,80.41]],"id":26496185}]}]}
{"op":"mcm","id":2,"clk":"ANOjAgDj3AEAsoQC","pt":1743512068595,"mc":[{"id":"1.241629436","rc":[{"atl":[[4.7,70.47]],"trd":[[4.7,2047.24]],"batl":[[0,4.7,70.47]],"tv":21423.01,"id":270592},{"atb":[[18.5,35.7],[16.5,19.98]],"atl":[[19.5,4.56]],"batb":[[1,18.5,35.7]],"batl":[[0,19.5,4.56]],"id":58186642}],"tv":85516}]}
{"op":"mcm","id":2,"clk":"AN2jAgDn3AEAuYQC","pt":1743512068694,"mc":[{"id":"1.241629436","rc":[{"atb":[[11,111.28]],"batb":[[0,11,111.28]],"id":40389088},{"atb":[[1.17,1.27],[4.6,217.57]],"atl":[[4.7,71.76]],"batb":[[0,4.6,217.57]],"batl":[[0,4.7,71.76]],"id":270592},{"atb":[[4.9,89.62]],"batb":[[2,4.9,89.62]],"id":56297029},{"atl":[[19.5,0.07]],"batl":[[2,22,6.51],[1,21,10.93],[0,20,10.2]],"id":58186642},{"atb":[[11,95.35]],"atl":[[12.5,42.77]],"batb":[[0,11,95.35]],"batl":[[2,12.5,42.77]],"id":44049799}]}]}
{"op":"mcm","id":2,"clk":"AOmjAgDv3AEAwYQC","pt":1743512068801,"mc":[{"id":"1.241629436","rc":[{"atb":[[1.17,1]],"atl":[[5.5,101.8]],"batl":[],"id":270592},{"atb":[[19,18.23]],"batb":[[0,19,18.23]],"id":58186642}]}]}
{"op":"mcm","id":2,"clk":"APajAgD33AEAzIQC","pt":1743512068908,"mc":[{"id":"1.241629436","rc":[{"atb":[[4.5,144.94]],"batb":[[1,4.5,144.94]],"id":270592},{"atb":[[19,27.36]],"batb":[[0,19,27.36]],"id":58186642}]}]}
{"op":"mcm","id":2,"clk":"AIWkAgD93AEA0oQC","pt":1743512069006,"mc":[{"id":"1.241629436","rc":[{"atl":[[10.5,136.48]],"batl":[[0,10.5,136.48]],"id":27115873}]}]}
{"op":"mcm","id":2,"clk":"AJ6kAgCT3QEA74QC","pt":1743512069320,"mc":[{"id":"1.241629436","rc":[{"atb":[[19,24.01]],"trd":[[19,213.56]],"batb":[[0,19,24.01]],"tv":6095.29,"id":58186642}],"tv":85522.7}]}
{"op":"mcm","id":2,"clk":"AK2kAgCe3QEA9YQC","pt":1743512069424,"mc":[{"id":"1.241629436","rc":[{"atb":[[4.1,97.82],[4.3,143]],"batb":[],"id":270592},{"atl":[[10.5,130.91]],"batl":[[0,10.5,130.91]],"id":27115873},{"atl":[[21,13.09]],"batl":[[1,21,13.09]],"id":58186642},{"atb":[[6,176.43],[6.4,278.71]],"batb":[],"id":26496185}]}]}
{"op":"mcm","id":2,"clk":"AMSkAgCt3QEAhIUC","pt":1743512069621,"mc":[{"id":"1.241629436","rc":[{"atl":[[11.5,15.83]],"trd":[[11.5,1240.46]],"batl":[[0,11.5,15.83]],"tv":6480.24,"id":40389088},{"atl":[[5.6,89.96]],"batl":[],"id":56297029},{"atb":[[19,5.06]],"trd":[[19,251.46]],"batb":[[0,19,5.06]],"tv":6133.19,"id":58186642}],"tv":85572.23}]}
{"op":"mcm","id":2,"clk":"AM+kAgC33QEAkoUC","pt":1743512069727,"mc":[{"id":"1.241629436","rc":[{"atl":[[11.5,14.84]],"batl":[[0,11.5,14.84]],"id":40389088},{"atb":[[4.6,217.47],[4.5,132.85]],"trd":[[4.6,0.2]],"batb":[[1,4.5,132.85],[0,4.6,217.47]],"ltp":4.6,"tv":21423.21,"id":270592},{"atl":[[10.5,136.46]],"batl":[[0,10.5,136.46]],"id":27115873},{"atl":[[22,8.68],[20,13.1],[19.5,5.52]],"batl":[[2,21,13.09],[1,20,13.1],[0,19.5,5.52]],"id":58186642}],"tv":85572.43}]}
{"op":"mcm","id":2,"clk":"ANikAgDA3QEAlYUC","pt":1743512069825,"mc":[{"id":"1.241629436","rc":[{"atl":[[4.7,70.76]],"trd":[[4.7,2049.24]],"batl":[[0,4.7,70.76]],"ltp":4.7,"tv":21425.21,"id":270592},{"atl":[[10.5,130.91]],"batl":[[0,10.5,130.91]],"id":27115873},{"atb":[[19,1.47],[17.5,44.01]],"trd":[[19,273.58]],"batb":[[0,19,1.47]],"tv":6155.31,"id":58186642}],"tv":85596.55}]}
{"op":"mcm","id":2,"clk":"AOqkAgDM3QEAmoUC","pt":1743512069886,"mc":[{"id":"1.241629436","rc":[{"atb":[[19,0],[18.5,36.7]],"atl":[[19,10.65],[19.5,8.39]],"trd":[[19,276.52]],"batb":[[2,17.5,44.01],[1,18,28.1],[0,18.5,36.7]],"batl":[[2,20,13.1],[1,19.5,8.39],[0,19,10.65]],"tv":6158.25,"id":58186642},{"atb":[[7,90.41]],"batb":[[0,7,90.41]],"id":26496185}],"tv":85599.49}]}
{"op":"mcm","id":2,"clk":"APSkAgDa3QEAo4UC","pt":1743512069996,"mc":[{"id":"1.241629436","rc":[{"atb":[[4.5,144.91]],"atl":[[4.7,21.29]],"batb":[[1,4.5,144.91]],"batl":[[0,4.7,21.29]],"id":270592},{"atb":[[10,44.16]],"batb":[[0,10,44.16]],"id":27115873},{"atb":[[18.5,31.57]],"atl":[[19.5,10.58],[19,7.37]],"trd":[[19,283.08]],"batb":[[0,18.5,31.57]],"batl":[[1,19.5,10.58],[0,19,7.37]],"tv":6164.81,"id":58186642}],"tv":85606.05}]}
{"op":"mcm","id":2,"clk":"APykAgDk3QEAroUC","pt":1743512070093,"mc":[{"id":"1.241629436","rc":[{"atb":[[4.6,231.9],[4.5,132.85]],"atl":[[1000,23.16]],"batb":[[1,4.5,132.85],[0,4.6,231.9]],"id":270592},{"atl":[[1000,1.46]],"id":27115873},{"atl":[[19.5,13.85],[19,3.87]],"trd":[[19,290.08]],"batl":[[1,19.5,13.85],[0,19,3.87]],"tv":6171.81,"id":58186642}],"tv":85613.05}]}
{"op":"mcm","id":2,"clk":"AIalAgDu3QEAtoUC","pt":1743512070198,"mc":[{"id":"1.241629436","rc":[{"atl":[[4.8,152.21]],"batl":[[1,4.8,152.21]],"id":270592},{"atl":[[1000,1.16]],"id":27115873},{"atb":[[19,1],[18.5,34.53]],"atl":[[19,0]],"batb":[[2,18,28.1],[1,18.5,34.53],[0,19,1]],"batl":[[2,21,13.09],[1,20,13.1],[0,19.5,13.85]],"id":58186642},{"atb":[[5.5,126.13]],"id":26496185}]}]}
{"op":"mcm","id":2,"clk":"AI+lAgD33QEAwIUC","pt":1743512070303,"mc":[{"id":"1.241629436","rc":[{"atl":[[1000,21.16],[5.1,121.83]],"batl":[],"id":270592},{"atb":[[6.2,0]],"id":59626646},{"atl":[[11,59.81]],"batl":[[1,11,59.81]],"id":27115873},{"atb":[[19,0],[18.5,31.57]],"atl":[[19.5,16.89]],"trd":[[19,292.08]],"batb":[[2,17.5,44.01],[1,18,28.1],[0,18.5,31.57]],"batl":[[0,19.5,16.89]],"tv":6173.81,"id":58186642}],"tv":85615.05}]}
{"op":"mcm","id":2,"clk":"AJulAgCO3gEA1IUC","pt":1743512070507,"mc":[{"id":"1.241629436","rc":[{"atl":[[19.5,13.85]],"batl":[[0,19.5,13.85]],"id":58186642}]}]}
{"op":"mcm","id":2,"clk":"AKSlAgCd3gEA44UC","pt":1743512070619,"mc":[{"id":"1.241629436","rc":[{"atl":[[4.7,1.29],[5.5,90.83],[4.8,172.21]],"trd":[[4.7,2089.23]],"batl":[[1,4.8,172.21],[0,4.7,1.29]],"tv":21465.2,"id":270592},{"atb":[[18.5,34.53]],"batb":[[0,18.5,34.53]],"id":58186642}],"tv":85655.04}]}
{"op":"mcm","id":2,"clk":"AKqlAgCo3gEA8IUC","pt":1743512070721,"mc":[{"id":"1.241629436","rc":[{"atb":[[4.6,243.96],[4.5,154.93]],"atl":[[4.7,2.96]],"batb":[[1,4.5,154.93],[0,4.6,243.96]],"batl":[[0,4.7,2.96]],"id":270592},{"atl":[[10.5,136.45]],"batl":[[0,10.5,136.45]],"id":27115873},{"atl":[[19.5,17.19]],"batl":[[0,19.5,17.19]],"id":58186642},{"atl":[[11.5,29.69]],"batl":[[0,11.5,29.69]],"id":44049799}]}]}
{"op":"mcm","id":2,"clk":"ALKlAgCt3gEA9IUC","pt":1743512070814,"mc":[{"id":"1.241629436","rc":[{"atb":[[4.9,78.72]],"batb":[[2,4.9,78.72]],"id":56297029},{"atb":[[10,43.16]],"trd":[[10,605.9]],"batb":[[0,10,43.16]],"tv":7241.54,"id":27115873}],"tv":85657.04}]}
{"op":"mcm","id":2,"clk":"ALilAgC03gEA/4UC","pt":1743512070927,"mc":[{"id":"1.241629436","rc":[{"atb":[[4.7,1]],"atl":[[4.7,0],[1000,23.16],[4.9,268.88],[4.8,145.17]],"trd":[[4.7,2095.15],[4.8,3525.87]],"batb":[[2,4.5,154.93],[1,4.6,243.96],[0,4.7,1]],"batl":[[2,5,198.09],[1,4.9,268.88],[0,4.8,145.17]],"ltp":4.8,"tv":21525.2,"id":270592}],"tv":85717.04}]}
{"op":"mcm","id":2,"clk":"AMOlAgC93gEAhoYC","pt":1743512071022,"mc":[{"id":"1.241629436","rc":[{"atl":[[4.8,194.73]],"batl":[[0,4.8,194.73]],"id":270592},{"atl":[[19.5,20.16]],"batl":[[0,19.5,20.16]],"id":58186642},{"atb":[[6.2,173.3]],"batb":[],"id":26496185}]}]}
{"op":"mcm","id":2,"clk":"AMqlAgDF3gEAk4YC","pt":1743512071128,"mc":[{"id":"1.241629436","rc":[{"atb":[[11,106.18]],"batb":[[0,11,106.18]],"id":40389088},{"atb":[[4.7,26.16],[4.6,240.87],[4.3,141.81]],"atl":[[1000,21.16],[5,167.6]],"batb":[[1,4.6,240.87],[0,4.7,26.16]],"batl":[[2,5,167.6]],"id":270592},{"atb":[[10,30.16]],"batb":[[0,10,30.16]],"id":27115873},{"atb":[[18.5,33.53]],"batb":[[0,18.5,33.53]],"id":58186642}]}]}
{"op":"mcm","id":2,"clk":"ANWlAgDN3gEAooYC","pt":1743512071235,"mc":[{"id":"1.241629436","rc":[{"atb":[[4.7,21.31],[4.4,225.38]],"atl":[[5.1,122.73]],"trd":[[4.7,2104.85]],"batb":[[0,4.7,21.31]],"batl":[],"ltp":4.7,"tv":21534.9,"id":270592}],"tv":85726.74}]}
{"op":"mcm","id":2,"clk":"ANylAgDZ3gEAooYC","pt":1743512071285,"mc":[{"id":"1.241629436","rc":[{"atl":[[5.4,52.67]],"batl":[],"id":270592},{"atb":[[10,28.02]],"batb":[[0,10,28.02]],"id":27115873}]}]}
{"op":"mcm","id":2,"clk":"AOKlAgDh3gEAp4YC","pt":1743512071385,"mc":[{"id":"1.241629436","rc":[{"atb":[[6.4,274.71]],"batb":[],"id":26496185}]}]}
{"op":"mcm","id":2,"clk":"AO+lAgDu3gEAroYC","pt":1743512071492,"mc":[{"id":"1.241629436","rc":[{"atl":[[5.3,123.13]],"batl":[],"id":270592},{"atl":[[20,13.17]],"batl":[[1,20,13.17]],"id":58186642},{"atb":[[6.4,272.71]],"batb":[],"id":26496185}]}]}
{"op":"mcm","id":2,"clk":"AP6lAgD93gEAuIYC","pt":1743512071606,"mc":[{"id":"1.241629436","rc":[{"atb":[[5.1,254.52]],"trd":[[5.1,4526.49]],"batb":[[0,5.1,254.52]],"ltp":5.1,"tv":13765.25,"id":56297029},{"atl":[[20,16.52]],"batl":[[1,20,16.52]],"id":58186642},{"atb":[[7,88.41]],"trd":[[7,550.21]],"batb":[[0,7,88.41]],"tv":13570.48,"id":26496185}],"tv":85734.74}]}
{"op":"mcm","id":2,"clk":"AIimAgCI3wEAvoYC","pt":1743512071702,"mc":[{"id":"1.241629436","rc":[{"atl":[[5.3,128.74]],"batl":[],"id":270592}]}]}
{"op":"mcm","id":2,"clk":"AJymAgCd3wEAz4YC","pt":1743512071909,"mc":[{"id":"1.241629436","rc":[{"atb":[[7,85.41]],"trd":[[7,556.21]],"batb":[[0,7,85.41]],"tv":13576.48,"id":26496185}],"tv":85740.74}]}
{"op":"mcm","id":2,"clk":"AKymAgCs3wEA3YYC","pt":1743512072114,"mc":[{"id":"1.241629436","rc":[{"atb":[[11,102.18]],"trd":[[11,253.72]],"batb":[[0,11,102.18]],"ltp":11,"tv":6488.24,"id":40389088},{"atl":[[5.7,57.55]],"batl":[],"id":270592}],"tv":85748.74}]}
{"op":"mcm","id":2,"clk":"ALamAgCv3wEA4IYC","pt":1743512072217,"mc":[{"id":"1.241629436","rc":[{"atl":[[11.5,21.05]],"batl":[[0,11.5,21.05]],"id":40389088}]}]}
{"op":"mcm","id":2,"clk":"ANSmAgDH3wEA+YYC","pt":1743512072522,"mc":[{"id":"1.241629436","rc":[{"atb":[[6.8,171.9]],"batb":[[1,6.8,171.9]],"id":26496185}]}]}
{"op":"mcm","id":2,"clk":"AN6mAgDT3wEAgYcC","pt":1743512072629,"mc":[{"id":"1.241629436","rc":[{"atl":[[4.8,193.13]],"trd":[[4.8,3529.07]],"batl":[[0,4.8,193.13]],"ltp":4.8,"tv":21538.1,"id":270592},{"atb":[[7,106.94]],"batb":[[0,7,106.94]],"id":26496185}],"tv":85751.94}]}
{"op":"mcm","id":2,"clk":"AOqmAgDa3wEAiIcC","pt":1743512072730,"mc":[{"id":"1.241629436","rc":[{"atb":[[7,58.15]],"trd":[[7,653.79]],"batb":[[0,7,58.15]],"tv":13674.06,"id":26496185}],"tv":85849.52}]}
{"op":"mcm","id":2,"clk":"APOmAgDl3wEAjYcC","pt":1743512072782,"mc":[{"id":"1.241629436","rc":[{"atb":[[4.9,89.64]],"batb":[[2,4.9,89.64]],"id":56297029},{"atl":[[7.2,139.25]],"batl":[[0,7.2,139.25]],"id":26496185}]}]}
{"op":"mcm","id":2,"clk":"APumAgDw3wEAkYcC","pt":1743512072894,"mc":[{"id":"1.241629436","rc":[{"atl":[[19.5,17.19]],"batl":[[0,19.5,17.19]],"id":58186642}]}]}
{"op":"mcm","id":2,"clk":"AIenAgD63wEAmocC","pt":1743512072994,"mc":[{"id":"1.241629436","rc":[{"atl":[[4.8,192.13]],"trd":[[4.8,3531.07]],"batl":[[0,4.8,192.13]],"tv":21540.1,"id":270592},{"atl":[[5.3,95.51]],"batl":[[1,5.3,95.51]],"id":56297029}],"tv":85851.52}]}
{"op":"mcm","id":2,"clk":"AJanAgD/3wEAqYcC","pt":1743512073112,"mc":[{"id":"1.241629436","rc":[{"atb":[[7,14.68]],"trd":[[7,740.73]],"batb":[[0,7,14.68]],"tv":13761,"id":26496185}],"tv":85938.46}]}
{"op":"mcm","id":2,"clk":"AJ2nAgCG4AEAsIcC","pt":1743512073196,"mc":[{"id":"1.241629436","rc":[{"atl":[[4.8,191.13]],"trd":[[4.8,3533.07]],"batl":[[0,4.8,191.13]],"tv":21542.1,"id":270592},{"atb":[[7,32.75]],"trd":[[7,747.55]],"batb":[[0,7,32.75]],"tv":13767.82,"id":26496185}],"tv":85947.28}]}
{"op":"mcm","id":2,"clk":"AKqnAgCO4AEAuIcC","pt":1743512073313,"mc":[{"id":"1.241629436","rc":[{"atb":[[10,33.59]],"batb":[[0,10,33.59]],"id":27115873}]}]}
{"op":"mcm","id":2,"clk":"ALanAgCS4AEAw4cC","pt":1743512073414,"mc":[{"id":"1.241629436","rc":[{"atb":[[10,28.02]],"batb":[[0,10,28.02]],"id":27115873}]}]}
{"op":"mcm","id":2,"clk":"AMGnAgCf4AEAyocC","pt":1743512073522,"mc":[{"id":"1.241629436","rc":[{"atb":[[11,101.4]],"atl":[[1000,0.38],[12,85.14],[11.5,20.93]],"batb":[[0,11,101.4]],"batl":[[1,12,85.14],[0,11.5,20.93]],"id":40389088},{"atb":[[4.7,28.77],[4.6,226.44]],"atl":[[4.9,270.89],[4.8,188.23]],"batb":[[1,4.6,226.44],[0,4.7,28.77]],"batl":[[1,4.9,270.89],[0,4.8,188.23]],"id":270592},{"atb":[[9.8,59.66]],"atl":[[1000,0.68],[10.5,75.76]],"batb":[[0,9.8,59.66]],"batl":[[1,10.5,75.76]],"id":35856222},{"atl":[[5.2,229.13]],"batl":[[0,5.2,229.13]],"id":56297029},{"atl":[[10.5,136.23]],"batl":[[0,10.5,136.23]],"id":27115873},{"atb":[[18,29.83],[18.5,31.9]],"atl":[[19.5,19.94]],"batb":[[1,18,29.83],[0,18.5,31.9]],"batl":[[0,19.5,19.94]],"id":58186642},{"atb":[[7,29.75]],"atl":[[7.2,138.62]],"trd":[[7,753.55]],"batb":[[0,7,29.75]],"batl":[[0,7.2,138.62]],"tv":13773.82,"id":26496185}],"tv":85953.28}]}
{"op":"mcm","id":2,"clk":"AMqnAgCn4AEAzYcC","pt":1743512073617,"mc":[{"id":"1.241629436","rc":[{"atl":[[6,68.24]],"id":270592}]}]}
{"op":"mcm","id":2,"clk":"ANKnAgCu4AEA24cC","pt":1743512073720,"mc":[{"id":"1.241629436","rc":[{"atl":[[1000,0.25]],"id":40389088},{"atl":[[1000,0.41]],"id":35856222}]}]}
{"op":"mcm","id":2,"clk":"ANmnAgC04AEA4ocC","pt":1743512073824,"mc":[{"id":"1.241629436","rc":[{"atl":[[11.5,21.06]],"batl":[[0,11.5,21.06]],"id":40389088},{"atl":[[10,96.49]],"batl":[[0,10,96.49]],"id":35856222},{"atb":[[10,13.02]],"trd":[[10,635.9]],"batb":[[0,10,13.02]],"tv":7271.54,"id":27115873}],"tv":85983.28}]}
{"op":"mcm","id":2,"clk":"AOKnAgC94AEA7IcC","pt":1743512073927,"mc":[{"id":"1.241629436","rc":[{"atb":[[9.8,54.66]],"trd":[[9.8,894.33]],"batb":[[0,9.8,54.66]],"tv":9865.11,"id":35856222}],"tv":85993.28}]}
{"op":"mcm","id":2,"clk":"AO2nAgDE4AEA8ocC","pt":1743512074033,"mc":[{"id":"1.241629436","rc":[{"atl":[[5.4,126.19]],"batl":[[2,5.4,126.19]],"id":56297029},{"atb":[[9.8,93.67]],"batb":[[1,9.8,93.67]],"id":27115873}]}]}
{"op":"mcm","id":2,"clk":"APmnAgDI4AEA+4cC","pt":1743512074096,"mc":[{"id":"1.241629436","rc":[{"atl":[[7.2,136.62]],"trd":[[7.2,11.73]],"batl":[[0,7.2,136.62]],"ltp":7.2,"tv":13777.83,"id":26496185}],"tv":85997.29}]}
{"op":"mcm","id":2,"clk":"AISoAgDP4AEAgIgC","pt":1743512074195,"mc":[{"id":"1.241629436","rc":[{"atb":[[11,99.45]],"batb":[[0,11,99.45]],"id":40389088},{"atb":[[4.6,228.01],[4.5,154.66]],"batb":[[2,4.5,154.66],[1,4.6,228.01]],"id":270592},{"atb":[[5.1,253.08]],"atl":[[5.3,94.86]],"batb":[[0,5.1,253.08]],"batl":[[1,5.3,94.86]],"id":56297029},{"atb":[[6.2,170.09]],"atl":[[8.2,91.24],[7.2,158.58],[8,53.72]],"batb":[],"batl":[[0,7.2,158.58]],"id":26496185}]}]}
{"op":"mcm","id":2,"clk":"AJOoAgDW4AEAhogC","pt":1743512074299,"mc":[{"id":"1.241629436","rc":[{"atb":[[11,99.12]],"batb":[[0,11,99.12]],"id":40389088},{"atl":[[4.8,183.61]],"trd":[[4.8,3542.31]],"batl":[[0,4.8,183.61]],"tv":21551.34,"id":270592},{"atb":[[18.5,29.9]],"trd":[[18.5,187.73]],"batb":[[0,18.5,29.9]],"ltp":18.5,"tv":6177.81,"id":58186642},{"atb":[[6.2,173.3]],"atl":[[7.4,37.19],[8,51.88]],"batb":[],"batl":[[1,7.4,37.19]],"id":26496185}],"tv":86010.53}]}
{"op":"mcm","id":2,"clk":"AJuoAgDd4AEAjogC","pt":1743512074398,"mc":[{"id":"1.241629436","rc":[{"atl":[[19,6.13]],"batl":[[2,20,16.52],[1,19.5,19.94],[0,19,6.13]],"id":58186642},{"atl":[[7.2,152.27]],"trd":[[7.2,24.33]],"batl":[[0,7.2,152.27]],"tv":13790.43,"id":26496185}],"tv":86023.13}]}
{"op":"mcm","id":2,"clk":"AKWoAgDn4AEAmIgC","pt":1743512074501,"mc":[{"id":"1.241629436","rc":[{"atb":[[18.5,22.9]],"batb":[[0,18.5,22.9]],"id":58186642},{"atl":[[8.2,89.5]],"batl":[],"id":26496185}]}]}
{"op":"mcm","id":2,"clk":"ALOoAgDt4AEApYgC","pt":1743512074608,"mc":[{"id":"1.241629436","rc":[{"atb":[[18.5,14.67]],"batb":[[0,18.5,14.67]],"id":58186642},{"atl":[[7.4,39.14]],"batl":[[1,7.4,39.14]],"id":26496185}]}]}
{"op":"mcm","id":2,"clk":"AMCoAgD24AEArIgC","pt":1743512074708,"mc":[{"id":"1.241629436","rc":[{"atl":[[19.5,22.95]],"batl":[[1,19.5,22.95]],"id":58186642}]}]}
{"op":"mcm","id":2,"clk":"AMaoAgD/4AEAu4gC","pt":1743512074815,"mc":[{"id":"1.241629436","rc":[{"atl":[[11.5,38.55]],"batl":[[0,11.5,38.55]],"id":44049799}]}]}
{"op":"mcm","id":2,"clk":"ANOoAgCD4QEAwIgC","pt":1743512074914,"mc":[{"id":"1.241629436","rc":[{"atb":[[7,12.52]],"trd":[[7,788.01]],"batb":[[0,7,12.52]],"ltp":7,"tv":13824.89,"id":26496185}],"tv":86057.59}]}
{"op":"mcm","id":2,"clk":"ANeoAgCI4QEAxYgC","pt":1743512075012,"mc":[{"id":"1.241629436","rc":[{"atl":[[4.8,171.55]],"batl":[[0,4.8,171.55]],"id":270592},{"atb":[[9.8,53.66]],"trd":[[9.8,896.33]],"batb":[[0,9.8,53.66]],"tv":9867.11,"id":35856222},{"atb":[[10,19.44]],"trd":[[10,655.9]],"batb":[[0,10,19.44]],"tv":7291.54,"id":27115873}],"tv":86079.59}]}
{"op":"mcm","id":2,"clk":"ANuoAgCM4QEAzIgC","pt":1743512075113,"mc":[{"id":"1.241629436","rc":[{"atb":[[4.7,18.77]],"trd":[[4.7,2124.85]],"batb":[[0,4.7,18.77]],"ltp":4.7,"tv":21571.34,"id":270592},{"atl":[[5.5,89.18]],"batl":[],"id":56297029},{"atb":[[7,0]],"batb":[[2,6.4,272.71],[1,6.6,263.69],[0,6.8,171.9]],"id":26496185}],"tv":86099.59}]}
{"op":"mcm","id":2,"clk":"AOKoAgCW4QEA14gC","pt":1743512075229,"mc":[{"id":"1.241629436","rc":[{"atb":[[10,33]],"batb":[[0,10,33]],"id":27115873},{"atl":[[19.5,19.94]],"batl":[[1,19.5,19.94]],"id":58186642},{"atb":[[6.2,170.09]],"batb":[],"id":26496185}]}]}
{"op":"mcm","id":2,"clk":"AOmoAgCY4QEA2YgC","pt":1743512075321,"mc":[{"id":"1.241629436","rc":[{"atl":[[4.8,196.55]],"batl":[[0,4.8,196.55]],"id":270592},{"atb":[[6.2,155.59]],"atl":[[7.2,154.21]],"batb":[],"batl":[[0,7.2,154.21]],"id":26496185}]}]}
{"op":"mcm","id":2,"clk":"AO6oAgCf4QEA3YgC","pt":1743512075422,"mc":[{"id":"1.241629436","rc":[{"atb":[[10,46]],"batb":[[0,10,46]],"id":27115873},{"atb":[[6.8,224.78]],"batb":[[0,6.8,224.78]],"id":26496185}]}]}
{"op":"mcm","id":2,"clk":"APSoAgCk4QEA44gC","pt":1743512075527,"mc":[{"id":"1.241629436","rc":[{"atl":[[1000,23.16]],"id":270592},{"atl":[[10.5,130.69]],"batl":[[0,10.5,130.69]],"id":27115873}]}]}
{"op":"mcm","id":2,"clk":"APuoAgCq4QEA7IgC","pt":1743512075626,"mc":[{"id":"1.241629436","rc":[{"atb":[[1.17,2.49]],"atl":[[11.5,20.93]],"batl":[[0,11.5,20.93]],"id":40389088},{"atl":[[4.8,194.78]],"trd":[[4.8,3545.85]],"batl":[[0,4.8,194.78]],"ltp":4.8,"tv":21574.88,"id":270592},{"atb":[[55,13.97]],"batb":[[0,55,13.97]],"id":59626646},{"atb":[[6.2,153.59]],"batb":[],"id":26496185},{"atb":[[11,94.79]],"batb":[[0,11,94.79]],"id":44049799}],"tv":86103.13}]}
{"op":"mcm","id":2,"clk":"AICpAgCx4QEA9YgC","pt":1743512075727,"mc":[{"id":"1.241629436","rc":[{"atb":[[4.7,22.13]],"atl":[[1000,21.16]],"batb":[[0,4.7,22.13]],"id":270592},{"atl":[[7.2,152.21]],"trd":[[7.2,28.33]],"batl":[[0,7.2,152.21]],"ltp":7.2,"tv":13828.89,"id":26496185}],"tv":86107.13}]}
{"op":"mcm","id":2,"clk":"AIepAgC74QEA/YgC","pt":1743512075784,"mc":[{"id":"1.241629436","rc":[{"atb":[[1.17,2]],"id":40389088},{"atl":[[11.5,33.56]],"batl":[[0,11.5,33.56]],"id":44049799}]}]}
{"op":"mcm","id":2,"clk":"AI+pAgDC4QEAgokC","pt":1743512075887,"mc":[{"id":"1.241629436","rc":[{"atl":[[11.5,20.44]],"trd":[[11.5,1241.44]],"batl":[[0,11.5,20.44]],"ltp":11.5,"tv":6489.22,"id":40389088}],"tv":86108.11}]}
{"op":"mcm","id":2,"clk":"AJepAgDH4QEAiIkC","pt":1743512075988,"mc":[{"id":"1.241629436","rc":[{"atl":[[7,1]],"batl":[[2,7.4,39.14],[1,7.2,152.21],[0,7,1]],"id":26496185}]}]}
{"op":"mcm","id":2,"clk":"AKGpAgDL4QEAkYkC","pt":1743512076098,"mc":[{"id":"1.241629436","rc":[{"atb":[[4.6,231.1]],"batb":[[1,4.6,231.1]],"id":270592},{"atb":[[6.2,156.8]],"atl":[[7,2.67]],"batb":[],"batl":[[0,7,2.67]],"id":26496185}]}]}
{"op":"mcm","id":2,"clk":"AKmpAgDT4QEAlokC","pt":1743512076202,"mc":[{"id":"1.241629436","rc":[{"atl":[[11.5,19.56]],"trd":[[11.5,1245.12]],"batl":[[0,11.5,19.56]],"tv":6492.9,"id":40389088},{"atb":[[4.7,20.19]],"batb":[[0,4.7,20.19]],"id":270592},{"atb":[[55,14.39]],"batb":[[0,55,14.39]],"id":59626646},{"atl":[[11.5,32.56]],"trd":[[11.5,1043.03]],"batl":[[0,11.5,32.56]],"ltp":11.5,"tv":5117.08,"id":44049799}],"tv":86113.79}]}
{"op":"mcm","id":2,"clk":"ALCpAgDZ4QEAn4kC","pt":1743512076300,"mc":[{"id":"1.241629436","rc":[{"atb":[[11,115.48]],"batb":[[0,11,115.48]],"id":40389088},{"atl":[[1000,23.16]],"id":270592},{"atb":[[18.5,8.81]],"atl":[[19,7.59]],"batb":[[0,18.5,8.81]],"batl":[[0,19,7.59]],"id":58186642}]}]}
{"op":"mcm","id":2,"clk":"ALqpAgDh4QEAqIkC","pt":1743512076409,"mc":[{"id":"1.241629436","rc":[{"atb":[[18.5,5.85]],"atl":[[19.5,22.96]],"batb":[[0,18.5,5.85]],"batl":[[1,19.5,22.96]],"id":58186642}]}]}
{"op":"mcm","id":2,"clk":"AMKpAgDt4QEAs4kC","pt":1743512076514,"mc":[{"id":"1.241629436","rc":[{"atl":[[1000,21.16]],"id":270592},{"atl":[[7,4.21]],"trd":[[7,790.93]],"batl":[[0,7,4.21]],"ltp":7,"tv":13831.81,"id":26496185}],"tv":86116.71}]}
{"op":"mcm","id":2,"clk":"AM2pAgD14QEAwIkC","pt":1743512076714,"mc":[{"id":"1.241629436","rc":[{"atl":[[4.8,206.7]],"batl":[[0,4.8,206.7]],"id":270592},{"atl":[[7,21.47]],"batl":[[0,7,21.47]],"id":26496185},{"atb":[[11,91.79]],"trd":[[11,1591.56]],"batb":[[0,11,91.79]],"ltp":11,"tv":5123.08,"id":44049799}],"tv":86122.71}]}
{"op":"mcm","id":2,"clk":"ANqpAgD84QEAyIkC","pt":1743512076821,"mc":[{"id":"1.241629436","rc":[{"atl":[[7,32.28]],"batl":[[0,7,32.28]],"id":26496185},{"atb":[[11,96.78]],"atl":[[11.5,37.54]],"batb":[[0,11,96.78]],"batl":[[0,11.5,37.54]],"id":44049799}]}]}
{"op":"mcm","id":2,"clk":"AOqpAgCD4gEA1IkC","pt":1743512076923,"mc":[{"id":"1.241629436","rc":[{"atb":[[4.7,0],[4.6,229.6]],"atl":[[4.7,179.81]],"trd":[[4.7,2165.23],[4.6,3.2]],"batb":[[2,4.4,225.38],[1,4.5,154.66],[0,4.6,229.6]],"batl":[[2,4.9,270.89],[1,4.8,206.7],[0,4.7,179.81]],"ltp":4.6,"tv":21618.26,"id":270592}],"tv":86166.09}]}
{"op":"mcm","id":2,"clk":"APWpAgCM4gEA2YkC","pt":1743512077017,"mc":[{"id":"1.241629436","rc":[{"atb":[[4.4,224.22]],"atl":[[5.1,121.83]],"batb":[[2,4.4,224.22]],"batl":[],"id":270592},{"atl":[[5.2,226.79]],"batl":[[0,5.2,226.79]],"id":56297029},{"atb":[[18.5,15.29]],"atl":[[19.5,19.94]],"batb":[[0,18.5,15.29]],"batl":[[1,19.5,19.94]],"id":58186642},{"atl":[[11.5,32.56]],"batl":[[0,11.5,32.56]],"id":44049799}]}]}
{"op":"mcm","id":2,"clk":"AICqAgCW4gEA4YkC","pt":1743512077120,"mc":[{"id":"1.241629436","rc":[{"atb":[[4.1,104.14],[4.6,228.2],[4.3,143]],"atl":[[4.7,202.82],[5,168.52]],"batb":[[0,4.6,228.2]],"batl":[[0,4.7,202.82]],"id":270592},{"atb":[[9.2,79.65]],"batb":[],"id":35856222},{"atb":[[18.5,21.55]],"batb":[[0,18.5,21.55]],"id":58186642}]}]}
{"op":"mcm","id":2,"clk":"AIiqAgCc4gEA84kC","pt":1743512077227,"mc":[{"id":"1.241629436","rc":[{"atl":[[4.7,250.7]],"batl":[[0,4.7,250.7]],"id":270592},{"atl":[[7,33.78]],"batl":[[0,7,33.78]],"id":26496185},{"atl":[[11.5,37.53]],"batl":[[0,11.5,37.53]],"id":44049799}]}]}
{"op":"mcm","id":2,"clk":"AKOqAgCv4gEA/okC","pt":1743512077431,"mc":[{"id":"1.241629436","rc":[{"atb":[[4.6,205.36]],"batb":[[0,4.6,205.36]],"id":270592}]}]}
{"op":"mcm","id":2,"clk":"ALKqAgC74gEAhIoC","pt":1743512077530,"mc":[{"id":"1.241629436","rc":[{"atl":[[11.5,7.17]],"batl":[[0,11.5,7.17]],"id":40389088},{"atl":[[4.7,249.7]],"trd":[[4.7,2167.23]],"batl":[[0,4.7,249.7]],"ltp":4.7,"tv":21620.26,"id":270592},{"atl":[[5.2,226.41]],"trd":[[5.2,3803.93]],"batl":[[0,5.2,226.41]],"ltp":5.2,"tv":13766.01,"id":56297029},{"atb":[[6.2,158.8]],"batb":[],"id":26496185}],"tv":86168.85}]}
{"op":"mcm","id":2,"clk":"ALuqAgDD4gEAjIoC","pt":1743512077636,"mc":[{"id":"1.241629436","rc":[{"atb":[[5.1,251.08]],"trd":[[5.1,4530.49]],"batb":[[0,5.1,251.08]],"ltp":5.1,"tv":13770.01,"id":56297029}],"tv":86172.85}]}
{"op":"mcm","id":2,"clk":"APmqAgD+4gEAvIoC","pt":1743512078212,"mc":[{"id":"1.241629436","rc":[{"atl":[[4.7,241.7]],"trd":[[4.7,2183.23]],"batl":[[0,4.7,241.7]],"tv":21636.26,"id":270592}],"tv":86188.85}]}
{"op":"mcm","id":2,"clk":"AIOrAgCG4wEAxYoC","pt":1743512078323,"mc":[{"id":"1.241629436","rc":[{"atl":[[4.8,228.15]],"batl":[[1,4.8,228.15]],"id":270592},{"atl":[[5.3,95.86]],"batl":[[1,5.3,95.86]],"id":56297029}]}]}
{"op":"mcm","id":2,"clk":"AIqrAgCQ4wEAyooC","pt":1743512078420,"mc":[{"id":"1.241629436","rc":[{"atb":[[18.5,21.46]],"trd":[[18.5,187.9]],"batb":[[0,18.5,21.46]],"tv":6177.98,"id":58186642}],"tv":86189.02}]}
{"op":"mcm","id":2,"clk":"AJWrAgCY4wEA2IoC","pt":1743512078525,"mc":[{"id":"1.241629436","rc":[{"atl":[[4.7,246.7]],"batl":[[0,4.7,246.7]],"id":270592},{"atl":[[7,34.56]],"batl":[[0,7,34.56]],"id":26496185}]}]}
{"op":"mcm","id":2,"clk":"AK2rAgCm4wEA4YoC","pt":1743512078723,"mc":[{"id":"1.241629436","rc":[{"atl":[[4.7,245.7]],"trd":[[4.7,2185.23]],"batl":[[0,4.7,245.7]],"tv":21638.26,"id":270592},{"atb":[[5,1162.51],[5.1,249.08]],"trd":[[5.1,4534.49]],"batb":[[1,5,1162.51],[0,5.1,249.08]],"tv":13774.01,"id":56297029},{"atb":[[6.8,223.78]],"trd":[[6.8,777.41]],"batb":[[0,6.8,223.78]],"ltp":6.8,"tv":13833.81,"id":26496185}],"tv":86197.02}]}
{"op":"mcm","id":2,"clk":"ALirAgCs4wEA8IoC","pt":1743512078832,"mc":[{"id":"1.241629436","rc":[{"atb":[[4.6,205.15]],"trd":[[4.6,3.62]],"batb":[[0,4.6,205.15]],"ltp":4.6,"tv":21638.68,"id":270592},{"atb":[[5.1,293.08]],"batb":[[0,5.1,293.08]],"id":56297029}],"tv":86197.44}]}
{"op":"mcm","id":2,"clk":"ANSrAgC64wEA/YoC","pt":1743512079034,"mc":[{"id":"1.241629436","rc":[{"atb":[[4.6,207.19]],"batb":[[0,4.6,207.19]],"id":270592}]}]}
{"op":"mcm","id":2,"clk":"AN+rAgC+4wEAh4sC","pt":1743512079135,"mc":[{"id":"1.241629436","rc":[{"atl":[[5.3,108.57]],"batl":[],"id":270592}]}]}
{"op":"mcm","id":2,"clk":"AIasAgDY4wEAn4sC","pt":1743512079502,"mc":[{"id":"1.241629436","rc":[{"atl":[[1000,0.39]],"id":40389088},{"atl":[[4.9,268.88],[4.8,230.76]],"batl":[[2,4.9,268.88],[1,4.8,230.76]],"id":270592},{"atl":[[1000,0.61],[10,96.22]],"batl":[[0,10,96.22]],"id":35856222},{"atl":[[60,10]],"batl":[[0,60,10]],"id":59626646},{"atl":[[1000,1.4]],"id":27115873},{"atl":[[19.5,13.92],[19,10.25]],"batl":[[1,19.5,13.92],[0,19,10.25]],"id":58186642},{"atl":[[7.4,38.29],[7.2,153.46]],"batl":[[2,7.4,38.29],[1,7.2,153.46]],"id":26496185}]}]}
{"op":"mcm","id":2,"clk":"AJKsAgDg4wEAo4sC","pt":1743512079603,"mc":[{"id":"1.241629436","rc":[{"atb":[[1.5,36]],"atl":[[1000,0.25]],"id":40389088},{"atl":[[1000,0.41]],"id":35856222},{"atl":[[1000,1.16]],"id":27115873},{"atb":[[18.5,30.69]],"batb":[[0,18.5,30.69]],"id":58186642}]}]}
{"op":"mcm","id":2,"clk":"AJmsAgDl4wEAq4sC","pt":1743512079703,"mc":[{"id":"1.241629436","rc":[{"atl":[[11.5,7.31]],"batl":[[0,11.5,7.31]],"id":40389088},{"atl":[[10.5,75.96]],"batl":[[1,10.5,75.96]],"id":35856222},{"atl":[[10.5,130.93]],"batl":[[0,10.5,130.93]],"id":27115873},{"atb":[[18.5,30.72]],"batb":[[0,18.5,30.72]],"id":58186642}]}]}
{"op":"mcm","id":2,"clk":"AMesAgCU5AEAxosC","pt":1743512080220,"mc":[{"id":"1.241629436","rc":[{"atb":[[4.5,156.66]],"batb":[[1,4.5,156.66]],"id":270592}]}]}
{"op":"mcm","id":2,"clk":"AOqsAgCr5AEA3IsC","pt":1743512080538,"mc":[{"id":"1.241629436","rc":[{"atl":[[60,12.81]],"batl":[[0,60,12.81]],"id":59626646},{"atl":[[19,45.36]],"batl":[[0,19,45.36]],"id":58186642},{"atb":[[6.8,223.3]],"batb":[[0,6.8,223.3]],"id":26496185},{"atl":[[11.5,95.53]],"batl":[[0,11.5,95.53]],"id":44049799}]}]}
{"op":"mcm","id":2,"clk":"AIetAgC/5AEA7IsC","pt":1743512080745,"mc":[{"id":"1.241629436","rc":[{"atb":[[9.8,66.66]],"batb":[[0,9.8,66.66]],"id":35856222},{"atb":[[5.1,302.68]],"batb":[[0,5.1,302.68]],"id":56297029},{"atb":[[18.5,24.46]],"batb":[[0,18.5,24.46]],"id":58186642},{"atl":[[7,33.06]],"batl":[[0,7,33.06]],"id":26496185}]}]}
{"op":"mcm","id":2,"clk":"AJGtAgDE5AEA8osC","pt":1743512080835,"mc":[{"id":"1.241629436","rc":[{"atb":[[11,114.67]],"batb":[[0,11,114.67]],"id":40389088},{"atb":[[1.17,1.62],[4.4,229.32],[4.6,205.62],[4.5,158.66]],"atl":[[4.7,248.72],[4.8,205.76]],"batb":[[2,4.4,229.32],[1,4.5,158.66],[0,4.6,205.62]],"batl":[[1,4.8,205.76],[0,4.7,248.72]],"id":270592},{"atb":[[10,47]],"batb":[[0,10,47]],"id":27115873},{"atb":[[6.8,221.8]],"trd":[[6.8,780.41]],"batb":[[0,6.8,221.8]],"tv":13836.81,"id":26496185}],"tv":86200.44}]}
{"op":"mcm","id":2,"clk":"AJ2tAgDK5AEA+4sC","pt":1743512080939,"mc":[{"id":"1.241629436","rc":[{"atb":[[4.6,180.63]],"atl":[[1000,23.16]],"trd":[[4.6,53.61]],"batb":[[0,4.6,180.63]],"tv":21688.67,"id":270592},{"atb":[[18.5,19.47]],"atl":[[19.5,16.93]],"batb":[[0,18.5,19.47]],"batl":[[1,19.5,16.93]],"id":58186642}],"tv":86250.43}]}
{"op":"mcm","id":2,"clk":"ALCtAgDZ5AEAg4wC","pt":1743512081003,"mc":[{"id":"1.241629436","rc":[{"atl":[[11.5,4.2]],"batl":[[0,11.5,4.2]],"id":40389088},{"atb":[[1.17,1]],"id":270592}]}]}
{"op":"mcm","id":2,"clk":"ANOtAgDw5AEAmowC","pt":1743512081116,"mc":[{"id":"1.241629436","rc":[{"atb":[[4.5,159.28]],"atl":[[1000,21.16]],"batb":[[1,4.5,159.28]],"id":270592},{"atb":[[18.5,11.99]],"batb":[[0,18.5,11.99]],"id":58186642}]}]}
{"op":"mcm","id":2,"clk":"AO+tAgCR5QEAzIwC","pt":1743512081326,"mc":[{"id":"1.241629436","rc":[{"atb":[[16,10.02]],"batb":[],"id":58186642}]}]}
{"op":"mcm","id":2,"clk":"APytAgCY5QEAzowC","pt":1743512081428,"mc":[{"id":"1.241629436","rc":[{"atb":[[4.6,171.96]],"atl":[[4.8,211.14]],"trd":[[4.6,70.95]],"batb":[[0,4.6,171.96]],"batl":[[1,4.8,211.14]],"tv":21706.01,"id":270592}],"tv":86267.77}]}
{"op":"mcm","id":2,"clk":"AIyuAgCi5QEA1owC","pt":1743512081525,"mc":[{"id":"1.241629436","rc":[{"atb":[[4.5,161.28]],"batb":[[1,4.5,161.28]],"id":270592}]}]}
{"op":"mcm","id":2,"clk":"AJuuAgCy5QEA54wC","pt":1743512081636,"mc":[{"id":"1.241629436","rc":[{"atl":[[11.5,1.1]],"batl":[[0,11.5,1.1]],"id":40389088},{"atb":[[9.8,66.17]],"trd":[[9.8,897.3]],"batb":[[0,9.8,66.17]],"tv":9868.08,"id":35856222}],"tv":86268.74}]}
{"op":"mcm","id":2,"clk":"ALyuAgC/5QEAgY0C","pt":1743512081839,"mc":[{"id":"1.241629436","rc":[{"atl":[[7,34.06]],"batl":[[0,7,34.06]],"id":26496185}]}]}
{"op":"mcm","id":2,"clk":"AOOuAgDa5QEAoo0C","pt":1743512082113,"mc":[{"id":"1.241629436","rc":[{"atb":[[4.5,163.28]],"batb":[[1,4.5,163.28]],"id":270592},{"atb":[[55,12.45]],"trd":[[55,319.65]],"batb":[[0,55,12.45]],"ltp":55,"tv":2002.21,"id":59626646}],"tv":86272.62}]}
{"op":"mcm","id":2,"clk":"APCuAgDl5QEAr40C","pt":1743512082207,"mc":[{"id":"1.241629436","rc":[{"atb":[[9.4,61.65],[9.6,63.06]],"batb":[[2,9.4,61.65],[1,9.6,63.06]],"id":35856222}]}]}
{"op":"mcm","id":2,"clk":"AIevAgDz5QEAy40C","pt":1743512082420,"mc":[{"id":"1.241629436","rc":[{"atl":[[4.7,288.72]],"batl":[[0,4.7,288.72]],"id":270592},{"atb":[[9.8,46.17]],"trd":[[9.8,937.3]],"batb":[[0,9.8,46.17]],"tv":9908.08,"id":35856222},{"atl":[[7.8,86.14]],"batl":[],"id":26496185}],"tv":86312.62}]}
{"op":"mcm","id":2,"clk":"AJavAgCA5gEA2Y0C","pt":1743512082523,"mc":[{"id":"1.241629436","rc":[{"atb":[[11,115.58]],"atl":[[1000,0.44]],"batb":[[0,11,115.58]],"id":40389088},{"atb":[[4.6,184.85]],"batb":[[0,4.6,184.85]],"id":270592},{"atb":[[1.17,8.1]],"id":35856222},{"atl":[[5.2,230.19]],"batl":[[0,5.2,230.19]],"id":56297029},{"atb":[[6.8,225.98]],"trd":[[6.8,784.41]],"batb":[[0,6.8,225.98]],"tv":13840.81,"id":26496185}],"tv":86316.62}]}
{"op":"mcm","id":2,"clk":"AKSvAgCF5gEA4o0C","pt":1743512082627,"mc":[{"id":"1.241629436","rc":[{"atl":[[1000,0.25]],"id":40389088},{"atb":[[1.17,7.15],[9.8,52.04]],"batb":[[0,9.8,52.04]],"id":35856222},{"atb":[[6.8,251.74]],"batb":[[0,6.8,251.74]],"id":26496185}]}]}
{"op":"mcm","id":2,"clk":"AK+vAgCL5gEA640C","pt":1743512082726,"mc":[{"id":"1.241629436","rc":[{"atl":[[12,80.34]],"batl":[[1,12,80.34]],"id":40389088},{"atb":[[4.5,165.28]],"batb":[[1,4.5,165.28]],"id":270592},{"atb":[[9.8,52.99]],"batb":[[0,9.8,52.99]],"id":35856222}]}]}
{"op":"mcm","id":2,"clk":"ANmvAgCh5gEAiI4C","pt":1743512083032,"mc":[{"id":"1.241629436","rc":[{"atl":[[4.7,276.96]],"trd":[[4.7,2208.75]],"batl":[[0,4.7,276.96]],"ltp":4.7,"tv":21729.53,"id":270592}],"tv":86340.14}]}
{"op":"mcm","id":2,"clk":"AOSvAgCv5gEAkI4C","pt":1743512083132,"mc":[{"id":"1.241629436","rc":[{"atb":[[3.6,38.18]],"atl":[[19.5,13.58]],"batl":[[1,19.5,13.58]],"id":58186642}]}]}
{"op":"mcm","id":2,"clk":"APOvAgDB5gEAoI4C","pt":1743512083341,"mc":[{"id":"1.241629436","rc":[{"atb":[[4.5,167.28]],"batb":[[1,4.5,167.28]],"id":270592}]}]}
{"op":"mcm","id":2,"clk":"AIywAgDQ5gEAsI4C","pt":1743512083504,"mc":[{"id":"1.241629436","rc":[{"atb":[[11,73.84]],"trd":[[11,1637.44]],"batb":[[0,11,73.84]],"tv":5168.96,"id":44049799}],"tv":86386.02}]}
{"op":"mcm","id":2,"clk":"AJawAgDV5gEAu44C","pt":1743512083601,"mc":[{"id":"1.241629436","rc":[{"atb":[[5.8,16.15]],"id":27115873},{"atl":[[11.5,103.89]],"batl":[[0,11.5,103.89]],"id":44049799}]}]}
{"op":"mcm","id":2,"clk":"AKGwAgDj5gEAxY4C","pt":1743512083711,"mc":[{"id":"1.241629436","rc":[{"atb":[[11,93.6]],"batb":[[0,11,93.6]],"id":44049799}]}]}
{"op":"mcm","id":2,"clk":"AKqwAgDw5gEA0Y4C","pt":1743512083811,"mc":[{"id":"1.241629436","rc":[{"atl":[[13,40.08]],"batl":[],"id":44049799}]}]}
{"op":"mcm","id":2,"clk":"AMawAgCa5wEA8o4C","pt":1743512084018,"mc":[{"id":"1.241629436","rc":[{"atb":[[6.6,269.3]],"batb":[[1,6.6,269.3]],"id":26496185}]}]}
{"op":"mcm","id":2,"clk":"AM+wAgCp5wEA+44C","pt":1743512084128,"mc":[{"id":"1.241629436","rc":[{"atb":[[4.5,169.28]],"batb":[[1,4.5,169.28]],"id":270592},{"atl":[[7,32.5]],"trd":[[7,794.05]],"batl":[[0,7,32.5]],"ltp":7,"tv":13843.93,"id":26496185}],"tv":86389.14}]}
{"op":"mcm","id":2,"clk":"ANawAgCs5wEAgY8C","pt":1743512084229,"mc":[{"id":"1.241629436","rc":[{"atl":[[12,85.21]],"batl":[[1,12,85.21]],"id":40389088},{"atb":[[18.5,13]],"atl":[[22,10.14]],"batb":[[0,18.5,13]],"batl":[],"id":58186642},{"atl":[[7,26.33]],"batl":[[0,7,26.33]],"id":26496185}]}]}
{"op":"mcm","id":2,"clk":"AIqxAgDO5wEAno8C","pt":1743512084645,"mc":[{"id":"1.241629436","rc":[{"atb":[[6.8,248.74]],"trd":[[6.8,790.41]],"batb":[[0,6.8,248.74]],"ltp":6.8,"tv":13849.93,"id":26496185}],"tv":86395.14}]}
{"op":"mcm","id":2,"clk":"AJOxAgDY5wEAp48C","pt":1743512084700,"mc":[{"id":"1.241629436","rc":[{"atb":[[3.75,42.67]],"id":270592}]}]}
{"op":"mcm","id":2,"clk":"AJ+xAgDe5wEAs48C","pt":1743512084812,"mc":[{"id":"1.241629436","rc":[{"atb":[[4.5,171.28]],"batb":[[1,4.5,171.28]],"id":270592}]}]}
{"op":"mcm","id":2,"clk":"AKmxAgDl5wEAwY8C","pt":1743512084908,"mc":[{"id":"1.241629436","rc":[{"atl":[[7,31.93]],"batl":[[0,7,31.93]],"id":26496185}]}]}
{"op":"mcm","id":2,"clk":"AM6xAgD85wEA5Y8C","pt":1743512085219,"mc":[{"id":"1.241629436","rc":[{"atl":[[4.9,289.86]],"batl":[[2,4.9,289.86]],"id":270592}]}]}
{"op":"mcm","id":2,"clk":"ANyxAgCC6AEA648C","pt":1743512085321,"mc":[{"id":"1.241629436","rc":[{"atb":[[4.5,173.28]],"batb":[[1,4.5,173.28]],"id":270592}]}]}
{"op":"mcm","id":2,"clk":"AOixAgCN6AEA/I8C","pt":1743512085430,"mc":[{"id":"1.241629436","rc":[{"atl":[[19,51.29]],"batl":[[0,19,51.29]],"id":58186642}]}]}
{"op":"mcm","id":2,"clk":"APGxAgCa6AEA/48C","pt":1743512085533,"mc":[{"id":"1.241629436","rc":[{"atb":[[55,9.95]],"trd":[[55,324.65]],"batb":[[0,55,9.95]],"tv":2007.21,"id":59626646},{"atl":[[24,7.56]],"batl":[],"id":58186642}],"tv":86400.14}]}
{"op":"mcm","id":2,"clk":"AIWyAgCm6AEAkpAC","pt":1743512085730,"mc":[{"id":"1.241629436","rc":[{"atl":[[4.9,306.83]],"batl":[[2,4.9,306.83]],"id":270592},{"atb":[[18.5,3.77]],"batb":[[0,18.5,3.77]],"id":58186642}]}]}
{"op":"mcm","id":2,"clk":"AJGyAgCw6AEAnJAC","pt":1743512085832,"mc":[{"id":"1.241629436","rc":[{"atl":[[12,80.34]],"batl":[[1,12,80.34]],"id":40389088},{"atb":[[18,39.82]],"batb":[[1,18,39.82]],"id":58186642}]}]}
{"op":"mcm","id":2,"clk":"AJyyAgC96AEArJAC","pt":1743512085944,"mc":[{"id":"1.241629436","rc":[{"atb":[[18.5,2.94]],"atl":[[19,54.3]],"trd":[[18.5,189.56]],"batb":[[0,18.5,2.94]],"batl":[[0,19,54.3]],"tv":6179.64,"id":58186642}],"tv":86401.8}]}
{"op":"mcm","id":2,"clk":"AKyyAgDC6AEAr5AC","pt":1743512086037,"mc":[{"id":"1.241629436","rc":[{"atb":[[4.6,177.79]],"atl":[[4.9,285.85]],"trd":[[4.6,85.05]],"batb":[[0,4.6,177.79]],"batl":[[2,4.9,285.85]],"ltp":4.6,"tv":21743.63,"id":270592},{"atb":[[18.5,0.94]],"trd":[[18.5,193.56]],"batb":[[2,17,42.11],[1,17.5,44.01],[0,18,40.76]],"tv":6183.64,"id":58186642}],"tv":86419.9}]}
{"op":"mcm","id":2,"clk":"ALqyAgDL6AEAuZAC","pt":1743512086149,"mc":[{"id":"1.241629436","rc":[{"atl":[[12,85.22]],"batl":[[1,12,85.22]],"id":40389088},{"atb":[[4.9,64.64]],"batb":[[2,4.9,64.64]],"id":56297029},{"atb":[[18.5,0.3]],"atl":[[19,57.36]],"trd":[[18.5,194.84]],"batb":[[0,18,40.12]],"batl":[[0,19,57.36]],"tv":6184.92,"id":58186642}],"tv":86421.18}]}
{"op":"mcm","id":2,"clk":"AMOyAgDT6AEAvpAC","pt":1743512086201,"mc":[{"id":"1.241629436","rc":[{"atb":[[10,46]],"trd":[[10,657.9]],"batb":[[0,10,46]],"tv":7293.54,"id":27115873},{"atb":[[18.5,0]],"atl":[[19,54.3],[18.5,1.19]],"trd":[[18.5,195.44]],"batb":[[0,18,39.82]],"batl":[[2,19.5,13.58],[1,19,54.3],[0,18.5,1.19]],"tv":6185.52,"id":58186642}],"tv":86423.78}]}
{"op":"mcm","id":2,"clk":"AMyyAgDe6AEAy5AC","pt":1743512086303,"mc":[{"id":"1.241629436","rc":[{"atb":[[11,113.08]],"trd":[[11,258.72]],"batb":[[0,11,113.08]],"ltp":11,"tv":6497.9,"id":40389088},{"atl":[[1000,23.16]],"id":270592},{"atb":[[18,29.83]],"atl":[[19.5,10.58]],"batb":[[0,18,29.83]],"batl":[[2,19.5,10.58]],"id":58186642}],"tv":86428.78}]}
{"op":"mcm","id":2,"clk":"ANeyAgDn6AEA1pAC","pt":1743512086414,"mc":[{"id":"1.241629436","rc":[{"atb":[[10,47.17]],"batb":[[0,10,47.17]],"id":27115873},{"atl":[[19.5,13.57],[18.5,8.23]],"batl":[[2,19.5,13.57],[0,18.5,8.23]],"id":58186642}]}]}
{"op":"mcm","id":2,"clk":"AOWyAgDz6AEA4ZAC","pt":1743512086526,"mc":[{"id":"1.241629436","rc":[{"atl":[[1000,21.16]],"id":270592},{"atb":[[17.5,33.71]],"batb":[[1,17.5,33.71]],"id":58186642}]}]}
{"op":"mcm","id":2,"clk":"APKyAgD56AEA55AC","pt":1743512086617,"mc":[{"id":"1.241629436","rc":[{"atl":[[20,16.32]],"batl":[],"id":58186642}]}]}
{"op":"mcm","id":2,"clk":"APyyAgCH6QEA9ZAC","pt":1743512086722,"mc":[{"id":"1.241629436","rc":[{"atl":[[4.9,291.11]],"batl":[[2,4.9,291.11]],"id":270592}]}]}
{"op":"mcm","id":2,"clk":"AIyzAgCU6QEA+pAC","pt":1743512086827,"mc":[{"id":"1.241629436","rc":[{"atb":[[11,114.34]],"batb":[[0,11,114.34]],"id":40389088},{"atl":[[4.7,274.82]],"batl":[[0,4.7,274.82]],"id":270592},{"atb":[[1.17,2.84]],"atl":[[1000,5.69]],"id":56297029},{"atl":[[24,6.1]],"batl":[],"id":58186642}]}]}
{"op":"mcm","id":2,"clk":"AJ2zAgCg6QEAhJEC","pt":1743512086924,"mc":[{"id":"1.241629436","rc":[{"atb":[[1.17,2]],"id":56297029}]}]}
{"op":"mcm","id":2,"clk":"AK+zAgC16QEAjJEC","pt":1743512087029,"mc":[{"id":"1.241629436","rc":[{"atb":[[5.1,303.52]],"atl":[[1000,5.52],[5.2,230.16]],"trd":[[5.2,3803.99]],"batb":[[0,5.1,303.52]],"batl":[[0,5.2,230.16]],"ltp":5.2,"tv":13774.07,"id":56297029},{"atl":[[7,30.28]],"trd":[[7,797.35]],"batl":[[0,7,30.28]],"ltp":7,"tv":13853.23,"id":26496185}],"tv":86432.14}]}
{"op":"mcm","id":2,"clk":"ALqzAgDC6QEAmZEC","pt":1743512087132,"mc":[{"id":"1.241629436","rc":[{"atl":[[5.3,96.03]],"batl":[[1,5.3,96.03]],"id":56297029},{"atl":[[7,35.28]],"batl":[[0,7,35.28]],"id":26496185},{"atl":[[11.5,103.82]],"batl":[[0,11.5,103.82]],"id":44049799}]}]}
{"op":"mcm","id":2,"clk":"AM+zAgDZ6QEAsJEC","pt":1743512087335,"mc":[{"id":"1.241629436","rc":[{"atl":[[12,80.34]],"batl":[[1,12,80.34]],"id":40389088},{"atl":[[19.5,18.04]],"batl":[[2,19.5,18.04]],"id":58186642}]}]}
{"op":"mcm","id":2,"clk":"AOezAgDw6QEAxJEC","pt":1743512087545,"mc":[{"id":"1.241629436","rc":[{"atl":[[4.7,290.82]],"batl":[[0,4.7,290.82]],"id":270592}]}]}
{"op":"mcm","id":2,"clk":"AMC0AgDJ6gEAmZIC","pt":1743512088217,"mc":[{"id":"1.241629436","rc":[{"atl":[[5.3,94.03]],"batl":[[1,5.3,94.03]],"id":56297029}]}]}
{"op":"mcm","id":2,"clk":"AOO0AgDo6gEAupIC","pt":1743512088528,"mc":[{"id":"1.241629436","rc":[{"atl":[[4.7,250.82]],"batl":[[0,4.7,250.82]],"id":270592}]}]}
{"op":"mcm","id":2,"clk":"APW0AgD26gEAw5IC","pt":1743512088639,"mc":[{"id":"1.241629436","rc":[{"atb":[[4.6,137.79]],"trd":[[4.6,165.06]],"batb":[[0,4.6,137.79]],"tv":21823.64,"id":270592}],"tv":86512.15}]}
{"op":"mcm","id":2,"clk":"ALC1AgCq6wEA7JIC","pt":1743512088947,"mc":[{"id":"1.241629436","rc":[{"atl":[[90,1]],"id":40389088},{"atl":[[5,177.88]],"batl":[],"id":270592},{"atb":[[9.8,52.89]],"trd":[[9.8,937.5]],"batb":[[0,9.8,52.89]],"tv":9908.28,"id":35856222}],"tv":86512.35}]}
{"op":"mcm","id":2,"clk":"AL21AgDA6wEA8ZIC","pt":1743512089141,"mc":[{"id":"1.241629436","rc":[{"atl":[[4.7,256.31]],"batl":[[0,4.7,256.31]],"id":270592}]}]}
{"op":"mcm","id":2,"clk":"AM21AgDK6wEAgJMC","pt":1743512089250,"mc":[{"id":"1.241629436","rc":[{"atb":[[11,104.33]],"trd":[[11,278.73]],"batb":[[0,11,104.33]],"tv":6517.91,"id":40389088}],"tv":86532.36}]}
{"op":"mcm","id":2,"clk":"AOK1AgDh6wEAiJMC","pt":1743512089408,"mc":[{"id":"1.241629436","rc":[{"atl":[[7.2,150.12]],"batl":[[1,7.2,150.12]],"id":26496185}]}]}
{"op":"mcm","id":2,"clk":"AOa1AgDt6wEAkJMC","pt":1743512089502,"mc":[{"id":"1.241629436","rc":[{"atl":[[4.7,258.16]],"batl":[[0,4.7,258.16]],"id":270592}]}]}
{"op":"mcm","id":2,"clk":"AIO2AgCL7AEAppMC","pt":1743512089820,"mc":[{"id":"1.241629436","rc":[{"atb":[[6.8,246.74]],"trd":[[6.8,794.41]],"batb":[[0,6.8,246.74]],"ltp":6.8,"tv":13857.23,"id":26496185}],"tv":86536.36}]}
{"op":"mcm","id":2,"clk":"AK62AgCy7AEA55MC","pt":1743512090022,"mc":[{"id":"1.241629436","rc":[{"atb":[[6.8,231.31]],"trd":[[6.8,825.27]],"batb":[[0,6.8,231.31]],"tv":13888.09,"id":26496185}],"tv":86567.22}]}
{"op":"mcm","id":2,"clk":"ALe2AgC47AEA75MC","pt":1743512090122,"mc":[{"id":"1.241629436","rc":[{"atb":[[4.6,143.95]],"batb":[[0,4.6,143.95]],"id":270592}]}]}
{"op":"mcm","id":2,"clk":"AMO2AgDB7AEA9pMC","pt":1743512090231,"mc":[{"id":"1.241629436","rc":[{"atb":[[6.8,234.37]],"batb":[[0,6.8,234.37]],"id":26496185}]}]}
{"op":"mcm","id":2,"clk":"ANW2AgDT7AEAgpQC","pt":1743512090439,"mc":[{"id":"1.241629436","rc":[{"atl":[[7,41.1]],"batl":[[0,7,41.1]],"id":26496185}]}]}
{"op":"mcm","id":2,"clk":"AOO2AgDn7AEAj5QC","pt":1743512090643,"mc":[{"id":"1.241629436","rc":[{"atl":[[24,7.99]],"batl":[],"id":58186642},{"atl":[[7.8,91.03]],"batl":[],"id":26496185}]}]}
{"op":"mcm","id":2,"clk":"APS2AgD77AEAm5QC","pt":1743512090839,"mc":[{"id":"1.241629436","rc":[{"atl":[[5.2,223.16]],"trd":[[5.2,3817.99]],"batl":[[0,5.2,223.16]],"tv":13788.07,"id":56297029}],"tv":86581.22}]}
{"op":"mcm","id":2,"clk":"AIS3AgCO7QEAp5QC","pt":1743512091053,"mc":[{"id":"1.241629436","rc":[{"atb":[[4,53]],"atl":[[12,85.2]],"batl":[[1,12,85.2]],"id":40389088},{"atb":[[4,110.55]],"atl":[[4.7,323.16]],"batb":[],"batl":[[0,4.7,323.16]],"id":270592},{"atb":[[4,52]],"id":35856222},{"atb":[[5,9.01]],"id":59626646},{"atb":[[5,1173.39],[4,191.01]],"atl":[[5.2,136.92]],"batb":[[1,5,1173.39]],"batl":[[0,5.2,136.92]],"id":56297029},{"atb":[[4,52]],"atl":[[10.5,136.43]],"batl":[[0,10.5,136.43]],"id":27115873},{"atb":[[5,5.75]],"atl":[[19,57.32]],"batl":[[1,19,57.32]],"id":58186642},{"atb":[[4,75.47]],"id":26496185},{"atb":[[4,52]],"id":44049799}]}]}
{"op":"mcm","id":2,"clk":"AKq3AgC67QEAx5QC","pt":1743512091418,"mc":[{"id":"1.241629436","rc":[{"atl":[[4.7,165.11]],"batl":[[0,4.7,165.11]],"id":270592},{"atl":[[5.4,76.19],[6,12.39],[5.8,57.59],[5.6,39.96]],"batl":[[2,5.4,76.19]],"id":56297029}]}]}
{"op":"mcm","id":2,"clk":"ALm3AgDL7QEA0JQC","pt":1743512091526,"mc":[{"id":"1.241629436","rc":[{"atl":[[4.7,160.04]],"trd":[[4.7,2218.89]],"batl":[[0,4.7,160.04]],"ltp":4.7,"tv":21833.78,"id":270592},{"atl":[[19.5,13.57]],"batl":[[2,19.5,13.57]],"id":58186642}],"tv":86591.36}]}
{"op":"mcm","id":2,"clk":"ANW3AgDt7QEA35QC","pt":1743512091735,"mc":[{"id":"1.241629436","rc":[{"atb":[[5.1,303.42]],"atl":[[5.5,69.47]],"trd":[[5.1,4534.69]],"batb":[[0,5.1,303.42]],"batl":[],"ltp":5.1,"tv":13788.27,"id":56297029}],"tv":86591.56}]}
{"op":"mcm","id":2,"clk":"AN63AgD17QEA65QC","pt":1743512091834,"mc":[{"id":"1.241629436","rc":[{"atl":[[12,85.01],[11.5,0.96]],"batl":[[2,13,19.71],[1,12.5,60.31],[0,12,85.97]],"id":40389088},{"atb":[[4.6,140.95]],"trd":[[4.6,171.06]],"batb":[[0,4.6,140.95]],"ltp":4.6,"tv":21839.78,"id":270592},{"atl":[[10.5,75.76]],"batl":[[1,10.5,75.76]],"id":35856222},{"atl":[[5.2,141.07]],"batl":[[0,5.2,141.07]],"id":56297029},{"atb":[[18,29.2],[17.5,35.21]],"atl":[[19,48.73],[18.5,11.11]],"batb":[[1,17.5,35.21],[0,18,29.2]],"batl":[[1,19,48.73],[0,18.5,11.11]],"id":58186642}],"tv":86597.56}]}
{"op":"mcm","id":2,"clk":"AOq3AgCO7gEAiJUC","pt":1743512091945,"mc":[{"id":"1.241629436","rc":[{"atl":[[4.7,166.16]],"batl":[[0,4.7,166.16]],"id":270592},{"atb":[[9.6,61.82]],"batb":[[1,9.6,61.82]],"id":35856222}]}]}
{"op":"mcm","id":2,"clk":"APu3AgCV7gEAjpUC","pt":1743512092040,"mc":[{"id":"1.241629436","rc":[{"atl":[[12,91.35]],"batl":[[0,12,92.31]],"id":40389088},{"atl":[[5.2,77.38]],"batl":[],"id":270592}]}]}
{"op":"mcm","id":2,"clk":"AIO4AgCg7gEAlJUC","pt":1743512092144,"mc":[{"id":"1.241629436","rc":[{"atl":[[5.2,218.38]],"trd":[[5.2,3825.49]],"batl":[[0,5.2,218.38]],"ltp":5.2,"tv":13795.77,"id":56297029},{"atl":[[7.4,40.19]],"batl":[[2,7.4,40.19]],"id":26496185}],"tv":86605.06}]}
{"op":"mcm","id":2,"clk":"AI64AgCw7gEAmJUC","pt":1743512092248,"mc":[{"id":"1.241629436","rc":[{"atb":[[10,50.52]],"batb":[[0,10,50.52]],"id":27115873},{"atl":[[18.5,4.07]],"batl":[[0,18.5,4.07]],"id":58186642}]}]}
{"op":"mcm","id":2,"clk":"AJW4AgCz7gEAn5UC","pt":1743512092348,"mc":[{"id":"1.241629436","rc":[{"atl":[[5.2,229.26]],"batl":[[0,5.2,229.26]],"id":56297029}]}]}
{"op":"mcm","id":2,"clk":"AJy4AgC87gEAoZUC","pt":1743512092446,"mc":[{"id":"1.241629436","rc":[{"atl":[[19,45.71]],"batl":[[1,19,45.71]],"id":58186642}]}]}
{"op":"mcm","id":2,"clk":"AKO4AgDM7gEAqJUC","pt":1743512092552,"mc":[{"id":"1.241629436","rc":[{"atb":[[4.6,136.73]],"trd":[[4.6,179.5]],"batb":[[0,4.6,136.73]],"tv":21848.22,"id":270592}],"tv":86613.5}]}
{"op":"mcm","id":2,"clk":"AMK4AgDq7gEAvZUC","pt":1743512092816,"mc":[{"id":"1.241629436","rc":[{"atl":[[4.7,165.28]],"batl":[[0,4.7,165.28]],"id":270592}]}]}
{"op":"mcm","id":2,"clk":"AMy4AgDy7gEAxJUC","pt":1743512092915,"mc":[{"id":"1.241629436","rc":[{"atb":[[9.8,49.39]],"trd":[[9.8,944.5]],"batb":[[0,9.8,49.39]],"tv":9915.28,"id":35856222}],"tv":86620.5}]}
{"op":"mcm","id":2,"clk":"AJa5AgDC7wEAjZYC","pt":1743512093644,"mc":[{"id":"1.241629436","rc":[{"atl":[[7,25.1]],"trd":[[7,829.35]],"batl":[[0,7,25.1]],"ltp":7,"tv":13920.09,"id":26496185}],"tv":86652.5}]}
{"op":"mcm","id":2,"clk":"AKC5AgDN7wEAnZYC","pt":1743512093743,"mc":[{"id":"1.241629436","rc":[{"atl":[[4.7,181.28]],"batl":[[0,4.7,181.28]],"id":270592}]}]}
{"op":"mcm","id":2,"clk":"AK25AgDZ7wEAppYC","pt":1743512093850,"mc":[{"id":"1.241629436","rc":[{"atb":[[9.8,28.39]],"trd":[[9.8,986.5]],"batb":[[0,9.8,28.39]],"tv":9957.28,"id":35856222},{"atl":[[7,19.5]],"batl":[[0,7,19.5]],"id":26496185}],"tv":86694.5}]}
{"op":"mcm","id":2,"clk":"ALa5AgDg7wEAtJYC","pt":1743512093941,"mc":[{"id":"1.241629436","rc":[{"atb":[[55,7.95]],"trd":[[55,328.65]],"batb":[[0,55,7.95]],"tv":2011.21,"id":59626646}],"tv":86698.5}]}
{"op":"mcm","id":2,"clk":"AMW5AgDq7wEAvJYC","pt":1743512094047,"mc":[{"id":"1.241629436","rc":[{"atb":[[4.6,155.21]],"batb":[[0,4.6,155.21]],"id":270592},{"atb":[[9.8,6.82]],"batb":[[0,9.8,6.82]],"id":35856222},{"atb":[[55,9.89]],"batb":[[0,55,9.89]],"id":59626646},{"atb":[[6.4,275.7]],"batb":[[2,6.4,275.7]],"id":26496185}]}]}
{"op":"mcm","id":2,"clk":"ANi5AgD/7wEA1JYC","pt":1743512094208,"mc":[{"id":"1.241629436","rc":[{"atb":[[9.6,56.12]],"atl":[[10,101.97]],"batb":[[1,9.6,56.12]],"batl":[[0,10,101.97]],"id":35856222}]}]}
{"op":"mcm","id":2,"clk":"APG5AgCZ8AEA5JYC","pt":1743512094418,"mc":[{"id":"1.241629436","rc":[{"atb":[[9.8,0.95]],"batb":[[2,9.2,79.65],[1,9.4,61.65],[0,9.6,57.07]],"id":35856222}]}]}
{"op":"mcm","id":2,"clk":"APm5AgCp8AEA85YC","pt":1743512094515,"mc":[{"id":"1.241629436","rc":[{"atl":[[5.5,89.18]],"batl":[],"id":56297029}]}]}
{"op":"mcm","id":2,"clk":"AJK6AgC38AEAhZcC","pt":1743512094629,"mc":[{"id":"1.241629436","rc":[{"atb":[[9.4,60.35]],"batb":[[1,9.4,60.35]],"id":35856222}]}]}
{"op":"mcm","id":2,"clk":"AKS6AgDF8AEAjpcC","pt":1743512094731,"mc":[{"id":"1.241629436","rc":[{"atl":[[4.7,168.28]],"trd":[[4.7,2244.89]],"batl":[[0,4.7,168.28]],"ltp":4.7,"tv":21874.22,"id":270592}],"tv":86724.5}]}
{"op":"mcm","id":2,"clk":"AL26AgDZ8AEAnZcC","pt":1743512094934,"mc":[{"id":"1.241629436","rc":[{"atb":[[10,49.52]],"trd":[[10,659.9]],"batb":[[0,10,49.52]],"tv":7295.54,"id":27115873}],"tv":86726.5}]}
{"op":"mcm","id":2,"clk":"AL+6AgDk8AEAqpcC","pt":1743512095035,"mc":[{"id":"1.241629436","rc":[{"atb":[[4.5,180.42]],"batb":[[1,4.5,180.42]],"id":270592}]}]}
{"op":"mcm","id":2,"clk":"ANK6AgDx8AEAspcC","pt":1743512095141,"mc":[{"id":"1.241629436","rc":[{"atl":[[4.7,188.11]],"batl":[[0,4.7,188.11]],"id":270592},{"atb":[[6.8,229.37]],"trd":[[6.8,835.27]],"batb":[[0,6.8,229.37]],"ltp":6.8,"tv":13930.09,"id":26496185}],"tv":86736.5}]}
{"op":"mcm","id":2,"clk":"AJm7AgCm8QEA5JcC","pt":1743512095614,"mc":[{"id":"1.241629436","rc":[{"atb":[[4.5,183.99]],"atl":[[4.7,185.11]],"trd":[[4.7,2250.89]],"batb":[[1,4.5,183.99]],"batl":[[0,4.7,185.11]],"tv":21880.22,"id":270592},{"atb":[[5.1,290.42]],"trd":[[5.1,4560.69]],"batb":[[0,5.1,290.42]],"ltp":5.1,"tv":13821.77,"id":56297029},{"atl":[[7.8,89.13]],"batl":[],"id":26496185}],"tv":86768.5}]}
{"op":"mcm","id":2,"clk":"AKm7AgC18QEA8pcC","pt":1743512095720,"mc":[{"id":"1.241629436","rc":[{"atb":[[11,109.33]],"batb":[[0,11,109.33]],"id":40389088}]}]}
{"op":"mcm","id":2,"clk":"AP67AgCJ8gEApZgC","pt":1743512096438,"mc":[{"id":"1.241629436","rc":[{"atl":[[5,194.85]],"batl":[],"id":270592}]}]}
{"op":"mcm","id":2,"clk":"AK+8AgC28gEAzZgC","pt":1743512096848,"mc":[{"id":"1.241629436","rc":[{"atb":[[10,44.52]],"trd":[[10,669.9]],"batb":[[0,10,44.52]],"tv":7305.54,"id":27115873}],"tv":86778.5}]}
{"op":"mcm","id":2,"clk":"APW8AgDu8gEAhpkC","pt":1743512097424,"mc":[{"id":"1.241629436","rc":[{"atl":[[60,7.56]],"trd":[[60,399.89]],"batl":[[0,60,7.56]],"ltp":60,"tv":2021.71,"id":59626646},{"atl":[[5.2,230.76]],"batl":[[0,5.2,230.76]],"id":56297029},{"atl":[[7,29.58]],"batl":[[0,7,29.58]],"id":26496185}],"tv":86789}]}
{"op":"mcm","id":2,"clk":"AP68AgD38gEAjJkC","pt":1743512097522,"mc":[{"id":"1.241629436","rc":[{"atl":[[1000,0.43]],"id":40389088},{"atb":[[1.5,52]],"atl":[[60,9.29]],"batl":[[0,60,9.29]],"id":59626646},{"atb":[[5.1,289.35]],"batb":[[0,5.1,289.35]],"id":56297029},{"atb":[[18,28.1]],"atl":[[18.5,1.19]],"batb":[[0,18,28.1]],"batl":[[0,18.5,1.19]],"id":58186642},{"atb":[[6.8,223.49]],"atl":[[7,33.48]],"batb":[[0,6.8,223.49]],"batl":[[0,7,33.48]],"id":26496185}]}]}
{"op":"mcm","id":2,"clk":"AJO9AgCB8wEAmJkC","pt":1743512097631,"mc":[{"id":"1.241629436","rc":[{"atl":[[1000,0.25]],"id":40389088},{"atb":[[4.6,150.51],[1.8,4.84]],"batb":[[0,4.6,150.51]],"id":270592},{"atb":[[5,1173.01]],"atl":[[5.2,222.83]],"batb":[[1,5,1173.01]],"batl":[[0,5.2,222.83]],"id":56297029},{"atb":[[17.5,33.71]],"batb":[[1,17.5,33.71]],"id":58186642},{"atl":[[7.2,148.87]],"batl":[[1,7.2,148.87]],"id":26496185}]}]}
{"op":"mcm","id":2,"clk":"AKS9AgCJ8wEAopkC","pt":1743512097741,"mc":[{"id":"1.241629436","rc":[{"atl":[[11.5,1.14]],"batl":[[2,12.5,60.31],[1,12,91.35],[0,11.5,1.14]],"id":40389088}]}]}
{"op":"mcm","id":2,"clk":"ALG9AgCV8wEAq5kC","pt":1743512097840,"mc":[{"id":"1.241629436","rc":[{"atb":[[1.8,4.01]],"id":270592},{"atb":[[9.4,61.65]],"batb":[[1,9.4,61.65]],"id":35856222},{"atb":[[5.1,282.95]],"trd":[[5.1,4573.49]],"batb":[[0,5.1,282.95]],"tv":13834.57,"id":56297029}],"tv":86801.8}]}
{"op":"mcm","id":2,"clk":"AL+9AgCi8wEAu5kC","pt":1743512097944,"mc":[{"id":"1.241629436","rc":[{"atb":[[4,51]],"id":40389088},{"atb":[[1.8,4],[4,108.55]],"batb":[],"id":270592},{"atb":[[4,50]],"id":35856222},{"atb":[[5,7.01]],"id":59626646},{"atb":[[4,189.01]],"id":56297029},{"atb":[[4,50]],"id":27115873},{"atb":[[5,3.75]],"id":58186642},{"atb":[[4,73.47]],"id":26496185},{"atb":[[4,50]],"id":44049799}]}]}
{"op":"mcm","id":2,"clk":"ANi9AgC28wEAzpkC","pt":1743512098042,"mc":[{"id":"1.241629436","rc":[{"atl":[[4.7,185.1]],"trd":[[4.7,2250.91]],"batl":[[0,4.7,185.1]],"tv":21880.24,"id":270592}],"tv":86801.82}]}
{"op":"mcm","id":2,"clk":"APK9AgDF8wEA45kC","pt":1743512098248,"mc":[{"id":"1.241629436","rc":[{"atl":[[1000,21.99]],"id":270592}]}]}
{"op":"mcm","id":2,"clk":"APu9AgDP8wEA45kC","pt":1743512098343,"mc":[{"id":"1.241629436","rc":[{"atl":[[1000,22.05]],"id":270592}]}]}
{"op":"mcm","id":2,"clk":"AIW+AgDa8wEA75kC","pt":1743512098455,"mc":[{"id":"1.241629436","rc":[{"atl":[[1000,21.17]],"id":270592}]}]}
{"op":"mcm","id":2,"clk":"AJG+AgDp8wEA/JkC","pt":1743512098548,"mc":[{"id":"1.241629436","rc":[{"atl":[[4.7,185.98],[1000,21.16]],"batl":[[0,4.7,185.98]],"id":270592}]}]}
{"op":"mcm","id":2,"clk":"AJy+AgDx8wEAh5oC","pt":1743512098651,"mc":[{"id":"1.241629436","rc":[{"atl":[[8.4,3.56]],"id":270592}]}]}
{"op":"mcm","id":2,"clk":"ALO+AgCJ9AEAmpoC","pt":1743512098815,"mc":[{"id":"1.241629436","rc":[{"atb":[[4.1,146.09]],"atl":[[4.7,180.98]],"batb":[],"batl":[[0,4.7,180.98]],"id":270592}]}]}
{"op":"mcm","id":2,"clk":"AMC+AgCU9AEApZoC","pt":1743512098922,"mc":[{"id":"1.241629436","rc":[{"atb":[[6.6,267.3]],"batb":[[1,6.6,267.3]],"id":26496185}]}]}
{"op":"mcm","id":2,"clk":"AMy+AgCZ9AEArpoC","pt":1743512099019,"mc":[{"id":"1.241629436","rc":[{"atb":[[6.6,263.3]],"batb":[[1,6.6,263.3]],"id":26496185}]}]}
{"op":"mcm","id":2,"clk":"AOS+AgCo9AEAu5oC","pt":1743512099225,"mc":[{"id":"1.241629436","rc":[{"atl":[[10.5,133.43]],"trd":[[10.5,630.64]],"batl":[[0,10.5,133.43]],"ltp":10.5,"tv":7311.54,"id":27115873}],"tv":86807.82}]}
{"op":"mcm","id":2,"clk":"AOq+AgCw9AEAwJoC","pt":1743512099319,"mc":[{"id":"1.241629436","rc":[{"atl":[[5,201.97]],"batl":[],"id":270592},{"atb":[[10,47.67]],"batb":[[0,10,47.67]],"id":27115873}]}]}
{"op":"mcm","id":2,"clk":"APW+AgC89AEAxZoC","pt":1743512099425,"mc":[{"id":"1.241629436","rc":[{"atb":[[4.1,138.03]],"batb":[],"id":270592}]}]}
{"op":"mcm","id":2,"clk":"AP6+AgDG9AEAzZoC","pt":1743512099526,"mc":[{"id":"1.241629436","rc":[{"atb":[[1.66,3]],"id":40389088}]}]}
{"op":"mcm","id":2,"clk":"AI+/AgDe9AEA5JoC","pt":1743512099736,"mc":[{"id":"1.241629436","rc":[{"atl":[[7,21.48]],"trd":[[7,853.35]],"batl":[[0,7,21.48]],"ltp":7,"tv":13954.09,"id":26496185}],"tv":86831.82}]}
{"op":"mcm","id":2,"clk":"AJi/AgDs9AEA7JoC","pt":1743512099833,"mc":[{"id":"1.241629436","rc":[{"atl":[[4.7,193.05]],"batl":[[0,4.7,193.05]],"id":270592},{"atb":[[6.8,225.49]],"atl":[[7,17.58]],"batb":[[0,6.8,225.49]],"batl":[[0,7,17.58]],"id":26496185}]}]}
{"op":"mcm","id":2,"clk":"AKC/AgD/9AEA9poC","pt":1743512099940,"mc":[{"id":"1.241629436","rc":[{"atl":[[7.2,140.92]],"batl":[[1,7.2,140.92]],"id":26496185}]}]}
{"op":"mcm","id":2,"clk":"AMG/AgCe9QEAj5sC","pt":1743512100146,"mc":[{"id":"1.241629436","rc":[{"atb":[[6.8,227.49]],"batb":[[0,6.8,227.49]],"id":26496185}]}]}
{"op":"mcm","id":2,"clk":"AM+/AgCo9QEAl5sC","pt":1743512100250,"mc":[{"id":"1.241629436","rc":[{"atb":[[4.4,236.67]],"batb":[[2,4.4,236.67]],"id":270592}]}]}
{"op":"mcm","id":2,"clk":"AOW/AgDL9QEAtpsC","pt":1743512100556,"mc":[{"id":"1.241629436","rc":[{"atb":[[10,35.17]],"trd":[[10,694.9]],"batb":[[0,10,35.17]],"ltp":10,"tv":7336.54,"id":27115873}],"tv":86856.82}]}
{"op":"mcm","id":2,"clk":"AOu/AgDT9QEAwZsC","pt":1743512100606,"mc":[{"id":"1.241629436","rc":[{"atl":[[1000,0.49]],"id":40389088},{"atl":[[5.4,41.92]],"batl":[],"id":270592},{"atl":[[1000,0.67]],"id":35856222},{"atl":[[1000,12.86]],"id":59626646},{"atb":[[10,36.85]],"batb":[[0,10,36.85]],"id":27115873},{"atl":[[1000,2.41]],"id":58186642},{"atb":[[1.17,1.33]],"id":26496185}]}]}
{"op":"mcm","id":2,"clk":"APK/AgDf9QEAy5sC","pt":1743512100766,"mc":[{"id":"1.241629436","rc":[{"atl":[[1000,0.25],[12,146.93],[90,1.5]],"batl":[[1,12,146.93]],"id":40389088},{"atl":[[60,12.85]],"batl":[[0,60,12.85]],"id":59626646},{"atb":[[10,52.86]],"batb":[[0,10,52.86]],"id":27115873},{"atb":[[1.17,1],[6.8,226.87]],"batb":[[0,6.8,226.87]],"id":26496185},{"atl":[[12,48.33]],"batl":[[1,12,48.33]],"id":44049799}]}]}
{"op":"mcm","id":2,"clk":"APu/AgDl9QEA05sC","pt":1743512100814,"mc":[{"id":"1.241629436","rc":[{"atl":[[12,147.17]],"batl":[[1,12,147.17]],"id":40389088},{"atb":[[4.5,173.99]],"batb":[[1,4.5,173.99]],"id":270592},{"atl":[[1000,0.41]],"id":35856222},{"atl":[[5.2,218.28]],"trd":[[5.2,3834.59]],"batl":[[0,5.2,218.28]],"ltp":5.2,"tv":13843.67,"id":56297029},{"atl":[[7,17.25]],"trd":[[7,854.01]],"batl":[[0,7,17.25]],"tv":13954.75,"id":26496185}],"tv":86866.58}]}
{"op":"mcm","id":2,"clk":"AIXAAgDz9QEA2psC","pt":1743512100923,"mc":[{"id":"1.241629436","rc":[{"atl":[[10.5,76.02]],"batl":[[1,10.5,76.02]],"id":35856222},{"atb":[[7,0.33]],"atl":[[7,0]],"trd":[[7,888.51]],"batb":[[0,6.8,227.2]],"batl":[[2,7.6,87.19],[1,7.4,40.19],[0,7.2,140.92]],"tv":13989.25,"id":26496185}],"tv":86901.08}]}
{"op":"mcm","id":2,"clk":"AJ/AAgCL9gEA+ZsC","pt":1743512101023,"mc":[{"id":"1.241629436","rc":[{"atb":[[4.5,183.99]],"batb":[[1,4.5,183.99]],"id":270592},{"atb":[[9.4,60.35]],"batb":[[1,9.4,60.35]],"id":35856222},{"atl":[[19,48.69]],"batl":[[1,19,48.69]],"id":58186642},{"atb":[[7,20.49],[6.8,228.87],[6.2,155.59],[6.4,272.71]],"batb":[[2,6.6,263.3],[1,6.8,228.87],[0,7,20.49]],"id":26496185}]}]}
{"op":"mcm","id":2,"clk":"AK3AAgCV9gEA/5sC","pt":1743512101130,"mc":[{"id":"1.241629436","rc":[{"atb":[[7,27.34],[6.2,158.8]],"batb":[[0,7,27.34]],"id":26496185}]}]}
{"op":"mcm","id":2,"clk":"ALbAAgCd9gEAiJwC","pt":1743512101228,"mc":[{"id":"1.241629436","rc":[{"atb":[[7,37.99],[6,151.34]],"batb":[[0,7,37.99]],"id":26496185}]}]}
{"op":"mcm","id":2,"clk":"AMPAAgCo9gEAjZwC","pt":1743512101331,"mc":[{"id":"1.241629436","rc":[{"atb":[[55,9.95]],"batb":[[0,55,9.95]],"id":59626646}]}]}
{"op":"mcm","id":2,"clk":"ANDAAgC19gEAl5wC","pt":1743512101435,"mc":[{"id":"1.241629436","rc":[{"atb":[[6.4,275.7]],"batb":[],"id":26496185}]}]}
{"op":"mcm","id":2,"clk":"AN3AAgDE9gEAn5wC","pt":1743512101540,"mc":[{"id":"1.241629436","rc":[{"atb":[[11.5,1.86]],"atl":[[12,147.84],[11.5,0]],"trd":[[11.5,1247.4]],"batb":[[2,10.5,51.01],[1,11,109.33],[0,11.5,1.86]],"batl":[[2,13,19.71],[1,12.5,60.31],[0,12,147.84]],"ltp":11.5,"tv":6520.19,"id":40389088},{"atl":[[60,12.89]],"batl":[[0,60,12.89]],"id":59626646},{"atl":[[11.5,104.04]],"batl":[[0,11.5,104.04]],"id":44049799}],"tv":86903.36}]}
{"op":"mcm","id":2,"clk":"AOzAAgDU9gEArZwC","pt":1743512101646,"mc":[{"id":"1.241629436","rc":[{"atl":[[5.2,220.62]],"batl":[[0,5.2,220.62]],"id":56297029}]}]}
{"op":"mcm","id":2,"clk":"APfAAgDd9gEAupwC","pt":1743512101752,"mc":[{"id":"1.241629436","rc":[{"atb":[[11.5,0]],"atl":[[14.5,12.01],[14,18.66]],"trd":[[11.5,1251.12]],"batb":[[2,10,66.05],[1,10.5,51.01],[0,11,109.33]],"batl":[],"tv":6523.91,"id":40389088},{"atb":[[4.4,213.99]],"atl":[[4.7,196.05]],"batb":[[2,4.4,213.99]],"batl":[[0,4.7,196.05]],"id":270592},{"atl":[[7.4,90.19]],"batl":[[1,7.4,90.19]],"id":26496185},{"atl":[[12.5,44.59]],"batl":[[2,12.5,44.59]],"id":44049799}],"tv":86907.08}]}
{"op":"mcm","id":2,"clk":"AIfBAgDp9gEAw5wC","pt":1743512101852,"mc":[{"id":"1.241629436","rc":[{"atb":[[10.5,50.01]],"batb":[[1,10.5,50.01]],"id":40389088},{"atb":[[7,39.32],[5.8,120.96]],"batb":[[0,7,39.32]],"id":26496185}]}]}
{"op":"mcm","id":2,"clk":"AJDBAgD/9gEA0JwC","pt":1743512101954,"mc":[{"id":"1.241629436","rc":[{"atl":[[14.5,10.68],[14,17.23]],"batl":[],"id":40389088},{"atb":[[11,83.6]],"atl":[[12.5,42.77]],"trd":[[11,1657.44]],"batb":[[0,11,83.6]],"batl":[[2,12.5,42.77]],"tv":5188.96,"id":44049799}],"tv":86927.08}]}
{"op":"mcm","id":2,"clk":"AJ3BAgCR9wEA3JwC","pt":1743512102059,"mc":[{"id":"1.241629436","rc":[{"atb":[[11.5,7.44]],"batb":[[2,10.5,50.01],[1,11,109.33],[0,11.5,7.44]],"id":40389088},{"atb":[[4.6,138.45]],"batb":[[0,4.6,138.45]],"id":270592}]}]}
{"op":"mcm","id":2,"clk":"AKnBAgCY9wEA6JwC","pt":1743512102118,"mc":[{"id":"1.241629436","rc":[{"atb":[[11,113.35]],"atl":[[12.5,75.16]],"batb":[[1,11,113.35]],"batl":[[1,12.5,75.16]],"id":40389088},{"atb":[[6.6,280.02]],"batb":[[2,6.6,280.02]],"id":26496185}]}]}
{"op":"mcm","id":2,"clk":"ALXBAgCj9wEA8ZwC","pt":1743512102214,"mc":[{"id":"1.241629436","rc":[{"atb":[[11.5,18.95]],"atl":[[14.5,12.01],[14,18.66],[12.5,60.31]],"trd":[[11.5,1253.08]],"batb":[[0,11.5,18.95]],"batl":[[1,12.5,60.31]],"tv":6525.87,"id":40389088},{"atl":[[12.5,44.59]],"batl":[[2,12.5,44.59]],"id":44049799}],"tv":86929.04}]}
{"op":"mcm","id":2,"clk":"AMHBAgCw9wEA+pwC","pt":1743512102325,"mc":[{"id":"1.241629436","rc":[{"atb":[[11.5,0]],"atl":[[11.5,0.02]],"trd":[[11.5,1290.98]],"batb":[[2,10,66.05],[1,10.5,50.01],[0,11,113.35]],"batl":[[0,12,147.86]],"tv":6563.77,"id":40389088},{"atb":[[6.6,263.3]],"batb":[[2,6.6,263.3]],"id":26496185}],"tv":86966.94}]}
{"op":"mcm","id":2,"clk":"AMzBAgC+9wEAhZ0C","pt":1743512102423,"mc":[{"id":"1.241629436","rc":[{"atl":[[14.5,10.68],[14,17.23],[11.5,17.34]],"batl":[[2,12.5,60.31],[1,12,147.84],[0,11.5,17.34]],"id":40389088},{"atl":[[12.5,42.77]],"batl":[[2,12.5,42.77]],"id":44049799}]}]}
{"op":"mcm","id":2,"clk":"ANrBAgDJ9wEAk50C","pt":1743512102538,"mc":[{"id":"1.241629436","rc":[{"atb":[[10.5,51.01]],"batb":[[1,10.5,51.01]],"id":40389088},{"atb":[[4.6,150.52]],"atl":[[5,211.42],[4.8,221.14]],"batb":[[0,4.6,150.52]],"batl":[[1,4.8,221.14]],"id":270592}]}]}
{"op":"mcm","id":2,"clk":"APXBAgD19wEAqp0C","pt":1743512102848,"mc":[{"id":"1.241629436","rc":[{"atb":[[7,41.32]],"batb":[[0,7,41.32]],"id":26496185}]}]}
{"op":"mcm","id":2,"clk":"AJnCAgCf+AEAwp0C","pt":1743512103149,"mc":[{"id":"1.241629436","rc":[{"atb":[[7,43.32]],"batb":[[0,7,43.32]],"id":26496185}]}]}
{"op":"mcm","id":2,"clk":"ALTCAgC2+AEA4J0C","pt":1743512103309,"mc":[{"id":"1.241629436","rc":[{"atb":[[5.1,272.72]],"trd":[[5.1,4593.95]],"batb":[[0,5.1,272.72]],"ltp":5.1,"tv":13864.13,"id":56297029}],"tv":86987.4}]}
{"op":"mcm","id":2,"clk":"ANXCAgDb+AEAgZ4C","pt":1743512103621,"mc":[{"id":"1.241629436","rc":[{"atb":[[11,114.73]],"atl":[[1000,0.59]],"batb":[[0,11,114.73]],"id":40389088},{"atl":[[5.5,87.18]],"batl":[],"id":56297029},{"atb":[[10,54.05]],"batb":[[0,10,54.05]],"id":27115873},{"atl":[[1000,4.5]],"id":26496185}]}]}
{"op":"mcm","id":2,"clk":"AOLCAgDp+AEAip4C","pt":1743512103721,"mc":[{"id":"1.241629436","rc":[{"atb":[[6.8,228.57]],"batb":[[1,6.8,228.57]],"id":26496185}]}]}
{"op":"mcm","id":2,"clk":"AOzCAgD0+AEAlZ4C","pt":1743512103831,"mc":[{"id":"1.241629436","rc":[{"atl":[[1000,0.25]],"id":40389088},{"atl":[[1000,3.9]],"id":26496185}]}]}
{"op":"mcm","id":2,"clk":"APfCAgD/+AEAm54C","pt":1743512103933,"mc":[{"id":"1.241629436","rc":[{"atl":[[11.5,17.68]],"batl":[[0,11.5,17.68]],"id":40389088},{"atl":[[7.2,141.52]],"batl":[[0,7.2,141.52]],"id":26496185}]}]}
{"op":"mcm","id":2,"clk":"AIbDAgCK+QEAo54C","pt":1743512104031,"mc":[{"id":"1.241629436","rc":[{"atl":[[12,147.17]],"batl":[[1,12,147.17]],"id":40389088}]}]}
{"op":"mcm","id":2,"clk":"AI7DAgCT+QEAqZ4C","pt":1743512104129,"mc":[{"id":"1.241629436","rc":[{"atl":[[5.2,79.38]],"batl":[],"id":270592}]}]}
{"op":"mcm","id":2,"clk":"AKDDAgCb+QEAu54C","pt":1743512104239,"mc":[{"id":"1.241629436","rc":[{"atl":[[7.2,143.52]],"batl":[[0,7.2,143.52]],"id":26496185}]}]}
{"op":"mcm","id":2,"clk":"AKjDAgCp+QEAwZ4C","pt":1743512104335,"mc":[{"id":"1.241629436","rc":[{"atl":[[4.7,197.19]],"batl":[[0,4.7,197.19]],"id":270592},{"atb":[[5.1,275.65]],"batb":[[0,5.1,275.65]],"id":56297029},{"atl":[[7.6,90.19]],"batl":[[2,7.6,90.19]],"id":26496185}]}]}
{"op":"mcm","id":2,"clk":"ALbDAgC2+QEAyZ4C","pt":1743512104443,"mc":[{"id":"1.241629436","rc":[{"atb":[[7,45.32]],"batb":[[0,7,45.32]],"id":26496185}]}]}
{"op":"mcm","id":2,"clk":"AMLDAgDA+QEA054C","pt":1743512104542,"mc":[{"id":"1.241629436","rc":[{"atl":[[4.7,168.19]],"trd":[[4.7,2308.91]],"batl":[[0,4.7,168.19]],"tv":21938.24,"id":270592},{"atb":[[5.1,277.18]],"batb":[[0,5.1,277.18]],"id":56297029}],"tv":87045.4}]}
{"op":"mcm","id":2,"clk":"AMvDAgDN+QEA3J4C","pt":1743512104645,"mc":[{"id":"1.241629436","rc":[{"atl":[[4.7,162.06]],"batl":[[0,4.7,162.06]],"id":270592}]}]}
{"op":"mcm","id":2,"clk":"ANrDAgDr+QEA+J4C","pt":1743512104859,"mc":[{"id":"1.241629436","rc":[{"atl":[[7.4,92.19]],"batl":[[1,7.4,92.19]],"id":26496185}]}]}
{"op":"mcm","id":2,"clk":"APLDAgCA+gEAiJ8C","pt":1743512105016,"mc":[{"id":"1.241629436","rc":[{"atb":[[4.6,148.52]],"trd":[[4.6,183.5]],"batb":[[0,4.6,148.52]],"ltp":4.6,"tv":21942.24,"id":270592}],"tv":87049.4}]}
{"op":"mcm","id":2,"clk":"AJTEAgCn+gEAtp8C","pt":1743512105424,"mc":[{"id":"1.241629436","rc":[{"atl":[[10.5,76.83]],"batl":[[1,10.5,76.83]],"id":35856222},{"atl":[[7.6,92.19]],"batl":[[2,7.6,92.19]],"id":26496185}]}]}
{"op":"mcm","id":2,"clk":"AKvEAgC/+gEAyp8C","pt":1743512105691,"mc":[{"id":"1.241629436","rc":[{"atl":[[11.5,11.86]],"trd":[[11.5,1302.62]],"batl":[[0,11.5,11.86]],"tv":6575.41,"id":40389088},{"atb":[[12,23.09]],"id":58186642},{"atb":[[7,38.32]],"trd":[[7,902.51]],"batb":[[0,7,38.32]],"tv":14003.25,"id":26496185}],"tv":87075.04}]}
{"op":"mcm","id":2,"clk":"ALHEAgDG+gEA0J8C","pt":1743512105753,"mc":[{"id":"1.241629436","rc":[{"atb":[[55,8.95]],"trd":[[55,330.65]],"batb":[[0,55,8.95]],"ltp":55,"tv":2023.71,"id":59626646}],"tv":87077.04}]}
{"op":"mcm","id":2,"clk":"ALvEAgDU+gEA1Z8C","pt":1743512105849,"mc":[{"id":"1.241629436","rc":[{"atl":[[11.5,0.34]],"batl":[[2,13,19.71],[1,12.5,60.31],[0,12,147.51]],"id":40389088}]}]}
{"op":"mcm","id":2,"clk":"AN3EAgD5+gEA8J8C","pt":1743512106163,"mc":[{"id":"1.241629436","rc":[{"atl":[[4.9,290.5]],"batl":[[2,4.9,290.5]],"id":270592},{"atl":[[11,27.67]],"batl":[[2,11,27.67]],"id":35856222}]}]}
{"op":"mcm","id":2,"clk":"AOjEAgCG+wEA+J8C","pt":1743512106269,"mc":[{"id":"1.241629436","rc":[{"atl":[[7.8,91.13]],"batl":[],"id":26496185}]}]}
{"op":"mcm","id":2,"clk":"APXEAgCR+wEA/p8C","pt":1743512106321,"mc":[{"id":"1.241629436","rc":[{"atl":[[5.3,114.57]],"batl":[],"id":270592}]}]}
{"op":"mcm","id":2,"clk":"AIDFAgCh+wEAiKAC","pt":1743512106476,"mc":[{"id":"1.241629436","rc":[{"atb":[[55,0]],"atl":[[55,3.55]],"trd":[[55,348.56]],"batb":[[2,46,9.61],[1,48,11.32],[0,50,22.05]],"batl":[[2,65,2.61],[1,60,12.89],[0,55,3.55]],"tv":2041.62,"id":59626646}],"tv":87094.95}]}
{"op":"mcm","id":2,"clk":"AJ3FAgC7+wEAnaAC","pt":1743512106638,"mc":[{"id":"1.241629436","rc":[{"atl":[[12,147.84]],"batl":[[0,12,148.18]],"id":40389088},{"atb":[[4.6,149.52]],"batb":[[0,4.6,149.52]],"id":270592},{"atl":[[60,14.16],[55,4.48]],"trd":[[55,350.28]],"batl":[[1,60,14.16],[0,55,4.48]],"tv":2043.34,"id":59626646},{"atb":[[7,64.03]],"atl":[[1000,4.7]],"batb":[[0,7,64.03]],"id":26496185},{"atl":[[12.5,44.59]],"batl":[[2,12.5,44.59]],"id":44049799}],"tv":87096.67}]}
{"op":"mcm","id":2,"clk":"AKvFAgDI+wEArKAC","pt":1743512106745,"mc":[{"id":"1.241629436","rc":[{"atb":[[50,22.36]],"batb":[[0,50,22.36]],"id":59626646}]}]}
{"op":"mcm","id":2,"clk":"ALzFAgDX+wEAtKAC","pt":1743512106848,"mc":[{"id":"1.241629436","rc":[{"atb":[[13.5,30.04]],"batb":[],"id":58186642},{"atl":[[1000,3.9]],"id":26496185}]}]}
{"op":"mcm","id":2,"clk":"AMzFAgDo+wEAvKAC","pt":1743512106950,"mc":[{"id":"1.241629436","rc":[{"atl":[[7.4,92.99]],"batl":[[1,7.4,92.99]],"id":26496185}]}]}
{"op":"mcm","id":2,"clk":"ANXFAgD0+wEAwKAC","pt":1743512107050,"mc":[{"id":"1.241629436","rc":[{"atl":[[8,53.88]],"batl":[],"id":26496185}]}]}
{"op":"mcm","id":2,"clk":"AN/FAgCB/AEAxaAC","pt":1743512107148,"mc":[{"id":"1.241629436","rc":[{"atb":[[4.6,148.52]],"atl":[[5.2,85.38]],"trd":[[4.6,185.5]],"batb":[[0,4.6,148.52]],"batl":[],"tv":21944.24,"id":270592},{"atb":[[1.01,44319.07]],"id":58186642}],"tv":87098.67}]}
{"op":"mcm","id":2,"clk":"AOnFAgCL/AEA0aAC","pt":1743512107256,"mc":[{"id":"1.241629436","rc":[{"atl":[[4.7,159.59]],"trd":[[4.7,2313.85]],"batl":[[0,4.7,159.59]],"ltp":4.7,"tv":21949.18,"id":270592},{"atb":[[9.4,61.87],[9.8,71.88],[8.2,16.82]],"batb":[[1,9.8,71.88]],"id":27115873},{"atb":[[1.01,44318.07]],"id":58186642},{"atb":[[4.7,23.52],[7,60.59],[5.7,74.92],[6.8,212.65],[6,138.78]],"trd":[[7,909.39]],"batb":[[1,6.8,212.65],[0,7,60.59]],"tv":14010.13,"id":26496185}],"tv":87110.49}]}
{"op":"mcm","id":2,"clk":"APfFAgCb/AEA2qAC","pt":1743512107357,"mc":[{"id":"1.241629436","rc":[{"atb":[[9.4,49.48],[8.2,13.22],[7.2,25.11]],"batb":[[1,9.4,49.48]],"id":35856222},{"atb":[[15.5,28.01],[14.5,29.76],[12.5,20.49],[1.01,44317.07]],"batb":[],"id":58186642}]}]}
{"op":"mcm","id":2,"clk":"AIXGAgCl/AEA4qAC","pt":1743512107464,"mc":[{"id":"1.241629436","rc":[{"atb":[[38,13.77],[16,9.7]],"batb":[],"id":59626646},{"atb":[[17,43.11]],"batb":[[2,17,43.11]],"id":58186642}]}]}
{"op":"mcm","id":2,"clk":"AJHGAgCx/AEA66AC","pt":1743512107517,"mc":[{"id":"1.241629436","rc":[{"atb":[[3.9,12.53]],"batb":[],"id":270592}]}]}
{"op":"mcm","id":2,"clk":"AJzGAgC//AEA8aAC","pt":1743512107620,"mc":[{"id":"1.241629436","rc":[{"atb":[[4.6,149.52]],"batb":[[0,4.6,149.52]],"id":270592}]}]}
{"op":"mcm","id":2,"clk":"ALzGAgDZ/AEAh6EC","pt":1743512107831,"mc":[{"id":"1.241629436","rc":[{"atb":[[11,115.39]],"batb":[[0,11,115.39]],"id":40389088},{"atl":[[4.7,160.96]],"batl":[[0,4.7,160.96]],"id":270592},{"atb":[[11,84.25]],"batb":[[0,11,84.25]],"id":44049799}]}]}
{"op":"mcm","id":2,"clk":"AMfGAgDl/AEAjaEC","pt":1743512107933,"mc":[{"id":"1.241629436","rc":[{"atl":[[5.1,136.37]],"batl":[],"id":270592}]}]}
{"op":"mcm","id":2,"clk":"AP/GAgD//AEAsKEC","pt":1743512108346,"mc":[{"id":"1.241629436","rc":[{"atb":[[3,74.53]],"id":270592}]}]}
{"op":"mcm","id":2,"clk":"AIzHAgCH/QEAt6EC","pt":1743512108452,"mc":[{"id":"1.241629436","rc":[{"atl":[[7.4,42.99]],"batl":[[1,7.4,42.99]],"id":26496185}]}]}
{"op":"mcm","id":2,"clk":"AJXHAgCP/QEAv6EC","pt":1743512108551,"mc":[{"id":"1.241629436","rc":[{"atb":[[11,100.65]],"trd":[[11,308.22]],"batb":[[0,11,100.65]],"ltp":11,"tv":6604.9,"id":40389088}],"tv":87139.98}]}
{"op":"mcm","id":2,"clk":"AKLHAgCc/QEAxqEC","pt":1743512108653,"mc":[{"id":"1.241629436","rc":[{"atl":[[7.6,89.19]],"batl":[[2,7.6,89.19]],"id":26496185}]}]}
{"op":"mcm","id":2,"clk":"AKvHAgCl/QEAzaEC","pt":1743512108747,"mc":[{"id":"1.241629436","rc":[{"atl":[[11.5,18.03]],"batl":[[2,12.5,60.31],[1,12,147.84],[0,11.5,18.03]],"id":40389088}]}]}
{"op":"mcm","id":2,"clk":"AMfHAgDG/QEA8KEC","pt":1743512108990,"mc":[{"id":"1.241629436","rc":[{"atb":[[4.6,123.52]],"trd":[[4.6,237.51]],"batb":[[0,4.6,123.52]],"ltp":4.6,"tv":22001.19,"id":270592},{"atb":[[6.6,268.9]],"batb":[[2,6.6,268.9]],"id":26496185}],"con":true,"tv":87191.99}]}
{"op":"mcm","id":2,"clk":"AN7HAgDR/QEA+6EC","pt":1743512109163,"mc":[{"id":"1.241629436","rc":[{"atl":[[5,214.33]],"batl":[],"id":270592},{"atl":[[60,14.12]],"batl":[[1,60,14.12]],"id":59626646},{"atb":[[5.1,275.18]],"trd":[[5.1,4597.95]],"batb":[[0,5.1,275.18]],"tv":13868.13,"id":56297029},{"atl":[[19,45.71]],"batl":[[1,19,45.71]],"id":58186642}],"tv":87195.99}]}
{"op":"mcm","id":2,"clk":"AO3HAgDc/QEAhKIC","pt":1743512109218,"mc":[{"id":"1.241629436","rc":[{"atl":[[5,218.45]],"batl":[],"id":270592},{"atb":[[10,86.5]],"batb":[[2,10,86.5]],"id":44049799}]}]}
{"op":"mcm","id":2,"clk":"AIDIAgD2/QEAlaIC","pt":1743512109425,"mc":[{"id":"1.241629436","rc":[{"atb":[[11,99.04]],"batb":[[0,11,99.04]],"id":40389088},{"atb":[[5.1,276.71]],"batb":[[0,5.1,276.71]],"id":56297029},{"atb":[[10,52.29]],"batb":[[0,10,52.29]],"id":27115873}]}]}
{"op":"mcm","id":2,"clk":"AJjIAgCM/gEArqIC","pt":1743512109633,"mc":[{"id":"1.241629436","rc":[{"atl":[[4.8,226.51]],"batl":[[1,4.8,226.51]],"id":270592}]}]}
{"op":"mcm","id":2,"clk":"AK/IAgCb/gEAxKIC","pt":1743512109839,"mc":[{"id":"1.241629436","rc":[{"atb":[[4.6,100.37]],"trd":[[4.6,283.81]],"batb":[[0,4.6,100.37]],"tv":22047.49,"id":270592}],"tv":87242.29}]}
{"op":"mcm","id":2,"clk":"ALvIAgCj/gEA0KIC","pt":1743512109943,"mc":[{"id":"1.241629436","rc":[{"atb":[[4.4,208.89],[4.6,89.5]],"trd":[[4.6,293.23]],"batb":[[2,4.4,208.89],[0,4.6,89.5]],"tv":22056.91,"id":270592}],"tv":87251.71}]}
{"op":"mcm","id":2,"clk":"AMbIAgCu/gEA36IC","pt":1743512110050,"mc":[{"id":"1.241629436","rc":[{"atl":[[11.5,0.34]],"batl":[[2,13,19.71],[1,12.5,60.31],[0,12,148.18]],"id":40389088},{"atb":[[4.6,34]],"atl":[[5.4,43.59]],"trd":[[4.6,380.08]],"batb":[[0,4.6,34]],"batl":[],"tv":22143.76,"id":270592},{"atl":[[55,2.69]],"batl":[[0,55,2.69]],"id":59626646},{"atb":[[5.1,275.71]],"trd":[[5.1,4599.95]],"batb":[[0,5.1,275.71]],"tv":13870.13,"id":56297029}],"tv":87340.56}]}
{"op":"mcm","id":2,"clk":"AM/IAgC4/gEA6aIC","pt":1743512110147,"mc":[{"id":"1.241629436","rc":[{"atl":[[4.7,159.46]],"trd":[[4.7,2316.85]],"batl":[[0,4.7,159.46]],"ltp":4.7,"tv":22146.76,"id":270592}],"tv":87343.56}]}
{"op":"mcm","id":2,"clk":"ANzIAgDI/gEA86IC","pt":1743512110256,"mc":[{"id":"1.241629436","rc":[{"atb":[[4.6,50.38],[4.5,183.37]],"atl":[[4.7,157.44],[5,222.57]],"batb":[[1,4.5,183.37],[0,4.6,50.38]],"batl":[[0,4.7,157.44]],"id":270592},{"atb":[[5.1,272.52]],"batb":[[0,5.1,272.52]],"id":56297029}]}]}
{"op":"mcm","id":2,"clk":"AOfIAgDS/gEA+aIC","pt":1743512110358,"mc":[{"id":"1.241629436","rc":[{"atl":[[5,227.8]],"batl":[],"id":270592}]}]}
{"op":"mcm","id":2,"clk":"APnIAgDw/gEAh6MC","pt":1743512110556,"mc":[{"id":"1.241629436","rc":[{"atl":[[4.7,149.94]],"trd":[[4.7,2331.85]],"batl":[[0,4.7,149.94]],"tv":22161.76,"id":270592}],"tv":87358.56}]}
{"op":"mcm","id":2,"clk":"AITJAgD+/gEAm6MC","pt":1743512110671,"mc":[{"id":"1.241629436","rc":[{"atb":[[3.95,51.18],[4.6,44.78]],"trd":[[4.6,391.29]],"batb":[[0,4.6,44.78]],"ltp":4.6,"tv":22172.97,"id":270592}],"tv":87369.77}]}
{"op":"mcm","id":2,"clk":"AI7JAgCH/wEAoKMC","pt":1743512110723,"mc":[{"id":"1.241629436","rc":[{"atb":[[4.6,45.78]],"batb":[[0,4.6,45.78]],"id":270592}]}]}
{"op":"mcm","id":2,"clk":"AJ3JAgCO/wEAq6MC","pt":1743512110831,"mc":[{"id":"1.241629436","rc":[{"atl":[[4.7,156.09]],"batl":[[0,4.7,156.09]],"id":270592}]}]}
{"op":"mcm","id":2,"clk":"AKjJAgCY/wEAtKMC","pt":1743512110930,"mc":[{"id":"1.241629436","rc":[{"atb":[[5.8,127.96]],"batb":[],"id":26496185}]}]}
{"op":"mcm","id":2,"clk":"ALzJAgCy/wEAxaMC","pt":1743512111130,"mc":[{"id":"1.241629436","rc":[{"atb":[[4.2,103.47]],"batb":[],"id":270592}]}]}
{"op":"mcm","id":2,"clk":"ANfJAgDQ/wEA3aMC","pt":1743512111345,"mc":[{"id":"1.241629436","rc":[{"atb":[[3.9,42.5]],"batb":[],"id":270592},{"atb":[[9.8,0]],"atl":[[9.8,0.05]],"trd":[[9.8,988.4]],"batb":[[0,9.6,56.12]],"batl":[[0,10,102.02]],"tv":9959.18,"id":35856222},{"atl":[[7.2,144.87]],"batl":[[0,7.2,144.87]],"id":26496185}],"tv":87371.67}]}
{"op":"mcm","id":2,"clk":"AOXJAgDe/wEA6aMC","pt":1743512111454,"mc":[{"id":"1.241629436","rc":[{"atl":[[5.1,147.37]],"batl":[],"id":270592}]}]}
{"op":"mcm","id":2,"clk":"AKDKAgCTgAIAkqQC","pt":1743512111860,"mc":[{"id":"1.241629436","rc":[{"atb":[[6.8,212.21]],"batb":[[1,6.8,212.21]],"id":26496185}]}]}
{"op":"mcm","id":2,"clk":"ALDKAgChgAIAo6QC","pt":1743512111942,"mc":[{"id":"1.241629436","rc":[{"atl":[[4.7,153.13],[5.1,136.37]],"trd":[[4.7,2337.77]],"batl":[[0,4.7,153.13]],"ltp":4.7,"tv":22178.89,"id":270592},{"atb":[[5.1,270.25]],"trd":[[5.1,4604.49]],"batb":[[0,5.1,270.25]],"tv":13874.67,"id":56297029},{"atl":[[11.5,99.11]],"trd":[[11.5,1052.89]],"batl":[[0,11.5,99.11]],"ltp":11.5,"tv":5198.82,"id":44049799}],"tv":87391.99}]}
{"op":"mcm","id":2,"clk":"AL7KAgCsgAIAr6QC","pt":1743512112021,"mc":[{"id":"1.241629436","rc":[{"atb":[[4.4,213.99]],"batb":[[2,4.4,213.99]],"id":270592},{"atb":[[6.8,209.58]],"batb":[[1,6.8,209.58]],"id":26496185}]}]}
{"op":"mcm","id":2,"clk":"AMrKAgC4gAIAvKQC","pt":1743512112136,"mc":[{"id":"1.241629436","rc":[{"atb":[[7,63.22]],"batb":[[0,7,63.22]],"id":26496185}]}]}
{"op":"mcm","id":2,"clk":"AOnKAgDYgAIA4aQC","pt":1743512112447,"mc":[{"id":"1.241629436","rc":[{"atb":[[5,1175.13]],"atl":[[5.2,230.79]],"batb":[[1,5,1175.13]],"batl":[[0,5.2,230.79]],"id":56297029},{"atb":[[7,64.29]],"batb":[[0,7,64.29]],"id":26496185},{"atl":[[1000,19.99]],"id":44049799}]}]}
{"op":"mcm","id":2,"clk":"APTKAgDlgAIA5qQC","pt":1743512112544,"mc":[{"id":"1.241629436","rc":[{"atb":[[3.95,52.85]],"batb":[],"id":270592},{"atb":[[1.17,2.59]],"id":44049799}]}]}
{"op":"mcm","id":2,"clk":"AILLAgD0gAIA86QC","pt":1743512112650,"mc":[{"id":"1.241629436","rc":[{"atb":[[50,22.05]],"batb":[[0,50,22.05]],"id":59626646},{"atb":[[1.17,2]],"atl":[[1000,19.87]],"id":44049799}]}]}
{"op":"mcm","id":2,"clk":"AI7LAgCAgQIA+aQC","pt":1743512112745,"mc":[{"id":"1.241629436","rc":[{"atl":[[7.4,44.34]],"batl":[[1,7.4,44.34]],"id":26496185},{"atb":[[11,84.84]],"atl":[[12,48.45]],"batb":[[0,11,84.84]],"batl":[[1,12,48.45]],"id":44049799}]}]}
{"op":"mcm","id":2,"clk":"AJ3LAgCNgQIAg6UC","pt":1743512112859,"mc":[{"id":"1.241629436","rc":[{"atb":[[4.6,0],[4.5,168.42]],"trd":[[4.6,482.85],[4.5,29.92]],"batb":[[2,4.3,143],[1,4.4,213.99],[0,4.5,168.42]],"ltp":4.5,"tv":22300.37,"id":270592}],"tv":87513.47}]}
{"op":"mcm","id":2,"clk":"AK7LAgCdgQIAjqUC","pt":1743512112961,"mc":[{"id":"1.241629436","rc":[{"atb":[[7,73.01]],"batb":[[0,7,73.01]],"id":26496185}]}]}
{"op":"mcm","id":2,"clk":"ALjLAgCqgQIAoKUC","pt":1743512113068,"mc":[{"id":"1.241629436","rc":[{"atb":[[4.2,134.47],[4.5,196.28]],"atl":[[4.7,191.42]],"batb":[[0,4.5,196.28]],"batl":[[0,4.7,191.42]],"id":270592},{"atb":[[18.5,6.63]],"atl":[[18.5,0]],"trd":[[18.5,197.82]],"batb":[[2,17.5,33.71],[1,18,28.1],[0,18.5,6.63]],"batl":[[2,20,16.32],[1,19.5,13.57],[0,19,45.71]],"tv":6187.9,"id":58186642},{"atb":[[7,82.96]],"batb":[[0,7,82.96]],"id":26496185},{"atl":[[12.5,42.77]],"batl":[[2,12.5,42.77]],"id":44049799}],"tv":87515.85}]}
{"op":"mcm","id":2,"clk":"AMvLAgC2gQIAoqUC","pt":1743512113159,"mc":[{"id":"1.241629436","rc":[{"atb":[[3.85,123.46]],"atl":[[5,234.93]],"batb":[],"batl":[],"id":270592}]}]}
{"op":"mcm","id":2,"clk":"ANnLAgDDgQIArqUC","pt":1743512113231,"mc":[{"id":"1.241629436","rc":[{"atb":[[4.3,141.81]],"batb":[[2,4.3,141.81]],"id":270592},{"atl":[[19,48.74]],"batl":[[0,19,48.74]],"id":58186642}]}]}
{"op":"mcm","id":2,"clk":"AObLAgDOgQIAtKUC","pt":1743512113327,"mc":[{"id":"1.241629436","rc":[{"atb":[[4.4,208.89],[4,132.69]],"batb":[[1,4.4,208.89]],"id":270592},{"atl":[[7.6,97.09]],"batl":[[2,7.6,97.09]],"id":26496185}]}]}
{"op":"mcm","id":2,"clk":"APPLAgDbgQIAwqUC","pt":1743512113424,"mc":[{"id":"1.241629436","rc":[{"atb":[[4.2,135.69]],"atl":[[5,272.14]],"batb":[],"batl":[],"id":270592}]}]}
{"op":"mcm","id":2,"clk":"APnLAgDngQIAz6UC","pt":1743512113526,"mc":[{"id":"1.241629436","rc":[{"atb":[[1.85,5.5]],"id":270592},{"atb":[[5.1,268.25]],"trd":[[5.1,4608.49]],"batb":[[0,5.1,268.25]],"tv":13878.67,"id":56297029}],"tv":87519.85}]}
{"op":"mcm","id":2,"clk":"AJXMAgCXggIA76UC","pt":1743512113843,"mc":[{"id":"1.241629436","rc":[{"atl":[[11.5,48.31]],"batl":[],"id":35856222}]}]}
{"op":"mcm","id":2,"clk":"AKPMAgCtggIAh6YC","pt":1743512114052,"mc":[{"id":"1.241629436","rc":[{"atb":[[5.1,263.25]],"trd":[[5.1,4618.49]],"batb":[[0,5.1,263.25]],"tv":13888.67,"id":56297029},{"atb":[[18.5,5.63]],"trd":[[18.5,199.82]],"batb":[[0,18.5,5.63]],"tv":6189.9,"id":58186642},{"atb":[[7,80.96]],"trd":[[7,913.39]],"batb":[[0,7,80.96]],"tv":14014.13,"id":26496185}],"tv":87535.85}]}
{"op":"mcm","id":2,"clk":"AK/MAgC4ggIAkKYC","pt":1743512114147,"mc":[{"id":"1.241629436","rc":[{"atb":[[4.3,148.04]],"atl":[[4.7,189.42]],"trd":[[4.7,2341.77]],"batb":[[2,4.3,148.04]],"batl":[[0,4.7,189.42]],"ltp":4.7,"tv":22304.37,"id":270592},{"atl":[[5.9,21.7]],"batl":[],"id":56297029}],"tv":87539.85}]}
{"op":"mcm","id":2,"clk":"ALnMAgDGggIAnqYC","pt":1743512114252,"mc":[{"id":"1.241629436","rc":[{"atb":[[18.5,0]],"batb":[[2,17,43.11],[1,17.5,33.71],[0,18,28.1]],"id":58186642},{"atb":[[7,35.91]],"trd":[[7,1003.49]],"batb":[[0,7,35.91]],"tv":14104.23,"id":26496185}],"tv":87629.95}]}
{"op":"mcm","id":2,"clk":"AMTMAgDRggIAq6YC","pt":1743512114354,"mc":[{"id":"1.241629436","rc":[{"atb":[[10,55.64]],"batb":[[0,10,55.64]],"id":27115873},{"atb":[[7,27.19]],"batb":[[0,7,27.19]],"id":26496185}]}]}
{"op":"mcm","id":2,"clk":"ANHMAgDcggIAuKYC","pt":1743512114459,"mc":[{"id":"1.241629436","rc":[{"atl":[[4.7,199.42]],"batl":[[0,4.7,199.42]],"id":270592},{"atb":[[7,36.45]],"atl":[[7.2,152.8]],"batb":[[0,7,36.45]],"batl":[[0,7.2,152.8]],"id":26496185}]}]}
{"op":"mcm","id":2,"clk":"AN3MAgDmggIAwqYC","pt":1743512114560,"mc":[{"id":"1.241629436","rc":[{"atb":[[18.5,7.39]],"batb":[[2,17.5,33.71],[1,18,28.1],[0,18.5,7.39]],"id":58186642}]}]}
{"op":"mcm","id":2,"clk":"AObMAgDzggIA0qYC","pt":1743512114624,"mc":[{"id":"1.241629436","rc":[{"atl":[[5.2,330.79]],"batl":[[0,5.2,330.79]],"id":56297029}]}]}
{"op":"mcm","id":2,"clk":"AO7MAgCCgwIA26YC","pt":1743512114726,"mc":[{"id":"1.241629436","rc":[{"atb":[[4.6,1.16]],"batb":[[2,4.4,208.89],[1,4.5,196.28],[0,4.6,1.16]],"id":270592}]}]}
{"op":"mcm","id":2,"clk":"APbMAgCPgwIA4qYC","pt":1743512114829,"mc":[{"id":"1.241629436","rc":[{"atb":[[4.6,2.83],[4.5,199.53]],"batb":[[1,4.5,199.53],[0,4.6,2.83]],"id":270592},{"atb":[[5.1,264.39]],"batb":[[0,5.1,264.39]],"id":56297029},{"atl":[[10.5,127.93]],"batl":[[0,10.5,127.93]],"id":27115873},{"atl":[[7.2,158.62]],"batl":[[0,7.2,158.62]],"id":26496185},{"atl":[[12.5,44.59]],"batl":[[2,12.5,44.59]],"id":44049799}]}]}
{"op":"mcm","id":2,"clk":"APzMAgCdgwIA76YC","pt":1743512114932,"mc":[{"id":"1.241629436","rc":[{"atb":[[11,100.11]],"batb":[[0,11,100.11]],"id":40389088},{"atb":[[11,85.93]],"batb":[[0,11,85.93]],"id":44049799}]}]}
{"op":"mcm","id":2,"clk":"AILNAgCngwIA9KYC","pt":1743512115025,"mc":[{"id":"1.241629436","rc":[{"atl":[[1000,13.16]],"id":59626646},{"atl":[[1000,3.01]],"id":58186642}]}]}
{"op":"mcm","id":2,"clk":"AIrNAgCxgwIAgKcC","pt":1743512115143,"mc":[{"id":"1.241629436","rc":[{"atb":[[7,49.11]],"batb":[[0,7,49.11]],"id":26496185}]}]}
{"op":"mcm","id":2,"clk":"AJXNAgC2gwIAh6cC","pt":1743512115235,"mc":[{"id":"1.241629436","rc":[{"atl":[[10.5,133.42]],"batl":[[0,10.5,133.42]],"id":27115873}]}]}
{"op":"mcm","id":2,"clk":"AJ7NAgDBgwIAkacC","pt":1743512115337,"mc":[{"id":"1.241629436","rc":[{"atl":[[5,274.36]],"batl":[],"id":270592}]}]}
{"op":"mcm","id":2,"clk":"AKnNAgDNgwIAnacC","pt":1743512115450,"mc":[{"id":"1.241629436","rc":[{"atl":[[5,276.26]],"batl":[],"id":270592}]}]}
{"op":"mcm","id":2,"clk":"AMjNAgDkgwIAuKcC","pt":1743512115754,"mc":[{"id":"1.241629436","rc":[{"atb":[[4.4,54.86]],"batb":[],"id":56297029}]}]}
{"op":"mcm","id":2,"clk":"ANDNAgDugwIAwKcC","pt":1743512115856,"mc":[{"id":"1.241629436","rc":[{"atl":[[10.5,76.57]],"batl":[[1,10.5,76.57]],"id":35856222},{"atb":[[5,1173.01],[5.1,262.86]],"atl":[[5.2,320.62]],"batb":[[1,5,1173.01],[0,5.1,262.86]],"batl":[[0,5.2,320.62]],"id":56297029},{"atb":[[7,53.99]],"batb":[[0,7,53.99]],"id":26496185},{"atl":[[1000,20.02]],"id":44049799}]}]}
{"op":"mcm","id":2,"clk":"AOPNAgCEhAIA0acC","pt":1743512116062,"mc":[{"id":"1.241629436","rc":[{"atb":[[4.2,134.47]],"batb":[],"id":270592},{"atl":[[10.5,127.93]],"batl":[[0,10.5,127.93]],"id":27115873},{"atl":[[7.6,98.44]],"batl":[[2,7.6,98.44]],"id":26496185},{"atl":[[1000,19.87]],"id":44049799}]}]}
{"op":"mcm","id":2,"clk":"AOrNAgCFhAIA1KcC","pt":1743512116156,"mc":[{"id":"1.241629436","rc":[{"atb":[[4.6,5.05],[4.3,149.24]],"batb":[[0,4.6,5.05]],"id":270592},{"atl":[[11.5,99.26]],"batl":[[0,11.5,99.26]],"id":44049799}]}]}
{"op":"mcm","id":2,"clk":"APXNAgCMhAIA2qcC","pt":1743512116267,"mc":[{"id":"1.241629436","rc":[{"atl":[[4.7,219.42]],"batl":[[0,4.7,219.42]],"id":270592},{"atb":[[7,45.99]],"trd":[[7,1019.49]],"batb":[[0,7,45.99]],"tv":14120.23,"id":26496185}],"tv":87645.95}]}
{"op":"mcm","id":2,"clk":"AKLOAgC4hAIAiagC","pt":1743512116737,"mc":[{"id":"1.241629436","rc":[{"atb":[[7,64.09]],"batb":[[0,7,64.09]],"id":26496185}]}]}
{"op":"mcm","id":2,"clk":"ALDOAgDAhAIAkqgC","pt":1743512116840,"mc":[{"id":"1.241629436","rc":[{"atb":[[9.6,62.52]],"batb":[[0,9.6,62.52]],"id":35856222}]}]}
{"op":"mcm","id":2,"clk":"ALjOAgDLhAIAl6gC","pt":1743512116942,"mc":[{"id":"1.241629436","rc":[{"atl":[[10.5,110.38]],"trd":[[10.5,665.75]],"batl":[[0,10.5,110.38]],"ltp":10.5,"tv":7371.65,"id":27115873}],"tv":87681.06}]}
{"op":"mcm","id":2,"clk":"AMPOAgDThAIAo6gC","pt":1743512117047,"mc":[{"id":"1.241629436","rc":[{"atl":[[4.7,218.42]],"trd":[[4.7,2343.77]],"batl":[[0,4.7,218.42]],"tv":22306.37,"id":270592},{"atb":[[50,22.77]],"batb":[[0,50,22.77]],"id":59626646},{"atb":[[5.1,262.28]],"atl":[[5.3,93.86]],"batb":[[0,5.1,262.28]],"batl":[[1,5.3,93.86]],"id":56297029},{"atb":[[10,66.89]],"batb":[[0,10,66.89]],"id":27115873},{"atb":[[18.5,13.29]],"batb":[[0,18.5,13.29]],"id":58186642}],"tv":87683.06}]}
{"op":"mcm","id":2,"clk":"ANDOAgDchAIArKgC","pt":1743512117155,"mc":[{"id":"1.241629436","rc":[{"atb":[[1.85,27.5]],"id":40389088},{"atb":[[1.85,27.5]],"id":270592},{"atb":[[1.85,27.5]],"id":35856222},{"atb":[[2.52,22]],"id":59626646},{"atb":[[1.81,22],[5.1,261.28]],"trd":[[5.1,4620.49]],"batb":[[0,5.1,261.28]],"tv":13890.67,"id":56297029},{"atb":[[1.85,27.5],[10,80.9]],"batb":[[0,10,80.9]],"id":27115873},{"atb":[[1.85,27.5]],"id":58186642},{"atb":[[1.81,22]],"id":26496185},{"atb":[[1.85,27.5]],"id":44049799}],"tv":87685.06}]}
{"op":"mcm","id":2,"clk":"AObOAgDwhAIAu6gC","pt":1743512117361,"mc":[{"id":"1.241629436","rc":[{"atb":[[18.5,14.29]],"batb":[[0,18.5,14.29]],"id":58186642}]}]}
{"op":"mcm","id":2,"clk":"AO/OAgD7hAIAvqgC","pt":1743512117457,"mc":[{"id":"1.241629436","rc":[{"atb":[[4.6,15.05]],"batb":[[0,4.6,15.05]],"id":270592}]}]}
{"op":"mcm","id":2,"clk":"AITPAgCQhQIAy6gC","pt":1743512117670,"mc":[{"id":"1.241629436","rc":[{"atl":[[12,142.36],[11.5,0]],"trd":[[12,1391.27],[11.5,1303.29]],"batl":[[0,12,142.36]],"ltp":12,"tv":6616.52,"id":40389088},{"atb":[[18.5,8.47]],"trd":[[18.5,211.46]],"batb":[[0,18.5,8.47]],"tv":6201.54,"id":58186642}],"tv":87708.32}]}
{"op":"mcm","id":2,"clk":"AI3PAgCahQIA1KgC","pt":1743512117720,"mc":[{"id":"1.241629436","rc":[{"atb":[[4.6,14.05]],"trd":[[4.6,484.85]],"batb":[[0,4.6,14.05]],"ltp":4.6,"tv":22308.37,"id":270592}],"tv":87710.32}]}
{"op":"mcm","id":2,"clk":"AJXPAgClhQIA26gC","pt":1743512117824,"mc":[{"id":"1.241629436","rc":[{"atb":[[10.5,50.01]],"batb":[[1,10.5,50.01]],"id":40389088},{"atl":[[4.9,280.5]],"batl":[[2,4.9,280.5]],"id":270592},{"atl":[[13,10.09]],"batl":[],"id":27115873},{"atb":[[18.5,6.9]],"batb":[[0,18.5,6.9]],"id":58186642}]}]}
{"op":"mcm","id":2,"clk":"AJ3PAgCthQIA5KgC","pt":1743512117971,"mc":[{"id":"1.241629436","rc":[{"atb":[[11.5,1]],"batb":[[2,10.5,50.01],[1,11,100.11],[0,11.5,1]],"id":40389088},{"atl":[[4.8,236.51]],"batl":[[1,4.8,236.51]],"id":270592}]}]}
{"op":"mcm","id":2,"clk":"AKvPAgDAhQIA9agC","pt":1743512118131,"mc":[{"id":"1.241629436","rc":[{"atl":[[14.5,12.01],[14,18.66]],"batl":[],"id":40389088},{"atl":[[4.7,217.42]],"trd":[[4.7,2345.77]],"batl":[[0,4.7,217.42]],"ltp":4.7,"tv":22310.37,"id":270592},{"atb":[[7,62.76]],"batb":[[0,7,62.76]],"id":26496185}],"tv":87712.32}]}
{"op":"mcm","id":2,"clk":"AN3PAgDihQIAoakC","pt":1743512118545,"mc":[{"id":"1.241629436","rc":[{"atb":[[18.5,1.99]],"trd":[[18.5,221.29]],"batb":[[0,18.5,1.99]],"tv":6211.37,"id":58186642}],"tv":87722.15}]}
{"op":"mcm","id":2,"clk":"AOfPAgDqhQIAqKkC","pt":1743512118645,"mc":[{"id":"1.241629436","rc":[{"atb":[[6.8,205.58]],"batb":[[1,6.8,205.58]],"id":26496185}]}]}
{"op":"mcm","id":2,"clk":"APHPAgD4hQIAsakC","pt":1743512118751,"mc":[{"id":"1.241629436","rc":[{"atb":[[18.5,0]],"atl":[[18.5,7.61]],"trd":[[18.5,225.27]],"batb":[[2,17,43.11],[1,17.5,33.71],[0,18,28.1]],"batl":[[2,19.5,13.57],[1,19,48.74],[0,18.5,7.61]],"tv":6215.35,"id":58186642},{"atb":[[6.8,203.58]],"batb":[[1,6.8,203.58]],"id":26496185}],"tv":87726.13}]}
{"op":"mcm","id":2,"clk":"APvPAgD8hQIAuakC","pt":1743512118855,"mc":[{"id":"1.241629436","rc":[{"atb":[[11.5,13.5]],"batb":[[0,11.5,13.5]],"id":40389088},{"atb":[[1.17,1.99]],"id":270592},{"atb":[[9.6,64.19]],"batb":[[0,9.6,64.19]],"id":35856222},{"atb":[[18,27.36]],"atl":[[19,55.81]],"batb":[[0,18,27.36]],"batl":[[1,19,55.81]],"id":58186642},{"atb":[[7,72.81]],"batb":[[0,7,72.81]],"id":26496185}]}]}
{"op":"mcm","id":2,"clk":"AILQAgCDhgIAwakC","pt":1743512118957,"mc":[{"id":"1.241629436","rc":[{"atb":[[1.17,1]],"id":270592}]}]}
{"op":"mcm","id":2,"clk":"AIvQAgCIhgIAx6kC","pt":1743512119060,"mc":[{"id":"1.241629436","rc":[{"atb":[[11.5,12.5]],"batb":[[0,11.5,12.5]],"id":40389088},{"atb":[[4.6,15.04]],"batb":[[0,4.6,15.04]],"id":270592}]}]}
{"op":"mcm","id":2,"clk":"AJXQAgCQhgIA0KkC","pt":1743512119161,"mc":[{"id":"1.241629436","rc":[{"atb":[[10.5,58.23]],"batb":[[2,10.5,58.23]],"id":40389088}]}]}
{"op":"mcm","id":2,"clk":"AJvQAgCVhgIA16kC","pt":1743512119264,"mc":[{"id":"1.241629436","rc":[{"atb":[[11.5,0]],"batb":[[2,10,66.05],[1,10.5,58.23],[0,11,100.11]],"id":40389088},{"atl":[[4.7,216.42]],"trd":[[4.7,2347.77]],"batl":[[0,4.7,216.42]],"tv":22312.37,"id":270592}],"tv":87728.13}]}
{"op":"mcm","id":2,"clk":"AKTQAgCfhgIA46kC","pt":1743512119367,"mc":[{"id":"1.241629436","rc":[{"atl":[[18.5,14.47]],"batl":[[0,18.5,14.47]],"id":58186642},{"atb":[[7,74.81]],"batb":[[0,7,74.81]],"id":26496185}]}]}
{"op":"mcm","id":2,"clk":"AKvQAgCrhgIA7akC","pt":1743512119422,"mc":[{"id":"1.241629436","rc":[{"atb":[[11.5,1],[10.5,50.01]],"atl":[[14.5,10.68],[14,17.23]],"batb":[[2,10.5,50.01],[1,11,100.11],[0,11.5,1]],"batl":[],"id":40389088},{"atb":[[9.6,63.19]],"trd":[[9.6,616.2]],"batb":[[0,9.6,63.19]],"ltp":9.6,"tv":9961.18,"id":35856222}],"tv":87730.13}]}
{"op":"mcm","id":2,"clk":"ALTQAgC3hgIA+akC","pt":1743512119530,"mc":[{"id":"1.241629436","rc":[{"atb":[[11.5,13.5]],"atl":[[14.5,12.01],[14,18.66]],"batb":[[0,11.5,13.5]],"batl":[],"id":40389088}]}]}
{"op":"mcm","id":2,"clk":"AL3QAgDAhgIAg6oC","pt":1743512119631,"mc":[{"id":"1.241629436","rc":[{"atb":[[4.6,17.47]],"batb":[[0,4.6,17.47]],"id":270592}]}]}
{"op":"mcm","id":2,"clk":"AMXQAgDLhgIAiKoC","pt":1743512119730,"mc":[{"id":"1.241629436","rc":[{"atb":[[11.5,12.5]],"batb":[[0,11.5,12.5]],"id":40389088},{"atb":[[7,76.81]],"batb":[[0,7,76.81]],"id":26496185}]}]}
{"op":"mcm","id":2,"clk":"ANLQAgDZhgIAkqoC","pt":1743512119839,"mc":[{"id":"1.241629436","rc":[{"atb":[[11.5,0]],"batb":[[2,10,66.05],[1,10.5,50.01],[0,11,100.11]],"id":40389088}]}]}
{"op":"mcm","id":2,"clk":"ANnQAgDihgIAl6oC","pt":1743512119941,"mc":[{"id":"1.241629436","rc":[{"atb":[[11.5,1]],"batb":[[2,10.5,50.01],[1,11,100.11],[0,11.5,1]],"id":40389088}]}]}
{"op":"mcm","id":2,"clk":"AOPQAgDohgIAnqoC","pt":1743512120040,"mc":[{"id":"1.241629436","rc":[{"atb":[[11.5,13.5]],"atl":[[14.5,10.68],[14,17.23]],"batb":[[0,11.5,13.5]],"batl":[],"id":40389088},{"atl":[[18.5,17.47]],"batl":[[0,18.5,17.47]],"id":58186642}]}]}
{"op":"mcm","id":2,"clk":"AOfQAgDwhgIAoaoC","pt":1743512120140,"mc":[{"id":"1.241629436","rc":[{"atl":[[14.5,12.01],[14,18.66]],"batl":[],"id":40389088},{"atl":[[4.9,290.5]],"batl":[[2,4.9,290.5]],"id":270592},{"atb":[[18,25.96]],"trd":[[18,265.35]],"batb":[[0,18,25.96]],"ltp":18,"tv":6218.15,"id":58186642}],"tv":87732.93}]}
{"op":"mcm","id":2,"clk":"APTQAgD4hgIAraoC","pt":1743512120250,"mc":[{"id":"1.241629436","rc":[{"atb":[[11.5,12.5]],"batb":[[0,11.5,12.5]],"id":40389088}]}]}
{"op":"mcm","id":2,"clk":"AI7RAgCLhwIAvqoC","pt":1743512120468,"mc":[{"id":"1.241629436","rc":[{"atb":[[11.5,0]],"batb":[[2,10,66.05],[1,10.5,50.01],[0,11,100.11]],"id":40389088},{"atl":[[4.7,215.42]],"trd":[[4.7,2349.77]],"batl":[[0,4.7,215.42]],"tv":22314.37,"id":270592}],"tv":87734.93}]}
{"op":"mcm","id":2,"clk":"AJnRAgCXhwIAwqoC","pt":1743512120562,"mc":[{"id":"1.241629436","rc":[{"atl":[[7.8,92.48]],"batl":[],"id":26496185}]}]}
{"op":"mcm","id":2,"clk":"AKbRAgCehwIAzaoC","pt":1743512120664,"mc":[{"id":"1.241629436","rc":[{"atb":[[11.5,1]],"atl":[[14.5,10.68],[14,17.23]],"batb":[[2,10.5,50.01],[1,11,100.11],[0,11.5,1]],"batl":[],"id":40389088}]}]}
{"op":"mcm","id":2,"clk":"ALPRAgCmhwIA0qoC","pt":1743512120765,"mc":[{"id":"1.241629436","rc":[{"atl":[[12,86.78]],"batl":[[0,12,86.78]],"id":40389088},{"atb":[[9.6,62.19]],"trd":[[9.6,618.2]],"batb":[[0,9.6,62.19]],"tv":9963.18,"id":35856222}],"tv":87736.93}]}
{"op":"mcm","id":2,"clk":"AL7RAgCwhwIA3KoC","pt":1743512120873,"mc":[{"id":"1.241629436","rc":[{"atb":[[11.5,13.5],[11,117.36]],"atl":[[14.5,12.01],[14,18.66],[12,86.54]],"batb":[[1,11,117.36],[0,11.5,13.5]],"batl":[[0,12,86.54]],"id":40389088},{"atb":[[4.6,22.59]],"batb":[[0,4.6,22.59]],"id":270592},{"atb":[[9.6,60.52]],"batb":[[0,9.6,60.52]],"id":35856222},{"atl":[[55,14.82]],"batl":[[0,55,14.82]],"id":59626646},{"atb":[[5.1,262.66]],"batb":[[0,5.1,262.66]],"id":56297029},{"atb":[[10,79.79]],"atl":[[10.5,110.14]],"batb":[[0,10,79.79]],"batl":[[0,10.5,110.14]],"id":27115873},{"atb":[[18,24.51]],"atl":[[19,48.74],[18.5,53.52]],"batb":[[0,18,24.51]],"batl":[[1,19,48.74],[0,18.5,53.52]],"id":58186642},{"atb":[[7,87.06]],"atl":[[7.4,43.54],[7.2,158.02]],"batb":[[0,7,87.06]],"batl":[[1,7.4,43.54],[0,7.2,158.02]],"id":26496185},{"atb":[[11,85.34]],"atl":[[12,48.33],[11.5,99.11]],"batb":[[0,11,85.34]],"batl":[[1,12,48.33],[0,11.5,99.11]],"id":44049799}]}]}
{"op":"mcm","id":2,"clk":"ANXRAgDOhwIA6qoC","pt":1743512121035,"mc":[{"id":"1.241629436","rc":[{"atb":[[11.5,17.02]],"atl":[[12,67.63]],"batb":[[0,11.5,17.02]],"batl":[[0,12,67.63]],"id":40389088},{"atl":[[55,16.67]],"batl":[[0,55,16.67]],"id":59626646},{"atb":[[18,11.45]],"batb":[[0,18,11.45]],"id":58186642}]}]}
{"op":"mcm","id":2,"clk":"AOHRAgDdhwIA8KoC","pt":1743512121138,"mc":[{"id":"1.241629436","rc":[{"atb":[[8.4,59.67]],"batb":[],"id":27115873},{"atb":[[18,6.82]],"atl":[[18.5,59.67]],"batb":[[0,18,6.82]],"batl":[[0,18.5,59.67]],"id":58186642},{"atb":[[7,89.06]],"batb":[[0,7,89.06]],"id":26496185}]}]}
{"op":"mcm","id":2,"clk":"AOvRAgDuhwIA96oC","pt":1743512121239,"mc":[{"id":"1.241629436","rc":[{"atb":[[17.5,24.86]],"batb":[[1,17.5,24.86]],"id":58186642}]}]}
{"op":"mcm","id":2,"clk":"APrRAgD5hwIAgqsC","pt":1743512121347,"mc":[{"id":"1.241629436","rc":[{"atb":[[11.5,19.08]],"batb":[[0,11.5,19.08]],"id":40389088},{"atb":[[4.6,27.75]],"batb":[[0,4.6,27.75]],"id":270592},{"atb":[[9.8,2.37]],"atl":[[9.8,0]],"trd":[[9.8,988.5]],"batb":[[2,9.4,49.48],[1,9.6,60.52],[0,9.8,2.37]],"batl":[[0,10,101.97]],"ltp":9.8,"tv":9963.28,"id":35856222},{"atb":[[50,23.24]],"batb":[[0,50,23.24]],"id":59626646},{"atb":[[5.1,267.31]],"batb":[[0,5.1,267.31]],"id":56297029},{"atb":[[10,82.16]],"batb":[[0,10,82.16]],"id":27115873},{"atb":[[18,0]],"atl":[[18,6.56]],"trd":[[18,281.63]],"batb":[[2,16.5,19.98],[1,17,43.11],[0,17.5,24.86]],"batl":[[2,19,48.74],[1,18.5,59.67],[0,18,6.56]],"tv":6234.43,"id":58186642},{"atb":[[7,92.45]],"batb":[[0,7,92.45]],"id":26496185},{"atb":[[11,87.5]],"batb":[[0,11,87.5]],"id":44049799}],"tv":87753.31}]}
{"op":"mcm","id":2,"clk":"AIjSAgCBiAIAiKsC","pt":1743512121454,"mc":[{"id":"1.241629436","rc":[{"atb":[[4.6,25.53]],"batb":[[0,4.6,25.53]],"id":270592},{"atb":[[17.5,22.61]],"batb":[[0,17.5,22.61]],"id":58186642}]}]}
{"op":"mcm","id":2,"clk":"AJfSAgCNiAIAk6sC","pt":1743512121563,"mc":[{"id":"1.241629436","rc":[{"atb":[[4.6,22.86]],"atl":[[4.7,214.42]],"trd":[[4.7,2351.77],[4.6,490.17]],"batb":[[0,4.6,22.86]],"batl":[[0,4.7,214.42]],"ltp":4.6,"tv":22321.69,"id":270592},{"atb":[[9.4,50.78]],"batb":[[2,9.4,50.78]],"id":35856222},{"atl":[[5.2,318.62]],"trd":[[5.2,3838.59]],"batl":[[0,5.2,318.62]],"ltp":5.2,"tv":13894.67,"id":56297029}],"tv":87764.63}]}
{"op":"mcm","id":2,"clk":"AKTSAgCYiAIAmqsC","pt":1743512121657,"mc":[{"id":"1.241629436","rc":[{"atl":[[4.7,263.07]],"batl":[[0,4.7,263.07]],"id":270592},{"atb":[[11,86.5]],"trd":[[11,1659.44]],"batb":[[0,11,86.5]],"ltp":11,"tv":5200.82,"id":44049799}],"tv":87766.63}]}
{"op":"mcm","id":2,"clk":"ALHSAgCiiAIAoKsC","pt":1743512121760,"mc":[{"id":"1.241629436","rc":[{"atb":[[4.6,30.51]],"batb":[[0,4.6,30.51]],"id":270592}]}]}
{"op":"mcm","id":2,"clk":"AMDSAgCuiAIAp6sC","pt":1743512121864,"mc":[{"id":"1.241629436","rc":[{"atl":[[18,9.56]],"batl":[[0,18,9.56]],"id":58186642}]}]}
{"op":"mcm","id":2,"clk":"AMnSAgC5iAIAt6sC","pt":1743512121964,"mc":[{"id":"1.241629436","rc":[{"atb":[[50,23.74]],"batb":[[0,50,23.74]],"id":59626646},{"atb":[[7,91.45]],"trd":[[7,1021.49]],"batb":[[0,7,91.45]],"tv":14122.23,"id":26496185}],"tv":87768.63}]}
{"op":"mcm","id":2,"clk":"ANjSAgDCiAIAwasC","pt":1743512122067,"mc":[{"id":"1.241629436","rc":[{"atb":[[17.5,20.36]],"batb":[[0,17.5,20.36]],"id":58186642}]}]}
{"op":"mcm","id":2,"clk":"APDSAgDZiAIA1asC","pt":1743512122274,"mc":[{"id":"1.241629436","rc":[{"atb":[[3.95,48.85],[4.6,29.51]],"trd":[[4.6,492.17]],"batb":[[0,4.6,29.51]],"tv":22323.69,"id":270592}],"tv":87770.63}]}
{"op":"mcm","id":2,"clk":"APnSAgDjiAIA3asC","pt":1743512122328,"mc":[{"id":"1.241629436","rc":[{"atb":[[11,82.73]],"trd":[[11,1666.98]],"batb":[[0,11,82.73]],"tv":5208.36,"id":44049799}],"tv":87778.17}]}
{"op":"mcm","id":2,"clk":"AJPTAgD2iAIA9KsC","pt":1743512122544,"mc":[{"id":"1.241629436","rc":[{"atb":[[1.17,2.8],[11,116.1]],"atl":[[1000,0.5],[12,67.48]],"batb":[[1,11,116.1]],"batl":[[0,12,67.48]],"id":40389088},{"atb":[[1.17,1.23]],"atl":[[4.7,264.22]],"batl":[[0,4.7,264.22]],"id":270592},{"atb":[[5.1,268.7]],"atl":[[1000,5.81]],"batb":[[0,5.1,268.7]],"id":56297029}]}]}
{"op":"mcm","id":2,"clk":"AKPTAgCPiQIA/6sC","pt":1743512122736,"mc":[{"id":"1.241629436","rc":[{"atb":[[1.17,2]],"atl":[[1000,0.25]],"id":40389088},{"atb":[[1.17,1]],"id":270592},{"atb":[[9.8,21.71]],"batb":[[0,9.8,21.71]],"id":35856222},{"atl":[[1000,5.52]],"id":56297029},{"atl":[[26,1]],"id":44049799}]}]}
{"op":"mcm","id":2,"clk":"AKfTAgCciQIAh6wC","pt":1743512122844,"mc":[{"id":"1.241629436","rc":[{"atb":[[11.5,19.88]],"atl":[[12.5,60.56]],"batb":[[0,11.5,19.88]],"batl":[[1,12.5,60.56]],"id":40389088},{"atb":[[4.6,21.86],[4.5,199.76]],"batb":[[1,4.5,199.76],[0,4.6,21.86]],"id":270592},{"atb":[[9.6,66.22]],"batb":[[1,9.6,66.22]],"id":35856222},{"atl":[[5.3,94.15]],"batl":[[1,5.3,94.15]],"id":56297029},{"atb":[[17.5,15.91]],"atl":[[19,52.96]],"batb":[[0,17.5,15.91]],"batl":[[2,19,52.96]],"id":58186642}]}]}
{"op":"mcm","id":2,"clk":"ALjTAgCpiQIAk6wC","pt":1743512122950,"mc":[{"id":"1.241629436","rc":[{"atl":[[19,48.74]],"batl":[[2,19,48.74]],"id":58186642}]}]}
{"op":"mcm","id":2,"clk":"AMfTAgC6iQIAoKwC","pt":1743512123154,"mc":[{"id":"1.241629436","rc":[{"atb":[[8.2,10.44],[11,96.69]],"batb":[[1,11,96.69]],"id":40389088},{"atb":[[10,91.37]],"batb":[[0,10,91.37]],"id":27115873},{"atb":[[17.5,19.03]],"atl":[[44,1.02]],"batb":[[0,17.5,19.03]],"id":58186642}]}]}
{"op":"mcm","id":2,"clk":"ANXTAgDWiQIAt6wC","pt":1743512123369,"mc":[{"id":"1.241629436","rc":[{"atl":[[10.5,107.42]],"batl":[[0,10.5,107.42]],"id":27115873}]}]}
{"op":"mcm","id":2,"clk":"AOjTAgDuiQIAw6wC","pt":1743512123568,"mc":[{"id":"1.241629436","rc":[{"atb":[[11.5,18.88]],"trd":[[11.5,1305.29]],"batb":[[0,11.5,18.88]],"ltp":11.5,"tv":6618.52,"id":40389088},{"atb":[[46,9.01]],"batb":[[2,46,9.01]],"id":59626646}],"tv":87780.17}]}
{"op":"mcm","id":2,"clk":"APTTAgD0iQIA0awC","pt":1743512123665,"mc":[{"id":"1.241629436","rc":[{"atb":[[4.5,196.19]],"batb":[[1,4.5,196.19]],"id":270592},{"atb":[[44,5.43]],"batb":[],"id":59626646}]}]}
{"op":"mcm","id":2,"clk":"AIHUAgCBigIA2awC","pt":1743512123771,"mc":[{"id":"1.241629436","rc":[{"atl":[[90,1]],"id":40389088}]}]}
{"op":"mcm","id":2,"clk":"AIvUAgCMigIA5qwC","pt":1743512123825,"mc":[{"id":"1.241629436","rc":[{"atb":[[11.5,18.38]],"trd":[[11.5,1306.29]],"batb":[[0,11.5,18.38]],"tv":6619.52,"id":40389088},{"atl":[[4.7,263.22]],"trd":[[4.7,2353.77]],"batl":[[0,4.7,263.22]],"ltp":4.7,"tv":22325.69,"id":270592},{"atb":[[5,1174.9]],"atl":[[5.2,327.79]],"batb":[[1,5,1174.9]],"batl":[[0,5.2,327.79]],"id":56297029}],"tv":87783.17}]}
{"op":"mcm","id":2,"clk":"AKHUAgCcigIAg60C","pt":1743512124035,"mc":[{"id":"1.241629436","rc":[{"atl":[[11.5,26.68]],"batl":[[2,11.5,26.68]],"id":27115873}]}]}
{"op":"mcm","id":2,"clk":"AKvUAgCfigIAja0C","pt":1743512124137,"mc":[{"id":"1.241629436","rc":[{"atb":[[10,89.37]],"trd":[[10,698.9]],"batb":[[0,10,89.37]],"ltp":10,"tv":7375.65,"id":27115873}],"tv":87787.17}]}
{"op":"mcm","id":2,"clk":"ALfUAgCpigIAlK0C","pt":1743512124242,"mc":[{"id":"1.241629436","rc":[{"atb":[[4.6,29.17]],"batb":[[0,4.6,29.17]],"id":270592},{"atb":[[50,18.82]],"trd":[[50,67.73]],"batb":[[0,50,18.82]],"ltp":50,"tv":2053.18,"id":59626646},{"atl":[[10.5,112.89]],"batl":[[0,10.5,112.89]],"id":27115873}],"tv":87797.01}]}
{"op":"mcm","id":2,"clk":"AMPUAgCwigIAm60C","pt":1743512124342,"mc":[{"id":"1.241629436","rc":[{"atb":[[50,21.82]],"batb":[[0,50,21.82]],"id":59626646}]}]}
{"op":"mcm","id":2,"clk":"ANHUAgC4igIApq0C","pt":1743512124448,"mc":[{"id":"1.241629436","rc":[{"atl":[[1000,12.86]],"id":59626646},{"atl":[[1000,2.41],[18,34.56]],"batl":[[0,18,34.56]],"id":58186642},{"atb":[[7,16.45]],"trd":[[7,1171.49]],"batb":[[0,7,16.45]],"tv":14272.23,"id":26496185}],"tv":87947.01}]}
{"op":"mcm","id":2,"clk":"ANzUAgDAigIAr60C","pt":1743512124553,"mc":[{"id":"1.241629436","rc":[{"atb":[[9.8,27.12]],"batb":[[0,9.8,27.12]],"id":35856222},{"atl":[[55,16.97]],"batl":[[0,55,16.97]],"id":59626646},{"atb":[[5.1,279.59]],"batb":[[0,5.1,279.59]],"id":56297029},{"atl":[[18.5,56.56],[18,35.16]],"batl":[[1,18.5,56.56],[0,18,35.16]],"id":58186642},{"atb":[[7,36.95]],"batb":[[0,7,36.95]],"id":26496185}]}]}
{"op":"mcm","id":2,"clk":"AOzUAgDMigIAuK0C","pt":1743512124654,"mc":[{"id":"1.241629436","rc":[{"atb":[[11.5,19.38]],"batb":[[0,11.5,19.38]],"id":40389088},{"atb":[[17.5,20.03]],"atl":[[18.5,59.74]],"batb":[[0,17.5,20.03]],"batl":[[1,18.5,59.74]],"id":58186642},{"atb":[[7,35.95]],"trd":[[7,1173.49]],"batb":[[0,7,35.95]],"tv":14274.23,"id":26496185}],"tv":87949.01}]}
{"op":"mcm","id":2,"clk":"APPUAgDTigIAw60C","pt":1743512124752,"mc":[{"id":"1.241629436","rc":[{"atb":[[7,33.39]],"trd":[[7,1178.61]],"batb":[[0,7,33.39]],"tv":14279.35,"id":26496185},{"atl":[[11.5,94.11]],"trd":[[11.5,1062.89]],"batl":[[0,11.5,94.11]],"ltp":11.5,"tv":5218.36,"id":44049799}],"tv":87964.13}]}
{"op":"mcm","id":2,"clk":"AP7UAgDhigIA1a0C","pt":1743512124863,"mc":[{"id":"1.241629436","rc":[{"atl":[[7.2,159.96]],"batl":[[0,7.2,159.96]],"id":26496185}]}]}
{"op":"mcm","id":2,"clk":"AInVAgDnigIA3a0C","pt":1743512124963,"mc":[{"id":"1.241629436","rc":[{"atb":[[11.5,17.38]],"trd":[[11.5,1310.29]],"batb":[[0,11.5,17.38]],"tv":6623.52,"id":40389088},{"atl":[[5.2,135.38]],"batl":[],"id":270592},{"atl":[[7.2,161.9]],"batl":[[0,7.2,161.9]],"id":26496185},{"atl":[[11.5,85.75]],"batl":[[0,11.5,85.75]],"id":44049799}],"tv":87968.13}]}
{"op":"mcm","id":2,"clk":"AJjVAgD0igIA5q0C","pt":1743512125061,"mc":[{"id":"1.241629436","rc":[{"atb":[[11,99.09]],"batb":[[0,11,99.09]],"id":44049799}]}]}
{"op":"mcm","id":2,"clk":"AKXVAgD8igIA8a0C","pt":1743512125176,"mc":[{"id":"1.241629436","rc":[{"atl":[[4.7,262.22]],"trd":[[4.7,2355.77]],"batl":[[0,4.7,262.22]],"tv":22327.69,"id":270592}],"tv":87970.13}]}
{"op":"mcm","id":2,"clk":"ANDVAgCciwIAjK4C","pt":1743512125572,"mc":[{"id":"1.241629436","rc":[{"atb":[[11.5,16.58]],"atl":[[1000,0.94],[12,69.71]],"batb":[[0,11.5,16.58]],"batl":[[0,12,69.71]],"id":40389088},{"atb":[[1.17,2.68]],"id":56297029},{"atl":[[24,6.1]],"batl":[],"id":58186642}]}]}
{"op":"mcm","id":2,"clk":"ANrVAgCoiwIAlK4C","pt":1743512125636,"mc":[{"id":"1.241629436","rc":[{"atl":[[1000,0.25]],"id":40389088},{"atb":[[1.17,2],[5.1,277.59]],"trd":[[5.1,4624.49]],"batb":[[0,5.1,277.59]],"ltp":5.1,"tv":13898.67,"id":56297029},{"atb":[[17.5,18.14]],"trd":[[17.5,245.03]],"batb":[[0,17.5,18.14]],"ltp":17.5,"tv":6238.21,"id":58186642},{"atb":[[6.6,270.8]],"batb":[[2,6.6,270.8]],"id":26496185}],"tv":87977.91}]}
{"op":"mcm","id":2,"clk":"AOPVAgC0iwIAna4C","pt":1743512125732,"mc":[{"id":"1.241629436","rc":[{"atb":[[11.5,15.89]],"trd":[[11.5,1311.67]],"batb":[[0,11.5,15.89]],"tv":6624.9,"id":40389088},{"atb":[[5.1,278.27]],"batb":[[0,5.1,278.27]],"id":56297029}],"tv":87979.29}]}
{"op":"mcm","id":2,"clk":"AO3VAgDCiwIAqq4C","pt":1743512125838,"mc":[{"id":"1.241629436","rc":[{"atl":[[4.7,182.23],[5.4,93.59]],"trd":[[4.7,2515.77]],"batl":[[0,4.7,182.23]],"tv":22487.69,"id":270592},{"atb":[[10,89.27]],"trd":[[10,699.1]],"batb":[[0,10,89.27]],"tv":7375.85,"id":27115873}],"tv":88139.49}]}
{"op":"mcm","id":2,"clk":"APTVAgDNiwIAta4C","pt":1743512125937,"mc":[{"id":"1.241629436","rc":[{"atb":[[4.6,41.4]],"atl":[[4.7,176.07]],"batb":[[0,4.6,41.4]],"batl":[[0,4.7,176.07]],"id":270592},{"atb":[[17.5,11.5]],"batb":[[0,17.5,11.5]],"id":58186642},{"atb":[[7,10.12]],"trd":[[7,1225.15]],"batb":[[0,7,10.12]],"tv":14325.89,"id":26496185}],"tv":88186.03}]}
{"op":"mcm","id":2,"clk":"AP7VAgDZiwIAxa4C","pt":1743512126042,"mc":[{"id":"1.241629436","rc":[{"atl":[[4.7,127.42]],"batl":[[0,4.7,127.42]],"id":270592},{"atb":[[17.5,8.38]],"atl":[[18,38.26]],"batb":[[0,17.5,8.38]],"batl":[[0,18,38.26]],"id":58186642}]}]}
{"op":"mcm","id":2,"clk":"AIvWAgDkiwIAyq4C","pt":1743512126146,"mc":[{"id":"1.241629436","rc":[{"atb":[[9.8,26.12]],"trd":[[9.8,990.5]],"batb":[[0,9.8,26.12]],"tv":9965.28,"id":35856222}],"tv":88188.03}]}
{"op":"mcm","id":2,"clk":"AJHWAgDwiwIA1K4C","pt":1743512126248,"mc":[{"id":"1.241629436","rc":[{"atb":[[4.5,221.19]],"batb":[[1,4.5,221.19]],"id":270592}]}]}
{"op":"mcm","id":2,"clk":"AJzWAgD5iwIA3K4C","pt":1743512126351,"mc":[{"id":"1.241629436","rc":[{"atl":[[4.7,126.42]],"trd":[[4.7,2517.77]],"batl":[[0,4.7,126.42]],"tv":22489.69,"id":270592},{"atb":[[50,20.82]],"trd":[[50,69.73]],"batb":[[0,50,20.82]],"tv":2055.18,"id":59626646}],"tv":88192.03}]}
{"op":"mcm","id":2,"clk":"AKPWAgCBjAIA5K4C","pt":1743512126453,"mc":[{"id":"1.241629436","rc":[{"atb":[[50,23.07]],"batb":[[0,50,23.07]],"id":59626646},{"atl":[[7.2,163.84]],"batl":[[0,7.2,163.84]],"id":26496185}]}]}
{"op":"mcm","id":2,"clk":"AKjWAgCIjAIA7a4C","pt":1743512126555,"mc":[{"id":"1.241629436","rc":[{"atb":[[4.6,50.4]],"atl":[[4.7,173.78]],"batb":[[0,4.6,50.4]],"batl":[[0,4.7,173.78]],"id":270592},{"atl":[[13,38.41],[12.5,42.77]],"batl":[[2,12.5,42.77]],"id":44049799}]}]}
{"op":"mcm","id":2,"clk":"ANLWAgCujAIAkq8C","pt":1743512126970,"mc":[{"id":"1.241629436","rc":[{"atb":[[9.4,55.25]],"batb":[[2,9.4,55.25]],"id":35856222},{"atb":[[1.28,13]],"id":58186642}]}]}
{"op":"mcm","id":2,"clk":"ANrWAgC+jAIAoK8C","pt":1743512127071,"mc":[{"id":"1.241629436","rc":[{"atl":[[4.7,157.71]],"trd":[[4.7,2549.91]],"batl":[[0,4.7,157.71]],"tv":22521.83,"id":270592}],"tv":88224.17}]}
{"op":"mcm","id":2,"clk":"AOPWAgDKjAIArq8C","pt":1743512127128,"mc":[{"id":"1.241629436","rc":[{"atb":[[6.6,272.7]],"batb":[[2,6.6,272.7]],"id":26496185}]}]}
{"op":"mcm","id":2,"clk":"AOvWAgDXjAIAv68C","pt":1743512127242,"mc":[{"id":"1.241629436","rc":[{"atb":[[4.4,246.89]],"batb":[[2,4.4,246.89]],"id":270592},{"atb":[[10,79.27]],"trd":[[10,719.1]],"batb":[[0,10,79.27]],"tv":7395.85,"id":27115873}],"tv":88244.17}]}
{"op":"mcm","id":2,"clk":"APLWAgDljAIAzq8C","pt":1743512127351,"mc":[{"id":"1.241629436","rc":[{"atb":[[16.5,22.27]],"batb":[[2,16.5,22.27]],"id":58186642}]}]}
{"op":"mcm","id":2,"clk":"AP7WAgDyjAIA268C","pt":1743512127442,"mc":[{"id":"1.241629436","rc":[{"atb":[[10,84.74]],"batb":[[0,10,84.74]],"id":27115873},{"atl":[[18.5,56.56]],"batl":[[1,18.5,56.56]],"id":58186642},{"atl":[[11.5,80.77]],"batl":[[0,11.5,80.77]],"id":44049799}]}]}
{"op":"mcm","id":2,"clk":"AInXAgD+jAIA4q8C","pt":1743512127548,"mc":[{"id":"1.241629436","rc":[{"atb":[[10,79.27]],"batb":[[0,10,79.27]],"id":27115873},{"atl":[[18,35.16]],"batl":[[0,18,35.16]],"id":58186642}]}]}
{"op":"mcm","id":2,"clk":"AJXXAgCMjQIA7a8C","pt":1743512127653,"mc":[{"id":"1.241629436","rc":[{"atb":[[4.6,56.38]],"atl":[[5.7,107.55]],"batb":[[0,4.6,56.38]],"id":270592},{"atb":[[5.1,273.27]],"atl":[[5.2,324.21]],"trd":[[5.1,4634.49]],"batb":[[0,5.1,273.27]],"batl":[[0,5.2,324.21]],"tv":13908.67,"id":56297029},{"atl":[[1000,1.45]],"id":27115873}],"tv":88254.17}]}
{"op":"mcm","id":2,"clk":"AJ/XAgCUjQIA868C","pt":1743512127755,"mc":[{"id":"1.241629436","rc":[{"atb":[[4.6,86.38]],"batb":[[0,4.6,86.38]],"id":270592},{"atb":[[50,20.07]],"trd":[[50,75.73]],"batb":[[0,50,20.07]],"tv":2061.18,"id":59626646},{"atl":[[1000,1.16]],"id":27115873},{"atb":[[7,20]],"batb":[[0,7,20]],"id":26496185}],"tv":88260.17}]}
{"op":"mcm","id":2,"clk":"AKjXAgCijQIAg7AC","pt":1743512127859,"mc":[{"id":"1.241629436","rc":[{"atl":[[4.7,98.28]],"batl":[[0,4.7,98.28]],"id":270592},{"atb":[[50,18.45],[48,9.65],[46,10.68]],"batb":[[2,46,10.68],[1,48,9.65],[0,50,18.45]],"id":59626646},{"atl":[[10.5,113.18]],"batl":[[0,10.5,113.18]],"id":27115873}]}]}
{"op":"mcm","id":2,"clk":"AK7XAgCrjQIAhrAC","pt":1743512127952,"mc":[{"id":"1.241629436","rc":[{"atb":[[2.56,2]],"id":27115873},{"atb":[[11,98.09]],"trd":[[11,1668.98]],"batb":[[0,11,98.09]],"ltp":11,"tv":5220.36,"id":44049799}],"tv":88262.17}]}
{"op":"mcm","id":2,"clk":"ALfXAgC4jQIAl7AC","pt":1743512128056,"mc":[{"id":"1.241629436","rc":[{"atb":[[4.2,144.47]],"batb":[],"id":270592}]}]}
{"op":"mcm","id":2,"clk":"AMzXAgDZjQIAurAC","pt":1743512128370,"mc":[{"id":"1.241629436","rc":[{"atb":[[6.6,274.6]],"batb":[[2,6.6,274.6]],"id":26496185}]}]}
{"op":"mcm","id":2,"clk":"AN/XAgDsjQIA1bAC","pt":1743512128575,"mc":[{"id":"1.241629436","rc":[{"atb":[[1.17,2.8]],"id":40389088}]}]}
{"op":"mcm","id":2,"clk":"AOzXAgD4jQIA4LAC","pt":1743512128631,"mc":[{"id":"1.241629436","rc":[{"atb":[[4.3,197.24]],"batb":[],"id":270592}]}]}
{"op":"mcm","id":2,"clk":"APbXAgCAjgIA6bAC","pt":1743512128735,"mc":[{"id":"1.241629436","rc":[{"atb":[[1.17,2]],"id":40389088}]}]}
{"op":"mcm","id":2,"clk":"AIHYAgCJjgIA9LAC","pt":1743512128835,"mc":[{"id":"1.241629436","rc":[{"atb":[[11.5,16.69]],"batb":[[0,11.5,16.69]],"id":40389088},{"atb":[[4.1,148.03]],"batb":[],"id":270592}]}]}
{"op":"mcm","id":2,"clk":"AJ7YAgCnjgIAm7EC","pt":1743512129144,"mc":[{"id":"1.241629436","rc":[{"atb":[[8.6,11.56]],"batb":[],"id":44049799}]}]}
{"op":"mcm","id":2,"clk":"AKjYAgCyjgIAqrEC","pt":1743512129256,"mc":[{"id":"1.241629436","rc":[{"atb":[[9.6,39.93]],"batb":[],"id":44049799}]}]}
{"op":"mcm","id":2,"clk":"AOfYAgD1jgIA2rEC","pt":1743512129562,"mc":[{"id":"1.241629436","rc":[{"atl":[[4.7,145.04]],"batl":[[0,4.7,145.04]],"id":270592}]}]}
{"op":"mcm","id":2,"clk":"AO3YAgD/jgIA47EC","pt":1743512129667,"mc":[{"id":"1.241629436","rc":[{"atl":[[4.7,210.04]],"batl":[[0,4.7,210.04]],"id":270592}]}]}
{"op":"mcm","id":2,"clk":"APnYAgCOjwIA8LEC","pt":1743512129772,"mc":[{"id":"1.241629436","rc":[{"atb":[[4.6,126.38]],"atl":[[4.7,209.2]],"trd":[[4.7,2551.58]],"batb":[[0,4.6,126.38]],"batl":[[0,4.7,209.2]],"tv":22523.5,"id":270592},{"atb":[[17.5,16.52]],"batb":[[0,17.5,16.52]],"id":58186642},{"atb":[[7,15]],"trd":[[7,1235.15]],"batb":[[0,7,15]],"tv":14335.89,"id":26496185}],"tv":88273.84}]}
{"op":"mcm","id":2,"clk":"AIPZAgCcjwIA9bEC","pt":1743512129871,"mc":[{"id":"1.241629436","rc":[{"atb":[[4,142.69]],"atl":[[5.2,130.38]],"batb":[],"batl":[],"id":270592}]}]}
{"op":"mcm","id":2,"clk":"AIvZAgCmjwIA/rEC","pt":1743512129933,"mc":[{"id":"1.241629436","rc":[{"atl":[[5.1,141.37]],"batl":[],"id":270592},{"atl":[[55,14.09]],"trd":[[55,356.04]],"batl":[[0,55,14.09]],"ltp":55,"tv":2066.94,"id":59626646}],"tv":88279.6}]}
{"op":"mcm","id":2,"clk":"AJXZAgCyjwIAibIC","pt":1743512130035,"mc":[{"id":"1.241629436","rc":[{"atl":[[55,12.24]],"batl":[[0,55,12.24]],"id":59626646}]}]}
{"op":"mcm","id":2,"clk":"AJrZAgC+jwIAkbIC","pt":1743512130128,"mc":[{"id":"1.241629436","rc":[{"atl":[[55,14.37]],"batl":[[0,55,14.37]],"id":59626646}]}]}
{"op":"mcm","id":2,"clk":"AKbZAgDGjwIAnLIC","pt":1743512130237,"mc":[{"id":"1.241629436","rc":[{"atb":[[11.5,18.75]],"batb":[[0,11.5,18.75]],"id":40389088},{"atb":[[4.6,131.53]],"batb":[[0,4.6,131.53]],"id":270592},{"atb":[[9.8,28.54]],"batb":[[0,9.8,28.54]],"id":35856222},{"atb":[[50,18.92]],"batb":[[0,50,18.92]],"id":59626646},{"atb":[[5.1,277.91]],"batb":[[0,5.1,277.91]],"id":56297029},{"atb":[[10,81.64]],"batb":[[0,10,81.64]],"id":27115873},{"atb":[[17.5,17.87]],"batb":[[0,17.5,17.87]],"id":58186642},{"atb":[[7,18.38],[6.4,277.6]],"batb":[[0,7,18.38]],"id":26496185},{"atb":[[11,100.24]],"batb":[[0,11,100.24]],"id":44049799}]}]}
{"op":"mcm","id":2,"clk":"ALrZAgDejwIAs7IC","pt":1743512130459,"mc":[{"id":"1.241629436","rc":[{"atl":[[5.2,325.36]],"batl":[[0,5.2,325.36]],"id":56297029}]}]}
{"op":"mcm","id":2,"clk":"AMfZAgDrjwIAwLIC","pt":1743512130561,"mc":[{"id":"1.241629436","rc":[{"atb":[[11.5,6.22]],"trd":[[11.5,1335.12]],"batb":[[0,11.5,6.22]],"tv":6648.35,"id":40389088},{"atb":[[8.4,60.82]],"batb":[],"id":27115873}],"tv":88303.05}]}
{"op":"mcm","id":2,"clk":"ANDZAgD0jwIAy7IC","pt":1743512130665,"mc":[{"id":"1.241629436","rc":[{"atb":[[11.5,18.73]],"atl":[[12,74.53]],"batb":[[0,11.5,18.73]],"batl":[[0,12,74.53]],"id":40389088}]}]}
{"op":"mcm","id":2,"clk":"ANTZAgD9jwIA0bIC","pt":1743512130758,"mc":[{"id":"1.241629436","rc":[{"atb":[[11.5,20.17]],"atl":[[1000,0.55]],"batb":[[0,11.5,20.17]],"id":40389088},{"atb":[[9.8,29.94]],"atl":[[1000,0.7]],"batb":[[0,9.8,29.94]],"id":35856222},{"atb":[[10,83.6]],"batb":[[0,10,83.6]],"id":27115873},{"atb":[[7,21.54]],"atl":[[1000,4.54]],"batb":[[0,7,21.54]],"id":26496185}]}]}
{"op":"mcm","id":2,"clk":"AOrZAgCSkAIA4rIC","pt":1743512130963,"mc":[{"id":"1.241629436","rc":[{"atl":[[1000,0.25]],"id":40389088},{"atl":[[1000,3.9]],"id":26496185}]}]}
{"op":"mcm","id":2,"clk":"APTZAgCckAIA6rIC","pt":1743512131070,"mc":[{"id":"1.241629436","rc":[{"atl":[[12.5,60.86]],"batl":[[1,12.5,60.86]],"id":40389088},{"atl":[[1000,0.41]],"id":35856222},{"atb":[[6.4,279.5]],"atl":[[7.4,44.18]],"batb":[],"batl":[[1,7.4,44.18]],"id":26496185}]}]}
{"op":"mcm","id":2,"clk":"AP7ZAgCekAIA7rIC","pt":1743512131169,"mc":[{"id":"1.241629436","rc":[{"atl":[[10.5,76.86]],"batl":[[1,10.5,76.86]],"id":35856222}]}]}
{"op":"mcm","id":2,"clk":"AIbaAgCmkAIA87IC","pt":1743512131273,"mc":[{"id":"1.241629436","rc":[{"atb":[[4.5,211.19]],"atl":[[30,0]],"batb":[[1,4.5,211.19]],"id":270592}]}]}
{"op":"mcm","id":2,"clk":"AJbaAgC3kAIA/rIC","pt":1743512131452,"mc":[{"id":"1.241629436","rc":[{"atb":[[4.5,221.19]],"batb":[[1,4.5,221.19]],"id":270592}]}]}
{"op":"mcm","id":2,"clk":"AKPaAgC+kAIAhrMC","pt":1743512131538,"mc":[{"id":"1.241629436","rc":[{"atb":[[1.01,143933.92]],"id":40389088},{"atb":[[4.6,156.53]],"batb":[[0,4.6,156.53]],"id":270592},{"atl":[[16.5,1]],"id":35856222}]}]}
{"op":"mcm","id":2,"clk":"AK3aAgDHkAIAkLMC","pt":1743512131688,"mc":[{"id":"1.241629436","rc":[{"atb":[[7,19.54]],"trd":[[7,1239.15]],"batb":[[0,7,19.54]],"tv":14339.89,"id":26496185}],"tv":88307.05}]}
{"op":"mcm","id":2,"clk":"ALraAgDOkAIAl7MC","pt":1743512131745,"mc":[{"id":"1.241629436","rc":[{"atb":[[10,71.05]],"batb":[],"id":40389088}]}]}
{"op":"mcm","id":2,"clk":"AMXaAgDXkAIAobMC","pt":1743512131848,"mc":[{"id":"1.241629436","rc":[{"atl":[[36,1.99]],"id":44049799}]}]}
{"op":"mcm","id":2,"clk":"AM7aAgDgkAIAp7MC","pt":1743512131948,"mc":[{"id":"1.241629436","rc":[{"atb":[[3,89.53]],"id":270592},{"atb":[[6.4,281.4]],"batb":[],"id":26496185}]}]}
{"op":"mcm","id":2,"clk":"ANraAgDskAIAtrMC","pt":1743512132054,"mc":[{"id":"1.241629436","rc":[{"atl":[[65,1]],"id":58186642}]}]}
{"op":"mcm","id":2,"clk":"AOTaAgD3kAIAxLMC","pt":1743512132158,"mc":[{"id":"1.241629436","rc":[{"atl":[[12,65.3]],"trd":[[12,1409.73]],"batl":[[0,12,65.3]],"ltp":12,"tv":6666.81,"id":40389088},{"atb":[[9.4,50.78],[9.8,25.86]],"atl":[[10,89.97]],"trd":[[9.8,998.66],[10,800.51]],"batb":[[2,9.4,50.78],[0,9.8,25.86]],"batl":[[0,10,89.97]],"ltp":10,"tv":9997.44,"id":35856222},{"atb":[[5.1,265.91]],"trd":[[5.1,4658.49]],"batb":[[0,5.1,265.91]],"tv":13932.67,"id":56297029},{"atb":[[10,81.6]],"atl":[[10.5,104.6]],"trd":[[10.5,682.91],[10,723.1]],"batb":[[0,10,81.6]],"batl":[[0,10.5,104.6]],"ltp":10.5,"tv":7417.01,"id":27115873},{"atl":[[18,27.53]],"trd":[[18,296.89]],"batl":[[0,18,27.53]],"ltp":18,"tv":6253.47,"id":58186642},{"atl":[[7.2,162.26]],"trd":[[7.2,31.49]],"batl":[[0,7.2,162.26]],"ltp":7.2,"tv":14343.05,"id":26496185},{"atl":[[11.5,72.18]],"trd":[[11.5,1080.07]],"batl":[[0,11.5,72.18]],"ltp":11.5,"tv":5237.54,"id":44049799}],"tv":88438.43}]}
{"op":"mcm","id":2,"clk":"AO/aAgCEkQIA0LMC","pt":1743512132260,"mc":[{"id":"1.241629436","rc":[{"atb":[[11.5,40.73]],"atl":[[12,83.86]],"batb":[[0,11.5,40.73]],"batl":[[0,12,83.86]],"id":40389088},{"atb":[[10,80.6]],"trd":[[10,725.1]],"batb":[[0,10,80.6]],"ltp":10,"tv":7419.01,"id":27115873},{"atl":[[18,35.46]],"batl":[[0,18,35.46]],"id":58186642},{"atl":[[11.5,93.19]],"batl":[[0,11.5,93.19]],"id":44049799}],"tv":88440.43}]}
{"op":"mcm","id":2,"clk":"APraAgCSkQIA1bMC","pt":1743512132357,"mc":[{"id":"1.241629436","rc":[{"atb":[[9.8,23.01]],"trd":[[9.8,1004.36]],"batb":[[0,9.8,23.01]],"ltp":9.8,"tv":10003.14,"id":35856222},{"atb":[[17.5,21.03]],"batb":[[0,17.5,21.03]],"id":58186642}],"tv":88446.13}]}
{"op":"mcm","id":2,"clk":"AJfbAgCvkQIA7bMC","pt":1743512132665,"mc":[{"id":"1.241629436","rc":[{"atb":[[4.5,218.88]],"batb":[[1,4.5,218.88]],"id":270592},{"atb":[[10,78.09]],"trd":[[10,730.12]],"batb":[[0,10,78.09]],"tv":7424.03,"id":27115873}],"tv":88451.15}]}
{"op":"mcm","id":2,"clk":"AKDbAgC4kQIA97MC","pt":1743512132768,"mc":[{"id":"1.241629436","rc":[{"atl":[[4.7,207.2]],"trd":[[4.7,2555.58]],"batl":[[0,4.7,207.2]],"tv":22527.5,"id":270592}],"tv":88455.15}]}
{"op":"mcm","id":2,"clk":"ALHbAgDGkQIAgrQC","pt":1743512132978,"mc":[{"id":"1.241629436","rc":[{"atb":[[4.6,181.53]],"batb":[[0,4.6,181.53]],"id":270592},{"atl":[[7.2,168.93]],"trd":[[7.2,38.15]],"batl":[[0,7.2,168.93]],"tv":14349.71,"id":26496185}],"tv":88461.81}]}
{"op":"mcm","id":2,"clk":"AMLbAgDgkQIAlbQC","pt":1743512133183,"mc":[{"id":"1.241629436","rc":[{"atl":[[7.2,180.26]],"batl":[[0,7.2,180.26]],"id":26496185}]}]}
{"op":"mcm","id":2,"clk":"AMzbAgDikQIAo7QC","pt":1743512133241,"mc":[{"id":"1.241629436","rc":[{"atb":[[4.4,244.04]],"batb":[[2,4.4,244.04]],"id":270592},{"atl":[[1000,11.86]],"id":59626646},{"atl":[[1000,1.41]],"id":58186642},{"atb":[[6.4,283.3]],"batb":[],"id":26496185}]}]}
{"op":"mcm","id":2,"clk":"ANjbAgDokQIAr7QC","pt":1743512133343,"mc":[{"id":"1.241629436","rc":[{"atl":[[1000,0.47]],"id":40389088},{"atl":[[5.2,321.78]],"batl":[[0,5.2,321.78]],"id":56297029}]}]}
{"op":"mcm","id":2,"clk":"AODbAgDykQIAtrQC","pt":1743512133445,"mc":[{"id":"1.241629436","rc":[{"atl":[[1000,0.25]],"id":40389088},{"atb":[[4.5,238.88]],"atl":[[5,285.84]],"batb":[[1,4.5,238.88]],"batl":[],"id":270592},{"atl":[[10.5,49.16]],"batl":[[1,10.5,49.16]],"id":35856222},{"atb":[[7,28.59]],"batb":[[0,7,28.59]],"id":26496185}]}]}
{"op":"mcm","id":2,"clk":"AOnbAgD9kQIAv7QC","pt":1743512133549,"mc":[{"id":"1.241629436","rc":[{"atb":[[11.5,50.7]],"atl":[[12,84.08]],"batb":[[0,11.5,50.7]],"batl":[[0,12,84.08]],"id":40389088},{"atb":[[4.4,249.14]],"batb":[[2,4.4,249.14]],"id":270592},{"atl":[[10,139.94]],"batl":[[0,10,139.94]],"id":35856222},{"atb":[[7,40.65]],"batb":[[0,7,40.65]],"id":26496185}]}]}
{"op":"mcm","id":2,"clk":"APHbAgCFkgIAxrQC","pt":1743512133644,"mc":[{"id":"1.241629436","rc":[{"atb":[[9.8,18.01]],"trd":[[9.8,1014.36]],"batb":[[0,9.8,18.01]],"tv":10013.14,"id":35856222}],"tv":88471.81}]}
{"op":"mcm","id":2,"clk":"APnbAgCOkgIA0bQC","pt":1743512133749,"mc":[{"id":"1.241629436","rc":[{"atb":[[9.8,12.6]],"batb":[[0,9.8,12.6]],"id":35856222}]}]}
{"op":"mcm","id":2,"clk":"AP/bAgCWkgIA1bQC","pt":1743512133854,"mc":[{"id":"1.241629436","rc":[{"atb":[[11.5,49.7]],"batb":[[0,11.5,49.7]],"id":40389088},{"atb":[[9.8,3.82]],"batb":[[0,9.8,3.82]],"id":35856222}]}]}
{"op":"mcm","id":2,"clk":"AIncAgCgkgIA3rQC","pt":1743512133954,"mc":[{"id":"1.241629436","rc":[{"atb":[[10,83.55]],"batb":[[0,10,83.55]],"id":27115873}]}]}
{"op":"mcm","id":2,"clk":"AJjcAgC4kgIA7LQC","pt":1743512134161,"mc":[{"id":"1.241629436","rc":[{"atb":[[11.5,44.7]],"trd":[[11.5,1345.12]],"batb":[[0,11.5,44.7]],"ltp":11.5,"tv":6676.81,"id":40389088},{"atb":[[4.6,182.09]],"atl":[[4.7,198.43]],"trd":[[4.7,2574.2]],"batb":[[0,4.6,182.09]],"batl":[[0,4.7,198.43]],"tv":22546.12,"id":270592}],"tv":88500.43}]}
{"op":"mcm","id":2,"clk":"AKrcAgDMkgIA9LQC","pt":1743512134363,"mc":[{"id":"1.241629436","rc":[{"atl":[[4.7,160.14]],"batl":[[0,4.7,160.14]],"id":270592},{"atb":[[48,11.32]],"batb":[[1,48,11.32]],"id":59626646}]}]}
{"op":"mcm","id":2,"clk":"AK7cAgDWkgIA+rQC","pt":1743512134462,"mc":[{"id":"1.241629436","rc":[{"atl":[[4.8,256.51]],"batl":[[1,4.8,256.51]],"id":270592},{"atb":[[4.5,102.15]],"batb":[],"id":56297029}]}]}
{"op":"mcm","id":2,"clk":"ALXcAgDfkgIAg7UC","pt":1743512134568,"mc":[{"id":"1.241629436","rc":[{"atb":[[11.5,25.14]],"batb":[[0,11.5,25.14]],"id":40389088}]}]}
{"op":"mcm","id":2,"clk":"AMPcAgDmkgIAjLUC","pt":1743512134668,"mc":[{"id":"1.241629436","rc":[{"atl":[[4.7,175.21]],"batl":[[0,4.7,175.21]],"id":270592}]}]}
{"op":"mcm","id":2,"clk":"AM/cAgDzkgIAlrUC","pt":1743512134771,"mc":[{"id":"1.241629436","rc":[{"atb":[[4.5,248.88]],"batb":[[1,4.5,248.88]],"id":270592}]}]}
{"op":"mcm","id":2,"clk":"ANjcAgD7kgIAoLUC","pt":1743512134877,"mc":[{"id":"1.241629436","rc":[{"atb":[[6.2,160.7]],"batb":[],"id":26496185}]}]}
{"op":"mcm","id":2,"clk":"AOXcAgCHkwIApLUC","pt":1743512134938,"mc":[{"id":"1.241629436","rc":[{"atb":[[11,98.54]],"trd":[[11,1672.38]],"batb":[[0,11,98.54]],"ltp":11,"tv":5240.94,"id":44049799}],"tv":88503.83}]}
{"op":"mcm","id":2,"clk":"APvcAgCokwIAsrUC","pt":1743512135144,"mc":[{"id":"1.241629436","rc":[{"atb":[[11.5,24.14]],"trd":[[11.5,1347.12]],"batb":[[0,11.5,24.14]],"tv":6678.81,"id":40389088}],"tv":88505.83}]}
{"op":"mcm","id":2,"clk":"AITdAgC3kwIAtbUC","pt":1743512135241,"mc":[{"id":"1.241629436","rc":[{"atb":[[6.2,162.6]],"batb":[],"id":26496185},{"atb":[[11,103.27]],"batb":[[0,11,103.27]],"id":44049799}]}]}
{"op":"mcm","id":2,"clk":"AJLdAgDEkwIAwLUC","pt":1743512135353,"mc":[{"id":"1.241629436","rc":[{"atb":[[1.17,2.66]],"id":40389088},{"atb":[[4.5,248.65]],"atl":[[4.7,174.06]],"batb":[[1,4.5,248.65]],"batl":[[0,4.7,174.06]],"id":270592},{"atb":[[5.1,267.78]],"batb":[[0,5.1,267.78]],"id":56297029}]}]}
{"op":"mcm","id":2,"clk":"AJ3dAgDMkwIAx7UC","pt":1743512135454,"mc":[{"id":"1.241629436","rc":[{"atb":[[1.17,2]],"id":40389088},{"atl":[[5,305.84]],"batl":[],"id":270592}]}]}
{"op":"mcm","id":2,"clk":"AKfdAgDWkwIA0bUC","pt":1743512135556,"mc":[{"id":"1.241629436","rc":[{"atb":[[11.5,24.8]],"batb":[[0,11.5,24.8]],"id":40389088}]}]}
{"op":"mcm","id":2,"clk":"ALTdAgDgkwIA47UC","pt":1743512135667,"mc":[{"id":"1.241629436","rc":[{"atb":[[4.6,192.09]],"batb":[[0,4.6,192.09]],"id":270592}]}]}
{"op":"mcm","id":2,"clk":"AMzdAgDzkwIA8bUC","pt":1743512135871,"mc":[{"id":"1.241629436","rc":[{"atb":[[6.2,164.5]],"batb":[],"id":26496185}]}]}
{"op":"mcm","id":2,"clk":"APXdAgCUlAIAmbYC","pt":1743512136280,"mc":[{"id":"1.241629436","rc":[{"atl":[[5.2,150.38]],"batl":[],"id":270592}]}]}
{"op":"mcm","id":2,"clk":"AIfeAgCplAIArrYC","pt":1743512136443,"mc":[{"id":"1.241629436","rc":[{"atl":[[4.7,172.06]],"trd":[[4.7,2578.2]],"batl":[[0,4.7,172.06]],"tv":22550.12,"id":270592}],"tv":88509.83}]}
{"op":"mcm","id":2,"clk":"AJveAgDFlAIAx7YC","pt":1743512136650,"mc":[{"id":"1.241629436","rc":[{"atb":[[4.6,181.66]],"atl":[[4.8,246.51]],"trd":[[4.6,513.03]],"batb":[[0,4.6,181.66]],"batl":[[1,4.8,246.51]],"ltp":4.6,"tv":22570.98,"id":270592}],"tv":88530.69}]}
{"op":"mcm","id":2,"clk":"AKjeAgDdlAIA4LYC","pt":1743512136860,"mc":[{"id":"1.241629436","rc":[{"atl":[[55,13.84]],"trd":[[55,357.1]],"batl":[[0,55,13.84]],"tv":2068,"id":59626646},{"atb":[[7,20.65],[6.2,166.4]],"trd":[[7,1279.15]],"batb":[[0,7,20.65]],"ltp":7,"tv":14389.71,"id":26496185}],"tv":88571.75}]}
{"op":"mcm","id":2,"clk":"AK7eAgDrlAIA67YC","pt":1743512136958,"mc":[{"id":"1.241629436","rc":[{"atl":[[12,82.04]],"batl":[[0,12,82.04]],"id":40389088},{"atb":[[9.8,21.9]],"batb":[[0,9.8,21.9]],"id":35856222},{"atb":[[5.1,263.93]],"batb":[[0,5.1,263.93]],"id":56297029},{"atb":[[7,29.1]],"batb":[[0,7,29.1]],"id":26496185}]}]}
{"op":"mcm","id":2,"clk":"ALTeAgD4lAIA9rYC","pt":1743512137067,"mc":[{"id":"1.241629436","rc":[{"atb":[[7,28.26]],"trd":[[7,1280.83]],"batb":[[0,7,28.26]],"tv":14391.39,"id":26496185}],"tv":88573.43}]}
{"op":"mcm","id":2,"clk":"ALveAgCBlQIAgLcC","pt":1743512137169,"mc":[{"id":"1.241629436","rc":[{"atl":[[5.4,113.59]],"batl":[],"id":270592}]}]}
{"op":"mcm","id":2,"clk":"AN7eAgCtlQIAqLcC","pt":1743512137578,"mc":[{"id":"1.241629436","rc":[{"atl":[[4.9,292.5]],"batl":[[2,4.9,292.5]],"id":270592}]}]}
{"op":"mcm","id":2,"clk":"AO3eAgC+lQIAxLcC","pt":1743512137779,"mc":[{"id":"1.241629436","rc":[{"atl":[[16,9.63]],"batl":[],"id":40389088}]}]}
{"op":"mcm","id":2,"clk":"APPeAgDPlQIA07cC","pt":1743512137880,"mc":[{"id":"1.241629436","rc":[{"atb":[[10,69.55]],"trd":[[10,758.12]],"batb":[[0,10,69.55]],"tv":7452.03,"id":27115873}],"tv":88601.43}]}
{"op":"mcm","id":2,"clk":"APneAgDVlQIA27cC","pt":1743512137982,"mc":[{"id":"1.241629436","rc":[{"atb":[[11.5,23.8]],"trd":[[11.5,1349.12]],"batb":[[0,11.5,23.8]],"tv":6680.81,"id":40389088},{"atb":[[10,60.74]],"atl":[[10.5,107.4]],"batb":[[0,10,60.74]],"batl":[[0,10.5,107.4]],"id":27115873}],"tv":88603.43}]}
{"op":"mcm","id":2,"clk":"AITfAgDplQIA97cC","pt":1743512138146,"mc":[{"id":"1.241629436","rc":[{"atb":[[9.8,0]],"atl":[[9.8,8.1]],"trd":[[9.8,1058.16]],"batb":[[2,9.2,79.65],[1,9.4,50.78],[0,9.6,66.22]],"batl":[[2,10.5,49.16],[1,10,139.94],[0,9.8,8.1]],"tv":10056.94,"id":35856222},{"atb":[[10,74.74]],"atl":[[10.5,121]],"batb":[[0,10,74.74]],"batl":[[0,10.5,121]],"id":27115873}],"tv":88647.23}]}
{"op":"mcm","id":2,"clk":"AIzfAgDxlQIAhLgC","pt":1743512138254,"mc":[{"id":"1.241629436","rc":[{"atb":[[4.6,184.75]],"batb":[[0,4.6,184.75]],"id":270592},{"atb":[[9.6,67.46]],"atl":[[9.8,7.61]],"trd":[[9.8,1079.14]],"batb":[[0,9.6,67.46]],"batl":[[0,9.8,7.61]],"tv":10077.92,"id":35856222},{"atb":[[50,15.92]],"trd":[[50,81.73]],"batb":[[0,50,15.92]],"ltp":50,"tv":2074,"id":59626646},{"atb":[[10,80.21]],"batb":[[0,10,80.21]],"id":27115873},{"atb":[[7,39.55]],"batb":[[0,7,39.55]],"id":26496185}],"tv":88674.21}]}
{"op":"mcm","id":2,"clk":"AJbfAgD7lQIAirgC","pt":1743512138346,"mc":[{"id":"1.241629436","rc":[{"atl":[[55,16.57]],"batl":[[0,55,16.57]],"id":59626646}]}]}
{"op":"mcm","id":2,"clk":"AKDfAgCGlgIAl7gC","pt":1743512138456,"mc":[{"id":"1.241629436","rc":[{"atl":[[5.1,136.37]],"batl":[],"id":270592},{"atb":[[9.2,65.05]],"batb":[[2,9.2,65.05]],"id":35856222}]}]}
{"op":"mcm","id":2,"clk":"AKvfAgCSlgIAnbgC","pt":1743512138561,"mc":[{"id":"1.241629436","rc":[{"atb":[[4.6,187.52]],"batb":[[0,4.6,187.52]],"id":270592},{"atl":[[1000,0.8],[10.5,48.87]],"batl":[[2,10.5,48.87]],"id":35856222},{"atl":[[5.2,320.39]],"batl":[[0,5.2,320.39]],"id":56297029}]}]}
{"op":"mcm","id":2,"clk":"ALDfAgCglgIApLgC","pt":1743512138657,"mc":[{"id":"1.241629436","rc":[{"atl":[[1000,0.41]],"id":35856222},{"atb":[[6,140.68]],"batb":[],"id":26496185}]}]}
{"op":"mcm","id":2,"clk":"AL3fAgCnlgIAqrgC","pt":1743512138761,"mc":[{"id":"1.241629436","rc":[{"atl":[[10,140.33]],"batl":[[1,10,140.33]],"id":35856222},{"atl":[[55,17.9]],"batl":[[0,55,17.9]],"id":59626646},{"atl":[[7.6,48.44]],"batl":[[2,7.6,48.44]],"id":26496185}]}]}
{"op":"mcm","id":2,"clk":"AMTfAgCzlgIAtrgC","pt":1743512138871,"mc":[{"id":"1.241629436","rc":[{"atb":[[4.4,244.04]],"batb":[[2,4.4,244.04]],"id":270592},{"atb":[[5.1,233.93]],"trd":[[5.1,4718.49]],"batb":[[0,5.1,233.93]],"tv":13992.67,"id":56297029}],"tv":88734.21}]}
{"op":"mcm","id":2,"clk":"ANLfAgC8lgIAwrgC","pt":1743512138981,"mc":[{"id":"1.241629436","rc":[{"atb":[[7,0]],"atl":[[7,60.45],[8,55.55]],"trd":[[7,1359.93]],"batb":[[2,6.4,283.3],[1,6.6,274.6],[0,6.8,203.58]],"batl":[[2,7.4,44.18],[1,7.2,180.26],[0,7,60.45]],"tv":14470.49,"id":26496185}],"tv":88813.31}]}
{"op":"mcm","id":2,"clk":"ANnfAgDElgIAx7gC","pt":1743512139070,"mc":[{"id":"1.241629436","rc":[{"atl":[[5.2,335.22]],"batl":[[0,5.2,335.22]],"id":56297029},{"atb":[[17.5,29.03]],"batb":[[0,17.5,29.03]],"id":58186642},{"atl":[[11.5,90.09]],"batl":[[0,11.5,90.09]],"id":44049799}]}]}
{"op":"mcm","id":2,"clk":"AOLfAgDQlgIAzbgC","pt":1743512139176,"mc":[{"id":"1.241629436","rc":[{"atb":[[11.5,47.15]],"batb":[[0,11.5,47.15]],"id":40389088},{"atb":[[4.6,216.41]],"batb":[[0,4.6,216.41]],"id":270592},{"atb":[[5.1,233.83]],"trd":[[5.1,4718.69]],"batb":[[0,5.1,233.83]],"tv":13992.87,"id":56297029},{"atl":[[12,30.28]],"batl":[],"id":27115873},{"atl":[[19,45.71]],"batl":[[2,19,45.71]],"id":58186642},{"atb":[[1.17,1.18],[5.9,119.74],[6.6,277.4],[6.8,195.56]],"atl":[[7,79.77]],"batb":[[1,6.6,277.4],[0,6.8,195.56]],"batl":[[0,7,79.77]],"id":26496185}],"tv":88813.51}]}
{"op":"mcm","id":2,"clk":"AO3fAgDWlgIA2bgC","pt":1743512139276,"mc":[{"id":"1.241629436","rc":[{"atb":[[11.5,73.67]],"batb":[[0,11.5,73.67]],"id":40389088},{"atb":[[4.6,277.46]],"batb":[[0,4.6,277.46]],"id":270592},{"atb":[[9.6,81.68]],"batb":[[0,9.6,81.68]],"id":35856222},{"atb":[[50,20.93]],"batb":[[0,50,20.93]],"id":59626646},{"atb":[[5.1,262.26]],"batb":[[0,5.1,262.26]],"id":56297029},{"atb":[[10,107.81]],"batb":[[0,10,107.81]],"id":27115873},{"atb":[[17.5,37.4]],"batb":[[0,17.5,37.4]],"id":58186642},{"atb":[[1.17,1]],"id":26496185},{"atb":[[11,128.36]],"batb":[[0,11,128.36]],"id":44049799}]}]}
{"op":"mcm","id":2,"clk":"APbfAgDelgIA6bgC","pt":1743512139380,"mc":[{"id":"1.241629436","rc":[{"atb":[[11.5,62.67]],"trd":[[11.5,1371.12]],"batb":[[0,11.5,62.67]],"tv":6702.81,"id":40389088},{"atl":[[4.7,125.3]],"batl":[[0,4.7,125.3]],"id":270592},{"atl":[[10.5,59.85]],"batl":[[2,10.5,59.85]],"id":35856222},{"atl":[[7,79.59]],"trd":[[7,1360.29]],"batl":[[0,7,79.59]],"tv":14470.85,"id":26496185}],"tv":88835.87}]}
{"op":"mcm","id":2,"clk":"AIDgAgDqlgIA8bgC","pt":1743512139484,"mc":[{"id":"1.241629436","rc":[{"atb":[[11.5,74.67]],"batb":[[0,11.5,74.67]],"id":40389088},{"atl":[[4.7,99.9]],"batl":[[0,4.7,99.9]],"id":270592},{"atb":[[9.6,88.07]],"batb":[[0,9.6,88.07]],"id":35856222},{"atl":[[10.5,107.4]],"batl":[[0,10.5,107.4]],"id":27115873},{"atb":[[6,142.58]],"atl":[[7,70.54]],"trd":[[7,1378.39]],"batb":[],"batl":[[0,7,70.54]],"tv":14488.95,"id":26496185}],"tv":88853.97}]}
{"op":"mcm","id":2,"clk":"AIzgAgDxlgIA+bgC","pt":1743512139591,"mc":[{"id":"1.241629436","rc":[{"atb":[[10,117.03]],"batb":[[0,10,117.03]],"id":27115873}]}]}
{"op":"mcm","id":2,"clk":"AJXgAgD8lgIA/7gC","pt":1743512139645,"mc":[{"id":"1.241629436","rc":[{"atb":[[11.5,84.64]],"batb":[[0,11.5,84.64]],"id":40389088},{"atb":[[4.4,254.04]],"batb":[[2,4.4,254.04]],"id":270592},{"atb":[[9.6,85.07]],"trd":[[9.6,624.2]],"batb":[[0,9.6,85.07]],"ltp":9.6,"tv":10083.92,"id":35856222}],"tv":88859.97}]}
{"op":"mcm","id":2,"clk":"AKfgAgCClwIAirkC","pt":1743512139758,"mc":[{"id":"1.241629436","rc":[{"atb":[[17.5,40.52]],"batb":[[0,17.5,40.52]],"id":58186642}]}]}
{"op":"mcm","id":2,"clk":"ALLgAgCMlwIAlbkC","pt":1743512139851,"mc":[{"id":"1.241629436","rc":[{"atb":[[50,21.65]],"batb":[[0,50,21.65]],"id":59626646}]}]}
{"op":"mcm","id":2,"clk":"AMrgAgCilwIAorkC","pt":1743512140065,"mc":[{"id":"1.241629436","rc":[{"atb":[[3.9,44.5]],"batb":[],"id":270592},{"atb":[[9.6,81.07]],"trd":[[9.6,632.2]],"batb":[[0,9.6,81.07]],"tv":10091.92,"id":35856222},{"atb":[[17.5,41.52]],"batb":[[0,17.5,41.52]],"id":58186642},{"atb":[[6.8,249.35],[6,144.48]],"batb":[[0,6.8,249.35]],"id":26496185}],"tv":88867.97}]}
{"op":"mcm","id":2,"clk":"ANPgAgCrlwIAqrkC","pt":1743512140160,"mc":[{"id":"1.241629436","rc":[{"atl":[[12,81.37]],"batl":[[0,12,81.37]],"id":40389088}]}]}
{"op":"mcm","id":2,"clk":"AN7gAgC5lwIAs7kC","pt":1743512140268,"mc":[{"id":"1.241629436","rc":[{"atb":[[4.6,275.46]],"trd":[[4.6,517.04]],"batb":[[0,4.6,275.46]],"tv":22574.99,"id":270592},{"atb":[[10,114.03]],"trd":[[10,764.12]],"batb":[[0,10,114.03]],"tv":7458.03,"id":27115873},{"atb":[[17.5,45.31]],"batb":[[0,17.5,45.31]],"id":58186642}],"tv":88877.98}]}
{"op":"mcm","id":2,"clk":"APHgAgDVlwIAvrkC","pt":1743512140472,"mc":[{"id":"1.241629436","rc":[{"atl":[[7.4,59.16]],"batl":[[2,7.4,59.16]],"id":26496185}]}]}
{"op":"mcm","id":2,"clk":"AIDhAgDolwIAyLkC","pt":1743512140670,"mc":[{"id":"1.241629436","rc":[{"atb":[[6,146.38]],"atl":[[7,80.54]],"batb":[],"batl":[[0,7,80.54]],"id":26496185}]}]}
{"op":"mcm","id":2,"clk":"AInhAgDzlwIA0LkC","pt":1743512140775,"mc":[{"id":"1.241629436","rc":[{"atb":[[11,78.76]],"batb":[[1,11,78.76]],"id":40389088},{"atb":[[4.6,279.15]],"batb":[[0,4.6,279.15]],"id":270592},{"atl":[[60,3]],"batl":[[1,60,3]],"id":59626646},{"atl":[[19,10.6],[18.5,20.51]],"batl":[[2,19,10.6],[1,18.5,20.51]],"id":58186642},{"atb":[[6.8,232.59]],"atl":[[7.4,44.18]],"batb":[[0,6.8,232.59]],"batl":[[2,7.4,44.18]],"id":26496185}]}]}
{"op":"mcm","id":2,"clk":"AJDhAgD8lwIA2LkC","pt":1743512140880,"mc":[{"id":"1.241629436","rc":[{"atl":[[7,80.64]],"batl":[[0,7,80.64]],"id":26496185}]}]}
{"op":"mcm","id":2,"clk":"AJzhAgCJmAIA4LkC","pt":1743512140983,"mc":[{"id":"1.241629436","rc":[{"atb":[[1.17,1.2],[4.6,278.15]],"atl":[[4.7,100.9]],"trd":[[4.6,519.04]],"batb":[[0,4.6,278.15]],"batl":[[0,4.7,100.9]],"tv":22576.99,"id":270592},{"atl":[[10.5,48.87]],"batl":[[2,10.5,48.87]],"id":35856222},{"atb":[[5.1,265.48]],"batb":[[0,5.1,265.48]],"id":56297029},{"atl":[[7,90.64]],"batl":[[0,7,90.64]],"id":26496185}],"tv":88879.98}]}
{"op":"mcm","id":2,"clk":"AKbhAgCXmAIA5bkC","pt":1743512141088,"mc":[{"id":"1.241629436","rc":[{"atb":[[17.5,37.31]],"trd":[[17.5,261.03]],"batb":[[0,17.5,37.31]],"ltp":17.5,"tv":6269.47,"id":58186642}],"tv":88895.98}]}
{"op":"mcm","id":2,"clk":"AK7hAgChmAIA6rkC","pt":1743512141136,"mc":[{"id":"1.241629436","rc":[{"atb":[[1.17,1]],"id":270592}]}]}
{"op":"mcm","id":2,"clk":"ALjhAgCrmAIA87kC","pt":1743512141296,"mc":[{"id":"1.241629436","rc":[{"atb":[[10.5,51.01]],"batb":[[2,10.5,51.01]],"id":40389088},{"atb":[[4.1,106.08],[4.5,248.85]],"atl":[[4.7,58.95]],"trd":[[4.7,2662.11]],"batb":[[1,4.5,248.85]],"batl":[[0,4.7,58.95]],"ltp":4.7,"tv":22660.9,"id":270592},{"atl":[[18.5,22.78]],"batl":[[1,18.5,22.78]],"id":58186642},{"atb":[[6,148.28]],"batb":[],"id":26496185}],"tv":88979.89}]}
{"op":"mcm","id":2,"clk":"ANLhAgDHmAIAk7oC","pt":1743512141552,"mc":[{"id":"1.241629436","rc":[{"atb":[[9.6,82.64]],"batb":[[0,9.6,82.64]],"id":35856222},{"atb":[[50,22.54]],"atl":[[60,3.18]],"batb":[[0,50,22.54]],"batl":[[1,60,3.18]],"id":59626646},{"atl":[[7,89.02]],"trd":[[7,1381.63]],"batl":[[0,7,89.02]],"tv":14492.19,"id":26496185}],"tv":88983.13}]}
{"op":"mcm","id":2,"clk":"AOHhAgDhmAIAoroC","pt":1743512141766,"mc":[{"id":"1.241629436","rc":[{"atl":[[12,75.55]],"trd":[[12,1421.37]],"batl":[[0,12,75.55]],"ltp":12,"tv":6714.45,"id":40389088},{"atl":[[55,16.57]],"batl":[[0,55,16.57]],"id":59626646}],"tv":88994.77}]}
{"op":"mcm","id":2,"clk":"AOrhAgDqmAIAp7oC","pt":1743512141863,"mc":[{"id":"1.241629436","rc":[{"atl":[[9.8,24.21]],"batl":[[0,9.8,24.21]],"id":35856222},{"atl":[[11,69.81]],"batl":[[1,11,69.81]],"id":27115873}]}]}
{"op":"mcm","id":2,"clk":"APbhAgDxmAIAuLoC","pt":1743512141971,"mc":[{"id":"1.241629436","rc":[{"atb":[[10,81.03]],"trd":[[10,830.12]],"batb":[[0,10,81.03]],"tv":7524.03,"id":27115873}],"tv":89060.77}]}
{"op":"mcm","id":2,"clk":"AIXiAgCDmQIA07oC","pt":1743512142177,"mc":[{"id":"1.241629436","rc":[{"atb":[[11.5,91.89]],"batb":[[0,11.5,91.89]],"id":40389088},{"atl":[[10.5,132.03]],"batl":[[0,10.5,132.03]],"id":27115873},{"atb":[[17.5,35.59]],"trd":[[17.5,264.47]],"batb":[[0,17.5,35.59]],"tv":6272.91,"id":58186642}],"tv":89064.21}]}
{"op":"mcm","id":2,"clk":"AI7iAgCOmQIA2roC","pt":1743512142279,"mc":[{"id":"1.241629436","rc":[{"atb":[[10,102.46]],"batb":[[0,10,102.46]],"id":27115873},{"atl":[[19,12.87]],"batl":[[2,19,12.87]],"id":58186642}]}]}
{"op":"mcm","id":2,"clk":"AJ3iAgCdmQIA6roC","pt":1743512142394,"mc":[{"id":"1.241629436","rc":[{"atb":[[16,11.65]],"atl":[[21,10.93]],"batb":[],"batl":[],"id":58186642}]}]}
{"op":"mcm","id":2,"clk":"AKTiAgCimQIA8roC","pt":1743512142476,"mc":[{"id":"1.241629436","rc":[{"atl":[[7.2,160.81]],"batl":[[1,7.2,160.81]],"id":26496185}]}]}
{"op":"mcm","id":2,"clk":"ALfiAgC0mQIAiLsC","pt":1743512142683,"mc":[{"id":"1.241629436","rc":[{"atb":[[9.6,80.84]],"trd":[[9.6,635.8]],"batb":[[0,9.6,80.84]],"tv":10095.52,"id":35856222}],"tv":89067.81}]}
{"op":"mcm","id":2,"clk":"AL/iAgDAmQIAlrsC","pt":1743512142785,"mc":[{"id":"1.241629436","rc":[{"atb":[[11,115.36]],"trd":[[11,1698.38]],"batb":[[0,11,115.36]],"tv":5266.94,"id":44049799}],"tv":89093.81}]}
{"op":"mcm","id":2,"clk":"AMjiAgDQmQIAn7sC","pt":1743512142887,"mc":[{"id":"1.241629436","rc":[{"atb":[[4.3,202.24]],"batb":[],"id":270592}]}]}
{"op":"mcm","id":2,"clk":"AObiAgDxmQIAwrsC","pt":1743512143148,"mc":[{"id":"1.241629436","rc":[{"atb":[[4.6,274.15]],"trd":[[4.6,527.04]],"batb":[[0,4.6,274.15]],"ltp":4.6,"tv":22668.9,"id":270592}],"tv":89101.81}]}
{"op":"mcm","id":2,"clk":"APLiAgD5mQIAybsC","pt":1743512143260,"mc":[{"id":"1.241629436","rc":[{"atb":[[6,149.95]],"batb":[],"id":26496185}]}]}
{"op":"mcm","id":2,"clk":"APziAgCJmgIAzrsC","pt":1743512143362,"mc":[{"id":"1.241629436","rc":[{"atb":[[11,77.69]],"batb":[[1,11,77.69]],"id":40389088},{"atb":[[3.9,42.5]],"batb":[],"id":270592}]}]}
{"op":"mcm","id":2,"clk":"AJrjAgCtmgIA4rsC","pt":1743512143665,"mc":[{"id":"1.241629436","rc":[{"atb":[[11.5,90.89]],"trd":[[11.5,1373.12]],"batb":[[0,11.5,90.89]],"ltp":11.5,"tv":6716.45,"id":40389088},{"atl":[[4.7,48.95]],"trd":[[4.7,2682.11]],"batl":[[0,4.7,48.95]],"ltp":4.7,"tv":22688.9,"id":270592}],"tv":89123.81}]}
{"op":"mcm","id":2,"clk":"AKzjAgDBmgIA67sC","pt":1743512143779,"mc":[{"id":"1.241629436","rc":[{"atb":[[9.6,75.13]],"batb":[[0,9.6,75.13]],"id":35856222},{"atl":[[5.2,324.34]],"batl":[[0,5.2,324.34]],"id":56297029}]}]}
{"op":"mcm","id":2,"clk":"ANLjAgDemgIAhLwC","pt":1743512144083,"mc":[{"id":"1.241629436","rc":[{"atl":[[12,73.49]],"trd":[[12,1425.49]],"batl":[[0,12,73.49]],"ltp":12,"tv":6720.57,"id":40389088}],"tv":89127.93}]}
{"op":"mcm","id":2,"clk":"AOTjAgD2mgIAl7wC","pt":1743512144287,"mc":[{"id":"1.241629436","rc":[{"atl":[[90,1]],"id":44049799}]}]}
{"op":"mcm","id":2,"clk":"AOvjAgCAmwIApLwC","pt":1743512144399,"mc":[{"id":"1.241629436","rc":[{"atl":[[34,18]],"id":270592}]}]}
{"op":"mcm","id":2,"clk":"APPjAgCPmwIAqbwC","pt":1743512144499,"mc":[{"id":"1.241629436","rc":[{"atl":[[16.5,1.99]],"id":26496185}]}]}
{"op":"mcm","id":2,"clk":"AIDkAgCUmwIArbwC","pt":1743512144551,"mc":[{"id":"1.241629436","rc":[{"atb":[[9,19.26]],"batb":[],"id":27115873}]}]}
{"op":"mcm","id":2,"clk":"AI3kAgCcmwIAvLwC","pt":1743512144658,"mc":[{"id":"1.241629436","rc":[{"atb":[[4.6,268.61]],"batb":[[0,4.6,268.61]],"id":270592},{"atl":[[18,70]],"id":35856222},{"atb":[[50,21.65]],"atl":[[60,3]],"batb":[[0,50,21.65]],"batl":[[1,60,3]],"id":59626646},{"atb":[[5,1173.85]],"atl":[[5.2,323.72]],"batb":[[1,5,1173.85]],"batl":[[0,5.2,323.72]],"id":56297029},{"atb":[[10,107.46]],"batb":[[0,10,107.46]],"id":27115873},{"atl":[[1000,4.32],[7.4,43.54]],"batl":[[2,7.4,43.54]],"id":26496185}]}]}
{"op":"mcm","id":2,"clk":"AJbkAgClmwIAyLwC","pt":1743512144751,"mc":[{"id":"1.241629436","rc":[{"atl":[[40,0]],"id":270592}]}]}
