{"op":"connection","connectionId":"110-291024114947-21809"}{"op":"status","id":1,"statusCode":"SUCCESS","connectionClosed":false,"connectionsAvailable":9}{"op":"status","id":2,"statusCode":"SUCCESS","connectionClosed":false}{"op":"mcm","id":2,"initialClk":"+wGBwouDCv0BvJTp8AnxAYCYj/8J","clk":"AAAAAAAA","conflateMs":0,"heartbeatMs":5000,"pt":1730202588118,"ct":"SUB_IMAGE","mc":[{"id":"1.235123059","marketDefinition":{"bspMarket":true,"turnInPlayEnabled":true,"persistenceEnabled":true,"marketBaseRate":5,"eventId":"33728902","eventTypeId":"7","numberOfWinners":1,"bettingType":"ODDS","marketType":"WIN","marketTime":"2024-10-29T12:40:00.000Z","suspendTime":"2024-10-29T12:40:00.000Z","bspReconciled":false,"complete":true,"inPlay":false,"crossMatching":true,"runnersVoidable":false,"numberOfActiveRunners":4,"betDelay":0,"status":"OPEN","runners":[{"adjustmentFactor":48.37,"status":"ACTIVE","sortPriority":1,"id":72176817},{"adjustmentFactor":27.648,"status":"ACTIVE","sortPriority":2,"id":74399333},{"adjustmentFactor":19.875,"status":"ACTIVE","sortPriority":3,"id":73074145},{"adjustmentFactor":4.107,"status":"ACTIVE","sortPriority":4,"id":9517643},{"adjustmentFactor":10.869,"status":"REMOVED","sortPriority":5,"removalDate":"2024-10-28T09:11:27.000Z","id":73115482}],"regulators":["MR_INT"],"venue":"Catterick","countryCode":"GB","discountAllowed":true,"timezone":"Europe/London","openDate":"2024-10-29T12:40:00.000Z","version":6242839770,"raceType":"Flat","priceLadderDefinition":{"type":"CLASSIC"}},"rc":[{"atb":[[29,4.57],[26,0.41],[30,7.06],[10.5,3],[15,2],[15.5,8.9],[19,5.35],[25,10.47],[27,4.18],[28,1.46],[23,7.55],[21,9.19],[22,5.21],[1.68,1],[24,14.43],[1.04,11.77],[20,33.86],[19.5,5.18],[11.5,3.91],[18.5,5.47],[18,2.81],[1.03,33],[13,4.55],[8.4,17.84],[1.06,5918.62],[1.01,41565.98],[8,8],[3.05,10],[1.55,0.08],[1.1,100],[2.1,19],[11,9],[1.02,5085.01],[12,8.33],[9.6,3.55],[1.26,50],[1.11,70],[17.5,2.88],[5,5],[1.22,1],[7.6,30],[1.51,117.65],[1.23,3],[6.8,22.76],[2.04,86.54],[5.3,2],[5.8,13.75],[5.2,90],[6.2,20.31],[8.6,3],[7.2,3],[3.1,42.86],[6.4,12.22],[1.2,1],[2,1]],"atl":[[42,1.19],[32,0.57],[34,1.8],[36,1.97],[38,0.28],[44,2.13],[48,1.23],[70,0.81],[40,10.51],[60,0.83],[1000,3.5],[55,1.94],[50,4.01],[75,1],[200,0.3],[65,0.5],[770,1],[46,1.09],[500,0.01],[290,1],[160,2],[130,0.31]],"trd":[[30,68.36],[32,29.84],[34,11.3],[38,2.98],[36,13.28],[29,53.12],[28,28.37],[27,80.88],[26,44.3],[25,50.58],[24,45.02],[22,47.4],[21,5.2],[23,79.05],[40,4.45],[20,6.26],[19.5,5.18],[18,4],[17,2.42]],"spb":[[1000,60],[12,83.33]],"spl":[[1.01,118.95],[21,2]],"batb":[[1,29,4.57],[0,30,7.06],[2,28,1.46]],"batl":[[0,34,2.37],[2,40,10.79],[1,36,1.97]],"bdatb":[[1,29,4.57],[0,30,7.06],[2,28,1.46]],"bdatl":[[2,40,10.79],[0,34,2.37],[1,36,1.97]],"spn":22.3,"spf":2.2,"ltp":30,"tv":581.99,"id":9517643},{"atb":[[3.95,26.67],[2.5,7.5],[3,61.68],[3.8,40.66],[3.9,26.14],[2.12,2],[2.1,1],[3.45,42.11],[3.25,20.21],[3.75,3.04],[3.7,17.73],[3.85,25.61],[2.88,0.38],[1.04,11.77],[1.68,1],[3.65,106.33],[3.6,90.63],[3.55,14.68],[3.5,54.46],[2,1],[2.08,122.22],[3.4,14.46],[3.3,20.21],[1.06,5594.11],[3.2,10.1],[3.35,27.86],[1.01,41796.4],[1.03,33],[1.55,0.08],[1.1,9],[2.16,170.69],[2.04,150],[1.98,67.35],[2.24,106.45],[2.52,2.55],[2.36,5.24],[1.7,7.5],[1.02,5083.35],[1.26,50],[1.22,1],[1.3,30],[2.34,90],[1.51,117.65],[1.23,3],[1.2,3]],"atl":[[4.1,28.7],[4.4,25],[4.6,22.88],[4.5,16.83],[4.2,13.64],[4.3,2.19],[4.7,26.2],[5.3,1.86],[6,2],[5,60.4],[4.9,16.2],[4.8,6.2],[5.2,3.71],[200,0.3],[44,1],[34,19.5],[5.1,5.66],[500,0.01],[18.5,1],[17.5,1],[17,18],[13.5,3.5],[10.5,3],[160,2],[9,1],[8,14],[55,21]],"trd":[[3.95,631.32],[4,656.13],[3.9,898.11],[3.85,550.47],[3.75,175.3],[3.8,203.71],[3.7,21.28],[4.2,111.28],[4.1,387.66],[4.6,14.07],[4.5,16.57],[4.4,99.85],[4.3,44.57],[4.7,3.28],[5,20.64],[4.9,42.4]],"spb":[[1000,87],[3.4,83.33]],"spl":[[1.01,67.58],[2,2],[6.6,19.64]],"batb":[[0,3.95,26.67],[2,3.85,25.61],[1,3.9,26.14]],"batl":[[0,4.1,28.7],[2,4.3,2.19],[1,4.2,13.64]],"bdatb":[[0,3.95,26.67],[2,3.85,26.56],[1,3.9,30.82]],"bdatl":[[0,4.1,28.7],[2,4.3,29.21],[1,4.2,17.52]],"spn":3.93,"spf":3.4,"ltp":3.95,"tv":3876.64,"id":74399333},{"atb":[[5.4,21.52],[4.9,7.41],[5,16.66],[5.2,22.69],[5.3,2.02],[5.5,2.96],[5.1,10.25],[3.45,2],[4.5,21.48],[1.03,33],[1.68,1],[4.2,13.08],[4.1,9.29],[4.7,16.45],[4.8,17.86],[4.4,10.65],[4.3,42.68],[4,13.34],[3.65,3.02],[4.6,22.82],[1.04,11.77],[3.9,7.67],[1.06,6255.62],[3.8,6.28],[1.01,42885.6],[1.55,0.08],[2.66,39.76],[2.7,77.65],[2.78,111.24],[2.58,41.77],[2.86,70.97],[2.98,3.55],[3.35,2.55],[1.02,5084.94],[1.26,50],[1.22,1],[1.3,30],[1.51,117.65],[1.23,3],[2.04,86.54],[2.6,90],[3,2.74],[1.2,1],[2,1]],"atl":[[5.7,3.85],[5.8,17.32],[5.9,2.56],[6.4,4.84],[6.2,7.54],[6,1.05],[6.6,15.08],[7,29.33],[6.8,6.51],[7.4,3.71],[7.2,3.71],[11.5,17.16],[13,2],[10,2],[7.6,5.03],[14,1],[8.2,4.93],[8,4.96],[7.8,7.71],[9.2,3],[970,0.01],[200,0.3],[44,1],[500,0.01],[17,18],[15,1],[14.5,1],[160,2],[9,2.12],[900,1],[55,21],[34,18]],"trd":[[5.5,482.29],[5.6,358.75],[5.7,309.2],[5.8,147.67],[5.3,231.71],[5.4,75.26],[5.9,184.26],[6,89.14],[6.2,63.53],[6.4,26.68],[6.6,12.07],[4.1,100.56],[5.1,140.61],[4.8,26.56],[4.7,51.63],[5.2,162.5],[5,102.88],[4.5,57.41],[4.4,57.6],[4.9,85.92],[4.6,18.38],[7.6,1.84],[6.8,2],[4.3,12.82],[4.2,41.16],[3.95,4],[4,48],[7.4,1.04]],"spb":[[1000,70],[6,45],[4.3,83.33]],"spl":[[1.01,113.68],[11.5,10.48]],"batb":[[1,5.4,21.52],[2,5.3,2.02],[0,5.5,2.96]],"batl":[[0,5.7,3.85],[2,5.9,2.56],[1,5.8,17.32]],"bdatb":[[0,5.5,2.96],[2,5.3,5.46],[1,5.4,21.52]],"bdatl":[[1,5.8,17.32],[2,5.9,9.78],[0,5.7,3.85]],"spn":5.23,"spf":2.74,"ltp":5.5,"tv":2895.47,"id":73074145},{"atb":[[1.81,31.54],[1.83,67.65],[1.03,2234],[1.66,38],[1.53,91.35],[1.82,3.02],[1.84,23.16],[1.68,97.5],[1.71,10],[1.8,161.75],[1.75,74.63],[1.74,7.55],[1.72,13.42],[1.79,6.64],[1.77,8.65],[1.04,11.77],[1.05,83.21],[1.06,5006.66],[1.02,5291.37],[1.16,83.21],[1.27,80.13],[1.76,7.39],[1.78,7.35],[1.01,42331.77],[1.6,47.36],[1.55,0.08],[1.1,2.1],[1.17,776.47],[1.07,942.86],[1.13,1523.08],[1.09,1466.67],[1.31,2.55],[1.23,6.55],[1.4,20],[1.5,7.69],[1.73,58.7],[1.41,0.16],[1.26,50],[1.22,1],[1.3,30],[1.49,4.08]],"atl":[[1.86,12.96],[1.87,19.72],[5.3,2],[1.89,13.01],[2.22,0.77],[1.88,368.19],[1.91,6.6],[1.9,27.82],[1.93,136.15],[1.92,23.49],[2,39.82],[2.06,39],[2.02,217.42],[1.95,30.1],[1.96,33.08],[1.97,9.5],[1.94,45],[2.04,36.1],[1.99,14.82],[4,6.66],[1.98,10.1],[5,6],[2.7,3],[990,4.41],[27,8.32],[2.1,2],[2.14,35],[2.16,5],[2.68,0.16],[2.26,4],[200,0.3],[44,1],[2.9,0.83],[21,4.5],[500,0.01],[3.7,1],[17,18],[55,21],[160,2],[34,18],[8,14]],"trd":[[1.85,616.9],[1.86,815.55],[1.87,625.71],[1.84,922.38],[1.88,612.59],[1.89,777.77],[1.9,1209.92],[1.92,289.07],[1.91,220.48],[1.83,239.71],[1.97,663.25],[1.79,50.35],[1.82,84.11],[1.8,80.32],[1.76,86.33],[1.94,331.29],[2.04,34.79],[1.98,556.13],[1.73,87.07],[1.77,131.19],[1.81,174.48],[1.99,161.73],[1.95,121.57],[1.93,104.01],[1.96,407.14],[1.78,78.8],[1.7,16.03],[2,473.14],[1.57,26.03],[1.75,18],[2.06,2.98],[1.58,10],[1.59,1.96],[1.66,20],[1.74,57.02],[2.02,76.97],[1.71,1.96]],"spb":[[1000,114.06],[1.75,83.33]],"spl":[[1.01,383.89],[2,2],[2.34,82.09]],"batb":[[1,1.83,67.65],[2,1.82,3.02],[0,1.84,23.16]],"batl":[[0,1.86,12.96],[2,1.88,368.19],[1,1.87,19.72]],"bdatb":[[0,1.84,23.16],[2,1.82,13.04],[1,1.83,67.65]],"bdatl":[[0,1.86,12.96],[1,1.87,19.72],[2,1.88,368.19]],"spn":1.82,"spf":1.49,"ltp":1.85,"tv":10186.73,"id":72176817}],"img":true,"tv":17540.83}]}{"op":"mcm","id":2,"clk":"ANQBAPoBAOsB","pt":1730202590407,"mc":[{"id":"1.235123059","rc":[{"atl":[[5.7,0],[5.8,15.46]],"trd":[[5.7,316.89],[5.8,151.39]],"batl":[[2,6,1.05],[1,5.9,2.56],[0,5.8,15.46]],"ltp":5.8,"tv":2906.88,"id":73074145}],"tv":17552.24}]}{"op":"mcm","id":2,"clk":"ANkBAIECAO8B","pt":1730202590428,"mc":[{"id":"1.235123059","rc":[{"bdatb":[[1,3.9,26.14],[2,3.85,30.34]],"id":74399333},{"bdatl":[[0,5.8,15.46],[1,5.9,9.78],[2,6,11.51]],"id":73074145},{"bdatb":[[2,1.82,3.02]],"id":72176817}]}]}{"op":"mcm","id":2,"clk":"ANwBAI4CAPkB","pt":1730202590517,"mc":[{"id":"1.235123059","rc":[{"atb":[[3.95,22.71]],"batb":[[0,3.95,22.71]],"id":74399333},{"atb":[[5.4,22.41]],"atl":[[5.8,14.57]],"batb":[[1,5.4,22.41]],"batl":[[0,5.8,14.57]],"id":73074145}]}]}{"op":"mcm","id":2,"clk":"AOEBAI4CAPkB","pt":1730202590533,"mc":[{"id":"1.235123059","rc":[{"bdatb":[[0,3.95,22.71]],"bdatl":[[2,4.3,30.33]],"id":74399333},{"bdatb":[[1,5.4,22.41]],"bdatl":[[0,5.8,14.57],[2,6,8.9]],"id":73074145}]}]}{"op":"mcm","id":2,"clk":"AO8BAKECAIoC","pt":1730202590712,"mc":[{"id":"1.235123059","rc":[{"atl":[[5.8,24.07]],"batl":[[0,5.8,24.07]],"id":73074145}]}]}{"op":"mcm","id":2,"clk":"APUBAKYCAI4C","pt":1730202590716,"mc":[{"id":"1.235123059","rc":[{"bdatl":[[0,5.8,24.07]],"id":73074145}]}]}{"op":"mcm","id":2,"clk":"AMkCAIIDAPUC","pt":1730202591706,"mc":[{"id":"1.235123059","rc":[{"atb":[[3.95,24.71]],"batb":[[0,3.95,24.71]],"id":74399333}]}]}{"op":"mcm","id":2,"clk":"AM4CAIQDAPgC","pt":1730202591724,"mc":[{"id":"1.235123059","rc":[{"bdatb":[[0,3.95,24.71]],"id":74399333},{"bdatl":[[2,6,10.21]],"id":73074145}]}]}{"op":"mcm","id":2,"clk":"AJwDAOkDAO0D","pt":1730202592693,"mc":[{"id":"1.235123059","rc":[{"atl":[[5.7,2]],"batl":[[2,5.9,2.56],[1,5.8,24.07],[0,5.7,2]],"id":73074145}]}]}{"op":"mcm","id":2,"clk":"AJwDAOkDAO0D","pt":1730202592701,"mc":[{"id":"1.235123059","rc":[{"bdatb":[[1,3.9,29.07],[2,3.85,27.38]],"id":74399333},{"bdatl":[[0,5.7,2],[1,5.8,24.07],[2,5.9,9.78]],"id":73074145},{"bdatb":[[2,1.82,9.28]],"id":72176817}]}]}{"op":"mcm","id":2,"clk":"AKQDAPMDAPQD","pt":1730202592786,"mc":[{"id":"1.235123059","rc":[{"atl":[[5.7,4.58]],"batl":[[0,5.7,4.58]],"id":73074145}]}]}{"op":"mcm","id":2,"clk":"AKQDAPMDAPQD","pt":1730202592805,"mc":[{"id":"1.235123059","rc":[{"bdatb":[[1,3.9,30.82],[2,3.85,27.13]],"id":74399333},{"bdatl":[[0,5.7,4.58]],"id":73074145},{"bdatb":[[2,1.82,13.04]],"id":72176817}]}]}{"op":"mcm","id":2,"clk":"AOkDAM0EAMwE","pt":1730202593612,"mc":[{"id":"1.235123059","rc":[{"atb":[[4,2]],"batb":[[2,3.9,26.14],[1,3.95,24.71],[0,4,2]],"id":74399333}]}]}{"op":"mcm","id":2,"clk":"AOoDAM0EANAE","pt":1730202593617,"mc":[{"id":"1.235123059","rc":[{"bdatb":[[0,4,2],[1,3.95,24.71],[2,3.9,30.82]],"id":74399333},{"bdatl":[[1,5.8,25.45],[2,5.9,8.43]],"id":73074145},{"bdatl":[[1,1.87,24]],"id":72176817}]}]}{"op":"mcm","id":2,"clk":"APUDANcEANQE","pt":1730202593718,"mc":[{"id":"1.235123059","rc":[{"atl":[[4.5,20.08]],"batl":[],"id":74399333}]}]}{"op":"mcm","id":2,"clk":"APsDAOEEAOYE","pt":1730202593819,"mc":[{"id":"1.235123059","rc":[{"atb":[[3.9,32.73],[3.95,26.75],[4,6.65]],"batb":[[2,3.9,32.73],[1,3.95,26.75],[0,4,6.65]],"id":74399333}]}]}{"op":"mcm","id":2,"clk":"AP0DAOMEAOkE","pt":1730202593827,"mc":[{"id":"1.235123059","rc":[{"bdatb":[[0,4,6.65],[1,3.95,26.75],[2,3.9,37.4]],"id":74399333},{"bdatl":[[1,5.8,28.65],[2,5.9,5.27]],"id":73074145},{"bdatl":[[1,1.87,28.43]],"id":72176817}]}]}{"op":"mcm","id":2,"clk":"AJEEAPsEAIYF","pt":1730202594055,"mc":[{"id":"1.235123059","rc":[{"atb":[[1.84,13.27]],"batb":[[0,1.84,13.27]],"bdatb":[[0,1.84,13.27]],"id":72176817},{"bdatl":[[1,5.8,28.28],[2,5.9,2.93]],"id":73074145}]}]}{"op":"mcm","id":2,"clk":"APYGAJ8IAJEI","pt":1730202598010,"mc":[{"id":"1.235123059","rc":[{"atb":[[3.9,39.17]],"batb":[[2,3.9,39.17]],"id":74399333}]}]}{"op":"mcm","id":2,"clk":"APcGAKMIAJMI","pt":1730202598016,"mc":[{"id":"1.235123059","rc":[{"bdatb":[[2,3.9,43.85]],"id":74399333}]}]}{"op":"mcm","id":2,"clk":"AJsIAKwKANkJ","pt":1730202600199,"mc":[{"id":"1.235123059","rc":[{"atl":[[5.7,54.58]],"batl":[[0,5.7,54.58]],"id":73074145}]}]}{"op":"mcm","id":2,"clk":"AJwIAKwKANsJ","pt":1730202600220,"mc":[{"id":"1.235123059","rc":[{"bdatl":[[0,5.7,54.58]],"id":73074145}]}]}{"op":"mcm","id":2,"clk":"AKsIAMcKAOsJ","pt":1730202600410,"mc":[{"id":"1.235123059","rc":[{"atb":[[5.5,0]],"atl":[[5.5,2.96]],"trd":[[5.5,488.21]],"batb":[[2,5.2,22.69],[1,5.3,2.02],[0,5.4,22.41]],"batl":[[2,5.8,24.07],[1,5.7,54.58],[0,5.5,2.96]],"ltp":5.5,"tv":2912.8,"id":73074145}],"tv":17558.16}]}{"op":"mcm","id":2,"clk":"AKsIAMsKAOwJ","pt":1730202600427,"mc":[{"id":"1.235123059","rc":[{"bdatb":[[0,4,10.72],[2,3.9,39.68]],"bdatl":[[1,4.2,13.64]],"id":74399333},{"bdatb":[[0,5.4,22.41],[1,5.3,5.46],[2,5.2,30.91]],"bdatl":[[0,5.5,2.96],[1,5.7,54.58],[2,5.8,28.28]],"id":73074145},{"bdatb":[[0,1.84,22.12],[2,1.82,4.1]],"bdatl":[[1,1.87,19.72]],"id":72176817}]}]}{"op":"mcm","id":2,"clk":"AL0IANcKAPQJ","pt":1730202600513,"mc":[{"id":"1.235123059","rc":[{"atb":[[4,9.32]],"batb":[[0,4,9.32]],"id":74399333},{"atb":[[4.9,10.09],[5,19.22]],"atl":[[5.5,0]],"trd":[[5.5,494.13]],"batb":[],"batl":[[2,5.9,2.56],[1,5.8,24.07],[0,5.7,54.58]],"tv":2918.72,"id":73074145},{"atb":[[1.84,23.5]],"atl":[[1.86,2.76]],"batb":[[0,1.84,23.5]],"batl":[[0,1.86,2.76]],"id":72176817}],"tv":17564.08}]}{"op":"mcm","id":2,"clk":"AL4IANkKAPYJ","pt":1730202600519,"mc":[{"id":"1.235123059","rc":[{"bdatb":[[0,4,9.32],[2,3.9,40.49]],"bdatl":[],"id":74399333},{"bdatb":[[1,5.3,2.99],[2,5.2,29.78]],"bdatl":[[0,5.7,54.58],[1,5.8,30.5],[2,5.9,3.57]],"id":73074145},{"bdatb":[[0,1.84,23.5],[2,1.82,13.04]],"bdatl":[[0,1.86,2.76]],"id":72176817}]}]}{"op":"mcm","id":2,"clk":"AMQIAOQKAIEK","pt":1730202600624,"mc":[{"id":"1.235123059","rc":[{"atb":[[4,3.32]],"trd":[[4,668.13]],"batb":[[0,4,3.32]],"ltp":4,"tv":3888.64,"id":74399333},{"atb":[[5.3,2.99],[5.5,1]],"batb":[[2,5.3,2.99],[1,5.4,22.41],[0,5.5,1]],"id":73074145}],"tv":17576.08}]}{"op":"mcm","id":2,"clk":"AMQIAOQKAIEK","pt":1730202600660,"mc":[{"id":"1.235123059","rc":[{"bdatb":[[0,4,3.32]],"bdatl":[[1,4.2,14.95]],"id":74399333},{"bdatb":[[0,5.5,1],[1,5.4,22.41],[2,5.3,3.96]],"bdatl":[[1,5.8,26.36],[2,5.9,7.64]],"id":73074145},{"bdatl":[[1,1.87,22.66]],"id":72176817}]}]}{"op":"mcm","id":2,"clk":"AM4IAOsKAIcK","pt":1730202600720,"mc":[{"id":"1.235123059","rc":[{"atb":[[4.9,7.41],[5,16.66]],"batb":[],"id":73074145},{"atb":[[1.85,10.2]],"batb":[[2,1.83,67.65],[1,1.84,23.5],[0,1.85,10.2]],"id":72176817}]}]}{"op":"mcm","id":2,"clk":"ANUIAO4KAIkK","pt":1730202600729,"mc":[{"id":"1.235123059","rc":[{"bdatl":[[2,40,10.93]],"id":9517643},{"bdatl":[[0,4.1,30.04],[1,4.2,16.83],[2,4.3,27.22]],"id":74399333},{"bdatb":[],"bdatl":[[0,5.7,56.91],[1,5.8,25.03],[2,5.9,9.89]],"id":73074145},{"bdatb":[[0,1.85,10.2],[1,1.84,23.5],[2,1.83,67.65]],"id":72176817}]}]}{"op":"mcm","id":2,"clk":"ANoIAPkKAJMK","pt":1730202600827,"mc":[{"id":"1.235123059","rc":[{"atb":[[4,6.67]],"batb":[[0,4,6.67]],"id":74399333},{"atb":[[5.4,25.41]],"batb":[[1,5.4,25.41]],"id":73074145}]}]}{"op":"mcm","id":2,"clk":"AOAIAP8KAJgK","pt":1730202600855,"mc":[{"id":"1.235123059","rc":[{"bdatb":[[0,4,6.67]],"bdatl":[[2,4.3,30.99]],"id":74399333},{"bdatb":[[1,5.4,25.41]],"bdatl":[[0,5.7,57.89],[1,5.8,25.41],[2,5.9,8.57]],"id":73074145}]}]}{"op":"mcm","id":2,"clk":"AOMIAIsLAJ0K","pt":1730202600926,"mc":[{"id":"1.235123059","rc":[{"atb":[[4,4]],"batb":[[0,4,4]],"id":74399333}]}]}{"op":"mcm","id":2,"clk":"AO0IAIwLAJ8K","pt":1730202600943,"mc":[{"id":"1.235123059","rc":[{"bdatb":[[0,4,4]],"id":74399333},{"bdatl":[[0,5.7,57.39],[1,5.8,24.56],[2,5.9,9.89]],"id":73074145}]}]}{"op":"mcm","id":2,"clk":"APgIAJ8LALUK","pt":1730202601132,"mc":[{"id":"1.235123059","rc":[{"atb":[[1.34,1]],"id":9517643},{"atb":[[2,2]],"id":74399333},{"atl":[[1000,0.03]],"id":72176817}]}]}{"op":"mcm","id":2,"clk":"AI8JALQLAMYK","pt":1730202601295,"mc":[{"id":"1.235123059","rc":[{"atb":[[1.34,0.06]],"id":9517643},{"atb":[[4,1],[2,1.02]],"trd":[[4,674.13]],"batb":[[0,4,1]],"tv":3894.64,"id":74399333},{"atl":[[1000,0]],"id":72176817}],"tv":17582.08}]}{"op":"mcm","id":2,"clk":"AI8JALULAMgK","pt":1730202601328,"mc":[{"id":"1.235123059","rc":[{"bdatl":[[2,40,10.9]],"id":9517643},{"bdatb":[[0,4,1]],"id":74399333},{"bdatl":[[0,5.7,55.28],[1,5.8,26.63]],"id":73074145},{"bdatl":[[1,1.87,21.86]],"id":72176817}]}]}{"op":"mcm","id":2,"clk":"AJcJAMQLANEK","pt":1730202601407,"mc":[{"id":"1.235123059","rc":[{"atb":[[1.34,0]],"id":9517643},{"atb":[[4,0],[2,1]],"atl":[[4,2.81]],"trd":[[4,676.13]],"batb":[[2,3.85,25.61],[1,3.9,39.17],[0,3.95,26.75]],"batl":[[2,4.2,13.64],[1,4.1,28.7],[0,4,2.81]],"tv":3896.64,"id":74399333},{"atb":[[1.85,10.17]],"trd":[[1.85,616.96]],"batb":[[0,1.85,10.17]],"tv":10186.79,"id":72176817}],"tv":17584.14}]}{"op":"mcm","id":2,"clk":"AJcJAMQLANEK","pt":1730202601427,"mc":[{"id":"1.235123059","rc":[{"bdatb":[],"bdatl":[[2,40,10.79]],"id":9517643},{"bdatb":[[0,3.95,26.75],[1,3.9,40.49],[2,3.85,29.01]],"bdatl":[[0,4,2.81],[1,4.1,30.04],[2,4.2,16.81]],"id":74399333},{"bdatb":[[0,5.5,1.93],[1,5.4,26.54],[2,5.3,2.99]],"bdatl":[[0,5.7,54.58],[1,5.8,27.31]],"id":73074145},{"bdatb":[[0,1.85,10.17],[1,1.84,29.61]],"bdatl":[[1,1.87,19.72]],"id":72176817}]}]}{"op":"mcm","id":2,"clk":"AKAJANMLANsK","pt":1730202601510,"mc":[{"id":"1.235123059","rc":[{"atl":[[32,0.51]],"trd":[[32,29.96]],"batl":[[0,34,2.31]],"ltp":32,"tv":582.11,"id":9517643},{"atb":[[3,56.01]],"atl":[[4,2.79]],"trd":[[4,676.17]],"batl":[[0,4,2.79]],"tv":3896.68,"id":74399333}],"tv":17584.3}]}{"op":"mcm","id":2,"clk":"AKAJANMLANwK","pt":1730202601524,"mc":[{"id":"1.235123059","rc":[{"bdatb":[],"bdatl":[[0,34,2.31]],"id":9517643},{"bdatb":[[2,3.85,28.51]],"bdatl":[[0,4,2.79]],"id":74399333},{"bdatb":[[1,5.4,26.52]],"id":73074145},{"bdatb":[[1,1.84,29.57]],"id":72176817}]}]}{"op":"mcm","id":2,"clk":"AKkJANoLAOUK","pt":1730202601606,"mc":[{"id":"1.235123059","rc":[{"atb":[[3.9,26.14]],"atl":[[4.1,26.73],[4,0]],"trd":[[4.1,387.7],[4,681.75]],"batb":[[1,3.9,26.14]],"batl":[[2,4.3,2.19],[1,4.2,13.64],[0,4.1,26.73]],"ltp":4.1,"tv":3902.3,"id":74399333},{"atl":[[5.8,19.26]],"batl":[[1,5.8,19.26]],"id":73074145}],"tv":17589.92}]}{"op":"mcm","id":2,"clk":"AKoJANsLAOkK","pt":1730202601620,"mc":[{"id":"1.235123059","rc":[{"bdatb":[[1,3.9,27.46]],"bdatl":[[0,4.1,28.07],[1,4.2,16.81],[2,4.3,31]],"id":74399333},{"bdatb":[[0,5.5,1],[1,5.4,25.41],[2,5.3,3.96]],"bdatl":[[1,5.8,22.5]],"id":73074145},{"bdatb":[[1,1.84,23.5]],"bdatl":[],"id":72176817}]}]}{"op":"mcm","id":2,"clk":"ALEJAOYLAO8K","pt":1730202601710,"mc":[{"id":"1.235123059","rc":[{"atb":[[3.95,30.72]],"batb":[[0,3.95,30.72]],"id":74399333},{"atl":[[5.6,2.98]],"batl":[[2,5.8,19.26],[1,5.7,54.58],[0,5.6,2.98]],"id":73074145},{"atb":[[1.81,26.44]],"batb":[],"id":72176817}]}]}{"op":"mcm","id":2,"clk":"ALIJAOgLAPIK","pt":1730202601730,"mc":[{"id":"1.235123059","rc":[{"bdatb":[[0,3.95,32.02],[1,3.9,29.01],[2,3.85,25.7]],"id":74399333},{"bdatl":[[0,5.6,2.98],[1,5.7,54.58],[2,5.8,22.5]],"id":73074145},{"bdatb":[[2,1.83,76.57]],"bdatl":[],"id":72176817}]}]}{"op":"mcm","id":2,"clk":"ALsJAPELAPwK","pt":1730202601816,"mc":[{"id":"1.235123059","rc":[{"atl":[[4.5,16.83]],"batl":[],"id":74399333},{"atl":[[5.6,3.94]],"batl":[[0,5.6,3.94]],"id":73074145}]}]}{"op":"mcm","id":2,"clk":"AMEJAPYLAP8K","pt":1730202601827,"mc":[{"id":"1.235123059","rc":[{"bdatb":[[2,3.85,27.09]],"bdatl":[],"id":74399333},{"bdatl":[[0,5.6,3.94]],"id":73074145}]}]}{"op":"mcm","id":2,"clk":"AMsJAIEMAIoL","pt":1730202601926,"mc":[{"id":"1.235123059","rc":[{"atl":[[5.8,17.31]],"batl":[[2,5.8,17.31]],"id":73074145}]}]}{"op":"mcm","id":2,"clk":"AMwJAIUMAI0L","pt":1730202601949,"mc":[{"id":"1.235123059","rc":[{"bdatl":[[2,5.8,20.56]],"id":73074145}]}]}{"op":"mcm","id":2,"clk":"AM8JAI4MAJYL","pt":1730202602023,"mc":[{"id":"1.235123059","rc":[{"spb":[[1000,82.91]],"id":73074145}]}]}{"op":"mcm","id":2,"clk":"AOUJAKkMAKoL","pt":1730202602231,"mc":[{"id":"1.235123059","rc":[{"atl":[[5.6,8.51]],"batl":[[0,5.6,8.51]],"id":73074145}]}]}{"op":"mcm","id":2,"clk":"AOYJAKsMAKsL","pt":1730202602238,"mc":[{"id":"1.235123059","rc":[{"bdatb":[[2,3.85,32.28]],"id":74399333},{"bdatl":[[0,5.6,8.51]],"id":73074145}]}]}{"op":"mcm","id":2,"clk":"AMcNAJsRAKMP","pt":1730202607122,"mc":[{"id":"1.235123059","rc":[{"atb":[[30,6.06]],"trd":[[30,70.36]],"batb":[[0,30,6.06]],"ltp":30,"tv":584.11,"id":9517643}],"tv":17591.92}]}{"op":"mcm","id":2,"clk":"AMkNAJwRAKQP","pt":1730202607127,"mc":[{"id":"1.235123059","rc":[{"bdatb":[[0,30,6.06]],"id":9517643}]}]}{"op":"mcm","id":2,"clk":"AN0NALMRALgP","pt":1730202607325,"mc":[{"id":"1.235123059","rc":[{"atb":[[5.5,0]],"batb":[[2,5.2,22.69],[1,5.3,2.99],[0,5.4,25.41]],"id":73074145}]}]}{"op":"mcm","id":2,"clk":"AOINALkRALoP","pt":1730202607334,"mc":[{"id":"1.235123059","rc":[{"bdatl":[[0,4.1,26.73],[1,4.2,18.12],[2,4.3,29.72]],"id":74399333},{"bdatb":[[0,5.4,25.41],[1,5.3,3.96],[2,5.2,29.78]],"id":73074145}]}]}{"op":"mcm","id":2,"clk":"APUNAMwRAM0P","pt":1730202607535,"mc":[{"id":"1.235123059","rc":[{"atb":[[3.9,27.74]],"batb":[[1,3.9,27.74]],"id":74399333},{"atb":[[5.2,25.69],[5.3,6.32],[5.1,13.25]],"batb":[[2,5.2,25.69],[1,5.3,6.32]],"id":73074145}]}]}{"op":"mcm","id":2,"clk":"APwNANMRANIP","pt":1730202607552,"mc":[{"id":"1.235123059","rc":[{"bdatb":[[1,3.9,30.61]],"bdatl":[],"id":74399333},{"bdatb":[[1,5.3,7.29],[2,5.2,32.78]],"bdatl":[],"id":73074145}]}]}{"op":"mcm","id":2,"clk":"AP0NAN0RANgP","pt":1730202607589,"mc":[{"id":"1.235123059","rc":[{"atl":[[5.6,8.42]],"trd":[[5.6,358.94]],"batl":[[0,5.6,8.42]],"ltp":5.6,"tv":2918.91,"id":73074145}],"tv":17592.11}]}{"op":"mcm","id":2,"clk":"AP0NAN0RANkP","pt":1730202607599,"mc":[{"id":"1.235123059","rc":[{"bdatl":[[0,5.6,8.42]],"id":73074145}]}]}{"op":"mcm","id":2,"clk":"AKAOAKUSAIUQ","pt":1730202608103,"mc":[{"id":"1.235123059","rc":[{"atl":[[32,3.4]],"batl":[[2,36,1.97],[1,34,1.8],[0,32,3.4]],"id":9517643}]}]}{"op":"mcm","id":2,"clk":"AKEOAKYSAIcQ","pt":1730202608120,"mc":[{"id":"1.235123059","rc":[{"bdatl":[[0,32,3.4],[1,34,1.8],[2,36,1.97]],"id":9517643},{"bdatb":[[1,3.9,37.2],[2,3.85,26.94]],"id":74399333},{"bdatb":[[2,1.83,93.41]],"id":72176817}]}]}{"op":"mcm","id":2,"clk":"AKoOAMASAJgQ","pt":1730202608305,"mc":[{"id":"1.235123059","rc":[{"atl":[[32,2.16]],"trd":[[32,32.44]],"batl":[[0,32,2.16]],"ltp":32,"tv":586.59,"id":9517643}],"tv":17594.59}]}{"op":"mcm","id":2,"clk":"AKoOAMESAJoQ","pt":1730202608318,"mc":[{"id":"1.235123059","rc":[{"bdatl":[[0,32,2.16]],"id":9517643}]}]}{"op":"mcm","id":2,"clk":"AMIOAOYSAMYQ","pt":1730202608619,"mc":[{"id":"1.235123059","rc":[{"atb":[[29,3.54]],"batb":[[1,29,3.54]],"id":9517643}]}]}{"op":"mcm","id":2,"clk":"AMYOAOoSAMYQ","pt":1730202608636,"mc":[{"id":"1.235123059","rc":[{"bdatb":[[1,29,3.54]],"id":9517643}]}]}{"op":"mcm","id":2,"clk":"AMkOAPQSANMQ","pt":1730202608727,"mc":[{"id":"1.235123059","rc":[{"atb":[[5.4,19.24]],"batb":[[0,5.4,19.24]],"id":73074145}]}]}{"op":"mcm","id":2,"clk":"AM4OAPcSANYQ","pt":1730202608750,"mc":[{"id":"1.235123059","rc":[{"bdatl":[[2,4.3,21.98]],"id":74399333},{"bdatb":[[0,5.4,19.24]],"id":73074145}]}]}{"op":"mcm","id":2,"clk":"ANcOAIkTAOkQ","pt":1730202608923,"mc":[{"id":"1.235123059","rc":[{"atb":[[29,1.76]],"batb":[[1,29,1.76]],"id":9517643}]}]}{"op":"mcm","id":2,"clk":"ANgOAIoTAOwQ","pt":1730202608929,"mc":[{"id":"1.235123059","rc":[{"bdatb":[[1,29,1.76]],"id":9517643}]}]}{"op":"mcm","id":2,"clk":"AOoOAKYTAIUR","pt":1730202609090,"mc":[{"id":"1.235123059","rc":[{"atl":[[32,0.92]],"trd":[[32,34.92]],"batl":[[2,40,10.79],[1,36,1.97],[0,34,2.72]],"tv":589.07,"id":9517643}],"tv":17597.07}]}{"op":"mcm","id":2,"clk":"AOoOAKYTAIUR","pt":1730202609101,"mc":[{"id":"1.235123059","rc":[{"bdatl":[[0,34,2.72],[1,36,1.97],[2,40,10.79]],"id":9517643},{"bdatb":[[1,3.9,33.94],[2,3.85,28.9]],"id":74399333},{"bdatb":[[2,1.83,83.68]],"id":72176817}]}]}{"op":"mcm","id":2,"clk":"AI0PANcTAK4R","pt":1730202609506,"mc":[{"id":"1.235123059","rc":[{"atb":[[29,2.8]],"batb":[[1,29,2.8]],"id":9517643}]}]}{"op":"mcm","id":2,"clk":"AI0PANcTALAR","pt":1730202609529,"mc":[{"id":"1.235123059","rc":[{"bdatb":[[1,29,2.8]],"id":9517643}]}]}{"op":"mcm","id":2,"clk":"AOoPAOYUAKgS","pt":1730202610597,"mc":[{"id":"1.235123059","rc":[{"atb":[[4,2]],"batb":[[2,3.9,27.74],[1,3.95,30.72],[0,4,2]],"id":74399333}]}]}{"op":"mcm","id":2,"clk":"AOoPAOYUAKoS","pt":1730202610603,"mc":[{"id":"1.235123059","rc":[{"bdatb":[[0,4,2],[1,3.95,32.02],[2,3.9,33.94]],"id":74399333},{"bdatl":[[1,5.7,55.98],[2,5.8,19.18]],"id":73074145}]}]}{"op":"mcm","id":2,"clk":"APAPAPIUALES","pt":1730202610693,"mc":[{"id":"1.235123059","rc":[{"atb":[[4,9]],"atl":[[4.5,20.08]],"batb":[[0,4,9]],"batl":[],"id":74399333}]}]}{"op":"mcm","id":2,"clk":"APIPAPIUALsS","pt":1730202610711,"mc":[{"id":"1.235123059","rc":[{"bdatb":[[0,4,9]],"bdatl":[],"id":74399333},{"bdatb":[],"bdatl":[[1,5.7,57.88],[2,5.8,20.28]],"id":73074145}]}]}{"op":"mcm","id":2,"clk":"AKAQALMVAOwS","pt":1730202611221,"mc":[{"id":"1.235123059","rc":[{"atb":[[1.86,2.24]],"atl":[[1.86,0]],"trd":[[1.86,821.07]],"batb":[[2,1.84,23.5],[1,1.85,10.17],[0,1.86,2.24]],"batl":[[2,1.89,13.01],[1,1.88,368.19],[0,1.87,19.72]],"ltp":1.86,"tv":10192.31,"id":72176817}],"tv":17602.59}]}{"op":"mcm","id":2,"clk":"AKAQALcVAOwS","pt":1730202611235,"mc":[{"id":"1.235123059","rc":[{"bdatb":[],"bdatl":[[2,40,10.9]],"id":9517643},{"bdatb":[[1,3.95,30.72],[2,3.9,35.26]],"bdatl":[[1,4.2,19.11],[2,4.3,21.01]],"id":74399333},{"bdatb":[[1,5.3,6.32]],"bdatl":[[0,5.6,9.16],[2,5.8,19.56]],"id":73074145},{"bdatb":[[0,1.86,2.24],[1,1.85,10.17],[2,1.84,23.5]],"bdatl":[[0,1.87,19.72],[1,1.88,368.19],[2,1.89,32.06]],"id":72176817}]}]}{"op":"mcm","id":2,"clk":"AKcQAL4VAPIS","pt":1730202611321,"mc":[{"id":"1.235123059","rc":[{"atl":[[4.4,28.42]],"batl":[],"id":74399333},{"atb":[[1.86,0],[1.85,13.36]],"trd":[[1.86,825.55]],"batb":[[2,1.83,67.65],[1,1.84,23.5],[0,1.85,13.36]],"tv":10196.79,"id":72176817}],"tv":17607.07}]}{"op":"mcm","id":2,"clk":"ALAQAMMVAPcS","pt":1730202611336,"mc":[{"id":"1.235123059","rc":[{"bdatl":[[2,40,10.79]],"id":9517643},{"bdatl":[[1,4.2,19.53],[2,4.3,20.61]],"id":74399333},{"bdatb":[],"bdatl":[[0,5.6,8.42],[1,5.7,58.92],[2,5.8,19.26]],"id":73074145},{"bdatb":[[0,1.85,13.36],[1,1.84,23.5],[2,1.83,83.68]],"id":72176817}]}]}{"op":"mcm","id":2,"clk":"ALMQAMQVAPwS","pt":1730202611419,"mc":[{"id":"1.235123059","rc":[{"atl":[[5.5,1.78]],"batl":[[2,5.7,54.58],[1,5.6,8.42],[0,5.5,1.78]],"id":73074145}]}]}{"op":"mcm","id":2,"clk":"ALMQAMQVAIMT","pt":1730202611425,"mc":[{"id":"1.235123059","rc":[{"bdatb":[[1,3.95,33.2],[2,3.9,32.75]],"id":74399333},{"bdatl":[[0,5.5,1.78],[1,5.6,8.42],[2,5.7,58.92]],"id":73074145},{"bdatb":[[1,1.84,28.82],[2,1.83,78.33]],"id":72176817}]}]}{"op":"mcm","id":2,"clk":"ALgQANUVAIoT","pt":1730202611529,"mc":[{"id":"1.235123059","rc":[{"atl":[[4.4,25]],"batl":[],"id":74399333},{"atb":[[4.9,10.09],[5,19.22]],"batb":[],"id":73074145},{"atl":[[1.87,29.88]],"batl":[[0,1.87,29.88]],"id":72176817}]}]}{"op":"mcm","id":2,"clk":"AL4QANwVAI4T","pt":1730202611541,"mc":[{"id":"1.235123059","rc":[{"bdatb":[[2,5.2,36.43]],"id":73074145},{"bdatl":[[0,1.87,29.88]],"id":72176817}]}]}{"op":"mcm","id":2,"clk":"ANMQAPkVAKgT","pt":1730202611818,"mc":[{"id":"1.235123059","rc":[{"atb":[[3.9,29.74]],"batb":[[2,3.9,29.74]],"id":74399333}]}]}{"op":"mcm","id":2,"clk":"ANMQAPoVAKkT","pt":1730202611829,"mc":[{"id":"1.235123059","rc":[{"bdatb":[[2,3.9,34.75]],"id":74399333}]}]}{"op":"mcm","id":2,"clk":"AMcRAJEXAKEU","pt":1730202613095,"mc":[{"id":"1.235123059","rc":[{"atb":[[3.95,32.72]],"batb":[[1,3.95,32.72]],"id":74399333}]}]}{"op":"mcm","id":2,"clk":"AMcRAJIXAKQU","pt":1730202613104,"mc":[{"id":"1.235123059","rc":[{"bdatb":[[1,3.95,35.2]],"id":74399333}]}]}{"op":"mcm","id":2,"clk":"APISAI0ZAOIV","pt":1730202615002,"mc":[{"id":"1.235123059","rc":[{"atb":[[1.86,2]],"batb":[[2,1.84,23.5],[1,1.85,13.36],[0,1.86,2]],"id":72176817}]}]}{"op":"mcm","id":2,"clk":"APISAI4ZAOYV","pt":1730202615012,"mc":[{"id":"1.235123059","rc":[{"bdatl":[[2,40,10.89]],"id":9517643},{"bdatl":[[1,4.2,20.41],[2,4.3,19.74]],"id":74399333},{"bdatl":[[1,5.6,9.08]],"id":73074145},{"bdatb":[[0,1.86,2],[1,1.85,13.36],[2,1.84,28.82]],"id":72176817}]}]}{"op":"mcm","id":2,"clk":"AP4SAJwZAO4V","pt":1730202615109,"mc":[{"id":"1.235123059","rc":[{"atl":[[4.4,28.42]],"batl":[],"id":74399333},{"atb":[[5.4,16.24]],"batb":[[0,5.4,16.24]],"id":73074145},{"atb":[[1.85,22.36]],"batb":[[1,1.85,22.36]],"id":72176817}]}]}{"op":"mcm","id":2,"clk":"AP4SAJ0ZAPEV","pt":1730202615120,"mc":[{"id":"1.235123059","rc":[{"bdatl":[[1,4.2,24.38],[2,4.3,12.25]],"id":74399333},{"bdatb":[[0,5.4,16.24]],"bdatl":[[2,5.7,60.24]],"id":73074145},{"bdatb":[[1,1.85,22.36]],"bdatl":[],"id":72176817}]}]}{"op":"mcm","id":2,"clk":"AOcUANQbANwX","pt":1730202617426,"mc":[{"id":"1.235123059","rc":[{"atb":[[1.85,24.16]],"batb":[[1,1.85,24.16]],"id":72176817}]}]}{"op":"mcm","id":2,"clk":"AOcUANUbANwX","pt":1730202617437,"mc":[{"id":"1.235123059","rc":[{"bdatl":[[1,4.2,25.17]],"id":74399333},{"bdatb":[[1,1.85,24.16]],"id":72176817}]}]}{"op":"mcm","id":2,"clk":"AO0UAOQbAOQX","pt":1730202617500,"mc":[{"id":"1.235123059","rc":[{"atb":[[4,10.15]],"batb":[[0,4,10.15]],"id":74399333},{"atb":[[5.4,17.1]],"batb":[[0,5.4,17.1]],"id":73074145}]}]}{"op":"mcm","id":2,"clk":"AO0UAOQbAOUX","pt":1730202617517,"mc":[{"id":"1.235123059","rc":[{"bdatb":[[0,4,10.15]],"bdatl":[[2,4.3,12.4]],"id":74399333},{"bdatb":[[0,5.4,17.1]],"bdatl":[[2,5.7,61.05]],"id":73074145},{"bdatl":[[2,1.89,34.49]],"id":72176817}]}]}{"op":"mcm","id":2,"clk":"AKQYAP0gAI8c","pt":1730202622517,"ct":"HEARTBEAT"}{"op":"mcm","id":2,"clk":"AOoaAOkkAJMf","pt":1730202626118,"mc":[{"id":"1.235123059","rc":[{"atb":[[30,0.06]],"trd":[[30,82.36]],"batb":[[2,27,4.18],[1,28,1.46],[0,29,2.86]],"ltp":30,"tv":601.07,"id":9517643}],"tv":17619.07}]}{"op":"mcm","id":2,"clk":"AOoaAOkkAJMf","pt":1730202626140,"mc":[{"id":"1.235123059","rc":[{"bdatb":[[0,29,2.86],[1,28,1.46],[2,27,4.18]],"id":9517643},{"bdatl":[[1,5.6,8.74],[2,5.7,54.92]],"id":73074145}]}]}{"op":"mcm","id":2,"clk":"APMaAPckAJwf","pt":1730202626221,"mc":[{"id":"1.235123059","rc":[{"atb":[[30,0]],"atl":[[30,6.1]],"trd":[[30,82.48]],"batb":[[0,29,2.8]],"batl":[[2,36,1.97],[1,34,2.72],[0,30,6.1]],"tv":601.19,"id":9517643}],"tv":17619.19}]}{"op":"mcm","id":2,"clk":"APMaAPckAJwf","pt":1730202626225,"mc":[{"id":"1.235123059","rc":[{"bdatb":[[0,29,2.8]],"bdatl":[[0,30,6.1],[1,34,2.72],[2,36,1.97]],"id":9517643},{"bdatb":[[2,3.9,41.83]],"bdatl":[],"id":74399333},{"bdatb":[[1,5.3,16.86],[2,5.2,36.02]],"bdatl":[[1,5.6,8.42],[2,5.7,55.23]],"id":73074145}]}]}{"op":"mcm","id":2,"clk":"APoaAIAlAKgf","pt":1730202626320,"mc":[{"id":"1.235123059","rc":[{"atb":[[29,2.4]],"atl":[[30,4.9],[32,1.15]],"trd":[[30,84.88]],"batb":[[0,29,2.4]],"batl":[[2,34,1.8],[1,32,1.15],[0,30,4.9]],"tv":603.59,"id":9517643},{"atb":[[5.4,20.1],[5,16.66]],"batb":[[0,5.4,20.1]],"id":73074145}],"tv":17621.59}]}{"op":"mcm","id":2,"clk":"APsaAIIlAKgf","pt":1730202626334,"mc":[{"id":"1.235123059","rc":[{"bdatb":[[0,29,2.4]],"bdatl":[[0,30,4.9],[1,32,1.15],[2,34,1.8]],"id":9517643},{"bdatb":[],"bdatl":[[2,4.3,16.17]],"id":74399333},{"bdatb":[[0,5.4,20.1]],"bdatl":[],"id":73074145}]}]}{"op":"mcm","id":2,"clk":"AIobAJwlAL0f","pt":1730202626526,"mc":[{"id":"1.235123059","rc":[{"atb":[[29,0]],"atl":[[30,4.47]],"trd":[[30,85.74]],"batb":[[2,25,10.88],[1,27,4.18],[0,28,1.46]],"batl":[[0,30,4.47]],"tv":604.45,"id":9517643}],"tv":17622.45}]}{"op":"mcm","id":2,"clk":"AIwbAJwlAL0f","pt":1730202626532,"mc":[{"id":"1.235123059","rc":[{"bdatb":[[0,28,1.46],[1,27,4.18],[2,25,11.27]],"bdatl":[[0,30,4.47]],"id":9517643},{"bdatb":[],"bdatl":[[1,4.2,23.34],[2,4.3,14.03]],"id":74399333}]}]}{"op":"mcm","id":2,"clk":"ANUbAIMmAIkg","pt":1730202627314,"mc":[{"id":"1.235123059","rc":[{"atb":[[27,3.15]],"batb":[[1,27,3.15]],"id":9517643}]}]}{"op":"mcm","id":2,"clk":"ANUbAIMmAIkg","pt":1730202627328,"mc":[{"id":"1.235123059","rc":[{"bdatb":[[1,27,3.15]],"id":9517643}]}]}{"op":"mcm","id":2,"clk":"AOMbAJomAJwg","pt":1730202627525,"mc":[{"id":"1.235123059","rc":[{"atb":[[27,0.66]],"batb":[[2,25,10.47],[1,26,1.07]],"id":9517643}]}]}{"op":"mcm","id":2,"clk":"AOMbAJsmAJwg","pt":1730202627534,"mc":[{"id":"1.235123059","rc":[{"bdatb":[[1,26,1.07],[2,25,10.86]],"id":9517643},{"bdatl":[[2,4.3,8.82]],"id":74399333}]}]}{"op":"mcm","id":2,"clk":"APobALYmAL4g","pt":1730202627820,"mc":[{"id":"1.235123059","rc":[{"atb":[[23,10.81]],"batb":[],"id":9517643}]}]}{"op":"mcm","id":2,"clk":"AI0cANcmAN8g","pt":1730202628030,"mc":[{"id":"1.235123059","rc":[{"atb":[[23,7.55]],"batb":[],"id":9517643}]}]}{"op":"mcm","id":2,"clk":"ANEcAMYnALEh","pt":1730202628805,"mc":[{"id":"1.235123059","rc":[{"atb":[[1.85,25.06]],"batb":[[1,1.85,25.06]],"id":72176817}]}]}{"op":"mcm","id":2,"clk":"ANEcAMYnALQh","pt":1730202628810,"mc":[{"id":"1.235123059","rc":[{"bdatb":[[1,1.85,25.06]],"id":72176817}]}]}{"op":"mcm","id":2,"clk":"ANUcANMnAMYh","pt":1730202628914,"mc":[{"id":"1.235123059","rc":[{"atb":[[1.04,12.6]],"id":9517643},{"atb":[[1.04,12.6]],"id":74399333}]}]}{"op":"mcm","id":2,"clk":"AOUcAO0nAN0h","pt":1730202629120,"mc":[{"id":"1.235123059","rc":[{"atb":[[1.04,12.25]],"id":9517643},{"atb":[[1.04,12.19]],"id":74399333}]}]}{"op":"mcm","id":2,"clk":"AI8dAKooAJQi","pt":1730202629631,"mc":[{"id":"1.235123059","rc":[{"atb":[[1.04,11.77]],"atl":[[30,3.99]],"trd":[[30,86.7]],"batl":[[0,30,3.99]],"bdatl":[[0,30,3.99]],"tv":605.41,"id":9517643},{"atb":[[4,10.56],[1.04,11.77]],"batb":[[0,4,10.56]],"bdatb":[[0,4,10.56]],"id":74399333},{"bdatb":[],"bdatl":[[2,1.89,34.57]],"id":72176817}],"con":true,"tv":17623.41}]}{"op":"mcm","id":2,"clk":"AJAdAKwoAJUi","pt":1730202629639,"mc":[{"id":"1.235123059","rc":[{"atb":[[28,1.02],[27,0.2]],"batb":[[2,24,14.43],[1,25,11.08],[0,28,1.02]],"id":9517643}]}]}{"op":"mcm","id":2,"clk":"AJAdAK8oAJYi","pt":1730202629645,"mc":[{"id":"1.235123059","rc":[{"bdatb":[[0,28,1.02],[1,25,11.47],[2,24,14.43]],"id":9517643},{"bdatl":[[1,4.2,20.41],[2,4.3,7.23]],"id":74399333},{"bdatl":[[2,1.89,28.05]],"id":72176817}]}]}{"op":"mcm","id":2,"clk":"AOEfANIsAMIl","pt":1730202633854,"mc":[{"id":"1.235123059","rc":[{"atb":[[23,9.77]],"batb":[],"id":9517643}]}]}{"op":"mcm","id":2,"clk":"APYhALAwAJop","pt":1730202637727,"mc":[{"id":"1.235123059","rc":[{"spn":20.85,"id":9517643},{"spn":3.96,"id":74399333},{"atb":[[5.4,6.1]],"trd":[[5.4,103.27]],"batb":[[0,5.4,6.1]],"spn":5.11,"spf":2.86,"ltp":5.4,"tv":2946.92,"id":73074145},{"spf":1.51,"id":72176817}],"tv":17651.42}]}{"op":"mcm","id":2,"clk":"APchALYwAJ8p","pt":1730202637742,"mc":[{"id":"1.235123059","rc":[{"bdatl":[[2,4.3,3.45]],"id":74399333},{"bdatb":[[0,5.4,6.1]],"id":73074145}]}]}{"op":"mcm","id":2,"clk":"APshAMAwAKcp","pt":1730202637839,"mc":[{"id":"1.235123059","rc":[{"atb":[[4,14.52]],"batb":[[0,4,14.52]],"id":74399333},{"atb":[[5.4,5.21]],"batb":[[0,5.4,5.21]],"id":73074145},{"atl":[[1.87,19.72]],"batl":[[0,1.87,19.72]],"id":72176817}]}]}{"op":"mcm","id":2,"clk":"APwhAMEwAKgp","pt":1730202637850,"mc":[{"id":"1.235123059","rc":[{"bdatb":[[0,4,14.52]],"bdatl":[[1,4.2,20.33],[2,4.3,3.52]],"id":74399333},{"bdatb":[[0,5.4,5.21],[1,5.3,13.28],[2,5.2,39.67]],"bdatl":[],"id":73074145},{"bdatl":[[0,1.87,19.72],[2,1.89,27.89]],"id":72176817}]}]}{"op":"mcm","id":2,"clk":"AI8iANwwALwp","pt":1730202638052,"mc":[{"id":"1.235123059","rc":[{"atb":[[5.4,2.21]],"batb":[[0,5.4,2.21]],"id":73074145},{"atb":[[1.86,4]],"batb":[[0,1.86,4]],"id":72176817}]}]}{"op":"mcm","id":2,"clk":"AI8iANwwALwp","pt":1730202638062,"mc":[{"id":"1.235123059","rc":[{"bdatl":[[1,4.2,16.48],[2,4.3,7.29]],"id":74399333},{"bdatb":[[0,5.4,2.21]],"bdatl":[[2,5.7,55.89]],"id":73074145},{"bdatb":[[0,1.86,4]],"bdatl":[[2,1.89,19.32]],"id":72176817}]}]}{"op":"mcm","id":2,"clk":"AMQjAOcyAJsr","pt":1730202640215,"mc":[{"id":"1.235123059","rc":[{"atb":[[4,16.82]],"batb":[[0,4,16.82]],"id":74399333},{"atb":[[5.4,4.22]],"batb":[[0,5.4,4.22]],"id":73074145},{"atb":[[1.85,30.04]],"batb":[[1,1.85,30.04]],"id":72176817}]}]}{"op":"mcm","id":2,"clk":"AMQjAOwyAJ4r","pt":1730202640231,"mc":[{"id":"1.235123059","rc":[{"bdatb":[[0,4,16.82]],"bdatl":[[1,4.2,19.07],[2,4.3,4.76]],"id":74399333},{"bdatb":[[0,5.4,4.22]],"bdatl":[],"id":73074145},{"bdatb":[[1,1.85,30.04]],"bdatl":[[2,1.89,25.07]],"id":72176817}]}]}{"op":"mcm","id":2,"clk":"ANsjAI8zAL4r","pt":1730202640525,"mc":[{"id":"1.235123059","rc":[{"atb":[[26,8.41]],"batb":[[2,25,10.47],[1,26,8.61]],"id":9517643}]}]}{"op":"mcm","id":2,"clk":"ANsjAJAzAL4r","pt":1730202640531,"mc":[{"id":"1.235123059","rc":[{"bdatb":[[1,26,8.61],[2,25,10.86]],"id":9517643}]}]}{"op":"mcm","id":2,"clk":"AOUjAKYzANEr","pt":1730202640733,"mc":[{"id":"1.235123059","rc":[{"atb":[[27,1.23]],"batb":[[2,26,8.41],[1,27,1.23]],"id":9517643}]}]}{"op":"mcm","id":2,"clk":"AOUjAKYzANEr","pt":1730202640735,"mc":[{"id":"1.235123059","rc":[{"bdatb":[[1,27,1.23],[2,26,8.41]],"id":9517643},{"bdatl":[[2,4.3,9.98]],"id":74399333}]}]}{"op":"mcm","id":2,"clk":"AO0jALAzAN4r","pt":1730202640836,"mc":[{"id":"1.235123059","rc":[{"spb":[[6,145]],"id":73074145}]}]}{"op":"mcm","id":2,"clk":"AIEkAM0zAP4r","pt":1730202641146,"mc":[{"id":"1.235123059","rc":[{"atb":[[27,2.34]],"batb":[[1,27,2.34]],"id":9517643}]}]}{"op":"mcm","id":2,"clk":"AIMkANkzAIcs","pt":1730202641190,"mc":[{"id":"1.235123059","rc":[{"bdatb":[[1,27,2.34]],"id":9517643}]}]}{"op":"mcm","id":2,"clk":"ALokALs0AOMs","pt":1730202641935,"mc":[{"id":"1.235123059","rc":[{"atb":[[5.4,6.22]],"batb":[[0,5.4,6.22]],"id":73074145}]}]}{"op":"mcm","id":2,"clk":"ALokALs0AOUs","pt":1730202641939,"mc":[{"id":"1.235123059","rc":[{"bdatl":[[1,4.2,20.41],[2,4.3,10.24]],"id":74399333},{"bdatb":[[0,5.4,6.22]],"id":73074145},{"bdatl":[[2,1.89,28.05]],"id":72176817}]}]}{"op":"mcm","id":2,"clk":"AJslAOQ1AOMt","pt":1730202643135,"mc":[{"id":"1.235123059","rc":[{"atb":[[4,14.15]],"batb":[[0,4,14.15]],"id":74399333},{"atb":[[5.4,10.4],[4.9,7.41],[5.5,0.22]],"atl":[[5.5,0]],"trd":[[5.5,497.69]],"batb":[[0,5.4,10.62]],"batl":[[2,5.8,17.31],[1,5.7,54.58],[0,5.6,8.42]],"ltp":5.5,"tv":2950.48,"id":73074145}],"con":true,"tv":17654.98}]}{"op":"mcm","id":2,"clk":"AJslAOQ1AOMt","pt":1730202643137,"mc":[{"id":"1.235123059","rc":[{"bdatb":[],"bdatl":[[2,34,1.84]],"id":9517643},{"bdatb":[[1,3.95,32.72],[0,4,14.15]],"bdatl":[[0,4.1,27.03],[1,4.2,20.12]],"id":74399333},{"bdatb":[[0,5.4,10.62]],"bdatl":[[0,5.6,8.42],[1,5.7,55.89],[2,5.8,25.79]],"id":73074145},{"bdatb":[[2,1.84,23.5]],"bdatl":[[1,1.88,368.83],[2,1.89,27.41]],"id":72176817}]}]}{"op":"mcm","id":2,"clk":"ALMmAK83AJMv","pt":1730202644739,"mc":[{"id":"1.235123059","rc":[{"atl":[[5.9,12.05]],"batl":[],"id":73074145}]}]}{"op":"mcm","id":2,"clk":"ALomALc3AJov","pt":1730202644839,"mc":[{"id":"1.235123059","rc":[{"atb":[[5.4,6.2],[5.5,0]],"trd":[[5.4,111.68],[5.5,498.13]],"batb":[[0,5.4,6.2]],"ltp":5.4,"tv":2959.33,"id":73074145}],"tv":17663.83}]}{"op":"mcm","id":2,"clk":"ALsmAME3AJsv","pt":1730202644850,"mc":[{"id":"1.235123059","rc":[{"bdatl":[[2,34,1.8]],"id":9517643},{"bdatl":[[0,4.1,26.73],[1,4.2,20.41]],"id":74399333},{"bdatb":[[0,5.4,6.2]],"id":73074145},{"bdatl":[[1,1.88,368.19],[2,1.89,28.05]],"id":72176817}]}]}{"op":"mcm","id":2,"clk":"AMEmAMg3AKQv","pt":1730202644946,"mc":[{"id":"1.235123059","rc":[{"atb":[[5.4,8.02]],"batb":[[0,5.4,8.02]],"id":73074145}]}]}{"op":"mcm","id":2,"clk":"AMImAMs3AKYv","pt":1730202644951,"mc":[{"id":"1.235123059","rc":[{"bdatb":[[0,5.4,8.02]],"id":73074145}]}]}{"op":"mcm","id":2,"clk":"ANAmAOM3ALYv","pt":1730202645153,"mc":[{"id":"1.235123059","rc":[{"atb":[[5.3,10.69]],"batb":[[1,5.3,10.69]],"id":73074145}]}]}{"op":"mcm","id":2,"clk":"ANImAOQ3ALgv","pt":1730202645161,"mc":[{"id":"1.235123059","rc":[{"bdatb":[[1,5.3,17.65]],"id":73074145}]}]}{"op":"mcm","id":2,"clk":"AIsnALE4AIEw","pt":1730202645828,"mc":[{"id":"1.235123059","rc":[{"atb":[[5.3,6.32]],"atl":[[5.9,2.56]],"batb":[[1,5.3,6.32]],"batl":[],"id":73074145}]}]}{"op":"mcm","id":2,"clk":"AI0nALI4AIMw","pt":1730202645848,"mc":[{"id":"1.235123059","rc":[{"bdatb":[[1,5.3,13.28]],"bdatl":[],"id":73074145}]}]}{"op":"mcm","id":2,"clk":"AKInANM4AJww","pt":1730202646165,"mc":[{"id":"1.235123059","marketDefinition":{"bspMarket":true,"turnInPlayEnabled":true,"persistenceEnabled":true,"marketBaseRate":5,"eventId":"33728902","eventTypeId":"7","numberOfWinners":1,"bettingType":"ODDS","marketType":"WIN","marketTime":"2024-10-29T12:40:00.000Z","suspendTime":"2024-10-29T12:40:00.000Z","bspReconciled":false,"complete":true,"inPlay":false,"crossMatching":true,"runnersVoidable":false,"numberOfActiveRunners":4,"betDelay":0,"status":"OPEN","runners":[{"adjustmentFactor":48.37,"status":"ACTIVE","sortPriority":1,"id":72176817},{"adjustmentFactor":27.648,"status":"ACTIVE","sortPriority":2,"id":74399333},{"adjustmentFactor":19.875,"status":"ACTIVE","sortPriority":3,"id":73074145},{"adjustmentFactor":4.107,"status":"ACTIVE","sortPriority":4,"id":9517643},{"adjustmentFactor":10.869,"status":"REMOVED","sortPriority":5,"removalDate":"2024-10-28T09:11:27.000Z","id":73115482}],"regulators":["MR_INT"],"venue":"Catterick","countryCode":"GB","discountAllowed":true,"timezone":"Europe/London","openDate":"2024-10-29T12:40:00.000Z","version":6242880441,"raceType":"Flat","priceLadderDefinition":{"type":"CLASSIC"}}}]}{"op":"mcm","id":2,"clk":"AK4oAIg6AM8x","pt":1730202647716,"mc":[{"id":"1.235123059","rc":[{"atl":[[2.22,0]],"id":72176817}]}]}{"op":"mcm","id":2,"clk":"AM8oALQ6APox","pt":1730202648117,"mc":[{"id":"1.235123059","rc":[{"atl":[[1.88,36.75]],"batl":[[1,1.88,36.75]],"id":72176817}]}]}{"op":"mcm","id":2,"clk":"ANEoALQ6APwx","pt":1730202648126,"mc":[{"id":"1.235123059","rc":[{"bdatb":[[2,5.2,38.98]],"id":73074145},{"bdatl":[[1,1.88,36.75]],"id":72176817}]}]}{"op":"mcm","id":2,"clk":"ANooAME6AIEy","pt":1730202648214,"mc":[{"id":"1.235123059","rc":[{"atb":[[1.86,0]],"atl":[[1.86,327.44]],"trd":[[1.86,833.55]],"batb":[[2,1.83,67.65],[1,1.84,23.5],[0,1.85,30.04]],"batl":[[2,1.88,36.75],[1,1.87,19.72],[0,1.86,327.44]],"tv":10204.79,"id":72176817}],"tv":17671.83}]}{"op":"mcm","id":2,"clk":"ANooAMQ6AIIy","pt":1730202648221,"mc":[{"id":"1.235123059","rc":[{"bdatb":[[1,3.95,44.65],[2,3.9,57.76]],"bdatl":[[2,4.3,8.51]],"id":74399333},{"bdatb":[[0,5.4,28.31],[1,5.3,6.32],[2,5.2,27.63]],"bdatl":[[1,5.7,54.58],[2,5.8,26.9]],"id":73074145},{"bdatb":[[0,1.85,30.04],[1,1.84,23.5],[2,1.83,93.41]],"bdatl":[[0,1.86,327.44],[1,1.87,19.72],[2,1.88,36.75]],"id":72176817}]}]}{"op":"mcm","id":2,"clk":"AOMoAMw6AIoy","pt":1730202648323,"mc":[{"id":"1.235123059","rc":[{"atb":[[5.4,11.05]],"batb":[[0,5.4,11.05]],"id":73074145}]}]}{"op":"mcm","id":2,"clk":"AOQoANY6AIoy","pt":1730202648340,"mc":[{"id":"1.235123059","rc":[{"bdatl":[[2,4.3,9.46]],"id":74399333},{"bdatb":[[0,5.4,31.35]],"id":73074145}]}]}{"op":"mcm","id":2,"clk":"AO0oANs6AI4y","pt":1730202648439,"mc":[{"id":"1.235123059","rc":[{"atl":[[4.4,25]],"batl":[],"id":74399333},{"atb":[[1.85,26.85]],"batb":[[0,1.85,26.85]],"id":72176817}]}]}{"op":"mcm","id":2,"clk":"AO0oANw6AJYy","pt":1730202648443,"mc":[{"id":"1.235123059","rc":[{"bdatb":[],"bdatl":[[2,5.8,25.88]],"id":73074145},{"bdatb":[[0,1.85,26.85]],"id":72176817}]}]}{"op":"mcm","id":2,"clk":"ANApAJg8AJoz","pt":1730202649823,"mc":[{"id":"1.235123059","rc":[{"atb":[[1.82,35.86]],"batb":[],"id":72176817}]}]}{"op":"mcm","id":2,"clk":"AOgpAMA8ALcz","pt":1730202650132,"mc":[{"id":"1.235123059","rc":[{"atb":[[15,0]],"id":9517643},{"atb":[[2.12,0]],"atl":[[4.1,24.73]],"batl":[[0,4.1,24.73]],"id":74399333},{"atb":[[3.45,0]],"id":73074145},{"atl":[[5.3,0]],"id":72176817}]}]}{"op":"mcm","id":2,"clk":"AOkpAMY8ALwz","pt":1730202650143,"mc":[{"id":"1.235123059","rc":[{"bdatl":[[0,4.1,24.73]],"id":74399333},{"bdatb":[[0,5.4,29.83],[2,5.2,29.21]],"id":73074145}]}]}{"op":"mcm","id":2,"clk":"APEpAM08AL8z","pt":1730202650236,"mc":[{"id":"1.235123059","rc":[{"atl":[[1.88,67.86]],"batl":[[2,1.88,67.86]],"id":72176817}]}]}{"op":"mcm","id":2,"clk":"APIpAM48AMIz","pt":1730202650242,"mc":[{"id":"1.235123059","rc":[{"bdatl":[[2,1.88,67.86]],"id":72176817}]}]}{"op":"mcm","id":2,"clk":"AIoqAPM8ANoz","pt":1730202650543,"mc":[{"id":"1.235123059","rc":[{"atb":[[15,2]],"id":9517643},{"atb":[[2.12,2]],"atl":[[4.1,26.73]],"batl":[[0,4.1,26.73]],"id":74399333},{"atb":[[3.45,2]],"id":73074145},{"atb":[[1.85,28.85]],"atl":[[5.4,2]],"batb":[[0,1.85,28.85]],"id":72176817}]}]}{"op":"mcm","id":2,"clk":"AIsqAPQ8ANsz","pt":1730202650549,"mc":[{"id":"1.235123059","rc":[{"bdatl":[[0,4.1,26.73]],"id":74399333},{"bdatb":[[0,5.4,31.35],[2,5.2,27.63]],"bdatl":[[2,5.8,26.52]],"id":73074145},{"bdatb":[[0,1.85,28.85]],"id":72176817}]}]}{"op":"mcm","id":2,"clk":"AJkqAJA9AOsz","pt":1730202650752,"mc":[{"id":"1.235123059","rc":[{"atb":[[29,1.72]],"atl":[[34,0.33]],"batb":[[2,27,2.34],[1,28,1.02],[0,29,1.72]],"batl":[[2,36,2.3]],"id":9517643},{"atb":[[5.4,20.31]],"atl":[[5.8,8.69]],"batb":[[0,5.4,20.31]],"batl":[[2,5.8,8.69]],"id":73074145}]}]}{"op":"mcm","id":2,"clk":"AJ4qAJc9AO0z","pt":1730202650763,"mc":[{"id":"1.235123059","rc":[{"bdatb":[[0,29,1.72],[1,28,1.02],[2,27,2.34]],"bdatl":[[2,36,2.3]],"id":9517643},{"bdatb":[],"bdatl":[[1,4.2,26.35],[2,4.3,12.25]],"id":74399333},{"bdatb":[[0,5.4,40.61]],"bdatl":[[2,5.8,17.9]],"id":73074145}]}]}{"op":"mcm","id":2,"clk":"AKUqAJk9APYz","pt":1730202650862,"mc":[{"id":"1.235123059","rc":[{"atb":[[28,1.28]],"atl":[[30,2.99],[32,0.92]],"trd":[[30,88.7]],"batb":[[1,28,1.28]],"batl":[[2,36,1.97],[1,34,1.25],[0,30,2.99]],"tv":607.41,"id":9517643}],"tv":17673.83}]}{"op":"mcm","id":2,"clk":"AKYqAJw9APcz","pt":1730202650873,"mc":[{"id":"1.235123059","rc":[{"bdatb":[[1,28,1.28]],"bdatl":[[0,30,2.99],[1,34,1.25],[2,36,1.97]],"id":9517643},{"bdatb":[[2,3.9,48.18]],"bdatl":[],"id":74399333},{"bdatb":[[0,5.4,36.92],[1,5.3,10.08],[2,5.2,25.69]],"bdatl":[],"id":73074145}]}]}{"op":"mcm","id":2,"clk":"AOgqAIU+ALw0","pt":1730202651634,"mc":[{"id":"1.235123059","rc":[{"atl":[[1.87,14.16],[1.86,0]],"trd":[[1.87,636.83],[1.86,1488.43]],"batl":[[2,1.89,13.01],[1,1.88,67.86],[0,1.87,14.16]],"ltp":1.87,"tv":10870.79,"id":72176817}],"tv":18339.83}]}{"op":"mcm","id":2,"clk":"AOsqAIY+AL40","pt":1730202651642,"mc":[{"id":"1.235123059","rc":[{"bdatb":[[1,3.95,32.72],[2,3.9,41.83]],"id":74399333},{"bdatb":[[0,5.4,20.31],[1,5.3,11.32],[2,5.2,37.85]],"id":73074145},{"bdatl":[[0,1.87,14.16],[1,1.88,67.86],[2,1.89,42.96]],"id":72176817}]}]}{"op":"mcm","id":2,"clk":"APEqAJU+AMg0","pt":1730202651739,"mc":[{"id":"1.235123059","rc":[{"atb":[[1.86,27.16],[1.85,31.71]],"batb":[[2,1.84,23.5],[1,1.85,31.71],[0,1.86,27.16]],"id":72176817}]}]}{"op":"mcm","id":2,"clk":"APMqAJY+AMk0","pt":1730202651748,"mc":[{"id":"1.235123059","rc":[{"bdatl":[[1,4.2,34.02],[2,4.3,7.8]],"id":74399333},{"bdatl":[[1,5.7,63.44],[2,5.8,9.74]],"id":73074145},{"bdatb":[[0,1.86,27.16],[1,1.85,31.71],[2,1.84,23.5]],"id":72176817}]}]}{"op":"mcm","id":2,"clk":"AP4qAKE+ANM0","pt":1730202651843,"mc":[{"id":"1.235123059","rc":[{"atl":[[4.4,28.42]],"batl":[],"id":74399333},{"atb":[[5.5,1]],"batb":[[2,5.3,6.32],[1,5.4,20.31],[0,5.5,1]],"id":73074145}]}]}{"op":"mcm","id":2,"clk":"AP4qAKM+ANU0","pt":1730202651854,"mc":[{"id":"1.235123059","rc":[{"bdatl":[[1,34,1.41]],"id":9517643},{"bdatl":[[0,4.1,28.07],[1,4.2,32.71],[2,4.3,9.08]],"id":74399333},{"bdatb":[[0,5.5,1],[1,5.4,20.31],[2,5.3,11.32]],"id":73074145},{"bdatl":[[1,1.88,70.79],[2,1.89,40.05]],"id":72176817}]}]}{"op":"mcm","id":2,"clk":"AIYrAKw+AOA0","pt":1730202651949,"mc":[{"id":"1.235123059","rc":[{"atb":[[5.4,18.49]],"batb":[[1,5.4,18.49]],"id":73074145},{"atl":[[1.88,36.75]],"batl":[[1,1.88,36.75]],"id":72176817}]}]}{"op":"mcm","id":2,"clk":"AIYrALQ+AOI0","pt":1730202651962,"mc":[{"id":"1.235123059","rc":[{"bdatb":[],"bdatl":[[2,4.3,7.68]],"id":74399333},{"bdatb":[[1,5.4,18.49]],"id":73074145},{"bdatl":[[1,1.88,39.68]],"id":72176817}]}]}{"op":"mcm","id":2,"clk":"AJgrAMg+APY0","pt":1730202652156,"mc":[{"id":"1.235123059","rc":[{"atb":[[1.82,3.02]],"batb":[],"id":72176817}]}]}{"op":"mcm","id":2,"clk":"AO4sAP1AANQ2","pt":1730202654350,"mc":[{"id":"1.235123059","rc":[{"atb":[[1.86,36.34]],"batb":[[0,1.86,36.34]],"id":72176817}]}]}{"op":"mcm","id":2,"clk":"AO8sAINBANU2","pt":1730202654362,"mc":[{"id":"1.235123059","rc":[{"bdatl":[[2,4.3,11.65]],"id":74399333},{"bdatl":[[1,5.7,64.51],[2,5.8,10.59]],"id":73074145},{"bdatb":[[0,1.86,36.34]],"id":72176817}]}]}{"op":"mcm","id":2,"clk":"APgsAIpBANk2","pt":1730202654453,"mc":[{"id":"1.235123059","rc":[{"atl":[[30,2.12]],"trd":[[30,90.44]],"batl":[[0,30,2.12]],"tv":609.15,"id":9517643},{"atb":[[4,20.42]],"batb":[[0,4,20.42]],"id":74399333},{"atb":[[5.4,21.66]],"batb":[[1,5.4,21.66]],"id":73074145}],"tv":18341.57}]}{"op":"mcm","id":2,"clk":"APksAItBANo2","pt":1730202654460,"mc":[{"id":"1.235123059","rc":[{"bdatl":[[0,30,2.12]],"id":9517643},{"bdatb":[[0,4,20.42]],"bdatl":[],"id":74399333},{"bdatb":[[1,5.4,21.66]],"bdatl":[[1,5.7,66.44],[2,5.8,11.12]],"id":73074145},{"bdatb":[],"bdatl":[[2,1.89,53.32]],"id":72176817}]}]}{"op":"mcm","id":2,"clk":"AIMtAJdBAOQ2","pt":1730202654554,"mc":[{"id":"1.235123059","rc":[{"atb":[[1.86,39.14]],"batb":[[0,1.86,39.14]],"id":72176817}]}]}{"op":"mcm","id":2,"clk":"AIQtAJdBAOY2","pt":1730202654557,"mc":[{"id":"1.235123059","rc":[{"bdatl":[[2,4.3,12.86]],"id":74399333},{"bdatl":[[1,5.7,67.35],[2,5.8,10.23]],"id":73074145},{"bdatb":[[0,1.86,39.14]],"id":72176817}]}]}{"op":"mcm","id":2,"clk":"ANQuAPVCALU4","pt":1730202656533,"mc":[{"id":"1.235123059","rc":[{"atl":[[5.6,10.42]],"batl":[[0,5.6,10.42]],"id":73074145}]}]}{"op":"mcm","id":2,"clk":"ANUuAPtCALc4","pt":1730202656543,"mc":[{"id":"1.235123059","rc":[{"bdatb":[[2,3.9,44.7]],"id":74399333},{"bdatl":[[0,5.6,10.42]],"id":73074145}]}]}{"op":"mcm","id":2,"clk":"AKcvANJDAII5","pt":1730202657461,"mc":[{"id":"1.235123059","rc":[{"atl":[[5.6,11.42]],"batl":[[0,5.6,11.42]],"id":73074145}]}]}{"op":"mcm","id":2,"clk":"AKcvANZDAIM5","pt":1730202657469,"mc":[{"id":"1.235123059","rc":[{"bdatb":[[2,3.9,46.05]],"id":74399333},{"bdatl":[[0,5.6,11.42]],"id":73074145}]}]}{"op":"mcm","id":2,"clk":"AJAxAIxGAOo6","pt":1730202660044,"mc":[{"id":"1.235123059","rc":[{"atl":[[5.6,13.42]],"batl":[[0,5.6,13.42]],"id":73074145}]}]}{"op":"mcm","id":2,"clk":"AJMxAI9GAOs6","pt":1730202660050,"mc":[{"id":"1.235123059","rc":[{"bdatl":[[0,5.6,13.42]],"id":73074145}]}]}{"op":"mcm","id":2,"clk":"APsxAPFGAOE7","pt":1730202661147,"mc":[{"id":"1.235123059","rc":[{"atb":[[26,0.41]],"batb":[],"id":9517643}]}]}{"op":"mcm","id":2,"clk":"ALMyALdHAJY8","pt":1730202661747,"mc":[{"id":"1.235123059","rc":[{"atb":[[5.5,3]],"batb":[[0,5.5,3]],"id":73074145}]}]}{"op":"mcm","id":2,"clk":"ALMyAL1HAJg8","pt":1730202661763,"mc":[{"id":"1.235123059","rc":[{"bdatl":[[1,34,1.74]],"id":9517643},{"bdatl":[[0,4.1,30.76],[1,4.2,30.09],[2,4.3,13.32]],"id":74399333},{"bdatb":[[0,5.5,3]],"id":73074145},{"bdatl":[[1,1.88,45.53],[2,1.89,47.5]],"id":72176817}]}]}{"op":"mcm","id":2,"clk":"ALwyAMJHAJw8","pt":1730202661848,"mc":[{"id":"1.235123059","rc":[{"atl":[[1.87,32.47]],"batl":[[0,1.87,32.47]],"id":72176817}]}]}{"op":"mcm","id":2,"clk":"ALwyAMJHAJ08","pt":1730202661852,"mc":[{"id":"1.235123059","rc":[{"bdatb":[[2,5.3,17.77]],"id":73074145},{"bdatl":[[0,1.87,32.47]],"id":72176817}]}]}{"op":"mcm","id":2,"clk":"AMYyAM9HAKo8","pt":1730202661960,"mc":[{"id":"1.235123059","rc":[{"atb":[[1.86,36.34]],"batb":[[0,1.86,36.34]],"id":72176817}]}]}{"op":"mcm","id":2,"clk":"AMYyAM9HAKs8","pt":1730202661962,"mc":[{"id":"1.235123059","rc":[{"bdatl":[[1,5.7,66.44],[2,5.8,11.12]],"id":73074145},{"bdatb":[[0,1.86,36.34]],"id":72176817}]}]}{"op":"mcm","id":2,"clk":"AP8yAJ5IAO08","pt":1730202662577,"mc":[{"id":"1.235123059","rc":[{"atl":[[4.4,25],[4.5,16.83]],"batl":[],"id":74399333}]}]}{"op":"mcm","id":2,"clk":"AOczAKJJANA9","pt":1730202663573,"mc":[{"id":"1.235123059","rc":[{"atb":[[30,4.78]],"atl":[[30,0]],"trd":[[30,94.68]],"batb":[[2,28,1.28],[1,29,1.72],[0,30,4.78]],"batl":[[2,40,10.79],[1,36,1.97],[0,34,1.25]],"tv":613.39,"id":9517643}],"tv":18345.81}]}{"op":"mcm","id":2,"clk":"AOczAKxJANE9","pt":1730202663583,"mc":[{"id":"1.235123059","rc":[{"bdatb":[[0,30,4.78],[1,29,1.72],[2,28,1.28]],"bdatl":[[0,34,1.74],[1,36,1.97],[2,38,1.62]],"id":9517643},{"bdatb":[[2,3.9,37.26]],"bdatl":[[1,4.2,39.77],[2,4.3,11.65]],"id":74399333},{"bdatb":[[2,5.3,6.32]],"bdatl":[[0,5.6,25.49],[1,5.7,57.05],[2,5.8,16.38]],"id":73074145},{"bdatb":[],"bdatl":[[0,1.87,41.29],[1,1.88,36.75]],"id":72176817}]}]}{"op":"mcm","id":2,"clk":"APQzALVJAOs9","pt":1730202663726,"mc":[{"id":"1.235123059","rc":[{"atb":[[30,1.45]],"trd":[[30,104.24]],"batb":[[0,30,1.45]],"tv":622.95,"id":9517643},{"atl":[[4.5,20.08]],"batl":[],"id":74399333}],"tv":18355.37}]}{"op":"mcm","id":2,"clk":"APQzALVJAO49","pt":1730202663732,"mc":[{"id":"1.235123059","rc":[{"bdatb":[[0,30,1.45]],"id":9517643},{"bdatl":[[2,4.3,3.86]],"id":74399333},{"bdatl":[[0,5.6,21.18],[1,5.7,58.81],[2,5.8,11.12]],"id":73074145}]}]}{"op":"mcm","id":2,"clk":"AP4zAMBJAP09","pt":1730202663884,"mc":[{"id":"1.235123059","rc":[{"atl":[[32,2.91]],"batl":[[1,36,2.3],[0,32,2.91]],"id":9517643}]}]}{"op":"mcm","id":2,"clk":"AP4zAMBJAP49","pt":1730202663889,"mc":[{"id":"1.235123059","rc":[{"bdatl":[[0,32,2.91],[1,36,2.79]],"id":9517643},{"bdatb":[[2,3.9,45.31]],"id":74399333}]}]}{"op":"mcm","id":2,"clk":"AIg0AMtJAIE+","pt":1730202663938,"mc":[{"id":"1.235123059","rc":[{"atb":[[30,0.22]],"batb":[[2,27,2.34],[1,28,1.28],[0,29,1.94]],"id":9517643}]}]}{"op":"mcm","id":2,"clk":"AIg0AMtJAII+","pt":1730202663943,"mc":[{"id":"1.235123059","rc":[{"bdatb":[[0,29,1.94],[1,28,1.28],[2,27,2.34]],"id":9517643},{"bdatl":[[1,4.2,31.66],[2,4.3,11.79]],"id":74399333},{"bdatl":[[0,5.6,14.59],[1,5.7,65.28]],"id":73074145},{"bdatl":[[0,1.87,36],[1,1.88,42.02]],"id":72176817}]}]}{"op":"mcm","id":2,"clk":"AJI0ANVJAIk+","pt":1730202664040,"mc":[{"id":"1.235123059","rc":[{"atb":[[30,0],[29,1.94]],"id":9517643}]}]}{"op":"mcm","id":2,"clk":"AJI0ANVJAIk+","pt":1730202664043,"mc":[{"id":"1.235123059","rc":[{"bdatl":[[1,4.2,31.61],[2,4.3,11.84]],"id":74399333},{"bdatl":[[0,5.6,13.42],[1,5.7,66.44]],"id":73074145},{"bdatl":[[0,1.87,32.47],[1,1.88,45.53]],"id":72176817}]}]}{"op":"mcm","id":2,"clk":"AJ40AN5JAI8+","pt":1730202664144,"mc":[{"id":"1.235123059","rc":[{"atl":[[32,7.6]],"batl":[[0,32,7.6]],"id":9517643}]}]}{"op":"mcm","id":2,"clk":"AJ80AN9JAI8+","pt":1730202664155,"mc":[{"id":"1.235123059","rc":[{"bdatl":[[0,32,7.6]],"id":9517643}]}]}{"op":"mcm","id":2,"clk":"AJM1APZKAJE/","pt":1730202665444,"mc":[{"id":"1.235123059","rc":[{"atb":[[24,18.39]],"batb":[],"id":9517643}]}]}{"op":"mcm","id":2,"clk":"AIo2AJRMAJpA","pt":1730202666747,"mc":[{"id":"1.235123059","rc":[{"atb":[[4.9,54.41]],"batb":[],"id":73074145}]}]}{"op":"mcm","id":2,"clk":"AKc4AIJPAMxC","pt":1730202669747,"mc":[{"id":"1.235123059","rc":[{"atl":[[2.22,0.77]],"id":72176817}]}]}{"op":"mcm","id":2,"clk":"AJc5AIZQALtD","pt":1730202670843,"mc":[{"id":"1.235123059","rc":[{"atb":[[5.5,23.07]],"batb":[[0,5.5,23.07]],"id":73074145}]}]}{"op":"mcm","id":2,"clk":"AJc5AIdQAL1D","pt":1730202670848,"mc":[{"id":"1.235123059","rc":[{"bdatl":[[1,34,2.32],[2,36,1.97]],"id":9517643},{"bdatl":[[0,4.1,43.22],[1,4.2,27.61],[2,4.3,11.4]],"id":74399333},{"bdatb":[[0,5.5,23.07]],"id":73074145},{"bdatl":[[1,1.88,80.2],[2,1.89,18.45]],"id":72176817}]}]}{"op":"mcm","id":2,"clk":"AKI6AKdRAOBE","pt":1730202672340,"mc":[{"id":"1.235123059","rc":[{"atl":[[4.5,16.83]],"batl":[],"id":74399333}]}]}{"op":"mcm","id":2,"clk":"ALY/AKlXAOpI","pt":1730202677341,"ct":"HEARTBEAT"}{"op":"mcm","id":2,"clk":"AJdAALVYAOhJ","pt":1730202678548,"mc":[{"id":"1.235123059","rc":[{"atb":[[27,1.23]],"batb":[[2,27,1.23]],"id":9517643}]}]}{"op":"mcm","id":2,"clk":"AJdAALxYAOpJ","pt":1730202678563,"mc":[{"id":"1.235123059","rc":[{"bdatb":[[2,27,1.23]],"id":9517643},{"bdatl":[[2,4.3,4.43]],"id":74399333}]}]}{"op":"mcm","id":2,"clk":"AM1AAPdYAKFK","pt":1730202679066,"mc":[{"id":"1.235123059","rc":[{"atb":[[24,14.43]],"batb":[],"id":9517643}]}]}{"op":"mcm","id":2,"clk":"AO1AAKZZAMBK","pt":1730202679384,"mc":[{"id":"1.235123059","rc":[{"atb":[[5.6,6.29]],"atl":[[5.6,0]],"trd":[[5.6,385.77]],"batb":[[2,5.4,21.66],[1,5.5,23.07],[0,5.6,6.29]],"batl":[[2,5.9,2.56],[1,5.8,8.69],[0,5.7,54.58]],"ltp":5.6,"tv":2986.16,"id":73074145}],"tv":18382.2}]}{"op":"mcm","id":2,"clk":"AO1AAKZZAMBK","pt":1730202679397,"mc":[{"id":"1.235123059","rc":[{"bdatb":[],"bdatl":[[0,30,1.17],[1,32,7.6],[2,34,1.28]],"id":9517643},{"bdatb":[[2,3.9,29.74]],"bdatl":[[2,4.3,10.53]],"id":74399333},{"bdatb":[[0,5.6,6.29],[1,5.5,23.07],[2,5.4,21.66]],"bdatl":[[0,5.7,66.44],[1,5.8,11.12],[2,5.9,4.3]],"id":73074145},{"bdatb":[],"bdatl":[[0,1.87,51.3],[1,1.88,61.46]],"id":72176817}]}]}{"op":"mcm","id":2,"clk":"APlAAK5ZAMpK","pt":1730202679485,"mc":[{"id":"1.235123059","rc":[{"atl":[[5.7,62.2]],"batl":[[0,5.7,62.2]],"id":73074145},{"atl":[[1.87,42.83]],"batl":[[0,1.87,42.83]],"id":72176817}]}]}{"op":"mcm","id":2,"clk":"APtAALJZAMtK","pt":1730202679501,"mc":[{"id":"1.235123059","rc":[{"bdatb":[],"bdatl":[[0,5.7,74.06]],"id":73074145},{"bdatl":[[0,1.87,61.66]],"id":72176817}]}]}{"op":"mcm","id":2,"clk":"AINBALNZANBK","pt":1730202679581,"mc":[{"id":"1.235123059","rc":[{"atb":[[4,12.14]],"batb":[[0,4,12.14]],"id":74399333},{"atb":[[5.5,27.31]],"batb":[[1,5.5,27.31]],"id":73074145}]}]}{"op":"mcm","id":2,"clk":"AIRBALRZANFK","pt":1730202679589,"mc":[{"id":"1.235123059","rc":[{"bdatl":[[2,36,2.69]],"id":9517643},{"bdatb":[[0,4,12.14]],"bdatl":[[2,4.3,12.25]],"id":74399333},{"bdatb":[[1,5.5,27.31]],"bdatl":[[0,5.7,70.72],[1,5.8,11.98],[2,5.9,6.69]],"id":73074145},{"bdatl":[[1,1.88,43.84],[2,1.89,35.98]],"id":72176817}]}]}{"op":"mcm","id":2,"clk":"AJBBAMNZAN1K","pt":1730202679688,"mc":[{"id":"1.235123059","rc":[{"atb":[[27,0.2]],"batb":[[2,25,11.08]],"id":9517643}]}]}{"op":"mcm","id":2,"clk":"AJJBAM9ZAN5K","pt":1730202679699,"mc":[{"id":"1.235123059","rc":[{"bdatb":[[2,25,11.08]],"id":9517643},{"bdatl":[[1,4.2,23.27],[2,4.3,16.49]],"id":74399333}]}]}{"op":"mcm","id":2,"clk":"AKZBAOxZAPxK","pt":1730202679954,"mc":[{"id":"1.235123059","rc":[{"atb":[[5.6,5.29]],"trd":[[5.6,387.77]],"batb":[[0,5.6,5.29]],"tv":2988.16,"id":73074145}],"tv":18384.2}]}{"op":"mcm","id":2,"clk":"AKZBAO1ZAP9K","pt":1730202679965,"mc":[{"id":"1.235123059","rc":[{"bdatl":[[0,32,8.59],[1,36,2.86],[2,40,11.29]],"id":9517643},{"bdatb":[[0,5.6,5.29]],"id":73074145},{"bdatl":[[0,1.87,58.67],[1,1.88,46.82]],"id":72176817}]}]}{"op":"mcm","id":2,"clk":"AK5BAP1ZAIhL","pt":1730202680053,"mc":[{"id":"1.235123059","rc":[{"atb":[[5.4,23.66]],"batb":[[2,5.4,23.66]],"id":73074145}]}]}{"op":"mcm","id":2,"clk":"AK9BAP9ZAIhL","pt":1730202680060,"mc":[{"id":"1.235123059","rc":[{"bdatb":[[2,5.4,23.66]],"id":73074145}]}]}{"op":"mcm","id":2,"clk":"AL9BAJdaAJZL","pt":1730202680256,"mc":[{"id":"1.235123059","rc":[{"atb":[[5.4,25.66]],"batb":[[2,5.4,25.66]],"id":73074145}]}]}{"op":"mcm","id":2,"clk":"AL9BAJpaAJdL","pt":1730202680261,"mc":[{"id":"1.235123059","rc":[{"bdatb":[[2,5.4,25.66]],"id":73074145}]}]}{"op":"mcm","id":2,"clk":"AMlBAKtaAKJL","pt":1730202680371,"mc":[{"id":"1.235123059","rc":[{"atb":[[5.5,25.63],[5.6,0]],"trd":[[5.5,501.49],[5.6,398.35]],"batb":[[2,5.3,6.32],[1,5.4,25.66],[0,5.5,25.63]],"ltp":5.5,"tv":3002.1,"id":73074145}],"tv":18398.14}]}{"op":"mcm","id":2,"clk":"AMlBAKxaAKJL","pt":1730202680381,"mc":[{"id":"1.235123059","rc":[{"bdatl":[[0,32,7.6],[1,34,1.76],[2,36,1.97]],"id":9517643},{"bdatl":[[2,4.3,9.85]],"id":74399333},{"bdatb":[[0,5.5,25.63],[1,5.4,25.66],[2,5.3,6.32]],"id":73074145},{"bdatl":[[0,1.87,42.83],[1,1.88,62.58]],"id":72176817}]}]}{"op":"mcm","id":2,"clk":"ANJBALFaAKZL","pt":1730202680465,"mc":[{"id":"1.235123059","rc":[{"atl":[[5.7,65.22]],"batl":[[0,5.7,65.22]],"id":73074145}]}]}{"op":"mcm","id":2,"clk":"ANNBALJaAKlL","pt":1730202680476,"mc":[{"id":"1.235123059","rc":[{"bdatl":[[0,5.7,73.74]],"id":73074145}]}]}{"op":"mcm","id":2,"clk":"AOBBAL9aAK9L","pt":1730202680570,"mc":[{"id":"1.235123059","rc":[{"atb":[[5.5,22.63]],"batb":[[0,5.5,22.63]],"id":73074145}]}]}{"op":"mcm","id":2,"clk":"AOBBAMBaALFL","pt":1730202680581,"mc":[{"id":"1.235123059","rc":[{"bdatl":[[2,4.3,6.43]],"id":74399333},{"bdatb":[[0,5.5,22.63]],"id":73074145}]}]}{"op":"mcm","id":2,"clk":"AIBCAOZaAM9L","pt":1730202680884,"mc":[{"id":"1.235123059","rc":[{"atb":[[5.4,26.66]],"batb":[[1,5.4,26.66]],"id":73074145}]}]}{"op":"mcm","id":2,"clk":"AIJCAOdaANBL","pt":1730202680904,"mc":[{"id":"1.235123059","rc":[{"bdatb":[[1,5.4,26.66]],"id":73074145}]}]}{"op":"mcm","id":2,"clk":"APVCAPdbANlM","pt":1730202681989,"mc":[{"id":"1.235123059","rc":[{"atl":[[1.88,66.75]],"batl":[[1,1.88,66.75]],"id":72176817}]}]}{"op":"mcm","id":2,"clk":"APVCAPdbANlM","pt":1730202682000,"mc":[{"id":"1.235123059","rc":[{"bdatl":[[1,1.88,92.58]],"id":72176817}]}]}{"op":"mcm","id":2,"clk":"AORDANhcALRN","pt":1730202682917,"mc":[{"id":"1.235123059","rc":[{"atb":[[5.5,20.63]],"trd":[[5.5,505.49]],"batb":[[0,5.5,20.63]],"tv":3006.1,"id":73074145}],"tv":18402.14}]}{"op":"mcm","id":2,"clk":"AORDANhcALRN","pt":1730202682919,"mc":[{"id":"1.235123059","rc":[{"bdatb":[[0,5.5,20.63]],"id":73074145}]}]}{"op":"mcm","id":2,"clk":"AJ9FANVeAI5P","pt":1730202684894,"mc":[{"id":"1.235123059","rc":[{"atb":[[4,10.14]],"trd":[[4,685.75]],"batb":[[0,4,10.14]],"ltp":4,"tv":3906.3,"id":74399333}],"tv":18406.14}]}{"op":"mcm","id":2,"clk":"AKRFANZeAI9P","pt":1730202684905,"mc":[{"id":"1.235123059","rc":[{"bdatl":[[1,34,1.52]],"id":9517643},{"bdatb":[[0,4,10.14]],"id":74399333},{"bdatl":[[0,5.7,72.34],[1,5.8,13.36]],"id":73074145},{"bdatl":[[1,1.88,88.32],[2,1.89,40.21]],"id":72176817}]}]}{"op":"mcm","id":2,"clk":"AKVFAN9eAJRP","pt":1730202684989,"mc":[{"id":"1.235123059","rc":[{"atb":[[1.86,29.67]],"trd":[[1.86,1501.77]],"batb":[[0,1.86,29.67]],"ltp":1.86,"tv":10884.13,"id":72176817}],"tv":18419.48}]}{"op":"mcm","id":2,"clk":"AKVFAN9eAJRP","pt":1730202684991,"mc":[{"id":"1.235123059","rc":[{"bdatl":[[0,4.1,40.19],[1,4.2,26.22],[2,4.3,3.55]],"id":74399333},{"bdatl":[[1,5.8,11.22],[2,5.9,8.79]],"id":73074145},{"bdatb":[[0,1.86,29.67]],"id":72176817}]}]}{"op":"mcm","id":2,"clk":"AOxFAMpfAPtP","pt":1730202685879,"mc":[{"id":"1.235123059","rc":[{"atb":[[29,0.94]],"trd":[[29,55.12]],"batb":[[2,24,14.43],[1,25,11.08],[0,28,2.22]],"ltp":29,"tv":624.95,"id":9517643}],"tv":18421.48}]}{"op":"mcm","id":2,"clk":"AOxFAMpfAPtP","pt":1730202685893,"mc":[{"id":"1.235123059","rc":[{"bdatb":[[0,28,2.22],[1,25,11.08],[2,24,14.43]],"id":9517643},{"bdatl":[[1,4.2,19.32],[2,4.3,10.29]],"id":74399333},{"bdatl":[[2,5.9,3.88]],"id":73074145},{"bdatl":[[2,1.89,24.87]],"id":72176817}]}]}{"op":"mcm","id":2,"clk":"APNFANdfAIlQ","pt":1730202685991,"mc":[{"id":"1.235123059","rc":[{"atb":[[29,0.72],[28,1.02],[27,0.46]],"batb":[[1,25,11.34],[0,28,1.74]],"id":9517643},{"atb":[[4,14.14]],"batb":[[0,4,14.14]],"id":74399333},{"atb":[[5.5,23.67]],"batb":[[0,5.5,23.67]],"id":73074145}]}]}{"op":"mcm","id":2,"clk":"APZFANdfAIlQ","pt":1730202686015,"mc":[{"id":"1.235123059","rc":[{"bdatb":[[0,28,1.74],[1,25,11.34]],"bdatl":[[1,34,1.95]],"id":9517643},{"bdatb":[[0,4,14.14]],"bdatl":[[0,4.1,38.76],[1,4.2,19.14],[2,4.3,15.64]],"id":74399333},{"bdatb":[[0,5.5,23.67]],"bdatl":[[0,5.7,73.87],[1,5.8,9.94],[2,5.9,2.56]],"id":73074145},{"bdatl":[[1,1.88,92.98],[2,1.89,16.84]],"id":72176817}]}]}{"op":"mcm","id":2,"clk":"AP5FAOFfAJRQ","pt":1730202686087,"mc":[{"id":"1.235123059","rc":[{"atl":[[32,8.88]],"batl":[[0,32,8.88]],"id":9517643}]}]}{"op":"mcm","id":2,"clk":"AIBGAOJfAJdQ","pt":1730202686106,"mc":[{"id":"1.235123059","rc":[{"bdatl":[[0,32,8.88]],"id":9517643}]}]}{"op":"mcm","id":2,"clk":"ALNGAL1gANRQ","pt":1730202686755,"mc":[{"id":"1.235123059","rc":[{"atb":[[1.86,31.67]],"batb":[[0,1.86,31.67]],"id":72176817}]}]}{"op":"mcm","id":2,"clk":"ALRGAL1gANRQ","pt":1730202686760,"mc":[{"id":"1.235123059","rc":[{"bdatl":[[1,34,1.99]],"id":9517643},{"bdatl":[[2,5.9,2.96]],"id":73074145},{"bdatb":[[0,1.86,31.67]],"id":72176817}]}]}{"op":"mcm","id":2,"clk":"AI1HANBhAK9R","pt":1730202687850,"mc":[{"id":"1.235123059","rc":[{"atb":[[1.86,21.67]],"trd":[[1.86,1521.77]],"batb":[[0,1.86,21.67]],"tv":10904.13,"id":72176817}],"tv":18441.48}]}{"op":"mcm","id":2,"clk":"AI1HANFhALBR","pt":1730202687859,"mc":[{"id":"1.235123059","rc":[{"bdatl":[[1,34,1.52]],"id":9517643},{"bdatl":[[0,4.1,36.56],[1,4.2,21.28]],"id":74399333},{"bdatl":[[0,5.7,72.3],[1,5.8,11.5],[2,5.9,2.56]],"id":73074145},{"bdatb":[[0,1.86,21.67]],"id":72176817}]}]}{"op":"mcm","id":2,"clk":"AK9IAM5jAOtS","pt":1730202689773,"mc":[{"id":"1.235123059","rc":[{"atl":[[1.87,40.83]],"trd":[[1.87,640.83]],"batl":[[0,1.87,40.83]],"ltp":1.87,"tv":10908.13,"id":72176817}],"tv":18445.48}]}{"op":"mcm","id":2,"clk":"AK9IAM9jAO5S","pt":1730202689783,"mc":[{"id":"1.235123059","rc":[{"bdatl":[[0,1.87,40.83]],"id":72176817}]}]}{"op":"mcm","id":2,"clk":"AP5IAMpkAMtT","pt":1730202690705,"mc":[{"id":"1.235123059","rc":[{"atb":[[5.2,23.69]],"batb":[],"id":73074145}]}]}{"op":"mcm","id":2,"clk":"AL1JAKhlAKZU","pt":1730202691483,"mc":[{"id":"1.235123059","rc":[{"atb":[[4,12.14]],"trd":[[4,689.74]],"batb":[[0,4,12.14]],"tv":3910.29,"id":74399333}],"tv":18449.47}]}{"op":"mcm","id":2,"clk":"AMBJAK1lAKlU","pt":1730202691491,"mc":[{"id":"1.235123059","rc":[{"bdatb":[[0,4,12.14]],"id":74399333},{"bdatl":[[1,5.8,10.12],[2,5.9,2.69]],"id":73074145},{"bdatl":[[1,1.88,92.58],[2,1.89,13.4]],"id":72176817}]}]}{"op":"mcm","id":2,"clk":"AJxKALlmAJVV","pt":1730202692579,"mc":[{"id":"1.235123059","rc":[{"atb":[[5.5,21.67]],"trd":[[5.5,509.49]],"batb":[[0,5.5,21.67]],"tv":3010.1,"id":73074145}],"tv":18453.47}]}{"op":"mcm","id":2,"clk":"AKBKAL1mAJVV","pt":1730202692591,"mc":[{"id":"1.235123059","rc":[{"bdatl":[[2,4.3,13.08]],"id":74399333},{"bdatb":[[0,5.5,21.67]],"id":73074145}]}]}{"op":"mcm","id":2,"clk":"AKZKAMJmAJ9V","pt":1730202692680,"mc":[{"id":"1.235123059","rc":[{"atl":[[1.87,30.47]],"batl":[[0,1.87,30.47]],"id":72176817}]}]}{"op":"mcm","id":2,"clk":"AKZKAMdmAJ9V","pt":1730202692692,"mc":[{"id":"1.235123059","rc":[{"bdatl":[[0,1.87,30.47]],"id":72176817}]}]}{"op":"mcm","id":2,"clk":"ANBKAPZmAMhV","pt":1730202693049,"mc":[{"id":"1.235123059","rc":[{"atb":[[5.5,23.67]],"batb":[[0,5.5,23.67]],"id":73074145}]}]}{"op":"mcm","id":2,"clk":"ANBKAPZmANBV","pt":1730202693064,"mc":[{"id":"1.235123059","rc":[{"bdatl":[[2,4.3,15.64]],"id":74399333},{"bdatb":[[0,5.5,23.67]],"id":73074145}]}]}{"op":"mcm","id":2,"clk":"AMxLAKVoAOJW","pt":1730202694461,"mc":[{"id":"1.235123059","rc":[{"atb":[[5.6,2]],"batb":[[2,5.4,26.66],[1,5.5,23.67],[0,5.6,2]],"id":73074145}]}]}{"op":"mcm","id":2,"clk":"AMxLAKVoAORW","pt":1730202694473,"mc":[{"id":"1.235123059","rc":[{"bdatl":[[0,32,9.25],[1,34,1.19]],"id":9517643},{"bdatl":[[2,4.3,18.24]],"id":74399333},{"bdatb":[[0,5.6,2],[1,5.5,23.67],[2,5.4,26.66]],"id":73074145},{"bdatl":[[0,1.87,36.46],[1,1.88,86.62]],"id":72176817}]}]}{"op":"mcm","id":2,"clk":"ANdLAKxoAOtW","pt":1730202694555,"mc":[{"id":"1.235123059","rc":[{"atb":[[4,8.14]],"batb":[[0,4,8.14]],"id":74399333},{"atb":[[5.5,26.67]],"batb":[[1,5.5,26.67]],"id":73074145}]}]}{"op":"mcm","id":2,"clk":"ANdLAK9oAO1W","pt":1730202694566,"mc":[{"id":"1.235123059","rc":[{"bdatl":[[1,36,2.93],[2,40,10.99]],"id":9517643},{"bdatb":[[0,4,8.14]],"bdatl":[[2,4.3,18.43]],"id":74399333},{"bdatb":[[1,5.5,26.67]],"bdatl":[[0,5.7,70.94],[1,5.8,10.03],[2,5.9,4.09]],"id":73074145},{"bdatl":[[1,1.88,78.11],[2,1.89,21.87]],"id":72176817}]}]}{"op":"mcm","id":2,"clk":"AJ1NAJhqAK5Y","pt":1730202696564,"mc":[{"id":"1.235123059","rc":[{"atl":[[5.7,51.18]],"trd":[[5.7,344.97]],"batl":[[0,5.7,51.18]],"bdatb":[],"bdatl":[[0,5.7,56.9]],"ltp":5.7,"tv":3038.18,"id":73074145},{"atl":[[1.87,40.86]],"batl":[[0,1.87,40.86]],"bdatl":[[0,1.87,46.85]],"id":72176817}],"con":true,"tv":18481.55}]}{"op":"mcm","id":2,"clk":"AKpPAPhsALFa","pt":1730202699190,"mc":[{"id":"1.235123059","rc":[{"spn":20.96,"id":9517643},{"atb":[[5.5,28.67]],"batb":[[1,5.5,28.67]],"spn":5.44,"spf":3.74,"id":73074145},{"spn":1.83,"id":72176817}]}]}{"op":"mcm","id":2,"clk":"AKpPAPpsALNa","pt":1730202699204,"mc":[{"id":"1.235123059","rc":[{"bdatb":[[1,5.5,28.67]],"id":73074145}]}]}{"op":"mcm","id":2,"clk":"AOdPAMxtAOxa","pt":1730202699811,"mc":[{"id":"1.235123059","rc":[{"atb":[[5.6,0]],"trd":[[5.6,402.35]],"batb":[[2,5.3,6.32],[1,5.4,26.66],[0,5.5,28.67]],"ltp":5.6,"tv":3042.18,"id":73074145}],"tv":18485.55}]}{"op":"mcm","id":2,"clk":"AOpPANJtAO9a","pt":1730202699823,"mc":[{"id":"1.235123059","rc":[{"bdatl":[[0,32,8.88],[1,34,1.29],[2,36,1.97]],"id":9517643},{"bdatb":[[0,5.5,28.67],[1,5.4,26.66],[2,5.3,6.32]],"id":73074145},{"bdatl":[[0,1.87,40.86],[1,1.88,84.07]],"id":72176817}]}]}{"op":"mcm","id":2,"clk":"APhPAORtAIBb","pt":1730202699972,"mc":[{"id":"1.235123059","rc":[{"atb":[[5.5,25.67]],"atl":[[5.7,52.44]],"batb":[[0,5.5,25.67]],"batl":[[0,5.7,52.44]],"id":73074145},{"atl":[[1.87,89.36]],"batl":[[0,1.87,89.36]],"id":72176817}]}]}{"op":"mcm","id":2,"clk":"APhPAOVtAIFb","pt":1730202699982,"mc":[{"id":"1.235123059","rc":[{"bdatb":[],"bdatl":[[2,4.3,18.19]],"id":74399333},{"bdatb":[[0,5.5,25.67]],"bdatl":[[0,5.7,58.16]],"id":73074145},{"bdatl":[[0,1.87,89.36]],"id":72176817}]}]}{"op":"mcm","id":2,"clk":"AIBQAPJtAI9b","pt":1730202700088,"mc":[{"id":"1.235123059","rc":[{"atb":[[4,12.14]],"batb":[[0,4,12.14]],"id":74399333}]}]}{"op":"mcm","id":2,"clk":"AIVQAPNtAI9b","pt":1730202700099,"mc":[{"id":"1.235123059","rc":[{"bdatl":[[1,34,1.52]],"id":9517643},{"bdatb":[[0,4,12.14]],"id":74399333},{"bdatl":[[0,5.7,59.52],[1,5.8,10.12],[2,5.9,2.69]],"id":73074145},{"bdatl":[[1,1.88,92.58],[2,1.89,13.4]],"id":72176817}]}]}{"op":"mcm","id":2,"clk":"AJpRALVvAJ1c","pt":1730202701695,"mc":[{"id":"1.235123059","rc":[{"atl":[[5.6,2]],"batl":[[2,5.8,8.69],[1,5.7,52.44],[0,5.6,2]],"id":73074145}]}]}{"op":"mcm","id":2,"clk":"AJxRALVvAJ1c","pt":1730202701710,"mc":[{"id":"1.235123059","rc":[{"bdatb":[[2,3.9,32.61]],"id":74399333},{"bdatl":[[0,5.6,2],[1,5.7,59.52],[2,5.8,10.12]],"id":73074145}]}]}{"op":"mcm","id":2,"clk":"AKdRALxvAKhc","pt":1730202701790,"mc":[{"id":"1.235123059","rc":[{"atb":[[5,19.22]],"batb":[],"id":73074145}]}]}{"op":"mcm","id":2,"clk":"AI1SANVwAIpd","pt":1730202702877,"mc":[{"id":"1.235123059","rc":[{"atb":[[4,14.14]],"batb":[[0,4,14.14]],"id":74399333}]}]}{"op":"mcm","id":2,"clk":"AI9SAN5wAIxd","pt":1730202702886,"mc":[{"id":"1.235123059","rc":[{"bdatb":[[0,4,14.14]],"id":74399333},{"bdatl":[[2,5.8,11.5]],"id":73074145},{"bdatl":[[1,1.88,92.98],[2,1.89,16.85]],"id":72176817}]}]}{"op":"mcm","id":2,"clk":"APJUAPN0AJdg","pt":1730202707191,"mc":[{"id":"1.235123059","rc":[{"atb":[[29,2.51]],"batb":[[2,25,11.34],[1,28,1.02],[0,29,2.51]],"id":9517643}]}]}{"op":"mcm","id":2,"clk":"APJUAPR0AJhg","pt":1730202707195,"mc":[{"id":"1.235123059","rc":[{"bdatb":[[0,29,2.51],[1,28,1.02],[2,25,11.34]],"id":9517643},{"bdatl":[[1,4.2,28.14],[2,4.3,11.49]],"id":74399333},{"bdatl":[[1,1.88,96.84],[2,1.89,36.63]],"id":72176817}]}]}{"op":"mcm","id":2,"clk":"APxUAPx0AJ9g","pt":1730202707292,"mc":[{"id":"1.235123059","rc":[{"atb":[[28,1.31]],"batb":[[1,28,1.31]],"id":9517643}]}]}{"op":"mcm","id":2,"clk":"AIFVAIR1AKJg","pt":1730202707300,"mc":[{"id":"1.235123059","rc":[{"bdatb":[[1,28,1.31]],"id":9517643},{"bdatl":[[1,4.2,30.08],[2,4.3,9.6]],"id":74399333},{"bdatl":[[2,1.89,40.93]],"id":72176817}]}]}{"op":"mcm","id":2,"clk":"AJhYAMJ5AJZk","pt":1730202712300,"ct":"HEARTBEAT"}{"op":"mcm","id":2,"clk":"AM9ZAOx7AIZm","pt":1730202714692,"mc":[{"id":"1.235123059","rc":[{"atl":[[5.6,0]],"trd":[[5.6,406.35]],"batl":[[2,5.9,2.56],[1,5.8,8.69],[0,5.7,52.44]],"tv":3046.18,"id":73074145}],"tv":18489.55}]}{"op":"mcm","id":2,"clk":"AM9ZAPB7AIZm","pt":1730202714698,"mc":[{"id":"1.235123059","rc":[{"bdatb":[[2,3.9,29.74]],"id":74399333},{"bdatl":[[0,5.7,59.52],[1,5.8,11.5],[2,5.9,9.75]],"id":73074145}]}]}{"op":"mcm","id":2,"clk":"ANpZAIN8AJVm","pt":1730202714897,"mc":[{"id":"1.235123059","rc":[{"atb":[[5,16.66]],"batb":[],"id":73074145},{"atb":[[1.86,20.32]],"trd":[[1.86,1524.47]],"batb":[[0,1.86,20.32]],"ltp":1.86,"tv":10910.83,"id":72176817}],"tv":18492.25}]}{"op":"mcm","id":2,"clk":"ANtZAIR8AJVm","pt":1730202714902,"mc":[{"id":"1.235123059","rc":[{"bdatl":[[1,34,1.44]],"id":9517643},{"bdatl":[[0,4.1,35.95],[1,4.2,30.67],[2,4.3,9.25]],"id":74399333},{"bdatb":[],"bdatl":[[0,5.7,59.07],[1,5.8,11.93],[2,5.9,9.32]],"id":73074145},{"bdatb":[[0,1.86,20.32]],"id":72176817}]}]}{"op":"mcm","id":2,"clk":"AOJZAI58AJ1m","pt":1730202715000,"mc":[{"id":"1.235123059","rc":[{"atb":[[29,3.51]],"batb":[[0,29,3.51]],"id":9517643},{"atb":[[5.4,17.4]],"batb":[[1,5.4,17.4]],"id":73074145}]}]}{"op":"mcm","id":2,"clk":"AOhZAJV8AJ5m","pt":1730202715010,"mc":[{"id":"1.235123059","rc":[{"bdatb":[[0,29,3.51]],"id":9517643},{"bdatl":[[1,4.2,37.58],[2,4.3,2.86]],"id":74399333},{"bdatb":[[1,5.4,17.4]],"bdatl":[],"id":73074145},{"bdatl":[[2,1.89,56.28]],"id":72176817}]}]}{"op":"mcm","id":2,"clk":"APBZAKp8AKtm","pt":1730202715210,"mc":[{"id":"1.235123059","rc":[{"atb":[[29,3.82]],"batb":[[0,29,3.82]],"id":9517643}]}]}{"op":"mcm","id":2,"clk":"APFZAKt8AK5m","pt":1730202715216,"mc":[{"id":"1.235123059","rc":[{"bdatb":[[0,29,3.82]],"id":9517643},{"bdatl":[[1,4.2,37.9],[2,4.3,3.96]],"id":74399333},{"bdatl":[[2,1.89,57.79]],"id":72176817}]}]}